package mod.arcalitegames.odyssey.world.structure.structures.ruins.castle_ruins;

import mod.arcalitegames.odyssey.world.structure.StructureBase;
import net.minecraft.block.Blocks;
import net.minecraft.block.SlabBlock;
import net.minecraft.block.SnowyDirtBlock;
import net.minecraft.block.StairsBlock;
import net.minecraft.block.WallBlock;
import net.minecraft.block.WallHeight;
import net.minecraft.state.properties.Half;
import net.minecraft.state.properties.SlabType;
import net.minecraft.state.properties.StairsShape;
import net.minecraft.util.Direction;
import net.minecraft.util.math.BlockPos;
import net.minecraft.world.World;

public class CastleComponent9
{

	public static BlockPos start;
    public static World world;
    public static StructureBase structure;

    public static void init(World worldIn, BlockPos blockPos, StructureBase structureIn)
    {
        world = worldIn; start = blockPos; structure = structureIn;
    }
    
    public static void generatePart91()
    {
        structure.fillWithBlocks(world, start, 77, -42, 18, 77, -41, 19, Blocks.STONE_BRICKS.getDefaultState());
        structure.fillWithBlocks(world, start, 77, -42, 21, 77, -42, 23, Blocks.STONE_BRICKS.getDefaultState());
        structure.fillWithBlocks(world, start, 77, -41, 6, 77, -41, 7, Blocks.MOSSY_STONE_BRICKS.getDefaultState());
        structure.fillWithBlocks(world, start, 77, -41, 8, 77, -39, 10, Blocks.STONE_BRICKS.getDefaultState());
        structure.fillWithBlocks(world, start, 77, -41, 11, 78, -41, 11, Blocks.STONE_BRICKS.getDefaultState());
        structure.fillWithBlocks(world, start, 77, -41, 12, 79, -41, 14, Blocks.AIR.getDefaultState());
        structure.fillWithBlocks(world, start, 77, -41, 15, 77, -40, 18, Blocks.STONE_BRICKS.getDefaultState());
        structure.fillWithBlocks(world, start, 77, -41, 20, 77, -41, 20, Blocks.MOSSY_STONE_BRICKS.getDefaultState());
        structure.fillWithBlocks(world, start, 77, -41, 21, 77, -40, 21, Blocks.STONE_BRICKS.getDefaultState());
        structure.fillWithBlocks(world, start, 77, -40, 4, 77, -40, 5, Blocks.STONE_BRICKS.getDefaultState());
        structure.fillWithBlocks(world, start, 77, -40, 6, 77, -39, 6, Blocks.MOSSY_STONE_BRICKS.getDefaultState());
        structure.fillWithBlocks(world, start, 77, -40, 7, 78, -40, 10, Blocks.STONE_BRICKS.getDefaultState());
        structure.fillWithBlocks(world, start, 77, -40, 19, 77, -40, 19, Blocks.MOSSY_STONE_BRICKS.getDefaultState());
        structure.fillWithBlocks(world, start, 77, -40, 22, 77, -39, 22, Blocks.STONE_BRICKS.getDefaultState());
        structure.fillWithBlocks(world, start, 77, -39, 4, 77, -38, 4, Blocks.MOSSY_STONE_BRICKS.getDefaultState());
        structure.fillWithBlocks(world, start, 77, -39, 7, 77, -39, 10, Blocks.STONE_BRICKS.getDefaultState());
        structure.fillWithBlocks(world, start, 77, -39, 11, 77, -38, 11, Blocks.AIR.getDefaultState());
        structure.fillWithBlocks(world, start, 77, -39, 13, 77, -39, 14, Blocks.STONE_BRICKS.getDefaultState());
        structure.fillWithBlocks(world, start, 77, -39, 16, 77, -38, 17, Blocks.STONE_BRICKS.getDefaultState());
        structure.fillWithBlocks(world, start, 77, -39, 18, 77, -39, 18, Blocks.STONE_BRICKS.getDefaultState());
        structure.fillWithBlocks(world, start, 77, -39, 20, 77, -39, 20, Blocks.STONE_BRICKS.getDefaultState());
        structure.fillWithBlocks(world, start, 77, -38, 7, 77, -38, 9, Blocks.STONE_BRICKS.getDefaultState());
        structure.fillWithBlocks(world, start, 77, -38, 10, 77, -37, 10, Blocks.MOSSY_STONE_BRICKS.getDefaultState());
        structure.fillWithBlocks(world, start, 77, -38, 12, 77, -38, 15, Blocks.MOSSY_STONE_BRICKS.getDefaultState());
        structure.fillWithBlocks(world, start, 77, -38, 18, 78, -38, 18, Blocks.MOSSY_STONE_BRICKS.getDefaultState());
        structure.fillWithBlocks(world, start, 77, -38, 20, 77, -37, 21, Blocks.STONE_BRICKS.getDefaultState());
        structure.fillWithBlocks(world, start, 77, -38, 22, 77, -38, 23, Blocks.MOSSY_STONE_BRICKS.getDefaultState());
        structure.fillWithBlocks(world, start, 77, -37, 3, 77, -37, 4, Blocks.STONE_BRICKS.getDefaultState());
        structure.fillWithBlocks(world, start, 77, -37, 5, 77, -37, 5, Blocks.MOSSY_STONE_BRICKS.getDefaultState());
        structure.fillWithBlocks(world, start, 77, -37, 7, 77, -37, 7, Blocks.MOSSY_STONE_BRICKS.getDefaultState());
        structure.fillWithBlocks(world, start, 77, -37, 11, 78, -37, 11, Blocks.MOSSY_STONE_BRICKS.getDefaultState());
        structure.fillWithBlocks(world, start, 77, -37, 15, 77, -37, 16, Blocks.MOSSY_COBBLESTONE.getDefaultState());
        structure.fillWithBlocks(world, start, 77, -37, 17, 77, -37, 21, Blocks.STONE_BRICKS.getDefaultState());
        structure.fillWithBlocks(world, start, 77, -26, 30, 79, -26, 32, Blocks.STONE_BRICKS.getDefaultState());
        structure.fillWithBlocks(world, start, 77, -25, 28, 77, -23, 28, Blocks.STONE_BRICKS.getDefaultState());
        structure.fillWithBlocks(world, start, 77, -25, 29, 77, -25, 33, Blocks.AIR.getDefaultState());
        structure.fillWithBlocks(world, start, 77, -24, 29, 77, -24, 33, Blocks.AIR.getDefaultState());
        structure.fillWithBlocks(world, start, 77, -24, 34, 77, -23, 34, Blocks.STONE_BRICKS.getDefaultState());
        structure.fillWithBlocks(world, start, 77, -23, 29, 77, -23, 33, Blocks.AIR.getDefaultState());
        structure.fillWithBlocks(world, start, 77, -22, 32, 77, -22, 32, Blocks.STONE_BRICKS.getDefaultState());
        structure.fillWithBlocks(world, start, 77, -16, 24, 80, -16, 32, Blocks.STONE_BRICKS.getDefaultState());
        structure.fillWithBlocks(world, start, 77, -16, 33, 78, -16, 33, Blocks.MOSSY_STONE_BRICKS.getDefaultState());
        structure.fillWithBlocks(world, start, 77, -16, 34, 80, -16, 38, Blocks.STONE_BRICKS.getDefaultState());
        structure.fillWithBlocks(world, start, 77, -14, 24, 78, -14, 25, Blocks.STONE_BRICKS.getDefaultState());
        structure.fillWithBlocks(world, start, 77, -13, 24, 78, -13, 25, Blocks.STONE_BRICKS.getDefaultState());
        structure.fillWithBlocks(world, start, 77, -12, 24, 78, -12, 25, Blocks.STONE_BRICKS.getDefaultState());
        structure.fillWithBlocks(world, start, 77, -12, 37, 78, -12, 38, Blocks.STONE_BRICKS.getDefaultState());
        structure.fillWithBlocks(world, start, 77, -11, 24, 78, -11, 25, Blocks.STONE_BRICKS.getDefaultState());
        structure.fillWithBlocks(world, start, 77, -11, 27, 77, -11, 27, Blocks.STONE_BRICKS.getDefaultState());
        structure.fillWithBlocks(world, start, 77, -11, 29, 80, -11, 34, Blocks.STONE_BRICKS.getDefaultState());
        structure.fillWithBlocks(world, start, 77, -11, 35, 79, -11, 38, Blocks.STONE_BRICKS.getDefaultState());
        structure.fillWithBlocks(world, start, 77, -9, 24, 80, -9, 30, Blocks.STONE_BRICKS.getDefaultState());
        structure.fillWithBlocks(world, start, 77, -8, 24, 77, -8, 24, Blocks.STONE_BRICKS.getDefaultState());
        structure.fillWithBlocks(world, start, 77, -8, 26, 80, -8, 30, Blocks.STONE_BRICKS.getDefaultState());
        structure.fillWithBlocks(world, start, 77, -7, 31, 80, -7, 38, Blocks.STONE_BRICKS.getDefaultState());
        structure.fillWithBlocks(world, start, 77, 0, 58, 79, 0, 58, Blocks.GRASS_BLOCK.getDefaultState().with(SnowyDirtBlock.SNOWY, false));
        structure.fillWithBlocks(world, start, 77, 1, 7, 79, 1, 7, Blocks.GRASS_BLOCK.getDefaultState().with(SnowyDirtBlock.SNOWY, false));
        structure.fillWithBlocks(world, start, 77, 1, 8, 78, 1, 9, Blocks.DIRT.getDefaultState());
        structure.fillWithBlocks(world, start, 77, 2, 8, 79, 2, 8, Blocks.GRASS_BLOCK.getDefaultState().with(SnowyDirtBlock.SNOWY, false));
        structure.fillWithBlocks(world, start, 77, 3, 11, 78, 3, 22, Blocks.STONE.getDefaultState());
        structure.fillWithBlocks(world, start, 77, 4, 10, 79, 4, 10, Blocks.GRASS_BLOCK.getDefaultState().with(SnowyDirtBlock.SNOWY, false));
        structure.fillWithBlocks(world, start, 77, 4, 11, 78, 4, 12, Blocks.DIRT.getDefaultState());
        structure.fillWithBlocks(world, start, 77, 4, 13, 79, 4, 22, Blocks.STONE.getDefaultState());
        structure.fillWithBlocks(world, start, 77, 5, 11, 78, 5, 12, Blocks.DIRT.getDefaultState());
        structure.fillWithBlocks(world, start, 77, 5, 13, 77, 5, 22, Blocks.STONE.getDefaultState());
        structure.fillWithBlocks(world, start, 77, 6, 11, 77, 6, 11, Blocks.GRASS_BLOCK.getDefaultState().with(SnowyDirtBlock.SNOWY, false));
        structure.fillWithBlocks(world, start, 77, 6, 12, 77, 6, 12, Blocks.DIRT.getDefaultState());
        structure.fillWithBlocks(world, start, 77, 6, 13, 77, 6, 14, Blocks.STONE.getDefaultState());
        structure.fillWithBlocks(world, start, 77, 6, 15, 77, 6, 16, Blocks.GRAVEL.getDefaultState());
        structure.fillWithBlocks(world, start, 77, 6, 17, 77, 7, 18, Blocks.STONE.getDefaultState());
        structure.fillWithBlocks(world, start, 77, 6, 19, 77, 8, 19, Blocks.GRAVEL.getDefaultState());
        structure.fillWithBlocks(world, start, 77, 7, 11, 78, 7, 11, Blocks.GRASS.getDefaultState());
        structure.fillWithBlocks(world, start, 77, 7, 15, 77, 7, 16, Blocks.GRAVEL.getDefaultState());
        structure.fillWithBlocks(world, start, 77, 7, 20, 78, 7, 21, Blocks.STONE.getDefaultState());
        structure.fillWithBlocks(world, start, 77, 8, 13, 77, 8, 14, Blocks.CRACKED_STONE_BRICKS.getDefaultState());
        structure.fillWithBlocks(world, start, 77, 8, 15, 77, 8, 16, Blocks.GRAVEL.getDefaultState());
        structure.fillWithBlocks(world, start, 77, 8, 18, 77, 8, 18, Blocks.STONE.getDefaultState());
        structure.fillWithBlocks(world, start, 77, 8, 20, 77, 8, 21, Blocks.CRACKED_STONE_BRICKS.getDefaultState());
        structure.fillWithBlocks(world, start, 77, 13, 17, 80, 13, 17, Blocks.CRACKED_STONE_BRICKS.getDefaultState());
        structure.fillWithBlocks(world, start, 78, -57, -35, 80, -57, -33, Blocks.STONE_BRICKS.getDefaultState());
        structure.fillWithBlocks(world, start, 78, -57, -25, 80, -57, -23, Blocks.STONE_BRICKS.getDefaultState());
        structure.fillWithBlocks(world, start, 78, -56, -37, 79, -56, -36, Blocks.STONE_BRICKS.getDefaultState());
        structure.fillWithBlocks(world, start, 78, -56, -35, 80, -56, -33, Blocks.AIR.getDefaultState());
        structure.fillWithBlocks(world, start, 78, -56, -32, 84, -56, -26, Blocks.STONE_BRICKS.getDefaultState());
        structure.fillWithBlocks(world, start, 78, -56, -25, 80, -56, -23, Blocks.AIR.getDefaultState());
        structure.fillWithBlocks(world, start, 78, -56, -22, 78, -56, -22, Blocks.STONE_BRICKS.getDefaultState());
        structure.fillWithBlocks(world, start, 78, -55, -37, 86, -52, -37, Blocks.STONE_BRICKS.getDefaultState());
        structure.fillWithBlocks(world, start, 78, -55, -36, 79, -55, -36, Blocks.STONE_BRICK_WALL.getDefaultState().with(WallBlock.WATERLOGGED, false).with(WallBlock.UP, true).with(WallBlock.WALL_HEIGHT_NORTH, WallHeight.LOW).with(WallBlock.WALL_HEIGHT_SOUTH, WallHeight.LOW).with(WallBlock.WALL_HEIGHT_EAST, WallHeight.LOW).with(WallBlock.WALL_HEIGHT_WEST, WallHeight.LOW));
        structure.fillWithBlocks(world, start, 78, -55, -35, 80, -55, -33, Blocks.AIR.getDefaultState());
        structure.fillWithBlocks(world, start, 78, -55, -26, 79, -55, -26, Blocks.STONE_BRICK_WALL.getDefaultState().with(WallBlock.WATERLOGGED, false).with(WallBlock.UP, false).with(WallBlock.WALL_HEIGHT_NORTH, WallHeight.LOW).with(WallBlock.WALL_HEIGHT_SOUTH, WallHeight.LOW).with(WallBlock.WALL_HEIGHT_EAST, WallHeight.LOW).with(WallBlock.WALL_HEIGHT_WEST, WallHeight.LOW));
        structure.fillWithBlocks(world, start, 78, -55, -25, 80, -55, -23, Blocks.AIR.getDefaultState());
        structure.fillWithBlocks(world, start, 78, -55, -21, 80, -53, -21, Blocks.STONE_BRICKS.getDefaultState());
        structure.fillWithBlocks(world, start, 78, -55, 26, 79, -55, 46, Blocks.STONE_BRICKS.getDefaultState());
        structure.fillWithBlocks(world, start, 78, -54, -36, 80, -54, -22, Blocks.AIR.getDefaultState());
        structure.fillWithBlocks(world, start, 78, -54, 26, 79, -54, 31, Blocks.STONE_BRICKS.getDefaultState());
        structure.fillWithBlocks(world, start, 78, -54, 32, 79, -54, 32, Blocks.AIR.getDefaultState());
        structure.fillWithBlocks(world, start, 78, -54, 33, 78, -52, 46, Blocks.STONE_BRICKS.getDefaultState());
        structure.fillWithBlocks(world, start, 78, -53, -36, 80, -53, -22, Blocks.AIR.getDefaultState());
        structure.fillWithBlocks(world, start, 78, -53, 26, 78, -51, 28, Blocks.STONE_BRICKS.getDefaultState());
        structure.fillWithBlocks(world, start, 78, -53, 30, 79, -53, 38, Blocks.STONE_BRICKS.getDefaultState());
        structure.fillWithBlocks(world, start, 78, -52, -36, 80, -52, -22, Blocks.AIR.getDefaultState());
        structure.fillWithBlocks(world, start, 78, -52, 29, 78, -52, 29, Blocks.STONE_BRICKS.getDefaultState());
        structure.fillWithBlocks(world, start, 78, -52, 30, 78, -52, 31, Blocks.AIR.getDefaultState());
        structure.fillWithBlocks(world, start, 78, -51, -37, 79, -51, -36, Blocks.STONE_BRICKS.getDefaultState());
        structure.fillWithBlocks(world, start, 78, -51, -35, 80, -51, -33, Blocks.AIR.getDefaultState());
        structure.fillWithBlocks(world, start, 78, -51, -32, 90, -51, -32, Blocks.STONE_BRICKS.getDefaultState());
        structure.fillWithBlocks(world, start, 78, -51, -31, 80, -51, -27, Blocks.AIR.getDefaultState());
        structure.fillWithBlocks(world, start, 78, -51, -26, 80, -49, -26, Blocks.STONE_BRICKS.getDefaultState());
        structure.fillWithBlocks(world, start, 78, -51, -25, 80, -51, -23, Blocks.AIR.getDefaultState());
        structure.fillWithBlocks(world, start, 78, -51, -22, 79, -51, -21, Blocks.STONE_BRICKS.getDefaultState());
        structure.fillWithBlocks(world, start, 78, -51, 36, 79, -51, 37, Blocks.STONE_BRICKS.getDefaultState());
        structure.fillWithBlocks(world, start, 78, -51, 38, 78, -51, 46, Blocks.STONE_BRICKS.getDefaultState());
        structure.fillWithBlocks(world, start, 78, -50, -37, 80, -50, -35, Blocks.STONE_BRICKS.getDefaultState());
        structure.fillWithBlocks(world, start, 78, -50, 28, 79, -50, 46, Blocks.STONE_BRICKS.getDefaultState());
        structure.fillWithBlocks(world, start, 78, -49, -21, 80, -47, -21, Blocks.STONE_BRICKS.getDefaultState());
        structure.fillWithBlocks(world, start, 78, -49, 26, 79, -49, 27, Blocks.STONE_BRICKS.getDefaultState());
        structure.fillWithBlocks(world, start, 78, -49, 28, 78, -49, 28, Blocks.AIR.getDefaultState());
        structure.fillWithBlocks(world, start, 78, -49, 29, 78, -49, 46, Blocks.STONE_BRICKS.getDefaultState());
        structure.fillWithBlocks(world, start, 78, -48, -33, 80, -48, -21, Blocks.STONE_BRICKS.getDefaultState());
        structure.fillWithBlocks(world, start, 78, -48, 26, 79, -48, 30, Blocks.STONE_BRICKS.getDefaultState());
        structure.fillWithBlocks(world, start, 78, -48, 45, 79, -48, 46, Blocks.STONE_BRICKS.getDefaultState());
        structure.fillWithBlocks(world, start, 78, -47, -23, 78, -47, -21, Blocks.STONE_BRICKS.getDefaultState());
        structure.fillWithBlocks(world, start, 78, -46, 5, 78, -46, 9, Blocks.STONE_BRICKS.getDefaultState());
        structure.fillWithBlocks(world, start, 78, -46, 11, 78, -46, 11, Blocks.STONE_BRICKS.getDefaultState());
        structure.fillWithBlocks(world, start, 78, -46, 16, 78, -46, 16, Blocks.MOSSY_STONE_BRICKS.getDefaultState());
        structure.fillWithBlocks(world, start, 78, -46, 18, 78, -46, 22, Blocks.MOSSY_STONE_BRICKS.getDefaultState());
        structure.fillWithBlocks(world, start, 78, -45, 3, 78, -45, 5, Blocks.STONE_BRICKS.getDefaultState());
        structure.fillWithBlocks(world, start, 78, -45, 7, 80, -45, 19, Blocks.AIR.getDefaultState());
        structure.fillWithBlocks(world, start, 78, -45, 20, 79, -45, 21, Blocks.STONE_BRICKS.getDefaultState());
        structure.fillWithBlocks(world, start, 78, -45, 22, 78, -45, 23, Blocks.STONE_BRICKS.getDefaultState());
        structure.fillWithBlocks(world, start, 78, -44, 3, 79, -44, 3, Blocks.MOSSY_STONE_BRICKS.getDefaultState());
        structure.fillWithBlocks(world, start, 78, -44, 7, 80, -44, 19, Blocks.AIR.getDefaultState());
        structure.fillWithBlocks(world, start, 78, -44, 20, 78, -43, 22, Blocks.STONE_BRICKS.getDefaultState());
        structure.fillWithBlocks(world, start, 78, -44, 23, 80, -44, 23, Blocks.STONE_BRICKS.getDefaultState());
        structure.fillWithBlocks(world, start, 78, -43, 4, 79, -43, 4, Blocks.STONE_BRICKS.getDefaultState());
        structure.fillWithBlocks(world, start, 78, -43, 5, 79, -43, 6, Blocks.MOSSY_STONE_BRICKS.getDefaultState());
        structure.fillWithBlocks(world, start, 78, -43, 7, 80, -43, 19, Blocks.AIR.getDefaultState());
        structure.fillWithBlocks(world, start, 78, -43, 23, 79, -43, 23, Blocks.MOSSY_STONE_BRICKS.getDefaultState());
        structure.fillWithBlocks(world, start, 78, -42, 3, 78, -42, 4, Blocks.MOSSY_STONE_BRICKS.getDefaultState());
        structure.fillWithBlocks(world, start, 78, -42, 6, 81, -42, 6, Blocks.STONE_BRICKS.getDefaultState());
        structure.fillWithBlocks(world, start, 78, -42, 7, 80, -42, 10, Blocks.AIR.getDefaultState());
        structure.fillWithBlocks(world, start, 78, -42, 18, 79, -42, 19, Blocks.AIR.getDefaultState());
        structure.fillWithBlocks(world, start, 78, -42, 20, 78, -42, 20, Blocks.STONE_BRICKS.getDefaultState());
        structure.fillWithBlocks(world, start, 78, -42, 21, 78, -41, 21, Blocks.MOSSY_STONE_BRICKS.getDefaultState());
        structure.fillWithBlocks(world, start, 78, -42, 22, 78, -42, 22, Blocks.STONE_BRICKS.getDefaultState());
        structure.fillWithBlocks(world, start, 78, -42, 23, 78, -41, 23, Blocks.MOSSY_STONE_BRICKS.getDefaultState());
        structure.fillWithBlocks(world, start, 78, -41, 3, 78, -40, 3, Blocks.STONE_BRICKS.getDefaultState());
        structure.fillWithBlocks(world, start, 78, -41, 7, 80, -41, 10, Blocks.AIR.getDefaultState());
        structure.fillWithBlocks(world, start, 78, -41, 15, 78, -37, 15, Blocks.STONE_BRICKS.getDefaultState());
        structure.fillWithBlocks(world, start, 78, -41, 16, 80, -41, 19, Blocks.AIR.getDefaultState());
        structure.fillWithBlocks(world, start, 78, -41, 22, 78, -41, 23, Blocks.MOSSY_STONE_BRICKS.getDefaultState());
        structure.fillWithBlocks(world, start, 78, -40, 6, 79, -40, 6, Blocks.AIR.getDefaultState());
        structure.fillWithBlocks(world, start, 78, -40, 11, 78, -37, 11, Blocks.MOSSY_STONE_BRICKS.getDefaultState());
        structure.fillWithBlocks(world, start, 78, -40, 12, 78, -40, 13, Blocks.STONE_BRICKS.getDefaultState());
        structure.fillWithBlocks(world, start, 78, -40, 16, 78, -40, 17, Blocks.STONE_BRICKS.getDefaultState());
        structure.fillWithBlocks(world, start, 78, -40, 18, 78, -38, 18, Blocks.MOSSY_STONE_BRICKS.getDefaultState());
        structure.fillWithBlocks(world, start, 78, -40, 19, 79, -39, 19, Blocks.STONE_BRICKS.getDefaultState());
        structure.fillWithBlocks(world, start, 78, -40, 20, 79, -40, 20, Blocks.MOSSY_STONE_BRICKS.getDefaultState());
        structure.fillWithBlocks(world, start, 78, -40, 21, 78, -40, 21, Blocks.STONE_BRICKS.getDefaultState());
        structure.fillWithBlocks(world, start, 78, -40, 22, 78, -40, 22, Blocks.MOSSY_STONE_BRICKS.getDefaultState());
        structure.fillWithBlocks(world, start, 78, -40, 23, 78, -37, 23, Blocks.STONE_BRICKS.getDefaultState());
        structure.fillWithBlocks(world, start, 78, -39, 3, 79, -39, 3, Blocks.MOSSY_STONE_BRICKS.getDefaultState());
        structure.fillWithBlocks(world, start, 78, -39, 4, 78, -38, 4, Blocks.STONE_BRICKS.getDefaultState());
        structure.fillWithBlocks(world, start, 78, -39, 6, 78, -39, 6, Blocks.MOSSY_STONE_BRICKS.getDefaultState());
        structure.fillWithBlocks(world, start, 78, -39, 8, 78, -39, 8, Blocks.STONE_BRICKS.getDefaultState());
        structure.fillWithBlocks(world, start, 78, -39, 9, 78, -37, 9, Blocks.MOSSY_STONE_BRICKS.getDefaultState());
        structure.fillWithBlocks(world, start, 78, -39, 10, 78, -37, 10, Blocks.STONE_BRICKS.getDefaultState());
        structure.fillWithBlocks(world, start, 78, -39, 13, 80, -39, 13, Blocks.MOSSY_STONE_BRICKS.getDefaultState());
        structure.fillWithBlocks(world, start, 78, -39, 14, 78, -39, 15, Blocks.STONE_BRICKS.getDefaultState());
        structure.fillWithBlocks(world, start, 78, -39, 17, 78, -38, 17, Blocks.AIR.getDefaultState());
        structure.fillWithBlocks(world, start, 78, -39, 20, 78, -39, 21, Blocks.STONE_BRICKS.getDefaultState());
        structure.fillWithBlocks(world, start, 78, -38, 3, 79, -38, 5, Blocks.STONE_BRICKS.getDefaultState());
        structure.fillWithBlocks(world, start, 78, -38, 6, 78, -38, 9, Blocks.MOSSY_STONE_BRICKS.getDefaultState());
        structure.fillWithBlocks(world, start, 78, -38, 12, 78, -38, 13, Blocks.STONE_BRICKS.getDefaultState());
        structure.fillWithBlocks(world, start, 78, -38, 14, 78, -37, 14, Blocks.MOSSY_STONE_BRICKS.getDefaultState());
        structure.fillWithBlocks(world, start, 78, -38, 19, 78, -38, 20, Blocks.STONE_BRICKS.getDefaultState());
        structure.fillWithBlocks(world, start, 78, -38, 22, 78, -38, 22, Blocks.MOSSY_STONE_BRICKS.getDefaultState());
        structure.fillWithBlocks(world, start, 78, -37, 3, 79, -37, 3, Blocks.STONE_BRICKS.getDefaultState());
        structure.fillWithBlocks(world, start, 78, -37, 4, 78, -37, 6, Blocks.MOSSY_STONE_BRICKS.getDefaultState());
        structure.fillWithBlocks(world, start, 78, -37, 8, 78, -37, 9, Blocks.MOSSY_STONE_BRICKS.getDefaultState());
        structure.fillWithBlocks(world, start, 78, -37, 13, 79, -37, 13, Blocks.MOSSY_COBBLESTONE.getDefaultState());
        structure.fillWithBlocks(world, start, 78, -37, 16, 78, -37, 17, Blocks.MOSSY_STONE_BRICKS.getDefaultState());
        structure.fillWithBlocks(world, start, 78, -37, 19, 78, -37, 19, Blocks.STONE_BRICKS.getDefaultState());
        structure.fillWithBlocks(world, start, 78, -37, 21, 78, -37, 23, Blocks.STONE_BRICKS.getDefaultState());
        structure.fillWithBlocks(world, start, 78, -26, 29, 78, -26, 32, Blocks.STONE_BRICKS.getDefaultState());
        structure.fillWithBlocks(world, start, 78, -25, 29, 78, -22, 29, Blocks.STONE_BRICKS.getDefaultState());
        structure.fillWithBlocks(world, start, 78, -25, 33, 78, -24, 33, Blocks.STONE_BRICKS.getDefaultState());
        structure.fillWithBlocks(world, start, 78, -22, 32, 78, -22, 33, Blocks.STONE_BRICKS.getDefaultState());
        structure.fillWithBlocks(world, start, 78, -15, 24, 80, -15, 26, Blocks.STONE_BRICKS.getDefaultState());
        structure.fillWithBlocks(world, start, 78, -15, 27, 78, -14, 28, Blocks.AIR.getDefaultState());
        structure.fillWithBlocks(world, start, 78, -15, 29, 78, -11, 29, Blocks.STONE_BRICKS.getDefaultState());
        structure.fillWithBlocks(world, start, 78, -15, 30, 80, -15, 32, Blocks.AIR.getDefaultState());
        structure.fillWithBlocks(world, start, 78, -15, 33, 78, -7, 33, Blocks.STONE_BRICKS.getDefaultState());
        structure.fillWithBlocks(world, start, 78, -15, 34, 78, -14, 35, Blocks.AIR.getDefaultState());
        structure.fillWithBlocks(world, start, 78, -15, 36, 80, -15, 38, Blocks.STONE_BRICKS.getDefaultState());
        structure.fillWithBlocks(world, start, 78, -14, 26, 78, -7, 26, Blocks.STONE_BRICKS.getDefaultState());
        structure.fillWithBlocks(world, start, 78, -14, 30, 80, -14, 32, Blocks.AIR.getDefaultState());
        structure.fillWithBlocks(world, start, 78, -14, 36, 80, -14, 38, Blocks.STONE_BRICKS.getDefaultState());
        structure.fillWithBlocks(world, start, 78, -13, 27, 78, -12, 28, Blocks.AIR.getDefaultState());
        structure.fillWithBlocks(world, start, 78, -13, 30, 80, -13, 32, Blocks.AIR.getDefaultState());
        structure.fillWithBlocks(world, start, 78, -13, 34, 78, -12, 35, Blocks.AIR.getDefaultState());
        structure.fillWithBlocks(world, start, 78, -13, 36, 79, -13, 38, Blocks.STONE_BRICKS.getDefaultState());
        structure.fillWithBlocks(world, start, 78, -13, 83, 78, -12, 83, Blocks.CAVE_AIR.getDefaultState());
        structure.fillWithBlocks(world, start, 78, -12, 30, 78, -12, 32, Blocks.AIR.getDefaultState());
        structure.fillWithBlocks(world, start, 78, -12, 36, 80, -12, 38, Blocks.STONE_BRICKS.getDefaultState());
        structure.fillWithBlocks(world, start, 78, -11, 27, 78, -10, 28, Blocks.STONE_BRICKS.getDefaultState());
        structure.fillWithBlocks(world, start, 78, -10, 30, 80, -10, 33, Blocks.STONE_BRICKS.getDefaultState());
        structure.fillWithBlocks(world, start, 78, -10, 35, 80, -10, 38, Blocks.STONE_BRICKS.getDefaultState());
        structure.fillWithBlocks(world, start, 78, -8, 24, 80, -8, 30, Blocks.STONE_BRICKS.getDefaultState());
        structure.fillWithBlocks(world, start, 78, -8, 35, 80, -8, 38, Blocks.STONE_BRICKS.getDefaultState());
        structure.fillWithBlocks(world, start, 78, -7, 24, 80, -7, 29, Blocks.STONE_BRICKS.getDefaultState());
        structure.fillWithBlocks(world, start, 78, -7, 30, 78, -7, 38, Blocks.STONE_BRICKS.getDefaultState());
        structure.fillWithBlocks(world, start, 78, 0, 5, 78, 0, 6, Blocks.GRASS_BLOCK.getDefaultState().with(SnowyDirtBlock.SNOWY, false));
        structure.fillWithBlocks(world, start, 78, 0, 7, 79, 0, 8, Blocks.DIRT.getDefaultState());
        structure.fillWithBlocks(world, start, 78, 1, 23, 78, 2, 23, Blocks.DIRT.getDefaultState());
        structure.fillWithBlocks(world, start, 78, 2, 9, 79, 2, 10, Blocks.DIRT.getDefaultState());
        structure.fillWithBlocks(world, start, 78, 5, 13, 78, 5, 13, Blocks.DIRT.getDefaultState());
        structure.fillWithBlocks(world, start, 78, 5, 14, 78, 5, 22, Blocks.STONE.getDefaultState());
        structure.fillWithBlocks(world, start, 78, 6, 11, 78, 6, 12, Blocks.GRASS_BLOCK.getDefaultState().with(SnowyDirtBlock.SNOWY, false));
        structure.fillWithBlocks(world, start, 78, 6, 13, 79, 6, 14, Blocks.DIRT.getDefaultState());
        structure.fillWithBlocks(world, start, 78, 6, 15, 78, 7, 15, Blocks.DIRT.getDefaultState());
        structure.fillWithBlocks(world, start, 78, 6, 16, 78, 8, 16, Blocks.GRAVEL.getDefaultState());
        structure.fillWithBlocks(world, start, 78, 6, 17, 78, 6, 17, Blocks.STONE.getDefaultState());
        structure.fillWithBlocks(world, start, 78, 6, 18, 78, 8, 18, Blocks.GRAVEL.getDefaultState());
        structure.fillWithBlocks(world, start, 78, 6, 19, 78, 6, 21, Blocks.STONE.getDefaultState());
        structure.fillWithBlocks(world, start, 78, 7, 13, 78, 7, 15, Blocks.DIRT.getDefaultState());
        structure.fillWithBlocks(world, start, 78, 7, 17, 78, 7, 17, Blocks.STONE.getDefaultState());
        structure.fillWithBlocks(world, start, 78, 7, 19, 78, 7, 21, Blocks.STONE.getDefaultState());
        structure.fillWithBlocks(world, start, 78, 8, 15, 78, 8, 15, Blocks.GRASS_BLOCK.getDefaultState().with(SnowyDirtBlock.SNOWY, false));
        structure.fillWithBlocks(world, start, 78, 8, 20, 79, 8, 20, Blocks.CRACKED_STONE_BRICKS.getDefaultState());
        structure.fillWithBlocks(world, start, 78, 9, 14, 79, 9, 14, Blocks.COBBLESTONE.getDefaultState());
        structure.fillWithBlocks(world, start, 78, 9, 15, 78, 9, 15, Blocks.GRASS.getDefaultState());
        structure.fillWithBlocks(world, start, 78, 13, 21, 79, 13, 21, Blocks.CRACKED_STONE_BRICKS.getDefaultState());
        structure.fillWithBlocks(world, start, 79, -56, -22, 80, -56, -21, Blocks.STONE_BRICKS.getDefaultState());
        structure.fillWithBlocks(world, start, 79, -54, 33, 79, -47, 33, Blocks.STONE_BRICKS.getDefaultState());
        structure.fillWithBlocks(world, start, 79, -54, 35, 79, -53, 38, Blocks.STONE_BRICKS.getDefaultState());
        structure.fillWithBlocks(world, start, 79, -53, 26, 79, -47, 26, Blocks.STONE_BRICKS.getDefaultState());
        structure.fillWithBlocks(world, start, 79, -53, 28, 79, -50, 34, Blocks.STONE_BRICKS.getDefaultState());
        structure.fillWithBlocks(world, start, 79, -53, 40, 79, -53, 46, Blocks.STONE_BRICKS.getDefaultState());
        structure.fillWithBlocks(world, start, 79, -52, 27, 79, -50, 34, Blocks.STONE_BRICKS.getDefaultState());
        structure.fillWithBlocks(world, start, 79, -52, 36, 79, -51, 37, Blocks.STONE_BRICKS.getDefaultState());
        structure.fillWithBlocks(world, start, 79, -52, 38, 79, -52, 40, Blocks.STONE_BRICKS.getDefaultState());
        structure.fillWithBlocks(world, start, 79, -52, 41, 79, -52, 42, Blocks.AIR.getDefaultState());
        structure.fillWithBlocks(world, start, 79, -52, 43, 79, -49, 46, Blocks.STONE_BRICKS.getDefaultState());
        structure.fillWithBlocks(world, start, 79, -51, 35, 79, -49, 37, Blocks.STONE_BRICKS.getDefaultState());
        structure.fillWithBlocks(world, start, 79, -51, 39, 79, -50, 40, Blocks.STONE_BRICKS.getDefaultState());
        structure.fillWithBlocks(world, start, 79, -51, 42, 79, -47, 46, Blocks.STONE_BRICKS.getDefaultState());
        structure.fillWithBlocks(world, start, 79, -50, -33, 79, -50, -33, Blocks.STONE_BRICKS.getDefaultState());
        structure.fillWithBlocks(world, start, 79, -50, -31, 80, -50, -30, Blocks.STONE_BRICKS.getDefaultState());
        structure.fillWithBlocks(world, start, 79, -50, -28, 80, -50, -25, Blocks.STONE_BRICKS.getDefaultState());
        structure.fillWithBlocks(world, start, 79, -50, -23, 81, -50, -21, Blocks.STONE_BRICKS.getDefaultState());
        structure.fillWithBlocks(world, start, 79, -49, -24, 82, -49, -21, Blocks.STONE_BRICKS.getDefaultState());
        structure.fillWithBlocks(world, start, 79, -49, 28, 79, -47, 28, Blocks.STONE_BRICKS.getDefaultState());
        structure.fillWithBlocks(world, start, 79, -49, 31, 79, -47, 40, Blocks.STONE_BRICKS.getDefaultState());
        structure.fillWithBlocks(world, start, 79, -48, -37, 84, -48, -32, Blocks.STONE_BRICKS.getDefaultState());
        structure.fillWithBlocks(world, start, 79, -47, -22, 80, -47, -21, Blocks.STONE_BRICKS.getDefaultState());
        structure.fillWithBlocks(world, start, 79, -46, 3, 79, -46, 4, Blocks.STONE_BRICKS.getDefaultState());
        structure.fillWithBlocks(world, start, 79, -46, 5, 79, -45, 5, Blocks.AIR.getDefaultState());
        structure.fillWithBlocks(world, start, 79, -46, 6, 79, -46, 7, Blocks.STONE_BRICKS.getDefaultState());
        structure.fillWithBlocks(world, start, 79, -46, 9, 80, -46, 9, Blocks.MOSSY_STONE_BRICKS.getDefaultState());
        structure.fillWithBlocks(world, start, 79, -46, 12, 80, -46, 13, Blocks.STONE_BRICKS.getDefaultState());
        structure.fillWithBlocks(world, start, 79, -46, 15, 80, -46, 15, Blocks.STONE_BRICKS.getDefaultState());
        structure.fillWithBlocks(world, start, 79, -46, 16, 79, -46, 18, Blocks.MOSSY_STONE_BRICKS.getDefaultState());
        structure.fillWithBlocks(world, start, 79, -46, 21, 79, -46, 23, Blocks.STONE_BRICKS.getDefaultState());
        structure.fillWithBlocks(world, start, 79, -45, 3, 79, -45, 3, Blocks.STONE_BRICKS.getDefaultState());
        structure.fillWithBlocks(world, start, 79, -45, 6, 82, -45, 6, Blocks.STONE_BRICKS.getDefaultState());
        structure.fillWithBlocks(world, start, 79, -44, 4, 80, -44, 4, Blocks.AIR.getDefaultState());
        structure.fillWithBlocks(world, start, 79, -44, 5, 81, -44, 5, Blocks.MOSSY_STONE_BRICKS.getDefaultState());
        structure.fillWithBlocks(world, start, 79, -44, 22, 79, -44, 23, Blocks.STONE_BRICKS.getDefaultState());
        structure.fillWithBlocks(world, start, 79, -43, 3, 79, -43, 4, Blocks.STONE_BRICKS.getDefaultState());
        structure.fillWithBlocks(world, start, 79, -43, 20, 79, -38, 20, Blocks.MOSSY_STONE_BRICKS.getDefaultState());
        structure.fillWithBlocks(world, start, 79, -43, 21, 80, -43, 22, Blocks.STONE_BRICKS.getDefaultState());
        structure.fillWithBlocks(world, start, 79, -42, 4, 79, -42, 5, Blocks.MOSSY_STONE_BRICKS.getDefaultState());
        structure.fillWithBlocks(world, start, 79, -42, 21, 79, -37, 21, Blocks.STONE_BRICKS.getDefaultState());
        structure.fillWithBlocks(world, start, 79, -42, 23, 81, -42, 23, Blocks.STONE_BRICKS.getDefaultState());
        structure.fillWithBlocks(world, start, 79, -41, 3, 79, -41, 4, Blocks.MOSSY_STONE_BRICKS.getDefaultState());
        structure.fillWithBlocks(world, start, 79, -41, 5, 79, -41, 5, Blocks.STONE_BRICKS.getDefaultState());
        structure.fillWithBlocks(world, start, 79, -41, 22, 79, -40, 22, Blocks.STONE_BRICKS.getDefaultState());
        structure.fillWithBlocks(world, start, 79, -41, 23, 79, -40, 23, Blocks.MOSSY_STONE_BRICKS.getDefaultState());
        structure.fillWithBlocks(world, start, 79, -40, 3, 80, -40, 3, Blocks.STONE_BRICKS.getDefaultState());
        structure.fillWithBlocks(world, start, 79, -40, 4, 79, -40, 6, Blocks.AIR.getDefaultState());
        structure.fillWithBlocks(world, start, 79, -40, 7, 79, -40, 8, Blocks.STONE_BRICKS.getDefaultState());
        structure.fillWithBlocks(world, start, 79, -40, 10, 80, -40, 12, Blocks.STONE_BRICKS.getDefaultState());
        structure.fillWithBlocks(world, start, 79, -40, 14, 79, -40, 14, Blocks.STONE_BRICKS.getDefaultState());
        structure.fillWithBlocks(world, start, 79, -40, 15, 79, -40, 15, Blocks.MOSSY_COBBLESTONE.getDefaultState());
        structure.fillWithBlocks(world, start, 79, -40, 16, 79, -40, 16, Blocks.STONE_BRICKS.getDefaultState());
        structure.fillWithBlocks(world, start, 79, -40, 18, 79, -39, 19, Blocks.STONE_BRICKS.getDefaultState());
        structure.fillWithBlocks(world, start, 79, -39, 5, 79, -39, 7, Blocks.MOSSY_STONE_BRICKS.getDefaultState());
        structure.fillWithBlocks(world, start, 79, -39, 8, 79, -39, 9, Blocks.STONE_BRICKS.getDefaultState());
        structure.fillWithBlocks(world, start, 79, -39, 11, 79, -39, 12, Blocks.STONE_BRICKS.getDefaultState());
        structure.fillWithBlocks(world, start, 79, -39, 15, 79, -39, 16, Blocks.MOSSY_STONE_BRICKS.getDefaultState());
        structure.fillWithBlocks(world, start, 79, -39, 17, 80, -39, 19, Blocks.STONE_BRICKS.getDefaultState());
        structure.fillWithBlocks(world, start, 79, -38, 6, 79, -37, 6, Blocks.MOSSY_STONE_BRICKS.getDefaultState());
        structure.fillWithBlocks(world, start, 79, -38, 7, 82, -38, 7, Blocks.STONE_BRICKS.getDefaultState());
        structure.fillWithBlocks(world, start, 79, -38, 8, 79, -38, 8, Blocks.MOSSY_STONE_BRICKS.getDefaultState());
        structure.fillWithBlocks(world, start, 79, -38, 10, 80, -37, 10, Blocks.STONE_BRICKS.getDefaultState());
        structure.fillWithBlocks(world, start, 79, -38, 11, 79, -38, 12, Blocks.MOSSY_COBBLESTONE.getDefaultState());
        structure.fillWithBlocks(world, start, 79, -38, 13, 79, -38, 15, Blocks.STONE_BRICKS.getDefaultState());
        structure.fillWithBlocks(world, start, 79, -38, 16, 80, -38, 16, Blocks.MOSSY_STONE_BRICKS.getDefaultState());
        structure.fillWithBlocks(world, start, 79, -38, 17, 80, -38, 17, Blocks.AIR.getDefaultState());
        structure.fillWithBlocks(world, start, 79, -38, 18, 79, -38, 19, Blocks.STONE_BRICKS.getDefaultState());
        structure.fillWithBlocks(world, start, 79, -38, 22, 79, -38, 23, Blocks.MOSSY_STONE_BRICKS.getDefaultState());
        structure.fillWithBlocks(world, start, 79, -37, 5, 79, -37, 5, Blocks.STONE_BRICKS.getDefaultState());
        structure.fillWithBlocks(world, start, 79, -37, 7, 79, -37, 7, Blocks.STONE_BRICKS.getDefaultState());
        structure.fillWithBlocks(world, start, 79, -37, 9, 79, -37, 11, Blocks.STONE_BRICKS.getDefaultState());
        structure.fillWithBlocks(world, start, 79, -37, 17, 80, -37, 18, Blocks.MOSSY_STONE_BRICKS.getDefaultState());
        structure.fillWithBlocks(world, start, 79, -37, 20, 79, -37, 21, Blocks.STONE_BRICKS.getDefaultState());
        structure.fillWithBlocks(world, start, 79, -26, 33, 80, -26, 33, Blocks.STONE_BRICKS.getDefaultState());
        structure.fillWithBlocks(world, start, 79, -25, 29, 81, -25, 33, Blocks.AIR.getDefaultState());
        structure.fillWithBlocks(world, start, 79, -25, 34, 81, -25, 34, Blocks.CRACKED_STONE_BRICKS.getDefaultState());
        structure.fillWithBlocks(world, start, 79, -24, 28, 79, -23, 28, Blocks.STONE_BRICKS.getDefaultState());
        structure.fillWithBlocks(world, start, 79, -24, 29, 81, -24, 33, Blocks.AIR.getDefaultState());
        structure.fillWithBlocks(world, start, 79, -24, 34, 79, -23, 34, Blocks.STONE_BRICKS.getDefaultState());
        structure.fillWithBlocks(world, start, 79, -23, 29, 81, -23, 33, Blocks.AIR.getDefaultState());
        structure.fillWithBlocks(world, start, 79, -22, 31, 79, -22, 31, Blocks.MOSSY_STONE_BRICKS.getDefaultState());
        structure.fillWithBlocks(world, start, 79, -16, 33, 79, -16, 38, Blocks.STONE_BRICKS.getDefaultState());
        structure.fillWithBlocks(world, start, 79, -15, 27, 80, -15, 28, Blocks.STONE_BRICKS.getDefaultState());
        structure.fillWithBlocks(world, start, 79, -15, 29, 81, -15, 33, Blocks.AIR.getDefaultState());
        structure.fillWithBlocks(world, start, 79, -15, 34, 80, -15, 38, Blocks.STONE_BRICKS.getDefaultState());
        structure.fillWithBlocks(world, start, 79, -14, 24, 80, -14, 25, Blocks.STONE_BRICKS.getDefaultState());
        structure.fillWithBlocks(world, start, 79, -14, 27, 79, -13, 28, Blocks.STONE_BRICKS.getDefaultState());
        structure.fillWithBlocks(world, start, 79, -14, 29, 81, -14, 33, Blocks.AIR.getDefaultState());
        structure.fillWithBlocks(world, start, 79, -14, 34, 79, -14, 38, Blocks.STONE_BRICKS.getDefaultState());
        structure.fillWithBlocks(world, start, 79, -13, 26, 80, -13, 28, Blocks.STONE_BRICKS.getDefaultState());
        structure.fillWithBlocks(world, start, 79, -13, 29, 81, -13, 33, Blocks.AIR.getDefaultState());
        structure.fillWithBlocks(world, start, 79, -13, 34, 80, -13, 35, Blocks.STONE_BRICKS.getDefaultState());
        structure.fillWithBlocks(world, start, 79, -12, 24, 80, -12, 25, Blocks.STONE_BRICKS.getDefaultState());
        structure.fillWithBlocks(world, start, 79, -12, 27, 79, -12, 27, Blocks.STONE_BRICKS.getDefaultState());
        structure.fillWithBlocks(world, start, 79, -12, 29, 79, -9, 38, Blocks.STONE_BRICKS.getDefaultState());
        structure.fillWithBlocks(world, start, 79, -11, 24, 80, -11, 27, Blocks.STONE_BRICKS.getDefaultState());
        structure.fillWithBlocks(world, start, 79, -10, 24, 80, -10, 26, Blocks.STONE_BRICKS.getDefaultState());
        structure.fillWithBlocks(world, start, 79, -10, 28, 80, -10, 38, Blocks.STONE_BRICKS.getDefaultState());
        structure.fillWithBlocks(world, start, 79, -8, 32, 80, -8, 38, Blocks.STONE_BRICKS.getDefaultState());
        structure.fillWithBlocks(world, start, 79, 0, 6, 79, 0, 6, Blocks.GRASS_BLOCK.getDefaultState().with(SnowyDirtBlock.SNOWY, false));
        structure.fillWithBlocks(world, start, 79, 0, 24, 80, 0, 24, Blocks.GRASS_BLOCK.getDefaultState().with(SnowyDirtBlock.SNOWY, false));
        structure.fillWithBlocks(world, start, 79, 0, 48, 79, 0, 58, Blocks.GRASS_BLOCK.getDefaultState().with(SnowyDirtBlock.SNOWY, false));
        structure.fillWithBlocks(world, start, 79, 1, 8, 79, 1, 9, Blocks.DIRT.getDefaultState());
        structure.fillWithBlocks(world, start, 79, 3, 11, 79, 3, 11, Blocks.DIRT.getDefaultState());
        structure.fillWithBlocks(world, start, 79, 4, 11, 79, 4, 12, Blocks.DIRT.getDefaultState());
        structure.fillWithBlocks(world, start, 79, 5, 12, 80, 5, 14, Blocks.DIRT.getDefaultState());
        structure.fillWithBlocks(world, start, 79, 6, 12, 79, 6, 12, Blocks.GRASS_BLOCK.getDefaultState().with(SnowyDirtBlock.SNOWY, false));
        structure.fillWithBlocks(world, start, 79, 6, 15, 79, 8, 15, Blocks.GRAVEL.getDefaultState());
        structure.fillWithBlocks(world, start, 79, 6, 16, 81, 7, 16, Blocks.DIRT.getDefaultState());
        structure.fillWithBlocks(world, start, 79, 6, 17, 80, 6, 18, Blocks.STONE.getDefaultState());
        structure.fillWithBlocks(world, start, 79, 6, 19, 79, 8, 19, Blocks.GRAVEL.getDefaultState());
        structure.fillWithBlocks(world, start, 79, 6, 20, 80, 6, 21, Blocks.STONE.getDefaultState());
        structure.fillWithBlocks(world, start, 79, 7, 12, 79, 7, 12, Blocks.GRASS.getDefaultState());
        structure.fillWithBlocks(world, start, 79, 7, 14, 79, 7, 14, Blocks.DIRT.getDefaultState());
        structure.fillWithBlocks(world, start, 79, 7, 17, 80, 7, 18, Blocks.STONE.getDefaultState());
        structure.fillWithBlocks(world, start, 79, 7, 20, 79, 7, 20, Blocks.STONE.getDefaultState());
        structure.fillWithBlocks(world, start, 80, -56, -37, 81, -56, -36, Blocks.STONE_BRICKS.getDefaultState());
        structure.fillWithBlocks(world, start, 80, -51, -36, 80, -51, -36, Blocks.STONE_BRICKS.getDefaultState());
        structure.fillWithBlocks(world, start, 80, -51, -22, 81, -51, -21, Blocks.STONE_BRICKS.getDefaultState());
        structure.fillWithBlocks(world, start, 80, -50, -34, 83, -50, -31, Blocks.STONE_BRICKS.getDefaultState());
        structure.fillWithBlocks(world, start, 80, -50, -29, 81, -50, -28, Blocks.STONE_BRICKS.getDefaultState());
        structure.fillWithBlocks(world, start, 80, -50, -24, 83, -50, -21, Blocks.STONE_BRICKS.getDefaultState());
        structure.fillWithBlocks(world, start, 80, -49, -25, 84, -49, -21, Blocks.STONE_BRICKS.getDefaultState());
        structure.fillWithBlocks(world, start, 80, -47, -37, 81, -47, -36, Blocks.STONE_BRICKS.getDefaultState());
        structure.fillWithBlocks(world, start, 80, -47, -34, 82, -47, -21, Blocks.STONE_BRICKS.getDefaultState());
        structure.fillWithBlocks(world, start, 80, -46, 3, 80, -44, 3, Blocks.STONE_BRICKS.getDefaultState());
        structure.fillWithBlocks(world, start, 80, -46, 4, 80, -46, 4, Blocks.MOSSY_STONE_BRICKS.getDefaultState());
        structure.fillWithBlocks(world, start, 80, -46, 6, 81, -46, 6, Blocks.AIR.getDefaultState());
        structure.fillWithBlocks(world, start, 80, -46, 7, 80, -46, 8, Blocks.STONE_BRICKS.getDefaultState());
        structure.fillWithBlocks(world, start, 80, -46, 10, 80, -46, 10, Blocks.STONE_BRICKS.getDefaultState());
        structure.fillWithBlocks(world, start, 80, -46, 17, 80, -46, 21, Blocks.STONE_BRICKS.getDefaultState());
        structure.fillWithBlocks(world, start, 80, -46, 23, 80, -45, 23, Blocks.MOSSY_STONE_BRICKS.getDefaultState());
        structure.fillWithBlocks(world, start, 80, -45, 20, 81, -45, 21, Blocks.STONE_BRICKS.getDefaultState());
        structure.fillWithBlocks(world, start, 80, -45, 22, 80, -45, 22, Blocks.STONE_BRICKS.getDefaultState());
        structure.fillWithBlocks(world, start, 80, -44, 6, 80, -44, 6, Blocks.STONE_BRICKS.getDefaultState());
        structure.fillWithBlocks(world, start, 80, -44, 20, 80, -44, 21, Blocks.STONE_BRICKS.getDefaultState());
        structure.fillWithBlocks(world, start, 80, -43, 5, 80, -43, 5, Blocks.STONE_BRICKS.getDefaultState());
        structure.fillWithBlocks(world, start, 80, -43, 20, 80, -43, 23, Blocks.STONE_BRICKS.getDefaultState());
        structure.fillWithBlocks(world, start, 80, -42, 3, 80, -42, 4, Blocks.MOSSY_STONE_BRICKS.getDefaultState());
        structure.fillWithBlocks(world, start, 80, -42, 5, 80, -42, 6, Blocks.STONE_BRICKS.getDefaultState());
        structure.fillWithBlocks(world, start, 80, -42, 11, 80, -40, 11, Blocks.STONE_BRICKS.getDefaultState());
        structure.fillWithBlocks(world, start, 80, -42, 12, 81, -42, 14, Blocks.AIR.getDefaultState());
        structure.fillWithBlocks(world, start, 80, -42, 15, 85, -42, 15, Blocks.STONE_BRICKS.getDefaultState());
        structure.fillWithBlocks(world, start, 80, -42, 16, 81, -42, 18, Blocks.AIR.getDefaultState());
        structure.fillWithBlocks(world, start, 80, -42, 19, 80, -41, 19, Blocks.AIR.getDefaultState());
        structure.fillWithBlocks(world, start, 80, -42, 20, 80, -42, 20, Blocks.STONE_BRICKS.getDefaultState());
        structure.fillWithBlocks(world, start, 80, -42, 22, 81, -42, 23, Blocks.STONE_BRICKS.getDefaultState());
        structure.fillWithBlocks(world, start, 80, -41, 3, 81, -41, 4, Blocks.STONE_BRICKS.getDefaultState());
        structure.fillWithBlocks(world, start, 80, -41, 6, 81, -40, 6, Blocks.STONE_BRICKS.getDefaultState());
        structure.fillWithBlocks(world, start, 80, -41, 12, 80, -41, 14, Blocks.AIR.getDefaultState());
        structure.fillWithBlocks(world, start, 80, -41, 15, 80, -37, 15, Blocks.STONE_BRICKS.getDefaultState());
        structure.fillWithBlocks(world, start, 80, -41, 21, 80, -41, 22, Blocks.MOSSY_COBBLESTONE.getDefaultState());
        structure.fillWithBlocks(world, start, 80, -40, 5, 81, -40, 7, Blocks.STONE_BRICKS.getDefaultState());
        structure.fillWithBlocks(world, start, 80, -40, 8, 80, -38, 8, Blocks.MOSSY_STONE_BRICKS.getDefaultState());
        structure.fillWithBlocks(world, start, 80, -40, 9, 81, -40, 11, Blocks.STONE_BRICKS.getDefaultState());
        structure.fillWithBlocks(world, start, 80, -40, 13, 80, -40, 13, Blocks.STONE_BRICKS.getDefaultState());
        structure.fillWithBlocks(world, start, 80, -40, 14, 80, -38, 14, Blocks.MOSSY_STONE_BRICKS.getDefaultState());
        structure.fillWithBlocks(world, start, 80, -40, 17, 80, -40, 17, Blocks.STONE_BRICKS.getDefaultState());
        structure.fillWithBlocks(world, start, 80, -40, 18, 80, -40, 19, Blocks.MOSSY_STONE_BRICKS.getDefaultState());
        structure.fillWithBlocks(world, start, 80, -40, 20, 80, -40, 21, Blocks.STONE_BRICKS.getDefaultState());
        structure.fillWithBlocks(world, start, 80, -39, 3, 81, -39, 4, Blocks.STONE_BRICKS.getDefaultState());
        structure.fillWithBlocks(world, start, 80, -39, 5, 80, -39, 5, Blocks.STONE_BRICKS.getDefaultState());
        structure.fillWithBlocks(world, start, 80, -39, 6, 80, -39, 8, Blocks.MOSSY_STONE_BRICKS.getDefaultState());
        structure.fillWithBlocks(world, start, 80, -39, 10, 81, -39, 10, Blocks.MOSSY_COBBLESTONE.getDefaultState());
        structure.fillWithBlocks(world, start, 80, -39, 11, 80, -39, 14, Blocks.MOSSY_STONE_BRICKS.getDefaultState());
        structure.fillWithBlocks(world, start, 80, -39, 20, 82, -39, 20, Blocks.MOSSY_STONE_BRICKS.getDefaultState());
        structure.fillWithBlocks(world, start, 80, -39, 22, 80, -38, 22, Blocks.MOSSY_STONE_BRICKS.getDefaultState());
        structure.fillWithBlocks(world, start, 80, -38, 3, 80, -38, 3, Blocks.STONE_BRICKS.getDefaultState());
        structure.fillWithBlocks(world, start, 80, -38, 6, 80, -38, 7, Blocks.STONE_BRICKS.getDefaultState());
        structure.fillWithBlocks(world, start, 80, -38, 12, 81, -38, 13, Blocks.STONE_BRICKS.getDefaultState());
        structure.fillWithBlocks(world, start, 80, -38, 18, 80, -37, 18, Blocks.MOSSY_STONE_BRICKS.getDefaultState());
        structure.fillWithBlocks(world, start, 80, -38, 19, 80, -38, 21, Blocks.STONE_BRICKS.getDefaultState());
        structure.fillWithBlocks(world, start, 80, -38, 23, 81, -38, 23, Blocks.STONE_BRICKS.getDefaultState());
        structure.fillWithBlocks(world, start, 80, -37, 4, 81, -37, 6, Blocks.STONE_BRICKS.getDefaultState());
        structure.fillWithBlocks(world, start, 80, -37, 11, 80, -37, 12, Blocks.MOSSY_STONE_BRICKS.getDefaultState());
        structure.fillWithBlocks(world, start, 80, -37, 13, 80, -37, 15, Blocks.STONE_BRICKS.getDefaultState());
        structure.fillWithBlocks(world, start, 80, -37, 16, 80, -37, 18, Blocks.MOSSY_STONE_BRICKS.getDefaultState());
        structure.fillWithBlocks(world, start, 80, -37, 19, 80, -37, 20, Blocks.STONE_BRICKS.getDefaultState());
        structure.fillWithBlocks(world, start, 80, -37, 22, 80, -37, 23, Blocks.STONE_BRICKS.getDefaultState());
        structure.fillWithBlocks(world, start, 80, -26, 29, 81, -26, 32, Blocks.STONE_BRICKS.getDefaultState());
        structure.fillWithBlocks(world, start, 80, -23, 34, 83, -23, 34, Blocks.STONE_BRICKS.getDefaultState());
        structure.fillWithBlocks(world, start, 80, -22, 29, 80, -22, 30, Blocks.MOSSY_STONE_BRICKS.getDefaultState());
        structure.fillWithBlocks(world, start, 80, -22, 31, 80, -22, 31, Blocks.STONE_BRICKS.getDefaultState());
        structure.fillWithBlocks(world, start, 80, -14, 26, 80, -13, 27, Blocks.STONE_BRICKS.getDefaultState());
        structure.fillWithBlocks(world, start, 80, -14, 35, 80, -14, 38, Blocks.STONE_BRICKS.getDefaultState());
        structure.fillWithBlocks(world, start, 80, -13, 24, 80, -9, 28, Blocks.STONE_BRICKS.getDefaultState());
        structure.fillWithBlocks(world, start, 80, -13, 37, 80, -12, 38, Blocks.STONE_BRICKS.getDefaultState());
        structure.fillWithBlocks(world, start, 80, -12, 29, 80, -12, 29, Blocks.STONE_BRICKS.getDefaultState());
        structure.fillWithBlocks(world, start, 80, -12, 30, 80, -12, 30, Blocks.MOSSY_STONE_BRICKS.getDefaultState());
        structure.fillWithBlocks(world, start, 80, -12, 31, 80, -12, 34, Blocks.STONE_BRICKS.getDefaultState());
        structure.fillWithBlocks(world, start, 80, -12, 35, 80, -11, 35, Blocks.MOSSY_STONE_BRICKS.getDefaultState());
        structure.fillWithBlocks(world, start, 80, -11, 36, 80, -10, 38, Blocks.STONE_BRICKS.getDefaultState());
        structure.fillWithBlocks(world, start, 80, -9, 31, 80, -7, 36, Blocks.STONE_BRICKS.getDefaultState());
        structure.fillWithBlocks(world, start, 80, -9, 38, 80, -7, 38, Blocks.STONE_BRICKS.getDefaultState());
        structure.fillWithBlocks(world, start, 80, -7, 30, 80, -7, 38, Blocks.STONE_BRICKS.getDefaultState());
        structure.fillWithBlocks(world, start, 80, 0, 6, 81, 0, 7, Blocks.GRASS_BLOCK.getDefaultState().with(SnowyDirtBlock.SNOWY, false));
        structure.fillWithBlocks(world, start, 80, 0, 8, 80, 0, 9, Blocks.DIRT.getDefaultState());
        structure.fillWithBlocks(world, start, 80, 0, 23, 80, 0, 24, Blocks.GRASS_BLOCK.getDefaultState().with(SnowyDirtBlock.SNOWY, false));
        structure.fillWithBlocks(world, start, 80, 1, 10, 80, 1, 10, Blocks.DIRT.getDefaultState());
        structure.fillWithBlocks(world, start, 80, 1, 22, 80, 3, 22, Blocks.CRACKED_STONE_BRICKS.getDefaultState());
        structure.fillWithBlocks(world, start, 80, 2, 10, 81, 2, 11, Blocks.DIRT.getDefaultState());
        structure.fillWithBlocks(world, start, 80, 3, 10, 80, 3, 10, Blocks.GRASS_BLOCK.getDefaultState().with(SnowyDirtBlock.SNOWY, false));
        structure.fillWithBlocks(world, start, 80, 3, 11, 80, 3, 12, Blocks.DIRT.getDefaultState());
        structure.fillWithBlocks(world, start, 80, 4, 12, 82, 4, 14, Blocks.DIRT.getDefaultState());
        structure.fillWithBlocks(world, start, 80, 4, 15, 80, 4, 21, Blocks.STONE.getDefaultState());
        structure.fillWithBlocks(world, start, 80, 5, 15, 82, 6, 15, Blocks.DIRT.getDefaultState());
        structure.fillWithBlocks(world, start, 80, 5, 16, 81, 5, 20, Blocks.STONE.getDefaultState());
        structure.fillWithBlocks(world, start, 80, 5, 21, 80, 8, 21, Blocks.STONE.getDefaultState());
        structure.fillWithBlocks(world, start, 80, 6, 13, 80, 6, 13, Blocks.GRASS_BLOCK.getDefaultState().with(SnowyDirtBlock.SNOWY, false));
        structure.fillWithBlocks(world, start, 80, 6, 14, 80, 6, 16, Blocks.DIRT.getDefaultState());
        structure.fillWithBlocks(world, start, 80, 6, 19, 81, 6, 21, Blocks.STONE.getDefaultState());
        structure.fillWithBlocks(world, start, 80, 7, 13, 80, 7, 13, Blocks.GRASS.getDefaultState());
        structure.fillWithBlocks(world, start, 80, 7, 14, 80, 7, 14, Blocks.MOSSY_STONE_BRICKS.getDefaultState());
        structure.fillWithBlocks(world, start, 80, 7, 15, 80, 7, 16, Blocks.DIRT.getDefaultState());
        structure.fillWithBlocks(world, start, 80, 7, 19, 81, 7, 21, Blocks.STONE.getDefaultState());
        structure.fillWithBlocks(world, start, 80, 8, 14, 80, 9, 14, Blocks.MOSSY_COBBLESTONE.getDefaultState());
        structure.fillWithBlocks(world, start, 80, 8, 15, 80, 9, 15, Blocks.STONE_BRICKS.getDefaultState());
        structure.fillWithBlocks(world, start, 80, 8, 16, 81, 8, 16, Blocks.DIRT.getDefaultState());
        structure.fillWithBlocks(world, start, 80, 8, 20, 80, 8, 21, Blocks.STONE.getDefaultState());
        structure.fillWithBlocks(world, start, 80, 9, 20, 80, 9, 21, Blocks.CRACKED_STONE_BRICKS.getDefaultState());
        structure.fillWithBlocks(world, start, 80, 10, 15, 80, 12, 15, Blocks.CRACKED_STONE_BRICKS.getDefaultState());
        structure.fillWithBlocks(world, start, 80, 10, 17, 80, 11, 17, Blocks.STONE_BRICKS.getDefaultState());
        structure.fillWithBlocks(world, start, 80, 10, 20, 80, 11, 20, Blocks.STONE_BRICKS.getDefaultState());
        structure.fillWithBlocks(world, start, 80, 10, 21, 80, 12, 21, Blocks.CRACKED_STONE_BRICKS.getDefaultState());
        structure.fillWithBlocks(world, start, 80, 12, 17, 80, 12, 18, Blocks.CRACKED_STONE_BRICKS.getDefaultState());
        structure.fillWithBlocks(world, start, 80, 12, 20, 80, 12, 21, Blocks.CRACKED_STONE_BRICKS.getDefaultState());
        structure.fillWithBlocks(world, start, 80, 13, 20, 80, 15, 20, Blocks.CRACKED_STONE_BRICKS.getDefaultState());
        structure.fillWithBlocks(world, start, 80, 14, 17, 80, 15, 17, Blocks.CRACKED_STONE_BRICKS.getDefaultState());
        structure.fillWithBlocks(world, start, 81, -57, -35, 83, -57, -33, Blocks.STONE_BRICKS.getDefaultState());
        structure.fillWithBlocks(world, start, 81, -57, -25, 83, -57, -23, Blocks.STONE_BRICKS.getDefaultState());
        structure.fillWithBlocks(world, start, 81, -56, -35, 83, -56, -33, Blocks.AIR.getDefaultState());
        structure.fillWithBlocks(world, start, 81, -56, -25, 83, -56, -23, Blocks.AIR.getDefaultState());
        structure.fillWithBlocks(world, start, 81, -56, -22, 82, -56, -21, Blocks.STONE_BRICKS.getDefaultState());
        structure.fillWithBlocks(world, start, 81, -55, -36, 81, -47, -36, Blocks.STONE_BRICKS.getDefaultState());
        structure.fillWithBlocks(world, start, 81, -55, -35, 83, -55, -33, Blocks.AIR.getDefaultState());
        structure.fillWithBlocks(world, start, 81, -55, -32, 81, -47, -32, Blocks.STONE_BRICKS.getDefaultState());
        structure.fillWithBlocks(world, start, 81, -55, -30, 83, -55, -28, Blocks.AIR.getDefaultState());
        structure.fillWithBlocks(world, start, 81, -55, -26, 81, -52, -26, Blocks.STONE_BRICKS.getDefaultState());
        structure.fillWithBlocks(world, start, 81, -55, -25, 83, -55, -23, Blocks.AIR.getDefaultState());
        structure.fillWithBlocks(world, start, 81, -55, -22, 81, -55, -21, Blocks.STONE_BRICKS.getDefaultState());
        structure.fillWithBlocks(world, start, 81, -54, -35, 83, -54, -33, Blocks.AIR.getDefaultState());
        structure.fillWithBlocks(world, start, 81, -54, -25, 83, -54, -23, Blocks.AIR.getDefaultState());
        structure.fillWithBlocks(world, start, 81, -54, -22, 81, -54, -21, Blocks.STONE_BRICKS.getDefaultState());
        structure.fillWithBlocks(world, start, 81, -53, -35, 83, -53, -33, Blocks.AIR.getDefaultState());
        structure.fillWithBlocks(world, start, 81, -53, -25, 83, -53, -23, Blocks.AIR.getDefaultState());
        structure.fillWithBlocks(world, start, 81, -53, -22, 81, -47, -22, Blocks.STONE_BRICKS.getDefaultState());
        structure.fillWithBlocks(world, start, 81, -52, -35, 83, -52, -33, Blocks.AIR.getDefaultState());
        structure.fillWithBlocks(world, start, 81, -52, -25, 83, -52, -23, Blocks.AIR.getDefaultState());
        structure.fillWithBlocks(world, start, 81, -51, -37, 82, -51, -36, Blocks.STONE_BRICKS.getDefaultState());
        structure.fillWithBlocks(world, start, 81, -51, -35, 81, -48, -32, Blocks.STONE_BRICKS.getDefaultState());
        structure.fillWithBlocks(world, start, 81, -51, -31, 81, -51, -27, Blocks.STONE_BRICKS.getDefaultState());
        structure.fillWithBlocks(world, start, 81, -51, -26, 81, -51, -26, Blocks.AIR.getDefaultState());
        structure.fillWithBlocks(world, start, 81, -51, -25, 81, -48, -22, Blocks.STONE_BRICKS.getDefaultState());
        structure.fillWithBlocks(world, start, 81, -50, -37, 82, -50, -31, Blocks.STONE_BRICKS.getDefaultState());
        structure.fillWithBlocks(world, start, 81, -50, -26, 82, -50, -21, Blocks.STONE_BRICKS.getDefaultState());
        structure.fillWithBlocks(world, start, 81, -48, -30, 83, -48, -28, Blocks.STONE_BRICKS.getDefaultState());
        structure.fillWithBlocks(world, start, 81, -48, -27, 82, -48, -22, Blocks.STONE_BRICKS.getDefaultState());
        structure.fillWithBlocks(world, start, 81, -47, -35, 81, -47, -21, Blocks.STONE_BRICKS.getDefaultState());
        structure.fillWithBlocks(world, start, 81, -46, 3, 81, -45, 4, Blocks.MOSSY_STONE_BRICKS.getDefaultState());
        structure.fillWithBlocks(world, start, 81, -46, 8, 82, -46, 9, Blocks.STONE_BRICKS.getDefaultState());
        structure.fillWithBlocks(world, start, 81, -46, 10, 81, -46, 10, Blocks.MOSSY_COBBLESTONE.getDefaultState());
        structure.fillWithBlocks(world, start, 81, -46, 11, 81, -46, 11, Blocks.STONE_BRICKS.getDefaultState());
        structure.fillWithBlocks(world, start, 81, -46, 13, 81, -46, 14, Blocks.STONE_BRICKS.getDefaultState());
        structure.fillWithBlocks(world, start, 81, -46, 15, 81, -46, 15, Blocks.MOSSY_COBBLESTONE.getDefaultState());
        structure.fillWithBlocks(world, start, 81, -46, 18, 81, -46, 23, Blocks.STONE_BRICKS.getDefaultState());
        structure.fillWithBlocks(world, start, 81, -45, 5, 82, -45, 5, Blocks.MOSSY_COBBLESTONE.getDefaultState());
        structure.fillWithBlocks(world, start, 81, -45, 7, 81, -42, 7, Blocks.STONE_BRICKS.getDefaultState());
        structure.fillWithBlocks(world, start, 81, -45, 8, 81, -43, 10, Blocks.AIR.getDefaultState());
        structure.fillWithBlocks(world, start, 81, -45, 11, 81, -44, 11, Blocks.MOSSY_STONE_BRICKS.getDefaultState());
        structure.fillWithBlocks(world, start, 81, -45, 12, 81, -45, 12, Blocks.AIR.getDefaultState());
        structure.fillWithBlocks(world, start, 81, -45, 14, 82, -44, 14, Blocks.AIR.getDefaultState());
        structure.fillWithBlocks(world, start, 81, -45, 15, 81, -44, 15, Blocks.MOSSY_STONE_BRICKS.getDefaultState());
        structure.fillWithBlocks(world, start, 81, -45, 16, 81, -43, 18, Blocks.AIR.getDefaultState());
        structure.fillWithBlocks(world, start, 81, -45, 19, 81, -45, 21, Blocks.STONE_BRICKS.getDefaultState());
        structure.fillWithBlocks(world, start, 81, -44, 3, 82, -44, 4, Blocks.STONE_BRICKS.getDefaultState());
        structure.fillWithBlocks(world, start, 81, -44, 6, 81, -43, 7, Blocks.STONE_BRICKS.getDefaultState());
        structure.fillWithBlocks(world, start, 81, -44, 12, 82, -44, 14, Blocks.AIR.getDefaultState());
        structure.fillWithBlocks(world, start, 81, -44, 20, 81, -43, 20, Blocks.MOSSY_STONE_BRICKS.getDefaultState());
        structure.fillWithBlocks(world, start, 81, -44, 21, 81, -44, 22, Blocks.STONE_BRICKS.getDefaultState());
        structure.fillWithBlocks(world, start, 81, -43, 3, 81, -42, 4, Blocks.STONE_BRICKS.getDefaultState());
        structure.fillWithBlocks(world, start, 81, -43, 5, 82, -43, 6, Blocks.STONE_BRICKS.getDefaultState());
        structure.fillWithBlocks(world, start, 81, -43, 11, 85, -43, 11, Blocks.STONE_BRICKS.getDefaultState());
        structure.fillWithBlocks(world, start, 81, -43, 12, 82, -43, 14, Blocks.AIR.getDefaultState());
        structure.fillWithBlocks(world, start, 81, -43, 15, 81, -43, 15, Blocks.STONE_BRICKS.getDefaultState());
        structure.fillWithBlocks(world, start, 81, -43, 19, 81, -43, 22, Blocks.MOSSY_STONE_BRICKS.getDefaultState());
        structure.fillWithBlocks(world, start, 81, -43, 23, 85, -43, 23, Blocks.STONE_BRICKS.getDefaultState());
        structure.fillWithBlocks(world, start, 81, -42, 8, 81, -41, 10, Blocks.AIR.getDefaultState());
        structure.fillWithBlocks(world, start, 81, -42, 11, 81, -42, 11, Blocks.MOSSY_STONE_BRICKS.getDefaultState());
        structure.fillWithBlocks(world, start, 81, -42, 19, 82, -42, 22, Blocks.STONE_BRICKS.getDefaultState());
        structure.fillWithBlocks(world, start, 81, -41, 11, 83, -40, 11, Blocks.STONE_BRICKS.getDefaultState());
        structure.fillWithBlocks(world, start, 81, -41, 12, 81, -40, 12, Blocks.MOSSY_COBBLESTONE.getDefaultState());
        structure.fillWithBlocks(world, start, 81, -41, 13, 81, -40, 14, Blocks.STONE_BRICKS.getDefaultState());
        structure.fillWithBlocks(world, start, 81, -41, 15, 81, -41, 18, Blocks.AIR.getDefaultState());
        structure.fillWithBlocks(world, start, 81, -41, 19, 81, -40, 19, Blocks.STONE_BRICKS.getDefaultState());
        structure.fillWithBlocks(world, start, 81, -41, 20, 82, -41, 20, Blocks.MOSSY_COBBLESTONE.getDefaultState());
        structure.fillWithBlocks(world, start, 81, -41, 21, 81, -37, 21, Blocks.STONE_BRICKS.getDefaultState());
        structure.fillWithBlocks(world, start, 81, -41, 22, 81, -41, 23, Blocks.MOSSY_STONE_BRICKS.getDefaultState());
        structure.fillWithBlocks(world, start, 81, -40, 4, 81, -40, 11, Blocks.STONE_BRICKS.getDefaultState());
        structure.fillWithBlocks(world, start, 81, -40, 15, 81, -40, 16, Blocks.MOSSY_STONE_BRICKS.getDefaultState());
        structure.fillWithBlocks(world, start, 81, -40, 17, 81, -39, 18, Blocks.STONE_BRICKS.getDefaultState());
        structure.fillWithBlocks(world, start, 81, -40, 20, 81, -39, 20, Blocks.MOSSY_STONE_BRICKS.getDefaultState());
        structure.fillWithBlocks(world, start, 81, -40, 22, 81, -39, 22, Blocks.STONE_BRICKS.getDefaultState());
        structure.fillWithBlocks(world, start, 81, -39, 5, 81, -39, 5, Blocks.MOSSY_STONE_BRICKS.getDefaultState());
        structure.fillWithBlocks(world, start, 81, -39, 6, 81, -39, 9, Blocks.STONE_BRICKS.getDefaultState());
        structure.fillWithBlocks(world, start, 81, -39, 11, 81, -39, 13, Blocks.STONE_BRICKS.getDefaultState());
        structure.fillWithBlocks(world, start, 81, -39, 15, 82, -39, 18, Blocks.STONE_BRICKS.getDefaultState());
        structure.fillWithBlocks(world, start, 81, -39, 19, 82, -39, 19, Blocks.AIR.getDefaultState());
        structure.fillWithBlocks(world, start, 81, -38, 4, 82, -38, 5, Blocks.STONE_BRICKS.getDefaultState());
        structure.fillWithBlocks(world, start, 81, -38, 9, 81, -38, 10, Blocks.STONE_BRICKS.getDefaultState());
        structure.fillWithBlocks(world, start, 81, -38, 11, 81, -38, 11, Blocks.MOSSY_STONE_BRICKS.getDefaultState());
        structure.fillWithBlocks(world, start, 81, -38, 14, 81, -38, 15, Blocks.STONE_BRICKS.getDefaultState());
        structure.fillWithBlocks(world, start, 81, -38, 18, 81, -38, 18, Blocks.STONE_BRICKS.getDefaultState());
        structure.fillWithBlocks(world, start, 81, -38, 20, 81, -38, 21, Blocks.STONE_BRICKS.getDefaultState());
        structure.fillWithBlocks(world, start, 81, -38, 22, 82, -38, 22, Blocks.MOSSY_STONE_BRICKS.getDefaultState());
        structure.fillWithBlocks(world, start, 81, -37, 3, 82, -37, 4, Blocks.STONE_BRICKS.getDefaultState());
        structure.fillWithBlocks(world, start, 81, -37, 8, 82, -37, 8, Blocks.MOSSY_COBBLESTONE.getDefaultState());
        structure.fillWithBlocks(world, start, 81, -37, 12, 82, -37, 12, Blocks.MOSSY_STONE_BRICKS.getDefaultState());
        structure.fillWithBlocks(world, start, 81, -37, 14, 82, -37, 15, Blocks.STONE_BRICKS.getDefaultState());
        structure.fillWithBlocks(world, start, 81, -37, 17, 81, -37, 18, Blocks.STONE_BRICKS.getDefaultState());
        structure.fillWithBlocks(world, start, 81, -37, 22, 81, -37, 22, Blocks.STONE_BRICKS.getDefaultState());
        structure.fillWithBlocks(world, start, 81, -25, 28, 81, -24, 28, Blocks.CRACKED_STONE_BRICKS.getDefaultState());
        structure.fillWithBlocks(world, start, 81, -22, 30, 81, -22, 30, Blocks.CRACKED_STONE_BRICKS.getDefaultState());
        structure.fillWithBlocks(world, start, 81, -22, 31, 81, -22, 33, Blocks.STONE_BRICKS.getDefaultState());
        structure.fillWithBlocks(world, start, 81, -16, 29, 83, -16, 33, Blocks.STONE_BRICKS.getDefaultState());
        structure.fillWithBlocks(world, start, 81, -15, 28, 81, -15, 28, Blocks.STONE_BRICKS.getDefaultState());
        structure.fillWithBlocks(world, start, 81, -15, 34, 81, -15, 34, Blocks.STONE_BRICKS.getDefaultState());
        structure.fillWithBlocks(world, start, 81, -14, 28, 81, -14, 28, Blocks.STONE_BRICKS.getDefaultState());
        structure.fillWithBlocks(world, start, 81, -14, 34, 81, -14, 34, Blocks.STONE_BRICKS.getDefaultState());
        structure.fillWithBlocks(world, start, 81, -13, 28, 81, -13, 28, Blocks.STONE_BRICKS.getDefaultState());
        structure.fillWithBlocks(world, start, 81, -13, 34, 81, -13, 34, Blocks.STONE_BRICKS.getDefaultState());
        structure.fillWithBlocks(world, start, 81, -12, 29, 82, -12, 30, Blocks.STONE_BRICKS.getDefaultState());
        structure.fillWithBlocks(world, start, 81, -12, 32, 82, -12, 33, Blocks.STONE_BRICKS.getDefaultState());
        structure.fillWithBlocks(world, start, 81, 0, 8, 81, 1, 9, Blocks.STONE.getDefaultState());
        structure.fillWithBlocks(world, start, 81, 0, 22, 82, 0, 22, Blocks.DIRT.getDefaultState());
        structure.fillWithBlocks(world, start, 81, 0, 52, 83, 0, 56, Blocks.GRASS_BLOCK.getDefaultState().with(SnowyDirtBlock.SNOWY, false));
        structure.fillWithBlocks(world, start, 81, 1, 10, 82, 1, 11, Blocks.DIRT.getDefaultState());
        structure.fillWithBlocks(world, start, 81, 3, 10, 81, 3, 11, Blocks.GRASS_BLOCK.getDefaultState().with(SnowyDirtBlock.SNOWY, false));
        structure.fillWithBlocks(world, start, 81, 3, 12, 81, 3, 12, Blocks.DIRT.getDefaultState());
        structure.fillWithBlocks(world, start, 81, 4, 15, 81, 4, 15, Blocks.DIRT.getDefaultState());
        structure.fillWithBlocks(world, start, 81, 4, 16, 81, 4, 21, Blocks.STONE.getDefaultState());
        structure.fillWithBlocks(world, start, 81, 5, 12, 81, 5, 12, Blocks.GRASS_BLOCK.getDefaultState().with(SnowyDirtBlock.SNOWY, false));
        structure.fillWithBlocks(world, start, 81, 5, 13, 81, 5, 15, Blocks.DIRT.getDefaultState());
        structure.fillWithBlocks(world, start, 81, 6, 13, 81, 6, 14, Blocks.GRASS_BLOCK.getDefaultState().with(SnowyDirtBlock.SNOWY, false));
        structure.fillWithBlocks(world, start, 81, 6, 17, 81, 6, 17, Blocks.STONE.getDefaultState());
        structure.fillWithBlocks(world, start, 81, 6, 18, 81, 8, 18, Blocks.GRAVEL.getDefaultState());
        structure.fillWithBlocks(world, start, 81, 7, 13, 81, 7, 14, Blocks.GRASS.getDefaultState());
        structure.fillWithBlocks(world, start, 81, 7, 15, 81, 9, 15, Blocks.MOSSY_STONE_BRICKS.getDefaultState());
        structure.fillWithBlocks(world, start, 81, 7, 17, 81, 7, 17, Blocks.STONE.getDefaultState());
        structure.fillWithBlocks(world, start, 81, 8, 19, 81, 8, 20, Blocks.COBBLESTONE.getDefaultState());
        structure.fillWithBlocks(world, start, 81, 8, 21, 81, 9, 21, Blocks.STONE.getDefaultState());
        structure.fillWithBlocks(world, start, 81, 9, 16, 81, 11, 16, Blocks.STONE_BRICKS.getDefaultState());
        structure.fillWithBlocks(world, start, 81, 12, 16, 81, 13, 16, Blocks.CRACKED_STONE_BRICKS.getDefaultState());
        structure.fillWithBlocks(world, start, 81, 12, 21, 81, 13, 21, Blocks.CRACKED_STONE_BRICKS.getDefaultState());
        structure.fillWithBlocks(world, start, 82, -56, -37, 83, -56, -36, Blocks.STONE_BRICKS.getDefaultState());
        structure.fillWithBlocks(world, start, 82, -55, -31, 86, -55, -27, Blocks.AIR.getDefaultState());
        structure.fillWithBlocks(world, start, 82, -55, -21, 86, -51, -21, Blocks.STONE_BRICKS.getDefaultState());
        structure.fillWithBlocks(world, start, 82, -54, -36, 86, -54, -22, Blocks.AIR.getDefaultState());
        structure.fillWithBlocks(world, start, 82, -53, -36, 86, -53, -22, Blocks.AIR.getDefaultState());
        structure.fillWithBlocks(world, start, 82, -52, -36, 86, -52, -22, Blocks.AIR.getDefaultState());
        structure.fillWithBlocks(world, start, 82, -51, -35, 84, -51, -33, Blocks.AIR.getDefaultState());
        structure.fillWithBlocks(world, start, 82, -51, -31, 86, -51, -27, Blocks.AIR.getDefaultState());
        structure.fillWithBlocks(world, start, 82, -51, -26, 105, -51, -26, Blocks.STONE_BRICKS.getDefaultState());
        structure.fillWithBlocks(world, start, 82, -51, -25, 84, -51, -23, Blocks.AIR.getDefaultState());
        structure.fillWithBlocks(world, start, 82, -51, -22, 83, -51, -21, Blocks.STONE_BRICKS.getDefaultState());
        structure.fillWithBlocks(world, start, 82, -50, -30, 83, -50, -27, Blocks.STONE_BRICKS.getDefaultState());
        structure.fillWithBlocks(world, start, 82, -49, -37, 86, -49, -33, Blocks.STONE_BRICKS.getDefaultState());
        structure.fillWithBlocks(world, start, 82, -49, -31, 83, -49, -30, Blocks.STONE_BRICKS.getDefaultState());
        structure.fillWithBlocks(world, start, 82, -49, -29, 82, -49, -21, Blocks.STONE_BRICKS.getDefaultState());
        structure.fillWithBlocks(world, start, 82, -48, -31, 83, -48, -28, Blocks.STONE_BRICKS.getDefaultState());
        structure.fillWithBlocks(world, start, 82, -48, -21, 92, -47, -21, Blocks.STONE_BRICKS.getDefaultState());
        structure.fillWithBlocks(world, start, 82, -47, -37, 82, -47, -36, Blocks.STONE_BRICKS.getDefaultState());
        structure.fillWithBlocks(world, start, 82, -46, 3, 82, -45, 4, Blocks.STONE_BRICKS.getDefaultState());
        structure.fillWithBlocks(world, start, 82, -46, 5, 82, -46, 9, Blocks.STONE_BRICKS.getDefaultState());
        structure.fillWithBlocks(world, start, 82, -46, 12, 83, -46, 12, Blocks.STONE_BRICKS.getDefaultState());
        structure.fillWithBlocks(world, start, 82, -46, 14, 83, -46, 15, Blocks.STONE_BRICKS.getDefaultState());
        structure.fillWithBlocks(world, start, 82, -46, 18, 82, -46, 18, Blocks.MOSSY_STONE_BRICKS.getDefaultState());
        structure.fillWithBlocks(world, start, 82, -46, 19, 82, -46, 19, Blocks.STONE_BRICKS.getDefaultState());
        structure.fillWithBlocks(world, start, 82, -46, 21, 82, -46, 22, Blocks.STONE_BRICKS.getDefaultState());
        structure.fillWithBlocks(world, start, 82, -45, 8, 82, -45, 11, Blocks.STONE_BRICKS.getDefaultState());
        structure.fillWithBlocks(world, start, 82, -45, 12, 82, -43, 14, Blocks.AIR.getDefaultState());
        structure.fillWithBlocks(world, start, 82, -45, 15, 82, -45, 18, Blocks.STONE_BRICKS.getDefaultState());
        structure.fillWithBlocks(world, start, 82, -45, 20, 82, -45, 21, Blocks.MOSSY_COBBLESTONE.getDefaultState());
        structure.fillWithBlocks(world, start, 82, -45, 22, 82, -45, 22, Blocks.STONE_BRICKS.getDefaultState());
        structure.fillWithBlocks(world, start, 82, -44, 5, 83, -44, 5, Blocks.STONE_BRICKS.getDefaultState());
        structure.fillWithBlocks(world, start, 82, -44, 7, 84, -44, 7, Blocks.AIR.getDefaultState());
        structure.fillWithBlocks(world, start, 82, -44, 8, 83, -44, 8, Blocks.STONE_BRICKS.getDefaultState());
        structure.fillWithBlocks(world, start, 82, -44, 10, 83, -44, 11, Blocks.STONE_BRICKS.getDefaultState());
        structure.fillWithBlocks(world, start, 82, -44, 16, 82, -44, 16, Blocks.STONE_BRICKS.getDefaultState());
        structure.fillWithBlocks(world, start, 82, -44, 19, 82, -43, 19, Blocks.AIR.getDefaultState());
        structure.fillWithBlocks(world, start, 82, -44, 21, 82, -44, 22, Blocks.MOSSY_STONE_BRICKS.getDefaultState());
        structure.fillWithBlocks(world, start, 82, -43, 3, 83, -42, 3, Blocks.STONE_BRICKS.getDefaultState());
        structure.fillWithBlocks(world, start, 82, -43, 4, 83, -43, 4, Blocks.MOSSY_STONE_BRICKS.getDefaultState());
        structure.fillWithBlocks(world, start, 82, -43, 7, 82, -43, 8, Blocks.MOSSY_STONE_BRICKS.getDefaultState());
        structure.fillWithBlocks(world, start, 82, -43, 9, 82, -43, 9, Blocks.STONE_BRICKS.getDefaultState());
        structure.fillWithBlocks(world, start, 82, -43, 15, 82, -43, 17, Blocks.STONE_BRICKS.getDefaultState());
        structure.fillWithBlocks(world, start, 82, -43, 20, 85, -42, 20, Blocks.STONE_BRICKS.getDefaultState());
        structure.fillWithBlocks(world, start, 82, -42, 4, 82, -42, 5, Blocks.STONE_BRICKS.getDefaultState());
        structure.fillWithBlocks(world, start, 82, -42, 7, 82, -42, 10, Blocks.STONE_BRICKS.getDefaultState());
        structure.fillWithBlocks(world, start, 82, -42, 12, 82, -40, 12, Blocks.MOSSY_STONE_BRICKS.getDefaultState());
        structure.fillWithBlocks(world, start, 82, -42, 13, 84, -42, 15, Blocks.STONE_BRICKS.getDefaultState());
        structure.fillWithBlocks(world, start, 82, -42, 16, 82, -42, 16, Blocks.STONE_BRICKS.getDefaultState());
        structure.fillWithBlocks(world, start, 82, -42, 17, 82, -42, 17, Blocks.MOSSY_COBBLESTONE.getDefaultState());
        structure.fillWithBlocks(world, start, 82, -42, 18, 82, -42, 22, Blocks.STONE_BRICKS.getDefaultState());
        structure.fillWithBlocks(world, start, 82, -42, 23, 84, -42, 23, Blocks.MOSSY_COBBLESTONE.getDefaultState());
        structure.fillWithBlocks(world, start, 82, -41, 3, 82, -41, 3, Blocks.STONE_BRICKS.getDefaultState());
        structure.fillWithBlocks(world, start, 82, -41, 7, 82, -40, 7, Blocks.MOSSY_STONE_BRICKS.getDefaultState());
        structure.fillWithBlocks(world, start, 82, -41, 8, 83, -41, 9, Blocks.STONE_BRICKS.getDefaultState());
        structure.fillWithBlocks(world, start, 82, -41, 10, 82, -41, 11, Blocks.STONE_BRICKS.getDefaultState());
        structure.fillWithBlocks(world, start, 82, -41, 13, 84, -41, 13, Blocks.STONE_BRICKS.getDefaultState());
        structure.fillWithBlocks(world, start, 82, -41, 14, 83, -41, 14, Blocks.AIR.getDefaultState());
        structure.fillWithBlocks(world, start, 82, -41, 16, 83, -41, 16, Blocks.STONE_BRICKS.getDefaultState());
        structure.fillWithBlocks(world, start, 82, -41, 17, 82, -40, 17, Blocks.MOSSY_STONE_BRICKS.getDefaultState());
        structure.fillWithBlocks(world, start, 82, -41, 18, 82, -41, 18, Blocks.STONE_BRICKS.getDefaultState());
        structure.fillWithBlocks(world, start, 82, -41, 19, 82, -41, 19, Blocks.MOSSY_STONE_BRICKS.getDefaultState());
        structure.fillWithBlocks(world, start, 82, -41, 22, 82, -41, 22, Blocks.STONE_BRICKS.getDefaultState());
        structure.fillWithBlocks(world, start, 82, -41, 23, 82, -40, 23, Blocks.MOSSY_STONE_BRICKS.getDefaultState());
        structure.fillWithBlocks(world, start, 82, -40, 3, 83, -40, 4, Blocks.MOSSY_STONE_BRICKS.getDefaultState());
        structure.fillWithBlocks(world, start, 82, -40, 5, 82, -40, 5, Blocks.STONE_BRICKS.getDefaultState());
        structure.fillWithBlocks(world, start, 82, -40, 8, 82, -40, 8, Blocks.STONE_BRICKS.getDefaultState());
        structure.fillWithBlocks(world, start, 82, -40, 10, 83, -40, 11, Blocks.STONE_BRICKS.getDefaultState());
        structure.fillWithBlocks(world, start, 82, -40, 15, 82, -39, 16, Blocks.STONE_BRICKS.getDefaultState());
        structure.fillWithBlocks(world, start, 82, -40, 19, 82, -40, 21, Blocks.STONE_BRICKS.getDefaultState());
        structure.fillWithBlocks(world, start, 82, -39, 3, 82, -39, 3, Blocks.STONE_BRICKS.getDefaultState());
        structure.fillWithBlocks(world, start, 82, -39, 4, 82, -39, 6, Blocks.MOSSY_STONE_BRICKS.getDefaultState());
        structure.fillWithBlocks(world, start, 82, -39, 7, 82, -38, 7, Blocks.STONE_BRICKS.getDefaultState());
        structure.fillWithBlocks(world, start, 82, -39, 8, 82, -38, 8, Blocks.AIR.getDefaultState());
        structure.fillWithBlocks(world, start, 82, -39, 10, 83, -39, 10, Blocks.STONE_BRICKS.getDefaultState());
        structure.fillWithBlocks(world, start, 82, -39, 11, 82, -37, 11, Blocks.MOSSY_STONE_BRICKS.getDefaultState());
        structure.fillWithBlocks(world, start, 82, -39, 21, 82, -38, 21, Blocks.MOSSY_STONE_BRICKS.getDefaultState());
        structure.fillWithBlocks(world, start, 82, -39, 22, 82, -39, 23, Blocks.STONE_BRICKS.getDefaultState());
        structure.fillWithBlocks(world, start, 82, -38, 3, 82, -37, 4, Blocks.STONE_BRICKS.getDefaultState());
        structure.fillWithBlocks(world, start, 82, -38, 9, 82, -38, 9, Blocks.STONE_BRICKS.getDefaultState());
        structure.fillWithBlocks(world, start, 82, -38, 10, 82, -38, 12, Blocks.MOSSY_STONE_BRICKS.getDefaultState());
        structure.fillWithBlocks(world, start, 82, -38, 13, 85, -37, 13, Blocks.STONE_BRICKS.getDefaultState());
        structure.fillWithBlocks(world, start, 82, -38, 15, 82, -37, 15, Blocks.STONE_BRICKS.getDefaultState());
        structure.fillWithBlocks(world, start, 82, -38, 17, 82, -38, 20, Blocks.STONE_BRICKS.getDefaultState());
        structure.fillWithBlocks(world, start, 82, -37, 6, 83, -37, 6, Blocks.STONE_BRICKS.getDefaultState());
        structure.fillWithBlocks(world, start, 82, -37, 7, 82, -37, 7, Blocks.MOSSY_STONE_BRICKS.getDefaultState());
        structure.fillWithBlocks(world, start, 82, -37, 9, 82, -37, 10, Blocks.STONE_BRICKS.getDefaultState());
        structure.fillWithBlocks(world, start, 82, -37, 16, 82, -37, 17, Blocks.STONE_BRICKS.getDefaultState());
        structure.fillWithBlocks(world, start, 82, -37, 19, 82, -37, 23, Blocks.STONE_BRICKS.getDefaultState());
        structure.fillWithBlocks(world, start, 82, -26, 30, 85, -26, 33, Blocks.STONE_BRICKS.getDefaultState());
        structure.fillWithBlocks(world, start, 82, -25, 28, 82, -24, 29, Blocks.STONE_BRICKS.getDefaultState());
        structure.fillWithBlocks(world, start, 82, -25, 30, 84, -25, 32, Blocks.AIR.getDefaultState());
        structure.fillWithBlocks(world, start, 82, -25, 33, 82, -25, 34, Blocks.STONE_BRICKS.getDefaultState());
        structure.fillWithBlocks(world, start, 82, -24, 30, 84, -24, 32, Blocks.AIR.getDefaultState());
        structure.fillWithBlocks(world, start, 82, -24, 33, 82, -24, 34, Blocks.STONE_BRICKS.getDefaultState());
        structure.fillWithBlocks(world, start, 82, -23, 28, 82, -23, 29, Blocks.STONE_BRICKS.getDefaultState());
        structure.fillWithBlocks(world, start, 82, -23, 30, 84, -23, 32, Blocks.AIR.getDefaultState());
        structure.fillWithBlocks(world, start, 82, -23, 33, 82, -23, 34, Blocks.STONE_BRICKS.getDefaultState());
        structure.fillWithBlocks(world, start, 82, -22, 29, 82, -22, 31, Blocks.CRACKED_STONE_BRICKS.getDefaultState());
        structure.fillWithBlocks(world, start, 82, -22, 32, 83, -22, 33, Blocks.STONE_BRICKS.getDefaultState());
        structure.fillWithBlocks(world, start, 82, -16, 25, 85, -16, 28, Blocks.STONE_BRICKS.getDefaultState());
        structure.fillWithBlocks(world, start, 82, -16, 34, 83, -16, 35, Blocks.STONE_BRICKS.getDefaultState());
        structure.fillWithBlocks(world, start, 82, -16, 36, 82, -16, 38, Blocks.STONE_BRICKS.getDefaultState());
        structure.fillWithBlocks(world, start, 82, -15, 24, 84, -15, 26, Blocks.STONE_BRICKS.getDefaultState());
        structure.fillWithBlocks(world, start, 82, -15, 27, 83, -15, 29, Blocks.STONE_BRICKS.getDefaultState());
        structure.fillWithBlocks(world, start, 82, -15, 30, 84, -15, 32, Blocks.AIR.getDefaultState());
        structure.fillWithBlocks(world, start, 82, -15, 33, 83, -15, 38, Blocks.STONE_BRICKS.getDefaultState());
        structure.fillWithBlocks(world, start, 82, -14, 24, 84, -14, 26, Blocks.STONE_BRICKS.getDefaultState());
        structure.fillWithBlocks(world, start, 82, -14, 27, 83, -14, 29, Blocks.STONE_BRICKS.getDefaultState());
        structure.fillWithBlocks(world, start, 82, -14, 30, 84, -14, 32, Blocks.AIR.getDefaultState());
        structure.fillWithBlocks(world, start, 82, -14, 33, 83, -14, 35, Blocks.STONE_BRICKS.getDefaultState());
        structure.fillWithBlocks(world, start, 82, -14, 36, 82, -7, 36, Blocks.STONE_BRICKS.getDefaultState());
        structure.fillWithBlocks(world, start, 82, -14, 38, 85, -11, 38, Blocks.STONE_BRICKS.getDefaultState());
        structure.fillWithBlocks(world, start, 82, -13, 24, 82, -13, 24, Blocks.STONE_BRICKS.getDefaultState());
        structure.fillWithBlocks(world, start, 82, -13, 26, 83, -13, 29, Blocks.STONE_BRICKS.getDefaultState());
        structure.fillWithBlocks(world, start, 82, -13, 30, 84, -13, 32, Blocks.AIR.getDefaultState());
        structure.fillWithBlocks(world, start, 82, -13, 33, 83, -13, 35, Blocks.STONE_BRICKS.getDefaultState());
        structure.fillWithBlocks(world, start, 82, -13, 37, 83, -13, 38, Blocks.STONE_BRICKS.getDefaultState());
        structure.fillWithBlocks(world, start, 82, -12, 24, 84, -12, 26, Blocks.STONE_BRICKS.getDefaultState());
        structure.fillWithBlocks(world, start, 82, -12, 27, 83, -12, 30, Blocks.STONE_BRICKS.getDefaultState());
        structure.fillWithBlocks(world, start, 82, -12, 31, 82, -12, 34, Blocks.STONE_BRICKS.getDefaultState());
        structure.fillWithBlocks(world, start, 82, -12, 35, 82, -12, 35, Blocks.MOSSY_STONE_BRICKS.getDefaultState());
        structure.fillWithBlocks(world, start, 82, -12, 37, 83, -12, 38, Blocks.STONE_BRICKS.getDefaultState());
        structure.fillWithBlocks(world, start, 82, -11, 24, 82, -9, 28, Blocks.STONE_BRICKS.getDefaultState());
        structure.fillWithBlocks(world, start, 82, -11, 29, 82, -11, 29, Blocks.STONE_BRICKS.getDefaultState());
        structure.fillWithBlocks(world, start, 82, -11, 31, 82, -11, 31, Blocks.STONE_BRICKS.getDefaultState());
        structure.fillWithBlocks(world, start, 82, -11, 33, 83, -11, 34, Blocks.STONE_BRICKS.getDefaultState());
        structure.fillWithBlocks(world, start, 82, -11, 35, 82, -11, 38, Blocks.STONE_BRICKS.getDefaultState());
        structure.fillWithBlocks(world, start, 82, -10, 30, 88, -10, 38, Blocks.STONE_BRICKS.getDefaultState());
        structure.fillWithBlocks(world, start, 82, -9, 29, 88, -9, 38, Blocks.STONE_BRICKS.getDefaultState());
        structure.fillWithBlocks(world, start, 82, -8, 24, 84, -8, 26, Blocks.STONE_BRICKS.getDefaultState());
        structure.fillWithBlocks(world, start, 82, -8, 28, 83, -8, 29, Blocks.STONE_BRICKS.getDefaultState());
        structure.fillWithBlocks(world, start, 82, -8, 30, 82, -8, 33, Blocks.STONE_BRICKS.getDefaultState());
        structure.fillWithBlocks(world, start, 82, -8, 35, 83, -8, 38, Blocks.STONE_BRICKS.getDefaultState());
        structure.fillWithBlocks(world, start, 82, -7, 24, 82, -7, 25, Blocks.MOSSY_STONE_BRICKS.getDefaultState());
        structure.fillWithBlocks(world, start, 82, -7, 26, 85, -7, 36, Blocks.STONE_BRICKS.getDefaultState());
        structure.fillWithBlocks(world, start, 82, -7, 38, 85, -7, 38, Blocks.STONE_BRICKS.getDefaultState());
        structure.fillWithBlocks(world, start, 82, 0, 5, 84, 0, 7, Blocks.GRASS_BLOCK.getDefaultState().with(SnowyDirtBlock.SNOWY, false));
        structure.fillWithBlocks(world, start, 82, 0, 8, 84, 0, 10, Blocks.DIRT.getDefaultState());
        structure.fillWithBlocks(world, start, 82, 0, 48, 86, 0, 52, Blocks.GRASS_BLOCK.getDefaultState().with(SnowyDirtBlock.SNOWY, false));
        structure.fillWithBlocks(world, start, 82, 1, 8, 82, 1, 8, Blocks.GRASS_BLOCK.getDefaultState().with(SnowyDirtBlock.SNOWY, false));
        structure.fillWithBlocks(world, start, 82, 1, 9, 82, 1, 11, Blocks.DIRT.getDefaultState());
        structure.fillWithBlocks(world, start, 82, 1, 12, 83, 1, 19, Blocks.STONE.getDefaultState());
        structure.fillWithBlocks(world, start, 82, 1, 20, 82, 2, 21, Blocks.STONE.getDefaultState());
        structure.fillWithBlocks(world, start, 82, 2, 9, 82, 2, 10, Blocks.GRASS_BLOCK.getDefaultState().with(SnowyDirtBlock.SNOWY, false));
        structure.fillWithBlocks(world, start, 82, 2, 11, 83, 2, 12, Blocks.DIRT.getDefaultState());
        structure.fillWithBlocks(world, start, 82, 2, 13, 82, 2, 21, Blocks.STONE.getDefaultState());
        structure.fillWithBlocks(world, start, 82, 3, 11, 83, 3, 11, Blocks.GRASS_BLOCK.getDefaultState().with(SnowyDirtBlock.SNOWY, false));
        structure.fillWithBlocks(world, start, 82, 3, 12, 83, 3, 14, Blocks.DIRT.getDefaultState());
        structure.fillWithBlocks(world, start, 82, 3, 15, 82, 3, 21, Blocks.STONE.getDefaultState());
        structure.fillWithBlocks(world, start, 82, 4, 15, 83, 4, 16, Blocks.DIRT.getDefaultState());
        structure.fillWithBlocks(world, start, 82, 4, 17, 83, 4, 18, Blocks.STONE.getDefaultState());
        structure.fillWithBlocks(world, start, 82, 4, 19, 82, 5, 21, Blocks.STONE.getDefaultState());
        structure.fillWithBlocks(world, start, 82, 5, 13, 82, 5, 14, Blocks.GRASS_BLOCK.getDefaultState().with(SnowyDirtBlock.SNOWY, false));
        structure.fillWithBlocks(world, start, 82, 5, 16, 83, 5, 16, Blocks.DIRT.getDefaultState());
        structure.fillWithBlocks(world, start, 82, 5, 17, 82, 6, 20, Blocks.STONE.getDefaultState());
        structure.fillWithBlocks(world, start, 82, 6, 21, 82, 7, 21, Blocks.CRACKED_STONE_BRICKS.getDefaultState());
        structure.fillWithBlocks(world, start, 82, 7, 16, 82, 7, 17, Blocks.CRACKED_STONE_BRICKS.getDefaultState());
        structure.fillWithBlocks(world, start, 82, 7, 18, 82, 7, 20, Blocks.STONE.getDefaultState());
        structure.fillWithBlocks(world, start, 82, 8, 17, 82, 8, 19, Blocks.CRACKED_STONE_BRICKS.getDefaultState());
        structure.fillWithBlocks(world, start, 82, 11, 17, 82, 12, 17, Blocks.CRACKED_STONE_BRICKS.getDefaultState());
        structure.fillWithBlocks(world, start, 82, 12, 19, 82, 12, 20, Blocks.CRACKED_STONE_BRICKS.getDefaultState());
        structure.fillWithBlocks(world, start, 82, 14, 19, 82, 14, 19, Blocks.CRACKED_STONE_BRICKS.getDefaultState());
        structure.fillWithBlocks(world, start, 83, -56, -22, 84, -56, -21, Blocks.STONE_BRICKS.getDefaultState());
        structure.fillWithBlocks(world, start, 83, -55, -32, 86, -55, -32, Blocks.STONE_BRICK_WALL.getDefaultState().with(WallBlock.WATERLOGGED, false).with(WallBlock.UP, false).with(WallBlock.WALL_HEIGHT_NORTH, WallHeight.LOW).with(WallBlock.WALL_HEIGHT_SOUTH, WallHeight.LOW).with(WallBlock.WALL_HEIGHT_EAST, WallHeight.LOW).with(WallBlock.WALL_HEIGHT_WEST, WallHeight.LOW));
        structure.fillWithBlocks(world, start, 83, -55, -26, 85, -55, -26, Blocks.STONE_BRICK_WALL.getDefaultState().with(WallBlock.WATERLOGGED, false).with(WallBlock.UP, false).with(WallBlock.WALL_HEIGHT_NORTH, WallHeight.LOW).with(WallBlock.WALL_HEIGHT_SOUTH, WallHeight.LOW).with(WallBlock.WALL_HEIGHT_EAST, WallHeight.LOW).with(WallBlock.WALL_HEIGHT_WEST, WallHeight.LOW));
        structure.fillWithBlocks(world, start, 83, -55, -22, 86, -55, -22, Blocks.STONE_BRICK_WALL.getDefaultState().with(WallBlock.WATERLOGGED, false).with(WallBlock.UP, false).with(WallBlock.WALL_HEIGHT_NORTH, WallHeight.LOW).with(WallBlock.WALL_HEIGHT_SOUTH, WallHeight.LOW).with(WallBlock.WALL_HEIGHT_EAST, WallHeight.LOW).with(WallBlock.WALL_HEIGHT_WEST, WallHeight.LOW));
        structure.fillWithBlocks(world, start, 83, -51, -37, 83, -50, -37, Blocks.AIR.getDefaultState());
        structure.fillWithBlocks(world, start, 83, -51, -36, 90, -48, -36, Blocks.STONE_BRICKS.getDefaultState());
        structure.fillWithBlocks(world, start, 83, -50, -35, 83, -47, -32, Blocks.STONE_BRICKS.getDefaultState());
        structure.fillWithBlocks(world, start, 83, -50, -25, 83, -47, -21, Blocks.STONE_BRICKS.getDefaultState());
        structure.fillWithBlocks(world, start, 83, -49, -28, 84, -49, -21, Blocks.STONE_BRICKS.getDefaultState());
        structure.fillWithBlocks(world, start, 83, -48, -26, 88, -48, -21, Blocks.STONE_BRICKS.getDefaultState());
        structure.fillWithBlocks(world, start, 83, -47, -37, 83, -47, -37, Blocks.STONE_BRICKS.getDefaultState());
        structure.fillWithBlocks(world, start, 83, -47, -30, 88, -47, -25, Blocks.STONE_BRICKS.getDefaultState());
        structure.fillWithBlocks(world, start, 83, -46, 3, 83, -45, 3, Blocks.MOSSY_STONE_BRICKS.getDefaultState());
        structure.fillWithBlocks(world, start, 83, -46, 5, 83, -44, 5, Blocks.STONE_BRICKS.getDefaultState());
        structure.fillWithBlocks(world, start, 83, -46, 6, 83, -46, 6, Blocks.MOSSY_STONE_BRICKS.getDefaultState());
        structure.fillWithBlocks(world, start, 83, -46, 7, 83, -46, 8, Blocks.STONE_BRICKS.getDefaultState());
        structure.fillWithBlocks(world, start, 83, -46, 9, 83, -46, 9, Blocks.MOSSY_STONE_BRICKS.getDefaultState());
        structure.fillWithBlocks(world, start, 83, -46, 10, 83, -43, 10, Blocks.STONE_BRICKS.getDefaultState());
        structure.fillWithBlocks(world, start, 83, -46, 11, 83, -46, 11, Blocks.MOSSY_STONE_BRICKS.getDefaultState());
        structure.fillWithBlocks(world, start, 83, -46, 13, 84, -46, 13, Blocks.AIR.getDefaultState());
        structure.fillWithBlocks(world, start, 83, -46, 16, 84, -46, 18, Blocks.STONE_BRICKS.getDefaultState());
        structure.fillWithBlocks(world, start, 83, -46, 20, 84, -46, 21, Blocks.STONE_BRICKS.getDefaultState());
        structure.fillWithBlocks(world, start, 83, -46, 22, 83, -46, 23, Blocks.MOSSY_STONE_BRICKS.getDefaultState());
        structure.fillWithBlocks(world, start, 83, -45, 7, 83, -45, 7, Blocks.STONE_BRICKS.getDefaultState());
        structure.fillWithBlocks(world, start, 83, -45, 9, 83, -45, 11, Blocks.STONE_BRICKS.getDefaultState());
        structure.fillWithBlocks(world, start, 83, -45, 13, 83, -45, 14, Blocks.STONE_BRICKS.getDefaultState());
        structure.fillWithBlocks(world, start, 83, -45, 15, 84, -45, 15, Blocks.AIR.getDefaultState());
        structure.fillWithBlocks(world, start, 83, -45, 16, 84, -45, 17, Blocks.STONE_BRICKS.getDefaultState());
        structure.fillWithBlocks(world, start, 83, -45, 21, 83, -45, 23, Blocks.STONE_BRICKS.getDefaultState());
        structure.fillWithBlocks(world, start, 83, -44, 3, 83, -44, 3, Blocks.MOSSY_COBBLESTONE.getDefaultState());
        structure.fillWithBlocks(world, start, 83, -44, 4, 83, -44, 5, Blocks.STONE_BRICKS.getDefaultState());
        structure.fillWithBlocks(world, start, 83, -44, 6, 83, -44, 7, Blocks.AIR.getDefaultState());
        structure.fillWithBlocks(world, start, 83, -44, 9, 85, -44, 9, Blocks.MOSSY_STONE_BRICKS.getDefaultState());
        structure.fillWithBlocks(world, start, 83, -44, 12, 83, -43, 12, Blocks.STONE_BRICKS.getDefaultState());
        structure.fillWithBlocks(world, start, 83, -44, 14, 83, -42, 14, Blocks.STONE_BRICKS.getDefaultState());
        structure.fillWithBlocks(world, start, 83, -44, 16, 83, -44, 17, Blocks.STONE_BRICKS.getDefaultState());
        structure.fillWithBlocks(world, start, 83, -44, 20, 83, -42, 20, Blocks.STONE_BRICKS.getDefaultState());
        structure.fillWithBlocks(world, start, 83, -44, 22, 84, -44, 23, Blocks.STONE_BRICKS.getDefaultState());
        structure.fillWithBlocks(world, start, 83, -43, 7, 84, -43, 7, Blocks.STONE_BRICKS.getDefaultState());
        structure.fillWithBlocks(world, start, 83, -43, 8, 83, -43, 8, Blocks.AIR.getDefaultState());
        structure.fillWithBlocks(world, start, 83, -43, 9, 83, -43, 14, Blocks.STONE_BRICKS.getDefaultState());
        structure.fillWithBlocks(world, start, 83, -43, 16, 83, -43, 16, Blocks.STONE_BRICKS.getDefaultState());
        structure.fillWithBlocks(world, start, 83, -43, 18, 83, -43, 20, Blocks.STONE_BRICKS.getDefaultState());
        structure.fillWithBlocks(world, start, 83, -43, 22, 83, -43, 23, Blocks.STONE_BRICKS.getDefaultState());
        structure.fillWithBlocks(world, start, 83, -42, 7, 83, -42, 11, Blocks.MOSSY_STONE_BRICKS.getDefaultState());
        structure.fillWithBlocks(world, start, 83, -42, 16, 83, -42, 17, Blocks.STONE_BRICKS.getDefaultState());
        structure.fillWithBlocks(world, start, 83, -42, 18, 83, -41, 18, Blocks.MOSSY_COBBLESTONE.getDefaultState());
        structure.fillWithBlocks(world, start, 83, -42, 19, 83, -42, 20, Blocks.STONE_BRICKS.getDefaultState());
        structure.fillWithBlocks(world, start, 83, -42, 21, 84, -42, 21, Blocks.MOSSY_STONE_BRICKS.getDefaultState());
        structure.fillWithBlocks(world, start, 83, -41, 3, 83, -41, 3, Blocks.MOSSY_STONE_BRICKS.getDefaultState());
        structure.fillWithBlocks(world, start, 83, -41, 4, 83, -41, 5, Blocks.STONE_BRICKS.getDefaultState());
        structure.fillWithBlocks(world, start, 83, -41, 12, 84, -41, 13, Blocks.STONE_BRICKS.getDefaultState());
        structure.fillWithBlocks(world, start, 83, -41, 15, 83, -41, 16, Blocks.STONE_BRICKS.getDefaultState());
        structure.fillWithBlocks(world, start, 83, -41, 17, 84, -40, 17, Blocks.AIR.getDefaultState());
        structure.fillWithBlocks(world, start, 83, -41, 19, 83, -41, 19, Blocks.STONE_BRICKS.getDefaultState());
        structure.fillWithBlocks(world, start, 83, -41, 21, 83, -41, 21, Blocks.STONE_BRICKS.getDefaultState());
        structure.fillWithBlocks(world, start, 83, -41, 22, 83, -40, 22, Blocks.MOSSY_STONE_BRICKS.getDefaultState());
        structure.fillWithBlocks(world, start, 83, -40, 5, 83, -40, 6, Blocks.STONE_BRICKS.getDefaultState());
        structure.fillWithBlocks(world, start, 83, -40, 7, 83, -39, 7, Blocks.MOSSY_STONE_BRICKS.getDefaultState());
        structure.fillWithBlocks(world, start, 83, -40, 8, 83, -40, 11, Blocks.STONE_BRICKS.getDefaultState());
        structure.fillWithBlocks(world, start, 83, -40, 13, 83, -40, 13, Blocks.STONE_BRICKS.getDefaultState());
        structure.fillWithBlocks(world, start, 83, -40, 15, 83, -40, 15, Blocks.MOSSY_STONE_BRICKS.getDefaultState());
        structure.fillWithBlocks(world, start, 83, -40, 16, 83, -40, 17, Blocks.AIR.getDefaultState());
        structure.fillWithBlocks(world, start, 83, -40, 18, 83, -40, 18, Blocks.MOSSY_STONE_BRICKS.getDefaultState());
        structure.fillWithBlocks(world, start, 83, -40, 19, 83, -40, 19, Blocks.STONE_BRICKS.getDefaultState());
        structure.fillWithBlocks(world, start, 83, -40, 21, 83, -40, 21, Blocks.STONE_BRICKS.getDefaultState());
        structure.fillWithBlocks(world, start, 83, -40, 23, 83, -38, 23, Blocks.MOSSY_STONE_BRICKS.getDefaultState());
        structure.fillWithBlocks(world, start, 83, -39, 3, 84, -39, 4, Blocks.STONE_BRICKS.getDefaultState());
        structure.fillWithBlocks(world, start, 83, -39, 5, 83, -39, 6, Blocks.AIR.getDefaultState());
        structure.fillWithBlocks(world, start, 83, -39, 8, 83, -39, 8, Blocks.STONE_BRICKS.getDefaultState());
        structure.fillWithBlocks(world, start, 83, -39, 12, 83, -39, 13, Blocks.STONE_BRICKS.getDefaultState());
        structure.fillWithBlocks(world, start, 83, -39, 14, 83, -39, 14, Blocks.MOSSY_STONE_BRICKS.getDefaultState());
        structure.fillWithBlocks(world, start, 83, -39, 15, 83, -39, 16, Blocks.STONE_BRICKS.getDefaultState());
        structure.fillWithBlocks(world, start, 83, -39, 18, 83, -39, 18, Blocks.STONE_BRICKS.getDefaultState());
        structure.fillWithBlocks(world, start, 83, -39, 19, 83, -39, 19, Blocks.MOSSY_STONE_BRICKS.getDefaultState());
        structure.fillWithBlocks(world, start, 83, -39, 21, 83, -39, 22, Blocks.MOSSY_COBBLESTONE.getDefaultState());
        structure.fillWithBlocks(world, start, 83, -38, 3, 85, -37, 3, Blocks.STONE_BRICKS.getDefaultState());
        structure.fillWithBlocks(world, start, 83, -38, 5, 83, -38, 5, Blocks.AIR.getDefaultState());
        structure.fillWithBlocks(world, start, 83, -38, 6, 83, -37, 6, Blocks.STONE_BRICKS.getDefaultState());
        structure.fillWithBlocks(world, start, 83, -38, 7, 83, -38, 8, Blocks.MOSSY_COBBLESTONE.getDefaultState());
        structure.fillWithBlocks(world, start, 83, -38, 9, 84, -38, 10, Blocks.STONE_BRICKS.getDefaultState());
        structure.fillWithBlocks(world, start, 83, -38, 15, 83, -37, 15, Blocks.MOSSY_STONE_BRICKS.getDefaultState());
        structure.fillWithBlocks(world, start, 83, -38, 16, 83, -38, 16, Blocks.STONE_BRICKS.getDefaultState());
        structure.fillWithBlocks(world, start, 83, -38, 17, 83, -37, 17, Blocks.MOSSY_STONE_BRICKS.getDefaultState());
        structure.fillWithBlocks(world, start, 83, -38, 18, 84, -38, 19, Blocks.STONE_BRICKS.getDefaultState());
        structure.fillWithBlocks(world, start, 83, -38, 20, 83, -37, 20, Blocks.MOSSY_COBBLESTONE.getDefaultState());
        structure.fillWithBlocks(world, start, 83, -38, 21, 84, -38, 22, Blocks.STONE_BRICKS.getDefaultState());
        structure.fillWithBlocks(world, start, 83, -37, 4, 84, -37, 5, Blocks.STONE_BRICKS.getDefaultState());
        structure.fillWithBlocks(world, start, 83, -37, 7, 83, -37, 10, Blocks.MOSSY_STONE_BRICKS.getDefaultState());
        structure.fillWithBlocks(world, start, 83, -37, 11, 84, -37, 13, Blocks.STONE_BRICKS.getDefaultState());
        structure.fillWithBlocks(world, start, 83, -37, 14, 83, -37, 15, Blocks.MOSSY_STONE_BRICKS.getDefaultState());
        structure.fillWithBlocks(world, start, 83, -37, 16, 85, -37, 16, Blocks.STONE_BRICKS.getDefaultState());
        structure.fillWithBlocks(world, start, 83, -37, 18, 83, -37, 19, Blocks.STONE_BRICKS.getDefaultState());
        structure.fillWithBlocks(world, start, 83, -37, 21, 83, -37, 23, Blocks.STONE_BRICKS.getDefaultState());
        structure.fillWithBlocks(world, start, 83, -26, 29, 84, -26, 33, Blocks.STONE_BRICKS.getDefaultState());
        structure.fillWithBlocks(world, start, 83, -25, 28, 83, -23, 28, Blocks.STONE_BRICKS.getDefaultState());
        structure.fillWithBlocks(world, start, 83, -25, 29, 83, -25, 33, Blocks.AIR.getDefaultState());
        structure.fillWithBlocks(world, start, 83, -25, 34, 83, -23, 34, Blocks.STONE_BRICKS.getDefaultState());
        structure.fillWithBlocks(world, start, 83, -24, 29, 83, -24, 33, Blocks.AIR.getDefaultState());
        structure.fillWithBlocks(world, start, 83, -23, 29, 83, -23, 33, Blocks.AIR.getDefaultState());
        structure.fillWithBlocks(world, start, 83, -22, 29, 83, -22, 29, Blocks.STONE_BRICKS.getDefaultState());
        structure.fillWithBlocks(world, start, 83, -22, 31, 83, -22, 33, Blocks.STONE_BRICKS.getDefaultState());
        structure.fillWithBlocks(world, start, 83, -16, 24, 87, -16, 28, Blocks.STONE_BRICKS.getDefaultState());
        structure.fillWithBlocks(world, start, 83, -16, 36, 84, -16, 36, Blocks.MOSSY_STONE_BRICKS.getDefaultState());
        structure.fillWithBlocks(world, start, 83, -16, 37, 83, -15, 38, Blocks.STONE_BRICKS.getDefaultState());
        structure.fillWithBlocks(world, start, 83, -14, 37, 84, -14, 38, Blocks.STONE_BRICKS.getDefaultState());
        structure.fillWithBlocks(world, start, 83, -13, 24, 84, -13, 26, Blocks.STONE_BRICKS.getDefaultState());
        structure.fillWithBlocks(world, start, 83, -12, 31, 83, -12, 32, Blocks.MOSSY_STONE_BRICKS.getDefaultState());
        structure.fillWithBlocks(world, start, 83, -12, 33, 83, -11, 34, Blocks.STONE_BRICKS.getDefaultState());
        structure.fillWithBlocks(world, start, 83, -12, 35, 83, -12, 35, Blocks.STONE_BRICKS.getDefaultState());
        structure.fillWithBlocks(world, start, 83, -11, 26, 84, -11, 31, Blocks.STONE_BRICKS.getDefaultState());
        structure.fillWithBlocks(world, start, 83, -11, 32, 83, -11, 34, Blocks.STONE_BRICKS.getDefaultState());
        structure.fillWithBlocks(world, start, 83, -11, 36, 83, -9, 38, Blocks.STONE_BRICKS.getDefaultState());
        structure.fillWithBlocks(world, start, 83, -10, 24, 85, -10, 38, Blocks.STONE_BRICKS.getDefaultState());
        structure.fillWithBlocks(world, start, 83, -9, 24, 85, -9, 38, Blocks.STONE_BRICKS.getDefaultState());
        structure.fillWithBlocks(world, start, 83, -8, 27, 85, -8, 29, Blocks.STONE_BRICKS.getDefaultState());
        structure.fillWithBlocks(world, start, 83, -8, 31, 86, -8, 34, Blocks.STONE_BRICKS.getDefaultState());
        structure.fillWithBlocks(world, start, 83, -7, 24, 85, -7, 36, Blocks.STONE_BRICKS.getDefaultState());
