package mod.arcalitegames.odyssey.world.structure.structures.ruins.castle_ruins;

import mod.arcalitegames.odyssey.world.structure.StructureBase;
import net.minecraft.block.Blocks;
import net.minecraft.block.WallBlock;
import net.minecraft.block.WallHeight;
import net.minecraft.util.math.BlockPos;
import net.minecraft.world.World;

public class CastleComponent3
{

	public static BlockPos start;
    public static World world;
    public static StructureBase structure;

    public static void init(World worldIn, BlockPos blockPos, StructureBase structureIn)
    {
        world = worldIn; start = blockPos; structure = structureIn;
    }
    
    public static void generatePart31()
    {
        structure.fillWithBlocks(world, start, -26, -23, 56, -26, -22, 58, Blocks.STONE_BRICKS.getDefaultState());
        structure.fillWithBlocks(world, start, -26, -23, 59, -25, -23, 60, Blocks.AIR.getDefaultState());
        structure.fillWithBlocks(world, start, -26, -23, 61, -26, -17, 61, Blocks.STONE_BRICKS.getDefaultState());
        structure.fillWithBlocks(world, start, -26, -23, 62, -24, -23, 64, Blocks.AIR.getDefaultState());
        structure.fillWithBlocks(world, start, -26, -23, 66, -25, -23, 67, Blocks.AIR.getDefaultState());
        structure.fillWithBlocks(world, start, -26, -23, 69, -24, -21, 69, Blocks.STONE_BRICKS.getDefaultState());
        structure.fillWithBlocks(world, start, -26, -23, 74, -26, -23, 74, Blocks.CRACKED_STONE_BRICKS.getDefaultState());
        structure.fillWithBlocks(world, start, -26, -23, 75, -26, -23, 76, Blocks.STONE_BRICKS.getDefaultState());
        structure.fillWithBlocks(world, start, -26, -23, 77, -25, -23, 78, Blocks.AIR.getDefaultState());
        structure.fillWithBlocks(world, start, -26, -23, 80, -24, -23, 82, Blocks.AIR.getDefaultState());
        structure.fillWithBlocks(world, start, -26, -23, 84, -25, -23, 85, Blocks.AIR.getDefaultState());
        structure.fillWithBlocks(world, start, -26, -23, 87, -26, -23, 88, Blocks.STONE_BRICKS.getDefaultState());
        structure.fillWithBlocks(world, start, -26, -22, -6, -26, -22, -5, Blocks.STONE_BRICKS.getDefaultState());
        structure.fillWithBlocks(world, start, -26, -22, -4, -25, -22, 6, Blocks.AIR.getDefaultState());
        structure.fillWithBlocks(world, start, -26, -22, 8, -24, -21, 8, Blocks.STONE_BRICKS.getDefaultState());
        structure.fillWithBlocks(world, start, -26, -22, 29, -25, -22, 30, Blocks.STONE_BRICKS.getDefaultState());
        structure.fillWithBlocks(world, start, -26, -22, 31, -26, -22, 32, Blocks.STONE_BRICKS.getDefaultState());
        structure.fillWithBlocks(world, start, -26, -22, 59, -25, -22, 60, Blocks.AIR.getDefaultState());
        structure.fillWithBlocks(world, start, -26, -22, 62, -24, -22, 64, Blocks.AIR.getDefaultState());
        structure.fillWithBlocks(world, start, -26, -22, 66, -25, -22, 67, Blocks.AIR.getDefaultState());
        structure.fillWithBlocks(world, start, -26, -22, 70, -25, -22, 70, Blocks.CRACKED_STONE_BRICKS.getDefaultState());
        structure.fillWithBlocks(world, start, -26, -22, 74, -26, -22, 74, Blocks.STONE_BRICKS.getDefaultState());
        structure.fillWithBlocks(world, start, -26, -22, 77, -25, -22, 78, Blocks.AIR.getDefaultState());
        structure.fillWithBlocks(world, start, -26, -22, 80, -24, -22, 82, Blocks.AIR.getDefaultState());
        structure.fillWithBlocks(world, start, -26, -22, 84, -25, -22, 85, Blocks.AIR.getDefaultState());
        structure.fillWithBlocks(world, start, -26, -22, 87, -26, -21, 87, Blocks.CRACKED_STONE_BRICKS.getDefaultState());
        structure.fillWithBlocks(world, start, -26, -22, 88, -25, -21, 88, Blocks.STONE_BRICKS.getDefaultState());
        structure.fillWithBlocks(world, start, -26, -21, -6, -26, -20, -6, Blocks.STONE_BRICKS.getDefaultState());
        structure.fillWithBlocks(world, start, -26, -21, -5, -26, -20, -5, Blocks.MOSSY_STONE_BRICKS.getDefaultState());
        structure.fillWithBlocks(world, start, -26, -21, -3, -26, -21, 2, Blocks.STONE_BRICKS.getDefaultState());
        structure.fillWithBlocks(world, start, -26, -21, 3, -26, -20, 3, Blocks.MOSSY_STONE_BRICKS.getDefaultState());
        structure.fillWithBlocks(world, start, -26, -21, 4, -26, -21, 5, Blocks.CRACKED_STONE_BRICKS.getDefaultState());
        structure.fillWithBlocks(world, start, -26, -21, 7, -26, -21, 8, Blocks.STONE_BRICKS.getDefaultState());
        structure.fillWithBlocks(world, start, -26, -21, 56, -25, -21, 57, Blocks.STONE_BRICKS.getDefaultState());
        structure.fillWithBlocks(world, start, -26, -21, 59, -26, -21, 59, Blocks.CRACKED_STONE_BRICKS.getDefaultState());
        structure.fillWithBlocks(world, start, -26, -21, 60, -26, -21, 61, Blocks.STONE_BRICKS.getDefaultState());
        structure.fillWithBlocks(world, start, -26, -21, 63, -25, -21, 63, Blocks.STONE_BRICKS.getDefaultState());
        structure.fillWithBlocks(world, start, -26, -21, 64, -25, -21, 64, Blocks.CRACKED_STONE_BRICKS.getDefaultState());
        structure.fillWithBlocks(world, start, -26, -21, 66, -26, -21, 66, Blocks.STONE_BRICKS.getDefaultState());
        structure.fillWithBlocks(world, start, -26, -21, 67, -26, -21, 68, Blocks.CRACKED_STONE_BRICKS.getDefaultState());
        structure.fillWithBlocks(world, start, -26, -21, 75, -26, -21, 75, Blocks.STONE_BRICKS.getDefaultState());
        structure.fillWithBlocks(world, start, -26, -21, 76, -26, -20, 76, Blocks.CRACKED_STONE_BRICKS.getDefaultState());
        structure.fillWithBlocks(world, start, -26, -21, 77, -26, -20, 78, Blocks.STONE_BRICKS.getDefaultState());
        structure.fillWithBlocks(world, start, -26, -21, 80, -25, -21, 81, Blocks.STONE_BRICKS.getDefaultState());
        structure.fillWithBlocks(world, start, -26, -21, 84, -25, -21, 86, Blocks.STONE_BRICKS.getDefaultState());
        structure.fillWithBlocks(world, start, -26, -20, -4, -26, -17, -4, Blocks.STONE_BRICKS.getDefaultState());
        structure.fillWithBlocks(world, start, -26, -20, -3, -26, -19, -3, Blocks.CRACKED_STONE_BRICKS.getDefaultState());
        structure.fillWithBlocks(world, start, -26, -20, -2, -26, -20, -1, Blocks.STONE_BRICKS.getDefaultState());
        structure.fillWithBlocks(world, start, -26, -20, 1, -26, -20, 2, Blocks.STONE_BRICKS.getDefaultState());
        structure.fillWithBlocks(world, start, -26, -20, 4, -26, -20, 4, Blocks.STONE_BRICKS.getDefaultState());
        structure.fillWithBlocks(world, start, -26, -20, 57, -26, -20, 57, Blocks.STONE_BRICKS.getDefaultState());
        structure.fillWithBlocks(world, start, -26, -20, 59, -26, -20, 61, Blocks.STONE_BRICKS.getDefaultState());
        structure.fillWithBlocks(world, start, -26, -20, 62, -26, -20, 62, Blocks.CRACKED_STONE_BRICKS.getDefaultState());
        structure.fillWithBlocks(world, start, -26, -20, 63, -26, -20, 65, Blocks.STONE_BRICKS.getDefaultState());
        structure.fillWithBlocks(world, start, -26, -20, 67, -26, -19, 67, Blocks.STONE_BRICKS.getDefaultState());
        structure.fillWithBlocks(world, start, -26, -20, 68, -26, -20, 70, Blocks.CRACKED_STONE_BRICKS.getDefaultState());
        structure.fillWithBlocks(world, start, -26, -20, 75, -26, -17, 75, Blocks.STONE_BRICKS.getDefaultState());
        structure.fillWithBlocks(world, start, -26, -20, 79, -26, -17, 79, Blocks.STONE_BRICKS.getDefaultState());
        structure.fillWithBlocks(world, start, -26, -20, 80, -26, -20, 80, Blocks.CRACKED_STONE_BRICKS.getDefaultState());
        structure.fillWithBlocks(world, start, -26, -20, 82, -26, -19, 82, Blocks.STONE_BRICKS.getDefaultState());
        structure.fillWithBlocks(world, start, -26, -20, 83, -25, -20, 83, Blocks.MOSSY_STONE_BRICKS.getDefaultState());
        structure.fillWithBlocks(world, start, -26, -20, 84, -26, -20, 84, Blocks.STONE_BRICKS.getDefaultState());
        structure.fillWithBlocks(world, start, -26, -20, 85, -26, -20, 87, Blocks.MOSSY_STONE_BRICKS.getDefaultState());
        structure.fillWithBlocks(world, start, -26, -20, 88, -24, -20, 88, Blocks.CRACKED_STONE_BRICKS.getDefaultState());
        structure.fillWithBlocks(world, start, -26, -19, -5, -26, -18, -4, Blocks.STONE_BRICKS.getDefaultState());
        structure.fillWithBlocks(world, start, -26, -19, -2, -26, -19, -2, Blocks.STONE_BRICKS.getDefaultState());
        structure.fillWithBlocks(world, start, -26, -19, -1, -26, -18, -1, Blocks.CRACKED_STONE_BRICKS.getDefaultState());
        structure.fillWithBlocks(world, start, -26, -19, 0, -25, -19, 2, Blocks.STONE_BRICKS.getDefaultState());
        structure.fillWithBlocks(world, start, -26, -19, 3, -26, -19, 3, Blocks.CRACKED_STONE_BRICKS.getDefaultState());
        structure.fillWithBlocks(world, start, -26, -19, 4, -26, -19, 5, Blocks.STONE_BRICKS.getDefaultState());
        structure.fillWithBlocks(world, start, -26, -19, 8, -25, -19, 8, Blocks.STONE_BRICKS.getDefaultState());
        structure.fillWithBlocks(world, start, -26, -19, 56, -26, -19, 58, Blocks.STONE_BRICKS.getDefaultState());
        structure.fillWithBlocks(world, start, -26, -19, 59, -26, -18, 59, Blocks.CRACKED_STONE_BRICKS.getDefaultState());
        structure.fillWithBlocks(world, start, -26, -19, 62, -25, -19, 63, Blocks.STONE_BRICKS.getDefaultState());
        structure.fillWithBlocks(world, start, -26, -19, 64, -26, -18, 64, Blocks.STONE_BRICKS.getDefaultState());
        structure.fillWithBlocks(world, start, -26, -19, 66, -24, -19, 68, Blocks.STONE_BRICKS.getDefaultState());
        structure.fillWithBlocks(world, start, -26, -19, 69, -25, -19, 70, Blocks.STONE_BRICKS.getDefaultState());
        structure.fillWithBlocks(world, start, -26, -19, 74, -26, -18, 75, Blocks.STONE_BRICKS.getDefaultState());
        structure.fillWithBlocks(world, start, -26, -19, 77, -26, -19, 77, Blocks.STONE_BRICKS.getDefaultState());
        structure.fillWithBlocks(world, start, -26, -19, 80, -26, -19, 80, Blocks.MOSSY_STONE_BRICKS.getDefaultState());
        structure.fillWithBlocks(world, start, -26, -19, 81, -26, -19, 83, Blocks.STONE_BRICKS.getDefaultState());
        structure.fillWithBlocks(world, start, -26, -19, 84, -26, -19, 87, Blocks.CRACKED_STONE_BRICKS.getDefaultState());
        structure.fillWithBlocks(world, start, -26, -19, 88, -25, -19, 88, Blocks.STONE_BRICKS.getDefaultState());
        structure.fillWithBlocks(world, start, -26, -18, -6, -26, -18, -3, Blocks.STONE_BRICKS.getDefaultState());
        structure.fillWithBlocks(world, start, -26, -18, -2, -26, -18, -1, Blocks.CRACKED_STONE_BRICKS.getDefaultState());
        structure.fillWithBlocks(world, start, -26, -18, 0, -26, -18, 0, Blocks.STONE_BRICKS.getDefaultState());
        structure.fillWithBlocks(world, start, -26, -18, 4, -26, -18, 4, Blocks.CRACKED_STONE_BRICKS.getDefaultState());
        structure.fillWithBlocks(world, start, -26, -18, 5, -26, -18, 6, Blocks.MOSSY_STONE_BRICKS.getDefaultState());
        structure.fillWithBlocks(world, start, -26, -18, 56, -26, -17, 56, Blocks.MOSSY_STONE_BRICKS.getDefaultState());
        structure.fillWithBlocks(world, start, -26, -18, 57, -25, -18, 58, Blocks.STONE_BRICKS.getDefaultState());
        structure.fillWithBlocks(world, start, -26, -18, 60, -26, -17, 61, Blocks.STONE_BRICKS.getDefaultState());
        structure.fillWithBlocks(world, start, -26, -18, 62, -26, -18, 65, Blocks.STONE_BRICKS.getDefaultState());
        structure.fillWithBlocks(world, start, -26, -18, 66, -26, -18, 69, Blocks.MOSSY_STONE_BRICKS.getDefaultState());
        structure.fillWithBlocks(world, start, -26, -18, 76, -26, -18, 76, Blocks.CRACKED_STONE_BRICKS.getDefaultState());
        structure.fillWithBlocks(world, start, -26, -18, 78, -25, -18, 78, Blocks.CRACKED_STONE_BRICKS.getDefaultState());
        structure.fillWithBlocks(world, start, -26, -18, 80, -26, -18, 80, Blocks.STONE_BRICKS.getDefaultState());
        structure.fillWithBlocks(world, start, -26, -18, 81, -26, -18, 81, Blocks.MOSSY_STONE_BRICKS.getDefaultState());
        structure.fillWithBlocks(world, start, -26, -18, 82, -26, -17, 82, Blocks.CRACKED_STONE_BRICKS.getDefaultState());
        structure.fillWithBlocks(world, start, -26, -18, 83, -26, -17, 84, Blocks.STONE_BRICKS.getDefaultState());
        structure.fillWithBlocks(world, start, -26, -18, 85, -25, -18, 85, Blocks.MOSSY_STONE_BRICKS.getDefaultState());
        structure.fillWithBlocks(world, start, -26, -18, 88, -25, -18, 88, Blocks.CRACKED_STONE_BRICKS.getDefaultState());
        structure.fillWithBlocks(world, start, -26, -17, -6, -26, -17, -6, Blocks.STONE_BRICKS.getDefaultState());
        structure.fillWithBlocks(world, start, -26, -17, -5, -26, -17, -5, Blocks.CRACKED_STONE_BRICKS.getDefaultState());
        structure.fillWithBlocks(world, start, -26, -17, -3, -26, -17, 2, Blocks.STONE_BRICKS.getDefaultState());
        structure.fillWithBlocks(world, start, -26, -17, 4, -25, -17, 6, Blocks.STONE_BRICKS.getDefaultState());
        structure.fillWithBlocks(world, start, -26, -17, 7, -26, -17, 8, Blocks.MOSSY_STONE_BRICKS.getDefaultState());
        structure.fillWithBlocks(world, start, -26, -17, 29, -26, -16, 29, Blocks.STONE_BRICKS.getDefaultState());
        structure.fillWithBlocks(world, start, -26, -17, 31, -26, -16, 33, Blocks.STONE_BRICKS.getDefaultState());
        structure.fillWithBlocks(world, start, -26, -17, 57, -25, -17, 58, Blocks.STONE_BRICKS.getDefaultState());
        structure.fillWithBlocks(world, start, -26, -17, 59, -26, -17, 61, Blocks.STONE_BRICKS.getDefaultState());
        structure.fillWithBlocks(world, start, -26, -17, 65, -23, -17, 65, Blocks.STONE_BRICKS.getDefaultState());
        structure.fillWithBlocks(world, start, -26, -17, 66, -25, -17, 66, Blocks.CRACKED_STONE_BRICKS.getDefaultState());
        structure.fillWithBlocks(world, start, -26, -17, 67, -26, -17, 68, Blocks.STONE_BRICKS.getDefaultState());
        structure.fillWithBlocks(world, start, -26, -17, 69, -26, -17, 69, Blocks.CRACKED_STONE_BRICKS.getDefaultState());
        structure.fillWithBlocks(world, start, -26, -17, 74, -26, -17, 77, Blocks.STONE_BRICKS.getDefaultState());
        structure.fillWithBlocks(world, start, -26, -17, 81, -23, -17, 81, Blocks.STONE_BRICKS.getDefaultState());
        structure.fillWithBlocks(world, start, -26, -17, 87, -26, -17, 88, Blocks.STONE_BRICKS.getDefaultState());
        structure.fillWithBlocks(world, start, -26, -15, 24, -25, -15, 25, Blocks.STONE_BRICKS.getDefaultState());
        structure.fillWithBlocks(world, start, -26, -15, 26, -26, -15, 36, Blocks.AIR.getDefaultState());
        structure.fillWithBlocks(world, start, -26, -15, 37, -25, -15, 38, Blocks.STONE_BRICKS.getDefaultState());
        structure.fillWithBlocks(world, start, -26, -14, 26, -24, -14, 30, Blocks.AIR.getDefaultState());
        structure.fillWithBlocks(world, start, -26, -14, 36, -24, -12, 36, Blocks.AIR.getDefaultState());
        structure.fillWithBlocks(world, start, -26, -14, 37, -26, -7, 37, Blocks.STONE_BRICKS.getDefaultState());
        structure.fillWithBlocks(world, start, -26, -13, 26, -24, -13, 36, Blocks.AIR.getDefaultState());
        structure.fillWithBlocks(world, start, -26, -13, 38, -22, -9, 38, Blocks.STONE_BRICKS.getDefaultState());
        structure.fillWithBlocks(world, start, -26, -12, 26, -24, -12, 36, Blocks.AIR.getDefaultState());
        structure.fillWithBlocks(world, start, -26, -11, 24, -25, -11, 25, Blocks.STONE_BRICKS.getDefaultState());
        structure.fillWithBlocks(world, start, -26, -11, 27, -18, -10, 27, Blocks.STONE_BRICKS.getDefaultState());
        structure.fillWithBlocks(world, start, -26, -10, 24, -22, -10, 28, Blocks.STONE_BRICKS.getDefaultState());
        structure.fillWithBlocks(world, start, -26, -9, 29, -26, -8, 29, Blocks.MOSSY_STONE_BRICKS.getDefaultState());
        structure.fillWithBlocks(world, start, -26, -9, 34, -25, -9, 38, Blocks.STONE_BRICKS.getDefaultState());
        structure.fillWithBlocks(world, start, -26, -8, 28, -26, -7, 28, Blocks.STONE_BRICKS.getDefaultState());
        structure.fillWithBlocks(world, start, -26, -8, 30, -23, -8, 33, Blocks.STONE_BRICKS.getDefaultState());
        structure.fillWithBlocks(world, start, -26, -8, 35, -23, -8, 38, Blocks.STONE_BRICKS.getDefaultState());
        structure.fillWithBlocks(world, start, -26, -7, 27, -26, -7, 31, Blocks.STONE_BRICKS.getDefaultState());
        structure.fillWithBlocks(world, start, -26, -7, 32, -26, -7, 33, Blocks.MOSSY_STONE_BRICKS.getDefaultState());
        structure.fillWithBlocks(world, start, -26, -7, 34, -25, -7, 38, Blocks.STONE_BRICKS.getDefaultState());
        structure.fillWithBlocks(world, start, -25, -56, -11, -23, -56, -9, Blocks.STONE_BRICKS.getDefaultState());
        structure.fillWithBlocks(world, start, -25, -56, 6, -25, -55, 6, Blocks.AIR.getDefaultState());
        structure.fillWithBlocks(world, start, -25, -56, 7, -23, -56, 9, Blocks.STONE_BRICKS.getDefaultState());
        structure.fillWithBlocks(world, start, -25, -55, -15, -24, -55, -14, Blocks.STONE_BRICKS.getDefaultState());
        structure.fillWithBlocks(world, start, -25, -55, -12, -24, -55, -4, Blocks.STONE_BRICKS.getDefaultState());
        structure.fillWithBlocks(world, start, -25, -55, 7, -25, -55, 9, Blocks.STONE_BRICKS.getDefaultState());
        structure.fillWithBlocks(world, start, -25, -54, -4, -23, -54, 8, Blocks.STONE_BRICKS.getDefaultState());
        structure.fillWithBlocks(world, start, -25, -53, -10, -22, -53, -6, Blocks.STONE_BRICKS.getDefaultState());
        structure.fillWithBlocks(world, start, -25, -53, -5, -24, -53, 4, Blocks.STONE_BRICKS.getDefaultState());
        structure.fillWithBlocks(world, start, -25, -53, 6, -22, -53, 9, Blocks.STONE_BRICKS.getDefaultState());
        structure.fillWithBlocks(world, start, -25, -52, 8, -25, -51, 9, Blocks.STONE_BRICKS.getDefaultState());
        structure.fillWithBlocks(world, start, -25, -51, -8, -24, -51, -4, Blocks.STONE_BRICKS.getDefaultState());
        structure.fillWithBlocks(world, start, -25, -50, -15, -24, -50, -5, Blocks.STONE_BRICKS.getDefaultState());
        structure.fillWithBlocks(world, start, -25, -50, 1, -22, -50, 9, Blocks.STONE_BRICKS.getDefaultState());
        structure.fillWithBlocks(world, start, -25, -49, -11, -24, -49, -10, Blocks.STONE_BRICKS.getDefaultState());
        structure.fillWithBlocks(world, start, -25, -49, -8, -25, -48, -7, Blocks.STONE_BRICKS.getDefaultState());
        structure.fillWithBlocks(world, start, -25, -48, -5, -23, -48, -3, Blocks.STONE_BRICKS.getDefaultState());
        structure.fillWithBlocks(world, start, -25, -48, -2, -25, -48, 9, Blocks.STONE_BRICKS.getDefaultState());
        structure.fillWithBlocks(world, start, -25, -47, -3, -25, -47, -3, Blocks.STONE_BRICKS.getDefaultState());
        structure.fillWithBlocks(world, start, -25, -47, -1, -25, -47, -1, Blocks.STONE_BRICKS.getDefaultState());
        structure.fillWithBlocks(world, start, -25, -47, 0, -25, -47, 4, Blocks.AIR.getDefaultState());
        structure.fillWithBlocks(world, start, -25, -47, 5, -23, -47, 9, Blocks.STONE_BRICKS.getDefaultState());
        structure.fillWithBlocks(world, start, -25, -46, -2, -25, -46, -2, Blocks.STONE_BRICKS.getDefaultState());
        structure.fillWithBlocks(world, start, -25, -46, 0, -25, -46, 0, Blocks.MOSSY_COBBLESTONE.getDefaultState());
        structure.fillWithBlocks(world, start, -25, -46, 3, -25, -46, 5, Blocks.STONE_BRICKS.getDefaultState());
        structure.fillWithBlocks(world, start, -25, -45, -2, -25, -45, -2, Blocks.STONE_BRICKS.getDefaultState());
        structure.fillWithBlocks(world, start, -25, -45, -1, -25, -45, 3, Blocks.AIR.getDefaultState());
        structure.fillWithBlocks(world, start, -25, -45, 4, -25, -44, 5, Blocks.STONE_BRICKS.getDefaultState());
        structure.fillWithBlocks(world, start, -25, -44, -3, -24, -44, -2, Blocks.STONE_BRICKS.getDefaultState());
        structure.fillWithBlocks(world, start, -25, -44, -1, -25, -44, 3, Blocks.AIR.getDefaultState());
        structure.fillWithBlocks(world, start, -25, -43, -3, -25, -42, -2, Blocks.STONE_BRICKS.getDefaultState());
        structure.fillWithBlocks(world, start, -25, -43, 4, -25, -43, 5, Blocks.STONE_BRICKS.getDefaultState());
        structure.fillWithBlocks(world, start, -25, -42, -1, -24, -42, 0, Blocks.STONE_BRICKS.getDefaultState());
        structure.fillWithBlocks(world, start, -25, -42, 2, -25, -42, 3, Blocks.STONE_BRICKS.getDefaultState());
        structure.fillWithBlocks(world, start, -25, -42, 5, -25, -42, 5, Blocks.STONE_BRICKS.getDefaultState());
        structure.fillWithBlocks(world, start, -25, -41, -2, -25, -41, -1, Blocks.AIR.getDefaultState());
        structure.fillWithBlocks(world, start, -25, -41, 0, -23, -41, 0, Blocks.MOSSY_STONE_BRICKS.getDefaultState());
        structure.fillWithBlocks(world, start, -25, -41, 1, -25, -37, 1, Blocks.STONE_BRICKS.getDefaultState());
        structure.fillWithBlocks(world, start, -25, -41, 3, -25, -41, 5, Blocks.STONE_BRICKS.getDefaultState());
        structure.fillWithBlocks(world, start, -25, -40, -3, -25, -38, -3, Blocks.MOSSY_STONE_BRICKS.getDefaultState());
        structure.fillWithBlocks(world, start, -25, -40, -2, -25, -39, -1, Blocks.STONE_BRICKS.getDefaultState());
        structure.fillWithBlocks(world, start, -25, -40, 3, -24, -40, 5, Blocks.STONE_BRICKS.getDefaultState());
        structure.fillWithBlocks(world, start, -25, -39, 2, -24, -39, 3, Blocks.STONE_BRICKS.getDefaultState());
        structure.fillWithBlocks(world, start, -25, -39, 4, -25, -39, 5, Blocks.MOSSY_COBBLESTONE.getDefaultState());
        structure.fillWithBlocks(world, start, -25, -38, -2, -25, -37, -2, Blocks.INFESTED_COBBLESTONE.getDefaultState());
        structure.fillWithBlocks(world, start, -25, -38, -1, -25, -38, 1, Blocks.STONE_BRICKS.getDefaultState());
        structure.fillWithBlocks(world, start, -25, -38, 2, -24, -38, 2, Blocks.MOSSY_STONE_BRICKS.getDefaultState());
        structure.fillWithBlocks(world, start, -25, -37, -3, -25, -37, -3, Blocks.STONE_BRICKS.getDefaultState());
        structure.fillWithBlocks(world, start, -25, -37, -1, -25, -37, -1, Blocks.MOSSY_STONE_BRICKS.getDefaultState());
        structure.fillWithBlocks(world, start, -25, -37, 3, -25, -37, 3, Blocks.STONE_BRICKS.getDefaultState());
        structure.fillWithBlocks(world, start, -25, -37, 5, -25, -37, 5, Blocks.STONE_BRICKS.getDefaultState());
        structure.fillWithBlocks(world, start, -25, -36, 10, -25, -36, 12, Blocks.STONE_BRICKS.getDefaultState());
        structure.fillWithBlocks(world, start, -25, -36, 13, -24, -36, 13, Blocks.MOSSY_STONE_BRICKS.getDefaultState());
        structure.fillWithBlocks(world, start, -25, -36, 14, -25, -36, 16, Blocks.STONE_BRICKS.getDefaultState());
        structure.fillWithBlocks(world, start, -25, -36, 18, -24, -36, 20, Blocks.STONE_BRICKS.getDefaultState());
        structure.fillWithBlocks(world, start, -25, -36, 21, -25, -36, 24, Blocks.STONE_BRICKS.getDefaultState());
        structure.fillWithBlocks(world, start, -25, -36, 25, -23, -36, 25, Blocks.MOSSY_STONE_BRICKS.getDefaultState());
        structure.fillWithBlocks(world, start, -25, -36, 26, -24, -35, 26, Blocks.STONE_BRICKS.getDefaultState());
        structure.fillWithBlocks(world, start, -25, -35, -43, -25, -35, -42, Blocks.MOSSY_STONE_BRICKS.getDefaultState());
        structure.fillWithBlocks(world, start, -25, -35, -41, -24, -35, -25, Blocks.AIR.getDefaultState());
        structure.fillWithBlocks(world, start, -25, -35, -24, -24, -35, -24, Blocks.MOSSY_STONE_BRICKS.getDefaultState());
        structure.fillWithBlocks(world, start, -25, -35, -23, -14, -35, -23, Blocks.STONE_BRICKS.getDefaultState());
        structure.fillWithBlocks(world, start, -25, -35, 10, -23, -34, 10, Blocks.STONE_BRICKS.getDefaultState());
        structure.fillWithBlocks(world, start, -25, -35, 11, -24, -35, 11, Blocks.MOSSY_STONE_BRICKS.getDefaultState());
        structure.fillWithBlocks(world, start, -25, -35, 14, -25, -33, 16, Blocks.STONE_BRICKS.getDefaultState());
        structure.fillWithBlocks(world, start, -25, -35, 17, -25, -34, 17, Blocks.STONE_BRICKS.getDefaultState());
        structure.fillWithBlocks(world, start, -25, -35, 19, -25, -33, 21, Blocks.STONE_BRICKS.getDefaultState());
        structure.fillWithBlocks(world, start, -25, -35, 23, -25, -35, 26, Blocks.STONE_BRICKS.getDefaultState());
        structure.fillWithBlocks(world, start, -25, -34, -43, -25, -34, -43, Blocks.MOSSY_STONE_BRICKS.getDefaultState());
        structure.fillWithBlocks(world, start, -25, -34, -41, -9, -34, -25, Blocks.AIR.getDefaultState());
        structure.fillWithBlocks(world, start, -25, -34, -24, -25, -34, -23, Blocks.STONE_BRICKS.getDefaultState());
        structure.fillWithBlocks(world, start, -25, -34, 11, -25, -33, 16, Blocks.STONE_BRICKS.getDefaultState());
        structure.fillWithBlocks(world, start, -25, -34, 18, -25, -34, 23, Blocks.STONE_BRICKS.getDefaultState());
        structure.fillWithBlocks(world, start, -25, -34, 25, -24, -34, 25, Blocks.STONE_BRICKS.getDefaultState());
        structure.fillWithBlocks(world, start, -25, -34, 26, -24, -34, 26, Blocks.MOSSY_STONE_BRICKS.getDefaultState());
        structure.fillWithBlocks(world, start, -25, -33, -43, -25, -33, -43, Blocks.STONE_BRICKS.getDefaultState());
        structure.fillWithBlocks(world, start, -25, -33, -42, -25, -32, -42, Blocks.MOSSY_STONE_BRICKS.getDefaultState());
        structure.fillWithBlocks(world, start, -25, -33, -41, -9, -33, -25, Blocks.AIR.getDefaultState());
        structure.fillWithBlocks(world, start, -25, -33, -24, -25, -33, -24, Blocks.STONE_BRICKS.getDefaultState());
        structure.fillWithBlocks(world, start, -25, -33, 17, -25, -33, 18, Blocks.MOSSY_STONE_BRICKS.getDefaultState());
        structure.fillWithBlocks(world, start, -25, -33, 22, -25, -32, 22, Blocks.CRACKED_STONE_BRICKS.getDefaultState());
        structure.fillWithBlocks(world, start, -25, -33, 23, -25, -33, 26, Blocks.STONE_BRICKS.getDefaultState());
        structure.fillWithBlocks(world, start, -25, -32, -43, -24, -32, -43, Blocks.STONE_BRICKS.getDefaultState());
        structure.fillWithBlocks(world, start, -25, -32, -41, -9, -32, -25, Blocks.AIR.getDefaultState());
        structure.fillWithBlocks(world, start, -25, -32, -24, -24, -32, -23, Blocks.STONE_BRICKS.getDefaultState());
        structure.fillWithBlocks(world, start, -25, -32, 14, -25, -32, 16, Blocks.STONE_BRICKS.getDefaultState());
        structure.fillWithBlocks(world, start, -25, -32, 18, -25, -29, 18, Blocks.STONE_BRICKS.getDefaultState());
        structure.fillWithBlocks(world, start, -25, -32, 20, -25, -32, 21, Blocks.STONE_BRICKS.getDefaultState());
        structure.fillWithBlocks(world, start, -25, -32, 23, -25, -29, 23, Blocks.STONE_BRICKS.getDefaultState());
        structure.fillWithBlocks(world, start, -25, -32, 24, -25, -32, 24, Blocks.MOSSY_STONE_BRICKS.getDefaultState());
        structure.fillWithBlocks(world, start, -25, -32, 25, -25, -32, 26, Blocks.STONE_BRICKS.getDefaultState());
        structure.fillWithBlocks(world, start, -25, -31, -41, -9, -31, -25, Blocks.AIR.getDefaultState());
        structure.fillWithBlocks(world, start, -25, -31, -24, -25, -30, -24, Blocks.MOSSY_STONE_BRICKS.getDefaultState());
        structure.fillWithBlocks(world, start, -25, -31, -23, -23, -31, -23, Blocks.STONE_BRICKS.getDefaultState());
        structure.fillWithBlocks(world, start, -25, -31, 10, -25, -31, 10, Blocks.STONE_BRICKS.getDefaultState());
        structure.fillWithBlocks(world, start, -25, -31, 12, -25, -30, 12, Blocks.MOSSY_STONE_BRICKS.getDefaultState());
        structure.fillWithBlocks(world, start, -25, -31, 13, -24, -31, 14, Blocks.STONE_BRICKS.getDefaultState());
        structure.fillWithBlocks(world, start, -25, -31, 15, -25, -31, 20, Blocks.STONE_BRICKS.getDefaultState());
        structure.fillWithBlocks(world, start, -25, -31, 22, -24, -31, 25, Blocks.STONE_BRICKS.getDefaultState());
        structure.fillWithBlocks(world, start, -25, -30, -39, -25, -30, -39, Blocks.STONE_BRICKS.getDefaultState());
        structure.fillWithBlocks(world, start, -25, -30, -37, -25, -30, -36, Blocks.STONE_BRICKS.getDefaultState());
        structure.fillWithBlocks(world, start, -25, -30, -35, -25, -29, -35, Blocks.MOSSY_STONE_BRICKS.getDefaultState());
        structure.fillWithBlocks(world, start, -25, -30, -34, -25, -30, -34, Blocks.STONE_BRICKS.getDefaultState());
        structure.fillWithBlocks(world, start, -25, -30, -33, -25, -30, -30, Blocks.MOSSY_STONE_BRICKS.getDefaultState());
        structure.fillWithBlocks(world, start, -25, -30, -29, -25, -30, -29, Blocks.STONE_BRICKS.getDefaultState());
        structure.fillWithBlocks(world, start, -25, -30, -27, -25, -29, -27, Blocks.CRACKED_STONE_BRICKS.getDefaultState());
        structure.fillWithBlocks(world, start, -25, -30, -25, -25, -30, -23, Blocks.MOSSY_STONE_BRICKS.getDefaultState());
        structure.fillWithBlocks(world, start, -25, -30, 10, -24, -30, 10, Blocks.MOSSY_STONE_BRICKS.getDefaultState());
        structure.fillWithBlocks(world, start, -25, -30, 11, -20, -30, 11, Blocks.STONE_BRICKS.getDefaultState());
        structure.fillWithBlocks(world, start, -25, -30, 13, -24, -29, 13, Blocks.STONE_BRICKS.getDefaultState());
        structure.fillWithBlocks(world, start, -25, -30, 14, -25, -29, 15, Blocks.MOSSY_STONE_BRICKS.getDefaultState());
        structure.fillWithBlocks(world, start, -25, -30, 16, -25, -29, 16, Blocks.STONE_BRICKS.getDefaultState());
        structure.fillWithBlocks(world, start, -25, -30, 20, -24, -30, 21, Blocks.STONE_BRICKS.getDefaultState());
        structure.fillWithBlocks(world, start, -25, -30, 24, -25, -30, 24, Blocks.MOSSY_STONE_BRICKS.getDefaultState());
        structure.fillWithBlocks(world, start, -25, -30, 25, -25, -30, 26, Blocks.STONE_BRICKS.getDefaultState());
        structure.fillWithBlocks(world, start, -25, -29, -43, -23, -29, -40, Blocks.STONE_BRICKS.getDefaultState());
        structure.fillWithBlocks(world, start, -25, -29, -38, -24, -29, -37, Blocks.STONE_BRICKS.getDefaultState());
        structure.fillWithBlocks(world, start, -25, -29, -36, -25, -29, -35, Blocks.MOSSY_STONE_BRICKS.getDefaultState());
        structure.fillWithBlocks(world, start, -25, -29, -34, -25, -28, -33, Blocks.STONE_BRICKS.getDefaultState());
        structure.fillWithBlocks(world, start, -25, -29, -32, -25, -29, -30, Blocks.STONE_BRICKS.getDefaultState());
        structure.fillWithBlocks(world, start, -25, -29, -28, -25, -27, -28, Blocks.STONE_BRICKS.getDefaultState());
        structure.fillWithBlocks(world, start, -25, -29, -25, -24, -29, -23, Blocks.STONE_BRICKS.getDefaultState());
        structure.fillWithBlocks(world, start, -25, -29, 10, -25, -27, 10, Blocks.STONE_BRICKS.getDefaultState());
        structure.fillWithBlocks(world, start, -25, -29, 12, -24, -29, 13, Blocks.STONE_BRICKS.getDefaultState());
        structure.fillWithBlocks(world, start, -25, -29, 17, -24, -29, 23, Blocks.STONE_BRICKS.getDefaultState());
        structure.fillWithBlocks(world, start, -25, -29, 24, -25, -27, 24, Blocks.STONE_BRICKS.getDefaultState());
        structure.fillWithBlocks(world, start, -25, -29, 25, -25, -28, 25, Blocks.MOSSY_STONE_BRICKS.getDefaultState());
        structure.fillWithBlocks(world, start, -25, -29, 26, -25, -26, 26, Blocks.STONE_BRICKS.getDefaultState());
        structure.fillWithBlocks(world, start, -25, -28, -40, -25, -28, -38, Blocks.STONE_BRICKS.getDefaultState());
        structure.fillWithBlocks(world, start, -25, -28, -37, -25, -28, -36, Blocks.MOSSY_STONE_BRICKS.getDefaultState());
        structure.fillWithBlocks(world, start, -25, -28, -32, -25, -27, -32, Blocks.MOSSY_STONE_BRICKS.getDefaultState());
        structure.fillWithBlocks(world, start, -25, -28, -29, -24, -28, -27, Blocks.STONE_BRICKS.getDefaultState());
        structure.fillWithBlocks(world, start, -25, -28, -24, -24, -28, -23, Blocks.STONE_BRICKS.getDefaultState());
        structure.fillWithBlocks(world, start, -25, -28, 11, -25, -28, 11, Blocks.STONE_BRICKS.getDefaultState());
        structure.fillWithBlocks(world, start, -25, -28, 12, -25, -27, 12, Blocks.MOSSY_STONE_BRICKS.getDefaultState());
        structure.fillWithBlocks(world, start, -25, -28, 13, -25, -27, 15, Blocks.STONE_BRICKS.getDefaultState());
        structure.fillWithBlocks(world, start, -25, -28, 18, -25, -28, 19, Blocks.MOSSY_STONE_BRICKS.getDefaultState());
        structure.fillWithBlocks(world, start, -25, -28, 20, -25, -28, 22, Blocks.STONE_BRICKS.getDefaultState());
        structure.fillWithBlocks(world, start, -25, -28, 23, -24, -28, 23, Blocks.MOSSY_STONE_BRICKS.getDefaultState());
        structure.fillWithBlocks(world, start, -25, -27, -37, -25, -27, -37, Blocks.STONE_BRICKS.getDefaultState());
        structure.fillWithBlocks(world, start, -25, -27, -35, -24, -27, -34, Blocks.STONE_BRICKS.getDefaultState());
        structure.fillWithBlocks(world, start, -25, -27, -33, -25, -27, -33, Blocks.STONE_BRICKS.getDefaultState());
        structure.fillWithBlocks(world, start, -25, -27, -31, -25, -27, -26, Blocks.STONE_BRICKS.getDefaultState());
        structure.fillWithBlocks(world, start, -25, -27, -24, -25, -27, -23, Blocks.STONE_BRICKS.getDefaultState());
        structure.fillWithBlocks(world, start, -25, -27, 11, -25, -27, 12, Blocks.MOSSY_STONE_BRICKS.getDefaultState());
        structure.fillWithBlocks(world, start, -25, -27, 16, -25, -27, 16, Blocks.STONE_BRICKS.getDefaultState());
        structure.fillWithBlocks(world, start, -25, -27, 18, -25, -27, 18, Blocks.STONE_BRICKS.getDefaultState());
        structure.fillWithBlocks(world, start, -25, -27, 19, -25, -27, 21, Blocks.MOSSY_STONE_BRICKS.getDefaultState());
        structure.fillWithBlocks(world, start, -25, -27, 22, -24, -27, 26, Blocks.STONE_BRICKS.getDefaultState());
        structure.fillWithBlocks(world, start, -25, -26, -6, -25, -25, -5, Blocks.STONE_BRICKS.getDefaultState());
        structure.fillWithBlocks(world, start, -25, -26, -2, -19, -26, 4, Blocks.STONE_BRICKS.getDefaultState());
        structure.fillWithBlocks(world, start, -25, -26, 5, -23, -26, 7, Blocks.STONE_BRICKS.getDefaultState());
        structure.fillWithBlocks(world, start, -25, -26, 27, -25, -25, 28, Blocks.STONE_BRICKS.getDefaultState());
        structure.fillWithBlocks(world, start, -25, -26, 57, -25, -26, 57, Blocks.CRACKED_STONE_BRICKS.getDefaultState());
        structure.fillWithBlocks(world, start, -25, -26, 58, -25, -26, 60, Blocks.STONE_BRICKS.getDefaultState());
        structure.fillWithBlocks(world, start, -25, -26, 62, -25, -26, 62, Blocks.STONE_BRICKS.getDefaultState());
        structure.fillWithBlocks(world, start, -25, -26, 63, -25, -26, 65, Blocks.CRACKED_STONE_BRICKS.getDefaultState());
        structure.fillWithBlocks(world, start, -25, -26, 66, -24, -26, 69, Blocks.STONE_BRICKS.getDefaultState());
        structure.fillWithBlocks(world, start, -25, -26, 70, -24, -26, 70, Blocks.MOSSY_STONE_BRICKS.getDefaultState());
        structure.fillWithBlocks(world, start, -25, -26, 79, -25, -26, 79, Blocks.STONE_BRICKS.getDefaultState());
        structure.fillWithBlocks(world, start, -25, -26, 83, -25, -26, 83, Blocks.STONE_BRICKS.getDefaultState());
        structure.fillWithBlocks(world, start, -25, -26, 86, -24, -26, 87, Blocks.STONE_BRICKS.getDefaultState());
        structure.fillWithBlocks(world, start, -25, -25, 29, -25, -25, 33, Blocks.AIR.getDefaultState());
        structure.fillWithBlocks(world, start, -25, -25, 57, -25, -24, 57, Blocks.CRACKED_STONE_BRICKS.getDefaultState());
        structure.fillWithBlocks(world, start, -25, -25, 58, -24, -25, 68, Blocks.AIR.getDefaultState());
        structure.fillWithBlocks(world, start, -25, -25, 69, -25, -25, 70, Blocks.STONE_BRICKS.getDefaultState());
        structure.fillWithBlocks(world, start, -25, -25, 74, -25, -25, 75, Blocks.STONE_BRICKS.getDefaultState());
        structure.fillWithBlocks(world, start, -25, -25, 76, -24, -25, 86, Blocks.AIR.getDefaultState());
        structure.fillWithBlocks(world, start, -25, -25, 87, -25, -25, 88, Blocks.STONE_BRICKS.getDefaultState());
        structure.fillWithBlocks(world, start, -25, -24, -6, -25, -24, -5, Blocks.STONE_BRICKS.getDefaultState());
        structure.fillWithBlocks(world, start, -25, -24, 28, -25, -24, 28, Blocks.STONE_BRICKS.getDefaultState());
        structure.fillWithBlocks(world, start, -25, -24, 29, -25, -24, 33, Blocks.AIR.getDefaultState());
        structure.fillWithBlocks(world, start, -25, -24, 56, -25, -24, 56, Blocks.STONE_BRICKS.getDefaultState());
        structure.fillWithBlocks(world, start, -25, -24, 58, -24, -24, 68, Blocks.AIR.getDefaultState());
        structure.fillWithBlocks(world, start, -25, -24, 69, -23, -22, 69, Blocks.STONE_BRICKS.getDefaultState());
        structure.fillWithBlocks(world, start, -25, -24, 70, -24, -23, 70, Blocks.CRACKED_STONE_BRICKS.getDefaultState());
        structure.fillWithBlocks(world, start, -25, -24, 74, -25, -24, 75, Blocks.STONE_BRICKS.getDefaultState());
        structure.fillWithBlocks(world, start, -25, -24, 76, -24, -24, 86, Blocks.AIR.getDefaultState());
        structure.fillWithBlocks(world, start, -25, -23, -5, -25, -23, -5, Blocks.STONE_BRICKS.getDefaultState());
        structure.fillWithBlocks(world, start, -25, -23, 8, -24, -22, 8, Blocks.STONE_BRICKS.getDefaultState());
        structure.fillWithBlocks(world, start, -25, -23, 28, -25, -23, 28, Blocks.STONE_BRICKS.getDefaultState());
        structure.fillWithBlocks(world, start, -25, -23, 29, -25, -23, 33, Blocks.AIR.getDefaultState());
        structure.fillWithBlocks(world, start, -25, -23, 56, -25, -23, 56, Blocks.STONE_BRICKS.getDefaultState());
        structure.fillWithBlocks(world, start, -25, -23, 58, -24, -23, 68, Blocks.AIR.getDefaultState());
        structure.fillWithBlocks(world, start, -25, -23, 74, -25, -23, 75, Blocks.CRACKED_STONE_BRICKS.getDefaultState());
        structure.fillWithBlocks(world, start, -25, -23, 76, -24, -23, 86, Blocks.AIR.getDefaultState());
        structure.fillWithBlocks(world, start, -25, -23, 87, -23, -21, 87, Blocks.STONE_BRICKS.getDefaultState());
        structure.fillWithBlocks(world, start, -25, -22, -6, -25, -22, -5, Blocks.CRACKED_STONE_BRICKS.getDefaultState());
        structure.fillWithBlocks(world, start, -25, -22, 7, -24, -22, 8, Blocks.STONE_BRICKS.getDefaultState());
        structure.fillWithBlocks(world, start, -25, -22, 32, -25, -22, 33, Blocks.STONE_BRICKS.getDefaultState());
        structure.fillWithBlocks(world, start, -25, -22, 56, -25, -22, 56, Blocks.CRACKED_STONE_BRICKS.getDefaultState());
        structure.fillWithBlocks(world, start, -25, -22, 57, -25, -17, 57, Blocks.STONE_BRICKS.getDefaultState());
        structure.fillWithBlocks(world, start, -25, -22, 58, -24, -22, 68, Blocks.AIR.getDefaultState());
        structure.fillWithBlocks(world, start, -25, -22, 74, -24, -22, 75, Blocks.STONE_BRICKS.getDefaultState());
        structure.fillWithBlocks(world, start, -25, -22, 76, -24, -22, 86, Blocks.AIR.getDefaultState());
        structure.fillWithBlocks(world, start, -25, -21, -5, -25, -21, -4, Blocks.STONE_BRICKS.getDefaultState());
        structure.fillWithBlocks(world, start, -25, -21, -3, -25, -20, -3, Blocks.MOSSY_STONE_BRICKS.getDefaultState());
        structure.fillWithBlocks(world, start, -25, -21, -2, -19, -21, 4, Blocks.AIR.getDefaultState());
        structure.fillWithBlocks(world, start, -25, -21, 5, -24, -21, 6, Blocks.STONE_BRICKS.getDefaultState());
        structure.fillWithBlocks(world, start, -25, -21, 59, -25, -20, 60, Blocks.CRACKED_STONE_BRICKS.getDefaultState());
        structure.fillWithBlocks(world, start, -25, -21, 65, -25, -20, 66, Blocks.STONE_BRICKS.getDefaultState());
        structure.fillWithBlocks(world, start, -25, -21, 67, -22, -21, 67, Blocks.STONE_BRICKS.getDefaultState());
        structure.fillWithBlocks(world, start, -25, -21, 74, -25, -21, 77, Blocks.STONE_BRICKS.getDefaultState());
        structure.fillWithBlocks(world, start, -25, -21, 79, -25, -21, 88, Blocks.STONE_BRICKS.getDefaultState());
        structure.fillWithBlocks(world, start, -25, -20, -6, -25, -20, -6, Blocks.STONE_BRICKS.getDefaultState());
        structure.fillWithBlocks(world, start, -25, -20, -5, -25, -20, -3, Blocks.MOSSY_STONE_BRICKS.getDefaultState());
        structure.fillWithBlocks(world, start, -25, -20, -1, -24, -20, 0, Blocks.STONE_BRICKS.getDefaultState());
        structure.fillWithBlocks(world, start, -25, -20, 2, -24, -20, 3, Blocks.STONE_BRICKS.getDefaultState());
        structure.fillWithBlocks(world, start, -25, -20, 4, -25, -20, 8, Blocks.STONE_BRICKS.getDefaultState());
        structure.fillWithBlocks(world, start, -25, -20, 56, -25, -20, 58, Blocks.STONE_BRICKS.getDefaultState());
        structure.fillWithBlocks(world, start, -25, -20, 62, -25, -20, 62, Blocks.STONE_BRICKS.getDefaultState());
        structure.fillWithBlocks(world, start, -25, -20, 64, -25, -20, 66, Blocks.STONE_BRICKS.getDefaultState());
        structure.fillWithBlocks(world, start, -25, -20, 68, -24, -20, 69, Blocks.STONE_BRICKS.getDefaultState());
        structure.fillWithBlocks(world, start, -25, -20, 76, -25, -20, 77, Blocks.CRACKED_STONE_BRICKS.getDefaultState());
        structure.fillWithBlocks(world, start, -25, -20, 78, -23, -19, 78, Blocks.STONE_BRICKS.getDefaultState());
        structure.fillWithBlocks(world, start, -25, -20, 80, -23, -19, 80, Blocks.STONE_BRICKS.getDefaultState());
        structure.fillWithBlocks(world, start, -25, -20, 81, -25, -20, 82, Blocks.CRACKED_STONE_BRICKS.getDefaultState());
        structure.fillWithBlocks(world, start, -25, -20, 84, -25, -20, 85, Blocks.STONE_BRICKS.getDefaultState());
        structure.fillWithBlocks(world, start, -25, -20, 86, -23, -20, 86, Blocks.CRACKED_STONE_BRICKS.getDefaultState());
        structure.fillWithBlocks(world, start, -25, -19, -5, -25, -17, -5, Blocks.STONE_BRICKS.getDefaultState());
        structure.fillWithBlocks(world, start, -25, -19, -4, -25, -19, -3, Blocks.CRACKED_STONE_BRICKS.getDefaultState());
        structure.fillWithBlocks(world, start, -25, -19, -2, -25, -19, 2, Blocks.STONE_BRICKS.getDefaultState());
        structure.fillWithBlocks(world, start, -25, -19, 3, -25, -18, 3, Blocks.MOSSY_STONE_BRICKS.getDefaultState());
        structure.fillWithBlocks(world, start, -25, -19, 4, -25, -19, 4, Blocks.CRACKED_STONE_BRICKS.getDefaultState());
        structure.fillWithBlocks(world, start, -25, -19, 5, -25, -19, 8, Blocks.STONE_BRICKS.getDefaultState());
        structure.fillWithBlocks(world, start, -25, -19, 58, -24, -19, 59, Blocks.STONE_BRICKS.getDefaultState());
        structure.fillWithBlocks(world, start, -25, -19, 60, -25, -19, 60, Blocks.CRACKED_STONE_BRICKS.getDefaultState());
        structure.fillWithBlocks(world, start, -25, -19, 61, -25, -19, 63, Blocks.STONE_BRICKS.getDefaultState());
        structure.fillWithBlocks(world, start, -25, -19, 64, -24, -19, 64, Blocks.CRACKED_STONE_BRICKS.getDefaultState());
        structure.fillWithBlocks(world, start, -25, -19, 65, -23, -19, 68, Blocks.STONE_BRICKS.getDefaultState());
        structure.fillWithBlocks(world, start, -25, -19, 74, -25, -18, 74, Blocks.STONE_BRICKS.getDefaultState());
        structure.fillWithBlocks(world, start, -25, -19, 75, -25, -18, 77, Blocks.CRACKED_STONE_BRICKS.getDefaultState());
        structure.fillWithBlocks(world, start, -25, -19, 79, -24, -19, 80, Blocks.STONE_BRICKS.getDefaultState());
        structure.fillWithBlocks(world, start, -25, -19, 81, -25, -19, 82, Blocks.MOSSY_STONE_BRICKS.getDefaultState());
        structure.fillWithBlocks(world, start, -25, -19, 83, -24, -19, 85, Blocks.STONE_BRICKS.getDefaultState());
        structure.fillWithBlocks(world, start, -25, -19, 86, -25, -19, 86, Blocks.STONE_BRICKS.getDefaultState());
        structure.fillWithBlocks(world, start, -25, -18, -6, -25, -18, -6, Blocks.CRACKED_STONE_BRICKS.getDefaultState());
        structure.fillWithBlocks(world, start, -25, -18, -4, -25, -18, -2, Blocks.STONE_BRICKS.getDefaultState());
        structure.fillWithBlocks(world, start, -25, -18, -1, -25, -18, -1, Blocks.MOSSY_STONE_BRICKS.getDefaultState());
        structure.fillWithBlocks(world, start, -25, -18, 0, -25, -18, 2, Blocks.STONE_BRICKS.getDefaultState());
        structure.fillWithBlocks(world, start, -25, -18, 4, -24, -17, 4, Blocks.STONE_BRICKS.getDefaultState());
        structure.fillWithBlocks(world, start, -25, -18, 5, -25, -18, 5, Blocks.CRACKED_STONE_BRICKS.getDefaultState());
        structure.fillWithBlocks(world, start, -25, -18, 6, -25, -18, 7, Blocks.STONE_BRICKS.getDefaultState());
        structure.fillWithBlocks(world, start, -25, -18, 56, -25, -18, 60, Blocks.STONE_BRICKS.getDefaultState());
        structure.fillWithBlocks(world, start, -25, -18, 62, -25, -18, 62, Blocks.STONE_BRICKS.getDefaultState());
        structure.fillWithBlocks(world, start, -25, -18, 63, -25, -18, 63, Blocks.CRACKED_STONE_BRICKS.getDefaultState());
        structure.fillWithBlocks(world, start, -25, -18, 64, -25, -18, 64, Blocks.STONE_BRICKS.getDefaultState());
        structure.fillWithBlocks(world, start, -25, -18, 65, -25, -18, 65, Blocks.CRACKED_STONE_BRICKS.getDefaultState());
        structure.fillWithBlocks(world, start, -25, -18, 66, -25, -18, 67, Blocks.STONE_BRICKS.getDefaultState());
        structure.fillWithBlocks(world, start, -25, -18, 69, -25, -17, 69, Blocks.STONE_BRICKS.getDefaultState());
        structure.fillWithBlocks(world, start, -25, -18, 70, -25, -17, 70, Blocks.CRACKED_STONE_BRICKS.getDefaultState());
        structure.fillWithBlocks(world, start, -25, -18, 79, -24, -18, 79, Blocks.STONE_BRICKS.getDefaultState());
        structure.fillWithBlocks(world, start, -25, -18, 81, -23, -17, 81, Blocks.STONE_BRICKS.getDefaultState());
        structure.fillWithBlocks(world, start, -25, -18, 83, -25, -18, 84, Blocks.CRACKED_STONE_BRICKS.getDefaultState());
        structure.fillWithBlocks(world, start, -25, -18, 87, -25, -18, 87, Blocks.STONE_BRICKS.getDefaultState());
        structure.fillWithBlocks(world, start, -25, -17, -6, -25, -17, -6, Blocks.CRACKED_STONE_BRICKS.getDefaultState());
        structure.fillWithBlocks(world, start, -25, -17, -4, -25, -17, -4, Blocks.CRACKED_STONE_BRICKS.getDefaultState());
        structure.fillWithBlocks(world, start, -25, -17, -3, -25, -17, -3, Blocks.STONE_BRICKS.getDefaultState());
        structure.fillWithBlocks(world, start, -25, -17, -1, -25, -17, -1, Blocks.STONE_BRICKS.getDefaultState());
        structure.fillWithBlocks(world, start, -25, -17, 1, -25, -17, 2, Blocks.CRACKED_STONE_BRICKS.getDefaultState());
        structure.fillWithBlocks(world, start, -25, -17, 3, -25, -17, 6, Blocks.STONE_BRICKS.getDefaultState());
        structure.fillWithBlocks(world, start, -25, -17, 7, -24, -17, 7, Blocks.MOSSY_STONE_BRICKS.getDefaultState());
        structure.fillWithBlocks(world, start, -25, -17, 8, -24, -17, 8, Blocks.STONE_BRICKS.getDefaultState());
        structure.fillWithBlocks(world, start, -25, -17, 60, -25, -17, 61, Blocks.STONE_BRICKS.getDefaultState());
        structure.fillWithBlocks(world, start, -25, -17, 62, -25, -17, 64, Blocks.MOSSY_STONE_BRICKS.getDefaultState());
        structure.fillWithBlocks(world, start, -25, -17, 67, -25, -17, 67, Blocks.STONE_BRICKS.getDefaultState());
        structure.fillWithBlocks(world, start, -25, -17, 74, -24, -17, 74, Blocks.MOSSY_STONE_BRICKS.getDefaultState());
        structure.fillWithBlocks(world, start, -25, -17, 75, -25, -17, 78, Blocks.STONE_BRICKS.getDefaultState());
        structure.fillWithBlocks(world, start, -25, -17, 80, -25, -17, 81, Blocks.STONE_BRICKS.getDefaultState());
        structure.fillWithBlocks(world, start, -25, -17, 83, -22, -17, 83, Blocks.STONE_BRICKS.getDefaultState());
        structure.fillWithBlocks(world, start, -25, -17, 84, -25, -17, 86, Blocks.CRACKED_STONE_BRICKS.getDefaultState());
        structure.fillWithBlocks(world, start, -25, -16, 38, -23, -14, 38, Blocks.STONE_BRICKS.getDefaultState());
        structure.fillWithBlocks(world, start, -25, -15, 32, -22, -15, 35, Blocks.AIR.getDefaultState());
        structure.fillWithBlocks(world, start, -25, -14, 32, -22, -14, 35, Blocks.AIR.getDefaultState());
        structure.fillWithBlocks(world, start, -25, -13, 24, -24, -13, 25, Blocks.STONE_BRICKS.getDefaultState());
        structure.fillWithBlocks(world, start, -25, -12, 24, -24, -12, 25, Blocks.STONE_BRICKS.getDefaultState());
        structure.fillWithBlocks(world, start, -25, -12, 37, -24, -12, 38, Blocks.STONE_BRICKS.getDefaultState());
        structure.fillWithBlocks(world, start, -25, -11, 26, -24, -11, 27, Blocks.STONE_BRICKS.getDefaultState());
        structure.fillWithBlocks(world, start, -25, -11, 35, -22, -11, 38, Blocks.STONE_BRICKS.getDefaultState());
        structure.fillWithBlocks(world, start, -25, -10, 29, -25, -10, 30, Blocks.STONE_BRICKS.getDefaultState());
        structure.fillWithBlocks(world, start, -25, -10, 32, -22, -10, 35, Blocks.STONE_BRICKS.getDefaultState());
        structure.fillWithBlocks(world, start, -25, -10, 36, -23, -10, 38, Blocks.STONE_BRICKS.getDefaultState());
        structure.fillWithBlocks(world, start, -25, -9, 24, -23, -9, 26, Blocks.STONE_BRICKS.getDefaultState());
        structure.fillWithBlocks(world, start, -25, -9, 28, -23, -9, 30, Blocks.STONE_BRICKS.getDefaultState());
        structure.fillWithBlocks(world, start, -25, -9, 31, -25, -9, 32, Blocks.MOSSY_STONE_BRICKS.getDefaultState());
        structure.fillWithBlocks(world, start, -25, -9, 33, -25, -7, 38, Blocks.STONE_BRICKS.getDefaultState());
        structure.fillWithBlocks(world, start, -25, -7, 24, -23, -7, 26, Blocks.STONE_BRICKS.getDefaultState());
        structure.fillWithBlocks(world, start, -25, -7, 28, -24, -7, 29, Blocks.STONE_BRICKS.getDefaultState());
        structure.fillWithBlocks(world, start, -25, -7, 31, -22, -7, 35, Blocks.STONE_BRICKS.getDefaultState());
        structure.fillWithBlocks(world, start, -24, -56, 3, -22, -56, 5, Blocks.STONE_BRICKS.getDefaultState());
        structure.fillWithBlocks(world, start, -24, -56, 6, -24, -56, 9, Blocks.STONE_BRICKS.getDefaultState());
        structure.fillWithBlocks(world, start, -24, -55, -13, -24, -50, -5, Blocks.STONE_BRICKS.getDefaultState());
        structure.fillWithBlocks(world, start, -24, -55, -2, -23, -55, 5, Blocks.STONE_BRICKS.getDefaultState());
        structure.fillWithBlocks(world, start, -24, -55, 6, -24, -46, 6, Blocks.STONE_BRICKS.getDefaultState());
        structure.fillWithBlocks(world, start, -24, -55, 8, -23, -55, 9, Blocks.STONE_BRICKS.getDefaultState());
        structure.fillWithBlocks(world, start, -24, -53, -14, -17, -53, -7, Blocks.STONE_BRICKS.getDefaultState());
        structure.fillWithBlocks(world, start, -24, -53, 5, -21, -53, 9, Blocks.STONE_BRICKS.getDefaultState());
        structure.fillWithBlocks(world, start, -24, -52, -15, -16, -52, -7, Blocks.STONE_BRICKS.getDefaultState());
        structure.fillWithBlocks(world, start, -24, -52, 8, -24, -44, 8, Blocks.STONE_BRICKS.getDefaultState());
        structure.fillWithBlocks(world, start, -24, -52, 9, -23, -52, 9, Blocks.AIR.getDefaultState());
        structure.fillWithBlocks(world, start, -24, -51, -2, -23, -51, 0, Blocks.STONE_BRICKS.getDefaultState());
        structure.fillWithBlocks(world, start, -24, -50, -3, -21, -50, 1, Blocks.STONE_BRICKS.getDefaultState());
        structure.fillWithBlocks(world, start, -24, -49, -9, -23, -49, -8, Blocks.STONE_BRICKS.getDefaultState());
        structure.fillWithBlocks(world, start, -24, -49, -6, -20, -49, -1, Blocks.STONE_BRICKS.getDefaultState());
        structure.fillWithBlocks(world, start, -24, -49, 5, -20, -49, 9, Blocks.STONE_BRICKS.getDefaultState());
        structure.fillWithBlocks(world, start, -24, -48, -1, -24, -48, -1, Blocks.STONE_BRICKS.getDefaultState());
        structure.fillWithBlocks(world, start, -24, -48, 5, -20, -48, 9, Blocks.STONE_BRICKS.getDefaultState());
        structure.fillWithBlocks(world, start, -24, -47, -3, -19, -47, 2, Blocks.STONE_BRICKS.getDefaultState());
        structure.fillWithBlocks(world, start, -24, -47, 3, -22, -47, 6, Blocks.STONE_BRICKS.getDefaultState());
        structure.fillWithBlocks(world, start, -24, -46, -3, -24, -44, -1, Blocks.STONE_BRICKS.getDefaultState());
        structure.fillWithBlocks(world, start, -24, -46, 0, -24, -46, 1, Blocks.MOSSY_COBBLESTONE.getDefaultState());
        structure.fillWithBlocks(world, start, -24, -46, 2, -24, -46, 2, Blocks.MOSSY_STONE_BRICKS.getDefaultState());
        structure.fillWithBlocks(world, start, -24, -46, 4, -24, -46, 9, Blocks.STONE_BRICKS.getDefaultState());
        structure.fillWithBlocks(world, start, -24, -46, 10, -24, -46, 11, Blocks.MOSSY_STONE_BRICKS.getDefaultState());
        structure.fillWithBlocks(world, start, -24, -46, 12, -24, -46, 17, Blocks.STONE_BRICKS.getDefaultState());
        structure.fillWithBlocks(world, start, -24, -46, 18, -23, -46, 18, Blocks.MOSSY_STONE_BRICKS.getDefaultState());
        structure.fillWithBlocks(world, start, -24, -46, 21, -19, -46, 21, Blocks.STONE_BRICKS.getDefaultState());
        structure.fillWithBlocks(world, start, -24, -45, 0, -22, -45, 2, Blocks.AIR.getDefaultState());
        structure.fillWithBlocks(world, start, -24, -45, 3, -24, -45, 4, Blocks.STONE_BRICKS.getDefaultState());
        structure.fillWithBlocks(world, start, -24, -45, 7, -24, -44, 8, Blocks.STONE_BRICKS.getDefaultState());
        structure.fillWithBlocks(world, start, -24, -45, 9, -24, -45, 10, Blocks.MOSSY_STONE_BRICKS.getDefaultState());
        structure.fillWithBlocks(world, start, -24, -45, 11, -24, -43, 11, Blocks.STONE_BRICKS.getDefaultState());
        structure.fillWithBlocks(world, start, -24, -45, 13, -24, -44, 14, Blocks.STONE_BRICKS.getDefaultState());
        structure.fillWithBlocks(world, start, -24, -45, 15, -24, -44, 15, Blocks.MOSSY_STONE_BRICKS.getDefaultState());
        structure.fillWithBlocks(world, start, -24, -45, 16, -24, -45, 19, Blocks.STONE_BRICKS.getDefaultState());
        structure.fillWithBlocks(world, start, -24, -45, 20, -24, -45, 20, Blocks.MOSSY_STONE_BRICKS.getDefaultState());
        structure.fillWithBlocks(world, start, -24, -45, 21, -24, -42, 21, Blocks.STONE_BRICKS.getDefaultState());
        structure.fillWithBlocks(world, start, -24, -44, 0, -22, -44, 2, Blocks.AIR.getDefaultState());
        structure.fillWithBlocks(world, start, -24, -44, 3, -24, -44, 4, Blocks.MOSSY_STONE_BRICKS.getDefaultState());
        structure.fillWithBlocks(world, start, -24, -44, 5, -23, -44, 6, Blocks.STONE_BRICKS.getDefaultState());
        structure.fillWithBlocks(world, start, -24, -44, 9, -24, -44, 14, Blocks.STONE_BRICKS.getDefaultState());
        structure.fillWithBlocks(world, start, -24, -44, 17, -24, -43, 17, Blocks.STONE_BRICKS.getDefaultState());
        structure.fillWithBlocks(world, start, -24, -44, 20, -24, -44, 21, Blocks.STONE_BRICKS.getDefaultState());
        structure.fillWithBlocks(world, start, -24, -43, -3, -24, -43, -3, Blocks.STONE_BRICKS.getDefaultState());
        structure.fillWithBlocks(world, start, -24, -43, -1, -22, -43, -1, Blocks.STONE_BRICKS.getDefaultState());
        structure.fillWithBlocks(world, start, -24, -43, 0, -22, -43, 2, Blocks.AIR.getDefaultState());
        structure.fillWithBlocks(world, start, -24, -43, 3, -23, -43, 3, Blocks.STONE_BRICKS.getDefaultState());
        structure.fillWithBlocks(world, start, -24, -43, 5, -24, -43, 5, Blocks.STONE_BRICKS.getDefaultState());
        structure.fillWithBlocks(world, start, -24, -43, 8, -24, -42, 8, Blocks.MOSSY_STONE_BRICKS.getDefaultState());
        structure.fillWithBlocks(world, start, -24, -43, 9, -24, -42, 9, Blocks.STONE_BRICKS.getDefaultState());
        structure.fillWithBlocks(world, start, -24, -43, 10, -24, -42, 10, Blocks.MOSSY_STONE_BRICKS.getDefaultState());
        structure.fillWithBlocks(world, start, -24, -43, 13, -24, -41, 13, Blocks.MOSSY_COBBLESTONE.getDefaultState());
        structure.fillWithBlocks(world, start, -24, -43, 14, -24, -43, 15, Blocks.STONE_BRICKS.getDefaultState());
        structure.fillWithBlocks(world, start, -24, -43, 18, -24, -43, 19, Blocks.STONE_BRICKS.getDefaultState());
        structure.fillWithBlocks(world, start, -24, -43, 20, -24, -43, 20, Blocks.MOSSY_STONE_BRICKS.getDefaultState());
        structure.fillWithBlocks(world, start, -24, -42, -3, -24, -42, -3, Blocks.MOSSY_STONE_BRICKS.getDefaultState());
        structure.fillWithBlocks(world, start, -24, -42, -2, -24, -42, 2, Blocks.STONE_BRICKS.getDefaultState());
        structure.fillWithBlocks(world, start, -24, -42, 3, -23, -42, 3, Blocks.MOSSY_STONE_BRICKS.getDefaultState());
        structure.fillWithBlocks(world, start, -24, -42, 4, -24, -42, 6, Blocks.STONE_BRICKS.getDefaultState());
        structure.fillWithBlocks(world, start, -24, -42, 7, -24, -42, 8, Blocks.MOSSY_STONE_BRICKS.getDefaultState());
        structure.fillWithBlocks(world, start, -24, -42, 12, -24, -42, 15, Blocks.MOSSY_COBBLESTONE.getDefaultState());
        structure.fillWithBlocks(world, start, -24, -42, 16, -24, -40, 16, Blocks.STONE_BRICKS.getDefaultState());
        structure.fillWithBlocks(world, start, -24, -42, 20, -23, -42, 21, Blocks.STONE_BRICKS.getDefaultState());
        structure.fillWithBlocks(world, start, -24, -41, -2, -24, -41, -2, Blocks.STONE_BRICKS.getDefaultState());
        structure.fillWithBlocks(world, start, -24, -41, 2, -24, -39, 2, Blocks.STONE_BRICKS.getDefaultState());
        structure.fillWithBlocks(world, start, -24, -41, 3, -23, -41, 3, Blocks.AIR.getDefaultState());
        structure.fillWithBlocks(world, start, -24, -41, 4, -24, -41, 4, Blocks.STONE_BRICKS.getDefaultState());
        structure.fillWithBlocks(world, start, -24, -41, 6, -24, -41, 6, Blocks.STONE_BRICKS.getDefaultState());
        structure.fillWithBlocks(world, start, -24, -41, 9, -24, -40, 9, Blocks.MOSSY_STONE_BRICKS.getDefaultState());
        structure.fillWithBlocks(world, start, -24, -41, 12, -24, -40, 12, Blocks.STONE_BRICKS.getDefaultState());
        structure.fillWithBlocks(world, start, -24, -41, 17, -24, -40, 17, Blocks.MOSSY_COBBLESTONE.getDefaultState());
        structure.fillWithBlocks(world, start, -24, -41, 18, -23, -41, 19, Blocks.STONE_BRICKS.getDefaultState());
        structure.fillWithBlocks(world, start, -24, -41, 21, -23, -41, 21, Blocks.MOSSY_STONE_BRICKS.getDefaultState());
        structure.fillWithBlocks(world, start, -24, -40, -3, -22, -40, -3, Blocks.STONE_BRICKS.getDefaultState());
        structure.fillWithBlocks(world, start, -24, -40, 0, -24, -39, 5, Blocks.STONE_BRICKS.getDefaultState());
        structure.fillWithBlocks(world, start, -24, -40, 6, -24, -40, 7, Blocks.MOSSY_COBBLESTONE.getDefaultState());
        structure.fillWithBlocks(world, start, -24, -40, 8, -24, -39, 8, Blocks.STONE_BRICKS.getDefaultState());
        structure.fillWithBlocks(world, start, -24, -40, 10, -24, -40, 14, Blocks.STONE_BRICKS.getDefaultState());
        structure.fillWithBlocks(world, start, -24, -40, 18, -24, -40, 18, Blocks.STONE_BRICKS.getDefaultState());
        structure.fillWithBlocks(world, start, -24, -40, 20, -23, -40, 21, Blocks.STONE_BRICKS.getDefaultState());
        structure.fillWithBlocks(world, start, -24, -39, -3, -24, -39, 5, Blocks.STONE_BRICKS.getDefaultState());
        structure.fillWithBlocks(world, start, -24, -39, 7, -24, -39, 9, Blocks.STONE_BRICKS.getDefaultState());
        structure.fillWithBlocks(world, start, -24, -39, 10, -24, -39, 12, Blocks.MOSSY_STONE_BRICKS.getDefaultState());
        structure.fillWithBlocks(world, start, -24, -39, 14, -24, -39, 15, Blocks.STONE_BRICKS.getDefaultState());
        structure.fillWithBlocks(world, start, -24, -39, 16, -24, -38, 17, Blocks.MOSSY_STONE_BRICKS.getDefaultState());
        structure.fillWithBlocks(world, start, -24, -39, 18, -24, -36, 18, Blocks.STONE_BRICKS.getDefaultState());
        structure.fillWithBlocks(world, start, -24, -39, 20, -24, -39, 20, Blocks.STONE_BRICKS.getDefaultState());
        structure.fillWithBlocks(world, start, -24, -39, 21, -24, -38, 21, Blocks.MOSSY_STONE_BRICKS.getDefaultState());
        structure.fillWithBlocks(world, start, -24, -38, -2, -23, -38, -2, Blocks.STONE_BRICKS.getDefaultState());
        structure.fillWithBlocks(world, start, -24, -38, -1, -24, -38, -1, Blocks.MOSSY_STONE_BRICKS.getDefaultState());
        structure.fillWithBlocks(world, start, -24, -38, 0, -24, -38, 1, Blocks.STONE_BRICKS.getDefaultState());
        structure.fillWithBlocks(world, start, -24, -38, 7, -24, -38, 8, Blocks.MOSSY_STONE_BRICKS.getDefaultState());
        structure.fillWithBlocks(world, start, -24, -38, 9, -24, -38, 12, Blocks.STONE_BRICKS.getDefaultState());
        structure.fillWithBlocks(world, start, -24, -38, 14, -22, -37, 14, Blocks.STONE_BRICKS.getDefaultState());
        structure.fillWithBlocks(world, start, -24, -38, 15, -24, -38, 17, Blocks.MOSSY_STONE_BRICKS.getDefaultState());
        structure.fillWithBlocks(world, start, -24, -38, 19, -22, -38, 19, Blocks.STONE_BRICKS.getDefaultState());
        structure.fillWithBlocks(world, start, -24, -38, 20, -24, -38, 21, Blocks.MOSSY_STONE_BRICKS.getDefaultState());
        structure.fillWithBlocks(world, start, -24, -37, -3, -24, -36, -2, Blocks.STONE_BRICKS.getDefaultState());
        structure.fillWithBlocks(world, start, -24, -37, -1, -24, -37, -1, Blocks.STONE_BRICKS.getDefaultState());
        structure.fillWithBlocks(world, start, -24, -37, 2, -23, -37, 2, Blocks.MOSSY_STONE_BRICKS.getDefaultState());
        structure.fillWithBlocks(world, start, -24, -37, 3, -24, -37, 7, Blocks.STONE_BRICKS.getDefaultState());
        structure.fillWithBlocks(world, start, -24, -37, 8, -23, -37, 9, Blocks.MOSSY_STONE_BRICKS.getDefaultState());
        structure.fillWithBlocks(world, start, -24, -37, 10, -24, -37, 11, Blocks.STONE_BRICKS.getDefaultState());
        structure.fillWithBlocks(world, start, -24, -37, 13, -23, -37, 14, Blocks.STONE_BRICKS.getDefaultState());
        structure.fillWithBlocks(world, start, -24, -37, 15, -24, -36, 15, Blocks.STONE_BRICKS.getDefaultState());
        structure.fillWithBlocks(world, start, -24, -37, 16, -24, -37, 17, Blocks.MOSSY_STONE_BRICKS.getDefaultState());
        structure.fillWithBlocks(world, start, -24, -37, 19, -24, -37, 21, Blocks.STONE_BRICKS.getDefaultState());
        structure.fillWithBlocks(world, start, -24, -36, -43, -22, -36, -43, Blocks.MOSSY_STONE_BRICKS.getDefaultState());
        structure.fillWithBlocks(world, start, -24, -36, -42, -16, -36, -34, Blocks.STONE_BRICKS.getDefaultState());
        structure.fillWithBlocks(world, start, -24, -36, -32, -16, -36, -24, Blocks.STONE_BRICKS.getDefaultState());
        structure.fillWithBlocks(world, start, -24, -36, -23, -24, -35, -23, Blocks.STONE_BRICKS.getDefaultState());
        structure.fillWithBlocks(world, start, -24, -36, -6, -24, -35, -5, Blocks.STONE_BRICKS.getDefaultState());
        structure.fillWithBlocks(world, start, -24, -36, -4, -24, -36, -4, Blocks.MOSSY_STONE_BRICKS.getDefaultState());
        structure.fillWithBlocks(world, start, -24, -36, 0, -23, -36, 1, Blocks.STONE_BRICKS.getDefaultState());
        structure.fillWithBlocks(world, start, -24, -36, 3, -23, -35, 3, Blocks.STONE_BRICKS.getDefaultState());
        structure.fillWithBlocks(world, start, -24, -36, 4, -24, -36, 4, Blocks.MOSSY_STONE_BRICKS.getDefaultState());
        structure.fillWithBlocks(world, start, -24, -36, 5, -24, -29, 5, Blocks.STONE_BRICKS.getDefaultState());
        structure.fillWithBlocks(world, start, -24, -36, 6, -24, -36, 8, Blocks.MOSSY_STONE_BRICKS.getDefaultState());
        structure.fillWithBlocks(world, start, -24, -36, 10, -24, -33, 10, Blocks.STONE_BRICKS.getDefaultState());
        structure.fillWithBlocks(world, start, -24, -36, 11, -24, -35, 11, Blocks.MOSSY_STONE_BRICKS.getDefaultState());
        structure.fillWithBlocks(world, start, -24, -36, 16, -24, -36, 20, Blocks.STONE_BRICKS.getDefaultState());
        structure.fillWithBlocks(world, start, -24, -36, 22, -24, -36, 23, Blocks.STONE_BRICKS.getDefaultState());
        structure.fillWithBlocks(world, start, -24, -36, 24, -24, -36, 25, Blocks.MOSSY_STONE_BRICKS.getDefaultState());
        structure.fillWithBlocks(world, start, -24, -35, -43, -24, -35, -43, Blocks.STONE_BRICKS.getDefaultState());
        structure.fillWithBlocks(world, start, -24, -35, -4, -23, -35, -3, Blocks.STONE_BRICKS.getDefaultState());
        structure.fillWithBlocks(world, start, -24, -35, -2, -24, -35, 3, Blocks.STONE_BRICKS.getDefaultState());
        structure.fillWithBlocks(world, start, -24, -35, 6, -22, -35, 8, Blocks.STONE_BRICKS.getDefaultState());
        structure.fillWithBlocks(world, start, -24, -35, 13, -24, -35, 14, Blocks.STONE_BRICK_WALL.getDefaultState().with(WallBlock.WATERLOGGED, false).with(WallBlock.UP, false).with(WallBlock.WALL_HEIGHT_NORTH, WallHeight.LOW).with(WallBlock.WALL_HEIGHT_SOUTH, WallHeight.LOW).with(WallBlock.WALL_HEIGHT_EAST, WallHeight.LOW).with(WallBlock.WALL_HEIGHT_WEST, WallHeight.LOW));
        structure.fillWithBlocks(world, start, -24, -35, 15, -24, -34, 15, Blocks.MOSSY_STONE_BRICKS.getDefaultState());
        structure.fillWithBlocks(world, start, -24, -35, 17, -24, -35, 19, Blocks.STONE_BRICK_WALL.getDefaultState().with(WallBlock.WATERLOGGED, false).with(WallBlock.UP, true).with(WallBlock.WALL_HEIGHT_NORTH, WallHeight.LOW).with(WallBlock.WALL_HEIGHT_SOUTH, WallHeight.LOW).with(WallBlock.WALL_HEIGHT_EAST, WallHeight.LOW).with(WallBlock.WALL_HEIGHT_WEST, WallHeight.LOW));
        structure.fillWithBlocks(world, start, -24, -35, 21, -24, -28, 21, Blocks.STONE_BRICKS.getDefaultState());
        structure.fillWithBlocks(world, start, -24, -35, 23, -24, -35, 24, Blocks.STONE_BRICK_WALL.getDefaultState().with(WallBlock.WATERLOGGED, false).with(WallBlock.UP, false).with(WallBlock.WALL_HEIGHT_NORTH, WallHeight.LOW).with(WallBlock.WALL_HEIGHT_SOUTH, WallHeight.LOW).with(WallBlock.WALL_HEIGHT_EAST, WallHeight.LOW).with(WallBlock.WALL_HEIGHT_WEST, WallHeight.LOW));
        structure.fillWithBlocks(world, start, -24, -34, -43, -23, -34, -43, Blocks.STONE_BRICKS.getDefaultState());
        structure.fillWithBlocks(world, start, -24, -34, -24, -24, -27, -24, Blocks.STONE_BRICKS.getDefaultState());
        structure.fillWithBlocks(world, start, -24, -34, -6, -24, -34, -2, Blocks.STONE_BRICKS.getDefaultState());
        structure.fillWithBlocks(world, start, -24, -34, 0, -24, -34, 3, Blocks.STONE_BRICKS.getDefaultState());
        structure.fillWithBlocks(world, start, -24, -34, 4, -23, -34, 4, Blocks.MOSSY_STONE_BRICKS.getDefaultState());
        structure.fillWithBlocks(world, start, -24, -34, 6, -24, -34, 6, Blocks.STONE_BRICKS.getDefaultState());
        structure.fillWithBlocks(world, start, -24, -34, 8, -23, -33, 8, Blocks.STONE_BRICKS.getDefaultState());
        structure.fillWithBlocks(world, start, -24, -34, 11, -24, -27, 11, Blocks.STONE_BRICKS.getDefaultState());
        structure.fillWithBlocks(world, start, -24, -34, 12, -22, -34, 14, Blocks.AIR.getDefaultState());
        structure.fillWithBlocks(world, start, -24, -34, 16, -20, -34, 20, Blocks.AIR.getDefaultState());
        structure.fillWithBlocks(world, start, -24, -34, 22, -22, -34, 24, Blocks.AIR.getDefaultState());
        structure.fillWithBlocks(world, start, -24, -33, -43, -24, -33, -42, Blocks.STONE_BRICKS.getDefaultState());
        structure.fillWithBlocks(world, start, -24, -33, -23, -23, -32, -23, Blocks.STONE_BRICKS.getDefaultState());
        structure.fillWithBlocks(world, start, -24, -33, -5, -24, -32, -4, Blocks.STONE_BRICKS.getDefaultState());
        structure.fillWithBlocks(world, start, -24, -33, -3, -24, -33, -2, Blocks.MOSSY_STONE_BRICKS.getDefaultState());
        structure.fillWithBlocks(world, start, -24, -33, -1, -24, -28, -1, Blocks.STONE_BRICKS.getDefaultState());
        structure.fillWithBlocks(world, start, -24, -33, 1, -21, -33, 4, Blocks.STONE_BRICKS.getDefaultState());
        structure.fillWithBlocks(world, start, -24, -33, 6, -23, -33, 6, Blocks.MOSSY_STONE_BRICKS.getDefaultState());
        structure.fillWithBlocks(world, start, -24, -33, 7, -23, -33, 8, Blocks.STONE_BRICKS.getDefaultState());
        structure.fillWithBlocks(world, start, -24, -33, 12, -22, -33, 14, Blocks.AIR.getDefaultState());
        structure.fillWithBlocks(world, start, -24, -33, 15, -24, -32, 15, Blocks.STONE_BRICKS.getDefaultState());
        structure.fillWithBlocks(world, start, -24, -33, 16, -20, -33, 20, Blocks.AIR.getDefaultState());
        structure.fillWithBlocks(world, start, -24, -33, 22, -22, -33, 24, Blocks.AIR.getDefaultState());
        structure.fillWithBlocks(world, start, -24, -33, 26, -23, -32, 26, Blocks.STONE_BRICKS.getDefaultState());
        structure.fillWithBlocks(world, start, -24, -32, -6, -24, -31, 1, Blocks.STONE_BRICKS.getDefaultState());
        structure.fillWithBlocks(world, start, -24, -32, 2, -24, -32, 3, Blocks.CRACKED_STONE_BRICKS.getDefaultState());
        structure.fillWithBlocks(world, start, -24, -32, 4, -22, -32, 6, Blocks.STONE_BRICKS.getDefaultState());
        structure.fillWithBlocks(world, start, -24, -32, 7, -24, -32, 8, Blocks.STONE_BRICKS.getDefaultState());
        structure.fillWithBlocks(world, start, -24, -32, 10, -24, -29, 10, Blocks.MOSSY_STONE_BRICKS.getDefaultState());
        structure.fillWithBlocks(world, start, -24, -32, 12, -22, -32, 14, Blocks.AIR.getDefaultState());
        structure.fillWithBlocks(world, start, -24, -32, 16, -20, -32, 20, Blocks.AIR.getDefaultState());
        structure.fillWithBlocks(world, start, -24, -32, 22, -22, -32, 24, Blocks.AIR.getDefaultState());
        structure.fillWithBlocks(world, start, -24, -31, 2, -24, -31, 2, Blocks.MOSSY_STONE_BRICKS.getDefaultState());
        structure.fillWithBlocks(world, start, -24, -31, 3, -24, -30, 3, Blocks.STONE_BRICKS.getDefaultState());
        structure.fillWithBlocks(world, start, -24, -31, 4, -24, -30, 4, Blocks.MOSSY_STONE_BRICKS.getDefaultState());
        structure.fillWithBlocks(world, start, -24, -31, 6, -24, -31, 8, Blocks.STONE_BRICKS.getDefaultState());
        structure.fillWithBlocks(world, start, -24, -31, 12, -24, -31, 14, Blocks.STONE_BRICKS.getDefaultState());
        structure.fillWithBlocks(world, start, -24, -31, 17, -24, -31, 18, Blocks.MOSSY_STONE_BRICKS.getDefaultState());
        structure.fillWithBlocks(world, start, -24, -31, 20, -24, -29, 23, Blocks.STONE_BRICKS.getDefaultState());
        structure.fillWithBlocks(world, start, -24, -30, -43, -24, -29, -40, Blocks.STONE_BRICKS.getDefaultState());
        structure.fillWithBlocks(world, start, -24, -30, -39, -24, -30, -38, Blocks.STONE_BRICKS.getDefaultState());
        structure.fillWithBlocks(world, start, -24, -30, -36, -24, -30, -31, Blocks.STONE_BRICKS.getDefaultState());
        structure.fillWithBlocks(world, start, -24, -30, -29, -23, -30, -28, Blocks.STONE_BRICKS.getDefaultState());
        structure.fillWithBlocks(world, start, -24, -30, -27, -24, -27, -27, Blocks.STONE_BRICKS.getDefaultState());
        structure.fillWithBlocks(world, start, -24, -30, -26, -24, -30, -25, Blocks.MOSSY_STONE_BRICKS.getDefaultState());
        structure.fillWithBlocks(world, start, -24, -30, -23, -16, -30, -23, Blocks.STONE_BRICKS.getDefaultState());
        structure.fillWithBlocks(world, start, -24, -30, -6, -24, -30, -6, Blocks.MOSSY_STONE_BRICKS.getDefaultState());
        structure.fillWithBlocks(world, start, -24, -30, -5, -24, -30, -3, Blocks.STONE_BRICKS.getDefaultState());
        structure.fillWithBlocks(world, start, -24, -30, 0, -22, -30, 2, Blocks.STONE_BRICKS.getDefaultState());
        structure.fillWithBlocks(world, start, -24, -30, 6, -24, -29, 6, Blocks.MOSSY_STONE_BRICKS.getDefaultState());
        structure.fillWithBlocks(world, start, -24, -30, 7, -24, -30, 7, Blocks.STONE_BRICKS.getDefaultState());
        structure.fillWithBlocks(world, start, -24, -30, 8, -24, -29, 8, Blocks.MOSSY_STONE_BRICKS.getDefaultState());
        structure.fillWithBlocks(world, start, -24, -30, 15, -23, -30, 15, Blocks.STONE_BRICKS.getDefaultState());
        structure.fillWithBlocks(world, start, -24, -30, 16, -22, -30, 16, Blocks.MOSSY_STONE_BRICKS.getDefaultState());
        structure.fillWithBlocks(world, start, -24, -30, 17, -23, -30, 18, Blocks.STONE_BRICKS.getDefaultState());
        structure.fillWithBlocks(world, start, -24, -30, 19, -24, -30, 19, Blocks.MOSSY_STONE_BRICKS.getDefaultState());
        structure.fillWithBlocks(world, start, -24, -30, 25, -24, -30, 26, Blocks.MOSSY_STONE_BRICKS.getDefaultState());
        structure.fillWithBlocks(world, start, -24, -29, -36, -24, -29, -35, Blocks.STONE_BRICKS.getDefaultState());
        structure.fillWithBlocks(world, start, -24, -29, -34, -24, -29, -32, Blocks.MOSSY_STONE_BRICKS.getDefaultState());
        structure.fillWithBlocks(world, start, -24, -29, -31, -22, -29, -29, Blocks.STONE_BRICKS.getDefaultState());
        structure.fillWithBlocks(world, start, -24, -29, -26, -24, -29, -23, Blocks.STONE_BRICKS.getDefaultState());
        structure.fillWithBlocks(world, start, -24, -29, -6, -24, -29, -6, Blocks.STONE_BRICKS.getDefaultState());
        structure.fillWithBlocks(world, start, -24, -29, -5, -24, -28, -5, Blocks.MOSSY_STONE_BRICKS.getDefaultState());
        structure.fillWithBlocks(world, start, -24, -29, -3, -24, -28, -3, Blocks.MOSSY_STONE_BRICKS.getDefaultState());
        structure.fillWithBlocks(world, start, -24, -29, -2, -23, -29, 0, Blocks.STONE_BRICKS.getDefaultState());
        structure.fillWithBlocks(world, start, -24, -29, 1, -24, -29, 3, Blocks.MOSSY_STONE_BRICKS.getDefaultState());
        structure.fillWithBlocks(world, start, -24, -29, 4, -23, -29, 5, Blocks.STONE_BRICKS.getDefaultState());
        structure.fillWithBlocks(world, start, -24, -29, 7, -24, -21, 7, Blocks.STONE_BRICKS.getDefaultState());
        structure.fillWithBlocks(world, start, -24, -29, 14, -24, -29, 14, Blocks.STONE_BRICKS.getDefaultState());
        structure.fillWithBlocks(world, start, -24, -29, 16, -24, -29, 23, Blocks.STONE_BRICKS.getDefaultState());
        structure.fillWithBlocks(world, start, -24, -29, 25, -24, -29, 25, Blocks.STONE_BRICKS.getDefaultState());
        structure.fillWithBlocks(world, start, -24, -29, 26, -24, -28, 26, Blocks.MOSSY_STONE_BRICKS.getDefaultState());
        structure.fillWithBlocks(world, start, -24, -28, -43, -24, -28, -43, Blocks.STONE_BRICKS.getDefaultState());
        structure.fillWithBlocks(world, start, -24, -28, -42, -24, -28, -42, Blocks.MOSSY_STONE_BRICKS.getDefaultState());
        structure.fillWithBlocks(world, start, -24, -28, -41, -24, -28, -41, Blocks.STONE_BRICKS.getDefaultState());
        structure.fillWithBlocks(world, start, -24, -28, -39, -23, -28, -38, Blocks.STONE_BRICKS.getDefaultState());
        structure.fillWithBlocks(world, start, -24, -28, -37, -24, -27, -37, Blocks.STONE_BRICKS.getDefaultState());
        structure.fillWithBlocks(world, start, -24, -28, -35, -24, -27, -34, Blocks.STONE_BRICKS.getDefaultState());
        structure.fillWithBlocks(world, start, -24, -28, -33, -23, -28, -32, Blocks.STONE_BRICKS.getDefaultState());
        structure.fillWithBlocks(world, start, -24, -28, -31, -24, -28, -27, Blocks.STONE_BRICKS.getDefaultState());
        structure.fillWithBlocks(world, start, -24, -28, -26, -24, -28, -25, Blocks.MOSSY_STONE_BRICKS.getDefaultState());
        structure.fillWithBlocks(world, start, -24, -28, -6, -24, -23, -6, Blocks.STONE_BRICKS.getDefaultState());
        structure.fillWithBlocks(world, start, -24, -28, -4, -24, -28, -3, Blocks.MOSSY_STONE_BRICKS.getDefaultState());
        structure.fillWithBlocks(world, start, -24, -28, -2, -23, -28, -1, Blocks.STONE_BRICKS.getDefaultState());
        structure.fillWithBlocks(world, start, -24, -28, 0, -24, -28, 0, Blocks.MOSSY_STONE_BRICKS.getDefaultState());
        structure.fillWithBlocks(world, start, -24, -28, 1, -24, -26, 3, Blocks.STONE_BRICKS.getDefaultState());
        structure.fillWithBlocks(world, start, -24, -28, 4, -24, -28, 5, Blocks.MOSSY_STONE_BRICKS.getDefaultState());
        structure.fillWithBlocks(world, start, -24, -28, 6, -23, -28, 7, Blocks.STONE_BRICKS.getDefaultState());
        structure.fillWithBlocks(world, start, -24, -28, 8, -24, -27, 8, Blocks.STONE_BRICKS.getDefaultState());
        structure.fillWithBlocks(world, start, -24, -28, 12, -23, -28, 13, Blocks.STONE_BRICKS.getDefaultState());
        structure.fillWithBlocks(world, start, -24, -28, 15, -23, -28, 16, Blocks.STONE_BRICKS.getDefaultState());
        structure.fillWithBlocks(world, start, -24, -28, 18, -24, -28, 18, Blocks.MOSSY_STONE_BRICKS.getDefaultState());
        structure.fillWithBlocks(world, start, -24, -28, 20, -24, -27, 20, Blocks.MOSSY_STONE_BRICKS.getDefaultState());
        structure.fillWithBlocks(world, start, -24, -28, 22, -24, -27, 22, Blocks.STONE_BRICKS.getDefaultState());
        structure.fillWithBlocks(world, start, -24, -28, 24, -24, -27, 24, Blocks.STONE_BRICKS.getDefaultState());
        structure.fillWithBlocks(world, start, -24, -28, 25, -24, -28, 26, Blocks.MOSSY_STONE_BRICKS.getDefaultState());
        structure.fillWithBlocks(world, start, -24, -27, -43, -24, -27, -42, Blocks.STONE_BRICKS.getDefaultState());
        structure.fillWithBlocks(world, start, -24, -27, -41, -24, -27, -41, Blocks.MOSSY_STONE_BRICKS.getDefaultState());
        structure.fillWithBlocks(world, start, -24, -27, -40, -24, -27, -39, Blocks.STONE_BRICKS.getDefaultState());
        structure.fillWithBlocks(world, start, -24, -27, -36, -23, -27, -35, Blocks.STONE_BRICKS.getDefaultState());
        structure.fillWithBlocks(world, start, -24, -27, -33, -23, -27, -33, Blocks.MOSSY_STONE_BRICKS.getDefaultState());
        structure.fillWithBlocks(world, start, -24, -27, -32, -23, -27, -31, Blocks.STONE_BRICKS.getDefaultState());
        structure.fillWithBlocks(world, start, -24, -27, -30, -24, -27, -28, Blocks.MOSSY_STONE_BRICKS.getDefaultState());
        structure.fillWithBlocks(world, start, -24, -27, -26, -23, -27, -24, Blocks.STONE_BRICKS.getDefaultState());
        structure.fillWithBlocks(world, start, -24, -27, -23, -23, -27, -23, Blocks.MOSSY_STONE_BRICKS.getDefaultState());
        structure.fillWithBlocks(world, start, -24, -27, -5, -24, -26, -5, Blocks.CRACKED_STONE_BRICKS.getDefaultState());
        structure.fillWithBlocks(world, start, -24, -27, -4, -24, -26, -2, Blocks.STONE_BRICKS.getDefaultState());
        structure.fillWithBlocks(world, start, -24, -27, 0, -23, -27, 0, Blocks.CRACKED_STONE_BRICKS.getDefaultState());
        structure.fillWithBlocks(world, start, -24, -27, 4, -23, -26, 4, Blocks.STONE_BRICKS.getDefaultState());
        structure.fillWithBlocks(world, start, -24, -27, 5, -24, -27, 5, Blocks.MOSSY_STONE_BRICKS.getDefaultState());
        structure.fillWithBlocks(world, start, -24, -27, 6, -24, -27, 8, Blocks.STONE_BRICKS.getDefaultState());
        structure.fillWithBlocks(world, start, -24, -27, 10, -23, -27, 10, Blocks.MOSSY_STONE_BRICKS.getDefaultState());
        structure.fillWithBlocks(world, start, -24, -27, 12, -22, -27, 12, Blocks.MOSSY_STONE_BRICKS.getDefaultState());
        structure.fillWithBlocks(world, start, -24, -27, 13, -24, -27, 14, Blocks.STONE_BRICKS.getDefaultState());
        structure.fillWithBlocks(world, start, -24, -27, 16, -22, -27, 18, Blocks.STONE_BRICKS.getDefaultState());
        structure.fillWithBlocks(world, start, -24, -27, 19, -24, -27, 19, Blocks.STONE_BRICKS.getDefaultState());
        structure.fillWithBlocks(world, start, -24, -26, 29, -23, -26, 32, Blocks.STONE_BRICKS.getDefaultState());
        structure.fillWithBlocks(world, start, -24, -26, 56, -24, -26, 58, Blocks.CRACKED_STONE_BRICKS.getDefaultState());
        structure.fillWithBlocks(world, start, -24, -26, 59, -21, -26, 62, Blocks.STONE_BRICKS.getDefaultState());
        structure.fillWithBlocks(world, start, -24, -26, 63, -22, -26, 67, Blocks.STONE_BRICKS.getDefaultState());
        structure.fillWithBlocks(world, start, -24, -26, 74, -24, -26, 75, Blocks.STONE_BRICKS.getDefaultState());
        structure.fillWithBlocks(world, start, -24, -26, 76, -23, -26, 76, Blocks.CRACKED_STONE_BRICKS.getDefaultState());
        structure.fillWithBlocks(world, start, -24, -26, 77, -21, -26, 80, Blocks.STONE_BRICKS.getDefaultState());
        structure.fillWithBlocks(world, start, -24, -26, 81, -22, -26, 85, Blocks.STONE_BRICKS.getDefaultState());
        structure.fillWithBlocks(world, start, -24, -25, -5, -24, -25, -4, Blocks.STONE_BRICKS.getDefaultState());
        structure.fillWithBlocks(world, start, -24, -25, -3, -21, -25, 0, Blocks.AIR.getDefaultState());
        structure.fillWithBlocks(world, start, -24, -25, 1, -23, -25, 5, Blocks.AIR.getDefaultState());
        structure.fillWithBlocks(world, start, -24, -25, 6, -24, -25, 7, Blocks.STONE_BRICKS.getDefaultState());
        structure.fillWithBlocks(world, start, -24, -25, 29, -24, -22, 29, Blocks.STONE_BRICKS.getDefaultState());
        structure.fillWithBlocks(world, start, -24, -25, 33, -24, -23, 33, Blocks.STONE_BRICKS.getDefaultState());
        structure.fillWithBlocks(world, start, -24, -25, 56, -24, -25, 56, Blocks.CRACKED_STONE_BRICKS.getDefaultState());
        structure.fillWithBlocks(world, start, -24, -25, 57, -24, -23, 57, Blocks.STONE_BRICKS.getDefaultState());
        structure.fillWithBlocks(world, start, -24, -25, 70, -24, -25, 70, Blocks.STONE_BRICKS.getDefaultState());
        structure.fillWithBlocks(world, start, -24, -25, 72, -24, -25, 73, Blocks.STONE_BRICKS.getDefaultState());
        structure.fillWithBlocks(world, start, -24, -25, 75, -24, -25, 75, Blocks.STONE_BRICKS.getDefaultState());
        structure.fillWithBlocks(world, start, -24, -24, -4, -24, -22, -4, Blocks.STONE_BRICKS.getDefaultState());
        structure.fillWithBlocks(world, start, -24, -24, -3, -18, -24, 5, Blocks.AIR.getDefaultState());
        structure.fillWithBlocks(world, start, -24, -24, 6, -24, -24, 8, Blocks.STONE_BRICKS.getDefaultState());
        structure.fillWithBlocks(world, start, -24, -24, 28, -24, -23, 29, Blocks.STONE_BRICKS.getDefaultState());
        structure.fillWithBlocks(world, start, -24, -24, 56, -24, -23, 57, Blocks.STONE_BRICKS.getDefaultState());
        structure.fillWithBlocks(world, start, -24, -24, 74, -24, -22, 74, Blocks.STONE_BRICKS.getDefaultState());
        structure.fillWithBlocks(world, start, -24, -24, 87, -24, -24, 88, Blocks.STONE_BRICKS.getDefaultState());
        structure.fillWithBlocks(world, start, -24, -23, -5, -24, -22, -4, Blocks.STONE_BRICKS.getDefaultState());
        structure.fillWithBlocks(world, start, -24, -23, -3, -18, -23, 5, Blocks.AIR.getDefaultState());
        structure.fillWithBlocks(world, start, -24, -23, 6, -24, -21, 8, Blocks.STONE_BRICKS.getDefaultState());
        structure.fillWithBlocks(world, start, -24, -23, 72, -24, -23, 73, Blocks.MOSSY_STONE_BRICKS.getDefaultState());
        structure.fillWithBlocks(world, start, -24, -23, 75, -24, -23, 75, Blocks.STONE_BRICKS.getDefaultState());
        structure.fillWithBlocks(world, start, -24, -23, 88, -24, -22, 88, Blocks.CRACKED_STONE_BRICKS.getDefaultState());
        structure.fillWithBlocks(world, start, -24, -22, -3, -18, -22, 5, Blocks.AIR.getDefaultState());
        structure.fillWithBlocks(world, start, -24, -22, 30, -23, -22, 32, Blocks.STONE_BRICKS.getDefaultState());
        structure.fillWithBlocks(world, start, -24, -22, 56, -24, -22, 56, Blocks.STONE_BRICKS.getDefaultState());
        structure.fillWithBlocks(world, start, -24, -22, 70, -24, -22, 70, Blocks.STONE_BRICKS.getDefaultState());
        structure.fillWithBlocks(world, start, -24, -21, -6, -23, -21, -5, Blocks.STONE_BRICKS.getDefaultState());
        structure.fillWithBlocks(world, start, -24, -21, -4, -23, -21, -4, Blocks.CRACKED_STONE_BRICKS.getDefaultState());
        structure.fillWithBlocks(world, start, -24, -21, -3, -23, -20, -3, Blocks.STONE_BRICKS.getDefaultState());
        structure.fillWithBlocks(world, start, -24, -21, 56, -24, -21, 59, Blocks.STONE_BRICKS.getDefaultState());
        structure.fillWithBlocks(world, start, -24, -21, 60, -18, -21, 66, Blocks.AIR.getDefaultState());
        structure.fillWithBlocks(world, start, -24, -21, 68, -24, -21, 68, Blocks.CRACKED_STONE_BRICKS.getDefaultState());
        structure.fillWithBlocks(world, start, -24, -21, 74, -24, -19, 74, Blocks.CRACKED_STONE_BRICKS.getDefaultState());
        structure.fillWithBlocks(world, start, -24, -21, 75, -24, -21, 76, Blocks.STONE_BRICKS.getDefaultState());
        structure.fillWithBlocks(world, start, -24, -21, 77, -24, -20, 77, Blocks.CRACKED_STONE_BRICKS.getDefaultState());
        structure.fillWithBlocks(world, start, -24, -21, 78, -18, -21, 84, Blocks.AIR.getDefaultState());
        structure.fillWithBlocks(world, start, -24, -21, 85, -23, -20, 85, Blocks.STONE_BRICKS.getDefaultState());
        structure.fillWithBlocks(world, start, -24, -21, 86, -23, -20, 86, Blocks.CRACKED_STONE_BRICKS.getDefaultState());
        structure.fillWithBlocks(world, start, -24, -20, -6, -24, -20, -6, Blocks.CRACKED_STONE_BRICKS.getDefaultState());
        structure.fillWithBlocks(world, start, -24, -20, -5, -24, -20, 3, Blocks.STONE_BRICKS.getDefaultState());
        structure.fillWithBlocks(world, start, -24, -20, 4, -24, -20, 4, Blocks.CRACKED_STONE_BRICKS.getDefaultState());
        structure.fillWithBlocks(world, start, -24, -20, 5, -24, -20, 6, Blocks.STONE_BRICKS.getDefaultState());
        structure.fillWithBlocks(world, start, -24, -20, 8, -24, -18, 8, Blocks.CRACKED_STONE_BRICKS.getDefaultState());
        structure.fillWithBlocks(world, start, -24, -20, 56, -24, -19, 56, Blocks.STONE_BRICKS.getDefaultState());
        structure.fillWithBlocks(world, start, -24, -20, 58, -24, -19, 58, Blocks.STONE_BRICKS.getDefaultState());
        structure.fillWithBlocks(world, start, -24, -20, 59, -24, -20, 60, Blocks.CRACKED_STONE_BRICKS.getDefaultState());
        structure.fillWithBlocks(world, start, -24, -20, 61, -24, -20, 64, Blocks.STONE_BRICKS.getDefaultState());
        structure.fillWithBlocks(world, start, -24, -20, 67, -24, -19, 68, Blocks.STONE_BRICKS.getDefaultState());
        structure.fillWithBlocks(world, start, -24, -20, 76, -24, -18, 76, Blocks.STONE_BRICKS.getDefaultState());
        structure.fillWithBlocks(world, start, -24, -20, 81, -23, -20, 81, Blocks.CRACKED_STONE_BRICKS.getDefaultState());
        structure.fillWithBlocks(world, start, -24, -20, 82, -23, -20, 83, Blocks.STONE_BRICKS.getDefaultState());
        structure.fillWithBlocks(world, start, -24, -19, -6, -24, -19, -6, Blocks.STONE_BRICKS.getDefaultState());
        structure.fillWithBlocks(world, start, -24, -19, -5, -24, -17, -5, Blocks.CRACKED_STONE_BRICKS.getDefaultState());
        structure.fillWithBlocks(world, start, -24, -19, -4, -24, -19, -3, Blocks.STONE_BRICKS.getDefaultState());
        structure.fillWithBlocks(world, start, -24, -19, -2, -24, -19, -1, Blocks.CRACKED_STONE_BRICKS.getDefaultState());
        structure.fillWithBlocks(world, start, -24, -19, 0, -24, -19, 1, Blocks.STONE_BRICKS.getDefaultState());
        structure.fillWithBlocks(world, start, -24, -19, 3, -23, -19, 3, Blocks.STONE_BRICKS.getDefaultState());
        structure.fillWithBlocks(world, start, -24, -19, 5, -24, -17, 5, Blocks.CRACKED_STONE_BRICKS.getDefaultState());
        structure.fillWithBlocks(world, start, -24, -19, 7, -24, -19, 8, Blocks.CRACKED_STONE_BRICKS.getDefaultState());
        structure.fillWithBlocks(world, start, -24, -19, 60, -20, -19, 60, Blocks.STONE_BRICKS.getDefaultState());
        structure.fillWithBlocks(world, start, -24, -19, 61, -23, -19, 61, Blocks.CRACKED_STONE_BRICKS.getDefaultState());
        structure.fillWithBlocks(world, start, -24, -19, 62, -24, -19, 63, Blocks.STONE_BRICKS.getDefaultState());
        structure.fillWithBlocks(world, start, -24, -19, 69, -24, -19, 69, Blocks.CRACKED_STONE_BRICKS.getDefaultState());
        structure.fillWithBlocks(world, start, -24, -19, 75, -24, -19, 85, Blocks.STONE_BRICKS.getDefaultState());
        structure.fillWithBlocks(world, start, -24, -19, 87, -24, -19, 87, Blocks.STONE_BRICKS.getDefaultState());
        structure.fillWithBlocks(world, start, -24, -18, -6, -24, -18, -4, Blocks.CRACKED_STONE_BRICKS.getDefaultState());
        structure.fillWithBlocks(world, start, -24, -18, -3, -24, -18, -2, Blocks.STONE_BRICKS.getDefaultState());
        structure.fillWithBlocks(world, start, -24, -18, -1, -24, -18, 0, Blocks.MOSSY_STONE_BRICKS.getDefaultState());
        structure.fillWithBlocks(world, start, -24, -18, 1, -24, -18, 2, Blocks.STONE_BRICKS.getDefaultState());
        structure.fillWithBlocks(world, start, -24, -18, 3, -24, -17, 3, Blocks.CRACKED_STONE_BRICKS.getDefaultState());
        structure.fillWithBlocks(world, start, -24, -18, 6, -24, -18, 6, Blocks.CRACKED_STONE_BRICKS.getDefaultState());
        structure.fillWithBlocks(world, start, -24, -18, 7, -24, -17, 7, Blocks.MOSSY_STONE_BRICKS.getDefaultState());
        structure.fillWithBlocks(world, start, -24, -18, 57, -24, -18, 57, Blocks.STONE_BRICKS.getDefaultState());
        structure.fillWithBlocks(world, start, -24, -18, 60, -24, -18, 62, Blocks.MOSSY_STONE_BRICKS.getDefaultState());
        structure.fillWithBlocks(world, start, -24, -18, 63, -24, -17, 63, Blocks.STONE_BRICKS.getDefaultState());
        structure.fillWithBlocks(world, start, -24, -18, 65, -23, -17, 65, Blocks.STONE_BRICKS.getDefaultState());
        structure.fillWithBlocks(world, start, -24, -18, 66, -23, -18, 66, Blocks.CRACKED_STONE_BRICKS.getDefaultState());
        structure.fillWithBlocks(world, start, -24, -18, 67, -24, -18, 67, Blocks.STONE_BRICKS.getDefaultState());
        structure.fillWithBlocks(world, start, -24, -18, 69, -23, -18, 69, Blocks.MOSSY_STONE_BRICKS.getDefaultState());
        structure.fillWithBlocks(world, start, -24, -18, 74, -23, -18, 74, Blocks.STONE_BRICKS.getDefaultState());
        structure.fillWithBlocks(world, start, -24, -18, 75, -23, -18, 75, Blocks.MOSSY_STONE_BRICKS.getDefaultState());
        structure.fillWithBlocks(world, start, -24, -18, 77, -24, -18, 79, Blocks.STONE_BRICKS.getDefaultState());
        structure.fillWithBlocks(world, start, -24, -18, 82, -24, -18, 82, Blocks.CRACKED_STONE_BRICKS.getDefaultState());
        structure.fillWithBlocks(world, start, -24, -18, 83, -24, -18, 88, Blocks.STONE_BRICKS.getDefaultState());
        structure.fillWithBlocks(world, start, -24, -17, -6, -24, -17, -6, Blocks.STONE_BRICKS.getDefaultState());
        structure.fillWithBlocks(world, start, -24, -17, -4, -24, -17, -3, Blocks.CRACKED_STONE_BRICKS.getDefaultState());
        structure.fillWithBlocks(world, start, -24, -17, -2, -21, -17, -2, Blocks.STONE_BRICKS.getDefaultState());
        structure.fillWithBlocks(world, start, -24, -17, 0, -24, -17, 2, Blocks.STONE_BRICKS.getDefaultState());
        structure.fillWithBlocks(world, start, -24, -17, 6, -22, -17, 6, Blocks.STONE_BRICKS.getDefaultState());
        structure.fillWithBlocks(world, start, -24, -17, 56, -24, -17, 56, Blocks.STONE_BRICKS.getDefaultState());
        structure.fillWithBlocks(world, start, -24, -17, 57, -24, -17, 57, Blocks.CRACKED_STONE_BRICKS.getDefaultState());
        structure.fillWithBlocks(world, start, -24, -17, 60, -24, -17, 60, Blocks.STONE_BRICKS.getDefaultState());
        structure.fillWithBlocks(world, start, -24, -17, 62, -23, -17, 63, Blocks.STONE_BRICKS.getDefaultState());
        structure.fillWithBlocks(world, start, -24, -17, 64, -24, -17, 66, Blocks.STONE_BRICKS.getDefaultState());
        structure.fillWithBlocks(world, start, -24, -17, 68, -24, -17, 69, Blocks.STONE_BRICKS.getDefaultState());
        structure.fillWithBlocks(world, start, -24, -17, 77, -24, -17, 77, Blocks.STONE_BRICKS.getDefaultState());
        structure.fillWithBlocks(world, start, -24, -17, 80, -23, -17, 80, Blocks.MOSSY_STONE_BRICKS.getDefaultState());
        structure.fillWithBlocks(world, start, -24, -17, 82, -23, -17, 83, Blocks.STONE_BRICKS.getDefaultState());
        structure.fillWithBlocks(world, start, -24, -17, 86, -24, -17, 86, Blocks.STONE_BRICKS.getDefaultState());
        structure.fillWithBlocks(world, start, -24, -17, 87, -24, -17, 88, Blocks.CRACKED_STONE_BRICKS.getDefaultState());
        structure.fillWithBlocks(world, start, -24, -16, 25, -24, -16, 25, Blocks.STONE_BRICKS.getDefaultState());
        structure.fillWithBlocks(world, start, -24, -16, 26, -24, -16, 27, Blocks.MOSSY_STONE_BRICKS.getDefaultState());
        structure.fillWithBlocks(world, start, -24, -16, 28, -18, -16, 34, Blocks.STONE_BRICKS.getDefaultState());
        structure.fillWithBlocks(world, start, -24, -16, 37, -23, -16, 38, Blocks.STONE_BRICKS.getDefaultState());
        structure.fillWithBlocks(world, start, -24, -15, 24, -23, -15, 25, Blocks.STONE_BRICKS.getDefaultState());
        structure.fillWithBlocks(world, start, -24, -15, 26, -24, -15, 36, Blocks.AIR.getDefaultState());
        structure.fillWithBlocks(world, start, -24, -15, 37, -23, -15, 38, Blocks.STONE_BRICKS.getDefaultState());
        structure.fillWithBlocks(world, start, -24, -14, 24, -23, -14, 25, Blocks.STONE_BRICKS.getDefaultState());
        structure.fillWithBlocks(world, start, -24, -14, 31, -21, -14, 35, Blocks.AIR.getDefaultState());
        structure.fillWithBlocks(world, start, -24, -14, 37, -23, -14, 38, Blocks.STONE_BRICKS.getDefaultState());
        structure.fillWithBlocks(world, start, -24, -13, 37, -23, -13, 38, Blocks.STONE_BRICKS.getDefaultState());
        structure.fillWithBlocks(world, start, -24, -11, 24, -21, -11, 27, Blocks.STONE_BRICKS.getDefaultState());
        structure.fillWithBlocks(world, start, -24, -10, 30, -24, -10, 30, Blocks.STONE_BRICKS.getDefaultState());
        structure.fillWithBlocks(world, start, -24, -9, 27, -23, -9, 32, Blocks.STONE_BRICKS.getDefaultState());
        structure.fillWithBlocks(world, start, -24, -9, 33, -24, -9, 34, Blocks.MOSSY_STONE_BRICKS.getDefaultState());
        structure.fillWithBlocks(world, start, -24, -8, 24, -23, -7, 24, Blocks.STONE_BRICKS.getDefaultState());
        structure.fillWithBlocks(world, start, -24, -8, 25, -23, -8, 25, Blocks.MOSSY_STONE_BRICKS.getDefaultState());
        structure.fillWithBlocks(world, start, -24, -8, 26, -23, -8, 33, Blocks.STONE_BRICKS.getDefaultState());
        structure.fillWithBlocks(world, start, -24, -8, 34, -24, -8, 38, Blocks.STONE_BRICKS.getDefaultState());
        structure.fillWithBlocks(world, start, -24, -7, 27, -24, -7, 35, Blocks.STONE_BRICKS.getDefaultState());
        structure.fillWithBlocks(world, start, -24, -7, 37, -23, -7, 38, Blocks.STONE_BRICKS.getDefaultState());
        structure.fillWithBlocks(world, start, -23, -56, -8, -23, -56, -8, Blocks.AIR.getDefaultState());
        structure.fillWithBlocks(world, start, -23, -56, -7, -23, -56, 5, Blocks.STONE_BRICKS.getDefaultState());
        structure.fillWithBlocks(world, start, -23, -56, 6, -23, -55, 6, Blocks.AIR.getDefaultState());
        structure.fillWithBlocks(world, start, -23, -55, -15, -22, -55, -14, Blocks.STONE_BRICKS.getDefaultState());
        structure.fillWithBlocks(world, start, -23, -55, -13, -23, -47, -13, Blocks.STONE_BRICKS.getDefaultState());
        structure.fillWithBlocks(world, start, -23, -55, -3, -23, -54, 5, Blocks.STONE_BRICKS.getDefaultState());
        structure.fillWithBlocks(world, start, -23, -55, 7, -21, -55, 9, Blocks.STONE_BRICKS.getDefaultState());
        structure.fillWithBlocks(world, start, -23, -54, -14, -20, -54, -7, Blocks.STONE_BRICKS.getDefaultState());
        structure.fillWithBlocks(world, start, -23, -54, -6, -23, -52, -4, Blocks.STONE_BRICKS.getDefaultState());
        structure.fillWithBlocks(world, start, -23, -53, -15, -18, -53, -7, Blocks.STONE_BRICKS.getDefaultState());
        structure.fillWithBlocks(world, start, -23, -53, -2, -23, -51, 0, Blocks.STONE_BRICKS.getDefaultState());
        structure.fillWithBlocks(world, start, -23, -53, 1, -20, -53, 4, Blocks.STONE_BRICKS.getDefaultState());
        structure.fillWithBlocks(world, start, -23, -52, 8, -23, -52, 9, Blocks.AIR.getDefaultState());
        structure.fillWithBlocks(world, start, -23, -51, -15, -20, -51, -11, Blocks.STONE_BRICKS.getDefaultState());
        structure.fillWithBlocks(world, start, -23, -51, -9, -23, -51, -9, Blocks.STONE_BRICKS.getDefaultState());
        structure.fillWithBlocks(world, start, -23, -51, -7, -22, -51, -6, Blocks.STONE_BRICKS.getDefaultState());
        structure.fillWithBlocks(world, start, -23, -51, -5, -23, -47, -1, Blocks.STONE_BRICKS.getDefaultState());
        structure.fillWithBlocks(world, start, -23, -51, 2, -19, -51, 9, Blocks.STONE_BRICKS.getDefaultState());
        structure.fillWithBlocks(world, start, -23, -50, -14, -19, -50, -10, Blocks.STONE_BRICKS.getDefaultState());
        structure.fillWithBlocks(world, start, -23, -49, -11, -20, -49, -1, Blocks.STONE_BRICKS.getDefaultState());
        structure.fillWithBlocks(world, start, -23, -49, 1, -21, -49, 9, Blocks.STONE_BRICKS.getDefaultState());
        structure.fillWithBlocks(world, start, -23, -48, 0, -18, -48, 9, Blocks.STONE_BRICKS.getDefaultState());
        structure.fillWithBlocks(world, start, -23, -46, -11, -23, -46, -9, Blocks.STONE_BRICKS.getDefaultState());
        structure.fillWithBlocks(world, start, -23, -46, -7, -22, -46, -6, Blocks.STONE_BRICKS.getDefaultState());
        structure.fillWithBlocks(world, start, -23, -46, -5, -23, -45, -5, Blocks.STONE_BRICKS.getDefaultState());
        structure.fillWithBlocks(world, start, -23, -46, -4, -23, -44, -4, Blocks.MOSSY_STONE_BRICKS.getDefaultState());
        structure.fillWithBlocks(world, start, -23, -46, -3, -22, -46, -3, Blocks.STONE_BRICKS.getDefaultState());
        structure.fillWithBlocks(world, start, -23, -46, -1, -23, -43, -1, Blocks.STONE_BRICKS.getDefaultState());
        structure.fillWithBlocks(world, start, -23, -46, 0, -23, -46, 0, Blocks.MOSSY_COBBLESTONE.getDefaultState());
        structure.fillWithBlocks(world, start, -23, -46, 1, -23, -46, 1, Blocks.MOSSY_STONE_BRICKS.getDefaultState());
        structure.fillWithBlocks(world, start, -23, -46, 3, -23, -46, 3, Blocks.MOSSY_STONE_BRICKS.getDefaultState());
        structure.fillWithBlocks(world, start, -23, -46, 4, -23, -45, 4, Blocks.AIR.getDefaultState());
        structure.fillWithBlocks(world, start, -23, -46, 5, -23, -46, 8, Blocks.STONE_BRICKS.getDefaultState());
        structure.fillWithBlocks(world, start, -23, -46, 10, -23, -46, 11, Blocks.STONE_BRICKS.getDefaultState());
        structure.fillWithBlocks(world, start, -23, -46, 14, -23, -46, 15, Blocks.MOSSY_STONE_BRICKS.getDefaultState());
        structure.fillWithBlocks(world, start, -23, -46, 16, -23, -46, 17, Blocks.STONE_BRICKS.getDefaultState());
        structure.fillWithBlocks(world, start, -23, -46, 19, -23, -46, 21, Blocks.STONE_BRICKS.getDefaultState());
        structure.fillWithBlocks(world, start, -23, -45, -11, -23, -45, -10, Blocks.STONE_BRICKS.getDefaultState());
        structure.fillWithBlocks(world, start, -23, -45, -9, -23, -44, -9, Blocks.MOSSY_STONE_BRICKS.getDefaultState());
        structure.fillWithBlocks(world, start, -23, -45, -8, -23, -45, -8, Blocks.STONE_BRICKS.getDefaultState());
        structure.fillWithBlocks(world, start, -23, -45, -6, -23, -45, -5, Blocks.STONE_BRICKS.getDefaultState());
        structure.fillWithBlocks(world, start, -23, -45, -2, -23, -45, -1, Blocks.STONE_BRICKS.getDefaultState());
        structure.fillWithBlocks(world, start, -23, -45, 3, -23, -45, 3, Blocks.STONE_BRICKS.getDefaultState());
        structure.fillWithBlocks(world, start, -23, -45, 5, -16, -45, 5, Blocks.STONE_BRICKS.getDefaultState());
