package mod.arcalitegames.odyssey.world.structure.structures.ruins.castle_ruins;

import mod.arcalitegames.odyssey.world.structure.StructureBase;
import net.minecraft.block.Blocks;
import net.minecraft.block.SlabBlock;
import net.minecraft.block.SnowyDirtBlock;
import net.minecraft.block.StairsBlock;
import net.minecraft.block.WallBlock;
import net.minecraft.block.WallHeight;
import net.minecraft.state.properties.Half;
import net.minecraft.state.properties.SlabType;
import net.minecraft.state.properties.StairsShape;
import net.minecraft.util.Direction;
import net.minecraft.util.math.BlockPos;
import net.minecraft.world.World;

public class CastleComponent8
{

	public static BlockPos start;
    public static World world;
    public static StructureBase structure;

    public static void init(World worldIn, BlockPos blockPos, StructureBase structureIn)
    {
        world = worldIn; start = blockPos; structure = structureIn;
    }
    
    public static void generatePart81()
    {
        structure.fillWithBlocks(world, start, 49, -47, 41, 50, -47, 46, Blocks.AIR.getDefaultState());
        structure.fillWithBlocks(world, start, 49, -47, 47, 49, -46, 47, Blocks.MOSSY_STONE_BRICKS.getDefaultState());
        structure.fillWithBlocks(world, start, 49, -47, 64, 52, -47, 67, Blocks.STONE_BRICKS.getDefaultState());
        structure.fillWithBlocks(world, start, 49, -46, -31, 49, -46, -30, Blocks.STONE_BRICKS.getDefaultState());
        structure.fillWithBlocks(world, start, 49, -46, -29, 49, -46, -28, Blocks.MOSSY_COBBLESTONE.getDefaultState());
        structure.fillWithBlocks(world, start, 49, -46, -4, 51, -46, 1, Blocks.STONE_BRICKS.getDefaultState());
        structure.fillWithBlocks(world, start, 49, -46, 2, 49, -46, 3, Blocks.STONE_BRICKS.getDefaultState());
        structure.fillWithBlocks(world, start, 49, -46, 8, 49, -46, 8, Blocks.MOSSY_STONE_BRICKS.getDefaultState());
        structure.fillWithBlocks(world, start, 49, -46, 10, 49, -46, 11, Blocks.MOSSY_COBBLESTONE.getDefaultState());
        structure.fillWithBlocks(world, start, 49, -46, 12, 49, -46, 12, Blocks.MOSSY_STONE_BRICKS.getDefaultState());
        structure.fillWithBlocks(world, start, 49, -46, 13, 49, -46, 13, Blocks.STONE_BRICKS.getDefaultState());
        structure.fillWithBlocks(world, start, 49, -46, 14, 49, -46, 17, Blocks.MOSSY_COBBLESTONE.getDefaultState());
        structure.fillWithBlocks(world, start, 49, -46, 21, 49, -46, 22, Blocks.MOSSY_COBBLESTONE.getDefaultState());
        structure.fillWithBlocks(world, start, 49, -46, 23, 49, -46, 25, Blocks.STONE_BRICKS.getDefaultState());
        structure.fillWithBlocks(world, start, 49, -46, 28, 49, -46, 29, Blocks.STONE_BRICKS.getDefaultState());
        structure.fillWithBlocks(world, start, 49, -46, 31, 49, -46, 33, Blocks.MOSSY_STONE_BRICKS.getDefaultState());
        structure.fillWithBlocks(world, start, 49, -46, 34, 49, -46, 36, Blocks.MOSSY_COBBLESTONE.getDefaultState());
        structure.fillWithBlocks(world, start, 49, -46, 43, 49, -46, 46, Blocks.STONE_BRICKS.getDefaultState());
        structure.fillWithBlocks(world, start, 49, -46, 48, 49, -45, 48, Blocks.MOSSY_STONE_BRICKS.getDefaultState());
        structure.fillWithBlocks(world, start, 49, -46, 49, 49, -46, 50, Blocks.STONE_BRICKS.getDefaultState());
        structure.fillWithBlocks(world, start, 49, -45, -32, 51, -45, -32, Blocks.STONE_BRICKS.getDefaultState());
        structure.fillWithBlocks(world, start, 49, -45, -31, 51, -45, -27, Blocks.AIR.getDefaultState());
        structure.fillWithBlocks(world, start, 49, -45, -9, 49, -45, -7, Blocks.STONE_BRICKS.getDefaultState());
        structure.fillWithBlocks(world, start, 49, -45, 1, 49, -45, 1, Blocks.STONE_BRICKS.getDefaultState());
        structure.fillWithBlocks(world, start, 49, -45, 3, 49, -44, 3, Blocks.MOSSY_COBBLESTONE.getDefaultState());
        structure.fillWithBlocks(world, start, 49, -45, 23, 49, -45, 23, Blocks.STONE_BRICKS.getDefaultState());
        structure.fillWithBlocks(world, start, 49, -45, 24, 49, -43, 26, Blocks.AIR.getDefaultState());
        structure.fillWithBlocks(world, start, 49, -45, 27, 49, -45, 27, Blocks.STONE_BRICKS.getDefaultState());
        structure.fillWithBlocks(world, start, 49, -45, 28, 49, -43, 28, Blocks.AIR.getDefaultState());
        structure.fillWithBlocks(world, start, 49, -45, 30, 49, -44, 31, Blocks.AIR.getDefaultState());
        structure.fillWithBlocks(world, start, 49, -45, 32, 51, -45, 32, Blocks.STONE_BRICKS.getDefaultState());
        structure.fillWithBlocks(world, start, 49, -45, 33, 51, -45, 37, Blocks.AIR.getDefaultState());
        structure.fillWithBlocks(world, start, 49, -45, 40, 50, -45, 46, Blocks.AIR.getDefaultState());
        structure.fillWithBlocks(world, start, 49, -45, 47, 50, -45, 47, Blocks.MOSSY_COBBLESTONE.getDefaultState());
        structure.fillWithBlocks(world, start, 49, -45, 49, 49, -43, 49, Blocks.STONE_BRICKS.getDefaultState());
        structure.fillWithBlocks(world, start, 49, -45, 50, 49, -44, 50, Blocks.MOSSY_STONE_BRICKS.getDefaultState());
        structure.fillWithBlocks(world, start, 49, -44, -32, 49, -43, -32, Blocks.STONE_BRICKS.getDefaultState());
        structure.fillWithBlocks(world, start, 49, -44, -31, 51, -44, -27, Blocks.AIR.getDefaultState());
        structure.fillWithBlocks(world, start, 49, -44, -26, 49, -43, -26, Blocks.STONE_BRICKS.getDefaultState());
        structure.fillWithBlocks(world, start, 49, -44, 1, 50, -44, 2, Blocks.STONE_BRICKS.getDefaultState());
        structure.fillWithBlocks(world, start, 49, -44, 23, 49, -44, 23, Blocks.STONE_BRICKS.getDefaultState());
        structure.fillWithBlocks(world, start, 49, -44, 29, 49, -42, 29, Blocks.STONE_BRICKS.getDefaultState());
        structure.fillWithBlocks(world, start, 49, -44, 33, 51, -44, 37, Blocks.AIR.getDefaultState());
        structure.fillWithBlocks(world, start, 49, -44, 39, 51, -44, 39, Blocks.MOSSY_COBBLESTONE.getDefaultState());
        structure.fillWithBlocks(world, start, 49, -44, 40, 50, -44, 46, Blocks.AIR.getDefaultState());
        structure.fillWithBlocks(world, start, 49, -44, 48, 50, -44, 49, Blocks.STONE_BRICKS.getDefaultState());
        structure.fillWithBlocks(world, start, 49, -43, -31, 51, -43, -27, Blocks.AIR.getDefaultState());
        structure.fillWithBlocks(world, start, 49, -43, -9, 49, -43, -9, Blocks.MOSSY_COBBLESTONE.getDefaultState());
        structure.fillWithBlocks(world, start, 49, -43, -8, 49, -42, -8, Blocks.MOSSY_STONE_BRICKS.getDefaultState());
        structure.fillWithBlocks(world, start, 49, -43, 1, 51, -41, 1, Blocks.STONE_BRICKS.getDefaultState());
        structure.fillWithBlocks(world, start, 49, -43, 2, 49, -43, 2, Blocks.MOSSY_STONE_BRICKS.getDefaultState());
        structure.fillWithBlocks(world, start, 49, -43, 3, 49, -43, 3, Blocks.STONE_BRICKS.getDefaultState());
        structure.fillWithBlocks(world, start, 49, -43, 23, 49, -43, 23, Blocks.STONE_BRICKS.getDefaultState());
        structure.fillWithBlocks(world, start, 49, -43, 27, 49, -43, 27, Blocks.STONE_BRICKS.getDefaultState());
        structure.fillWithBlocks(world, start, 49, -43, 30, 49, -43, 31, Blocks.AIR.getDefaultState());
        structure.fillWithBlocks(world, start, 49, -43, 32, 51, -43, 32, Blocks.STONE_BRICKS.getDefaultState());
        structure.fillWithBlocks(world, start, 49, -43, 33, 51, -43, 37, Blocks.AIR.getDefaultState());
        structure.fillWithBlocks(world, start, 49, -43, 47, 49, -43, 47, Blocks.STONE_BRICKS.getDefaultState());
        structure.fillWithBlocks(world, start, 49, -43, 50, 50, -42, 50, Blocks.STONE_BRICKS.getDefaultState());
        structure.fillWithBlocks(world, start, 49, -42, -31, 49, -42, -30, Blocks.STONE_BRICKS.getDefaultState());
        structure.fillWithBlocks(world, start, 49, -42, -29, 49, -42, -28, Blocks.MOSSY_STONE_BRICKS.getDefaultState());
        structure.fillWithBlocks(world, start, 49, -42, -6, 49, -42, -6, Blocks.STONE_BRICKS.getDefaultState());
        structure.fillWithBlocks(world, start, 49, -42, 0, 50, -42, 1, Blocks.STONE_BRICKS.getDefaultState());
        structure.fillWithBlocks(world, start, 49, -42, 24, 50, -42, 24, Blocks.MOSSY_COBBLESTONE.getDefaultState());
        structure.fillWithBlocks(world, start, 49, -42, 26, 49, -42, 28, Blocks.MOSSY_STONE_BRICKS.getDefaultState());
        structure.fillWithBlocks(world, start, 49, -42, 32, 49, -42, 34, Blocks.STONE_BRICKS.getDefaultState());
        structure.fillWithBlocks(world, start, 49, -42, 37, 53, -42, 37, Blocks.STONE_BRICKS.getDefaultState());
        structure.fillWithBlocks(world, start, 49, -42, 38, 49, -42, 39, Blocks.MOSSY_COBBLESTONE.getDefaultState());
        structure.fillWithBlocks(world, start, 49, -42, 47, 49, -42, 48, Blocks.MOSSY_COBBLESTONE.getDefaultState());
        structure.fillWithBlocks(world, start, 49, -41, -9, 49, -41, -9, Blocks.MOSSY_STONE_BRICKS.getDefaultState());
        structure.fillWithBlocks(world, start, 49, -41, -8, 49, -41, -6, Blocks.STONE_BRICKS.getDefaultState());
        structure.fillWithBlocks(world, start, 49, -41, -4, 49, -41, -2, Blocks.STONE_BRICK_STAIRS.getDefaultState().with(StairsBlock.FACING, Direction.EAST).with(StairsBlock.WATERLOGGED, false).with(StairsBlock.SHAPE, StairsShape.STRAIGHT).with(StairsBlock.HALF, Half.TOP));
        structure.fillWithBlocks(world, start, 49, -41, 0, 50, -41, 1, Blocks.STONE_BRICKS.getDefaultState());
        structure.fillWithBlocks(world, start, 49, -41, 2, 49, -39, 2, Blocks.MOSSY_STONE_BRICKS.getDefaultState());
        structure.fillWithBlocks(world, start, 49, -41, 22, 49, -39, 22, Blocks.STONE_BRICKS.getDefaultState());
        structure.fillWithBlocks(world, start, 49, -41, 25, 49, -39, 25, Blocks.STONE_BRICKS.getDefaultState());
        structure.fillWithBlocks(world, start, 49, -41, 38, 50, -41, 38, Blocks.STONE_BRICKS.getDefaultState());
        structure.fillWithBlocks(world, start, 49, -41, 47, 49, -40, 47, Blocks.STONE_BRICKS.getDefaultState());
        structure.fillWithBlocks(world, start, 49, -41, 48, 49, -41, 48, Blocks.MOSSY_STONE_BRICKS.getDefaultState());
        structure.fillWithBlocks(world, start, 49, -41, 50, 49, -40, 50, Blocks.MOSSY_STONE_BRICKS.getDefaultState());
        structure.fillWithBlocks(world, start, 49, -40, -9, 49, -40, -8, Blocks.MOSSY_STONE_BRICKS.getDefaultState());
        structure.fillWithBlocks(world, start, 49, -40, 3, 49, -40, 3, Blocks.MOSSY_STONE_BRICKS.getDefaultState());
        structure.fillWithBlocks(world, start, 49, -40, 6, 50, -40, 8, Blocks.STONE_BRICKS.getDefaultState());
        structure.fillWithBlocks(world, start, 49, -40, 9, 50, -40, 9, Blocks.MOSSY_STONE_BRICKS.getDefaultState());
        structure.fillWithBlocks(world, start, 49, -40, 12, 51, -40, 14, Blocks.AIR.getDefaultState());
        structure.fillWithBlocks(world, start, 49, -40, 15, 50, -40, 16, Blocks.STONE_BRICKS.getDefaultState());
        structure.fillWithBlocks(world, start, 49, -40, 17, 49, -40, 18, Blocks.STONE_BRICKS.getDefaultState());
        structure.fillWithBlocks(world, start, 49, -40, 19, 49, -40, 20, Blocks.MOSSY_STONE_BRICKS.getDefaultState());
        structure.fillWithBlocks(world, start, 49, -40, 24, 50, -40, 25, Blocks.STONE_BRICKS.getDefaultState());
        structure.fillWithBlocks(world, start, 49, -40, 40, 49, -40, 40, Blocks.STONE_BRICKS.getDefaultState());
        structure.fillWithBlocks(world, start, 49, -40, 42, 50, -39, 42, Blocks.STONE_BRICKS.getDefaultState());
        structure.fillWithBlocks(world, start, 49, -40, 45, 49, -40, 48, Blocks.STONE_BRICKS.getDefaultState());
        structure.fillWithBlocks(world, start, 49, -40, 49, 49, -40, 50, Blocks.MOSSY_STONE_BRICKS.getDefaultState());
        structure.fillWithBlocks(world, start, 49, -39, -9, 49, -39, -9, Blocks.STONE_BRICKS.getDefaultState());
        structure.fillWithBlocks(world, start, 49, -39, -6, 49, -38, -5, Blocks.STONE_BRICKS.getDefaultState());
        structure.fillWithBlocks(world, start, 49, -39, -4, 49, -39, -3, Blocks.MOSSY_STONE_BRICKS.getDefaultState());
        structure.fillWithBlocks(world, start, 49, -39, -2, 49, -39, -1, Blocks.STONE_BRICKS.getDefaultState());
        structure.fillWithBlocks(world, start, 49, -39, 3, 49, -39, 3, Blocks.STONE_BRICKS.getDefaultState());
        structure.fillWithBlocks(world, start, 49, -39, 4, 49, -39, 5, Blocks.MOSSY_STONE_BRICKS.getDefaultState());
        structure.fillWithBlocks(world, start, 49, -39, 7, 49, -38, 8, Blocks.STONE_BRICKS.getDefaultState());
        structure.fillWithBlocks(world, start, 49, -39, 9, 50, -39, 15, Blocks.STONE_BRICKS.getDefaultState());
        structure.fillWithBlocks(world, start, 49, -39, 17, 49, -38, 17, Blocks.AIR.getDefaultState());
        structure.fillWithBlocks(world, start, 49, -39, 18, 49, -39, 20, Blocks.STONE_BRICKS.getDefaultState());
        structure.fillWithBlocks(world, start, 49, -39, 21, 50, -39, 21, Blocks.MOSSY_STONE_BRICKS.getDefaultState());
        structure.fillWithBlocks(world, start, 49, -39, 36, 49, -39, 37, Blocks.STONE_BRICKS.getDefaultState());
        structure.fillWithBlocks(world, start, 49, -39, 38, 49, -39, 38, Blocks.MOSSY_STONE_BRICKS.getDefaultState());
        structure.fillWithBlocks(world, start, 49, -39, 40, 50, -39, 40, Blocks.STONE_BRICKS.getDefaultState());
        structure.fillWithBlocks(world, start, 49, -39, 41, 50, -39, 41, Blocks.MOSSY_STONE_BRICKS.getDefaultState());
        structure.fillWithBlocks(world, start, 49, -39, 43, 49, -38, 45, Blocks.STONE_BRICKS.getDefaultState());
        structure.fillWithBlocks(world, start, 49, -39, 47, 49, -38, 47, Blocks.MOSSY_STONE_BRICKS.getDefaultState());
        structure.fillWithBlocks(world, start, 49, -39, 48, 49, -39, 50, Blocks.STONE_BRICKS.getDefaultState());
        structure.fillWithBlocks(world, start, 49, -38, -9, 49, -38, -9, Blocks.MOSSY_STONE_BRICKS.getDefaultState());
        structure.fillWithBlocks(world, start, 49, -38, -3, 49, -38, -3, Blocks.MOSSY_STONE_BRICKS.getDefaultState());
        structure.fillWithBlocks(world, start, 49, -38, 0, 49, -38, 1, Blocks.AIR.getDefaultState());
        structure.fillWithBlocks(world, start, 49, -38, 3, 49, -38, 4, Blocks.MOSSY_STONE_BRICKS.getDefaultState());
        structure.fillWithBlocks(world, start, 49, -38, 5, 51, -38, 5, Blocks.MOSSY_COBBLESTONE.getDefaultState());
        structure.fillWithBlocks(world, start, 49, -38, 6, 49, -38, 8, Blocks.STONE_BRICKS.getDefaultState());
        structure.fillWithBlocks(world, start, 49, -38, 10, 49, -37, 10, Blocks.STONE_BRICKS.getDefaultState());
        structure.fillWithBlocks(world, start, 49, -38, 11, 49, -38, 12, Blocks.MOSSY_STONE_BRICKS.getDefaultState());
        structure.fillWithBlocks(world, start, 49, -38, 13, 49, -38, 13, Blocks.STONE_BRICKS.getDefaultState());
        structure.fillWithBlocks(world, start, 49, -38, 14, 49, -38, 14, Blocks.MOSSY_STONE_BRICKS.getDefaultState());
        structure.fillWithBlocks(world, start, 49, -38, 15, 49, -38, 16, Blocks.STONE_BRICKS.getDefaultState());
        structure.fillWithBlocks(world, start, 49, -38, 18, 49, -38, 19, Blocks.STONE_BRICKS.getDefaultState());
        structure.fillWithBlocks(world, start, 49, -38, 20, 49, -38, 21, Blocks.MOSSY_STONE_BRICKS.getDefaultState());
        structure.fillWithBlocks(world, start, 49, -38, 22, 49, -38, 22, Blocks.AIR.getDefaultState());
        structure.fillWithBlocks(world, start, 49, -38, 24, 49, -38, 24, Blocks.STONE_BRICKS.getDefaultState());
        structure.fillWithBlocks(world, start, 49, -38, 36, 49, -38, 37, Blocks.MOSSY_STONE_BRICKS.getDefaultState());
        structure.fillWithBlocks(world, start, 49, -38, 38, 49, -38, 40, Blocks.STONE_BRICKS.getDefaultState());
        structure.fillWithBlocks(world, start, 49, -38, 42, 50, -38, 44, Blocks.STONE_BRICKS.getDefaultState());
        structure.fillWithBlocks(world, start, 49, -38, 46, 49, -38, 46, Blocks.STONE_BRICKS.getDefaultState());
        structure.fillWithBlocks(world, start, 49, -38, 48, 49, -37, 48, Blocks.MOSSY_STONE_BRICKS.getDefaultState());
        structure.fillWithBlocks(world, start, 49, -38, 49, 49, -38, 50, Blocks.AIR.getDefaultState());
        structure.fillWithBlocks(world, start, 49, -37, -9, 49, -37, -9, Blocks.STONE_BRICKS.getDefaultState());
        structure.fillWithBlocks(world, start, 49, -37, -8, 49, -37, -8, Blocks.MOSSY_STONE_BRICKS.getDefaultState());
        structure.fillWithBlocks(world, start, 49, -37, -7, 49, -37, -6, Blocks.STONE_BRICKS.getDefaultState());
        structure.fillWithBlocks(world, start, 49, -37, -4, 49, -37, -3, Blocks.STONE_BRICKS.getDefaultState());
        structure.fillWithBlocks(world, start, 49, -37, -1, 49, -37, -1, Blocks.STONE_BRICKS.getDefaultState());
        structure.fillWithBlocks(world, start, 49, -37, 1, 49, -37, 1, Blocks.STONE_BRICKS.getDefaultState());
        structure.fillWithBlocks(world, start, 49, -37, 3, 49, -37, 3, Blocks.STONE_BRICKS.getDefaultState());
        structure.fillWithBlocks(world, start, 49, -37, 4, 49, -37, 5, Blocks.MOSSY_STONE_BRICKS.getDefaultState());
        structure.fillWithBlocks(world, start, 49, -37, 6, 51, -37, 6, Blocks.STONE_BRICKS.getDefaultState());
        structure.fillWithBlocks(world, start, 49, -37, 7, 50, -37, 7, Blocks.MOSSY_STONE_BRICKS.getDefaultState());
        structure.fillWithBlocks(world, start, 49, -37, 8, 51, -37, 8, Blocks.STONE_BRICKS.getDefaultState());
        structure.fillWithBlocks(world, start, 49, -37, 9, 50, -37, 9, Blocks.MOSSY_STONE_BRICKS.getDefaultState());
        structure.fillWithBlocks(world, start, 49, -37, 11, 49, -37, 11, Blocks.MOSSY_STONE_BRICKS.getDefaultState());
        structure.fillWithBlocks(world, start, 49, -37, 13, 49, -37, 13, Blocks.MOSSY_STONE_BRICKS.getDefaultState());
        structure.fillWithBlocks(world, start, 49, -37, 16, 49, -37, 17, Blocks.STONE_BRICKS.getDefaultState());
        structure.fillWithBlocks(world, start, 49, -37, 19, 49, -37, 20, Blocks.STONE_BRICKS.getDefaultState());
        structure.fillWithBlocks(world, start, 49, -37, 21, 49, -37, 21, Blocks.MOSSY_STONE_BRICKS.getDefaultState());
        structure.fillWithBlocks(world, start, 49, -37, 25, 50, -37, 25, Blocks.MOSSY_STONE_BRICKS.getDefaultState());
        structure.fillWithBlocks(world, start, 49, -37, 36, 49, -37, 37, Blocks.STONE_BRICKS.getDefaultState());
        structure.fillWithBlocks(world, start, 49, -37, 40, 49, -37, 41, Blocks.STONE_BRICKS.getDefaultState());
        structure.fillWithBlocks(world, start, 49, -37, 42, 49, -37, 42, Blocks.MOSSY_STONE_BRICKS.getDefaultState());
        structure.fillWithBlocks(world, start, 49, -37, 44, 49, -37, 45, Blocks.STONE_BRICKS.getDefaultState());
        structure.fillWithBlocks(world, start, 49, -37, 46, 51, -37, 46, Blocks.MOSSY_STONE_BRICKS.getDefaultState());
        structure.fillWithBlocks(world, start, 49, -37, 50, 53, -37, 50, Blocks.STONE_BRICKS.getDefaultState());
        structure.fillWithBlocks(world, start, 49, -36, 48, 51, -36, 50, Blocks.GRAVEL.getDefaultState());
        structure.fillWithBlocks(world, start, 49, -35, 48, 52, -35, 48, Blocks.GRAVEL.getDefaultState());
        structure.fillWithBlocks(world, start, 49, -26, 33, 53, -26, 33, Blocks.STONE_BRICKS.getDefaultState());
        structure.fillWithBlocks(world, start, 49, -26, 61, 50, -26, 61, Blocks.CRACKED_STONE_BRICKS.getDefaultState());
        structure.fillWithBlocks(world, start, 49, -25, 28, 53, -25, 28, Blocks.STONE_BRICKS.getDefaultState());
        structure.fillWithBlocks(world, start, 49, -25, 29, 51, -25, 33, Blocks.AIR.getDefaultState());
        structure.fillWithBlocks(world, start, 49, -25, 61, 51, -25, 65, Blocks.AIR.getDefaultState());
        structure.fillWithBlocks(world, start, 49, -25, 66, 49, -24, 66, Blocks.STONE_BRICKS.getDefaultState());
        structure.fillWithBlocks(world, start, 49, -24, 29, 51, -24, 33, Blocks.AIR.getDefaultState());
        structure.fillWithBlocks(world, start, 49, -24, 61, 51, -24, 65, Blocks.AIR.getDefaultState());
        structure.fillWithBlocks(world, start, 49, -23, 29, 51, -23, 33, Blocks.AIR.getDefaultState());
        structure.fillWithBlocks(world, start, 49, -23, 61, 51, -23, 65, Blocks.AIR.getDefaultState());
        structure.fillWithBlocks(world, start, 49, -22, 32, 49, -22, 32, Blocks.CRACKED_STONE_BRICKS.getDefaultState());
        structure.fillWithBlocks(world, start, 49, -22, 64, 49, -22, 64, Blocks.CRACKED_STONE_BRICKS.getDefaultState());
        structure.fillWithBlocks(world, start, 49, -15, 28, 67, -15, 28, Blocks.STONE_BRICKS.getDefaultState());
        structure.fillWithBlocks(world, start, 49, -15, 29, 51, -15, 33, Blocks.AIR.getDefaultState());
        structure.fillWithBlocks(world, start, 49, -14, 28, 49, -13, 28, Blocks.STONE_BRICKS.getDefaultState());
        structure.fillWithBlocks(world, start, 49, -14, 29, 51, -14, 33, Blocks.AIR.getDefaultState());
        structure.fillWithBlocks(world, start, 49, -13, 29, 51, -13, 33, Blocks.AIR.getDefaultState());
        structure.fillWithBlocks(world, start, 49, -12, 29, 49, -12, 33, Blocks.STONE_BRICKS.getDefaultState());
        structure.fillWithBlocks(world, start, 49, 0, 7, 50, 0, 8, Blocks.GRASS_BLOCK.getDefaultState().with(SnowyDirtBlock.SNOWY, false));
        structure.fillWithBlocks(world, start, 49, 0, 29, 52, 0, 32, Blocks.STONE.getDefaultState());
        structure.fillWithBlocks(world, start, 49, 0, 33, 49, 1, 34, Blocks.COAL_ORE.getDefaultState());
        structure.fillWithBlocks(world, start, 49, 0, 35, 57, 0, 43, Blocks.STONE.getDefaultState());
        structure.fillWithBlocks(world, start, 49, 0, 59, 52, 0, 62, Blocks.DIRT.getDefaultState());
        structure.fillWithBlocks(world, start, 49, 0, 63, 51, 0, 65, Blocks.GRASS_BLOCK.getDefaultState().with(SnowyDirtBlock.SNOWY, false));
        structure.fillWithBlocks(world, start, 49, 1, 31, 50, 1, 32, Blocks.STONE.getDefaultState());
        structure.fillWithBlocks(world, start, 49, 1, 35, 49, 2, 35, Blocks.DIRT.getDefaultState());
        structure.fillWithBlocks(world, start, 49, 1, 36, 56, 1, 44, Blocks.STONE.getDefaultState());
        structure.fillWithBlocks(world, start, 49, 1, 46, 50, 1, 47, Blocks.STONE.getDefaultState());
        structure.fillWithBlocks(world, start, 49, 1, 49, 50, 1, 50, Blocks.DIRT.getDefaultState());
        structure.fillWithBlocks(world, start, 49, 1, 53, 50, 1, 53, Blocks.STONE.getDefaultState());
        structure.fillWithBlocks(world, start, 49, 1, 54, 55, 1, 60, Blocks.DIRT.getDefaultState());
        structure.fillWithBlocks(world, start, 49, 1, 62, 56, 1, 62, Blocks.GRASS_BLOCK.getDefaultState().with(SnowyDirtBlock.SNOWY, false));
        structure.fillWithBlocks(world, start, 49, 2, 13, 49, 2, 13, Blocks.GRAVEL.getDefaultState());
        structure.fillWithBlocks(world, start, 49, 2, 14, 49, 2, 33, Blocks.STONE.getDefaultState());
        structure.fillWithBlocks(world, start, 49, 2, 34, 49, 2, 35, Blocks.DIRT.getDefaultState());
        structure.fillWithBlocks(world, start, 49, 2, 36, 56, 2, 43, Blocks.STONE.getDefaultState());
        structure.fillWithBlocks(world, start, 49, 2, 46, 49, 2, 47, Blocks.COAL_ORE.getDefaultState());
        structure.fillWithBlocks(world, start, 49, 2, 59, 50, 2, 60, Blocks.GRASS_BLOCK.getDefaultState().with(SnowyDirtBlock.SNOWY, false));
        structure.fillWithBlocks(world, start, 49, 3, 11, 50, 3, 11, Blocks.GRASS_BLOCK.getDefaultState().with(SnowyDirtBlock.SNOWY, false));
        structure.fillWithBlocks(world, start, 49, 3, 29, 53, 3, 33, Blocks.STONE.getDefaultState());
        structure.fillWithBlocks(world, start, 49, 3, 35, 56, 3, 43, Blocks.STONE.getDefaultState());
        structure.fillWithBlocks(world, start, 49, 3, 46, 50, 3, 46, Blocks.COAL_ORE.getDefaultState());
        structure.fillWithBlocks(world, start, 49, 3, 47, 50, 3, 47, Blocks.STONE.getDefaultState());
        structure.fillWithBlocks(world, start, 49, 3, 50, 49, 3, 50, Blocks.GRASS_BLOCK.getDefaultState().with(SnowyDirtBlock.SNOWY, false));
        structure.fillWithBlocks(world, start, 49, 3, 51, 49, 3, 54, Blocks.DIRT.getDefaultState());
        structure.fillWithBlocks(world, start, 49, 3, 55, 50, 3, 57, Blocks.GRASS_BLOCK.getDefaultState().with(SnowyDirtBlock.SNOWY, false));
        structure.fillWithBlocks(world, start, 49, 4, 12, 51, 4, 12, Blocks.GRASS_BLOCK.getDefaultState().with(SnowyDirtBlock.SNOWY, false));
        structure.fillWithBlocks(world, start, 49, 4, 14, 52, 5, 14, Blocks.DIRT.getDefaultState());
        structure.fillWithBlocks(world, start, 49, 4, 15, 50, 4, 46, Blocks.STONE.getDefaultState());
        structure.fillWithBlocks(world, start, 49, 4, 47, 50, 4, 48, Blocks.DIRT.getDefaultState());
        structure.fillWithBlocks(world, start, 49, 4, 51, 49, 4, 53, Blocks.GRASS_BLOCK.getDefaultState().with(SnowyDirtBlock.SNOWY, false));
        structure.fillWithBlocks(world, start, 49, 6, 14, 51, 6, 14, Blocks.GRASS_BLOCK.getDefaultState().with(SnowyDirtBlock.SNOWY, false));
        structure.fillWithBlocks(world, start, 49, 6, 46, 52, 6, 46, Blocks.DIRT.getDefaultState());
        structure.fillWithBlocks(world, start, 49, 6, 47, 50, 6, 47, Blocks.GRASS_BLOCK.getDefaultState().with(SnowyDirtBlock.SNOWY, false));
        structure.fillWithBlocks(world, start, 49, 7, 14, 51, 7, 14, Blocks.GRASS.getDefaultState());
        structure.fillWithBlocks(world, start, 49, 7, 21, 64, 7, 39, Blocks.STONE.getDefaultState());
        structure.fillWithBlocks(world, start, 49, 8, 24, 60, 8, 36, Blocks.STONE.getDefaultState());
        structure.fillWithBlocks(world, start, 49, 8, 44, 49, 9, 45, Blocks.STONE.getDefaultState());
        structure.fillWithBlocks(world, start, 49, 9, 16, 50, 9, 16, Blocks.GRASS_BLOCK.getDefaultState().with(SnowyDirtBlock.SNOWY, false));
        structure.fillWithBlocks(world, start, 49, 9, 17, 50, 9, 18, Blocks.STONE.getDefaultState());
        structure.fillWithBlocks(world, start, 49, 9, 19, 49, 9, 20, Blocks.DIRT.getDefaultState());
        structure.fillWithBlocks(world, start, 49, 9, 24, 52, 9, 29, Blocks.STONE.getDefaultState());
        structure.fillWithBlocks(world, start, 49, 9, 30, 50, 9, 41, Blocks.STONE.getDefaultState());
        structure.fillWithBlocks(world, start, 49, 9, 43, 50, 10, 43, Blocks.DIRT.getDefaultState());
        structure.fillWithBlocks(world, start, 49, 10, 16, 50, 10, 16, Blocks.GRASS.getDefaultState());
        structure.fillWithBlocks(world, start, 49, 10, 23, 49, 12, 23, Blocks.GRAVEL.getDefaultState());
        structure.fillWithBlocks(world, start, 49, 10, 29, 49, 11, 34, Blocks.DIRT.getDefaultState());
        structure.fillWithBlocks(world, start, 49, 10, 35, 49, 12, 35, Blocks.GRAVEL.getDefaultState());
        structure.fillWithBlocks(world, start, 49, 10, 36, 50, 10, 37, Blocks.DIRT.getDefaultState());
        structure.fillWithBlocks(world, start, 49, 10, 38, 49, 10, 43, Blocks.DIRT.getDefaultState());
        structure.fillWithBlocks(world, start, 49, 10, 44, 50, 10, 44, Blocks.MOSSY_STONE_BRICKS.getDefaultState());
        structure.fillWithBlocks(world, start, 49, 11, 24, 49, 11, 34, Blocks.DIRT.getDefaultState());
        structure.fillWithBlocks(world, start, 49, 11, 36, 50, 11, 37, Blocks.DIRT.getDefaultState());
        structure.fillWithBlocks(world, start, 49, 11, 38, 49, 11, 43, Blocks.DIRT.getDefaultState());
        structure.fillWithBlocks(world, start, 49, 12, 18, 49, 12, 18, Blocks.DIRT.getDefaultState());
        structure.fillWithBlocks(world, start, 49, 12, 19, 49, 12, 20, Blocks.MOSSY_STONE_BRICKS.getDefaultState());
        structure.fillWithBlocks(world, start, 49, 12, 21, 50, 12, 22, Blocks.GRASS_BLOCK.getDefaultState().with(SnowyDirtBlock.SNOWY, false));
        structure.fillWithBlocks(world, start, 49, 12, 24, 49, 12, 25, Blocks.GRASS_BLOCK.getDefaultState().with(SnowyDirtBlock.SNOWY, false));
        structure.fillWithBlocks(world, start, 49, 12, 27, 49, 12, 30, Blocks.GRASS_BLOCK.getDefaultState().with(SnowyDirtBlock.SNOWY, false));
        structure.fillWithBlocks(world, start, 49, 12, 31, 50, 12, 32, Blocks.DIRT.getDefaultState());
        structure.fillWithBlocks(world, start, 49, 12, 33, 49, 12, 34, Blocks.GRASS_BLOCK.getDefaultState().with(SnowyDirtBlock.SNOWY, false));
        structure.fillWithBlocks(world, start, 49, 12, 36, 49, 12, 37, Blocks.GRASS_BLOCK.getDefaultState().with(SnowyDirtBlock.SNOWY, false));
        structure.fillWithBlocks(world, start, 49, 12, 39, 49, 12, 39, Blocks.GRASS_BLOCK.getDefaultState().with(SnowyDirtBlock.SNOWY, false));
        structure.fillWithBlocks(world, start, 49, 12, 43, 49, 12, 43, Blocks.CRACKED_STONE_BRICKS.getDefaultState());
        structure.fillWithBlocks(world, start, 49, 13, 17, 49, 13, 17, Blocks.CRACKED_STONE_BRICKS.getDefaultState());
        structure.fillWithBlocks(world, start, 49, 13, 22, 49, 13, 22, Blocks.GRASS.getDefaultState());
        structure.fillWithBlocks(world, start, 49, 13, 24, 49, 13, 25, Blocks.GRASS.getDefaultState());
        structure.fillWithBlocks(world, start, 49, 13, 31, 49, 13, 31, Blocks.COBBLESTONE_SLAB.getDefaultState().with(SlabBlock.TYPE, SlabType.BOTTOM).with(SlabBlock.WATERLOGGED, false));
        structure.fillWithBlocks(world, start, 49, 13, 37, 50, 13, 37, Blocks.GRASS.getDefaultState());
        structure.fillWithBlocks(world, start, 49, 13, 39, 50, 13, 39, Blocks.GRASS.getDefaultState());
        structure.fillWithBlocks(world, start, 49, 13, 43, 49, 14, 44, Blocks.CRACKED_STONE_BRICKS.getDefaultState());
        structure.fillWithBlocks(world, start, 49, 15, 43, 50, 15, 43, Blocks.CRACKED_STONE_BRICKS.getDefaultState());
        structure.fillWithBlocks(world, start, 49, 17, 18, 49, 17, 20, Blocks.CRACKED_STONE_BRICKS.getDefaultState());
        structure.fillWithBlocks(world, start, 50, -59, 26, 51, -59, 27, Blocks.STONE_BRICKS.getDefaultState());
        structure.fillWithBlocks(world, start, 50, -59, 29, 53, -59, 43, Blocks.STONE_BRICKS.getDefaultState());
        structure.fillWithBlocks(world, start, 50, -59, 45, 51, -59, 46, Blocks.STONE_BRICKS.getDefaultState());
        structure.fillWithBlocks(world, start, 50, -58, 30, 51, -58, 30, Blocks.STONE_BRICK_STAIRS.getDefaultState().with(StairsBlock.FACING, Direction.NORTH).with(StairsBlock.WATERLOGGED, false).with(StairsBlock.SHAPE, StairsShape.STRAIGHT).with(StairsBlock.HALF, Half.BOTTOM));
        structure.fillWithBlocks(world, start, 50, -58, 34, 52, -57, 34, Blocks.AIR.getDefaultState());
        structure.fillWithBlocks(world, start, 50, -58, 35, 50, -57, 37, Blocks.SHROOMLIGHT.getDefaultState());
        structure.fillWithBlocks(world, start, 50, -58, 38, 51, -58, 39, Blocks.AIR.getDefaultState());
        structure.fillWithBlocks(world, start, 50, -58, 42, 51, -58, 42, Blocks.STONE_BRICK_STAIRS.getDefaultState().with(StairsBlock.FACING, Direction.SOUTH).with(StairsBlock.WATERLOGGED, false).with(StairsBlock.SHAPE, StairsShape.STRAIGHT).with(StairsBlock.HALF, Half.BOTTOM));
        structure.fillWithBlocks(world, start, 50, -58, 43, 53, -58, 46, Blocks.STONE_BRICKS.getDefaultState());
        structure.fillWithBlocks(world, start, 50, -57, -65, 50, -57, -61, Blocks.STONE_BRICK_STAIRS.getDefaultState().with(StairsBlock.FACING, Direction.EAST).with(StairsBlock.WATERLOGGED, false).with(StairsBlock.SHAPE, StairsShape.STRAIGHT).with(StairsBlock.HALF, Half.BOTTOM));
        structure.fillWithBlocks(world, start, 50, -57, 29, 51, -57, 29, Blocks.STONE_BRICK_STAIRS.getDefaultState().with(StairsBlock.FACING, Direction.NORTH).with(StairsBlock.WATERLOGGED, false).with(StairsBlock.SHAPE, StairsShape.STRAIGHT).with(StairsBlock.HALF, Half.BOTTOM));
        structure.fillWithBlocks(world, start, 50, -57, 30, 51, -57, 34, Blocks.AIR.getDefaultState());
        structure.fillWithBlocks(world, start, 50, -57, 38, 52, -57, 41, Blocks.AIR.getDefaultState());
        structure.fillWithBlocks(world, start, 50, -57, 42, 51, -56, 42, Blocks.AIR.getDefaultState());
        structure.fillWithBlocks(world, start, 50, -57, 43, 51, -57, 43, Blocks.STONE_BRICK_STAIRS.getDefaultState().with(StairsBlock.FACING, Direction.SOUTH).with(StairsBlock.WATERLOGGED, false).with(StairsBlock.SHAPE, StairsShape.STRAIGHT).with(StairsBlock.HALF, Half.BOTTOM));
        structure.fillWithBlocks(world, start, 50, -57, 44, 53, -57, 47, Blocks.STONE_BRICKS.getDefaultState());
        structure.fillWithBlocks(world, start, 50, -56, -70, 51, -56, -70, Blocks.SHROOMLIGHT.getDefaultState());
        structure.fillWithBlocks(world, start, 50, -56, -69, 52, -56, -67, Blocks.STONE_BRICKS.getDefaultState());
        structure.fillWithBlocks(world, start, 50, -56, -66, 50, -51, -60, Blocks.AIR.getDefaultState());
        structure.fillWithBlocks(world, start, 50, -56, -59, 52, -56, -57, Blocks.STONE_BRICKS.getDefaultState());
        structure.fillWithBlocks(world, start, 50, -56, -56, 51, -56, -56, Blocks.SHROOMLIGHT.getDefaultState());
        structure.fillWithBlocks(world, start, 50, -56, -55, 52, -56, -53, Blocks.STONE_BRICKS.getDefaultState());
        structure.fillWithBlocks(world, start, 50, -56, -48, 50, -53, -48, Blocks.STONE_BRICKS.getDefaultState());
        structure.fillWithBlocks(world, start, 50, -56, -35, 51, -56, -27, Blocks.STONE_BRICKS.getDefaultState());
        structure.fillWithBlocks(world, start, 50, -56, -25, 51, -56, -23, Blocks.STONE_BRICKS.getDefaultState());
        structure.fillWithBlocks(world, start, 50, -56, -9, 53, -56, -3, Blocks.STONE_BRICKS.getDefaultState());
        structure.fillWithBlocks(world, start, 50, -56, 2, 51, -56, 3, Blocks.STONE_BRICKS.getDefaultState());
        structure.fillWithBlocks(world, start, 50, -56, 25, 51, -56, 26, Blocks.STONE_BRICKS.getDefaultState());
        structure.fillWithBlocks(world, start, 50, -56, 27, 52, -56, 29, Blocks.AIR.getDefaultState());
        structure.fillWithBlocks(world, start, 50, -56, 30, 51, -56, 33, Blocks.AIR.getDefaultState());
        structure.fillWithBlocks(world, start, 50, -56, 34, 53, -56, 38, Blocks.STONE_BRICKS.getDefaultState());
        structure.fillWithBlocks(world, start, 50, -56, 39, 52, -56, 41, Blocks.AIR.getDefaultState());
        structure.fillWithBlocks(world, start, 50, -56, 43, 52, -56, 45, Blocks.AIR.getDefaultState());
        structure.fillWithBlocks(world, start, 50, -56, 47, 56, -52, 47, Blocks.STONE_BRICKS.getDefaultState());
        structure.fillWithBlocks(world, start, 50, -56, 58, 51, -56, 59, Blocks.STONE_BRICKS.getDefaultState());
        structure.fillWithBlocks(world, start, 50, -56, 61, 53, -56, 65, Blocks.STONE_BRICKS.getDefaultState());
        structure.fillWithBlocks(world, start, 50, -56, 69, 51, -56, 70, Blocks.STONE_BRICKS.getDefaultState());
        structure.fillWithBlocks(world, start, 50, -55, -70, 51, -55, -69, Blocks.AIR.getDefaultState());
        structure.fillWithBlocks(world, start, 50, -55, -68, 50, -51, -68, Blocks.AIR.getDefaultState());
        structure.fillWithBlocks(world, start, 50, -55, -67, 50, -47, -67, Blocks.STONE_BRICKS.getDefaultState());
        structure.fillWithBlocks(world, start, 50, -55, -59, 50, -50, -59, Blocks.STONE_BRICKS.getDefaultState());
        structure.fillWithBlocks(world, start, 50, -55, -58, 50, -55, -56, Blocks.AIR.getDefaultState());
        structure.fillWithBlocks(world, start, 50, -55, -55, 52, -55, -53, Blocks.STONE_BRICKS.getDefaultState());
        structure.fillWithBlocks(world, start, 50, -55, -52, 50, -53, -48, Blocks.STONE_BRICKS.getDefaultState());
        structure.fillWithBlocks(world, start, 50, -55, -47, 50, -55, -32, Blocks.STONE_BRICKS.getDefaultState());
        structure.fillWithBlocks(world, start, 50, -55, -31, 52, -55, -27, Blocks.AIR.getDefaultState());
        structure.fillWithBlocks(world, start, 50, -55, -26, 53, -55, -23, Blocks.STONE_BRICKS.getDefaultState());
        structure.fillWithBlocks(world, start, 50, -55, -22, 50, -53, -18, Blocks.STONE_BRICKS.getDefaultState());
        structure.fillWithBlocks(world, start, 50, -55, -17, 50, -55, -10, Blocks.STONE_BRICKS.getDefaultState());
        structure.fillWithBlocks(world, start, 50, -55, -8, 52, -55, -6, Blocks.STONE_BRICKS.getDefaultState());
        structure.fillWithBlocks(world, start, 50, -55, -5, 50, -51, -1, Blocks.AIR.getDefaultState());
        structure.fillWithBlocks(world, start, 50, -55, 0, 53, -55, 3, Blocks.STONE_BRICKS.getDefaultState());
        structure.fillWithBlocks(world, start, 50, -55, 4, 50, -53, 6, Blocks.STONE_BRICKS.getDefaultState());
        structure.fillWithBlocks(world, start, 50, -55, 7, 50, -55, 25, Blocks.STONE_BRICKS.getDefaultState());
        structure.fillWithBlocks(world, start, 50, -55, 26, 51, -55, 46, Blocks.AIR.getDefaultState());
        structure.fillWithBlocks(world, start, 50, -55, 48, 50, -55, 56, Blocks.STONE_BRICKS.getDefaultState());
        structure.fillWithBlocks(world, start, 50, -55, 58, 51, -55, 60, Blocks.STONE_BRICKS.getDefaultState());
        structure.fillWithBlocks(world, start, 50, -55, 68, 50, -47, 68, Blocks.STONE_BRICKS.getDefaultState());
        structure.fillWithBlocks(world, start, 50, -55, 69, 50, -54, 69, Blocks.AIR.getDefaultState());
        structure.fillWithBlocks(world, start, 50, -54, -73, 52, -54, -71, Blocks.STONE_BRICKS.getDefaultState());
        structure.fillWithBlocks(world, start, 50, -54, -70, 51, -54, -69, Blocks.AIR.getDefaultState());
        structure.fillWithBlocks(world, start, 50, -54, -58, 50, -54, -56, Blocks.AIR.getDefaultState());
        structure.fillWithBlocks(world, start, 50, -54, -55, 51, -54, -54, Blocks.STONE_BRICKS.getDefaultState());
        structure.fillWithBlocks(world, start, 50, -54, -46, 50, -54, -44, Blocks.STONE_BRICKS.getDefaultState());
        structure.fillWithBlocks(world, start, 50, -54, -42, 50, -53, -40, Blocks.STONE_BRICKS.getDefaultState());
        structure.fillWithBlocks(world, start, 50, -54, -38, 50, -53, -36, Blocks.STONE_BRICKS.getDefaultState());
        structure.fillWithBlocks(world, start, 50, -54, -34, 51, -54, -33, Blocks.STONE_BRICKS.getDefaultState());
        structure.fillWithBlocks(world, start, 50, -54, -32, 50, -45, -32, Blocks.STONE_BRICKS.getDefaultState());
        structure.fillWithBlocks(world, start, 50, -54, -31, 52, -54, -27, Blocks.AIR.getDefaultState());
        structure.fillWithBlocks(world, start, 50, -54, -26, 50, -54, -24, Blocks.STONE_BRICKS.getDefaultState());
        structure.fillWithBlocks(world, start, 50, -54, -16, 50, -54, -12, Blocks.STONE_BRICKS.getDefaultState());
        structure.fillWithBlocks(world, start, 50, -54, -10, 50, -54, -6, Blocks.STONE_BRICKS.getDefaultState());
        structure.fillWithBlocks(world, start, 50, -54, 0, 52, -54, 2, Blocks.STONE_BRICKS.getDefaultState());
        structure.fillWithBlocks(world, start, 50, -54, 8, 50, -53, 12, Blocks.STONE_BRICKS.getDefaultState());
        structure.fillWithBlocks(world, start, 50, -54, 14, 50, -53, 18, Blocks.STONE_BRICKS.getDefaultState());
        structure.fillWithBlocks(world, start, 50, -54, 20, 50, -53, 22, Blocks.STONE_BRICKS.getDefaultState());
        structure.fillWithBlocks(world, start, 50, -54, 24, 50, -54, 25, Blocks.STONE_BRICKS.getDefaultState());
        structure.fillWithBlocks(world, start, 50, -54, 26, 51, -54, 46, Blocks.AIR.getDefaultState());
        structure.fillWithBlocks(world, start, 50, -54, 48, 50, -53, 48, Blocks.STONE_BRICKS.getDefaultState());
        structure.fillWithBlocks(world, start, 50, -54, 50, 50, -54, 54, Blocks.STONE_BRICKS.getDefaultState());
        structure.fillWithBlocks(world, start, 50, -54, 56, 50, -53, 56, Blocks.STONE_BRICKS.getDefaultState());
        structure.fillWithBlocks(world, start, 50, -54, 58, 51, -54, 59, Blocks.STONE_BRICKS.getDefaultState());
        structure.fillWithBlocks(world, start, 50, -54, 60, 50, -47, 60, Blocks.STONE_BRICKS.getDefaultState());
        structure.fillWithBlocks(world, start, 50, -53, -70, 51, -53, -69, Blocks.AIR.getDefaultState());
        structure.fillWithBlocks(world, start, 50, -53, -58, 50, -53, -56, Blocks.AIR.getDefaultState());
        structure.fillWithBlocks(world, start, 50, -53, -55, 52, -53, -53, Blocks.STONE_BRICKS.getDefaultState());
        structure.fillWithBlocks(world, start, 50, -53, -47, 50, -53, -46, Blocks.STONE_BRICKS.getDefaultState());
        structure.fillWithBlocks(world, start, 50, -53, -44, 50, -53, -32, Blocks.STONE_BRICKS.getDefaultState());
        structure.fillWithBlocks(world, start, 50, -53, -31, 52, -53, -27, Blocks.AIR.getDefaultState());
        structure.fillWithBlocks(world, start, 50, -53, -26, 53, -53, -23, Blocks.STONE_BRICKS.getDefaultState());
        structure.fillWithBlocks(world, start, 50, -53, -17, 50, -53, -16, Blocks.STONE_BRICKS.getDefaultState());
        structure.fillWithBlocks(world, start, 50, -53, -12, 50, -53, -6, Blocks.STONE_BRICKS.getDefaultState());
        structure.fillWithBlocks(world, start, 50, -53, 0, 52, -53, 3, Blocks.STONE_BRICKS.getDefaultState());
        structure.fillWithBlocks(world, start, 50, -53, 7, 50, -53, 25, Blocks.STONE_BRICKS.getDefaultState());
        structure.fillWithBlocks(world, start, 50, -53, 26, 51, -53, 46, Blocks.AIR.getDefaultState());
        structure.fillWithBlocks(world, start, 50, -53, 49, 50, -53, 50, Blocks.STONE_BRICKS.getDefaultState());
        structure.fillWithBlocks(world, start, 50, -53, 54, 50, -53, 56, Blocks.STONE_BRICKS.getDefaultState());
        structure.fillWithBlocks(world, start, 50, -53, 58, 50, -51, 60, Blocks.STONE_BRICKS.getDefaultState());
        structure.fillWithBlocks(world, start, 50, -53, 69, 51, -53, 70, Blocks.STONE_BRICKS.getDefaultState());
        structure.fillWithBlocks(world, start, 50, -52, -70, 51, -52, -69, Blocks.AIR.getDefaultState());
        structure.fillWithBlocks(world, start, 50, -52, -58, 50, -52, -56, Blocks.AIR.getDefaultState());
        structure.fillWithBlocks(world, start, 50, -52, -55, 50, -50, -53, Blocks.STONE_BRICKS.getDefaultState());
        structure.fillWithBlocks(world, start, 50, -52, -35, 50, -50, -31, Blocks.STONE_BRICKS.getDefaultState());
        structure.fillWithBlocks(world, start, 50, -52, -30, 53, -52, -23, Blocks.STONE_BRICKS.getDefaultState());
        structure.fillWithBlocks(world, start, 50, -52, -9, 51, -52, -6, Blocks.STONE_BRICKS.getDefaultState());
        structure.fillWithBlocks(world, start, 50, -52, 0, 53, -52, 3, Blocks.STONE_BRICKS.getDefaultState());
        structure.fillWithBlocks(world, start, 50, -52, 18, 50, -52, 19, Blocks.STONE_BRICKS.getDefaultState());
        structure.fillWithBlocks(world, start, 50, -52, 25, 51, -52, 26, Blocks.STONE_BRICKS.getDefaultState());
        structure.fillWithBlocks(world, start, 50, -52, 27, 52, -52, 29, Blocks.AIR.getDefaultState());
        structure.fillWithBlocks(world, start, 50, -52, 30, 56, -49, 30, Blocks.STONE_BRICKS.getDefaultState());
        structure.fillWithBlocks(world, start, 50, -52, 31, 52, -52, 33, Blocks.AIR.getDefaultState());
        structure.fillWithBlocks(world, start, 50, -52, 35, 52, -52, 37, Blocks.AIR.getDefaultState());
        structure.fillWithBlocks(world, start, 50, -52, 38, 57, -50, 38, Blocks.STONE_BRICKS.getDefaultState());
        structure.fillWithBlocks(world, start, 50, -52, 39, 52, -52, 41, Blocks.AIR.getDefaultState());
        structure.fillWithBlocks(world, start, 50, -52, 43, 52, -52, 45, Blocks.AIR.getDefaultState());
        structure.fillWithBlocks(world, start, 50, -52, 46, 51, -52, 47, Blocks.STONE_BRICKS.getDefaultState());
        structure.fillWithBlocks(world, start, 50, -52, 52, 50, -51, 52, Blocks.GRAVEL.getDefaultState());
        structure.fillWithBlocks(world, start, 50, -51, -70, 51, -51, -69, Blocks.AIR.getDefaultState());
        structure.fillWithBlocks(world, start, 50, -51, -58, 50, -51, -56, Blocks.AIR.getDefaultState());
        structure.fillWithBlocks(world, start, 50, -51, -8, 52, -51, -6, Blocks.STONE_BRICKS.getDefaultState());
        structure.fillWithBlocks(world, start, 50, -51, 0, 53, -51, 3, Blocks.STONE_BRICKS.getDefaultState());
        structure.fillWithBlocks(world, start, 50, -51, 46, 55, -50, 46, Blocks.STONE_BRICKS.getDefaultState());
        structure.fillWithBlocks(world, start, 50, -50, -71, 51, -49, -71, Blocks.STONE_BRICKS.getDefaultState());
        structure.fillWithBlocks(world, start, 50, -50, -70, 51, -50, -70, Blocks.SHROOMLIGHT.getDefaultState());
        structure.fillWithBlocks(world, start, 50, -50, -69, 51, -50, -68, Blocks.STONE_BRICKS.getDefaultState());
        structure.fillWithBlocks(world, start, 50, -50, -65, 50, -50, -61, Blocks.STONE_BRICK_STAIRS.getDefaultState().with(StairsBlock.FACING, Direction.EAST).with(StairsBlock.WATERLOGGED, false).with(StairsBlock.SHAPE, StairsShape.STRAIGHT).with(StairsBlock.HALF, Half.TOP));
        structure.fillWithBlocks(world, start, 50, -50, -56, 51, -50, -56, Blocks.SHROOMLIGHT.getDefaultState());
        structure.fillWithBlocks(world, start, 50, -50, -29, 52, -50, -23, Blocks.STONE_BRICKS.getDefaultState());
        structure.fillWithBlocks(world, start, 50, -50, -6, 50, -50, -6, Blocks.STONE_BRICKS.getDefaultState());
        structure.fillWithBlocks(world, start, 50, -50, -5, 50, -47, -1, Blocks.AIR.getDefaultState());
        structure.fillWithBlocks(world, start, 50, -50, 0, 51, -50, 1, Blocks.STONE_BRICKS.getDefaultState());
        structure.fillWithBlocks(world, start, 50, -50, 31, 50, -50, 33, Blocks.AIR.getDefaultState());
        structure.fillWithBlocks(world, start, 50, -50, 35, 50, -50, 37, Blocks.AIR.getDefaultState());
        structure.fillWithBlocks(world, start, 50, -50, 39, 52, -50, 39, Blocks.AIR.getDefaultState());
        structure.fillWithBlocks(world, start, 50, -50, 40, 51, -49, 40, Blocks.STONE_BRICKS.getDefaultState());
        structure.fillWithBlocks(world, start, 50, -50, 41, 52, -50, 41, Blocks.AIR.getDefaultState());
        structure.fillWithBlocks(world, start, 50, -50, 70, 52, -48, 70, Blocks.STONE_BRICKS.getDefaultState());
        structure.fillWithBlocks(world, start, 50, -49, -72, 51, -49, -64, Blocks.STONE_BRICKS.getDefaultState());
        structure.fillWithBlocks(world, start, 50, -49, -60, 50, -49, -59, Blocks.AIR.getDefaultState());
        structure.fillWithBlocks(world, start, 50, -49, -58, 51, -49, -57, Blocks.STONE_BRICKS.getDefaultState());
        structure.fillWithBlocks(world, start, 50, -49, -56, 50, -49, -53, Blocks.STONE_BRICKS.getDefaultState());
        structure.fillWithBlocks(world, start, 50, -49, -35, 50, -47, -35, Blocks.STONE_BRICKS.getDefaultState());
        structure.fillWithBlocks(world, start, 50, -49, -33, 51, -49, -32, Blocks.STONE_BRICKS.getDefaultState());
        structure.fillWithBlocks(world, start, 50, -49, -8, 51, -49, -6, Blocks.STONE_BRICKS.getDefaultState());
        structure.fillWithBlocks(world, start, 50, -49, 0, 53, -49, 3, Blocks.STONE_BRICKS.getDefaultState());
        structure.fillWithBlocks(world, start, 50, -49, 27, 53, -49, 30, Blocks.STONE_BRICKS.getDefaultState());
        structure.fillWithBlocks(world, start, 50, -49, 37, 51, -49, 42, Blocks.STONE_BRICKS.getDefaultState());
        structure.fillWithBlocks(world, start, 50, -49, 44, 51, -49, 44, Blocks.MOSSY_STONE_BRICKS.getDefaultState());
        structure.fillWithBlocks(world, start, 50, -49, 46, 51, -49, 46, Blocks.MOSSY_STONE_BRICKS.getDefaultState());
        structure.fillWithBlocks(world, start, 50, -49, 58, 53, -49, 62, Blocks.STONE_BRICKS.getDefaultState());
        structure.fillWithBlocks(world, start, 50, -49, 63, 52, -49, 70, Blocks.STONE_BRICKS.getDefaultState());
        structure.fillWithBlocks(world, start, 50, -48, -73, 52, -48, -71, Blocks.STONE_BRICKS.getDefaultState());
        structure.fillWithBlocks(world, start, 50, -48, -69, 53, -48, -66, Blocks.STONE_BRICKS.getDefaultState());
        structure.fillWithBlocks(world, start, 50, -48, -64, 51, -48, -62, Blocks.STONE_BRICKS.getDefaultState());
        structure.fillWithBlocks(world, start, 50, -48, -61, 50, -48, -53, Blocks.STONE_BRICKS.getDefaultState());
        structure.fillWithBlocks(world, start, 50, -48, -6, 50, -48, -6, Blocks.STONE_BRICKS.getDefaultState());
        structure.fillWithBlocks(world, start, 50, -48, 0, 53, -48, 3, Blocks.STONE_BRICKS.getDefaultState());
        structure.fillWithBlocks(world, start, 50, -48, 32, 52, -48, 34, Blocks.STONE_BRICKS.getDefaultState());
        structure.fillWithBlocks(world, start, 50, -48, 35, 51, -48, 38, Blocks.STONE_BRICKS.getDefaultState());
        structure.fillWithBlocks(world, start, 50, -48, 39, 50, -48, 39, Blocks.MOSSY_COBBLESTONE.getDefaultState());
        structure.fillWithBlocks(world, start, 50, -48, 40, 50, -48, 44, Blocks.AIR.getDefaultState());
        structure.fillWithBlocks(world, start, 50, -48, 45, 50, -48, 45, Blocks.STONE_BRICKS.getDefaultState());
        structure.fillWithBlocks(world, start, 50, -48, 47, 50, -47, 47, Blocks.MOSSY_COBBLESTONE.getDefaultState());
        structure.fillWithBlocks(world, start, 50, -48, 58, 53, -48, 67, Blocks.STONE_BRICKS.getDefaultState());
        structure.fillWithBlocks(world, start, 50, -47, -69, 50, -47, -69, Blocks.AIR.getDefaultState());
        structure.fillWithBlocks(world, start, 50, -47, -68, 50, -47, -65, Blocks.STONE_BRICKS.getDefaultState());
        structure.fillWithBlocks(world, start, 50, -47, -64, 50, -47, -63, Blocks.AIR.getDefaultState());
        structure.fillWithBlocks(world, start, 50, -47, -62, 52, -47, -53, Blocks.STONE_BRICKS.getDefaultState());
        structure.fillWithBlocks(world, start, 50, -47, -34, 51, -47, -23, Blocks.STONE_BRICKS.getDefaultState());
        structure.fillWithBlocks(world, start, 50, -47, -6, 50, -47, -6, Blocks.STONE_BRICKS.getDefaultState());
        structure.fillWithBlocks(world, start, 50, -47, 0, 53, -47, 3, Blocks.STONE_BRICKS.getDefaultState());
        structure.fillWithBlocks(world, start, 50, -47, 27, 50, -47, 38, Blocks.STONE_BRICKS.getDefaultState());
        structure.fillWithBlocks(world, start, 50, -46, -31, 54, -46, -31, Blocks.STONE_BRICKS.getDefaultState());
        structure.fillWithBlocks(world, start, 50, -46, -30, 51, -46, -30, Blocks.MOSSY_STONE_BRICKS.getDefaultState());
        structure.fillWithBlocks(world, start, 50, -46, -28, 53, -46, -28, Blocks.MOSSY_COBBLESTONE.getDefaultState());
        structure.fillWithBlocks(world, start, 50, -46, -9, 50, -46, -9, Blocks.AIR.getDefaultState());
        structure.fillWithBlocks(world, start, 50, -46, -6, 51, -46, 1, Blocks.STONE_BRICKS.getDefaultState());
        structure.fillWithBlocks(world, start, 50, -46, 2, 50, -46, 3, Blocks.MOSSY_STONE_BRICKS.getDefaultState());
        structure.fillWithBlocks(world, start, 50, -46, 4, 50, -46, 5, Blocks.MOSSY_COBBLESTONE.getDefaultState());
        structure.fillWithBlocks(world, start, 50, -46, 8, 50, -46, 9, Blocks.MOSSY_STONE_BRICKS.getDefaultState());
        structure.fillWithBlocks(world, start, 50, -46, 10, 50, -46, 10, Blocks.MOSSY_COBBLESTONE.getDefaultState());
        structure.fillWithBlocks(world, start, 50, -46, 11, 50, -46, 11, Blocks.MOSSY_STONE_BRICKS.getDefaultState());
        structure.fillWithBlocks(world, start, 50, -46, 14, 51, -46, 14, Blocks.STONE_BRICKS.getDefaultState());
        structure.fillWithBlocks(world, start, 50, -46, 15, 51, -46, 15, Blocks.MOSSY_STONE_BRICKS.getDefaultState());
        structure.fillWithBlocks(world, start, 50, -46, 16, 50, -46, 17, Blocks.MOSSY_COBBLESTONE.getDefaultState());
        structure.fillWithBlocks(world, start, 50, -46, 20, 50, -46, 21, Blocks.MOSSY_COBBLESTONE.getDefaultState());
        structure.fillWithBlocks(world, start, 50, -46, 23, 50, -46, 23, Blocks.STONE_BRICKS.getDefaultState());
        structure.fillWithBlocks(world, start, 50, -46, 25, 52, -45, 25, Blocks.STONE_BRICKS.getDefaultState());
        structure.fillWithBlocks(world, start, 50, -46, 28, 50, -43, 28, Blocks.STONE_BRICKS.getDefaultState());
        structure.fillWithBlocks(world, start, 50, -46, 33, 50, -46, 34, Blocks.MOSSY_COBBLESTONE.getDefaultState());
        structure.fillWithBlocks(world, start, 50, -46, 38, 51, -46, 38, Blocks.STONE_BRICKS.getDefaultState());
        structure.fillWithBlocks(world, start, 50, -46, 40, 51, -46, 42, Blocks.STONE_BRICKS.getDefaultState());
        structure.fillWithBlocks(world, start, 50, -46, 43, 50, -46, 43, Blocks.MOSSY_COBBLESTONE.getDefaultState());
        structure.fillWithBlocks(world, start, 50, -46, 45, 50, -46, 45, Blocks.STONE_BRICKS.getDefaultState());
        structure.fillWithBlocks(world, start, 50, -46, 46, 50, -46, 46, Blocks.MOSSY_COBBLESTONE.getDefaultState());
        structure.fillWithBlocks(world, start, 50, -46, 47, 50, -46, 48, Blocks.STONE_BRICKS.getDefaultState());
        structure.fillWithBlocks(world, start, 50, -46, 49, 50, -45, 49, Blocks.MOSSY_STONE_BRICKS.getDefaultState());
        structure.fillWithBlocks(world, start, 50, -45, -6, 50, -45, -6, Blocks.STONE_BRICKS.getDefaultState());
        structure.fillWithBlocks(world, start, 50, -45, -5, 50, -43, -1, Blocks.AIR.getDefaultState());
        structure.fillWithBlocks(world, start, 50, -45, 0, 51, -45, 1, Blocks.STONE_BRICKS.getDefaultState());
        structure.fillWithBlocks(world, start, 50, -45, 2, 50, -44, 3, Blocks.STONE_BRICKS.getDefaultState());
        structure.fillWithBlocks(world, start, 50, -45, 5, 50, -42, 9, Blocks.AIR.getDefaultState());
        structure.fillWithBlocks(world, start, 50, -45, 10, 50, -44, 10, Blocks.STONE_BRICKS.getDefaultState());
        structure.fillWithBlocks(world, start, 50, -45, 11, 54, -45, 15, Blocks.AIR.getDefaultState());
        structure.fillWithBlocks(world, start, 50, -45, 17, 50, -42, 21, Blocks.AIR.getDefaultState());
        structure.fillWithBlocks(world, start, 50, -45, 23, 50, -44, 24, Blocks.STONE_BRICKS.getDefaultState());
        structure.fillWithBlocks(world, start, 50, -45, 26, 50, -44, 26, Blocks.STONE_BRICKS.getDefaultState());
        structure.fillWithBlocks(world, start, 50, -45, 39, 51, -44, 39, Blocks.MOSSY_COBBLESTONE.getDefaultState());
        structure.fillWithBlocks(world, start, 50, -45, 48, 50, -45, 48, Blocks.STONE_BRICKS.getDefaultState());
        structure.fillWithBlocks(world, start, 50, -44, -8, 51, -44, -6, Blocks.STONE_BRICKS.getDefaultState());
        structure.fillWithBlocks(world, start, 50, -44, 0, 51, -44, 3, Blocks.STONE_BRICKS.getDefaultState());
        structure.fillWithBlocks(world, start, 50, -44, 4, 50, -43, 4, Blocks.STONE_BRICKS.getDefaultState());
        structure.fillWithBlocks(world, start, 50, -44, 11, 54, -44, 15, Blocks.AIR.getDefaultState());
        structure.fillWithBlocks(world, start, 50, -44, 22, 51, -44, 24, Blocks.STONE_BRICKS.getDefaultState());
        structure.fillWithBlocks(world, start, 50, -44, 31, 50, -44, 32, Blocks.STONE_BRICKS.getDefaultState());
        structure.fillWithBlocks(world, start, 50, -44, 38, 51, -43, 38, Blocks.STONE_BRICKS.getDefaultState());
        structure.fillWithBlocks(world, start, 50, -44, 47, 50, -44, 50, Blocks.STONE_BRICKS.getDefaultState());
        structure.fillWithBlocks(world, start, 50, -43, -26, 51, -43, -26, Blocks.STONE_BRICKS.getDefaultState());
        structure.fillWithBlocks(world, start, 50, -43, -9, 50, -43, -9, Blocks.STONE_BRICKS.getDefaultState());
        structure.fillWithBlocks(world, start, 50, -43, -6, 50, -43, -6, Blocks.STONE_BRICKS.getDefaultState());
        structure.fillWithBlocks(world, start, 50, -43, 0, 51, -43, 1, Blocks.STONE_BRICKS.getDefaultState());
        structure.fillWithBlocks(world, start, 50, -43, 10, 50, -42, 10, Blocks.MOSSY_STONE_BRICKS.getDefaultState());
        structure.fillWithBlocks(world, start, 50, -43, 11, 54, -43, 15, Blocks.AIR.getDefaultState());
        structure.fillWithBlocks(world, start, 50, -43, 16, 50, -40, 16, Blocks.STONE_BRICKS.getDefaultState());
        structure.fillWithBlocks(world, start, 50, -43, 22, 50, -43, 22, Blocks.MOSSY_STONE_BRICKS.getDefaultState());
        structure.fillWithBlocks(world, start, 50, -43, 23, 50, -43, 25, Blocks.STONE_BRICKS.getDefaultState());
        structure.fillWithBlocks(world, start, 50, -43, 27, 50, -43, 28, Blocks.STONE_BRICKS.getDefaultState());
        structure.fillWithBlocks(world, start, 50, -43, 39, 53, -43, 39, Blocks.STONE_BRICKS.getDefaultState());
        structure.fillWithBlocks(world, start, 50, -43, 47, 50, -43, 50, Blocks.STONE_BRICKS.getDefaultState());
        structure.fillWithBlocks(world, start, 50, -42, -30, 52, -42, -30, Blocks.MOSSY_STONE_BRICKS.getDefaultState());
        structure.fillWithBlocks(world, start, 50, -42, -29, 51, -42, -28, Blocks.STONE_BRICKS.getDefaultState());
        structure.fillWithBlocks(world, start, 50, -42, -6, 51, -42, -5, Blocks.STONE_BRICKS.getDefaultState());
        structure.fillWithBlocks(world, start, 50, -42, -4, 50, -42, -2, Blocks.AIR.getDefaultState());
        structure.fillWithBlocks(world, start, 50, -42, -1, 52, -42, 1, Blocks.STONE_BRICKS.getDefaultState());
        structure.fillWithBlocks(world, start, 50, -42, 3, 53, -42, 3, Blocks.STONE_BRICKS.getDefaultState());
        structure.fillWithBlocks(world, start, 50, -42, 4, 51, -42, 4, Blocks.MOSSY_STONE_BRICKS.getDefaultState());
        structure.fillWithBlocks(world, start, 50, -42, 11, 54, -42, 15, Blocks.AIR.getDefaultState());
        structure.fillWithBlocks(world, start, 50, -42, 22, 50, -42, 23, Blocks.STONE_BRICKS.getDefaultState());
        structure.fillWithBlocks(world, start, 50, -42, 26, 50, -42, 27, Blocks.STONE_BRICKS.getDefaultState());
        structure.fillWithBlocks(world, start, 50, -42, 33, 50, -42, 33, Blocks.STONE_BRICKS.getDefaultState());
        structure.fillWithBlocks(world, start, 50, -42, 35, 52, -42, 37, Blocks.STONE_BRICKS.getDefaultState());
        structure.fillWithBlocks(world, start, 50, -42, 38, 50, -42, 39, Blocks.MOSSY_STONE_BRICKS.getDefaultState());
        structure.fillWithBlocks(world, start, 50, -42, 48, 51, -42, 48, Blocks.MOSSY_STONE_BRICKS.getDefaultState());
        structure.fillWithBlocks(world, start, 50, -42, 49, 50, -42, 50, Blocks.STONE_BRICKS.getDefaultState());
        structure.fillWithBlocks(world, start, 50, -41, -9, 50, -41, -8, Blocks.MOSSY_STONE_BRICKS.getDefaultState());
        structure.fillWithBlocks(world, start, 50, -41, -5, 51, -41, 1, Blocks.STONE_BRICKS.getDefaultState());
        structure.fillWithBlocks(world, start, 50, -41, 2, 50, -40, 2, Blocks.STONE_BRICKS.getDefaultState());
        structure.fillWithBlocks(world, start, 50, -41, 5, 50, -41, 7, Blocks.STONE_BRICKS.getDefaultState());
        structure.fillWithBlocks(world, start, 50, -41, 9, 52, -41, 9, Blocks.STONE_BRICKS.getDefaultState());
        structure.fillWithBlocks(world, start, 50, -41, 11, 54, -41, 15, Blocks.AIR.getDefaultState());
        structure.fillWithBlocks(world, start, 50, -41, 17, 50, -41, 19, Blocks.STONE_BRICKS.getDefaultState());
        structure.fillWithBlocks(world, start, 50, -41, 20, 50, -41, 23, Blocks.MOSSY_STONE_BRICKS.getDefaultState());
        structure.fillWithBlocks(world, start, 50, -41, 24, 50, -41, 25, Blocks.AIR.getDefaultState());
        structure.fillWithBlocks(world, start, 50, -41, 36, 50, -41, 37, Blocks.MOSSY_STONE_BRICKS.getDefaultState());
        structure.fillWithBlocks(world, start, 50, -41, 39, 50, -41, 39, Blocks.MOSSY_COBBLESTONE.getDefaultState());
        structure.fillWithBlocks(world, start, 50, -41, 48, 52, -40, 48, Blocks.STONE_BRICKS.getDefaultState());
        structure.fillWithBlocks(world, start, 50, -41, 49, 50, -41, 49, Blocks.MOSSY_STONE_BRICKS.getDefaultState());
        structure.fillWithBlocks(world, start, 50, -40, -8, 51, -40, -2, Blocks.STONE_BRICKS.getDefaultState());
        structure.fillWithBlocks(world, start, 50, -40, 3, 50, -40, 3, Blocks.STONE_BRICKS.getDefaultState());
        structure.fillWithBlocks(world, start, 50, -40, 5, 50, -40, 8, Blocks.STONE_BRICKS.getDefaultState());
        structure.fillWithBlocks(world, start, 50, -40, 11, 52, -39, 11, Blocks.STONE_BRICKS.getDefaultState());
        structure.fillWithBlocks(world, start, 50, -40, 17, 50, -40, 18, Blocks.MOSSY_STONE_BRICKS.getDefaultState());
        structure.fillWithBlocks(world, start, 50, -40, 19, 51, -40, 20, Blocks.STONE_BRICKS.getDefaultState());
        structure.fillWithBlocks(world, start, 50, -40, 37, 50, -40, 37, Blocks.STONE_BRICKS.getDefaultState());
        structure.fillWithBlocks(world, start, 50, -40, 38, 50, -40, 38, Blocks.MOSSY_STONE_BRICKS.getDefaultState());
        structure.fillWithBlocks(world, start, 50, -40, 39, 50, -40, 42, Blocks.STONE_BRICKS.getDefaultState());
        structure.fillWithBlocks(world, start, 50, -40, 43, 51, -40, 43, Blocks.MOSSY_STONE_BRICKS.getDefaultState());
        structure.fillWithBlocks(world, start, 50, -40, 46, 50, -39, 46, Blocks.MOSSY_STONE_BRICKS.getDefaultState());
        structure.fillWithBlocks(world, start, 50, -40, 49, 50, -40, 49, Blocks.STONE_BRICKS.getDefaultState());
        structure.fillWithBlocks(world, start, 50, -39, -8, 50, -39, -6, Blocks.STONE_BRICKS.getDefaultState());
        structure.fillWithBlocks(world, start, 50, -39, -4, 50, -39, -4, Blocks.STONE_BRICKS.getDefaultState());
        structure.fillWithBlocks(world, start, 50, -39, -3, 50, -39, -3, Blocks.MOSSY_COBBLESTONE.getDefaultState());
        structure.fillWithBlocks(world, start, 50, -39, -2, 50, -39, -2, Blocks.STONE_BRICKS.getDefaultState());
        structure.fillWithBlocks(world, start, 50, -39, -1, 50, -38, -1, Blocks.MOSSY_COBBLESTONE.getDefaultState());
        structure.fillWithBlocks(world, start, 50, -39, 0, 50, -39, 0, Blocks.AIR.getDefaultState());
        structure.fillWithBlocks(world, start, 50, -39, 1, 50, -39, 2, Blocks.MOSSY_STONE_BRICKS.getDefaultState());
        structure.fillWithBlocks(world, start, 50, -39, 3, 50, -39, 4, Blocks.STONE_BRICKS.getDefaultState());
        structure.fillWithBlocks(world, start, 50, -39, 5, 50, -39, 6, Blocks.MOSSY_STONE_BRICKS.getDefaultState());
        structure.fillWithBlocks(world, start, 50, -39, 7, 50, -39, 7, Blocks.STONE_BRICKS.getDefaultState());
        structure.fillWithBlocks(world, start, 50, -39, 17, 50, -38, 17, Blocks.MOSSY_STONE_BRICKS.getDefaultState());
        structure.fillWithBlocks(world, start, 50, -39, 19, 51, -38, 19, Blocks.STONE_BRICKS.getDefaultState());
        structure.fillWithBlocks(world, start, 50, -39, 20, 50, -39, 21, Blocks.MOSSY_STONE_BRICKS.getDefaultState());
        structure.fillWithBlocks(world, start, 50, -39, 22, 50, -39, 22, Blocks.STONE_BRICKS.getDefaultState());
        structure.fillWithBlocks(world, start, 50, -39, 23, 50, -39, 25, Blocks.MOSSY_STONE_BRICKS.getDefaultState());
        structure.fillWithBlocks(world, start, 50, -39, 36, 52, -39, 36, Blocks.STONE_BRICKS.getDefaultState());
        structure.fillWithBlocks(world, start, 50, -39, 37, 51, -39, 37, Blocks.MOSSY_STONE_BRICKS.getDefaultState());
        structure.fillWithBlocks(world, start, 50, -39, 38, 55, -39, 38, Blocks.STONE_BRICKS.getDefaultState());
        structure.fillWithBlocks(world, start, 50, -39, 43, 51, -39, 43, Blocks.AIR.getDefaultState());
        structure.fillWithBlocks(world, start, 50, -39, 44, 50, -39, 46, Blocks.MOSSY_STONE_BRICKS.getDefaultState());
        structure.fillWithBlocks(world, start, 50, -39, 47, 50, -37, 47, Blocks.STONE_BRICKS.getDefaultState());
        structure.fillWithBlocks(world, start, 50, -39, 48, 50, -39, 49, Blocks.MOSSY_STONE_BRICKS.getDefaultState());
        structure.fillWithBlocks(world, start, 50, -38, -8, 53, -38, -8, Blocks.MOSSY_STONE_BRICKS.getDefaultState());
        structure.fillWithBlocks(world, start, 50, -38, -6, 50, -37, -5, Blocks.STONE_BRICKS.getDefaultState());
        structure.fillWithBlocks(world, start, 50, -38, -3, 50, -38, -3, Blocks.STONE_BRICKS.getDefaultState());
        structure.fillWithBlocks(world, start, 50, -38, 0, 53, -38, 0, Blocks.STONE_BRICKS.getDefaultState());
        structure.fillWithBlocks(world, start, 50, -38, 3, 50, -37, 4, Blocks.STONE_BRICKS.getDefaultState());
        structure.fillWithBlocks(world, start, 50, -38, 6, 51, -37, 6, Blocks.STONE_BRICKS.getDefaultState());
        structure.fillWithBlocks(world, start, 50, -38, 7, 51, -38, 7, Blocks.MOSSY_STONE_BRICKS.getDefaultState());
        structure.fillWithBlocks(world, start, 50, -38, 9, 51, -38, 9, Blocks.STONE_BRICKS.getDefaultState());
        structure.fillWithBlocks(world, start, 50, -38, 12, 50, -38, 13, Blocks.MOSSY_COBBLESTONE.getDefaultState());
        structure.fillWithBlocks(world, start, 50, -38, 14, 50, -38, 14, Blocks.STONE_BRICKS.getDefaultState());
        structure.fillWithBlocks(world, start, 50, -38, 20, 51, -38, 21, Blocks.STONE_BRICKS.getDefaultState());
        structure.fillWithBlocks(world, start, 50, -38, 24, 50, -38, 25, Blocks.STONE_BRICKS.getDefaultState());
        structure.fillWithBlocks(world, start, 50, -38, 36, 50, -38, 37, Blocks.MOSSY_COBBLESTONE.getDefaultState());
        structure.fillWithBlocks(world, start, 50, -38, 39, 50, -38, 39, Blocks.STONE_BRICKS.getDefaultState());
        structure.fillWithBlocks(world, start, 50, -38, 40, 50, -38, 41, Blocks.AIR.getDefaultState());
        structure.fillWithBlocks(world, start, 50, -38, 45, 50, -38, 46, Blocks.AIR.getDefaultState());
        structure.fillWithBlocks(world, start, 50, -38, 48, 50, -37, 49, Blocks.STONE_BRICKS.getDefaultState());
        structure.fillWithBlocks(world, start, 50, -38, 50, 52, -38, 50, Blocks.MOSSY_STONE_BRICKS.getDefaultState());
        structure.fillWithBlocks(world, start, 50, -37, -9, 51, -37, -8, Blocks.STONE_BRICKS.getDefaultState());
        structure.fillWithBlocks(world, start, 50, -37, -7, 50, -37, -7, Blocks.MOSSY_STONE_BRICKS.getDefaultState());
        structure.fillWithBlocks(world, start, 50, -37, -4, 50, -37, -4, Blocks.STONE_BRICKS.getDefaultState());
        structure.fillWithBlocks(world, start, 50, -37, -2, 51, -37, -1, Blocks.STONE_BRICKS.getDefaultState());
        structure.fillWithBlocks(world, start, 50, -37, 0, 50, -37, 4, Blocks.STONE_BRICKS.getDefaultState());
        structure.fillWithBlocks(world, start, 50, -37, 10, 50, -37, 11, Blocks.STONE_BRICKS.getDefaultState());
        structure.fillWithBlocks(world, start, 50, -37, 12, 50, -37, 12, Blocks.MOSSY_STONE_BRICKS.getDefaultState());
        structure.fillWithBlocks(world, start, 50, -37, 16, 50, -37, 16, Blocks.STONE_BRICKS.getDefaultState());
        structure.fillWithBlocks(world, start, 50, -37, 18, 50, -37, 19, Blocks.STONE_BRICKS.getDefaultState());
        structure.fillWithBlocks(world, start, 50, -37, 20, 50, -37, 20, Blocks.MOSSY_STONE_BRICKS.getDefaultState());
        structure.fillWithBlocks(world, start, 50, -37, 22, 51, -37, 22, Blocks.MOSSY_STONE_BRICKS.getDefaultState());
        structure.fillWithBlocks(world, start, 50, -37, 36, 50, -37, 36, Blocks.STONE_BRICKS.getDefaultState());
        structure.fillWithBlocks(world, start, 50, -37, 38, 50, -37, 39, Blocks.STONE_BRICKS.getDefaultState());
        structure.fillWithBlocks(world, start, 50, -37, 40, 50, -37, 40, Blocks.MOSSY_STONE_BRICKS.getDefaultState());
        structure.fillWithBlocks(world, start, 50, -37, 42, 50, -37, 42, Blocks.STONE_BRICKS.getDefaultState());
        structure.fillWithBlocks(world, start, 50, -37, 43, 50, -37, 43, Blocks.MOSSY_STONE_BRICKS.getDefaultState());
        structure.fillWithBlocks(world, start, 50, -37, 44, 50, -37, 44, Blocks.STONE_BRICKS.getDefaultState());
        structure.fillWithBlocks(world, start, 50, -37, 45, 50, -37, 46, Blocks.MOSSY_STONE_BRICKS.getDefaultState());
        structure.fillWithBlocks(world, start, 50, -26, 62, 52, -26, 64, Blocks.STONE_BRICKS.getDefaultState());
        structure.fillWithBlocks(world, start, 50, -25, 66, 51, -25, 66, Blocks.CRACKED_STONE_BRICKS.getDefaultState());
        structure.fillWithBlocks(world, start, 50, -23, 60, 53, -23, 60, Blocks.STONE_BRICKS.getDefaultState());
        structure.fillWithBlocks(world, start, 50, -23, 66, 53, -23, 66, Blocks.STONE_BRICKS.getDefaultState());
        structure.fillWithBlocks(world, start, 50, -22, 30, 50, -22, 32, Blocks.STONE_BRICKS.getDefaultState());
        structure.fillWithBlocks(world, start, 50, -22, 33, 51, -22, 33, Blocks.CRACKED_STONE_BRICKS.getDefaultState());
        structure.fillWithBlocks(world, start, 50, -22, 61, 50, -22, 61, Blocks.STONE_BRICKS.getDefaultState());
        structure.fillWithBlocks(world, start, 50, -22, 62, 50, -22, 63, Blocks.CRACKED_STONE_BRICKS.getDefaultState());
        structure.fillWithBlocks(world, start, 50, -22, 64, 50, -22, 64, Blocks.STONE_BRICKS.getDefaultState());
        structure.fillWithBlocks(world, start, 50, -15, 34, 67, -15, 34, Blocks.STONE_BRICKS.getDefaultState());
        structure.fillWithBlocks(world, start, 50, -13, 34, 67, -13, 34, Blocks.STONE_BRICKS.getDefaultState());
        structure.fillWithBlocks(world, start, 50, -12, 29, 50, -12, 29, Blocks.STONE_BRICKS.getDefaultState());
        structure.fillWithBlocks(world, start, 50, -12, 30, 50, -12, 31, Blocks.MOSSY_STONE_BRICKS.getDefaultState());
        structure.fillWithBlocks(world, start, 50, -12, 32, 51, -12, 33, Blocks.STONE_BRICKS.getDefaultState());
        structure.fillWithBlocks(world, start, 50, 0, 6, 52, 0, 8, Blocks.GRASS_BLOCK.getDefaultState().with(SnowyDirtBlock.SNOWY, false));
        structure.fillWithBlocks(world, start, 50, 0, 9, 50, 0, 10, Blocks.DIRT.getDefaultState());
        structure.fillWithBlocks(world, start, 50, 0, 33, 60, 0, 43, Blocks.STONE.getDefaultState());
        structure.fillWithBlocks(world, start, 50, 0, 58, 54, 0, 62, Blocks.DIRT.getDefaultState());
        structure.fillWithBlocks(world, start, 50, 1, 10, 51, 1, 10, Blocks.GRASS_BLOCK.getDefaultState().with(SnowyDirtBlock.SNOWY, false));
        structure.fillWithBlocks(world, start, 50, 1, 33, 60, 1, 43, Blocks.STONE.getDefaultState());
        structure.fillWithBlocks(world, start, 50, 1, 51, 50, 1, 51, Blocks.DIRT.getDefaultState());
        structure.fillWithBlocks(world, start, 50, 1, 61, 51, 1, 62, Blocks.GRASS_BLOCK.getDefaultState().with(SnowyDirtBlock.SNOWY, false));
        structure.fillWithBlocks(world, start, 50, 2, 13, 50, 2, 14, Blocks.GRAVEL.getDefaultState());
        structure.fillWithBlocks(world, start, 50, 2, 15, 50, 2, 45, Blocks.STONE.getDefaultState());
        structure.fillWithBlocks(world, start, 50, 2, 46, 50, 3, 46, Blocks.COAL_ORE.getDefaultState());
        structure.fillWithBlocks(world, start, 50, 2, 47, 50, 2, 48, Blocks.STONE.getDefaultState());
        structure.fillWithBlocks(world, start, 50, 2, 58, 52, 2, 60, Blocks.GRASS_BLOCK.getDefaultState().with(SnowyDirtBlock.SNOWY, false));
        structure.fillWithBlocks(world, start, 50, 3, 14, 50, 3, 14, Blocks.GRAVEL.getDefaultState());
        structure.fillWithBlocks(world, start, 50, 3, 15, 50, 3, 45, Blocks.STONE.getDefaultState());
        structure.fillWithBlocks(world, start, 50, 3, 48, 53, 3, 48, Blocks.DIRT.getDefaultState());
        structure.fillWithBlocks(world, start, 50, 3, 49, 52, 3, 51, Blocks.GRASS_BLOCK.getDefaultState().with(SnowyDirtBlock.SNOWY, false));
        structure.fillWithBlocks(world, start, 50, 3, 52, 50, 3, 53, Blocks.DIRT.getDefaultState());
        structure.fillWithBlocks(world, start, 50, 3, 54, 51, 3, 56, Blocks.GRASS_BLOCK.getDefaultState().with(SnowyDirtBlock.SNOWY, false));
        structure.fillWithBlocks(world, start, 50, 4, 52, 50, 4, 53, Blocks.GRASS_BLOCK.getDefaultState().with(SnowyDirtBlock.SNOWY, false));
        structure.fillWithBlocks(world, start, 50, 5, 15, 52, 6, 15, Blocks.DIRT.getDefaultState());
        structure.fillWithBlocks(world, start, 50, 5, 45, 51, 5, 45, Blocks.STONE.getDefaultState());
        structure.fillWithBlocks(world, start, 50, 5, 46, 50, 5, 47, Blocks.DIRT.getDefaultState());
        structure.fillWithBlocks(world, start, 50, 7, 15, 50, 7, 16, Blocks.DIRT.getDefaultState());
        structure.fillWithBlocks(world, start, 50, 7, 45, 51, 7, 45, Blocks.DIRT.getDefaultState());
        structure.fillWithBlocks(world, start, 50, 7, 46, 51, 7, 46, Blocks.GRASS_BLOCK.getDefaultState().with(SnowyDirtBlock.SNOWY, false));
        structure.fillWithBlocks(world, start, 50, 8, 17, 53, 8, 41, Blocks.STONE.getDefaultState());
        structure.fillWithBlocks(world, start, 50, 8, 43, 50, 8, 43, Blocks.DIRT.getDefaultState());
        structure.fillWithBlocks(world, start, 50, 9, 19, 50, 9, 19, Blocks.STONE.getDefaultState());
        structure.fillWithBlocks(world, start, 50, 9, 20, 50, 11, 20, Blocks.DIRT.getDefaultState());
        structure.fillWithBlocks(world, start, 50, 9, 21, 52, 9, 29, Blocks.STONE.getDefaultState());
        structure.fillWithBlocks(world, start, 50, 9, 42, 50, 10, 43, Blocks.DIRT.getDefaultState());
        structure.fillWithBlocks(world, start, 50, 9, 44, 50, 10, 44, Blocks.MOSSY_STONE_BRICKS.getDefaultState());
        structure.fillWithBlocks(world, start, 50, 10, 23, 50, 10, 23, Blocks.DIRT.getDefaultState());
        structure.fillWithBlocks(world, start, 50, 10, 24, 50, 12, 24, Blocks.GRAVEL.getDefaultState());
        structure.fillWithBlocks(world, start, 50, 10, 25, 50, 11, 27, Blocks.DIRT.getDefaultState());
        structure.fillWithBlocks(world, start, 50, 10, 28, 50, 12, 28, Blocks.GRAVEL.getDefaultState());
        structure.fillWithBlocks(world, start, 50, 10, 29, 50, 11, 29, Blocks.DIRT.getDefaultState());
        structure.fillWithBlocks(world, start, 50, 10, 30, 50, 12, 30, Blocks.GRAVEL.getDefaultState());
        structure.fillWithBlocks(world, start, 50, 10, 31, 50, 11, 33, Blocks.DIRT.getDefaultState());
        structure.fillWithBlocks(world, start, 50, 10, 34, 50, 12, 34, Blocks.GRAVEL.getDefaultState());
        structure.fillWithBlocks(world, start, 50, 10, 35, 50, 10, 37, Blocks.DIRT.getDefaultState());
        structure.fillWithBlocks(world, start, 50, 10, 38, 50, 12, 38, Blocks.GRAVEL.getDefaultState());
        structure.fillWithBlocks(world, start, 50, 10, 39, 50, 11, 40, Blocks.DIRT.getDefaultState());
        structure.fillWithBlocks(world, start, 50, 10, 41, 50, 12, 41, Blocks.GRAVEL.getDefaultState());
        structure.fillWithBlocks(world, start, 50, 11, 18, 51, 11, 23, Blocks.DIRT.getDefaultState());
        structure.fillWithBlocks(world, start, 50, 11, 35, 50, 11, 37, Blocks.DIRT.getDefaultState());
        structure.fillWithBlocks(world, start, 50, 11, 42, 51, 11, 42, Blocks.DIRT.getDefaultState());
        structure.fillWithBlocks(world, start, 50, 11, 43, 51, 11, 43, Blocks.CRACKED_STONE_BRICKS.getDefaultState());
        structure.fillWithBlocks(world, start, 50, 12, 18, 51, 12, 19, Blocks.DIRT.getDefaultState());
        structure.fillWithBlocks(world, start, 50, 12, 23, 50, 12, 23, Blocks.GRASS_BLOCK.getDefaultState().with(SnowyDirtBlock.SNOWY, false));
        structure.fillWithBlocks(world, start, 50, 12, 25, 50, 12, 27, Blocks.GRASS_BLOCK.getDefaultState().with(SnowyDirtBlock.SNOWY, false));
        structure.fillWithBlocks(world, start, 50, 12, 29, 50, 12, 29, Blocks.GRASS_BLOCK.getDefaultState().with(SnowyDirtBlock.SNOWY, false));
        structure.fillWithBlocks(world, start, 50, 12, 33, 50, 12, 33, Blocks.GRASS_BLOCK.getDefaultState().with(SnowyDirtBlock.SNOWY, false));
        structure.fillWithBlocks(world, start, 50, 12, 35, 50, 12, 35, Blocks.GRASS_BLOCK.getDefaultState().with(SnowyDirtBlock.SNOWY, false));
        structure.fillWithBlocks(world, start, 50, 12, 37, 50, 12, 37, Blocks.GRASS_BLOCK.getDefaultState().with(SnowyDirtBlock.SNOWY, false));
        structure.fillWithBlocks(world, start, 50, 12, 39, 50, 12, 40, Blocks.GRASS_BLOCK.getDefaultState().with(SnowyDirtBlock.SNOWY, false));
        structure.fillWithBlocks(world, start, 50, 12, 42, 50, 12, 44, Blocks.CRACKED_STONE_BRICKS.getDefaultState());
        structure.fillWithBlocks(world, start, 50, 13, 18, 50, 13, 18, Blocks.CRACKED_STONE_BRICKS.getDefaultState());
        structure.fillWithBlocks(world, start, 50, 13, 25, 50, 13, 26, Blocks.GRASS.getDefaultState());
        structure.fillWithBlocks(world, start, 50, 13, 31, 50, 13, 32, Blocks.COBBLESTONE_SLAB.getDefaultState().with(SlabBlock.TYPE, SlabType.BOTTOM).with(SlabBlock.WATERLOGGED, false));
        structure.fillWithBlocks(world, start, 50, 13, 33, 50, 13, 33, Blocks.GRASS.getDefaultState());
        structure.fillWithBlocks(world, start, 50, 13, 43, 52, 13, 43, Blocks.CRACKED_STONE_BRICKS.getDefaultState());
        structure.fillWithBlocks(world, start, 50, 13, 44, 50, 14, 44, Blocks.STONE_BRICK_STAIRS.getDefaultState().with(StairsBlock.FACING, Direction.WEST).with(StairsBlock.WATERLOGGED, false).with(StairsBlock.SHAPE, StairsShape.STRAIGHT).with(StairsBlock.HALF, Half.BOTTOM));
        structure.fillWithBlocks(world, start, 50, 14, 17, 50, 14, 18, Blocks.CRACKED_STONE_BRICKS.getDefaultState());
        structure.fillWithBlocks(world, start, 50, 14, 42, 50, 14, 43, Blocks.CRACKED_STONE_BRICKS.getDefaultState());
        structure.fillWithBlocks(world, start, 50, 15, 18, 50, 15, 18, Blocks.CRACKED_STONE_BRICKS.getDefaultState());
        structure.fillWithBlocks(world, start, 50, 16, 18, 50, 16, 18, Blocks.CRACKED_STONE_BRICKS.getDefaultState());
        structure.fillWithBlocks(world, start, 50, 16, 19, 50, 16, 20, Blocks.STONE_BRICK_STAIRS.getDefaultState().with(StairsBlock.FACING, Direction.EAST).with(StairsBlock.WATERLOGGED, false).with(StairsBlock.SHAPE, StairsShape.STRAIGHT).with(StairsBlock.HALF, Half.TOP));
        structure.fillWithBlocks(world, start, 50, 16, 42, 51, 16, 42, Blocks.CRACKED_STONE_BRICKS.getDefaultState());
        structure.fillWithBlocks(world, start, 50, 17, 19, 50, 17, 20, Blocks.CRACKED_STONE_BRICKS.getDefaultState());
        structure.fillWithBlocks(world, start, 51, -59, 28, 53, -59, 46, Blocks.STONE_BRICKS.getDefaultState());
        structure.fillWithBlocks(world, start, 51, -58, -67, 51, -57, -59, Blocks.STONE_BRICKS.getDefaultState());
        structure.fillWithBlocks(world, start, 51, -58, 31, 51, -58, 31, Blocks.AIR.getDefaultState());
        structure.fillWithBlocks(world, start, 51, -58, 33, 52, -58, 34, Blocks.AIR.getDefaultState());
        structure.fillWithBlocks(world, start, 51, -58, 35, 51, -58, 35, Blocks.SHROOMLIGHT.getDefaultState());
        structure.fillWithBlocks(world, start, 51, -58, 36, 51, -56, 36, Blocks.STONE_BRICKS.getDefaultState());
        structure.fillWithBlocks(world, start, 51, -58, 37, 52, -57, 37, Blocks.SHROOMLIGHT.getDefaultState());
        structure.fillWithBlocks(world, start, 51, -58, 41, 52, -57, 41, Blocks.AIR.getDefaultState());
        structure.fillWithBlocks(world, start, 51, -58, 47, 51, -52, 47, Blocks.STONE_BRICKS.getDefaultState());
        structure.fillWithBlocks(world, start, 51, -57, 25, 54, -57, 28, Blocks.STONE_BRICKS.getDefaultState());
        structure.fillWithBlocks(world, start, 51, -57, 35, 51, -57, 35, Blocks.SHROOMLIGHT.getDefaultState());
        structure.fillWithBlocks(world, start, 51, -56, -73, 53, -56, -71, Blocks.STONE_BRICKS.getDefaultState());
        structure.fillWithBlocks(world, start, 51, -56, -66, 51, -56, -66, Blocks.STONE_BRICKS.getDefaultState());
        structure.fillWithBlocks(world, start, 51, -56, -65, 51, -56, -61, Blocks.STONE_BRICK_STAIRS.getDefaultState().with(StairsBlock.FACING, Direction.EAST).with(StairsBlock.WATERLOGGED, false).with(StairsBlock.SHAPE, StairsShape.STRAIGHT).with(StairsBlock.HALF, Half.BOTTOM));
        structure.fillWithBlocks(world, start, 51, -56, -60, 53, -56, -57, Blocks.STONE_BRICKS.getDefaultState());
        structure.fillWithBlocks(world, start, 51, -56, -26, 53, -56, -24, Blocks.STONE_BRICKS.getDefaultState());
        structure.fillWithBlocks(world, start, 51, -56, 1, 53, -56, 3, Blocks.STONE_BRICKS.getDefaultState());
        structure.fillWithBlocks(world, start, 51, -56, 60, 53, -56, 65, Blocks.STONE_BRICKS.getDefaultState());
        structure.fillWithBlocks(world, start, 51, -56, 68, 53, -56, 70, Blocks.STONE_BRICKS.getDefaultState());
        structure.fillWithBlocks(world, start, 51, -55, -73, 53, -55, -71, Blocks.STONE_BRICKS.getDefaultState());
        structure.fillWithBlocks(world, start, 51, -55, -68, 51, -48, -68, Blocks.STONE_BRICKS.getDefaultState());
        structure.fillWithBlocks(world, start, 51, -55, -67, 51, -50, -67, Blocks.AIR.getDefaultState());
        structure.fillWithBlocks(world, start, 51, -55, -66, 51, -47, -66, Blocks.STONE_BRICKS.getDefaultState());
        structure.fillWithBlocks(world, start, 51, -55, -65, 53, -55, -61, Blocks.AIR.getDefaultState());
        structure.fillWithBlocks(world, start, 51, -55, -60, 51, -47, -60, Blocks.STONE_BRICKS.getDefaultState());
        structure.fillWithBlocks(world, start, 51, -55, -59, 51, -50, -59, Blocks.AIR.getDefaultState());
        structure.fillWithBlocks(world, start, 51, -55, -58, 51, -47, -58, Blocks.STONE_BRICKS.getDefaultState());
        structure.fillWithBlocks(world, start, 51, -55, -57, 51, -54, -56, Blocks.AIR.getDefaultState());
        structure.fillWithBlocks(world, start, 51, -55, -35, 53, -55, -32, Blocks.STONE_BRICKS.getDefaultState());
        structure.fillWithBlocks(world, start, 51, -55, -9, 52, -55, -2, Blocks.STONE_BRICKS.getDefaultState());
        structure.fillWithBlocks(world, start, 51, -55, -1, 51, -55, 3, Blocks.STONE_BRICKS.getDefaultState());
        structure.fillWithBlocks(world, start, 51, -55, 25, 51, -55, 25, Blocks.STONE_BRICKS.getDefaultState());
        structure.fillWithBlocks(world, start, 51, -55, 61, 53, -55, 63, Blocks.STONE_BRICKS.getDefaultState());
        structure.fillWithBlocks(world, start, 51, -55, 64, 51, -55, 67, Blocks.STONE_BRICKS.getDefaultState());
        structure.fillWithBlocks(world, start, 51, -55, 69, 51, -55, 69, Blocks.STONE_BRICKS.getDefaultState());
        structure.fillWithBlocks(world, start, 51, -54, -65, 53, -54, -61, Blocks.AIR.getDefaultState());
        structure.fillWithBlocks(world, start, 51, -54, -53, 51, -50, -53, Blocks.STONE_BRICKS.getDefaultState());
        structure.fillWithBlocks(world, start, 51, -54, -35, 52, -54, -33, Blocks.STONE_BRICKS.getDefaultState());
        structure.fillWithBlocks(world, start, 51, -54, -25, 53, -54, -23, Blocks.STONE_BRICKS.getDefaultState());
        structure.fillWithBlocks(world, start, 51, -54, -6, 53, -54, -4, Blocks.STONE_BRICKS.getDefaultState());
        structure.fillWithBlocks(world, start, 51, -54, -3, 52, -54, -3, Blocks.SHROOMLIGHT.getDefaultState());
        structure.fillWithBlocks(world, start, 51, -54, -2, 52, -54, 3, Blocks.STONE_BRICKS.getDefaultState());
        structure.fillWithBlocks(world, start, 51, -54, 18, 51, -53, 19, Blocks.STONE_BRICKS.getDefaultState());
        structure.fillWithBlocks(world, start, 51, -54, 25, 51, -54, 25, Blocks.STONE_BRICKS.getDefaultState());
        structure.fillWithBlocks(world, start, 51, -54, 60, 52, -54, 60, Blocks.AIR.getDefaultState());
        structure.fillWithBlocks(world, start, 51, -54, 61, 52, -54, 63, Blocks.STONE_BRICKS.getDefaultState());
        structure.fillWithBlocks(world, start, 51, -54, 64, 52, -54, 64, Blocks.SHROOMLIGHT.getDefaultState());
        structure.fillWithBlocks(world, start, 51, -54, 65, 52, -54, 68, Blocks.STONE_BRICKS.getDefaultState());
        structure.fillWithBlocks(world, start, 51, -54, 69, 51, -54, 70, Blocks.STONE_BRICKS.getDefaultState());
        structure.fillWithBlocks(world, start, 51, -53, -65, 53, -53, -61, Blocks.AIR.getDefaultState());
        structure.fillWithBlocks(world, start, 51, -53, -57, 51, -52, -56, Blocks.AIR.getDefaultState());
        structure.fillWithBlocks(world, start, 51, -53, -35, 53, -53, -32, Blocks.STONE_BRICKS.getDefaultState());
        structure.fillWithBlocks(world, start, 51, -53, -6, 52, -53, -2, Blocks.STONE_BRICKS.getDefaultState());
        structure.fillWithBlocks(world, start, 51, -53, -1, 51, -53, 3, Blocks.STONE_BRICKS.getDefaultState());
        structure.fillWithBlocks(world, start, 51, -53, 25, 51, -53, 25, Blocks.STONE_BRICKS.getDefaultState());
        structure.fillWithBlocks(world, start, 51, -53, 58, 51, -53, 58, Blocks.STONE_BRICKS.getDefaultState());
        structure.fillWithBlocks(world, start, 51, -53, 60, 53, -53, 70, Blocks.STONE_BRICKS.getDefaultState());
        structure.fillWithBlocks(world, start, 51, -52, -73, 53, -52, -71, Blocks.STONE_BRICKS.getDefaultState());
        structure.fillWithBlocks(world, start, 51, -52, -65, 53, -52, -61, Blocks.AIR.getDefaultState());
        structure.fillWithBlocks(world, start, 51, -52, -55, 51, -52, -55, Blocks.STONE_BRICKS.getDefaultState());
        structure.fillWithBlocks(world, start, 51, -52, -35, 51, -52, -35, Blocks.STONE_BRICKS.getDefaultState());
        structure.fillWithBlocks(world, start, 51, -52, -34, 51, -52, -33, Blocks.AIR.getDefaultState());
        structure.fillWithBlocks(world, start, 51, -52, -32, 53, -52, -23, Blocks.STONE_BRICKS.getDefaultState());
        structure.fillWithBlocks(world, start, 51, -52, -5, 52, -52, -4, Blocks.STONE_BRICKS.getDefaultState());
        structure.fillWithBlocks(world, start, 51, -52, -3, 51, -52, 3, Blocks.STONE_BRICKS.getDefaultState());
        structure.fillWithBlocks(world, start, 51, -52, 42, 64, -52, 42, Blocks.STONE_BRICKS.getDefaultState());
        structure.fillWithBlocks(world, start, 51, -52, 58, 53, -52, 63, Blocks.STONE_BRICKS.getDefaultState());
        structure.fillWithBlocks(world, start, 51, -52, 64, 52, -52, 68, Blocks.STONE_BRICKS.getDefaultState());
        structure.fillWithBlocks(world, start, 51, -51, -73, 53, -51, -71, Blocks.STONE_BRICKS.getDefaultState());
        structure.fillWithBlocks(world, start, 51, -51, -65, 53, -51, -61, Blocks.AIR.getDefaultState());
        structure.fillWithBlocks(world, start, 51, -51, -57, 51, -51, -56, Blocks.AIR.getDefaultState());
        structure.fillWithBlocks(world, start, 51, -51, -55, 51, -50, -53, Blocks.STONE_BRICKS.getDefaultState());
        structure.fillWithBlocks(world, start, 51, -51, -9, 53, -51, 3, Blocks.STONE_BRICKS.getDefaultState());
        structure.fillWithBlocks(world, start, 51, -51, 27, 51, -51, 27, Blocks.STONE_BRICKS.getDefaultState());
        structure.fillWithBlocks(world, start, 51, -51, 29, 53, -51, 31, Blocks.STONE_BRICKS.getDefaultState());
        structure.fillWithBlocks(world, start, 51, -51, 33, 53, -51, 35, Blocks.STONE_BRICKS.getDefaultState());
        structure.fillWithBlocks(world, start, 51, -51, 36, 51, -50, 36, Blocks.SHROOMLIGHT.getDefaultState());
        structure.fillWithBlocks(world, start, 51, -51, 37, 53, -51, 39, Blocks.STONE_BRICKS.getDefaultState());
        structure.fillWithBlocks(world, start, 51, -51, 41, 51, -51, 41, Blocks.STONE_BRICKS.getDefaultState());
        structure.fillWithBlocks(world, start, 51, -51, 43, 52, -51, 46, Blocks.STONE_BRICKS.getDefaultState());
        structure.fillWithBlocks(world, start, 51, -50, -73, 52, -50, -71, Blocks.STONE_BRICKS.getDefaultState());
        structure.fillWithBlocks(world, start, 51, -50, -65, 53, -50, -60, Blocks.STONE_BRICKS.getDefaultState());
        structure.fillWithBlocks(world, start, 51, -50, -30, 53, -50, -28, Blocks.STONE_BRICKS.getDefaultState());
        structure.fillWithBlocks(world, start, 51, -50, -9, 53, -50, -6, Blocks.STONE_BRICKS.getDefaultState());
        structure.fillWithBlocks(world, start, 51, -50, -5, 51, -50, 1, Blocks.STONE_BRICKS.getDefaultState());
        structure.fillWithBlocks(world, start, 51, -50, 3, 53, -48, 3, Blocks.STONE_BRICKS.getDefaultState());
        structure.fillWithBlocks(world, start, 51, -50, 27, 51, -50, 27, Blocks.STONE_BRICKS.getDefaultState());
        structure.fillWithBlocks(world, start, 51, -50, 29, 52, -50, 30, Blocks.STONE_BRICKS.getDefaultState());
        structure.fillWithBlocks(world, start, 51, -50, 31, 51, -50, 31, Blocks.AIR.getDefaultState());
        structure.fillWithBlocks(world, start, 51, -50, 32, 51, -47, 32, Blocks.STONE_BRICKS.getDefaultState());
        structure.fillWithBlocks(world, start, 51, -50, 35, 51, -50, 35, Blocks.AIR.getDefaultState());
        structure.fillWithBlocks(world, start, 51, -50, 37, 52, -50, 37, Blocks.AIR.getDefaultState());
        structure.fillWithBlocks(world, start, 51, -50, 42, 52, -50, 46, Blocks.STONE_BRICKS.getDefaultState());
        structure.fillWithBlocks(world, start, 51, -50, 67, 53, -50, 70, Blocks.STONE_BRICKS.getDefaultState());
        structure.fillWithBlocks(world, start, 51, -49, -73, 52, -49, -72, Blocks.STONE_BRICKS.getDefaultState());
        structure.fillWithBlocks(world, start, 51, -49, -63, 51, -49, -62, Blocks.AIR.getDefaultState());
        structure.fillWithBlocks(world, start, 51, -49, -61, 54, -49, -58, Blocks.STONE_BRICKS.getDefaultState());
        structure.fillWithBlocks(world, start, 51, -49, -55, 52, -49, -54, Blocks.STONE_BRICKS.getDefaultState());
        structure.fillWithBlocks(world, start, 51, -49, -34, 53, -49, -32, Blocks.STONE_BRICKS.getDefaultState());
        structure.fillWithBlocks(world, start, 51, -49, -31, 52, -49, -26, Blocks.STONE_BRICKS.getDefaultState());
        structure.fillWithBlocks(world, start, 51, -49, -9, 52, -49, -8, Blocks.STONE_BRICKS.getDefaultState());
        structure.fillWithBlocks(world, start, 51, -49, -5, 53, -49, -2, Blocks.STONE_BRICKS.getDefaultState());
        structure.fillWithBlocks(world, start, 51, -49, -1, 52, -49, 3, Blocks.STONE_BRICKS.getDefaultState());
        structure.fillWithBlocks(world, start, 51, -49, 33, 53, -49, 36, Blocks.STONE_BRICKS.getDefaultState());
        structure.fillWithBlocks(world, start, 51, -49, 45, 51, -49, 45, Blocks.STONE_BRICKS.getDefaultState());
        structure.fillWithBlocks(world, start, 51, -48, -70, 54, -48, -63, Blocks.STONE_BRICKS.getDefaultState());
        structure.fillWithBlocks(world, start, 51, -48, -53, 57, -47, -53, Blocks.STONE_BRICKS.getDefaultState());
        structure.fillWithBlocks(world, start, 51, -48, -9, 53, -48, -4, Blocks.STONE_BRICKS.getDefaultState());
        structure.fillWithBlocks(world, start, 51, -48, -3, 52, -48, -2, Blocks.STONE_BRICKS.getDefaultState());
        structure.fillWithBlocks(world, start, 51, -48, -1, 51, -48, 3, Blocks.STONE_BRICKS.getDefaultState());
        structure.fillWithBlocks(world, start, 51, -48, 39, 51, -48, 40, Blocks.MOSSY_COBBLESTONE.getDefaultState());
        structure.fillWithBlocks(world, start, 51, -48, 42, 52, -48, 43, Blocks.STONE_BRICKS.getDefaultState());
        structure.fillWithBlocks(world, start, 51, -48, 45, 52, -48, 46, Blocks.STONE_BRICKS.getDefaultState());
        structure.fillWithBlocks(world, start, 51, -48, 47, 51, -47, 47, Blocks.STONE_BRICKS.getDefaultState());
        structure.fillWithBlocks(world, start, 51, -47, -73, 52, -47, -72, Blocks.STONE_BRICKS.getDefaultState());
        structure.fillWithBlocks(world, start, 51, -47, -70, 52, -47, -69, Blocks.STONE_BRICKS.getDefaultState());
        structure.fillWithBlocks(world, start, 51, -47, -67, 52, -47, -66, Blocks.STONE_BRICKS.getDefaultState());
        structure.fillWithBlocks(world, start, 51, -47, -65, 51, -47, -53, Blocks.STONE_BRICKS.getDefaultState());
        structure.fillWithBlocks(world, start, 51, -47, -35, 51, -47, -23, Blocks.STONE_BRICKS.getDefaultState());
        structure.fillWithBlocks(world, start, 51, -47, -9, 52, -47, -4, Blocks.STONE_BRICKS.getDefaultState());
        structure.fillWithBlocks(world, start, 51, -47, -3, 51, -47, 3, Blocks.STONE_BRICKS.getDefaultState());
        structure.fillWithBlocks(world, start, 51, -47, 27, 51, -47, 27, Blocks.STONE_BRICKS.getDefaultState());
        structure.fillWithBlocks(world, start, 51, -47, 35, 51, -47, 36, Blocks.STONE_BRICKS.getDefaultState());
        structure.fillWithBlocks(world, start, 51, -47, 38, 51, -47, 38, Blocks.STONE_BRICKS.getDefaultState());
        structure.fillWithBlocks(world, start, 51, -47, 39, 51, -47, 41, Blocks.MOSSY_STONE_BRICKS.getDefaultState());
        structure.fillWithBlocks(world, start, 51, -47, 43, 52, -47, 44, Blocks.STONE_BRICKS.getDefaultState());
        structure.fillWithBlocks(world, start, 51, -47, 45, 51, -47, 46, Blocks.MOSSY_COBBLESTONE.getDefaultState());
        structure.fillWithBlocks(world, start, 51, -47, 58, 52, -47, 59, Blocks.STONE_BRICKS.getDefaultState());
        structure.fillWithBlocks(world, start, 51, -47, 61, 52, -47, 67, Blocks.STONE_BRICKS.getDefaultState());
        structure.fillWithBlocks(world, start, 51, -46, -32, 51, -46, -31, Blocks.STONE_BRICKS.getDefaultState());
        structure.fillWithBlocks(world, start, 51, -46, -29, 51, -46, -28, Blocks.MOSSY_COBBLESTONE.getDefaultState());
        structure.fillWithBlocks(world, start, 51, -46, -9, 51, -46, -9, Blocks.STONE_BRICKS.getDefaultState());
        structure.fillWithBlocks(world, start, 51, -46, -8, 51, -46, -7, Blocks.AIR.getDefaultState());
        structure.fillWithBlocks(world, start, 51, -46, 4, 51, -46, 5, Blocks.STONE_BRICKS.getDefaultState());
        structure.fillWithBlocks(world, start, 51, -46, 6, 52, -46, 6, Blocks.MOSSY_COBBLESTONE.getDefaultState());
        structure.fillWithBlocks(world, start, 51, -46, 9, 57, -46, 9, Blocks.STONE_BRICKS.getDefaultState());
        structure.fillWithBlocks(world, start, 51, -46, 10, 52, -46, 11, Blocks.MOSSY_COBBLESTONE.getDefaultState());
        structure.fillWithBlocks(world, start, 51, -46, 13, 51, -46, 13, Blocks.MOSSY_COBBLESTONE.getDefaultState());
        structure.fillWithBlocks(world, start, 51, -46, 16, 52, -46, 16, Blocks.MOSSY_COBBLESTONE.getDefaultState());
        structure.fillWithBlocks(world, start, 51, -46, 17, 52, -46, 17, Blocks.STONE_BRICKS.getDefaultState());
        structure.fillWithBlocks(world, start, 51, -46, 19, 51, -46, 21, Blocks.STONE_BRICKS.getDefaultState());
        structure.fillWithBlocks(world, start, 51, -46, 23, 52, -46, 25, Blocks.STONE_BRICKS.getDefaultState());
        structure.fillWithBlocks(world, start, 51, -46, 33, 54, -46, 33, Blocks.STONE_BRICKS.getDefaultState());
        structure.fillWithBlocks(world, start, 51, -46, 34, 52, -46, 36, Blocks.MOSSY_COBBLESTONE.getDefaultState());
        structure.fillWithBlocks(world, start, 51, -46, 39, 52, -46, 39, Blocks.MOSSY_COBBLESTONE.getDefaultState());
        structure.fillWithBlocks(world, start, 51, -46, 43, 52, -46, 43, Blocks.STONE_BRICKS.getDefaultState());
        structure.fillWithBlocks(world, start, 51, -46, 45, 52, -46, 45, Blocks.AIR.getDefaultState());
        structure.fillWithBlocks(world, start, 51, -46, 46, 51, -46, 46, Blocks.STONE_BRICKS.getDefaultState());
        structure.fillWithBlocks(world, start, 51, -46, 48, 51, -46, 48, Blocks.MOSSY_STONE_BRICKS.getDefaultState());
        structure.fillWithBlocks(world, start, 51, -46, 49, 51, -45, 49, Blocks.STONE_BRICKS.getDefaultState());
        structure.fillWithBlocks(world, start, 51, -46, 50, 52, -46, 50, Blocks.MOSSY_STONE_BRICKS.getDefaultState());
        structure.fillWithBlocks(world, start, 51, -45, -26, 51, -44, -26, Blocks.MOSSY_STONE_BRICKS.getDefaultState());
        structure.fillWithBlocks(world, start, 51, -45, -9, 51, -45, -9, Blocks.MOSSY_STONE_BRICKS.getDefaultState());
        structure.fillWithBlocks(world, start, 51, -45, -8, 51, -43, -4, Blocks.STONE_BRICKS.getDefaultState());
        structure.fillWithBlocks(world, start, 51, -45, -3, 51, -45, 1, Blocks.STONE_BRICKS.getDefaultState());
        structure.fillWithBlocks(world, start, 51, -45, 2, 51, -45, 3, Blocks.MOSSY_COBBLESTONE.getDefaultState());
        structure.fillWithBlocks(world, start, 51, -45, 4, 51, -45, 4, Blocks.MOSSY_STONE_BRICKS.getDefaultState());
        structure.fillWithBlocks(world, start, 51, -45, 5, 51, -42, 5, Blocks.STONE_BRICKS.getDefaultState());
        structure.fillWithBlocks(world, start, 51, -45, 7, 51, -45, 7, Blocks.AIR.getDefaultState());
        structure.fillWithBlocks(world, start, 51, -45, 10, 55, -45, 16, Blocks.AIR.getDefaultState());
        structure.fillWithBlocks(world, start, 51, -45, 18, 51, -43, 18, Blocks.STONE_BRICK_WALL.getDefaultState().with(WallBlock.WATERLOGGED, false).with(WallBlock.UP, true).with(WallBlock.WALL_HEIGHT_NORTH, WallHeight.LOW).with(WallBlock.WALL_HEIGHT_SOUTH, WallHeight.LOW).with(WallBlock.WALL_HEIGHT_EAST, WallHeight.LOW).with(WallBlock.WALL_HEIGHT_WEST, WallHeight.LOW));
        structure.fillWithBlocks(world, start, 51, -45, 19, 51, -45, 19, Blocks.AIR.getDefaultState());
        structure.fillWithBlocks(world, start, 51, -45, 20, 51, -43, 20, Blocks.STONE_BRICK_WALL.getDefaultState().with(WallBlock.WATERLOGGED, false).with(WallBlock.UP, false).with(WallBlock.WALL_HEIGHT_NORTH, WallHeight.LOW).with(WallBlock.WALL_HEIGHT_SOUTH, WallHeight.LOW).with(WallBlock.WALL_HEIGHT_EAST, WallHeight.LOW).with(WallBlock.WALL_HEIGHT_WEST, WallHeight.LOW));
        structure.fillWithBlocks(world, start, 51, -45, 21, 51, -45, 21, Blocks.INFESTED_COBBLESTONE.getDefaultState());
        structure.fillWithBlocks(world, start, 51, -45, 22, 51, -45, 23, Blocks.MOSSY_STONE_BRICKS.getDefaultState());
        structure.fillWithBlocks(world, start, 51, -45, 38, 51, -42, 38, Blocks.STONE_BRICKS.getDefaultState());
        structure.fillWithBlocks(world, start, 51, -45, 40, 51, -44, 41, Blocks.STONE_BRICKS.getDefaultState());
        structure.fillWithBlocks(world, start, 51, -45, 42, 51, -45, 43, Blocks.MOSSY_COBBLESTONE.getDefaultState());
        structure.fillWithBlocks(world, start, 51, -45, 44, 51, -45, 50, Blocks.STONE_BRICKS.getDefaultState());
        structure.fillWithBlocks(world, start, 51, -44, -32, 51, -43, -32, Blocks.STONE_BRICKS.getDefaultState());
        structure.fillWithBlocks(world, start, 51, -44, -2, 53, -44, 1, Blocks.STONE_BRICKS.getDefaultState());
        structure.fillWithBlocks(world, start, 51, -44, 4, 52, -44, 4, Blocks.MOSSY_STONE_BRICKS.getDefaultState());
        structure.fillWithBlocks(world, start, 51, -44, 7, 51, -44, 7, Blocks.AIR.getDefaultState());
        structure.fillWithBlocks(world, start, 51, -44, 8, 51, -43, 8, Blocks.STONE_BRICK_WALL.getDefaultState().with(WallBlock.WATERLOGGED, false).with(WallBlock.UP, false).with(WallBlock.WALL_HEIGHT_NORTH, WallHeight.LOW).with(WallBlock.WALL_HEIGHT_SOUTH, WallHeight.LOW).with(WallBlock.WALL_HEIGHT_EAST, WallHeight.LOW).with(WallBlock.WALL_HEIGHT_WEST, WallHeight.LOW));
        structure.fillWithBlocks(world, start, 51, -44, 9, 51, -40, 9, Blocks.STONE_BRICKS.getDefaultState());
        structure.fillWithBlocks(world, start, 51, -44, 10, 55, -44, 16, Blocks.AIR.getDefaultState());
        structure.fillWithBlocks(world, start, 51, -44, 17, 51, -43, 17, Blocks.STONE_BRICKS.getDefaultState());
        structure.fillWithBlocks(world, start, 51, -44, 19, 51, -44, 19, Blocks.AIR.getDefaultState());
        structure.fillWithBlocks(world, start, 51, -44, 21, 52, -44, 23, Blocks.STONE_BRICKS.getDefaultState());
        structure.fillWithBlocks(world, start, 51, -44, 25, 51, -39, 25, Blocks.STONE_BRICKS.getDefaultState());
        structure.fillWithBlocks(world, start, 51, -44, 32, 51, -43, 32, Blocks.STONE_BRICKS.getDefaultState());
        structure.fillWithBlocks(world, start, 51, -44, 42, 51, -42, 42, Blocks.MOSSY_COBBLESTONE.getDefaultState());
        structure.fillWithBlocks(world, start, 51, -44, 45, 51, -44, 45, Blocks.STONE_BRICKS.getDefaultState());
        structure.fillWithBlocks(world, start, 51, -44, 46, 51, -44, 47, Blocks.MOSSY_STONE_BRICKS.getDefaultState());
        structure.fillWithBlocks(world, start, 51, -44, 50, 52, -44, 50, Blocks.STONE_BRICKS.getDefaultState());
        structure.fillWithBlocks(world, start, 51, -43, -9, 51, -43, 2, Blocks.STONE_BRICKS.getDefaultState());
        structure.fillWithBlocks(world, start, 51, -43, 4, 52, -43, 5, Blocks.STONE_BRICKS.getDefaultState());
