package mod.arcalitegames.odyssey.world.structure.structures.dungeons.masoleum;

import mod.arcalitegames.odyssey.world.structure.StructureBase;
import net.minecraft.block.Blocks;
import net.minecraft.block.CactusBlock;
import net.minecraft.block.FourWayBlock;
import net.minecraft.block.RedstoneWireBlock;
import net.minecraft.block.StairsBlock;
import net.minecraft.state.properties.Half;
import net.minecraft.state.properties.RedstoneSide;
import net.minecraft.state.properties.StairsShape;
import net.minecraft.util.Direction;
import net.minecraft.util.math.BlockPos;
import net.minecraft.world.World;

public class MasoleumComponent1
{

	public static BlockPos start;
    public static World world;
    public static StructureBase structure;

    public static void init(World worldIn, BlockPos blockPos, StructureBase structureIn)
    {
        world = worldIn; start = blockPos; structure = structureIn;
    }
    
    public static void generatePart11()
    {
        structure.fillWithBlocks(world, start, 38, -23, 28, 39, -23, 28, Blocks.DIRT.getDefaultState());
        structure.fillWithBlocks(world, start, 38, -23, 29, 39, -23, 31, Blocks.SANDSTONE.getDefaultState());
        structure.fillWithBlocks(world, start, 38, -23, 33, 38, -23, 42, Blocks.SANDSTONE.getDefaultState());
        structure.fillWithBlocks(world, start, 38, -23, 45, 38, -23, 45, Blocks.SANDSTONE.getDefaultState());
        structure.fillWithBlocks(world, start, 38, -23, 47, 39, -23, 53, Blocks.SANDSTONE.getDefaultState());
        structure.fillWithBlocks(world, start, 38, -22, -15, 39, -22, -13, Blocks.STONE_BRICKS.getDefaultState());
        structure.fillWithBlocks(world, start, 38, -22, -11, 39, -22, -8, Blocks.STONE_BRICKS.getDefaultState());
        structure.fillWithBlocks(world, start, 38, -22, -7, 38, -22, -6, Blocks.STONE_BRICKS.getDefaultState());
        structure.fillWithBlocks(world, start, 38, -22, -5, 38, -22, -5, Blocks.AIR.getDefaultState());
        structure.fillWithBlocks(world, start, 38, -22, -4, 38, -22, -2, Blocks.STONE_BRICKS.getDefaultState());
        structure.fillWithBlocks(world, start, 38, -22, 4, 38, -21, 4, Blocks.SANDSTONE.getDefaultState());
        structure.fillWithBlocks(world, start, 38, -22, 8, 40, -22, 10, Blocks.SANDSTONE.getDefaultState());
        structure.fillWithBlocks(world, start, 38, -22, 13, 39, -22, 14, Blocks.SANDSTONE.getDefaultState());
        structure.fillWithBlocks(world, start, 38, -22, 22, 39, -22, 24, Blocks.SANDSTONE.getDefaultState());
        structure.fillWithBlocks(world, start, 38, -22, 28, 39, -22, 29, Blocks.SANDSTONE.getDefaultState());
        structure.fillWithBlocks(world, start, 38, -22, 31, 38, -22, 31, Blocks.DIRT.getDefaultState());
        structure.fillWithBlocks(world, start, 38, -22, 32, 38, -22, 33, Blocks.SANDSTONE.getDefaultState());
        structure.fillWithBlocks(world, start, 38, -22, 36, 38, -22, 47, Blocks.SANDSTONE.getDefaultState());
        structure.fillWithBlocks(world, start, 38, -22, 48, 39, -22, 48, Blocks.DIRT.getDefaultState());
        structure.fillWithBlocks(world, start, 38, -22, 50, 38, -21, 51, Blocks.SANDSTONE.getDefaultState());
        structure.fillWithBlocks(world, start, 38, -22, 54, 39, -22, 55, Blocks.SANDSTONE.getDefaultState());
        structure.fillWithBlocks(world, start, 38, -21, -16, 39, -21, -14, Blocks.STONE_BRICKS.getDefaultState());
        structure.fillWithBlocks(world, start, 38, -21, -13, 38, -21, -13, Blocks.SANDSTONE.getDefaultState());
        structure.fillWithBlocks(world, start, 38, -21, -12, 38, -21, -8, Blocks.STONE_BRICKS.getDefaultState());
        structure.fillWithBlocks(world, start, 38, -21, -4, 38, -21, -4, Blocks.AIR.getDefaultState());
        structure.fillWithBlocks(world, start, 38, -21, 0, 41, -21, 6, Blocks.SANDSTONE.getDefaultState());
        structure.fillWithBlocks(world, start, 38, -21, 7, 38, -21, 11, Blocks.SANDSTONE.getDefaultState());
        structure.fillWithBlocks(world, start, 38, -21, 13, 38, -21, 13, Blocks.SANDSTONE.getDefaultState());
        structure.fillWithBlocks(world, start, 38, -21, 14, 38, -21, 15, Blocks.AIR.getDefaultState());
        structure.fillWithBlocks(world, start, 38, -21, 16, 38, -21, 17, Blocks.DIRT.getDefaultState());
        structure.fillWithBlocks(world, start, 38, -21, 18, 39, -21, 21, Blocks.SANDSTONE.getDefaultState());
        structure.fillWithBlocks(world, start, 38, -21, 23, 38, -21, 27, Blocks.SANDSTONE.getDefaultState());
        structure.fillWithBlocks(world, start, 38, -21, 30, 38, -21, 31, Blocks.AIR.getDefaultState());
        structure.fillWithBlocks(world, start, 38, -21, 32, 38, -21, 37, Blocks.SANDSTONE.getDefaultState());
        structure.fillWithBlocks(world, start, 38, -21, 38, 39, -21, 38, Blocks.AIR.getDefaultState());
        structure.fillWithBlocks(world, start, 38, -21, 39, 39, -21, 40, Blocks.SANDSTONE.getDefaultState());
        structure.fillWithBlocks(world, start, 38, -21, 42, 39, -21, 43, Blocks.SANDSTONE.getDefaultState());
        structure.fillWithBlocks(world, start, 38, -21, 44, 39, -21, 45, Blocks.AIR.getDefaultState());
        structure.fillWithBlocks(world, start, 38, -21, 46, 38, -21, 46, Blocks.DIRT.getDefaultState());
        structure.fillWithBlocks(world, start, 38, -21, 47, 38, -21, 54, Blocks.SANDSTONE.getDefaultState());
        structure.fillWithBlocks(world, start, 38, -19, 22, 40, -19, 24, Blocks.SANDSTONE.getDefaultState());
        structure.fillWithBlocks(world, start, 38, -19, 25, 40, -19, 27, Blocks.AIR.getDefaultState());
        structure.fillWithBlocks(world, start, 38, -19, 31, 42, -16, 31, Blocks.AIR.getDefaultState());
        structure.fillWithBlocks(world, start, 38, -19, 32, 40, -19, 34, Blocks.SANDSTONE.getDefaultState());
        structure.fillWithBlocks(world, start, 38, -18, 25, 40, -18, 27, Blocks.AIR.getDefaultState());
        structure.fillWithBlocks(world, start, 38, -18, 32, 40, -18, 34, Blocks.SANDSTONE.getDefaultState());
        structure.fillWithBlocks(world, start, 38, -17, 22, 40, -17, 24, Blocks.SANDSTONE.getDefaultState());
        structure.fillWithBlocks(world, start, 38, -17, 25, 42, -17, 31, Blocks.AIR.getDefaultState());
        structure.fillWithBlocks(world, start, 38, -17, 32, 40, -17, 34, Blocks.SANDSTONE.getDefaultState());
        structure.fillWithBlocks(world, start, 38, -16, 25, 42, -16, 31, Blocks.AIR.getDefaultState());
        structure.fillWithBlocks(world, start, 38, -16, 32, 40, -16, 34, Blocks.SANDSTONE.getDefaultState());
        structure.fillWithBlocks(world, start, 38, -15, 22, 40, -15, 25, Blocks.SANDSTONE.getDefaultState());
        structure.fillWithBlocks(world, start, 38, -15, 27, 40, -15, 29, Blocks.AIR.getDefaultState());
        structure.fillWithBlocks(world, start, 38, -15, 30, 38, -15, 34, Blocks.SANDSTONE.getDefaultState());
        structure.fillWithBlocks(world, start, 38, -14, 22, 40, -14, 27, Blocks.SANDSTONE.getDefaultState());
        structure.fillWithBlocks(world, start, 38, -14, 28, 39, -14, 30, Blocks.SANDSTONE.getDefaultState());
        structure.fillWithBlocks(world, start, 38, -14, 31, 38, -14, 32, Blocks.AIR.getDefaultState());
        structure.fillWithBlocks(world, start, 38, -14, 33, 39, -14, 34, Blocks.SANDSTONE.getDefaultState());
        structure.fillWithBlocks(world, start, 38, -13, 29, 39, -13, 30, Blocks.SANDSTONE.getDefaultState());
        structure.fillWithBlocks(world, start, 38, -13, 31, 38, -13, 34, Blocks.SANDSTONE.getDefaultState());
        structure.fillWithBlocks(world, start, 38, -12, 31, 40, -12, 33, Blocks.SANDSTONE.getDefaultState());
        structure.fillWithBlocks(world, start, 38, -11, 28, 43, -11, 33, Blocks.SANDSTONE.getDefaultState());
        structure.fillWithBlocks(world, start, 38, 1, 4, 43, 1, 9, Blocks.SANDSTONE.getDefaultState());
        structure.fillWithBlocks(world, start, 38, 1, 10, 39, 1, 14, Blocks.SANDSTONE.getDefaultState());
        structure.fillWithBlocks(world, start, 39, -51, 22, 41, -51, 24, Blocks.SANDSTONE.getDefaultState());
        structure.fillWithBlocks(world, start, 39, -51, 32, 41, -51, 34, Blocks.SANDSTONE.getDefaultState());
        structure.fillWithBlocks(world, start, 39, -50, 22, 41, -50, 24, Blocks.AIR.getDefaultState());
        structure.fillWithBlocks(world, start, 39, -50, 32, 41, -50, 34, Blocks.AIR.getDefaultState());
        structure.fillWithBlocks(world, start, 39, -49, 21, 39, -41, 21, Blocks.SANDSTONE.getDefaultState());
        structure.fillWithBlocks(world, start, 39, -49, 22, 41, -49, 24, Blocks.AIR.getDefaultState());
        structure.fillWithBlocks(world, start, 39, -49, 25, 39, -41, 25, Blocks.SANDSTONE.getDefaultState());
        structure.fillWithBlocks(world, start, 39, -49, 26, 40, -49, 27, Blocks.AIR.getDefaultState());
        structure.fillWithBlocks(world, start, 39, -49, 29, 40, -49, 30, Blocks.AIR.getDefaultState());
        structure.fillWithBlocks(world, start, 39, -49, 31, 39, -41, 31, Blocks.SANDSTONE.getDefaultState());
        structure.fillWithBlocks(world, start, 39, -49, 32, 41, -49, 34, Blocks.AIR.getDefaultState());
        structure.fillWithBlocks(world, start, 39, -49, 35, 39, -49, 36, Blocks.SANDSTONE.getDefaultState());
        structure.fillWithBlocks(world, start, 39, -48, 22, 41, -48, 24, Blocks.AIR.getDefaultState());
        structure.fillWithBlocks(world, start, 39, -48, 26, 43, -48, 30, Blocks.AIR.getDefaultState());
        structure.fillWithBlocks(world, start, 39, -48, 32, 41, -48, 34, Blocks.AIR.getDefaultState());
        structure.fillWithBlocks(world, start, 39, -48, 35, 39, -48, 36, Blocks.SANDSTONE.getDefaultState());
        structure.fillWithBlocks(world, start, 39, -47, 22, 41, -47, 24, Blocks.AIR.getDefaultState());
        structure.fillWithBlocks(world, start, 39, -47, 26, 43, -47, 30, Blocks.AIR.getDefaultState());
        structure.fillWithBlocks(world, start, 39, -47, 32, 41, -47, 34, Blocks.AIR.getDefaultState());
        structure.fillWithBlocks(world, start, 39, -47, 35, 39, -47, 36, Blocks.SANDSTONE.getDefaultState());
        structure.fillWithBlocks(world, start, 39, -46, 22, 41, -46, 24, Blocks.AIR.getDefaultState());
        structure.fillWithBlocks(world, start, 39, -46, 26, 43, -46, 30, Blocks.AIR.getDefaultState());
        structure.fillWithBlocks(world, start, 39, -46, 32, 41, -46, 34, Blocks.AIR.getDefaultState());
        structure.fillWithBlocks(world, start, 39, -46, 35, 39, -46, 36, Blocks.SANDSTONE.getDefaultState());
        structure.fillWithBlocks(world, start, 39, -45, 22, 39, -42, 36, Blocks.SANDSTONE.getDefaultState());
        structure.fillWithBlocks(world, start, 39, -41, 22, 41, -41, 24, Blocks.STONE_BRICKS.getDefaultState());
        structure.fillWithBlocks(world, start, 39, -41, 26, 44, -41, 31, Blocks.SANDSTONE.getDefaultState());
        structure.fillWithBlocks(world, start, 39, -41, 32, 41, -41, 34, Blocks.STONE_BRICKS.getDefaultState());
        structure.fillWithBlocks(world, start, 39, -41, 35, 40, -41, 36, Blocks.SANDSTONE.getDefaultState());
        structure.fillWithBlocks(world, start, 39, -40, 20, 40, -40, 21, Blocks.STONE_BRICKS.getDefaultState());
        structure.fillWithBlocks(world, start, 39, -40, 35, 40, -40, 36, Blocks.STONE_BRICKS.getDefaultState());
        structure.fillWithBlocks(world, start, 39, -39, 22, 41, -39, 24, Blocks.AIR.getDefaultState());
        structure.fillWithBlocks(world, start, 39, -39, 32, 41, -39, 34, Blocks.AIR.getDefaultState());
        structure.fillWithBlocks(world, start, 39, -35, 35, 40, -35, 36, Blocks.STONE_BRICKS.getDefaultState());
        structure.fillWithBlocks(world, start, 39, -34, 22, 39, -34, 22, Blocks.STONE_BRICKS.getDefaultState());
        structure.fillWithBlocks(world, start, 39, -34, 24, 42, -34, 27, Blocks.STONE_BRICKS.getDefaultState());
        structure.fillWithBlocks(world, start, 39, -34, 29, 42, -34, 32, Blocks.STONE_BRICKS.getDefaultState());
        structure.fillWithBlocks(world, start, 39, -34, 34, 41, -34, 36, Blocks.STONE_BRICKS.getDefaultState());
        structure.fillWithBlocks(world, start, 39, -33, 22, 39, -33, 33, Blocks.STONE_BRICKS.getDefaultState());
        structure.fillWithBlocks(world, start, 39, -33, 35, 40, -33, 36, Blocks.STONE_BRICKS.getDefaultState());
        structure.fillWithBlocks(world, start, 39, -31, 24, 39, -31, 29, Blocks.STONE_BRICKS.getDefaultState());
        structure.fillWithBlocks(world, start, 39, -31, 31, 43, -31, 35, Blocks.STONE_BRICKS.getDefaultState());
        structure.fillWithBlocks(world, start, 39, -30, -16, 40, -30, -16, Blocks.STONE_BRICKS.getDefaultState());
        structure.fillWithBlocks(world, start, 39, -30, -14, 40, -30, -14, Blocks.DIRT.getDefaultState());
        structure.fillWithBlocks(world, start, 39, -30, -12, 39, -30, -12, Blocks.AIR.getDefaultState());
        structure.fillWithBlocks(world, start, 39, -30, -11, 39, -30, -8, Blocks.DIRT.getDefaultState());
        structure.fillWithBlocks(world, start, 39, -30, -7, 40, -30, -5, Blocks.SANDSTONE.getDefaultState());
        structure.fillWithBlocks(world, start, 39, -30, -3, 47, -30, 7, Blocks.SANDSTONE.getDefaultState());
        structure.fillWithBlocks(world, start, 39, -30, 8, 39, -30, 9, Blocks.SANDSTONE.getDefaultState());
        structure.fillWithBlocks(world, start, 39, -30, 10, 40, -30, 10, Blocks.DIRT.getDefaultState());
        structure.fillWithBlocks(world, start, 39, -30, 15, 42, -30, 18, Blocks.SANDSTONE.getDefaultState());
        structure.fillWithBlocks(world, start, 39, -30, 20, 43, -30, 24, Blocks.SANDSTONE.getDefaultState());
        structure.fillWithBlocks(world, start, 39, -30, 25, 39, -30, 25, Blocks.AIR.getDefaultState());
        structure.fillWithBlocks(world, start, 39, -30, 26, 39, -29, 26, Blocks.SANDSTONE.getDefaultState());
        structure.fillWithBlocks(world, start, 39, -30, 27, 39, -30, 27, Blocks.DIRT.getDefaultState());
        structure.fillWithBlocks(world, start, 39, -30, 29, 40, -30, 29, Blocks.DIRT.getDefaultState());
        structure.fillWithBlocks(world, start, 39, -30, 30, 39, -29, 31, Blocks.SANDSTONE.getDefaultState());
        structure.fillWithBlocks(world, start, 39, -30, 33, 39, -30, 35, Blocks.SANDSTONE.getDefaultState());
        structure.fillWithBlocks(world, start, 39, -30, 36, 39, -30, 36, Blocks.DIRT.getDefaultState());
        structure.fillWithBlocks(world, start, 39, -30, 37, 39, -21, 37, Blocks.SANDSTONE.getDefaultState());
        structure.fillWithBlocks(world, start, 39, -30, 38, 39, -30, 38, Blocks.DIRT.getDefaultState());
        structure.fillWithBlocks(world, start, 39, -30, 41, 39, -21, 41, Blocks.SANDSTONE.getDefaultState());
        structure.fillWithBlocks(world, start, 39, -30, 44, 39, -30, 45, Blocks.DIRT.getDefaultState());
        structure.fillWithBlocks(world, start, 39, -30, 46, 39, -30, 47, Blocks.AIR.getDefaultState());
        structure.fillWithBlocks(world, start, 39, -30, 48, 39, -26, 48, Blocks.SANDSTONE.getDefaultState());
        structure.fillWithBlocks(world, start, 39, -30, 49, 39, -29, 49, Blocks.AIR.getDefaultState());
        structure.fillWithBlocks(world, start, 39, -30, 50, 39, -21, 50, Blocks.SANDSTONE.getDefaultState());
        structure.fillWithBlocks(world, start, 39, -30, 51, 39, -29, 51, Blocks.AIR.getDefaultState());
        structure.fillWithBlocks(world, start, 39, -30, 52, 41, -30, 52, Blocks.DIRT.getDefaultState());
        structure.fillWithBlocks(world, start, 39, -30, 53, 40, -30, 54, Blocks.SANDSTONE.getDefaultState());
        structure.fillWithBlocks(world, start, 39, -29, -15, 42, -28, -15, Blocks.STONE_BRICKS.getDefaultState());
        structure.fillWithBlocks(world, start, 39, -29, -14, 39, -29, -14, Blocks.DIRT.getDefaultState());
        structure.fillWithBlocks(world, start, 39, -29, -13, 39, -29, -12, Blocks.STONE_BRICKS.getDefaultState());
        structure.fillWithBlocks(world, start, 39, -29, -11, 39, -29, -11, Blocks.SANDSTONE.getDefaultState());
        structure.fillWithBlocks(world, start, 39, -29, -10, 39, -29, -7, Blocks.STONE_BRICKS.getDefaultState());
        structure.fillWithBlocks(world, start, 39, -29, -5, 40, -29, -4, Blocks.STONE_BRICKS.getDefaultState());
        structure.fillWithBlocks(world, start, 39, -29, 4, 39, -29, 4, Blocks.AIR.getDefaultState());
        structure.fillWithBlocks(world, start, 39, -29, 6, 40, -28, 6, Blocks.AIR.getDefaultState());
        structure.fillWithBlocks(world, start, 39, -29, 12, 39, -28, 12, Blocks.AIR.getDefaultState());
        structure.fillWithBlocks(world, start, 39, -29, 13, 39, -29, 15, Blocks.SANDSTONE.getDefaultState());
        structure.fillWithBlocks(world, start, 39, -29, 22, 41, -29, 24, Blocks.AIR.getDefaultState());
        structure.fillWithBlocks(world, start, 39, -29, 27, 39, -29, 27, Blocks.SANDSTONE.getDefaultState());
        structure.fillWithBlocks(world, start, 39, -29, 28, 39, -29, 29, Blocks.DIRT.getDefaultState());
        structure.fillWithBlocks(world, start, 39, -29, 32, 40, -29, 33, Blocks.SANDSTONE.getDefaultState());
        structure.fillWithBlocks(world, start, 39, -29, 34, 39, -28, 34, Blocks.DIRT.getDefaultState());
        structure.fillWithBlocks(world, start, 39, -29, 35, 40, -29, 38, Blocks.SANDSTONE.getDefaultState());
        structure.fillWithBlocks(world, start, 39, -29, 42, 41, -29, 47, Blocks.SANDSTONE.getDefaultState());
        structure.fillWithBlocks(world, start, 39, -29, 53, 39, -28, 54, Blocks.SANDSTONE.getDefaultState());
        structure.fillWithBlocks(world, start, 39, -28, -16, 39, -28, -15, Blocks.STONE_BRICKS.getDefaultState());
        structure.fillWithBlocks(world, start, 39, -28, -13, 41, -27, -13, Blocks.STONE_BRICKS.getDefaultState());
        structure.fillWithBlocks(world, start, 39, -28, -12, 40, -28, -12, Blocks.SANDSTONE.getDefaultState());
        structure.fillWithBlocks(world, start, 39, -28, -11, 39, -28, -11, Blocks.STONE_BRICKS.getDefaultState());
        structure.fillWithBlocks(world, start, 39, -28, -9, 40, -28, -9, Blocks.STONE_BRICKS.getDefaultState());
        structure.fillWithBlocks(world, start, 39, -28, -8, 40, -27, -8, Blocks.AIR.getDefaultState());
        structure.fillWithBlocks(world, start, 39, -28, -6, 40, -27, -6, Blocks.AIR.getDefaultState());
        structure.fillWithBlocks(world, start, 39, -28, -4, 40, -27, -4, Blocks.AIR.getDefaultState());
        structure.fillWithBlocks(world, start, 39, -28, 4, 40, -28, 6, Blocks.AIR.getDefaultState());
        structure.fillWithBlocks(world, start, 39, -28, 7, 39, -28, 7, Blocks.SANDSTONE.getDefaultState());
        structure.fillWithBlocks(world, start, 39, -28, 9, 40, -28, 10, Blocks.SANDSTONE.getDefaultState());
        structure.fillWithBlocks(world, start, 39, -28, 11, 39, -28, 12, Blocks.AIR.getDefaultState());
        structure.fillWithBlocks(world, start, 39, -28, 13, 39, -28, 15, Blocks.SANDSTONE.getDefaultState());
        structure.fillWithBlocks(world, start, 39, -28, 25, 42, -25, 25, Blocks.SANDSTONE.getDefaultState());
        structure.fillWithBlocks(world, start, 39, -28, 26, 41, -28, 26, Blocks.SHROOMLIGHT.getDefaultState());
        structure.fillWithBlocks(world, start, 39, -28, 27, 41, -27, 27, Blocks.SANDSTONE.getDefaultState());
        structure.fillWithBlocks(world, start, 39, -28, 28, 41, -28, 28, Blocks.SHROOMLIGHT.getDefaultState());
        structure.fillWithBlocks(world, start, 39, -28, 29, 41, -26, 29, Blocks.SANDSTONE.getDefaultState());
        structure.fillWithBlocks(world, start, 39, -28, 30, 41, -28, 30, Blocks.SHROOMLIGHT.getDefaultState());
        structure.fillWithBlocks(world, start, 39, -28, 32, 39, -28, 32, Blocks.SANDSTONE.getDefaultState());
        structure.fillWithBlocks(world, start, 39, -28, 33, 39, -28, 34, Blocks.DIRT.getDefaultState());
        structure.fillWithBlocks(world, start, 39, -28, 35, 40, -28, 38, Blocks.SANDSTONE.getDefaultState());
        structure.fillWithBlocks(world, start, 39, -28, 40, 39, -28, 41, Blocks.SANDSTONE.getDefaultState());
        structure.fillWithBlocks(world, start, 39, -28, 43, 40, -27, 43, Blocks.AIR.getDefaultState());
        structure.fillWithBlocks(world, start, 39, -28, 44, 39, -28, 44, Blocks.SANDSTONE.getDefaultState());
        structure.fillWithBlocks(world, start, 39, -28, 45, 39, -25, 45, Blocks.AIR.getDefaultState());
        structure.fillWithBlocks(world, start, 39, -28, 46, 39, -27, 46, Blocks.SANDSTONE.getDefaultState());
        structure.fillWithBlocks(world, start, 39, -28, 47, 40, -27, 47, Blocks.AIR.getDefaultState());
        structure.fillWithBlocks(world, start, 39, -28, 51, 40, -27, 51, Blocks.SANDSTONE.getDefaultState());
        structure.fillWithBlocks(world, start, 39, -28, 55, 39, -27, 55, Blocks.AIR.getDefaultState());
        structure.fillWithBlocks(world, start, 39, -27, -16, 40, -27, -15, Blocks.STONE_BRICKS.getDefaultState());
        structure.fillWithBlocks(world, start, 39, -27, -14, 40, -27, -14, Blocks.SANDSTONE.getDefaultState());
        structure.fillWithBlocks(world, start, 39, -27, -12, 39, -27, -12, Blocks.STONE_BRICKS.getDefaultState());
        structure.fillWithBlocks(world, start, 39, -27, -11, 39, -27, -10, Blocks.DIRT.getDefaultState());
        structure.fillWithBlocks(world, start, 39, -27, 4, 40, -27, 6, Blocks.AIR.getDefaultState());
        structure.fillWithBlocks(world, start, 39, -27, 7, 40, -27, 8, Blocks.SANDSTONE.getDefaultState());
        structure.fillWithBlocks(world, start, 39, -27, 13, 41, -27, 15, Blocks.SANDSTONE.getDefaultState());
        structure.fillWithBlocks(world, start, 39, -27, 26, 40, -27, 26, Blocks.AIR.getDefaultState());
        structure.fillWithBlocks(world, start, 39, -27, 28, 40, -27, 28, Blocks.AIR.getDefaultState());
        structure.fillWithBlocks(world, start, 39, -27, 30, 40, -27, 30, Blocks.AIR.getDefaultState());
        structure.fillWithBlocks(world, start, 39, -27, 31, 39, -27, 31, Blocks.SANDSTONE.getDefaultState());
        structure.fillWithBlocks(world, start, 39, -27, 33, 40, -27, 36, Blocks.SANDSTONE.getDefaultState());
        structure.fillWithBlocks(world, start, 39, -27, 38, 39, -27, 38, Blocks.DIRT.getDefaultState());
        structure.fillWithBlocks(world, start, 39, -27, 39, 39, -23, 39, Blocks.SANDSTONE.getDefaultState());
        structure.fillWithBlocks(world, start, 39, -27, 44, 41, -27, 44, Blocks.SANDSTONE.getDefaultState());
        structure.fillWithBlocks(world, start, 39, -27, 53, 39, -27, 53, Blocks.SANDSTONE.getDefaultState());
        structure.fillWithBlocks(world, start, 39, -26, -16, 39, -26, -9, Blocks.STONE_BRICKS.getDefaultState());
        structure.fillWithBlocks(world, start, 39, -26, -8, 40, -25, -8, Blocks.AIR.getDefaultState());
        structure.fillWithBlocks(world, start, 39, -26, -7, 39, -24, -7, Blocks.SANDSTONE.getDefaultState());
        structure.fillWithBlocks(world, start, 39, -26, -6, 40, -25, -6, Blocks.AIR.getDefaultState());
        structure.fillWithBlocks(world, start, 39, -26, -5, 40, -26, -5, Blocks.STONE_BRICKS.getDefaultState());
        structure.fillWithBlocks(world, start, 39, -26, -4, 40, -25, -4, Blocks.AIR.getDefaultState());
        structure.fillWithBlocks(world, start, 39, -26, 10, 39, -25, 10, Blocks.DIRT.getDefaultState());
        structure.fillWithBlocks(world, start, 39, -26, 11, 39, -23, 15, Blocks.SANDSTONE.getDefaultState());
        structure.fillWithBlocks(world, start, 39, -26, 26, 41, -26, 26, Blocks.SHROOMLIGHT.getDefaultState());
        structure.fillWithBlocks(world, start, 39, -26, 27, 39, -24, 27, Blocks.SANDSTONE.getDefaultState());
        structure.fillWithBlocks(world, start, 39, -26, 28, 41, -26, 28, Blocks.SHROOMLIGHT.getDefaultState());
        structure.fillWithBlocks(world, start, 39, -26, 30, 41, -26, 30, Blocks.SHROOMLIGHT.getDefaultState());
        structure.fillWithBlocks(world, start, 39, -26, 31, 41, -26, 33, Blocks.SANDSTONE.getDefaultState());
        structure.fillWithBlocks(world, start, 39, -26, 38, 40, -26, 41, Blocks.SANDSTONE.getDefaultState());
        structure.fillWithBlocks(world, start, 39, -26, 43, 39, -26, 47, Blocks.AIR.getDefaultState());
        structure.fillWithBlocks(world, start, 39, -26, 49, 39, -26, 53, Blocks.SANDSTONE.getDefaultState());
        structure.fillWithBlocks(world, start, 39, -26, 55, 44, -26, 55, Blocks.SANDSTONE.getDefaultState());
        structure.fillWithBlocks(world, start, 39, -25, -14, 39, -24, -13, Blocks.STONE_BRICKS.getDefaultState());
        structure.fillWithBlocks(world, start, 39, -25, -12, 40, -25, -12, Blocks.DIRT.getDefaultState());
        structure.fillWithBlocks(world, start, 39, -25, -11, 39, -24, -11, Blocks.STONE_BRICKS.getDefaultState());
        structure.fillWithBlocks(world, start, 39, -25, -9, 39, -24, -9, Blocks.STONE_BRICKS.getDefaultState());
        structure.fillWithBlocks(world, start, 39, -25, -5, 39, -24, -5, Blocks.SANDSTONE.getDefaultState());
        structure.fillWithBlocks(world, start, 39, -25, 16, 39, -25, 16, Blocks.SANDSTONE.getDefaultState());
        structure.fillWithBlocks(world, start, 39, -25, 19, 42, -23, 19, Blocks.SANDSTONE.getDefaultState());
        structure.fillWithBlocks(world, start, 39, -25, 29, 41, -24, 29, Blocks.SANDSTONE.getDefaultState());
        structure.fillWithBlocks(world, start, 39, -25, 30, 40, -25, 30, Blocks.AIR.getDefaultState());
        structure.fillWithBlocks(world, start, 39, -25, 31, 39, -24, 34, Blocks.SANDSTONE.getDefaultState());
        structure.fillWithBlocks(world, start, 39, -25, 43, 40, -25, 43, Blocks.AIR.getDefaultState());
        structure.fillWithBlocks(world, start, 39, -25, 44, 39, -25, 44, Blocks.SANDSTONE.getDefaultState());
        structure.fillWithBlocks(world, start, 39, -25, 47, 40, -25, 49, Blocks.AIR.getDefaultState());
        structure.fillWithBlocks(world, start, 39, -25, 51, 39, -25, 51, Blocks.SANDSTONE.getDefaultState());
        structure.fillWithBlocks(world, start, 39, -25, 52, 39, -25, 53, Blocks.AIR.getDefaultState());
        structure.fillWithBlocks(world, start, 39, -25, 54, 39, -25, 54, Blocks.SANDSTONE.getDefaultState());
        structure.fillWithBlocks(world, start, 39, -24, -10, 39, -24, -8, Blocks.STONE_BRICKS.getDefaultState());
        structure.fillWithBlocks(world, start, 39, -24, -4, 40, -24, -3, Blocks.STONE_BRICKS.getDefaultState());
        structure.fillWithBlocks(world, start, 39, -24, 7, 39, -22, 11, Blocks.SANDSTONE.getDefaultState());
        structure.fillWithBlocks(world, start, 39, -24, 16, 41, -24, 33, Blocks.SANDSTONE.getDefaultState());
        structure.fillWithBlocks(world, start, 39, -24, 35, 39, -24, 36, Blocks.DIRT.getDefaultState());
        structure.fillWithBlocks(world, start, 39, -24, 38, 40, -24, 39, Blocks.SANDSTONE.getDefaultState());
        structure.fillWithBlocks(world, start, 39, -24, 40, 39, -24, 51, Blocks.SANDSTONE.getDefaultState());
        structure.fillWithBlocks(world, start, 39, -24, 52, 39, -24, 52, Blocks.AIR.getDefaultState());
        structure.fillWithBlocks(world, start, 39, -24, 53, 39, -24, 55, Blocks.SANDSTONE.getDefaultState());
        structure.fillWithBlocks(world, start, 39, -23, -12, 39, -23, -12, Blocks.STONE_BRICKS.getDefaultState());
        structure.fillWithBlocks(world, start, 39, -23, -10, 39, -22, -10, Blocks.STONE_BRICKS.getDefaultState());
        structure.fillWithBlocks(world, start, 39, -23, -9, 39, -23, -8, Blocks.SANDSTONE.getDefaultState());
        structure.fillWithBlocks(world, start, 39, -23, -7, 39, -23, -7, Blocks.STONE_BRICKS.getDefaultState());
        structure.fillWithBlocks(world, start, 39, -23, -5, 39, -21, -5, Blocks.STONE_BRICKS.getDefaultState());
        structure.fillWithBlocks(world, start, 39, -23, -4, 40, -23, -4, Blocks.SANDSTONE.getDefaultState());
        structure.fillWithBlocks(world, start, 39, -23, -3, 39, -23, -2, Blocks.STONE_BRICKS.getDefaultState());
        structure.fillWithBlocks(world, start, 39, -23, 6, 40, -23, 6, Blocks.DIRT.getDefaultState());
        structure.fillWithBlocks(world, start, 39, -23, 16, 39, -21, 16, Blocks.SANDSTONE.getDefaultState());
        structure.fillWithBlocks(world, start, 39, -23, 18, 40, -23, 19, Blocks.SANDSTONE.getDefaultState());
        structure.fillWithBlocks(world, start, 39, -23, 21, 41, -23, 26, Blocks.SANDSTONE.getDefaultState());
        structure.fillWithBlocks(world, start, 39, -23, 27, 39, -23, 28, Blocks.DIRT.getDefaultState());
        structure.fillWithBlocks(world, start, 39, -23, 32, 39, -23, 32, Blocks.SANDSTONE.getDefaultState());
        structure.fillWithBlocks(world, start, 39, -23, 34, 39, -23, 34, Blocks.SANDSTONE.getDefaultState());
        structure.fillWithBlocks(world, start, 39, -23, 35, 39, -23, 36, Blocks.DIRT.getDefaultState());
        structure.fillWithBlocks(world, start, 39, -23, 38, 40, -23, 39, Blocks.SANDSTONE.getDefaultState());
        structure.fillWithBlocks(world, start, 39, -23, 43, 42, -23, 47, Blocks.SANDSTONE.getDefaultState());
        structure.fillWithBlocks(world, start, 39, -23, 54, 40, -23, 55, Blocks.SANDSTONE.getDefaultState());
        structure.fillWithBlocks(world, start, 39, -22, -12, 39, -22, -8, Blocks.STONE_BRICKS.getDefaultState());
        structure.fillWithBlocks(world, start, 39, -22, -7, 39, -22, -6, Blocks.SANDSTONE.getDefaultState());
        structure.fillWithBlocks(world, start, 39, -22, -4, 39, -21, -4, Blocks.AIR.getDefaultState());
        structure.fillWithBlocks(world, start, 39, -22, 5, 42, -22, 8, Blocks.SANDSTONE.getDefaultState());
        structure.fillWithBlocks(world, start, 39, -22, 17, 39, -22, 17, Blocks.SANDSTONE.getDefaultState());
        structure.fillWithBlocks(world, start, 39, -22, 19, 40, -22, 20, Blocks.SANDSTONE.getDefaultState());
        structure.fillWithBlocks(world, start, 39, -22, 21, 39, -22, 24, Blocks.SANDSTONE.getDefaultState());
        structure.fillWithBlocks(world, start, 39, -22, 25, 40, -22, 25, Blocks.DIRT.getDefaultState());
        structure.fillWithBlocks(world, start, 39, -22, 26, 40, -22, 28, Blocks.SANDSTONE.getDefaultState());
        structure.fillWithBlocks(world, start, 39, -22, 31, 39, -22, 31, Blocks.SANDSTONE.getDefaultState());
        structure.fillWithBlocks(world, start, 39, -22, 32, 39, -21, 32, Blocks.DIRT.getDefaultState());
        structure.fillWithBlocks(world, start, 39, -22, 33, 41, -22, 35, Blocks.SANDSTONE.getDefaultState());
        structure.fillWithBlocks(world, start, 39, -22, 36, 39, -22, 36, Blocks.AIR.getDefaultState());
        structure.fillWithBlocks(world, start, 39, -22, 38, 39, -22, 38, Blocks.SANDSTONE.getDefaultState());
        structure.fillWithBlocks(world, start, 39, -22, 40, 40, -22, 41, Blocks.SANDSTONE.getDefaultState());
        structure.fillWithBlocks(world, start, 39, -22, 42, 39, -21, 42, Blocks.SANDSTONE.getDefaultState());
        structure.fillWithBlocks(world, start, 39, -22, 45, 40, -22, 46, Blocks.SANDSTONE.getDefaultState());
        structure.fillWithBlocks(world, start, 39, -22, 47, 39, -22, 47, Blocks.SANDSTONE.getDefaultState());
        structure.fillWithBlocks(world, start, 39, -22, 49, 39, -21, 50, Blocks.SANDSTONE.getDefaultState());
        structure.fillWithBlocks(world, start, 39, -22, 52, 39, -22, 52, Blocks.SANDSTONE.getDefaultState());
        structure.fillWithBlocks(world, start, 39, -21, -13, 39, -21, -12, Blocks.SANDSTONE.getDefaultState());
        structure.fillWithBlocks(world, start, 39, -21, -8, 40, -21, -8, Blocks.SANDSTONE.getDefaultState());
        structure.fillWithBlocks(world, start, 39, -21, -7, 39, -21, -7, Blocks.STONE_BRICKS.getDefaultState());
        structure.fillWithBlocks(world, start, 39, -21, -3, 40, -21, -3, Blocks.AIR.getDefaultState());
        structure.fillWithBlocks(world, start, 39, -21, -2, 39, -21, 7, Blocks.SANDSTONE.getDefaultState());
        structure.fillWithBlocks(world, start, 39, -21, 9, 42, -21, 12, Blocks.SANDSTONE.getDefaultState());
        structure.fillWithBlocks(world, start, 39, -21, 13, 39, -21, 16, Blocks.SANDSTONE.getDefaultState());
        structure.fillWithBlocks(world, start, 39, -21, 22, 39, -21, 22, Blocks.SANDSTONE.getDefaultState());
        structure.fillWithBlocks(world, start, 39, -21, 24, 39, -20, 30, Blocks.SANDSTONE.getDefaultState());
        structure.fillWithBlocks(world, start, 39, -21, 33, 39, -21, 33, Blocks.SANDSTONE.getDefaultState());
        structure.fillWithBlocks(world, start, 39, -21, 35, 41, -21, 37, Blocks.SANDSTONE.getDefaultState());
        structure.fillWithBlocks(world, start, 39, -21, 46, 39, -21, 47, Blocks.DIRT.getDefaultState());
        structure.fillWithBlocks(world, start, 39, -21, 51, 40, -21, 52, Blocks.SANDSTONE.getDefaultState());
        structure.fillWithBlocks(world, start, 39, -21, 53, 39, -21, 55, Blocks.SANDSTONE.getDefaultState());
        structure.fillWithBlocks(world, start, 39, -16, 22, 41, -16, 24, Blocks.SANDSTONE.getDefaultState());
        structure.fillWithBlocks(world, start, 39, -15, 26, 41, -15, 30, Blocks.AIR.getDefaultState());
        structure.fillWithBlocks(world, start, 39, -15, 31, 40, -15, 34, Blocks.SANDSTONE.getDefaultState());
        structure.fillWithBlocks(world, start, 39, -14, 31, 39, -14, 34, Blocks.SANDSTONE.getDefaultState());
        structure.fillWithBlocks(world, start, 39, -13, 28, 40, -13, 30, Blocks.SANDSTONE.getDefaultState());
        structure.fillWithBlocks(world, start, 39, -13, 32, 41, -13, 34, Blocks.SANDSTONE.getDefaultState());
        structure.fillWithBlocks(world, start, 39, -12, 30, 43, -12, 34, Blocks.SANDSTONE.getDefaultState());
        structure.fillWithBlocks(world, start, 39, 0, 2, 44, 0, 7, Blocks.SANDSTONE.getDefaultState());
        structure.fillWithBlocks(world, start, 39, 0, 8, 39, 0, 9, Blocks.SANDSTONE.getDefaultState());
        structure.fillWithBlocks(world, start, 39, 0, 152, 40, 0, 153, Blocks.STONE.getDefaultState());
        structure.fillWithBlocks(world, start, 39, 1, 19, 42, 4, 19, Blocks.SANDSTONE.getDefaultState());
        structure.fillWithBlocks(world, start, 39, 1, 20, 102, 1, 136, Blocks.STONE.getDefaultState());
        structure.fillWithBlocks(world, start, 39, 1, 137, 39, 6, 137, Blocks.SANDSTONE.getDefaultState());
        structure.fillWithBlocks(world, start, 39, 1, 138, 47, 1, 146, Blocks.STONE.getDefaultState());
        structure.fillWithBlocks(world, start, 40, -50, 20, 41, -50, 21, Blocks.SANDSTONE.getDefaultState());
        structure.fillWithBlocks(world, start, 40, -50, 25, 44, -50, 31, Blocks.SANDSTONE.getDefaultState());
        structure.fillWithBlocks(world, start, 40, -50, 35, 41, -50, 36, Blocks.SANDSTONE.getDefaultState());
        structure.fillWithBlocks(world, start, 40, -49, 21, 42, -49, 21, Blocks.IRON_BARS.getDefaultState().with(FourWayBlock.WATERLOGGED, false).with(FourWayBlock.NORTH, true).with(FourWayBlock.SOUTH, true).with(FourWayBlock.EAST, true).with(FourWayBlock.WEST, true));
        structure.fillWithBlocks(world, start, 40, -49, 25, 42, -49, 25, Blocks.IRON_BARS.getDefaultState().with(FourWayBlock.WATERLOGGED, false).with(FourWayBlock.NORTH, true).with(FourWayBlock.SOUTH, true).with(FourWayBlock.EAST, true).with(FourWayBlock.WEST, true));
        structure.fillWithBlocks(world, start, 40, -49, 28, 42, -49, 30, Blocks.AIR.getDefaultState());
        structure.fillWithBlocks(world, start, 40, -49, 31, 42, -49, 31, Blocks.IRON_BARS.getDefaultState().with(FourWayBlock.WATERLOGGED, false).with(FourWayBlock.NORTH, true).with(FourWayBlock.SOUTH, true).with(FourWayBlock.EAST, true).with(FourWayBlock.WEST, true));
        structure.fillWithBlocks(world, start, 40, -49, 35, 42, -49, 35, Blocks.IRON_BARS.getDefaultState().with(FourWayBlock.WATERLOGGED, false).with(FourWayBlock.NORTH, true).with(FourWayBlock.SOUTH, true).with(FourWayBlock.EAST, true).with(FourWayBlock.WEST, true));
        structure.fillWithBlocks(world, start, 40, -48, 21, 42, -48, 35, Blocks.AIR.getDefaultState());
        structure.fillWithBlocks(world, start, 40, -47, 21, 42, -47, 35, Blocks.AIR.getDefaultState());
        structure.fillWithBlocks(world, start, 40, -46, 21, 42, -46, 35, Blocks.AIR.getDefaultState());
        structure.fillWithBlocks(world, start, 40, -45, 22, 42, -45, 24, Blocks.AIR.getDefaultState());
        structure.fillWithBlocks(world, start, 40, -45, 26, 42, -45, 30, Blocks.AIR.getDefaultState());
        structure.fillWithBlocks(world, start, 40, -45, 32, 42, -45, 34, Blocks.AIR.getDefaultState());
        structure.fillWithBlocks(world, start, 40, -45, 35, 41, -45, 36, Blocks.SANDSTONE.getDefaultState());
        structure.fillWithBlocks(world, start, 40, -41, 25, 44, -41, 31, Blocks.SANDSTONE.getDefaultState());
        structure.fillWithBlocks(world, start, 40, -40, 22, 41, -40, 24, Blocks.AIR.getDefaultState());
        structure.fillWithBlocks(world, start, 40, -40, 32, 41, -40, 34, Blocks.AIR.getDefaultState());
        structure.fillWithBlocks(world, start, 40, -35, 21, 50, -35, 21, Blocks.STONE_BRICKS.getDefaultState());
        structure.fillWithBlocks(world, start, 40, -35, 22, 41, -35, 24, Blocks.AIR.getDefaultState());
        structure.fillWithBlocks(world, start, 40, -35, 32, 41, -35, 34, Blocks.AIR.getDefaultState());
        structure.fillWithBlocks(world, start, 40, -34, 22, 41, -34, 36, Blocks.STONE_BRICKS.getDefaultState());
        structure.fillWithBlocks(world, start, 40, -33, 21, 40, -33, 21, Blocks.STONE_BRICKS.getDefaultState());
        structure.fillWithBlocks(world, start, 40, -33, 23, 41, -33, 29, Blocks.STONE_BRICKS.getDefaultState());
        structure.fillWithBlocks(world, start, 40, -33, 31, 42, -33, 33, Blocks.STONE_BRICKS.getDefaultState());
        structure.fillWithBlocks(world, start, 40, -33, 34, 41, -33, 36, Blocks.STONE_BRICKS.getDefaultState());
        structure.fillWithBlocks(world, start, 40, -32, 22, 40, -32, 22, Blocks.STONE_BRICKS.getDefaultState());
        structure.fillWithBlocks(world, start, 40, -32, 24, 40, -32, 27, Blocks.STONE_BRICKS.getDefaultState());
        structure.fillWithBlocks(world, start, 40, -32, 29, 41, -32, 32, Blocks.STONE_BRICKS.getDefaultState());
        structure.fillWithBlocks(world, start, 40, -32, 34, 40, -31, 36, Blocks.STONE_BRICKS.getDefaultState());
        structure.fillWithBlocks(world, start, 40, -31, 25, 43, -31, 28, Blocks.STONE_BRICKS.getDefaultState());
        structure.fillWithBlocks(world, start, 40, -31, 30, 43, -31, 35, Blocks.STONE_BRICKS.getDefaultState());
        structure.fillWithBlocks(world, start, 40, -30, -11, 40, -29, -11, Blocks.AIR.getDefaultState());
        structure.fillWithBlocks(world, start, 40, -30, -10, 40, -30, -10, Blocks.SANDSTONE.getDefaultState());
        structure.fillWithBlocks(world, start, 40, -30, -4, 47, -30, 7, Blocks.SANDSTONE.getDefaultState());
        structure.fillWithBlocks(world, start, 40, -30, 9, 40, -30, 9, Blocks.SANDSTONE.getDefaultState());
        structure.fillWithBlocks(world, start, 40, -30, 11, 40, -30, 12, Blocks.SANDSTONE.getDefaultState());
        structure.fillWithBlocks(world, start, 40, -30, 14, 41, -30, 18, Blocks.SANDSTONE.getDefaultState());
        structure.fillWithBlocks(world, start, 40, -30, 25, 40, -30, 25, Blocks.SANDSTONE.getDefaultState());
        structure.fillWithBlocks(world, start, 40, -30, 26, 40, -30, 26, Blocks.AIR.getDefaultState());
        structure.fillWithBlocks(world, start, 40, -30, 27, 40, -27, 27, Blocks.SANDSTONE.getDefaultState());
        structure.fillWithBlocks(world, start, 40, -30, 28, 40, -30, 29, Blocks.DIRT.getDefaultState());
        structure.fillWithBlocks(world, start, 40, -30, 30, 40, -30, 31, Blocks.AIR.getDefaultState());
        structure.fillWithBlocks(world, start, 40, -30, 32, 40, -30, 32, Blocks.DIRT.getDefaultState());
        structure.fillWithBlocks(world, start, 40, -30, 33, 40, -26, 33, Blocks.SANDSTONE.getDefaultState());
        structure.fillWithBlocks(world, start, 40, -30, 34, 40, -30, 35, Blocks.DIRT.getDefaultState());
        structure.fillWithBlocks(world, start, 40, -30, 36, 40, -30, 36, Blocks.SANDSTONE.getDefaultState());
        structure.fillWithBlocks(world, start, 40, -30, 37, 40, -30, 39, Blocks.DIRT.getDefaultState());
        structure.fillWithBlocks(world, start, 40, -30, 42, 41, -30, 43, Blocks.SANDSTONE.getDefaultState());
        structure.fillWithBlocks(world, start, 40, -30, 46, 40, -30, 48, Blocks.DIRT.getDefaultState());
        structure.fillWithBlocks(world, start, 40, -30, 49, 40, -27, 49, Blocks.SANDSTONE.getDefaultState());
        structure.fillWithBlocks(world, start, 40, -30, 50, 40, -30, 52, Blocks.DIRT.getDefaultState());
        structure.fillWithBlocks(world, start, 40, -29, -16, 40, -29, -15, Blocks.STONE_BRICKS.getDefaultState());
        structure.fillWithBlocks(world, start, 40, -29, -12, 40, -29, -12, Blocks.STONE_BRICKS.getDefaultState());
        structure.fillWithBlocks(world, start, 40, -29, -7, 40, -29, -7, Blocks.SANDSTONE.getDefaultState());
        structure.fillWithBlocks(world, start, 40, -29, -6, 40, -29, -4, Blocks.STONE_BRICKS.getDefaultState());
        structure.fillWithBlocks(world, start, 40, -29, 4, 40, -29, 6, Blocks.AIR.getDefaultState());
        structure.fillWithBlocks(world, start, 40, -29, 7, 40, -29, 7, Blocks.SANDSTONE.getDefaultState());
        structure.fillWithBlocks(world, start, 40, -29, 9, 41, -29, 10, Blocks.SANDSTONE.getDefaultState());
        structure.fillWithBlocks(world, start, 40, -29, 12, 40, -29, 12, Blocks.SANDSTONE.getDefaultState());
        structure.fillWithBlocks(world, start, 40, -29, 14, 40, -29, 15, Blocks.SANDSTONE.getDefaultState());
        structure.fillWithBlocks(world, start, 40, -29, 20, 44, -29, 24, Blocks.AIR.getDefaultState());
        structure.fillWithBlocks(world, start, 40, -29, 25, 41, -29, 30, Blocks.SANDSTONE.getDefaultState());
        structure.fillWithBlocks(world, start, 40, -29, 34, 40, -28, 34, Blocks.AIR.getDefaultState());
        structure.fillWithBlocks(world, start, 40, -29, 39, 40, -27, 39, Blocks.DIRT.getDefaultState());
        structure.fillWithBlocks(world, start, 40, -29, 40, 40, -29, 53, Blocks.SANDSTONE.getDefaultState());
        structure.fillWithBlocks(world, start, 40, -28, -14, 40, -28, -13, Blocks.STONE_BRICKS.getDefaultState());
        structure.fillWithBlocks(world, start, 40, -28, -10, 40, -27, -9, Blocks.STONE_BRICKS.getDefaultState());
        structure.fillWithBlocks(world, start, 40, -28, -5, 41, -28, -5, Blocks.SANDSTONE.getDefaultState());
        structure.fillWithBlocks(world, start, 40, -28, 7, 41, -28, 10, Blocks.SANDSTONE.getDefaultState());
        structure.fillWithBlocks(world, start, 40, -28, 11, 40, -28, 12, Blocks.SANDSTONE.getDefaultState());
        structure.fillWithBlocks(world, start, 40, -28, 14, 41, -28, 15, Blocks.SANDSTONE.getDefaultState());
        structure.fillWithBlocks(world, start, 40, -28, 31, 41, -28, 32, Blocks.SANDSTONE.getDefaultState());
        structure.fillWithBlocks(world, start, 40, -28, 41, 40, -27, 42, Blocks.SANDSTONE.getDefaultState());
        structure.fillWithBlocks(world, start, 40, -28, 44, 40, -28, 45, Blocks.SANDSTONE.getDefaultState());
        structure.fillWithBlocks(world, start, 40, -28, 48, 40, -27, 49, Blocks.SANDSTONE.getDefaultState());
        structure.fillWithBlocks(world, start, 40, -28, 50, 41, -28, 50, Blocks.AIR.getDefaultState());
        structure.fillWithBlocks(world, start, 40, -28, 54, 40, -27, 55, Blocks.SANDSTONE.getDefaultState());
        structure.fillWithBlocks(world, start, 40, -27, -12, 40, -27, -9, Blocks.STONE_BRICKS.getDefaultState());
        structure.fillWithBlocks(world, start, 40, -27, -7, 40, -27, -7, Blocks.SANDSTONE.getDefaultState());
        structure.fillWithBlocks(world, start, 40, -27, 9, 41, -27, 15, Blocks.SANDSTONE.getDefaultState());
        structure.fillWithBlocks(world, start, 40, -27, 31, 41, -27, 34, Blocks.SANDSTONE.getDefaultState());
        structure.fillWithBlocks(world, start, 40, -27, 37, 40, -26, 37, Blocks.DIRT.getDefaultState());
        structure.fillWithBlocks(world, start, 40, -27, 40, 40, -26, 41, Blocks.SANDSTONE.getDefaultState());
        structure.fillWithBlocks(world, start, 40, -27, 45, 40, -26, 45, Blocks.AIR.getDefaultState());
        structure.fillWithBlocks(world, start, 40, -27, 46, 40, -27, 46, Blocks.SANDSTONE.getDefaultState());
        structure.fillWithBlocks(world, start, 40, -27, 50, 40, -27, 50, Blocks.AIR.getDefaultState());
        structure.fillWithBlocks(world, start, 40, -27, 52, 41, -27, 53, Blocks.SANDSTONE.getDefaultState());
        structure.fillWithBlocks(world, start, 40, -26, -16, 40, -25, -16, Blocks.STONE_BRICKS.getDefaultState());
        structure.fillWithBlocks(world, start, 40, -26, -14, 40, -26, -12, Blocks.STONE_BRICKS.getDefaultState());
        structure.fillWithBlocks(world, start, 40, -26, -11, 40, -25, -11, Blocks.SANDSTONE.getDefaultState());
        structure.fillWithBlocks(world, start, 40, -26, -10, 41, -26, -10, Blocks.STONE_BRICKS.getDefaultState());
        structure.fillWithBlocks(world, start, 40, -26, -9, 40, -26, -8, Blocks.AIR.getDefaultState());
        structure.fillWithBlocks(world, start, 40, -26, 7, 40, -26, 7, Blocks.SANDSTONE.getDefaultState());
        structure.fillWithBlocks(world, start, 40, -26, 9, 41, -26, 11, Blocks.SANDSTONE.getDefaultState());
        structure.fillWithBlocks(world, start, 40, -26, 13, 41, -26, 15, Blocks.SANDSTONE.getDefaultState());
        structure.fillWithBlocks(world, start, 40, -26, 34, 40, -21, 34, Blocks.SANDSTONE.getDefaultState());
        structure.fillWithBlocks(world, start, 40, -26, 35, 41, -26, 35, Blocks.AIR.getDefaultState());
        structure.fillWithBlocks(world, start, 40, -26, 36, 40, -26, 36, Blocks.SANDSTONE.getDefaultState());
        structure.fillWithBlocks(world, start, 40, -26, 42, 40, -25, 43, Blocks.AIR.getDefaultState());
        structure.fillWithBlocks(world, start, 40, -26, 44, 41, -25, 44, Blocks.SANDSTONE.getDefaultState());
        structure.fillWithBlocks(world, start, 40, -26, 46, 41, -25, 46, Blocks.SANDSTONE.getDefaultState());
        structure.fillWithBlocks(world, start, 40, -26, 47, 40, -25, 47, Blocks.AIR.getDefaultState());
        structure.fillWithBlocks(world, start, 40, -26, 48, 40, -26, 48, Blocks.SANDSTONE.getDefaultState());
        structure.fillWithBlocks(world, start, 40, -26, 49, 40, -25, 49, Blocks.AIR.getDefaultState());
        structure.fillWithBlocks(world, start, 40, -26, 50, 41, -26, 51, Blocks.SANDSTONE.getDefaultState());
        structure.fillWithBlocks(world, start, 40, -26, 52, 40, -25, 55, Blocks.SANDSTONE.getDefaultState());
        structure.fillWithBlocks(world, start, 40, -25, -15, 41, -25, -14, Blocks.STONE_BRICKS.getDefaultState());
        structure.fillWithBlocks(world, start, 40, -25, -13, 40, -24, -13, Blocks.AIR.getDefaultState());
        structure.fillWithBlocks(world, start, 40, -25, -10, 40, -25, -9, Blocks.SANDSTONE.getDefaultState());
        structure.fillWithBlocks(world, start, 40, -25, -7, 40, -24, -7, Blocks.STONE_BRICKS.getDefaultState());
        structure.fillWithBlocks(world, start, 40, -25, 5, 42, -25, 8, Blocks.SANDSTONE.getDefaultState());
        structure.fillWithBlocks(world, start, 40, -25, 9, 41, -25, 13, Blocks.SANDSTONE.getDefaultState());
        structure.fillWithBlocks(world, start, 40, -25, 14, 40, -25, 15, Blocks.DIRT.getDefaultState());
        structure.fillWithBlocks(world, start, 40, -25, 16, 40, -25, 19, Blocks.SANDSTONE.getDefaultState());
        structure.fillWithBlocks(world, start, 40, -25, 31, 40, -25, 31, Blocks.SANDSTONE.getDefaultState());
        structure.fillWithBlocks(world, start, 40, -25, 32, 40, -25, 33, Blocks.DIRT.getDefaultState());
        structure.fillWithBlocks(world, start, 40, -25, 36, 42, -25, 38, Blocks.SANDSTONE.getDefaultState());
        structure.fillWithBlocks(world, start, 40, -25, 40, 41, -25, 41, Blocks.SANDSTONE.getDefaultState());
        structure.fillWithBlocks(world, start, 40, -25, 45, 41, -25, 46, Blocks.SANDSTONE.getDefaultState());
        structure.fillWithBlocks(world, start, 40, -25, 50, 42, -25, 53, Blocks.SANDSTONE.getDefaultState());
        structure.fillWithBlocks(world, start, 40, -24, -16, 40, -24, -16, Blocks.DIRT.getDefaultState());
        structure.fillWithBlocks(world, start, 40, -24, -15, 40, -24, -14, Blocks.STONE_BRICKS.getDefaultState());
        structure.fillWithBlocks(world, start, 40, -24, -12, 41, -24, -11, Blocks.STONE_BRICKS.getDefaultState());
        structure.fillWithBlocks(world, start, 40, -24, -10, 41, -24, -10, Blocks.DIRT.getDefaultState());
        structure.fillWithBlocks(world, start, 40, -24, -9, 40, -24, -9, Blocks.STONE_BRICKS.getDefaultState());
        structure.fillWithBlocks(world, start, 40, -24, -8, 40, -23, -8, Blocks.AIR.getDefaultState());
        structure.fillWithBlocks(world, start, 40, -24, -6, 40, -24, -5, Blocks.SANDSTONE.getDefaultState());
        structure.fillWithBlocks(world, start, 40, -24, 7, 43, -24, 7, Blocks.SANDSTONE.getDefaultState());
        structure.fillWithBlocks(world, start, 40, -24, 10, 40, -24, 10, Blocks.SANDSTONE.getDefaultState());
        structure.fillWithBlocks(world, start, 40, -24, 12, 40, -21, 12, Blocks.SANDSTONE.getDefaultState());
        structure.fillWithBlocks(world, start, 40, -24, 13, 40, -24, 14, Blocks.AIR.getDefaultState());
        structure.fillWithBlocks(world, start, 40, -24, 15, 40, -24, 35, Blocks.SANDSTONE.getDefaultState());
        structure.fillWithBlocks(world, start, 40, -24, 37, 41, -24, 38, Blocks.SANDSTONE.getDefaultState());
        structure.fillWithBlocks(world, start, 40, -24, 41, 41, -24, 42, Blocks.SANDSTONE.getDefaultState());
        structure.fillWithBlocks(world, start, 40, -24, 44, 46, -24, 52, Blocks.SANDSTONE.getDefaultState());
        structure.fillWithBlocks(world, start, 40, -24, 54, 41, -24, 55, Blocks.SANDSTONE.getDefaultState());
        structure.fillWithBlocks(world, start, 40, -23, -16, 40, -23, -15, Blocks.STONE_BRICKS.getDefaultState());
        structure.fillWithBlocks(world, start, 40, -23, -13, 40, -23, -11, Blocks.STONE_BRICKS.getDefaultState());
        structure.fillWithBlocks(world, start, 40, -23, -9, 40, -23, -8, Blocks.AIR.getDefaultState());
        structure.fillWithBlocks(world, start, 40, -23, -6, 41, -22, -6, Blocks.STONE_BRICKS.getDefaultState());
        structure.fillWithBlocks(world, start, 40, -23, -5, 40, -23, -4, Blocks.SANDSTONE.getDefaultState());
        structure.fillWithBlocks(world, start, 40, -23, -3, 40, -23, -3, Blocks.STONE_BRICKS.getDefaultState());
        structure.fillWithBlocks(world, start, 40, -23, 0, 41, -22, 0, Blocks.SANDSTONE.getDefaultState());
        structure.fillWithBlocks(world, start, 40, -23, 1, 41, -23, 1, Blocks.DIRT.getDefaultState());
        structure.fillWithBlocks(world, start, 40, -23, 2, 42, -23, 4, Blocks.SANDSTONE.getDefaultState());
        structure.fillWithBlocks(world, start, 40, -23, 5, 41, -22, 5, Blocks.SANDSTONE.getDefaultState());
        structure.fillWithBlocks(world, start, 40, -23, 7, 40, -23, 13, Blocks.SANDSTONE.getDefaultState());
        structure.fillWithBlocks(world, start, 40, -23, 14, 40, -23, 14, Blocks.DIRT.getDefaultState());
        structure.fillWithBlocks(world, start, 40, -23, 16, 40, -23, 16, Blocks.DIRT.getDefaultState());
        structure.fillWithBlocks(world, start, 40, -23, 17, 40, -23, 19, Blocks.SANDSTONE.getDefaultState());
        structure.fillWithBlocks(world, start, 40, -23, 28, 40, -23, 28, Blocks.SANDSTONE.getDefaultState());
        structure.fillWithBlocks(world, start, 40, -23, 29, 40, -22, 29, Blocks.DIRT.getDefaultState());
        structure.fillWithBlocks(world, start, 40, -23, 30, 40, -23, 30, Blocks.SANDSTONE.getDefaultState());
        structure.fillWithBlocks(world, start, 40, -23, 32, 42, -23, 34, Blocks.SANDSTONE.getDefaultState());
        structure.fillWithBlocks(world, start, 40, -23, 35, 40, -23, 39, Blocks.SANDSTONE.getDefaultState());
        structure.fillWithBlocks(world, start, 40, -23, 40, 40, -23, 41, Blocks.AIR.getDefaultState());
        structure.fillWithBlocks(world, start, 40, -23, 42, 40, -23, 47, Blocks.SANDSTONE.getDefaultState());
        structure.fillWithBlocks(world, start, 40, -22, -16, 41, -22, -15, Blocks.SANDSTONE.getDefaultState());
        structure.fillWithBlocks(world, start, 40, -22, -14, 40, -22, -14, Blocks.STONE_BRICKS.getDefaultState());
        structure.fillWithBlocks(world, start, 40, -22, -13, 40, -22, -13, Blocks.SANDSTONE.getDefaultState());
        structure.fillWithBlocks(world, start, 40, -22, -12, 40, -22, -11, Blocks.AIR.getDefaultState());
        structure.fillWithBlocks(world, start, 40, -22, -10, 40, -22, -9, Blocks.STONE_BRICKS.getDefaultState());
        structure.fillWithBlocks(world, start, 40, -22, -8, 40, -21, -8, Blocks.SANDSTONE.getDefaultState());
        structure.fillWithBlocks(world, start, 40, -22, -7, 40, -22, -6, Blocks.STONE_BRICKS.getDefaultState());
        structure.fillWithBlocks(world, start, 40, -22, -5, 40, -22, -5, Blocks.SANDSTONE.getDefaultState());
        structure.fillWithBlocks(world, start, 40, -22, -4, 40, -22, -2, Blocks.STONE_BRICKS.getDefaultState());
        structure.fillWithBlocks(world, start, 40, -22, 4, 41, -22, 8, Blocks.SANDSTONE.getDefaultState());
        structure.fillWithBlocks(world, start, 40, -22, 13, 41, -22, 16, Blocks.SANDSTONE.getDefaultState());
        structure.fillWithBlocks(world, start, 40, -22, 17, 40, -22, 20, Blocks.SANDSTONE.getDefaultState());
        structure.fillWithBlocks(world, start, 40, -22, 21, 40, -22, 21, Blocks.AIR.getDefaultState());
        structure.fillWithBlocks(world, start, 40, -22, 22, 40, -11, 22, Blocks.SANDSTONE.getDefaultState());
        structure.fillWithBlocks(world, start, 40, -22, 24, 40, -22, 24, Blocks.SANDSTONE.getDefaultState());
        structure.fillWithBlocks(world, start, 40, -22, 30, 41, -22, 35, Blocks.SANDSTONE.getDefaultState());
        structure.fillWithBlocks(world, start, 40, -22, 36, 40, -22, 37, Blocks.AIR.getDefaultState());
        structure.fillWithBlocks(world, start, 40, -22, 38, 41, -22, 41, Blocks.SANDSTONE.getDefaultState());
        structure.fillWithBlocks(world, start, 40, -22, 43, 40, -22, 46, Blocks.SANDSTONE.getDefaultState());
        structure.fillWithBlocks(world, start, 40, -22, 47, 41, -22, 47, Blocks.DIRT.getDefaultState());
        structure.fillWithBlocks(world, start, 40, -22, 48, 40, -22, 49, Blocks.SANDSTONE.getDefaultState());
        structure.fillWithBlocks(world, start, 40, -22, 50, 41, -22, 50, Blocks.DIRT.getDefaultState());
        structure.fillWithBlocks(world, start, 40, -22, 51, 41, -22, 52, Blocks.SANDSTONE.getDefaultState());
        structure.fillWithBlocks(world, start, 40, -22, 53, 40, -22, 55, Blocks.SANDSTONE.getDefaultState());
        structure.fillWithBlocks(world, start, 40, -21, -16, 40, -21, -15, Blocks.STONE_BRICKS.getDefaultState());
        structure.fillWithBlocks(world, start, 40, -21, -14, 41, -21, -14, Blocks.SANDSTONE.getDefaultState());
        structure.fillWithBlocks(world, start, 40, -21, -11, 40, -21, -9, Blocks.STONE_BRICKS.getDefaultState());
        structure.fillWithBlocks(world, start, 40, -21, -6, 40, -21, -6, Blocks.STONE_BRICKS.getDefaultState());
        structure.fillWithBlocks(world, start, 40, -21, -5, 40, -21, -4, Blocks.SANDSTONE.getDefaultState());
        structure.fillWithBlocks(world, start, 40, -21, -2, 41, -21, -2, Blocks.STONE_BRICKS.getDefaultState());
        structure.fillWithBlocks(world, start, 40, -21, -1, 41, -21, 6, Blocks.SANDSTONE.getDefaultState());
        structure.fillWithBlocks(world, start, 40, -21, 7, 40, -21, 12, Blocks.SANDSTONE.getDefaultState());
        structure.fillWithBlocks(world, start, 40, -21, 14, 40, -21, 19, Blocks.SANDSTONE.getDefaultState());
        structure.fillWithBlocks(world, start, 40, -21, 21, 40, -21, 24, Blocks.SANDSTONE.getDefaultState());
        structure.fillWithBlocks(world, start, 40, -21, 26, 41, -21, 27, Blocks.SANDSTONE.getDefaultState());
        structure.fillWithBlocks(world, start, 40, -21, 28, 40, -21, 39, Blocks.SANDSTONE.getDefaultState());
        structure.fillWithBlocks(world, start, 40, -21, 41, 40, -21, 52, Blocks.SANDSTONE.getDefaultState());
        structure.fillWithBlocks(world, start, 40, -21, 53, 41, -21, 53, Blocks.AIR.getDefaultState());
        structure.fillWithBlocks(world, start, 40, -21, 54, 48, -21, 54, Blocks.SANDSTONE.getDefaultState());
        structure.fillWithBlocks(world, start, 40, -21, 55, 41, -21, 55, Blocks.AIR.getDefaultState());
        structure.fillWithBlocks(world, start, 40, -19, 29, 42, -19, 31, Blocks.AIR.getDefaultState());
        structure.fillWithBlocks(world, start, 40, -18, 23, 41, -18, 24, Blocks.SANDSTONE.getDefaultState());
        structure.fillWithBlocks(world, start, 40, -18, 29, 42, -18, 31, Blocks.AIR.getDefaultState());
        structure.fillWithBlocks(world, start, 40, -14, 29, 42, -14, 31, Blocks.SANDSTONE.getDefaultState());
        structure.fillWithBlocks(world, start, 40, -14, 33, 41, -14, 34, Blocks.SANDSTONE.getDefaultState());
        structure.fillWithBlocks(world, start, 40, -13, 31, 43, -13, 34, Blocks.SANDSTONE.getDefaultState());
        structure.fillWithBlocks(world, start, 40, 0, 8, 40, 0, 8, Blocks.STONE.getDefaultState());
        structure.fillWithBlocks(world, start, 40, 0, 9, 40, 4, 9, Blocks.SANDSTONE.getDefaultState());
        structure.fillWithBlocks(world, start, 40, 1, 10, 40, 1, 10, Blocks.STONE.getDefaultState());
        structure.fillWithBlocks(world, start, 40, 1, 11, 40, 1, 14, Blocks.SANDSTONE.getDefaultState());
        structure.fillWithBlocks(world, start, 40, 1, 137, 49, 1, 146, Blocks.STONE.getDefaultState());
        structure.fillWithBlocks(world, start, 40, 2, 17, 42, 2, 19, Blocks.SANDSTONE.getDefaultState());
        structure.fillWithBlocks(world, start, 40, 5, 10, 49, 5, 19, Blocks.SANDSTONE.getDefaultState());
        structure.fillWithBlocks(world, start, 40, 7, 68, 41, 7, 68, Blocks.SANDSTONE.getDefaultState());
        structure.fillWithBlocks(world, start, 40, 7, 69, 40, 7, 69, Blocks.SAND.getDefaultState());
        structure.fillWithBlocks(world, start, 40, 7, 70, 40, 7, 136, Blocks.SANDSTONE.getDefaultState());
        structure.fillWithBlocks(world, start, 40, 8, 68, 41, 8, 68, Blocks.SAND.getDefaultState());
        structure.fillWithBlocks(world, start, 40, 8, 70, 40, 8, 136, Blocks.SAND.getDefaultState());
        structure.fillWithBlocks(world, start, 41, -49, 26, 43, -49, 30, Blocks.AIR.getDefaultState());
        structure.fillWithBlocks(world, start, 41, -44, 22, 41, -44, 22, Blocks.SANDSTONE.getDefaultState());
        structure.fillWithBlocks(world, start, 41, -44, 24, 44, -44, 27, Blocks.SANDSTONE.getDefaultState());
        structure.fillWithBlocks(world, start, 41, -44, 29, 44, -44, 32, Blocks.SANDSTONE.getDefaultState());
        structure.fillWithBlocks(world, start, 41, -44, 34, 43, -44, 36, Blocks.SANDSTONE.getDefaultState());
        structure.fillWithBlocks(world, start, 41, -41, 35, 42, -41, 36, Blocks.SANDSTONE.getDefaultState());
        structure.fillWithBlocks(world, start, 41, -40, 16, 44, -40, 21, Blocks.STONE_BRICKS.getDefaultState());
        structure.fillWithBlocks(world, start, 41, -40, 35, 41, -40, 35, Blocks.STONE_BRICKS.getDefaultState());
        structure.fillWithBlocks(world, start, 41, -40, 37, 43, -40, 40, Blocks.STONE_BRICKS.getDefaultState());
        structure.fillWithBlocks(world, start, 41, -39, 16, 42, -39, 20, Blocks.STONE_BRICKS.getDefaultState());
        structure.fillWithBlocks(world, start, 41, -39, 36, 41, -37, 40, Blocks.STONE_BRICKS.getDefaultState());
        structure.fillWithBlocks(world, start, 41, -38, 16, 43, -38, 18, Blocks.STONE_BRICKS.getDefaultState());
        structure.fillWithBlocks(world, start, 41, -38, 19, 41, -38, 20, Blocks.STONE_BRICKS.getDefaultState());
        structure.fillWithBlocks(world, start, 41, -37, 16, 44, -37, 20, Blocks.STONE_BRICKS.getDefaultState());
        structure.fillWithBlocks(world, start, 41, -36, 16, 43, -36, 18, Blocks.STONE_BRICKS.getDefaultState());
        structure.fillWithBlocks(world, start, 41, -36, 19, 42, -36, 20, Blocks.STONE_BRICKS.getDefaultState());
        structure.fillWithBlocks(world, start, 41, -36, 37, 44, -36, 40, Blocks.STONE_BRICKS.getDefaultState());
        structure.fillWithBlocks(world, start, 41, -35, 16, 42, -35, 21, Blocks.STONE_BRICKS.getDefaultState());
        structure.fillWithBlocks(world, start, 41, -35, 35, 50, -35, 35, Blocks.STONE_BRICKS.getDefaultState());
        structure.fillWithBlocks(world, start, 41, -35, 36, 42, -35, 36, Blocks.AIR.getDefaultState());
        structure.fillWithBlocks(world, start, 41, -35, 37, 43, -35, 40, Blocks.STONE_BRICKS.getDefaultState());
        structure.fillWithBlocks(world, start, 41, -34, 16, 42, -34, 17, Blocks.STONE_BRICKS.getDefaultState());
        structure.fillWithBlocks(world, start, 41, -34, 18, 41, -34, 40, Blocks.STONE_BRICKS.getDefaultState());
        structure.fillWithBlocks(world, start, 41, -33, 16, 43, -33, 18, Blocks.STONE_BRICKS.getDefaultState());
        structure.fillWithBlocks(world, start, 41, -33, 19, 41, -31, 19, Blocks.STONE_BRICKS.getDefaultState());
        structure.fillWithBlocks(world, start, 41, -33, 21, 44, -33, 24, Blocks.STONE_BRICKS.getDefaultState());
        structure.fillWithBlocks(world, start, 41, -33, 30, 43, -33, 33, Blocks.STONE_BRICKS.getDefaultState());
        structure.fillWithBlocks(world, start, 41, -33, 37, 41, -33, 40, Blocks.STONE_BRICKS.getDefaultState());
        structure.fillWithBlocks(world, start, 41, -32, 16, 44, -32, 19, Blocks.STONE_BRICKS.getDefaultState());
        structure.fillWithBlocks(world, start, 41, -32, 20, 41, -32, 24, Blocks.STONE_BRICKS.getDefaultState());
        structure.fillWithBlocks(world, start, 41, -32, 25, 41, -32, 25, Blocks.AIR.getDefaultState());
        structure.fillWithBlocks(world, start, 41, -32, 26, 41, -32, 34, Blocks.STONE_BRICKS.getDefaultState());
        structure.fillWithBlocks(world, start, 41, -32, 36, 43, -32, 40, Blocks.STONE_BRICKS.getDefaultState());
        structure.fillWithBlocks(world, start, 41, -31, 16, 42, -31, 17, Blocks.STONE_BRICKS.getDefaultState());
        structure.fillWithBlocks(world, start, 41, -31, 18, 41, -31, 40, Blocks.STONE_BRICKS.getDefaultState());
        structure.fillWithBlocks(world, start, 41, -30, -16, 41, -30, -14, Blocks.AIR.getDefaultState());
        structure.fillWithBlocks(world, start, 41, -30, -12, 41, -30, -11, Blocks.DIRT.getDefaultState());
        structure.fillWithBlocks(world, start, 41, -30, -10, 42, -30, -7, Blocks.SANDSTONE.getDefaultState());
        structure.fillWithBlocks(world, start, 41, -30, -5, 47, -30, 7, Blocks.SANDSTONE.getDefaultState());
        structure.fillWithBlocks(world, start, 41, -30, 8, 41, -30, 10, Blocks.SANDSTONE.getDefaultState());
        structure.fillWithBlocks(world, start, 41, -30, 11, 41, -30, 12, Blocks.AIR.getDefaultState());
        structure.fillWithBlocks(world, start, 41, -30, 13, 41, -30, 26, Blocks.SANDSTONE.getDefaultState());
        structure.fillWithBlocks(world, start, 41, -30, 29, 41, -30, 29, Blocks.SANDSTONE.getDefaultState());
        structure.fillWithBlocks(world, start, 41, -30, 30, 41, -30, 30, Blocks.DIRT.getDefaultState());
        structure.fillWithBlocks(world, start, 41, -30, 31, 41, -20, 31, Blocks.SANDSTONE.getDefaultState());
        structure.fillWithBlocks(world, start, 41, -30, 32, 41, -29, 32, Blocks.AIR.getDefaultState());
        structure.fillWithBlocks(world, start, 41, -30, 34, 41, -29, 36, Blocks.SANDSTONE.getDefaultState());
        structure.fillWithBlocks(world, start, 41, -30, 37, 41, -30, 37, Blocks.SANDSTONE.getDefaultState());
        structure.fillWithBlocks(world, start, 41, -30, 39, 42, -30, 40, Blocks.SANDSTONE.getDefaultState());
        structure.fillWithBlocks(world, start, 41, -30, 41, 41, -29, 41, Blocks.AIR.getDefaultState());
        structure.fillWithBlocks(world, start, 41, -30, 44, 44, -30, 47, Blocks.SANDSTONE.getDefaultState());
        structure.fillWithBlocks(world, start, 41, -30, 48, 41, -30, 49, Blocks.AIR.getDefaultState());
        structure.fillWithBlocks(world, start, 41, -30, 51, 41, -30, 51, Blocks.AIR.getDefaultState());
        structure.fillWithBlocks(world, start, 41, -30, 53, 41, -29, 53, Blocks.DIRT.getDefaultState());
        structure.fillWithBlocks(world, start, 41, -30, 54, 41, -30, 55, Blocks.SANDSTONE.getDefaultState());
        structure.fillWithBlocks(world, start, 41, -29, -16, 42, -28, -16, Blocks.SANDSTONE.getDefaultState());
        structure.fillWithBlocks(world, start, 41, -29, -14, 41, -29, -14, Blocks.STONE_BRICKS.getDefaultState());
        structure.fillWithBlocks(world, start, 41, -29, -12, 41, -29, -9, Blocks.STONE_BRICKS.getDefaultState());
        structure.fillWithBlocks(world, start, 41, -29, -8, 41, -29, -3, Blocks.SANDSTONE.getDefaultState());
        structure.fillWithBlocks(world, start, 41, -29, 4, 41, -27, 4, Blocks.IRON_BARS.getDefaultState().with(FourWayBlock.WATERLOGGED, false).with(FourWayBlock.NORTH, true).with(FourWayBlock.SOUTH, true).with(FourWayBlock.EAST, true).with(FourWayBlock.WEST, true));
        structure.fillWithBlocks(world, start, 41, -29, 5, 41, -29, 5, Blocks.AIR.getDefaultState());
        structure.fillWithBlocks(world, start, 41, -29, 6, 41, -27, 6, Blocks.IRON_BARS.getDefaultState().with(FourWayBlock.WATERLOGGED, false).with(FourWayBlock.NORTH, true).with(FourWayBlock.SOUTH, true).with(FourWayBlock.EAST, true).with(FourWayBlock.WEST, true));
        structure.fillWithBlocks(world, start, 41, -29, 7, 41, -29, 13, Blocks.SANDSTONE.getDefaultState());
        structure.fillWithBlocks(world, start, 41, -29, 14, 41, -29, 14, Blocks.AIR.getDefaultState());
        structure.fillWithBlocks(world, start, 41, -29, 15, 41, -25, 15, Blocks.SANDSTONE.getDefaultState());
        structure.fillWithBlocks(world, start, 41, -29, 16, 41, -27, 16, Blocks.IRON_BARS.getDefaultState().with(FourWayBlock.WATERLOGGED, false).with(FourWayBlock.NORTH, true).with(FourWayBlock.SOUTH, true).with(FourWayBlock.EAST, true).with(FourWayBlock.WEST, true));
        structure.fillWithBlocks(world, start, 41, -29, 17, 41, -29, 17, Blocks.AIR.getDefaultState());
        structure.fillWithBlocks(world, start, 41, -29, 18, 41, -27, 18, Blocks.IRON_BARS.getDefaultState().with(FourWayBlock.WATERLOGGED, false).with(FourWayBlock.NORTH, true).with(FourWayBlock.SOUTH, true).with(FourWayBlock.EAST, true).with(FourWayBlock.WEST, true));
        structure.fillWithBlocks(world, start, 41, -29, 33, 43, -29, 35, Blocks.SANDSTONE.getDefaultState());
        structure.fillWithBlocks(world, start, 41, -29, 38, 41, -29, 40, Blocks.SANDSTONE.getDefaultState());
        structure.fillWithBlocks(world, start, 41, -29, 49, 42, -29, 50, Blocks.SANDSTONE.getDefaultState());
        structure.fillWithBlocks(world, start, 41, -29, 51, 41, -29, 52, Blocks.SANDSTONE.getDefaultState());
        structure.fillWithBlocks(world, start, 41, -29, 54, 41, -29, 54, Blocks.SANDSTONE.getDefaultState());
        structure.fillWithBlocks(world, start, 41, -28, -12, 42, -28, -10, Blocks.STONE_BRICKS.getDefaultState());
        structure.fillWithBlocks(world, start, 41, -28, -9, 42, -28, -9, Blocks.SANDSTONE.getDefaultState());
        structure.fillWithBlocks(world, start, 41, -28, -7, 41, -25, -7, Blocks.SANDSTONE.getDefaultState());
        structure.fillWithBlocks(world, start, 41, -28, 5, 41, -28, 5, Blocks.AIR.getDefaultState());
        structure.fillWithBlocks(world, start, 41, -28, 12, 41, -25, 15, Blocks.SANDSTONE.getDefaultState());
        structure.fillWithBlocks(world, start, 41, -28, 17, 41, -28, 17, Blocks.AIR.getDefaultState());
        structure.fillWithBlocks(world, start, 41, -28, 33, 41, -28, 33, Blocks.AIR.getDefaultState());
        structure.fillWithBlocks(world, start, 41, -28, 34, 41, -27, 34, Blocks.SANDSTONE.getDefaultState());
        structure.fillWithBlocks(world, start, 41, -28, 35, 41, -28, 36, Blocks.AIR.getDefaultState());
        structure.fillWithBlocks(world, start, 41, -28, 37, 41, -28, 37, Blocks.SANDSTONE.getDefaultState());
        structure.fillWithBlocks(world, start, 41, -28, 38, 41, -28, 39, Blocks.AIR.getDefaultState());
        structure.fillWithBlocks(world, start, 41, -28, 40, 42, -28, 41, Blocks.SANDSTONE.getDefaultState());
        structure.fillWithBlocks(world, start, 41, -28, 44, 41, -22, 44, Blocks.SANDSTONE.getDefaultState());
        structure.fillWithBlocks(world, start, 41, -28, 46, 41, -23, 46, Blocks.SANDSTONE.getDefaultState());
        structure.fillWithBlocks(world, start, 41, -28, 48, 42, -28, 48, Blocks.SANDSTONE.getDefaultState());
        structure.fillWithBlocks(world, start, 41, -28, 49, 41, -28, 50, Blocks.AIR.getDefaultState());
        structure.fillWithBlocks(world, start, 41, -28, 51, 42, -28, 53, Blocks.SANDSTONE.getDefaultState());
        structure.fillWithBlocks(world, start, 41, -28, 54, 41, -28, 55, Blocks.AIR.getDefaultState());
        structure.fillWithBlocks(world, start, 41, -27, -14, 41, -27, -12, Blocks.STONE_BRICKS.getDefaultState());
        structure.fillWithBlocks(world, start, 41, -27, -10, 41, -27, -9, Blocks.STONE_BRICKS.getDefaultState());
        structure.fillWithBlocks(world, start, 41, -27, -8, 41, -27, -3, Blocks.SANDSTONE.getDefaultState());
        structure.fillWithBlocks(world, start, 41, -27, 5, 41, -27, 6, Blocks.IRON_BARS.getDefaultState().with(FourWayBlock.WATERLOGGED, false).with(FourWayBlock.NORTH, true).with(FourWayBlock.SOUTH, true).with(FourWayBlock.EAST, true).with(FourWayBlock.WEST, true));
        structure.fillWithBlocks(world, start, 41, -27, 7, 41, -27, 15, Blocks.SANDSTONE.getDefaultState());
        structure.fillWithBlocks(world, start, 41, -27, 17, 41, -27, 18, Blocks.IRON_BARS.getDefaultState().with(FourWayBlock.WATERLOGGED, false).with(FourWayBlock.NORTH, true).with(FourWayBlock.SOUTH, true).with(FourWayBlock.EAST, true).with(FourWayBlock.WEST, true));
        structure.fillWithBlocks(world, start, 41, -27, 26, 41, -27, 34, Blocks.SANDSTONE.getDefaultState());
        structure.fillWithBlocks(world, start, 41, -27, 36, 42, -27, 37, Blocks.SANDSTONE.getDefaultState());
        structure.fillWithBlocks(world, start, 41, -27, 38, 41, -27, 40, Blocks.SANDSTONE.getDefaultState());
        structure.fillWithBlocks(world, start, 41, -27, 42, 41, -27, 47, Blocks.SANDSTONE.getDefaultState());
        structure.fillWithBlocks(world, start, 41, -27, 48, 41, -27, 48, Blocks.DIRT.getDefaultState());
        structure.fillWithBlocks(world, start, 41, -27, 49, 41, -27, 50, Blocks.SANDSTONE.getDefaultState());
        structure.fillWithBlocks(world, start, 41, -27, 51, 41, -27, 51, Blocks.AIR.getDefaultState());
        structure.fillWithBlocks(world, start, 41, -26, -15, 41, -26, -15, Blocks.STONE_BRICKS.getDefaultState());
        structure.fillWithBlocks(world, start, 41, -26, -12, 42, -26, -12, Blocks.DIRT.getDefaultState());
        structure.fillWithBlocks(world, start, 41, -26, -11, 41, -26, -10, Blocks.STONE_BRICKS.getDefaultState());
        structure.fillWithBlocks(world, start, 41, -26, -5, 41, -25, -5, Blocks.SANDSTONE.getDefaultState());
        structure.fillWithBlocks(world, start, 41, -26, 4, 41, -24, 7, Blocks.SANDSTONE.getDefaultState());
        structure.fillWithBlocks(world, start, 41, -26, 8, 41, -25, 15, Blocks.SANDSTONE.getDefaultState());
        structure.fillWithBlocks(world, start, 41, -26, 16, 41, -26, 19, Blocks.SANDSTONE.getDefaultState());
        structure.fillWithBlocks(world, start, 41, -26, 27, 41, -23, 27, Blocks.SANDSTONE.getDefaultState());
        structure.fillWithBlocks(world, start, 41, -26, 36, 42, -26, 37, Blocks.SANDSTONE.getDefaultState());
        structure.fillWithBlocks(world, start, 41, -26, 38, 41, -26, 39, Blocks.DIRT.getDefaultState());
        structure.fillWithBlocks(world, start, 41, -26, 40, 42, -26, 42, Blocks.SANDSTONE.getDefaultState());
        structure.fillWithBlocks(world, start, 41, -26, 49, 42, -26, 51, Blocks.SANDSTONE.getDefaultState());
        structure.fillWithBlocks(world, start, 41, -26, 52, 41, -26, 53, Blocks.AIR.getDefaultState());
        structure.fillWithBlocks(world, start, 41, -26, 54, 42, -26, 55, Blocks.SANDSTONE.getDefaultState());
        structure.fillWithBlocks(world, start, 41, -25, -13, 41, -21, -13, Blocks.STONE_BRICKS.getDefaultState());
        structure.fillWithBlocks(world, start, 41, -25, -12, 42, -25, -12, Blocks.SANDSTONE.getDefaultState());
        structure.fillWithBlocks(world, start, 41, -25, -11, 41, -25, -11, Blocks.AIR.getDefaultState());
        structure.fillWithBlocks(world, start, 41, -25, -9, 41, -25, -3, Blocks.SANDSTONE.getDefaultState());
        structure.fillWithBlocks(world, start, 41, -25, 2, 42, -25, 8, Blocks.SANDSTONE.getDefaultState());
        structure.fillWithBlocks(world, start, 41, -25, 17, 42, -25, 19, Blocks.SANDSTONE.getDefaultState());
        structure.fillWithBlocks(world, start, 41, -25, 26, 41, -23, 33, Blocks.SANDSTONE.getDefaultState());
        structure.fillWithBlocks(world, start, 41, -25, 34, 42, -25, 42, Blocks.SANDSTONE.getDefaultState());
        structure.fillWithBlocks(world, start, 41, -25, 43, 41, -23, 48, Blocks.SANDSTONE.getDefaultState());
        structure.fillWithBlocks(world, start, 41, -25, 54, 41, -25, 54, Blocks.DIRT.getDefaultState());
        structure.fillWithBlocks(world, start, 41, -25, 55, 41, -22, 55, Blocks.SANDSTONE.getDefaultState());
        structure.fillWithBlocks(world, start, 41, -24, -16, 41, -24, -16, Blocks.AIR.getDefaultState());
        structure.fillWithBlocks(world, start, 41, -24, -14, 41, -24, -11, Blocks.STONE_BRICKS.getDefaultState());
        structure.fillWithBlocks(world, start, 41, -24, -9, 41, -24, -7, Blocks.STONE_BRICKS.getDefaultState());
        structure.fillWithBlocks(world, start, 41, -24, -6, 41, -24, -6, Blocks.SANDSTONE.getDefaultState());
        structure.fillWithBlocks(world, start, 41, -24, -5, 41, -24, -3, Blocks.STONE_BRICKS.getDefaultState());
        structure.fillWithBlocks(world, start, 41, -24, 9, 43, -24, 11, Blocks.SANDSTONE.getDefaultState());
        structure.fillWithBlocks(world, start, 41, -24, 13, 42, -24, 14, Blocks.SANDSTONE.getDefaultState());
        structure.fillWithBlocks(world, start, 41, -24, 15, 41, -24, 15, Blocks.AIR.getDefaultState());
        structure.fillWithBlocks(world, start, 41, -24, 34, 41, -24, 35, Blocks.DIRT.getDefaultState());
        structure.fillWithBlocks(world, start, 41, -24, 36, 42, -24, 38, Blocks.SANDSTONE.getDefaultState());
        structure.fillWithBlocks(world, start, 41, -24, 40, 42, -24, 55, Blocks.SANDSTONE.getDefaultState());
        structure.fillWithBlocks(world, start, 41, -23, -16, 41, -23, -16, Blocks.STONE_BRICKS.getDefaultState());
        structure.fillWithBlocks(world, start, 41, -23, -15, 41, -22, -14, Blocks.SANDSTONE.getDefaultState());
        structure.fillWithBlocks(world, start, 41, -23, -12, 41, -22, -12, Blocks.SANDSTONE.getDefaultState());
        structure.fillWithBlocks(world, start, 41, -23, -10, 41, -23, -9, Blocks.SANDSTONE.getDefaultState());
        structure.fillWithBlocks(world, start, 41, -23, -8, 42, -23, -8, Blocks.DIRT.getDefaultState());
        structure.fillWithBlocks(world, start, 41, -23, -7, 41, -23, -6, Blocks.STONE_BRICKS.getDefaultState());
        structure.fillWithBlocks(world, start, 41, -23, -5, 41, -22, -5, Blocks.SANDSTONE.getDefaultState());
        structure.fillWithBlocks(world, start, 41, -23, -4, 41, -23, -2, Blocks.STONE_BRICKS.getDefaultState());
        structure.fillWithBlocks(world, start, 41, -23, -1, 41, -22, 0, Blocks.SANDSTONE.getDefaultState());
        structure.fillWithBlocks(world, start, 41, -23, 6, 41, -23, 7, Blocks.AIR.getDefaultState());
        structure.fillWithBlocks(world, start, 41, -23, 8, 42, -23, 11, Blocks.SANDSTONE.getDefaultState());
        structure.fillWithBlocks(world, start, 41, -23, 12, 41, -23, 14, Blocks.SANDSTONE.getDefaultState());
        structure.fillWithBlocks(world, start, 41, -23, 15, 42, -23, 15, Blocks.DIRT.getDefaultState());
        structure.fillWithBlocks(world, start, 41, -23, 16, 41, -23, 16, Blocks.SANDSTONE.getDefaultState());
        structure.fillWithBlocks(world, start, 41, -23, 18, 42, -23, 19, Blocks.SANDSTONE.getDefaultState());
        structure.fillWithBlocks(world, start, 41, -23, 20, 41, -23, 34, Blocks.SANDSTONE.getDefaultState());
        structure.fillWithBlocks(world, start, 41, -23, 36, 42, -23, 38, Blocks.SANDSTONE.getDefaultState());
        structure.fillWithBlocks(world, start, 41, -23, 39, 41, -23, 39, Blocks.AIR.getDefaultState());
        structure.fillWithBlocks(world, start, 41, -23, 40, 41, -23, 41, Blocks.SANDSTONE.getDefaultState());
        structure.fillWithBlocks(world, start, 41, -23, 49, 42, -23, 52, Blocks.SANDSTONE.getDefaultState());
        structure.fillWithBlocks(world, start, 41, -23, 54, 42, -23, 55, Blocks.SANDSTONE.getDefaultState());
        structure.fillWithBlocks(world, start, 41, -22, -11, 41, -22, -10, Blocks.SANDSTONE.getDefaultState());
        structure.fillWithBlocks(world, start, 41, -22, -9, 42, -22, -8, Blocks.STONE_BRICKS.getDefaultState());
        structure.fillWithBlocks(world, start, 41, -22, -4, 41, -22, -3, Blocks.SANDSTONE.getDefaultState());
        structure.fillWithBlocks(world, start, 41, -22, 9, 41, -22, 10, Blocks.AIR.getDefaultState());
        structure.fillWithBlocks(world, start, 41, -22, 11, 42, -22, 12, Blocks.SANDSTONE.getDefaultState());
        structure.fillWithBlocks(world, start, 41, -22, 17, 41, -21, 17, Blocks.AIR.getDefaultState());
        structure.fillWithBlocks(world, start, 41, -22, 18, 41, -22, 21, Blocks.SANDSTONE.getDefaultState());
        structure.fillWithBlocks(world, start, 41, -22, 23, 42, -22, 24, Blocks.SANDSTONE.getDefaultState());
        structure.fillWithBlocks(world, start, 41, -22, 25, 41, -22, 26, Blocks.SANDSTONE.getDefaultState());
        structure.fillWithBlocks(world, start, 41, -22, 36, 41, -22, 36, Blocks.SANDSTONE.getDefaultState());
        structure.fillWithBlocks(world, start, 41, -22, 42, 41, -22, 42, Blocks.SANDSTONE.getDefaultState());
        structure.fillWithBlocks(world, start, 41, -22, 45, 41, -22, 45, Blocks.SANDSTONE.getDefaultState());
        structure.fillWithBlocks(world, start, 41, -22, 46, 41, -22, 47, Blocks.DIRT.getDefaultState());
        structure.fillWithBlocks(world, start, 41, -22, 49, 41, -22, 49, Blocks.SANDSTONE.getDefaultState());
        structure.fillWithBlocks(world, start, 41, -22, 54, 41, -22, 55, Blocks.SANDSTONE.getDefaultState());
        structure.fillWithBlocks(world, start, 41, -21, -12, 41, -21, -12, Blocks.STONE_BRICKS.getDefaultState());
        structure.fillWithBlocks(world, start, 41, -21, -10, 41, -21, -9, Blocks.STONE_BRICKS.getDefaultState());
        structure.fillWithBlocks(world, start, 41, -21, -6, 42, -21, -4, Blocks.STONE_BRICKS.getDefaultState());
        structure.fillWithBlocks(world, start, 41, -21, 8, 42, -21, 13, Blocks.SANDSTONE.getDefaultState());
        structure.fillWithBlocks(world, start, 41, -21, 15, 42, -21, 16, Blocks.SANDSTONE.getDefaultState());
        structure.fillWithBlocks(world, start, 41, -21, 20, 45, -21, 20, Blocks.SANDSTONE.getDefaultState());
        structure.fillWithBlocks(world, start, 41, -21, 21, 42, -21, 21, Blocks.AIR.getDefaultState());
        structure.fillWithBlocks(world, start, 41, -21, 22, 42, -21, 26, Blocks.SANDSTONE.getDefaultState());
        structure.fillWithBlocks(world, start, 41, -21, 29, 43, -21, 34, Blocks.SANDSTONE.getDefaultState());
        structure.fillWithBlocks(world, start, 41, -21, 38, 42, -21, 39, Blocks.SANDSTONE.getDefaultState());
        structure.fillWithBlocks(world, start, 41, -21, 40, 41, -21, 41, Blocks.SANDSTONE.getDefaultState());
        structure.fillWithBlocks(world, start, 41, -21, 43, 41, -21, 43, Blocks.SANDSTONE.getDefaultState());
        structure.fillWithBlocks(world, start, 41, -21, 45, 42, -21, 46, Blocks.SANDSTONE.getDefaultState());
        structure.fillWithBlocks(world, start, 41, -21, 48, 43, -21, 50, Blocks.SANDSTONE.getDefaultState());
        structure.fillWithBlocks(world, start, 41, -21, 51, 41, -21, 52, Blocks.SANDSTONE.getDefaultState());
        structure.fillWithBlocks(world, start, 41, -20, 34, 46, -18, 34, Blocks.SANDSTONE.getDefaultState());
        structure.fillWithBlocks(world, start, 41, -19, 22, 43, -19, 24, Blocks.SANDSTONE.getDefaultState());
        structure.fillWithBlocks(world, start, 41, -19, 25, 42, -19, 31, Blocks.AIR.getDefaultState());
        structure.fillWithBlocks(world, start, 41, -19, 32, 42, -19, 34, Blocks.SANDSTONE.getDefaultState());
        structure.fillWithBlocks(world, start, 41, -18, 22, 42, -18, 24, Blocks.SANDSTONE.getDefaultState());
        structure.fillWithBlocks(world, start, 41, -18, 25, 42, -18, 31, Blocks.AIR.getDefaultState());
        structure.fillWithBlocks(world, start, 41, -18, 32, 43, -18, 34, Blocks.SANDSTONE.getDefaultState());
        structure.fillWithBlocks(world, start, 41, -17, 22, 41, -14, 22, Blocks.SANDSTONE.getDefaultState());
        structure.fillWithBlocks(world, start, 41, -17, 24, 46, -15, 24, Blocks.SANDSTONE.getDefaultState());
        structure.fillWithBlocks(world, start, 41, -17, 32, 41, -17, 32, Blocks.SANDSTONE.getDefaultState());
        structure.fillWithBlocks(world, start, 41, -16, 32, 43, -16, 34, Blocks.SANDSTONE.getDefaultState());
        structure.fillWithBlocks(world, start, 41, -15, 25, 41, -15, 25, Blocks.SANDSTONE.getDefaultState());
        structure.fillWithBlocks(world, start, 41, -15, 31, 41, -15, 31, Blocks.SANDSTONE.getDefaultState());
        structure.fillWithBlocks(world, start, 41, -15, 33, 42, -15, 34, Blocks.SANDSTONE.getDefaultState());
        structure.fillWithBlocks(world, start, 41, -14, 23, 43, -12, 23, Blocks.SANDSTONE.getDefaultState());
        structure.fillWithBlocks(world, start, 41, -14, 24, 43, -14, 24, Blocks.AIR.getDefaultState());
        structure.fillWithBlocks(world, start, 41, -14, 25, 44, -14, 28, Blocks.SANDSTONE.getDefaultState());
        structure.fillWithBlocks(world, start, 41, -14, 32, 42, -14, 34, Blocks.SANDSTONE.getDefaultState());
        structure.fillWithBlocks(world, start, 41, -13, 24, 44, -13, 28, Blocks.SANDSTONE.getDefaultState());
        structure.fillWithBlocks(world, start, 41, -13, 30, 43, -13, 34, Blocks.SANDSTONE.getDefaultState());
        structure.fillWithBlocks(world, start, 41, 0, 8, 57, 0, 151, Blocks.STONE.getDefaultState());
        structure.fillWithBlocks(world, start, 41, 0, 152, 41, 0, 153, Blocks.STONE.getDefaultState());
        structure.fillWithBlocks(world, start, 41, 1, 10, 42, 1, 11, Blocks.STONE.getDefaultState());
        structure.fillWithBlocks(world, start, 41, 1, 12, 41, 1, 14, Blocks.SANDSTONE.getDefaultState());
        structure.fillWithBlocks(world, start, 41, 1, 15, 44, 1, 18, Blocks.STONE.getDefaultState());
        structure.fillWithBlocks(world, start, 41, 4, 8, 52, 4, 19, Blocks.SANDSTONE.getDefaultState());
        structure.fillWithBlocks(world, start, 41, 7, 69, 41, 7, 69, Blocks.CAVE_AIR.getDefaultState());
        structure.fillWithBlocks(world, start, 41, 7, 71, 42, 7, 73, Blocks.SANDSTONE.getDefaultState());
        structure.fillWithBlocks(world, start, 41, 7, 75, 41, 7, 78, Blocks.SAND.getDefaultState());
        structure.fillWithBlocks(world, start, 41, 7, 79, 41, 7, 136, Blocks.SANDSTONE.getDefaultState());
        structure.fillWithBlocks(world, start, 41, 8, 69, 41, 8, 69, Blocks.CAVE_AIR.getDefaultState());
        structure.fillWithBlocks(world, start, 41, 8, 71, 42, 8, 73, Blocks.SAND.getDefaultState());
        structure.fillWithBlocks(world, start, 41, 8, 79, 41, 8, 136, Blocks.SAND.getDefaultState());
        structure.fillWithBlocks(world, start, 42, -51, 22, 42, -51, 24, Blocks.SANDSTONE.getDefaultState());
        structure.fillWithBlocks(world, start, 42, -51, 32, 42, -51, 34, Blocks.SANDSTONE.getDefaultState());
        structure.fillWithBlocks(world, start, 42, -50, 20, 43, -50, 21, Blocks.SANDSTONE.getDefaultState());
        structure.fillWithBlocks(world, start, 42, -50, 22, 42, -48, 24, Blocks.AIR.getDefaultState());
        structure.fillWithBlocks(world, start, 42, -50, 32, 42, -48, 34, Blocks.AIR.getDefaultState());
        structure.fillWithBlocks(world, start, 42, -50, 35, 43, -50, 36, Blocks.SANDSTONE.getDefaultState());
        structure.fillWithBlocks(world, start, 42, -45, 35, 43, -45, 36, Blocks.SANDSTONE.getDefaultState());
        structure.fillWithBlocks(world, start, 42, -44, 22, 44, -44, 36, Blocks.SANDSTONE.getDefaultState());
        structure.fillWithBlocks(world, start, 42, -41, 22, 43, -41, 23, Blocks.STONE_BRICKS.getDefaultState());
        structure.fillWithBlocks(world, start, 42, -41, 32, 44, -41, 34, Blocks.STONE_BRICKS.getDefaultState());
        structure.fillWithBlocks(world, start, 42, -40, 22, 42, -40, 22, Blocks.AIR.getDefaultState());
        structure.fillWithBlocks(world, start, 42, -40, 32, 42, -40, 32, Blocks.AIR.getDefaultState());
        structure.fillWithBlocks(world, start, 42, -40, 35, 43, -40, 40, Blocks.STONE_BRICKS.getDefaultState());
        structure.fillWithBlocks(world, start, 42, -39, 21, 42, -35, 21, Blocks.STONE_BRICKS.getDefaultState());
        structure.fillWithBlocks(world, start, 42, -39, 22, 44, -39, 24, Blocks.AIR.getDefaultState());
        structure.fillWithBlocks(world, start, 42, -39, 25, 42, -34, 25, Blocks.STONE_BRICKS.getDefaultState());
        structure.fillWithBlocks(world, start, 42, -39, 26, 45, -39, 30, Blocks.AIR.getDefaultState());
        structure.fillWithBlocks(world, start, 42, -39, 31, 42, -33, 31, Blocks.STONE_BRICKS.getDefaultState());
        structure.fillWithBlocks(world, start, 42, -39, 32, 44, -39, 34, Blocks.AIR.getDefaultState());
        structure.fillWithBlocks(world, start, 42, -39, 35, 42, -39, 36, Blocks.STONE_BRICKS.getDefaultState());
        structure.fillWithBlocks(world, start, 42, -39, 37, 42, -38, 37, Blocks.AIR.getDefaultState());
        structure.fillWithBlocks(world, start, 42, -39, 38, 44, -39, 40, Blocks.STONE_BRICKS.getDefaultState());
        structure.fillWithBlocks(world, start, 42, -38, 20, 42, -37, 21, Blocks.STONE_BRICKS.getDefaultState());
        structure.fillWithBlocks(world, start, 42, -38, 22, 44, -38, 24, Blocks.AIR.getDefaultState());
        structure.fillWithBlocks(world, start, 42, -38, 26, 46, -38, 30, Blocks.AIR.getDefaultState());
        structure.fillWithBlocks(world, start, 42, -38, 32, 44, -38, 34, Blocks.AIR.getDefaultState());
        structure.fillWithBlocks(world, start, 42, -38, 35, 42, -38, 36, Blocks.STONE_BRICKS.getDefaultState());
        structure.fillWithBlocks(world, start, 42, -38, 38, 42, -38, 38, Blocks.STONE_BRICKS.getDefaultState());
        structure.fillWithBlocks(world, start, 42, -38, 40, 44, -36, 40, Blocks.STONE_BRICKS.getDefaultState());
        structure.fillWithBlocks(world, start, 42, -37, 22, 44, -37, 24, Blocks.AIR.getDefaultState());
        structure.fillWithBlocks(world, start, 42, -37, 26, 46, -37, 30, Blocks.AIR.getDefaultState());
        structure.fillWithBlocks(world, start, 42, -37, 32, 44, -37, 34, Blocks.AIR.getDefaultState());
        structure.fillWithBlocks(world, start, 42, -37, 35, 42, -37, 40, Blocks.STONE_BRICKS.getDefaultState());
        structure.fillWithBlocks(world, start, 42, -36, 22, 44, -36, 24, Blocks.AIR.getDefaultState());
        structure.fillWithBlocks(world, start, 42, -36, 26, 46, -36, 30, Blocks.AIR.getDefaultState());
        structure.fillWithBlocks(world, start, 42, -36, 32, 44, -36, 34, Blocks.AIR.getDefaultState());
        structure.fillWithBlocks(world, start, 42, -36, 35, 42, -36, 40, Blocks.STONE_BRICKS.getDefaultState());
        structure.fillWithBlocks(world, start, 42, -35, 22, 42, -35, 35, Blocks.STONE_BRICKS.getDefaultState());
        structure.fillWithBlocks(world, start, 42, -34, 19, 43, -34, 20, Blocks.STONE_BRICKS.getDefaultState());
        structure.fillWithBlocks(world, start, 42, -34, 22, 42, -34, 22, Blocks.STONE_BRICKS.getDefaultState());
        structure.fillWithBlocks(world, start, 42, -34, 33, 42, -34, 34, Blocks.STONE_BRICKS.getDefaultState());
        structure.fillWithBlocks(world, start, 42, -34, 36, 44, -34, 38, Blocks.STONE_BRICKS.getDefaultState());
        structure.fillWithBlocks(world, start, 42, -34, 39, 43, -34, 40, Blocks.STONE_BRICKS.getDefaultState());
        structure.fillWithBlocks(world, start, 42, -33, 20, 46, -33, 24, Blocks.STONE_BRICKS.getDefaultState());
        structure.fillWithBlocks(world, start, 42, -33, 26, 44, -33, 30, Blocks.STONE_BRICKS.getDefaultState());
        structure.fillWithBlocks(world, start, 42, -33, 34, 42, -33, 34, Blocks.AIR.getDefaultState());
        structure.fillWithBlocks(world, start, 42, -33, 35, 42, -31, 35, Blocks.STONE_BRICKS.getDefaultState());
        structure.fillWithBlocks(world, start, 42, -33, 36, 42, -33, 37, Blocks.AIR.getDefaultState());
        structure.fillWithBlocks(world, start, 42, -33, 38, 44, -33, 40, Blocks.STONE_BRICKS.getDefaultState());
        structure.fillWithBlocks(world, start, 42, -32, 21, 45, -32, 25, Blocks.STONE_BRICKS.getDefaultState());
        structure.fillWithBlocks(world, start, 42, -32, 27, 42, -32, 30, Blocks.STONE_BRICKS.getDefaultState());
        structure.fillWithBlocks(world, start, 42, -32, 31, 42, -32, 33, Blocks.AIR.getDefaultState());
        structure.fillWithBlocks(world, start, 42, -32, 34, 42, -32, 40, Blocks.STONE_BRICKS.getDefaultState());
        structure.fillWithBlocks(world, start, 42, -31, 19, 42, -31, 22, Blocks.STONE_BRICKS.getDefaultState());
        structure.fillWithBlocks(world, start, 42, -31, 24, 44, -31, 28, Blocks.STONE_BRICKS.getDefaultState());
        structure.fillWithBlocks(world, start, 42, -31, 29, 43, -31, 35, Blocks.STONE_BRICKS.getDefaultState());
        structure.fillWithBlocks(world, start, 42, -31, 37, 43, -31, 38, Blocks.STONE_BRICKS.getDefaultState());
        structure.fillWithBlocks(world, start, 42, -31, 40, 45, -31, 40, Blocks.STONE_BRICKS.getDefaultState());
        structure.fillWithBlocks(world, start, 42, -30, -16, 44, -30, -16, Blocks.STONE_BRICKS.getDefaultState());
        structure.fillWithBlocks(world, start, 42, -30, -15, 42, -30, -15, Blocks.DIRT.getDefaultState());
        structure.fillWithBlocks(world, start, 42, -30, -14, 42, -30, -14, Blocks.SANDSTONE.getDefaultState());
        structure.fillWithBlocks(world, start, 42, -30, -13, 42, -30, -12, Blocks.DIRT.getDefaultState());
        structure.fillWithBlocks(world, start, 42, -30, -11, 43, -30, -11, Blocks.AIR.getDefaultState());
        structure.fillWithBlocks(world, start, 42, -30, -6, 47, -30, 7, Blocks.SANDSTONE.getDefaultState());
        structure.fillWithBlocks(world, start, 42, -30, 9, 46, -30, 13, Blocks.SANDSTONE.getDefaultState());
        structure.fillWithBlocks(world, start, 42, -30, 19, 47, -30, 30, Blocks.SANDSTONE.getDefaultState());
        structure.fillWithBlocks(world, start, 42, -30, 32, 42, -29, 34, Blocks.SANDSTONE.getDefaultState());
        structure.fillWithBlocks(world, start, 42, -30, 35, 42, -30, 35, Blocks.DIRT.getDefaultState());
        structure.fillWithBlocks(world, start, 42, -30, 36, 42, -29, 36, Blocks.AIR.getDefaultState());
        structure.fillWithBlocks(world, start, 42, -30, 37, 42, -30, 37, Blocks.DIRT.getDefaultState());
        structure.fillWithBlocks(world, start, 42, -30, 38, 42, -30, 40, Blocks.SANDSTONE.getDefaultState());
        structure.fillWithBlocks(world, start, 42, -30, 41, 43, -30, 41, Blocks.DIRT.getDefaultState());
        structure.fillWithBlocks(world, start, 42, -30, 42, 47, -30, 47, Blocks.SANDSTONE.getDefaultState());
        structure.fillWithBlocks(world, start, 42, -30, 49, 42, -29, 50, Blocks.SANDSTONE.getDefaultState());
        structure.fillWithBlocks(world, start, 42, -30, 51, 43, -30, 51, Blocks.SANDSTONE.getDefaultState());
        structure.fillWithBlocks(world, start, 42, -30, 52, 42, -30, 54, Blocks.AIR.getDefaultState());
        structure.fillWithBlocks(world, start, 42, -30, 55, 46, -27, 55, Blocks.SANDSTONE.getDefaultState());
        structure.fillWithBlocks(world, start, 42, -29, -14, 43, -29, -13, Blocks.STONE_BRICKS.getDefaultState());
        structure.fillWithBlocks(world, start, 42, -29, -11, 42, -28, -10, Blocks.STONE_BRICKS.getDefaultState());
        structure.fillWithBlocks(world, start, 42, -29, -9, 42, -25, -9, Blocks.SANDSTONE.getDefaultState());
        structure.fillWithBlocks(world, start, 42, -29, -8, 45, -29, -4, Blocks.AIR.getDefaultState());
        structure.fillWithBlocks(world, start, 42, -29, 3, 46, -29, 7, Blocks.AIR.getDefaultState());
        structure.fillWithBlocks(world, start, 42, -29, 8, 42, -21, 8, Blocks.SANDSTONE.getDefaultState());
        structure.fillWithBlocks(world, start, 42, -29, 9, 46, -29, 13, Blocks.AIR.getDefaultState());
        structure.fillWithBlocks(world, start, 42, -29, 14, 42, -21, 14, Blocks.SANDSTONE.getDefaultState());
        structure.fillWithBlocks(world, start, 42, -29, 15, 44, -29, 24, Blocks.AIR.getDefaultState());
        structure.fillWithBlocks(world, start, 42, -29, 25, 42, -23, 25, Blocks.SANDSTONE.getDefaultState());
        structure.fillWithBlocks(world, start, 42, -29, 26, 44, -29, 30, Blocks.AIR.getDefaultState());
        structure.fillWithBlocks(world, start, 42, -29, 31, 42, -29, 35, Blocks.SANDSTONE.getDefaultState());
        structure.fillWithBlocks(world, start, 42, -29, 37, 43, -29, 38, Blocks.SANDSTONE.getDefaultState());
        structure.fillWithBlocks(world, start, 42, -29, 40, 42, -29, 40, Blocks.SANDSTONE.getDefaultState());
        structure.fillWithBlocks(world, start, 42, -29, 42, 42, -21, 42, Blocks.SANDSTONE.getDefaultState());
        structure.fillWithBlocks(world, start, 42, -29, 43, 44, -29, 47, Blocks.AIR.getDefaultState());
        structure.fillWithBlocks(world, start, 42, -29, 48, 42, -29, 50, Blocks.SANDSTONE.getDefaultState());
        structure.fillWithBlocks(world, start, 42, -29, 52, 43, -29, 55, Blocks.SANDSTONE.getDefaultState());
        structure.fillWithBlocks(world, start, 42, -28, -14, 42, -28, -10, Blocks.STONE_BRICKS.getDefaultState());
        structure.fillWithBlocks(world, start, 42, -28, -8, 46, -28, -4, Blocks.AIR.getDefaultState());
        structure.fillWithBlocks(world, start, 42, -28, 3, 46, -28, 7, Blocks.AIR.getDefaultState());
        structure.fillWithBlocks(world, start, 42, -28, 9, 46, -28, 13, Blocks.AIR.getDefaultState());
        structure.fillWithBlocks(world, start, 42, -28, 15, 48, -28, 24, Blocks.AIR.getDefaultState());
        structure.fillWithBlocks(world, start, 42, -28, 26, 44, -28, 30, Blocks.AIR.getDefaultState());
        structure.fillWithBlocks(world, start, 42, -28, 31, 42, -20, 31, Blocks.SANDSTONE.getDefaultState());
        structure.fillWithBlocks(world, start, 42, -28, 33, 42, -28, 33, Blocks.SANDSTONE.getDefaultState());
        structure.fillWithBlocks(world, start, 42, -28, 34, 42, -28, 35, Blocks.AIR.getDefaultState());
        structure.fillWithBlocks(world, start, 42, -28, 36, 43, -28, 37, Blocks.SANDSTONE.getDefaultState());
        structure.fillWithBlocks(world, start, 42, -28, 38, 42, -28, 42, Blocks.SANDSTONE.getDefaultState());
        structure.fillWithBlocks(world, start, 42, -28, 43, 44, -28, 47, Blocks.AIR.getDefaultState());
        structure.fillWithBlocks(world, start, 42, -28, 50, 42, -27, 51, Blocks.SANDSTONE.getDefaultState());
        structure.fillWithBlocks(world, start, 42, -28, 54, 42, -28, 55, Blocks.SANDSTONE.getDefaultState());
        structure.fillWithBlocks(world, start, 42, -27, -15, 42, -27, -14, Blocks.STONE_BRICKS.getDefaultState());
        structure.fillWithBlocks(world, start, 42, -27, -10, 42, -27, -10, Blocks.AIR.getDefaultState());
        structure.fillWithBlocks(world, start, 42, -27, -8, 46, -27, -4, Blocks.AIR.getDefaultState());
        structure.fillWithBlocks(world, start, 42, -27, 3, 46, -27, 7, Blocks.AIR.getDefaultState());
        structure.fillWithBlocks(world, start, 42, -27, 9, 46, -27, 13, Blocks.AIR.getDefaultState());
        structure.fillWithBlocks(world, start, 42, -27, 15, 48, -27, 24, Blocks.AIR.getDefaultState());
        structure.fillWithBlocks(world, start, 42, -27, 26, 46, -27, 30, Blocks.AIR.getDefaultState());
        structure.fillWithBlocks(world, start, 42, -27, 32, 42, -27, 32, Blocks.SANDSTONE.getDefaultState());
        structure.fillWithBlocks(world, start, 42, -27, 33, 42, -27, 33, Blocks.DIRT.getDefaultState());
        structure.fillWithBlocks(world, start, 42, -27, 34, 42, -27, 37, Blocks.SANDSTONE.getDefaultState());
        structure.fillWithBlocks(world, start, 42, -27, 39, 42, -24, 42, Blocks.SANDSTONE.getDefaultState());
        structure.fillWithBlocks(world, start, 42, -27, 43, 46, -27, 47, Blocks.AIR.getDefaultState());
        structure.fillWithBlocks(world, start, 42, -27, 48, 42, -24, 48, Blocks.SANDSTONE.getDefaultState());
        structure.fillWithBlocks(world, start, 42, -27, 53, 44, -27, 55, Blocks.SANDSTONE.getDefaultState());
        structure.fillWithBlocks(world, start, 42, -26, -16, 43, -26, -13, Blocks.STONE_BRICKS.getDefaultState());
        structure.fillWithBlocks(world, start, 42, -26, -11, 42, -26, -9, Blocks.SANDSTONE.getDefaultState());
        structure.fillWithBlocks(world, start, 42, -26, -8, 46, -26, -4, Blocks.AIR.getDefaultState());
        structure.fillWithBlocks(world, start, 42, -26, 3, 46, -26, 7, Blocks.AIR.getDefaultState());
        structure.fillWithBlocks(world, start, 42, -26, 9, 46, -26, 13, Blocks.AIR.getDefaultState());
        structure.fillWithBlocks(world, start, 42, -26, 15, 48, -26, 24, Blocks.AIR.getDefaultState());
        structure.fillWithBlocks(world, start, 42, -26, 26, 46, -26, 30, Blocks.AIR.getDefaultState());
        structure.fillWithBlocks(world, start, 42, -26, 32, 42, -23, 32, Blocks.SANDSTONE.getDefaultState());
        structure.fillWithBlocks(world, start, 42, -26, 33, 42, -26, 34, Blocks.SHROOMLIGHT.getDefaultState());
        structure.fillWithBlocks(world, start, 42, -26, 35, 43, -26, 38, Blocks.SANDSTONE.getDefaultState());
        structure.fillWithBlocks(world, start, 42, -26, 43, 46, -26, 47, Blocks.AIR.getDefaultState());
        structure.fillWithBlocks(world, start, 42, -26, 52, 42, -26, 52, Blocks.SANDSTONE.getDefaultState());
        structure.fillWithBlocks(world, start, 42, -25, -16, 44, -25, -16, Blocks.STONE_BRICKS.getDefaultState());
        structure.fillWithBlocks(world, start, 42, -25, -14, 43, -24, -14, Blocks.STONE_BRICKS.getDefaultState());
        structure.fillWithBlocks(world, start, 42, -25, -13, 42, -25, -12, Blocks.SANDSTONE.getDefaultState());
        structure.fillWithBlocks(world, start, 42, -25, -10, 42, -24, -10, Blocks.AIR.getDefaultState());
        structure.fillWithBlocks(world, start, 42, -25, -8, 46, -25, -4, Blocks.AIR.getDefaultState());
        structure.fillWithBlocks(world, start, 42, -25, -2, 45, -25, 1, Blocks.AIR.getDefaultState());
        structure.fillWithBlocks(world, start, 42, -25, 9, 46, -25, 13, Blocks.AIR.getDefaultState());
        structure.fillWithBlocks(world, start, 42, -25, 15, 42, -25, 19, Blocks.SANDSTONE.getDefaultState());
        structure.fillWithBlocks(world, start, 42, -25, 26, 46, -25, 30, Blocks.AIR.getDefaultState());
        structure.fillWithBlocks(world, start, 42, -25, 33, 42, -22, 37, Blocks.SANDSTONE.getDefaultState());
        structure.fillWithBlocks(world, start, 42, -25, 43, 46, -25, 47, Blocks.AIR.getDefaultState());
        structure.fillWithBlocks(world, start, 42, -25, 49, 42, -22, 53, Blocks.SANDSTONE.getDefaultState());
        structure.fillWithBlocks(world, start, 42, -25, 54, 42, -25, 54, Blocks.SANDSTONE.getDefaultState());
        structure.fillWithBlocks(world, start, 42, -24, -16, 42, -23, -16, Blocks.SANDSTONE.getDefaultState());
