package mod.arcalitegames.odyssey.world.structure.structures.dungeons.masoleum;

import mod.arcalitegames.odyssey.world.structure.StructureBase;
import net.minecraft.block.BarrelBlock;
import net.minecraft.block.Blocks;
import net.minecraft.block.CactusBlock;
import net.minecraft.block.FourWayBlock;
import net.minecraft.block.SlabBlock;
import net.minecraft.block.StairsBlock;
import net.minecraft.state.properties.Half;
import net.minecraft.state.properties.SlabType;
import net.minecraft.state.properties.StairsShape;
import net.minecraft.util.Direction;
import net.minecraft.util.math.BlockPos;
import net.minecraft.world.World;

public class MasoleumComponent2
{

	public static BlockPos start;
    public static World world;
    public static StructureBase structure;

    public static void init(World worldIn, BlockPos blockPos, StructureBase structureIn)
    {
        world = worldIn; start = blockPos; structure = structureIn;
    }
    
    public static void generatePart21()
    {
        structure.fillWithBlocks(world, start, 76, -19, 68, 76, -19, 71, Blocks.SANDSTONE.getDefaultState());
        structure.fillWithBlocks(world, start, 76, -18, 10, 78, -18, 12, Blocks.AIR.getDefaultState());
        structure.fillWithBlocks(world, start, 76, -18, 20, 76, -17, 20, Blocks.STONE_BRICKS.getDefaultState());
        structure.fillWithBlocks(world, start, 76, -18, 22, 76, -17, 22, Blocks.STONE_BRICKS.getDefaultState());
        structure.fillWithBlocks(world, start, 76, -18, 23, 77, -18, 24, Blocks.SANDSTONE.getDefaultState());
        structure.fillWithBlocks(world, start, 76, -18, 26, 80, -18, 30, Blocks.AIR.getDefaultState());
        structure.fillWithBlocks(world, start, 76, -18, 31, 76, -18, 34, Blocks.SANDSTONE.getDefaultState());
        structure.fillWithBlocks(world, start, 76, -18, 38, 76, -17, 38, Blocks.STONE_BRICKS.getDefaultState());
        structure.fillWithBlocks(world, start, 76, -18, 40, 76, -17, 40, Blocks.STONE_BRICKS.getDefaultState());
        structure.fillWithBlocks(world, start, 76, -18, 44, 76, -17, 44, Blocks.STONE_BRICKS.getDefaultState());
        structure.fillWithBlocks(world, start, 76, -18, 46, 76, -17, 47, Blocks.STONE_BRICKS.getDefaultState());
        structure.fillWithBlocks(world, start, 76, -18, 50, 76, -17, 50, Blocks.STONE_BRICKS.getDefaultState());
        structure.fillWithBlocks(world, start, 76, -18, 52, 76, -17, 52, Blocks.STONE_BRICKS.getDefaultState());
        structure.fillWithBlocks(world, start, 76, -18, 56, 76, -17, 56, Blocks.STONE_BRICKS.getDefaultState());
        structure.fillWithBlocks(world, start, 76, -18, 58, 76, -17, 58, Blocks.STONE_BRICKS.getDefaultState());
        structure.fillWithBlocks(world, start, 76, -18, 61, 76, -17, 62, Blocks.SANDSTONE.getDefaultState());
        structure.fillWithBlocks(world, start, 76, -18, 63, 78, -18, 67, Blocks.AIR.getDefaultState());
        structure.fillWithBlocks(world, start, 76, -17, 5, 77, -17, 6, Blocks.SANDSTONE.getDefaultState());
        structure.fillWithBlocks(world, start, 76, -17, 7, 76, -16, 8, Blocks.OAK_PLANKS.getDefaultState());
        structure.fillWithBlocks(world, start, 76, -17, 10, 78, -17, 12, Blocks.AIR.getDefaultState());
        structure.fillWithBlocks(world, start, 76, -17, 14, 76, -16, 15, Blocks.OAK_PLANKS.getDefaultState());
        structure.fillWithBlocks(world, start, 76, -17, 21, 76, -17, 22, Blocks.STONE_BRICKS.getDefaultState());
        structure.fillWithBlocks(world, start, 76, -17, 23, 77, -17, 24, Blocks.SANDSTONE.getDefaultState());
        structure.fillWithBlocks(world, start, 76, -17, 26, 80, -17, 30, Blocks.AIR.getDefaultState());
        structure.fillWithBlocks(world, start, 76, -17, 31, 76, -17, 32, Blocks.SANDSTONE.getDefaultState());
        structure.fillWithBlocks(world, start, 76, -17, 39, 76, -17, 40, Blocks.STONE_BRICKS.getDefaultState());
        structure.fillWithBlocks(world, start, 76, -17, 45, 76, -17, 47, Blocks.STONE_BRICKS.getDefaultState());
        structure.fillWithBlocks(world, start, 76, -17, 51, 76, -17, 52, Blocks.STONE_BRICKS.getDefaultState());
        structure.fillWithBlocks(world, start, 76, -17, 57, 76, -17, 58, Blocks.STONE_BRICKS.getDefaultState());
        structure.fillWithBlocks(world, start, 76, -17, 63, 80, -17, 67, Blocks.AIR.getDefaultState());
        structure.fillWithBlocks(world, start, 76, -17, 68, 76, -17, 71, Blocks.SANDSTONE.getDefaultState());
        structure.fillWithBlocks(world, start, 76, -16, 5, 76, -16, 6, Blocks.AIR.getDefaultState());
        structure.fillWithBlocks(world, start, 76, -16, 10, 76, -16, 13, Blocks.SANDSTONE.getDefaultState());
        structure.fillWithBlocks(world, start, 76, -16, 16, 76, -15, 17, Blocks.SANDSTONE.getDefaultState());
        structure.fillWithBlocks(world, start, 76, -16, 18, 76, -16, 18, Blocks.SANDSTONE.getDefaultState());
        structure.fillWithBlocks(world, start, 76, -16, 22, 78, -16, 24, Blocks.SANDSTONE.getDefaultState());
        structure.fillWithBlocks(world, start, 76, -16, 27, 78, -16, 29, Blocks.AIR.getDefaultState());
        structure.fillWithBlocks(world, start, 76, -16, 30, 76, -16, 34, Blocks.SANDSTONE.getDefaultState());
        structure.fillWithBlocks(world, start, 76, -16, 63, 80, -16, 67, Blocks.AIR.getDefaultState());
        structure.fillWithBlocks(world, start, 76, -16, 68, 76, -16, 71, Blocks.SANDSTONE.getDefaultState());
        structure.fillWithBlocks(world, start, 76, -15, 7, 77, -15, 8, Blocks.OAK_PLANKS.getDefaultState());
        structure.fillWithBlocks(world, start, 76, -15, 9, 76, -15, 15, Blocks.OAK_PLANKS.getDefaultState());
        structure.fillWithBlocks(world, start, 76, -15, 26, 76, -10, 33, Blocks.SANDSTONE.getDefaultState());
        structure.fillWithBlocks(world, start, 76, -15, 61, 78, -15, 63, Blocks.SANDSTONE.getDefaultState());
        structure.fillWithBlocks(world, start, 76, -15, 71, 85, -11, 71, Blocks.SANDSTONE.getDefaultState());
        structure.fillWithBlocks(world, start, 76, -14, 5, 77, -14, 6, Blocks.SANDSTONE.getDefaultState());
        structure.fillWithBlocks(world, start, 76, -14, 7, 76, -14, 17, Blocks.SANDSTONE.getDefaultState());
        structure.fillWithBlocks(world, start, 76, -14, 59, 76, -14, 59, Blocks.SANDSTONE.getDefaultState());
        structure.fillWithBlocks(world, start, 76, -13, 9, 85, -11, 9, Blocks.SANDSTONE.getDefaultState());
        structure.fillWithBlocks(world, start, 76, -13, 10, 77, -13, 10, Blocks.AIR.getDefaultState());
        structure.fillWithBlocks(world, start, 76, -13, 11, 76, -13, 11, Blocks.SANDSTONE.getDefaultState());
        structure.fillWithBlocks(world, start, 76, -13, 13, 80, -13, 17, Blocks.SANDSTONE.getDefaultState());
        structure.fillWithBlocks(world, start, 76, -13, 22, 78, -13, 24, Blocks.SANDSTONE.getDefaultState());
        structure.fillWithBlocks(world, start, 76, -13, 34, 76, -1, 34, Blocks.SANDSTONE.getDefaultState());
        structure.fillWithBlocks(world, start, 76, -13, 65, 77, -13, 66, Blocks.SANDSTONE.getDefaultState());
        structure.fillWithBlocks(world, start, 76, -13, 67, 76, -11, 67, Blocks.SANDSTONE.getDefaultState());
        structure.fillWithBlocks(world, start, 76, -13, 68, 77, -13, 68, Blocks.AIR.getDefaultState());
        structure.fillWithBlocks(world, start, 76, -13, 69, 78, -13, 71, Blocks.SANDSTONE.getDefaultState());
        structure.fillWithBlocks(world, start, 76, -12, 22, 82, -12, 34, Blocks.SANDSTONE.getDefaultState());
        structure.fillWithBlocks(world, start, 76, -12, 59, 76, -12, 59, Blocks.SANDSTONE.getDefaultState());
        structure.fillWithBlocks(world, start, 76, -12, 60, 76, -12, 61, Blocks.AIR.getDefaultState());
        structure.fillWithBlocks(world, start, 76, -12, 63, 77, -12, 64, Blocks.SANDSTONE.getDefaultState());
        structure.fillWithBlocks(world, start, 76, -11, 24, 80, -11, 34, Blocks.SANDSTONE.getDefaultState());
        structure.fillWithBlocks(world, start, 76, -11, 59, 76, -11, 60, Blocks.SANDSTONE.getDefaultState());
        structure.fillWithBlocks(world, start, 76, -11, 63, 78, -11, 65, Blocks.SANDSTONE.getDefaultState());
        structure.fillWithBlocks(world, start, 76, -11, 66, 76, -11, 71, Blocks.SANDSTONE.getDefaultState());
        structure.fillWithBlocks(world, start, 76, -10, 22, 76, -8, 24, Blocks.SANDSTONE.getDefaultState());
        structure.fillWithBlocks(world, start, 76, -10, 25, 76, -9, 25, Blocks.AIR.getDefaultState());
        structure.fillWithBlocks(world, start, 76, -9, 26, 78, -7, 26, Blocks.SANDSTONE.getDefaultState());
        structure.fillWithBlocks(world, start, 76, -9, 27, 78, -9, 29, Blocks.AIR.getDefaultState());
        structure.fillWithBlocks(world, start, 76, -9, 30, 78, -9, 34, Blocks.SANDSTONE.getDefaultState());
        structure.fillWithBlocks(world, start, 76, -8, 27, 78, -8, 29, Blocks.AIR.getDefaultState());
        structure.fillWithBlocks(world, start, 76, -8, 30, 78, -8, 33, Blocks.SANDSTONE.getDefaultState());
        structure.fillWithBlocks(world, start, 76, -7, 27, 78, -7, 29, Blocks.AIR.getDefaultState());
        structure.fillWithBlocks(world, start, 76, -7, 30, 78, -7, 34, Blocks.SANDSTONE.getDefaultState());
        structure.fillWithBlocks(world, start, 76, -6, 22, 78, -6, 22, Blocks.SANDSTONE.getDefaultState());
        structure.fillWithBlocks(world, start, 76, -6, 23, 76, -6, 24, Blocks.AIR.getDefaultState());
        structure.fillWithBlocks(world, start, 76, -6, 25, 76, -2, 29, Blocks.SANDSTONE.getDefaultState());
        structure.fillWithBlocks(world, start, 76, -6, 30, 78, -6, 34, Blocks.SANDSTONE.getDefaultState());
        structure.fillWithBlocks(world, start, 76, -5, 23, 78, -5, 25, Blocks.SANDSTONE.getDefaultState());
        structure.fillWithBlocks(world, start, 76, -4, 22, 76, -4, 22, Blocks.SANDSTONE.getDefaultState());
        structure.fillWithBlocks(world, start, 76, -4, 23, 76, -3, 23, Blocks.AIR.getDefaultState());
        structure.fillWithBlocks(world, start, 76, -4, 24, 78, -4, 34, Blocks.SANDSTONE.getDefaultState());
        structure.fillWithBlocks(world, start, 76, -3, 22, 78, -1, 22, Blocks.SANDSTONE.getDefaultState());
        structure.fillWithBlocks(world, start, 76, -3, 24, 78, -3, 34, Blocks.SANDSTONE.getDefaultState());
        structure.fillWithBlocks(world, start, 76, -2, 30, 76, -2, 31, Blocks.AIR.getDefaultState());
        structure.fillWithBlocks(world, start, 76, -2, 32, 78, -2, 34, Blocks.SANDSTONE.getDefaultState());
        structure.fillWithBlocks(world, start, 76, -1, 30, 76, -1, 34, Blocks.SANDSTONE.getDefaultState());
        structure.fillWithBlocks(world, start, 76, 1, 146, 78, 1, 148, Blocks.STONE.getDefaultState());
        structure.fillWithBlocks(world, start, 76, 1, 149, 84, 1, 161, Blocks.SANDSTONE.getDefaultState());
        structure.fillWithBlocks(world, start, 76, 7, 20, 112, 7, 56, Blocks.SANDSTONE.getDefaultState());
        structure.fillWithBlocks(world, start, 76, 7, 57, 102, 7, 136, Blocks.SANDSTONE.getDefaultState());
        structure.fillWithBlocks(world, start, 76, 8, 20, 111, 8, 55, Blocks.SAND.getDefaultState());
        structure.fillWithBlocks(world, start, 76, 8, 56, 101, 8, 136, Blocks.SAND.getDefaultState());
        structure.fillWithBlocks(world, start, 76, 9, 44, 76, 10, 44, Blocks.SAND.getDefaultState());
        structure.fillWithBlocks(world, start, 76, 9, 45, 77, 9, 46, Blocks.SANDSTONE.getDefaultState());
        structure.fillWithBlocks(world, start, 76, 9, 47, 76, 9, 51, Blocks.STONE.getDefaultState());
        structure.fillWithBlocks(world, start, 76, 9, 70, 83, 9, 77, Blocks.SANDSTONE.getDefaultState());
        structure.fillWithBlocks(world, start, 76, 9, 78, 76, 10, 79, Blocks.SANDSTONE.getDefaultState());
        structure.fillWithBlocks(world, start, 76, 10, 45, 77, 10, 46, Blocks.SANDSTONE.getDefaultState());
        structure.fillWithBlocks(world, start, 76, 10, 47, 76, 10, 51, Blocks.STONE.getDefaultState());
        structure.fillWithBlocks(world, start, 76, 10, 70, 83, 10, 77, Blocks.SANDSTONE.getDefaultState());
        structure.fillWithBlocks(world, start, 76, 11, 45, 77, 11, 46, Blocks.SANDSTONE.getDefaultState());
        structure.fillWithBlocks(world, start, 76, 11, 47, 76, 11, 51, Blocks.STONE.getDefaultState());
        structure.fillWithBlocks(world, start, 76, 11, 70, 83, 11, 77, Blocks.SANDSTONE.getDefaultState());
        structure.fillWithBlocks(world, start, 76, 11, 78, 76, 11, 78, Blocks.SANDSTONE.getDefaultState());
        structure.fillWithBlocks(world, start, 76, 12, 45, 77, 12, 46, Blocks.SANDSTONE.getDefaultState());
        structure.fillWithBlocks(world, start, 76, 12, 47, 76, 12, 51, Blocks.STONE.getDefaultState());
        structure.fillWithBlocks(world, start, 76, 12, 70, 83, 12, 77, Blocks.SANDSTONE.getDefaultState());
        structure.fillWithBlocks(world, start, 76, 12, 78, 82, 18, 78, Blocks.SANDSTONE.getDefaultState());
        structure.fillWithBlocks(world, start, 76, 12, 91, 76, 14, 94, Blocks.SANDSTONE.getDefaultState());
        structure.fillWithBlocks(world, start, 76, 12, 99, 77, 12, 101, Blocks.SAND.getDefaultState());
        structure.fillWithBlocks(world, start, 76, 12, 103, 76, 12, 125, Blocks.SANDSTONE.getDefaultState());
        structure.fillWithBlocks(world, start, 76, 12, 126, 88, 12, 126, Blocks.SAND.getDefaultState());
        structure.fillWithBlocks(world, start, 76, 13, 45, 77, 13, 46, Blocks.SANDSTONE.getDefaultState());
        structure.fillWithBlocks(world, start, 76, 13, 47, 76, 13, 51, Blocks.STONE.getDefaultState());
        structure.fillWithBlocks(world, start, 76, 13, 122, 78, 13, 124, Blocks.SANDSTONE.getDefaultState());
        structure.fillWithBlocks(world, start, 76, 13, 125, 76, 14, 126, Blocks.SAND.getDefaultState());
        structure.fillWithBlocks(world, start, 76, 14, 47, 76, 14, 51, Blocks.STONE.getDefaultState());
        structure.fillWithBlocks(world, start, 76, 14, 90, 76, 15, 93, Blocks.SANDSTONE.getDefaultState());
        structure.fillWithBlocks(world, start, 76, 14, 95, 76, 15, 98, Blocks.SAND.getDefaultState());
        structure.fillWithBlocks(world, start, 76, 14, 99, 76, 14, 108, Blocks.SAND.getDefaultState());
        structure.fillWithBlocks(world, start, 76, 15, 47, 76, 15, 51, Blocks.STONE.getDefaultState());
        structure.fillWithBlocks(world, start, 76, 15, 87, 76, 15, 93, Blocks.SANDSTONE.getDefaultState());
        structure.fillWithBlocks(world, start, 76, 15, 102, 76, 15, 125, Blocks.SAND.getDefaultState());
        structure.fillWithBlocks(world, start, 76, 16, 45, 77, 16, 46, Blocks.SANDSTONE.getDefaultState());
        structure.fillWithBlocks(world, start, 76, 16, 47, 76, 16, 50, Blocks.STONE.getDefaultState());
        structure.fillWithBlocks(world, start, 76, 16, 51, 76, 17, 51, Blocks.ANDESITE.getDefaultState());
        structure.fillWithBlocks(world, start, 76, 16, 85, 76, 16, 91, Blocks.SANDSTONE.getDefaultState());
        structure.fillWithBlocks(world, start, 76, 16, 92, 76, 17, 94, Blocks.SAND.getDefaultState());
        structure.fillWithBlocks(world, start, 76, 16, 122, 78, 16, 124, Blocks.SAND.getDefaultState());
        structure.fillWithBlocks(world, start, 76, 17, 45, 77, 17, 46, Blocks.SANDSTONE.getDefaultState());
        structure.fillWithBlocks(world, start, 76, 17, 47, 76, 17, 50, Blocks.STONE.getDefaultState());
        structure.fillWithBlocks(world, start, 76, 17, 85, 79, 17, 88, Blocks.SANDSTONE.getDefaultState());
        structure.fillWithBlocks(world, start, 76, 17, 91, 76, 18, 93, Blocks.SAND.getDefaultState());
        structure.fillWithBlocks(world, start, 76, 18, 45, 76, 18, 45, Blocks.SANDSTONE.getDefaultState());
        structure.fillWithBlocks(world, start, 76, 18, 46, 76, 21, 46, Blocks.SAND.getDefaultState());
        structure.fillWithBlocks(world, start, 76, 18, 47, 76, 19, 49, Blocks.SANDSTONE.getDefaultState());
        structure.fillWithBlocks(world, start, 76, 18, 50, 76, 18, 51, Blocks.STONE.getDefaultState());
        structure.fillWithBlocks(world, start, 76, 18, 85, 79, 18, 88, Blocks.SANDSTONE.getDefaultState());
        structure.fillWithBlocks(world, start, 76, 19, 45, 77, 19, 46, Blocks.SAND.getDefaultState());
        structure.fillWithBlocks(world, start, 76, 19, 50, 76, 20, 50, Blocks.SANDSTONE.getDefaultState());
        structure.fillWithBlocks(world, start, 76, 19, 51, 76, 20, 51, Blocks.STONE.getDefaultState());
        structure.fillWithBlocks(world, start, 76, 19, 75, 79, 19, 78, Blocks.SANDSTONE.getDefaultState());
        structure.fillWithBlocks(world, start, 76, 19, 85, 78, 19, 88, Blocks.SANDSTONE.getDefaultState());
        structure.fillWithBlocks(world, start, 76, 19, 89, 77, 19, 90, Blocks.SAND.getDefaultState());
        structure.fillWithBlocks(world, start, 76, 20, 45, 78, 20, 47, Blocks.SAND.getDefaultState());
        structure.fillWithBlocks(world, start, 76, 20, 48, 76, 20, 49, Blocks.SAND.getDefaultState());
        structure.fillWithBlocks(world, start, 76, 20, 79, 107, 42, 79, Blocks.SANDSTONE.getDefaultState());
        structure.fillWithBlocks(world, start, 76, 20, 84, 79, 20, 87, Blocks.SANDSTONE.getDefaultState());
        structure.fillWithBlocks(world, start, 76, 20, 89, 76, 20, 90, Blocks.SAND.getDefaultState());
        structure.fillWithBlocks(world, start, 76, 21, 45, 78, 21, 47, Blocks.SAND.getDefaultState());
        structure.fillWithBlocks(world, start, 76, 21, 51, 79, 21, 79, Blocks.SANDSTONE.getDefaultState());
        structure.fillWithBlocks(world, start, 76, 21, 83, 80, 21, 87, Blocks.SANDSTONE.getDefaultState());
        structure.fillWithBlocks(world, start, 76, 22, 47, 78, 23, 47, Blocks.SAND.getDefaultState());
        structure.fillWithBlocks(world, start, 76, 22, 51, 79, 22, 87, Blocks.SANDSTONE.getDefaultState());
        structure.fillWithBlocks(world, start, 76, 22, 88, 77, 23, 88, Blocks.SAND.getDefaultState());
        structure.fillWithBlocks(world, start, 76, 24, 80, 82, 24, 86, Blocks.SANDSTONE.getDefaultState());
        structure.fillWithBlocks(world, start, 76, 25, 80, 81, 25, 86, Blocks.SANDSTONE.getDefaultState());
        structure.fillWithBlocks(world, start, 76, 26, 80, 81, 26, 85, Blocks.SANDSTONE.getDefaultState());
        structure.fillWithBlocks(world, start, 76, 27, 80, 81, 27, 85, Blocks.SANDSTONE.getDefaultState());
        structure.fillWithBlocks(world, start, 76, 28, 51, 79, 28, 86, Blocks.SANDSTONE.getDefaultState());
        structure.fillWithBlocks(world, start, 76, 29, 51, 79, 29, 85, Blocks.SANDSTONE.getDefaultState());
        structure.fillWithBlocks(world, start, 76, 30, 51, 79, 30, 85, Blocks.SANDSTONE.getDefaultState());
        structure.fillWithBlocks(world, start, 76, 31, 50, 79, 31, 85, Blocks.SANDSTONE.getDefaultState());
        structure.fillWithBlocks(world, start, 76, 32, 48, 79, 32, 85, Blocks.SANDSTONE.getDefaultState());
        structure.fillWithBlocks(world, start, 76, 33, 48, 79, 33, 85, Blocks.SANDSTONE.getDefaultState());
        structure.fillWithBlocks(world, start, 76, 34, 48, 78, 34, 85, Blocks.SANDSTONE.getDefaultState());
        structure.fillWithBlocks(world, start, 76, 34, 86, 77, 35, 86, Blocks.SAND.getDefaultState());
        structure.fillWithBlocks(world, start, 76, 35, 48, 78, 37, 48, Blocks.SAND.getDefaultState());
        structure.fillWithBlocks(world, start, 76, 35, 49, 79, 35, 85, Blocks.SANDSTONE.getDefaultState());
        structure.fillWithBlocks(world, start, 76, 36, 49, 79, 36, 85, Blocks.SANDSTONE.getDefaultState());
        structure.fillWithBlocks(world, start, 76, 37, 49, 78, 37, 85, Blocks.SANDSTONE.getDefaultState());
        structure.fillWithBlocks(world, start, 76, 38, 49, 77, 38, 85, Blocks.SANDSTONE.getDefaultState());
        structure.fillWithBlocks(world, start, 76, 39, 49, 78, 39, 51, Blocks.SAND.getDefaultState());
        structure.fillWithBlocks(world, start, 76, 39, 52, 81, 39, 57, Blocks.SANDSTONE.getDefaultState());
        structure.fillWithBlocks(world, start, 76, 39, 58, 76, 40, 59, Blocks.SAND.getDefaultState());
        structure.fillWithBlocks(world, start, 76, 39, 61, 86, 39, 81, Blocks.SANDSTONE.getDefaultState());
        structure.fillWithBlocks(world, start, 76, 39, 85, 76, 42, 85, Blocks.SAND.getDefaultState());
        structure.fillWithBlocks(world, start, 76, 40, 53, 76, 42, 53, Blocks.SAND.getDefaultState());
        structure.fillWithBlocks(world, start, 76, 40, 54, 79, 40, 57, Blocks.SANDSTONE.getDefaultState());
        structure.fillWithBlocks(world, start, 76, 40, 61, 76, 40, 61, Blocks.SAND.getDefaultState());
        structure.fillWithBlocks(world, start, 76, 40, 65, 76, 40, 70, Blocks.SAND.getDefaultState());
        structure.fillWithBlocks(world, start, 76, 40, 71, 86, 40, 81, Blocks.SANDSTONE.getDefaultState());
        structure.fillWithBlocks(world, start, 76, 41, 54, 76, 42, 55, Blocks.SAND.getDefaultState());
        structure.fillWithBlocks(world, start, 76, 41, 56, 77, 41, 57, Blocks.SANDSTONE.getDefaultState());
        structure.fillWithBlocks(world, start, 76, 41, 66, 77, 41, 72, Blocks.SAND.getDefaultState());
        structure.fillWithBlocks(world, start, 76, 41, 75, 82, 41, 81, Blocks.SANDSTONE.getDefaultState());
        structure.fillWithBlocks(world, start, 76, 41, 84, 77, 41, 85, Blocks.SAND.getDefaultState());
        structure.fillWithBlocks(world, start, 76, 42, 57, 76, 44, 57, Blocks.SAND.getDefaultState());
        structure.fillWithBlocks(world, start, 76, 42, 66, 79, 42, 69, Blocks.SAND.getDefaultState());
        structure.fillWithBlocks(world, start, 76, 42, 76, 76, 44, 76, Blocks.SAND.getDefaultState());
        structure.fillWithBlocks(world, start, 76, 42, 77, 80, 42, 81, Blocks.SANDSTONE.getDefaultState());
        structure.fillWithBlocks(world, start, 76, 42, 82, 78, 42, 84, Blocks.SAND.getDefaultState());
        structure.fillWithBlocks(world, start, 76, 43, 54, 78, 43, 56, Blocks.SAND.getDefaultState());
        structure.fillWithBlocks(world, start, 76, 43, 71, 78, 43, 75, Blocks.SAND.getDefaultState());
        structure.fillWithBlocks(world, start, 76, 44, 56, 77, 44, 57, Blocks.SAND.getDefaultState());
        structure.fillWithBlocks(world, start, 76, 44, 75, 78, 44, 82, Blocks.SAND.getDefaultState());
        structure.fillWithBlocks(world, start, 76, 45, 77, 79, 45, 81, Blocks.SAND.getDefaultState());
        structure.fillWithBlocks(world, start, 77, -52, 12, 77, -52, 12, Blocks.SANDSTONE.getDefaultState());
        structure.fillWithBlocks(world, start, 77, -52, 17, 80, -52, 20, Blocks.SANDSTONE.getDefaultState());
        structure.fillWithBlocks(world, start, 77, -51, 11, 77, -50, 11, Blocks.SANDSTONE.getDefaultState());
        structure.fillWithBlocks(world, start, 77, -51, 17, 80, -51, 20, Blocks.SANDSTONE.getDefaultState());
        structure.fillWithBlocks(world, start, 77, -49, 9, 78, -49, 10, Blocks.AIR.getDefaultState());
        structure.fillWithBlocks(world, start, 77, -49, 12, 78, -49, 27, Blocks.AIR.getDefaultState());
        structure.fillWithBlocks(world, start, 77, -49, 29, 78, -49, 60, Blocks.AIR.getDefaultState());
        structure.fillWithBlocks(world, start, 77, -49, 62, 81, -49, 68, Blocks.AIR.getDefaultState());
        structure.fillWithBlocks(world, start, 77, -49, 70, 79, -49, 72, Blocks.SANDSTONE.getDefaultState());
        structure.fillWithBlocks(world, start, 77, -48, 9, 78, -48, 10, Blocks.AIR.getDefaultState());
        structure.fillWithBlocks(world, start, 77, -48, 12, 78, -48, 69, Blocks.AIR.getDefaultState());
        structure.fillWithBlocks(world, start, 77, -48, 71, 78, -48, 72, Blocks.SANDSTONE.getDefaultState());
        structure.fillWithBlocks(world, start, 77, -47, 70, 79, -47, 72, Blocks.SANDSTONE.getDefaultState());
        structure.fillWithBlocks(world, start, 77, -45, 5, 82, -45, 10, Blocks.SANDSTONE.getDefaultState());
        structure.fillWithBlocks(world, start, 77, -45, 12, 83, -45, 19, Blocks.SANDSTONE.getDefaultState());
        structure.fillWithBlocks(world, start, 77, -45, 21, 79, -45, 23, Blocks.SANDSTONE.getDefaultState());
        structure.fillWithBlocks(world, start, 77, -45, 25, 79, -45, 27, Blocks.SANDSTONE.getDefaultState());
        structure.fillWithBlocks(world, start, 77, -45, 29, 79, -45, 31, Blocks.SANDSTONE.getDefaultState());
        structure.fillWithBlocks(world, start, 77, -45, 33, 79, -45, 35, Blocks.SANDSTONE.getDefaultState());
        structure.fillWithBlocks(world, start, 77, -45, 37, 78, -45, 38, Blocks.SANDSTONE.getDefaultState());
        structure.fillWithBlocks(world, start, 77, -44, 23, 77, -44, 23, Blocks.AIR.getDefaultState());
        structure.fillWithBlocks(world, start, 77, -44, 24, 77, -41, 24, Blocks.SANDSTONE.getDefaultState());
        structure.fillWithBlocks(world, start, 77, -44, 25, 78, -44, 25, Blocks.AIR.getDefaultState());
        structure.fillWithBlocks(world, start, 77, -44, 27, 77, -43, 28, Blocks.SANDSTONE.getDefaultState());
        structure.fillWithBlocks(world, start, 77, -44, 29, 78, -44, 29, Blocks.AIR.getDefaultState());
        structure.fillWithBlocks(world, start, 77, -44, 31, 77, -44, 31, Blocks.SHROOMLIGHT.getDefaultState());
        structure.fillWithBlocks(world, start, 77, -44, 32, 77, -41, 32, Blocks.SANDSTONE.getDefaultState());
        structure.fillWithBlocks(world, start, 77, -44, 33, 78, -44, 33, Blocks.SHROOMLIGHT.getDefaultState());
        structure.fillWithBlocks(world, start, 77, -42, 71, 77, -41, 72, Blocks.SANDSTONE.getDefaultState());
        structure.fillWithBlocks(world, start, 77, -40, -10, 77, -40, -3, Blocks.STONE_BRICKS.getDefaultState());
        structure.fillWithBlocks(world, start, 77, -40, -1, 87, -40, 9, Blocks.STONE_BRICKS.getDefaultState());
        structure.fillWithBlocks(world, start, 77, -40, 32, 77, -40, 35, Blocks.STONE_BRICKS.getDefaultState());
        structure.fillWithBlocks(world, start, 77, -40, 40, 98, -40, 40, Blocks.STONE_BRICKS.getDefaultState());
        structure.fillWithBlocks(world, start, 77, -40, 41, 77, -40, 41, Blocks.AIR.getDefaultState());
        structure.fillWithBlocks(world, start, 77, -40, 42, 77, -40, 47, Blocks.STONE_BRICKS.getDefaultState());
        structure.fillWithBlocks(world, start, 77, -40, 49, 80, -40, 52, Blocks.STONE_BRICKS.getDefaultState());
        structure.fillWithBlocks(world, start, 77, -40, 54, 78, -40, 56, Blocks.STONE_BRICKS.getDefaultState());
        structure.fillWithBlocks(world, start, 77, -40, 61, 77, -40, 62, Blocks.STONE_BRICKS.getDefaultState());
        structure.fillWithBlocks(world, start, 77, -40, 63, 79, -40, 63, Blocks.AIR.getDefaultState());
        structure.fillWithBlocks(world, start, 77, -40, 64, 79, -38, 64, Blocks.STONE_BRICKS.getDefaultState());
        structure.fillWithBlocks(world, start, 77, -40, 74, 78, -40, 75, Blocks.STONE_BRICKS.getDefaultState());
        structure.fillWithBlocks(world, start, 77, -39, -10, 78, -39, -8, Blocks.STONE_BRICKS.getDefaultState());
        structure.fillWithBlocks(world, start, 77, -39, -6, 78, -39, -5, Blocks.STONE_BRICKS.getDefaultState());
        structure.fillWithBlocks(world, start, 77, -39, -4, 77, -39, -4, Blocks.AIR.getDefaultState());
        structure.fillWithBlocks(world, start, 77, -39, -3, 77, -39, 3, Blocks.STONE_BRICKS.getDefaultState());
        structure.fillWithBlocks(world, start, 77, -39, 4, 81, -39, 8, Blocks.AIR.getDefaultState());
        structure.fillWithBlocks(world, start, 77, -39, 9, 78, -39, 10, Blocks.STONE_BRICKS.getDefaultState());
        structure.fillWithBlocks(world, start, 77, -39, 30, 77, -39, 30, Blocks.STONE_BRICKS.getDefaultState());
        structure.fillWithBlocks(world, start, 77, -39, 32, 77, -39, 33, Blocks.STONE_BRICKS.getDefaultState());
        structure.fillWithBlocks(world, start, 77, -39, 34, 77, -38, 34, Blocks.AIR.getDefaultState());
        structure.fillWithBlocks(world, start, 77, -39, 35, 79, -37, 35, Blocks.STONE_BRICKS.getDefaultState());
        structure.fillWithBlocks(world, start, 77, -39, 39, 77, -37, 39, Blocks.STONE_BRICKS.getDefaultState());
        structure.fillWithBlocks(world, start, 77, -39, 40, 78, -39, 40, Blocks.AIR.getDefaultState());
        structure.fillWithBlocks(world, start, 77, -39, 43, 78, -39, 43, Blocks.AIR.getDefaultState());
        structure.fillWithBlocks(world, start, 77, -39, 44, 78, -39, 52, Blocks.STONE_BRICKS.getDefaultState());
        structure.fillWithBlocks(world, start, 77, -39, 60, 77, -39, 60, Blocks.AIR.getDefaultState());
        structure.fillWithBlocks(world, start, 77, -39, 61, 77, -39, 64, Blocks.STONE_BRICKS.getDefaultState());
        structure.fillWithBlocks(world, start, 77, -39, 69, 78, -39, 74, Blocks.STONE_BRICKS.getDefaultState());
        structure.fillWithBlocks(world, start, 77, -39, 76, 78, -39, 80, Blocks.STONE_BRICKS.getDefaultState());
        structure.fillWithBlocks(world, start, 77, -38, -7, 77, -38, -7, Blocks.STONE_BRICKS.getDefaultState());
        structure.fillWithBlocks(world, start, 77, -38, 9, 78, -38, 10, Blocks.STONE_BRICKS.getDefaultState());
        structure.fillWithBlocks(world, start, 77, -38, 19, 78, -38, 23, Blocks.STONE_BRICKS.getDefaultState());
        structure.fillWithBlocks(world, start, 77, -38, 40, 77, -38, 40, Blocks.STONE_BRICKS.getDefaultState());
        structure.fillWithBlocks(world, start, 77, -38, 45, 77, -38, 45, Blocks.STONE_BRICKS.getDefaultState());
        structure.fillWithBlocks(world, start, 77, -38, 47, 77, -38, 47, Blocks.STONE_BRICKS.getDefaultState());
        structure.fillWithBlocks(world, start, 77, -38, 49, 77, -36, 60, Blocks.STONE_BRICKS.getDefaultState());
        structure.fillWithBlocks(world, start, 77, -38, 62, 79, -37, 62, Blocks.STONE_BRICKS.getDefaultState());
        structure.fillWithBlocks(world, start, 77, -38, 63, 78, -37, 63, Blocks.AIR.getDefaultState());
        structure.fillWithBlocks(world, start, 77, -38, 66, 77, -38, 66, Blocks.STONE_BRICKS.getDefaultState());
        structure.fillWithBlocks(world, start, 77, -38, 68, 77, -37, 80, Blocks.STONE_BRICKS.getDefaultState());
        structure.fillWithBlocks(world, start, 77, -37, -10, 77, -35, -8, Blocks.STONE_BRICKS.getDefaultState());
        structure.fillWithBlocks(world, start, 77, -37, -6, 77, -37, -6, Blocks.STONE_BRICKS.getDefaultState());
        structure.fillWithBlocks(world, start, 77, -37, -5, 77, -37, -4, Blocks.AIR.getDefaultState());
        structure.fillWithBlocks(world, start, 77, -37, -3, 77, -31, -3, Blocks.STONE_BRICKS.getDefaultState());
        structure.fillWithBlocks(world, start, 77, -37, 9, 78, -37, 10, Blocks.STONE_BRICKS.getDefaultState());
        structure.fillWithBlocks(world, start, 77, -37, 34, 77, -37, 35, Blocks.STONE_BRICKS.getDefaultState());
        structure.fillWithBlocks(world, start, 77, -37, 40, 78, -37, 41, Blocks.STONE_BRICKS.getDefaultState());
        structure.fillWithBlocks(world, start, 77, -37, 42, 77, -37, 43, Blocks.AIR.getDefaultState());
        structure.fillWithBlocks(world, start, 77, -37, 44, 77, -37, 62, Blocks.STONE_BRICKS.getDefaultState());
        structure.fillWithBlocks(world, start, 77, -37, 64, 79, -36, 64, Blocks.STONE_BRICKS.getDefaultState());
        structure.fillWithBlocks(world, start, 77, -36, -7, 77, -36, -7, Blocks.STONE_BRICKS.getDefaultState());
        structure.fillWithBlocks(world, start, 77, -36, -6, 77, -36, -6, Blocks.AIR.getDefaultState());
        structure.fillWithBlocks(world, start, 77, -36, -5, 77, -36, -3, Blocks.STONE_BRICKS.getDefaultState());
        structure.fillWithBlocks(world, start, 77, -36, 0, 78, -36, 0, Blocks.SHROOMLIGHT.getDefaultState());
        structure.fillWithBlocks(world, start, 77, -36, 1, 78, -35, 1, Blocks.STONE_BRICKS.getDefaultState());
        structure.fillWithBlocks(world, start, 77, -36, 2, 78, -36, 2, Blocks.SHROOMLIGHT.getDefaultState());
        structure.fillWithBlocks(world, start, 77, -36, 9, 78, -36, 10, Blocks.STONE_BRICKS.getDefaultState());
        structure.fillWithBlocks(world, start, 77, -36, 34, 78, -36, 35, Blocks.STONE_BRICKS.getDefaultState());
        structure.fillWithBlocks(world, start, 77, -36, 39, 77, -36, 40, Blocks.AIR.getDefaultState());
        structure.fillWithBlocks(world, start, 77, -36, 41, 78, -36, 47, Blocks.STONE_BRICKS.getDefaultState());
        structure.fillWithBlocks(world, start, 77, -36, 66, 77, -35, 67, Blocks.STONE_BRICKS.getDefaultState());
        structure.fillWithBlocks(world, start, 77, -36, 69, 78, -36, 72, Blocks.STONE_BRICKS.getDefaultState());
        structure.fillWithBlocks(world, start, 77, -36, 74, 78, -36, 80, Blocks.STONE_BRICKS.getDefaultState());
        structure.fillWithBlocks(world, start, 77, -35, -7, 77, -35, -7, Blocks.AIR.getDefaultState());
        structure.fillWithBlocks(world, start, 77, -35, -6, 77, -35, -1, Blocks.STONE_BRICKS.getDefaultState());
        structure.fillWithBlocks(world, start, 77, -35, 24, 77, -34, 29, Blocks.STONE_BRICKS.getDefaultState());
        structure.fillWithBlocks(world, start, 77, -35, 31, 77, -33, 35, Blocks.STONE_BRICKS.getDefaultState());
        structure.fillWithBlocks(world, start, 77, -35, 39, 77, -34, 40, Blocks.STONE_BRICKS.getDefaultState());
        structure.fillWithBlocks(world, start, 77, -35, 41, 77, -35, 42, Blocks.AIR.getDefaultState());
        structure.fillWithBlocks(world, start, 77, -35, 46, 78, -35, 46, Blocks.AIR.getDefaultState());
        structure.fillWithBlocks(world, start, 77, -35, 47, 78, -35, 48, Blocks.STONE_BRICKS.getDefaultState());
        structure.fillWithBlocks(world, start, 77, -35, 49, 77, -34, 49, Blocks.AIR.getDefaultState());
        structure.fillWithBlocks(world, start, 77, -35, 50, 77, -35, 50, Blocks.STONE_BRICKS.getDefaultState());
        structure.fillWithBlocks(world, start, 77, -35, 56, 77, -35, 57, Blocks.STONE_BRICKS.getDefaultState());
        structure.fillWithBlocks(world, start, 77, -35, 59, 77, -35, 62, Blocks.STONE_BRICKS.getDefaultState());
        structure.fillWithBlocks(world, start, 77, -35, 68, 78, -35, 69, Blocks.STONE_BRICKS.getDefaultState());
        structure.fillWithBlocks(world, start, 77, -35, 71, 77, -35, 71, Blocks.STONE_BRICKS.getDefaultState());
        structure.fillWithBlocks(world, start, 77, -35, 73, 78, -35, 74, Blocks.STONE_BRICKS.getDefaultState());
        structure.fillWithBlocks(world, start, 77, -35, 76, 78, -35, 77, Blocks.STONE_BRICKS.getDefaultState());
        structure.fillWithBlocks(world, start, 77, -34, -10, 77, -31, -10, Blocks.STONE_BRICKS.getDefaultState());
        structure.fillWithBlocks(world, start, 77, -34, -8, 78, -34, -2, Blocks.STONE_BRICKS.getDefaultState());
        structure.fillWithBlocks(world, start, 77, -34, -1, 77, -34, 0, Blocks.AIR.getDefaultState());
        structure.fillWithBlocks(world, start, 77, -34, 1, 79, -34, 4, Blocks.STONE_BRICKS.getDefaultState());
        structure.fillWithBlocks(world, start, 77, -34, 44, 77, -34, 46, Blocks.STONE_BRICKS.getDefaultState());
        structure.fillWithBlocks(world, start, 77, -34, 48, 77, -34, 48, Blocks.STONE_BRICKS.getDefaultState());
        structure.fillWithBlocks(world, start, 77, -34, 54, 79, -34, 58, Blocks.STONE_BRICKS.getDefaultState());
        structure.fillWithBlocks(world, start, 77, -34, 60, 78, -34, 62, Blocks.STONE_BRICKS.getDefaultState());
        structure.fillWithBlocks(world, start, 77, -34, 66, 77, -34, 66, Blocks.STONE_BRICKS.getDefaultState());
        structure.fillWithBlocks(world, start, 77, -34, 67, 77, -34, 68, Blocks.AIR.getDefaultState());
        structure.fillWithBlocks(world, start, 77, -34, 69, 81, -34, 75, Blocks.STONE_BRICKS.getDefaultState());
        structure.fillWithBlocks(world, start, 77, -34, 76, 77, -33, 76, Blocks.AIR.getDefaultState());
        structure.fillWithBlocks(world, start, 77, -34, 77, 80, -34, 80, Blocks.STONE_BRICKS.getDefaultState());
        structure.fillWithBlocks(world, start, 77, -33, 1, 77, -33, 1, Blocks.AIR.getDefaultState());
        structure.fillWithBlocks(world, start, 77, -33, 2, 77, -31, 2, Blocks.STONE_BRICKS.getDefaultState());
        structure.fillWithBlocks(world, start, 77, -33, 3, 78, -33, 3, Blocks.AIR.getDefaultState());
        structure.fillWithBlocks(world, start, 77, -33, 4, 77, -33, 4, Blocks.STONE_BRICKS.getDefaultState());
        structure.fillWithBlocks(world, start, 77, -33, 6, 78, -33, 10, Blocks.STONE_BRICKS.getDefaultState());
        structure.fillWithBlocks(world, start, 77, -33, 27, 78, -33, 35, Blocks.STONE_BRICKS.getDefaultState());
        structure.fillWithBlocks(world, start, 77, -33, 39, 78, -33, 40, Blocks.STONE_BRICKS.getDefaultState());
        structure.fillWithBlocks(world, start, 77, -33, 42, 79, -33, 44, Blocks.STONE_BRICKS.getDefaultState());
        structure.fillWithBlocks(world, start, 77, -33, 47, 77, -33, 47, Blocks.STONE_BRICKS.getDefaultState());
        structure.fillWithBlocks(world, start, 77, -33, 48, 77, -33, 48, Blocks.AIR.getDefaultState());
        structure.fillWithBlocks(world, start, 77, -33, 49, 77, -33, 62, Blocks.STONE_BRICKS.getDefaultState());
        structure.fillWithBlocks(world, start, 77, -33, 66, 79, -33, 71, Blocks.STONE_BRICKS.getDefaultState());
        structure.fillWithBlocks(world, start, 77, -33, 72, 77, -33, 75, Blocks.STONE_BRICKS.getDefaultState());
        structure.fillWithBlocks(world, start, 77, -33, 77, 80, -33, 80, Blocks.STONE_BRICKS.getDefaultState());
        structure.fillWithBlocks(world, start, 77, -32, -9, 77, -32, -9, Blocks.AIR.getDefaultState());
        structure.fillWithBlocks(world, start, 77, -32, -8, 77, -32, 2, Blocks.STONE_BRICKS.getDefaultState());
        structure.fillWithBlocks(world, start, 77, -32, 4, 78, -32, 5, Blocks.STONE_BRICKS.getDefaultState());
        structure.fillWithBlocks(world, start, 77, -32, 6, 77, -32, 10, Blocks.STONE_BRICKS.getDefaultState());
        structure.fillWithBlocks(world, start, 77, -32, 25, 78, -32, 27, Blocks.STONE_BRICKS.getDefaultState());
        structure.fillWithBlocks(world, start, 77, -32, 28, 77, -32, 29, Blocks.STONE_BRICKS.getDefaultState());
        structure.fillWithBlocks(world, start, 77, -32, 30, 77, -32, 31, Blocks.AIR.getDefaultState());
        structure.fillWithBlocks(world, start, 77, -32, 32, 80, -32, 35, Blocks.STONE_BRICKS.getDefaultState());
        structure.fillWithBlocks(world, start, 77, -32, 44, 79, -32, 46, Blocks.STONE_BRICKS.getDefaultState());
        structure.fillWithBlocks(world, start, 77, -32, 47, 78, -32, 52, Blocks.STONE_BRICKS.getDefaultState());
        structure.fillWithBlocks(world, start, 77, -32, 53, 77, -32, 62, Blocks.STONE_BRICKS.getDefaultState());
        structure.fillWithBlocks(world, start, 77, -32, 66, 77, -31, 71, Blocks.STONE_BRICKS.getDefaultState());
        structure.fillWithBlocks(world, start, 77, -32, 72, 77, -32, 73, Blocks.AIR.getDefaultState());
        structure.fillWithBlocks(world, start, 77, -32, 74, 78, -32, 80, Blocks.STONE_BRICKS.getDefaultState());
        structure.fillWithBlocks(world, start, 77, -31, -9, 78, -31, -1, Blocks.STONE_BRICKS.getDefaultState());
        structure.fillWithBlocks(world, start, 77, -31, 0, 77, -31, 0, Blocks.AIR.getDefaultState());
        structure.fillWithBlocks(world, start, 77, -31, 6, 79, -31, 10, Blocks.STONE_BRICKS.getDefaultState());
        structure.fillWithBlocks(world, start, 77, -31, 30, 78, -31, 31, Blocks.STONE_BRICKS.getDefaultState());
        structure.fillWithBlocks(world, start, 77, -31, 32, 78, -31, 32, Blocks.AIR.getDefaultState());
        structure.fillWithBlocks(world, start, 77, -31, 33, 77, -31, 35, Blocks.STONE_BRICKS.getDefaultState());
        structure.fillWithBlocks(world, start, 77, -31, 38, 77, -31, 38, Blocks.STONE_BRICKS.getDefaultState());
        structure.fillWithBlocks(world, start, 77, -31, 40, 79, -31, 42, Blocks.STONE_BRICKS.getDefaultState());
        structure.fillWithBlocks(world, start, 77, -31, 43, 78, -31, 50, Blocks.STONE_BRICKS.getDefaultState());
        structure.fillWithBlocks(world, start, 77, -30, -16, 77, -30, -15, Blocks.SANDSTONE.getDefaultState());
        structure.fillWithBlocks(world, start, 77, -30, -14, 78, -30, -14, Blocks.STONE_BRICKS.getDefaultState());
        structure.fillWithBlocks(world, start, 77, -30, -13, 77, -30, -13, Blocks.SANDSTONE.getDefaultState());
        structure.fillWithBlocks(world, start, 77, -30, -11, 85, -30, 0, Blocks.SANDSTONE.getDefaultState());
        structure.fillWithBlocks(world, start, 77, -30, 1, 77, -30, 1, Blocks.SANDSTONE.getDefaultState());
        structure.fillWithBlocks(world, start, 77, -30, 3, 81, -30, 7, Blocks.SANDSTONE.getDefaultState());
        structure.fillWithBlocks(world, start, 77, -30, 8, 80, -30, 16, Blocks.SANDSTONE.getDefaultState());
        structure.fillWithBlocks(world, start, 77, -30, 18, 81, -30, 23, Blocks.SANDSTONE.getDefaultState());
        structure.fillWithBlocks(world, start, 77, -30, 25, 81, -30, 31, Blocks.SANDSTONE.getDefaultState());
        structure.fillWithBlocks(world, start, 77, -30, 36, 77, -30, 36, Blocks.DIRT.getDefaultState());
        structure.fillWithBlocks(world, start, 77, -30, 37, 77, -29, 37, Blocks.SANDSTONE.getDefaultState());
        structure.fillWithBlocks(world, start, 77, -30, 39, 77, -25, 39, Blocks.AIR.getDefaultState());
        structure.fillWithBlocks(world, start, 77, -30, 40, 78, -30, 48, Blocks.SANDSTONE.getDefaultState());
        structure.fillWithBlocks(world, start, 77, -30, 49, 77, -29, 49, Blocks.SANDSTONE.getDefaultState());
        structure.fillWithBlocks(world, start, 77, -30, 50, 77, -30, 53, Blocks.AIR.getDefaultState());
        structure.fillWithBlocks(world, start, 77, -30, 54, 77, -29, 55, Blocks.SANDSTONE.getDefaultState());
        structure.fillWithBlocks(world, start, 77, -29, -16, 78, -29, -15, Blocks.STONE_BRICKS.getDefaultState());
        structure.fillWithBlocks(world, start, 77, -29, -14, 77, -29, -12, Blocks.SANDSTONE.getDefaultState());
        structure.fillWithBlocks(world, start, 77, -29, -11, 83, -29, -1, Blocks.AIR.getDefaultState());
        structure.fillWithBlocks(world, start, 77, -29, 0, 77, -27, 4, Blocks.SANDSTONE.getDefaultState());
        structure.fillWithBlocks(world, start, 77, -29, 5, 77, -28, 5, Blocks.DARK_OAK_LOG.getDefaultState());
        structure.fillWithBlocks(world, start, 77, -29, 6, 77, -29, 6, Blocks.AIR.getDefaultState());
        structure.fillWithBlocks(world, start, 77, -29, 7, 77, -27, 7, Blocks.DARK_OAK_LOG.getDefaultState());
        structure.fillWithBlocks(world, start, 77, -29, 10, 78, -29, 12, Blocks.AIR.getDefaultState());
        structure.fillWithBlocks(world, start, 77, -29, 13, 77, -23, 13, Blocks.SANDSTONE.getDefaultState());
        structure.fillWithBlocks(world, start, 77, -29, 14, 79, -29, 16, Blocks.AIR.getDefaultState());
        structure.fillWithBlocks(world, start, 77, -29, 17, 77, -27, 17, Blocks.DARK_OAK_LOG.getDefaultState());
        structure.fillWithBlocks(world, start, 77, -29, 18, 77, -29, 18, Blocks.AIR.getDefaultState());
        structure.fillWithBlocks(world, start, 77, -29, 19, 77, -27, 19, Blocks.DARK_OAK_LOG.getDefaultState());
        structure.fillWithBlocks(world, start, 77, -29, 20, 79, -29, 22, Blocks.AIR.getDefaultState());
        structure.fillWithBlocks(world, start, 77, -29, 23, 77, -28, 24, Blocks.SANDSTONE.getDefaultState());
        structure.fillWithBlocks(world, start, 77, -29, 25, 79, -29, 27, Blocks.AIR.getDefaultState());
        structure.fillWithBlocks(world, start, 77, -29, 31, 81, -25, 31, Blocks.AIR.getDefaultState());
        structure.fillWithBlocks(world, start, 77, -29, 32, 80, -29, 35, Blocks.SANDSTONE.getDefaultState());
        structure.fillWithBlocks(world, start, 77, -29, 38, 77, -29, 39, Blocks.AIR.getDefaultState());
        structure.fillWithBlocks(world, start, 77, -29, 42, 81, -29, 48, Blocks.AIR.getDefaultState());
        structure.fillWithBlocks(world, start, 77, -29, 50, 78, -29, 52, Blocks.SANDSTONE.getDefaultState());
        structure.fillWithBlocks(world, start, 77, -29, 53, 78, -29, 53, Blocks.DIRT.getDefaultState());
        structure.fillWithBlocks(world, start, 77, -28, -15, 77, -28, -14, Blocks.STONE_BRICKS.getDefaultState());
        structure.fillWithBlocks(world, start, 77, -28, -13, 77, -27, -12, Blocks.SANDSTONE.getDefaultState());
        structure.fillWithBlocks(world, start, 77, -28, -11, 84, -28, -1, Blocks.AIR.getDefaultState());
        structure.fillWithBlocks(world, start, 77, -28, 6, 77, -28, 6, Blocks.AIR.getDefaultState());
        structure.fillWithBlocks(world, start, 77, -28, 8, 77, -27, 9, Blocks.SANDSTONE.getDefaultState());
        structure.fillWithBlocks(world, start, 77, -28, 10, 79, -28, 12, Blocks.AIR.getDefaultState());
        structure.fillWithBlocks(world, start, 77, -28, 14, 79, -28, 16, Blocks.AIR.getDefaultState());
        structure.fillWithBlocks(world, start, 77, -28, 18, 77, -28, 18, Blocks.AIR.getDefaultState());
        structure.fillWithBlocks(world, start, 77, -28, 20, 79, -28, 22, Blocks.AIR.getDefaultState());
        structure.fillWithBlocks(world, start, 77, -28, 25, 79, -28, 27, Blocks.AIR.getDefaultState());
        structure.fillWithBlocks(world, start, 77, -28, 32, 78, -28, 33, Blocks.SANDSTONE.getDefaultState());
        structure.fillWithBlocks(world, start, 77, -28, 34, 77, -28, 35, Blocks.AIR.getDefaultState());
        structure.fillWithBlocks(world, start, 77, -28, 36, 78, -27, 36, Blocks.SANDSTONE.getDefaultState());
        structure.fillWithBlocks(world, start, 77, -28, 37, 78, -28, 37, Blocks.DIRT.getDefaultState());
        structure.fillWithBlocks(world, start, 77, -28, 38, 77, -28, 38, Blocks.SANDSTONE.getDefaultState());
        structure.fillWithBlocks(world, start, 77, -28, 40, 79, -28, 40, Blocks.AIR.getDefaultState());
        structure.fillWithBlocks(world, start, 77, -28, 42, 81, -28, 48, Blocks.AIR.getDefaultState());
        structure.fillWithBlocks(world, start, 77, -28, 50, 77, -27, 51, Blocks.AIR.getDefaultState());
        structure.fillWithBlocks(world, start, 77, -28, 52, 77, -28, 53, Blocks.SANDSTONE.getDefaultState());
        structure.fillWithBlocks(world, start, 77, -27, -14, 77, -27, -12, Blocks.SANDSTONE.getDefaultState());
        structure.fillWithBlocks(world, start, 77, -27, -11, 84, -27, -1, Blocks.AIR.getDefaultState());
        structure.fillWithBlocks(world, start, 77, -27, 6, 77, -27, 6, Blocks.AIR.getDefaultState());
        structure.fillWithBlocks(world, start, 77, -27, 10, 79, -27, 12, Blocks.AIR.getDefaultState());
        structure.fillWithBlocks(world, start, 77, -27, 14, 79, -27, 16, Blocks.AIR.getDefaultState());
        structure.fillWithBlocks(world, start, 77, -27, 18, 77, -27, 18, Blocks.AIR.getDefaultState());
        structure.fillWithBlocks(world, start, 77, -27, 20, 79, -27, 22, Blocks.AIR.getDefaultState());
        structure.fillWithBlocks(world, start, 77, -27, 23, 77, -26, 24, Blocks.SANDSTONE.getDefaultState());
        structure.fillWithBlocks(world, start, 77, -27, 25, 78, -27, 26, Blocks.AIR.getDefaultState());
        structure.fillWithBlocks(world, start, 77, -27, 32, 77, -27, 32, Blocks.SANDSTONE.getDefaultState());
        structure.fillWithBlocks(world, start, 77, -27, 33, 77, -26, 33, Blocks.AIR.getDefaultState());
        structure.fillWithBlocks(world, start, 77, -27, 34, 77, -27, 36, Blocks.SANDSTONE.getDefaultState());
        structure.fillWithBlocks(world, start, 77, -27, 38, 77, -27, 38, Blocks.SANDSTONE.getDefaultState());
        structure.fillWithBlocks(world, start, 77, -27, 40, 77, -25, 40, Blocks.AIR.getDefaultState());
        structure.fillWithBlocks(world, start, 77, -27, 41, 82, -27, 41, Blocks.SANDSTONE.getDefaultState());
        structure.fillWithBlocks(world, start, 77, -27, 42, 81, -27, 48, Blocks.AIR.getDefaultState());
        structure.fillWithBlocks(world, start, 77, -27, 49, 77, -27, 49, Blocks.SANDSTONE.getDefaultState());
        structure.fillWithBlocks(world, start, 77, -26, -16, 77, -25, -16, Blocks.DIRT.getDefaultState());
        structure.fillWithBlocks(world, start, 77, -26, -15, 77, -26, -14, Blocks.STONE_BRICKS.getDefaultState());
        structure.fillWithBlocks(world, start, 77, -26, -12, 77, -25, -11, Blocks.SANDSTONE.getDefaultState());
        structure.fillWithBlocks(world, start, 77, -26, -10, 83, -26, -2, Blocks.AIR.getDefaultState());
        structure.fillWithBlocks(world, start, 77, -26, -1, 77, -24, 2, Blocks.SANDSTONE.getDefaultState());
        structure.fillWithBlocks(world, start, 77, -26, 6, 79, -26, 8, Blocks.SANDSTONE.getDefaultState());
        structure.fillWithBlocks(world, start, 77, -26, 16, 81, -26, 24, Blocks.SANDSTONE.getDefaultState());
        structure.fillWithBlocks(world, start, 77, -26, 25, 78, -26, 31, Blocks.AIR.getDefaultState());
        structure.fillWithBlocks(world, start, 77, -26, 32, 77, -26, 32, Blocks.SANDSTONE.getDefaultState());
        structure.fillWithBlocks(world, start, 77, -26, 38, 77, -26, 38, Blocks.SANDSTONE.getDefaultState());
        structure.fillWithBlocks(world, start, 77, -26, 42, 81, -26, 48, Blocks.AIR.getDefaultState());
        structure.fillWithBlocks(world, start, 77, -26, 50, 77, -25, 51, Blocks.AIR.getDefaultState());
        structure.fillWithBlocks(world, start, 77, -26, 52, 77, -26, 52, Blocks.SANDSTONE.getDefaultState());
        structure.fillWithBlocks(world, start, 77, -26, 54, 77, -26, 55, Blocks.SANDSTONE.getDefaultState());
        structure.fillWithBlocks(world, start, 77, -25, -15, 77, -25, -15, Blocks.SANDSTONE.getDefaultState());
        structure.fillWithBlocks(world, start, 77, -25, -14, 77, -25, -13, Blocks.STONE_BRICKS.getDefaultState());
        structure.fillWithBlocks(world, start, 77, -25, -10, 77, -23, -10, Blocks.SANDSTONE.getDefaultState());
        structure.fillWithBlocks(world, start, 77, -25, -9, 82, -25, -3, Blocks.AIR.getDefaultState());
        structure.fillWithBlocks(world, start, 77, -25, -2, 77, -25, 4, Blocks.SANDSTONE.getDefaultState());
        structure.fillWithBlocks(world, start, 77, -25, 7, 77, -21, 7, Blocks.SANDSTONE.getDefaultState());
        structure.fillWithBlocks(world, start, 77, -25, 9, 81, -25, 14, Blocks.SANDSTONE.getDefaultState());
        structure.fillWithBlocks(world, start, 77, -25, 15, 77, -24, 15, Blocks.DIRT.getDefaultState());
        structure.fillWithBlocks(world, start, 77, -25, 23, 78, -25, 24, Blocks.SANDSTONE.getDefaultState());
        structure.fillWithBlocks(world, start, 77, -25, 25, 79, -25, 27, Blocks.AIR.getDefaultState());
        structure.fillWithBlocks(world, start, 77, -25, 32, 79, -25, 34, Blocks.SANDSTONE.getDefaultState());
        structure.fillWithBlocks(world, start, 77, -25, 35, 77, -25, 38, Blocks.SANDSTONE.getDefaultState());
        structure.fillWithBlocks(world, start, 77, -25, 41, 79, -24, 41, Blocks.SANDSTONE.getDefaultState());
        structure.fillWithBlocks(world, start, 77, -25, 42, 81, -25, 48, Blocks.AIR.getDefaultState());
        structure.fillWithBlocks(world, start, 77, -25, 49, 77, -25, 49, Blocks.SANDSTONE.getDefaultState());
        structure.fillWithBlocks(world, start, 77, -25, 55, 78, -24, 55, Blocks.SANDSTONE.getDefaultState());
        structure.fillWithBlocks(world, start, 77, -24, -16, 77, -23, -14, Blocks.STONE_BRICKS.getDefaultState());
        structure.fillWithBlocks(world, start, 77, -24, -11, 78, -24, -3, Blocks.SANDSTONE.getDefaultState());
        structure.fillWithBlocks(world, start, 77, -24, 8, 79, -24, 10, Blocks.SANDSTONE.getDefaultState());
        structure.fillWithBlocks(world, start, 77, -24, 23, 78, -24, 24, Blocks.SANDSTONE.getDefaultState());
        structure.fillWithBlocks(world, start, 77, -24, 25, 79, -24, 27, Blocks.AIR.getDefaultState());
        structure.fillWithBlocks(world, start, 77, -24, 31, 81, -21, 31, Blocks.AIR.getDefaultState());
        structure.fillWithBlocks(world, start, 77, -24, 32, 78, -24, 34, Blocks.SANDSTONE.getDefaultState());
        structure.fillWithBlocks(world, start, 77, -24, 36, 77, -24, 36, Blocks.SANDSTONE.getDefaultState());
        structure.fillWithBlocks(world, start, 77, -24, 38, 78, -24, 48, Blocks.SANDSTONE.getDefaultState());
        structure.fillWithBlocks(world, start, 77, -24, 49, 77, -24, 49, Blocks.AIR.getDefaultState());
        structure.fillWithBlocks(world, start, 77, -24, 50, 77, -20, 50, Blocks.SANDSTONE.getDefaultState());
        structure.fillWithBlocks(world, start, 77, -24, 52, 78, -24, 55, Blocks.SANDSTONE.getDefaultState());
        structure.fillWithBlocks(world, start, 77, -23, -12, 77, -23, -11, Blocks.STONE_BRICKS.getDefaultState());
        structure.fillWithBlocks(world, start, 77, -23, -9, 77, -21, -9, Blocks.STONE_BRICKS.getDefaultState());
        structure.fillWithBlocks(world, start, 77, -23, -7, 77, -22, -6, Blocks.STONE_BRICKS.getDefaultState());
        structure.fillWithBlocks(world, start, 77, -23, -5, 77, -23, -4, Blocks.SANDSTONE.getDefaultState());
        structure.fillWithBlocks(world, start, 77, -23, 2, 77, -23, 4, Blocks.SANDSTONE.getDefaultState());
        structure.fillWithBlocks(world, start, 77, -23, 9, 78, -23, 9, Blocks.SANDSTONE.getDefaultState());
        structure.fillWithBlocks(world, start, 77, -23, 10, 78, -23, 10, Blocks.DIRT.getDefaultState());
        structure.fillWithBlocks(world, start, 77, -23, 11, 78, -23, 13, Blocks.SANDSTONE.getDefaultState());
        structure.fillWithBlocks(world, start, 77, -23, 15, 82, -22, 15, Blocks.SANDSTONE.getDefaultState());
        structure.fillWithBlocks(world, start, 77, -23, 22, 79, -23, 24, Blocks.SANDSTONE.getDefaultState());
        structure.fillWithBlocks(world, start, 77, -23, 25, 78, -23, 26, Blocks.AIR.getDefaultState());
        structure.fillWithBlocks(world, start, 77, -23, 32, 79, -23, 34, Blocks.SANDSTONE.getDefaultState());
        structure.fillWithBlocks(world, start, 77, -23, 39, 78, -23, 40, Blocks.SANDSTONE.getDefaultState());
        structure.fillWithBlocks(world, start, 77, -23, 42, 77, -22, 42, Blocks.DIRT.getDefaultState());
        structure.fillWithBlocks(world, start, 77, -23, 43, 77, -23, 53, Blocks.SANDSTONE.getDefaultState());
        structure.fillWithBlocks(world, start, 77, -23, 54, 77, -23, 55, Blocks.AIR.getDefaultState());
        structure.fillWithBlocks(world, start, 77, -22, -16, 78, -22, -16, Blocks.STONE_BRICKS.getDefaultState());
        structure.fillWithBlocks(world, start, 77, -22, -15, 79, -22, -15, Blocks.SANDSTONE.getDefaultState());
        structure.fillWithBlocks(world, start, 77, -22, -13, 77, -22, -12, Blocks.SANDSTONE.getDefaultState());
        structure.fillWithBlocks(world, start, 77, -22, -11, 77, -21, -11, Blocks.DIRT.getDefaultState());
        structure.fillWithBlocks(world, start, 77, -22, -10, 77, -21, -9, Blocks.STONE_BRICKS.getDefaultState());
        structure.fillWithBlocks(world, start, 77, -22, -5, 78, -22, -3, Blocks.STONE_BRICKS.getDefaultState());
        structure.fillWithBlocks(world, start, 77, -22, -2, 77, -22, 3, Blocks.SANDSTONE.getDefaultState());
        structure.fillWithBlocks(world, start, 77, -22, 14, 78, -22, 15, Blocks.SANDSTONE.getDefaultState());
        structure.fillWithBlocks(world, start, 77, -22, 23, 78, -22, 24, Blocks.SANDSTONE.getDefaultState());
        structure.fillWithBlocks(world, start, 77, -22, 25, 78, -22, 31, Blocks.AIR.getDefaultState());
        structure.fillWithBlocks(world, start, 77, -22, 32, 78, -22, 33, Blocks.SANDSTONE.getDefaultState());
        structure.fillWithBlocks(world, start, 77, -22, 34, 77, -22, 34, Blocks.AIR.getDefaultState());
        structure.fillWithBlocks(world, start, 77, -22, 35, 77, -22, 36, Blocks.SANDSTONE.getDefaultState());
        structure.fillWithBlocks(world, start, 77, -22, 37, 77, -21, 37, Blocks.DIRT.getDefaultState());
        structure.fillWithBlocks(world, start, 77, -22, 38, 77, -22, 38, Blocks.SANDSTONE.getDefaultState());
        structure.fillWithBlocks(world, start, 77, -22, 40, 77, -22, 41, Blocks.SANDSTONE.getDefaultState());
        structure.fillWithBlocks(world, start, 77, -22, 43, 77, -22, 43, Blocks.SANDSTONE.getDefaultState());
        structure.fillWithBlocks(world, start, 77, -22, 45, 77, -22, 51, Blocks.SANDSTONE.getDefaultState());
        structure.fillWithBlocks(world, start, 77, -22, 53, 77, -21, 54, Blocks.SANDSTONE.getDefaultState());
        structure.fillWithBlocks(world, start, 77, -22, 55, 78, -22, 55, Blocks.AIR.getDefaultState());
        structure.fillWithBlocks(world, start, 77, -21, -15, 77, -21, -14, Blocks.STONE_BRICKS.getDefaultState());
        structure.fillWithBlocks(world, start, 77, -21, -8, 77, -21, -8, Blocks.STONE_BRICKS.getDefaultState());
        structure.fillWithBlocks(world, start, 77, -21, -5, 77, -21, -2, Blocks.STONE_BRICKS.getDefaultState());
        structure.fillWithBlocks(world, start, 77, -21, -1, 79, -21, 4, Blocks.SANDSTONE.getDefaultState());
        structure.fillWithBlocks(world, start, 77, -21, 8, 77, -21, 15, Blocks.SANDSTONE.getDefaultState());
        structure.fillWithBlocks(world, start, 77, -21, 22, 78, -21, 24, Blocks.SANDSTONE.getDefaultState());
        structure.fillWithBlocks(world, start, 77, -21, 25, 79, -21, 27, Blocks.AIR.getDefaultState());
        structure.fillWithBlocks(world, start, 77, -21, 32, 77, -21, 32, Blocks.SANDSTONE.getDefaultState());
        structure.fillWithBlocks(world, start, 77, -21, 35, 78, -21, 36, Blocks.SANDSTONE.getDefaultState());
        structure.fillWithBlocks(world, start, 77, -21, 38, 78, -21, 39, Blocks.SANDSTONE.getDefaultState());
        structure.fillWithBlocks(world, start, 77, -21, 40, 77, -21, 40, Blocks.DIRT.getDefaultState());
        structure.fillWithBlocks(world, start, 77, -21, 41, 77, -21, 42, Blocks.SANDSTONE.getDefaultState());
        structure.fillWithBlocks(world, start, 77, -21, 44, 78, -21, 45, Blocks.SANDSTONE.getDefaultState());
        structure.fillWithBlocks(world, start, 77, -21, 47, 81, -20, 47, Blocks.SANDSTONE.getDefaultState());
        structure.fillWithBlocks(world, start, 77, -21, 51, 77, -21, 51, Blocks.SANDSTONE.getDefaultState());
        structure.fillWithBlocks(world, start, 77, -21, 55, 81, -20, 55, Blocks.SANDSTONE.getDefaultState());
        structure.fillWithBlocks(world, start, 77, -21, 66, 81, -20, 66, Blocks.SANDSTONE.getDefaultState());
        structure.fillWithBlocks(world, start, 77, -20, 5, 77, -20, 6, Blocks.SANDSTONE.getDefaultState());
        structure.fillWithBlocks(world, start, 77, -20, 9, 81, -20, 13, Blocks.SANDSTONE.getDefaultState());
        structure.fillWithBlocks(world, start, 77, -20, 14, 77, -20, 15, Blocks.OAK_PLANKS.getDefaultState());
        structure.fillWithBlocks(world, start, 77, -20, 17, 81, -20, 26, Blocks.SANDSTONE.getDefaultState());
        structure.fillWithBlocks(world, start, 77, -20, 31, 77, -20, 31, Blocks.SANDSTONE.getDefaultState());
        structure.fillWithBlocks(world, start, 77, -20, 33, 81, -20, 40, Blocks.SANDSTONE.getDefaultState());
        structure.fillWithBlocks(world, start, 77, -20, 41, 77, -17, 41, Blocks.STONE.getDefaultState());
        structure.fillWithBlocks(world, start, 77, -20, 42, 81, -20, 52, Blocks.SANDSTONE.getDefaultState());
        structure.fillWithBlocks(world, start, 77, -20, 53, 80, -20, 70, Blocks.SANDSTONE.getDefaultState());
        structure.fillWithBlocks(world, start, 77, -19, 5, 77, -19, 5, Blocks.SANDSTONE.getDefaultState());
        structure.fillWithBlocks(world, start, 77, -19, 7, 77, -15, 7, Blocks.OAK_PLANKS.getDefaultState());
        structure.fillWithBlocks(world, start, 77, -19, 8, 77, -16, 8, Blocks.STONE.getDefaultState());
        structure.fillWithBlocks(world, start, 77, -19, 9, 78, -19, 13, Blocks.AIR.getDefaultState());
        structure.fillWithBlocks(world, start, 77, -19, 14, 77, -16, 14, Blocks.STONE.getDefaultState());
        structure.fillWithBlocks(world, start, 77, -19, 15, 77, -18, 16, Blocks.SANDSTONE.getDefaultState());
        structure.fillWithBlocks(world, start, 77, -19, 17, 77, -16, 17, Blocks.STONE.getDefaultState());
        structure.fillWithBlocks(world, start, 77, -19, 18, 77, -19, 18, Blocks.AIR.getDefaultState());
        structure.fillWithBlocks(world, start, 77, -19, 19, 77, -17, 19, Blocks.STONE.getDefaultState());
        structure.fillWithBlocks(world, start, 77, -19, 20, 79, -19, 22, Blocks.AIR.getDefaultState());
        structure.fillWithBlocks(world, start, 77, -19, 25, 81, -19, 31, Blocks.AIR.getDefaultState());
        structure.fillWithBlocks(world, start, 77, -19, 32, 77, -17, 34, Blocks.SANDSTONE.getDefaultState());
        structure.fillWithBlocks(world, start, 77, -19, 35, 77, -17, 35, Blocks.STONE.getDefaultState());
        structure.fillWithBlocks(world, start, 77, -19, 36, 77, -19, 36, Blocks.AIR.getDefaultState());
        structure.fillWithBlocks(world, start, 77, -19, 37, 77, -17, 37, Blocks.STONE.getDefaultState());
        structure.fillWithBlocks(world, start, 77, -19, 38, 79, -19, 40, Blocks.AIR.getDefaultState());
        structure.fillWithBlocks(world, start, 77, -19, 42, 77, -19, 42, Blocks.AIR.getDefaultState());
        structure.fillWithBlocks(world, start, 77, -19, 43, 77, -17, 43, Blocks.STONE.getDefaultState());
        structure.fillWithBlocks(world, start, 77, -19, 44, 79, -19, 46, Blocks.AIR.getDefaultState());
        structure.fillWithBlocks(world, start, 77, -19, 47, 77, -17, 47, Blocks.STONE.getDefaultState());
        structure.fillWithBlocks(world, start, 77, -19, 48, 77, -19, 48, Blocks.AIR.getDefaultState());
        structure.fillWithBlocks(world, start, 77, -19, 49, 77, -17, 49, Blocks.STONE.getDefaultState());
        structure.fillWithBlocks(world, start, 77, -19, 50, 79, -19, 52, Blocks.AIR.getDefaultState());
        structure.fillWithBlocks(world, start, 77, -19, 53, 77, -17, 53, Blocks.STONE.getDefaultState());
        structure.fillWithBlocks(world, start, 77, -19, 54, 77, -19, 54, Blocks.AIR.getDefaultState());
        structure.fillWithBlocks(world, start, 77, -19, 55, 77, -17, 55, Blocks.STONE.getDefaultState());
        structure.fillWithBlocks(world, start, 77, -19, 56, 79, -19, 58, Blocks.AIR.getDefaultState());
        structure.fillWithBlocks(world, start, 77, -19, 59, 77, -17, 61, Blocks.SANDSTONE.getDefaultState());
        structure.fillWithBlocks(world, start, 77, -19, 62, 78, -19, 68, Blocks.AIR.getDefaultState());
        structure.fillWithBlocks(world, start, 77, -19, 69, 78, -19, 70, Blocks.SANDSTONE.getDefaultState());
        structure.fillWithBlocks(world, start, 77, -18, 5, 78, -18, 6, Blocks.SANDSTONE.getDefaultState());
        structure.fillWithBlocks(world, start, 77, -18, 9, 81, -18, 13, Blocks.AIR.getDefaultState());
        structure.fillWithBlocks(world, start, 77, -18, 18, 77, -18, 18, Blocks.AIR.getDefaultState());
        structure.fillWithBlocks(world, start, 77, -18, 20, 79, -18, 22, Blocks.AIR.getDefaultState());
        structure.fillWithBlocks(world, start, 77, -18, 25, 81, -18, 31, Blocks.AIR.getDefaultState());
        structure.fillWithBlocks(world, start, 77, -18, 36, 77, -18, 36, Blocks.AIR.getDefaultState());
        structure.fillWithBlocks(world, start, 77, -18, 38, 79, -18, 40, Blocks.AIR.getDefaultState());
        structure.fillWithBlocks(world, start, 77, -18, 42, 77, -18, 42, Blocks.AIR.getDefaultState());
        structure.fillWithBlocks(world, start, 77, -18, 44, 79, -18, 46, Blocks.AIR.getDefaultState());
        structure.fillWithBlocks(world, start, 77, -18, 48, 77, -18, 48, Blocks.AIR.getDefaultState());
        structure.fillWithBlocks(world, start, 77, -18, 50, 79, -18, 52, Blocks.AIR.getDefaultState());
        structure.fillWithBlocks(world, start, 77, -18, 54, 77, -18, 54, Blocks.AIR.getDefaultState());
        structure.fillWithBlocks(world, start, 77, -18, 56, 79, -18, 58, Blocks.AIR.getDefaultState());
        structure.fillWithBlocks(world, start, 77, -18, 62, 79, -18, 64, Blocks.AIR.getDefaultState());
        structure.fillWithBlocks(world, start, 77, -18, 68, 81, -16, 68, Blocks.AIR.getDefaultState());
        structure.fillWithBlocks(world, start, 77, -18, 69, 79, -18, 71, Blocks.SANDSTONE.getDefaultState());
        structure.fillWithBlocks(world, start, 77, -17, 9, 81, -17, 13, Blocks.AIR.getDefaultState());
        structure.fillWithBlocks(world, start, 77, -17, 15, 77, -17, 16, Blocks.SANDSTONE.getDefaultState());
        structure.fillWithBlocks(world, start, 77, -17, 18, 77, -17, 18, Blocks.AIR.getDefaultState());
        structure.fillWithBlocks(world, start, 77, -17, 20, 79, -17, 22, Blocks.AIR.getDefaultState());
        structure.fillWithBlocks(world, start, 77, -17, 25, 81, -17, 31, Blocks.AIR.getDefaultState());
        structure.fillWithBlocks(world, start, 77, -17, 36, 77, -17, 36, Blocks.AIR.getDefaultState());
        structure.fillWithBlocks(world, start, 77, -17, 38, 79, -17, 40, Blocks.AIR.getDefaultState());
        structure.fillWithBlocks(world, start, 77, -17, 42, 77, -17, 42, Blocks.AIR.getDefaultState());
        structure.fillWithBlocks(world, start, 77, -17, 44, 79, -17, 46, Blocks.AIR.getDefaultState());
        structure.fillWithBlocks(world, start, 77, -17, 48, 77, -17, 48, Blocks.AIR.getDefaultState());
        structure.fillWithBlocks(world, start, 77, -17, 50, 79, -17, 52, Blocks.AIR.getDefaultState());
        structure.fillWithBlocks(world, start, 77, -17, 54, 77, -17, 54, Blocks.AIR.getDefaultState());
        structure.fillWithBlocks(world, start, 77, -17, 56, 79, -17, 58, Blocks.AIR.getDefaultState());
        structure.fillWithBlocks(world, start, 77, -17, 62, 81, -17, 68, Blocks.AIR.getDefaultState());
        structure.fillWithBlocks(world, start, 77, -16, 5, 78, -16, 6, Blocks.SANDSTONE.getDefaultState());
        structure.fillWithBlocks(world, start, 77, -16, 9, 81, -16, 13, Blocks.AIR.getDefaultState());
        structure.fillWithBlocks(world, start, 77, -16, 15, 77, -15, 15, Blocks.OAK_PLANKS.getDefaultState());
        structure.fillWithBlocks(world, start, 77, -16, 16, 77, -16, 16, Blocks.SANDSTONE.getDefaultState());
        structure.fillWithBlocks(world, start, 77, -16, 18, 81, -16, 23, Blocks.SANDSTONE.getDefaultState());
        structure.fillWithBlocks(world, start, 77, -16, 25, 77, -1, 25, Blocks.SANDSTONE.getDefaultState());
        structure.fillWithBlocks(world, start, 77, -16, 26, 81, -16, 30, Blocks.AIR.getDefaultState());
        structure.fillWithBlocks(world, start, 77, -16, 31, 77, -16, 61, Blocks.SANDSTONE.getDefaultState());
        structure.fillWithBlocks(world, start, 77, -16, 62, 81, -16, 68, Blocks.AIR.getDefaultState());
        structure.fillWithBlocks(world, start, 77, -16, 69, 79, -16, 71, Blocks.SANDSTONE.getDefaultState());
        structure.fillWithBlocks(world, start, 77, -15, 5, 78, -15, 6, Blocks.SANDSTONE.getDefaultState());
        structure.fillWithBlocks(world, start, 77, -15, 9, 78, -15, 14, Blocks.SANDSTONE.getDefaultState());
        structure.fillWithBlocks(world, start, 77, -15, 16, 78, -15, 17, Blocks.SANDSTONE.getDefaultState());
        structure.fillWithBlocks(world, start, 77, -15, 22, 77, -15, 22, Blocks.SANDSTONE.getDefaultState());
        structure.fillWithBlocks(world, start, 77, -15, 23, 77, -14, 23, Blocks.AIR.getDefaultState());
        structure.fillWithBlocks(world, start, 77, -15, 24, 77, -15, 25, Blocks.SANDSTONE.getDefaultState());
        structure.fillWithBlocks(world, start, 77, -15, 26, 81, -15, 30, Blocks.AIR.getDefaultState());
        structure.fillWithBlocks(world, start, 77, -15, 31, 77, -15, 31, Blocks.SANDSTONE.getDefaultState());
        structure.fillWithBlocks(world, start, 77, -15, 33, 78, -15, 34, Blocks.SANDSTONE.getDefaultState());
        structure.fillWithBlocks(world, start, 77, -15, 59, 81, -15, 63, Blocks.SANDSTONE.getDefaultState());
        structure.fillWithBlocks(world, start, 77, -15, 70, 77, -15, 71, Blocks.SANDSTONE.getDefaultState());
        structure.fillWithBlocks(world, start, 77, -14, 17, 82, -12, 17, Blocks.SANDSTONE.getDefaultState());
        structure.fillWithBlocks(world, start, 77, -14, 22, 77, -14, 22, Blocks.SANDSTONE.getDefaultState());
        structure.fillWithBlocks(world, start, 77, -14, 26, 78, -14, 33, Blocks.SANDSTONE.getDefaultState());
        structure.fillWithBlocks(world, start, 77, -14, 59, 81, -14, 63, Blocks.SANDSTONE.getDefaultState());
        structure.fillWithBlocks(world, start, 77, -14, 65, 78, -14, 71, Blocks.SANDSTONE.getDefaultState());
        structure.fillWithBlocks(world, start, 77, -13, 8, 78, -13, 9, Blocks.SANDSTONE.getDefaultState());
        structure.fillWithBlocks(world, start, 77, -13, 11, 82, -13, 17, Blocks.SANDSTONE.getDefaultState());
        structure.fillWithBlocks(world, start, 77, -13, 33, 77, -13, 34, Blocks.AIR.getDefaultState());
        structure.fillWithBlocks(world, start, 77, -13, 67, 77, -13, 68, Blocks.AIR.getDefaultState());
        structure.fillWithBlocks(world, start, 77, -12, 59, 79, -12, 62, Blocks.SANDSTONE.getDefaultState());
        structure.fillWithBlocks(world, start, 77, -12, 66, 80, -12, 71, Blocks.SANDSTONE.getDefaultState());
        structure.fillWithBlocks(world, start, 77, -11, 5, 77, -11, 5, Blocks.SANDSTONE.getDefaultState());
        structure.fillWithBlocks(world, start, 77, -11, 7, 80, -11, 14, Blocks.SANDSTONE.getDefaultState());
        structure.fillWithBlocks(world, start, 77, -11, 16, 78, -11, 17, Blocks.SANDSTONE.getDefaultState());
        structure.fillWithBlocks(world, start, 77, -11, 22, 83, -11, 28, Blocks.SANDSTONE.getDefaultState());
        structure.fillWithBlocks(world, start, 77, -11, 60, 81, -11, 64, Blocks.SANDSTONE.getDefaultState());
        structure.fillWithBlocks(world, start, 77, -11, 67, 80, -11, 71, Blocks.SANDSTONE.getDefaultState());
        structure.fillWithBlocks(world, start, 77, -10, 22, 77, -10, 22, Blocks.SANDSTONE.getDefaultState());
        structure.fillWithBlocks(world, start, 77, -10, 24, 78, -10, 34, Blocks.SANDSTONE.getDefaultState());
        structure.fillWithBlocks(world, start, 77, -9, 22, 78, -9, 26, Blocks.SANDSTONE.getDefaultState());
        structure.fillWithBlocks(world, start, 77, -6, 24, 78, -6, 25, Blocks.SANDSTONE.getDefaultState());
        structure.fillWithBlocks(world, start, 77, -6, 26, 78, -6, 26, Blocks.AIR.getDefaultState());
        structure.fillWithBlocks(world, start, 77, -6, 27, 80, -6, 30, Blocks.SANDSTONE.getDefaultState());
        structure.fillWithBlocks(world, start, 77, -5, 22, 78, -5, 25, Blocks.SANDSTONE.getDefaultState());
        structure.fillWithBlocks(world, start, 77, -5, 26, 77, -5, 27, Blocks.AIR.getDefaultState());
        structure.fillWithBlocks(world, start, 77, -5, 28, 78, -5, 29, Blocks.SANDSTONE.getDefaultState());
        structure.fillWithBlocks(world, start, 77, -5, 31, 78, -5, 34, Blocks.SANDSTONE.getDefaultState());
        structure.fillWithBlocks(world, start, 77, -4, 22, 78, -4, 34, Blocks.SANDSTONE.getDefaultState());
        structure.fillWithBlocks(world, start, 77, -3, 23, 77, -2, 23, Blocks.AIR.getDefaultState());
        structure.fillWithBlocks(world, start, 77, -2, 26, 77, -1, 29, Blocks.SANDSTONE.getDefaultState());
        structure.fillWithBlocks(world, start, 77, -2, 30, 77, -2, 34, Blocks.SANDSTONE.getDefaultState());
        structure.fillWithBlocks(world, start, 77, -1, 31, 78, -1, 32, Blocks.SANDSTONE.getDefaultState());
        structure.fillWithBlocks(world, start, 77, 0, 149, 77, 0, 149, Blocks.STONE.getDefaultState());
        structure.fillWithBlocks(world, start, 77, 0, 151, 78, 0, 164, Blocks.SANDSTONE.getDefaultState());
        structure.fillWithBlocks(world, start, 77, 1, 17, 78, 1, 18, Blocks.SANDSTONE.getDefaultState());
        structure.fillWithBlocks(world, start, 77, 9, 47, 79, 11, 47, Blocks.SANDSTONE.getDefaultState());
        structure.fillWithBlocks(world, start, 77, 9, 48, 78, 9, 49, Blocks.STONE.getDefaultState());
        structure.fillWithBlocks(world, start, 77, 9, 50, 77, 19, 50, Blocks.STONE.getDefaultState());
        structure.fillWithBlocks(world, start, 77, 9, 51, 79, 9, 78, Blocks.SANDSTONE.getDefaultState());
        structure.fillWithBlocks(world, start, 77, 9, 79, 89, 9, 79, Blocks.STONE.getDefaultState());
        structure.fillWithBlocks(world, start, 77, 9, 91, 77, 10, 92, Blocks.SAND.getDefaultState());
        structure.fillWithBlocks(world, start, 77, 9, 123, 81, 9, 127, Blocks.SANDSTONE.getDefaultState());
        structure.fillWithBlocks(world, start, 77, 10, 48, 78, 10, 49, Blocks.STONE.getDefaultState());
        structure.fillWithBlocks(world, start, 77, 10, 51, 79, 10, 78, Blocks.SANDSTONE.getDefaultState());
        structure.fillWithBlocks(world, start, 77, 10, 79, 77, 11, 79, Blocks.SANDSTONE.getDefaultState());
        structure.fillWithBlocks(world, start, 77, 10, 93, 77, 12, 93, Blocks.SAND.getDefaultState());
        structure.fillWithBlocks(world, start, 77, 10, 123, 80, 10, 127, Blocks.SANDSTONE.getDefaultState());
        structure.fillWithBlocks(world, start, 77, 10, 128, 77, 10, 129, Blocks.SAND.getDefaultState());
        structure.fillWithBlocks(world, start, 77, 11, 48, 78, 11, 49, Blocks.STONE.getDefaultState());
        structure.fillWithBlocks(world, start, 77, 11, 51, 79, 11, 78, Blocks.SANDSTONE.getDefaultState());
        structure.fillWithBlocks(world, start, 77, 11, 94, 77, 13, 101, Blocks.SAND.getDefaultState());
        structure.fillWithBlocks(world, start, 77, 11, 102, 77, 11, 126, Blocks.SANDSTONE.getDefaultState());
        structure.fillWithBlocks(world, start, 77, 11, 127, 78, 11, 128, Blocks.SAND.getDefaultState());
        structure.fillWithBlocks(world, start, 77, 12, 47, 79, 14, 47, Blocks.SANDSTONE.getDefaultState());
        structure.fillWithBlocks(world, start, 77, 12, 48, 78, 12, 49, Blocks.STONE.getDefaultState());
        structure.fillWithBlocks(world, start, 77, 12, 51, 79, 12, 78, Blocks.SANDSTONE.getDefaultState());
        structure.fillWithBlocks(world, start, 77, 12, 102, 78, 12, 103, Blocks.SAND.getDefaultState());
        structure.fillWithBlocks(world, start, 77, 12, 104, 79, 12, 123, Blocks.SANDSTONE.getDefaultState());
        structure.fillWithBlocks(world, start, 77, 13, 48, 78, 13, 49, Blocks.STONE.getDefaultState());
        structure.fillWithBlocks(world, start, 77, 13, 51, 79, 13, 78, Blocks.SANDSTONE.getDefaultState());
        structure.fillWithBlocks(world, start, 77, 13, 120, 80, 13, 123, Blocks.SANDSTONE.getDefaultState());
        structure.fillWithBlocks(world, start, 77, 14, 44, 79, 14, 47, Blocks.SANDSTONE.getDefaultState());
        structure.fillWithBlocks(world, start, 77, 14, 48, 78, 14, 49, Blocks.STONE.getDefaultState());
        structure.fillWithBlocks(world, start, 77, 14, 51, 79, 14, 78, Blocks.SANDSTONE.getDefaultState());
        structure.fillWithBlocks(world, start, 77, 14, 102, 77, 14, 108, Blocks.SAND.getDefaultState());
        structure.fillWithBlocks(world, start, 77, 14, 118, 87, 14, 118, Blocks.SANDSTONE.getDefaultState());
        structure.fillWithBlocks(world, start, 77, 14, 119, 78, 14, 125, Blocks.SAND.getDefaultState());
        structure.fillWithBlocks(world, start, 77, 15, 44, 79, 17, 44, Blocks.SAND.getDefaultState());
        structure.fillWithBlocks(world, start, 77, 15, 45, 79, 15, 47, Blocks.SANDSTONE.getDefaultState());
        structure.fillWithBlocks(world, start, 77, 15, 48, 78, 15, 49, Blocks.STONE.getDefaultState());
        structure.fillWithBlocks(world, start, 77, 15, 51, 79, 15, 78, Blocks.SANDSTONE.getDefaultState());
        structure.fillWithBlocks(world, start, 77, 15, 88, 78, 15, 89, Blocks.SANDSTONE.getDefaultState());
        structure.fillWithBlocks(world, start, 77, 15, 90, 77, 16, 90, Blocks.SANDSTONE.getDefaultState());
        structure.fillWithBlocks(world, start, 77, 15, 104, 79, 15, 123, Blocks.SAND.getDefaultState());
        structure.fillWithBlocks(world, start, 77, 15, 124, 77, 16, 125, Blocks.SAND.getDefaultState());
        structure.fillWithBlocks(world, start, 77, 16, 47, 79, 18, 47, Blocks.SANDSTONE.getDefaultState());
        structure.fillWithBlocks(world, start, 77, 16, 48, 78, 16, 49, Blocks.STONE.getDefaultState());
        structure.fillWithBlocks(world, start, 77, 16, 51, 79, 16, 78, Blocks.SANDSTONE.getDefaultState());
        structure.fillWithBlocks(world, start, 77, 16, 86, 79, 16, 89, Blocks.SANDSTONE.getDefaultState());
        structure.fillWithBlocks(world, start, 77, 16, 120, 80, 16, 123, Blocks.SAND.getDefaultState());
        structure.fillWithBlocks(world, start, 77, 17, 48, 78, 17, 49, Blocks.STONE.getDefaultState());
        structure.fillWithBlocks(world, start, 77, 17, 51, 79, 17, 78, Blocks.SANDSTONE.getDefaultState());
        structure.fillWithBlocks(world, start, 77, 17, 90, 77, 19, 90, Blocks.SAND.getDefaultState());
        structure.fillWithBlocks(world, start, 77, 17, 118, 88, 17, 118, Blocks.SAND.getDefaultState());
        structure.fillWithBlocks(world, start, 77, 18, 45, 79, 18, 47, Blocks.SANDSTONE.getDefaultState());
        structure.fillWithBlocks(world, start, 77, 18, 48, 78, 18, 49, Blocks.STONE.getDefaultState());
        structure.fillWithBlocks(world, start, 77, 18, 51, 79, 18, 78, Blocks.SANDSTONE.getDefaultState());
        structure.fillWithBlocks(world, start, 77, 19, 47, 77, 23, 47, Blocks.SAND.getDefaultState());
        structure.fillWithBlocks(world, start, 77, 19, 48, 77, 20, 49, Blocks.SANDSTONE.getDefaultState());
        structure.fillWithBlocks(world, start, 77, 19, 51, 79, 19, 78, Blocks.SANDSTONE.getDefaultState());
        structure.fillWithBlocks(world, start, 77, 20, 50, 79, 20, 79, Blocks.SANDSTONE.getDefaultState());
        structure.fillWithBlocks(world, start, 77, 20, 89, 78, 20, 89, Blocks.SAND.getDefaultState());
        structure.fillWithBlocks(world, start, 77, 21, 48, 77, 21, 49, Blocks.SAND.getDefaultState());
        structure.fillWithBlocks(world, start, 77, 21, 50, 79, 21, 80, Blocks.SANDSTONE.getDefaultState());
        structure.fillWithBlocks(world, start, 77, 23, 51, 79, 23, 87, Blocks.SANDSTONE.getDefaultState());
        structure.fillWithBlocks(world, start, 77, 24, 51, 79, 24, 86, Blocks.SANDSTONE.getDefaultState());
        structure.fillWithBlocks(world, start, 77, 25, 51, 79, 25, 86, Blocks.SANDSTONE.getDefaultState());
        structure.fillWithBlocks(world, start, 77, 26, 51, 79, 26, 86, Blocks.SANDSTONE.getDefaultState());
        structure.fillWithBlocks(world, start, 77, 26, 87, 78, 27, 87, Blocks.SAND.getDefaultState());
        structure.fillWithBlocks(world, start, 77, 27, 51, 79, 27, 86, Blocks.SANDSTONE.getDefaultState());
        structure.fillWithBlocks(world, start, 77, 29, 50, 79, 29, 85, Blocks.SANDSTONE.getDefaultState());
        structure.fillWithBlocks(world, start, 77, 30, 50, 79, 30, 85, Blocks.SANDSTONE.getDefaultState());
        structure.fillWithBlocks(world, start, 77, 31, 49, 79, 31, 85, Blocks.SANDSTONE.getDefaultState());
        structure.fillWithBlocks(world, start, 77, 33, 86, 78, 33, 86, Blocks.SAND.getDefaultState());
        structure.fillWithBlocks(world, start, 77, 39, 58, 87, 39, 69, Blocks.SANDSTONE.getDefaultState());
        structure.fillWithBlocks(world, start, 77, 40, 52, 87, 41, 52, Blocks.SAND.getDefaultState());
        structure.fillWithBlocks(world, start, 77, 40, 53, 84, 40, 60, Blocks.SANDSTONE.getDefaultState());
        structure.fillWithBlocks(world, start, 77, 40, 61, 77, 40, 62, Blocks.SAND.getDefaultState());
        structure.fillWithBlocks(world, start, 77, 40, 64, 77, 40, 64, Blocks.SANDSTONE.getDefaultState());
        structure.fillWithBlocks(world, start, 77, 40, 65, 77, 42, 65, Blocks.SAND.getDefaultState());
        structure.fillWithBlocks(world, start, 77, 40, 66, 80, 40, 69, Blocks.SANDSTONE.getDefaultState());
        structure.fillWithBlocks(world, start, 77, 40, 70, 77, 43, 70, Blocks.SAND.getDefaultState());
        structure.fillWithBlocks(world, start, 77, 40, 83, 79, 40, 83, Blocks.SANDSTONE.getDefaultState());
        structure.fillWithBlocks(world, start, 77, 40, 84, 78, 40, 85, Blocks.SAND.getDefaultState());
        structure.fillWithBlocks(world, start, 77, 41, 53, 77, 42, 54, Blocks.SAND.getDefaultState());
        structure.fillWithBlocks(world, start, 77, 41, 55, 81, 41, 59, Blocks.SANDSTONE.getDefaultState());
        structure.fillWithBlocks(world, start, 77, 41, 60, 77, 41, 61, Blocks.SAND.getDefaultState());
        structure.fillWithBlocks(world, start, 77, 41, 64, 77, 41, 72, Blocks.SAND.getDefaultState());
        structure.fillWithBlocks(world, start, 77, 41, 73, 85, 41, 81, Blocks.SANDSTONE.getDefaultState());
        structure.fillWithBlocks(world, start, 77, 41, 83, 78, 41, 85, Blocks.SAND.getDefaultState());
        structure.fillWithBlocks(world, start, 77, 42, 57, 79, 42, 59, Blocks.SANDSTONE.getDefaultState());
        structure.fillWithBlocks(world, start, 77, 42, 60, 77, 43, 60, Blocks.SAND.getDefaultState());
        structure.fillWithBlocks(world, start, 77, 42, 76, 82, 42, 81, Blocks.SANDSTONE.getDefaultState());
        structure.fillWithBlocks(world, start, 77, 43, 53, 78, 43, 56, Blocks.SAND.getDefaultState());
        structure.fillWithBlocks(world, start, 77, 43, 57, 77, 43, 60, Blocks.SAND.getDefaultState());
        structure.fillWithBlocks(world, start, 77, 43, 66, 80, 43, 70, Blocks.SAND.getDefaultState());
        structure.fillWithBlocks(world, start, 77, 44, 55, 79, 44, 59, Blocks.SAND.getDefaultState());
        structure.fillWithBlocks(world, start, 77, 44, 72, 80, 44, 75, Blocks.SAND.getDefaultState());
        structure.fillWithBlocks(world, start, 77, 45, 57, 79, 45, 59, Blocks.SAND.getDefaultState());
        structure.fillWithBlocks(world, start, 77, 45, 76, 79, 45, 81, Blocks.SAND.getDefaultState());
        structure.fillWithBlocks(world, start, 78, -53, 10, 78, -50, 10, Blocks.SANDSTONE.getDefaultState());
        structure.fillWithBlocks(world, start, 78, -53, 12, 78, -53, 12, Blocks.SANDSTONE.getDefaultState());
        structure.fillWithBlocks(world, start, 78, -52, 9, 78, -52, 10, Blocks.SANDSTONE.getDefaultState());
        structure.fillWithBlocks(world, start, 78, -52, 21, 78, -52, 22, Blocks.SANDSTONE.getDefaultState());
        structure.fillWithBlocks(world, start, 78, -51, 21, 78, -51, 22, Blocks.SANDSTONE.getDefaultState());
        structure.fillWithBlocks(world, start, 78, -49, 5, 81, -49, 8, Blocks.SANDSTONE.getDefaultState());
        structure.fillWithBlocks(world, start, 78, -49, 11, 80, -49, 13, Blocks.AIR.getDefaultState());
        structure.fillWithBlocks(world, start, 78, -49, 28, 79, -49, 29, Blocks.AIR.getDefaultState());
        structure.fillWithBlocks(world, start, 78, -49, 61, 83, -49, 66, Blocks.AIR.getDefaultState());
        structure.fillWithBlocks(world, start, 78, -49, 69, 78, -46, 69, Blocks.AIR.getDefaultState());
        structure.fillWithBlocks(world, start, 78, -48, 5, 80, -48, 8, Blocks.SANDSTONE.getDefaultState());
        structure.fillWithBlocks(world, start, 78, -48, 11, 80, -48, 13, Blocks.AIR.getDefaultState());
        structure.fillWithBlocks(world, start, 78, -48, 70, 80, -48, 72, Blocks.SANDSTONE.getDefaultState());
        structure.fillWithBlocks(world, start, 78, -45, 11, 83, -45, 19, Blocks.SANDSTONE.getDefaultState());
        structure.fillWithBlocks(world, start, 78, -45, 20, 80, -45, 26, Blocks.SANDSTONE.getDefaultState());
        structure.fillWithBlocks(world, start, 78, -45, 28, 79, -45, 38, Blocks.SANDSTONE.getDefaultState());
        structure.fillWithBlocks(world, start, 78, -45, 52, 81, -45, 55, Blocks.SANDSTONE.getDefaultState());
        structure.fillWithBlocks(world, start, 78, -45, 69, 81, -45, 72, Blocks.SANDSTONE.getDefaultState());
        structure.fillWithBlocks(world, start, 78, -44, 23, 78, -44, 25, Blocks.AIR.getDefaultState());
        structure.fillWithBlocks(world, start, 78, -44, 27, 78, -44, 27, Blocks.SANDSTONE.getDefaultState());
        structure.fillWithBlocks(world, start, 78, -44, 28, 78, -44, 29, Blocks.AIR.getDefaultState());
        structure.fillWithBlocks(world, start, 78, -44, 31, 78, -44, 33, Blocks.SHROOMLIGHT.getDefaultState());
        structure.fillWithBlocks(world, start, 78, -44, 52, 81, -44, 55, Blocks.SANDSTONE.getDefaultState());
        structure.fillWithBlocks(world, start, 78, -44, 69, 81, -44, 72, Blocks.SANDSTONE.getDefaultState());
        structure.fillWithBlocks(world, start, 78, -43, 68, 80, -43, 70, Blocks.SANDSTONE.getDefaultState());
        structure.fillWithBlocks(world, start, 78, -43, 71, 80, -43, 77, Blocks.STONE_BRICKS.getDefaultState());
        structure.fillWithBlocks(world, start, 78, -42, 71, 78, -39, 77, Blocks.STONE_BRICKS.getDefaultState());
        structure.fillWithBlocks(world, start, 78, -41, 70, 79, -41, 71, Blocks.STONE_BRICKS.getDefaultState());
        structure.fillWithBlocks(world, start, 78, -40, -9, 81, -40, 10, Blocks.STONE_BRICKS.getDefaultState());
        structure.fillWithBlocks(world, start, 78, -40, 27, 80, -40, 29, Blocks.STONE_BRICKS.getDefaultState());
        structure.fillWithBlocks(world, start, 78, -40, 31, 78, -40, 31, Blocks.SANDSTONE.getDefaultState());
        structure.fillWithBlocks(world, start, 78, -40, 33, 78, -40, 33, Blocks.STONE_BRICKS.getDefaultState());
        structure.fillWithBlocks(world, start, 78, -40, 35, 78, -40, 35, Blocks.STONE_BRICKS.getDefaultState());
        structure.fillWithBlocks(world, start, 78, -40, 39, 78, -40, 40, Blocks.STONE_BRICKS.getDefaultState());
        structure.fillWithBlocks(world, start, 78, -40, 41, 78, -40, 42, Blocks.AIR.getDefaultState());
        structure.fillWithBlocks(world, start, 78, -40, 43, 87, -40, 52, Blocks.STONE_BRICKS.getDefaultState());
        structure.fillWithBlocks(world, start, 78, -40, 53, 78, -39, 53, Blocks.AIR.getDefaultState());
        structure.fillWithBlocks(world, start, 78, -40, 58, 80, -40, 60, Blocks.STONE_BRICKS.getDefaultState());
        structure.fillWithBlocks(world, start, 78, -40, 61, 78, -39, 61, Blocks.AIR.getDefaultState());
        structure.fillWithBlocks(world, start, 78, -40, 62, 79, -39, 62, Blocks.STONE_BRICKS.getDefaultState());
        structure.fillWithBlocks(world, start, 78, -40, 79, 78, -40, 80, Blocks.STONE_BRICKS.getDefaultState());
        structure.fillWithBlocks(world, start, 78, -39, -7, 79, -39, -4, Blocks.STONE_BRICKS.getDefaultState());
        structure.fillWithBlocks(world, start, 78, -39, -3, 78, -39, -3, Blocks.AIR.getDefaultState());
        structure.fillWithBlocks(world, start, 78, -39, -2, 78, -39, 3, Blocks.STONE_BRICKS.getDefaultState());
        structure.fillWithBlocks(world, start, 78, -39, 23, 78, -39, 23, Blocks.STONE_BRICKS.getDefaultState());
        structure.fillWithBlocks(world, start, 78, -39, 24, 78, -34, 24, Blocks.SANDSTONE.getDefaultState());
        structure.fillWithBlocks(world, start, 78, -39, 25, 78, -38, 26, Blocks.STONE_BRICKS.getDefaultState());
        structure.fillWithBlocks(world, start, 78, -39, 30, 78, -38, 31, Blocks.STONE_BRICKS.getDefaultState());
        structure.fillWithBlocks(world, start, 78, -39, 32, 78, -34, 32, Blocks.SANDSTONE.getDefaultState());
        structure.fillWithBlocks(world, start, 78, -39, 33, 79, -39, 35, Blocks.STONE_BRICKS.getDefaultState());
        structure.fillWithBlocks(world, start, 78, -39, 39, 78, -39, 40, Blocks.AIR.getDefaultState());
        structure.fillWithBlocks(world, start, 78, -39, 41, 79, -39, 42, Blocks.STONE_BRICKS.getDefaultState());
        structure.fillWithBlocks(world, start, 78, -39, 54, 78, -38, 55, Blocks.STONE_BRICKS.getDefaultState());
        structure.fillWithBlocks(world, start, 78, -39, 57, 79, -39, 60, Blocks.STONE_BRICKS.getDefaultState());
        structure.fillWithBlocks(world, start, 78, -39, 63, 79, -39, 64, Blocks.STONE_BRICKS.getDefaultState());
        structure.fillWithBlocks(world, start, 78, -39, 66, 79, -39, 69, Blocks.STONE_BRICKS.getDefaultState());
        structure.fillWithBlocks(world, start, 78, -38, -10, 80, -38, -7, Blocks.STONE_BRICKS.getDefaultState());
        structure.fillWithBlocks(world, start, 78, -38, -6, 78, -37, -5, Blocks.STONE_BRICKS.getDefaultState());
        structure.fillWithBlocks(world, start, 78, -38, 33, 79, -38, 35, Blocks.STONE_BRICKS.getDefaultState());
        structure.fillWithBlocks(world, start, 78, -38, 39, 79, -38, 41, Blocks.STONE_BRICKS.getDefaultState());
        structure.fillWithBlocks(world, start, 78, -38, 42, 78, -38, 49, Blocks.STONE_BRICKS.getDefaultState());
        structure.fillWithBlocks(world, start, 78, -38, 51, 78, -35, 54, Blocks.STONE_BRICKS.getDefaultState());
        structure.fillWithBlocks(world, start, 78, -38, 56, 79, -37, 56, Blocks.STONE_BRICKS.getDefaultState());
        structure.fillWithBlocks(world, start, 78, -38, 57, 79, -38, 57, Blocks.AIR.getDefaultState());
        structure.fillWithBlocks(world, start, 78, -38, 58, 78, -38, 62, Blocks.STONE_BRICKS.getDefaultState());
        structure.fillWithBlocks(world, start, 78, -38, 66, 79, -38, 68, Blocks.STONE_BRICKS.getDefaultState());
        structure.fillWithBlocks(world, start, 78, -38, 69, 78, -38, 69, Blocks.AIR.getDefaultState());
        structure.fillWithBlocks(world, start, 78, -38, 70, 78, -36, 72, Blocks.STONE_BRICKS.getDefaultState());
        structure.fillWithBlocks(world, start, 78, -38, 74, 78, -35, 77, Blocks.STONE_BRICKS.getDefaultState());
        structure.fillWithBlocks(world, start, 78, -38, 78, 80, -38, 80, Blocks.STONE_BRICKS.getDefaultState());
        structure.fillWithBlocks(world, start, 78, -37, -10, 78, -37, -10, Blocks.STONE_BRICKS.getDefaultState());
        structure.fillWithBlocks(world, start, 78, -37, -9, 78, -37, -9, Blocks.AIR.getDefaultState());
        structure.fillWithBlocks(world, start, 78, -37, -8, 78, -37, -5, Blocks.STONE_BRICKS.getDefaultState());
        structure.fillWithBlocks(world, start, 78, -37, -4, 78, -37, -3, Blocks.AIR.getDefaultState());
        structure.fillWithBlocks(world, start, 78, -37, -2, 78, -37, 3, Blocks.STONE_BRICKS.getDefaultState());
        structure.fillWithBlocks(world, start, 78, -37, 25, 78, -36, 26, Blocks.STONE_BRICKS.getDefaultState());
        structure.fillWithBlocks(world, start, 78, -37, 30, 78, -36, 31, Blocks.STONE_BRICKS.getDefaultState());
        structure.fillWithBlocks(world, start, 78, -37, 33, 79, -36, 33, Blocks.STONE_BRICKS.getDefaultState());
        structure.fillWithBlocks(world, start, 78, -37, 34, 79, -37, 34, Blocks.AIR.getDefaultState());
        structure.fillWithBlocks(world, start, 78, -37, 39, 79, -37, 43, Blocks.STONE_BRICKS.getDefaultState());
        structure.fillWithBlocks(world, start, 78, -37, 45, 79, -37, 47, Blocks.STONE_BRICKS.getDefaultState());
        structure.fillWithBlocks(world, start, 78, -37, 48, 78, -34, 54, Blocks.STONE_BRICKS.getDefaultState());
        structure.fillWithBlocks(world, start, 78, -37, 57, 78, -37, 57, Blocks.STONE_BRICKS.getDefaultState());
        structure.fillWithBlocks(world, start, 78, -37, 59, 79, -37, 62, Blocks.STONE_BRICKS.getDefaultState());
        structure.fillWithBlocks(world, start, 78, -37, 73, 78, -33, 77, Blocks.STONE_BRICKS.getDefaultState());
        structure.fillWithBlocks(world, start, 78, -36, -10, 80, -36, -8, Blocks.STONE_BRICKS.getDefaultState());
        structure.fillWithBlocks(world, start, 78, -36, -7, 79, -36, -6, Blocks.STONE_BRICKS.getDefaultState());
        structure.fillWithBlocks(world, start, 78, -36, -4, 79, -36, -3, Blocks.STONE_BRICKS.getDefaultState());
        structure.fillWithBlocks(world, start, 78, -36, 40, 79, -36, 41, Blocks.STONE_BRICKS.getDefaultState());
        structure.fillWithBlocks(world, start, 78, -36, 55, 79, -36, 57, Blocks.STONE_BRICKS.getDefaultState());
        structure.fillWithBlocks(world, start, 78, -36, 58, 78, -36, 64, Blocks.STONE_BRICKS.getDefaultState());
        structure.fillWithBlocks(world, start, 78, -36, 66, 80, -34, 66, Blocks.STONE_BRICKS.getDefaultState());
        structure.fillWithBlocks(world, start, 78, -36, 67, 79, -36, 67, Blocks.AIR.getDefaultState());
        structure.fillWithBlocks(world, start, 78, -36, 68, 79, -36, 69, Blocks.STONE_BRICKS.getDefaultState());
        structure.fillWithBlocks(world, start, 78, -35, -10, 79, -35, -7, Blocks.STONE_BRICKS.getDefaultState());
        structure.fillWithBlocks(world, start, 78, -35, -6, 80, -35, -6, Blocks.AIR.getDefaultState());
        structure.fillWithBlocks(world, start, 78, -35, -5, 79, -35, -3, Blocks.STONE_BRICKS.getDefaultState());
        structure.fillWithBlocks(world, start, 78, -35, -2, 78, -34, -1, Blocks.STONE_BRICKS.getDefaultState());
        structure.fillWithBlocks(world, start, 78, -35, 2, 78, -35, 3, Blocks.STONE_BRICKS.getDefaultState());
        structure.fillWithBlocks(world, start, 78, -35, 9, 79, -35, 10, Blocks.STONE_BRICKS.getDefaultState());
        structure.fillWithBlocks(world, start, 78, -35, 21, 78, -35, 21, Blocks.STONE_BRICKS.getDefaultState());
        structure.fillWithBlocks(world, start, 78, -35, 22, 78, -34, 22, Blocks.AIR.getDefaultState());
        structure.fillWithBlocks(world, start, 78, -35, 23, 79, -34, 23, Blocks.STONE_BRICKS.getDefaultState());
        structure.fillWithBlocks(world, start, 78, -35, 25, 78, -34, 32, Blocks.SANDSTONE.getDefaultState());
        structure.fillWithBlocks(world, start, 78, -35, 33, 81, -32, 33, Blocks.STONE_BRICKS.getDefaultState());
        structure.fillWithBlocks(world, start, 78, -35, 34, 80, -35, 34, Blocks.AIR.getDefaultState());
        structure.fillWithBlocks(world, start, 78, -35, 35, 79, -34, 35, Blocks.STONE_BRICKS.getDefaultState());
        structure.fillWithBlocks(world, start, 78, -35, 39, 78, -35, 39, Blocks.STONE_BRICKS.getDefaultState());
        structure.fillWithBlocks(world, start, 78, -35, 40, 78, -35, 41, Blocks.AIR.getDefaultState());
        structure.fillWithBlocks(world, start, 78, -35, 42, 78, -35, 43, Blocks.STONE_BRICKS.getDefaultState());
        structure.fillWithBlocks(world, start, 78, -35, 45, 78, -35, 45, Blocks.STONE_BRICKS.getDefaultState());
        structure.fillWithBlocks(world, start, 78, -35, 57, 80, -35, 59, Blocks.STONE_BRICKS.getDefaultState());
        structure.fillWithBlocks(world, start, 78, -35, 61, 79, -35, 62, Blocks.STONE_BRICKS.getDefaultState());
        structure.fillWithBlocks(world, start, 78, -35, 67, 80, -35, 69, Blocks.STONE_BRICKS.getDefaultState());
        structure.fillWithBlocks(world, start, 78, -35, 70, 78, -34, 77, Blocks.STONE_BRICKS.getDefaultState());
        structure.fillWithBlocks(world, start, 78, -35, 79, 79, -35, 80, Blocks.STONE_BRICKS.getDefaultState());
        structure.fillWithBlocks(world, start, 78, -34, -9, 78, -33, 1, Blocks.STONE_BRICKS.getDefaultState());
        structure.fillWithBlocks(world, start, 78, -34, 21, 91, -32, 21, Blocks.STONE_BRICKS.getDefaultState());
        structure.fillWithBlocks(world, start, 78, -34, 34, 79, -34, 35, Blocks.STONE_BRICKS.getDefaultState());
        structure.fillWithBlocks(world, start, 78, -34, 39, 78, -34, 43, Blocks.STONE_BRICKS.getDefaultState());
        structure.fillWithBlocks(world, start, 78, -34, 45, 79, -34, 59, Blocks.STONE_BRICKS.getDefaultState());
        structure.fillWithBlocks(world, start, 78, -34, 67, 80, -34, 80, Blocks.STONE_BRICKS.getDefaultState());
        structure.fillWithBlocks(world, start, 78, -33, -10, 80, -33, -6, Blocks.STONE_BRICKS.getDefaultState());
        structure.fillWithBlocks(world, start, 78, -33, 2, 78, -33, 3, Blocks.AIR.getDefaultState());
        structure.fillWithBlocks(world, start, 78, -33, 4, 79, -33, 7, Blocks.STONE_BRICKS.getDefaultState());
        structure.fillWithBlocks(world, start, 78, -33, 22, 79, -33, 23, Blocks.STONE_BRICKS.getDefaultState());
        structure.fillWithBlocks(world, start, 78, -33, 25, 78, -33, 35, Blocks.STONE_BRICKS.getDefaultState());
        structure.fillWithBlocks(world, start, 78, -33, 41, 81, -33, 44, Blocks.STONE_BRICKS.getDefaultState());
        structure.fillWithBlocks(world, start, 78, -33, 46, 80, -33, 48, Blocks.STONE_BRICKS.getDefaultState());
        structure.fillWithBlocks(world, start, 78, -33, 72, 78, -33, 72, Blocks.AIR.getDefaultState());
        structure.fillWithBlocks(world, start, 78, -32, -10, 82, -31, -10, Blocks.STONE_BRICKS.getDefaultState());
        structure.fillWithBlocks(world, start, 78, -32, -9, 78, -32, -8, Blocks.AIR.getDefaultState());
        structure.fillWithBlocks(world, start, 78, -32, 0, 78, -32, 1, Blocks.STONE_BRICKS.getDefaultState());
        structure.fillWithBlocks(world, start, 78, -32, 3, 79, -32, 5, Blocks.STONE_BRICKS.getDefaultState());
        structure.fillWithBlocks(world, start, 78, -32, 10, 92, -31, 10, Blocks.STONE_BRICKS.getDefaultState());
        structure.fillWithBlocks(world, start, 78, -32, 28, 79, -32, 28, Blocks.AIR.getDefaultState());
        structure.fillWithBlocks(world, start, 78, -32, 30, 78, -32, 35, Blocks.STONE_BRICKS.getDefaultState());
        structure.fillWithBlocks(world, start, 78, -32, 43, 81, -32, 46, Blocks.STONE_BRICKS.getDefaultState());
        structure.fillWithBlocks(world, start, 78, -32, 58, 79, -32, 59, Blocks.STONE_BRICKS.getDefaultState());
        structure.fillWithBlocks(world, start, 78, -32, 66, 78, -32, 66, Blocks.STONE_BRICKS.getDefaultState());
        structure.fillWithBlocks(world, start, 78, -32, 68, 78, -32, 68, Blocks.STONE_BRICKS.getDefaultState());
        structure.fillWithBlocks(world, start, 78, -32, 69, 78, -32, 70, Blocks.AIR.getDefaultState());
        structure.fillWithBlocks(world, start, 78, -32, 71, 79, -32, 72, Blocks.STONE_BRICKS.getDefaultState());
        structure.fillWithBlocks(world, start, 78, -32, 73, 78, -32, 73, Blocks.AIR.getDefaultState());
        structure.fillWithBlocks(world, start, 78, -31, 0, 78, -31, 1, Blocks.AIR.getDefaultState());
        structure.fillWithBlocks(world, start, 78, -31, 2, 78, -31, 4, Blocks.STONE_BRICKS.getDefaultState());
        structure.fillWithBlocks(world, start, 78, -31, 21, 78, -31, 21, Blocks.STONE_BRICKS.getDefaultState());
        structure.fillWithBlocks(world, start, 78, -31, 23, 79, -31, 24, Blocks.STONE_BRICKS.getDefaultState());
        structure.fillWithBlocks(world, start, 78, -31, 25, 78, -31, 28, Blocks.STONE_BRICKS.getDefaultState());
        structure.fillWithBlocks(world, start, 78, -31, 29, 78, -31, 29, Blocks.SANDSTONE.getDefaultState());
        structure.fillWithBlocks(world, start, 78, -31, 33, 78, -31, 33, Blocks.STONE_BRICKS.getDefaultState());
        structure.fillWithBlocks(world, start, 78, -31, 35, 89, -31, 35, Blocks.STONE_BRICKS.getDefaultState());
        structure.fillWithBlocks(world, start, 78, -31, 38, 82, -31, 42, Blocks.STONE_BRICKS.getDefaultState());
        structure.fillWithBlocks(world, start, 78, -31, 51, 78, -30, 51, Blocks.AIR.getDefaultState());
        structure.fillWithBlocks(world, start, 78, -31, 52, 78, -31, 62, Blocks.STONE_BRICKS.getDefaultState());
        structure.fillWithBlocks(world, start, 78, -31, 66, 81, -31, 69, Blocks.STONE_BRICKS.getDefaultState());
        structure.fillWithBlocks(world, start, 78, -30, -15, 78, -30, -14, Blocks.STONE_BRICKS.getDefaultState());
        structure.fillWithBlocks(world, start, 78, -30, -13, 80, -30, 31, Blocks.SANDSTONE.getDefaultState());
        structure.fillWithBlocks(world, start, 78, -30, 32, 78, -30, 36, Blocks.SANDSTONE.getDefaultState());
        structure.fillWithBlocks(world, start, 78, -30, 38, 79, -30, 38, Blocks.AIR.getDefaultState());
        structure.fillWithBlocks(world, start, 78, -30, 39, 79, -30, 40, Blocks.SANDSTONE.getDefaultState());
        structure.fillWithBlocks(world, start, 78, -30, 53, 78, -30, 54, Blocks.SANDSTONE.getDefaultState());
        structure.fillWithBlocks(world, start, 78, -29, -14, 80, -29, -14, Blocks.SANDSTONE.getDefaultState());
        structure.fillWithBlocks(world, start, 78, -29, -12, 78, -29, 23, Blocks.AIR.getDefaultState());
        structure.fillWithBlocks(world, start, 78, -29, 24, 78, -27, 24, Blocks.IRON_BARS.getDefaultState().with(FourWayBlock.WATERLOGGED, false).with(FourWayBlock.NORTH, true).with(FourWayBlock.SOUTH, true).with(FourWayBlock.EAST, true).with(FourWayBlock.WEST, true));
