package mod.arcalitegames.odyssey.world.structure.structures.dungeons.masoleum;

import mod.arcalitegames.odyssey.world.structure.StructureBase;
import net.minecraft.block.Blocks;
import net.minecraft.block.CactusBlock;
import net.minecraft.block.FourWayBlock;
import net.minecraft.block.StairsBlock;
import net.minecraft.state.properties.Half;
import net.minecraft.state.properties.StairsShape;
import net.minecraft.util.Direction;
import net.minecraft.util.math.BlockPos;
import net.minecraft.world.World;

public class MasoleumComponent4
{

	public static BlockPos start;
    public static World world;
    public static StructureBase structure;

    public static void init(World worldIn, BlockPos blockPos, StructureBase structureIn)
    {
        world = worldIn; start = blockPos; structure = structureIn;
    }
    
    public static void generatePart41()
    {
        structure.fillWithBlocks(world, start, 125, 21, 52, 132, 21, 59, Blocks.SANDSTONE.getDefaultState());
        structure.fillWithBlocks(world, start, 125, 22, 40, 126, 22, 40, Blocks.SANDSTONE_STAIRS.getDefaultState().with(StairsBlock.FACING, Direction.SOUTH).with(StairsBlock.WATERLOGGED, false).with(StairsBlock.SHAPE, StairsShape.STRAIGHT).with(StairsBlock.HALF, Half.TOP));
        structure.fillWithBlocks(world, start, 125, 22, 41, 126, 22, 51, Blocks.CUT_SANDSTONE.getDefaultState());
        structure.fillWithBlocks(world, start, 125, 22, 52, 132, 22, 59, Blocks.SANDSTONE.getDefaultState());
        structure.fillWithBlocks(world, start, 125, 22, 60, 127, 24, 60, Blocks.SANDSTONE.getDefaultState());
        structure.fillWithBlocks(world, start, 125, 23, 40, 126, 23, 40, Blocks.SANDSTONE_STAIRS.getDefaultState().with(StairsBlock.FACING, Direction.SOUTH).with(StairsBlock.WATERLOGGED, false).with(StairsBlock.SHAPE, StairsShape.STRAIGHT).with(StairsBlock.HALF, Half.BOTTOM));
        structure.fillWithBlocks(world, start, 125, 23, 41, 126, 23, 51, Blocks.CUT_SANDSTONE.getDefaultState());
        structure.fillWithBlocks(world, start, 125, 23, 52, 133, 23, 60, Blocks.SANDSTONE.getDefaultState());
        structure.fillWithBlocks(world, start, 125, 23, 61, 125, 25, 63, Blocks.SANDSTONE.getDefaultState());
        structure.fillWithBlocks(world, start, 125, 25, 77, 125, 46, 77, Blocks.SANDSTONE.getDefaultState());
        structure.fillWithBlocks(world, start, 125, 25, 105, 125, 56, 105, Blocks.SANDSTONE.getDefaultState());
        structure.fillWithBlocks(world, start, 125, 26, 43, 125, 27, 44, Blocks.CUT_SANDSTONE.getDefaultState());
        structure.fillWithBlocks(world, start, 125, 26, 49, 126, 26, 50, Blocks.CUT_SANDSTONE.getDefaultState());
        structure.fillWithBlocks(world, start, 125, 26, 76, 125, 27, 77, Blocks.SANDSTONE.getDefaultState());
        structure.fillWithBlocks(world, start, 125, 27, 49, 126, 27, 50, Blocks.CUT_SANDSTONE.getDefaultState());
        structure.fillWithBlocks(world, start, 125, 28, 43, 125, 29, 44, Blocks.CUT_SANDSTONE.getDefaultState());
        structure.fillWithBlocks(world, start, 125, 28, 49, 126, 28, 50, Blocks.CUT_SANDSTONE.getDefaultState());
        structure.fillWithBlocks(world, start, 125, 28, 66, 125, 45, 66, Blocks.SANDSTONE.getDefaultState());
        structure.fillWithBlocks(world, start, 125, 28, 75, 125, 30, 77, Blocks.SANDSTONE.getDefaultState());
        structure.fillWithBlocks(world, start, 125, 29, 49, 126, 29, 50, Blocks.CUT_SANDSTONE.getDefaultState());
        structure.fillWithBlocks(world, start, 125, 29, 73, 125, 34, 78, Blocks.SANDSTONE.getDefaultState());
        structure.fillWithBlocks(world, start, 125, 30, 43, 125, 31, 44, Blocks.CUT_SANDSTONE.getDefaultState());
        structure.fillWithBlocks(world, start, 125, 30, 49, 126, 30, 50, Blocks.CUT_SANDSTONE.getDefaultState());
        structure.fillWithBlocks(world, start, 125, 30, 67, 125, 35, 67, Blocks.STONE.getDefaultState());
        structure.fillWithBlocks(world, start, 125, 31, 49, 126, 31, 50, Blocks.CUT_SANDSTONE.getDefaultState());
        structure.fillWithBlocks(world, start, 125, 31, 72, 125, 35, 72, Blocks.STONE.getDefaultState());
        structure.fillWithBlocks(world, start, 125, 31, 79, 125, 46, 79, Blocks.SANDSTONE.getDefaultState());
        structure.fillWithBlocks(world, start, 125, 32, 43, 125, 33, 44, Blocks.CUT_SANDSTONE.getDefaultState());
        structure.fillWithBlocks(world, start, 125, 32, 49, 126, 32, 50, Blocks.CUT_SANDSTONE.getDefaultState());
        structure.fillWithBlocks(world, start, 125, 32, 71, 125, 34, 71, Blocks.SANDSTONE.getDefaultState());
        structure.fillWithBlocks(world, start, 125, 32, 104, 125, 33, 105, Blocks.SANDSTONE.getDefaultState());
        structure.fillWithBlocks(world, start, 125, 33, 49, 126, 33, 50, Blocks.CUT_SANDSTONE.getDefaultState());
        structure.fillWithBlocks(world, start, 125, 33, 80, 125, 47, 80, Blocks.SANDSTONE.getDefaultState());
        structure.fillWithBlocks(world, start, 125, 33, 81, 125, 47, 81, Blocks.STONE.getDefaultState());
        structure.fillWithBlocks(world, start, 125, 33, 103, 125, 35, 105, Blocks.SANDSTONE.getDefaultState());
        structure.fillWithBlocks(world, start, 125, 34, 43, 125, 35, 44, Blocks.CUT_SANDSTONE.getDefaultState());
        structure.fillWithBlocks(world, start, 125, 34, 49, 126, 34, 50, Blocks.CUT_SANDSTONE.getDefaultState());
        structure.fillWithBlocks(world, start, 125, 34, 101, 125, 38, 105, Blocks.SANDSTONE.getDefaultState());
        structure.fillWithBlocks(world, start, 125, 35, 49, 126, 35, 50, Blocks.CUT_SANDSTONE.getDefaultState());
        structure.fillWithBlocks(world, start, 125, 35, 73, 125, 42, 80, Blocks.SANDSTONE.getDefaultState());
        structure.fillWithBlocks(world, start, 125, 36, 43, 125, 37, 44, Blocks.CUT_SANDSTONE.getDefaultState());
        structure.fillWithBlocks(world, start, 125, 36, 49, 126, 36, 50, Blocks.CUT_SANDSTONE.getDefaultState());
        structure.fillWithBlocks(world, start, 125, 36, 72, 125, 38, 80, Blocks.SANDSTONE.getDefaultState());
        structure.fillWithBlocks(world, start, 125, 37, 49, 126, 37, 50, Blocks.CUT_SANDSTONE.getDefaultState());
        structure.fillWithBlocks(world, start, 125, 38, 43, 125, 39, 44, Blocks.CUT_SANDSTONE.getDefaultState());
        structure.fillWithBlocks(world, start, 125, 38, 49, 126, 38, 50, Blocks.CUT_SANDSTONE.getDefaultState());
        structure.fillWithBlocks(world, start, 125, 39, 49, 126, 39, 50, Blocks.CUT_SANDSTONE.getDefaultState());
        structure.fillWithBlocks(world, start, 125, 39, 100, 125, 44, 105, Blocks.SANDSTONE.getDefaultState());
        structure.fillWithBlocks(world, start, 125, 39, 106, 125, 40, 106, Blocks.SANDSTONE.getDefaultState());
        structure.fillWithBlocks(world, start, 125, 40, 43, 125, 41, 44, Blocks.CUT_SANDSTONE.getDefaultState());
        structure.fillWithBlocks(world, start, 125, 40, 49, 126, 40, 50, Blocks.CUT_SANDSTONE.getDefaultState());
        structure.fillWithBlocks(world, start, 125, 40, 61, 125, 40, 61, Blocks.SAND.getDefaultState());
        structure.fillWithBlocks(world, start, 125, 40, 62, 125, 41, 66, Blocks.SANDSTONE.getDefaultState());
        structure.fillWithBlocks(world, start, 125, 41, 46, 125, 41, 47, Blocks.SANDSTONE_STAIRS.getDefaultState().with(StairsBlock.FACING, Direction.EAST).with(StairsBlock.WATERLOGGED, false).with(StairsBlock.SHAPE, StairsShape.STRAIGHT).with(StairsBlock.HALF, Half.TOP));
        structure.fillWithBlocks(world, start, 125, 41, 49, 126, 41, 51, Blocks.CUT_SANDSTONE.getDefaultState());
        structure.fillWithBlocks(world, start, 125, 41, 52, 125, 41, 60, Blocks.SANDSTONE.getDefaultState());
        structure.fillWithBlocks(world, start, 125, 41, 61, 125, 41, 61, Blocks.SAND.getDefaultState());
        structure.fillWithBlocks(world, start, 125, 41, 106, 125, 45, 106, Blocks.SAND.getDefaultState());
        structure.fillWithBlocks(world, start, 125, 42, 42, 125, 43, 42, Blocks.CUT_SANDSTONE.getDefaultState());
        structure.fillWithBlocks(world, start, 125, 42, 44, 125, 42, 44, Blocks.CUT_SANDSTONE.getDefaultState());
        structure.fillWithBlocks(world, start, 125, 42, 46, 125, 42, 46, Blocks.CUT_SANDSTONE.getDefaultState());
        structure.fillWithBlocks(world, start, 125, 42, 48, 125, 42, 48, Blocks.CUT_SANDSTONE.getDefaultState());
        structure.fillWithBlocks(world, start, 125, 42, 52, 129, 44, 52, Blocks.SAND.getDefaultState());
        structure.fillWithBlocks(world, start, 125, 42, 55, 127, 42, 57, Blocks.SANDSTONE.getDefaultState());
        structure.fillWithBlocks(world, start, 125, 42, 58, 125, 42, 59, Blocks.SANDSTONE.getDefaultState());
        structure.fillWithBlocks(world, start, 125, 42, 60, 125, 43, 62, Blocks.SAND.getDefaultState());
        structure.fillWithBlocks(world, start, 125, 42, 63, 125, 42, 66, Blocks.SANDSTONE.getDefaultState());
        structure.fillWithBlocks(world, start, 125, 42, 72, 125, 45, 80, Blocks.SANDSTONE.getDefaultState());
        structure.fillWithBlocks(world, start, 125, 43, 44, 125, 43, 44, Blocks.CUT_SANDSTONE.getDefaultState());
        structure.fillWithBlocks(world, start, 125, 43, 46, 125, 43, 46, Blocks.CUT_SANDSTONE.getDefaultState());
        structure.fillWithBlocks(world, start, 125, 43, 48, 125, 43, 48, Blocks.CUT_SANDSTONE.getDefaultState());
        structure.fillWithBlocks(world, start, 125, 43, 53, 129, 45, 53, Blocks.SAND.getDefaultState());
        structure.fillWithBlocks(world, start, 125, 43, 55, 127, 43, 57, Blocks.SANDSTONE.getDefaultState());
        structure.fillWithBlocks(world, start, 125, 43, 58, 125, 44, 58, Blocks.SANDSTONE.getDefaultState());
        structure.fillWithBlocks(world, start, 125, 43, 59, 125, 44, 60, Blocks.SAND.getDefaultState());
        structure.fillWithBlocks(world, start, 125, 43, 63, 125, 46, 63, Blocks.SAND.getDefaultState());
        structure.fillWithBlocks(world, start, 125, 43, 64, 125, 45, 67, Blocks.SANDSTONE.getDefaultState());
        structure.fillWithBlocks(world, start, 125, 44, 42, 125, 44, 49, Blocks.CHISELED_SANDSTONE.getDefaultState());
        structure.fillWithBlocks(world, start, 125, 44, 50, 126, 44, 51, Blocks.CUT_SANDSTONE.getDefaultState());
        structure.fillWithBlocks(world, start, 125, 44, 54, 125, 44, 58, Blocks.SANDSTONE.getDefaultState());
        structure.fillWithBlocks(world, start, 125, 44, 62, 125, 45, 63, Blocks.SAND.getDefaultState());
        structure.fillWithBlocks(world, start, 125, 45, 41, 127, 45, 41, Blocks.SANDSTONE_STAIRS.getDefaultState().with(StairsBlock.FACING, Direction.SOUTH).with(StairsBlock.WATERLOGGED, false).with(StairsBlock.SHAPE, StairsShape.STRAIGHT).with(StairsBlock.HALF, Half.TOP));
        structure.fillWithBlocks(world, start, 125, 45, 42, 127, 45, 51, Blocks.CUT_SANDSTONE.getDefaultState());
        structure.fillWithBlocks(world, start, 125, 45, 55, 126, 45, 56, Blocks.SAND.getDefaultState());
        structure.fillWithBlocks(world, start, 125, 45, 57, 125, 45, 60, Blocks.SAND.getDefaultState());
        structure.fillWithBlocks(world, start, 125, 45, 71, 125, 45, 80, Blocks.SANDSTONE.getDefaultState());
        structure.fillWithBlocks(world, start, 125, 45, 82, 125, 47, 82, Blocks.STONE.getDefaultState());
        structure.fillWithBlocks(world, start, 125, 45, 100, 125, 50, 105, Blocks.SANDSTONE.getDefaultState());
        structure.fillWithBlocks(world, start, 125, 46, 64, 125, 49, 67, Blocks.SAND.getDefaultState());
        structure.fillWithBlocks(world, start, 125, 46, 71, 125, 47, 72, Blocks.SAND.getDefaultState());
        structure.fillWithBlocks(world, start, 125, 46, 73, 125, 46, 80, Blocks.SANDSTONE.getDefaultState());
        structure.fillWithBlocks(world, start, 125, 46, 99, 125, 52, 105, Blocks.SANDSTONE.getDefaultState());
        structure.fillWithBlocks(world, start, 125, 47, 53, 126, 47, 57, Blocks.SAND.getDefaultState());
        structure.fillWithBlocks(world, start, 125, 47, 58, 125, 49, 58, Blocks.SAND.getDefaultState());
        structure.fillWithBlocks(world, start, 125, 47, 73, 125, 50, 79, Blocks.SAND.getDefaultState());
        structure.fillWithBlocks(world, start, 125, 48, 71, 125, 49, 80, Blocks.SAND.getDefaultState());
        structure.fillWithBlocks(world, start, 125, 48, 81, 125, 49, 82, Blocks.SANDSTONE.getDefaultState());
        structure.fillWithBlocks(world, start, 125, 48, 98, 125, 55, 105, Blocks.SANDSTONE.getDefaultState());
        structure.fillWithBlocks(world, start, 125, 49, 54, 125, 49, 58, Blocks.SAND.getDefaultState());
        structure.fillWithBlocks(world, start, 125, 49, 97, 125, 56, 105, Blocks.SANDSTONE.getDefaultState());
        structure.fillWithBlocks(world, start, 125, 50, 80, 125, 51, 80, Blocks.SAND.getDefaultState());
        structure.fillWithBlocks(world, start, 125, 51, 81, 125, 51, 82, Blocks.SAND.getDefaultState());
        structure.fillWithBlocks(world, start, 125, 52, 96, 125, 52, 105, Blocks.SANDSTONE.getDefaultState());
        structure.fillWithBlocks(world, start, 125, 53, 95, 125, 59, 101, Blocks.SANDSTONE.getDefaultState());
        structure.fillWithBlocks(world, start, 125, 56, 93, 125, 58, 103, Blocks.SANDSTONE.getDefaultState());
        structure.fillWithBlocks(world, start, 125, 57, 105, 126, 58, 105, Blocks.SAND.getDefaultState());
        structure.fillWithBlocks(world, start, 125, 58, 104, 126, 58, 105, Blocks.SAND.getDefaultState());
        structure.fillWithBlocks(world, start, 125, 59, 93, 125, 60, 94, Blocks.SAND.getDefaultState());
        structure.fillWithBlocks(world, start, 125, 59, 102, 127, 59, 104, Blocks.SAND.getDefaultState());
        structure.fillWithBlocks(world, start, 125, 60, 96, 127, 62, 96, Blocks.SAND.getDefaultState());
        structure.fillWithBlocks(world, start, 125, 60, 97, 125, 60, 98, Blocks.SANDSTONE.getDefaultState());
        structure.fillWithBlocks(world, start, 125, 60, 99, 128, 60, 103, Blocks.SAND.getDefaultState());
        structure.fillWithBlocks(world, start, 125, 60, 105, 126, 60, 105, Blocks.SAND.getDefaultState());
        structure.fillWithBlocks(world, start, 125, 61, 93, 125, 62, 103, Blocks.SAND.getDefaultState());
        structure.fillWithBlocks(world, start, 125, 63, 95, 125, 63, 101, Blocks.SAND.getDefaultState());
        structure.fillWithBlocks(world, start, 125, 64, 97, 125, 64, 98, Blocks.SAND.getDefaultState());
        structure.fillWithBlocks(world, start, 125, 65, 81, 125, 66, 82, Blocks.SANDSTONE.getDefaultState());
        structure.fillWithBlocks(world, start, 125, 67, 81, 125, 68, 82, Blocks.SANDSTONE.getDefaultState());
        structure.fillWithBlocks(world, start, 125, 69, 81, 125, 69, 82, Blocks.SANDSTONE.getDefaultState());
        structure.fillWithBlocks(world, start, 125, 70, 82, 125, 73, 82, Blocks.SAND.getDefaultState());
        structure.fillWithBlocks(world, start, 125, 72, 81, 125, 73, 82, Blocks.SAND.getDefaultState());
        structure.fillWithBlocks(world, start, 126, -49, -24, 128, -49, 54, Blocks.AIR.getDefaultState());
        structure.fillWithBlocks(world, start, 126, -49, 62, 128, -47, 62, Blocks.AIR.getDefaultState());
        structure.fillWithBlocks(world, start, 126, -49, 63, 128, -49, 65, Blocks.SANDSTONE.getDefaultState());
        structure.fillWithBlocks(world, start, 126, -48, -24, 128, -48, 62, Blocks.AIR.getDefaultState());
        structure.fillWithBlocks(world, start, 126, -47, -24, 128, -47, 62, Blocks.AIR.getDefaultState());
        structure.fillWithBlocks(world, start, 126, -47, 63, 128, -47, 65, Blocks.SANDSTONE.getDefaultState());
        structure.fillWithBlocks(world, start, 126, -46, -24, 129, -46, 0, Blocks.SANDSTONE.getDefaultState());
        structure.fillWithBlocks(world, start, 126, -46, 1, 128, -46, 15, Blocks.AIR.getDefaultState());
        structure.fillWithBlocks(world, start, 126, -46, 16, 131, -46, 21, Blocks.SANDSTONE.getDefaultState());
        structure.fillWithBlocks(world, start, 126, -46, 48, 128, -46, 62, Blocks.AIR.getDefaultState());
        structure.fillWithBlocks(world, start, 126, -46, 63, 128, -46, 65, Blocks.SANDSTONE.getDefaultState());
        structure.fillWithBlocks(world, start, 126, -45, -2, 128, -45, 0, Blocks.SANDSTONE.getDefaultState());
        structure.fillWithBlocks(world, start, 126, -45, 1, 128, -45, 15, Blocks.AIR.getDefaultState());
        structure.fillWithBlocks(world, start, 126, -45, 16, 131, -45, 21, Blocks.SANDSTONE.getDefaultState());
        structure.fillWithBlocks(world, start, 126, -43, 34, 129, -43, 37, Blocks.SANDSTONE.getDefaultState());
        structure.fillWithBlocks(world, start, 126, -41, 47, 127, -41, 64, Blocks.SANDSTONE.getDefaultState());
        structure.fillWithBlocks(world, start, 126, -40, 22, 127, -40, 23, Blocks.STONE_BRICKS.getDefaultState());
        structure.fillWithBlocks(world, start, 126, -40, 31, 127, -40, 32, Blocks.SANDSTONE.getDefaultState());
        structure.fillWithBlocks(world, start, 126, -40, 42, 127, -40, 43, Blocks.STONE_BRICKS.getDefaultState());
        structure.fillWithBlocks(world, start, 126, -40, 47, 127, -40, 67, Blocks.STONE_BRICKS.getDefaultState());
        structure.fillWithBlocks(world, start, 126, -40, 71, 126, -40, 71, Blocks.STONE_BRICKS.getDefaultState());
        structure.fillWithBlocks(world, start, 126, -39, 72, 132, -35, 72, Blocks.STONE_BRICKS.getDefaultState());
        structure.fillWithBlocks(world, start, 126, -38, 22, 127, -38, 23, Blocks.STONE_BRICKS.getDefaultState());
        structure.fillWithBlocks(world, start, 126, -38, 24, 126, -37, 25, Blocks.STONE_BRICKS.getDefaultState());
        structure.fillWithBlocks(world, start, 126, -38, 31, 132, -37, 31, Blocks.STONE_BRICKS.getDefaultState());
        structure.fillWithBlocks(world, start, 126, -37, 22, 127, -37, 23, Blocks.STONE_BRICKS.getDefaultState());
        structure.fillWithBlocks(world, start, 126, -35, 43, 126, -35, 43, Blocks.STONE_BRICKS.getDefaultState());
        structure.fillWithBlocks(world, start, 126, -34, 43, 126, -34, 71, Blocks.STONE_BRICKS.getDefaultState());
        structure.fillWithBlocks(world, start, 126, -33, 43, 126, -33, 43, Blocks.STONE_BRICKS.getDefaultState());
        structure.fillWithBlocks(world, start, 126, -33, 45, 127, -33, 52, Blocks.STONE_BRICKS.getDefaultState());
        structure.fillWithBlocks(world, start, 126, -33, 54, 126, -31, 57, Blocks.STONE_BRICKS.getDefaultState());
        structure.fillWithBlocks(world, start, 126, -33, 58, 126, -33, 58, Blocks.STONE_BRICKS.getDefaultState());
        structure.fillWithBlocks(world, start, 126, -33, 60, 126, -31, 68, Blocks.STONE_BRICKS.getDefaultState());
        structure.fillWithBlocks(world, start, 126, -32, 42, 126, -32, 42, Blocks.STONE_BRICKS.getDefaultState());
        structure.fillWithBlocks(world, start, 126, -32, 44, 129, -32, 47, Blocks.STONE_BRICKS.getDefaultState());
        structure.fillWithBlocks(world, start, 126, -32, 48, 127, -32, 48, Blocks.AIR.getDefaultState());
        structure.fillWithBlocks(world, start, 126, -32, 49, 127, -32, 57, Blocks.STONE_BRICKS.getDefaultState());
        structure.fillWithBlocks(world, start, 126, -32, 59, 128, -32, 61, Blocks.STONE_BRICKS.getDefaultState());
        structure.fillWithBlocks(world, start, 126, -32, 70, 128, -32, 72, Blocks.STONE_BRICKS.getDefaultState());
        structure.fillWithBlocks(world, start, 126, -31, 69, 129, -31, 72, Blocks.STONE_BRICKS.getDefaultState());
        structure.fillWithBlocks(world, start, 126, -19, 26, 126, -19, 30, Blocks.AIR.getDefaultState());
        structure.fillWithBlocks(world, start, 126, -19, 57, 127, -19, 58, Blocks.SANDSTONE.getDefaultState());
        structure.fillWithBlocks(world, start, 126, -19, 71, 127, -19, 74, Blocks.SANDSTONE.getDefaultState());
        structure.fillWithBlocks(world, start, 126, -18, 25, 126, -17, 25, Blocks.STONE_BRICKS.getDefaultState());
        structure.fillWithBlocks(world, start, 126, -18, 31, 126, -17, 31, Blocks.STONE_BRICKS.getDefaultState());
        structure.fillWithBlocks(world, start, 126, -18, 56, 128, -18, 58, Blocks.SANDSTONE.getDefaultState());
        structure.fillWithBlocks(world, start, 126, -18, 70, 127, -18, 71, Blocks.SANDSTONE.getDefaultState());
        structure.fillWithBlocks(world, start, 126, -18, 72, 126, -11, 72, Blocks.SANDSTONE.getDefaultState());
        structure.fillWithBlocks(world, start, 126, -18, 73, 126, -18, 73, Blocks.AIR.getDefaultState());
        structure.fillWithBlocks(world, start, 126, -17, 70, 127, -17, 70, Blocks.AIR.getDefaultState());
        structure.fillWithBlocks(world, start, 126, -17, 71, 129, -17, 74, Blocks.SANDSTONE.getDefaultState());
        structure.fillWithBlocks(world, start, 126, -16, 26, 130, -16, 30, Blocks.SANDSTONE.getDefaultState());
        structure.fillWithBlocks(world, start, 126, -15, 50, 126, -15, 50, Blocks.SANDSTONE.getDefaultState());
        structure.fillWithBlocks(world, start, 126, -15, 52, 131, -15, 59, Blocks.SANDSTONE.getDefaultState());
        structure.fillWithBlocks(world, start, 126, -14, 61, 128, -14, 63, Blocks.AIR.getDefaultState());
        structure.fillWithBlocks(world, start, 126, -13, 50, 130, -13, 54, Blocks.SANDSTONE.getDefaultState());
        structure.fillWithBlocks(world, start, 126, -13, 55, 126, -13, 74, Blocks.SANDSTONE.getDefaultState());
        structure.fillWithBlocks(world, start, 126, -12, 51, 129, -12, 54, Blocks.SANDSTONE.getDefaultState());
        structure.fillWithBlocks(world, start, 126, -12, 55, 127, -12, 57, Blocks.SANDSTONE.getDefaultState());
        structure.fillWithBlocks(world, start, 126, -12, 58, 126, -12, 59, Blocks.SANDSTONE.getDefaultState());
        structure.fillWithBlocks(world, start, 126, -12, 61, 129, -12, 67, Blocks.SANDSTONE.getDefaultState());
        structure.fillWithBlocks(world, start, 126, -12, 69, 128, -12, 74, Blocks.SANDSTONE.getDefaultState());
        structure.fillWithBlocks(world, start, 126, -11, 50, 126, -11, 53, Blocks.SANDSTONE.getDefaultState());
        structure.fillWithBlocks(world, start, 126, -11, 57, 126, -11, 58, Blocks.AIR.getDefaultState());
        structure.fillWithBlocks(world, start, 126, -11, 60, 127, -11, 68, Blocks.SANDSTONE.getDefaultState());
        structure.fillWithBlocks(world, start, 126, -10, 32, 128, -10, 34, Blocks.SANDSTONE.getDefaultState());
        structure.fillWithBlocks(world, start, 126, -9, 22, 128, -9, 24, Blocks.SANDSTONE.getDefaultState());
        structure.fillWithBlocks(world, start, 126, -9, 25, 128, -9, 27, Blocks.AIR.getDefaultState());
        structure.fillWithBlocks(world, start, 126, -9, 29, 128, -9, 31, Blocks.AIR.getDefaultState());
        structure.fillWithBlocks(world, start, 126, -9, 32, 128, -9, 34, Blocks.SANDSTONE.getDefaultState());
        structure.fillWithBlocks(world, start, 126, -8, 22, 128, -8, 24, Blocks.SANDSTONE.getDefaultState());
        structure.fillWithBlocks(world, start, 126, -8, 25, 128, -8, 27, Blocks.AIR.getDefaultState());
        structure.fillWithBlocks(world, start, 126, -8, 31, 130, -6, 31, Blocks.AIR.getDefaultState());
        structure.fillWithBlocks(world, start, 126, -8, 32, 128, -8, 34, Blocks.SANDSTONE.getDefaultState());
        structure.fillWithBlocks(world, start, 126, -8, 55, 126, -7, 55, Blocks.STONE_BRICKS.getDefaultState());
        structure.fillWithBlocks(world, start, 126, -8, 61, 126, -7, 61, Blocks.STONE_BRICKS.getDefaultState());
        structure.fillWithBlocks(world, start, 126, -7, 22, 128, -7, 24, Blocks.SANDSTONE.getDefaultState());
        structure.fillWithBlocks(world, start, 126, -7, 25, 130, -7, 31, Blocks.AIR.getDefaultState());
        structure.fillWithBlocks(world, start, 126, -7, 32, 128, -7, 34, Blocks.SANDSTONE.getDefaultState());
        structure.fillWithBlocks(world, start, 126, -6, 23, 127, -6, 24, Blocks.SANDSTONE.getDefaultState());
        structure.fillWithBlocks(world, start, 126, -6, 25, 130, -6, 31, Blocks.AIR.getDefaultState());
        structure.fillWithBlocks(world, start, 126, -6, 32, 128, -6, 34, Blocks.SANDSTONE.getDefaultState());
        structure.fillWithBlocks(world, start, 126, -5, 27, 128, -5, 29, Blocks.AIR.getDefaultState());
        structure.fillWithBlocks(world, start, 126, -5, 30, 126, -5, 32, Blocks.SANDSTONE.getDefaultState());
        structure.fillWithBlocks(world, start, 126, -4, 22, 128, -4, 27, Blocks.SANDSTONE.getDefaultState());
        structure.fillWithBlocks(world, start, 126, -4, 28, 127, -4, 34, Blocks.SANDSTONE.getDefaultState());
        structure.fillWithBlocks(world, start, 126, -3, 26, 126, -3, 26, Blocks.SANDSTONE.getDefaultState());
        structure.fillWithBlocks(world, start, 126, -3, 28, 130, -3, 33, Blocks.SANDSTONE.getDefaultState());
        structure.fillWithBlocks(world, start, 126, -2, 31, 128, -2, 34, Blocks.SANDSTONE.getDefaultState());
        structure.fillWithBlocks(world, start, 126, -1, 22, 126, -1, 24, Blocks.SANDSTONE.getDefaultState());
        structure.fillWithBlocks(world, start, 126, -1, 26, 130, -1, 30, Blocks.SANDSTONE.getDefaultState());
        structure.fillWithBlocks(world, start, 126, 0, 10, 126, 4, 10, Blocks.SANDSTONE.getDefaultState());
        structure.fillWithBlocks(world, start, 126, 0, 11, 131, 0, 151, Blocks.STONE.getDefaultState());
        structure.fillWithBlocks(world, start, 126, 1, 16, 205, 1, 136, Blocks.STONE.getDefaultState());
        structure.fillWithBlocks(world, start, 126, 1, 144, 128, 1, 146, Blocks.STONE.getDefaultState());
        structure.fillWithBlocks(world, start, 126, 1, 147, 128, 1, 149, Blocks.SANDSTONE.getDefaultState());
        structure.fillWithBlocks(world, start, 126, 1, 152, 131, 1, 157, Blocks.SANDSTONE.getDefaultState());
        structure.fillWithBlocks(world, start, 126, 2, 144, 127, 2, 145, Blocks.STONE.getDefaultState());
        structure.fillWithBlocks(world, start, 126, 3, 7, 138, 3, 19, Blocks.SANDSTONE.getDefaultState());
        structure.fillWithBlocks(world, start, 126, 6, 16, 203, 6, 141, Blocks.SANDSTONE.getDefaultState());
        structure.fillWithBlocks(world, start, 126, 9, 85, 126, 10, 85, Blocks.SAND.getDefaultState());
        structure.fillWithBlocks(world, start, 126, 9, 94, 126, 12, 94, Blocks.SAND.getDefaultState());
        structure.fillWithBlocks(world, start, 126, 12, 56, 128, 12, 58, Blocks.SANDSTONE.getDefaultState());
        structure.fillWithBlocks(world, start, 126, 13, 57, 127, 13, 58, Blocks.SANDSTONE.getDefaultState());
        structure.fillWithBlocks(world, start, 126, 14, 58, 137, 25, 58, Blocks.SANDSTONE.getDefaultState());
        structure.fillWithBlocks(world, start, 126, 15, 54, 127, 15, 55, Blocks.SANDSTONE.getDefaultState());
        structure.fillWithBlocks(world, start, 126, 15, 57, 127, 15, 58, Blocks.SANDSTONE.getDefaultState());
        structure.fillWithBlocks(world, start, 126, 18, 52, 132, 18, 58, Blocks.SANDSTONE.getDefaultState());
        structure.fillWithBlocks(world, start, 126, 23, 61, 127, 24, 61, Blocks.SANDSTONE.getDefaultState());
        structure.fillWithBlocks(world, start, 126, 24, 52, 135, 24, 61, Blocks.SANDSTONE.getDefaultState());
        structure.fillWithBlocks(world, start, 126, 24, 62, 126, 25, 63, Blocks.SANDSTONE.getDefaultState());
        structure.fillWithBlocks(world, start, 126, 25, 52, 135, 25, 61, Blocks.SANDSTONE.getDefaultState());
        structure.fillWithBlocks(world, start, 126, 25, 64, 126, 39, 64, Blocks.SANDSTONE.getDefaultState());
        structure.fillWithBlocks(world, start, 126, 26, 41, 127, 26, 41, Blocks.SANDSTONE_STAIRS.getDefaultState().with(StairsBlock.FACING, Direction.SOUTH).with(StairsBlock.WATERLOGGED, false).with(StairsBlock.SHAPE, StairsShape.STRAIGHT).with(StairsBlock.HALF, Half.BOTTOM));
        structure.fillWithBlocks(world, start, 126, 26, 42, 127, 26, 43, Blocks.CUT_SANDSTONE.getDefaultState());
        structure.fillWithBlocks(world, start, 126, 26, 44, 126, 30, 48, Blocks.SMOOTH_SANDSTONE.getDefaultState());
        structure.fillWithBlocks(world, start, 126, 26, 51, 126, 40, 51, Blocks.SMOOTH_SANDSTONE.getDefaultState());
        structure.fillWithBlocks(world, start, 126, 27, 42, 127, 27, 43, Blocks.CUT_SANDSTONE.getDefaultState());
        structure.fillWithBlocks(world, start, 126, 28, 42, 127, 28, 43, Blocks.CUT_SANDSTONE.getDefaultState());
        structure.fillWithBlocks(world, start, 126, 29, 42, 127, 29, 43, Blocks.CUT_SANDSTONE.getDefaultState());
        structure.fillWithBlocks(world, start, 126, 30, 42, 127, 30, 43, Blocks.CUT_SANDSTONE.getDefaultState());
        structure.fillWithBlocks(world, start, 126, 31, 42, 127, 31, 43, Blocks.CUT_SANDSTONE.getDefaultState());
        structure.fillWithBlocks(world, start, 126, 31, 44, 126, 35, 48, Blocks.SMOOTH_SANDSTONE.getDefaultState());
        structure.fillWithBlocks(world, start, 126, 32, 42, 127, 32, 43, Blocks.CUT_SANDSTONE.getDefaultState());
        structure.fillWithBlocks(world, start, 126, 33, 42, 127, 33, 43, Blocks.CUT_SANDSTONE.getDefaultState());
        structure.fillWithBlocks(world, start, 126, 34, 42, 127, 34, 43, Blocks.CUT_SANDSTONE.getDefaultState());
        structure.fillWithBlocks(world, start, 126, 35, 42, 127, 35, 43, Blocks.CUT_SANDSTONE.getDefaultState());
        structure.fillWithBlocks(world, start, 126, 36, 42, 127, 36, 43, Blocks.CUT_SANDSTONE.getDefaultState());
        structure.fillWithBlocks(world, start, 126, 36, 44, 126, 40, 48, Blocks.SMOOTH_SANDSTONE.getDefaultState());
        structure.fillWithBlocks(world, start, 126, 36, 52, 132, 36, 58, Blocks.SANDSTONE.getDefaultState());
        structure.fillWithBlocks(world, start, 126, 36, 59, 126, 37, 66, Blocks.SANDSTONE.getDefaultState());
        structure.fillWithBlocks(world, start, 126, 37, 42, 127, 37, 43, Blocks.CUT_SANDSTONE.getDefaultState());
        structure.fillWithBlocks(world, start, 126, 37, 52, 132, 37, 58, Blocks.SANDSTONE.getDefaultState());
        structure.fillWithBlocks(world, start, 126, 38, 42, 127, 38, 43, Blocks.CUT_SANDSTONE.getDefaultState());
        structure.fillWithBlocks(world, start, 126, 38, 52, 130, 38, 57, Blocks.SANDSTONE.getDefaultState());
        structure.fillWithBlocks(world, start, 126, 38, 58, 126, 39, 59, Blocks.SANDSTONE.getDefaultState());
        structure.fillWithBlocks(world, start, 126, 38, 60, 126, 40, 62, Blocks.SAND.getDefaultState());
        structure.fillWithBlocks(world, start, 126, 38, 63, 126, 38, 66, Blocks.SANDSTONE.getDefaultState());
        structure.fillWithBlocks(world, start, 126, 39, 42, 127, 39, 43, Blocks.CUT_SANDSTONE.getDefaultState());
        structure.fillWithBlocks(world, start, 126, 39, 52, 129, 39, 57, Blocks.SANDSTONE.getDefaultState());
        structure.fillWithBlocks(world, start, 126, 39, 63, 126, 39, 63, Blocks.SAND.getDefaultState());
        structure.fillWithBlocks(world, start, 126, 39, 65, 127, 39, 65, Blocks.SANDSTONE.getDefaultState());
        structure.fillWithBlocks(world, start, 126, 39, 66, 126, 42, 66, Blocks.SAND.getDefaultState());
        structure.fillWithBlocks(world, start, 126, 40, 41, 127, 40, 41, Blocks.SANDSTONE_STAIRS.getDefaultState().with(StairsBlock.FACING, Direction.SOUTH).with(StairsBlock.WATERLOGGED, false).with(StairsBlock.SHAPE, StairsShape.STRAIGHT).with(StairsBlock.HALF, Half.TOP));
        structure.fillWithBlocks(world, start, 126, 40, 42, 127, 40, 43, Blocks.CUT_SANDSTONE.getDefaultState());
        structure.fillWithBlocks(world, start, 126, 40, 52, 127, 40, 57, Blocks.SANDSTONE.getDefaultState());
        structure.fillWithBlocks(world, start, 126, 40, 58, 126, 41, 58, Blocks.SANDSTONE.getDefaultState());
        structure.fillWithBlocks(world, start, 126, 40, 59, 126, 41, 64, Blocks.SAND.getDefaultState());
        structure.fillWithBlocks(world, start, 126, 40, 65, 126, 41, 65, Blocks.SANDSTONE.getDefaultState());
        structure.fillWithBlocks(world, start, 126, 41, 41, 127, 41, 41, Blocks.SANDSTONE_STAIRS.getDefaultState().with(StairsBlock.FACING, Direction.SOUTH).with(StairsBlock.WATERLOGGED, false).with(StairsBlock.SHAPE, StairsShape.STRAIGHT).with(StairsBlock.HALF, Half.BOTTOM));
        structure.fillWithBlocks(world, start, 126, 41, 42, 127, 41, 43, Blocks.CUT_SANDSTONE.getDefaultState());
        structure.fillWithBlocks(world, start, 126, 41, 44, 126, 45, 51, Blocks.CUT_SANDSTONE.getDefaultState());
        structure.fillWithBlocks(world, start, 126, 41, 52, 129, 44, 52, Blocks.SAND.getDefaultState());
        structure.fillWithBlocks(world, start, 126, 41, 53, 127, 41, 57, Blocks.SANDSTONE.getDefaultState());
        structure.fillWithBlocks(world, start, 126, 42, 43, 127, 42, 51, Blocks.CUT_SANDSTONE.getDefaultState());
        structure.fillWithBlocks(world, start, 126, 42, 58, 126, 43, 59, Blocks.SAND.getDefaultState());
        structure.fillWithBlocks(world, start, 126, 42, 63, 126, 42, 66, Blocks.SAND.getDefaultState());
        structure.fillWithBlocks(world, start, 126, 43, 43, 127, 43, 51, Blocks.CUT_SANDSTONE.getDefaultState());
        structure.fillWithBlocks(world, start, 126, 43, 64, 126, 43, 65, Blocks.SAND.getDefaultState());
        structure.fillWithBlocks(world, start, 126, 44, 42, 126, 44, 42, Blocks.CHISELED_SANDSTONE.getDefaultState());
        structure.fillWithBlocks(world, start, 126, 44, 43, 126, 45, 51, Blocks.CUT_SANDSTONE.getDefaultState());
        structure.fillWithBlocks(world, start, 126, 44, 54, 126, 44, 54, Blocks.SAND.getDefaultState());
        structure.fillWithBlocks(world, start, 126, 44, 55, 126, 44, 57, Blocks.SANDSTONE.getDefaultState());
        structure.fillWithBlocks(world, start, 126, 44, 58, 127, 44, 58, Blocks.SAND.getDefaultState());
        structure.fillWithBlocks(world, start, 126, 44, 65, 126, 45, 65, Blocks.SAND.getDefaultState());
        structure.fillWithBlocks(world, start, 126, 45, 52, 127, 45, 56, Blocks.SAND.getDefaultState());
        structure.fillWithBlocks(world, start, 126, 45, 58, 126, 46, 58, Blocks.SAND.getDefaultState());
        structure.fillWithBlocks(world, start, 126, 46, 53, 127, 46, 57, Blocks.SAND.getDefaultState());
        structure.fillWithBlocks(world, start, 126, 48, 54, 126, 48, 57, Blocks.SAND.getDefaultState());
        structure.fillWithBlocks(world, start, 126, 49, 55, 126, 49, 57, Blocks.SAND.getDefaultState());
        structure.fillWithBlocks(world, start, 126, 52, 97, 126, 57, 102, Blocks.SANDSTONE.getDefaultState());
        structure.fillWithBlocks(world, start, 126, 53, 103, 126, 54, 104, Blocks.SANDSTONE.getDefaultState());
        structure.fillWithBlocks(world, start, 126, 54, 96, 126, 54, 105, Blocks.SANDSTONE.getDefaultState());
        structure.fillWithBlocks(world, start, 126, 55, 95, 126, 55, 105, Blocks.SANDSTONE.getDefaultState());
        structure.fillWithBlocks(world, start, 126, 56, 95, 126, 56, 105, Blocks.SANDSTONE.getDefaultState());
        structure.fillWithBlocks(world, start, 126, 57, 95, 126, 57, 103, Blocks.SANDSTONE.getDefaultState());
        structure.fillWithBlocks(world, start, 126, 57, 104, 126, 58, 105, Blocks.SAND.getDefaultState());
        structure.fillWithBlocks(world, start, 126, 58, 95, 126, 58, 102, Blocks.SANDSTONE.getDefaultState());
        structure.fillWithBlocks(world, start, 126, 58, 103, 127, 58, 104, Blocks.SAND.getDefaultState());
        structure.fillWithBlocks(world, start, 126, 59, 95, 126, 62, 95, Blocks.SAND.getDefaultState());
        structure.fillWithBlocks(world, start, 126, 59, 96, 126, 59, 100, Blocks.SANDSTONE.getDefaultState());
        structure.fillWithBlocks(world, start, 126, 59, 101, 128, 59, 103, Blocks.SAND.getDefaultState());
        structure.fillWithBlocks(world, start, 126, 59, 105, 126, 60, 105, Blocks.SAND.getDefaultState());
        structure.fillWithBlocks(world, start, 126, 60, 98, 129, 60, 101, Blocks.SAND.getDefaultState());
        structure.fillWithBlocks(world, start, 126, 62, 97, 128, 62, 101, Blocks.SAND.getDefaultState());
        structure.fillWithBlocks(world, start, 126, 63, 96, 126, 63, 100, Blocks.SAND.getDefaultState());
        structure.fillWithBlocks(world, start, 126, 65, 81, 126, 69, 81, Blocks.SANDSTONE.getDefaultState());
        structure.fillWithBlocks(world, start, 126, 70, 81, 126, 73, 81, Blocks.SAND.getDefaultState());
        structure.fillWithBlocks(world, start, 127, -51, -38, 129, -51, -36, Blocks.SANDSTONE.getDefaultState());
        structure.fillWithBlocks(world, start, 127, -50, -40, 128, -50, -39, Blocks.SANDSTONE.getDefaultState());
        structure.fillWithBlocks(world, start, 127, -50, -38, 127, -50, -38, Blocks.AIR.getDefaultState());
        structure.fillWithBlocks(world, start, 127, -50, -36, 133, -46, -36, Blocks.AIR.getDefaultState());
        structure.fillWithBlocks(world, start, 127, -50, 8, 130, -50, 11, Blocks.AIR.getDefaultState());
        structure.fillWithBlocks(world, start, 127, -50, 29, 135, -50, 37, Blocks.SANDSTONE.getDefaultState());
        structure.fillWithBlocks(world, start, 127, -49, -38, 129, -49, -36, Blocks.AIR.getDefaultState());
        structure.fillWithBlocks(world, start, 127, -49, 56, 131, -49, 61, Blocks.AIR.getDefaultState());
        structure.fillWithBlocks(world, start, 127, -48, 64, 128, -48, 65, Blocks.SANDSTONE.getDefaultState());
        structure.fillWithBlocks(world, start, 127, -45, -25, 128, -45, -24, Blocks.SANDSTONE.getDefaultState());
        structure.fillWithBlocks(world, start, 127, -44, -38, 127, -44, -38, Blocks.SANDSTONE.getDefaultState());
        structure.fillWithBlocks(world, start, 127, -44, -36, 130, -44, -33, Blocks.SANDSTONE.getDefaultState());
        structure.fillWithBlocks(world, start, 127, -44, -31, 130, -44, -28, Blocks.SANDSTONE.getDefaultState());
        structure.fillWithBlocks(world, start, 127, -44, -26, 129, -44, -24, Blocks.SANDSTONE.getDefaultState());
        structure.fillWithBlocks(world, start, 127, -43, -2, 133, -43, 4, Blocks.SANDSTONE.getDefaultState());
        structure.fillWithBlocks(world, start, 127, -41, 44, 129, -41, 46, Blocks.STONE_BRICKS.getDefaultState());
        structure.fillWithBlocks(world, start, 127, -41, 68, 129, -41, 70, Blocks.STONE_BRICKS.getDefaultState());
        structure.fillWithBlocks(world, start, 127, -40, 24, 128, -40, 25, Blocks.SANDSTONE.getDefaultState());
        structure.fillWithBlocks(world, start, 127, -40, 27, 129, -40, 29, Blocks.STONE_BRICKS.getDefaultState());
        structure.fillWithBlocks(world, start, 127, -40, 30, 127, -40, 32, Blocks.SANDSTONE.getDefaultState());
        structure.fillWithBlocks(world, start, 127, -40, 44, 127, -40, 44, Blocks.AIR.getDefaultState());
        structure.fillWithBlocks(world, start, 127, -40, 71, 128, -40, 72, Blocks.STONE_BRICKS.getDefaultState());
        structure.fillWithBlocks(world, start, 127, -39, 22, 128, -39, 23, Blocks.STONE_BRICKS.getDefaultState());
        structure.fillWithBlocks(world, start, 127, -39, 24, 127, -38, 25, Blocks.AIR.getDefaultState());
        structure.fillWithBlocks(world, start, 127, -39, 26, 127, -36, 26, Blocks.STONE_BRICKS.getDefaultState());
        structure.fillWithBlocks(world, start, 127, -39, 27, 129, -39, 29, Blocks.AIR.getDefaultState());
        structure.fillWithBlocks(world, start, 127, -39, 30, 127, -39, 31, Blocks.STONE_BRICKS.getDefaultState());
        structure.fillWithBlocks(world, start, 127, -39, 43, 127, -34, 43, Blocks.STONE_BRICKS.getDefaultState());
        structure.fillWithBlocks(world, start, 127, -39, 44, 129, -39, 46, Blocks.AIR.getDefaultState());
        structure.fillWithBlocks(world, start, 127, -39, 47, 127, -36, 47, Blocks.STONE_BRICKS.getDefaultState());
        structure.fillWithBlocks(world, start, 127, -39, 48, 127, -39, 52, Blocks.IRON_BARS.getDefaultState().with(FourWayBlock.WATERLOGGED, false).with(FourWayBlock.NORTH, true).with(FourWayBlock.SOUTH, true).with(FourWayBlock.EAST, true).with(FourWayBlock.WEST, true));
        structure.fillWithBlocks(world, start, 127, -39, 53, 127, -34, 53, Blocks.STONE_BRICKS.getDefaultState());
        structure.fillWithBlocks(world, start, 127, -39, 54, 127, -39, 55, Blocks.IRON_BARS.getDefaultState().with(FourWayBlock.WATERLOGGED, false).with(FourWayBlock.NORTH, true).with(FourWayBlock.SOUTH, true).with(FourWayBlock.EAST, true).with(FourWayBlock.WEST, true));
        structure.fillWithBlocks(world, start, 127, -39, 56, 127, -38, 57, Blocks.STONE_BRICKS.getDefaultState());
        structure.fillWithBlocks(world, start, 127, -39, 58, 127, -39, 60, Blocks.IRON_BARS.getDefaultState().with(FourWayBlock.WATERLOGGED, false).with(FourWayBlock.NORTH, true).with(FourWayBlock.SOUTH, true).with(FourWayBlock.EAST, true).with(FourWayBlock.WEST, true));
        structure.fillWithBlocks(world, start, 127, -39, 61, 127, -34, 61, Blocks.STONE_BRICKS.getDefaultState());
        structure.fillWithBlocks(world, start, 127, -39, 62, 127, -39, 66, Blocks.IRON_BARS.getDefaultState().with(FourWayBlock.WATERLOGGED, false).with(FourWayBlock.NORTH, true).with(FourWayBlock.SOUTH, true).with(FourWayBlock.EAST, true).with(FourWayBlock.WEST, true));
        structure.fillWithBlocks(world, start, 127, -39, 67, 127, -31, 67, Blocks.STONE_BRICKS.getDefaultState());
        structure.fillWithBlocks(world, start, 127, -39, 68, 129, -39, 70, Blocks.AIR.getDefaultState());
        structure.fillWithBlocks(world, start, 127, -39, 71, 127, -39, 72, Blocks.STONE_BRICKS.getDefaultState());
        structure.fillWithBlocks(world, start, 127, -38, 27, 129, -38, 29, Blocks.AIR.getDefaultState());
        structure.fillWithBlocks(world, start, 127, -38, 30, 127, -38, 31, Blocks.STONE_BRICKS.getDefaultState());
        structure.fillWithBlocks(world, start, 127, -38, 44, 129, -38, 46, Blocks.AIR.getDefaultState());
        structure.fillWithBlocks(world, start, 127, -38, 48, 130, -38, 52, Blocks.AIR.getDefaultState());
        structure.fillWithBlocks(world, start, 127, -38, 54, 128, -38, 55, Blocks.AIR.getDefaultState());
        structure.fillWithBlocks(world, start, 127, -38, 58, 129, -38, 60, Blocks.AIR.getDefaultState());
        structure.fillWithBlocks(world, start, 127, -38, 62, 131, -38, 66, Blocks.AIR.getDefaultState());
        structure.fillWithBlocks(world, start, 127, -38, 68, 129, -38, 70, Blocks.AIR.getDefaultState());
        structure.fillWithBlocks(world, start, 127, -38, 71, 127, -38, 72, Blocks.STONE_BRICKS.getDefaultState());
        structure.fillWithBlocks(world, start, 127, -37, 24, 127, -37, 25, Blocks.AIR.getDefaultState());
        structure.fillWithBlocks(world, start, 127, -37, 27, 129, -37, 29, Blocks.AIR.getDefaultState());
        structure.fillWithBlocks(world, start, 127, -37, 30, 127, -37, 31, Blocks.STONE_BRICKS.getDefaultState());
        structure.fillWithBlocks(world, start, 127, -37, 44, 129, -37, 46, Blocks.AIR.getDefaultState());
        structure.fillWithBlocks(world, start, 127, -37, 48, 130, -37, 52, Blocks.AIR.getDefaultState());
        structure.fillWithBlocks(world, start, 127, -37, 54, 128, -37, 55, Blocks.AIR.getDefaultState());
        structure.fillWithBlocks(world, start, 127, -37, 56, 127, -37, 57, Blocks.STONE_BRICKS.getDefaultState());
        structure.fillWithBlocks(world, start, 127, -37, 58, 129, -37, 60, Blocks.AIR.getDefaultState());
        structure.fillWithBlocks(world, start, 127, -37, 62, 131, -37, 66, Blocks.AIR.getDefaultState());
        structure.fillWithBlocks(world, start, 127, -37, 68, 129, -37, 70, Blocks.AIR.getDefaultState());
        structure.fillWithBlocks(world, start, 127, -37, 71, 127, -37, 72, Blocks.STONE_BRICKS.getDefaultState());
        structure.fillWithBlocks(world, start, 127, -36, 44, 129, -36, 46, Blocks.AIR.getDefaultState());
        structure.fillWithBlocks(world, start, 127, -36, 48, 130, -36, 52, Blocks.AIR.getDefaultState());
        structure.fillWithBlocks(world, start, 127, -36, 54, 128, -36, 55, Blocks.AIR.getDefaultState());
        structure.fillWithBlocks(world, start, 127, -36, 57, 127, -31, 57, Blocks.STONE_BRICKS.getDefaultState());
        structure.fillWithBlocks(world, start, 127, -36, 58, 129, -36, 60, Blocks.AIR.getDefaultState());
        structure.fillWithBlocks(world, start, 127, -36, 62, 131, -36, 66, Blocks.AIR.getDefaultState());
        structure.fillWithBlocks(world, start, 127, -36, 68, 129, -36, 70, Blocks.AIR.getDefaultState());
        structure.fillWithBlocks(world, start, 127, -36, 71, 127, -36, 72, Blocks.STONE_BRICKS.getDefaultState());
        structure.fillWithBlocks(world, start, 127, -35, 44, 127, -35, 46, Blocks.STONE_BRICKS.getDefaultState());
        structure.fillWithBlocks(world, start, 127, -35, 48, 127, -33, 52, Blocks.STONE_BRICKS.getDefaultState());
        structure.fillWithBlocks(world, start, 127, -35, 54, 127, -34, 57, Blocks.STONE_BRICKS.getDefaultState());
        structure.fillWithBlocks(world, start, 127, -35, 58, 127, -35, 72, Blocks.STONE_BRICKS.getDefaultState());
        structure.fillWithBlocks(world, start, 127, -34, 45, 128, -34, 46, Blocks.STONE_BRICKS.getDefaultState());
        structure.fillWithBlocks(world, start, 127, -34, 59, 128, -34, 64, Blocks.STONE_BRICKS.getDefaultState());
        structure.fillWithBlocks(world, start, 127, -34, 66, 129, -34, 68, Blocks.STONE_BRICKS.getDefaultState());
        structure.fillWithBlocks(world, start, 127, -34, 69, 128, -34, 70, Blocks.STONE_BRICKS.getDefaultState());
        structure.fillWithBlocks(world, start, 127, -34, 72, 128, -33, 72, Blocks.STONE_BRICKS.getDefaultState());
        structure.fillWithBlocks(world, start, 127, -33, 43, 127, -33, 43, Blocks.AIR.getDefaultState());
        structure.fillWithBlocks(world, start, 127, -33, 44, 127, -31, 47, Blocks.STONE_BRICKS.getDefaultState());
        structure.fillWithBlocks(world, start, 127, -33, 54, 127, -31, 54, Blocks.STONE_BRICKS.getDefaultState());
        structure.fillWithBlocks(world, start, 127, -33, 56, 127, -31, 60, Blocks.STONE_BRICKS.getDefaultState());
        structure.fillWithBlocks(world, start, 127, -33, 61, 127, -33, 61, Blocks.AIR.getDefaultState());
        structure.fillWithBlocks(world, start, 127, -32, 42, 130, -32, 47, Blocks.STONE_BRICKS.getDefaultState());
        structure.fillWithBlocks(world, start, 127, -32, 62, 127, -32, 64, Blocks.STONE_BRICKS.getDefaultState());
        structure.fillWithBlocks(world, start, 127, -32, 66, 132, -32, 72, Blocks.STONE_BRICKS.getDefaultState());
        structure.fillWithBlocks(world, start, 127, -31, 61, 129, -31, 63, Blocks.STONE_BRICKS.getDefaultState());
        structure.fillWithBlocks(world, start, 127, -31, 65, 132, -31, 72, Blocks.STONE_BRICKS.getDefaultState());
        structure.fillWithBlocks(world, start, 127, -19, 26, 127, -17, 26, Blocks.STONE.getDefaultState());
        structure.fillWithBlocks(world, start, 127, -19, 27, 129, -19, 29, Blocks.AIR.getDefaultState());
        structure.fillWithBlocks(world, start, 127, -19, 30, 127, -17, 30, Blocks.STONE.getDefaultState());
        structure.fillWithBlocks(world, start, 127, -19, 50, 127, -19, 50, Blocks.SANDSTONE.getDefaultState());
        structure.fillWithBlocks(world, start, 127, -19, 52, 128, -19, 53, Blocks.SANDSTONE.getDefaultState());
        structure.fillWithBlocks(world, start, 127, -19, 55, 127, -17, 58, Blocks.SANDSTONE.getDefaultState());
        structure.fillWithBlocks(world, start, 127, -19, 63, 129, -19, 65, Blocks.AIR.getDefaultState());
        structure.fillWithBlocks(world, start, 127, -19, 66, 127, -17, 66, Blocks.AIR.getDefaultState());
        structure.fillWithBlocks(world, start, 127, -18, 27, 129, -18, 29, Blocks.AIR.getDefaultState());
        structure.fillWithBlocks(world, start, 127, -18, 63, 129, -18, 65, Blocks.AIR.getDefaultState());
        structure.fillWithBlocks(world, start, 127, -18, 73, 127, -18, 73, Blocks.SANDSTONE.getDefaultState());
        structure.fillWithBlocks(world, start, 127, -17, 27, 129, -17, 29, Blocks.AIR.getDefaultState());
        structure.fillWithBlocks(world, start, 127, -17, 50, 128, -17, 51, Blocks.SANDSTONE.getDefaultState());
        structure.fillWithBlocks(world, start, 127, -17, 52, 128, -17, 52, Blocks.AIR.getDefaultState());
        structure.fillWithBlocks(world, start, 127, -17, 53, 131, -17, 58, Blocks.SANDSTONE.getDefaultState());
        structure.fillWithBlocks(world, start, 127, -17, 67, 127, -11, 67, Blocks.SANDSTONE.getDefaultState());
        structure.fillWithBlocks(world, start, 127, -17, 69, 127, -17, 69, Blocks.SANDSTONE.getDefaultState());
        structure.fillWithBlocks(world, start, 127, -16, 50, 129, -16, 54, Blocks.SANDSTONE.getDefaultState());
        structure.fillWithBlocks(world, start, 127, -16, 56, 129, -16, 58, Blocks.SANDSTONE.getDefaultState());
        structure.fillWithBlocks(world, start, 127, -16, 73, 128, -16, 74, Blocks.SANDSTONE.getDefaultState());
        structure.fillWithBlocks(world, start, 127, -15, 50, 130, -15, 59, Blocks.SANDSTONE.getDefaultState());
        structure.fillWithBlocks(world, start, 127, -14, 50, 127, -14, 57, Blocks.SANDSTONE.getDefaultState());
        structure.fillWithBlocks(world, start, 127, -14, 60, 139, -12, 60, Blocks.SANDSTONE.getDefaultState());
        structure.fillWithBlocks(world, start, 127, -14, 73, 128, -14, 74, Blocks.SANDSTONE.getDefaultState());
        structure.fillWithBlocks(world, start, 127, -13, 56, 132, -13, 61, Blocks.SANDSTONE.getDefaultState());
        structure.fillWithBlocks(world, start, 127, -13, 63, 129, -13, 74, Blocks.SANDSTONE.getDefaultState());
        structure.fillWithBlocks(world, start, 127, -12, 50, 131, -12, 54, Blocks.SANDSTONE.getDefaultState());
        structure.fillWithBlocks(world, start, 127, -12, 68, 128, -12, 74, Blocks.SANDSTONE.getDefaultState());
        structure.fillWithBlocks(world, start, 127, -11, 50, 127, -11, 50, Blocks.SANDSTONE.getDefaultState());
        structure.fillWithBlocks(world, start, 127, -11, 52, 130, -11, 55, Blocks.SANDSTONE.getDefaultState());
        structure.fillWithBlocks(world, start, 127, -11, 56, 127, -11, 56, Blocks.AIR.getDefaultState());
        structure.fillWithBlocks(world, start, 127, -11, 57, 127, -11, 68, Blocks.SANDSTONE.getDefaultState());
        structure.fillWithBlocks(world, start, 127, -11, 70, 131, -11, 74, Blocks.SANDSTONE.getDefaultState());
        structure.fillWithBlocks(world, start, 127, -9, 28, 127, -9, 31, Blocks.AIR.getDefaultState());
        structure.fillWithBlocks(world, start, 127, -9, 56, 127, -7, 56, Blocks.STONE.getDefaultState());
        structure.fillWithBlocks(world, start, 127, -9, 57, 129, -9, 59, Blocks.AIR.getDefaultState());
        structure.fillWithBlocks(world, start, 127, -9, 60, 127, -7, 60, Blocks.STONE.getDefaultState());
        structure.fillWithBlocks(world, start, 127, -8, 57, 129, -8, 59, Blocks.AIR.getDefaultState());
        structure.fillWithBlocks(world, start, 127, -7, 57, 129, -7, 59, Blocks.AIR.getDefaultState());
        structure.fillWithBlocks(world, start, 127, -6, 22, 129, -6, 24, Blocks.SANDSTONE.getDefaultState());
        structure.fillWithBlocks(world, start, 127, -5, 22, 128, -5, 25, Blocks.SANDSTONE.getDefaultState());
        structure.fillWithBlocks(world, start, 127, -5, 26, 129, -5, 30, Blocks.AIR.getDefaultState());
        structure.fillWithBlocks(world, start, 127, -5, 31, 130, -5, 34, Blocks.SANDSTONE.getDefaultState());
        structure.fillWithBlocks(world, start, 127, -3, 26, 130, -3, 33, Blocks.SANDSTONE.getDefaultState());
        structure.fillWithBlocks(world, start, 127, -2, 30, 130, -2, 33, Blocks.SANDSTONE.getDefaultState());
        structure.fillWithBlocks(world, start, 127, -1, 22, 127, -1, 22, Blocks.SANDSTONE.getDefaultState());
        structure.fillWithBlocks(world, start, 127, -1, 24, 131, -1, 30, Blocks.SANDSTONE.getDefaultState());
        structure.fillWithBlocks(world, start, 127, 0, 2, 133, 0, 8, Blocks.SANDSTONE.getDefaultState());
        structure.fillWithBlocks(world, start, 127, 0, 10, 131, 0, 151, Blocks.STONE.getDefaultState());
        structure.fillWithBlocks(world, start, 127, 0, 154, 132, 0, 159, Blocks.SANDSTONE.getDefaultState());
        structure.fillWithBlocks(world, start, 127, 0, 160, 129, 0, 160, Blocks.SANDSTONE.getDefaultState());
        structure.fillWithBlocks(world, start, 127, 1, 4, 136, 1, 13, Blocks.SANDSTONE.getDefaultState());
        structure.fillWithBlocks(world, start, 127, 1, 150, 127, 1, 150, Blocks.SANDSTONE.getDefaultState());
        structure.fillWithBlocks(world, start, 127, 2, 146, 136, 2, 155, Blocks.SANDSTONE.getDefaultState());
        structure.fillWithBlocks(world, start, 127, 4, 8, 138, 4, 19, Blocks.SANDSTONE.getDefaultState());
        structure.fillWithBlocks(world, start, 127, 5, 10, 136, 5, 19, Blocks.SANDSTONE.getDefaultState());
        structure.fillWithBlocks(world, start, 127, 9, 42, 127, 18, 51, Blocks.SMOOTH_SANDSTONE.getDefaultState());
        structure.fillWithBlocks(world, start, 127, 9, 84, 128, 9, 84, Blocks.SAND.getDefaultState());
        structure.fillWithBlocks(world, start, 127, 9, 86, 127, 11, 86, Blocks.SAND.getDefaultState());
        structure.fillWithBlocks(world, start, 127, 9, 95, 127, 11, 95, Blocks.SAND.getDefaultState());
        structure.fillWithBlocks(world, start, 127, 9, 105, 128, 10, 105, Blocks.SAND.getDefaultState());
        structure.fillWithBlocks(world, start, 127, 11, 105, 127, 12, 105, Blocks.SAND.getDefaultState());
        structure.fillWithBlocks(world, start, 127, 12, 55, 130, 12, 58, Blocks.SANDSTONE.getDefaultState());
        structure.fillWithBlocks(world, start, 127, 13, 56, 129, 13, 58, Blocks.SANDSTONE.getDefaultState());
        structure.fillWithBlocks(world, start, 127, 14, 52, 127, 14, 52, Blocks.SANDSTONE.getDefaultState());
        structure.fillWithBlocks(world, start, 127, 14, 55, 130, 14, 58, Blocks.SANDSTONE.getDefaultState());
        structure.fillWithBlocks(world, start, 127, 15, 52, 133, 15, 58, Blocks.SANDSTONE.getDefaultState());
        structure.fillWithBlocks(world, start, 127, 19, 42, 127, 22, 51, Blocks.SMOOTH_SANDSTONE.getDefaultState());
        structure.fillWithBlocks(world, start, 127, 24, 62, 127, 27, 62, Blocks.SANDSTONE.getDefaultState());
        structure.fillWithBlocks(world, start, 127, 26, 60, 127, 26, 62, Blocks.SANDSTONE.getDefaultState());
        structure.fillWithBlocks(world, start, 127, 27, 52, 134, 27, 59, Blocks.SANDSTONE.getDefaultState());
        structure.fillWithBlocks(world, start, 127, 27, 60, 127, 28, 60, Blocks.SANDSTONE.getDefaultState());
        structure.fillWithBlocks(world, start, 127, 27, 61, 131, 29, 61, Blocks.SAND.getDefaultState());
        structure.fillWithBlocks(world, start, 127, 28, 52, 134, 28, 59, Blocks.SANDSTONE.getDefaultState());
        structure.fillWithBlocks(world, start, 127, 28, 62, 127, 31, 62, Blocks.SAND.getDefaultState());
        structure.fillWithBlocks(world, start, 127, 29, 52, 134, 29, 59, Blocks.SANDSTONE.getDefaultState());
        structure.fillWithBlocks(world, start, 127, 29, 60, 128, 29, 61, Blocks.SAND.getDefaultState());
        structure.fillWithBlocks(world, start, 127, 30, 52, 133, 30, 58, Blocks.SANDSTONE.getDefaultState());
        structure.fillWithBlocks(world, start, 127, 30, 59, 127, 36, 59, Blocks.SANDSTONE.getDefaultState());
        structure.fillWithBlocks(world, start, 127, 30, 60, 127, 30, 62, Blocks.SAND.getDefaultState());
        structure.fillWithBlocks(world, start, 127, 30, 63, 127, 37, 63, Blocks.SANDSTONE.getDefaultState());
        structure.fillWithBlocks(world, start, 127, 31, 52, 133, 31, 58, Blocks.SANDSTONE.getDefaultState());
        structure.fillWithBlocks(world, start, 127, 31, 60, 127, 32, 60, Blocks.SAND.getDefaultState());
        structure.fillWithBlocks(world, start, 127, 31, 64, 127, 32, 65, Blocks.SANDSTONE.getDefaultState());
        structure.fillWithBlocks(world, start, 127, 32, 52, 133, 32, 58, Blocks.SANDSTONE.getDefaultState());
        structure.fillWithBlocks(world, start, 127, 33, 52, 133, 33, 58, Blocks.SANDSTONE.getDefaultState());
        structure.fillWithBlocks(world, start, 127, 33, 64, 127, 33, 65, Blocks.SANDSTONE.getDefaultState());
        structure.fillWithBlocks(world, start, 127, 34, 52, 133, 34, 58, Blocks.SANDSTONE.getDefaultState());
        structure.fillWithBlocks(world, start, 127, 34, 64, 128, 34, 65, Blocks.SANDSTONE.getDefaultState());
        structure.fillWithBlocks(world, start, 127, 35, 52, 133, 35, 58, Blocks.SANDSTONE.getDefaultState());
        structure.fillWithBlocks(world, start, 127, 35, 64, 128, 35, 65, Blocks.SANDSTONE.getDefaultState());
        structure.fillWithBlocks(world, start, 127, 36, 64, 128, 36, 65, Blocks.SANDSTONE.getDefaultState());
        structure.fillWithBlocks(world, start, 127, 37, 59, 127, 41, 59, Blocks.SAND.getDefaultState());
        structure.fillWithBlocks(world, start, 127, 37, 64, 128, 37, 65, Blocks.SANDSTONE.getDefaultState());
        structure.fillWithBlocks(world, start, 127, 38, 58, 127, 39, 58, Blocks.SANDSTONE.getDefaultState());
        structure.fillWithBlocks(world, start, 127, 38, 63, 127, 41, 63, Blocks.SAND.getDefaultState());
        structure.fillWithBlocks(world, start, 127, 38, 64, 127, 38, 65, Blocks.SANDSTONE.getDefaultState());
        structure.fillWithBlocks(world, start, 127, 39, 64, 127, 39, 64, Blocks.SAND.getDefaultState());
        structure.fillWithBlocks(world, start, 127, 40, 58, 127, 41, 59, Blocks.SAND.getDefaultState());
        structure.fillWithBlocks(world, start, 127, 40, 64, 128, 40, 65, Blocks.SAND.getDefaultState());
        structure.fillWithBlocks(world, start, 127, 41, 45, 127, 41, 51, Blocks.SANDSTONE_STAIRS.getDefaultState().with(StairsBlock.FACING, Direction.WEST).with(StairsBlock.WATERLOGGED, false).with(StairsBlock.SHAPE, StairsShape.STRAIGHT).with(StairsBlock.HALF, Half.TOP));
        structure.fillWithBlocks(world, start, 127, 41, 64, 128, 41, 65, Blocks.SAND.getDefaultState());
        structure.fillWithBlocks(world, start, 127, 42, 42, 127, 43, 51, Blocks.CUT_SANDSTONE.getDefaultState());
        structure.fillWithBlocks(world, start, 127, 42, 53, 127, 42, 53, Blocks.SAND.getDefaultState());
        structure.fillWithBlocks(world, start, 127, 42, 54, 127, 42, 57, Blocks.SANDSTONE.getDefaultState());
        structure.fillWithBlocks(world, start, 127, 42, 58, 132, 42, 58, Blocks.SAND.getDefaultState());
        structure.fillWithBlocks(world, start, 127, 42, 64, 127, 42, 65, Blocks.SAND.getDefaultState());
        structure.fillWithBlocks(world, start, 127, 43, 54, 127, 43, 54, Blocks.SAND.getDefaultState());
        structure.fillWithBlocks(world, start, 127, 43, 58, 127, 44, 58, Blocks.SAND.getDefaultState());
        structure.fillWithBlocks(world, start, 127, 44, 42, 127, 44, 51, Blocks.CHISELED_SANDSTONE.getDefaultState());
        structure.fillWithBlocks(world, start, 127, 44, 54, 128, 44, 55, Blocks.SAND.getDefaultState());
        structure.fillWithBlocks(world, start, 127, 44, 56, 127, 44, 57, Blocks.SANDSTONE.getDefaultState());
        structure.fillWithBlocks(world, start, 127, 45, 57, 130, 47, 57, Blocks.SAND.getDefaultState());
        structure.fillWithBlocks(world, start, 127, 47, 54, 127, 47, 57, Blocks.SAND.getDefaultState());
        structure.fillWithBlocks(world, start, 127, 48, 55, 127, 48, 57, Blocks.SAND.getDefaultState());
        structure.fillWithBlocks(world, start, 127, 49, 56, 127, 49, 57, Blocks.SAND.getDefaultState());
        structure.fillWithBlocks(world, start, 127, 54, 97, 127, 58, 101, Blocks.SANDSTONE.getDefaultState());
        structure.fillWithBlocks(world, start, 127, 54, 102, 127, 57, 102, Blocks.SANDSTONE.getDefaultState());
        structure.fillWithBlocks(world, start, 127, 55, 85, 127, 55, 85, Blocks.SANDSTONE.getDefaultState());
        structure.fillWithBlocks(world, start, 127, 55, 96, 127, 55, 104, Blocks.SANDSTONE.getDefaultState());
        structure.fillWithBlocks(world, start, 127, 56, 85, 127, 56, 85, Blocks.SANDSTONE.getDefaultState());
        structure.fillWithBlocks(world, start, 127, 56, 96, 128, 56, 103, Blocks.SANDSTONE.getDefaultState());
        structure.fillWithBlocks(world, start, 127, 57, 85, 127, 60, 85, Blocks.SAND.getDefaultState());
        structure.fillWithBlocks(world, start, 127, 57, 96, 128, 57, 102, Blocks.SANDSTONE.getDefaultState());
        structure.fillWithBlocks(world, start, 127, 57, 103, 127, 58, 104, Blocks.SAND.getDefaultState());
        structure.fillWithBlocks(world, start, 127, 58, 96, 127, 58, 101, Blocks.SANDSTONE.getDefaultState());
        structure.fillWithBlocks(world, start, 127, 58, 102, 128, 58, 103, Blocks.SAND.getDefaultState());
        structure.fillWithBlocks(world, start, 127, 59, 96, 128, 60, 96, Blocks.SAND.getDefaultState());
        structure.fillWithBlocks(world, start, 127, 59, 97, 128, 59, 98, Blocks.SANDSTONE.getDefaultState());
        structure.fillWithBlocks(world, start, 127, 59, 100, 128, 59, 103, Blocks.SAND.getDefaultState());
        structure.fillWithBlocks(world, start, 127, 60, 97, 129, 60, 101, Blocks.SAND.getDefaultState());
        structure.fillWithBlocks(world, start, 127, 61, 97, 129, 61, 100, Blocks.SAND.getDefaultState());
        structure.fillWithBlocks(world, start, 127, 61, 101, 128, 61, 102, Blocks.SAND.getDefaultState());
        structure.fillWithBlocks(world, start, 127, 63, 97, 128, 63, 98, Blocks.SAND.getDefaultState());
        structure.fillWithBlocks(world, start, 128, -51, 26, 128, -50, 30, Blocks.SANDSTONE.getDefaultState());
        structure.fillWithBlocks(world, start, 128, -50, -38, 130, -50, -36, Blocks.AIR.getDefaultState());
        structure.fillWithBlocks(world, start, 128, -50, 4, 129, -50, 12, Blocks.AIR.getDefaultState());
        structure.fillWithBlocks(world, start, 128, -49, -39, 129, -49, -39, Blocks.IRON_BARS.getDefaultState().with(FourWayBlock.WATERLOGGED, false).with(FourWayBlock.NORTH, true).with(FourWayBlock.SOUTH, true).with(FourWayBlock.EAST, true).with(FourWayBlock.WEST, true));
        structure.fillWithBlocks(world, start, 128, -49, 55, 132, -49, 59, Blocks.AIR.getDefaultState());
        structure.fillWithBlocks(world, start, 128, -48, 63, 130, -48, 65, Blocks.SANDSTONE.getDefaultState());
        structure.fillWithBlocks(world, start, 128, -45, -38, 129, -45, -36, Blocks.AIR.getDefaultState());
        structure.fillWithBlocks(world, start, 128, -45, -28, 129, -45, -26, Blocks.AIR.getDefaultState());
        structure.fillWithBlocks(world, start, 128, -45, 35, 130, -45, 37, Blocks.SANDSTONE.getDefaultState());
        structure.fillWithBlocks(world, start, 128, -45, 45, 131, -45, 48, Blocks.SANDSTONE.getDefaultState());
        structure.fillWithBlocks(world, start, 128, -45, 62, 131, -45, 65, Blocks.SANDSTONE.getDefaultState());
        structure.fillWithBlocks(world, start, 128, -44, -38, 131, -44, -24, Blocks.SANDSTONE.getDefaultState());
        structure.fillWithBlocks(world, start, 128, -44, -2, 132, -44, 2, Blocks.SANDSTONE.getDefaultState());
        structure.fillWithBlocks(world, start, 128, -44, 35, 130, -44, 37, Blocks.SANDSTONE.getDefaultState());
        structure.fillWithBlocks(world, start, 128, -44, 45, 131, -44, 48, Blocks.SANDSTONE.getDefaultState());
        structure.fillWithBlocks(world, start, 128, -44, 62, 131, -44, 65, Blocks.SANDSTONE.getDefaultState());
        structure.fillWithBlocks(world, start, 128, -42, -2, 135, -42, 5, Blocks.SANDSTONE.getDefaultState());
        structure.fillWithBlocks(world, start, 128, -41, 47, 130, -41, 56, Blocks.STONE_BRICKS.getDefaultState());
        structure.fillWithBlocks(world, start, 128, -41, 58, 130, -41, 70, Blocks.STONE_BRICKS.getDefaultState());
        structure.fillWithBlocks(world, start, 128, -40, 22, 129, -40, 23, Blocks.STONE_BRICKS.getDefaultState());
        structure.fillWithBlocks(world, start, 128, -40, 26, 128, -40, 30, Blocks.STONE_BRICKS.getDefaultState());
        structure.fillWithBlocks(world, start, 128, -40, 31, 129, -40, 32, Blocks.SANDSTONE.getDefaultState());
        structure.fillWithBlocks(world, start, 128, -40, 42, 129, -40, 43, Blocks.STONE_BRICKS.getDefaultState());
        structure.fillWithBlocks(world, start, 128, -40, 44, 129, -40, 49, Blocks.AIR.getDefaultState());
        structure.fillWithBlocks(world, start, 128, -40, 50, 128, -40, 56, Blocks.AIR.getDefaultState());
        structure.fillWithBlocks(world, start, 128, -40, 57, 140, -40, 57, Blocks.STONE_BRICKS.getDefaultState());
        structure.fillWithBlocks(world, start, 128, -40, 58, 130, -40, 60, Blocks.AIR.getDefaultState());
        structure.fillWithBlocks(world, start, 128, -40, 61, 128, -40, 70, Blocks.AIR.getDefaultState());
        structure.fillWithBlocks(world, start, 128, -39, 24, 128, -39, 25, Blocks.STONE_BRICKS.getDefaultState());
        structure.fillWithBlocks(world, start, 128, -39, 26, 128, -39, 30, Blocks.AIR.getDefaultState());
        structure.fillWithBlocks(world, start, 128, -39, 43, 129, -39, 43, Blocks.IRON_BARS.getDefaultState().with(FourWayBlock.WATERLOGGED, false).with(FourWayBlock.NORTH, true).with(FourWayBlock.SOUTH, true).with(FourWayBlock.EAST, true).with(FourWayBlock.WEST, true));
        structure.fillWithBlocks(world, start, 128, -39, 47, 129, -39, 56, Blocks.AIR.getDefaultState());
        structure.fillWithBlocks(world, start, 128, -39, 57, 130, -39, 57, Blocks.IRON_BARS.getDefaultState().with(FourWayBlock.WATERLOGGED, false).with(FourWayBlock.NORTH, true).with(FourWayBlock.SOUTH, true).with(FourWayBlock.EAST, true).with(FourWayBlock.WEST, true));
        structure.fillWithBlocks(world, start, 128, -39, 58, 130, -39, 70, Blocks.AIR.getDefaultState());
        structure.fillWithBlocks(world, start, 128, -39, 71, 130, -39, 71, Blocks.IRON_BARS.getDefaultState().with(FourWayBlock.WATERLOGGED, false).with(FourWayBlock.NORTH, true).with(FourWayBlock.SOUTH, true).with(FourWayBlock.EAST, true).with(FourWayBlock.WEST, true));
        structure.fillWithBlocks(world, start, 128, -38, 22, 129, -38, 23, Blocks.STONE_BRICKS.getDefaultState());
        structure.fillWithBlocks(world, start, 128, -38, 24, 128, -38, 24, Blocks.AIR.getDefaultState());
        structure.fillWithBlocks(world, start, 128, -38, 25, 128, -36, 25, Blocks.STONE_BRICKS.getDefaultState());
        structure.fillWithBlocks(world, start, 128, -38, 26, 128, -38, 30, Blocks.AIR.getDefaultState());
        structure.fillWithBlocks(world, start, 128, -38, 43, 129, -38, 71, Blocks.AIR.getDefaultState());
        structure.fillWithBlocks(world, start, 128, -37, 22, 129, -37, 23, Blocks.STONE_BRICKS.getDefaultState());
        structure.fillWithBlocks(world, start, 128, -37, 24, 128, -36, 25, Blocks.STONE_BRICKS.getDefaultState());
        structure.fillWithBlocks(world, start, 128, -37, 26, 128, -37, 30, Blocks.AIR.getDefaultState());
        structure.fillWithBlocks(world, start, 128, -37, 43, 129, -37, 71, Blocks.AIR.getDefaultState());
        structure.fillWithBlocks(world, start, 128, -36, 43, 129, -36, 71, Blocks.AIR.getDefaultState());
        structure.fillWithBlocks(world, start, 128, -35, 43, 147, -34, 43, Blocks.STONE_BRICKS.getDefaultState());
        structure.fillWithBlocks(world, start, 128, -35, 44, 130, -35, 46, Blocks.AIR.getDefaultState());
        structure.fillWithBlocks(world, start, 128, -35, 47, 135, -35, 47, Blocks.STONE_BRICKS.getDefaultState());
        structure.fillWithBlocks(world, start, 128, -35, 48, 130, -35, 52, Blocks.AIR.getDefaultState());
        structure.fillWithBlocks(world, start, 128, -35, 54, 130, -35, 56, Blocks.AIR.getDefaultState());
        structure.fillWithBlocks(world, start, 128, -35, 58, 130, -35, 60, Blocks.AIR.getDefaultState());
        structure.fillWithBlocks(world, start, 128, -35, 61, 132, -34, 61, Blocks.STONE_BRICKS.getDefaultState());
        structure.fillWithBlocks(world, start, 128, -35, 62, 130, -35, 66, Blocks.AIR.getDefaultState());
        structure.fillWithBlocks(world, start, 128, -35, 68, 130, -35, 70, Blocks.AIR.getDefaultState());
        structure.fillWithBlocks(world, start, 128, -35, 71, 129, -35, 72, Blocks.STONE_BRICKS.getDefaultState());
        structure.fillWithBlocks(world, start, 128, -34, 44, 128, -34, 46, Blocks.STONE_BRICKS.getDefaultState());
        structure.fillWithBlocks(world, start, 128, -34, 47, 128, -33, 47, Blocks.AIR.getDefaultState());
        structure.fillWithBlocks(world, start, 128, -34, 48, 129, -34, 49, Blocks.STONE_BRICKS.getDefaultState());
        structure.fillWithBlocks(world, start, 128, -34, 50, 128, -34, 52, Blocks.STONE_BRICKS.getDefaultState());
        structure.fillWithBlocks(world, start, 128, -34, 54, 128, -34, 72, Blocks.STONE_BRICKS.getDefaultState());
        structure.fillWithBlocks(world, start, 128, -33, 43, 128, -33, 43, Blocks.STONE_BRICKS.getDefaultState());
        structure.fillWithBlocks(world, start, 128, -33, 44, 128, -33, 45, Blocks.AIR.getDefaultState());
        structure.fillWithBlocks(world, start, 128, -33, 46, 128, -33, 46, Blocks.STONE_BRICKS.getDefaultState());
        structure.fillWithBlocks(world, start, 128, -33, 48, 128, -33, 48, Blocks.STONE_BRICKS.getDefaultState());
        structure.fillWithBlocks(world, start, 128, -33, 49, 128, -33, 49, Blocks.AIR.getDefaultState());
        structure.fillWithBlocks(world, start, 128, -33, 50, 128, -33, 53, Blocks.STONE_BRICKS.getDefaultState());
        structure.fillWithBlocks(world, start, 128, -33, 54, 128, -32, 54, Blocks.AIR.getDefaultState());
        structure.fillWithBlocks(world, start, 128, -33, 55, 129, -33, 56, Blocks.STONE_BRICKS.getDefaultState());
        structure.fillWithBlocks(world, start, 128, -33, 58, 130, -33, 60, Blocks.STONE_BRICKS.getDefaultState());
        structure.fillWithBlocks(world, start, 128, -33, 61, 128, -31, 61, Blocks.STONE_BRICKS.getDefaultState());
        structure.fillWithBlocks(world, start, 128, -33, 62, 128, -32, 62, Blocks.AIR.getDefaultState());
        structure.fillWithBlocks(world, start, 128, -33, 70, 130, -33, 72, Blocks.STONE_BRICKS.getDefaultState());
        structure.fillWithBlocks(world, start, 128, -32, 48, 130, -32, 50, Blocks.STONE_BRICKS.getDefaultState());
        structure.fillWithBlocks(world, start, 128, -32, 52, 129, -32, 53, Blocks.STONE_BRICKS.getDefaultState());
        structure.fillWithBlocks(world, start, 128, -32, 55, 128, -32, 61, Blocks.STONE_BRICKS.getDefaultState());
        structure.fillWithBlocks(world, start, 128, -32, 63, 128, -32, 63, Blocks.STONE_BRICKS.getDefaultState());
        structure.fillWithBlocks(world, start, 128, -32, 64, 128, -32, 64, Blocks.AIR.getDefaultState());
        structure.fillWithBlocks(world, start, 128, -32, 65, 128, -32, 72, Blocks.STONE_BRICKS.getDefaultState());
        structure.fillWithBlocks(world, start, 128, -31, 59, 132, -31, 72, Blocks.STONE_BRICKS.getDefaultState());
        structure.fillWithBlocks(world, start, 128, -21, 60, 128, -20, 64, Blocks.SANDSTONE.getDefaultState());
        structure.fillWithBlocks(world, start, 128, -20, 25, 128, -20, 31, Blocks.SANDSTONE.getDefaultState());
        structure.fillWithBlocks(world, start, 128, -19, 25, 128, -16, 25, Blocks.SANDSTONE.getDefaultState());
        structure.fillWithBlocks(world, start, 128, -19, 26, 128, -19, 30, Blocks.AIR.getDefaultState());
        structure.fillWithBlocks(world, start, 128, -19, 31, 128, -16, 31, Blocks.SANDSTONE.getDefaultState());
        structure.fillWithBlocks(world, start, 128, -19, 50, 130, -19, 55, Blocks.SANDSTONE.getDefaultState());
        structure.fillWithBlocks(world, start, 128, -19, 57, 129, -19, 58, Blocks.SANDSTONE.getDefaultState());
        structure.fillWithBlocks(world, start, 128, -19, 59, 129, -19, 65, Blocks.AIR.getDefaultState());
        structure.fillWithBlocks(world, start, 128, -19, 66, 130, -19, 68, Blocks.SANDSTONE.getDefaultState());
        structure.fillWithBlocks(world, start, 128, -19, 72, 130, -19, 74, Blocks.SANDSTONE.getDefaultState());
        structure.fillWithBlocks(world, start, 128, -18, 26, 128, -18, 30, Blocks.AIR.getDefaultState());
        structure.fillWithBlocks(world, start, 128, -18, 50, 129, -18, 51, Blocks.SANDSTONE.getDefaultState());
        structure.fillWithBlocks(world, start, 128, -18, 52, 128, -17, 52, Blocks.AIR.getDefaultState());
        structure.fillWithBlocks(world, start, 128, -18, 53, 129, -18, 54, Blocks.SANDSTONE.getDefaultState());
        structure.fillWithBlocks(world, start, 128, -18, 59, 129, -18, 65, Blocks.AIR.getDefaultState());
        structure.fillWithBlocks(world, start, 128, -18, 66, 129, -18, 67, Blocks.SANDSTONE.getDefaultState());
        structure.fillWithBlocks(world, start, 128, -18, 69, 129, -18, 72, Blocks.SANDSTONE.getDefaultState());
        structure.fillWithBlocks(world, start, 128, -18, 73, 128, -18, 74, Blocks.SANDSTONE.getDefaultState());
        structure.fillWithBlocks(world, start, 128, -17, 26, 128, -17, 30, Blocks.AIR.getDefaultState());
        structure.fillWithBlocks(world, start, 128, -17, 66, 128, -17, 66, Blocks.SANDSTONE.getDefaultState());
        structure.fillWithBlocks(world, start, 128, -17, 68, 130, -17, 74, Blocks.SANDSTONE.getDefaultState());
        structure.fillWithBlocks(world, start, 128, -16, 55, 131, -16, 58, Blocks.SANDSTONE.getDefaultState());
        structure.fillWithBlocks(world, start, 128, -14, 51, 129, -14, 60, Blocks.SANDSTONE.getDefaultState());
        structure.fillWithBlocks(world, start, 128, -14, 72, 129, -14, 74, Blocks.SANDSTONE.getDefaultState());
        structure.fillWithBlocks(world, start, 128, -13, 55, 132, -13, 61, Blocks.SANDSTONE.getDefaultState());
        structure.fillWithBlocks(world, start, 128, -13, 62, 129, -13, 74, Blocks.SANDSTONE.getDefaultState());
        structure.fillWithBlocks(world, start, 128, -12, 56, 132, -12, 63, Blocks.SANDSTONE.getDefaultState());
        structure.fillWithBlocks(world, start, 128, -11, 50, 130, -11, 56, Blocks.SANDSTONE.getDefaultState());
        structure.fillWithBlocks(world, start, 128, -11, 57, 129, -11, 57, Blocks.AIR.getDefaultState());
        structure.fillWithBlocks(world, start, 128, -11, 58, 129, -11, 59, Blocks.SANDSTONE.getDefaultState());
        structure.fillWithBlocks(world, start, 128, -11, 61, 129, -11, 64, Blocks.SANDSTONE.getDefaultState());
        structure.fillWithBlocks(world, start, 128, -11, 66, 132, -11, 74, Blocks.SANDSTONE.getDefaultState());
        structure.fillWithBlocks(world, start, 128, -10, 55, 128, -10, 61, Blocks.SANDSTONE.getDefaultState());
        structure.fillWithBlocks(world, start, 128, -9, 55, 128, -7, 55, Blocks.SANDSTONE.getDefaultState());
        structure.fillWithBlocks(world, start, 128, -9, 56, 128, -9, 60, Blocks.AIR.getDefaultState());
        structure.fillWithBlocks(world, start, 128, -9, 61, 128, -9, 62, Blocks.SANDSTONE.getDefaultState());
        structure.fillWithBlocks(world, start, 128, -8, 29, 130, -8, 31, Blocks.AIR.getDefaultState());
        structure.fillWithBlocks(world, start, 128, -8, 56, 128, -8, 60, Blocks.AIR.getDefaultState());
        structure.fillWithBlocks(world, start, 128, -8, 61, 128, -7, 61, Blocks.SANDSTONE.getDefaultState());
        structure.fillWithBlocks(world, start, 128, -7, 56, 128, -7, 60, Blocks.AIR.getDefaultState());
        structure.fillWithBlocks(world, start, 128, -4, 29, 132, -4, 34, Blocks.SANDSTONE.getDefaultState());
        structure.fillWithBlocks(world, start, 128, -3, 23, 129, -3, 33, Blocks.SANDSTONE.getDefaultState());
        structure.fillWithBlocks(world, start, 128, -1, 22, 134, -1, 28, Blocks.SANDSTONE.getDefaultState());
        structure.fillWithBlocks(world, start, 128, 0, 9, 129, 1, 9, Blocks.SANDSTONE.getDefaultState());
        structure.fillWithBlocks(world, start, 128, 0, 152, 174, 4, 152, Blocks.SANDSTONE.getDefaultState());
        structure.fillWithBlocks(world, start, 128, 0, 153, 129, 0, 153, Blocks.STONE.getDefaultState());
        structure.fillWithBlocks(world, start, 128, 1, 150, 135, 1, 157, Blocks.SANDSTONE.getDefaultState());
        structure.fillWithBlocks(world, start, 128, 2, 5, 142, 2, 19, Blocks.SANDSTONE.getDefaultState());
        structure.fillWithBlocks(world, start, 128, 2, 145, 138, 2, 155, Blocks.SANDSTONE.getDefaultState());
        structure.fillWithBlocks(world, start, 128, 3, 6, 141, 3, 19, Blocks.SANDSTONE.getDefaultState());
        structure.fillWithBlocks(world, start, 128, 9, 52, 134, 9, 58, Blocks.SANDSTONE.getDefaultState());
        structure.fillWithBlocks(world, start, 128, 9, 59, 132, 9, 59, Blocks.SANDSTONE.getDefaultState());
        structure.fillWithBlocks(world, start, 128, 9, 62, 130, 11, 62, Blocks.SAND.getDefaultState());
        structure.fillWithBlocks(world, start, 128, 9, 87, 128, 10, 87, Blocks.SAND.getDefaultState());
        structure.fillWithBlocks(world, start, 128, 9, 104, 128, 10, 105, Blocks.SAND.getDefaultState());
        structure.fillWithBlocks(world, start, 128, 9, 114, 128, 11, 114, Blocks.CACTUS.getDefaultState().with(CactusBlock.AGE, 0));
        structure.fillWithBlocks(world, start, 128, 10, 84, 128, 12, 84, Blocks.SAND.getDefaultState());
        structure.fillWithBlocks(world, start, 128, 11, 52, 134, 11, 58, Blocks.SANDSTONE.getDefaultState());
        structure.fillWithBlocks(world, start, 128, 11, 104, 128, 12, 104, Blocks.SAND.getDefaultState());
        structure.fillWithBlocks(world, start, 128, 12, 53, 133, 12, 58, Blocks.SANDSTONE.getDefaultState());
        structure.fillWithBlocks(world, start, 128, 13, 52, 134, 13, 58, Blocks.SANDSTONE.getDefaultState());
        structure.fillWithBlocks(world, start, 128, 14, 52, 134, 14, 58, Blocks.SANDSTONE.getDefaultState());
        structure.fillWithBlocks(world, start, 128, 25, 41, 128, 25, 51, Blocks.SANDSTONE_STAIRS.getDefaultState().with(StairsBlock.FACING, Direction.WEST).with(StairsBlock.WATERLOGGED, false).with(StairsBlock.SHAPE, StairsShape.STRAIGHT).with(StairsBlock.HALF, Half.TOP));
        structure.fillWithBlocks(world, start, 128, 26, 42, 128, 26, 43, Blocks.SANDSTONE_STAIRS.getDefaultState().with(StairsBlock.FACING, Direction.WEST).with(StairsBlock.WATERLOGGED, false).with(StairsBlock.SHAPE, StairsShape.STRAIGHT).with(StairsBlock.HALF, Half.BOTTOM));
        structure.fillWithBlocks(world, start, 128, 26, 60, 128, 26, 61, Blocks.SAND.getDefaultState());
        structure.fillWithBlocks(world, start, 128, 27, 60, 129, 27, 61, Blocks.SAND.getDefaultState());
        structure.fillWithBlocks(world, start, 128, 28, 60, 129, 28, 61, Blocks.SAND.getDefaultState());
        structure.fillWithBlocks(world, start, 128, 30, 59, 128, 30, 60, Blocks.SAND.getDefaultState());
        structure.fillWithBlocks(world, start, 128, 31, 59, 128, 34, 59, Blocks.SAND.getDefaultState());
        structure.fillWithBlocks(world, start, 128, 33, 65, 128, 38, 65, Blocks.SANDSTONE.getDefaultState());
        structure.fillWithBlocks(world, start, 128, 38, 58, 132, 42, 58, Blocks.SAND.getDefaultState());
        structure.fillWithBlocks(world, start, 128, 38, 64, 128, 41, 64, Blocks.SAND.getDefaultState());
        structure.fillWithBlocks(world, start, 128, 39, 65, 128, 42, 65, Blocks.SAND.getDefaultState());
        structure.fillWithBlocks(world, start, 128, 40, 42, 128, 40, 43, Blocks.SANDSTONE_STAIRS.getDefaultState().with(StairsBlock.FACING, Direction.WEST).with(StairsBlock.WATERLOGGED, false).with(StairsBlock.SHAPE, StairsShape.STRAIGHT).with(StairsBlock.HALF, Half.TOP));
        structure.fillWithBlocks(world, start, 128, 40, 52, 133, 42, 52, Blocks.SAND.getDefaultState());
        structure.fillWithBlocks(world, start, 128, 40, 53, 129, 40, 57, Blocks.SANDSTONE.getDefaultState());
        structure.fillWithBlocks(world, start, 128, 41, 42, 128, 41, 43, Blocks.SANDSTONE_STAIRS.getDefaultState().with(StairsBlock.FACING, Direction.WEST).with(StairsBlock.WATERLOGGED, false).with(StairsBlock.SHAPE, StairsShape.STRAIGHT).with(StairsBlock.HALF, Half.BOTTOM));
        structure.fillWithBlocks(world, start, 128, 41, 53, 128, 41, 53, Blocks.SAND.getDefaultState());
        structure.fillWithBlocks(world, start, 128, 41, 55, 129, 41, 57, Blocks.SANDSTONE.getDefaultState());
        structure.fillWithBlocks(world, start, 128, 42, 53, 129, 42, 54, Blocks.SAND.getDefaultState());
        structure.fillWithBlocks(world, start, 128, 42, 55, 128, 42, 57, Blocks.SANDSTONE.getDefaultState());
        structure.fillWithBlocks(world, start, 128, 43, 54, 129, 43, 55, Blocks.SAND.getDefaultState());
        structure.fillWithBlocks(world, start, 128, 43, 56, 128, 43, 57, Blocks.SANDSTONE.getDefaultState());
        structure.fillWithBlocks(world, start, 128, 44, 56, 128, 44, 56, Blocks.SAND.getDefaultState());
        structure.fillWithBlocks(world, start, 128, 45, 42, 128, 45, 51, Blocks.SANDSTONE_STAIRS.getDefaultState().with(StairsBlock.FACING, Direction.WEST).with(StairsBlock.WATERLOGGED, false).with(StairsBlock.SHAPE, StairsShape.STRAIGHT).with(StairsBlock.HALF, Half.TOP));
        structure.fillWithBlocks(world, start, 128, 45, 54, 129, 45, 57, Blocks.SAND.getDefaultState());
        structure.fillWithBlocks(world, start, 128, 46, 54, 128, 46, 57, Blocks.SAND.getDefaultState());
        structure.fillWithBlocks(world, start, 128, 47, 55, 128, 47, 57, Blocks.SAND.getDefaultState());
        structure.fillWithBlocks(world, start, 128, 48, 56, 128, 48, 57, Blocks.SAND.getDefaultState());
        structure.fillWithBlocks(world, start, 128, 54, 85, 128, 57, 85, Blocks.SANDSTONE.getDefaultState());
        structure.fillWithBlocks(world, start, 128, 55, 86, 128, 56, 86, Blocks.SANDSTONE.getDefaultState());
        structure.fillWithBlocks(world, start, 128, 55, 97, 129, 55, 98, Blocks.SANDSTONE.getDefaultState());
        structure.fillWithBlocks(world, start, 128, 55, 99, 128, 57, 102, Blocks.SANDSTONE.getDefaultState());
        structure.fillWithBlocks(world, start, 128, 57, 86, 128, 60, 86, Blocks.SAND.getDefaultState());
        structure.fillWithBlocks(world, start, 128, 57, 103, 128, 60, 103, Blocks.SAND.getDefaultState());
        structure.fillWithBlocks(world, start, 128, 58, 85, 128, 59, 86, Blocks.SAND.getDefaultState());
        structure.fillWithBlocks(world, start, 128, 58, 96, 128, 61, 96, Blocks.SAND.getDefaultState());
        structure.fillWithBlocks(world, start, 128, 58, 97, 129, 58, 98, Blocks.SANDSTONE.getDefaultState());
        structure.fillWithBlocks(world, start, 128, 58, 99, 128, 58, 101, Blocks.SANDSTONE.getDefaultState());
        structure.fillWithBlocks(world, start, 128, 59, 99, 129, 59, 101, Blocks.SAND.getDefaultState());
        structure.fillWithBlocks(world, start, 128, 60, 85, 128, 60, 86, Blocks.SAND.getDefaultState());
        structure.fillWithBlocks(world, start, 129, -50, -40, 130, -50, -39, Blocks.SANDSTONE.getDefaultState());
        structure.fillWithBlocks(world, start, 129, -50, 28, 136, -50, 37, Blocks.SANDSTONE.getDefaultState());
        structure.fillWithBlocks(world, start, 129, -49, -24, 130, -49, -23, Blocks.SANDSTONE.getDefaultState());
        structure.fillWithBlocks(world, start, 129, -49, -22, 129, -47, -20, Blocks.AIR.getDefaultState());
        structure.fillWithBlocks(world, start, 129, -49, -19, 129, -49, -19, Blocks.SANDSTONE.getDefaultState());
        structure.fillWithBlocks(world, start, 129, -49, -18, 129, -47, -18, Blocks.AIR.getDefaultState());
        structure.fillWithBlocks(world, start, 129, -49, -17, 129, -49, -17, Blocks.SANDSTONE.getDefaultState());
        structure.fillWithBlocks(world, start, 129, -49, -16, 129, -47, -14, Blocks.AIR.getDefaultState());
        structure.fillWithBlocks(world, start, 129, -49, -13, 129, -49, -13, Blocks.SANDSTONE.getDefaultState());
        structure.fillWithBlocks(world, start, 129, -49, -12, 129, -47, -12, Blocks.AIR.getDefaultState());
        structure.fillWithBlocks(world, start, 129, -49, -11, 129, -49, -11, Blocks.SANDSTONE.getDefaultState());
        structure.fillWithBlocks(world, start, 129, -49, -10, 129, -47, -8, Blocks.AIR.getDefaultState());
        structure.fillWithBlocks(world, start, 129, -49, -7, 129, -49, -7, Blocks.SANDSTONE.getDefaultState());
        structure.fillWithBlocks(world, start, 129, -49, -6, 129, -47, -6, Blocks.AIR.getDefaultState());
        structure.fillWithBlocks(world, start, 129, -49, -5, 129, -49, -5, Blocks.SANDSTONE.getDefaultState());
        structure.fillWithBlocks(world, start, 129, -49, -4, 129, -47, -2, Blocks.AIR.getDefaultState());
        structure.fillWithBlocks(world, start, 129, -49, -1, 130, -49, 0, Blocks.SANDSTONE.getDefaultState());
        structure.fillWithBlocks(world, start, 129, -49, 1, 129, -41, 1, Blocks.SANDSTONE.getDefaultState());
        structure.fillWithBlocks(world, start, 129, -49, 15, 129, -49, 16, Blocks.SANDSTONE.getDefaultState());
        structure.fillWithBlocks(world, start, 129, -49, 17, 129, -47, 19, Blocks.AIR.getDefaultState());
        structure.fillWithBlocks(world, start, 129, -49, 20, 130, -49, 21, Blocks.SANDSTONE.getDefaultState());
        structure.fillWithBlocks(world, start, 129, -49, 35, 131, -49, 37, Blocks.SANDSTONE.getDefaultState());
        structure.fillWithBlocks(world, start, 129, -49, 38, 129, -47, 40, Blocks.AIR.getDefaultState());
        structure.fillWithBlocks(world, start, 129, -49, 41, 129, -49, 41, Blocks.SANDSTONE.getDefaultState());
        structure.fillWithBlocks(world, start, 129, -49, 42, 129, -47, 42, Blocks.AIR.getDefaultState());
        structure.fillWithBlocks(world, start, 129, -49, 43, 129, -49, 43, Blocks.SANDSTONE.getDefaultState());
        structure.fillWithBlocks(world, start, 129, -49, 44, 129, -47, 46, Blocks.AIR.getDefaultState());
        structure.fillWithBlocks(world, start, 129, -49, 47, 129, -48, 48, Blocks.SANDSTONE.getDefaultState());
        structure.fillWithBlocks(world, start, 129, -49, 62, 129, -49, 65, Blocks.SANDSTONE.getDefaultState());
        structure.fillWithBlocks(world, start, 129, -48, -24, 130, -48, -23, Blocks.SANDSTONE.getDefaultState());
        structure.fillWithBlocks(world, start, 129, -48, -19, 129, -48, -19, Blocks.SANDSTONE.getDefaultState());
        structure.fillWithBlocks(world, start, 129, -48, -17, 129, -48, -17, Blocks.SANDSTONE.getDefaultState());
        structure.fillWithBlocks(world, start, 129, -48, -13, 129, -48, -13, Blocks.SANDSTONE.getDefaultState());
        structure.fillWithBlocks(world, start, 129, -48, -11, 129, -48, -11, Blocks.SANDSTONE.getDefaultState());
        structure.fillWithBlocks(world, start, 129, -48, -7, 129, -48, -7, Blocks.SANDSTONE.getDefaultState());
        structure.fillWithBlocks(world, start, 129, -48, -5, 129, -48, -5, Blocks.SANDSTONE.getDefaultState());
        structure.fillWithBlocks(world, start, 129, -48, -1, 130, -48, 0, Blocks.SANDSTONE.getDefaultState());
        structure.fillWithBlocks(world, start, 129, -48, 15, 129, -48, 16, Blocks.SANDSTONE.getDefaultState());
        structure.fillWithBlocks(world, start, 129, -48, 20, 130, -48, 21, Blocks.SANDSTONE.getDefaultState());
        structure.fillWithBlocks(world, start, 129, -48, 35, 131, -48, 37, Blocks.SANDSTONE.getDefaultState());
        structure.fillWithBlocks(world, start, 129, -48, 41, 129, -48, 41, Blocks.SANDSTONE.getDefaultState());
        structure.fillWithBlocks(world, start, 129, -48, 43, 129, -48, 43, Blocks.SANDSTONE.getDefaultState());
        structure.fillWithBlocks(world, start, 129, -48, 62, 129, -48, 65, Blocks.SANDSTONE.getDefaultState());
        structure.fillWithBlocks(world, start, 129, -47, -24, 130, -47, -23, Blocks.SANDSTONE.getDefaultState());
        structure.fillWithBlocks(world, start, 129, -47, -19, 129, -47, -19, Blocks.SANDSTONE.getDefaultState());
        structure.fillWithBlocks(world, start, 129, -47, -17, 129, -47, -17, Blocks.SANDSTONE.getDefaultState());
        structure.fillWithBlocks(world, start, 129, -47, -13, 129, -47, -13, Blocks.SANDSTONE.getDefaultState());
        structure.fillWithBlocks(world, start, 129, -47, -11, 129, -47, -11, Blocks.SANDSTONE.getDefaultState());
        structure.fillWithBlocks(world, start, 129, -47, -7, 129, -47, -7, Blocks.SANDSTONE.getDefaultState());
        structure.fillWithBlocks(world, start, 129, -47, -5, 129, -47, -5, Blocks.SANDSTONE.getDefaultState());
        structure.fillWithBlocks(world, start, 129, -47, -1, 130, -47, 0, Blocks.SANDSTONE.getDefaultState());
        structure.fillWithBlocks(world, start, 129, -47, 15, 129, -47, 16, Blocks.SANDSTONE.getDefaultState());
        structure.fillWithBlocks(world, start, 129, -47, 20, 130, -47, 21, Blocks.SANDSTONE.getDefaultState());
        structure.fillWithBlocks(world, start, 129, -47, 35, 131, -47, 37, Blocks.SANDSTONE.getDefaultState());
        structure.fillWithBlocks(world, start, 129, -47, 41, 129, -47, 41, Blocks.SANDSTONE.getDefaultState());
        structure.fillWithBlocks(world, start, 129, -47, 43, 129, -47, 43, Blocks.SANDSTONE.getDefaultState());
        structure.fillWithBlocks(world, start, 129, -47, 47, 129, -46, 48, Blocks.SANDSTONE.getDefaultState());
        structure.fillWithBlocks(world, start, 129, -47, 62, 129, -47, 65, Blocks.SANDSTONE.getDefaultState());
        structure.fillWithBlocks(world, start, 129, -46, 15, 129, -46, 21, Blocks.SANDSTONE.getDefaultState());
        structure.fillWithBlocks(world, start, 129, -46, 62, 129, -46, 65, Blocks.SANDSTONE.getDefaultState());
        structure.fillWithBlocks(world, start, 129, -45, -25, 130, -45, -24, Blocks.SANDSTONE.getDefaultState());
        structure.fillWithBlocks(world, start, 129, -45, -2, 131, -45, 0, Blocks.SANDSTONE.getDefaultState());
        structure.fillWithBlocks(world, start, 129, -45, 15, 129, -45, 21, Blocks.SANDSTONE.getDefaultState());
        structure.fillWithBlocks(world, start, 129, -43, 45, 133, -43, 49, Blocks.SANDSTONE.getDefaultState());
        structure.fillWithBlocks(world, start, 129, -43, 61, 133, -43, 65, Blocks.SANDSTONE.getDefaultState());
        structure.fillWithBlocks(world, start, 129, -41, 26, 129, -41, 27, Blocks.AIR.getDefaultState());
        structure.fillWithBlocks(world, start, 129, -41, 28, 129, -40, 28, Blocks.STONE_BRICKS.getDefaultState());
        structure.fillWithBlocks(world, start, 129, -41, 29, 129, -41, 30, Blocks.AIR.getDefaultState());
        structure.fillWithBlocks(world, start, 129, -40, 24, 131, -40, 26, Blocks.SANDSTONE.getDefaultState());
        structure.fillWithBlocks(world, start, 129, -40, 30, 131, -40, 32, Blocks.SANDSTONE.getDefaultState());
        structure.fillWithBlocks(world, start, 129, -40, 51, 129, -36, 56, Blocks.AIR.getDefaultState());
        structure.fillWithBlocks(world, start, 129, -40, 62, 130, -40, 66, Blocks.AIR.getDefaultState());
        structure.fillWithBlocks(world, start, 129, -40, 68, 130, -40, 70, Blocks.AIR.getDefaultState());
        structure.fillWithBlocks(world, start, 129, -40, 71, 130, -40, 72, Blocks.STONE_BRICKS.getDefaultState());
        structure.fillWithBlocks(world, start, 129, -39, 22, 130, -39, 23, Blocks.STONE_BRICKS.getDefaultState());
        structure.fillWithBlocks(world, start, 129, -39, 24, 130, -39, 25, Blocks.AIR.getDefaultState());
        structure.fillWithBlocks(world, start, 129, -39, 26, 131, -37, 26, Blocks.STONE_BRICKS.getDefaultState());
        structure.fillWithBlocks(world, start, 129, -39, 30, 130, -39, 31, Blocks.STONE_BRICKS.getDefaultState());
        structure.fillWithBlocks(world, start, 129, -38, 24, 130, -38, 25, Blocks.AIR.getDefaultState());
        structure.fillWithBlocks(world, start, 129, -38, 30, 130, -38, 31, Blocks.STONE_BRICKS.getDefaultState());
        structure.fillWithBlocks(world, start, 129, -37, 24, 130, -37, 25, Blocks.AIR.getDefaultState());
        structure.fillWithBlocks(world, start, 129, -37, 30, 130, -37, 31, Blocks.STONE_BRICKS.getDefaultState());
        structure.fillWithBlocks(world, start, 129, -34, 44, 129, -34, 44, Blocks.STONE_BRICKS.getDefaultState());
        structure.fillWithBlocks(world, start, 129, -34, 46, 131, -34, 49, Blocks.STONE_BRICKS.getDefaultState());
        structure.fillWithBlocks(world, start, 129, -34, 51, 130, -34, 54, Blocks.STONE_BRICKS.getDefaultState());
        structure.fillWithBlocks(world, start, 129, -34, 56, 131, -34, 58, Blocks.STONE_BRICKS.getDefaultState());
        structure.fillWithBlocks(world, start, 129, -34, 60, 132, -34, 63, Blocks.STONE_BRICKS.getDefaultState());
        structure.fillWithBlocks(world, start, 129, -34, 65, 130, -34, 68, Blocks.STONE_BRICKS.getDefaultState());
        structure.fillWithBlocks(world, start, 129, -34, 70, 130, -34, 71, Blocks.STONE_BRICKS.getDefaultState());
        structure.fillWithBlocks(world, start, 129, -33, 43, 129, -33, 49, Blocks.STONE_BRICKS.getDefaultState());
        structure.fillWithBlocks(world, start, 129, -33, 50, 130, -33, 50, Blocks.AIR.getDefaultState());
        structure.fillWithBlocks(world, start, 129, -33, 51, 129, -31, 54, Blocks.STONE_BRICKS.getDefaultState());
        structure.fillWithBlocks(world, start, 129, -33, 57, 130, -33, 60, Blocks.STONE_BRICKS.getDefaultState());
        structure.fillWithBlocks(world, start, 129, -33, 62, 132, -33, 72, Blocks.STONE_BRICKS.getDefaultState());
        structure.fillWithBlocks(world, start, 129, -32, 56, 130, -32, 57, Blocks.STONE_BRICKS.getDefaultState());
        structure.fillWithBlocks(world, start, 129, -32, 58, 130, -32, 58, Blocks.AIR.getDefaultState());
        structure.fillWithBlocks(world, start, 129, -32, 59, 129, -32, 59, Blocks.STONE_BRICKS.getDefaultState());
        structure.fillWithBlocks(world, start, 129, -32, 61, 129, -31, 64, Blocks.STONE_BRICKS.getDefaultState());
        structure.fillWithBlocks(world, start, 129, -20, 26, 133, -20, 30, Blocks.SANDSTONE.getDefaultState());
        structure.fillWithBlocks(world, start, 129, -19, 26, 129, -17, 26, Blocks.STONE.getDefaultState());
        structure.fillWithBlocks(world, start, 129, -19, 30, 129, -17, 30, Blocks.STONE.getDefaultState());
        structure.fillWithBlocks(world, start, 129, -19, 56, 130, -19, 57, Blocks.SANDSTONE.getDefaultState());
        structure.fillWithBlocks(world, start, 129, -19, 70, 131, -19, 74, Blocks.SANDSTONE.getDefaultState());
        structure.fillWithBlocks(world, start, 129, -18, 52, 129, -18, 58, Blocks.SANDSTONE.getDefaultState());
        structure.fillWithBlocks(world, start, 129, -18, 68, 130, -18, 70, Blocks.SANDSTONE.getDefaultState());
        structure.fillWithBlocks(world, start, 129, -18, 74, 133, -14, 74, Blocks.SANDSTONE.getDefaultState());
        structure.fillWithBlocks(world, start, 129, -17, 50, 132, -17, 53, Blocks.SANDSTONE.getDefaultState());
        structure.fillWithBlocks(world, start, 129, -17, 66, 131, -17, 69, Blocks.SANDSTONE.getDefaultState());
        structure.fillWithBlocks(world, start, 129, -16, 73, 130, -16, 74, Blocks.SANDSTONE.getDefaultState());
        structure.fillWithBlocks(world, start, 129, -15, 60, 129, -15, 64, Blocks.AIR.getDefaultState());
        structure.fillWithBlocks(world, start, 129, -14, 50, 129, -14, 66, Blocks.SANDSTONE.getDefaultState());
        structure.fillWithBlocks(world, start, 129, -14, 68, 131, -14, 70, Blocks.SANDSTONE.getDefaultState());
        structure.fillWithBlocks(world, start, 129, -14, 71, 129, -14, 74, Blocks.SANDSTONE.getDefaultState());
        structure.fillWithBlocks(world, start, 129, -12, 55, 132, -12, 63, Blocks.SANDSTONE.getDefaultState());
        structure.fillWithBlocks(world, start, 129, -12, 69, 130, -12, 70, Blocks.SANDSTONE.getDefaultState());
        structure.fillWithBlocks(world, start, 129, -12, 72, 131, -12, 74, Blocks.SANDSTONE.getDefaultState());
        structure.fillWithBlocks(world, start, 129, -11, 26, 129, -10, 30, Blocks.SANDSTONE.getDefaultState());
        structure.fillWithBlocks(world, start, 129, -11, 60, 131, -11, 62, Blocks.SANDSTONE.getDefaultState());
        structure.fillWithBlocks(world, start, 129, -11, 65, 129, -11, 74, Blocks.SANDSTONE.getDefaultState());
        structure.fillWithBlocks(world, start, 129, -10, 22, 129, -10, 22, Blocks.SANDSTONE.getDefaultState());
        structure.fillWithBlocks(world, start, 129, -10, 23, 129, -10, 24, Blocks.AIR.getDefaultState());
        structure.fillWithBlocks(world, start, 129, -10, 25, 134, -10, 33, Blocks.SANDSTONE.getDefaultState());
        structure.fillWithBlocks(world, start, 129, -10, 34, 133, -6, 34, Blocks.SANDSTONE.getDefaultState());
        structure.fillWithBlocks(world, start, 129, -10, 56, 133, -10, 60, Blocks.SANDSTONE.getDefaultState());
        structure.fillWithBlocks(world, start, 129, -9, 22, 129, -9, 24, Blocks.SANDSTONE.getDefaultState());
        structure.fillWithBlocks(world, start, 129, -9, 25, 130, -9, 31, Blocks.AIR.getDefaultState());
        structure.fillWithBlocks(world, start, 129, -9, 32, 131, -9, 34, Blocks.SANDSTONE.getDefaultState());
        structure.fillWithBlocks(world, start, 129, -9, 56, 129, -7, 56, Blocks.STONE.getDefaultState());
        structure.fillWithBlocks(world, start, 129, -9, 60, 129, -7, 60, Blocks.STONE.getDefaultState());
        structure.fillWithBlocks(world, start, 129, -8, 22, 131, -8, 24, Blocks.SANDSTONE.getDefaultState());
        structure.fillWithBlocks(world, start, 129, -8, 25, 130, -8, 31, Blocks.AIR.getDefaultState());
        structure.fillWithBlocks(world, start, 129, -8, 32, 131, -8, 34, Blocks.SANDSTONE.getDefaultState());
        structure.fillWithBlocks(world, start, 129, -7, 22, 131, -7, 24, Blocks.SANDSTONE.getDefaultState());
        structure.fillWithBlocks(world, start, 129, -7, 32, 131, -7, 34, Blocks.SANDSTONE.getDefaultState());
        structure.fillWithBlocks(world, start, 129, -6, 32, 131, -6, 34, Blocks.SANDSTONE.getDefaultState());
        structure.fillWithBlocks(world, start, 129, -6, 56, 133, -6, 60, Blocks.SANDSTONE.getDefaultState());
        structure.fillWithBlocks(world, start, 129, -5, 22, 129, -4, 22, Blocks.AIR.getDefaultState());
        structure.fillWithBlocks(world, start, 129, -5, 23, 131, -5, 25, Blocks.SANDSTONE.getDefaultState());
        structure.fillWithBlocks(world, start, 129, -4, 23, 132, -4, 34, Blocks.SANDSTONE.getDefaultState());
        structure.fillWithBlocks(world, start, 129, -3, 22, 129, -3, 33, Blocks.SANDSTONE.getDefaultState());
        structure.fillWithBlocks(world, start, 129, -3, 34, 129, -2, 34, Blocks.AIR.getDefaultState());
        structure.fillWithBlocks(world, start, 129, -2, 23, 130, -2, 24, Blocks.SANDSTONE.getDefaultState());
        structure.fillWithBlocks(world, start, 129, -2, 26, 129, -2, 26, Blocks.SANDSTONE.getDefaultState());
        structure.fillWithBlocks(world, start, 129, -2, 28, 134, -2, 33, Blocks.SANDSTONE.getDefaultState());
        structure.fillWithBlocks(world, start, 129, -1, 32, 131, -1, 34, Blocks.SANDSTONE.getDefaultState());
        structure.fillWithBlocks(world, start, 129, 1, 15, 138, 1, 145, Blocks.STONE.getDefaultState());
        structure.fillWithBlocks(world, start, 129, 1, 146, 130, 1, 146, Blocks.STONE.getDefaultState());
        structure.fillWithBlocks(world, start, 129, 1, 147, 139, 1, 157, Blocks.SANDSTONE.getDefaultState());
        structure.fillWithBlocks(world, start, 129, 2, 144, 140, 2, 155, Blocks.SANDSTONE.getDefaultState());
        structure.fillWithBlocks(world, start, 129, 6, 15, 201, 6, 142, Blocks.SANDSTONE.getDefaultState());
        structure.fillWithBlocks(world, start, 129, 9, 29, 129, 9, 39, Blocks.SAND.getDefaultState());
        structure.fillWithBlocks(world, start, 129, 9, 40, 132, 9, 44, Blocks.SANDSTONE.getDefaultState());
        structure.fillWithBlocks(world, start, 129, 9, 45, 129, 9, 59, Blocks.SANDSTONE.getDefaultState());
        structure.fillWithBlocks(world, start, 129, 9, 85, 129, 11, 85, Blocks.SAND.getDefaultState());
        structure.fillWithBlocks(world, start, 129, 9, 96, 129, 11, 96, Blocks.SAND.getDefaultState());
        structure.fillWithBlocks(world, start, 129, 9, 102, 129, 9, 103, Blocks.SAND.getDefaultState());
        structure.fillWithBlocks(world, start, 129, 10, 31, 129, 10, 40, Blocks.SAND.getDefaultState());
        structure.fillWithBlocks(world, start, 129, 10, 41, 132, 10, 44, Blocks.SANDSTONE.getDefaultState());
        structure.fillWithBlocks(world, start, 129, 10, 45, 129, 10, 59, Blocks.SANDSTONE.getDefaultState());
