package mod.arcalitegames.odyssey.world.structure.structures.camps.tusken_raider_camp;

import mod.arcalitegames.buildersaddition.Index;
import mod.arcalitegames.buildersaddition.blocks.BedsideTable;
import mod.arcalitegames.buildersaddition.blocks.Bench;
import mod.arcalitegames.buildersaddition.blocks.Counter;
import mod.arcalitegames.buildersaddition.blocks.FireplaceGuard;
import mod.arcalitegames.buildersaddition.blocks.Shelf;
import mod.arcalitegames.buildersaddition.blocks.Stool;
import mod.arcalitegames.buildersaddition.blocks.SupportBracket;
import mod.arcalitegames.buildersaddition.blocks.Table;
import mod.arcalitegames.buildersaddition.blocks.VerticalSlab;
import mod.arcalitegames.buildersaddition.state.BenchState;
import mod.arcalitegames.buildersaddition.state.MountState;
import mod.arcalitegames.buildersaddition.state.StoolState;
import mod.arcalitegames.buildersaddition.state.VerticalSlabState;
import mod.arcalitegames.odyssey.blocks.ChairBlock;
import mod.arcalitegames.odyssey.blocks.ModBlocks;
import mod.arcalitegames.odyssey.world.structure.StructureBase;
import net.minecraft.block.AbstractFurnaceBlock;
import net.minecraft.block.AnvilBlock;
import net.minecraft.block.Blocks;
import net.minecraft.block.BrewingStandBlock;
import net.minecraft.block.CactusBlock;
import net.minecraft.block.CampfireBlock;
import net.minecraft.block.CauldronBlock;
import net.minecraft.block.ChestBlock;
import net.minecraft.block.DoorBlock;
import net.minecraft.block.FenceGateBlock;
import net.minecraft.block.FourWayBlock;
import net.minecraft.block.HorizontalBlock;
import net.minecraft.block.LadderBlock;
import net.minecraft.block.LanternBlock;
import net.minecraft.block.LecternBlock;
import net.minecraft.block.RailBlock;
import net.minecraft.block.RespawnAnchorBlock;
import net.minecraft.block.ScaffoldingBlock;
import net.minecraft.block.SlabBlock;
import net.minecraft.block.SnowyDirtBlock;
import net.minecraft.block.StairsBlock;
import net.minecraft.block.TrapDoorBlock;
import net.minecraft.block.WallBlock;
import net.minecraft.block.WallHeight;
import net.minecraft.block.WallTorchBlock;
import net.minecraft.state.properties.ChestType;
import net.minecraft.state.properties.DoorHingeSide;
import net.minecraft.state.properties.DoubleBlockHalf;
import net.minecraft.state.properties.Half;
import net.minecraft.state.properties.RailShape;
import net.minecraft.state.properties.SlabType;
import net.minecraft.state.properties.StairsShape;
import net.minecraft.util.Direction;
import net.minecraft.util.math.BlockPos;
import net.minecraft.world.World;

public class TuskenRaiderComponents
{

	public static BlockPos start;
    public static World world;
    public static StructureBase structure;

    public static void init(World worldIn, BlockPos blockPos, StructureBase structureIn)
    {
        world = worldIn; start = blockPos; structure = structureIn;
    }
    
    public static void generatePart1()
    {
        structure.setBlockState(world, Blocks.OAK_FENCE.getDefaultState().with(FourWayBlock.WATERLOGGED, false).with(FourWayBlock.NORTH, false).with(FourWayBlock.SOUTH, true).with(FourWayBlock.EAST, true).with(FourWayBlock.WEST, false), 6, 4, 101, start);
        structure.setBlockState(world, Blocks.OAK_FENCE.getDefaultState().with(FourWayBlock.WATERLOGGED, false).with(FourWayBlock.NORTH, true).with(FourWayBlock.SOUTH, true).with(FourWayBlock.EAST, true).with(FourWayBlock.WEST, false), 6, 4, 102, start);
        structure.setBlockState(world, Blocks.OAK_FENCE.getDefaultState().with(FourWayBlock.WATERLOGGED, false).with(FourWayBlock.NORTH, false).with(FourWayBlock.SOUTH, true).with(FourWayBlock.EAST, true).with(FourWayBlock.WEST, false), 7, 5, 101, start);
        structure.setBlockState(world, Blocks.OAK_FENCE.getDefaultState().with(FourWayBlock.WATERLOGGED, false).with(FourWayBlock.NORTH, true).with(FourWayBlock.SOUTH, true).with(FourWayBlock.EAST, false).with(FourWayBlock.WEST, false), 7, 5, 102, start);
        structure.setBlockState(world, Blocks.OAK_LOG.getDefaultState(), 7, 5, 103, start);
        structure.setBlockState(world, Blocks.OAK_FENCE.getDefaultState().with(FourWayBlock.WATERLOGGED, false).with(FourWayBlock.NORTH, true).with(FourWayBlock.SOUTH, true).with(FourWayBlock.EAST, true).with(FourWayBlock.WEST, false), 7, 5, 104, start);
        structure.setBlockState(world, Blocks.OAK_SLAB.getDefaultState().with(SlabBlock.TYPE, SlabType.BOTTOM).with(SlabBlock.WATERLOGGED, false), 7, 8, 103, start);
        structure.setBlockState(world, Blocks.OAK_FENCE.getDefaultState().with(FourWayBlock.WATERLOGGED, false).with(FourWayBlock.NORTH, true).with(FourWayBlock.SOUTH, false).with(FourWayBlock.EAST, false).with(FourWayBlock.WEST, true), 8, 6, 101, start);
        structure.setBlockState(world, Blocks.OAK_FENCE.getDefaultState().with(FourWayBlock.WATERLOGGED, false).with(FourWayBlock.NORTH, false).with(FourWayBlock.SOUTH, true).with(FourWayBlock.EAST, false).with(FourWayBlock.WEST, true), 8, 6, 103, start);
        structure.setBlockState(world, Blocks.OAK_FENCE.getDefaultState().with(FourWayBlock.WATERLOGGED, false).with(FourWayBlock.NORTH, true).with(FourWayBlock.SOUTH, true).with(FourWayBlock.EAST, false).with(FourWayBlock.WEST, false), 8, 6, 104, start);
        structure.setBlockState(world, Blocks.OAK_LOG.getDefaultState(), 8, 6, 105, start);
        structure.setBlockState(world, Blocks.OAK_FENCE.getDefaultState().with(FourWayBlock.WATERLOGGED, false).with(FourWayBlock.NORTH, true).with(FourWayBlock.SOUTH, true).with(FourWayBlock.EAST, true).with(FourWayBlock.WEST, false), 8, 7, 99, start);
        structure.setBlockState(world, Blocks.OAK_SLAB.getDefaultState().with(SlabBlock.TYPE, SlabType.BOTTOM).with(SlabBlock.WATERLOGGED, false), 8, 9, 105, start);
        structure.setBlockState(world, Blocks.OAK_FENCE.getDefaultState().with(FourWayBlock.WATERLOGGED, false).with(FourWayBlock.NORTH, false).with(FourWayBlock.SOUTH, true).with(FourWayBlock.EAST, false).with(FourWayBlock.WEST, true), 9, 6, 105, start);
        structure.setBlockState(world, Blocks.OAK_FENCE.getDefaultState().with(FourWayBlock.WATERLOGGED, false).with(FourWayBlock.NORTH, true).with(FourWayBlock.SOUTH, true).with(FourWayBlock.EAST, false).with(FourWayBlock.WEST, false), 9, 7, 99, start);
        structure.setBlockState(world, Blocks.OAK_FENCE.getDefaultState().with(FourWayBlock.WATERLOGGED, false).with(FourWayBlock.NORTH, true).with(FourWayBlock.SOUTH, false).with(FourWayBlock.EAST, false).with(FourWayBlock.WEST, true), 9, 7, 100, start);
        structure.setBlockState(world, Blocks.OAK_FENCE.getDefaultState().with(FourWayBlock.WATERLOGGED, false).with(FourWayBlock.NORTH, false).with(FourWayBlock.SOUTH, true).with(FourWayBlock.EAST, true).with(FourWayBlock.WEST, false), 9, 8, 97, start);
        structure.setBlockState(world, Blocks.OAK_FENCE.getDefaultState().with(FourWayBlock.WATERLOGGED, false).with(FourWayBlock.NORTH, true).with(FourWayBlock.SOUTH, false).with(FourWayBlock.EAST, true).with(FourWayBlock.WEST, false), 11, 6, 108, start);
        structure.setBlockState(world, Blocks.OAK_LOG.getDefaultState(), 11, 7, 108, start);
        structure.setBlockState(world, Blocks.OAK_SLAB.getDefaultState().with(SlabBlock.TYPE, SlabType.BOTTOM).with(SlabBlock.WATERLOGGED, false), 11, 10, 108, start);
        structure.setBlockState(world, Blocks.OAK_FENCE.getDefaultState().with(FourWayBlock.WATERLOGGED, false).with(FourWayBlock.NORTH, false).with(FourWayBlock.SOUTH, true).with(FourWayBlock.EAST, false).with(FourWayBlock.WEST, true), 12, 7, 108, start);
        structure.setBlockState(world, Blocks.STONE.getDefaultState(), 13, 1, 107, start);
        structure.setBlockState(world, Blocks.DEAD_BUSH.getDefaultState(), 13, 7, 95, start);
        structure.setBlockState(world, Blocks.DEAD_BUSH.getDefaultState(), 13, 7, 103, start);
        structure.setBlockState(world, Blocks.OAK_FENCE.getDefaultState().with(FourWayBlock.WATERLOGGED, false).with(FourWayBlock.NORTH, false).with(FourWayBlock.SOUTH, false).with(FourWayBlock.EAST, true).with(FourWayBlock.WEST, true), 13, 7, 109, start);
        structure.setBlockState(world, Blocks.OAK_FENCE.getDefaultState().with(FourWayBlock.WATERLOGGED, false).with(FourWayBlock.NORTH, true).with(FourWayBlock.SOUTH, false).with(FourWayBlock.EAST, true).with(FourWayBlock.WEST, true), 13, 8, 110, start);
        structure.setBlockState(world, Blocks.OAK_FENCE.getDefaultState().with(FourWayBlock.WATERLOGGED, false).with(FourWayBlock.NORTH, false).with(FourWayBlock.SOUTH, true).with(FourWayBlock.EAST, false).with(FourWayBlock.WEST, true), 14, 7, 109, start);
        structure.setBlockState(world, Blocks.OAK_FENCE.getDefaultState().with(FourWayBlock.WATERLOGGED, false).with(FourWayBlock.NORTH, true).with(FourWayBlock.SOUTH, false).with(FourWayBlock.EAST, true).with(FourWayBlock.WEST, false), 14, 7, 110, start);
        structure.setBlockState(world, Blocks.OAK_FENCE.getDefaultState().with(FourWayBlock.WATERLOGGED, false).with(FourWayBlock.NORTH, true).with(FourWayBlock.SOUTH, false).with(FourWayBlock.EAST, true).with(FourWayBlock.WEST, false), 14, 8, 111, start);
        structure.setBlockState(world, Blocks.STONE.getDefaultState(), 15, 1, 104, start);
        structure.setBlockState(world, Blocks.OAK_FENCE.getDefaultState().with(FourWayBlock.WATERLOGGED, false).with(FourWayBlock.NORTH, false).with(FourWayBlock.SOUTH, true).with(FourWayBlock.EAST, true).with(FourWayBlock.WEST, false), 16, 7, 97, start);
        structure.setBlockState(world, Blocks.OAK_FENCE.getDefaultState().with(FourWayBlock.WATERLOGGED, false).with(FourWayBlock.NORTH, true).with(FourWayBlock.SOUTH, false).with(FourWayBlock.EAST, false).with(FourWayBlock.WEST, true), 16, 7, 98, start);
        structure.setBlockState(world, Blocks.AIR.getDefaultState(), 16, 7, 104, start);
        structure.setBlockState(world, Blocks.OAK_FENCE.getDefaultState().with(FourWayBlock.WATERLOGGED, false).with(FourWayBlock.NORTH, false).with(FourWayBlock.SOUTH, true).with(FourWayBlock.EAST, true).with(FourWayBlock.WEST, false), 16, 8, 96, start);
        structure.setBlockState(world, Blocks.DEAD_BUSH.getDefaultState(), 17, 7, 95, start);
        structure.setBlockState(world, Blocks.OAK_FENCE.getDefaultState().with(FourWayBlock.WATERLOGGED, false).with(FourWayBlock.NORTH, false).with(FourWayBlock.SOUTH, true).with(FourWayBlock.EAST, true).with(FourWayBlock.WEST, false), 17, 7, 96, start);
        structure.setBlockState(world, Blocks.OAK_FENCE.getDefaultState().with(FourWayBlock.WATERLOGGED, false).with(FourWayBlock.NORTH, true).with(FourWayBlock.SOUTH, false).with(FourWayBlock.EAST, false).with(FourWayBlock.WEST, true), 17, 7, 97, start);
        structure.setBlockState(world, Blocks.OAK_FENCE.getDefaultState().with(FourWayBlock.WATERLOGGED, false).with(FourWayBlock.NORTH, false).with(FourWayBlock.SOUTH, true).with(FourWayBlock.EAST, true).with(FourWayBlock.WEST, false), 17, 8, 94, start);
        structure.setBlockState(world, Blocks.OAK_FENCE.getDefaultState().with(FourWayBlock.WATERLOGGED, false).with(FourWayBlock.NORTH, true).with(FourWayBlock.SOUTH, true).with(FourWayBlock.EAST, true).with(FourWayBlock.WEST, false), 17, 8, 95, start);
        structure.setBlockState(world, Blocks.OAK_TRAPDOOR.getDefaultState().with(HorizontalBlock.HORIZONTAL_FACING, Direction.WEST).with(TrapDoorBlock.HALF, Half.TOP).with(TrapDoorBlock.WATERLOGGED, false).with(TrapDoorBlock.POWERED, false).with(TrapDoorBlock.OPEN, true), 17, 13, 122, start);
        structure.setBlockState(world, Blocks.STONE.getDefaultState(), 18, 1, 27, start);
        structure.setBlockState(world, Blocks.STONE.getDefaultState(), 18, 1, 57, start);
        structure.setBlockState(world, Blocks.OAK_FENCE.getDefaultState().with(FourWayBlock.WATERLOGGED, false).with(FourWayBlock.NORTH, false).with(FourWayBlock.SOUTH, true).with(FourWayBlock.EAST, true).with(FourWayBlock.WEST, false), 18, 7, 94, start);
        structure.setBlockState(world, Blocks.OAK_FENCE.getDefaultState().with(FourWayBlock.WATERLOGGED, false).with(FourWayBlock.NORTH, true).with(FourWayBlock.SOUTH, true).with(FourWayBlock.EAST, false).with(FourWayBlock.WEST, false), 18, 7, 95, start);
        structure.setBlockState(world, Blocks.OAK_FENCE.getDefaultState().with(FourWayBlock.WATERLOGGED, false).with(FourWayBlock.NORTH, true).with(FourWayBlock.SOUTH, false).with(FourWayBlock.EAST, false).with(FourWayBlock.WEST, true), 18, 7, 96, start);
        structure.setBlockState(world, Blocks.OAK_FENCE.getDefaultState().with(FourWayBlock.WATERLOGGED, false).with(FourWayBlock.NORTH, false).with(FourWayBlock.SOUTH, true).with(FourWayBlock.EAST, true).with(FourWayBlock.WEST, false), 18, 7, 109, start);
        structure.setBlockState(world, Blocks.OAK_FENCE.getDefaultState().with(FourWayBlock.WATERLOGGED, false).with(FourWayBlock.NORTH, true).with(FourWayBlock.SOUTH, false).with(FourWayBlock.EAST, false).with(FourWayBlock.WEST, true), 18, 7, 110, start);
        structure.setBlockState(world, Blocks.OAK_FENCE.getDefaultState().with(FourWayBlock.WATERLOGGED, false).with(FourWayBlock.NORTH, false).with(FourWayBlock.SOUTH, true).with(FourWayBlock.EAST, true).with(FourWayBlock.WEST, false), 18, 8, 93, start);
        structure.setBlockState(world, Blocks.OAK_FENCE.getDefaultState().with(FourWayBlock.WATERLOGGED, false).with(FourWayBlock.NORTH, true).with(FourWayBlock.SOUTH, false).with(FourWayBlock.EAST, false).with(FourWayBlock.WEST, true), 18, 8, 111, start);
        structure.setBlockState(world, Blocks.OAK_FENCE.getDefaultState().with(FourWayBlock.WATERLOGGED, false).with(FourWayBlock.NORTH, false).with(FourWayBlock.SOUTH, false).with(FourWayBlock.EAST, false).with(FourWayBlock.WEST, false), 18, 8, 123, start);
        structure.setBlockState(world, Blocks.SPRUCE_SLAB.getDefaultState().with(SlabBlock.TYPE, SlabType.BOTTOM).with(SlabBlock.WATERLOGGED, false), 18, 9, 55, start);
        structure.setBlockState(world, Blocks.OAK_FENCE.getDefaultState().with(FourWayBlock.WATERLOGGED, false).with(FourWayBlock.NORTH, false).with(FourWayBlock.SOUTH, false).with(FourWayBlock.EAST, true).with(FourWayBlock.WEST, false), 18, 9, 56, start);
        structure.setBlockState(world, Blocks.COBBLESTONE_WALL.getDefaultState().with(WallBlock.WATERLOGGED, false).with(WallBlock.UP, false).with(WallBlock.WALL_HEIGHT_NORTH, WallHeight.LOW).with(WallBlock.WALL_HEIGHT_SOUTH, WallHeight.LOW).with(WallBlock.WALL_HEIGHT_EAST, WallHeight.LOW).with(WallBlock.WALL_HEIGHT_WEST, WallHeight.LOW), 18, 9, 122, start);
        structure.setBlockState(world, Blocks.COBBLESTONE_WALL.getDefaultState().with(WallBlock.WATERLOGGED, false).with(WallBlock.UP, true).with(WallBlock.WALL_HEIGHT_NORTH, WallHeight.LOW).with(WallBlock.WALL_HEIGHT_SOUTH, WallHeight.LOW).with(WallBlock.WALL_HEIGHT_EAST, WallHeight.LOW).with(WallBlock.WALL_HEIGHT_WEST, WallHeight.LOW), 18, 9, 123, start);
        structure.setBlockState(world, Blocks.SPRUCE_SLAB.getDefaultState().with(SlabBlock.TYPE, SlabType.BOTTOM).with(SlabBlock.WATERLOGGED, false), 18, 10, 53, start);
        structure.setBlockState(world, Blocks.SPRUCE_FENCE.getDefaultState().with(FourWayBlock.WATERLOGGED, false).with(FourWayBlock.NORTH, false).with(FourWayBlock.SOUTH, false).with(FourWayBlock.EAST, false).with(FourWayBlock.WEST, false), 18, 12, 54, start);
        structure.setBlockState(world, Blocks.COBBLESTONE_WALL.getDefaultState().with(WallBlock.WATERLOGGED, false).with(WallBlock.UP, false).with(WallBlock.WALL_HEIGHT_NORTH, WallHeight.LOW).with(WallBlock.WALL_HEIGHT_SOUTH, WallHeight.LOW).with(WallBlock.WALL_HEIGHT_EAST, WallHeight.LOW).with(WallBlock.WALL_HEIGHT_WEST, WallHeight.LOW), 18, 12, 122, start);
        structure.setBlockState(world, Blocks.COBBLESTONE_WALL.getDefaultState().with(WallBlock.WATERLOGGED, false).with(WallBlock.UP, true).with(WallBlock.WALL_HEIGHT_NORTH, WallHeight.LOW).with(WallBlock.WALL_HEIGHT_SOUTH, WallHeight.LOW).with(WallBlock.WALL_HEIGHT_EAST, WallHeight.LOW).with(WallBlock.WALL_HEIGHT_WEST, WallHeight.LOW), 18, 12, 123, start);
        structure.setBlockState(world, Blocks.OAK_TRAPDOOR.getDefaultState().with(HorizontalBlock.HORIZONTAL_FACING, Direction.NORTH).with(TrapDoorBlock.HALF, Half.BOTTOM).with(TrapDoorBlock.WATERLOGGED, false).with(TrapDoorBlock.POWERED, false).with(TrapDoorBlock.OPEN, true), 18, 13, 121, start);
        structure.setBlockState(world, Blocks.GLOWSTONE.getDefaultState(), 18, 13, 122, start);
        structure.setBlockState(world, Blocks.OAK_TRAPDOOR.getDefaultState().with(HorizontalBlock.HORIZONTAL_FACING, Direction.SOUTH).with(TrapDoorBlock.HALF, Half.BOTTOM).with(TrapDoorBlock.WATERLOGGED, false).with(TrapDoorBlock.POWERED, false).with(TrapDoorBlock.OPEN, true), 18, 13, 123, start);
        structure.setBlockState(world, Blocks.OAK_TRAPDOOR.getDefaultState().with(HorizontalBlock.HORIZONTAL_FACING, Direction.WEST).with(TrapDoorBlock.HALF, Half.BOTTOM).with(TrapDoorBlock.WATERLOGGED, false).with(TrapDoorBlock.POWERED, false).with(TrapDoorBlock.OPEN, false), 18, 14, 122, start);
        structure.setBlockState(world, Blocks.OAK_FENCE.getDefaultState().with(FourWayBlock.WATERLOGGED, false).with(FourWayBlock.NORTH, false).with(FourWayBlock.SOUTH, true).with(FourWayBlock.EAST, true).with(FourWayBlock.WEST, false), 19, 7, 93, start);
        structure.setBlockState(world, Blocks.OAK_FENCE.getDefaultState().with(FourWayBlock.WATERLOGGED, false).with(FourWayBlock.NORTH, true).with(FourWayBlock.SOUTH, false).with(FourWayBlock.EAST, false).with(FourWayBlock.WEST, true), 19, 7, 94, start);
        structure.setBlockState(world, Blocks.OAK_FENCE.getDefaultState().with(FourWayBlock.WATERLOGGED, false).with(FourWayBlock.NORTH, false).with(FourWayBlock.SOUTH, false).with(FourWayBlock.EAST, true).with(FourWayBlock.WEST, true), 19, 7, 109, start);
        structure.setBlockState(world, Blocks.OAK_FENCE.getDefaultState().with(FourWayBlock.WATERLOGGED, false).with(FourWayBlock.NORTH, false).with(FourWayBlock.SOUTH, true).with(FourWayBlock.EAST, true).with(FourWayBlock.WEST, false), 19, 8, 91, start);
        structure.setBlockState(world, Blocks.OAK_FENCE.getDefaultState().with(FourWayBlock.WATERLOGGED, false).with(FourWayBlock.NORTH, true).with(FourWayBlock.SOUTH, true).with(FourWayBlock.EAST, true).with(FourWayBlock.WEST, false), 19, 8, 92, start);
        structure.setBlockState(world, Blocks.OAK_FENCE.getDefaultState().with(FourWayBlock.WATERLOGGED, false).with(FourWayBlock.NORTH, true).with(FourWayBlock.SOUTH, false).with(FourWayBlock.EAST, true).with(FourWayBlock.WEST, true), 19, 8, 110, start);
        structure.setBlockState(world, Blocks.OAK_FENCE.getDefaultState().with(FourWayBlock.WATERLOGGED, false).with(FourWayBlock.NORTH, false).with(FourWayBlock.SOUTH, false).with(FourWayBlock.EAST, false).with(FourWayBlock.WEST, false), 19, 8, 122, start);
        structure.setBlockState(world, Blocks.COBBLESTONE_WALL.getDefaultState().with(WallBlock.WATERLOGGED, false).with(WallBlock.UP, true).with(WallBlock.WALL_HEIGHT_NORTH, WallHeight.LOW).with(WallBlock.WALL_HEIGHT_SOUTH, WallHeight.LOW).with(WallBlock.WALL_HEIGHT_EAST, WallHeight.LOW).with(WallBlock.WALL_HEIGHT_WEST, WallHeight.LOW), 19, 9, 122, start);
        structure.setBlockState(world, Blocks.SPRUCE_SLAB.getDefaultState().with(SlabBlock.TYPE, SlabType.BOTTOM).with(SlabBlock.WATERLOGGED, false), 19, 10, 51, start);
        structure.setBlockState(world, Blocks.OAK_LOG.getDefaultState(), 19, 10, 52, start);
        structure.setBlockState(world, Blocks.SPRUCE_SLAB.getDefaultState().with(SlabBlock.TYPE, SlabType.BOTTOM).with(SlabBlock.WATERLOGGED, false), 19, 10, 56, start);
        structure.setBlockState(world, Blocks.SPRUCE_SLAB.getDefaultState().with(SlabBlock.TYPE, SlabType.BOTTOM).with(SlabBlock.WATERLOGGED, false), 19, 11, 52, start);
        structure.setBlockState(world, Blocks.SPRUCE_FENCE.getDefaultState().with(FourWayBlock.WATERLOGGED, false).with(FourWayBlock.NORTH, false).with(FourWayBlock.SOUTH, false).with(FourWayBlock.EAST, false).with(FourWayBlock.WEST, false), 19, 12, 57, start);
        structure.setBlockState(world, Blocks.COBBLESTONE_WALL.getDefaultState().with(WallBlock.WATERLOGGED, false).with(WallBlock.UP, true).with(WallBlock.WALL_HEIGHT_NORTH, WallHeight.LOW).with(WallBlock.WALL_HEIGHT_SOUTH, WallHeight.LOW).with(WallBlock.WALL_HEIGHT_EAST, WallHeight.LOW).with(WallBlock.WALL_HEIGHT_WEST, WallHeight.LOW), 19, 12, 122, start);
        structure.setBlockState(world, Blocks.OAK_TRAPDOOR.getDefaultState().with(HorizontalBlock.HORIZONTAL_FACING, Direction.EAST).with(TrapDoorBlock.HALF, Half.TOP).with(TrapDoorBlock.WATERLOGGED, false).with(TrapDoorBlock.POWERED, false).with(TrapDoorBlock.OPEN, true), 19, 13, 122, start);
        structure.setBlockState(world, Blocks.OAK_FENCE.getDefaultState().with(FourWayBlock.WATERLOGGED, false).with(FourWayBlock.NORTH, false).with(FourWayBlock.SOUTH, true).with(FourWayBlock.EAST, true).with(FourWayBlock.WEST, false), 20, 7, 91, start);
        structure.setBlockState(world, Blocks.OAK_FENCE.getDefaultState().with(FourWayBlock.WATERLOGGED, false).with(FourWayBlock.NORTH, true).with(FourWayBlock.SOUTH, true).with(FourWayBlock.EAST, false).with(FourWayBlock.WEST, false), 20, 7, 92, start);
        structure.setBlockState(world, Blocks.OAK_FENCE.getDefaultState().with(FourWayBlock.WATERLOGGED, false).with(FourWayBlock.NORTH, true).with(FourWayBlock.SOUTH, false).with(FourWayBlock.EAST, false).with(FourWayBlock.WEST, true), 20, 7, 93, start);
        structure.setBlockState(world, Blocks.OAK_FENCE.getDefaultState().with(FourWayBlock.WATERLOGGED, false).with(FourWayBlock.NORTH, false).with(FourWayBlock.SOUTH, true).with(FourWayBlock.EAST, true).with(FourWayBlock.WEST, false), 20, 7, 108, start);
        structure.setBlockState(world, Blocks.OAK_FENCE.getDefaultState().with(FourWayBlock.WATERLOGGED, false).with(FourWayBlock.NORTH, true).with(FourWayBlock.SOUTH, false).with(FourWayBlock.EAST, false).with(FourWayBlock.WEST, true), 20, 7, 109, start);
        structure.setBlockState(world, Blocks.OAK_FENCE.getDefaultState().with(FourWayBlock.WATERLOGGED, false).with(FourWayBlock.NORTH, false).with(FourWayBlock.SOUTH, true).with(FourWayBlock.EAST, true).with(FourWayBlock.WEST, false), 20, 8, 90, start);
        structure.setBlockState(world, Blocks.OAK_FENCE.getDefaultState().with(FourWayBlock.WATERLOGGED, false).with(FourWayBlock.NORTH, true).with(FourWayBlock.SOUTH, false).with(FourWayBlock.EAST, false).with(FourWayBlock.WEST, true), 20, 8, 110, start);
        structure.setBlockState(world, Blocks.SPRUCE_SLAB.getDefaultState().with(SlabBlock.TYPE, SlabType.BOTTOM).with(SlabBlock.WATERLOGGED, false), 20, 10, 58, start);
        structure.setBlockState(world, Blocks.STONE.getDefaultState(), 21, 1, 19, start);
        structure.setBlockState(world, Blocks.OAK_FENCE.getDefaultState().with(FourWayBlock.WATERLOGGED, false).with(FourWayBlock.NORTH, false).with(FourWayBlock.SOUTH, false).with(FourWayBlock.EAST, true).with(FourWayBlock.WEST, true), 21, 7, 91, start);
        structure.setBlockState(world, Blocks.OAK_FENCE.getDefaultState().with(FourWayBlock.WATERLOGGED, false).with(FourWayBlock.NORTH, false).with(FourWayBlock.SOUTH, true).with(FourWayBlock.EAST, true).with(FourWayBlock.WEST, true), 21, 8, 90, start);
        structure.setBlockState(world, Blocks.SPRUCE_SLAB.getDefaultState().with(SlabBlock.TYPE, SlabType.BOTTOM).with(SlabBlock.WATERLOGGED, false), 21, 10, 48, start);
        structure.setBlockState(world, Blocks.SPRUCE_FENCE.getDefaultState().with(FourWayBlock.WATERLOGGED, false).with(FourWayBlock.NORTH, false).with(FourWayBlock.SOUTH, false).with(FourWayBlock.EAST, false).with(FourWayBlock.WEST, false), 21, 11, 59, start);
        structure.setBlockState(world, Blocks.SPRUCE_FENCE.getDefaultState().with(FourWayBlock.WATERLOGGED, false).with(FourWayBlock.NORTH, false).with(FourWayBlock.SOUTH, false).with(FourWayBlock.EAST, false).with(FourWayBlock.WEST, false), 21, 12, 47, start);
        structure.setBlockState(world, Blocks.STONE.getDefaultState(), 22, 1, 54, start);
        structure.setBlockState(world, Blocks.DEAD_BUSH.getDefaultState(), 22, 7, 66, start);
        structure.setBlockState(world, Blocks.OAK_FENCE.getDefaultState().with(FourWayBlock.WATERLOGGED, false).with(FourWayBlock.NORTH, false).with(FourWayBlock.SOUTH, true).with(FourWayBlock.EAST, true).with(FourWayBlock.WEST, false), 22, 7, 90, start);
        structure.setBlockState(world, Blocks.OAK_FENCE.getDefaultState().with(FourWayBlock.WATERLOGGED, false).with(FourWayBlock.NORTH, true).with(FourWayBlock.SOUTH, false).with(FourWayBlock.EAST, false).with(FourWayBlock.WEST, true), 22, 7, 91, start);
        structure.setBlockState(world, Blocks.AIR.getDefaultState(), 22, 7, 98, start);
        structure.setBlockState(world, Blocks.OAK_FENCE.getDefaultState().with(FourWayBlock.WATERLOGGED, false).with(FourWayBlock.NORTH, false).with(FourWayBlock.SOUTH, true).with(FourWayBlock.EAST, true).with(FourWayBlock.WEST, false), 22, 8, 89, start);
        structure.setBlockState(world, Blocks.SPRUCE_SLAB.getDefaultState().with(SlabBlock.TYPE, SlabType.BOTTOM).with(SlabBlock.WATERLOGGED, false), 22, 10, 46, start);
        structure.setBlockState(world, Blocks.OAK_FENCE.getDefaultState().with(FourWayBlock.WATERLOGGED, false).with(FourWayBlock.NORTH, false).with(FourWayBlock.SOUTH, false).with(FourWayBlock.EAST, true).with(FourWayBlock.WEST, true), 23, 7, 90, start);
        structure.setBlockState(world, Blocks.OAK_FENCE.getDefaultState().with(FourWayBlock.WATERLOGGED, false).with(FourWayBlock.NORTH, false).with(FourWayBlock.SOUTH, true).with(FourWayBlock.EAST, true).with(FourWayBlock.WEST, false), 23, 7, 107, start);
        structure.setBlockState(world, Blocks.OAK_FENCE.getDefaultState().with(FourWayBlock.WATERLOGGED, false).with(FourWayBlock.NORTH, true).with(FourWayBlock.SOUTH, false).with(FourWayBlock.EAST, false).with(FourWayBlock.WEST, true), 23, 7, 108, start);
        structure.setBlockState(world, Blocks.OAK_FENCE.getDefaultState().with(FourWayBlock.WATERLOGGED, false).with(FourWayBlock.NORTH, false).with(FourWayBlock.SOUTH, true).with(FourWayBlock.EAST, true).with(FourWayBlock.WEST, true), 23, 8, 89, start);
        structure.setBlockState(world, Blocks.OAK_FENCE.getDefaultState().with(FourWayBlock.WATERLOGGED, false).with(FourWayBlock.NORTH, true).with(FourWayBlock.SOUTH, false).with(FourWayBlock.EAST, false).with(FourWayBlock.WEST, true), 23, 8, 109, start);
        structure.setBlockState(world, Blocks.SPRUCE_SLAB.getDefaultState().with(SlabBlock.TYPE, SlabType.BOTTOM).with(SlabBlock.WATERLOGGED, false), 23, 10, 45, start);
        structure.setBlockState(world, Blocks.SPRUCE_SLAB.getDefaultState().with(SlabBlock.TYPE, SlabType.BOTTOM).with(SlabBlock.WATERLOGGED, false), 23, 10, 61, start);
        structure.setBlockState(world, Blocks.AIR.getDefaultState(), 24, 7, 54, start);
        structure.setBlockState(world, Blocks.OAK_FENCE.getDefaultState().with(FourWayBlock.WATERLOGGED, false).with(FourWayBlock.NORTH, false).with(FourWayBlock.SOUTH, true).with(FourWayBlock.EAST, true).with(FourWayBlock.WEST, false), 24, 7, 89, start);
        structure.setBlockState(world, Blocks.OAK_FENCE.getDefaultState().with(FourWayBlock.WATERLOGGED, false).with(FourWayBlock.NORTH, true).with(FourWayBlock.SOUTH, false).with(FourWayBlock.EAST, false).with(FourWayBlock.WEST, true), 24, 7, 90, start);
        structure.setBlockState(world, Blocks.OAK_FENCE.getDefaultState().with(FourWayBlock.WATERLOGGED, false).with(FourWayBlock.NORTH, false).with(FourWayBlock.SOUTH, true).with(FourWayBlock.EAST, true).with(FourWayBlock.WEST, false), 24, 7, 106, start);
        structure.setBlockState(world, Blocks.OAK_FENCE.getDefaultState().with(FourWayBlock.WATERLOGGED, false).with(FourWayBlock.NORTH, true).with(FourWayBlock.SOUTH, false).with(FourWayBlock.EAST, false).with(FourWayBlock.WEST, true), 24, 7, 107, start);
        structure.setBlockState(world, Blocks.OAK_FENCE.getDefaultState().with(FourWayBlock.WATERLOGGED, false).with(FourWayBlock.NORTH, false).with(FourWayBlock.SOUTH, true).with(FourWayBlock.EAST, true).with(FourWayBlock.WEST, false), 24, 8, 88, start);
        structure.setBlockState(world, Blocks.OAK_FENCE.getDefaultState().with(FourWayBlock.WATERLOGGED, false).with(FourWayBlock.NORTH, true).with(FourWayBlock.SOUTH, false).with(FourWayBlock.EAST, false).with(FourWayBlock.WEST, true), 24, 8, 108, start);
        structure.setBlockState(world, Blocks.OAK_LOG.getDefaultState(), 24, 10, 61, start);
        structure.setBlockState(world, Blocks.SPRUCE_FENCE.getDefaultState().with(FourWayBlock.WATERLOGGED, false).with(FourWayBlock.NORTH, false).with(FourWayBlock.SOUTH, false).with(FourWayBlock.EAST, false).with(FourWayBlock.WEST, false), 24, 11, 44, start);
        structure.setBlockState(world, Blocks.SPRUCE_SLAB.getDefaultState().with(SlabBlock.TYPE, SlabType.BOTTOM).with(SlabBlock.WATERLOGGED, false), 24, 11, 61, start);
        structure.setBlockState(world, Blocks.OAK_FENCE.getDefaultState().with(FourWayBlock.WATERLOGGED, false).with(FourWayBlock.NORTH, true).with(FourWayBlock.SOUTH, false).with(FourWayBlock.EAST, true).with(FourWayBlock.WEST, false), 25, 7, 62, start);
        structure.setBlockState(world, Blocks.OAK_FENCE.getDefaultState().with(FourWayBlock.WATERLOGGED, false).with(FourWayBlock.NORTH, false).with(FourWayBlock.SOUTH, true).with(FourWayBlock.EAST, true).with(FourWayBlock.WEST, false), 25, 7, 104, start);
        structure.setBlockState(world, Blocks.OAK_FENCE.getDefaultState().with(FourWayBlock.WATERLOGGED, false).with(FourWayBlock.NORTH, true).with(FourWayBlock.SOUTH, true).with(FourWayBlock.EAST, false).with(FourWayBlock.WEST, false), 25, 7, 105, start);
        structure.setBlockState(world, Blocks.OAK_FENCE.getDefaultState().with(FourWayBlock.WATERLOGGED, false).with(FourWayBlock.NORTH, true).with(FourWayBlock.SOUTH, false).with(FourWayBlock.EAST, false).with(FourWayBlock.WEST, true), 25, 7, 106, start);
        structure.setBlockState(world, Blocks.DEAD_BUSH.getDefaultState(), 25, 7, 120, start);
        structure.setBlockState(world, Blocks.OAK_FENCE.getDefaultState().with(FourWayBlock.WATERLOGGED, false).with(FourWayBlock.NORTH, true).with(FourWayBlock.SOUTH, false).with(FourWayBlock.EAST, false).with(FourWayBlock.WEST, true), 25, 8, 107, start);
        structure.setBlockState(world, Blocks.SPRUCE_SLAB.getDefaultState().with(SlabBlock.TYPE, SlabType.BOTTOM).with(SlabBlock.WATERLOGGED, false), 25, 10, 61, start);
        structure.setBlockState(world, Blocks.AIR.getDefaultState(), 26, 7, 49, start);
        structure.setBlockState(world, Blocks.OAK_FENCE.getDefaultState().with(FourWayBlock.WATERLOGGED, false).with(FourWayBlock.NORTH, true).with(FourWayBlock.SOUTH, true).with(FourWayBlock.EAST, true).with(FourWayBlock.WEST, true), 26, 7, 61, start);
        structure.setBlockState(world, Blocks.OAK_FENCE.getDefaultState().with(FourWayBlock.WATERLOGGED, false).with(FourWayBlock.NORTH, false).with(FourWayBlock.SOUTH, true).with(FourWayBlock.EAST, true).with(FourWayBlock.WEST, false), 26, 7, 103, start);
        structure.setBlockState(world, Blocks.OAK_FENCE.getDefaultState().with(FourWayBlock.WATERLOGGED, false).with(FourWayBlock.NORTH, true).with(FourWayBlock.SOUTH, false).with(FourWayBlock.EAST, false).with(FourWayBlock.WEST, true), 26, 7, 104, start);
        structure.setBlockState(world, Blocks.OAK_FENCE.getDefaultState().with(FourWayBlock.WATERLOGGED, false).with(FourWayBlock.NORTH, true).with(FourWayBlock.SOUTH, false).with(FourWayBlock.EAST, false).with(FourWayBlock.WEST, true), 26, 8, 61, start);
        structure.setBlockState(world, Blocks.OAK_FENCE.getDefaultState().with(FourWayBlock.WATERLOGGED, false).with(FourWayBlock.NORTH, true).with(FourWayBlock.SOUTH, true).with(FourWayBlock.EAST, false).with(FourWayBlock.WEST, true), 26, 8, 105, start);
        structure.setBlockState(world, Blocks.OAK_FENCE.getDefaultState().with(FourWayBlock.WATERLOGGED, false).with(FourWayBlock.NORTH, true).with(FourWayBlock.SOUTH, false).with(FourWayBlock.EAST, false).with(FourWayBlock.WEST, true), 26, 8, 106, start);
        structure.setBlockState(world, Blocks.SPRUCE_SLAB.getDefaultState().with(SlabBlock.TYPE, SlabType.BOTTOM).with(SlabBlock.WATERLOGGED, false), 26, 9, 59, start);
        structure.setBlockState(world, Blocks.SPRUCE_SLAB.getDefaultState().with(SlabBlock.TYPE, SlabType.BOTTOM).with(SlabBlock.WATERLOGGED, false), 26, 11, 60, start);
        structure.setBlockState(world, Blocks.STONE.getDefaultState(), 27, 2, 129, start);
        structure.setBlockState(world, Blocks.AIR.getDefaultState(), 27, 7, 96, start);
        structure.setBlockState(world, Blocks.OAK_FENCE.getDefaultState().with(FourWayBlock.WATERLOGGED, false).with(FourWayBlock.NORTH, false).with(FourWayBlock.SOUTH, true).with(FourWayBlock.EAST, true).with(FourWayBlock.WEST, false), 27, 7, 101, start);
        structure.setBlockState(world, Blocks.OAK_FENCE.getDefaultState().with(FourWayBlock.WATERLOGGED, false).with(FourWayBlock.NORTH, true).with(FourWayBlock.SOUTH, true).with(FourWayBlock.EAST, false).with(FourWayBlock.WEST, false), 27, 7, 102, start);
        structure.setBlockState(world, Blocks.OAK_FENCE.getDefaultState().with(FourWayBlock.WATERLOGGED, false).with(FourWayBlock.NORTH, true).with(FourWayBlock.SOUTH, false).with(FourWayBlock.EAST, false).with(FourWayBlock.WEST, true), 27, 7, 103, start);
        structure.setBlockState(world, Blocks.OAK_FENCE.getDefaultState().with(FourWayBlock.WATERLOGGED, false).with(FourWayBlock.NORTH, true).with(FourWayBlock.SOUTH, false).with(FourWayBlock.EAST, false).with(FourWayBlock.WEST, true), 27, 8, 104, start);
        structure.setBlockState(world, Blocks.SPRUCE_SLAB.getDefaultState().with(SlabBlock.TYPE, SlabType.BOTTOM).with(SlabBlock.WATERLOGGED, false), 27, 9, 41, start);
        structure.setBlockState(world, Blocks.SPRUCE_SLAB.getDefaultState().with(SlabBlock.TYPE, SlabType.BOTTOM).with(SlabBlock.WATERLOGGED, false), 27, 9, 78, start);
        structure.setBlockState(world, Blocks.OAK_LOG.getDefaultState(), 27, 10, 79, start);
        structure.setBlockState(world, Blocks.SPRUCE_SLAB.getDefaultState().with(SlabBlock.TYPE, SlabType.BOTTOM).with(SlabBlock.WATERLOGGED, false), 27, 10, 80, start);
        structure.setBlockState(world, Blocks.SPRUCE_FENCE.getDefaultState().with(FourWayBlock.WATERLOGGED, false).with(FourWayBlock.NORTH, false).with(FourWayBlock.SOUTH, false).with(FourWayBlock.EAST, false).with(FourWayBlock.WEST, false), 27, 11, 79, start);
        structure.setBlockState(world, Blocks.SPRUCE_FENCE.getDefaultState().with(FourWayBlock.WATERLOGGED, false).with(FourWayBlock.NORTH, false).with(FourWayBlock.SOUTH, false).with(FourWayBlock.EAST, false).with(FourWayBlock.WEST, false), 27, 12, 42, start);
        structure.setBlockState(world, Blocks.SPRUCE_FENCE.getDefaultState().with(FourWayBlock.WATERLOGGED, false).with(FourWayBlock.NORTH, false).with(FourWayBlock.SOUTH, false).with(FourWayBlock.EAST, false).with(FourWayBlock.WEST, false), 27, 12, 58, start);
        structure.setBlockState(world, Blocks.OAK_FENCE.getDefaultState().with(FourWayBlock.WATERLOGGED, false).with(FourWayBlock.NORTH, false).with(FourWayBlock.SOUTH, false).with(FourWayBlock.EAST, true).with(FourWayBlock.WEST, true), 28, 7, 101, start);
        structure.setBlockState(world, Blocks.OAK_FENCE.getDefaultState().with(FourWayBlock.WATERLOGGED, false).with(FourWayBlock.NORTH, true).with(FourWayBlock.SOUTH, true).with(FourWayBlock.EAST, true).with(FourWayBlock.WEST, true), 28, 8, 102, start);
        structure.setBlockState(world, Blocks.OAK_FENCE.getDefaultState().with(FourWayBlock.WATERLOGGED, false).with(FourWayBlock.NORTH, false).with(FourWayBlock.SOUTH, true).with(FourWayBlock.EAST, true).with(FourWayBlock.WEST, true), 28, 9, 29, start);
        structure.setBlockState(world, Blocks.OAK_FENCE.getDefaultState().with(FourWayBlock.WATERLOGGED, false).with(FourWayBlock.NORTH, true).with(FourWayBlock.SOUTH, false).with(FourWayBlock.EAST, true).with(FourWayBlock.WEST, true), 28, 9, 31, start);
        structure.setBlockState(world, Blocks.OAK_FENCE.getDefaultState().with(FourWayBlock.WATERLOGGED, false).with(FourWayBlock.NORTH, false).with(FourWayBlock.SOUTH, true).with(FourWayBlock.EAST, true).with(FourWayBlock.WEST, false), 28, 10, 29, start);
        structure.setBlockState(world, Blocks.OAK_FENCE.getDefaultState().with(FourWayBlock.WATERLOGGED, false).with(FourWayBlock.NORTH, true).with(FourWayBlock.SOUTH, false).with(FourWayBlock.EAST, true).with(FourWayBlock.WEST, false), 28, 10, 31, start);
        structure.setBlockState(world, Blocks.SPRUCE_SLAB.getDefaultState().with(SlabBlock.TYPE, SlabType.BOTTOM).with(SlabBlock.WATERLOGGED, false), 28, 10, 57, start);
        structure.setBlockState(world, Blocks.OAK_LOG.getDefaultState(), 28, 10, 76, start);
        structure.setBlockState(world, Blocks.OAK_SLAB.getDefaultState().with(SlabBlock.TYPE, SlabType.BOTTOM).with(SlabBlock.WATERLOGGED, false), 28, 11, 29, start);
        structure.setBlockState(world, Blocks.OAK_SLAB.getDefaultState().with(SlabBlock.TYPE, SlabType.DOUBLE).with(SlabBlock.WATERLOGGED, false), 28, 11, 30, start);
        structure.setBlockState(world, Blocks.OAK_SLAB.getDefaultState().with(SlabBlock.TYPE, SlabType.BOTTOM).with(SlabBlock.WATERLOGGED, false), 28, 11, 31, start);
        structure.setBlockState(world, Blocks.SPRUCE_FENCE.getDefaultState().with(FourWayBlock.WATERLOGGED, false).with(FourWayBlock.NORTH, false).with(FourWayBlock.SOUTH, false).with(FourWayBlock.EAST, false).with(FourWayBlock.WEST, false), 28, 11, 40, start);
        structure.setBlockState(world, Blocks.SPRUCE_FENCE.getDefaultState().with(FourWayBlock.WATERLOGGED, false).with(FourWayBlock.NORTH, false).with(FourWayBlock.SOUTH, false).with(FourWayBlock.EAST, false).with(FourWayBlock.WEST, false), 28, 11, 76, start);
        structure.setBlockState(world, Blocks.SPRUCE_SLAB.getDefaultState().with(SlabBlock.TYPE, SlabType.BOTTOM).with(SlabBlock.WATERLOGGED, false), 28, 11, 81, start);
        structure.setBlockState(world, Blocks.STONE.getDefaultState(), 29, 1, 107, start);
        structure.setBlockState(world, Blocks.TORCH.getDefaultState(), 29, 6, 29, start);
        structure.setBlockState(world, Blocks.TORCH.getDefaultState(), 29, 6, 31, start);
        structure.setBlockState(world, Blocks.PODZOL.getDefaultState().with(SnowyDirtBlock.SNOWY, false), 29, 6, 79, start);
        structure.setBlockState(world, Blocks.OAK_FENCE.getDefaultState().with(FourWayBlock.WATERLOGGED, false).with(FourWayBlock.NORTH, false).with(FourWayBlock.SOUTH, true).with(FourWayBlock.EAST, true).with(FourWayBlock.WEST, false), 29, 7, 88, start);
        structure.setBlockState(world, Blocks.OAK_FENCE.getDefaultState().with(FourWayBlock.WATERLOGGED, false).with(FourWayBlock.NORTH, true).with(FourWayBlock.SOUTH, false).with(FourWayBlock.EAST, false).with(FourWayBlock.WEST, true), 29, 7, 89, start);
        structure.setBlockState(world, Blocks.OAK_FENCE.getDefaultState().with(FourWayBlock.WATERLOGGED, false).with(FourWayBlock.NORTH, false).with(FourWayBlock.SOUTH, true).with(FourWayBlock.EAST, false).with(FourWayBlock.WEST, true), 29, 7, 101, start);
        structure.setBlockState(world, Blocks.OAK_FENCE.getDefaultState().with(FourWayBlock.WATERLOGGED, false).with(FourWayBlock.NORTH, true).with(FourWayBlock.SOUTH, false).with(FourWayBlock.EAST, true).with(FourWayBlock.WEST, false), 29, 7, 102, start);
        structure.setBlockState(world, Blocks.SAND.getDefaultState(), 29, 8, 60, start);
        structure.setBlockState(world, Blocks.OAK_FENCE.getDefaultState().with(FourWayBlock.WATERLOGGED, false).with(FourWayBlock.NORTH, false).with(FourWayBlock.SOUTH, true).with(FourWayBlock.EAST, true).with(FourWayBlock.WEST, false), 29, 8, 87, start);
        structure.setBlockState(world, Blocks.SPRUCE_SLAB.getDefaultState().with(SlabBlock.TYPE, SlabType.BOTTOM).with(SlabBlock.WATERLOGGED, false), 29, 9, 39, start);
        structure.setBlockState(world, Blocks.OAK_FENCE.getDefaultState().with(FourWayBlock.WATERLOGGED, false).with(FourWayBlock.NORTH, false).with(FourWayBlock.SOUTH, false).with(FourWayBlock.EAST, true).with(FourWayBlock.WEST, true), 29, 10, 29, start);
        structure.setBlockState(world, Blocks.OAK_FENCE.getDefaultState().with(FourWayBlock.WATERLOGGED, false).with(FourWayBlock.NORTH, false).with(FourWayBlock.SOUTH, false).with(FourWayBlock.EAST, true).with(FourWayBlock.WEST, true), 29, 10, 31, start);
        structure.setBlockState(world, Blocks.OAK_LOG.getDefaultState(), 29, 10, 57, start);
        structure.setBlockState(world, Blocks.SPRUCE_SLAB.getDefaultState().with(SlabBlock.TYPE, SlabType.BOTTOM).with(SlabBlock.WATERLOGGED, false), 29, 10, 75, start);
        structure.setBlockState(world, Blocks.SPRUCE_SLAB.getDefaultState().with(SlabBlock.TYPE, SlabType.BOTTOM).with(SlabBlock.WATERLOGGED, false), 29, 10, 82, start);
        structure.setBlockState(world, Blocks.OAK_FENCE.getDefaultState().with(FourWayBlock.WATERLOGGED, false).with(FourWayBlock.NORTH, false).with(FourWayBlock.SOUTH, false).with(FourWayBlock.EAST, true).with(FourWayBlock.WEST, false), 29, 11, 29, start);
        structure.setBlockState(world, Blocks.OAK_FENCE.getDefaultState().with(FourWayBlock.WATERLOGGED, false).with(FourWayBlock.NORTH, false).with(FourWayBlock.SOUTH, false).with(FourWayBlock.EAST, true).with(FourWayBlock.WEST, false), 29, 11, 31, start);
        structure.setBlockState(world, Blocks.SPRUCE_FENCE.getDefaultState().with(FourWayBlock.WATERLOGGED, false).with(FourWayBlock.NORTH, false).with(FourWayBlock.SOUTH, false).with(FourWayBlock.EAST, false).with(FourWayBlock.WEST, false), 29, 11, 57, start);
        structure.setBlockState(world, Blocks.OAK_SLAB.getDefaultState().with(SlabBlock.TYPE, SlabType.BOTTOM).with(SlabBlock.WATERLOGGED, false), 29, 12, 29, start);
        structure.setBlockState(world, Blocks.OAK_SLAB.getDefaultState().with(SlabBlock.TYPE, SlabType.DOUBLE).with(SlabBlock.WATERLOGGED, false), 29, 12, 30, start);
        structure.setBlockState(world, Blocks.OAK_SLAB.getDefaultState().with(SlabBlock.TYPE, SlabType.BOTTOM).with(SlabBlock.WATERLOGGED, false), 29, 12, 31, start);
        structure.setBlockState(world, Blocks.OAK_FENCE.getDefaultState().with(FourWayBlock.WATERLOGGED, false).with(FourWayBlock.NORTH, true).with(FourWayBlock.SOUTH, true).with(FourWayBlock.EAST, true).with(FourWayBlock.WEST, true), 30, 7, 57, start);
        structure.setBlockState(world, Index.TABLE_OAK.getDefaultState().with(Table.NE, true).with(Table.NW, true).with(Table.SE, false).with(Table.SW, false), 30, 7, 61, start);
        structure.setBlockState(world, Index.TABLE_OAK.getDefaultState().with(Table.NE, false).with(Table.NW, false).with(Table.SE, true).with(Table.SW, true), 30, 7, 62, start);
        structure.setBlockState(world, Blocks.CRAFTING_TABLE.getDefaultState(), 30, 7, 63, start);
        structure.setBlockState(world, Blocks.LODESTONE.getDefaultState(), 30, 7, 65, start);
        structure.setBlockState(world, Blocks.OAK_LOG.getDefaultState(), 30, 8, 85, start);
        structure.setBlockState(world, Blocks.OAK_FENCE.getDefaultState().with(FourWayBlock.WATERLOGGED, false).with(FourWayBlock.NORTH, false).with(FourWayBlock.SOUTH, true).with(FourWayBlock.EAST, false).with(FourWayBlock.WEST, false), 30, 10, 37, start);
        structure.setBlockState(world, Blocks.OAK_LOG.getDefaultState(), 30, 10, 38, start);
        structure.setBlockState(world, Blocks.SPRUCE_SLAB.getDefaultState().with(SlabBlock.TYPE, SlabType.BOTTOM).with(SlabBlock.WATERLOGGED, false), 30, 10, 55, start);
        structure.setBlockState(world, Blocks.SPRUCE_FENCE.getDefaultState().with(FourWayBlock.WATERLOGGED, false).with(FourWayBlock.NORTH, false).with(FourWayBlock.SOUTH, false).with(FourWayBlock.EAST, false).with(FourWayBlock.WEST, false), 30, 10, 56, start);
        structure.setBlockState(world, Blocks.OAK_FENCE.getDefaultState().with(FourWayBlock.WATERLOGGED, false).with(FourWayBlock.NORTH, false).with(FourWayBlock.SOUTH, false).with(FourWayBlock.EAST, true).with(FourWayBlock.WEST, true), 30, 11, 29, start);
        structure.setBlockState(world, Blocks.OAK_FENCE.getDefaultState().with(FourWayBlock.WATERLOGGED, false).with(FourWayBlock.NORTH, false).with(FourWayBlock.SOUTH, false).with(FourWayBlock.EAST, true).with(FourWayBlock.WEST, true), 30, 11, 31, start);
        structure.setBlockState(world, Blocks.SPRUCE_FENCE.getDefaultState().with(FourWayBlock.WATERLOGGED, false).with(FourWayBlock.NORTH, false).with(FourWayBlock.SOUTH, false).with(FourWayBlock.EAST, false).with(FourWayBlock.WEST, false), 30, 11, 38, start);
        structure.setBlockState(world, Blocks.SPRUCE_SLAB.getDefaultState().with(SlabBlock.TYPE, SlabType.BOTTOM).with(SlabBlock.WATERLOGGED, false), 30, 11, 74, start);
        structure.setBlockState(world, Blocks.OAK_FENCE.getDefaultState().with(FourWayBlock.WATERLOGGED, false).with(FourWayBlock.NORTH, false).with(FourWayBlock.SOUTH, false).with(FourWayBlock.EAST, true).with(FourWayBlock.WEST, false), 30, 12, 29, start);
        structure.setBlockState(world, Blocks.OAK_FENCE.getDefaultState().with(FourWayBlock.WATERLOGGED, false).with(FourWayBlock.NORTH, false).with(FourWayBlock.SOUTH, false).with(FourWayBlock.EAST, true).with(FourWayBlock.WEST, false), 30, 12, 31, start);
        structure.setBlockState(world, Blocks.STONE.getDefaultState(), 31, 2, 105, start);
        structure.setBlockState(world, ModBlocks.CHAIR.get().getDefaultState().with(ChairBlock.FACING, Direction.WEST), 31, 7, 62, start);
        structure.setBlockState(world, Blocks.OAK_LOG.getDefaultState(), 31, 9, 73, start);
        structure.setBlockState(world, Blocks.SPRUCE_SLAB.getDefaultState().with(SlabBlock.TYPE, SlabType.BOTTOM).with(SlabBlock.WATERLOGGED, false), 31, 10, 73, start);
        structure.setBlockState(world, Blocks.BROWN_TERRACOTTA.getDefaultState(), 31, 11, 29, start);
        structure.setBlockState(world, Blocks.AIR.getDefaultState(), 31, 11, 30, start);
        structure.setBlockState(world, Blocks.BROWN_TERRACOTTA.getDefaultState(), 31, 11, 31, start);
        structure.setBlockState(world, Blocks.SPRUCE_FENCE.getDefaultState().with(FourWayBlock.WATERLOGGED, false).with(FourWayBlock.NORTH, false).with(FourWayBlock.SOUTH, false).with(FourWayBlock.EAST, false).with(FourWayBlock.WEST, false), 31, 11, 85, start);
        structure.setBlockState(world, Blocks.OAK_FENCE_GATE.getDefaultState().with(FenceGateBlock.IN_WALL, false).with(FenceGateBlock.OPEN, false).with(FenceGateBlock.POWERED, false), 31, 12, 29, start);
        structure.setBlockState(world, Blocks.OAK_FENCE_GATE.getDefaultState().with(FenceGateBlock.IN_WALL, false).with(FenceGateBlock.OPEN, false).with(FenceGateBlock.POWERED, false), 31, 12, 31, start);
        structure.setBlockState(world, Blocks.SPRUCE_FENCE.getDefaultState().with(FourWayBlock.WATERLOGGED, false).with(FourWayBlock.NORTH, false).with(FourWayBlock.SOUTH, false).with(FourWayBlock.EAST, false).with(FourWayBlock.WEST, false), 31, 12, 54, start);
        structure.setBlockState(world, Blocks.OAK_TRAPDOOR.getDefaultState().with(HorizontalBlock.HORIZONTAL_FACING, Direction.WEST).with(TrapDoorBlock.HALF, Half.TOP).with(TrapDoorBlock.WATERLOGGED, false).with(TrapDoorBlock.POWERED, false).with(TrapDoorBlock.OPEN, true), 31, 12, 66, start);
        structure.setBlockState(world, Blocks.PODZOL.getDefaultState().with(SnowyDirtBlock.SNOWY, false), 32, 6, 76, start);
        structure.setBlockState(world, Blocks.PODZOL.getDefaultState().with(SnowyDirtBlock.SNOWY, false), 32, 6, 82, start);
        structure.setBlockState(world, Blocks.AIR.getDefaultState(), 32, 7, 63, start);
        structure.setBlockState(world, Blocks.LECTERN.getDefaultState().with(LecternBlock.FACING, Direction.NORTH).with(LecternBlock.HAS_BOOK, false).with(LecternBlock.POWERED, false), 32, 7, 65, start);
        structure.setBlockState(world, Blocks.OAK_FENCE.getDefaultState().with(FourWayBlock.WATERLOGGED, false).with(FourWayBlock.NORTH, false).with(FourWayBlock.SOUTH, true).with(FourWayBlock.EAST, true).with(FourWayBlock.WEST, false), 32, 7, 87, start);
        structure.setBlockState(world, Blocks.OAK_FENCE.getDefaultState().with(FourWayBlock.WATERLOGGED, false).with(FourWayBlock.NORTH, true).with(FourWayBlock.SOUTH, false).with(FourWayBlock.EAST, false).with(FourWayBlock.WEST, true), 32, 7, 88, start);
        structure.setBlockState(world, Blocks.OAK_FENCE.getDefaultState().with(FourWayBlock.WATERLOGGED, false).with(FourWayBlock.NORTH, true).with(FourWayBlock.SOUTH, true).with(FourWayBlock.EAST, true).with(FourWayBlock.WEST, false), 32, 8, 86, start);
        structure.setBlockState(world, Blocks.OAK_FENCE.getDefaultState().with(FourWayBlock.WATERLOGGED, false).with(FourWayBlock.NORTH, false).with(FourWayBlock.SOUTH, false).with(FourWayBlock.EAST, true).with(FourWayBlock.WEST, false), 32, 9, 22, start);
        structure.setBlockState(world, Blocks.OAK_FENCE.getDefaultState().with(FourWayBlock.WATERLOGGED, false).with(FourWayBlock.NORTH, false).with(FourWayBlock.SOUTH, false).with(FourWayBlock.EAST, true).with(FourWayBlock.WEST, false), 32, 9, 24, start);
        structure.setBlockState(world, Blocks.SPRUCE_FENCE.getDefaultState().with(FourWayBlock.WATERLOGGED, false).with(FourWayBlock.NORTH, true).with(FourWayBlock.SOUTH, false).with(FourWayBlock.EAST, false).with(FourWayBlock.WEST, true), 32, 9, 73, start);
        structure.setBlockState(world, Blocks.OAK_TRAPDOOR.getDefaultState().with(HorizontalBlock.HORIZONTAL_FACING, Direction.WEST).with(TrapDoorBlock.HALF, Half.BOTTOM).with(TrapDoorBlock.WATERLOGGED, false).with(TrapDoorBlock.POWERED, false).with(TrapDoorBlock.OPEN, false), 32, 10, 22, start);
        structure.setBlockState(world, Blocks.OAK_TRAPDOOR.getDefaultState().with(HorizontalBlock.HORIZONTAL_FACING, Direction.NORTH).with(TrapDoorBlock.HALF, Half.BOTTOM).with(TrapDoorBlock.WATERLOGGED, false).with(TrapDoorBlock.POWERED, false).with(TrapDoorBlock.OPEN, false), 32, 10, 24, start);
        structure.setBlockState(world, Blocks.OAK_LOG.getDefaultState(), 32, 10, 51, start);
        structure.setBlockState(world, Blocks.SPRUCE_SLAB.getDefaultState().with(SlabBlock.TYPE, SlabType.BOTTOM).with(SlabBlock.WATERLOGGED, false), 32, 10, 52, start);
        structure.setBlockState(world, Blocks.SPRUCE_FENCE.getDefaultState().with(FourWayBlock.WATERLOGGED, false).with(FourWayBlock.NORTH, false).with(FourWayBlock.SOUTH, false).with(FourWayBlock.EAST, false).with(FourWayBlock.WEST, false), 32, 10, 53, start);
        structure.setBlockState(world, Blocks.LANTERN.getDefaultState().with(LanternBlock.WATERLOGGED, false).with(LanternBlock.HANGING, true), 32, 10, 63, start);
        structure.setBlockState(world, Blocks.OAK_FENCE.getDefaultState().with(FourWayBlock.WATERLOGGED, false).with(FourWayBlock.NORTH, false).with(FourWayBlock.SOUTH, false).with(FourWayBlock.EAST, true).with(FourWayBlock.WEST, true), 32, 11, 29, start);
        structure.setBlockState(world, Blocks.OAK_FENCE.getDefaultState().with(FourWayBlock.WATERLOGGED, false).with(FourWayBlock.NORTH, false).with(FourWayBlock.SOUTH, false).with(FourWayBlock.EAST, true).with(FourWayBlock.WEST, true), 32, 11, 31, start);
        structure.setBlockState(world, Blocks.OAK_TRAPDOOR.getDefaultState().with(HorizontalBlock.HORIZONTAL_FACING, Direction.EAST).with(TrapDoorBlock.HALF, Half.BOTTOM).with(TrapDoorBlock.WATERLOGGED, false).with(TrapDoorBlock.POWERED, false).with(TrapDoorBlock.OPEN, false), 32, 11, 36, start);
        structure.setBlockState(world, Blocks.SPRUCE_FENCE.getDefaultState().with(FourWayBlock.WATERLOGGED, false).with(FourWayBlock.NORTH, false).with(FourWayBlock.SOUTH, false).with(FourWayBlock.EAST, false).with(FourWayBlock.WEST, false), 32, 11, 51, start);
        structure.setBlockState(world, Blocks.OAK_FENCE.getDefaultState().with(FourWayBlock.WATERLOGGED, false).with(FourWayBlock.NORTH, false).with(FourWayBlock.SOUTH, false).with(FourWayBlock.EAST, false).with(FourWayBlock.WEST, true), 32, 12, 29, start);
        structure.setBlockState(world, Blocks.OAK_FENCE.getDefaultState().with(FourWayBlock.WATERLOGGED, false).with(FourWayBlock.NORTH, false).with(FourWayBlock.SOUTH, false).with(FourWayBlock.EAST, false).with(FourWayBlock.WEST, true), 32, 12, 31, start);
        structure.setBlockState(world, Blocks.LANTERN.getDefaultState().with(LanternBlock.WATERLOGGED, false).with(LanternBlock.HANGING, false), 33, 7, 24, start);
        structure.setBlockState(world, Blocks.OAK_FENCE.getDefaultState().with(FourWayBlock.WATERLOGGED, false).with(FourWayBlock.NORTH, true).with(FourWayBlock.SOUTH, false).with(FourWayBlock.EAST, true).with(FourWayBlock.WEST, false), 33, 7, 26, start);
        structure.setBlockState(world, Blocks.AIR.getDefaultState(), 33, 7, 79, start);
        structure.setBlockState(world, Blocks.DEAD_BUSH.getDefaultState(), 33, 7, 108, start);
        structure.setBlockState(world, Blocks.OAK_FENCE.getDefaultState().with(FourWayBlock.WATERLOGGED, false).with(FourWayBlock.NORTH, true).with(FourWayBlock.SOUTH, false).with(FourWayBlock.EAST, false).with(FourWayBlock.WEST, false), 33, 8, 26, start);
        structure.setBlockState(world, Blocks.OAK_TRAPDOOR.getDefaultState().with(HorizontalBlock.HORIZONTAL_FACING, Direction.SOUTH).with(TrapDoorBlock.HALF, Half.BOTTOM).with(TrapDoorBlock.WATERLOGGED, false).with(TrapDoorBlock.POWERED, false).with(TrapDoorBlock.OPEN, true), 33, 8, 32, start);
        structure.setBlockState(world, Blocks.OAK_TRAPDOOR.getDefaultState().with(HorizontalBlock.HORIZONTAL_FACING, Direction.SOUTH).with(TrapDoorBlock.HALF, Half.TOP).with(TrapDoorBlock.WATERLOGGED, false).with(TrapDoorBlock.POWERED, false).with(TrapDoorBlock.OPEN, true), 33, 9, 32, start);
        structure.setBlockState(world, Blocks.SPRUCE_FENCE.getDefaultState().with(FourWayBlock.WATERLOGGED, false).with(FourWayBlock.NORTH, false).with(FourWayBlock.SOUTH, false).with(FourWayBlock.EAST, false).with(FourWayBlock.WEST, false), 33, 9, 50, start);
        structure.setBlockState(world, Blocks.OAK_LOG.getDefaultState(), 33, 9, 74, start);
        structure.setBlockState(world, Blocks.OAK_FENCE.getDefaultState().with(FourWayBlock.WATERLOGGED, false).with(FourWayBlock.NORTH, false).with(FourWayBlock.SOUTH, false).with(FourWayBlock.EAST, true).with(FourWayBlock.WEST, true), 33, 10, 29, start);
        structure.setBlockState(world, Blocks.OAK_TRAPDOOR.getDefaultState().with(HorizontalBlock.HORIZONTAL_FACING, Direction.EAST).with(TrapDoorBlock.HALF, Half.BOTTOM).with(TrapDoorBlock.WATERLOGGED, false).with(TrapDoorBlock.POWERED, false).with(TrapDoorBlock.OPEN, true), 33, 10, 30, start);
        structure.setBlockState(world, Blocks.OAK_FENCE.getDefaultState().with(FourWayBlock.WATERLOGGED, false).with(FourWayBlock.NORTH, false).with(FourWayBlock.SOUTH, false).with(FourWayBlock.EAST, true).with(FourWayBlock.WEST, true), 33, 10, 31, start);
        structure.setBlockState(world, Blocks.OAK_LOG.getDefaultState(), 33, 10, 38, start);
        structure.setBlockState(world, Blocks.SPRUCE_FENCE.getDefaultState().with(FourWayBlock.WATERLOGGED, false).with(FourWayBlock.NORTH, false).with(FourWayBlock.SOUTH, false).with(FourWayBlock.EAST, false).with(FourWayBlock.WEST, false), 33, 10, 74, start);
        structure.setBlockState(world, Blocks.OAK_FENCE.getDefaultState().with(FourWayBlock.WATERLOGGED, false).with(FourWayBlock.NORTH, false).with(FourWayBlock.SOUTH, false).with(FourWayBlock.EAST, false).with(FourWayBlock.WEST, true), 33, 11, 29, start);
        structure.setBlockState(world, Blocks.OAK_FENCE.getDefaultState().with(FourWayBlock.WATERLOGGED, false).with(FourWayBlock.NORTH, false).with(FourWayBlock.SOUTH, false).with(FourWayBlock.EAST, false).with(FourWayBlock.WEST, true), 33, 11, 31, start);
        structure.setBlockState(world, Blocks.OAK_TRAPDOOR.getDefaultState().with(HorizontalBlock.HORIZONTAL_FACING, Direction.NORTH).with(TrapDoorBlock.HALF, Half.TOP).with(TrapDoorBlock.WATERLOGGED, false).with(TrapDoorBlock.POWERED, false).with(TrapDoorBlock.OPEN, true), 33, 12, 61, start);
        structure.setBlockState(world, Blocks.SPRUCE_SLAB.getDefaultState().with(SlabBlock.TYPE, SlabType.TOP).with(SlabBlock.WATERLOGGED, false), 33, 14, 65, start);
        structure.setBlockState(world, Blocks.SPRUCE_SLAB.getDefaultState().with(SlabBlock.TYPE, SlabType.BOTTOM).with(SlabBlock.WATERLOGGED, false), 33, 15, 66, start);
        structure.setBlockState(world, Blocks.STONE.getDefaultState(), 34, 1, 50, start);
        structure.setBlockState(world, Blocks.AIR.getDefaultState(), 34, 7, 23, start);
        structure.setBlockState(world, Blocks.OAK_FENCE_GATE.getDefaultState().with(FenceGateBlock.IN_WALL, false).with(FenceGateBlock.OPEN, false).with(FenceGateBlock.POWERED, false), 34, 7, 26, start);
        structure.setBlockState(world, Blocks.AIR.getDefaultState(), 34, 7, 42, start);
        structure.setBlockState(world, Blocks.SAND.getDefaultState(), 34, 9, 60, start);
        structure.setBlockState(world, Blocks.SANDSTONE.getDefaultState(), 34, 9, 68, start);
        structure.setBlockState(world, Blocks.TORCH.getDefaultState(), 34, 9, 72, start);
        structure.setBlockState(world, Blocks.SPRUCE_SLAB.getDefaultState().with(SlabBlock.TYPE, SlabType.BOTTOM).with(SlabBlock.WATERLOGGED, false), 34, 9, 74, start);
        structure.setBlockState(world, Blocks.BROWN_TERRACOTTA.getDefaultState(), 34, 10, 23, start);
        structure.setBlockState(world, Blocks.SPRUCE_FENCE.getDefaultState().with(FourWayBlock.WATERLOGGED, false).with(FourWayBlock.NORTH, false).with(FourWayBlock.SOUTH, false).with(FourWayBlock.EAST, false).with(FourWayBlock.WEST, false), 34, 10, 49, start);
        structure.setBlockState(world, Blocks.OAK_LOG.getDefaultState(), 34, 10, 85, start);
        structure.setBlockState(world, Blocks.OAK_TRAPDOOR.getDefaultState().with(HorizontalBlock.HORIZONTAL_FACING, Direction.NORTH).with(TrapDoorBlock.HALF, Half.BOTTOM).with(TrapDoorBlock.WATERLOGGED, false).with(TrapDoorBlock.POWERED, false).with(TrapDoorBlock.OPEN, false), 34, 11, 34, start);
        structure.setBlockState(world, Blocks.SPRUCE_FENCE.getDefaultState().with(FourWayBlock.WATERLOGGED, false).with(FourWayBlock.NORTH, false).with(FourWayBlock.SOUTH, false).with(FourWayBlock.EAST, false).with(FourWayBlock.WEST, false), 34, 11, 85, start);
        structure.setBlockState(world, Blocks.OAK_TRAPDOOR.getDefaultState().with(HorizontalBlock.HORIZONTAL_FACING, Direction.EAST).with(TrapDoorBlock.HALF, Half.BOTTOM).with(TrapDoorBlock.WATERLOGGED, false).with(TrapDoorBlock.POWERED, false).with(TrapDoorBlock.OPEN, false), 34, 12, 23, start);
        structure.setBlockState(world, Blocks.OAK_TRAPDOOR.getDefaultState().with(HorizontalBlock.HORIZONTAL_FACING, Direction.EAST).with(TrapDoorBlock.HALF, Half.BOTTOM).with(TrapDoorBlock.WATERLOGGED, false).with(TrapDoorBlock.POWERED, false).with(TrapDoorBlock.OPEN, true), 34, 12, 66, start);
        structure.setBlockState(world, Blocks.PODZOL.getDefaultState().with(SnowyDirtBlock.SNOWY, false), 35, 6, 83, start);
        structure.setBlockState(world, Blocks.OAK_FENCE.getDefaultState().with(FourWayBlock.WATERLOGGED, false).with(FourWayBlock.NORTH, true).with(FourWayBlock.SOUTH, false).with(FourWayBlock.EAST, false).with(FourWayBlock.WEST, true), 35, 7, 26, start);
        structure.setBlockState(world, Blocks.AIR.getDefaultState(), 35, 7, 92, start);
        structure.setBlockState(world, Blocks.AIR.getDefaultState(), 35, 7, 97, start);
        structure.setBlockState(world, Blocks.OAK_FENCE.getDefaultState().with(FourWayBlock.WATERLOGGED, false).with(FourWayBlock.NORTH, true).with(FourWayBlock.SOUTH, false).with(FourWayBlock.EAST, false).with(FourWayBlock.WEST, false), 35, 8, 26, start);
        structure.setBlockState(world, Blocks.TORCH.getDefaultState(), 35, 9, 70, start);
        structure.setBlockState(world, Blocks.SPRUCE_FENCE.getDefaultState().with(FourWayBlock.WATERLOGGED, false).with(FourWayBlock.NORTH, true).with(FourWayBlock.SOUTH, false).with(FourWayBlock.EAST, false).with(FourWayBlock.WEST, false), 35, 9, 74, start);
        structure.setBlockState(world, Blocks.OAK_LOG.getDefaultState(), 35, 9, 84, start);
        structure.setBlockState(world, Blocks.SPRUCE_SLAB.getDefaultState().with(SlabBlock.TYPE, SlabType.BOTTOM).with(SlabBlock.WATERLOGGED, false), 35, 10, 49, start);
        structure.setBlockState(world, Blocks.SPRUCE_FENCE.getDefaultState().with(FourWayBlock.WATERLOGGED, false).with(FourWayBlock.NORTH, false).with(FourWayBlock.SOUTH, false).with(FourWayBlock.EAST, false).with(FourWayBlock.WEST, false), 35, 10, 73, start);
        structure.setBlockState(world, Blocks.SPRUCE_SLAB.getDefaultState().with(SlabBlock.TYPE, SlabType.BOTTOM).with(SlabBlock.WATERLOGGED, false), 35, 10, 84, start);
        structure.setBlockState(world, Blocks.PODZOL.getDefaultState().with(SnowyDirtBlock.SNOWY, false), 36, 6, 79, start);
        structure.setBlockState(world, Blocks.OAK_FENCE.getDefaultState().with(FourWayBlock.WATERLOGGED, false).with(FourWayBlock.NORTH, false).with(FourWayBlock.SOUTH, true).with(FourWayBlock.EAST, false).with(FourWayBlock.WEST, true), 36, 7, 65, start);
        structure.setBlockState(world, Blocks.OAK_FENCE.getDefaultState().with(FourWayBlock.WATERLOGGED, false).with(FourWayBlock.NORTH, true).with(FourWayBlock.SOUTH, true).with(FourWayBlock.EAST, true).with(FourWayBlock.WEST, false), 36, 7, 85, start);
        structure.setBlockState(world, Blocks.OAK_FENCE.getDefaultState().with(FourWayBlock.WATERLOGGED, false).with(FourWayBlock.NORTH, true).with(FourWayBlock.SOUTH, true).with(FourWayBlock.EAST, false).with(FourWayBlock.WEST, false), 36, 7, 86, start);
        structure.setBlockState(world, Blocks.OAK_FENCE.getDefaultState().with(FourWayBlock.WATERLOGGED, false).with(FourWayBlock.NORTH, true).with(FourWayBlock.SOUTH, false).with(FourWayBlock.EAST, false).with(FourWayBlock.WEST, true), 36, 7, 87, start);
        structure.setBlockState(world, Blocks.OAK_FENCE.getDefaultState().with(FourWayBlock.WATERLOGGED, false).with(FourWayBlock.NORTH, false).with(FourWayBlock.SOUTH, false).with(FourWayBlock.EAST, false).with(FourWayBlock.WEST, true), 36, 8, 65, start);
        structure.setBlockState(world, Blocks.OAK_FENCE.getDefaultState().with(FourWayBlock.WATERLOGGED, false).with(FourWayBlock.NORTH, false).with(FourWayBlock.SOUTH, false).with(FourWayBlock.EAST, false).with(FourWayBlock.WEST, true), 36, 9, 22, start);
        structure.setBlockState(world, Blocks.OAK_FENCE.getDefaultState().with(FourWayBlock.WATERLOGGED, false).with(FourWayBlock.NORTH, false).with(FourWayBlock.SOUTH, false).with(FourWayBlock.EAST, false).with(FourWayBlock.WEST, true), 36, 9, 24, start);
        structure.setBlockState(world, Blocks.TORCH.getDefaultState(), 36, 9, 69, start);
        structure.setBlockState(world, Blocks.OAK_FENCE_GATE.getDefaultState().with(FenceGateBlock.IN_WALL, false).with(FenceGateBlock.OPEN, false).with(FenceGateBlock.POWERED, false), 36, 9, 73, start);
        structure.setBlockState(world, Blocks.OAK_TRAPDOOR.getDefaultState().with(HorizontalBlock.HORIZONTAL_FACING, Direction.SOUTH).with(TrapDoorBlock.HALF, Half.BOTTOM).with(TrapDoorBlock.WATERLOGGED, false).with(TrapDoorBlock.POWERED, false).with(TrapDoorBlock.OPEN, false), 36, 10, 22, start);
        structure.setBlockState(world, Blocks.OAK_TRAPDOOR.getDefaultState().with(HorizontalBlock.HORIZONTAL_FACING, Direction.SOUTH).with(TrapDoorBlock.HALF, Half.BOTTOM).with(TrapDoorBlock.WATERLOGGED, false).with(TrapDoorBlock.POWERED, false).with(TrapDoorBlock.OPEN, false), 36, 10, 24, start);
        structure.setBlockState(world, Blocks.SPRUCE_FENCE.getDefaultState().with(FourWayBlock.WATERLOGGED, false).with(FourWayBlock.NORTH, false).with(FourWayBlock.SOUTH, false).with(FourWayBlock.EAST, false).with(FourWayBlock.WEST, false), 36, 12, 49, start);
        structure.setBlockState(world, Blocks.STONE.getDefaultState(), 37, 1, 48, start);
        structure.setBlockState(world, Blocks.SAND.getDefaultState(), 37, 5, 132, start);
        structure.setBlockState(world, Blocks.PODZOL.getDefaultState().with(SnowyDirtBlock.SNOWY, false), 37, 6, 75, start);
        structure.setBlockState(world, Blocks.AIR.getDefaultState(), 37, 7, 30, start);
        structure.setBlockState(world, Blocks.OAK_FENCE_GATE.getDefaultState().with(FenceGateBlock.IN_WALL, false).with(FenceGateBlock.OPEN, false).with(FenceGateBlock.POWERED, false), 37, 9, 73, start);
        structure.setBlockState(world, Blocks.SPRUCE_SLAB.getDefaultState().with(SlabBlock.TYPE, SlabType.BOTTOM).with(SlabBlock.WATERLOGGED, false), 37, 9, 85, start);
        structure.setBlockState(world, Blocks.SPRUCE_SLAB.getDefaultState().with(SlabBlock.TYPE, SlabType.BOTTOM).with(SlabBlock.WATERLOGGED, false), 37, 10, 48, start);
        structure.setBlockState(world, Blocks.PODZOL.getDefaultState().with(SnowyDirtBlock.SNOWY, false), 38, 6, 82, start);
        structure.setBlockState(world, Blocks.CAULDRON.getDefaultState().with(CauldronBlock.LEVEL, 0), 38, 7, 60, start);
        structure.setBlockState(world, Blocks.OAK_FENCE_GATE.getDefaultState().with(FenceGateBlock.IN_WALL, false).with(FenceGateBlock.OPEN, true).with(FenceGateBlock.POWERED, false), 38, 7, 61, start);
        structure.setBlockState(world, Blocks.OAK_FENCE.getDefaultState().with(FourWayBlock.WATERLOGGED, false).with(FourWayBlock.NORTH, false).with(FourWayBlock.SOUTH, false).with(FourWayBlock.EAST, true).with(FourWayBlock.WEST, false), 38, 9, 21, start);
        structure.setBlockState(world, Blocks.OAK_FENCE.getDefaultState().with(FourWayBlock.WATERLOGGED, false).with(FourWayBlock.NORTH, false).with(FourWayBlock.SOUTH, false).with(FourWayBlock.EAST, true).with(FourWayBlock.WEST, false), 38, 9, 24, start);
        structure.setBlockState(world, Blocks.OAK_FENCE_GATE.getDefaultState().with(FenceGateBlock.IN_WALL, false).with(FenceGateBlock.OPEN, false).with(FenceGateBlock.POWERED, false), 38, 9, 73, start);
        structure.setBlockState(world, Blocks.OAK_SLAB.getDefaultState().with(SlabBlock.TYPE, SlabType.BOTTOM).with(SlabBlock.WATERLOGGED, false), 38, 9, 106, start);
        structure.setBlockState(world, Blocks.OAK_SLAB.getDefaultState().with(SlabBlock.TYPE, SlabType.TOP).with(SlabBlock.WATERLOGGED, false), 38, 9, 107, start);
        structure.setBlockState(world, Blocks.OAK_SLAB.getDefaultState().with(SlabBlock.TYPE, SlabType.DOUBLE).with(SlabBlock.WATERLOGGED, false), 38, 9, 109, start);
        structure.setBlockState(world, Blocks.OAK_SLAB.getDefaultState().with(SlabBlock.TYPE, SlabType.DOUBLE).with(SlabBlock.WATERLOGGED, false), 38, 9, 115, start);
        structure.setBlockState(world, Blocks.OAK_SLAB.getDefaultState().with(SlabBlock.TYPE, SlabType.TOP).with(SlabBlock.WATERLOGGED, false), 38, 9, 121, start);
        structure.setBlockState(world, Blocks.SPRUCE_SLAB.getDefaultState().with(SlabBlock.TYPE, SlabType.DOUBLE).with(SlabBlock.WATERLOGGED, false), 38, 10, 39, start);
        structure.setBlockState(world, Blocks.SPRUCE_SLAB.getDefaultState().with(SlabBlock.TYPE, SlabType.BOTTOM).with(SlabBlock.WATERLOGGED, false), 38, 10, 47, start);
        structure.setBlockState(world, Blocks.OAK_LOG.getDefaultState(), 38, 10, 48, start);
        structure.setBlockState(world, Blocks.OAK_LOG.getDefaultState(), 38, 10, 85, start);
        structure.setBlockState(world, Blocks.SPRUCE_SLAB.getDefaultState().with(SlabBlock.TYPE, SlabType.BOTTOM).with(SlabBlock.WATERLOGGED, false), 38, 11, 48, start);
        structure.setBlockState(world, Blocks.OAK_FENCE_GATE.getDefaultState().with(FenceGateBlock.IN_WALL, false).with(FenceGateBlock.OPEN, false).with(FenceGateBlock.POWERED, false), 38, 11, 57, start);
        structure.setBlockState(world, Blocks.SPRUCE_FENCE.getDefaultState().with(FourWayBlock.WATERLOGGED, false).with(FourWayBlock.NORTH, false).with(FourWayBlock.SOUTH, false).with(FourWayBlock.EAST, false).with(FourWayBlock.WEST, false), 38, 11, 80, start);
        structure.setBlockState(world, Blocks.SPRUCE_FENCE.getDefaultState().with(FourWayBlock.WATERLOGGED, false).with(FourWayBlock.NORTH, false).with(FourWayBlock.SOUTH, false).with(FourWayBlock.EAST, false).with(FourWayBlock.WEST, false), 38, 11, 85, start);
        structure.setBlockState(world, Blocks.OAK_SLAB.getDefaultState().with(SlabBlock.TYPE, SlabType.BOTTOM).with(SlabBlock.WATERLOGGED, false), 39, 7, 56, start);
        structure.setBlockState(world, Blocks.OAK_PLANKS.getDefaultState(), 39, 7, 57, start);
        structure.setBlockState(world, Blocks.OAK_SLAB.getDefaultState().with(SlabBlock.TYPE, SlabType.BOTTOM).with(SlabBlock.WATERLOGGED, false), 39, 7, 58, start);
        structure.setBlockState(world, Blocks.OAK_FENCE.getDefaultState().with(FourWayBlock.WATERLOGGED, false).with(FourWayBlock.NORTH, true).with(FourWayBlock.SOUTH, true).with(FourWayBlock.EAST, true).with(FourWayBlock.WEST, true), 39, 8, 57, start);
        structure.setBlockState(world, Blocks.OAK_SLAB.getDefaultState().with(SlabBlock.TYPE, SlabType.DOUBLE).with(SlabBlock.WATERLOGGED, false), 39, 8, 105, start);
        structure.setBlockState(world, Blocks.OAK_FENCE.getDefaultState().with(FourWayBlock.WATERLOGGED, false).with(FourWayBlock.NORTH, true).with(FourWayBlock.SOUTH, true).with(FourWayBlock.EAST, true).with(FourWayBlock.WEST, false), 39, 8, 106, start);
        structure.setBlockState(world, Blocks.OAK_FENCE.getDefaultState().with(FourWayBlock.WATERLOGGED, false).with(FourWayBlock.NORTH, false).with(FourWayBlock.SOUTH, true).with(FourWayBlock.EAST, true).with(FourWayBlock.WEST, true), 39, 9, 21, start);
        structure.setBlockState(world, Blocks.OAK_FENCE.getDefaultState().with(FourWayBlock.WATERLOGGED, false).with(FourWayBlock.NORTH, true).with(FourWayBlock.SOUTH, false).with(FourWayBlock.EAST, true).with(FourWayBlock.WEST, true), 39, 9, 24, start);
        structure.setBlockState(world, Blocks.OAK_TRAPDOOR.getDefaultState().with(HorizontalBlock.HORIZONTAL_FACING, Direction.WEST).with(TrapDoorBlock.HALF, Half.TOP).with(TrapDoorBlock.WATERLOGGED, false).with(TrapDoorBlock.POWERED, false).with(TrapDoorBlock.OPEN, true), 39, 9, 35, start);
        structure.setBlockState(world, Blocks.OAK_TRAPDOOR.getDefaultState().with(HorizontalBlock.HORIZONTAL_FACING, Direction.WEST).with(TrapDoorBlock.HALF, Half.TOP).with(TrapDoorBlock.WATERLOGGED, false).with(TrapDoorBlock.POWERED, false).with(TrapDoorBlock.OPEN, true), 39, 9, 37, start);
        structure.setBlockState(world, Blocks.SPRUCE_SLAB.getDefaultState().with(SlabBlock.TYPE, SlabType.BOTTOM).with(SlabBlock.WATERLOGGED, false), 39, 9, 78, start);
        structure.setBlockState(world, Blocks.OAK_LOG.getDefaultState(), 39, 9, 107, start);
        structure.setBlockState(world, Blocks.OAK_FENCE.getDefaultState().with(FourWayBlock.WATERLOGGED, false).with(FourWayBlock.NORTH, true).with(FourWayBlock.SOUTH, true).with(FourWayBlock.EAST, false).with(FourWayBlock.WEST, false), 39, 9, 108, start);
        structure.setBlockState(world, Blocks.OAK_FENCE.getDefaultState().with(FourWayBlock.WATERLOGGED, false).with(FourWayBlock.NORTH, true).with(FourWayBlock.SOUTH, true).with(FourWayBlock.EAST, false).with(FourWayBlock.WEST, true), 39, 9, 109, start);
        structure.setBlockState(world, Blocks.OAK_FENCE.getDefaultState().with(FourWayBlock.WATERLOGGED, false).with(FourWayBlock.NORTH, true).with(FourWayBlock.SOUTH, true).with(FourWayBlock.EAST, false).with(FourWayBlock.WEST, true), 39, 9, 115, start);
        structure.setBlockState(world, Blocks.OAK_FENCE.getDefaultState().with(FourWayBlock.WATERLOGGED, false).with(FourWayBlock.NORTH, true).with(FourWayBlock.SOUTH, true).with(FourWayBlock.EAST, true).with(FourWayBlock.WEST, false), 39, 9, 119, start);
        structure.setBlockState(world, Blocks.SPRUCE_SLAB.getDefaultState().with(SlabBlock.TYPE, SlabType.BOTTOM).with(SlabBlock.WATERLOGGED, false), 39, 10, 40, start);
        structure.setBlockState(world, Blocks.SPRUCE_SLAB.getDefaultState().with(SlabBlock.TYPE, SlabType.BOTTOM).with(SlabBlock.WATERLOGGED, false), 39, 10, 45, start);
        structure.setBlockState(world, Blocks.OAK_LOG.getDefaultState(), 39, 10, 76, start);
        structure.setBlockState(world, Blocks.SPRUCE_FENCE.getDefaultState().with(FourWayBlock.WATERLOGGED, false).with(FourWayBlock.NORTH, false).with(FourWayBlock.SOUTH, false).with(FourWayBlock.EAST, false).with(FourWayBlock.WEST, false), 39, 10, 79, start);
        structure.setBlockState(world, Blocks.SPRUCE_SLAB.getDefaultState().with(SlabBlock.TYPE, SlabType.BOTTOM).with(SlabBlock.WATERLOGGED, false), 39, 10, 85, start);
        structure.setBlockState(world, Blocks.OAK_FENCE_GATE.getDefaultState().with(FenceGateBlock.IN_WALL, false).with(FenceGateBlock.OPEN, false).with(FenceGateBlock.POWERED, false), 39, 11, 56, start);
        structure.setBlockState(world, Blocks.OAK_FENCE_GATE.getDefaultState().with(FenceGateBlock.IN_WALL, false).with(FenceGateBlock.OPEN, false).with(FenceGateBlock.POWERED, false), 39, 11, 58, start);
        structure.setBlockState(world, Blocks.SPRUCE_FENCE.getDefaultState().with(FourWayBlock.WATERLOGGED, false).with(FourWayBlock.NORTH, false).with(FourWayBlock.SOUTH, false).with(FourWayBlock.EAST, false).with(FourWayBlock.WEST, false), 39, 11, 76, start);
        structure.setBlockState(world, Blocks.OAK_FENCE_GATE.getDefaultState().with(FenceGateBlock.IN_WALL, false).with(FenceGateBlock.OPEN, false).with(FenceGateBlock.POWERED, false), 39, 11, 123, start);
        structure.setBlockState(world, Blocks.SPRUCE_FENCE.getDefaultState().with(FourWayBlock.WATERLOGGED, false).with(FourWayBlock.NORTH, false).with(FourWayBlock.SOUTH, false).with(FourWayBlock.EAST, false).with(FourWayBlock.WEST, false), 39, 12, 46, start);
        structure.setBlockState(world, Blocks.PODZOL.getDefaultState().with(SnowyDirtBlock.SNOWY, false), 40, 6, 82, start);
        structure.setBlockState(world, Blocks.AIR.getDefaultState(), 40, 7, 62, start);
        structure.setBlockState(world, Blocks.OAK_FENCE.getDefaultState().with(FourWayBlock.WATERLOGGED, false).with(FourWayBlock.NORTH, false).with(FourWayBlock.SOUTH, true).with(FourWayBlock.EAST, true).with(FourWayBlock.WEST, true), 40, 7, 74, start);
        structure.setBlockState(world, Blocks.OAK_FENCE.getDefaultState().with(FourWayBlock.WATERLOGGED, false).with(FourWayBlock.NORTH, false).with(FourWayBlock.SOUTH, false).with(FourWayBlock.EAST, true).with(FourWayBlock.WEST, true), 40, 8, 74, start);
        structure.setBlockState(world, Blocks.OAK_FENCE.getDefaultState().with(FourWayBlock.WATERLOGGED, false).with(FourWayBlock.NORTH, false).with(FourWayBlock.SOUTH, false).with(FourWayBlock.EAST, true).with(FourWayBlock.WEST, true), 40, 8, 106, start);
        structure.setBlockState(world, Blocks.OAK_FENCE.getDefaultState().with(FourWayBlock.WATERLOGGED, false).with(FourWayBlock.NORTH, false).with(FourWayBlock.SOUTH, true).with(FourWayBlock.EAST, false).with(FourWayBlock.WEST, false), 40, 9, 19, start);
        structure.setBlockState(world, Blocks.OAK_FENCE.getDefaultState().with(FourWayBlock.WATERLOGGED, false).with(FourWayBlock.NORTH, true).with(FourWayBlock.SOUTH, true).with(FourWayBlock.EAST, true).with(FourWayBlock.WEST, false), 40, 9, 20, start);
        structure.setBlockState(world, Blocks.OAK_TRAPDOOR.getDefaultState().with(HorizontalBlock.HORIZONTAL_FACING, Direction.NORTH).with(TrapDoorBlock.HALF, Half.TOP).with(TrapDoorBlock.WATERLOGGED, false).with(TrapDoorBlock.POWERED, false).with(TrapDoorBlock.OPEN, true), 40, 9, 34, start);
        structure.setBlockState(world, Blocks.SPRUCE_SLAB.getDefaultState().with(SlabBlock.TYPE, SlabType.DOUBLE).with(SlabBlock.WATERLOGGED, false), 40, 9, 35, start);
        structure.setBlockState(world, Blocks.SPRUCE_SLAB.getDefaultState().with(SlabBlock.TYPE, SlabType.DOUBLE).with(SlabBlock.WATERLOGGED, false), 40, 9, 37, start);
        structure.setBlockState(world, Blocks.OAK_TRAPDOOR.getDefaultState().with(HorizontalBlock.HORIZONTAL_FACING, Direction.SOUTH).with(TrapDoorBlock.HALF, Half.TOP).with(TrapDoorBlock.WATERLOGGED, false).with(TrapDoorBlock.POWERED, false).with(TrapDoorBlock.OPEN, true), 40, 9, 38, start);
        structure.setBlockState(world, Blocks.OAK_LOG.getDefaultState(), 40, 9, 43, start);
        structure.setBlockState(world, Blocks.TORCH.getDefaultState(), 40, 9, 59, start);
        structure.setBlockState(world, Blocks.TORCH.getDefaultState(), 40, 9, 123, start);
        structure.setBlockState(world, Blocks.SPRUCE_SLAB.getDefaultState().with(SlabBlock.TYPE, SlabType.BOTTOM).with(SlabBlock.WATERLOGGED, false), 40, 10, 43, start);
        structure.setBlockState(world, Blocks.SPRUCE_SLAB.getDefaultState().with(SlabBlock.TYPE, SlabType.BOTTOM).with(SlabBlock.WATERLOGGED, false), 40, 10, 79, start);
        structure.setBlockState(world, Blocks.OAK_FENCE_GATE.getDefaultState().with(FenceGateBlock.IN_WALL, false).with(FenceGateBlock.OPEN, false).with(FenceGateBlock.POWERED, false), 40, 11, 57, start);
        structure.setBlockState(world, Blocks.SPRUCE_FENCE.getDefaultState().with(FourWayBlock.WATERLOGGED, false).with(FourWayBlock.NORTH, false).with(FourWayBlock.SOUTH, false).with(FourWayBlock.EAST, false).with(FourWayBlock.WEST, false), 40, 11, 86, start);
        structure.setBlockState(world, Blocks.SPRUCE_FENCE.getDefaultState().with(FourWayBlock.WATERLOGGED, false).with(FourWayBlock.NORTH, false).with(FourWayBlock.SOUTH, false).with(FourWayBlock.EAST, false).with(FourWayBlock.WEST, false), 40, 12, 41, start);
        structure.setBlockState(world, Blocks.SAND.getDefaultState(), 41, 6, 73, start);
        structure.setBlockState(world, Blocks.LANTERN.getDefaultState().with(LanternBlock.WATERLOGGED, false).with(LanternBlock.HANGING, false), 41, 7, 23, start);
        structure.setBlockState(world, Blocks.OAK_FENCE.getDefaultState().with(FourWayBlock.WATERLOGGED, false).with(FourWayBlock.NORTH, true).with(FourWayBlock.SOUTH, false).with(FourWayBlock.EAST, true).with(FourWayBlock.WEST, false), 41, 7, 27, start);
        structure.setBlockState(world, Blocks.OAK_TRAPDOOR.getDefaultState().with(HorizontalBlock.HORIZONTAL_FACING, Direction.WEST).with(TrapDoorBlock.HALF, Half.TOP).with(TrapDoorBlock.WATERLOGGED, false).with(TrapDoorBlock.POWERED, false).with(TrapDoorBlock.OPEN, true), 41, 7, 60, start);
        structure.setBlockState(world, Blocks.OAK_FENCE.getDefaultState().with(FourWayBlock.WATERLOGGED, false).with(FourWayBlock.NORTH, true).with(FourWayBlock.SOUTH, false).with(FourWayBlock.EAST, true).with(FourWayBlock.WEST, true), 41, 7, 76, start);
        structure.setBlockState(world, Blocks.OAK_FENCE.getDefaultState().with(FourWayBlock.WATERLOGGED, false).with(FourWayBlock.NORTH, true).with(FourWayBlock.SOUTH, false).with(FourWayBlock.EAST, false).with(FourWayBlock.WEST, false), 41, 8, 27, start);
        structure.setBlockState(world, Blocks.OAK_FENCE.getDefaultState().with(FourWayBlock.WATERLOGGED, false).with(FourWayBlock.NORTH, true).with(FourWayBlock.SOUTH, false).with(FourWayBlock.EAST, true).with(FourWayBlock.WEST, false), 41, 8, 76, start);
        structure.setBlockState(world, Blocks.OAK_FENCE.getDefaultState().with(FourWayBlock.WATERLOGGED, false).with(FourWayBlock.NORTH, false).with(FourWayBlock.SOUTH, true).with(FourWayBlock.EAST, true).with(FourWayBlock.WEST, false), 41, 8, 105, start);
        structure.setBlockState(world, Blocks.OAK_FENCE.getDefaultState().with(FourWayBlock.WATERLOGGED, false).with(FourWayBlock.NORTH, true).with(FourWayBlock.SOUTH, false).with(FourWayBlock.EAST, false).with(FourWayBlock.WEST, true), 41, 8, 106, start);
        structure.setBlockState(world, Blocks.OAK_FENCE_GATE.getDefaultState().with(FenceGateBlock.IN_WALL, false).with(FenceGateBlock.OPEN, false).with(FenceGateBlock.POWERED, false), 41, 9, 20, start);
        structure.setBlockState(world, Blocks.BROWN_TERRACOTTA.getDefaultState(), 41, 9, 25, start);
        structure.setBlockState(world, Blocks.OAK_FENCE.getDefaultState().with(FourWayBlock.WATERLOGGED, false).with(FourWayBlock.NORTH, false).with(FourWayBlock.SOUTH, false).with(FourWayBlock.EAST, true).with(FourWayBlock.WEST, true), 41, 9, 35, start);
        structure.setBlockState(world, Blocks.OAK_FENCE.getDefaultState().with(FourWayBlock.WATERLOGGED, false).with(FourWayBlock.NORTH, false).with(FourWayBlock.SOUTH, false).with(FourWayBlock.EAST, true).with(FourWayBlock.WEST, true), 41, 9, 37, start);
        structure.setBlockState(world, Blocks.SPRUCE_SLAB.getDefaultState().with(SlabBlock.TYPE, SlabType.BOTTOM).with(SlabBlock.WATERLOGGED, false), 41, 9, 80, start);
        structure.setBlockState(world, Blocks.SPRUCE_SLAB.getDefaultState().with(SlabBlock.TYPE, SlabType.BOTTOM).with(SlabBlock.WATERLOGGED, false), 41, 9, 87, start);
        structure.setBlockState(world, Blocks.OAK_SLAB.getDefaultState().with(SlabBlock.TYPE, SlabType.BOTTOM).with(SlabBlock.WATERLOGGED, false), 41, 9, 104, start);
        structure.setBlockState(world, Blocks.AIR.getDefaultState(), 41, 9, 122, start);
        structure.setBlockState(world, Index.COUNTER_OAK_ANDESITE.getDefaultState().with(Counter.FACING, Direction.NORTH).with(Counter.WATERLOGGED, false), 41, 9, 126, start);
        structure.setBlockState(world, Blocks.OAK_FENCE.getDefaultState().with(FourWayBlock.WATERLOGGED, false).with(FourWayBlock.NORTH, false).with(FourWayBlock.SOUTH, true).with(FourWayBlock.EAST, false).with(FourWayBlock.WEST, false), 41, 11, 88, start);
        structure.setBlockState(world, Blocks.OAK_FENCE.getDefaultState().with(FourWayBlock.WATERLOGGED, false).with(FourWayBlock.NORTH, true).with(FourWayBlock.SOUTH, true).with(FourWayBlock.EAST, false).with(FourWayBlock.WEST, false), 41, 11, 101, start);
        structure.setBlockState(world, Blocks.OAK_FENCE.getDefaultState().with(FourWayBlock.WATERLOGGED, false).with(FourWayBlock.NORTH, true).with(FourWayBlock.SOUTH, false).with(FourWayBlock.EAST, false).with(FourWayBlock.WEST, false), 41, 11, 102, start);
        structure.setBlockState(world, Blocks.OAK_FENCE.getDefaultState().with(FourWayBlock.WATERLOGGED, false).with(FourWayBlock.NORTH, false).with(FourWayBlock.SOUTH, true).with(FourWayBlock.EAST, false).with(FourWayBlock.WEST, false), 41, 12, 89, start);
        structure.setBlockState(world, Blocks.OAK_FENCE.getDefaultState().with(FourWayBlock.WATERLOGGED, false).with(FourWayBlock.NORTH, true).with(FourWayBlock.SOUTH, true).with(FourWayBlock.EAST, false).with(FourWayBlock.WEST, false), 41, 12, 91, start);
        structure.setBlockState(world, Blocks.OAK_LOG.getDefaultState(), 41, 12, 92, start);
        structure.setBlockState(world, Blocks.OAK_LOG.getDefaultState(), 41, 12, 98, start);
        structure.setBlockState(world, Blocks.OAK_FENCE.getDefaultState().with(FourWayBlock.WATERLOGGED, false).with(FourWayBlock.NORTH, true).with(FourWayBlock.SOUTH, false).with(FourWayBlock.EAST, false).with(FourWayBlock.WEST, false), 41, 12, 101, start);
        structure.setBlockState(world, Blocks.OAK_FENCE.getDefaultState().with(FourWayBlock.WATERLOGGED, false).with(FourWayBlock.NORTH, false).with(FourWayBlock.SOUTH, true).with(FourWayBlock.EAST, false).with(FourWayBlock.WEST, false), 41, 13, 91, start);
        structure.setBlockState(world, Blocks.OAK_FENCE.getDefaultState().with(FourWayBlock.WATERLOGGED, false).with(FourWayBlock.NORTH, true).with(FourWayBlock.SOUTH, true).with(FourWayBlock.EAST, false).with(FourWayBlock.WEST, false), 41, 13, 92, start);
        structure.setBlockState(world, Blocks.OAK_FENCE.getDefaultState().with(FourWayBlock.WATERLOGGED, false).with(FourWayBlock.NORTH, true).with(FourWayBlock.SOUTH, true).with(FourWayBlock.EAST, false).with(FourWayBlock.WEST, false), 41, 13, 98, start);
        structure.setBlockState(world, Blocks.OAK_FENCE.getDefaultState().with(FourWayBlock.WATERLOGGED, false).with(FourWayBlock.NORTH, true).with(FourWayBlock.SOUTH, false).with(FourWayBlock.EAST, false).with(FourWayBlock.WEST, false), 41, 13, 99, start);
        structure.setBlockState(world, Blocks.OAK_FENCE_GATE.getDefaultState().with(FenceGateBlock.IN_WALL, false).with(FenceGateBlock.OPEN, false).with(FenceGateBlock.POWERED, false), 41, 14, 123, start);
        structure.setBlockState(world, Blocks.OAK_FENCE.getDefaultState().with(FourWayBlock.WATERLOGGED, false).with(FourWayBlock.NORTH, true).with(FourWayBlock.SOUTH, true).with(FourWayBlock.EAST, false).with(FourWayBlock.WEST, false), 41, 15, 93, start);
        structure.setBlockState(world, Blocks.OAK_FENCE.getDefaultState().with(FourWayBlock.WATERLOGGED, false).with(FourWayBlock.NORTH, true).with(FourWayBlock.SOUTH, true).with(FourWayBlock.EAST, false).with(FourWayBlock.WEST, false), 41, 15, 97, start);
        structure.setBlockState(world, Blocks.OAK_FENCE.getDefaultState().with(FourWayBlock.WATERLOGGED, false).with(FourWayBlock.NORTH, true).with(FourWayBlock.SOUTH, true).with(FourWayBlock.EAST, false).with(FourWayBlock.WEST, false), 41, 17, 94, start);
        structure.setBlockState(world, Blocks.OAK_FENCE.getDefaultState().with(FourWayBlock.WATERLOGGED, false).with(FourWayBlock.NORTH, true).with(FourWayBlock.SOUTH, true).with(FourWayBlock.EAST, false).with(FourWayBlock.WEST, false), 41, 17, 96, start);
        structure.setBlockState(world, Blocks.OAK_FENCE.getDefaultState().with(FourWayBlock.WATERLOGGED, false).with(FourWayBlock.NORTH, false).with(FourWayBlock.SOUTH, true).with(FourWayBlock.EAST, false).with(FourWayBlock.WEST, false), 41, 18, 94, start);
        structure.setBlockState(world, Blocks.OAK_FENCE.getDefaultState().with(FourWayBlock.WATERLOGGED, false).with(FourWayBlock.NORTH, true).with(FourWayBlock.SOUTH, false).with(FourWayBlock.EAST, false).with(FourWayBlock.WEST, false), 41, 18, 96, start);
        structure.setBlockState(world, Blocks.SAND.getDefaultState(), 42, 5, 73, start);
        structure.setBlockState(world, Blocks.PODZOL.getDefaultState().with(SnowyDirtBlock.SNOWY, false), 42, 6, 82, start);
        structure.setBlockState(world, Blocks.PODZOL.getDefaultState().with(SnowyDirtBlock.SNOWY, false), 42, 6, 84, start);
        structure.setBlockState(world, Blocks.OAK_FENCE_GATE.getDefaultState().with(FenceGateBlock.IN_WALL, false).with(FenceGateBlock.OPEN, false).with(FenceGateBlock.POWERED, false), 42, 7, 27, start);
        structure.setBlockState(world, Blocks.OAK_FENCE.getDefaultState().with(FourWayBlock.WATERLOGGED, false).with(FourWayBlock.NORTH, false).with(FourWayBlock.SOUTH, false).with(FourWayBlock.EAST, true).with(FourWayBlock.WEST, false), 42, 7, 44, start);
        structure.setBlockState(world, Blocks.OAK_FENCE.getDefaultState().with(FourWayBlock.WATERLOGGED, false).with(FourWayBlock.NORTH, false).with(FourWayBlock.SOUTH, false).with(FourWayBlock.EAST, true).with(FourWayBlock.WEST, false), 42, 7, 47, start);
        structure.setBlockState(world, Blocks.OAK_FENCE_GATE.getDefaultState().with(FenceGateBlock.IN_WALL, false).with(FenceGateBlock.OPEN, true).with(FenceGateBlock.POWERED, false), 42, 7, 59, start);
        structure.setBlockState(world, Blocks.SPRUCE_SLAB.getDefaultState().with(SlabBlock.TYPE, SlabType.TOP).with(SlabBlock.WATERLOGGED, false), 42, 7, 60, start);
        structure.setBlockState(world, Blocks.LANTERN.getDefaultState().with(LanternBlock.WATERLOGGED, false).with(LanternBlock.HANGING, false), 42, 7, 75, start);
        structure.setBlockState(world, Blocks.OAK_FENCE.getDefaultState().with(FourWayBlock.WATERLOGGED, false).with(FourWayBlock.NORTH, false).with(FourWayBlock.SOUTH, true).with(FourWayBlock.EAST, false).with(FourWayBlock.WEST, true), 42, 8, 102, start);
        structure.setBlockState(world, Blocks.OAK_SLAB.getDefaultState().with(SlabBlock.TYPE, SlabType.DOUBLE).with(SlabBlock.WATERLOGGED, false), 42, 8, 103, start);
        structure.setBlockState(world, Blocks.OAK_FENCE.getDefaultState().with(FourWayBlock.WATERLOGGED, false).with(FourWayBlock.NORTH, true).with(FourWayBlock.SOUTH, true).with(FourWayBlock.EAST, true).with(FourWayBlock.WEST, false), 42, 8, 104, start);
        structure.setBlockState(world, Blocks.OAK_FENCE.getDefaultState().with(FourWayBlock.WATERLOGGED, false).with(FourWayBlock.NORTH, true).with(FourWayBlock.SOUTH, false).with(FourWayBlock.EAST, false).with(FourWayBlock.WEST, true), 42, 8, 105, start);
        structure.setBlockState(world, Blocks.OAK_FENCE.getDefaultState().with(FourWayBlock.WATERLOGGED, false).with(FourWayBlock.NORTH, false).with(FourWayBlock.SOUTH, true).with(FourWayBlock.EAST, false).with(FourWayBlock.WEST, false), 42, 9, 19, start);
        structure.setBlockState(world, Blocks.OAK_FENCE.getDefaultState().with(FourWayBlock.WATERLOGGED, false).with(FourWayBlock.NORTH, true).with(FourWayBlock.SOUTH, true).with(FourWayBlock.EAST, true).with(FourWayBlock.WEST, true), 42, 9, 20, start);
        structure.setBlockState(world, Blocks.OAK_TRAPDOOR.getDefaultState().with(HorizontalBlock.HORIZONTAL_FACING, Direction.NORTH).with(TrapDoorBlock.HALF, Half.TOP).with(TrapDoorBlock.WATERLOGGED, false).with(TrapDoorBlock.POWERED, false).with(TrapDoorBlock.OPEN, true), 42, 9, 25, start);
        structure.setBlockState(world, Blocks.OAK_FENCE.getDefaultState().with(FourWayBlock.WATERLOGGED, false).with(FourWayBlock.NORTH, false).with(FourWayBlock.SOUTH, false).with(FourWayBlock.EAST, true).with(FourWayBlock.WEST, false), 42, 9, 63, start);
        structure.setBlockState(world, Blocks.OAK_LOG.getDefaultState(), 42, 9, 87, start);
        structure.setBlockState(world, Blocks.OAK_FENCE.getDefaultState().with(FourWayBlock.WATERLOGGED, false).with(FourWayBlock.NORTH, false).with(FourWayBlock.SOUTH, false).with(FourWayBlock.EAST, false).with(FourWayBlock.WEST, true), 42, 9, 102, start);
        structure.setBlockState(world, Index.BENCH_OAK.getDefaultState().with(Bench.STATE, BenchState.SOUTH), 42, 9, 121, start);
        structure.setBlockState(world, Index.BENCH_OAK.getDefaultState().with(Bench.STATE, BenchState.NONE_Z), 42, 9, 122, start);
        structure.setBlockState(world, Index.BENCH_OAK.getDefaultState().with(Bench.STATE, BenchState.NORTH), 42, 9, 123, start);
        structure.setBlockState(world, Blocks.CAULDRON.getDefaultState().with(CauldronBlock.LEVEL, 0), 42, 9, 126, start);
        structure.setBlockState(world, Blocks.OAK_FENCE.getDefaultState().with(FourWayBlock.WATERLOGGED, false).with(FourWayBlock.NORTH, false).with(FourWayBlock.SOUTH, false).with(FourWayBlock.EAST, false).with(FourWayBlock.WEST, false), 42, 10, 75, start);
        structure.setBlockState(world, Blocks.OAK_LOG.getDefaultState(), 42, 10, 80, start);
        structure.setBlockState(world, Blocks.SPRUCE_SLAB.getDefaultState().with(SlabBlock.TYPE, SlabType.BOTTOM).with(SlabBlock.WATERLOGGED, false), 42, 10, 87, start);
        structure.setBlockState(world, Blocks.SPRUCE_SLAB.getDefaultState().with(SlabBlock.TYPE, SlabType.BOTTOM).with(SlabBlock.WATERLOGGED, false), 42, 11, 75, start);
        structure.setBlockState(world, Blocks.SPRUCE_FENCE.getDefaultState().with(FourWayBlock.WATERLOGGED, false).with(FourWayBlock.NORTH, false).with(FourWayBlock.SOUTH, false).with(FourWayBlock.EAST, false).with(FourWayBlock.WEST, false), 42, 11, 80, start);
        structure.setBlockState(world, Blocks.OAK_FENCE_GATE.getDefaultState().with(FenceGateBlock.IN_WALL, false).with(FenceGateBlock.OPEN, false).with(FenceGateBlock.POWERED, false), 42, 11, 127, start);
        structure.setBlockState(world, Blocks.OAK_FENCE_GATE.getDefaultState().with(FenceGateBlock.IN_WALL, false).with(FenceGateBlock.OPEN, false).with(FenceGateBlock.POWERED, false), 42, 12, 126, start);
        structure.setBlockState(world, Blocks.OAK_FENCE.getDefaultState().with(FourWayBlock.WATERLOGGED, false).with(FourWayBlock.NORTH, true).with(FourWayBlock.SOUTH, false).with(FourWayBlock.EAST, false).with(FourWayBlock.WEST, true), 43, 7, 27, start);
        structure.setBlockState(world, Blocks.DEAD_BUSH.getDefaultState(), 43, 7, 28, start);
        structure.setBlockState(world, Blocks.OAK_FENCE.getDefaultState().with(FourWayBlock.WATERLOGGED, false).with(FourWayBlock.NORTH, false).with(FourWayBlock.SOUTH, false).with(FourWayBlock.EAST, true).with(FourWayBlock.WEST, true), 43, 7, 44, start);
        structure.setBlockState(world, Blocks.OAK_FENCE.getDefaultState().with(FourWayBlock.WATERLOGGED, false).with(FourWayBlock.NORTH, false).with(FourWayBlock.SOUTH, false).with(FourWayBlock.EAST, true).with(FourWayBlock.WEST, true), 43, 7, 47, start);
        structure.setBlockState(world, Blocks.OAK_TRAPDOOR.getDefaultState().with(HorizontalBlock.HORIZONTAL_FACING, Direction.EAST).with(TrapDoorBlock.HALF, Half.TOP).with(TrapDoorBlock.WATERLOGGED, false).with(TrapDoorBlock.POWERED, false).with(TrapDoorBlock.OPEN, true), 43, 7, 60, start);
        structure.setBlockState(world, Blocks.OAK_TRAPDOOR.getDefaultState().with(HorizontalBlock.HORIZONTAL_FACING, Direction.NORTH).with(TrapDoorBlock.HALF, Half.BOTTOM).with(TrapDoorBlock.WATERLOGGED, false).with(TrapDoorBlock.POWERED, false).with(TrapDoorBlock.OPEN, true), 43, 7, 62, start);
        structure.setBlockState(world, Blocks.CAMPFIRE.getDefaultState().with(CampfireBlock.FACING, Direction.SOUTH).with(CampfireBlock.LIT, true).with(CampfireBlock.SIGNAL_FIRE, false).with(CampfireBlock.WATERLOGGED, false), 43, 7, 63, start);
        structure.setBlockState(world, Blocks.OAK_TRAPDOOR.getDefaultState().with(HorizontalBlock.HORIZONTAL_FACING, Direction.SOUTH).with(TrapDoorBlock.HALF, Half.BOTTOM).with(TrapDoorBlock.WATERLOGGED, false).with(TrapDoorBlock.POWERED, false).with(TrapDoorBlock.OPEN, true), 43, 7, 64, start);
        structure.setBlockState(world, Index.STOOL_SPRUCE.getDefaultState().with(Stool.PILLOW, StoolState.NONE), 43, 7, 67, start);
        structure.setBlockState(world, Blocks.AIR.getDefaultState(), 43, 7, 74, start);
        structure.setBlockState(world, Blocks.OAK_FENCE.getDefaultState().with(FourWayBlock.WATERLOGGED, false).with(FourWayBlock.NORTH, true).with(FourWayBlock.SOUTH, false).with(FourWayBlock.EAST, false).with(FourWayBlock.WEST, false), 43, 8, 27, start);
        structure.setBlockState(world, Blocks.CAULDRON.getDefaultState().with(CauldronBlock.LEVEL, 0), 43, 8, 63, start);
        structure.setBlockState(world, Blocks.OAK_FENCE.getDefaultState().with(FourWayBlock.WATERLOGGED, false).with(FourWayBlock.NORTH, false).with(FourWayBlock.SOUTH, false).with(FourWayBlock.EAST, true).with(FourWayBlock.WEST, true), 43, 8, 104, start);
        structure.setBlockState(world, Blocks.OAK_FENCE_GATE.getDefaultState().with(FenceGateBlock.IN_WALL, false).with(FenceGateBlock.OPEN, false).with(FenceGateBlock.POWERED, false), 43, 9, 20, start);
        structure.setBlockState(world, Blocks.BROWN_TERRACOTTA.getDefaultState(), 43, 9, 25, start);
        structure.setBlockState(world, Blocks.OAK_FENCE.getDefaultState().with(FourWayBlock.WATERLOGGED, false).with(FourWayBlock.NORTH, false).with(FourWayBlock.SOUTH, false).with(FourWayBlock.EAST, true).with(FourWayBlock.WEST, false), 43, 9, 39, start);
        structure.setBlockState(world, Blocks.OAK_FENCE.getDefaultState().with(FourWayBlock.WATERLOGGED, false).with(FourWayBlock.NORTH, false).with(FourWayBlock.SOUTH, false).with(FourWayBlock.EAST, true).with(FourWayBlock.WEST, true), 43, 9, 63, start);
        structure.setBlockState(world, Blocks.OAK_TRAPDOOR.getDefaultState().with(HorizontalBlock.HORIZONTAL_FACING, Direction.WEST).with(TrapDoorBlock.HALF, Half.TOP).with(TrapDoorBlock.WATERLOGGED, false).with(TrapDoorBlock.POWERED, false).with(TrapDoorBlock.OPEN, true), 43, 9, 66, start);
        structure.setBlockState(world, Blocks.OAK_TRAPDOOR.getDefaultState().with(HorizontalBlock.HORIZONTAL_FACING, Direction.WEST).with(TrapDoorBlock.HALF, Half.TOP).with(TrapDoorBlock.WATERLOGGED, false).with(TrapDoorBlock.POWERED, false).with(TrapDoorBlock.OPEN, true), 43, 9, 68, start);
        structure.setBlockState(world, Blocks.SPRUCE_SLAB.getDefaultState().with(SlabBlock.TYPE, SlabType.BOTTOM).with(SlabBlock.WATERLOGGED, false), 43, 9, 88, start);
        structure.setBlockState(world, Index.TABLE_OAK.getDefaultState().with(Table.NE, true).with(Table.NW, true).with(Table.SE, false).with(Table.SW, false), 43, 9, 121, start);
        structure.setBlockState(world, Index.TABLE_OAK.getDefaultState().with(Table.NE, false).with(Table.NW, false).with(Table.SE, false).with(Table.SW, false), 43, 9, 122, start);
        structure.setBlockState(world, Index.TABLE_OAK.getDefaultState().with(Table.NE, false).with(Table.NW, false).with(Table.SE, true).with(Table.SW, true), 43, 9, 123, start);
        structure.setBlockState(world, Blocks.CRAFTING_TABLE.getDefaultState(), 43, 9, 126, start);
        structure.setBlockState(world, Blocks.SPRUCE_SLAB.getDefaultState().with(SlabBlock.TYPE, SlabType.BOTTOM).with(SlabBlock.WATERLOGGED, false), 43, 10, 80, start);
        structure.setBlockState(world, Blocks.LANTERN.getDefaultState().with(LanternBlock.WATERLOGGED, false).with(LanternBlock.HANGING, true), 43, 12, 123, start);
        structure.setBlockState(world, Blocks.PODZOL.getDefaultState().with(SnowyDirtBlock.SNOWY, false), 44, 6, 81, start);
        structure.setBlockState(world, Blocks.PODZOL.getDefaultState().with(SnowyDirtBlock.SNOWY, false), 44, 6, 85, start);
        structure.setBlockState(world, Blocks.OAK_FENCE.getDefaultState().with(FourWayBlock.WATERLOGGED, false).with(FourWayBlock.NORTH, false).with(FourWayBlock.SOUTH, true).with(FourWayBlock.EAST, true).with(FourWayBlock.WEST, false), 44, 7, 18, start);
        structure.setBlockState(world, Blocks.OAK_FENCE.getDefaultState().with(FourWayBlock.WATERLOGGED, false).with(FourWayBlock.NORTH, true).with(FourWayBlock.SOUTH, true).with(FourWayBlock.EAST, false).with(FourWayBlock.WEST, true), 44, 7, 19, start);
        structure.setBlockState(world, Blocks.OAK_TRAPDOOR.getDefaultState().with(HorizontalBlock.HORIZONTAL_FACING, Direction.NORTH).with(TrapDoorBlock.HALF, Half.BOTTOM).with(TrapDoorBlock.WATERLOGGED, false).with(TrapDoorBlock.POWERED, false).with(TrapDoorBlock.OPEN, true), 44, 7, 38, start);
        structure.setBlockState(world, Blocks.CAMPFIRE.getDefaultState().with(CampfireBlock.FACING, Direction.WEST).with(CampfireBlock.LIT, true).with(CampfireBlock.SIGNAL_FIRE, false).with(CampfireBlock.WATERLOGGED, false), 44, 7, 39, start);
        structure.setBlockState(world, Blocks.OAK_TRAPDOOR.getDefaultState().with(HorizontalBlock.HORIZONTAL_FACING, Direction.SOUTH).with(TrapDoorBlock.HALF, Half.BOTTOM).with(TrapDoorBlock.WATERLOGGED, false).with(TrapDoorBlock.POWERED, false).with(TrapDoorBlock.OPEN, true), 44, 7, 40, start);
        structure.setBlockState(world, Blocks.OAK_FENCE.getDefaultState().with(FourWayBlock.WATERLOGGED, false).with(FourWayBlock.NORTH, false).with(FourWayBlock.SOUTH, false).with(FourWayBlock.EAST, false).with(FourWayBlock.WEST, true), 44, 7, 44, start);
        structure.setBlockState(world, Blocks.OAK_FENCE.getDefaultState().with(FourWayBlock.WATERLOGGED, false).with(FourWayBlock.NORTH, false).with(FourWayBlock.SOUTH, false).with(FourWayBlock.EAST, false).with(FourWayBlock.WEST, true), 44, 7, 47, start);
        structure.setBlockState(world, Blocks.AIR.getDefaultState(), 44, 7, 50, start);
        structure.setBlockState(world, Blocks.OAK_FENCE.getDefaultState().with(FourWayBlock.WATERLOGGED, false).with(FourWayBlock.NORTH, false).with(FourWayBlock.SOUTH, true).with(FourWayBlock.EAST, false).with(FourWayBlock.WEST, true), 44, 8, 19, start);
        structure.setBlockState(world, Blocks.CAULDRON.getDefaultState().with(CauldronBlock.LEVEL, 0), 44, 8, 39, start);
        structure.setBlockState(world, Blocks.OAK_SLAB.getDefaultState().with(SlabBlock.TYPE, SlabType.DOUBLE).with(SlabBlock.WATERLOGGED, false), 44, 8, 103, start);
        structure.setBlockState(world, Blocks.OAK_FENCE.getDefaultState().with(FourWayBlock.WATERLOGGED, false).with(FourWayBlock.NORTH, true).with(FourWayBlock.SOUTH, false).with(FourWayBlock.EAST, true).with(FourWayBlock.WEST, true), 44, 8, 104, start);
