package mod.arcalitegames.odyssey.world.structure.structures.ruins.goblin_ruins;

import mod.arcalitegames.odyssey.world.structure.StructureBase;
import net.minecraft.block.Blocks;
import net.minecraft.block.LeavesBlock;
import net.minecraft.block.SlabBlock;
import net.minecraft.block.SnowyDirtBlock;
import net.minecraft.block.StairsBlock;
import net.minecraft.block.WallBlock;
import net.minecraft.block.WallHeight;
import net.minecraft.state.properties.Half;
import net.minecraft.state.properties.SlabType;
import net.minecraft.state.properties.StairsShape;
import net.minecraft.util.Direction;
import net.minecraft.util.math.BlockPos;
import net.minecraft.world.World;

public class GoblinComponent1
{

	public static BlockPos start;
    public static World world;
    public static StructureBase structure;

    public static void init(World worldIn, BlockPos blockPos, StructureBase structureIn)
    {
        world = worldIn; start = blockPos; structure = structureIn;
    }
    
    public static void generatePart11()
    {
        structure.fillWithBlocks(world, start, 56, 27, 30, 56, 27, 30, Blocks.STONE_BRICK_SLAB.getDefaultState().with(SlabBlock.TYPE, SlabType.BOTTOM).with(SlabBlock.WATERLOGGED, false));
        structure.fillWithBlocks(world, start, 56, 27, 32, 56, 27, 33, Blocks.STONE_BRICK_SLAB.getDefaultState().with(SlabBlock.TYPE, SlabType.BOTTOM).with(SlabBlock.WATERLOGGED, false));
        structure.fillWithBlocks(world, start, 56, 27, 35, 56, 27, 37, Blocks.STONE_BRICK_SLAB.getDefaultState().with(SlabBlock.TYPE, SlabType.BOTTOM).with(SlabBlock.WATERLOGGED, false));
        structure.fillWithBlocks(world, start, 56, 27, 39, 56, 27, 40, Blocks.STONE_BRICK_SLAB.getDefaultState().with(SlabBlock.TYPE, SlabType.BOTTOM).with(SlabBlock.WATERLOGGED, false));
        structure.fillWithBlocks(world, start, 56, 31, 33, 56, 31, 33, Blocks.STONE_BRICKS.getDefaultState());
        structure.fillWithBlocks(world, start, 56, 32, 20, 57, 32, 20, Blocks.STONE_BRICK_SLAB.getDefaultState().with(SlabBlock.TYPE, SlabType.TOP).with(SlabBlock.WATERLOGGED, false));
        structure.fillWithBlocks(world, start, 56, 32, 52, 57, 32, 52, Blocks.STONE_BRICK_SLAB.getDefaultState().with(SlabBlock.TYPE, SlabType.TOP).with(SlabBlock.WATERLOGGED, false));
        structure.fillWithBlocks(world, start, 56, 33, 19, 57, 33, 19, Blocks.STONE_BRICK_SLAB.getDefaultState().with(SlabBlock.TYPE, SlabType.BOTTOM).with(SlabBlock.WATERLOGGED, false));
        structure.fillWithBlocks(world, start, 56, 33, 20, 57, 33, 20, Blocks.STONE_BRICK_SLAB.getDefaultState().with(SlabBlock.TYPE, SlabType.DOUBLE).with(SlabBlock.WATERLOGGED, false));
        structure.fillWithBlocks(world, start, 56, 33, 21, 57, 33, 21, Blocks.STONE_BRICK_SLAB.getDefaultState().with(SlabBlock.TYPE, SlabType.BOTTOM).with(SlabBlock.WATERLOGGED, false));
        structure.fillWithBlocks(world, start, 56, 33, 51, 57, 33, 51, Blocks.STONE_BRICK_SLAB.getDefaultState().with(SlabBlock.TYPE, SlabType.BOTTOM).with(SlabBlock.WATERLOGGED, false));
        structure.fillWithBlocks(world, start, 56, 33, 52, 57, 33, 52, Blocks.STONE_BRICK_SLAB.getDefaultState().with(SlabBlock.TYPE, SlabType.DOUBLE).with(SlabBlock.WATERLOGGED, false));
        structure.fillWithBlocks(world, start, 56, 33, 53, 57, 33, 53, Blocks.STONE_BRICK_SLAB.getDefaultState().with(SlabBlock.TYPE, SlabType.BOTTOM).with(SlabBlock.WATERLOGGED, false));
        structure.fillWithBlocks(world, start, 57, 0, 70, 61, 0, 74, Blocks.DIRT.getDefaultState());
        structure.fillWithBlocks(world, start, 57, 1, 68, 61, 1, 73, Blocks.DIRT.getDefaultState());
        structure.fillWithBlocks(world, start, 57, 2, 48, 68, 2, 59, Blocks.DIRT.getDefaultState());
        structure.fillWithBlocks(world, start, 57, 5, 68, 58, 5, 69, Blocks.GRASS_BLOCK.getDefaultState().with(SnowyDirtBlock.SNOWY, false));
        structure.fillWithBlocks(world, start, 57, 6, 59, 60, 6, 67, Blocks.GRASS_BLOCK.getDefaultState().with(SnowyDirtBlock.SNOWY, false));
        structure.fillWithBlocks(world, start, 57, 8, 20, 59, 8, 22, Blocks.STONE.getDefaultState());
        structure.fillWithBlocks(world, start, 57, 8, 24, 57, 8, 24, Blocks.STONE_BRICKS.getDefaultState());
        structure.fillWithBlocks(world, start, 57, 8, 25, 57, 8, 25, Blocks.COBBLESTONE_STAIRS.getDefaultState().with(StairsBlock.FACING, Direction.SOUTH).with(StairsBlock.WATERLOGGED, false).with(StairsBlock.SHAPE, StairsShape.OUTER_RIGHT).with(StairsBlock.HALF, Half.BOTTOM));
        structure.fillWithBlocks(world, start, 57, 8, 26, 57, 8, 26, Blocks.COBBLESTONE_STAIRS.getDefaultState().with(StairsBlock.FACING, Direction.WEST).with(StairsBlock.WATERLOGGED, false).with(StairsBlock.SHAPE, StairsShape.INNER_LEFT).with(StairsBlock.HALF, Half.BOTTOM));
        structure.fillWithBlocks(world, start, 57, 8, 27, 57, 8, 32, Blocks.STONE.getDefaultState());
        structure.fillWithBlocks(world, start, 57, 8, 34, 61, 8, 38, Blocks.SMOOTH_STONE.getDefaultState());
        structure.fillWithBlocks(world, start, 57, 8, 40, 59, 8, 43, Blocks.STONE.getDefaultState());
        structure.fillWithBlocks(world, start, 57, 8, 48, 59, 8, 48, Blocks.STONE_BRICKS.getDefaultState());
        structure.fillWithBlocks(world, start, 57, 8, 50, 59, 8, 52, Blocks.STONE.getDefaultState());
        structure.fillWithBlocks(world, start, 57, 9, 9, 57, 10, 9, Blocks.OAK_LEAVES.getDefaultState().with(LeavesBlock.PERSISTENT, false).with(LeavesBlock.DISTANCE, 3));
        structure.fillWithBlocks(world, start, 57, 9, 10, 57, 10, 10, Blocks.OAK_LEAVES.getDefaultState().with(LeavesBlock.PERSISTENT, false).with(LeavesBlock.DISTANCE, 2));
        structure.fillWithBlocks(world, start, 57, 9, 11, 57, 10, 11, Blocks.OAK_LEAVES.getDefaultState().with(LeavesBlock.PERSISTENT, false).with(LeavesBlock.DISTANCE, 3));
        structure.fillWithBlocks(world, start, 57, 9, 20, 59, 9, 22, Blocks.STONE_BRICKS.getDefaultState());
        structure.fillWithBlocks(world, start, 57, 9, 27, 57, 9, 27, Blocks.STONE_BRICKS.getDefaultState());
        structure.fillWithBlocks(world, start, 57, 9, 28, 57, 9, 30, Blocks.COBBLESTONE.getDefaultState());
        structure.fillWithBlocks(world, start, 57, 9, 31, 57, 9, 32, Blocks.STONE_BRICKS.getDefaultState());
        structure.fillWithBlocks(world, start, 57, 9, 40, 57, 9, 41, Blocks.STONE_BRICKS.getDefaultState());
        structure.fillWithBlocks(world, start, 57, 9, 42, 58, 9, 43, Blocks.COBBLESTONE.getDefaultState());
        structure.fillWithBlocks(world, start, 57, 9, 44, 57, 11, 44, Blocks.COBBLESTONE.getDefaultState());
        structure.fillWithBlocks(world, start, 57, 9, 50, 59, 9, 52, Blocks.STONE_BRICKS.getDefaultState());
        structure.fillWithBlocks(world, start, 57, 10, 20, 57, 11, 20, Blocks.COBBLESTONE_WALL.getDefaultState().with(WallBlock.WATERLOGGED, false).with(WallBlock.UP, true).with(WallBlock.WALL_HEIGHT_NORTH, WallHeight.LOW).with(WallBlock.WALL_HEIGHT_SOUTH, WallHeight.LOW).with(WallBlock.WALL_HEIGHT_EAST, WallHeight.LOW).with(WallBlock.WALL_HEIGHT_WEST, WallHeight.LOW));
        structure.fillWithBlocks(world, start, 57, 10, 22, 57, 11, 22, Blocks.COBBLESTONE_WALL.getDefaultState().with(WallBlock.WATERLOGGED, false).with(WallBlock.UP, true).with(WallBlock.WALL_HEIGHT_NORTH, WallHeight.LOW).with(WallBlock.WALL_HEIGHT_SOUTH, WallHeight.LOW).with(WallBlock.WALL_HEIGHT_EAST, WallHeight.LOW).with(WallBlock.WALL_HEIGHT_WEST, WallHeight.LOW));
        structure.fillWithBlocks(world, start, 57, 10, 28, 57, 10, 30, Blocks.COBBLESTONE.getDefaultState());
        structure.fillWithBlocks(world, start, 57, 10, 42, 58, 10, 43, Blocks.COBBLESTONE.getDefaultState());
        structure.fillWithBlocks(world, start, 57, 10, 50, 57, 11, 50, Blocks.COBBLESTONE_WALL.getDefaultState().with(WallBlock.WATERLOGGED, false).with(WallBlock.UP, true).with(WallBlock.WALL_HEIGHT_NORTH, WallHeight.LOW).with(WallBlock.WALL_HEIGHT_SOUTH, WallHeight.LOW).with(WallBlock.WALL_HEIGHT_EAST, WallHeight.LOW).with(WallBlock.WALL_HEIGHT_WEST, WallHeight.LOW));
        structure.fillWithBlocks(world, start, 57, 10, 52, 57, 11, 52, Blocks.COBBLESTONE_WALL.getDefaultState().with(WallBlock.WATERLOGGED, false).with(WallBlock.UP, true).with(WallBlock.WALL_HEIGHT_NORTH, WallHeight.LOW).with(WallBlock.WALL_HEIGHT_SOUTH, WallHeight.LOW).with(WallBlock.WALL_HEIGHT_EAST, WallHeight.LOW).with(WallBlock.WALL_HEIGHT_WEST, WallHeight.LOW));
        structure.fillWithBlocks(world, start, 57, 10, 57, 57, 11, 57, Blocks.OAK_LEAVES.getDefaultState().with(LeavesBlock.PERSISTENT, false).with(LeavesBlock.DISTANCE, 3));
        structure.fillWithBlocks(world, start, 57, 10, 58, 57, 12, 58, Blocks.OAK_LEAVES.getDefaultState().with(LeavesBlock.PERSISTENT, false).with(LeavesBlock.DISTANCE, 2));
        structure.fillWithBlocks(world, start, 57, 10, 59, 57, 12, 59, Blocks.OAK_LEAVES.getDefaultState().with(LeavesBlock.PERSISTENT, false).with(LeavesBlock.DISTANCE, 1));
        structure.fillWithBlocks(world, start, 57, 10, 60, 57, 12, 60, Blocks.OAK_LEAVES.getDefaultState().with(LeavesBlock.PERSISTENT, false).with(LeavesBlock.DISTANCE, 2));
        structure.fillWithBlocks(world, start, 57, 10, 61, 57, 11, 61, Blocks.OAK_LEAVES.getDefaultState().with(LeavesBlock.PERSISTENT, false).with(LeavesBlock.DISTANCE, 3));
        structure.fillWithBlocks(world, start, 57, 11, 28, 57, 11, 28, Blocks.COBBLESTONE.getDefaultState());
        structure.fillWithBlocks(world, start, 57, 11, 30, 57, 11, 30, Blocks.COBBLESTONE.getDefaultState());
        structure.fillWithBlocks(world, start, 57, 11, 42, 57, 11, 42, Blocks.COBBLESTONE.getDefaultState());
        structure.fillWithBlocks(world, start, 57, 12, 20, 59, 12, 22, Blocks.STONE_BRICKS.getDefaultState());
        structure.fillWithBlocks(world, start, 57, 12, 29, 57, 12, 30, Blocks.STONE_BRICKS.getDefaultState());
        structure.fillWithBlocks(world, start, 57, 12, 42, 57, 12, 43, Blocks.STONE_BRICKS.getDefaultState());
        structure.fillWithBlocks(world, start, 57, 12, 50, 59, 12, 52, Blocks.STONE_BRICKS.getDefaultState());
        structure.fillWithBlocks(world, start, 57, 13, 21, 57, 13, 21, Blocks.STONE_BRICKS.getDefaultState());
        structure.fillWithBlocks(world, start, 57, 13, 30, 57, 18, 30, Blocks.STONE_BRICKS.getDefaultState());
        structure.fillWithBlocks(world, start, 57, 13, 42, 57, 18, 42, Blocks.STONE_BRICKS.getDefaultState());
        structure.fillWithBlocks(world, start, 57, 13, 51, 57, 13, 51, Blocks.STONE_BRICKS.getDefaultState());
        structure.fillWithBlocks(world, start, 57, 15, 20, 59, 15, 22, Blocks.STONE_BRICKS.getDefaultState());
        structure.fillWithBlocks(world, start, 57, 15, 50, 59, 15, 52, Blocks.STONE_BRICKS.getDefaultState());
        structure.fillWithBlocks(world, start, 57, 17, 21, 57, 18, 21, Blocks.STONE_BRICKS.getDefaultState());
        structure.fillWithBlocks(world, start, 57, 17, 51, 57, 18, 51, Blocks.STONE_BRICKS.getDefaultState());
        structure.fillWithBlocks(world, start, 57, 18, 20, 59, 18, 22, Blocks.STONE_BRICKS.getDefaultState());
        structure.fillWithBlocks(world, start, 57, 18, 29, 57, 18, 30, Blocks.STONE_BRICKS.getDefaultState());
        structure.fillWithBlocks(world, start, 57, 18, 43, 58, 18, 43, Blocks.STONE_BRICKS.getDefaultState());
        structure.fillWithBlocks(world, start, 57, 18, 50, 59, 18, 52, Blocks.STONE_BRICKS.getDefaultState());
        structure.fillWithBlocks(world, start, 57, 19, 20, 57, 20, 20, Blocks.COBBLESTONE_WALL.getDefaultState().with(WallBlock.WATERLOGGED, false).with(WallBlock.UP, true).with(WallBlock.WALL_HEIGHT_NORTH, WallHeight.LOW).with(WallBlock.WALL_HEIGHT_SOUTH, WallHeight.LOW).with(WallBlock.WALL_HEIGHT_EAST, WallHeight.LOW).with(WallBlock.WALL_HEIGHT_WEST, WallHeight.LOW));
        structure.fillWithBlocks(world, start, 57, 19, 22, 57, 20, 22, Blocks.COBBLESTONE_WALL.getDefaultState().with(WallBlock.WATERLOGGED, false).with(WallBlock.UP, true).with(WallBlock.WALL_HEIGHT_NORTH, WallHeight.LOW).with(WallBlock.WALL_HEIGHT_SOUTH, WallHeight.LOW).with(WallBlock.WALL_HEIGHT_EAST, WallHeight.LOW).with(WallBlock.WALL_HEIGHT_WEST, WallHeight.LOW));
        structure.fillWithBlocks(world, start, 57, 19, 28, 57, 21, 28, Blocks.COBBLESTONE.getDefaultState());
        structure.fillWithBlocks(world, start, 57, 19, 30, 57, 19, 30, Blocks.COBBLESTONE.getDefaultState());
        structure.fillWithBlocks(world, start, 57, 19, 42, 57, 19, 42, Blocks.COBBLESTONE.getDefaultState());
        structure.fillWithBlocks(world, start, 57, 19, 44, 57, 21, 44, Blocks.COBBLESTONE.getDefaultState());
        structure.fillWithBlocks(world, start, 57, 19, 50, 57, 20, 50, Blocks.COBBLESTONE_WALL.getDefaultState().with(WallBlock.WATERLOGGED, false).with(WallBlock.UP, true).with(WallBlock.WALL_HEIGHT_NORTH, WallHeight.LOW).with(WallBlock.WALL_HEIGHT_SOUTH, WallHeight.LOW).with(WallBlock.WALL_HEIGHT_EAST, WallHeight.LOW).with(WallBlock.WALL_HEIGHT_WEST, WallHeight.LOW));
        structure.fillWithBlocks(world, start, 57, 19, 52, 57, 20, 52, Blocks.COBBLESTONE_WALL.getDefaultState().with(WallBlock.WATERLOGGED, false).with(WallBlock.UP, true).with(WallBlock.WALL_HEIGHT_NORTH, WallHeight.LOW).with(WallBlock.WALL_HEIGHT_SOUTH, WallHeight.LOW).with(WallBlock.WALL_HEIGHT_EAST, WallHeight.LOW).with(WallBlock.WALL_HEIGHT_WEST, WallHeight.LOW));
        structure.fillWithBlocks(world, start, 57, 20, 29, 58, 20, 30, Blocks.COBBLESTONE.getDefaultState());
        structure.fillWithBlocks(world, start, 57, 20, 42, 58, 20, 43, Blocks.COBBLESTONE.getDefaultState());
        structure.fillWithBlocks(world, start, 57, 21, 20, 59, 21, 22, Blocks.STONE_BRICKS.getDefaultState());
        structure.fillWithBlocks(world, start, 57, 21, 27, 57, 21, 27, Blocks.STONE_BRICKS.getDefaultState());
        structure.fillWithBlocks(world, start, 57, 21, 29, 58, 21, 30, Blocks.COBBLESTONE.getDefaultState());
        structure.fillWithBlocks(world, start, 57, 21, 31, 57, 21, 32, Blocks.STONE_BRICKS.getDefaultState());
        structure.fillWithBlocks(world, start, 57, 21, 40, 57, 21, 41, Blocks.STONE_BRICKS.getDefaultState());
        structure.fillWithBlocks(world, start, 57, 21, 42, 58, 21, 43, Blocks.COBBLESTONE.getDefaultState());
        structure.fillWithBlocks(world, start, 57, 21, 50, 59, 21, 52, Blocks.STONE_BRICKS.getDefaultState());
        structure.fillWithBlocks(world, start, 57, 22, 22, 57, 22, 22, Blocks.STONE_BRICK_STAIRS.getDefaultState().with(StairsBlock.FACING, Direction.EAST).with(StairsBlock.WATERLOGGED, false).with(StairsBlock.SHAPE, StairsShape.STRAIGHT).with(StairsBlock.HALF, Half.TOP));
        structure.fillWithBlocks(world, start, 57, 22, 28, 57, 22, 30, Blocks.STONE_BRICKS.getDefaultState());
        structure.fillWithBlocks(world, start, 57, 22, 31, 57, 24, 31, Blocks.COBBLESTONE_WALL.getDefaultState().with(WallBlock.WATERLOGGED, false).with(WallBlock.UP, true).with(WallBlock.WALL_HEIGHT_NORTH, WallHeight.LOW).with(WallBlock.WALL_HEIGHT_SOUTH, WallHeight.LOW).with(WallBlock.WALL_HEIGHT_EAST, WallHeight.LOW).with(WallBlock.WALL_HEIGHT_WEST, WallHeight.LOW));
        structure.fillWithBlocks(world, start, 57, 22, 32, 59, 24, 32, Blocks.STONE_BRICKS.getDefaultState());
        structure.fillWithBlocks(world, start, 57, 22, 40, 57, 22, 40, Blocks.STONE_BRICKS.getDefaultState());
        structure.fillWithBlocks(world, start, 57, 22, 41, 57, 24, 41, Blocks.COBBLESTONE_WALL.getDefaultState().with(WallBlock.WATERLOGGED, false).with(WallBlock.UP, true).with(WallBlock.WALL_HEIGHT_NORTH, WallHeight.LOW).with(WallBlock.WALL_HEIGHT_SOUTH, WallHeight.LOW).with(WallBlock.WALL_HEIGHT_EAST, WallHeight.LOW).with(WallBlock.WALL_HEIGHT_WEST, WallHeight.LOW));
        structure.fillWithBlocks(world, start, 57, 22, 42, 58, 22, 43, Blocks.STONE_BRICKS.getDefaultState());
        structure.fillWithBlocks(world, start, 57, 22, 44, 57, 26, 44, Blocks.STONE_BRICKS.getDefaultState());
        structure.fillWithBlocks(world, start, 57, 23, 20, 58, 23, 21, Blocks.STONE.getDefaultState());
        structure.fillWithBlocks(world, start, 57, 23, 29, 58, 23, 30, Blocks.STONE_BRICKS.getDefaultState());
        structure.fillWithBlocks(world, start, 57, 23, 40, 57, 23, 40, Blocks.STONE_BRICKS.getDefaultState());
        structure.fillWithBlocks(world, start, 57, 23, 42, 58, 23, 43, Blocks.STONE_BRICKS.getDefaultState());
        structure.fillWithBlocks(world, start, 57, 24, 23, 57, 24, 23, Blocks.STONE_BRICK_SLAB.getDefaultState().with(SlabBlock.TYPE, SlabType.TOP).with(SlabBlock.WATERLOGGED, false));
        structure.fillWithBlocks(world, start, 57, 24, 28, 57, 24, 30, Blocks.STONE_BRICKS.getDefaultState());
        structure.fillWithBlocks(world, start, 57, 24, 40, 57, 24, 40, Blocks.STONE_BRICKS.getDefaultState());
        structure.fillWithBlocks(world, start, 57, 24, 42, 58, 24, 43, Blocks.STONE_BRICKS.getDefaultState());
        structure.fillWithBlocks(world, start, 57, 25, 20, 58, 25, 21, Blocks.STONE.getDefaultState());
        structure.fillWithBlocks(world, start, 57, 25, 25, 57, 25, 25, Blocks.STONE_BRICKS.getDefaultState());
        structure.fillWithBlocks(world, start, 57, 25, 26, 57, 25, 26, Blocks.STONE_BRICK_SLAB.getDefaultState().with(SlabBlock.TYPE, SlabType.TOP).with(SlabBlock.WATERLOGGED, false));
        structure.fillWithBlocks(world, start, 57, 25, 27, 57, 25, 32, Blocks.STONE_BRICKS.getDefaultState());
        structure.fillWithBlocks(world, start, 57, 25, 40, 59, 25, 43, Blocks.STONE_BRICKS.getDefaultState());
        structure.fillWithBlocks(world, start, 57, 25, 45, 57, 25, 45, Blocks.STONE_BRICKS.getDefaultState());
        structure.fillWithBlocks(world, start, 57, 25, 47, 58, 25, 49, Blocks.STONE_BRICKS.getDefaultState());
        structure.fillWithBlocks(world, start, 57, 26, 20, 57, 26, 20, Blocks.STONE_BRICKS.getDefaultState());
        structure.fillWithBlocks(world, start, 57, 26, 25, 57, 26, 25, Blocks.SMOOTH_STONE.getDefaultState());
        structure.fillWithBlocks(world, start, 57, 26, 26, 57, 26, 26, Blocks.STONE_BRICK_STAIRS.getDefaultState().with(StairsBlock.FACING, Direction.NORTH).with(StairsBlock.WATERLOGGED, false).with(StairsBlock.SHAPE, StairsShape.INNER_RIGHT).with(StairsBlock.HALF, Half.BOTTOM));
        structure.fillWithBlocks(world, start, 57, 26, 27, 57, 26, 27, Blocks.STONE_BRICK_STAIRS.getDefaultState().with(StairsBlock.FACING, Direction.EAST).with(StairsBlock.WATERLOGGED, false).with(StairsBlock.SHAPE, StairsShape.OUTER_LEFT).with(StairsBlock.HALF, Half.BOTTOM));
        structure.fillWithBlocks(world, start, 57, 26, 28, 57, 26, 44, Blocks.STONE_BRICKS.getDefaultState());
        structure.fillWithBlocks(world, start, 57, 26, 47, 58, 26, 49, Blocks.SMOOTH_STONE.getDefaultState());
        structure.fillWithBlocks(world, start, 57, 26, 52, 57, 26, 53, Blocks.STONE_BRICKS.getDefaultState());
        structure.fillWithBlocks(world, start, 57, 27, 31, 57, 27, 32, Blocks.STONE_BRICK_SLAB.getDefaultState().with(SlabBlock.TYPE, SlabType.BOTTOM).with(SlabBlock.WATERLOGGED, false));
        structure.fillWithBlocks(world, start, 57, 27, 34, 57, 32, 34, Blocks.STONE_BRICKS.getDefaultState());
        structure.fillWithBlocks(world, start, 57, 27, 36, 57, 27, 36, Blocks.STONE_BRICK_SLAB.getDefaultState().with(SlabBlock.TYPE, SlabType.BOTTOM).with(SlabBlock.WATERLOGGED, false));
        structure.fillWithBlocks(world, start, 57, 27, 38, 57, 32, 38, Blocks.STONE_BRICKS.getDefaultState());
        structure.fillWithBlocks(world, start, 57, 27, 40, 57, 27, 41, Blocks.STONE_BRICK_SLAB.getDefaultState().with(SlabBlock.TYPE, SlabType.BOTTOM).with(SlabBlock.WATERLOGGED, false));
        structure.fillWithBlocks(world, start, 58, 2, 40, 58, 2, 40, Blocks.DIRT.getDefaultState());
        structure.fillWithBlocks(world, start, 58, 2, 47, 70, 2, 59, Blocks.DIRT.getDefaultState());
        structure.fillWithBlocks(world, start, 58, 2, 61, 65, 5, 61, Blocks.DIRT.getDefaultState());
        structure.fillWithBlocks(world, start, 58, 3, 71, 66, 3, 71, Blocks.DIRT.getDefaultState());
        structure.fillWithBlocks(world, start, 58, 4, 71, 66, 4, 71, Blocks.GRASS_BLOCK.getDefaultState().with(SnowyDirtBlock.SNOWY, false));
        structure.fillWithBlocks(world, start, 58, 6, 17, 72, 6, 17, Blocks.GRASS_BLOCK.getDefaultState().with(SnowyDirtBlock.SNOWY, false));
        structure.fillWithBlocks(world, start, 58, 6, 55, 62, 6, 62, Blocks.GRASS_BLOCK.getDefaultState().with(SnowyDirtBlock.SNOWY, false));
        structure.fillWithBlocks(world, start, 58, 7, 19, 59, 7, 19, Blocks.COBBLESTONE.getDefaultState());
        structure.fillWithBlocks(world, start, 58, 7, 53, 59, 7, 53, Blocks.COBBLESTONE.getDefaultState());
        structure.fillWithBlocks(world, start, 58, 8, 24, 59, 8, 25, Blocks.STONE_BRICKS.getDefaultState());
        structure.fillWithBlocks(world, start, 58, 8, 26, 58, 8, 26, Blocks.COBBLESTONE_STAIRS.getDefaultState().with(StairsBlock.FACING, Direction.SOUTH).with(StairsBlock.WATERLOGGED, false).with(StairsBlock.SHAPE, StairsShape.OUTER_RIGHT).with(StairsBlock.HALF, Half.BOTTOM));
        structure.fillWithBlocks(world, start, 58, 8, 27, 58, 8, 27, Blocks.COBBLESTONE_STAIRS.getDefaultState().with(StairsBlock.FACING, Direction.WEST).with(StairsBlock.WATERLOGGED, false).with(StairsBlock.SHAPE, StairsShape.INNER_LEFT).with(StairsBlock.HALF, Half.BOTTOM));
        structure.fillWithBlocks(world, start, 58, 8, 28, 58, 8, 33, Blocks.STONE.getDefaultState());
        structure.fillWithBlocks(world, start, 58, 8, 39, 60, 8, 41, Blocks.STONE.getDefaultState());
        structure.fillWithBlocks(world, start, 58, 8, 47, 59, 8, 48, Blocks.STONE_BRICKS.getDefaultState());
        structure.fillWithBlocks(world, start, 58, 9, 8, 58, 10, 8, Blocks.OAK_LEAVES.getDefaultState().with(LeavesBlock.PERSISTENT, false).with(LeavesBlock.DISTANCE, 3));
        structure.fillWithBlocks(world, start, 58, 9, 9, 58, 10, 9, Blocks.OAK_LEAVES.getDefaultState().with(LeavesBlock.PERSISTENT, false).with(LeavesBlock.DISTANCE, 2));
        structure.fillWithBlocks(world, start, 58, 9, 10, 58, 11, 10, Blocks.OAK_LEAVES.getDefaultState().with(LeavesBlock.PERSISTENT, false).with(LeavesBlock.DISTANCE, 1));
        structure.fillWithBlocks(world, start, 58, 9, 11, 58, 10, 11, Blocks.OAK_LEAVES.getDefaultState().with(LeavesBlock.PERSISTENT, false).with(LeavesBlock.DISTANCE, 2));
        structure.fillWithBlocks(world, start, 58, 9, 12, 58, 10, 12, Blocks.OAK_LEAVES.getDefaultState().with(LeavesBlock.PERSISTENT, false).with(LeavesBlock.DISTANCE, 3));
        structure.fillWithBlocks(world, start, 58, 9, 28, 58, 10, 28, Blocks.STONE_BRICKS.getDefaultState());
        structure.fillWithBlocks(world, start, 58, 9, 29, 58, 11, 32, Blocks.COBBLESTONE.getDefaultState());
        structure.fillWithBlocks(world, start, 58, 9, 33, 61, 10, 33, Blocks.STONE_BRICKS.getDefaultState());
        structure.fillWithBlocks(world, start, 58, 9, 39, 61, 10, 39, Blocks.STONE_BRICKS.getDefaultState());
        structure.fillWithBlocks(world, start, 58, 9, 40, 59, 9, 41, Blocks.COBBLESTONE.getDefaultState());
        structure.fillWithBlocks(world, start, 58, 9, 44, 58, 10, 44, Blocks.STONE_BRICKS.getDefaultState());
        structure.fillWithBlocks(world, start, 58, 10, 21, 58, 11, 21, Blocks.STONE.getDefaultState());
        structure.fillWithBlocks(world, start, 58, 10, 40, 59, 10, 41, Blocks.COBBLESTONE.getDefaultState());
        structure.fillWithBlocks(world, start, 58, 10, 51, 58, 11, 51, Blocks.STONE.getDefaultState());
        structure.fillWithBlocks(world, start, 58, 10, 57, 58, 11, 57, Blocks.OAK_LEAVES.getDefaultState().with(LeavesBlock.PERSISTENT, false).with(LeavesBlock.DISTANCE, 4));
        structure.fillWithBlocks(world, start, 58, 10, 58, 58, 11, 58, Blocks.OAK_LEAVES.getDefaultState().with(LeavesBlock.PERSISTENT, false).with(LeavesBlock.DISTANCE, 3));
        structure.fillWithBlocks(world, start, 58, 10, 59, 58, 11, 59, Blocks.OAK_LEAVES.getDefaultState().with(LeavesBlock.PERSISTENT, false).with(LeavesBlock.DISTANCE, 2));
        structure.fillWithBlocks(world, start, 58, 10, 60, 58, 11, 60, Blocks.OAK_LEAVES.getDefaultState().with(LeavesBlock.PERSISTENT, false).with(LeavesBlock.DISTANCE, 3));
        structure.fillWithBlocks(world, start, 58, 11, 33, 58, 20, 33, Blocks.STONE_BRICKS.getDefaultState());
        structure.fillWithBlocks(world, start, 58, 11, 39, 58, 20, 39, Blocks.STONE_BRICKS.getDefaultState());
        structure.fillWithBlocks(world, start, 58, 11, 40, 59, 11, 41, Blocks.COBBLESTONE.getDefaultState());
        structure.fillWithBlocks(world, start, 58, 11, 42, 58, 11, 43, Blocks.COBBLESTONE.getDefaultState());
        structure.fillWithBlocks(world, start, 58, 12, 10, 58, 12, 10, Blocks.OAK_LEAVES.getDefaultState().with(LeavesBlock.PERSISTENT, false).with(LeavesBlock.DISTANCE, 2));
        structure.fillWithBlocks(world, start, 58, 12, 29, 58, 18, 29, Blocks.STONE_BRICKS.getDefaultState());
        structure.fillWithBlocks(world, start, 58, 12, 30, 58, 12, 30, Blocks.COBBLESTONE.getDefaultState());
        structure.fillWithBlocks(world, start, 58, 12, 32, 59, 12, 32, Blocks.COBBLESTONE.getDefaultState());
        structure.fillWithBlocks(world, start, 58, 12, 40, 58, 12, 40, Blocks.COBBLESTONE.getDefaultState());
        structure.fillWithBlocks(world, start, 58, 12, 43, 58, 18, 43, Blocks.STONE_BRICKS.getDefaultState());
        structure.fillWithBlocks(world, start, 58, 13, 20, 58, 13, 20, Blocks.STONE_BRICKS.getDefaultState());
        structure.fillWithBlocks(world, start, 58, 13, 21, 58, 14, 21, Blocks.STONE.getDefaultState());
        structure.fillWithBlocks(world, start, 58, 13, 30, 58, 13, 30, Blocks.STONE.getDefaultState());
        structure.fillWithBlocks(world, start, 58, 13, 32, 59, 13, 32, Blocks.STONE.getDefaultState());
        structure.fillWithBlocks(world, start, 58, 13, 40, 58, 13, 40, Blocks.STONE.getDefaultState());
        structure.fillWithBlocks(world, start, 58, 13, 41, 58, 13, 41, Blocks.STONE_BRICKS.getDefaultState());
        structure.fillWithBlocks(world, start, 58, 13, 50, 58, 13, 50, Blocks.STONE_BRICKS.getDefaultState());
        structure.fillWithBlocks(world, start, 58, 13, 51, 58, 14, 51, Blocks.STONE.getDefaultState());
        structure.fillWithBlocks(world, start, 58, 14, 30, 58, 16, 30, Blocks.STONE_BRICKS.getDefaultState());
        structure.fillWithBlocks(world, start, 58, 14, 31, 58, 16, 31, Blocks.COBBLESTONE_WALL.getDefaultState().with(WallBlock.WATERLOGGED, false).with(WallBlock.UP, true).with(WallBlock.WALL_HEIGHT_NORTH, WallHeight.LOW).with(WallBlock.WALL_HEIGHT_SOUTH, WallHeight.LOW).with(WallBlock.WALL_HEIGHT_EAST, WallHeight.LOW).with(WallBlock.WALL_HEIGHT_WEST, WallHeight.LOW));
        structure.fillWithBlocks(world, start, 58, 14, 32, 58, 14, 33, Blocks.STONE_BRICKS.getDefaultState());
        structure.fillWithBlocks(world, start, 58, 14, 41, 58, 16, 41, Blocks.COBBLESTONE_WALL.getDefaultState().with(WallBlock.WATERLOGGED, false).with(WallBlock.UP, true).with(WallBlock.WALL_HEIGHT_NORTH, WallHeight.LOW).with(WallBlock.WALL_HEIGHT_SOUTH, WallHeight.LOW).with(WallBlock.WALL_HEIGHT_EAST, WallHeight.LOW).with(WallBlock.WALL_HEIGHT_WEST, WallHeight.LOW));
        structure.fillWithBlocks(world, start, 58, 14, 42, 58, 15, 43, Blocks.STONE_BRICKS.getDefaultState());
        structure.fillWithBlocks(world, start, 58, 15, 40, 58, 15, 41, Blocks.COBBLESTONE_WALL.getDefaultState().with(WallBlock.WATERLOGGED, false).with(WallBlock.UP, true).with(WallBlock.WALL_HEIGHT_NORTH, WallHeight.LOW).with(WallBlock.WALL_HEIGHT_SOUTH, WallHeight.LOW).with(WallBlock.WALL_HEIGHT_EAST, WallHeight.LOW).with(WallBlock.WALL_HEIGHT_WEST, WallHeight.LOW));
        structure.fillWithBlocks(world, start, 58, 16, 21, 58, 17, 21, Blocks.STONE.getDefaultState());
        structure.fillWithBlocks(world, start, 58, 16, 32, 58, 16, 33, Blocks.STONE_BRICKS.getDefaultState());
        structure.fillWithBlocks(world, start, 58, 16, 42, 58, 16, 43, Blocks.STONE_BRICKS.getDefaultState());
        structure.fillWithBlocks(world, start, 58, 16, 51, 58, 17, 51, Blocks.STONE.getDefaultState());
        structure.fillWithBlocks(world, start, 58, 17, 20, 58, 18, 20, Blocks.STONE_BRICKS.getDefaultState());
        structure.fillWithBlocks(world, start, 58, 17, 22, 58, 18, 22, Blocks.STONE_BRICKS.getDefaultState());
        structure.fillWithBlocks(world, start, 58, 17, 30, 58, 17, 30, Blocks.STONE.getDefaultState());
        structure.fillWithBlocks(world, start, 58, 17, 32, 58, 17, 32, Blocks.STONE.getDefaultState());
        structure.fillWithBlocks(world, start, 58, 17, 36, 58, 17, 36, Blocks.STONE_BRICK_SLAB.getDefaultState().with(SlabBlock.TYPE, SlabType.TOP).with(SlabBlock.WATERLOGGED, false));
        structure.fillWithBlocks(world, start, 58, 17, 40, 58, 17, 40, Blocks.STONE.getDefaultState());
        structure.fillWithBlocks(world, start, 58, 17, 41, 58, 17, 41, Blocks.STONE_BRICKS.getDefaultState());
        structure.fillWithBlocks(world, start, 58, 17, 50, 58, 18, 50, Blocks.STONE_BRICKS.getDefaultState());
        structure.fillWithBlocks(world, start, 58, 17, 52, 58, 18, 52, Blocks.STONE_BRICKS.getDefaultState());
        structure.fillWithBlocks(world, start, 58, 18, 30, 58, 21, 30, Blocks.COBBLESTONE.getDefaultState());
        structure.fillWithBlocks(world, start, 58, 18, 32, 59, 19, 32, Blocks.COBBLESTONE.getDefaultState());
        structure.fillWithBlocks(world, start, 58, 18, 40, 58, 18, 40, Blocks.COBBLESTONE.getDefaultState());
        structure.fillWithBlocks(world, start, 58, 18, 42, 58, 21, 42, Blocks.COBBLESTONE.getDefaultState());
        structure.fillWithBlocks(world, start, 58, 19, 21, 58, 20, 21, Blocks.STONE.getDefaultState());
        structure.fillWithBlocks(world, start, 58, 19, 29, 58, 21, 31, Blocks.COBBLESTONE.getDefaultState());
        structure.fillWithBlocks(world, start, 58, 19, 40, 59, 19, 41, Blocks.COBBLESTONE.getDefaultState());
        structure.fillWithBlocks(world, start, 58, 19, 43, 58, 21, 43, Blocks.COBBLESTONE.getDefaultState());
        structure.fillWithBlocks(world, start, 58, 19, 51, 58, 20, 51, Blocks.STONE.getDefaultState());
        structure.fillWithBlocks(world, start, 58, 20, 28, 58, 21, 28, Blocks.STONE_BRICKS.getDefaultState());
        structure.fillWithBlocks(world, start, 58, 20, 32, 58, 20, 32, Blocks.COBBLESTONE.getDefaultState());
        structure.fillWithBlocks(world, start, 58, 20, 40, 59, 20, 41, Blocks.COBBLESTONE.getDefaultState());
        structure.fillWithBlocks(world, start, 58, 20, 44, 58, 21, 44, Blocks.STONE_BRICKS.getDefaultState());
        structure.fillWithBlocks(world, start, 58, 21, 32, 58, 26, 32, Blocks.STONE_BRICKS.getDefaultState());
        structure.fillWithBlocks(world, start, 58, 21, 34, 58, 21, 38, Blocks.STONE_BRICKS.getDefaultState());
        structure.fillWithBlocks(world, start, 58, 21, 40, 58, 26, 40, Blocks.STONE_BRICKS.getDefaultState());
        structure.fillWithBlocks(world, start, 58, 21, 41, 58, 21, 43, Blocks.COBBLESTONE.getDefaultState());
        structure.fillWithBlocks(world, start, 58, 22, 20, 59, 22, 22, Blocks.STONE_BRICKS.getDefaultState());
        structure.fillWithBlocks(world, start, 58, 22, 23, 58, 22, 23, Blocks.STONE_BRICK_STAIRS.getDefaultState().with(StairsBlock.FACING, Direction.EAST).with(StairsBlock.WATERLOGGED, false).with(StairsBlock.SHAPE, StairsShape.STRAIGHT).with(StairsBlock.HALF, Half.TOP));
        structure.fillWithBlocks(world, start, 58, 22, 28, 58, 24, 28, Blocks.COBBLESTONE_WALL.getDefaultState().with(WallBlock.WATERLOGGED, false).with(WallBlock.UP, true).with(WallBlock.WALL_HEIGHT_NORTH, WallHeight.LOW).with(WallBlock.WALL_HEIGHT_SOUTH, WallHeight.LOW).with(WallBlock.WALL_HEIGHT_EAST, WallHeight.LOW).with(WallBlock.WALL_HEIGHT_WEST, WallHeight.LOW));
        structure.fillWithBlocks(world, start, 58, 22, 29, 58, 25, 32, Blocks.STONE_BRICKS.getDefaultState());
        structure.fillWithBlocks(world, start, 58, 22, 35, 60, 24, 35, Blocks.STONE_BRICKS.getDefaultState());
        structure.fillWithBlocks(world, start, 58, 22, 36, 58, 23, 36, Blocks.COBBLESTONE_WALL.getDefaultState().with(WallBlock.WATERLOGGED, false).with(WallBlock.UP, true).with(WallBlock.WALL_HEIGHT_NORTH, WallHeight.LOW).with(WallBlock.WALL_HEIGHT_SOUTH, WallHeight.LOW).with(WallBlock.WALL_HEIGHT_EAST, WallHeight.LOW).with(WallBlock.WALL_HEIGHT_WEST, WallHeight.LOW));
        structure.fillWithBlocks(world, start, 58, 22, 37, 58, 22, 37, Blocks.STONE_BRICKS.getDefaultState());
        structure.fillWithBlocks(world, start, 58, 22, 41, 58, 24, 43, Blocks.STONE_BRICKS.getDefaultState());
        structure.fillWithBlocks(world, start, 58, 22, 44, 58, 24, 44, Blocks.COBBLESTONE_WALL.getDefaultState().with(WallBlock.WATERLOGGED, false).with(WallBlock.UP, true).with(WallBlock.WALL_HEIGHT_NORTH, WallHeight.LOW).with(WallBlock.WALL_HEIGHT_SOUTH, WallHeight.LOW).with(WallBlock.WALL_HEIGHT_EAST, WallHeight.LOW).with(WallBlock.WALL_HEIGHT_WEST, WallHeight.LOW));
        structure.fillWithBlocks(world, start, 58, 22, 50, 59, 22, 52, Blocks.STONE_BRICKS.getDefaultState());
        structure.fillWithBlocks(world, start, 58, 23, 22, 58, 23, 22, Blocks.STONE.getDefaultState());
        structure.fillWithBlocks(world, start, 58, 23, 37, 58, 23, 37, Blocks.STONE_BRICKS.getDefaultState());
        structure.fillWithBlocks(world, start, 58, 23, 50, 59, 23, 51, Blocks.STONE.getDefaultState());
        structure.fillWithBlocks(world, start, 58, 24, 22, 58, 24, 22, Blocks.STONE.getDefaultState());
        structure.fillWithBlocks(world, start, 58, 24, 23, 58, 25, 23, Blocks.STONE_BRICKS.getDefaultState());
        structure.fillWithBlocks(world, start, 58, 24, 24, 58, 24, 24, Blocks.STONE_BRICK_SLAB.getDefaultState().with(SlabBlock.TYPE, SlabType.TOP).with(SlabBlock.WATERLOGGED, false));
        structure.fillWithBlocks(world, start, 58, 24, 33, 59, 24, 41, Blocks.STONE_BRICKS.getDefaultState());
        structure.fillWithBlocks(world, start, 58, 24, 49, 58, 25, 49, Blocks.STONE_BRICKS.getDefaultState());
        structure.fillWithBlocks(world, start, 58, 24, 50, 59, 24, 51, Blocks.STONE.getDefaultState());
        structure.fillWithBlocks(world, start, 58, 25, 22, 58, 25, 22, Blocks.STONE.getDefaultState());
        structure.fillWithBlocks(world, start, 58, 25, 24, 59, 25, 26, Blocks.STONE_BRICKS.getDefaultState());
        structure.fillWithBlocks(world, start, 58, 25, 27, 58, 25, 27, Blocks.STONE_BRICK_SLAB.getDefaultState().with(SlabBlock.TYPE, SlabType.TOP).with(SlabBlock.WATERLOGGED, false));
        structure.fillWithBlocks(world, start, 58, 25, 28, 58, 25, 32, Blocks.STONE_BRICKS.getDefaultState());
        structure.fillWithBlocks(world, start, 58, 25, 46, 59, 25, 48, Blocks.STONE_BRICKS.getDefaultState());
        structure.fillWithBlocks(world, start, 58, 25, 50, 59, 25, 51, Blocks.STONE.getDefaultState());
        structure.fillWithBlocks(world, start, 58, 26, 20, 59, 26, 21, Blocks.STONE_BRICKS.getDefaultState());
        structure.fillWithBlocks(world, start, 58, 26, 23, 58, 26, 26, Blocks.SMOOTH_STONE.getDefaultState());
        structure.fillWithBlocks(world, start, 58, 26, 27, 58, 26, 27, Blocks.STONE_BRICK_STAIRS.getDefaultState().with(StairsBlock.FACING, Direction.NORTH).with(StairsBlock.WATERLOGGED, false).with(StairsBlock.SHAPE, StairsShape.INNER_RIGHT).with(StairsBlock.HALF, Half.BOTTOM));
        structure.fillWithBlocks(world, start, 58, 26, 30, 58, 26, 43, Blocks.STONE_BRICKS.getDefaultState());
        structure.fillWithBlocks(world, start, 58, 26, 46, 59, 26, 48, Blocks.SMOOTH_STONE.getDefaultState());
        structure.fillWithBlocks(world, start, 58, 26, 51, 59, 26, 52, Blocks.STONE_BRICKS.getDefaultState());
        structure.fillWithBlocks(world, start, 58, 27, 35, 58, 27, 37, Blocks.STONE_BRICK_SLAB.getDefaultState().with(SlabBlock.TYPE, SlabType.BOTTOM).with(SlabBlock.WATERLOGGED, false));
        structure.fillWithBlocks(world, start, 58, 33, 20, 59, 33, 20, Blocks.STONE_BRICK_SLAB.getDefaultState().with(SlabBlock.TYPE, SlabType.BOTTOM).with(SlabBlock.WATERLOGGED, false));
        structure.fillWithBlocks(world, start, 58, 33, 21, 58, 33, 21, Blocks.STONE_BRICK_SLAB.getDefaultState().with(SlabBlock.TYPE, SlabType.DOUBLE).with(SlabBlock.WATERLOGGED, false));
        structure.fillWithBlocks(world, start, 58, 33, 22, 58, 33, 22, Blocks.STONE_BRICK_SLAB.getDefaultState().with(SlabBlock.TYPE, SlabType.BOTTOM).with(SlabBlock.WATERLOGGED, false));
        structure.fillWithBlocks(world, start, 58, 33, 51, 59, 33, 51, Blocks.STONE_BRICK_SLAB.getDefaultState().with(SlabBlock.TYPE, SlabType.DOUBLE).with(SlabBlock.WATERLOGGED, false));
        structure.fillWithBlocks(world, start, 58, 33, 52, 59, 33, 52, Blocks.STONE_BRICK_SLAB.getDefaultState().with(SlabBlock.TYPE, SlabType.BOTTOM).with(SlabBlock.WATERLOGGED, false));
        structure.fillWithBlocks(world, start, 59, 1, 16, 73, 5, 16, Blocks.DIRT.getDefaultState());
        structure.fillWithBlocks(world, start, 59, 2, 40, 60, 2, 41, Blocks.DIRT.getDefaultState());
        structure.fillWithBlocks(world, start, 59, 2, 42, 59, 2, 45, Blocks.STONE.getDefaultState());
        structure.fillWithBlocks(world, start, 59, 2, 46, 72, 2, 59, Blocks.DIRT.getDefaultState());
        structure.fillWithBlocks(world, start, 59, 2, 62, 59, 2, 67, Blocks.STONE.getDefaultState());
        structure.fillWithBlocks(world, start, 59, 5, 68, 60, 5, 69, Blocks.GRASS_BLOCK.getDefaultState().with(SnowyDirtBlock.SNOWY, false));
        structure.fillWithBlocks(world, start, 59, 6, 11, 62, 6, 14, Blocks.GRASS_BLOCK.getDefaultState().with(SnowyDirtBlock.SNOWY, false));
        structure.fillWithBlocks(world, start, 59, 6, 15, 61, 6, 17, Blocks.GRASS_BLOCK.getDefaultState().with(SnowyDirtBlock.SNOWY, false));
        structure.fillWithBlocks(world, start, 59, 7, 10, 59, 11, 10, Blocks.OAK_LOG.getDefaultState());
        structure.fillWithBlocks(world, start, 59, 8, 26, 59, 8, 26, Blocks.STONE_BRICKS.getDefaultState());
        structure.fillWithBlocks(world, start, 59, 8, 27, 59, 8, 27, Blocks.COBBLESTONE_STAIRS.getDefaultState().with(StairsBlock.FACING, Direction.SOUTH).with(StairsBlock.WATERLOGGED, false).with(StairsBlock.SHAPE, StairsShape.OUTER_RIGHT).with(StairsBlock.HALF, Half.BOTTOM));
        structure.fillWithBlocks(world, start, 59, 8, 29, 59, 8, 33, Blocks.STONE.getDefaultState());
        structure.fillWithBlocks(world, start, 59, 8, 46, 60, 8, 47, Blocks.STONE_BRICKS.getDefaultState());
        structure.fillWithBlocks(world, start, 59, 8, 62, 59, 9, 62, Blocks.OAK_LEAVES.getDefaultState().with(LeavesBlock.PERSISTENT, false).with(LeavesBlock.DISTANCE, 3));
        structure.fillWithBlocks(world, start, 59, 8, 63, 59, 9, 63, Blocks.OAK_LEAVES.getDefaultState().with(LeavesBlock.PERSISTENT, false).with(LeavesBlock.DISTANCE, 2));
        structure.fillWithBlocks(world, start, 59, 8, 64, 59, 9, 64, Blocks.OAK_LEAVES.getDefaultState().with(LeavesBlock.PERSISTENT, false).with(LeavesBlock.DISTANCE, 3));
        structure.fillWithBlocks(world, start, 59, 9, 8, 59, 10, 8, Blocks.OAK_LEAVES.getDefaultState().with(LeavesBlock.PERSISTENT, false).with(LeavesBlock.DISTANCE, 2));
        structure.fillWithBlocks(world, start, 59, 9, 9, 59, 11, 9, Blocks.OAK_LEAVES.getDefaultState().with(LeavesBlock.PERSISTENT, false).with(LeavesBlock.DISTANCE, 1));
        structure.fillWithBlocks(world, start, 59, 9, 11, 59, 11, 11, Blocks.OAK_LEAVES.getDefaultState().with(LeavesBlock.PERSISTENT, false).with(LeavesBlock.DISTANCE, 1));
        structure.fillWithBlocks(world, start, 59, 9, 12, 59, 10, 12, Blocks.OAK_LEAVES.getDefaultState().with(LeavesBlock.PERSISTENT, false).with(LeavesBlock.DISTANCE, 2));
        structure.fillWithBlocks(world, start, 59, 9, 29, 59, 9, 30, Blocks.STONE_BRICKS.getDefaultState());
        structure.fillWithBlocks(world, start, 59, 9, 31, 59, 10, 32, Blocks.COBBLESTONE.getDefaultState());
        structure.fillWithBlocks(world, start, 59, 9, 42, 59, 9, 43, Blocks.STONE_BRICKS.getDefaultState());
        structure.fillWithBlocks(world, start, 59, 10, 20, 59, 11, 20, Blocks.COBBLESTONE_WALL.getDefaultState().with(WallBlock.WATERLOGGED, false).with(WallBlock.UP, true).with(WallBlock.WALL_HEIGHT_NORTH, WallHeight.LOW).with(WallBlock.WALL_HEIGHT_SOUTH, WallHeight.LOW).with(WallBlock.WALL_HEIGHT_EAST, WallHeight.LOW).with(WallBlock.WALL_HEIGHT_WEST, WallHeight.LOW));
        structure.fillWithBlocks(world, start, 59, 10, 22, 59, 11, 22, Blocks.COBBLESTONE_WALL.getDefaultState().with(WallBlock.WATERLOGGED, false).with(WallBlock.UP, true).with(WallBlock.WALL_HEIGHT_NORTH, WallHeight.LOW).with(WallBlock.WALL_HEIGHT_SOUTH, WallHeight.LOW).with(WallBlock.WALL_HEIGHT_EAST, WallHeight.LOW).with(WallBlock.WALL_HEIGHT_WEST, WallHeight.LOW));
        structure.fillWithBlocks(world, start, 59, 10, 50, 59, 11, 50, Blocks.COBBLESTONE_WALL.getDefaultState().with(WallBlock.WATERLOGGED, false).with(WallBlock.UP, true).with(WallBlock.WALL_HEIGHT_NORTH, WallHeight.LOW).with(WallBlock.WALL_HEIGHT_SOUTH, WallHeight.LOW).with(WallBlock.WALL_HEIGHT_EAST, WallHeight.LOW).with(WallBlock.WALL_HEIGHT_WEST, WallHeight.LOW));
        structure.fillWithBlocks(world, start, 59, 10, 52, 59, 11, 52, Blocks.COBBLESTONE_WALL.getDefaultState().with(WallBlock.WATERLOGGED, false).with(WallBlock.UP, true).with(WallBlock.WALL_HEIGHT_NORTH, WallHeight.LOW).with(WallBlock.WALL_HEIGHT_SOUTH, WallHeight.LOW).with(WallBlock.WALL_HEIGHT_EAST, WallHeight.LOW).with(WallBlock.WALL_HEIGHT_WEST, WallHeight.LOW));
        structure.fillWithBlocks(world, start, 59, 11, 30, 59, 12, 30, Blocks.COBBLESTONE_WALL.getDefaultState().with(WallBlock.WATERLOGGED, false).with(WallBlock.UP, true).with(WallBlock.WALL_HEIGHT_NORTH, WallHeight.LOW).with(WallBlock.WALL_HEIGHT_SOUTH, WallHeight.LOW).with(WallBlock.WALL_HEIGHT_EAST, WallHeight.LOW).with(WallBlock.WALL_HEIGHT_WEST, WallHeight.LOW));
        structure.fillWithBlocks(world, start, 59, 11, 31, 59, 12, 32, Blocks.COBBLESTONE.getDefaultState());
        structure.fillWithBlocks(world, start, 59, 11, 33, 60, 11, 33, Blocks.COBBLESTONE_STAIRS.getDefaultState().with(StairsBlock.FACING, Direction.NORTH).with(StairsBlock.WATERLOGGED, false).with(StairsBlock.SHAPE, StairsShape.STRAIGHT).with(StairsBlock.HALF, Half.TOP));
        structure.fillWithBlocks(world, start, 59, 11, 39, 60, 11, 39, Blocks.COBBLESTONE_STAIRS.getDefaultState().with(StairsBlock.FACING, Direction.SOUTH).with(StairsBlock.WATERLOGGED, false).with(StairsBlock.SHAPE, StairsShape.STRAIGHT).with(StairsBlock.HALF, Half.TOP));
        structure.fillWithBlocks(world, start, 59, 11, 42, 59, 12, 42, Blocks.COBBLESTONE_WALL.getDefaultState().with(WallBlock.WATERLOGGED, false).with(WallBlock.UP, true).with(WallBlock.WALL_HEIGHT_NORTH, WallHeight.LOW).with(WallBlock.WALL_HEIGHT_SOUTH, WallHeight.LOW).with(WallBlock.WALL_HEIGHT_EAST, WallHeight.LOW).with(WallBlock.WALL_HEIGHT_WEST, WallHeight.LOW));
        structure.fillWithBlocks(world, start, 59, 12, 9, 59, 12, 9, Blocks.OAK_LEAVES.getDefaultState().with(LeavesBlock.PERSISTENT, false).with(LeavesBlock.DISTANCE, 2));
        structure.fillWithBlocks(world, start, 59, 12, 33, 60, 12, 33, Blocks.COBBLESTONE_STAIRS.getDefaultState().with(StairsBlock.FACING, Direction.NORTH).with(StairsBlock.WATERLOGGED, false).with(StairsBlock.SHAPE, StairsShape.STRAIGHT).with(StairsBlock.HALF, Half.BOTTOM));
        structure.fillWithBlocks(world, start, 59, 12, 39, 60, 12, 39, Blocks.COBBLESTONE_STAIRS.getDefaultState().with(StairsBlock.FACING, Direction.SOUTH).with(StairsBlock.WATERLOGGED, false).with(StairsBlock.SHAPE, StairsShape.STRAIGHT).with(StairsBlock.HALF, Half.BOTTOM));
        structure.fillWithBlocks(world, start, 59, 12, 40, 59, 12, 41, Blocks.COBBLESTONE.getDefaultState());
        structure.fillWithBlocks(world, start, 59, 13, 30, 59, 13, 30, Blocks.STONE_BRICKS.getDefaultState());
        structure.fillWithBlocks(world, start, 59, 13, 31, 59, 14, 32, Blocks.STONE.getDefaultState());
        structure.fillWithBlocks(world, start, 59, 13, 33, 61, 13, 33, Blocks.STONE_BRICKS.getDefaultState());
        structure.fillWithBlocks(world, start, 59, 13, 39, 59, 13, 39, Blocks.STONE_BRICKS.getDefaultState());
        structure.fillWithBlocks(world, start, 59, 13, 40, 59, 14, 41, Blocks.STONE.getDefaultState());
        structure.fillWithBlocks(world, start, 59, 14, 33, 60, 14, 33, Blocks.COBBLESTONE_STAIRS.getDefaultState().with(StairsBlock.FACING, Direction.NORTH).with(StairsBlock.WATERLOGGED, false).with(StairsBlock.SHAPE, StairsShape.STRAIGHT).with(StairsBlock.HALF, Half.BOTTOM));
        structure.fillWithBlocks(world, start, 59, 14, 39, 60, 14, 39, Blocks.COBBLESTONE_STAIRS.getDefaultState().with(StairsBlock.FACING, Direction.SOUTH).with(StairsBlock.WATERLOGGED, false).with(StairsBlock.SHAPE, StairsShape.STRAIGHT).with(StairsBlock.HALF, Half.BOTTOM));
        structure.fillWithBlocks(world, start, 59, 15, 31, 59, 16, 32, Blocks.STONE.getDefaultState());
        structure.fillWithBlocks(world, start, 59, 15, 33, 60, 15, 33, Blocks.COBBLESTONE_WALL.getDefaultState().with(WallBlock.WATERLOGGED, false).with(WallBlock.UP, true).with(WallBlock.WALL_HEIGHT_NORTH, WallHeight.LOW).with(WallBlock.WALL_HEIGHT_SOUTH, WallHeight.LOW).with(WallBlock.WALL_HEIGHT_EAST, WallHeight.LOW).with(WallBlock.WALL_HEIGHT_WEST, WallHeight.LOW));
        structure.fillWithBlocks(world, start, 59, 15, 39, 60, 15, 39, Blocks.COBBLESTONE_WALL.getDefaultState().with(WallBlock.WATERLOGGED, false).with(WallBlock.UP, true).with(WallBlock.WALL_HEIGHT_NORTH, WallHeight.LOW).with(WallBlock.WALL_HEIGHT_SOUTH, WallHeight.LOW).with(WallBlock.WALL_HEIGHT_EAST, WallHeight.LOW).with(WallBlock.WALL_HEIGHT_WEST, WallHeight.LOW));
        structure.fillWithBlocks(world, start, 59, 15, 40, 59, 16, 41, Blocks.STONE.getDefaultState());
        structure.fillWithBlocks(world, start, 59, 16, 33, 60, 16, 33, Blocks.COBBLESTONE_STAIRS.getDefaultState().with(StairsBlock.FACING, Direction.NORTH).with(StairsBlock.WATERLOGGED, false).with(StairsBlock.SHAPE, StairsShape.STRAIGHT).with(StairsBlock.HALF, Half.TOP));
        structure.fillWithBlocks(world, start, 59, 16, 39, 60, 16, 39, Blocks.COBBLESTONE_STAIRS.getDefaultState().with(StairsBlock.FACING, Direction.SOUTH).with(StairsBlock.WATERLOGGED, false).with(StairsBlock.SHAPE, StairsShape.STRAIGHT).with(StairsBlock.HALF, Half.TOP));
        structure.fillWithBlocks(world, start, 59, 17, 21, 59, 18, 21, Blocks.STONE_BRICKS.getDefaultState());
        structure.fillWithBlocks(world, start, 59, 17, 30, 59, 17, 30, Blocks.STONE_BRICKS.getDefaultState());
        structure.fillWithBlocks(world, start, 59, 17, 31, 59, 17, 33, Blocks.STONE.getDefaultState());
        structure.fillWithBlocks(world, start, 59, 17, 34, 60, 17, 34, Blocks.STONE_BRICK_SLAB.getDefaultState().with(SlabBlock.TYPE, SlabType.DOUBLE).with(SlabBlock.WATERLOGGED, false));
        structure.fillWithBlocks(world, start, 59, 17, 35, 60, 17, 35, Blocks.STONE_BRICK_SLAB.getDefaultState().with(SlabBlock.TYPE, SlabType.TOP).with(SlabBlock.WATERLOGGED, false));
        structure.fillWithBlocks(world, start, 59, 17, 37, 60, 17, 37, Blocks.STONE_BRICK_SLAB.getDefaultState().with(SlabBlock.TYPE, SlabType.TOP).with(SlabBlock.WATERLOGGED, false));
        structure.fillWithBlocks(world, start, 59, 17, 38, 60, 17, 38, Blocks.STONE_BRICK_SLAB.getDefaultState().with(SlabBlock.TYPE, SlabType.DOUBLE).with(SlabBlock.WATERLOGGED, false));
        structure.fillWithBlocks(world, start, 59, 17, 39, 59, 17, 41, Blocks.STONE.getDefaultState());
        structure.fillWithBlocks(world, start, 59, 17, 51, 59, 18, 51, Blocks.STONE_BRICKS.getDefaultState());
        structure.fillWithBlocks(world, start, 59, 18, 30, 59, 19, 30, Blocks.COBBLESTONE_WALL.getDefaultState().with(WallBlock.WATERLOGGED, false).with(WallBlock.UP, true).with(WallBlock.WALL_HEIGHT_NORTH, WallHeight.LOW).with(WallBlock.WALL_HEIGHT_SOUTH, WallHeight.LOW).with(WallBlock.WALL_HEIGHT_EAST, WallHeight.LOW).with(WallBlock.WALL_HEIGHT_WEST, WallHeight.LOW));
        structure.fillWithBlocks(world, start, 59, 18, 31, 59, 19, 32, Blocks.COBBLESTONE.getDefaultState());
        structure.fillWithBlocks(world, start, 59, 18, 33, 60, 18, 35, Blocks.STONE.getDefaultState());
        structure.fillWithBlocks(world, start, 59, 18, 36, 60, 18, 36, Blocks.STONE_BRICK_SLAB.getDefaultState().with(SlabBlock.TYPE, SlabType.DOUBLE).with(SlabBlock.WATERLOGGED, false));
        structure.fillWithBlocks(world, start, 59, 18, 37, 60, 18, 39, Blocks.STONE.getDefaultState());
        structure.fillWithBlocks(world, start, 59, 18, 40, 59, 19, 41, Blocks.COBBLESTONE.getDefaultState());
        structure.fillWithBlocks(world, start, 59, 18, 42, 59, 19, 42, Blocks.COBBLESTONE_WALL.getDefaultState().with(WallBlock.WATERLOGGED, false).with(WallBlock.UP, true).with(WallBlock.WALL_HEIGHT_NORTH, WallHeight.LOW).with(WallBlock.WALL_HEIGHT_SOUTH, WallHeight.LOW).with(WallBlock.WALL_HEIGHT_EAST, WallHeight.LOW).with(WallBlock.WALL_HEIGHT_WEST, WallHeight.LOW));
        structure.fillWithBlocks(world, start, 59, 19, 20, 59, 20, 20, Blocks.COBBLESTONE_WALL.getDefaultState().with(WallBlock.WATERLOGGED, false).with(WallBlock.UP, true).with(WallBlock.WALL_HEIGHT_NORTH, WallHeight.LOW).with(WallBlock.WALL_HEIGHT_SOUTH, WallHeight.LOW).with(WallBlock.WALL_HEIGHT_EAST, WallHeight.LOW).with(WallBlock.WALL_HEIGHT_WEST, WallHeight.LOW));
        structure.fillWithBlocks(world, start, 59, 19, 22, 59, 20, 22, Blocks.COBBLESTONE_WALL.getDefaultState().with(WallBlock.WATERLOGGED, false).with(WallBlock.UP, true).with(WallBlock.WALL_HEIGHT_NORTH, WallHeight.LOW).with(WallBlock.WALL_HEIGHT_SOUTH, WallHeight.LOW).with(WallBlock.WALL_HEIGHT_EAST, WallHeight.LOW).with(WallBlock.WALL_HEIGHT_WEST, WallHeight.LOW));
        structure.fillWithBlocks(world, start, 59, 19, 33, 60, 19, 33, Blocks.STONE.getDefaultState());
        structure.fillWithBlocks(world, start, 59, 19, 34, 60, 19, 34, Blocks.COBBLESTONE_STAIRS.getDefaultState().with(StairsBlock.FACING, Direction.NORTH).with(StairsBlock.WATERLOGGED, false).with(StairsBlock.SHAPE, StairsShape.STRAIGHT).with(StairsBlock.HALF, Half.BOTTOM));
        structure.fillWithBlocks(world, start, 59, 19, 35, 60, 19, 35, Blocks.STONE_BRICK_STAIRS.getDefaultState().with(StairsBlock.FACING, Direction.SOUTH).with(StairsBlock.WATERLOGGED, false).with(StairsBlock.SHAPE, StairsShape.STRAIGHT).with(StairsBlock.HALF, Half.BOTTOM));
        structure.fillWithBlocks(world, start, 59, 19, 37, 60, 19, 37, Blocks.STONE_BRICK_STAIRS.getDefaultState().with(StairsBlock.FACING, Direction.NORTH).with(StairsBlock.WATERLOGGED, false).with(StairsBlock.SHAPE, StairsShape.STRAIGHT).with(StairsBlock.HALF, Half.BOTTOM));
        structure.fillWithBlocks(world, start, 59, 19, 38, 60, 19, 38, Blocks.COBBLESTONE_STAIRS.getDefaultState().with(StairsBlock.FACING, Direction.SOUTH).with(StairsBlock.WATERLOGGED, false).with(StairsBlock.SHAPE, StairsShape.STRAIGHT).with(StairsBlock.HALF, Half.BOTTOM));
        structure.fillWithBlocks(world, start, 59, 19, 39, 60, 19, 39, Blocks.STONE.getDefaultState());
        structure.fillWithBlocks(world, start, 59, 19, 50, 59, 20, 50, Blocks.COBBLESTONE_WALL.getDefaultState().with(WallBlock.WATERLOGGED, false).with(WallBlock.UP, true).with(WallBlock.WALL_HEIGHT_NORTH, WallHeight.LOW).with(WallBlock.WALL_HEIGHT_SOUTH, WallHeight.LOW).with(WallBlock.WALL_HEIGHT_EAST, WallHeight.LOW).with(WallBlock.WALL_HEIGHT_WEST, WallHeight.LOW));
        structure.fillWithBlocks(world, start, 59, 19, 52, 59, 20, 52, Blocks.COBBLESTONE_WALL.getDefaultState().with(WallBlock.WATERLOGGED, false).with(WallBlock.UP, true).with(WallBlock.WALL_HEIGHT_NORTH, WallHeight.LOW).with(WallBlock.WALL_HEIGHT_SOUTH, WallHeight.LOW).with(WallBlock.WALL_HEIGHT_EAST, WallHeight.LOW).with(WallBlock.WALL_HEIGHT_WEST, WallHeight.LOW));
        structure.fillWithBlocks(world, start, 59, 20, 30, 59, 21, 30, Blocks.STONE_BRICKS.getDefaultState());
        structure.fillWithBlocks(world, start, 59, 20, 31, 59, 21, 32, Blocks.COBBLESTONE.getDefaultState());
        structure.fillWithBlocks(world, start, 59, 20, 33, 60, 20, 34, Blocks.COBBLESTONE.getDefaultState());
        structure.fillWithBlocks(world, start, 59, 20, 35, 60, 20, 35, Blocks.COBBLESTONE_STAIRS.getDefaultState().with(StairsBlock.FACING, Direction.NORTH).with(StairsBlock.WATERLOGGED, false).with(StairsBlock.SHAPE, StairsShape.STRAIGHT).with(StairsBlock.HALF, Half.TOP));
        structure.fillWithBlocks(world, start, 59, 20, 36, 60, 21, 36, Blocks.COBBLESTONE.getDefaultState());
        structure.fillWithBlocks(world, start, 59, 20, 37, 60, 20, 37, Blocks.COBBLESTONE_STAIRS.getDefaultState().with(StairsBlock.FACING, Direction.SOUTH).with(StairsBlock.WATERLOGGED, false).with(StairsBlock.SHAPE, StairsShape.STRAIGHT).with(StairsBlock.HALF, Half.TOP));
        structure.fillWithBlocks(world, start, 59, 20, 38, 60, 20, 39, Blocks.COBBLESTONE.getDefaultState());
        structure.fillWithBlocks(world, start, 59, 20, 42, 59, 21, 42, Blocks.STONE_BRICKS.getDefaultState());
        structure.fillWithBlocks(world, start, 59, 21, 29, 59, 21, 30, Blocks.STONE_BRICKS.getDefaultState());
        structure.fillWithBlocks(world, start, 59, 21, 33, 60, 21, 33, Blocks.STONE_BRICKS.getDefaultState());
        structure.fillWithBlocks(world, start, 59, 21, 34, 60, 21, 38, Blocks.COBBLESTONE.getDefaultState());
        structure.fillWithBlocks(world, start, 59, 21, 40, 59, 21, 41, Blocks.COBBLESTONE.getDefaultState());
        structure.fillWithBlocks(world, start, 59, 22, 23, 59, 22, 23, Blocks.STONE_BRICKS.getDefaultState());
        structure.fillWithBlocks(world, start, 59, 22, 31, 59, 26, 35, Blocks.STONE_BRICKS.getDefaultState());
        structure.fillWithBlocks(world, start, 59, 22, 36, 60, 23, 36, Blocks.COBBLESTONE.getDefaultState());
        structure.fillWithBlocks(world, start, 59, 22, 37, 60, 22, 38, Blocks.STONE_BRICKS.getDefaultState());
        structure.fillWithBlocks(world, start, 59, 22, 39, 59, 24, 41, Blocks.STONE_BRICKS.getDefaultState());
        structure.fillWithBlocks(world, start, 59, 22, 49, 60, 22, 51, Blocks.STONE_BRICKS.getDefaultState());
        structure.fillWithBlocks(world, start, 59, 23, 22, 60, 23, 23, Blocks.STONE.getDefaultState());
        structure.fillWithBlocks(world, start, 59, 23, 24, 59, 23, 24, Blocks.STONE_BRICK_SLAB.getDefaultState().with(SlabBlock.TYPE, SlabType.BOTTOM).with(SlabBlock.WATERLOGGED, false));
        structure.fillWithBlocks(world, start, 59, 23, 37, 60, 23, 39, Blocks.STONE_BRICKS.getDefaultState());
        structure.fillWithBlocks(world, start, 59, 23, 49, 60, 23, 51, Blocks.STONE.getDefaultState());
        structure.fillWithBlocks(world, start, 59, 24, 22, 60, 24, 23, Blocks.STONE.getDefaultState());
        structure.fillWithBlocks(world, start, 59, 24, 24, 59, 25, 24, Blocks.STONE_BRICKS.getDefaultState());
        structure.fillWithBlocks(world, start, 59, 24, 25, 59, 24, 25, Blocks.STONE_BRICK_SLAB.getDefaultState().with(SlabBlock.TYPE, SlabType.TOP).with(SlabBlock.WATERLOGGED, false));
        structure.fillWithBlocks(world, start, 59, 24, 48, 59, 25, 48, Blocks.STONE_BRICKS.getDefaultState());
        structure.fillWithBlocks(world, start, 59, 24, 49, 60, 24, 50, Blocks.STONE.getDefaultState());
        structure.fillWithBlocks(world, start, 59, 25, 22, 60, 25, 23, Blocks.STONE.getDefaultState());
        structure.fillWithBlocks(world, start, 59, 25, 27, 59, 25, 27, Blocks.STONE_BRICKS.getDefaultState());
        structure.fillWithBlocks(world, start, 59, 25, 29, 59, 25, 43, Blocks.STONE_BRICKS.getDefaultState());
        structure.fillWithBlocks(world, start, 59, 25, 45, 60, 25, 47, Blocks.STONE_BRICKS.getDefaultState());
        structure.fillWithBlocks(world, start, 59, 25, 49, 60, 25, 51, Blocks.STONE.getDefaultState());
        structure.fillWithBlocks(world, start, 59, 26, 22, 61, 26, 22, Blocks.STONE_BRICKS.getDefaultState());
        structure.fillWithBlocks(world, start, 59, 26, 23, 59, 26, 23, Blocks.STONE_BRICK_STAIRS.getDefaultState().with(StairsBlock.FACING, Direction.WEST).with(StairsBlock.WATERLOGGED, false).with(StairsBlock.SHAPE, StairsShape.INNER_LEFT).with(StairsBlock.HALF, Half.BOTTOM));
        structure.fillWithBlocks(world, start, 59, 26, 25, 60, 26, 27, Blocks.SMOOTH_STONE.getDefaultState());
        structure.fillWithBlocks(world, start, 59, 26, 36, 60, 26, 39, Blocks.STONE_BRICKS.getDefaultState());
        structure.fillWithBlocks(world, start, 59, 26, 40, 59, 26, 41, Blocks.STONE_BRICKS.getDefaultState());
        structure.fillWithBlocks(world, start, 59, 26, 45, 60, 26, 47, Blocks.SMOOTH_STONE.getDefaultState());
        structure.fillWithBlocks(world, start, 59, 26, 50, 60, 26, 51, Blocks.STONE_BRICKS.getDefaultState());
        structure.fillWithBlocks(world, start, 59, 27, 21, 59, 32, 21, Blocks.STONE_BRICKS.getDefaultState());
        structure.fillWithBlocks(world, start, 59, 27, 51, 59, 32, 51, Blocks.STONE_BRICKS.getDefaultState());
        structure.fillWithBlocks(world, start, 59, 33, 21, 59, 33, 22, Blocks.STONE_BRICK_SLAB.getDefaultState().with(SlabBlock.TYPE, SlabType.DOUBLE).with(SlabBlock.WATERLOGGED, false));
        structure.fillWithBlocks(world, start, 59, 33, 23, 59, 33, 23, Blocks.STONE_BRICK_SLAB.getDefaultState().with(SlabBlock.TYPE, SlabType.BOTTOM).with(SlabBlock.WATERLOGGED, false));
        structure.fillWithBlocks(world, start, 59, 33, 50, 59, 33, 51, Blocks.STONE_BRICK_SLAB.getDefaultState().with(SlabBlock.TYPE, SlabType.DOUBLE).with(SlabBlock.WATERLOGGED, false));
        structure.fillWithBlocks(world, start, 60, 2, 42, 77, 2, 59, Blocks.DIRT.getDefaultState());
        structure.fillWithBlocks(world, start, 60, 2, 62, 64, 5, 62, Blocks.DIRT.getDefaultState());
        structure.fillWithBlocks(world, start, 60, 2, 63, 64, 2, 67, Blocks.STONE.getDefaultState());
        structure.fillWithBlocks(world, start, 60, 2, 68, 64, 2, 72, Blocks.DIRT.getDefaultState());
        structure.fillWithBlocks(world, start, 60, 6, 10, 64, 6, 14, Blocks.GRASS_BLOCK.getDefaultState().with(SnowyDirtBlock.SNOWY, false));
        structure.fillWithBlocks(world, start, 60, 6, 18, 60, 6, 18, Blocks.GRASS_BLOCK.getDefaultState().with(SnowyDirtBlock.SNOWY, false));
        structure.fillWithBlocks(world, start, 60, 6, 54, 62, 6, 62, Blocks.GRASS_BLOCK.getDefaultState().with(SnowyDirtBlock.SNOWY, false));
        structure.fillWithBlocks(world, start, 60, 7, 20, 60, 7, 20, Blocks.COBBLESTONE.getDefaultState());
        structure.fillWithBlocks(world, start, 60, 8, 23, 60, 8, 24, Blocks.COBBLESTONE.getDefaultState());
        structure.fillWithBlocks(world, start, 60, 8, 25, 60, 8, 27, Blocks.STONE_BRICKS.getDefaultState());
        structure.fillWithBlocks(world, start, 60, 8, 31, 60, 8, 33, Blocks.STONE.getDefaultState());
        structure.fillWithBlocks(world, start, 60, 8, 45, 60, 8, 47, Blocks.STONE_BRICKS.getDefaultState());
        structure.fillWithBlocks(world, start, 60, 8, 48, 60, 8, 49, Blocks.COBBLESTONE.getDefaultState());
        structure.fillWithBlocks(world, start, 60, 8, 61, 60, 9, 61, Blocks.OAK_LEAVES.getDefaultState().with(LeavesBlock.PERSISTENT, false).with(LeavesBlock.DISTANCE, 3));
        structure.fillWithBlocks(world, start, 60, 8, 62, 60, 10, 62, Blocks.OAK_LEAVES.getDefaultState().with(LeavesBlock.PERSISTENT, false).with(LeavesBlock.DISTANCE, 2));
        structure.fillWithBlocks(world, start, 60, 8, 63, 60, 10, 63, Blocks.OAK_LEAVES.getDefaultState().with(LeavesBlock.PERSISTENT, false).with(LeavesBlock.DISTANCE, 1));
        structure.fillWithBlocks(world, start, 60, 8, 64, 60, 10, 64, Blocks.OAK_LEAVES.getDefaultState().with(LeavesBlock.PERSISTENT, false).with(LeavesBlock.DISTANCE, 2));
        structure.fillWithBlocks(world, start, 60, 8, 65, 60, 9, 65, Blocks.OAK_LEAVES.getDefaultState().with(LeavesBlock.PERSISTENT, false).with(LeavesBlock.DISTANCE, 3));
        structure.fillWithBlocks(world, start, 60, 9, 8, 60, 10, 8, Blocks.OAK_LEAVES.getDefaultState().with(LeavesBlock.PERSISTENT, false).with(LeavesBlock.DISTANCE, 3));
        structure.fillWithBlocks(world, start, 60, 9, 9, 60, 11, 9, Blocks.OAK_LEAVES.getDefaultState().with(LeavesBlock.PERSISTENT, false).with(LeavesBlock.DISTANCE, 2));
        structure.fillWithBlocks(world, start, 60, 9, 10, 60, 11, 10, Blocks.OAK_LEAVES.getDefaultState().with(LeavesBlock.PERSISTENT, false).with(LeavesBlock.DISTANCE, 1));
        structure.fillWithBlocks(world, start, 60, 9, 11, 60, 10, 11, Blocks.OAK_LEAVES.getDefaultState().with(LeavesBlock.PERSISTENT, false).with(LeavesBlock.DISTANCE, 2));
        structure.fillWithBlocks(world, start, 60, 9, 12, 60, 10, 12, Blocks.OAK_LEAVES.getDefaultState().with(LeavesBlock.PERSISTENT, false).with(LeavesBlock.DISTANCE, 3));
        structure.fillWithBlocks(world, start, 60, 9, 14, 60, 10, 14, Blocks.OAK_LEAVES.getDefaultState().with(LeavesBlock.PERSISTENT, false).with(LeavesBlock.DISTANCE, 3));
        structure.fillWithBlocks(world, start, 60, 9, 15, 60, 10, 15, Blocks.OAK_LEAVES.getDefaultState().with(LeavesBlock.PERSISTENT, false).with(LeavesBlock.DISTANCE, 2));
        structure.fillWithBlocks(world, start, 60, 9, 16, 60, 10, 16, Blocks.OAK_LEAVES.getDefaultState().with(LeavesBlock.PERSISTENT, false).with(LeavesBlock.DISTANCE, 3));
        structure.fillWithBlocks(world, start, 60, 9, 31, 60, 9, 33, Blocks.STONE_BRICKS.getDefaultState());
        structure.fillWithBlocks(world, start, 60, 9, 40, 60, 9, 41, Blocks.STONE_BRICKS.getDefaultState());
        structure.fillWithBlocks(world, start, 60, 10, 32, 60, 10, 33, Blocks.STONE_BRICKS.getDefaultState());
        structure.fillWithBlocks(world, start, 60, 11, 32, 60, 12, 32, Blocks.COBBLESTONE_WALL.getDefaultState().with(WallBlock.WATERLOGGED, false).with(WallBlock.UP, true).with(WallBlock.WALL_HEIGHT_NORTH, WallHeight.LOW).with(WallBlock.WALL_HEIGHT_SOUTH, WallHeight.LOW).with(WallBlock.WALL_HEIGHT_EAST, WallHeight.LOW).with(WallBlock.WALL_HEIGHT_WEST, WallHeight.LOW));
        structure.fillWithBlocks(world, start, 60, 11, 40, 60, 12, 40, Blocks.COBBLESTONE_WALL.getDefaultState().with(WallBlock.WATERLOGGED, false).with(WallBlock.UP, true).with(WallBlock.WALL_HEIGHT_NORTH, WallHeight.LOW).with(WallBlock.WALL_HEIGHT_SOUTH, WallHeight.LOW).with(WallBlock.WALL_HEIGHT_EAST, WallHeight.LOW).with(WallBlock.WALL_HEIGHT_WEST, WallHeight.LOW));
        structure.fillWithBlocks(world, start, 60, 11, 63, 60, 11, 63, Blocks.OAK_LEAVES.getDefaultState().with(LeavesBlock.PERSISTENT, false).with(LeavesBlock.DISTANCE, 2));
        structure.fillWithBlocks(world, start, 60, 13, 31, 60, 13, 33, Blocks.STONE_BRICKS.getDefaultState());
        structure.fillWithBlocks(world, start, 60, 13, 39, 60, 13, 41, Blocks.STONE_BRICKS.getDefaultState());
        structure.fillWithBlocks(world, start, 60, 15, 32, 60, 15, 32, Blocks.STONE_BRICKS.getDefaultState());
        structure.fillWithBlocks(world, start, 60, 17, 31, 60, 17, 32, Blocks.STONE_BRICKS.getDefaultState());
        structure.fillWithBlocks(world, start, 60, 17, 33, 60, 19, 33, Blocks.STONE.getDefaultState());
        structure.fillWithBlocks(world, start, 60, 17, 39, 60, 19, 39, Blocks.STONE.getDefaultState());
        structure.fillWithBlocks(world, start, 60, 17, 40, 60, 17, 41, Blocks.STONE_BRICKS.getDefaultState());
        structure.fillWithBlocks(world, start, 60, 18, 32, 60, 19, 32, Blocks.COBBLESTONE_WALL.getDefaultState().with(WallBlock.WATERLOGGED, false).with(WallBlock.UP, true).with(WallBlock.WALL_HEIGHT_NORTH, WallHeight.LOW).with(WallBlock.WALL_HEIGHT_SOUTH, WallHeight.LOW).with(WallBlock.WALL_HEIGHT_EAST, WallHeight.LOW).with(WallBlock.WALL_HEIGHT_WEST, WallHeight.LOW));
        structure.fillWithBlocks(world, start, 60, 18, 40, 60, 19, 40, Blocks.COBBLESTONE_WALL.getDefaultState().with(WallBlock.WATERLOGGED, false).with(WallBlock.UP, true).with(WallBlock.WALL_HEIGHT_NORTH, WallHeight.LOW).with(WallBlock.WALL_HEIGHT_SOUTH, WallHeight.LOW).with(WallBlock.WALL_HEIGHT_EAST, WallHeight.LOW).with(WallBlock.WALL_HEIGHT_WEST, WallHeight.LOW));
        structure.fillWithBlocks(world, start, 60, 20, 32, 60, 21, 32, Blocks.STONE_BRICKS.getDefaultState());
        structure.fillWithBlocks(world, start, 60, 20, 40, 60, 21, 40, Blocks.STONE_BRICKS.getDefaultState());
        structure.fillWithBlocks(world, start, 60, 21, 31, 60, 21, 33, Blocks.STONE_BRICKS.getDefaultState());
        structure.fillWithBlocks(world, start, 60, 21, 39, 60, 21, 41, Blocks.STONE_BRICKS.getDefaultState());
        structure.fillWithBlocks(world, start, 60, 22, 20, 60, 22, 20, Blocks.STONE_BRICK_STAIRS.getDefaultState().with(StairsBlock.FACING, Direction.WEST).with(StairsBlock.WATERLOGGED, false).with(StairsBlock.SHAPE, StairsShape.STRAIGHT).with(StairsBlock.HALF, Half.TOP));
        structure.fillWithBlocks(world, start, 60, 22, 21, 60, 22, 24, Blocks.STONE_BRICKS.getDefaultState());
        structure.fillWithBlocks(world, start, 60, 22, 25, 60, 22, 25, Blocks.STONE_BRICK_STAIRS.getDefaultState().with(StairsBlock.FACING, Direction.NORTH).with(StairsBlock.WATERLOGGED, false).with(StairsBlock.SHAPE, StairsShape.STRAIGHT).with(StairsBlock.HALF, Half.TOP));
        structure.fillWithBlocks(world, start, 60, 22, 34, 60, 22, 35, Blocks.STONE_BRICKS.getDefaultState());
        structure.fillWithBlocks(world, start, 60, 22, 48, 61, 22, 50, Blocks.STONE_BRICKS.getDefaultState());
        structure.fillWithBlocks(world, start, 60, 23, 21, 60, 23, 24, Blocks.STONE.getDefaultState());
        structure.fillWithBlocks(world, start, 60, 23, 33, 60, 23, 35, Blocks.STONE_BRICKS.getDefaultState());
        structure.fillWithBlocks(world, start, 60, 23, 48, 61, 23, 49, Blocks.STONE.getDefaultState());
        structure.fillWithBlocks(world, start, 60, 24, 24, 60, 24, 24, Blocks.STONE.getDefaultState());
        structure.fillWithBlocks(world, start, 60, 24, 25, 60, 25, 25, Blocks.STONE_BRICKS.getDefaultState());
        structure.fillWithBlocks(world, start, 60, 24, 26, 60, 24, 26, Blocks.STONE_BRICK_SLAB.getDefaultState().with(SlabBlock.TYPE, SlabType.TOP).with(SlabBlock.WATERLOGGED, false));
        structure.fillWithBlocks(world, start, 60, 24, 34, 60, 26, 38, Blocks.STONE_BRICKS.getDefaultState());
        structure.fillWithBlocks(world, start, 60, 24, 47, 60, 25, 47, Blocks.STONE_BRICKS.getDefaultState());
        structure.fillWithBlocks(world, start, 60, 24, 48, 61, 24, 49, Blocks.STONE.getDefaultState());
        structure.fillWithBlocks(world, start, 60, 25, 21, 60, 25, 24, Blocks.STONE.getDefaultState());
        structure.fillWithBlocks(world, start, 60, 25, 26, 61, 25, 29, Blocks.STONE_BRICKS.getDefaultState());
        structure.fillWithBlocks(world, start, 60, 25, 31, 60, 25, 41, Blocks.STONE_BRICKS.getDefaultState());
        structure.fillWithBlocks(world, start, 60, 25, 43, 62, 25, 45, Blocks.STONE_BRICKS.getDefaultState());
        structure.fillWithBlocks(world, start, 60, 25, 48, 61, 25, 49, Blocks.STONE.getDefaultState());
        structure.fillWithBlocks(world, start, 60, 26, 20, 60, 26, 20, Blocks.STONE_BRICK_STAIRS.getDefaultState().with(StairsBlock.FACING, Direction.WEST).with(StairsBlock.WATERLOGGED, false).with(StairsBlock.SHAPE, StairsShape.STRAIGHT).with(StairsBlock.HALF, Half.BOTTOM));
        structure.fillWithBlocks(world, start, 60, 26, 21, 60, 26, 22, Blocks.STONE_BRICKS.getDefaultState());
        structure.fillWithBlocks(world, start, 60, 26, 23, 60, 26, 23, Blocks.STONE_BRICK_STAIRS.getDefaultState().with(StairsBlock.FACING, Direction.SOUTH).with(StairsBlock.WATERLOGGED, false).with(StairsBlock.SHAPE, StairsShape.OUTER_RIGHT).with(StairsBlock.HALF, Half.BOTTOM));
        structure.fillWithBlocks(world, start, 60, 26, 28, 61, 26, 29, Blocks.SMOOTH_STONE.getDefaultState());
        structure.fillWithBlocks(world, start, 60, 26, 33, 60, 26, 39, Blocks.STONE_BRICKS.getDefaultState());
        structure.fillWithBlocks(world, start, 60, 26, 43, 62, 26, 45, Blocks.SMOOTH_STONE.getDefaultState());
        structure.fillWithBlocks(world, start, 60, 32, 23, 60, 32, 23, Blocks.STONE_BRICK_SLAB.getDefaultState().with(SlabBlock.TYPE, SlabType.TOP).with(SlabBlock.WATERLOGGED, false));
        structure.fillWithBlocks(world, start, 60, 32, 49, 61, 32, 49, Blocks.STONE_BRICK_SLAB.getDefaultState().with(SlabBlock.TYPE, SlabType.TOP).with(SlabBlock.WATERLOGGED, false));
        structure.fillWithBlocks(world, start, 60, 33, 21, 60, 33, 21, Blocks.STONE_BRICK_SLAB.getDefaultState().with(SlabBlock.TYPE, SlabType.BOTTOM).with(SlabBlock.WATERLOGGED, false));
        structure.fillWithBlocks(world, start, 60, 33, 22, 60, 33, 23, Blocks.STONE_BRICK_SLAB.getDefaultState().with(SlabBlock.TYPE, SlabType.DOUBLE).with(SlabBlock.WATERLOGGED, false));
        structure.fillWithBlocks(world, start, 60, 33, 24, 60, 33, 24, Blocks.STONE_BRICK_SLAB.getDefaultState().with(SlabBlock.TYPE, SlabType.BOTTOM).with(SlabBlock.WATERLOGGED, false));
        structure.fillWithBlocks(world, start, 60, 33, 49, 60, 33, 50, Blocks.STONE_BRICK_SLAB.getDefaultState().with(SlabBlock.TYPE, SlabType.DOUBLE).with(SlabBlock.WATERLOGGED, false));
        structure.fillWithBlocks(world, start, 61, 0, 0, 63, 0, 2, Blocks.DIRT.getDefaultState());
        structure.fillWithBlocks(world, start, 61, 0, 3, 62, 0, 4, Blocks.DIRT.getDefaultState());
        structure.fillWithBlocks(world, start, 61, 2, 20, 83, 5, 20, Blocks.DIRT.getDefaultState());
        structure.fillWithBlocks(world, start, 61, 2, 30, 64, 2, 33, Blocks.STONE.getDefaultState());
        structure.fillWithBlocks(world, start, 61, 2, 34, 63, 2, 62, Blocks.DIRT.getDefaultState());
        structure.fillWithBlocks(world, start, 61, 5, 68, 61, 5, 69, Blocks.GRASS_BLOCK.getDefaultState().with(SnowyDirtBlock.SNOWY, false));
        structure.fillWithBlocks(world, start, 61, 6, 5, 65, 6, 14, Blocks.GRASS_BLOCK.getDefaultState().with(SnowyDirtBlock.SNOWY, false));
        structure.fillWithBlocks(world, start, 61, 6, 18, 62, 6, 19, Blocks.GRASS_BLOCK.getDefaultState().with(SnowyDirtBlock.SNOWY, false));
        structure.fillWithBlocks(world, start, 61, 6, 53, 63, 6, 55, Blocks.GRASS_BLOCK.getDefaultState().with(SnowyDirtBlock.SNOWY, false));
        structure.fillWithBlocks(world, start, 61, 6, 64, 64, 6, 67, Blocks.GRASS_BLOCK.getDefaultState().with(SnowyDirtBlock.SNOWY, false));
        structure.fillWithBlocks(world, start, 61, 7, 21, 61, 8, 21, Blocks.COBBLESTONE.getDefaultState());
        structure.fillWithBlocks(world, start, 61, 7, 51, 61, 8, 51, Blocks.COBBLESTONE.getDefaultState());
        structure.fillWithBlocks(world, start, 61, 7, 63, 61, 10, 63, Blocks.OAK_LOG.getDefaultState());
        structure.fillWithBlocks(world, start, 61, 8, 29, 61, 8, 29, Blocks.STONE_BRICKS.getDefaultState());
        structure.fillWithBlocks(world, start, 61, 8, 43, 65, 8, 43, Blocks.STONE_BRICKS.getDefaultState());
        structure.fillWithBlocks(world, start, 61, 8, 61, 61, 9, 61, Blocks.OAK_LEAVES.getDefaultState().with(LeavesBlock.PERSISTENT, false).with(LeavesBlock.DISTANCE, 2));
        structure.fillWithBlocks(world, start, 61, 8, 62, 61, 10, 62, Blocks.OAK_LEAVES.getDefaultState().with(LeavesBlock.PERSISTENT, false).with(LeavesBlock.DISTANCE, 1));
        structure.fillWithBlocks(world, start, 61, 8, 64, 61, 10, 64, Blocks.OAK_LEAVES.getDefaultState().with(LeavesBlock.PERSISTENT, false).with(LeavesBlock.DISTANCE, 1));
        structure.fillWithBlocks(world, start, 61, 8, 65, 61, 9, 65, Blocks.OAK_LEAVES.getDefaultState().with(LeavesBlock.PERSISTENT, false).with(LeavesBlock.DISTANCE, 2));
        structure.fillWithBlocks(world, start, 61, 9, 9, 61, 10, 9, Blocks.OAK_LEAVES.getDefaultState().with(LeavesBlock.PERSISTENT, false).with(LeavesBlock.DISTANCE, 3));
        structure.fillWithBlocks(world, start, 61, 9, 10, 61, 10, 10, Blocks.OAK_LEAVES.getDefaultState().with(LeavesBlock.PERSISTENT, false).with(LeavesBlock.DISTANCE, 2));
        structure.fillWithBlocks(world, start, 61, 9, 11, 61, 10, 11, Blocks.OAK_LEAVES.getDefaultState().with(LeavesBlock.PERSISTENT, false).with(LeavesBlock.DISTANCE, 3));
        structure.fillWithBlocks(world, start, 61, 9, 12, 61, 10, 12, Blocks.OAK_LEAVES.getDefaultState().with(LeavesBlock.PERSISTENT, false).with(LeavesBlock.DISTANCE, 4));
        structure.fillWithBlocks(world, start, 61, 9, 13, 61, 10, 13, Blocks.OAK_LEAVES.getDefaultState().with(LeavesBlock.PERSISTENT, false).with(LeavesBlock.DISTANCE, 3));
        structure.fillWithBlocks(world, start, 61, 9, 14, 61, 10, 14, Blocks.OAK_LEAVES.getDefaultState().with(LeavesBlock.PERSISTENT, false).with(LeavesBlock.DISTANCE, 2));
        structure.fillWithBlocks(world, start, 61, 9, 15, 61, 11, 15, Blocks.OAK_LEAVES.getDefaultState().with(LeavesBlock.PERSISTENT, false).with(LeavesBlock.DISTANCE, 1));
        structure.fillWithBlocks(world, start, 61, 9, 16, 61, 10, 16, Blocks.OAK_LEAVES.getDefaultState().with(LeavesBlock.PERSISTENT, false).with(LeavesBlock.DISTANCE, 2));
        structure.fillWithBlocks(world, start, 61, 9, 17, 61, 10, 17, Blocks.OAK_LEAVES.getDefaultState().with(LeavesBlock.PERSISTENT, false).with(LeavesBlock.DISTANCE, 3));
        structure.fillWithBlocks(world, start, 61, 9, 55, 61, 10, 55, Blocks.OAK_LEAVES.getDefaultState().with(LeavesBlock.PERSISTENT, false).with(LeavesBlock.DISTANCE, 3));
        structure.fillWithBlocks(world, start, 61, 9, 56, 61, 10, 56, Blocks.OAK_LEAVES.getDefaultState().with(LeavesBlock.PERSISTENT, false).with(LeavesBlock.DISTANCE, 2));
        structure.fillWithBlocks(world, start, 61, 9, 57, 61, 10, 57, Blocks.OAK_LEAVES.getDefaultState().with(LeavesBlock.PERSISTENT, false).with(LeavesBlock.DISTANCE, 3));
        structure.fillWithBlocks(world, start, 61, 9, 58, 61, 10, 58, Blocks.OAK_LEAVES.getDefaultState().with(LeavesBlock.PERSISTENT, false).with(LeavesBlock.DISTANCE, 4));
        structure.fillWithBlocks(world, start, 61, 11, 33, 61, 20, 33, Blocks.STONE_BRICKS.getDefaultState());
        structure.fillWithBlocks(world, start, 61, 11, 39, 61, 20, 39, Blocks.STONE_BRICKS.getDefaultState());
        structure.fillWithBlocks(world, start, 61, 11, 62, 61, 11, 62, Blocks.OAK_LEAVES.getDefaultState().with(LeavesBlock.PERSISTENT, false).with(LeavesBlock.DISTANCE, 2));
        structure.fillWithBlocks(world, start, 61, 12, 15, 61, 12, 15, Blocks.OAK_LEAVES.getDefaultState().with(LeavesBlock.PERSISTENT, false).with(LeavesBlock.DISTANCE, 2));
        structure.fillWithBlocks(world, start, 61, 21, 34, 61, 21, 38, Blocks.STONE_BRICKS.getDefaultState());
        structure.fillWithBlocks(world, start, 61, 22, 22, 61, 22, 25, Blocks.STONE_BRICKS.getDefaultState());
        structure.fillWithBlocks(world, start, 61, 22, 26, 61, 22, 26, Blocks.STONE_BRICK_STAIRS.getDefaultState().with(StairsBlock.FACING, Direction.NORTH).with(StairsBlock.WATERLOGGED, false).with(StairsBlock.SHAPE, StairsShape.STRAIGHT).with(StairsBlock.HALF, Half.TOP));
        structure.fillWithBlocks(world, start, 61, 22, 35, 61, 23, 35, Blocks.STONE_BRICKS.getDefaultState());
        structure.fillWithBlocks(world, start, 61, 22, 37, 61, 23, 37, Blocks.STONE_BRICKS.getDefaultState());
        structure.fillWithBlocks(world, start, 61, 22, 47, 62, 22, 49, Blocks.STONE_BRICKS.getDefaultState());
        structure.fillWithBlocks(world, start, 61, 23, 23, 61, 23, 25, Blocks.STONE.getDefaultState());
        structure.fillWithBlocks(world, start, 61, 23, 47, 62, 23, 48, Blocks.STONE.getDefaultState());
        structure.fillWithBlocks(world, start, 61, 24, 23, 61, 24, 25, Blocks.STONE.getDefaultState());
        structure.fillWithBlocks(world, start, 61, 24, 26, 61, 25, 26, Blocks.STONE_BRICKS.getDefaultState());
        structure.fillWithBlocks(world, start, 61, 24, 46, 61, 25, 46, Blocks.STONE_BRICKS.getDefaultState());
        structure.fillWithBlocks(world, start, 61, 24, 47, 62, 24, 48, Blocks.STONE.getDefaultState());
        structure.fillWithBlocks(world, start, 61, 25, 23, 61, 25, 25, Blocks.STONE.getDefaultState());
        structure.fillWithBlocks(world, start, 61, 25, 30, 62, 25, 31, Blocks.STONE_BRICKS.getDefaultState());
        structure.fillWithBlocks(world, start, 61, 25, 32, 61, 25, 33, Blocks.STONE_BRICK_SLAB.getDefaultState().with(SlabBlock.TYPE, SlabType.TOP).with(SlabBlock.WATERLOGGED, false));
        structure.fillWithBlocks(world, start, 61, 25, 39, 61, 25, 40, Blocks.STONE_BRICK_SLAB.getDefaultState().with(SlabBlock.TYPE, SlabType.TOP).with(SlabBlock.WATERLOGGED, false));
        structure.fillWithBlocks(world, start, 61, 25, 41, 63, 25, 43, Blocks.STONE_BRICKS.getDefaultState());
        structure.fillWithBlocks(world, start, 61, 25, 47, 62, 25, 48, Blocks.STONE.getDefaultState());
        structure.fillWithBlocks(world, start, 61, 26, 23, 61, 26, 23, Blocks.STONE_BRICKS.getDefaultState());
        structure.fillWithBlocks(world, start, 61, 26, 25, 61, 26, 25, Blocks.STONE_BRICK_STAIRS.getDefaultState().with(StairsBlock.FACING, Direction.WEST).with(StairsBlock.WATERLOGGED, false).with(StairsBlock.SHAPE, StairsShape.STRAIGHT).with(StairsBlock.HALF, Half.BOTTOM));
        structure.fillWithBlocks(world, start, 61, 26, 26, 61, 26, 31, Blocks.SMOOTH_STONE.getDefaultState());
        structure.fillWithBlocks(world, start, 61, 26, 33, 61, 26, 39, Blocks.STONE_BRICK_STAIRS.getDefaultState().with(StairsBlock.FACING, Direction.EAST).with(StairsBlock.WATERLOGGED, false).with(StairsBlock.SHAPE, StairsShape.STRAIGHT).with(StairsBlock.HALF, Half.BOTTOM));
        structure.fillWithBlocks(world, start, 61, 26, 41, 63, 26, 43, Blocks.SMOOTH_STONE.getDefaultState());
        structure.fillWithBlocks(world, start, 61, 26, 49, 61, 26, 50, Blocks.STONE_BRICKS.getDefaultState());
        structure.fillWithBlocks(world, start, 61, 32, 23, 61, 32, 24, Blocks.STONE_BRICK_SLAB.getDefaultState().with(SlabBlock.TYPE, SlabType.TOP).with(SlabBlock.WATERLOGGED, false));
        structure.fillWithBlocks(world, start, 61, 32, 48, 61, 32, 49, Blocks.STONE_BRICK_SLAB.getDefaultState().with(SlabBlock.TYPE, SlabType.TOP).with(SlabBlock.WATERLOGGED, false));
        structure.fillWithBlocks(world, start, 61, 33, 22, 61, 33, 22, Blocks.STONE_BRICK_SLAB.getDefaultState().with(SlabBlock.TYPE, SlabType.BOTTOM).with(SlabBlock.WATERLOGGED, false));
        structure.fillWithBlocks(world, start, 61, 33, 23, 61, 33, 24, Blocks.STONE_BRICK_SLAB.getDefaultState().with(SlabBlock.TYPE, SlabType.DOUBLE).with(SlabBlock.WATERLOGGED, false));
        structure.fillWithBlocks(world, start, 61, 33, 25, 61, 33, 25, Blocks.STONE_BRICK_SLAB.getDefaultState().with(SlabBlock.TYPE, SlabType.BOTTOM).with(SlabBlock.WATERLOGGED, false));
        structure.fillWithBlocks(world, start, 61, 33, 48, 61, 33, 49, Blocks.STONE_BRICK_SLAB.getDefaultState().with(SlabBlock.TYPE, SlabType.DOUBLE).with(SlabBlock.WATERLOGGED, false));
        structure.fillWithBlocks(world, start, 62, 0, 70, 64, 0, 74, Blocks.DIRT.getDefaultState());
        structure.fillWithBlocks(world, start, 62, 1, 17, 74, 5, 17, Blocks.DIRT.getDefaultState());
        structure.fillWithBlocks(world, start, 62, 1, 34, 71, 1, 43, Blocks.STONE.getDefaultState());
        structure.fillWithBlocks(world, start, 62, 1, 68, 70, 1, 68, Blocks.STONE.getDefaultState());
        structure.fillWithBlocks(world, start, 62, 1, 69, 66, 1, 73, Blocks.DIRT.getDefaultState());
        structure.fillWithBlocks(world, start, 62, 2, 21, 62, 2, 33, Blocks.STONE.getDefaultState());
        structure.fillWithBlocks(world, start, 62, 5, 68, 70, 5, 68, Blocks.DIRT.getDefaultState());
        structure.fillWithBlocks(world, start, 62, 6, 20, 62, 6, 20, Blocks.GRASS_BLOCK.getDefaultState().with(SnowyDirtBlock.SNOWY, false));
        structure.fillWithBlocks(world, start, 62, 6, 52, 65, 6, 55, Blocks.GRASS_BLOCK.getDefaultState().with(SnowyDirtBlock.SNOWY, false));
        structure.fillWithBlocks(world, start, 62, 6, 63, 67, 6, 68, Blocks.GRASS_BLOCK.getDefaultState().with(SnowyDirtBlock.SNOWY, false));
        structure.fillWithBlocks(world, start, 62, 7, 15, 62, 11, 15, Blocks.OAK_LOG.getDefaultState());
        structure.fillWithBlocks(world, start, 62, 7, 22, 62, 8, 22, Blocks.COBBLESTONE.getDefaultState());
        structure.fillWithBlocks(world, start, 62, 7, 23, 62, 7, 49, Blocks.STONE.getDefaultState());
        structure.fillWithBlocks(world, start, 62, 7, 50, 62, 8, 50, Blocks.COBBLESTONE.getDefaultState());
        structure.fillWithBlocks(world, start, 62, 7, 53, 63, 7, 53, Blocks.GRASS.getDefaultState());
        structure.fillWithBlocks(world, start, 62, 8, 25, 64, 8, 27, Blocks.STONE.getDefaultState());
        structure.fillWithBlocks(world, start, 62, 8, 29, 63, 8, 31, Blocks.STONE_BRICKS.getDefaultState());
        structure.fillWithBlocks(world, start, 62, 8, 32, 63, 8, 32, Blocks.COBBLESTONE_STAIRS.getDefaultState().with(StairsBlock.FACING, Direction.SOUTH).with(StairsBlock.WATERLOGGED, false).with(StairsBlock.SHAPE, StairsShape.STRAIGHT).with(StairsBlock.HALF, Half.BOTTOM));
        structure.fillWithBlocks(world, start, 62, 8, 33, 64, 8, 33, Blocks.STONE_BRICKS.getDefaultState());
        structure.fillWithBlocks(world, start, 62, 8, 34, 66, 8, 38, Blocks.SMOOTH_STONE.getDefaultState());
        structure.fillWithBlocks(world, start, 62, 8, 39, 64, 8, 39, Blocks.STONE_BRICKS.getDefaultState());
        structure.fillWithBlocks(world, start, 62, 8, 40, 63, 8, 40, Blocks.COBBLESTONE_STAIRS.getDefaultState().with(StairsBlock.FACING, Direction.NORTH).with(StairsBlock.WATERLOGGED, false).with(StairsBlock.SHAPE, StairsShape.STRAIGHT).with(StairsBlock.HALF, Half.BOTTOM));
        structure.fillWithBlocks(world, start, 62, 8, 41, 63, 8, 43, Blocks.STONE_BRICKS.getDefaultState());
        structure.fillWithBlocks(world, start, 62, 8, 45, 64, 8, 47, Blocks.STONE.getDefaultState());
        structure.fillWithBlocks(world, start, 62, 8, 61, 62, 10, 61, Blocks.OAK_LEAVES.getDefaultState().with(LeavesBlock.PERSISTENT, false).with(LeavesBlock.DISTANCE, 3));
        structure.fillWithBlocks(world, start, 62, 8, 62, 62, 10, 62, Blocks.OAK_LEAVES.getDefaultState().with(LeavesBlock.PERSISTENT, false).with(LeavesBlock.DISTANCE, 2));
        structure.fillWithBlocks(world, start, 62, 8, 63, 62, 10, 63, Blocks.OAK_LEAVES.getDefaultState().with(LeavesBlock.PERSISTENT, false).with(LeavesBlock.DISTANCE, 1));
        structure.fillWithBlocks(world, start, 62, 8, 64, 62, 9, 64, Blocks.OAK_LEAVES.getDefaultState().with(LeavesBlock.PERSISTENT, false).with(LeavesBlock.DISTANCE, 2));
        structure.fillWithBlocks(world, start, 62, 8, 65, 62, 9, 65, Blocks.OAK_LEAVES.getDefaultState().with(LeavesBlock.PERSISTENT, false).with(LeavesBlock.DISTANCE, 3));
        structure.fillWithBlocks(world, start, 62, 9, 13, 62, 10, 13, Blocks.OAK_LEAVES.getDefaultState().with(LeavesBlock.PERSISTENT, false).with(LeavesBlock.DISTANCE, 2));
        structure.fillWithBlocks(world, start, 62, 9, 14, 62, 11, 14, Blocks.OAK_LEAVES.getDefaultState().with(LeavesBlock.PERSISTENT, false).with(LeavesBlock.DISTANCE, 1));
        structure.fillWithBlocks(world, start, 62, 9, 16, 62, 11, 16, Blocks.OAK_LEAVES.getDefaultState().with(LeavesBlock.PERSISTENT, false).with(LeavesBlock.DISTANCE, 1));
        structure.fillWithBlocks(world, start, 62, 9, 17, 62, 10, 17, Blocks.OAK_LEAVES.getDefaultState().with(LeavesBlock.PERSISTENT, false).with(LeavesBlock.DISTANCE, 2));
        structure.fillWithBlocks(world, start, 62, 9, 25, 64, 9, 27, Blocks.STONE_BRICKS.getDefaultState());
        structure.fillWithBlocks(world, start, 62, 9, 45, 64, 9, 47, Blocks.STONE_BRICKS.getDefaultState());
        structure.fillWithBlocks(world, start, 62, 9, 54, 62, 10, 54, Blocks.OAK_LEAVES.getDefaultState().with(LeavesBlock.PERSISTENT, false).with(LeavesBlock.DISTANCE, 3));
        structure.fillWithBlocks(world, start, 62, 9, 55, 62, 11, 55, Blocks.OAK_LEAVES.getDefaultState().with(LeavesBlock.PERSISTENT, false).with(LeavesBlock.DISTANCE, 2));
        structure.fillWithBlocks(world, start, 62, 9, 56, 62, 11, 56, Blocks.OAK_LEAVES.getDefaultState().with(LeavesBlock.PERSISTENT, false).with(LeavesBlock.DISTANCE, 1));
        structure.fillWithBlocks(world, start, 62, 9, 57, 62, 11, 57, Blocks.OAK_LEAVES.getDefaultState().with(LeavesBlock.PERSISTENT, false).with(LeavesBlock.DISTANCE, 2));
        structure.fillWithBlocks(world, start, 62, 9, 58, 62, 10, 59, Blocks.OAK_LEAVES.getDefaultState().with(LeavesBlock.PERSISTENT, false).with(LeavesBlock.DISTANCE, 3));
        structure.fillWithBlocks(world, start, 62, 9, 60, 62, 10, 60, Blocks.OAK_LEAVES.getDefaultState().with(LeavesBlock.PERSISTENT, false).with(LeavesBlock.DISTANCE, 2));
        structure.fillWithBlocks(world, start, 62, 10, 25, 62, 11, 25, Blocks.COBBLESTONE_WALL.getDefaultState().with(WallBlock.WATERLOGGED, false).with(WallBlock.UP, true).with(WallBlock.WALL_HEIGHT_NORTH, WallHeight.LOW).with(WallBlock.WALL_HEIGHT_SOUTH, WallHeight.LOW).with(WallBlock.WALL_HEIGHT_EAST, WallHeight.LOW).with(WallBlock.WALL_HEIGHT_WEST, WallHeight.LOW));
        structure.fillWithBlocks(world, start, 62, 10, 27, 62, 11, 27, Blocks.COBBLESTONE_WALL.getDefaultState().with(WallBlock.WATERLOGGED, false).with(WallBlock.UP, true).with(WallBlock.WALL_HEIGHT_NORTH, WallHeight.LOW).with(WallBlock.WALL_HEIGHT_SOUTH, WallHeight.LOW).with(WallBlock.WALL_HEIGHT_EAST, WallHeight.LOW).with(WallBlock.WALL_HEIGHT_WEST, WallHeight.LOW));
        structure.fillWithBlocks(world, start, 62, 10, 45, 62, 11, 45, Blocks.COBBLESTONE_WALL.getDefaultState().with(WallBlock.WATERLOGGED, false).with(WallBlock.UP, true).with(WallBlock.WALL_HEIGHT_NORTH, WallHeight.LOW).with(WallBlock.WALL_HEIGHT_SOUTH, WallHeight.LOW).with(WallBlock.WALL_HEIGHT_EAST, WallHeight.LOW).with(WallBlock.WALL_HEIGHT_WEST, WallHeight.LOW));
        structure.fillWithBlocks(world, start, 62, 10, 47, 62, 11, 47, Blocks.COBBLESTONE_WALL.getDefaultState().with(WallBlock.WATERLOGGED, false).with(WallBlock.UP, true).with(WallBlock.WALL_HEIGHT_NORTH, WallHeight.LOW).with(WallBlock.WALL_HEIGHT_SOUTH, WallHeight.LOW).with(WallBlock.WALL_HEIGHT_EAST, WallHeight.LOW).with(WallBlock.WALL_HEIGHT_WEST, WallHeight.LOW));
        structure.fillWithBlocks(world, start, 62, 12, 14, 62, 12, 14, Blocks.OAK_LEAVES.getDefaultState().with(LeavesBlock.PERSISTENT, false).with(LeavesBlock.DISTANCE, 2));
        structure.fillWithBlocks(world, start, 62, 12, 25, 64, 12, 27, Blocks.STONE_BRICKS.getDefaultState());
        structure.fillWithBlocks(world, start, 62, 12, 45, 64, 12, 47, Blocks.STONE_BRICKS.getDefaultState());
        structure.fillWithBlocks(world, start, 62, 12, 56, 62, 12, 56, Blocks.OAK_LEAVES.getDefaultState().with(LeavesBlock.PERSISTENT, false).with(LeavesBlock.DISTANCE, 2));
        structure.fillWithBlocks(world, start, 62, 13, 26, 62, 13, 26, Blocks.STONE_BRICKS.getDefaultState());
        structure.fillWithBlocks(world, start, 62, 13, 46, 62, 13, 46, Blocks.STONE_BRICKS.getDefaultState());
        structure.fillWithBlocks(world, start, 62, 15, 25, 64, 15, 27, Blocks.STONE_BRICKS.getDefaultState());
        structure.fillWithBlocks(world, start, 62, 15, 45, 64, 15, 47, Blocks.STONE_BRICKS.getDefaultState());
        structure.fillWithBlocks(world, start, 62, 17, 26, 62, 18, 26, Blocks.STONE_BRICKS.getDefaultState());
        structure.fillWithBlocks(world, start, 62, 17, 46, 62, 18, 46, Blocks.STONE_BRICKS.getDefaultState());
        structure.fillWithBlocks(world, start, 62, 18, 25, 64, 18, 27, Blocks.STONE_BRICKS.getDefaultState());
        structure.fillWithBlocks(world, start, 62, 18, 45, 64, 18, 47, Blocks.STONE_BRICKS.getDefaultState());
        structure.fillWithBlocks(world, start, 62, 19, 25, 62, 20, 25, Blocks.COBBLESTONE_WALL.getDefaultState().with(WallBlock.WATERLOGGED, false).with(WallBlock.UP, true).with(WallBlock.WALL_HEIGHT_NORTH, WallHeight.LOW).with(WallBlock.WALL_HEIGHT_SOUTH, WallHeight.LOW).with(WallBlock.WALL_HEIGHT_EAST, WallHeight.LOW).with(WallBlock.WALL_HEIGHT_WEST, WallHeight.LOW));
        structure.fillWithBlocks(world, start, 62, 19, 27, 62, 20, 27, Blocks.COBBLESTONE_WALL.getDefaultState().with(WallBlock.WATERLOGGED, false).with(WallBlock.UP, true).with(WallBlock.WALL_HEIGHT_NORTH, WallHeight.LOW).with(WallBlock.WALL_HEIGHT_SOUTH, WallHeight.LOW).with(WallBlock.WALL_HEIGHT_EAST, WallHeight.LOW).with(WallBlock.WALL_HEIGHT_WEST, WallHeight.LOW));
        structure.fillWithBlocks(world, start, 62, 19, 45, 62, 20, 45, Blocks.COBBLESTONE_WALL.getDefaultState().with(WallBlock.WATERLOGGED, false).with(WallBlock.UP, true).with(WallBlock.WALL_HEIGHT_NORTH, WallHeight.LOW).with(WallBlock.WALL_HEIGHT_SOUTH, WallHeight.LOW).with(WallBlock.WALL_HEIGHT_EAST, WallHeight.LOW).with(WallBlock.WALL_HEIGHT_WEST, WallHeight.LOW));
        structure.fillWithBlocks(world, start, 62, 19, 47, 62, 20, 47, Blocks.COBBLESTONE_WALL.getDefaultState().with(WallBlock.WATERLOGGED, false).with(WallBlock.UP, true).with(WallBlock.WALL_HEIGHT_NORTH, WallHeight.LOW).with(WallBlock.WALL_HEIGHT_SOUTH, WallHeight.LOW).with(WallBlock.WALL_HEIGHT_EAST, WallHeight.LOW).with(WallBlock.WALL_HEIGHT_WEST, WallHeight.LOW));
        structure.fillWithBlocks(world, start, 62, 21, 25, 64, 21, 27, Blocks.STONE_BRICKS.getDefaultState());
        structure.fillWithBlocks(world, start, 62, 21, 45, 64, 21, 47, Blocks.STONE_BRICKS.getDefaultState());
        structure.fillWithBlocks(world, start, 62, 22, 23, 62, 22, 26, Blocks.STONE_BRICKS.getDefaultState());
        structure.fillWithBlocks(world, start, 62, 22, 46, 63, 22, 48, Blocks.STONE_BRICKS.getDefaultState());
        structure.fillWithBlocks(world, start, 62, 23, 24, 63, 23, 26, Blocks.STONE.getDefaultState());
        structure.fillWithBlocks(world, start, 62, 23, 46, 63, 23, 48, Blocks.STONE.getDefaultState());
        structure.fillWithBlocks(world, start, 62, 24, 24, 62, 24, 26, Blocks.STONE.getDefaultState());
        structure.fillWithBlocks(world, start, 62, 24, 27, 62, 25, 28, Blocks.STONE_BRICKS.getDefaultState());
        structure.fillWithBlocks(world, start, 62, 24, 44, 62, 25, 45, Blocks.STONE_BRICKS.getDefaultState());
        structure.fillWithBlocks(world, start, 62, 24, 46, 63, 24, 47, Blocks.STONE.getDefaultState());
        structure.fillWithBlocks(world, start, 62, 25, 24, 63, 25, 26, Blocks.STONE.getDefaultState());
        structure.fillWithBlocks(world, start, 62, 25, 29, 63, 25, 43, Blocks.STONE_BRICKS.getDefaultState());
        structure.fillWithBlocks(world, start, 62, 25, 46, 63, 25, 48, Blocks.STONE.getDefaultState());
        structure.fillWithBlocks(world, start, 62, 26, 23, 62, 26, 25, Blocks.STONE_BRICKS.getDefaultState());
        structure.fillWithBlocks(world, start, 62, 26, 26, 62, 26, 26, Blocks.STONE_BRICK_STAIRS.getDefaultState().with(StairsBlock.FACING, Direction.WEST).with(StairsBlock.WATERLOGGED, false).with(StairsBlock.SHAPE, StairsShape.STRAIGHT).with(StairsBlock.HALF, Half.BOTTOM));
        structure.fillWithBlocks(world, start, 62, 26, 27, 62, 26, 45, Blocks.SMOOTH_STONE.getDefaultState());
        structure.fillWithBlocks(world, start, 62, 26, 47, 63, 26, 48, Blocks.STONE_BRICKS.getDefaultState());
        structure.fillWithBlocks(world, start, 62, 33, 23, 62, 33, 23, Blocks.STONE_BRICK_SLAB.getDefaultState().with(SlabBlock.TYPE, SlabType.BOTTOM).with(SlabBlock.WATERLOGGED, false));
        structure.fillWithBlocks(world, start, 62, 33, 24, 62, 33, 25, Blocks.STONE_BRICK_SLAB.getDefaultState().with(SlabBlock.TYPE, SlabType.DOUBLE).with(SlabBlock.WATERLOGGED, false));
        structure.fillWithBlocks(world, start, 62, 33, 26, 62, 33, 26, Blocks.STONE_BRICK_SLAB.getDefaultState().with(SlabBlock.TYPE, SlabType.BOTTOM).with(SlabBlock.WATERLOGGED, false));
        structure.fillWithBlocks(world, start, 62, 33, 47, 62, 33, 48, Blocks.STONE_BRICK_SLAB.getDefaultState().with(SlabBlock.TYPE, SlabType.DOUBLE).with(SlabBlock.WATERLOGGED, false));
        structure.fillWithBlocks(world, start, 63, 0, 3, 66, 0, 3, Blocks.STONE.getDefaultState());
        structure.fillWithBlocks(world, start, 63, 2, 21, 63, 2, 21, Blocks.DIRT.getDefaultState());
        structure.fillWithBlocks(world, start, 63, 2, 22, 63, 2, 33, Blocks.STONE.getDefaultState());
        structure.fillWithBlocks(world, start, 63, 4, 3, 66, 4, 69, Blocks.DIRT.getDefaultState());
        structure.fillWithBlocks(world, start, 63, 5, 3, 64, 5, 4, Blocks.GRASS_BLOCK.getDefaultState().with(SnowyDirtBlock.SNOWY, false));
        structure.fillWithBlocks(world, start, 63, 6, 15, 64, 6, 21, Blocks.GRASS_BLOCK.getDefaultState().with(SnowyDirtBlock.SNOWY, false));
        structure.fillWithBlocks(world, start, 63, 6, 22, 63, 6, 50, Blocks.DIRT.getDefaultState());
        structure.fillWithBlocks(world, start, 63, 6, 51, 65, 6, 55, Blocks.GRASS_BLOCK.getDefaultState().with(SnowyDirtBlock.SNOWY, false));
        structure.fillWithBlocks(world, start, 63, 6, 57, 65, 6, 59, Blocks.GRASS_BLOCK.getDefaultState().with(SnowyDirtBlock.SNOWY, false));
        structure.fillWithBlocks(world, start, 63, 6, 60, 63, 6, 68, Blocks.GRASS_BLOCK.getDefaultState().with(SnowyDirtBlock.SNOWY, false));
        structure.fillWithBlocks(world, start, 63, 7, 23, 63, 8, 23, Blocks.COBBLESTONE.getDefaultState());
        structure.fillWithBlocks(world, start, 63, 7, 24, 63, 7, 48, Blocks.STONE.getDefaultState());
        structure.fillWithBlocks(world, start, 63, 7, 49, 63, 8, 49, Blocks.COBBLESTONE.getDefaultState());
        structure.fillWithBlocks(world, start, 63, 7, 56, 63, 11, 56, Blocks.OAK_LOG.getDefaultState());
        structure.fillWithBlocks(world, start, 63, 8, 14, 64, 9, 14, Blocks.OAK_LEAVES.getDefaultState().with(LeavesBlock.PERSISTENT, false).with(LeavesBlock.DISTANCE, 2));
        structure.fillWithBlocks(world, start, 63, 8, 15, 64, 9, 15, Blocks.OAK_LEAVES.getDefaultState().with(LeavesBlock.PERSISTENT, false).with(LeavesBlock.DISTANCE, 1));
        structure.fillWithBlocks(world, start, 63, 8, 16, 64, 9, 16, Blocks.OAK_LEAVES.getDefaultState().with(LeavesBlock.PERSISTENT, false).with(LeavesBlock.DISTANCE, 2));
        structure.fillWithBlocks(world, start, 63, 8, 62, 63, 10, 62, Blocks.OAK_LEAVES.getDefaultState().with(LeavesBlock.PERSISTENT, false).with(LeavesBlock.DISTANCE, 3));
        structure.fillWithBlocks(world, start, 63, 8, 63, 63, 9, 63, Blocks.OAK_LEAVES.getDefaultState().with(LeavesBlock.PERSISTENT, false).with(LeavesBlock.DISTANCE, 2));
        structure.fillWithBlocks(world, start, 63, 8, 64, 63, 9, 64, Blocks.OAK_LEAVES.getDefaultState().with(LeavesBlock.PERSISTENT, false).with(LeavesBlock.DISTANCE, 3));
        structure.fillWithBlocks(world, start, 63, 8, 65, 63, 9, 65, Blocks.OAK_LEAVES.getDefaultState().with(LeavesBlock.PERSISTENT, false).with(LeavesBlock.DISTANCE, 4));
        structure.fillWithBlocks(world, start, 63, 9, 13, 64, 10, 13, Blocks.OAK_LEAVES.getDefaultState().with(LeavesBlock.PERSISTENT, false).with(LeavesBlock.DISTANCE, 3));
        structure.fillWithBlocks(world, start, 63, 9, 17, 64, 9, 17, Blocks.OAK_LEAVES.getDefaultState().with(LeavesBlock.PERSISTENT, false).with(LeavesBlock.DISTANCE, 3));
        structure.fillWithBlocks(world, start, 63, 9, 54, 63, 10, 54, Blocks.OAK_LEAVES.getDefaultState().with(LeavesBlock.PERSISTENT, false).with(LeavesBlock.DISTANCE, 2));
        structure.fillWithBlocks(world, start, 63, 9, 55, 63, 11, 55, Blocks.OAK_LEAVES.getDefaultState().with(LeavesBlock.PERSISTENT, false).with(LeavesBlock.DISTANCE, 1));
        structure.fillWithBlocks(world, start, 63, 9, 57, 63, 11, 57, Blocks.OAK_LEAVES.getDefaultState().with(LeavesBlock.PERSISTENT, false).with(LeavesBlock.DISTANCE, 1));
        structure.fillWithBlocks(world, start, 63, 9, 58, 63, 10, 59, Blocks.OAK_LEAVES.getDefaultState().with(LeavesBlock.PERSISTENT, false).with(LeavesBlock.DISTANCE, 2));
        structure.fillWithBlocks(world, start, 63, 9, 60, 63, 11, 60, Blocks.OAK_LEAVES.getDefaultState().with(LeavesBlock.PERSISTENT, false).with(LeavesBlock.DISTANCE, 1));
        structure.fillWithBlocks(world, start, 63, 9, 61, 63, 10, 61, Blocks.OAK_LEAVES.getDefaultState().with(LeavesBlock.PERSISTENT, false).with(LeavesBlock.DISTANCE, 2));
        structure.fillWithBlocks(world, start, 63, 10, 14, 64, 10, 14, Blocks.OAK_LEAVES.getDefaultState().with(LeavesBlock.PERSISTENT, false).with(LeavesBlock.DISTANCE, 2));
        structure.fillWithBlocks(world, start, 63, 10, 15, 64, 10, 15, Blocks.OAK_LEAVES.getDefaultState().with(LeavesBlock.PERSISTENT, false).with(LeavesBlock.DISTANCE, 1));
        structure.fillWithBlocks(world, start, 63, 10, 16, 64, 10, 16, Blocks.OAK_LEAVES.getDefaultState().with(LeavesBlock.PERSISTENT, false).with(LeavesBlock.DISTANCE, 2));
        structure.fillWithBlocks(world, start, 63, 10, 26, 63, 11, 26, Blocks.STONE.getDefaultState());
        structure.fillWithBlocks(world, start, 63, 10, 46, 63, 11, 46, Blocks.STONE.getDefaultState());
        structure.fillWithBlocks(world, start, 63, 11, 14, 63, 11, 14, Blocks.OAK_LEAVES.getDefaultState().with(LeavesBlock.PERSISTENT, false).with(LeavesBlock.DISTANCE, 2));
        structure.fillWithBlocks(world, start, 63, 12, 55, 63, 12, 55, Blocks.OAK_LEAVES.getDefaultState().with(LeavesBlock.PERSISTENT, false).with(LeavesBlock.DISTANCE, 2));
        structure.fillWithBlocks(world, start, 63, 12, 60, 63, 12, 60, Blocks.OAK_LEAVES.getDefaultState().with(LeavesBlock.PERSISTENT, false).with(LeavesBlock.DISTANCE, 2));
        structure.fillWithBlocks(world, start, 63, 13, 25, 63, 13, 25, Blocks.STONE_BRICKS.getDefaultState());
        structure.fillWithBlocks(world, start, 63, 13, 26, 63, 14, 26, Blocks.STONE.getDefaultState());
        structure.fillWithBlocks(world, start, 63, 13, 45, 63, 13, 45, Blocks.STONE_BRICKS.getDefaultState());
        structure.fillWithBlocks(world, start, 63, 13, 46, 63, 14, 46, Blocks.STONE.getDefaultState());
        structure.fillWithBlocks(world, start, 63, 16, 26, 63, 17, 26, Blocks.STONE.getDefaultState());
        structure.fillWithBlocks(world, start, 63, 16, 46, 63, 17, 46, Blocks.STONE.getDefaultState());
        structure.fillWithBlocks(world, start, 63, 17, 25, 63, 18, 25, Blocks.STONE_BRICKS.getDefaultState());
        structure.fillWithBlocks(world, start, 63, 17, 27, 63, 18, 27, Blocks.STONE_BRICKS.getDefaultState());
        structure.fillWithBlocks(world, start, 63, 17, 45, 63, 18, 45, Blocks.STONE_BRICKS.getDefaultState());
        structure.fillWithBlocks(world, start, 63, 17, 47, 63, 18, 47, Blocks.STONE_BRICKS.getDefaultState());
        structure.fillWithBlocks(world, start, 63, 19, 26, 63, 20, 26, Blocks.STONE.getDefaultState());
        structure.fillWithBlocks(world, start, 63, 19, 46, 63, 20, 46, Blocks.STONE.getDefaultState());
        structure.fillWithBlocks(world, start, 63, 22, 23, 63, 22, 23, Blocks.STONE_BRICK_STAIRS.getDefaultState().with(StairsBlock.FACING, Direction.SOUTH).with(StairsBlock.WATERLOGGED, false).with(StairsBlock.SHAPE, StairsShape.STRAIGHT).with(StairsBlock.HALF, Half.TOP));
        structure.fillWithBlocks(world, start, 63, 22, 24, 63, 22, 28, Blocks.STONE_BRICKS.getDefaultState());
        structure.fillWithBlocks(world, start, 63, 22, 44, 64, 22, 47, Blocks.STONE_BRICKS.getDefaultState());
        structure.fillWithBlocks(world, start, 63, 23, 27, 64, 23, 28, Blocks.STONE.getDefaultState());
        structure.fillWithBlocks(world, start, 63, 23, 44, 64, 23, 46, Blocks.STONE.getDefaultState());
        structure.fillWithBlocks(world, start, 63, 24, 25, 63, 25, 28, Blocks.STONE.getDefaultState());
        structure.fillWithBlocks(world, start, 63, 24, 29, 63, 25, 31, Blocks.STONE_BRICKS.getDefaultState());
        structure.fillWithBlocks(world, start, 63, 24, 32, 63, 24, 33, Blocks.STONE_BRICK_SLAB.getDefaultState().with(SlabBlock.TYPE, SlabType.TOP).with(SlabBlock.WATERLOGGED, false));
        structure.fillWithBlocks(world, start, 63, 24, 39, 63, 24, 40, Blocks.STONE_BRICK_SLAB.getDefaultState().with(SlabBlock.TYPE, SlabType.TOP).with(SlabBlock.WATERLOGGED, false));
        structure.fillWithBlocks(world, start, 63, 24, 41, 63, 25, 43, Blocks.STONE_BRICKS.getDefaultState());
        structure.fillWithBlocks(world, start, 63, 24, 44, 64, 24, 45, Blocks.STONE.getDefaultState());
