package mod.arcalitegames.odyssey.world.structure.structures.dungeons.mayan_temple;

import mod.arcalitegames.odyssey.world.structure.StructureBase;
import net.minecraft.block.Blocks;
import net.minecraft.block.SnowyDirtBlock;
import net.minecraft.block.StairsBlock;
import net.minecraft.block.WallBlock;
import net.minecraft.block.WallHeight;
import net.minecraft.state.properties.Half;
import net.minecraft.state.properties.StairsShape;
import net.minecraft.util.Direction;
import net.minecraft.util.math.BlockPos;
import net.minecraft.world.World;

public class TempleComponent9
{
	public static BlockPos start;
    public static World world;
    public static StructureBase structure;

    public static void init(World worldIn, BlockPos blockPos, StructureBase structureIn)
    {
        world = worldIn; start = blockPos; structure = structureIn;
    }
    
    public static void generatePart91()
    {
        structure.fillWithBlocks(world, start, 91, -33, 27, 91, -32, 27, Blocks.MOSSY_STONE_BRICKS.getDefaultState());
        structure.fillWithBlocks(world, start, 91, -33, 28, 92, -33, 29, Blocks.STONE_BRICKS.getDefaultState());
        structure.fillWithBlocks(world, start, 91, -33, 31, 91, -33, 32, Blocks.STONE_BRICKS.getDefaultState());
        structure.fillWithBlocks(world, start, 91, -33, 33, 91, -33, 34, Blocks.AIR.getDefaultState());
        structure.fillWithBlocks(world, start, 91, -33, 35, 92, -33, 37, Blocks.STONE_BRICKS.getDefaultState());
        structure.fillWithBlocks(world, start, 91, -32, 21, 91, -32, 22, Blocks.MOSSY_STONE_BRICKS.getDefaultState());
        structure.fillWithBlocks(world, start, 91, -32, 24, 91, -32, 25, Blocks.STONE_BRICKS.getDefaultState());
        structure.fillWithBlocks(world, start, 91, -32, 29, 91, -32, 30, Blocks.STONE_BRICKS.getDefaultState());
        structure.fillWithBlocks(world, start, 91, -32, 34, 91, -31, 34, Blocks.STONE_BRICKS.getDefaultState());
        structure.fillWithBlocks(world, start, 91, -32, 35, 91, -32, 35, Blocks.MOSSY_STONE_BRICKS.getDefaultState());
        structure.fillWithBlocks(world, start, 91, -32, 38, 92, -31, 38, Blocks.STONE_BRICKS.getDefaultState());
        structure.fillWithBlocks(world, start, 91, -32, 39, 91, -31, 39, Blocks.MOSSY_STONE_BRICKS.getDefaultState());
        structure.fillWithBlocks(world, start, 91, -31, 20, 91, -31, 21, Blocks.MOSSY_STONE_BRICKS.getDefaultState());
        structure.fillWithBlocks(world, start, 91, -31, 23, 91, -31, 23, Blocks.MOSSY_COBBLESTONE.getDefaultState());
        structure.fillWithBlocks(world, start, 91, -31, 24, 91, -31, 24, Blocks.STONE_BRICKS.getDefaultState());
        structure.fillWithBlocks(world, start, 91, -31, 31, 91, -31, 31, Blocks.STONE_BRICKS.getDefaultState());
        structure.fillWithBlocks(world, start, 91, -31, 36, 91, -31, 38, Blocks.STONE_BRICKS.getDefaultState());
        structure.fillWithBlocks(world, start, 91, -20, 41, 91, -19, 41, Blocks.CRACKED_STONE_BRICKS.getDefaultState());
        structure.fillWithBlocks(world, start, 91, -20, 42, 91, -19, 44, Blocks.STONE_BRICKS.getDefaultState());
        structure.fillWithBlocks(world, start, 91, -20, 72, 91, -20, 72, Blocks.STONE_BRICKS.getDefaultState());
        structure.fillWithBlocks(world, start, 91, -20, 73, 91, -19, 73, Blocks.MOSSY_STONE_BRICKS.getDefaultState());
        structure.fillWithBlocks(world, start, 91, -20, 74, 91, -20, 76, Blocks.STONE_BRICKS.getDefaultState());
        structure.fillWithBlocks(world, start, 91, -20, 80, 91, -20, 81, Blocks.CRACKED_STONE_BRICKS.getDefaultState());
        structure.fillWithBlocks(world, start, 91, -20, 82, 91, -20, 85, Blocks.STONE_BRICKS.getDefaultState());
        structure.fillWithBlocks(world, start, 91, -19, 74, 91, -19, 74, Blocks.STONE_BRICKS.getDefaultState());
        structure.fillWithBlocks(world, start, 91, -19, 75, 91, -18, 76, Blocks.AIR.getDefaultState());
        structure.fillWithBlocks(world, start, 91, -19, 77, 91, -19, 77, Blocks.STONE_BRICKS.getDefaultState());
        structure.fillWithBlocks(world, start, 91, -19, 78, 91, -16, 78, Blocks.AIR.getDefaultState());
        structure.fillWithBlocks(world, start, 91, -19, 80, 91, -16, 80, Blocks.AIR.getDefaultState());
        structure.fillWithBlocks(world, start, 91, -19, 81, 91, -19, 81, Blocks.STONE_BRICKS.getDefaultState());
        structure.fillWithBlocks(world, start, 91, -19, 82, 91, -18, 83, Blocks.AIR.getDefaultState());
        structure.fillWithBlocks(world, start, 91, -19, 84, 92, -19, 86, Blocks.STONE_BRICKS.getDefaultState());
        structure.fillWithBlocks(world, start, 91, -18, 41, 91, -17, 41, Blocks.STONE_BRICKS.getDefaultState());
        structure.fillWithBlocks(world, start, 91, -18, 72, 91, -16, 72, Blocks.STONE_BRICKS.getDefaultState());
        structure.fillWithBlocks(world, start, 91, -18, 74, 93, -16, 74, Blocks.STONE_BRICKS.getDefaultState());
        structure.fillWithBlocks(world, start, 91, -18, 77, 91, -16, 77, Blocks.STONE_BRICKS.getDefaultState());
        structure.fillWithBlocks(world, start, 91, -18, 79, 91, -17, 80, Blocks.AIR.getDefaultState());
        structure.fillWithBlocks(world, start, 91, -18, 81, 91, -18, 81, Blocks.STONE_BRICKS.getDefaultState());
        structure.fillWithBlocks(world, start, 91, -18, 84, 91, -17, 85, Blocks.STONE_BRICKS.getDefaultState());
        structure.fillWithBlocks(world, start, 91, -17, 73, 92, -17, 74, Blocks.STONE_BRICKS.getDefaultState());
        structure.fillWithBlocks(world, start, 91, -17, 75, 91, -16, 76, Blocks.AIR.getDefaultState());
        structure.fillWithBlocks(world, start, 91, -17, 81, 91, -15, 81, Blocks.STONE_BRICKS.getDefaultState());
        structure.fillWithBlocks(world, start, 91, -17, 82, 91, -16, 83, Blocks.AIR.getDefaultState());
        structure.fillWithBlocks(world, start, 91, -17, 86, 92, -17, 86, Blocks.CRACKED_STONE_BRICKS.getDefaultState());
        structure.fillWithBlocks(world, start, 91, -16, 41, 91, -16, 42, Blocks.CRACKED_STONE_BRICKS.getDefaultState());
        structure.fillWithBlocks(world, start, 91, -16, 43, 91, -16, 46, Blocks.STONE_BRICKS.getDefaultState());
        structure.fillWithBlocks(world, start, 91, -16, 47, 91, -16, 48, Blocks.CRACKED_STONE_BRICKS.getDefaultState());
        structure.fillWithBlocks(world, start, 91, -16, 73, 91, -16, 74, Blocks.STONE_BRICKS.getDefaultState());
        structure.fillWithBlocks(world, start, 91, -16, 79, 91, -16, 80, Blocks.AIR.getDefaultState());
        structure.fillWithBlocks(world, start, 91, -16, 84, 92, -16, 84, Blocks.STONE_BRICKS.getDefaultState());
        structure.fillWithBlocks(world, start, 91, -16, 85, 92, -16, 85, Blocks.CRACKED_STONE_BRICKS.getDefaultState());
        structure.fillWithBlocks(world, start, 91, -16, 86, 93, -16, 86, Blocks.STONE_BRICKS.getDefaultState());
        structure.fillWithBlocks(world, start, 91, -15, 76, 91, -15, 77, Blocks.CRACKED_STONE_BRICKS.getDefaultState());
        structure.fillWithBlocks(world, start, 91, -15, 78, 92, -14, 78, Blocks.STONE_BRICKS.getDefaultState());
        structure.fillWithBlocks(world, start, 91, -15, 79, 92, -15, 79, Blocks.CRACKED_STONE_BRICKS.getDefaultState());
        structure.fillWithBlocks(world, start, 91, -15, 80, 91, -15, 82, Blocks.STONE_BRICKS.getDefaultState());
        structure.fillWithBlocks(world, start, 91, -15, 85, 91, -15, 86, Blocks.STONE_BRICKS.getDefaultState());
        structure.fillWithBlocks(world, start, 91, -14, 72, 91, -14, 80, Blocks.STONE_BRICKS.getDefaultState());
        structure.fillWithBlocks(world, start, 91, -14, 81, 92, -14, 81, Blocks.MOSSY_STONE_BRICKS.getDefaultState());
        structure.fillWithBlocks(world, start, 91, -14, 83, 92, -14, 84, Blocks.STONE_BRICKS.getDefaultState());
        structure.fillWithBlocks(world, start, 91, -13, 73, 91, -12, 75, Blocks.STONE_BRICKS.getDefaultState());
        structure.fillWithBlocks(world, start, 91, -13, 77, 91, -11, 77, Blocks.STONE_BRICKS.getDefaultState());
        structure.fillWithBlocks(world, start, 91, -13, 78, 91, -13, 78, Blocks.CRACKED_STONE_BRICKS.getDefaultState());
        structure.fillWithBlocks(world, start, 91, -13, 79, 91, -12, 79, Blocks.MOSSY_STONE_BRICKS.getDefaultState());
        structure.fillWithBlocks(world, start, 91, -13, 80, 92, -13, 81, Blocks.STONE_BRICKS.getDefaultState());
        structure.fillWithBlocks(world, start, 91, -13, 83, 92, -13, 84, Blocks.STONE_BRICKS.getDefaultState());
        structure.fillWithBlocks(world, start, 91, -12, 72, 92, -12, 75, Blocks.STONE_BRICKS.getDefaultState());
        structure.fillWithBlocks(world, start, 91, -12, 76, 92, -12, 76, Blocks.CRACKED_STONE_BRICKS.getDefaultState());
        structure.fillWithBlocks(world, start, 91, -12, 78, 91, -12, 78, Blocks.STONE_BRICKS.getDefaultState());
        structure.fillWithBlocks(world, start, 91, -12, 80, 92, -12, 81, Blocks.STONE_BRICKS.getDefaultState());
        structure.fillWithBlocks(world, start, 91, -12, 82, 91, -11, 82, Blocks.CRACKED_STONE_BRICKS.getDefaultState());
        structure.fillWithBlocks(world, start, 91, -12, 83, 92, -12, 84, Blocks.STONE_BRICKS.getDefaultState());
        structure.fillWithBlocks(world, start, 91, -12, 85, 91, -11, 85, Blocks.AIR.getDefaultState());
        structure.fillWithBlocks(world, start, 91, -11, 45, 91, -10, 49, Blocks.STONE_BRICKS.getDefaultState());
        structure.fillWithBlocks(world, start, 91, -11, 72, 91, -11, 74, Blocks.CRACKED_STONE_BRICKS.getDefaultState());
        structure.fillWithBlocks(world, start, 91, -11, 75, 91, -11, 75, Blocks.STONE_BRICKS.getDefaultState());
        structure.fillWithBlocks(world, start, 91, -11, 78, 91, -11, 80, Blocks.STONE_BRICKS.getDefaultState());
        structure.fillWithBlocks(world, start, 91, -11, 81, 91, -11, 82, Blocks.CRACKED_STONE_BRICKS.getDefaultState());
        structure.fillWithBlocks(world, start, 91, -10, 41, 91, -10, 54, Blocks.STONE_BRICKS.getDefaultState());
        structure.fillWithBlocks(world, start, 91, -9, 53, 92, -9, 54, Blocks.STONE_BRICKS.getDefaultState());
        structure.fillWithBlocks(world, start, 91, -8, 41, 91, -8, 41, Blocks.STONE_BRICKS.getDefaultState());
        structure.fillWithBlocks(world, start, 91, -8, 53, 92, -8, 54, Blocks.STONE_BRICKS.getDefaultState());
        structure.fillWithBlocks(world, start, 91, -6, 53, 91, -6, 53, Blocks.STONE_BRICKS.getDefaultState());
        structure.fillWithBlocks(world, start, 91, -5, 40, 93, -5, 43, Blocks.STONE_BRICKS.getDefaultState());
        structure.fillWithBlocks(world, start, 91, -5, 99, 92, -5, 99, Blocks.CAVE_AIR.getDefaultState());
        structure.fillWithBlocks(world, start, 91, -4, 47, 94, -4, 54, Blocks.STONE_BRICKS.getDefaultState());
        structure.fillWithBlocks(world, start, 91, -3, 40, 92, -3, 42, Blocks.STONE_BRICKS.getDefaultState());
        structure.fillWithBlocks(world, start, 91, -3, 44, 93, -3, 46, Blocks.STONE_BRICKS.getDefaultState());
        structure.fillWithBlocks(world, start, 91, -3, 53, 92, -3, 54, Blocks.STONE_BRICKS.getDefaultState());
        structure.fillWithBlocks(world, start, 91, -2, 40, 93, -2, 44, Blocks.STONE_BRICKS.getDefaultState());
        structure.fillWithBlocks(world, start, 91, -2, 46, 94, -2, 54, Blocks.STONE_BRICKS.getDefaultState());
        structure.fillWithBlocks(world, start, 91, -1, 45, 92, -1, 47, Blocks.STONE_BRICKS.getDefaultState());
        structure.fillWithBlocks(world, start, 91, -1, 48, 91, -1, 49, Blocks.MOSSY_STONE_BRICKS.getDefaultState());
        structure.fillWithBlocks(world, start, 91, -1, 50, 94, -1, 53, Blocks.STONE_BRICKS.getDefaultState());
        structure.fillWithBlocks(world, start, 91, -1, 54, 92, -1, 54, Blocks.STONE_BRICKS.getDefaultState());
        structure.fillWithBlocks(world, start, 91, 0, 8, 91, 0, 9, Blocks.GRASS_BLOCK.getDefaultState().with(SnowyDirtBlock.SNOWY, false));
        structure.fillWithBlocks(world, start, 91, 0, 10, 91, 0, 15, Blocks.DIRT.getDefaultState());
        structure.fillWithBlocks(world, start, 91, 0, 16, 91, 0, 29, Blocks.STONE.getDefaultState());
        structure.fillWithBlocks(world, start, 91, 0, 30, 96, 0, 40, Blocks.DIRT.getDefaultState());
        structure.fillWithBlocks(world, start, 91, 0, 41, 91, 0, 77, Blocks.STONE.getDefaultState());
        structure.fillWithBlocks(world, start, 91, 0, 78, 93, 0, 81, Blocks.DIRT.getDefaultState());
        structure.fillWithBlocks(world, start, 91, 0, 84, 92, 0, 85, Blocks.GRASS_BLOCK.getDefaultState().with(SnowyDirtBlock.SNOWY, false));
        structure.fillWithBlocks(world, start, 91, 1, 10, 91, 1, 11, Blocks.GRASS_BLOCK.getDefaultState().with(SnowyDirtBlock.SNOWY, false));
        structure.fillWithBlocks(world, start, 91, 1, 12, 91, 1, 19, Blocks.DIRT.getDefaultState());
        structure.fillWithBlocks(world, start, 91, 1, 20, 91, 1, 22, Blocks.STONE.getDefaultState());
        structure.fillWithBlocks(world, start, 91, 1, 23, 95, 1, 46, Blocks.DIRT.getDefaultState());
        structure.fillWithBlocks(world, start, 91, 1, 47, 91, 1, 56, Blocks.STONE.getDefaultState());
        structure.fillWithBlocks(world, start, 91, 1, 60, 92, 1, 61, Blocks.DIRT.getDefaultState());
        structure.fillWithBlocks(world, start, 91, 1, 62, 93, 1, 67, Blocks.STONE.getDefaultState());
        structure.fillWithBlocks(world, start, 91, 1, 68, 92, 1, 73, Blocks.STONE.getDefaultState());
        structure.fillWithBlocks(world, start, 91, 1, 74, 91, 1, 75, Blocks.STONE.getDefaultState());
        structure.fillWithBlocks(world, start, 91, 1, 76, 93, 1, 79, Blocks.DIRT.getDefaultState());
        structure.fillWithBlocks(world, start, 91, 1, 82, 91, 1, 83, Blocks.GRASS_BLOCK.getDefaultState().with(SnowyDirtBlock.SNOWY, false));
        structure.fillWithBlocks(world, start, 91, 2, 12, 91, 2, 12, Blocks.GRASS_BLOCK.getDefaultState().with(SnowyDirtBlock.SNOWY, false));
        structure.fillWithBlocks(world, start, 91, 2, 13, 91, 2, 69, Blocks.DIRT.getDefaultState());
        structure.fillWithBlocks(world, start, 91, 2, 72, 94, 2, 76, Blocks.DIRT.getDefaultState());
        structure.fillWithBlocks(world, start, 91, 2, 80, 91, 2, 81, Blocks.GRASS_BLOCK.getDefaultState().with(SnowyDirtBlock.SNOWY, false));
        structure.fillWithBlocks(world, start, 91, 3, 13, 91, 3, 15, Blocks.GRASS_BLOCK.getDefaultState().with(SnowyDirtBlock.SNOWY, false));
        structure.fillWithBlocks(world, start, 91, 3, 16, 91, 3, 77, Blocks.DIRT.getDefaultState());
        structure.fillWithBlocks(world, start, 91, 3, 78, 91, 3, 79, Blocks.GRASS_BLOCK.getDefaultState().with(SnowyDirtBlock.SNOWY, false));
        structure.fillWithBlocks(world, start, 91, 4, 16, 91, 4, 19, Blocks.GRASS_BLOCK.getDefaultState().with(SnowyDirtBlock.SNOWY, false));
        structure.fillWithBlocks(world, start, 91, 4, 20, 91, 4, 75, Blocks.DIRT.getDefaultState());
        structure.fillWithBlocks(world, start, 91, 4, 76, 91, 4, 77, Blocks.GRASS_BLOCK.getDefaultState().with(SnowyDirtBlock.SNOWY, false));
        structure.fillWithBlocks(world, start, 91, 5, 20, 91, 5, 46, Blocks.GRASS_BLOCK.getDefaultState().with(SnowyDirtBlock.SNOWY, false));
        structure.fillWithBlocks(world, start, 91, 5, 47, 91, 5, 71, Blocks.DIRT.getDefaultState());
        structure.fillWithBlocks(world, start, 91, 5, 72, 92, 5, 73, Blocks.GRASS_BLOCK.getDefaultState().with(SnowyDirtBlock.SNOWY, false));
        structure.fillWithBlocks(world, start, 91, 6, 47, 91, 6, 71, Blocks.GRASS_BLOCK.getDefaultState().with(SnowyDirtBlock.SNOWY, false));
        structure.fillWithBlocks(world, start, 92, -50, -10, 92, -50, -10, Blocks.STONE_BRICKS.getDefaultState());
        structure.fillWithBlocks(world, start, 92, -50, 79, 93, -50, 80, Blocks.STONE_BRICKS.getDefaultState());
        structure.fillWithBlocks(world, start, 92, -49, 42, 94, -49, 44, Blocks.STONE_BRICKS.getDefaultState());
        structure.fillWithBlocks(world, start, 92, -49, 45, 92, -49, 46, Blocks.NETHERRACK.getDefaultState());
        structure.fillWithBlocks(world, start, 92, -49, 47, 96, -49, 47, Blocks.STONE_BRICKS.getDefaultState());
        structure.fillWithBlocks(world, start, 92, -49, 57, 96, -49, 57, Blocks.STONE_BRICKS.getDefaultState());
        structure.fillWithBlocks(world, start, 92, -49, 58, 93, -49, 58, Blocks.NETHERRACK.getDefaultState());
        structure.fillWithBlocks(world, start, 92, -49, 60, 94, -49, 62, Blocks.STONE_BRICKS.getDefaultState());
        structure.fillWithBlocks(world, start, 92, -49, 65, 92, -49, 65, Blocks.STONE_BRICK_WALL.getDefaultState().with(WallBlock.WATERLOGGED, false).with(WallBlock.UP, true).with(WallBlock.WALL_HEIGHT_NORTH, WallHeight.LOW).with(WallBlock.WALL_HEIGHT_SOUTH, WallHeight.LOW).with(WallBlock.WALL_HEIGHT_EAST, WallHeight.LOW).with(WallBlock.WALL_HEIGHT_WEST, WallHeight.LOW));
        structure.fillWithBlocks(world, start, 92, -48, -17, 93, -48, -16, Blocks.STONE_BRICKS.getDefaultState());
        structure.fillWithBlocks(world, start, 92, -48, -10, 92, -48, -10, Blocks.STONE_BRICKS.getDefaultState());
        structure.fillWithBlocks(world, start, 92, -48, 42, 93, -48, 43, Blocks.STONE_BRICKS.getDefaultState());
        structure.fillWithBlocks(world, start, 92, -48, 47, 92, -48, 57, Blocks.AIR.getDefaultState());
        structure.fillWithBlocks(world, start, 92, -48, 59, 95, -48, 62, Blocks.STONE_BRICKS.getDefaultState());
        structure.fillWithBlocks(world, start, 92, -47, 42, 94, -47, 44, Blocks.STONE_BRICKS.getDefaultState());
        structure.fillWithBlocks(world, start, 92, -47, 45, 92, -47, 46, Blocks.AIR.getDefaultState());
        structure.fillWithBlocks(world, start, 92, -47, 47, 93, -46, 47, Blocks.STONE_BRICKS.getDefaultState());
        structure.fillWithBlocks(world, start, 92, -47, 57, 95, -44, 57, Blocks.STONE_BRICKS.getDefaultState());
        structure.fillWithBlocks(world, start, 92, -47, 58, 92, -47, 59, Blocks.AIR.getDefaultState());
        structure.fillWithBlocks(world, start, 92, -47, 60, 94, -47, 62, Blocks.STONE_BRICKS.getDefaultState());
        structure.fillWithBlocks(world, start, 92, -46, 42, 93, -46, 47, Blocks.STONE_BRICKS.getDefaultState());
        structure.fillWithBlocks(world, start, 92, -46, 58, 93, -46, 62, Blocks.STONE_BRICKS.getDefaultState());
        structure.fillWithBlocks(world, start, 92, -45, 42, 92, -45, 42, Blocks.STONE_BRICKS.getDefaultState());
        structure.fillWithBlocks(world, start, 92, -45, 44, 96, -45, 48, Blocks.STONE_BRICKS.getDefaultState());
        structure.fillWithBlocks(world, start, 92, -45, 79, 93, -45, 80, Blocks.STONE_BRICKS.getDefaultState());
        structure.fillWithBlocks(world, start, 92, -44, 42, 93, -44, 48, Blocks.STONE_BRICKS.getDefaultState());
        structure.fillWithBlocks(world, start, 92, -44, 49, 92, -44, 55, Blocks.STONE_BRICK_STAIRS.getDefaultState().with(StairsBlock.FACING, Direction.EAST).with(StairsBlock.WATERLOGGED, false).with(StairsBlock.SHAPE, StairsShape.STRAIGHT).with(StairsBlock.HALF, Half.TOP));
        structure.fillWithBlocks(world, start, 92, -44, 59, 95, -44, 62, Blocks.STONE_BRICKS.getDefaultState());
        structure.fillWithBlocks(world, start, 92, -44, 67, 94, -44, 74, Blocks.STONE_BRICKS.getDefaultState());
        structure.fillWithBlocks(world, start, 92, -44, 77, 94, -44, 80, Blocks.STONE_BRICKS.getDefaultState());
        structure.fillWithBlocks(world, start, 92, -43, 49, 96, -43, 55, Blocks.STONE_BRICKS.getDefaultState());
        structure.fillWithBlocks(world, start, 92, -43, 73, 92, -43, 80, Blocks.STONE_BRICKS.getDefaultState());
        structure.fillWithBlocks(world, start, 92, -42, 45, 93, -42, 46, Blocks.STONE_BRICKS.getDefaultState());
        structure.fillWithBlocks(world, start, 92, -42, 66, 94, -42, 72, Blocks.STONE_BRICKS.getDefaultState());
        structure.fillWithBlocks(world, start, 92, -42, 74, 94, -42, 79, Blocks.STONE_BRICKS.getDefaultState());
        structure.fillWithBlocks(world, start, 92, -40, 19, 92, -40, 31, Blocks.STONE_BRICKS.getDefaultState());
        structure.fillWithBlocks(world, start, 92, -40, 33, 93, -40, 34, Blocks.STONE_BRICKS.getDefaultState());
        structure.fillWithBlocks(world, start, 92, -40, 35, 92, -40, 35, Blocks.STONE_BRICKS.getDefaultState());
        structure.fillWithBlocks(world, start, 92, -40, 36, 92, -40, 36, Blocks.MOSSY_STONE_BRICKS.getDefaultState());
        structure.fillWithBlocks(world, start, 92, -39, 22, 92, -39, 22, Blocks.AIR.getDefaultState());
        structure.fillWithBlocks(world, start, 92, -39, 31, 95, -39, 34, Blocks.AIR.getDefaultState());
        structure.fillWithBlocks(world, start, 92, -39, 36, 93, -38, 36, Blocks.AIR.getDefaultState());
        structure.fillWithBlocks(world, start, 92, -39, 38, 92, -39, 39, Blocks.STONE_BRICKS.getDefaultState());
        structure.fillWithBlocks(world, start, 92, -38, 19, 92, -38, 20, Blocks.STONE_BRICKS.getDefaultState());
        structure.fillWithBlocks(world, start, 92, -38, 22, 93, -38, 36, Blocks.AIR.getDefaultState());
        structure.fillWithBlocks(world, start, 92, -38, 38, 92, -38, 38, Blocks.MOSSY_STONE_BRICKS.getDefaultState());
        structure.fillWithBlocks(world, start, 92, -38, 39, 92, -36, 39, Blocks.MOSSY_COBBLESTONE.getDefaultState());
        structure.fillWithBlocks(world, start, 92, -37, 19, 92, -37, 21, Blocks.MOSSY_STONE_BRICKS.getDefaultState());
        structure.fillWithBlocks(world, start, 92, -37, 22, 93, -37, 36, Blocks.AIR.getDefaultState());
        structure.fillWithBlocks(world, start, 92, -37, 37, 93, -37, 37, Blocks.MOSSY_STONE_BRICKS.getDefaultState());
        structure.fillWithBlocks(world, start, 92, -36, 19, 92, -34, 19, Blocks.STONE_BRICKS.getDefaultState());
        structure.fillWithBlocks(world, start, 92, -36, 21, 92, -36, 22, Blocks.STONE_BRICKS.getDefaultState());
        structure.fillWithBlocks(world, start, 92, -36, 36, 92, -36, 38, Blocks.STONE_BRICKS.getDefaultState());
        structure.fillWithBlocks(world, start, 92, -35, 20, 92, -35, 20, Blocks.STONE_BRICKS.getDefaultState());
        structure.fillWithBlocks(world, start, 92, -35, 21, 92, -35, 21, Blocks.MOSSY_STONE_BRICKS.getDefaultState());
        structure.fillWithBlocks(world, start, 92, -35, 22, 92, -35, 23, Blocks.STONE_BRICKS.getDefaultState());
        structure.fillWithBlocks(world, start, 92, -35, 35, 93, -34, 35, Blocks.STONE_BRICKS.getDefaultState());
        structure.fillWithBlocks(world, start, 92, -35, 39, 93, -34, 39, Blocks.STONE_BRICKS.getDefaultState());
        structure.fillWithBlocks(world, start, 92, -34, 21, 92, -34, 21, Blocks.STONE_BRICKS.getDefaultState());
        structure.fillWithBlocks(world, start, 92, -34, 22, 92, -33, 22, Blocks.MOSSY_STONE_BRICKS.getDefaultState());
        structure.fillWithBlocks(world, start, 92, -34, 23, 92, -34, 25, Blocks.STONE_BRICKS.getDefaultState());
        structure.fillWithBlocks(world, start, 92, -34, 30, 93, -34, 31, Blocks.STONE_BRICKS.getDefaultState());
        structure.fillWithBlocks(world, start, 92, -34, 32, 92, -34, 32, Blocks.STONE_BRICKS.getDefaultState());
        structure.fillWithBlocks(world, start, 92, -34, 34, 92, -34, 36, Blocks.STONE_BRICKS.getDefaultState());
        structure.fillWithBlocks(world, start, 92, -34, 37, 93, -34, 37, Blocks.MOSSY_STONE_BRICKS.getDefaultState());
        structure.fillWithBlocks(world, start, 92, -33, 20, 93, -33, 20, Blocks.STONE_BRICKS.getDefaultState());
        structure.fillWithBlocks(world, start, 92, -33, 23, 92, -33, 25, Blocks.MOSSY_STONE_BRICKS.getDefaultState());
        structure.fillWithBlocks(world, start, 92, -33, 26, 92, -33, 30, Blocks.STONE_BRICKS.getDefaultState());
        structure.fillWithBlocks(world, start, 92, -33, 31, 92, -33, 33, Blocks.MOSSY_STONE_BRICKS.getDefaultState());
        structure.fillWithBlocks(world, start, 92, -33, 38, 92, -31, 38, Blocks.STONE_BRICKS.getDefaultState());
        structure.fillWithBlocks(world, start, 92, -33, 39, 92, -32, 39, Blocks.MOSSY_COBBLESTONE.getDefaultState());
        structure.fillWithBlocks(world, start, 92, -32, 20, 92, -31, 21, Blocks.STONE_BRICKS.getDefaultState());
        structure.fillWithBlocks(world, start, 92, -32, 22, 93, -32, 22, Blocks.STONE_BRICKS.getDefaultState());
        structure.fillWithBlocks(world, start, 92, -32, 23, 93, -32, 23, Blocks.MOSSY_STONE_BRICKS.getDefaultState());
        structure.fillWithBlocks(world, start, 92, -32, 24, 93, -32, 24, Blocks.MOSSY_COBBLESTONE.getDefaultState());
        structure.fillWithBlocks(world, start, 92, -32, 26, 92, -32, 28, Blocks.STONE_BRICKS.getDefaultState());
        structure.fillWithBlocks(world, start, 92, -32, 29, 92, -32, 31, Blocks.MOSSY_COBBLESTONE.getDefaultState());
        structure.fillWithBlocks(world, start, 92, -32, 32, 92, -31, 32, Blocks.STONE_BRICKS.getDefaultState());
        structure.fillWithBlocks(world, start, 92, -32, 33, 93, -32, 34, Blocks.MOSSY_STONE_BRICKS.getDefaultState());
        structure.fillWithBlocks(world, start, 92, -32, 35, 92, -32, 36, Blocks.MOSSY_STONE_BRICKS.getDefaultState());
        structure.fillWithBlocks(world, start, 92, -32, 37, 92, -32, 38, Blocks.STONE_BRICKS.getDefaultState());
        structure.fillWithBlocks(world, start, 92, -31, 19, 93, -31, 19, Blocks.MOSSY_STONE_BRICKS.getDefaultState());
        structure.fillWithBlocks(world, start, 92, -31, 22, 92, -31, 22, Blocks.MOSSY_COBBLESTONE.getDefaultState());
        structure.fillWithBlocks(world, start, 92, -31, 23, 92, -31, 23, Blocks.STONE_BRICKS.getDefaultState());
        structure.fillWithBlocks(world, start, 92, -31, 25, 93, -31, 26, Blocks.STONE_BRICKS.getDefaultState());
        structure.fillWithBlocks(world, start, 92, -31, 28, 95, -31, 28, Blocks.STONE_BRICKS.getDefaultState());
        structure.fillWithBlocks(world, start, 92, -31, 30, 92, -31, 34, Blocks.STONE_BRICKS.getDefaultState());
        structure.fillWithBlocks(world, start, 92, -31, 39, 97, -31, 39, Blocks.STONE_BRICKS.getDefaultState());
        structure.fillWithBlocks(world, start, 92, -20, 43, 92, -19, 43, Blocks.MOSSY_STONE_BRICKS.getDefaultState());
        structure.fillWithBlocks(world, start, 92, -20, 45, 93, -20, 48, Blocks.STONE_BRICKS.getDefaultState());
        structure.fillWithBlocks(world, start, 92, -20, 49, 93, -20, 49, Blocks.CRACKED_STONE_BRICKS.getDefaultState());
        structure.fillWithBlocks(world, start, 92, -20, 72, 93, -20, 73, Blocks.STONE_BRICKS.getDefaultState());
        structure.fillWithBlocks(world, start, 92, -20, 75, 92, -20, 75, Blocks.MOSSY_STONE_BRICKS.getDefaultState());
        structure.fillWithBlocks(world, start, 92, -20, 77, 93, -20, 77, Blocks.MOSSY_STONE_BRICKS.getDefaultState());
        structure.fillWithBlocks(world, start, 92, -20, 78, 92, -17, 78, Blocks.STONE_BRICKS.getDefaultState());
        structure.fillWithBlocks(world, start, 92, -20, 80, 92, -20, 80, Blocks.STONE_BRICKS.getDefaultState());
        structure.fillWithBlocks(world, start, 92, -20, 82, 92, -18, 82, Blocks.STONE_BRICKS.getDefaultState());
        structure.fillWithBlocks(world, start, 92, -20, 84, 92, -19, 86, Blocks.STONE_BRICKS.getDefaultState());
        structure.fillWithBlocks(world, start, 92, -19, 44, 92, -19, 44, Blocks.STONE_BRICKS.getDefaultState());
        structure.fillWithBlocks(world, start, 92, -19, 50, 94, -19, 50, Blocks.STONE_BRICKS.getDefaultState());
        structure.fillWithBlocks(world, start, 92, -19, 73, 92, -19, 86, Blocks.STONE_BRICKS.getDefaultState());
        structure.fillWithBlocks(world, start, 92, -18, 42, 92, -16, 42, Blocks.STONE_BRICKS.getDefaultState());
        structure.fillWithBlocks(world, start, 92, -18, 44, 92, -17, 44, Blocks.STONE_BRICKS.getDefaultState());
        structure.fillWithBlocks(world, start, 92, -18, 50, 92, -17, 50, Blocks.CRACKED_STONE_BRICKS.getDefaultState());
        structure.fillWithBlocks(world, start, 92, -18, 72, 93, -18, 72, Blocks.CRACKED_STONE_BRICKS.getDefaultState());
        structure.fillWithBlocks(world, start, 92, -18, 73, 93, -18, 74, Blocks.STONE_BRICKS.getDefaultState());
        structure.fillWithBlocks(world, start, 92, -18, 76, 92, -14, 76, Blocks.STONE_BRICKS.getDefaultState());
        structure.fillWithBlocks(world, start, 92, -18, 81, 92, -18, 84, Blocks.STONE_BRICKS.getDefaultState());
        structure.fillWithBlocks(world, start, 92, -18, 85, 92, -18, 86, Blocks.CRACKED_STONE_BRICKS.getDefaultState());
        structure.fillWithBlocks(world, start, 92, -17, 41, 92, -16, 42, Blocks.STONE_BRICKS.getDefaultState());
        structure.fillWithBlocks(world, start, 92, -17, 75, 92, -17, 78, Blocks.STONE_BRICKS.getDefaultState());
        structure.fillWithBlocks(world, start, 92, -17, 79, 92, -17, 79, Blocks.CRACKED_STONE_BRICKS.getDefaultState());
        structure.fillWithBlocks(world, start, 92, -17, 80, 92, -16, 80, Blocks.STONE_BRICKS.getDefaultState());
        structure.fillWithBlocks(world, start, 92, -17, 81, 93, -17, 81, Blocks.MOSSY_STONE_BRICKS.getDefaultState());
        structure.fillWithBlocks(world, start, 92, -17, 82, 93, -17, 82, Blocks.CRACKED_STONE_BRICKS.getDefaultState());
        structure.fillWithBlocks(world, start, 92, -17, 83, 92, -17, 84, Blocks.STONE_BRICKS.getDefaultState());
        structure.fillWithBlocks(world, start, 92, -16, 46, 92, -16, 46, Blocks.STONE_BRICKS.getDefaultState());
        structure.fillWithBlocks(world, start, 92, -16, 47, 92, -16, 47, Blocks.CRACKED_STONE_BRICKS.getDefaultState());
        structure.fillWithBlocks(world, start, 92, -16, 48, 92, -16, 49, Blocks.STONE_BRICKS.getDefaultState());
        structure.fillWithBlocks(world, start, 92, -16, 73, 93, -16, 73, Blocks.CRACKED_STONE_BRICKS.getDefaultState());
        structure.fillWithBlocks(world, start, 92, -16, 75, 93, -16, 77, Blocks.STONE_BRICKS.getDefaultState());
        structure.fillWithBlocks(world, start, 92, -16, 79, 92, -16, 81, Blocks.STONE_BRICKS.getDefaultState());
        structure.fillWithBlocks(world, start, 92, -16, 83, 92, -16, 83, Blocks.MOSSY_STONE_BRICKS.getDefaultState());
        structure.fillWithBlocks(world, start, 92, -15, 74, 92, -15, 75, Blocks.CRACKED_STONE_BRICKS.getDefaultState());
        structure.fillWithBlocks(world, start, 92, -15, 82, 93, -15, 85, Blocks.STONE_BRICKS.getDefaultState());
        structure.fillWithBlocks(world, start, 92, -14, 72, 92, -11, 72, Blocks.STONE_BRICKS.getDefaultState());
        structure.fillWithBlocks(world, start, 92, -14, 73, 92, -14, 74, Blocks.MOSSY_STONE_BRICKS.getDefaultState());
        structure.fillWithBlocks(world, start, 92, -14, 75, 92, -14, 79, Blocks.STONE_BRICKS.getDefaultState());
        structure.fillWithBlocks(world, start, 92, -14, 82, 92, -14, 86, Blocks.STONE_BRICKS.getDefaultState());
        structure.fillWithBlocks(world, start, 92, -13, 73, 92, -13, 74, Blocks.AIR.getDefaultState());
        structure.fillWithBlocks(world, start, 92, -13, 76, 92, -13, 77, Blocks.MOSSY_STONE_BRICKS.getDefaultState());
        structure.fillWithBlocks(world, start, 92, -13, 78, 92, -12, 78, Blocks.STONE_BRICKS.getDefaultState());
        structure.fillWithBlocks(world, start, 92, -13, 82, 92, -13, 86, Blocks.STONE_BRICKS.getDefaultState());
        structure.fillWithBlocks(world, start, 92, -12, 77, 93, -12, 80, Blocks.STONE_BRICKS.getDefaultState());
        structure.fillWithBlocks(world, start, 92, -12, 82, 93, -12, 83, Blocks.STONE_BRICKS.getDefaultState());
        structure.fillWithBlocks(world, start, 92, -11, 74, 92, -11, 74, Blocks.STONE_BRICKS.getDefaultState());
        structure.fillWithBlocks(world, start, 92, -11, 76, 92, -11, 77, Blocks.STONE_BRICKS.getDefaultState());
        structure.fillWithBlocks(world, start, 92, -11, 79, 93, -11, 82, Blocks.STONE_BRICKS.getDefaultState());
        structure.fillWithBlocks(world, start, 92, -11, 83, 92, -11, 84, Blocks.CRACKED_STONE_BRICKS.getDefaultState());
        structure.fillWithBlocks(world, start, 92, -11, 85, 93, -11, 85, Blocks.MOSSY_STONE_BRICKS.getDefaultState());
        structure.fillWithBlocks(world, start, 92, -10, 41, 92, -10, 41, Blocks.STONE_BRICKS.getDefaultState());
        structure.fillWithBlocks(world, start, 92, -10, 43, 97, -10, 48, Blocks.STONE_BRICKS.getDefaultState());
        structure.fillWithBlocks(world, start, 92, -9, 42, 92, -1, 42, Blocks.STONE_BRICKS.getDefaultState());
        structure.fillWithBlocks(world, start, 92, -9, 52, 92, -9, 54, Blocks.STONE_BRICKS.getDefaultState());
        structure.fillWithBlocks(world, start, 92, -8, 41, 92, -7, 42, Blocks.STONE_BRICKS.getDefaultState());
        structure.fillWithBlocks(world, start, 92, -8, 52, 92, -8, 54, Blocks.STONE_BRICKS.getDefaultState());
        structure.fillWithBlocks(world, start, 92, -7, 52, 92, -7, 54, Blocks.STONE_BRICKS.getDefaultState());
        structure.fillWithBlocks(world, start, 92, -6, 52, 92, -6, 54, Blocks.STONE_BRICKS.getDefaultState());
        structure.fillWithBlocks(world, start, 92, -6, 98, 93, -6, 99, Blocks.CAVE_AIR.getDefaultState());
        structure.fillWithBlocks(world, start, 92, -4, 40, 95, -4, 44, Blocks.STONE_BRICKS.getDefaultState());
        structure.fillWithBlocks(world, start, 92, -4, 45, 94, -4, 54, Blocks.STONE_BRICKS.getDefaultState());
        structure.fillWithBlocks(world, start, 92, -3, 43, 95, -3, 46, Blocks.STONE_BRICKS.getDefaultState());
        structure.fillWithBlocks(world, start, 92, -3, 48, 96, -3, 54, Blocks.STONE_BRICKS.getDefaultState());
        structure.fillWithBlocks(world, start, 92, -2, 45, 95, -2, 49, Blocks.STONE_BRICKS.getDefaultState());
        structure.fillWithBlocks(world, start, 92, -1, 48, 97, -1, 53, Blocks.STONE_BRICKS.getDefaultState());
        structure.fillWithBlocks(world, start, 92, 0, 9, 92, 0, 10, Blocks.GRASS_BLOCK.getDefaultState().with(SnowyDirtBlock.SNOWY, false));
        structure.fillWithBlocks(world, start, 92, 0, 11, 92, 0, 17, Blocks.DIRT.getDefaultState());
        structure.fillWithBlocks(world, start, 92, 0, 18, 92, 0, 21, Blocks.STONE.getDefaultState());
        structure.fillWithBlocks(world, start, 92, 0, 22, 96, 0, 41, Blocks.DIRT.getDefaultState());
        structure.fillWithBlocks(world, start, 92, 0, 42, 92, 0, 76, Blocks.STONE.getDefaultState());
        structure.fillWithBlocks(world, start, 92, 0, 77, 94, 0, 80, Blocks.DIRT.getDefaultState());
        structure.fillWithBlocks(world, start, 92, 0, 83, 93, 0, 84, Blocks.GRASS_BLOCK.getDefaultState().with(SnowyDirtBlock.SNOWY, false));
        structure.fillWithBlocks(world, start, 92, 1, 11, 92, 1, 12, Blocks.GRASS_BLOCK.getDefaultState().with(SnowyDirtBlock.SNOWY, false));
        structure.fillWithBlocks(world, start, 92, 1, 13, 92, 1, 51, Blocks.DIRT.getDefaultState());
        structure.fillWithBlocks(world, start, 92, 1, 52, 92, 1, 56, Blocks.STONE.getDefaultState());
        structure.fillWithBlocks(world, start, 92, 1, 74, 94, 1, 78, Blocks.DIRT.getDefaultState());
        structure.fillWithBlocks(world, start, 92, 1, 81, 92, 1, 82, Blocks.GRASS_BLOCK.getDefaultState().with(SnowyDirtBlock.SNOWY, false));
        structure.fillWithBlocks(world, start, 92, 2, 13, 92, 2, 14, Blocks.GRASS_BLOCK.getDefaultState().with(SnowyDirtBlock.SNOWY, false));
        structure.fillWithBlocks(world, start, 92, 2, 15, 92, 2, 69, Blocks.DIRT.getDefaultState());
        structure.fillWithBlocks(world, start, 92, 2, 71, 95, 2, 74, Blocks.DIRT.getDefaultState());
        structure.fillWithBlocks(world, start, 92, 2, 79, 92, 2, 80, Blocks.GRASS_BLOCK.getDefaultState().with(SnowyDirtBlock.SNOWY, false));
        structure.fillWithBlocks(world, start, 92, 3, 15, 92, 3, 17, Blocks.GRASS_BLOCK.getDefaultState().with(SnowyDirtBlock.SNOWY, false));
        structure.fillWithBlocks(world, start, 92, 3, 18, 92, 3, 76, Blocks.DIRT.getDefaultState());
        structure.fillWithBlocks(world, start, 92, 3, 77, 92, 3, 78, Blocks.GRASS_BLOCK.getDefaultState().with(SnowyDirtBlock.SNOWY, false));
        structure.fillWithBlocks(world, start, 92, 4, 18, 92, 4, 29, Blocks.GRASS_BLOCK.getDefaultState().with(SnowyDirtBlock.SNOWY, false));
        structure.fillWithBlocks(world, start, 92, 4, 30, 92, 4, 35, Blocks.DIRT.getDefaultState());
        structure.fillWithBlocks(world, start, 92, 4, 36, 93, 4, 37, Blocks.GRASS_BLOCK.getDefaultState().with(SnowyDirtBlock.SNOWY, false));
        structure.fillWithBlocks(world, start, 92, 4, 38, 92, 4, 73, Blocks.DIRT.getDefaultState());
        structure.fillWithBlocks(world, start, 92, 4, 74, 93, 4, 75, Blocks.GRASS_BLOCK.getDefaultState().with(SnowyDirtBlock.SNOWY, false));
        structure.fillWithBlocks(world, start, 92, 5, 30, 92, 5, 35, Blocks.GRASS_BLOCK.getDefaultState().with(SnowyDirtBlock.SNOWY, false));
        structure.fillWithBlocks(world, start, 92, 5, 38, 92, 5, 51, Blocks.GRASS_BLOCK.getDefaultState().with(SnowyDirtBlock.SNOWY, false));
        structure.fillWithBlocks(world, start, 92, 5, 52, 92, 5, 70, Blocks.DIRT.getDefaultState());
        structure.fillWithBlocks(world, start, 92, 5, 71, 93, 5, 72, Blocks.GRASS_BLOCK.getDefaultState().with(SnowyDirtBlock.SNOWY, false));
        structure.fillWithBlocks(world, start, 92, 6, 52, 92, 6, 70, Blocks.GRASS_BLOCK.getDefaultState().with(SnowyDirtBlock.SNOWY, false));
        structure.fillWithBlocks(world, start, 93, -50, -21, 94, -50, -5, Blocks.STONE_BRICKS.getDefaultState());
        structure.fillWithBlocks(world, start, 93, -50, 64, 94, -50, 80, Blocks.STONE_BRICKS.getDefaultState());
        structure.fillWithBlocks(world, start, 93, -49, -21, 94, -49, -20, Blocks.STONE_BRICKS.getDefaultState());
        structure.fillWithBlocks(world, start, 93, -49, -19, 93, -45, -15, Blocks.STONE_BRICKS.getDefaultState());
        structure.fillWithBlocks(world, start, 93, -49, -14, 95, -49, -12, Blocks.AIR.getDefaultState());
        structure.fillWithBlocks(world, start, 93, -49, -11, 93, -49, -5, Blocks.STONE_BRICKS.getDefaultState());
        structure.fillWithBlocks(world, start, 93, -49, 45, 93, -49, 45, Blocks.STONE_BRICKS.getDefaultState());
        structure.fillWithBlocks(world, start, 93, -49, 48, 93, -48, 49, Blocks.AIR.getDefaultState());
        structure.fillWithBlocks(world, start, 93, -49, 50, 93, -49, 50, Blocks.STONE_BRICKS.getDefaultState());
        structure.fillWithBlocks(world, start, 93, -49, 51, 93, -47, 53, Blocks.AIR.getDefaultState());
        structure.fillWithBlocks(world, start, 93, -49, 54, 93, -49, 54, Blocks.STONE_BRICKS.getDefaultState());
        structure.fillWithBlocks(world, start, 93, -49, 55, 93, -48, 56, Blocks.AIR.getDefaultState());
        structure.fillWithBlocks(world, start, 93, -49, 59, 96, -49, 62, Blocks.STONE_BRICKS.getDefaultState());
        structure.fillWithBlocks(world, start, 93, -49, 65, 93, -49, 65, Blocks.STONE_BRICKS.getDefaultState());
        structure.fillWithBlocks(world, start, 93, -49, 67, 93, -49, 68, Blocks.STONE_BRICK_WALL.getDefaultState().with(WallBlock.WATERLOGGED, false).with(WallBlock.UP, true).with(WallBlock.WALL_HEIGHT_NORTH, WallHeight.LOW).with(WallBlock.WALL_HEIGHT_SOUTH, WallHeight.LOW).with(WallBlock.WALL_HEIGHT_EAST, WallHeight.LOW).with(WallBlock.WALL_HEIGHT_WEST, WallHeight.LOW));
        structure.fillWithBlocks(world, start, 93, -49, 69, 93, -49, 69, Blocks.STONE_BRICKS.getDefaultState());
        structure.fillWithBlocks(world, start, 93, -49, 71, 93, -49, 74, Blocks.STONE_BRICK_WALL.getDefaultState().with(WallBlock.WATERLOGGED, false).with(WallBlock.UP, false).with(WallBlock.WALL_HEIGHT_NORTH, WallHeight.LOW).with(WallBlock.WALL_HEIGHT_SOUTH, WallHeight.LOW).with(WallBlock.WALL_HEIGHT_EAST, WallHeight.LOW).with(WallBlock.WALL_HEIGHT_WEST, WallHeight.LOW));
        structure.fillWithBlocks(world, start, 93, -49, 75, 93, -49, 75, Blocks.STONE_BRICKS.getDefaultState());
        structure.fillWithBlocks(world, start, 93, -49, 77, 93, -49, 78, Blocks.STONE_BRICK_WALL.getDefaultState().with(WallBlock.WATERLOGGED, false).with(WallBlock.UP, true).with(WallBlock.WALL_HEIGHT_NORTH, WallHeight.LOW).with(WallBlock.WALL_HEIGHT_SOUTH, WallHeight.LOW).with(WallBlock.WALL_HEIGHT_EAST, WallHeight.LOW).with(WallBlock.WALL_HEIGHT_WEST, WallHeight.LOW));
        structure.fillWithBlocks(world, start, 93, -49, 79, 94, -49, 80, Blocks.STONE_BRICKS.getDefaultState());
        structure.fillWithBlocks(world, start, 93, -48, -21, 94, -48, -20, Blocks.STONE_BRICKS.getDefaultState());
        structure.fillWithBlocks(world, start, 93, -48, -14, 95, -48, -12, Blocks.AIR.getDefaultState());
        structure.fillWithBlocks(world, start, 93, -48, -11, 93, -48, -5, Blocks.STONE_BRICKS.getDefaultState());
        structure.fillWithBlocks(world, start, 93, -48, 44, 96, -48, 47, Blocks.STONE_BRICKS.getDefaultState());
        structure.fillWithBlocks(world, start, 93, -48, 50, 93, -48, 50, Blocks.STONE_BRICKS.getDefaultState());
        structure.fillWithBlocks(world, start, 93, -48, 54, 93, -48, 54, Blocks.STONE_BRICKS.getDefaultState());
        structure.fillWithBlocks(world, start, 93, -48, 57, 96, -48, 62, Blocks.STONE_BRICKS.getDefaultState());
        structure.fillWithBlocks(world, start, 93, -48, 65, 93, -48, 65, Blocks.STONE_BRICKS.getDefaultState());
        structure.fillWithBlocks(world, start, 93, -48, 66, 93, -46, 68, Blocks.AIR.getDefaultState());
        structure.fillWithBlocks(world, start, 93, -48, 69, 93, -48, 69, Blocks.STONE_BRICKS.getDefaultState());
        structure.fillWithBlocks(world, start, 93, -48, 75, 93, -48, 75, Blocks.STONE_BRICKS.getDefaultState());
        structure.fillWithBlocks(world, start, 93, -48, 76, 93, -46, 78, Blocks.AIR.getDefaultState());
        structure.fillWithBlocks(world, start, 93, -48, 79, 93, -47, 80, Blocks.STONE_BRICKS.getDefaultState());
        structure.fillWithBlocks(world, start, 93, -47, -21, 94, -47, -20, Blocks.STONE_BRICKS.getDefaultState());
        structure.fillWithBlocks(world, start, 93, -47, -14, 95, -47, -12, Blocks.AIR.getDefaultState());
        structure.fillWithBlocks(world, start, 93, -47, -11, 93, -47, -5, Blocks.STONE_BRICKS.getDefaultState());
        structure.fillWithBlocks(world, start, 93, -47, 45, 93, -47, 45, Blocks.STONE_BRICKS.getDefaultState());
        structure.fillWithBlocks(world, start, 93, -47, 46, 93, -47, 46, Blocks.AIR.getDefaultState());
        structure.fillWithBlocks(world, start, 93, -47, 48, 93, -46, 49, Blocks.AIR.getDefaultState());
        structure.fillWithBlocks(world, start, 93, -47, 50, 93, -47, 50, Blocks.STONE_BRICKS.getDefaultState());
        structure.fillWithBlocks(world, start, 93, -47, 54, 93, -47, 54, Blocks.STONE_BRICKS.getDefaultState());
        structure.fillWithBlocks(world, start, 93, -47, 55, 93, -46, 56, Blocks.AIR.getDefaultState());
        structure.fillWithBlocks(world, start, 93, -47, 59, 96, -47, 62, Blocks.STONE_BRICKS.getDefaultState());
        structure.fillWithBlocks(world, start, 93, -47, 65, 93, -47, 65, Blocks.STONE_BRICKS.getDefaultState());
        structure.fillWithBlocks(world, start, 93, -47, 69, 93, -47, 69, Blocks.STONE_BRICKS.getDefaultState());
        structure.fillWithBlocks(world, start, 93, -47, 75, 93, -47, 75, Blocks.STONE_BRICKS.getDefaultState());
        structure.fillWithBlocks(world, start, 93, -46, -21, 94, -46, -20, Blocks.STONE_BRICKS.getDefaultState());
        structure.fillWithBlocks(world, start, 93, -46, -14, 93, -44, -12, Blocks.STONE_BRICKS.getDefaultState());
        structure.fillWithBlocks(world, start, 93, -46, -11, 93, -46, -7, Blocks.STONE_BRICKS.getDefaultState());
        structure.fillWithBlocks(world, start, 93, -46, -5, 103, -44, -5, Blocks.STONE_BRICKS.getDefaultState());
        structure.fillWithBlocks(world, start, 93, -46, 50, 93, -46, 50, Blocks.STONE_BRICKS.getDefaultState());
        structure.fillWithBlocks(world, start, 93, -46, 51, 93, -46, 53, Blocks.AIR.getDefaultState());
        structure.fillWithBlocks(world, start, 93, -46, 54, 93, -46, 54, Blocks.STONE_BRICKS.getDefaultState());
        structure.fillWithBlocks(world, start, 93, -46, 65, 93, -46, 65, Blocks.STONE_BRICKS.getDefaultState());
        structure.fillWithBlocks(world, start, 93, -46, 69, 93, -46, 69, Blocks.STONE_BRICKS.getDefaultState());
        structure.fillWithBlocks(world, start, 93, -46, 75, 93, -46, 75, Blocks.STONE_BRICKS.getDefaultState());
        structure.fillWithBlocks(world, start, 93, -46, 79, 94, -46, 80, Blocks.STONE_BRICKS.getDefaultState());
        structure.fillWithBlocks(world, start, 93, -45, -21, 94, -45, -12, Blocks.STONE_BRICKS.getDefaultState());
        structure.fillWithBlocks(world, start, 93, -45, -10, 94, -45, -5, Blocks.STONE_BRICKS.getDefaultState());
        structure.fillWithBlocks(world, start, 93, -45, 42, 96, -45, 50, Blocks.STONE_BRICKS.getDefaultState());
        structure.fillWithBlocks(world, start, 93, -45, 51, 94, -45, 62, Blocks.STONE_BRICKS.getDefaultState());
        structure.fillWithBlocks(world, start, 93, -45, 66, 94, -45, 80, Blocks.STONE_BRICKS.getDefaultState());
        structure.fillWithBlocks(world, start, 93, -44, -21, 93, -44, -7, Blocks.STONE_BRICKS.getDefaultState());
        structure.fillWithBlocks(world, start, 93, -44, 49, 96, -44, 57, Blocks.STONE_BRICKS.getDefaultState());
        structure.fillWithBlocks(world, start, 93, -44, 58, 93, -44, 62, Blocks.STONE_BRICKS.getDefaultState());
        structure.fillWithBlocks(world, start, 93, -44, 76, 94, -44, 80, Blocks.STONE_BRICKS.getDefaultState());
        structure.fillWithBlocks(world, start, 93, -43, -21, 98, -43, -10, Blocks.STONE_BRICKS.getDefaultState());
        structure.fillWithBlocks(world, start, 93, -43, -9, 95, -43, -6, Blocks.STONE_BRICKS.getDefaultState());
        structure.fillWithBlocks(world, start, 93, -43, -5, 93, -42, -5, Blocks.STONE_BRICKS.getDefaultState());
        structure.fillWithBlocks(world, start, 93, -43, 57, 95, -43, 62, Blocks.STONE_BRICKS.getDefaultState());
        structure.fillWithBlocks(world, start, 93, -43, 71, 94, -43, 73, Blocks.STONE_BRICKS.getDefaultState());
        structure.fillWithBlocks(world, start, 93, -43, 75, 94, -43, 80, Blocks.STONE_BRICKS.getDefaultState());
        structure.fillWithBlocks(world, start, 93, -42, -21, 95, -42, -19, Blocks.STONE_BRICKS.getDefaultState());
        structure.fillWithBlocks(world, start, 93, -42, -18, 94, -42, -10, Blocks.STONE_BRICKS.getDefaultState());
        structure.fillWithBlocks(world, start, 93, -42, -9, 93, -42, -5, Blocks.STONE_BRICKS.getDefaultState());
        structure.fillWithBlocks(world, start, 93, -42, 42, 94, -42, 43, Blocks.STONE_BRICKS.getDefaultState());
        structure.fillWithBlocks(world, start, 93, -42, 47, 94, -42, 62, Blocks.STONE_BRICKS.getDefaultState());
        structure.fillWithBlocks(world, start, 93, -42, 64, 94, -42, 80, Blocks.STONE_BRICKS.getDefaultState());
        structure.fillWithBlocks(world, start, 93, -41, -21, 96, -41, -8, Blocks.STONE_BRICKS.getDefaultState());
        structure.fillWithBlocks(world, start, 93, -41, -7, 94, -41, -6, Blocks.STONE_BRICKS.getDefaultState());
        structure.fillWithBlocks(world, start, 93, -41, 30, 93, -41, 31, Blocks.STONE_BRICKS.getDefaultState());
        structure.fillWithBlocks(world, start, 93, -40, 19, 93, -40, 19, Blocks.MOSSY_STONE_BRICKS.getDefaultState());
        structure.fillWithBlocks(world, start, 93, -40, 20, 93, -37, 20, Blocks.STONE_BRICKS.getDefaultState());
        structure.fillWithBlocks(world, start, 93, -40, 21, 93, -40, 22, Blocks.MOSSY_STONE_BRICKS.getDefaultState());
        structure.fillWithBlocks(world, start, 93, -40, 23, 93, -40, 27, Blocks.STONE_BRICKS.getDefaultState());
        structure.fillWithBlocks(world, start, 93, -40, 28, 93, -40, 28, Blocks.MOSSY_STONE_BRICKS.getDefaultState());
        structure.fillWithBlocks(world, start, 93, -40, 29, 93, -40, 30, Blocks.STONE_BRICKS.getDefaultState());
        structure.fillWithBlocks(world, start, 93, -40, 35, 93, -40, 35, Blocks.MOSSY_COBBLESTONE.getDefaultState());
        structure.fillWithBlocks(world, start, 93, -40, 37, 93, -40, 37, Blocks.MOSSY_STONE_BRICKS.getDefaultState());
        structure.fillWithBlocks(world, start, 93, -40, 38, 93, -40, 38, Blocks.STONE_BRICKS.getDefaultState());
        structure.fillWithBlocks(world, start, 93, -39, 19, 93, -39, 21, Blocks.STONE_BRICKS.getDefaultState());
        structure.fillWithBlocks(world, start, 93, -39, 22, 93, -37, 36, Blocks.AIR.getDefaultState());
        structure.fillWithBlocks(world, start, 93, -39, 37, 98, -39, 37, Blocks.STONE_BRICKS.getDefaultState());
        structure.fillWithBlocks(world, start, 93, -39, 38, 94, -39, 38, Blocks.MOSSY_STONE_BRICKS.getDefaultState());
        structure.fillWithBlocks(world, start, 93, -38, 19, 93, -35, 19, Blocks.MOSSY_STONE_BRICKS.getDefaultState());
        structure.fillWithBlocks(world, start, 93, -38, 21, 93, -38, 21, Blocks.STONE_BRICKS.getDefaultState());
        structure.fillWithBlocks(world, start, 93, -38, 37, 93, -38, 39, Blocks.MOSSY_STONE_BRICKS.getDefaultState());
        structure.fillWithBlocks(world, start, 93, -37, 21, 93, -37, 21, Blocks.STONE_BRICKS.getDefaultState());
        structure.fillWithBlocks(world, start, 93, -37, 39, 94, -37, 39, Blocks.STONE_BRICKS.getDefaultState());
        structure.fillWithBlocks(world, start, 93, -36, 21, 93, -36, 21, Blocks.AIR.getDefaultState());
        structure.fillWithBlocks(world, start, 93, -36, 22, 93, -36, 22, Blocks.STONE_BRICKS.getDefaultState());
        structure.fillWithBlocks(world, start, 93, -36, 37, 93, -36, 37, Blocks.STONE_BRICKS.getDefaultState());
        structure.fillWithBlocks(world, start, 93, -35, 21, 95, -34, 21, Blocks.STONE_BRICKS.getDefaultState());
        structure.fillWithBlocks(world, start, 93, -35, 22, 93, -35, 22, Blocks.MOSSY_STONE_BRICKS.getDefaultState());
        structure.fillWithBlocks(world, start, 93, -35, 23, 93, -34, 23, Blocks.STONE_BRICKS.getDefaultState());
        structure.fillWithBlocks(world, start, 93, -35, 37, 93, -35, 38, Blocks.MOSSY_STONE_BRICKS.getDefaultState());
        structure.fillWithBlocks(world, start, 93, -34, 19, 93, -34, 19, Blocks.STONE_BRICKS.getDefaultState());
        structure.fillWithBlocks(world, start, 93, -34, 22, 93, -34, 23, Blocks.STONE_BRICKS.getDefaultState());
        structure.fillWithBlocks(world, start, 93, -34, 27, 94, -34, 31, Blocks.STONE_BRICKS.getDefaultState());
        structure.fillWithBlocks(world, start, 93, -34, 33, 93, -34, 33, Blocks.STONE_BRICKS.getDefaultState());
        structure.fillWithBlocks(world, start, 93, -34, 34, 93, -31, 34, Blocks.MOSSY_STONE_BRICKS.getDefaultState());
        structure.fillWithBlocks(world, start, 93, -34, 36, 93, -34, 37, Blocks.MOSSY_STONE_BRICKS.getDefaultState());
        structure.fillWithBlocks(world, start, 93, -34, 38, 93, -34, 39, Blocks.STONE_BRICKS.getDefaultState());
        structure.fillWithBlocks(world, start, 93, -33, 19, 93, -33, 20, Blocks.STONE_BRICKS.getDefaultState());
        structure.fillWithBlocks(world, start, 93, -33, 21, 93, -33, 22, Blocks.AIR.getDefaultState());
        structure.fillWithBlocks(world, start, 93, -33, 23, 93, -32, 23, Blocks.MOSSY_STONE_BRICKS.getDefaultState());
        structure.fillWithBlocks(world, start, 93, -33, 24, 93, -33, 24, Blocks.STONE_BRICKS.getDefaultState());
        structure.fillWithBlocks(world, start, 93, -33, 26, 93, -32, 26, Blocks.AIR.getDefaultState());
        structure.fillWithBlocks(world, start, 93, -33, 27, 93, -33, 29, Blocks.STONE_BRICKS.getDefaultState());
        structure.fillWithBlocks(world, start, 93, -33, 31, 93, -33, 33, Blocks.STONE_BRICKS.getDefaultState());
        structure.fillWithBlocks(world, start, 93, -33, 35, 93, -33, 35, Blocks.STONE_BRICKS.getDefaultState());
        structure.fillWithBlocks(world, start, 93, -33, 37, 94, -33, 37, Blocks.MOSSY_STONE_BRICKS.getDefaultState());
        structure.fillWithBlocks(world, start, 93, -33, 38, 93, -32, 38, Blocks.AIR.getDefaultState());
        structure.fillWithBlocks(world, start, 93, -33, 39, 97, -33, 39, Blocks.STONE_BRICKS.getDefaultState());
        structure.fillWithBlocks(world, start, 93, -32, 20, 93, -32, 21, Blocks.MOSSY_STONE_BRICKS.getDefaultState());
        structure.fillWithBlocks(world, start, 93, -32, 25, 94, -31, 25, Blocks.STONE_BRICKS.getDefaultState());
        structure.fillWithBlocks(world, start, 93, -32, 28, 93, -32, 29, Blocks.STONE_BRICKS.getDefaultState());
        structure.fillWithBlocks(world, start, 93, -32, 31, 93, -31, 31, Blocks.STONE_BRICKS.getDefaultState());
        structure.fillWithBlocks(world, start, 93, -32, 32, 93, -32, 34, Blocks.MOSSY_STONE_BRICKS.getDefaultState());
        structure.fillWithBlocks(world, start, 93, -32, 36, 93, -31, 36, Blocks.MOSSY_STONE_BRICKS.getDefaultState());
        structure.fillWithBlocks(world, start, 93, -32, 37, 93, -31, 37, Blocks.MOSSY_COBBLESTONE.getDefaultState());
        structure.fillWithBlocks(world, start, 93, -32, 39, 93, -31, 39, Blocks.STONE_BRICKS.getDefaultState());
        structure.fillWithBlocks(world, start, 93, -31, 20, 93, -31, 22, Blocks.STONE_BRICKS.getDefaultState());
        structure.fillWithBlocks(world, start, 93, -31, 24, 94, -31, 25, Blocks.STONE_BRICKS.getDefaultState());
        structure.fillWithBlocks(world, start, 93, -31, 27, 93, -31, 28, Blocks.STONE_BRICKS.getDefaultState());
        structure.fillWithBlocks(world, start, 93, -31, 30, 96, -31, 30, Blocks.MOSSY_STONE_BRICKS.getDefaultState());
        structure.fillWithBlocks(world, start, 93, -31, 32, 93, -31, 33, Blocks.STONE_BRICKS.getDefaultState());
        structure.fillWithBlocks(world, start, 93, -31, 38, 93, -31, 39, Blocks.STONE_BRICKS.getDefaultState());
        structure.fillWithBlocks(world, start, 93, -20, 43, 93, -20, 48, Blocks.STONE_BRICKS.getDefaultState());
        structure.fillWithBlocks(world, start, 93, -20, 74, 93, -16, 74, Blocks.STONE_BRICKS.getDefaultState());
        structure.fillWithBlocks(world, start, 93, -20, 75, 93, -20, 77, Blocks.MOSSY_STONE_BRICKS.getDefaultState());
        structure.fillWithBlocks(world, start, 93, -20, 79, 93, -20, 81, Blocks.STONE_BRICKS.getDefaultState());
        structure.fillWithBlocks(world, start, 93, -20, 82, 93, -20, 83, Blocks.CRACKED_STONE_BRICKS.getDefaultState());
        structure.fillWithBlocks(world, start, 93, -20, 84, 93, -18, 84, Blocks.STONE_BRICKS.getDefaultState());
        structure.fillWithBlocks(world, start, 93, -19, 44, 93, -19, 45, Blocks.STONE_BRICKS.getDefaultState());
        structure.fillWithBlocks(world, start, 93, -19, 46, 95, -19, 48, Blocks.AIR.getDefaultState());
        structure.fillWithBlocks(world, start, 93, -19, 49, 93, -19, 50, Blocks.STONE_BRICKS.getDefaultState());
        structure.fillWithBlocks(world, start, 93, -19, 72, 93, -18, 72, Blocks.CRACKED_STONE_BRICKS.getDefaultState());
        structure.fillWithBlocks(world, start, 93, -19, 78, 93, -19, 79, Blocks.STONE_BRICKS.getDefaultState());
        structure.fillWithBlocks(world, start, 93, -19, 80, 93, -16, 80, Blocks.CRACKED_STONE_BRICKS.getDefaultState());
        structure.fillWithBlocks(world, start, 93, -19, 83, 93, -18, 84, Blocks.STONE_BRICKS.getDefaultState());
        structure.fillWithBlocks(world, start, 93, -18, 46, 95, -18, 48, Blocks.AIR.getDefaultState());
        structure.fillWithBlocks(world, start, 93, -18, 49, 93, -18, 50, Blocks.STONE_BRICKS.getDefaultState());
        structure.fillWithBlocks(world, start, 93, -18, 77, 93, -18, 78, Blocks.STONE_BRICKS.getDefaultState());
        structure.fillWithBlocks(world, start, 93, -18, 79, 93, -18, 81, Blocks.CRACKED_STONE_BRICKS.getDefaultState());
        structure.fillWithBlocks(world, start, 93, -18, 86, 93, -12, 86, Blocks.STONE_BRICKS.getDefaultState());
        structure.fillWithBlocks(world, start, 93, -17, 43, 93, -17, 44, Blocks.STONE_BRICKS.getDefaultState());
        structure.fillWithBlocks(world, start, 93, -17, 46, 95, -17, 48, Blocks.AIR.getDefaultState());
        structure.fillWithBlocks(world, start, 93, -17, 50, 94, -17, 50, Blocks.STONE_BRICKS.getDefaultState());
        structure.fillWithBlocks(world, start, 93, -17, 72, 93, -17, 74, Blocks.STONE_BRICKS.getDefaultState());
        structure.fillWithBlocks(world, start, 93, -17, 76, 93, -16, 76, Blocks.STONE_BRICKS.getDefaultState());
        structure.fillWithBlocks(world, start, 93, -17, 78, 93, -16, 78, Blocks.STONE_BRICKS.getDefaultState());
        structure.fillWithBlocks(world, start, 93, -17, 83, 93, -17, 84, Blocks.MOSSY_STONE_BRICKS.getDefaultState());
        structure.fillWithBlocks(world, start, 93, -17, 85, 93, -16, 86, Blocks.STONE_BRICKS.getDefaultState());
        structure.fillWithBlocks(world, start, 93, -16, 45, 94, -16, 47, Blocks.STONE_BRICKS.getDefaultState());
        structure.fillWithBlocks(world, start, 93, -16, 48, 93, -16, 48, Blocks.CRACKED_STONE_BRICKS.getDefaultState());
        structure.fillWithBlocks(world, start, 93, -16, 72, 93, -16, 73, Blocks.CRACKED_STONE_BRICKS.getDefaultState());
        structure.fillWithBlocks(world, start, 93, -16, 82, 93, -15, 83, Blocks.STONE_BRICKS.getDefaultState());
        structure.fillWithBlocks(world, start, 93, -15, 72, 93, -15, 73, Blocks.MOSSY_STONE_BRICKS.getDefaultState());
        structure.fillWithBlocks(world, start, 93, -15, 76, 93, -14, 76, Blocks.CRACKED_STONE_BRICKS.getDefaultState());
        structure.fillWithBlocks(world, start, 93, -15, 80, 93, -14, 81, Blocks.STONE_BRICKS.getDefaultState());
        structure.fillWithBlocks(world, start, 93, -14, 73, 93, -14, 74, Blocks.STONE_BRICKS.getDefaultState());
        structure.fillWithBlocks(world, start, 93, -14, 77, 93, -11, 77, Blocks.STONE_BRICKS.getDefaultState());
        structure.fillWithBlocks(world, start, 93, -14, 79, 93, -13, 81, Blocks.STONE_BRICKS.getDefaultState());
        structure.fillWithBlocks(world, start, 93, -14, 82, 93, -13, 82, Blocks.CRACKED_STONE_BRICKS.getDefaultState());
        structure.fillWithBlocks(world, start, 93, -14, 83, 93, -13, 84, Blocks.STONE_BRICKS.getDefaultState());
        structure.fillWithBlocks(world, start, 93, -13, 73, 93, -12, 73, Blocks.CRACKED_STONE_BRICKS.getDefaultState());
        structure.fillWithBlocks(world, start, 93, -13, 74, 93, -13, 77, Blocks.STONE_BRICKS.getDefaultState());
        structure.fillWithBlocks(world, start, 93, -12, 72, 93, -12, 74, Blocks.CRACKED_STONE_BRICKS.getDefaultState());
        structure.fillWithBlocks(world, start, 93, -12, 75, 93, -12, 80, Blocks.STONE_BRICKS.getDefaultState());
        structure.fillWithBlocks(world, start, 93, -12, 84, 93, -12, 85, Blocks.MOSSY_STONE_BRICKS.getDefaultState());
        structure.fillWithBlocks(world, start, 93, -11, 72, 93, -11, 75, Blocks.STONE_BRICKS.getDefaultState());
        structure.fillWithBlocks(world, start, 93, -10, 41, 97, -10, 48, Blocks.STONE_BRICKS.getDefaultState());
        structure.fillWithBlocks(world, start, 93, -9, 41, 97, -5, 41, Blocks.STONE_BRICKS.getDefaultState());
        structure.fillWithBlocks(world, start, 93, -9, 42, 94, -9, 52, Blocks.AIR.getDefaultState());
        structure.fillWithBlocks(world, start, 93, -9, 53, 94, -9, 54, Blocks.STONE_BRICKS.getDefaultState());
        structure.fillWithBlocks(world, start, 93, -8, 42, 94, -8, 52, Blocks.AIR.getDefaultState());
        structure.fillWithBlocks(world, start, 93, -8, 53, 94, -8, 54, Blocks.STONE_BRICKS.getDefaultState());
        structure.fillWithBlocks(world, start, 93, -7, 42, 94, -7, 52, Blocks.AIR.getDefaultState());
        structure.fillWithBlocks(world, start, 93, -7, 53, 94, -7, 54, Blocks.STONE_BRICKS.getDefaultState());
        structure.fillWithBlocks(world, start, 93, -7, 98, 94, -7, 99, Blocks.CAVE_AIR.getDefaultState());
        structure.fillWithBlocks(world, start, 93, -6, 42, 94, -6, 52, Blocks.AIR.getDefaultState());
        structure.fillWithBlocks(world, start, 93, -6, 53, 93, -6, 53, Blocks.STONE_BRICKS.getDefaultState());
        structure.fillWithBlocks(world, start, 93, -5, 52, 95, -5, 54, Blocks.STONE_BRICKS.getDefaultState());
        structure.fillWithBlocks(world, start, 93, -3, 42, 97, -3, 46, Blocks.STONE_BRICKS.getDefaultState());
        structure.fillWithBlocks(world, start, 93, -3, 47, 94, -3, 54, Blocks.STONE_BRICKS.getDefaultState());
        structure.fillWithBlocks(world, start, 93, -1, 45, 94, -1, 46, Blocks.STONE_BRICKS.getDefaultState());
        structure.fillWithBlocks(world, start, 93, 0, 10, 93, 0, 12, Blocks.GRASS_BLOCK.getDefaultState().with(SnowyDirtBlock.SNOWY, false));
        structure.fillWithBlocks(world, start, 93, 0, 13, 93, 0, 47, Blocks.DIRT.getDefaultState());
        structure.fillWithBlocks(world, start, 93, 0, 48, 93, 0, 56, Blocks.STONE.getDefaultState());
        structure.fillWithBlocks(world, start, 93, 0, 57, 93, 0, 57, Blocks.DIRT.getDefaultState());
        structure.fillWithBlocks(world, start, 93, 0, 58, 93, 0, 75, Blocks.STONE.getDefaultState());
        structure.fillWithBlocks(world, start, 93, 0, 76, 95, 0, 79, Blocks.DIRT.getDefaultState());
        structure.fillWithBlocks(world, start, 93, 0, 82, 94, 0, 83, Blocks.GRASS_BLOCK.getDefaultState().with(SnowyDirtBlock.SNOWY, false));
        structure.fillWithBlocks(world, start, 93, 1, 13, 93, 1, 14, Blocks.GRASS_BLOCK.getDefaultState().with(SnowyDirtBlock.SNOWY, false));
        structure.fillWithBlocks(world, start, 93, 1, 15, 93, 1, 60, Blocks.DIRT.getDefaultState());
        structure.fillWithBlocks(world, start, 93, 1, 61, 93, 1, 67, Blocks.STONE.getDefaultState());
        structure.fillWithBlocks(world, start, 93, 1, 68, 94, 1, 69, Blocks.DIRT.getDefaultState());
        structure.fillWithBlocks(world, start, 93, 1, 70, 93, 1, 72, Blocks.STONE.getDefaultState());
        structure.fillWithBlocks(world, start, 93, 1, 73, 95, 1, 76, Blocks.DIRT.getDefaultState());
        structure.fillWithBlocks(world, start, 93, 1, 80, 93, 1, 81, Blocks.GRASS_BLOCK.getDefaultState().with(SnowyDirtBlock.SNOWY, false));
        structure.fillWithBlocks(world, start, 93, 2, 15, 93, 2, 16, Blocks.GRASS_BLOCK.getDefaultState().with(SnowyDirtBlock.SNOWY, false));
        structure.fillWithBlocks(world, start, 93, 2, 17, 93, 2, 77, Blocks.DIRT.getDefaultState());
        structure.fillWithBlocks(world, start, 93, 2, 78, 93, 2, 79, Blocks.GRASS_BLOCK.getDefaultState().with(SnowyDirtBlock.SNOWY, false));
        structure.fillWithBlocks(world, start, 93, 3, 17, 93, 3, 22, Blocks.GRASS_BLOCK.getDefaultState().with(SnowyDirtBlock.SNOWY, false));
        structure.fillWithBlocks(world, start, 93, 3, 42, 93, 3, 75, Blocks.DIRT.getDefaultState());
        structure.fillWithBlocks(world, start, 93, 3, 76, 93, 3, 77, Blocks.GRASS_BLOCK.getDefaultState().with(SnowyDirtBlock.SNOWY, false));
        structure.fillWithBlocks(world, start, 93, 4, 23, 93, 4, 47, Blocks.GRASS_BLOCK.getDefaultState().with(SnowyDirtBlock.SNOWY, false));
        structure.fillWithBlocks(world, start, 93, 4, 48, 93, 4, 72, Blocks.DIRT.getDefaultState());
        structure.fillWithBlocks(world, start, 93, 4, 73, 93, 4, 75, Blocks.GRASS_BLOCK.getDefaultState().with(SnowyDirtBlock.SNOWY, false));
        structure.fillWithBlocks(world, start, 93, 5, 48, 93, 5, 57, Blocks.GRASS_BLOCK.getDefaultState().with(SnowyDirtBlock.SNOWY, false));
        structure.fillWithBlocks(world, start, 93, 5, 58, 93, 5, 67, Blocks.DIRT.getDefaultState());
        structure.fillWithBlocks(world, start, 93, 5, 68, 94, 5, 70, Blocks.GRASS_BLOCK.getDefaultState().with(SnowyDirtBlock.SNOWY, false));
        structure.fillWithBlocks(world, start, 93, 6, 58, 93, 6, 67, Blocks.GRASS_BLOCK.getDefaultState().with(SnowyDirtBlock.SNOWY, false));
        structure.fillWithBlocks(world, start, 94, -49, -18, 94, -49, -17, Blocks.STONE_BRICK_WALL.getDefaultState().with(WallBlock.WATERLOGGED, false).with(WallBlock.UP, false).with(WallBlock.WALL_HEIGHT_NORTH, WallHeight.LOW).with(WallBlock.WALL_HEIGHT_SOUTH, WallHeight.LOW).with(WallBlock.WALL_HEIGHT_EAST, WallHeight.LOW).with(WallBlock.WALL_HEIGHT_WEST, WallHeight.LOW));
        structure.fillWithBlocks(world, start, 94, -49, -16, 94, -41, -16, Blocks.STONE_BRICKS.getDefaultState());
        structure.fillWithBlocks(world, start, 94, -49, -15, 97, -49, -11, Blocks.AIR.getDefaultState());
        structure.fillWithBlocks(world, start, 94, -49, -8, 94, -49, -7, Blocks.STONE_BRICK_WALL.getDefaultState().with(WallBlock.WATERLOGGED, false).with(WallBlock.UP, false).with(WallBlock.WALL_HEIGHT_NORTH, WallHeight.LOW).with(WallBlock.WALL_HEIGHT_SOUTH, WallHeight.LOW).with(WallBlock.WALL_HEIGHT_EAST, WallHeight.LOW).with(WallBlock.WALL_HEIGHT_WEST, WallHeight.LOW));
        structure.fillWithBlocks(world, start, 94, -49, -6, 94, -49, -5, Blocks.STONE_BRICKS.getDefaultState());
        structure.fillWithBlocks(world, start, 94, -49, 45, 96, -49, 62, Blocks.STONE_BRICKS.getDefaultState());
        structure.fillWithBlocks(world, start, 94, -49, 65, 94, -41, 79, Blocks.STONE_BRICKS.getDefaultState());
        structure.fillWithBlocks(world, start, 94, -48, -19, 96, -48, -17, Blocks.AIR.getDefaultState());
        structure.fillWithBlocks(world, start, 94, -48, -15, 98, -48, -11, Blocks.AIR.getDefaultState());
        structure.fillWithBlocks(world, start, 94, -48, -10, 94, -41, -10, Blocks.STONE_BRICKS.getDefaultState());
        structure.fillWithBlocks(world, start, 94, -48, -9, 96, -48, -7, Blocks.AIR.getDefaultState());
        structure.fillWithBlocks(world, start, 94, -48, -6, 94, -48, -5, Blocks.STONE_BRICKS.getDefaultState());
        structure.fillWithBlocks(world, start, 94, -48, 42, 94, -48, 42, Blocks.STONE_BRICKS.getDefaultState());
        structure.fillWithBlocks(world, start, 94, -48, 48, 94, -48, 51, Blocks.STONE_BRICKS.getDefaultState());
        structure.fillWithBlocks(world, start, 94, -48, 53, 96, -48, 62, Blocks.STONE_BRICKS.getDefaultState());
        structure.fillWithBlocks(world, start, 94, -47, -19, 96, -47, -17, Blocks.AIR.getDefaultState());
        structure.fillWithBlocks(world, start, 94, -47, -15, 98, -47, -11, Blocks.AIR.getDefaultState());
        structure.fillWithBlocks(world, start, 94, -47, -9, 96, -47, -7, Blocks.AIR.getDefaultState());
        structure.fillWithBlocks(world, start, 94, -47, -6, 94, -47, -5, Blocks.STONE_BRICKS.getDefaultState());
        structure.fillWithBlocks(world, start, 94, -47, 45, 94, -47, 46, Blocks.STONE_BRICKS.getDefaultState());
        structure.fillWithBlocks(world, start, 94, -47, 47, 94, -46, 47, Blocks.AIR.getDefaultState());
        structure.fillWithBlocks(world, start, 94, -47, 48, 96, -47, 54, Blocks.STONE_BRICKS.getDefaultState());
        structure.fillWithBlocks(world, start, 94, -47, 55, 95, -47, 62, Blocks.STONE_BRICKS.getDefaultState());
        structure.fillWithBlocks(world, start, 94, -47, 80, 94, -41, 80, Blocks.STONE_BRICKS.getDefaultState());
        structure.fillWithBlocks(world, start, 94, -46, -19, 96, -46, -17, Blocks.AIR.getDefaultState());
        structure.fillWithBlocks(world, start, 94, -46, -15, 98, -46, -11, Blocks.AIR.getDefaultState());
        structure.fillWithBlocks(world, start, 94, -46, -9, 96, -46, -7, Blocks.AIR.getDefaultState());
        structure.fillWithBlocks(world, start, 94, -46, -6, 94, -46, -5, Blocks.STONE_BRICKS.getDefaultState());
        structure.fillWithBlocks(world, start, 94, -46, 42, 95, -46, 43, Blocks.STONE_BRICKS.getDefaultState());
        structure.fillWithBlocks(world, start, 94, -46, 45, 94, -45, 46, Blocks.STONE_BRICKS.getDefaultState());
        structure.fillWithBlocks(world, start, 94, -46, 48, 96, -46, 50, Blocks.STONE_BRICKS.getDefaultState());
        structure.fillWithBlocks(world, start, 94, -46, 51, 95, -46, 58, Blocks.STONE_BRICKS.getDefaultState());
        structure.fillWithBlocks(world, start, 94, -46, 60, 96, -46, 62, Blocks.STONE_BRICKS.getDefaultState());
        structure.fillWithBlocks(world, start, 94, -45, -11, 94, -45, -5, Blocks.STONE_BRICKS.getDefaultState());
        structure.fillWithBlocks(world, start, 94, -44, -20, 95, -44, -5, Blocks.STONE_BRICKS.getDefaultState());
        structure.fillWithBlocks(world, start, 94, -44, 42, 95, -44, 43, Blocks.STONE_BRICKS.getDefaultState());
        structure.fillWithBlocks(world, start, 94, -44, 45, 96, -44, 57, Blocks.STONE_BRICKS.getDefaultState());
        structure.fillWithBlocks(world, start, 94, -44, 64, 94, -41, 80, Blocks.STONE_BRICKS.getDefaultState());
        structure.fillWithBlocks(world, start, 94, -43, 56, 95, -43, 62, Blocks.STONE_BRICKS.getDefaultState());
        structure.fillWithBlocks(world, start, 94, -42, -8, 97, -42, -5, Blocks.STONE_BRICKS.getDefaultState());
        structure.fillWithBlocks(world, start, 94, -42, 44, 96, -42, 46, Blocks.STONE_BRICKS.getDefaultState());
        structure.fillWithBlocks(world, start, 94, -41, -5, 109, -41, -5, Blocks.STONE_BRICKS.getDefaultState());
        structure.fillWithBlocks(world, start, 94, -40, 19, 94, -38, 19, Blocks.STONE_BRICKS.getDefaultState());
        structure.fillWithBlocks(world, start, 94, -40, 20, 94, -39, 20, Blocks.MOSSY_STONE_BRICKS.getDefaultState());
        structure.fillWithBlocks(world, start, 94, -40, 21, 94, -40, 21, Blocks.STONE_BRICKS.getDefaultState());
        structure.fillWithBlocks(world, start, 94, -40, 23, 94, -40, 23, Blocks.STONE_BRICKS.getDefaultState());
        structure.fillWithBlocks(world, start, 94, -40, 26, 94, -40, 26, Blocks.STONE_BRICKS.getDefaultState());
        structure.fillWithBlocks(world, start, 94, -40, 27, 94, -40, 29, Blocks.MOSSY_STONE_BRICKS.getDefaultState());
        structure.fillWithBlocks(world, start, 94, -40, 30, 95, -40, 31, Blocks.STONE_BRICKS.getDefaultState());
        structure.fillWithBlocks(world, start, 94, -40, 32, 94, -40, 32, Blocks.STONE_BRICKS.getDefaultState());
        structure.fillWithBlocks(world, start, 94, -40, 33, 94, -40, 33, Blocks.MOSSY_STONE_BRICKS.getDefaultState());
        structure.fillWithBlocks(world, start, 94, -40, 34, 94, -40, 35, Blocks.STONE_BRICKS.getDefaultState());
        structure.fillWithBlocks(world, start, 94, -40, 37, 95, -40, 38, Blocks.MOSSY_STONE_BRICKS.getDefaultState());
        structure.fillWithBlocks(world, start, 94, -40, 39, 96, -39, 39, Blocks.STONE_BRICKS.getDefaultState());
        structure.fillWithBlocks(world, start, 94, -39, 21, 94, -38, 22, Blocks.STONE_BRICKS.getDefaultState());
        structure.fillWithBlocks(world, start, 94, -39, 24, 97, -39, 34, Blocks.AIR.getDefaultState());
        structure.fillWithBlocks(world, start, 94, -39, 35, 94, -38, 35, Blocks.MOSSY_STONE_BRICKS.getDefaultState());
        structure.fillWithBlocks(world, start, 94, -38, 20, 95, -38, 22, Blocks.STONE_BRICKS.getDefaultState());
        structure.fillWithBlocks(world, start, 94, -38, 23, 94, -36, 23, Blocks.STONE_BRICKS.getDefaultState());
        structure.fillWithBlocks(world, start, 94, -38, 37, 95, -38, 38, Blocks.STONE_BRICKS.getDefaultState());
        structure.fillWithBlocks(world, start, 94, -37, 19, 95, -37, 19, Blocks.MOSSY_STONE_BRICKS.getDefaultState());
        structure.fillWithBlocks(world, start, 94, -37, 21, 94, -37, 21, Blocks.MOSSY_STONE_BRICKS.getDefaultState());
        structure.fillWithBlocks(world, start, 94, -37, 22, 94, -37, 23, Blocks.STONE_BRICKS.getDefaultState());
        structure.fillWithBlocks(world, start, 94, -37, 35, 94, -37, 37, Blocks.STONE_BRICKS.getDefaultState());
        structure.fillWithBlocks(world, start, 94, -37, 38, 94, -37, 38, Blocks.MOSSY_STONE_BRICKS.getDefaultState());
        structure.fillWithBlocks(world, start, 94, -36, 19, 94, -33, 19, Blocks.STONE_BRICKS.getDefaultState());
        structure.fillWithBlocks(world, start, 94, -36, 20, 94, -36, 20, Blocks.AIR.getDefaultState());
        structure.fillWithBlocks(world, start, 94, -36, 21, 94, -32, 21, Blocks.STONE_BRICKS.getDefaultState());
        structure.fillWithBlocks(world, start, 94, -36, 22, 94, -36, 22, Blocks.AIR.getDefaultState());
        structure.fillWithBlocks(world, start, 94, -36, 34, 94, -35, 35, Blocks.STONE_BRICKS.getDefaultState());
        structure.fillWithBlocks(world, start, 94, -36, 37, 94, -36, 39, Blocks.STONE_BRICKS.getDefaultState());
        structure.fillWithBlocks(world, start, 94, -35, 22, 94, -35, 23, Blocks.MOSSY_STONE_BRICKS.getDefaultState());
        structure.fillWithBlocks(world, start, 94, -35, 24, 94, -33, 26, Blocks.STONE_BRICKS.getDefaultState());
        structure.fillWithBlocks(world, start, 94, -35, 27, 95, -35, 27, Blocks.STONE_BRICKS.getDefaultState());
        structure.fillWithBlocks(world, start, 94, -35, 28, 96, -35, 30, Blocks.AIR.getDefaultState());
        structure.fillWithBlocks(world, start, 94, -35, 31, 94, -34, 34, Blocks.STONE_BRICKS.getDefaultState());
        structure.fillWithBlocks(world, start, 94, -35, 36, 94, -35, 36, Blocks.MOSSY_STONE_BRICKS.getDefaultState());
        structure.fillWithBlocks(world, start, 94, -35, 37, 94, -34, 37, Blocks.STONE_BRICKS.getDefaultState());
        structure.fillWithBlocks(world, start, 94, -34, 20, 94, -34, 21, Blocks.STONE_BRICKS.getDefaultState());
        structure.fillWithBlocks(world, start, 94, -34, 22, 94, -33, 22, Blocks.MOSSY_STONE_BRICKS.getDefaultState());
        structure.fillWithBlocks(world, start, 94, -34, 23, 95, -34, 26, Blocks.STONE_BRICKS.getDefaultState());
        structure.fillWithBlocks(world, start, 94, -34, 35, 94, -34, 35, Blocks.MOSSY_STONE_BRICKS.getDefaultState());
        structure.fillWithBlocks(world, start, 94, -34, 38, 94, -33, 38, Blocks.STONE_BRICKS.getDefaultState());
        structure.fillWithBlocks(world, start, 94, -33, 20, 94, -32, 20, Blocks.MOSSY_STONE_BRICKS.getDefaultState());
        structure.fillWithBlocks(world, start, 94, -33, 23, 94, -33, 26, Blocks.STONE_BRICKS.getDefaultState());
        structure.fillWithBlocks(world, start, 94, -33, 27, 94, -32, 27, Blocks.AIR.getDefaultState());
        structure.fillWithBlocks(world, start, 94, -33, 29, 94, -33, 30, Blocks.STONE_BRICKS.getDefaultState());
        structure.fillWithBlocks(world, start, 94, -33, 32, 94, -32, 33, Blocks.STONE_BRICKS.getDefaultState());
        structure.fillWithBlocks(world, start, 94, -33, 34, 94, -33, 34, Blocks.STONE_BRICKS.getDefaultState());
        structure.fillWithBlocks(world, start, 94, -33, 36, 94, -33, 36, Blocks.STONE_BRICKS.getDefaultState());
        structure.fillWithBlocks(world, start, 94, -32, 23, 94, -32, 25, Blocks.STONE_BRICKS.getDefaultState());
        structure.fillWithBlocks(world, start, 94, -32, 26, 94, -31, 26, Blocks.MOSSY_STONE_BRICKS.getDefaultState());
        structure.fillWithBlocks(world, start, 94, -32, 28, 94, -32, 31, Blocks.MOSSY_STONE_BRICKS.getDefaultState());
        structure.fillWithBlocks(world, start, 94, -32, 34, 95, -32, 34, Blocks.MOSSY_STONE_BRICKS.getDefaultState());
        structure.fillWithBlocks(world, start, 94, -32, 36, 94, -31, 37, Blocks.STONE_BRICKS.getDefaultState());
        structure.fillWithBlocks(world, start, 94, -32, 38, 94, -32, 39, Blocks.MOSSY_STONE_BRICKS.getDefaultState());
        structure.fillWithBlocks(world, start, 94, -31, 19, 94, -31, 20, Blocks.STONE_BRICKS.getDefaultState());
        structure.fillWithBlocks(world, start, 94, -31, 21, 94, -31, 21, Blocks.MOSSY_STONE_BRICKS.getDefaultState());
        structure.fillWithBlocks(world, start, 94, -31, 23, 94, -31, 23, Blocks.MOSSY_STONE_BRICKS.getDefaultState());
        structure.fillWithBlocks(world, start, 94, -31, 27, 95, -31, 27, Blocks.MOSSY_STONE_BRICKS.getDefaultState());
        structure.fillWithBlocks(world, start, 94, -31, 31, 94, -31, 32, Blocks.MOSSY_COBBLESTONE.getDefaultState());
        structure.fillWithBlocks(world, start, 94, -31, 33, 94, -31, 37, Blocks.STONE_BRICKS.getDefaultState());
        structure.fillWithBlocks(world, start, 94, -20, 46, 96, -20, 48, Blocks.STONE_BRICKS.getDefaultState());
        structure.fillWithBlocks(world, start, 94, -19, 44, 94, -17, 44, Blocks.STONE_BRICKS.getDefaultState());
        structure.fillWithBlocks(world, start, 94, -19, 45, 94, -19, 49, Blocks.AIR.getDefaultState());
        structure.fillWithBlocks(world, start, 94, -18, 45, 94, -18, 49, Blocks.AIR.getDefaultState());
        structure.fillWithBlocks(world, start, 94, -18, 50, 94, -17, 50, Blocks.STONE_BRICKS.getDefaultState());
        structure.fillWithBlocks(world, start, 94, -17, 45, 94, -17, 49, Blocks.AIR.getDefaultState());
        structure.fillWithBlocks(world, start, 94, -16, 48, 94, -16, 48, Blocks.STONE_BRICKS.getDefaultState());
        structure.fillWithBlocks(world, start, 94, -10, 40, 97, -10, 48, Blocks.STONE_BRICKS.getDefaultState());
        structure.fillWithBlocks(world, start, 94, -10, 49, 95, -10, 49, Blocks.MOSSY_STONE_BRICKS.getDefaultState());
        structure.fillWithBlocks(world, start, 94, -10, 50, 97, -10, 54, Blocks.STONE_BRICKS.getDefaultState());
        structure.fillWithBlocks(world, start, 94, -8, 40, 95, -8, 41, Blocks.STONE_BRICKS.getDefaultState());
        structure.fillWithBlocks(world, start, 94, -7, 40, 95, -7, 41, Blocks.STONE_BRICKS.getDefaultState());
        structure.fillWithBlocks(world, start, 94, -6, 40, 95, -6, 41, Blocks.STONE_BRICKS.getDefaultState());
        structure.fillWithBlocks(world, start, 94, -6, 53, 95, -6, 54, Blocks.STONE_BRICKS.getDefaultState());
        structure.fillWithBlocks(world, start, 94, -5, 40, 95, -5, 41, Blocks.STONE_BRICKS.getDefaultState());
        structure.fillWithBlocks(world, start, 94, -5, 43, 94, -5, 43, Blocks.STONE_BRICKS.getDefaultState());
        structure.fillWithBlocks(world, start, 94, -5, 45, 97, -5, 50, Blocks.STONE_BRICKS.getDefaultState());
        structure.fillWithBlocks(world, start, 94, -5, 51, 96, -5, 54, Blocks.STONE_BRICKS.getDefaultState());
        structure.fillWithBlocks(world, start, 94, -3, 40, 97, -3, 46, Blocks.STONE_BRICKS.getDefaultState());
        structure.fillWithBlocks(world, start, 94, -2, 40, 94, -2, 40, Blocks.STONE_BRICKS.getDefaultState());
        structure.fillWithBlocks(world, start, 94, -2, 42, 97, -2, 46, Blocks.STONE_BRICKS.getDefaultState());
        structure.fillWithBlocks(world, start, 94, -1, 47, 97, -1, 54, Blocks.STONE_BRICKS.getDefaultState());
        structure.fillWithBlocks(world, start, 94, 0, 12, 94, 0, 14, Blocks.GRASS_BLOCK.getDefaultState().with(SnowyDirtBlock.SNOWY, false));
        structure.fillWithBlocks(world, start, 94, 0, 15, 94, 0, 52, Blocks.DIRT.getDefaultState());
        structure.fillWithBlocks(world, start, 94, 0, 53, 94, 0, 56, Blocks.STONE.getDefaultState());
        structure.fillWithBlocks(world, start, 94, 0, 57, 98, 0, 61, Blocks.DIRT.getDefaultState());
        structure.fillWithBlocks(world, start, 94, 0, 62, 95, 0, 67, Blocks.STONE.getDefaultState());
        structure.fillWithBlocks(world, start, 94, 0, 68, 94, 0, 73, Blocks.STONE.getDefaultState());
        structure.fillWithBlocks(world, start, 94, 0, 74, 96, 0, 78, Blocks.DIRT.getDefaultState());
        structure.fillWithBlocks(world, start, 94, 0, 81, 95, 0, 82, Blocks.GRASS_BLOCK.getDefaultState().with(SnowyDirtBlock.SNOWY, false));
        structure.fillWithBlocks(world, start, 94, 1, 15, 94, 1, 16, Blocks.GRASS_BLOCK.getDefaultState().with(SnowyDirtBlock.SNOWY, false));
        structure.fillWithBlocks(world, start, 94, 1, 17, 94, 1, 69, Blocks.DIRT.getDefaultState());
        structure.fillWithBlocks(world, start, 94, 1, 71, 96, 1, 75, Blocks.DIRT.getDefaultState());
        structure.fillWithBlocks(world, start, 94, 1, 79, 94, 1, 80, Blocks.GRASS_BLOCK.getDefaultState().with(SnowyDirtBlock.SNOWY, false));
        structure.fillWithBlocks(world, start, 94, 2, 17, 94, 2, 20, Blocks.GRASS_BLOCK.getDefaultState().with(SnowyDirtBlock.SNOWY, false));
        structure.fillWithBlocks(world, start, 94, 2, 31, 94, 2, 76, Blocks.DIRT.getDefaultState());
        structure.fillWithBlocks(world, start, 94, 2, 77, 94, 2, 78, Blocks.GRASS_BLOCK.getDefaultState().with(SnowyDirtBlock.SNOWY, false));
        structure.fillWithBlocks(world, start, 94, 3, 21, 94, 3, 45, Blocks.GRASS_BLOCK.getDefaultState().with(SnowyDirtBlock.SNOWY, false));
        structure.fillWithBlocks(world, start, 94, 3, 46, 94, 3, 73, Blocks.DIRT.getDefaultState());
        structure.fillWithBlocks(world, start, 94, 3, 74, 94, 3, 76, Blocks.GRASS_BLOCK.getDefaultState().with(SnowyDirtBlock.SNOWY, false));
        structure.fillWithBlocks(world, start, 94, 4, 46, 94, 4, 52, Blocks.GRASS_BLOCK.getDefaultState().with(SnowyDirtBlock.SNOWY, false));
        structure.fillWithBlocks(world, start, 94, 4, 53, 94, 4, 70, Blocks.DIRT.getDefaultState());
        structure.fillWithBlocks(world, start, 94, 4, 71, 94, 4, 73, Blocks.GRASS_BLOCK.getDefaultState().with(SnowyDirtBlock.SNOWY, false));
        structure.fillWithBlocks(world, start, 94, 5, 53, 94, 5, 70, Blocks.GRASS_BLOCK.getDefaultState().with(SnowyDirtBlock.SNOWY, false));
        structure.fillWithBlocks(world, start, 95, -51, -19, 97, -51, -17, Blocks.STONE_BRICKS.getDefaultState());
        structure.fillWithBlocks(world, start, 95, -51, -9, 97, -51, -7, Blocks.STONE_BRICKS.getDefaultState());
        structure.fillWithBlocks(world, start, 95, -50, -21, 96, -50, -20, Blocks.STONE_BRICKS.getDefaultState());
        structure.fillWithBlocks(world, start, 95, -50, -19, 97, -50, -17, Blocks.AIR.getDefaultState());
        structure.fillWithBlocks(world, start, 95, -50, -16, 101, -50, -10, Blocks.STONE_BRICKS.getDefaultState());
        structure.fillWithBlocks(world, start, 95, -50, -9, 97, -50, -7, Blocks.AIR.getDefaultState());
        structure.fillWithBlocks(world, start, 95, -50, -6, 95, -50, -6, Blocks.STONE_BRICKS.getDefaultState());
        structure.fillWithBlocks(world, start, 95, -49, -21, 103, -46, -21, Blocks.STONE_BRICKS.getDefaultState());
        structure.fillWithBlocks(world, start, 95, -49, -20, 96, -49, -20, Blocks.STONE_BRICK_WALL.getDefaultState().with(WallBlock.WATERLOGGED, false).with(WallBlock.UP, true).with(WallBlock.WALL_HEIGHT_NORTH, WallHeight.LOW).with(WallBlock.WALL_HEIGHT_SOUTH, WallHeight.LOW).with(WallBlock.WALL_HEIGHT_EAST, WallHeight.LOW).with(WallBlock.WALL_HEIGHT_WEST, WallHeight.LOW));
        structure.fillWithBlocks(world, start, 95, -49, -19, 97, -49, -17, Blocks.AIR.getDefaultState());
        structure.fillWithBlocks(world, start, 95, -49, -10, 96, -49, -10, Blocks.STONE_BRICK_WALL.getDefaultState().with(WallBlock.WATERLOGGED, false).with(WallBlock.UP, false).with(WallBlock.WALL_HEIGHT_NORTH, WallHeight.LOW).with(WallBlock.WALL_HEIGHT_SOUTH, WallHeight.LOW).with(WallBlock.WALL_HEIGHT_EAST, WallHeight.LOW).with(WallBlock.WALL_HEIGHT_WEST, WallHeight.LOW));
        structure.fillWithBlocks(world, start, 95, -49, -9, 97, -49, -7, Blocks.AIR.getDefaultState());
        structure.fillWithBlocks(world, start, 95, -49, -5, 97, -47, -5, Blocks.STONE_BRICKS.getDefaultState());
        structure.fillWithBlocks(world, start, 95, -49, 42, 96, -49, 62, Blocks.STONE_BRICKS.getDefaultState());
        structure.fillWithBlocks(world, start, 95, -48, -20, 97, -48, -6, Blocks.AIR.getDefaultState());
        structure.fillWithBlocks(world, start, 95, -48, 42, 96, -48, 47, Blocks.STONE_BRICKS.getDefaultState());
        structure.fillWithBlocks(world, start, 95, -48, 48, 96, -48, 48, Blocks.AIR.getDefaultState());
        structure.fillWithBlocks(world, start, 95, -48, 49, 95, -46, 62, Blocks.STONE_BRICKS.getDefaultState());
        structure.fillWithBlocks(world, start, 95, -47, -20, 97, -47, -6, Blocks.AIR.getDefaultState());
        structure.fillWithBlocks(world, start, 95, -47, 42, 95, -45, 44, Blocks.STONE_BRICKS.getDefaultState());
        structure.fillWithBlocks(world, start, 95, -47, 46, 96, -47, 54, Blocks.STONE_BRICKS.getDefaultState());
        structure.fillWithBlocks(world, start, 95, -46, -20, 97, -46, -6, Blocks.AIR.getDefaultState());
        structure.fillWithBlocks(world, start, 95, -46, 45, 95, -46, 45, Blocks.STONE_BRICKS.getDefaultState());
        structure.fillWithBlocks(world, start, 95, -46, 46, 95, -46, 47, Blocks.AIR.getDefaultState());
        structure.fillWithBlocks(world, start, 95, -45, -21, 96, -45, -20, Blocks.STONE_BRICKS.getDefaultState());
        structure.fillWithBlocks(world, start, 95, -45, -19, 97, -45, -17, Blocks.AIR.getDefaultState());
        structure.fillWithBlocks(world, start, 95, -45, -16, 107, -45, -16, Blocks.STONE_BRICKS.getDefaultState());
        structure.fillWithBlocks(world, start, 95, -45, -15, 97, -45, -11, Blocks.AIR.getDefaultState());
        structure.fillWithBlocks(world, start, 95, -45, -10, 97, -43, -10, Blocks.STONE_BRICKS.getDefaultState());
        structure.fillWithBlocks(world, start, 95, -45, -9, 97, -45, -7, Blocks.AIR.getDefaultState());
        structure.fillWithBlocks(world, start, 95, -45, -6, 96, -45, -5, Blocks.STONE_BRICKS.getDefaultState());
        structure.fillWithBlocks(world, start, 95, -45, 52, 96, -45, 53, Blocks.STONE_BRICKS.getDefaultState());
        structure.fillWithBlocks(world, start, 95, -45, 54, 95, -45, 62, Blocks.STONE_BRICKS.getDefaultState());
        structure.fillWithBlocks(world, start, 95, -44, -21, 97, -44, -19, Blocks.STONE_BRICKS.getDefaultState());
        structure.fillWithBlocks(world, start, 95, -44, 44, 96, -44, 62, Blocks.STONE_BRICKS.getDefaultState());
        structure.fillWithBlocks(world, start, 95, -43, -5, 97, -41, -5, Blocks.STONE_BRICKS.getDefaultState());
        structure.fillWithBlocks(world, start, 95, -43, 42, 96, -43, 43, Blocks.STONE_BRICKS.getDefaultState());
        structure.fillWithBlocks(world, start, 95, -43, 44, 95, -43, 44, Blocks.AIR.getDefaultState());
        structure.fillWithBlocks(world, start, 95, -43, 45, 95, -43, 62, Blocks.STONE_BRICKS.getDefaultState());
        structure.fillWithBlocks(world, start, 95, -42, -17, 97, -42, -5, Blocks.STONE_BRICKS.getDefaultState());
        structure.fillWithBlocks(world, start, 95, -42, 42, 96, -42, 46, Blocks.STONE_BRICKS.getDefaultState());
        structure.fillWithBlocks(world, start, 95, -42, 61, 96, -42, 62, Blocks.STONE_BRICKS.getDefaultState());
        structure.fillWithBlocks(world, start, 95, -41, -7, 95, -41, -5, Blocks.STONE_BRICKS.getDefaultState());
        structure.fillWithBlocks(world, start, 95, -40, 21, 95, -40, 25, Blocks.STONE_BRICKS.getDefaultState());
        structure.fillWithBlocks(world, start, 95, -40, 27, 95, -40, 27, Blocks.STONE_BRICKS.getDefaultState());
        structure.fillWithBlocks(world, start, 95, -40, 32, 95, -40, 32, Blocks.MOSSY_STONE_BRICKS.getDefaultState());
        structure.fillWithBlocks(world, start, 95, -40, 34, 95, -40, 38, Blocks.MOSSY_STONE_BRICKS.getDefaultState());
        structure.fillWithBlocks(world, start, 95, -39, 19, 95, -39, 21, Blocks.STONE_BRICKS.getDefaultState());
        structure.fillWithBlocks(world, start, 95, -39, 23, 97, -39, 35, Blocks.AIR.getDefaultState());
        structure.fillWithBlocks(world, start, 95, -39, 36, 96, -39, 37, Blocks.STONE_BRICKS.getDefaultState());
        structure.fillWithBlocks(world, start, 95, -39, 38, 95, -39, 39, Blocks.STONE_BRICKS.getDefaultState());
        structure.fillWithBlocks(world, start, 95, -38, 19, 96, -38, 19, Blocks.MOSSY_STONE_BRICKS.getDefaultState());
        structure.fillWithBlocks(world, start, 95, -38, 23, 97, -38, 35, Blocks.AIR.getDefaultState());
        structure.fillWithBlocks(world, start, 95, -38, 36, 95, -37, 38, Blocks.STONE_BRICKS.getDefaultState());
        structure.fillWithBlocks(world, start, 95, -38, 39, 97, -38, 39, Blocks.STONE_BRICKS.getDefaultState());
        structure.fillWithBlocks(world, start, 95, -37, 20, 96, -37, 20, Blocks.STONE_BRICKS.getDefaultState());
        structure.fillWithBlocks(world, start, 95, -37, 21, 96, -37, 22, Blocks.MOSSY_STONE_BRICKS.getDefaultState());
        structure.fillWithBlocks(world, start, 95, -37, 23, 97, -37, 35, Blocks.AIR.getDefaultState());
        structure.fillWithBlocks(world, start, 95, -37, 39, 96, -37, 39, Blocks.MOSSY_STONE_BRICKS.getDefaultState());
        structure.fillWithBlocks(world, start, 95, -36, 19, 95, -36, 20, Blocks.MOSSY_STONE_BRICKS.getDefaultState());
        structure.fillWithBlocks(world, start, 95, -36, 22, 98, -36, 22, Blocks.STONE_BRICKS.getDefaultState());
        structure.fillWithBlocks(world, start, 95, -36, 23, 97, -36, 26, Blocks.AIR.getDefaultState());
        structure.fillWithBlocks(world, start, 95, -36, 34, 96, -36, 35, Blocks.AIR.getDefaultState());
        structure.fillWithBlocks(world, start, 95, -36, 36, 95, -36, 36, Blocks.STONE_BRICKS.getDefaultState());
        structure.fillWithBlocks(world, start, 95, -36, 37, 95, -35, 37, Blocks.MOSSY_STONE_BRICKS.getDefaultState());
        structure.fillWithBlocks(world, start, 95, -36, 38, 95, -36, 38, Blocks.STONE_BRICKS.getDefaultState());
        structure.fillWithBlocks(world, start, 95, -36, 39, 95, -35, 39, Blocks.MOSSY_STONE_BRICKS.getDefaultState());
        structure.fillWithBlocks(world, start, 95, -35, 19, 95, -34, 19, Blocks.STONE_BRICKS.getDefaultState());
        structure.fillWithBlocks(world, start, 95, -35, 23, 97, -35, 26, Blocks.AIR.getDefaultState());
        structure.fillWithBlocks(world, start, 95, -35, 31, 95, -31, 31, Blocks.STONE_BRICKS.getDefaultState());
        structure.fillWithBlocks(world, start, 95, -35, 32, 97, -35, 35, Blocks.AIR.getDefaultState());
        structure.fillWithBlocks(world, start, 95, -35, 38, 95, -35, 39, Blocks.MOSSY_STONE_BRICKS.getDefaultState());
        structure.fillWithBlocks(world, start, 95, -34, 22, 96, -34, 22, Blocks.AIR.getDefaultState());
        structure.fillWithBlocks(world, start, 95, -34, 27, 95, -31, 27, Blocks.MOSSY_STONE_BRICKS.getDefaultState());
        structure.fillWithBlocks(world, start, 95, -34, 28, 95, -34, 29, Blocks.STONE_BRICKS.getDefaultState());
        structure.fillWithBlocks(world, start, 95, -34, 32, 95, -34, 33, Blocks.STONE_BRICKS.getDefaultState());
        structure.fillWithBlocks(world, start, 95, -34, 34, 95, -32, 34, Blocks.MOSSY_STONE_BRICKS.getDefaultState());
        structure.fillWithBlocks(world, start, 95, -34, 35, 96, -33, 35, Blocks.STONE_BRICKS.getDefaultState());
        structure.fillWithBlocks(world, start, 95, -34, 36, 96, -34, 36, Blocks.MOSSY_STONE_BRICKS.getDefaultState());
        structure.fillWithBlocks(world, start, 95, -34, 37, 95, -34, 37, Blocks.STONE_BRICKS.getDefaultState());
        structure.fillWithBlocks(world, start, 95, -34, 38, 95, -34, 38, Blocks.MOSSY_STONE_BRICKS.getDefaultState());
        structure.fillWithBlocks(world, start, 95, -34, 39, 95, -31, 39, Blocks.STONE_BRICKS.getDefaultState());
        structure.fillWithBlocks(world, start, 95, -33, 19, 96, -33, 19, Blocks.MOSSY_STONE_BRICKS.getDefaultState());
        structure.fillWithBlocks(world, start, 95, -33, 20, 95, -32, 20, Blocks.STONE_BRICKS.getDefaultState());
        structure.fillWithBlocks(world, start, 95, -33, 22, 95, -33, 22, Blocks.MOSSY_STONE_BRICKS.getDefaultState());
        structure.fillWithBlocks(world, start, 95, -33, 24, 95, -33, 24, Blocks.STONE_BRICKS.getDefaultState());
        structure.fillWithBlocks(world, start, 95, -33, 25, 95, -31, 25, Blocks.MOSSY_STONE_BRICKS.getDefaultState());
        structure.fillWithBlocks(world, start, 95, -33, 26, 95, -31, 26, Blocks.STONE_BRICKS.getDefaultState());
        structure.fillWithBlocks(world, start, 95, -33, 29, 97, -33, 29, Blocks.MOSSY_STONE_BRICKS.getDefaultState());
        structure.fillWithBlocks(world, start, 95, -33, 30, 95, -33, 31, Blocks.STONE_BRICKS.getDefaultState());
        structure.fillWithBlocks(world, start, 95, -33, 33, 95, -32, 33, Blocks.AIR.getDefaultState());
        structure.fillWithBlocks(world, start, 95, -33, 36, 95, -33, 37, Blocks.STONE_BRICKS.getDefaultState());
        structure.fillWithBlocks(world, start, 95, -32, 19, 96, -32, 21, Blocks.STONE_BRICKS.getDefaultState());
        structure.fillWithBlocks(world, start, 95, -32, 22, 95, -32, 25, Blocks.MOSSY_STONE_BRICKS.getDefaultState());
        structure.fillWithBlocks(world, start, 95, -32, 28, 95, -32, 29, Blocks.STONE_BRICKS.getDefaultState());
        structure.fillWithBlocks(world, start, 95, -32, 30, 95, -31, 30, Blocks.MOSSY_STONE_BRICKS.getDefaultState());
        structure.fillWithBlocks(world, start, 95, -32, 35, 95, -32, 36, Blocks.STONE_BRICKS.getDefaultState());
        structure.fillWithBlocks(world, start, 95, -32, 38, 95, -32, 38, Blocks.MOSSY_STONE_BRICKS.getDefaultState());
        structure.fillWithBlocks(world, start, 95, -31, 19, 96, -31, 19, Blocks.STONE_BRICKS.getDefaultState());
        structure.fillWithBlocks(world, start, 95, -31, 20, 95, -31, 22, Blocks.MOSSY_STONE_BRICKS.getDefaultState());
        structure.fillWithBlocks(world, start, 95, -31, 24, 95, -31, 25, Blocks.MOSSY_STONE_BRICKS.getDefaultState());
        structure.fillWithBlocks(world, start, 95, -31, 29, 96, -31, 29, Blocks.MOSSY_COBBLESTONE.getDefaultState());
        structure.fillWithBlocks(world, start, 95, -31, 32, 95, -31, 33, Blocks.MOSSY_STONE_BRICKS.getDefaultState());
        structure.fillWithBlocks(world, start, 95, -31, 35, 95, -31, 35, Blocks.STONE_BRICKS.getDefaultState());
        structure.fillWithBlocks(world, start, 95, -31, 37, 95, -31, 39, Blocks.STONE_BRICKS.getDefaultState());
        structure.fillWithBlocks(world, start, 95, -20, 45, 95, -20, 48, Blocks.STONE_BRICKS.getDefaultState());
        structure.fillWithBlocks(world, start, 95, -19, 45, 95, -16, 45, Blocks.STONE_BRICKS.getDefaultState());
        structure.fillWithBlocks(world, start, 95, -19, 49, 95, -18, 49, Blocks.STONE_BRICKS.getDefaultState());
        structure.fillWithBlocks(world, start, 95, -16, 48, 95, -16, 49, Blocks.STONE_BRICKS.getDefaultState());
        structure.fillWithBlocks(world, start, 95, -9, 40, 97, -9, 42, Blocks.STONE_BRICKS.getDefaultState());
        structure.fillWithBlocks(world, start, 95, -9, 43, 95, -8, 44, Blocks.AIR.getDefaultState());
        structure.fillWithBlocks(world, start, 95, -9, 45, 95, -5, 45, Blocks.STONE_BRICKS.getDefaultState());
        structure.fillWithBlocks(world, start, 95, -9, 46, 97, -9, 48, Blocks.AIR.getDefaultState());
        structure.fillWithBlocks(world, start, 95, -9, 49, 95, -1, 49, Blocks.STONE_BRICKS.getDefaultState());
        structure.fillWithBlocks(world, start, 95, -9, 50, 95, -8, 51, Blocks.AIR.getDefaultState());
        structure.fillWithBlocks(world, start, 95, -9, 52, 97, -9, 54, Blocks.STONE_BRICKS.getDefaultState());
        structure.fillWithBlocks(world, start, 95, -8, 42, 95, -1, 42, Blocks.STONE_BRICKS.getDefaultState());
        structure.fillWithBlocks(world, start, 95, -8, 46, 97, -8, 48, Blocks.AIR.getDefaultState());
        structure.fillWithBlocks(world, start, 95, -8, 52, 97, -8, 54, Blocks.STONE_BRICKS.getDefaultState());
        structure.fillWithBlocks(world, start, 95, -7, 43, 95, -6, 44, Blocks.AIR.getDefaultState());
        structure.fillWithBlocks(world, start, 95, -7, 46, 97, -7, 48, Blocks.AIR.getDefaultState());
        structure.fillWithBlocks(world, start, 95, -7, 50, 95, -6, 51, Blocks.AIR.getDefaultState());
        structure.fillWithBlocks(world, start, 95, -7, 52, 96, -7, 54, Blocks.STONE_BRICKS.getDefaultState());
        structure.fillWithBlocks(world, start, 95, -7, 99, 95, -6, 99, Blocks.CAVE_AIR.getDefaultState());
        structure.fillWithBlocks(world, start, 95, -6, 46, 95, -6, 48, Blocks.AIR.getDefaultState());
        structure.fillWithBlocks(world, start, 95, -6, 52, 97, -6, 54, Blocks.STONE_BRICKS.getDefaultState());
        structure.fillWithBlocks(world, start, 95, -5, 43, 95, -4, 44, Blocks.STONE_BRICKS.getDefaultState());
        structure.fillWithBlocks(world, start, 95, -4, 46, 97, -4, 49, Blocks.STONE_BRICKS.getDefaultState());
        structure.fillWithBlocks(world, start, 95, -4, 51, 97, -4, 54, Blocks.STONE_BRICKS.getDefaultState());
        structure.fillWithBlocks(world, start, 95, -2, 40, 97, -2, 46, Blocks.STONE_BRICKS.getDefaultState());
        structure.fillWithBlocks(world, start, 95, -2, 51, 97, -2, 54, Blocks.STONE_BRICKS.getDefaultState());
        structure.fillWithBlocks(world, start, 95, -1, 40, 97, -1, 45, Blocks.STONE_BRICKS.getDefaultState());
        structure.fillWithBlocks(world, start, 95, -1, 46, 95, -1, 54, Blocks.STONE_BRICKS.getDefaultState());
        structure.fillWithBlocks(world, start, 95, 0, 13, 95, 0, 16, Blocks.GRASS_BLOCK.getDefaultState().with(SnowyDirtBlock.SNOWY, false));
        structure.fillWithBlocks(world, start, 95, 0, 17, 95, 0, 61, Blocks.DIRT.getDefaultState());
        structure.fillWithBlocks(world, start, 95, 0, 68, 97, 0, 70, Blocks.DIRT.getDefaultState());
        structure.fillWithBlocks(world, start, 95, 0, 72, 97, 0, 76, Blocks.DIRT.getDefaultState());
        structure.fillWithBlocks(world, start, 95, 0, 80, 96, 0, 81, Blocks.GRASS_BLOCK.getDefaultState().with(SnowyDirtBlock.SNOWY, false));
        structure.fillWithBlocks(world, start, 95, 1, 17, 95, 1, 19, Blocks.GRASS_BLOCK.getDefaultState().with(SnowyDirtBlock.SNOWY, false));
        structure.fillWithBlocks(world, start, 95, 1, 20, 95, 1, 76, Blocks.DIRT.getDefaultState());
        structure.fillWithBlocks(world, start, 95, 1, 77, 96, 1, 78, Blocks.GRASS_BLOCK.getDefaultState().with(SnowyDirtBlock.SNOWY, false));
        structure.fillWithBlocks(world, start, 95, 2, 20, 95, 2, 43, Blocks.GRASS_BLOCK.getDefaultState().with(SnowyDirtBlock.SNOWY, false));
        structure.fillWithBlocks(world, start, 95, 2, 44, 95, 2, 74, Blocks.DIRT.getDefaultState());
        structure.fillWithBlocks(world, start, 95, 2, 75, 95, 2, 76, Blocks.GRASS_BLOCK.getDefaultState().with(SnowyDirtBlock.SNOWY, false));
        structure.fillWithBlocks(world, start, 95, 3, 44, 95, 3, 49, Blocks.GRASS_BLOCK.getDefaultState().with(SnowyDirtBlock.SNOWY, false));
        structure.fillWithBlocks(world, start, 95, 3, 72, 95, 3, 74, Blocks.GRASS_BLOCK.getDefaultState().with(SnowyDirtBlock.SNOWY, false));
        structure.fillWithBlocks(world, start, 95, 4, 50, 95, 4, 58, Blocks.GRASS_BLOCK.getDefaultState().with(SnowyDirtBlock.SNOWY, false));
        structure.fillWithBlocks(world, start, 95, 4, 59, 95, 4, 67, Blocks.DIRT.getDefaultState());
        structure.fillWithBlocks(world, start, 95, 4, 68, 96, 4, 69, Blocks.GRASS_BLOCK.getDefaultState().with(SnowyDirtBlock.SNOWY, false));
        structure.fillWithBlocks(world, start, 95, 4, 70, 95, 4, 71, Blocks.GRASS_BLOCK.getDefaultState().with(SnowyDirtBlock.SNOWY, false));
        structure.fillWithBlocks(world, start, 95, 5, 59, 95, 5, 67, Blocks.GRASS_BLOCK.getDefaultState().with(SnowyDirtBlock.SNOWY, false));
        structure.fillWithBlocks(world, start, 96, -50, -6, 97, -50, -5, Blocks.STONE_BRICKS.getDefaultState());
        structure.fillWithBlocks(world, start, 96, -48, 49, 96, -41, 49, Blocks.STONE_BRICKS.getDefaultState());
        structure.fillWithBlocks(world, start, 96, -48, 51, 96, -47, 54, Blocks.STONE_BRICKS.getDefaultState());
        structure.fillWithBlocks(world, start, 96, -47, 42, 96, -41, 42, Blocks.STONE_BRICKS.getDefaultState());
        structure.fillWithBlocks(world, start, 96, -47, 44, 96, -44, 50, Blocks.STONE_BRICKS.getDefaultState());
        structure.fillWithBlocks(world, start, 96, -47, 56, 96, -47, 62, Blocks.STONE_BRICKS.getDefaultState());
        structure.fillWithBlocks(world, start, 96, -46, 43, 96, -44, 50, Blocks.STONE_BRICKS.getDefaultState());
        structure.fillWithBlocks(world, start, 96, -46, 52, 96, -45, 53, Blocks.STONE_BRICKS.getDefaultState());
        structure.fillWithBlocks(world, start, 96, -46, 54, 96, -46, 56, Blocks.STONE_BRICKS.getDefaultState());
        structure.fillWithBlocks(world, start, 96, -46, 57, 96, -46, 58, Blocks.AIR.getDefaultState());
        structure.fillWithBlocks(world, start, 96, -46, 59, 96, -43, 62, Blocks.STONE_BRICKS.getDefaultState());
        structure.fillWithBlocks(world, start, 96, -45, 51, 96, -43, 53, Blocks.STONE_BRICKS.getDefaultState());
        structure.fillWithBlocks(world, start, 96, -45, 55, 96, -44, 56, Blocks.STONE_BRICKS.getDefaultState());
        structure.fillWithBlocks(world, start, 96, -45, 58, 96, -41, 62, Blocks.STONE_BRICKS.getDefaultState());
        structure.fillWithBlocks(world, start, 96, -44, -17, 96, -44, -17, Blocks.STONE_BRICKS.getDefaultState());
