package mod.arcalitegames.odyssey.world.structure.structures.statues.sphinx;

import mod.arcalitegames.odyssey.world.structure.StructureBase;
import net.minecraft.block.Blocks;
import net.minecraft.util.math.BlockPos;
import net.minecraft.world.World;

public class SphinxComponents
{

	public static BlockPos start;
    public static World world;
    public static StructureBase structure;

    public static void init(World worldIn, BlockPos blockPos, StructureBase structureIn)
    {
        world = worldIn; start = blockPos; structure = structureIn;
    }
    
    public static void generatePart1()
    {
        structure.setBlockState(world, Blocks.SANDSTONE.getDefaultState(), 0, 0, 0, start);
        structure.setBlockState(world, Blocks.STONE.getDefaultState(), 15, 0, 72, start);
        structure.setBlockState(world, Blocks.SANDSTONE.getDefaultState(), 21, 0, 14, start);
        structure.setBlockState(world, Blocks.SANDSTONE.getDefaultState(), 26, 7, 56, start);
        structure.setBlockState(world, Blocks.SANDSTONE.getDefaultState(), 27, 0, 13, start);
        structure.setBlockState(world, Blocks.SANDSTONE.getDefaultState(), 30, 0, 11, start);
        structure.setBlockState(world, Blocks.SANDSTONE.getDefaultState(), 30, 12, 40, start);
        structure.setBlockState(world, Blocks.STONE.getDefaultState(), 61, 0, 78, start);
        structure.setBlockState(world, Blocks.STONE.getDefaultState(), 61, 1, 76, start);
        structure.setBlockState(world, Blocks.SANDSTONE.getDefaultState(), 61, 20, 22, start);
        structure.setBlockState(world, Blocks.SANDSTONE.getDefaultState(), 61, 20, 54, start);
        structure.setBlockState(world, Blocks.SANDSTONE.getDefaultState(), 62, 19, 22, start);
        structure.setBlockState(world, Blocks.SANDSTONE.getDefaultState(), 62, 19, 54, start);
        structure.setBlockState(world, Blocks.SANDSTONE.getDefaultState(), 74, 0, 11, start);
        structure.setBlockState(world, Blocks.SANDSTONE.getDefaultState(), 85, 0, 73, start);
        structure.setBlockState(world, Blocks.STONE.getDefaultState(), 86, 0, 82, start);
        structure.setBlockState(world, Blocks.SANDSTONE.getDefaultState(), 98, 0, 9, start);
        structure.setBlockState(world, Blocks.SANDSTONE.getDefaultState(), 101, 0, 85, start);
        structure.setBlockState(world, Blocks.STONE.getDefaultState(), 103, 1, 75, start);
        structure.setBlockState(world, Blocks.SANDSTONE.getDefaultState(), 105, 13, 50, start);
        structure.setBlockState(world, Blocks.SANDSTONE.getDefaultState(), 105, 14, 49, start);
        structure.setBlockState(world, Blocks.BLACK_WOOL.getDefaultState(), 105, 42, 32, start);
        structure.setBlockState(world, Blocks.WHITE_WOOL.getDefaultState(), 105, 42, 33, start);
        structure.setBlockState(world, Blocks.BLACK_WOOL.getDefaultState(), 105, 42, 44, start);
        structure.setBlockState(world, Blocks.AIR.getDefaultState(), 106, 6, 38, start);
        structure.setBlockState(world, Blocks.BLACK_WOOL.getDefaultState(), 106, 41, 33, start);
        structure.setBlockState(world, Blocks.BLACK_WOOL.getDefaultState(), 106, 41, 43, start);
        structure.setBlockState(world, Blocks.BLACK_WOOL.getDefaultState(), 107, 41, 36, start);
        structure.setBlockState(world, Blocks.BLACK_WOOL.getDefaultState(), 107, 41, 40, start);
        structure.setBlockState(world, Blocks.STONE.getDefaultState(), 109, 0, 77, start);
        structure.setBlockState(world, Blocks.STONE.getDefaultState(), 109, 1, 13, start);
        structure.setBlockState(world, Blocks.SANDSTONE.getDefaultState(), 121, 0, 11, start);
        structure.setBlockState(world, Blocks.SANDSTONE.getDefaultState(), 123, 0, 10, start);
        structure.setBlockState(world, Blocks.STONE.getDefaultState(), 133, 0, 73, start);
        structure.setBlockState(world, Blocks.SANDSTONE.getDefaultState(), 144, 0, 81, start);
        structure.setBlockState(world, Blocks.SAND.getDefaultState(), 144, 3, 78, start);
        structure.setBlockState(world, Blocks.STONE.getDefaultState(), 145, 0, 73, start);
        structure.setBlockState(world, Blocks.SAND.getDefaultState(), 145, 4, 76, start);
        structure.setBlockState(world, Blocks.SAND.getDefaultState(), 147, 1, 77, start);
        structure.setBlockState(world, Blocks.STONE.getDefaultState(), 148, 0, 73, start);
        structure.setBlockState(world, Blocks.STONE.getDefaultState(), 148, 1, 22, start);
        structure.setBlockState(world, Blocks.SANDSTONE.getDefaultState(), 149, 0, 77, start);
        structure.setBlockState(world, Blocks.SAND.getDefaultState(), 149, 1, 75, start);
        structure.setBlockState(world, Blocks.SANDSTONE.getDefaultState(), 150, 0, 30, start);
        structure.fillWithBlocks(world, start, 6, 0, 22, 8, 0, 24, Blocks.SANDSTONE.getDefaultState());
        structure.fillWithBlocks(world, start, 7, 0, 17, 12, 0, 33, Blocks.SANDSTONE.getDefaultState());
        structure.fillWithBlocks(world, start, 7, 0, 50, 15, 0, 60, Blocks.SANDSTONE.getDefaultState());
        structure.fillWithBlocks(world, start, 7, 0, 61, 12, 0, 67, Blocks.SANDSTONE.getDefaultState());
        structure.fillWithBlocks(world, start, 7, 1, 23, 12, 1, 28, Blocks.SAND.getDefaultState());
        structure.fillWithBlocks(world, start, 8, 0, 15, 13, 0, 21, Blocks.SANDSTONE.getDefaultState());
        structure.fillWithBlocks(world, start, 8, 0, 34, 12, 0, 38, Blocks.SANDSTONE.getDefaultState());
        structure.fillWithBlocks(world, start, 8, 0, 45, 16, 0, 55, Blocks.SANDSTONE.getDefaultState());
        structure.fillWithBlocks(world, start, 8, 0, 68, 11, 0, 71, Blocks.SANDSTONE.getDefaultState());
        structure.fillWithBlocks(world, start, 8, 1, 18, 21, 1, 35, Blocks.SAND.getDefaultState());
        structure.fillWithBlocks(world, start, 8, 1, 55, 16, 1, 63, Blocks.SAND.getDefaultState());
        structure.fillWithBlocks(world, start, 8, 2, 22, 17, 2, 31, Blocks.SAND.getDefaultState());
        structure.fillWithBlocks(world, start, 9, 0, 13, 14, 0, 19, Blocks.SANDSTONE.getDefaultState());
        structure.fillWithBlocks(world, start, 9, 0, 39, 14, 0, 61, Blocks.SANDSTONE.getDefaultState());
        structure.fillWithBlocks(world, start, 9, 0, 72, 11, 0, 74, Blocks.SANDSTONE.getDefaultState());
        structure.fillWithBlocks(world, start, 9, 1, 16, 21, 1, 39, Blocks.SAND.getDefaultState());
        structure.fillWithBlocks(world, start, 9, 1, 49, 16, 1, 70, Blocks.SAND.getDefaultState());
        structure.fillWithBlocks(world, start, 9, 2, 18, 21, 2, 36, Blocks.SAND.getDefaultState());
        structure.fillWithBlocks(world, start, 9, 3, 21, 20, 3, 32, Blocks.SAND.getDefaultState());
        structure.fillWithBlocks(world, start, 10, 0, 12, 15, 0, 17, Blocks.SANDSTONE.getDefaultState());
        structure.fillWithBlocks(world, start, 10, 0, 75, 10, 0, 75, Blocks.SANDSTONE.getDefaultState());
        structure.fillWithBlocks(world, start, 10, 1, 14, 21, 1, 53, Blocks.SAND.getDefaultState());
        structure.fillWithBlocks(world, start, 10, 1, 71, 12, 1, 73, Blocks.SAND.getDefaultState());
        structure.fillWithBlocks(world, start, 10, 2, 16, 21, 2, 39, Blocks.SAND.getDefaultState());
        structure.fillWithBlocks(world, start, 10, 2, 51, 21, 2, 69, Blocks.SAND.getDefaultState());
        structure.fillWithBlocks(world, start, 10, 3, 18, 21, 3, 36, Blocks.SAND.getDefaultState());
        structure.fillWithBlocks(world, start, 10, 4, 23, 18, 4, 31, Blocks.SAND.getDefaultState());
        structure.fillWithBlocks(world, start, 11, 0, 11, 16, 0, 16, Blocks.SANDSTONE.getDefaultState());
        structure.fillWithBlocks(world, start, 11, 0, 75, 13, 0, 77, Blocks.SANDSTONE.getDefaultState());
        structure.fillWithBlocks(world, start, 11, 1, 13, 21, 1, 53, Blocks.SAND.getDefaultState());
        structure.fillWithBlocks(world, start, 11, 1, 74, 12, 1, 75, Blocks.SAND.getDefaultState());
        structure.fillWithBlocks(world, start, 11, 2, 15, 21, 2, 44, Blocks.SAND.getDefaultState());
        structure.fillWithBlocks(world, start, 11, 2, 46, 21, 2, 72, Blocks.SAND.getDefaultState());
        structure.fillWithBlocks(world, start, 11, 3, 16, 21, 3, 39, Blocks.SAND.getDefaultState());
        structure.fillWithBlocks(world, start, 11, 3, 54, 21, 3, 68, Blocks.SAND.getDefaultState());
        structure.fillWithBlocks(world, start, 11, 4, 19, 27, 4, 35, Blocks.SAND.getDefaultState());
        structure.fillWithBlocks(world, start, 12, 0, 10, 17, 0, 15, Blocks.SANDSTONE.getDefaultState());
        structure.fillWithBlocks(world, start, 12, 0, 68, 12, 0, 78, Blocks.SANDSTONE.getDefaultState());
        structure.fillWithBlocks(world, start, 12, 1, 12, 21, 1, 53, Blocks.SAND.getDefaultState());
        structure.fillWithBlocks(world, start, 12, 1, 76, 12, 1, 76, Blocks.SAND.getDefaultState());
        structure.fillWithBlocks(world, start, 12, 2, 13, 21, 2, 74, Blocks.SAND.getDefaultState());
        structure.fillWithBlocks(world, start, 12, 3, 15, 21, 3, 44, Blocks.SAND.getDefaultState());
        structure.fillWithBlocks(world, start, 12, 3, 48, 21, 3, 71, Blocks.SAND.getDefaultState());
        structure.fillWithBlocks(world, start, 12, 4, 17, 34, 4, 39, Blocks.SAND.getDefaultState());
        structure.fillWithBlocks(world, start, 13, 0, 9, 18, 0, 15, Blocks.SANDSTONE.getDefaultState());
        structure.fillWithBlocks(world, start, 13, 0, 22, 22, 0, 31, Blocks.STONE.getDefaultState());
        structure.fillWithBlocks(world, start, 13, 0, 32, 13, 0, 62, Blocks.SANDSTONE.getDefaultState());
        structure.fillWithBlocks(world, start, 13, 0, 63, 18, 0, 68, Blocks.STONE.getDefaultState());
        structure.fillWithBlocks(world, start, 13, 0, 69, 13, 0, 79, Blocks.SANDSTONE.getDefaultState());
        structure.fillWithBlocks(world, start, 13, 1, 11, 21, 1, 53, Blocks.SAND.getDefaultState());
        structure.fillWithBlocks(world, start, 13, 1, 71, 18, 1, 77, Blocks.SAND.getDefaultState());
        structure.fillWithBlocks(world, start, 13, 2, 12, 21, 2, 75, Blocks.SAND.getDefaultState());
        structure.fillWithBlocks(world, start, 13, 3, 14, 21, 3, 73, Blocks.SAND.getDefaultState());
        structure.fillWithBlocks(world, start, 13, 4, 16, 39, 4, 42, Blocks.SAND.getDefaultState());
        structure.fillWithBlocks(world, start, 13, 4, 53, 28, 4, 68, Blocks.SAND.getDefaultState());
        structure.fillWithBlocks(world, start, 13, 5, 22, 22, 5, 31, Blocks.SAND.getDefaultState());
        structure.fillWithBlocks(world, start, 14, 0, 8, 20, 0, 14, Blocks.SANDSTONE.getDefaultState());
        structure.fillWithBlocks(world, start, 14, 0, 20, 29, 0, 35, Blocks.STONE.getDefaultState());
        structure.fillWithBlocks(world, start, 14, 0, 36, 14, 0, 61, Blocks.SANDSTONE.getDefaultState());
        structure.fillWithBlocks(world, start, 14, 0, 62, 23, 0, 71, Blocks.STONE.getDefaultState());
        structure.fillWithBlocks(world, start, 14, 0, 72, 14, 0, 80, Blocks.SANDSTONE.getDefaultState());
        structure.fillWithBlocks(world, start, 14, 1, 10, 21, 1, 53, Blocks.SAND.getDefaultState());
        structure.fillWithBlocks(world, start, 14, 1, 78, 14, 1, 78, Blocks.SAND.getDefaultState());
        structure.fillWithBlocks(world, start, 14, 2, 76, 14, 2, 76, Blocks.SAND.getDefaultState());
        structure.fillWithBlocks(world, start, 14, 3, 13, 21, 3, 74, Blocks.SAND.getDefaultState());
        structure.fillWithBlocks(world, start, 14, 4, 15, 70, 4, 71, Blocks.SAND.getDefaultState());
        structure.fillWithBlocks(world, start, 14, 5, 20, 29, 5, 35, Blocks.SAND.getDefaultState());
        structure.fillWithBlocks(world, start, 15, 0, 18, 36, 0, 39, Blocks.STONE.getDefaultState());
        structure.fillWithBlocks(world, start, 15, 0, 40, 15, 0, 60, Blocks.SANDSTONE.getDefaultState());
        structure.fillWithBlocks(world, start, 15, 0, 61, 25, 0, 71, Blocks.STONE.getDefaultState());
        structure.fillWithBlocks(world, start, 15, 0, 73, 19, 0, 80, Blocks.SANDSTONE.getDefaultState());
        structure.fillWithBlocks(world, start, 15, 1, 9, 21, 1, 53, Blocks.SAND.getDefaultState());
        structure.fillWithBlocks(world, start, 15, 1, 78, 16, 1, 79, Blocks.SAND.getDefaultState());
        structure.fillWithBlocks(world, start, 15, 2, 11, 21, 2, 77, Blocks.SAND.getDefaultState());
        structure.fillWithBlocks(world, start, 15, 3, 12, 21, 3, 76, Blocks.SAND.getDefaultState());
        structure.fillWithBlocks(world, start, 15, 4, 14, 74, 4, 73, Blocks.SAND.getDefaultState());
        structure.fillWithBlocks(world, start, 15, 5, 18, 36, 5, 39, Blocks.SAND.getDefaultState());
        structure.fillWithBlocks(world, start, 16, 0, 7, 22, 0, 13, Blocks.SANDSTONE.getDefaultState());
        structure.fillWithBlocks(world, start, 16, 0, 17, 40, 0, 41, Blocks.STONE.getDefaultState());
        structure.fillWithBlocks(world, start, 16, 0, 42, 16, 0, 55, Blocks.SANDSTONE.getDefaultState());
        structure.fillWithBlocks(world, start, 16, 0, 56, 31, 0, 71, Blocks.STONE.getDefaultState());
        structure.fillWithBlocks(world, start, 16, 0, 72, 18, 0, 81, Blocks.SANDSTONE.getDefaultState());
        structure.fillWithBlocks(world, start, 16, 2, 10, 21, 2, 78, Blocks.SAND.getDefaultState());
        structure.fillWithBlocks(world, start, 16, 3, 77, 145, 3, 77, Blocks.SAND.getDefaultState());
        structure.fillWithBlocks(world, start, 16, 4, 13, 77, 4, 74, Blocks.SAND.getDefaultState());
        structure.fillWithBlocks(world, start, 16, 5, 17, 41, 5, 42, Blocks.SAND.getDefaultState());
        structure.fillWithBlocks(world, start, 17, 0, 16, 43, 0, 42, Blocks.STONE.getDefaultState());
        structure.fillWithBlocks(world, start, 17, 0, 43, 17, 0, 47, Blocks.SANDSTONE.getDefaultState());
        structure.fillWithBlocks(world, start, 17, 0, 48, 40, 0, 71, Blocks.STONE.getDefaultState());
        structure.fillWithBlocks(world, start, 17, 1, 54, 17, 5, 54, Blocks.SAND.getDefaultState());
        structure.fillWithBlocks(world, start, 17, 1, 55, 20, 1, 68, Blocks.STONE.getDefaultState());
        structure.fillWithBlocks(world, start, 17, 1, 69, 17, 4, 75, Blocks.SAND.getDefaultState());
        structure.fillWithBlocks(world, start, 17, 1, 78, 19, 1, 80, Blocks.SAND.getDefaultState());
        structure.fillWithBlocks(world, start, 17, 2, 79, 144, 2, 79, Blocks.SAND.getDefaultState());
        structure.fillWithBlocks(world, start, 17, 3, 11, 21, 3, 77, Blocks.SAND.getDefaultState());
        structure.fillWithBlocks(world, start, 17, 5, 16, 69, 5, 68, Blocks.SAND.getDefaultState());
        structure.fillWithBlocks(world, start, 18, 0, 43, 18, 0, 43, Blocks.STONE.getDefaultState());
        structure.fillWithBlocks(world, start, 18, 0, 44, 18, 0, 46, Blocks.SANDSTONE.getDefaultState());
        structure.fillWithBlocks(world, start, 18, 0, 47, 42, 0, 71, Blocks.STONE.getDefaultState());
        structure.fillWithBlocks(world, start, 18, 0, 82, 84, 0, 82, Blocks.SANDSTONE.getDefaultState());
        structure.fillWithBlocks(world, start, 18, 1, 8, 24, 1, 14, Blocks.SAND.getDefaultState());
        structure.fillWithBlocks(world, start, 18, 1, 54, 19, 1, 70, Blocks.STONE.getDefaultState());
        structure.fillWithBlocks(world, start, 18, 1, 81, 142, 1, 81, Blocks.SAND.getDefaultState());
        structure.fillWithBlocks(world, start, 18, 3, 78, 18, 3, 78, Blocks.SAND.getDefaultState());
        structure.fillWithBlocks(world, start, 18, 4, 12, 82, 4, 76, Blocks.SAND.getDefaultState());
        structure.fillWithBlocks(world, start, 18, 5, 69, 19, 5, 70, Blocks.SAND.getDefaultState());
        structure.fillWithBlocks(world, start, 19, 0, 6, 26, 0, 13, Blocks.SANDSTONE.getDefaultState());
        structure.fillWithBlocks(world, start, 19, 0, 15, 76, 0, 72, Blocks.STONE.getDefaultState());
        structure.fillWithBlocks(world, start, 19, 0, 81, 20, 0, 82, Blocks.SANDSTONE.getDefaultState());
        structure.fillWithBlocks(world, start, 19, 1, 71, 19, 1, 72, Blocks.STONE.getDefaultState());
        structure.fillWithBlocks(world, start, 19, 1, 73, 27, 1, 81, Blocks.SAND.getDefaultState());
        structure.fillWithBlocks(world, start, 19, 2, 9, 24, 2, 14, Blocks.SAND.getDefaultState());
        structure.fillWithBlocks(world, start, 19, 2, 80, 142, 2, 80, Blocks.SAND.getDefaultState());
        structure.fillWithBlocks(world, start, 19, 3, 10, 23, 3, 14, Blocks.SAND.getDefaultState());
        structure.fillWithBlocks(world, start, 19, 3, 78, 20, 3, 79, Blocks.SAND.getDefaultState());
        structure.fillWithBlocks(world, start, 19, 4, 77, 144, 4, 77, Blocks.SAND.getDefaultState());
        structure.fillWithBlocks(world, start, 19, 5, 15, 76, 5, 72, Blocks.SAND.getDefaultState());
        structure.fillWithBlocks(world, start, 20, 0, 73, 20, 0, 73, Blocks.STONE.getDefaultState());
        structure.fillWithBlocks(world, start, 20, 0, 74, 20, 0, 83, Blocks.SANDSTONE.getDefaultState());
        structure.fillWithBlocks(world, start, 20, 1, 54, 20, 1, 54, Blocks.SAND.getDefaultState());
        structure.fillWithBlocks(world, start, 20, 1, 69, 20, 1, 71, Blocks.STONE.getDefaultState());
        structure.fillWithBlocks(world, start, 20, 1, 72, 21, 1, 82, Blocks.SAND.getDefaultState());
        structure.fillWithBlocks(world, start, 20, 5, 73, 20, 5, 73, Blocks.SAND.getDefaultState());
        structure.fillWithBlocks(world, start, 21, 0, 73, 22, 0, 74, Blocks.STONE.getDefaultState());
        structure.fillWithBlocks(world, start, 21, 0, 75, 22, 0, 83, Blocks.SANDSTONE.getDefaultState());
        structure.fillWithBlocks(world, start, 21, 1, 54, 21, 2, 55, Blocks.SAND.getDefaultState());
        structure.fillWithBlocks(world, start, 21, 1, 56, 34, 1, 69, Blocks.STONE.getDefaultState());
        structure.fillWithBlocks(world, start, 21, 1, 70, 21, 5, 74, Blocks.SAND.getDefaultState());
        structure.fillWithBlocks(world, start, 21, 2, 81, 110, 2, 81, Blocks.SAND.getDefaultState());
        structure.fillWithBlocks(world, start, 21, 3, 78, 23, 3, 80, Blocks.SAND.getDefaultState());
        structure.fillWithBlocks(world, start, 21, 4, 11, 88, 4, 78, Blocks.SAND.getDefaultState());
        structure.fillWithBlocks(world, start, 22, 0, 14, 44, 0, 74, Blocks.STONE.getDefaultState());
        structure.fillWithBlocks(world, start, 22, 0, 84, 107, 0, 84, Blocks.SANDSTONE.getDefaultState());
        structure.fillWithBlocks(world, start, 22, 1, 7, 28, 1, 13, Blocks.SAND.getDefaultState());
        structure.fillWithBlocks(world, start, 22, 1, 15, 79, 1, 72, Blocks.STONE.getDefaultState());
        structure.fillWithBlocks(world, start, 22, 1, 82, 22, 1, 82, Blocks.SAND.getDefaultState());
        structure.fillWithBlocks(world, start, 22, 2, 15, 79, 2, 72, Blocks.STONE.getDefaultState());
        structure.fillWithBlocks(world, start, 22, 2, 73, 30, 2, 81, Blocks.SAND.getDefaultState());
        structure.fillWithBlocks(world, start, 22, 3, 15, 79, 3, 72, Blocks.STONE.getDefaultState());
        structure.fillWithBlocks(world, start, 22, 3, 73, 29, 3, 80, Blocks.SAND.getDefaultState());
        structure.fillWithBlocks(world, start, 22, 5, 14, 82, 5, 74, Blocks.SAND.getDefaultState());
        structure.fillWithBlocks(world, start, 23, 0, 75, 36, 0, 75, Blocks.STONE.getDefaultState());
        structure.fillWithBlocks(world, start, 23, 0, 76, 23, 0, 78, Blocks.SANDSTONE.getDefaultState());
        structure.fillWithBlocks(world, start, 23, 0, 79, 34, 0, 79, Blocks.STONE.getDefaultState());
        structure.fillWithBlocks(world, start, 23, 0, 80, 27, 0, 84, Blocks.SANDSTONE.getDefaultState());
        structure.fillWithBlocks(world, start, 23, 1, 82, 24, 1, 83, Blocks.SAND.getDefaultState());
        structure.fillWithBlocks(world, start, 23, 2, 82, 103, 2, 82, Blocks.SAND.getDefaultState());
        structure.fillWithBlocks(world, start, 23, 4, 79, 103, 4, 79, Blocks.SAND.getDefaultState());
        structure.fillWithBlocks(world, start, 23, 5, 75, 36, 5, 75, Blocks.SAND.getDefaultState());
        structure.fillWithBlocks(world, start, 23, 6, 50, 25, 6, 52, Blocks.SANDSTONE.getDefaultState());
        structure.fillWithBlocks(world, start, 23, 7, 46, 25, 7, 49, Blocks.SANDSTONE.getDefaultState());
        structure.fillWithBlocks(world, start, 24, 0, 76, 25, 0, 76, Blocks.SANDSTONE.getDefaultState());
        structure.fillWithBlocks(world, start, 24, 0, 77, 26, 0, 79, Blocks.STONE.getDefaultState());
        structure.fillWithBlocks(world, start, 24, 3, 10, 28, 3, 14, Blocks.SAND.getDefaultState());
        structure.fillWithBlocks(world, start, 24, 3, 81, 36, 3, 81, Blocks.SAND.getDefaultState());
        structure.fillWithBlocks(world, start, 24, 6, 47, 24, 8, 52, Blocks.SANDSTONE.getDefaultState());
        structure.fillWithBlocks(world, start, 24, 6, 53, 26, 6, 55, Blocks.SANDSTONE.getDefaultState());
        structure.fillWithBlocks(world, start, 24, 7, 44, 25, 7, 49, Blocks.SANDSTONE.getDefaultState());
        structure.fillWithBlocks(world, start, 24, 8, 46, 24, 9, 48, Blocks.SANDSTONE.getDefaultState());
        structure.fillWithBlocks(world, start, 25, 1, 14, 26, 2, 14, Blocks.SAND.getDefaultState());
        structure.fillWithBlocks(world, start, 25, 1, 82, 26, 1, 83, Blocks.SAND.getDefaultState());
        structure.fillWithBlocks(world, start, 25, 2, 9, 30, 2, 14, Blocks.SAND.getDefaultState());
        structure.fillWithBlocks(world, start, 25, 6, 56, 25, 6, 56, Blocks.SANDSTONE.getDefaultState());
        structure.fillWithBlocks(world, start, 25, 7, 53, 25, 7, 55, Blocks.SANDSTONE.getDefaultState());
        structure.fillWithBlocks(world, start, 25, 8, 42, 25, 8, 45, Blocks.SANDSTONE.getDefaultState());
        structure.fillWithBlocks(world, start, 25, 9, 44, 25, 10, 45, Blocks.SANDSTONE.getDefaultState());
        structure.fillWithBlocks(world, start, 26, 0, 76, 29, 0, 79, Blocks.STONE.getDefaultState());
        structure.fillWithBlocks(world, start, 26, 0, 85, 35, 0, 85, Blocks.SANDSTONE.getDefaultState());
        structure.fillWithBlocks(world, start, 26, 6, 56, 27, 6, 58, Blocks.SANDSTONE.getDefaultState());
        structure.fillWithBlocks(world, start, 26, 8, 43, 26, 8, 45, Blocks.SANDSTONE.getDefaultState());
        structure.fillWithBlocks(world, start, 26, 9, 41, 27, 9, 43, Blocks.SANDSTONE.getDefaultState());
        structure.fillWithBlocks(world, start, 26, 10, 42, 26, 11, 43, Blocks.SANDSTONE.getDefaultState());
        structure.fillWithBlocks(world, start, 27, 0, 6, 31, 0, 10, Blocks.SANDSTONE.getDefaultState());
        structure.fillWithBlocks(world, start, 27, 0, 11, 28, 0, 12, Blocks.SANDSTONE.getDefaultState());
        structure.fillWithBlocks(world, start, 27, 1, 14, 38, 1, 72, Blocks.STONE.getDefaultState());
        structure.fillWithBlocks(world, start, 27, 1, 82, 28, 1, 83, Blocks.SAND.getDefaultState());
        structure.fillWithBlocks(world, start, 27, 6, 59, 27, 6, 59, Blocks.SANDSTONE.getDefaultState());
        structure.fillWithBlocks(world, start, 27, 10, 40, 28, 10, 41, Blocks.SANDSTONE.getDefaultState());
        structure.fillWithBlocks(world, start, 27, 11, 41, 27, 12, 41, Blocks.SANDSTONE.getDefaultState());
        structure.fillWithBlocks(world, start, 28, 0, 13, 39, 0, 74, Blocks.STONE.getDefaultState());
        structure.fillWithBlocks(world, start, 28, 0, 80, 33, 0, 85, Blocks.SANDSTONE.getDefaultState());
        structure.fillWithBlocks(world, start, 28, 1, 73, 38, 1, 83, Blocks.SAND.getDefaultState());
        structure.fillWithBlocks(world, start, 28, 6, 59, 28, 6, 61, Blocks.SANDSTONE.getDefaultState());
        structure.fillWithBlocks(world, start, 28, 11, 39, 29, 11, 40, Blocks.SANDSTONE.getDefaultState());
        structure.fillWithBlocks(world, start, 28, 12, 40, 28, 13, 40, Blocks.SANDSTONE.getDefaultState());
        structure.fillWithBlocks(world, start, 29, 0, 5, 34, 0, 10, Blocks.SANDSTONE.getDefaultState());
        structure.fillWithBlocks(world, start, 29, 0, 11, 29, 0, 12, Blocks.SANDSTONE.getDefaultState());
        structure.fillWithBlocks(world, start, 29, 1, 7, 35, 1, 13, Blocks.SAND.getDefaultState());
        structure.fillWithBlocks(world, start, 29, 1, 84, 32, 1, 84, Blocks.SAND.getDefaultState());
        structure.fillWithBlocks(world, start, 29, 3, 10, 33, 3, 14, Blocks.SAND.getDefaultState());
        structure.fillWithBlocks(world, start, 29, 6, 61, 29, 6, 62, Blocks.SANDSTONE.getDefaultState());
        structure.fillWithBlocks(world, start, 29, 12, 38, 30, 12, 39, Blocks.SANDSTONE.getDefaultState());
        structure.fillWithBlocks(world, start, 29, 13, 39, 30, 14, 39, Blocks.SANDSTONE.getDefaultState());
        structure.fillWithBlocks(world, start, 30, 0, 12, 39, 0, 74, Blocks.STONE.getDefaultState());
        structure.fillWithBlocks(world, start, 30, 0, 76, 32, 0, 79, Blocks.STONE.getDefaultState());
        structure.fillWithBlocks(world, start, 30, 3, 73, 37, 3, 80, Blocks.SAND.getDefaultState());
        structure.fillWithBlocks(world, start, 30, 6, 62, 30, 6, 63, Blocks.SANDSTONE.getDefaultState());
        structure.fillWithBlocks(world, start, 31, 0, 11, 39, 0, 74, Blocks.STONE.getDefaultState());
        structure.fillWithBlocks(world, start, 31, 2, 9, 36, 2, 14, Blocks.SAND.getDefaultState());
        structure.fillWithBlocks(world, start, 31, 2, 73, 40, 2, 82, Blocks.SAND.getDefaultState());
        structure.fillWithBlocks(world, start, 31, 6, 63, 31, 6, 64, Blocks.SANDSTONE.getDefaultState());
        structure.fillWithBlocks(world, start, 31, 12, 38, 31, 15, 38, Blocks.SANDSTONE.getDefaultState());
        structure.fillWithBlocks(world, start, 31, 13, 37, 33, 13, 39, Blocks.SANDSTONE.getDefaultState());
        structure.fillWithBlocks(world, start, 32, 2, 8, 38, 2, 14, Blocks.SAND.getDefaultState());
        structure.fillWithBlocks(world, start, 32, 6, 64, 32, 6, 65, Blocks.SANDSTONE.getDefaultState());
        structure.fillWithBlocks(world, start, 32, 14, 38, 32, 14, 38, Blocks.SANDSTONE.getDefaultState());
        structure.fillWithBlocks(world, start, 32, 15, 38, 32, 15, 38, Blocks.SANDSTONE.getDefaultState());
        structure.fillWithBlocks(world, start, 33, 0, 76, 33, 0, 76, Blocks.SANDSTONE.getDefaultState());
        structure.fillWithBlocks(world, start, 33, 0, 77, 33, 0, 79, Blocks.STONE.getDefaultState());
        structure.fillWithBlocks(world, start, 33, 6, 65, 34, 6, 66, Blocks.SANDSTONE.getDefaultState());
        structure.fillWithBlocks(world, start, 33, 14, 36, 37, 14, 40, Blocks.SANDSTONE.getDefaultState());
        structure.fillWithBlocks(world, start, 33, 15, 37, 35, 15, 39, Blocks.SANDSTONE.getDefaultState());
        structure.fillWithBlocks(world, start, 33, 16, 38, 106, 16, 38, Blocks.SANDSTONE.getDefaultState());
        structure.fillWithBlocks(world, start, 34, 0, 76, 35, 0, 77, Blocks.SANDSTONE.getDefaultState());
        structure.fillWithBlocks(world, start, 34, 0, 78, 34, 0, 79, Blocks.STONE.getDefaultState());
        structure.fillWithBlocks(world, start, 34, 0, 80, 38, 0, 84, Blocks.SANDSTONE.getDefaultState());
        structure.fillWithBlocks(world, start, 34, 3, 10, 38, 3, 14, Blocks.SAND.getDefaultState());
        structure.fillWithBlocks(world, start, 34, 13, 37, 36, 13, 39, Blocks.SANDSTONE.getDefaultState());
        structure.fillWithBlocks(world, start, 35, 0, 5, 40, 0, 10, Blocks.SANDSTONE.getDefaultState());
        structure.fillWithBlocks(world, start, 35, 0, 78, 41, 0, 84, Blocks.SANDSTONE.getDefaultState());
        structure.fillWithBlocks(world, start, 35, 1, 6, 42, 1, 13, Blocks.SAND.getDefaultState());
        structure.fillWithBlocks(world, start, 35, 3, 9, 40, 3, 14, Blocks.SAND.getDefaultState());
        structure.fillWithBlocks(world, start, 35, 6, 66, 36, 6, 67, Blocks.SANDSTONE.getDefaultState());
        structure.fillWithBlocks(world, start, 35, 12, 36, 39, 12, 40, Blocks.SANDSTONE.getDefaultState());
        structure.fillWithBlocks(world, start, 35, 13, 36, 39, 13, 40, Blocks.SANDSTONE.getDefaultState());
        structure.fillWithBlocks(world, start, 35, 14, 35, 41, 14, 41, Blocks.SANDSTONE.getDefaultState());
        structure.fillWithBlocks(world, start, 35, 15, 36, 39, 15, 40, Blocks.SANDSTONE.getDefaultState());
        structure.fillWithBlocks(world, start, 35, 16, 36, 39, 16, 40, Blocks.SANDSTONE.getDefaultState());
        structure.fillWithBlocks(world, start, 35, 17, 38, 106, 17, 38, Blocks.SANDSTONE.getDefaultState());
        structure.fillWithBlocks(world, start, 36, 0, 4, 42, 0, 10, Blocks.SANDSTONE.getDefaultState());
        structure.fillWithBlocks(world, start, 36, 0, 76, 44, 0, 84, Blocks.SANDSTONE.getDefaultState());
        structure.fillWithBlocks(world, start, 37, 0, 75, 39, 0, 84, Blocks.SANDSTONE.getDefaultState());
        structure.fillWithBlocks(world, start, 37, 2, 7, 44, 2, 14, Blocks.SAND.getDefaultState());
        structure.fillWithBlocks(world, start, 37, 6, 67, 38, 6, 68, Blocks.SANDSTONE.getDefaultState());
        structure.fillWithBlocks(world, start, 37, 10, 38, 37, 10, 38, Blocks.SANDSTONE.getDefaultState());
        structure.fillWithBlocks(world, start, 37, 11, 35, 43, 11, 41, Blocks.SANDSTONE.getDefaultState());
        structure.fillWithBlocks(world, start, 37, 12, 34, 45, 12, 42, Blocks.SANDSTONE.getDefaultState());
        structure.fillWithBlocks(world, start, 37, 13, 33, 47, 13, 43, Blocks.SANDSTONE.getDefaultState());
        structure.fillWithBlocks(world, start, 37, 14, 33, 47, 14, 43, Blocks.SANDSTONE.getDefaultState());
        structure.fillWithBlocks(world, start, 37, 15, 33, 47, 15, 43, Blocks.SANDSTONE.getDefaultState());
        structure.fillWithBlocks(world, start, 37, 16, 34, 45, 16, 42, Blocks.SANDSTONE.getDefaultState());
        structure.fillWithBlocks(world, start, 37, 17, 35, 43, 17, 41, Blocks.SANDSTONE.getDefaultState());
        structure.fillWithBlocks(world, start, 37, 18, 38, 37, 18, 38, Blocks.SANDSTONE.getDefaultState());
        structure.fillWithBlocks(world, start, 38, 3, 73, 45, 3, 80, Blocks.SAND.getDefaultState());
        structure.fillWithBlocks(world, start, 38, 8, 33, 48, 8, 43, Blocks.SANDSTONE.getDefaultState());
        structure.fillWithBlocks(world, start, 38, 9, 33, 48, 9, 43, Blocks.SANDSTONE.getDefaultState());
        structure.fillWithBlocks(world, start, 38, 10, 31, 52, 10, 45, Blocks.SANDSTONE.getDefaultState());
        structure.fillWithBlocks(world, start, 38, 11, 31, 52, 11, 45, Blocks.SANDSTONE.getDefaultState());
        structure.fillWithBlocks(world, start, 38, 12, 31, 52, 12, 45, Blocks.SANDSTONE.getDefaultState());
        structure.fillWithBlocks(world, start, 38, 13, 31, 52, 13, 45, Blocks.SANDSTONE.getDefaultState());
        structure.fillWithBlocks(world, start, 38, 14, 31, 52, 14, 45, Blocks.SANDSTONE.getDefaultState());
        structure.fillWithBlocks(world, start, 38, 15, 31, 52, 15, 45, Blocks.SANDSTONE.getDefaultState());
        structure.fillWithBlocks(world, start, 38, 16, 31, 52, 16, 45, Blocks.SANDSTONE.getDefaultState());
        structure.fillWithBlocks(world, start, 38, 17, 33, 48, 17, 43, Blocks.SANDSTONE.getDefaultState());
        structure.fillWithBlocks(world, start, 38, 18, 34, 46, 18, 42, Blocks.SANDSTONE.getDefaultState());
        structure.fillWithBlocks(world, start, 39, 1, 14, 72, 5, 14, Blocks.SAND.getDefaultState());
        structure.fillWithBlocks(world, start, 39, 1, 73, 49, 1, 83, Blocks.SAND.getDefaultState());
        structure.fillWithBlocks(world, start, 39, 6, 67, 39, 6, 68, Blocks.SANDSTONE.getDefaultState());
        structure.fillWithBlocks(world, start, 39, 7, 29, 57, 7, 47, Blocks.SANDSTONE.getDefaultState());
        structure.fillWithBlocks(world, start, 39, 8, 28, 59, 8, 48, Blocks.SANDSTONE.getDefaultState());
        structure.fillWithBlocks(world, start, 39, 9, 28, 59, 9, 48, Blocks.SANDSTONE.getDefaultState());
        structure.fillWithBlocks(world, start, 39, 10, 28, 59, 10, 48, Blocks.SANDSTONE.getDefaultState());
        structure.fillWithBlocks(world, start, 39, 11, 28, 59, 11, 48, Blocks.SANDSTONE.getDefaultState());
        structure.fillWithBlocks(world, start, 39, 12, 28, 59, 12, 48, Blocks.SANDSTONE.getDefaultState());
        structure.fillWithBlocks(world, start, 39, 13, 28, 59, 13, 48, Blocks.SANDSTONE.getDefaultState());
        structure.fillWithBlocks(world, start, 39, 14, 28, 59, 14, 48, Blocks.SANDSTONE.getDefaultState());
        structure.fillWithBlocks(world, start, 39, 15, 28, 59, 15, 48, Blocks.SANDSTONE.getDefaultState());
        structure.fillWithBlocks(world, start, 39, 16, 28, 59, 16, 48, Blocks.SANDSTONE.getDefaultState());
        structure.fillWithBlocks(world, start, 39, 17, 28, 59, 17, 48, Blocks.SANDSTONE.getDefaultState());
        structure.fillWithBlocks(world, start, 39, 18, 28, 59, 18, 48, Blocks.SANDSTONE.getDefaultState());
        structure.fillWithBlocks(world, start, 39, 19, 33, 49, 19, 43, Blocks.SANDSTONE.getDefaultState());
        structure.fillWithBlocks(world, start, 40, 0, 11, 40, 0, 12, Blocks.STONE.getDefaultState());
        structure.fillWithBlocks(world, start, 40, 0, 13, 62, 0, 13, Blocks.SANDSTONE.getDefaultState());
        structure.fillWithBlocks(world, start, 40, 0, 75, 110, 0, 75, Blocks.STONE.getDefaultState());
        structure.fillWithBlocks(world, start, 40, 5, 75, 103, 5, 75, Blocks.SAND.getDefaultState());
        structure.fillWithBlocks(world, start, 40, 6, 29, 58, 6, 47, Blocks.SANDSTONE.getDefaultState());
        structure.fillWithBlocks(world, start, 40, 6, 68, 41, 6, 69, Blocks.SANDSTONE.getDefaultState());
        structure.fillWithBlocks(world, start, 40, 7, 28, 60, 7, 48, Blocks.SANDSTONE.getDefaultState());
        structure.fillWithBlocks(world, start, 40, 8, 27, 62, 8, 49, Blocks.SANDSTONE.getDefaultState());
        structure.fillWithBlocks(world, start, 40, 9, 27, 62, 9, 49, Blocks.SANDSTONE.getDefaultState());
        structure.fillWithBlocks(world, start, 40, 10, 21, 42, 10, 23, Blocks.SANDSTONE.getDefaultState());
        structure.fillWithBlocks(world, start, 40, 10, 27, 62, 10, 49, Blocks.SANDSTONE.getDefaultState());
        structure.fillWithBlocks(world, start, 40, 10, 53, 42, 10, 55, Blocks.SANDSTONE.getDefaultState());
        structure.fillWithBlocks(world, start, 40, 11, 21, 42, 11, 23, Blocks.SANDSTONE.getDefaultState());
        structure.fillWithBlocks(world, start, 40, 11, 27, 62, 11, 49, Blocks.SANDSTONE.getDefaultState());
        structure.fillWithBlocks(world, start, 40, 11, 53, 42, 11, 55, Blocks.SANDSTONE.getDefaultState());
        structure.fillWithBlocks(world, start, 40, 12, 20, 44, 12, 24, Blocks.SANDSTONE.getDefaultState());
        structure.fillWithBlocks(world, start, 40, 12, 27, 62, 12, 49, Blocks.SANDSTONE.getDefaultState());
        structure.fillWithBlocks(world, start, 40, 12, 52, 44, 12, 56, Blocks.SANDSTONE.getDefaultState());
        structure.fillWithBlocks(world, start, 40, 13, 20, 44, 13, 24, Blocks.SANDSTONE.getDefaultState());
        structure.fillWithBlocks(world, start, 40, 13, 27, 62, 13, 49, Blocks.SANDSTONE.getDefaultState());
        structure.fillWithBlocks(world, start, 40, 13, 52, 44, 13, 56, Blocks.SANDSTONE.getDefaultState());
        structure.fillWithBlocks(world, start, 40, 14, 21, 42, 14, 23, Blocks.SANDSTONE.getDefaultState());
        structure.fillWithBlocks(world, start, 40, 14, 27, 62, 14, 49, Blocks.SANDSTONE.getDefaultState());
        structure.fillWithBlocks(world, start, 40, 14, 53, 42, 14, 55, Blocks.SANDSTONE.getDefaultState());
        structure.fillWithBlocks(world, start, 40, 15, 21, 42, 15, 23, Blocks.SANDSTONE.getDefaultState());
        structure.fillWithBlocks(world, start, 40, 15, 27, 62, 15, 49, Blocks.SANDSTONE.getDefaultState());
        structure.fillWithBlocks(world, start, 40, 15, 53, 42, 15, 55, Blocks.SANDSTONE.getDefaultState());
        structure.fillWithBlocks(world, start, 40, 16, 27, 62, 16, 49, Blocks.SANDSTONE.getDefaultState());
        structure.fillWithBlocks(world, start, 40, 17, 27, 62, 17, 49, Blocks.SANDSTONE.getDefaultState());
        structure.fillWithBlocks(world, start, 40, 18, 27, 62, 18, 49, Blocks.SANDSTONE.getDefaultState());
        structure.fillWithBlocks(world, start, 40, 19, 31, 54, 19, 45, Blocks.SANDSTONE.getDefaultState());
        structure.fillWithBlocks(world, start, 40, 20, 33, 50, 20, 43, Blocks.SANDSTONE.getDefaultState());
        structure.fillWithBlocks(world, start, 41, 0, 11, 43, 0, 13, Blocks.SANDSTONE.getDefaultState());
        structure.fillWithBlocks(world, start, 41, 2, 73, 50, 2, 82, Blocks.SAND.getDefaultState());
        structure.fillWithBlocks(world, start, 41, 3, 9, 46, 3, 14, Blocks.SAND.getDefaultState());
        structure.fillWithBlocks(world, start, 41, 6, 28, 61, 6, 48, Blocks.SANDSTONE.getDefaultState());
        structure.fillWithBlocks(world, start, 41, 7, 27, 63, 7, 49, Blocks.SANDSTONE.getDefaultState());
        structure.fillWithBlocks(world, start, 41, 8, 21, 43, 8, 23, Blocks.SANDSTONE.getDefaultState());
        structure.fillWithBlocks(world, start, 41, 8, 53, 43, 8, 55, Blocks.SANDSTONE.getDefaultState());
        structure.fillWithBlocks(world, start, 41, 9, 20, 45, 9, 24, Blocks.SANDSTONE.getDefaultState());
        structure.fillWithBlocks(world, start, 41, 9, 52, 45, 9, 56, Blocks.SANDSTONE.getDefaultState());
        structure.fillWithBlocks(world, start, 41, 10, 19, 47, 10, 25, Blocks.SANDSTONE.getDefaultState());
        structure.fillWithBlocks(world, start, 41, 10, 51, 47, 10, 57, Blocks.SANDSTONE.getDefaultState());
        structure.fillWithBlocks(world, start, 41, 11, 19, 47, 11, 25, Blocks.SANDSTONE.getDefaultState());
        structure.fillWithBlocks(world, start, 41, 11, 51, 47, 11, 57, Blocks.SANDSTONE.getDefaultState());
        structure.fillWithBlocks(world, start, 41, 12, 19, 47, 12, 25, Blocks.SANDSTONE.getDefaultState());
        structure.fillWithBlocks(world, start, 41, 12, 51, 47, 12, 57, Blocks.SANDSTONE.getDefaultState());
        structure.fillWithBlocks(world, start, 41, 13, 19, 47, 13, 25, Blocks.SANDSTONE.getDefaultState());
        structure.fillWithBlocks(world, start, 41, 13, 51, 47, 13, 57, Blocks.SANDSTONE.getDefaultState());
        structure.fillWithBlocks(world, start, 41, 14, 19, 47, 14, 25, Blocks.SANDSTONE.getDefaultState());
        structure.fillWithBlocks(world, start, 41, 14, 51, 47, 14, 57, Blocks.SANDSTONE.getDefaultState());
        structure.fillWithBlocks(world, start, 41, 15, 19, 47, 15, 25, Blocks.SANDSTONE.getDefaultState());
        structure.fillWithBlocks(world, start, 41, 15, 51, 47, 15, 57, Blocks.SANDSTONE.getDefaultState());
        structure.fillWithBlocks(world, start, 41, 16, 20, 45, 16, 24, Blocks.SANDSTONE.getDefaultState());
        structure.fillWithBlocks(world, start, 41, 16, 52, 45, 16, 56, Blocks.SANDSTONE.getDefaultState());
        structure.fillWithBlocks(world, start, 41, 17, 21, 43, 17, 23, Blocks.SANDSTONE.getDefaultState());
        structure.fillWithBlocks(world, start, 41, 17, 53, 43, 17, 55, Blocks.SANDSTONE.getDefaultState());
        structure.fillWithBlocks(world, start, 41, 19, 29, 59, 19, 47, Blocks.SANDSTONE.getDefaultState());
        structure.fillWithBlocks(world, start, 41, 20, 31, 55, 20, 45, Blocks.SANDSTONE.getDefaultState());
        structure.fillWithBlocks(world, start, 42, 1, 5, 47, 1, 14, Blocks.SAND.getDefaultState());
        structure.fillWithBlocks(world, start, 42, 6, 22, 42, 6, 22, Blocks.SANDSTONE.getDefaultState());
        structure.fillWithBlocks(world, start, 42, 6, 27, 64, 6, 49, Blocks.SANDSTONE.getDefaultState());
        structure.fillWithBlocks(world, start, 42, 6, 54, 42, 6, 54, Blocks.SANDSTONE.getDefaultState());
        structure.fillWithBlocks(world, start, 42, 6, 68, 42, 6, 69, Blocks.SANDSTONE.getDefaultState());
        structure.fillWithBlocks(world, start, 42, 7, 20, 46, 7, 24, Blocks.SANDSTONE.getDefaultState());
        structure.fillWithBlocks(world, start, 42, 7, 52, 46, 7, 56, Blocks.SANDSTONE.getDefaultState());
        structure.fillWithBlocks(world, start, 42, 8, 19, 48, 8, 25, Blocks.SANDSTONE.getDefaultState());
        structure.fillWithBlocks(world, start, 42, 8, 51, 48, 8, 57, Blocks.SANDSTONE.getDefaultState());
        structure.fillWithBlocks(world, start, 42, 9, 19, 48, 9, 25, Blocks.SANDSTONE.getDefaultState());
        structure.fillWithBlocks(world, start, 42, 9, 51, 48, 9, 57, Blocks.SANDSTONE.getDefaultState());
        structure.fillWithBlocks(world, start, 42, 11, 18, 74, 11, 58, Blocks.SANDSTONE.getDefaultState());
        structure.fillWithBlocks(world, start, 42, 12, 18, 72, 12, 58, Blocks.SANDSTONE.getDefaultState());
        structure.fillWithBlocks(world, start, 42, 13, 18, 62, 13, 58, Blocks.SANDSTONE.getDefaultState());
        structure.fillWithBlocks(world, start, 42, 14, 18, 62, 14, 58, Blocks.SANDSTONE.getDefaultState());
        structure.fillWithBlocks(world, start, 42, 16, 19, 48, 16, 25, Blocks.SANDSTONE.getDefaultState());
        structure.fillWithBlocks(world, start, 42, 16, 51, 48, 16, 57, Blocks.SANDSTONE.getDefaultState());
        structure.fillWithBlocks(world, start, 42, 17, 19, 48, 17, 25, Blocks.SANDSTONE.getDefaultState());
        structure.fillWithBlocks(world, start, 42, 17, 51, 48, 17, 57, Blocks.SANDSTONE.getDefaultState());
        structure.fillWithBlocks(world, start, 42, 18, 20, 46, 18, 24, Blocks.SANDSTONE.getDefaultState());
        structure.fillWithBlocks(world, start, 42, 18, 52, 46, 18, 56, Blocks.SANDSTONE.getDefaultState());
        structure.fillWithBlocks(world, start, 42, 19, 22, 42, 19, 22, Blocks.SANDSTONE.getDefaultState());
        structure.fillWithBlocks(world, start, 42, 19, 54, 42, 19, 54, Blocks.SANDSTONE.getDefaultState());
        structure.fillWithBlocks(world, start, 43, 0, 4, 52, 0, 13, Blocks.SANDSTONE.getDefaultState());
        structure.fillWithBlocks(world, start, 43, 3, 81, 102, 3, 81, Blocks.SAND.getDefaultState());
        structure.fillWithBlocks(world, start, 43, 6, 20, 47, 6, 24, Blocks.SANDSTONE.getDefaultState());
        structure.fillWithBlocks(world, start, 43, 6, 52, 47, 6, 56, Blocks.SANDSTONE.getDefaultState());
        structure.fillWithBlocks(world, start, 43, 6, 69, 44, 6, 70, Blocks.SANDSTONE.getDefaultState());
        structure.fillWithBlocks(world, start, 43, 7, 19, 49, 7, 25, Blocks.SANDSTONE.getDefaultState());
        structure.fillWithBlocks(world, start, 43, 7, 51, 49, 7, 57, Blocks.SANDSTONE.getDefaultState());
        structure.fillWithBlocks(world, start, 43, 9, 18, 75, 9, 58, Blocks.SANDSTONE.getDefaultState());
        structure.fillWithBlocks(world, start, 43, 10, 18, 75, 10, 58, Blocks.SANDSTONE.getDefaultState());
        structure.fillWithBlocks(world, start, 43, 15, 18, 61, 15, 58, Blocks.SANDSTONE.getDefaultState());
        structure.fillWithBlocks(world, start, 43, 16, 18, 61, 16, 58, Blocks.SANDSTONE.getDefaultState());
        structure.fillWithBlocks(world, start, 43, 18, 19, 49, 18, 25, Blocks.SANDSTONE.getDefaultState());
        structure.fillWithBlocks(world, start, 43, 18, 51, 49, 18, 57, Blocks.SANDSTONE.getDefaultState());
        structure.fillWithBlocks(world, start, 43, 19, 20, 47, 19, 24, Blocks.SANDSTONE.getDefaultState());
        structure.fillWithBlocks(world, start, 43, 19, 52, 47, 19, 56, Blocks.SANDSTONE.getDefaultState());
        structure.fillWithBlocks(world, start, 43, 20, 22, 43, 20, 22, Blocks.SANDSTONE.getDefaultState());
        structure.fillWithBlocks(world, start, 43, 20, 54, 43, 20, 54, Blocks.SANDSTONE.getDefaultState());
        structure.fillWithBlocks(world, start, 44, 3, 8, 46, 3, 14, Blocks.SAND.getDefaultState());
        structure.fillWithBlocks(world, start, 44, 6, 19, 50, 6, 25, Blocks.SANDSTONE.getDefaultState());
        structure.fillWithBlocks(world, start, 44, 6, 51, 50, 6, 57, Blocks.SANDSTONE.getDefaultState());
        structure.fillWithBlocks(world, start, 44, 7, 18, 75, 7, 58, Blocks.SANDSTONE.getDefaultState());
        structure.fillWithBlocks(world, start, 44, 8, 18, 75, 8, 58, Blocks.SANDSTONE.getDefaultState());
        structure.fillWithBlocks(world, start, 44, 10, 17, 75, 10, 59, Blocks.SANDSTONE.getDefaultState());
        structure.fillWithBlocks(world, start, 44, 11, 17, 73, 11, 59, Blocks.SANDSTONE.getDefaultState());
        structure.fillWithBlocks(world, start, 44, 12, 17, 60, 12, 59, Blocks.SANDSTONE.getDefaultState());
        structure.fillWithBlocks(world, start, 44, 13, 17, 60, 13, 59, Blocks.SANDSTONE.getDefaultState());
        structure.fillWithBlocks(world, start, 44, 14, 17, 60, 14, 59, Blocks.SANDSTONE.getDefaultState());
        structure.fillWithBlocks(world, start, 44, 15, 17, 60, 15, 59, Blocks.SANDSTONE.getDefaultState());
        structure.fillWithBlocks(world, start, 44, 17, 18, 60, 17, 58, Blocks.SANDSTONE.getDefaultState());
        structure.fillWithBlocks(world, start, 44, 18, 18, 60, 18, 58, Blocks.SANDSTONE.getDefaultState());
        structure.fillWithBlocks(world, start, 44, 19, 19, 50, 19, 25, Blocks.SANDSTONE.getDefaultState());
        structure.fillWithBlocks(world, start, 44, 19, 51, 50, 19, 57, Blocks.SANDSTONE.getDefaultState());
        structure.fillWithBlocks(world, start, 44, 20, 20, 48, 20, 24, Blocks.SANDSTONE.getDefaultState());
        structure.fillWithBlocks(world, start, 44, 20, 52, 48, 20, 56, Blocks.SANDSTONE.getDefaultState());
        structure.fillWithBlocks(world, start, 45, 0, 14, 57, 0, 14, Blocks.SANDSTONE.getDefaultState());
        structure.fillWithBlocks(world, start, 45, 0, 73, 47, 0, 75, Blocks.STONE.getDefaultState());
        structure.fillWithBlocks(world, start, 45, 0, 76, 46, 0, 84, Blocks.SANDSTONE.getDefaultState());
        structure.fillWithBlocks(world, start, 45, 2, 7, 52, 2, 14, Blocks.SAND.getDefaultState());
        structure.fillWithBlocks(world, start, 45, 4, 10, 45, 4, 79, Blocks.SAND.getDefaultState());
        structure.fillWithBlocks(world, start, 45, 6, 70, 46, 6, 71, Blocks.SANDSTONE.getDefaultState());
        structure.fillWithBlocks(world, start, 45, 8, 17, 75, 8, 59, Blocks.SANDSTONE.getDefaultState());
        structure.fillWithBlocks(world, start, 45, 9, 17, 75, 9, 59, Blocks.SANDSTONE.getDefaultState());
        structure.fillWithBlocks(world, start, 45, 16, 17, 59, 16, 59, Blocks.SANDSTONE.getDefaultState());
        structure.fillWithBlocks(world, start, 45, 17, 17, 59, 17, 59, Blocks.SANDSTONE.getDefaultState());
        structure.fillWithBlocks(world, start, 45, 20, 19, 51, 20, 25, Blocks.SANDSTONE.getDefaultState());
        structure.fillWithBlocks(world, start, 45, 20, 51, 51, 20, 57, Blocks.SANDSTONE.getDefaultState());
        structure.fillWithBlocks(world, start, 45, 21, 21, 47, 21, 23, Blocks.SANDSTONE.getDefaultState());
        structure.fillWithBlocks(world, start, 45, 21, 53, 47, 21, 55, Blocks.SANDSTONE.getDefaultState());
        structure.fillWithBlocks(world, start, 46, 3, 73, 54, 3, 81, Blocks.SAND.getDefaultState());
        structure.fillWithBlocks(world, start, 46, 6, 18, 75, 6, 58, Blocks.SANDSTONE.getDefaultState());
        structure.fillWithBlocks(world, start, 46, 11, 16, 58, 11, 60, Blocks.SANDSTONE.getDefaultState());
        structure.fillWithBlocks(world, start, 46, 12, 16, 58, 12, 60, Blocks.SANDSTONE.getDefaultState());
        structure.fillWithBlocks(world, start, 46, 13, 16, 58, 13, 60, Blocks.SANDSTONE.getDefaultState());
        structure.fillWithBlocks(world, start, 46, 14, 16, 58, 14, 60, Blocks.SANDSTONE.getDefaultState());
        structure.fillWithBlocks(world, start, 46, 19, 18, 54, 19, 26, Blocks.SANDSTONE.getDefaultState());
        structure.fillWithBlocks(world, start, 46, 19, 50, 54, 19, 58, Blocks.SANDSTONE.getDefaultState());
        structure.fillWithBlocks(world, start, 46, 21, 20, 50, 21, 24, Blocks.SANDSTONE.getDefaultState());
        structure.fillWithBlocks(world, start, 46, 21, 52, 50, 21, 56, Blocks.SANDSTONE.getDefaultState());
        structure.fillWithBlocks(world, start, 47, 0, 76, 110, 0, 76, Blocks.STONE.getDefaultState());
        structure.fillWithBlocks(world, start, 47, 0, 77, 50, 0, 85, Blocks.SANDSTONE.getDefaultState());
        structure.fillWithBlocks(world, start, 47, 3, 9, 52, 3, 14, Blocks.SAND.getDefaultState());
        structure.fillWithBlocks(world, start, 47, 5, 76, 100, 5, 76, Blocks.SAND.getDefaultState());
        structure.fillWithBlocks(world, start, 47, 6, 70, 48, 6, 71, Blocks.SANDSTONE.getDefaultState());
        structure.fillWithBlocks(world, start, 47, 7, 17, 75, 7, 59, Blocks.SANDSTONE.getDefaultState());
        structure.fillWithBlocks(world, start, 47, 10, 16, 57, 10, 60, Blocks.SANDSTONE.getDefaultState());
        structure.fillWithBlocks(world, start, 47, 15, 16, 57, 15, 60, Blocks.SANDSTONE.getDefaultState());
        structure.fillWithBlocks(world, start, 47, 18, 17, 57, 18, 59, Blocks.SANDSTONE.getDefaultState());
        structure.fillWithBlocks(world, start, 47, 21, 19, 53, 21, 25, Blocks.SANDSTONE.getDefaultState());
        structure.fillWithBlocks(world, start, 47, 21, 51, 53, 21, 57, Blocks.SANDSTONE.getDefaultState());
        structure.fillWithBlocks(world, start, 47, 22, 21, 49, 22, 23, Blocks.SANDSTONE.getDefaultState());
        structure.fillWithBlocks(world, start, 47, 22, 53, 49, 22, 55, Blocks.SANDSTONE.getDefaultState());
        structure.fillWithBlocks(world, start, 48, 0, 73, 51, 0, 76, Blocks.STONE.getDefaultState());
        structure.fillWithBlocks(world, start, 48, 1, 6, 56, 1, 14, Blocks.SAND.getDefaultState());
        structure.fillWithBlocks(world, start, 48, 9, 16, 56, 9, 60, Blocks.SANDSTONE.getDefaultState());
        structure.fillWithBlocks(world, start, 48, 16, 16, 56, 16, 60, Blocks.SANDSTONE.getDefaultState());
        structure.fillWithBlocks(world, start, 48, 20, 18, 56, 20, 26, Blocks.SANDSTONE.getDefaultState());
        structure.fillWithBlocks(world, start, 48, 20, 50, 56, 20, 58, Blocks.SANDSTONE.getDefaultState());
        structure.fillWithBlocks(world, start, 49, 1, 84, 101, 1, 84, Blocks.SAND.getDefaultState());
        structure.fillWithBlocks(world, start, 49, 4, 80, 100, 4, 80, Blocks.SAND.getDefaultState());
        structure.fillWithBlocks(world, start, 49, 6, 70, 50, 6, 71, Blocks.SANDSTONE.getDefaultState());
        structure.fillWithBlocks(world, start, 49, 22, 20, 53, 22, 24, Blocks.SANDSTONE.getDefaultState());
        structure.fillWithBlocks(world, start, 49, 22, 52, 53, 22, 56, Blocks.SANDSTONE.getDefaultState());
        structure.fillWithBlocks(world, start, 50, 1, 73, 51, 1, 74, Blocks.STONE.getDefaultState());
        structure.fillWithBlocks(world, start, 50, 1, 75, 50, 4, 80, Blocks.SAND.getDefaultState());
        structure.fillWithBlocks(world, start, 50, 1, 82, 52, 1, 84, Blocks.SAND.getDefaultState());
        structure.fillWithBlocks(world, start, 51, 0, 77, 51, 0, 79, Blocks.SANDSTONE.getDefaultState());
        structure.fillWithBlocks(world, start, 51, 0, 80, 59, 0, 80, Blocks.STONE.getDefaultState());
        structure.fillWithBlocks(world, start, 51, 0, 81, 55, 0, 85, Blocks.SANDSTONE.getDefaultState());
        structure.fillWithBlocks(world, start, 51, 1, 75, 52, 1, 76, Blocks.STONE.getDefaultState());
        structure.fillWithBlocks(world, start, 51, 1, 77, 58, 1, 84, Blocks.SAND.getDefaultState());
        structure.fillWithBlocks(world, start, 51, 2, 73, 61, 2, 83, Blocks.SAND.getDefaultState());
        structure.fillWithBlocks(world, start, 51, 6, 70, 52, 6, 71, Blocks.SANDSTONE.getDefaultState());
        structure.fillWithBlocks(world, start, 52, 0, 73, 59, 0, 80, Blocks.STONE.getDefaultState());
        structure.fillWithBlocks(world, start, 52, 1, 73, 55, 1, 76, Blocks.STONE.getDefaultState());
        structure.fillWithBlocks(world, start, 53, 0, 4, 62, 0, 13, Blocks.SANDSTONE.getDefaultState());
        structure.fillWithBlocks(world, start, 53, 2, 7, 60, 2, 14, Blocks.SAND.getDefaultState());
        structure.fillWithBlocks(world, start, 53, 3, 9, 58, 3, 14, Blocks.SAND.getDefaultState());
        structure.fillWithBlocks(world, start, 53, 6, 69, 54, 6, 70, Blocks.SANDSTONE.getDefaultState());
        structure.fillWithBlocks(world, start, 54, 21, 19, 57, 21, 25, Blocks.SANDSTONE.getDefaultState());
        structure.fillWithBlocks(world, start, 54, 21, 51, 57, 21, 57, Blocks.SANDSTONE.getDefaultState());
        structure.fillWithBlocks(world, start, 54, 22, 20, 55, 22, 24, Blocks.SANDSTONE.getDefaultState());
        structure.fillWithBlocks(world, start, 54, 22, 52, 55, 22, 56, Blocks.SANDSTONE.getDefaultState());
        structure.fillWithBlocks(world, start, 55, 3, 73, 63, 3, 81, Blocks.SAND.getDefaultState());
        structure.fillWithBlocks(world, start, 55, 6, 68, 56, 6, 69, Blocks.SANDSTONE.getDefaultState());
        structure.fillWithBlocks(world, start, 55, 19, 18, 58, 19, 26, Blocks.SANDSTONE.getDefaultState());
        structure.fillWithBlocks(world, start, 55, 19, 50, 58, 19, 58, Blocks.SANDSTONE.getDefaultState());
        structure.fillWithBlocks(world, start, 56, 0, 81, 60, 0, 85, Blocks.SANDSTONE.getDefaultState());
        structure.fillWithBlocks(world, start, 56, 1, 73, 59, 1, 76, Blocks.STONE.getDefaultState());
        structure.fillWithBlocks(world, start, 56, 20, 31, 59, 20, 45, Blocks.SANDSTONE.getDefaultState());
        structure.fillWithBlocks(world, start, 56, 22, 21, 57, 22, 23, Blocks.SANDSTONE.getDefaultState());
        structure.fillWithBlocks(world, start, 56, 22, 53, 57, 22, 55, Blocks.SANDSTONE.getDefaultState());
        structure.fillWithBlocks(world, start, 57, 1, 6, 65, 1, 14, Blocks.SAND.getDefaultState());
        structure.fillWithBlocks(world, start, 57, 3, 82, 99, 3, 82, Blocks.SAND.getDefaultState());
        structure.fillWithBlocks(world, start, 57, 6, 67, 57, 6, 68, Blocks.SANDSTONE.getDefaultState());
        structure.fillWithBlocks(world, start, 57, 20, 19, 59, 20, 25, Blocks.SANDSTONE.getDefaultState());
        structure.fillWithBlocks(world, start, 57, 20, 51, 59, 20, 57, Blocks.SANDSTONE.getDefaultState());
        structure.fillWithBlocks(world, start, 58, 0, 14, 116, 0, 72, Blocks.STONE.getDefaultState());
        structure.fillWithBlocks(world, start, 58, 0, 86, 99, 0, 86, Blocks.SANDSTONE.getDefaultState());
        structure.fillWithBlocks(world, start, 58, 1, 5, 67, 1, 14, Blocks.SAND.getDefaultState());
        structure.fillWithBlocks(world, start, 58, 4, 10, 125, 4, 77, Blocks.SAND.getDefaultState());
        structure.fillWithBlocks(world, start, 58, 6, 66, 58, 6, 67, Blocks.SANDSTONE.getDefaultState());
        structure.fillWithBlocks(world, start, 58, 21, 20, 58, 21, 24, Blocks.SANDSTONE.getDefaultState());
        structure.fillWithBlocks(world, start, 58, 21, 52, 58, 21, 56, Blocks.SANDSTONE.getDefaultState());
        structure.fillWithBlocks(world, start, 59, 1, 77, 66, 1, 84, Blocks.SAND.getDefaultState());
        structure.fillWithBlocks(world, start, 59, 3, 8, 65, 3, 14, Blocks.SAND.getDefaultState());
        structure.fillWithBlocks(world, start, 59, 6, 65, 60, 6, 66, Blocks.SANDSTONE.getDefaultState());
        structure.fillWithBlocks(world, start, 59, 19, 19, 60, 19, 25, Blocks.SANDSTONE.getDefaultState());
        structure.fillWithBlocks(world, start, 59, 19, 51, 60, 19, 57, Blocks.SANDSTONE.getDefaultState());
        structure.fillWithBlocks(world, start, 59, 21, 21, 59, 21, 23, Blocks.SANDSTONE.getDefaultState());
        structure.fillWithBlocks(world, start, 59, 21, 53, 59, 21, 55, Blocks.SANDSTONE.getDefaultState());
        structure.fillWithBlocks(world, start, 60, 0, 73, 64, 0, 77, Blocks.STONE.getDefaultState());
        structure.fillWithBlocks(world, start, 60, 0, 78, 60, 0, 79, Blocks.STONE.getDefaultState());
        structure.fillWithBlocks(world, start, 60, 0, 80, 66, 0, 86, Blocks.SANDSTONE.getDefaultState());
        structure.fillWithBlocks(world, start, 60, 1, 73, 60, 1, 73, Blocks.SAND.getDefaultState());
        structure.fillWithBlocks(world, start, 60, 1, 74, 60, 1, 76, Blocks.STONE.getDefaultState());
        structure.fillWithBlocks(world, start, 60, 19, 29, 78, 19, 47, Blocks.SANDSTONE.getDefaultState());
        structure.fillWithBlocks(world, start, 60, 20, 20, 60, 20, 24, Blocks.SANDSTONE.getDefaultState());
        structure.fillWithBlocks(world, start, 60, 20, 32, 60, 20, 44, Blocks.SANDSTONE.getDefaultState());
        structure.fillWithBlocks(world, start, 60, 20, 52, 60, 20, 56, Blocks.SANDSTONE.getDefaultState());
        structure.fillWithBlocks(world, start, 61, 0, 79, 68, 0, 86, Blocks.SANDSTONE.getDefaultState());
        structure.fillWithBlocks(world, start, 61, 1, 73, 63, 1, 75, Blocks.SAND.getDefaultState());
        structure.fillWithBlocks(world, start, 61, 1, 85, 98, 1, 85, Blocks.SAND.getDefaultState());
        structure.fillWithBlocks(world, start, 61, 2, 7, 68, 2, 14, Blocks.SAND.getDefaultState());
        structure.fillWithBlocks(world, start, 61, 6, 64, 62, 6, 65, Blocks.SANDSTONE.getDefaultState());
        structure.fillWithBlocks(world, start, 61, 17, 19, 62, 17, 25, Blocks.SANDSTONE.getDefaultState());
        structure.fillWithBlocks(world, start, 61, 17, 51, 62, 17, 57, Blocks.SANDSTONE.getDefaultState());
        structure.fillWithBlocks(world, start, 61, 18, 19, 61, 18, 25, Blocks.SANDSTONE.getDefaultState());
        structure.fillWithBlocks(world, start, 61, 18, 51, 61, 18, 57, Blocks.SANDSTONE.getDefaultState());
        structure.fillWithBlocks(world, start, 61, 19, 20, 61, 19, 24, Blocks.SANDSTONE.getDefaultState());
        structure.fillWithBlocks(world, start, 61, 19, 52, 61, 19, 56, Blocks.SANDSTONE.getDefaultState());
        structure.fillWithBlocks(world, start, 62, 0, 78, 70, 0, 86, Blocks.SANDSTONE.getDefaultState());
        structure.fillWithBlocks(world, start, 62, 1, 76, 71, 1, 85, Blocks.SAND.getDefaultState());
        structure.fillWithBlocks(world, start, 62, 2, 73, 73, 2, 84, Blocks.SAND.getDefaultState());
        structure.fillWithBlocks(world, start, 62, 4, 81, 97, 4, 81, Blocks.SAND.getDefaultState());
        structure.fillWithBlocks(world, start, 62, 5, 77, 75, 5, 77, Blocks.SAND.getDefaultState());
        structure.fillWithBlocks(world, start, 62, 15, 19, 63, 15, 25, Blocks.SANDSTONE.getDefaultState());
        structure.fillWithBlocks(world, start, 62, 15, 51, 63, 15, 57, Blocks.SANDSTONE.getDefaultState());
        structure.fillWithBlocks(world, start, 62, 16, 19, 62, 16, 25, Blocks.SANDSTONE.getDefaultState());
        structure.fillWithBlocks(world, start, 62, 16, 51, 62, 16, 57, Blocks.SANDSTONE.getDefaultState());
        structure.fillWithBlocks(world, start, 62, 18, 20, 62, 18, 24, Blocks.SANDSTONE.getDefaultState());
        structure.fillWithBlocks(world, start, 62, 18, 52, 62, 18, 56, Blocks.SANDSTONE.getDefaultState());
        structure.fillWithBlocks(world, start, 63, 0, 4, 71, 0, 12, Blocks.SANDSTONE.getDefaultState());
        structure.fillWithBlocks(world, start, 63, 0, 13, 122, 0, 72, Blocks.STONE.getDefaultState());
        structure.fillWithBlocks(world, start, 63, 3, 83, 97, 3, 83, Blocks.SAND.getDefaultState());
        structure.fillWithBlocks(world, start, 63, 5, 13, 79, 5, 76, Blocks.SAND.getDefaultState());
        structure.fillWithBlocks(world, start, 63, 6, 17, 75, 6, 59, Blocks.SANDSTONE.getDefaultState());
        structure.fillWithBlocks(world, start, 63, 6, 64, 64, 6, 65, Blocks.SANDSTONE.getDefaultState());
        structure.fillWithBlocks(world, start, 63, 13, 19, 63, 13, 57, Blocks.SANDSTONE.getDefaultState());
        structure.fillWithBlocks(world, start, 63, 14, 19, 63, 15, 57, Blocks.SANDSTONE.getDefaultState());
        structure.fillWithBlocks(world, start, 63, 16, 20, 63, 16, 24, Blocks.SANDSTONE.getDefaultState());
        structure.fillWithBlocks(world, start, 63, 16, 27, 85, 16, 49, Blocks.SANDSTONE.getDefaultState());
        structure.fillWithBlocks(world, start, 63, 16, 52, 63, 16, 56, Blocks.SANDSTONE.getDefaultState());
        structure.fillWithBlocks(world, start, 63, 17, 21, 63, 17, 23, Blocks.SANDSTONE.getDefaultState());
        structure.fillWithBlocks(world, start, 63, 17, 27, 85, 17, 49, Blocks.SANDSTONE.getDefaultState());
        structure.fillWithBlocks(world, start, 63, 17, 53, 63, 17, 55, Blocks.SANDSTONE.getDefaultState());
        structure.fillWithBlocks(world, start, 63, 18, 27, 85, 18, 49, Blocks.SANDSTONE.getDefaultState());
        structure.fillWithBlocks(world, start, 64, 0, 87, 96, 0, 87, Blocks.SANDSTONE.getDefaultState());
        structure.fillWithBlocks(world, start, 64, 1, 73, 76, 1, 85, Blocks.SAND.getDefaultState());
        structure.fillWithBlocks(world, start, 64, 3, 73, 74, 3, 83, Blocks.SAND.getDefaultState());
        structure.fillWithBlocks(world, start, 64, 13, 20, 64, 13, 24, Blocks.SANDSTONE.getDefaultState());
        structure.fillWithBlocks(world, start, 64, 13, 26, 88, 13, 50, Blocks.SANDSTONE.getDefaultState());
        structure.fillWithBlocks(world, start, 64, 13, 52, 64, 13, 56, Blocks.SANDSTONE.getDefaultState());
        structure.fillWithBlocks(world, start, 64, 14, 21, 64, 15, 23, Blocks.SANDSTONE.getDefaultState());
        structure.fillWithBlocks(world, start, 64, 14, 26, 88, 14, 50, Blocks.SANDSTONE.getDefaultState());
        structure.fillWithBlocks(world, start, 64, 14, 53, 64, 15, 55, Blocks.SANDSTONE.getDefaultState());
        structure.fillWithBlocks(world, start, 64, 15, 26, 88, 15, 50, Blocks.SANDSTONE.getDefaultState());
        structure.fillWithBlocks(world, start, 65, 0, 73, 67, 0, 77, Blocks.STONE.getDefaultState());
        structure.fillWithBlocks(world, start, 65, 6, 63, 66, 6, 64, Blocks.SANDSTONE.getDefaultState());
        structure.fillWithBlocks(world, start, 66, 1, 86, 77, 1, 86, Blocks.SAND.getDefaultState());
        structure.fillWithBlocks(world, start, 66, 3, 8, 72, 3, 14, Blocks.SAND.getDefaultState());
        structure.fillWithBlocks(world, start, 67, 2, 6, 72, 2, 14, Blocks.SAND.getDefaultState());
        structure.fillWithBlocks(world, start, 67, 6, 63, 68, 6, 64, Blocks.SANDSTONE.getDefaultState());
        structure.fillWithBlocks(world, start, 68, 0, 73, 68, 0, 73, Blocks.SANDSTONE.getDefaultState());
        structure.fillWithBlocks(world, start, 68, 0, 74, 68, 0, 77, Blocks.STONE.getDefaultState());
        structure.fillWithBlocks(world, start, 68, 1, 5, 75, 1, 12, Blocks.SAND.getDefaultState());
        structure.fillWithBlocks(world, start, 68, 1, 13, 69, 1, 14, Blocks.SAND.getDefaultState());
        structure.fillWithBlocks(world, start, 68, 2, 85, 74, 2, 85, Blocks.SAND.getDefaultState());
        structure.fillWithBlocks(world, start, 68, 6, 16, 74, 6, 60, Blocks.SANDSTONE.getDefaultState());
        structure.fillWithBlocks(world, start, 68, 7, 16, 74, 7, 60, Blocks.SANDSTONE.getDefaultState());
        structure.fillWithBlocks(world, start, 68, 8, 16, 74, 8, 60, Blocks.SANDSTONE.getDefaultState());
        structure.fillWithBlocks(world, start, 69, 0, 73, 70, 0, 74, Blocks.SANDSTONE.getDefaultState());
        structure.fillWithBlocks(world, start, 69, 0, 77, 75, 0, 77, Blocks.STONE.getDefaultState());
        structure.fillWithBlocks(world, start, 69, 6, 63, 69, 6, 64, Blocks.SANDSTONE.getDefaultState());
        structure.fillWithBlocks(world, start, 69, 9, 16, 73, 9, 60, Blocks.SANDSTONE.getDefaultState());
        structure.fillWithBlocks(world, start, 70, 1, 13, 71, 1, 14, Blocks.SAND.getDefaultState());
        structure.fillWithBlocks(world, start, 70, 6, 64, 71, 6, 65, Blocks.SANDSTONE.getDefaultState());
        structure.fillWithBlocks(world, start, 71, 0, 73, 72, 0, 74, Blocks.SANDSTONE.getDefaultState());
        structure.fillWithBlocks(world, start, 71, 0, 78, 75, 0, 87, Blocks.SANDSTONE.getDefaultState());
        structure.fillWithBlocks(world, start, 72, 0, 4, 78, 0, 10, Blocks.SANDSTONE.getDefaultState());
        structure.fillWithBlocks(world, start, 72, 0, 11, 73, 0, 12, Blocks.SANDSTONE.getDefaultState());
        structure.fillWithBlocks(world, start, 72, 1, 13, 72, 2, 14, Blocks.SAND.getDefaultState());
        structure.fillWithBlocks(world, start, 72, 6, 64, 73, 6, 65, Blocks.SANDSTONE.getDefaultState());
        structure.fillWithBlocks(world, start, 73, 0, 73, 74, 0, 74, Blocks.SANDSTONE.getDefaultState());
        structure.fillWithBlocks(world, start, 73, 1, 13, 73, 5, 13, Blocks.SAND.getDefaultState());
        structure.fillWithBlocks(world, start, 73, 1, 14, 88, 1, 72, Blocks.STONE.getDefaultState());
        structure.fillWithBlocks(world, start, 73, 2, 7, 80, 2, 14, Blocks.SAND.getDefaultState());
        structure.fillWithBlocks(world, start, 73, 3, 8, 79, 3, 14, Blocks.SAND.getDefaultState());
        structure.fillWithBlocks(world, start, 73, 12, 19, 73, 12, 57, Blocks.SANDSTONE.getDefaultState());
        structure.fillWithBlocks(world, start, 74, 0, 12, 85, 0, 72, Blocks.STONE.getDefaultState());
        structure.fillWithBlocks(world, start, 74, 1, 13, 79, 1, 72, Blocks.STONE.getDefaultState());
        structure.fillWithBlocks(world, start, 74, 2, 73, 85, 2, 84, Blocks.SAND.getDefaultState());
        structure.fillWithBlocks(world, start, 74, 6, 64, 75, 6, 65, Blocks.SANDSTONE.getDefaultState());
        structure.fillWithBlocks(world, start, 74, 12, 26, 98, 12, 50, Blocks.SANDSTONE.getDefaultState());
        structure.fillWithBlocks(world, start, 75, 0, 11, 83, 0, 72, Blocks.STONE.getDefaultState());
        structure.fillWithBlocks(world, start, 75, 0, 73, 77, 0, 73, Blocks.SANDSTONE.getDefaultState());
        structure.fillWithBlocks(world, start, 75, 0, 74, 77, 0, 76, Blocks.STONE.getDefaultState());
        structure.fillWithBlocks(world, start, 75, 3, 73, 85, 3, 83, Blocks.SAND.getDefaultState());
        structure.fillWithBlocks(world, start, 75, 11, 19, 75, 11, 57, Blocks.SANDSTONE.getDefaultState());
        structure.fillWithBlocks(world, start, 76, 0, 77, 77, 0, 79, Blocks.SANDSTONE.getDefaultState());
        structure.fillWithBlocks(world, start, 76, 0, 80, 77, 0, 81, Blocks.STONE.getDefaultState());
        structure.fillWithBlocks(world, start, 76, 0, 83, 80, 0, 87, Blocks.SANDSTONE.getDefaultState());
        structure.fillWithBlocks(world, start, 76, 1, 5, 83, 1, 12, Blocks.SAND.getDefaultState());
        structure.fillWithBlocks(world, start, 76, 6, 17, 76, 6, 19, Blocks.SANDSTONE.getDefaultState());
        structure.fillWithBlocks(world, start, 76, 6, 21, 77, 6, 22, Blocks.SANDSTONE.getDefaultState());
        structure.fillWithBlocks(world, start, 76, 6, 24, 77, 6, 52, Blocks.SANDSTONE.getDefaultState());
        structure.fillWithBlocks(world, start, 76, 6, 54, 77, 6, 55, Blocks.SANDSTONE.getDefaultState());
        structure.fillWithBlocks(world, start, 76, 6, 57, 77, 6, 58, Blocks.SANDSTONE.getDefaultState());
        structure.fillWithBlocks(world, start, 76, 6, 59, 76, 9, 59, Blocks.SANDSTONE.getDefaultState());
        structure.fillWithBlocks(world, start, 76, 6, 64, 76, 6, 65, Blocks.SANDSTONE.getDefaultState());
        structure.fillWithBlocks(world, start, 76, 7, 17, 76, 7, 19, Blocks.SANDSTONE.getDefaultState());
        structure.fillWithBlocks(world, start, 76, 7, 21, 77, 7, 22, Blocks.SANDSTONE.getDefaultState());
        structure.fillWithBlocks(world, start, 76, 7, 24, 77, 7, 52, Blocks.SANDSTONE.getDefaultState());
        structure.fillWithBlocks(world, start, 76, 7, 54, 77, 7, 55, Blocks.SANDSTONE.getDefaultState());
        structure.fillWithBlocks(world, start, 76, 7, 57, 77, 7, 58, Blocks.SANDSTONE.getDefaultState());
        structure.fillWithBlocks(world, start, 76, 8, 17, 76, 8, 19, Blocks.SANDSTONE.getDefaultState());
        structure.fillWithBlocks(world, start, 76, 8, 21, 77, 8, 22, Blocks.SANDSTONE.getDefaultState());
        structure.fillWithBlocks(world, start, 76, 8, 24, 77, 8, 52, Blocks.SANDSTONE.getDefaultState());
        structure.fillWithBlocks(world, start, 76, 8, 54, 77, 8, 55, Blocks.SANDSTONE.getDefaultState());
        structure.fillWithBlocks(world, start, 76, 8, 57, 77, 8, 58, Blocks.SANDSTONE.getDefaultState());
        structure.fillWithBlocks(world, start, 76, 9, 17, 76, 9, 19, Blocks.SANDSTONE.getDefaultState());
        structure.fillWithBlocks(world, start, 76, 9, 21, 76, 10, 22, Blocks.SANDSTONE.getDefaultState());
        structure.fillWithBlocks(world, start, 76, 9, 24, 76, 10, 52, Blocks.SANDSTONE.getDefaultState());
        structure.fillWithBlocks(world, start, 76, 9, 54, 76, 10, 55, Blocks.SANDSTONE.getDefaultState());
        structure.fillWithBlocks(world, start, 76, 9, 57, 76, 10, 58, Blocks.SANDSTONE.getDefaultState());
        structure.fillWithBlocks(world, start, 76, 10, 18, 76, 10, 19, Blocks.SANDSTONE.getDefaultState());
        structure.fillWithBlocks(world, start, 76, 11, 26, 100, 11, 50, Blocks.SANDSTONE.getDefaultState());
        structure.fillWithBlocks(world, start, 76, 20, 32, 88, 20, 44, Blocks.SANDSTONE.getDefaultState());
        structure.fillWithBlocks(world, start, 77, 1, 73, 89, 1, 85, Blocks.SAND.getDefaultState());
        structure.fillWithBlocks(world, start, 77, 6, 18, 77, 7, 19, Blocks.SANDSTONE.getDefaultState());
        structure.fillWithBlocks(world, start, 77, 6, 65, 78, 6, 66, Blocks.SANDSTONE.getDefaultState());
        structure.fillWithBlocks(world, start, 77, 8, 18, 77, 8, 19, Blocks.SANDSTONE.getDefaultState());
        structure.fillWithBlocks(world, start, 77, 9, 26, 101, 9, 50, Blocks.SANDSTONE.getDefaultState());
        structure.fillWithBlocks(world, start, 77, 10, 26, 101, 10, 50, Blocks.SANDSTONE.getDefaultState());
        structure.fillWithBlocks(world, start, 77, 20, 31, 91, 20, 45, Blocks.SANDSTONE.getDefaultState());
        structure.fillWithBlocks(world, start, 78, 0, 73, 81, 0, 76, Blocks.STONE.getDefaultState());
        structure.fillWithBlocks(world, start, 78, 0, 77, 79, 0, 78, Blocks.SANDSTONE.getDefaultState());
        structure.fillWithBlocks(world, start, 78, 0, 79, 80, 0, 81, Blocks.STONE.getDefaultState());
        structure.fillWithBlocks(world, start, 78, 6, 27, 100, 6, 49, Blocks.SANDSTONE.getDefaultState());
        structure.fillWithBlocks(world, start, 78, 7, 26, 102, 7, 50, Blocks.SANDSTONE.getDefaultState());
        structure.fillWithBlocks(world, start, 78, 8, 26, 102, 8, 50, Blocks.SANDSTONE.getDefaultState());
        structure.fillWithBlocks(world, start, 79, 0, 4, 84, 0, 9, Blocks.SANDSTONE.getDefaultState());
        structure.fillWithBlocks(world, start, 79, 0, 10, 80, 0, 76, Blocks.STONE.getDefaultState());
        structure.fillWithBlocks(world, start, 79, 6, 65, 80, 6, 66, Blocks.SANDSTONE.getDefaultState());
        structure.fillWithBlocks(world, start, 79, 19, 29, 97, 19, 47, Blocks.SANDSTONE.getDefaultState());
        structure.fillWithBlocks(world, start, 80, 0, 77, 80, 0, 78, Blocks.SANDSTONE.getDefaultState());
        structure.fillWithBlocks(world, start, 80, 1, 13, 83, 4, 13, Blocks.SAND.getDefaultState());
        structure.fillWithBlocks(world, start, 80, 2, 15, 137, 2, 72, Blocks.STONE.getDefaultState());
        structure.fillWithBlocks(world, start, 80, 3, 8, 80, 3, 14, Blocks.SAND.getDefaultState());
        structure.fillWithBlocks(world, start, 80, 3, 15, 137, 3, 72, Blocks.STONE.getDefaultState());
        structure.fillWithBlocks(world, start, 80, 6, 64, 83, 6, 67, Blocks.SANDSTONE.getDefaultState());
        structure.fillWithBlocks(world, start, 80, 7, 65, 81, 7, 66, Blocks.SANDSTONE.getDefaultState());
        structure.fillWithBlocks(world, start, 81, 0, 10, 97, 0, 10, Blocks.SANDSTONE.getDefaultState());
        structure.fillWithBlocks(world, start, 81, 0, 77, 97, 0, 77, Blocks.STONE.getDefaultState());
        structure.fillWithBlocks(world, start, 81, 0, 78, 84, 0, 78, Blocks.SANDSTONE.getDefaultState());
        structure.fillWithBlocks(world, start, 81, 0, 79, 83, 0, 81, Blocks.STONE.getDefaultState());
        structure.fillWithBlocks(world, start, 81, 0, 83, 85, 0, 87, Blocks.SANDSTONE.getDefaultState());
        structure.fillWithBlocks(world, start, 81, 2, 7, 88, 2, 14, Blocks.SAND.getDefaultState());
        structure.fillWithBlocks(world, start, 81, 3, 9, 86, 3, 14, Blocks.SAND.getDefaultState());
        structure.fillWithBlocks(world, start, 81, 5, 77, 97, 5, 77, Blocks.SAND.getDefaultState());
        structure.fillWithBlocks(world, start, 81, 6, 63, 85, 6, 68, Blocks.SANDSTONE.getDefaultState());
        structure.fillWithBlocks(world, start, 81, 7, 64, 84, 7, 67, Blocks.SANDSTONE.getDefaultState());
        structure.fillWithBlocks(world, start, 81, 8, 65, 82, 8, 66, Blocks.SANDSTONE.getDefaultState());
        structure.fillWithBlocks(world, start, 82, 0, 73, 84, 0, 77, Blocks.STONE.getDefaultState());
        structure.fillWithBlocks(world, start, 82, 7, 63, 84, 7, 68, Blocks.SANDSTONE.getDefaultState());
        structure.fillWithBlocks(world, start, 82, 8, 64, 84, 8, 67, Blocks.SANDSTONE.getDefaultState());
        structure.fillWithBlocks(world, start, 83, 1, 86, 96, 1, 86, Blocks.SAND.getDefaultState());
        structure.fillWithBlocks(world, start, 83, 3, 8, 89, 3, 14, Blocks.SAND.getDefaultState());
        structure.fillWithBlocks(world, start, 83, 5, 14, 143, 5, 74, Blocks.SAND.getDefaultState());
        structure.fillWithBlocks(world, start, 84, 0, 11, 96, 0, 11, Blocks.SANDSTONE.getDefaultState());
        structure.fillWithBlocks(world, start, 84, 0, 79, 84, 0, 79, Blocks.SANDSTONE.getDefaultState());
        structure.fillWithBlocks(world, start, 84, 0, 80, 84, 0, 81, Blocks.STONE.getDefaultState());
        structure.fillWithBlocks(world, start, 84, 1, 5, 91, 1, 12, Blocks.SAND.getDefaultState());
        structure.fillWithBlocks(world, start, 84, 1, 13, 87, 1, 72, Blocks.STONE.getDefaultState());
        structure.fillWithBlocks(world, start, 84, 5, 13, 139, 5, 74, Blocks.SAND.getDefaultState());
        structure.fillWithBlocks(world, start, 85, 0, 4, 92, 0, 11, Blocks.SANDSTONE.getDefaultState());
        structure.fillWithBlocks(world, start, 85, 0, 74, 89, 0, 78, Blocks.STONE.getDefaultState());
        structure.fillWithBlocks(world, start, 85, 0, 79, 86, 0, 80, Blocks.SANDSTONE.getDefaultState());
        structure.fillWithBlocks(world, start, 85, 0, 81, 85, 0, 82, Blocks.STONE.getDefaultState());
        structure.fillWithBlocks(world, start, 85, 2, 85, 95, 2, 85, Blocks.SAND.getDefaultState());
        structure.fillWithBlocks(world, start, 85, 4, 82, 95, 4, 82, Blocks.SAND.getDefaultState());
        structure.fillWithBlocks(world, start, 85, 5, 78, 95, 5, 78, Blocks.SAND.getDefaultState());
        structure.fillWithBlocks(world, start, 85, 7, 64, 85, 7, 67, Blocks.SANDSTONE.getDefaultState());
        structure.fillWithBlocks(world, start, 85, 8, 65, 85, 8, 66, Blocks.SANDSTONE.getDefaultState());
        structure.fillWithBlocks(world, start, 86, 0, 12, 96, 0, 12, Blocks.SANDSTONE.getDefaultState());
        structure.fillWithBlocks(world, start, 86, 0, 73, 91, 0, 78, Blocks.STONE.getDefaultState());
        structure.fillWithBlocks(world, start, 86, 0, 81, 86, 0, 81, Blocks.SANDSTONE.getDefaultState());
        structure.fillWithBlocks(world, start, 86, 0, 83, 90, 0, 87, Blocks.SANDSTONE.getDefaultState());
        structure.fillWithBlocks(world, start, 86, 2, 73, 97, 2, 84, Blocks.SAND.getDefaultState());
        structure.fillWithBlocks(world, start, 86, 3, 73, 96, 3, 83, Blocks.SAND.getDefaultState());
        structure.fillWithBlocks(world, start, 86, 3, 84, 94, 3, 84, Blocks.SAND.getDefaultState());
        structure.fillWithBlocks(world, start, 86, 6, 64, 86, 6, 67, Blocks.SANDSTONE.getDefaultState());
        structure.fillWithBlocks(world, start, 86, 7, 65, 86, 7, 66, Blocks.SANDSTONE.getDefaultState());
        structure.fillWithBlocks(world, start, 86, 16, 27, 103, 16, 49, Blocks.SANDSTONE.getDefaultState());
        structure.fillWithBlocks(world, start, 86, 17, 27, 102, 17, 49, Blocks.SANDSTONE.getDefaultState());
        structure.fillWithBlocks(world, start, 86, 18, 27, 102, 18, 49, Blocks.SANDSTONE.getDefaultState());
        structure.fillWithBlocks(world, start, 86, 21, 34, 94, 21, 42, Blocks.SANDSTONE.getDefaultState());
        structure.fillWithBlocks(world, start, 86, 22, 34, 94, 22, 42, Blocks.SANDSTONE.getDefaultState());
        structure.fillWithBlocks(world, start, 86, 23, 34, 94, 23, 42, Blocks.SANDSTONE.getDefaultState());
        structure.fillWithBlocks(world, start, 86, 24, 34, 94, 24, 42, Blocks.SANDSTONE.getDefaultState());
        structure.fillWithBlocks(world, start, 87, 0, 3, 96, 0, 12, Blocks.SANDSTONE.getDefaultState());
        structure.fillWithBlocks(world, start, 87, 0, 79, 88, 0, 87, Blocks.SANDSTONE.getDefaultState());
        structure.fillWithBlocks(world, start, 87, 6, 65, 87, 6, 66, Blocks.SANDSTONE.getDefaultState());
        structure.fillWithBlocks(world, start, 87, 25, 34, 95, 25, 42, Blocks.SANDSTONE.getDefaultState());
        structure.fillWithBlocks(world, start, 87, 26, 34, 95, 26, 42, Blocks.SANDSTONE.getDefaultState());
        structure.fillWithBlocks(world, start, 87, 27, 34, 95, 27, 42, Blocks.SANDSTONE.getDefaultState());
        structure.fillWithBlocks(world, start, 87, 28, 34, 95, 28, 42, Blocks.SANDSTONE.getDefaultState());
        structure.fillWithBlocks(world, start, 87, 29, 34, 95, 29, 42, Blocks.SANDSTONE.getDefaultState());
        structure.fillWithBlocks(world, start, 87, 30, 34, 95, 30, 42, Blocks.SANDSTONE.getDefaultState());
        structure.fillWithBlocks(world, start, 88, 0, 88, 92, 0, 88, Blocks.SANDSTONE.getDefaultState());
        structure.fillWithBlocks(world, start, 88, 1, 13, 88, 1, 13, Blocks.SAND.getDefaultState());
        structure.fillWithBlocks(world, start, 88, 2, 6, 96, 2, 14, Blocks.SAND.getDefaultState());
        structure.fillWithBlocks(world, start, 88, 31, 34, 96, 31, 42, Blocks.SANDSTONE.getDefaultState());
        structure.fillWithBlocks(world, start, 88, 32, 34, 96, 32, 42, Blocks.SANDSTONE.getDefaultState());
        structure.fillWithBlocks(world, start, 88, 33, 34, 96, 33, 42, Blocks.SANDSTONE.getDefaultState());
        structure.fillWithBlocks(world, start, 88, 34, 34, 96, 34, 42, Blocks.SANDSTONE.getDefaultState());
        structure.fillWithBlocks(world, start, 89, 0, 79, 91, 0, 79, Blocks.STONE.getDefaultState());
        structure.fillWithBlocks(world, start, 89, 0, 80, 96, 0, 87, Blocks.SANDSTONE.getDefaultState());
        structure.fillWithBlocks(world, start, 89, 1, 13, 90, 1, 14, Blocks.SAND.getDefaultState());
        structure.fillWithBlocks(world, start, 89, 1, 15, 143, 1, 72, Blocks.STONE.getDefaultState());
        structure.fillWithBlocks(world, start, 89, 4, 78, 93, 4, 82, Blocks.SAND.getDefaultState());
        structure.fillWithBlocks(world, start, 89, 5, 79, 91, 5, 79, Blocks.SAND.getDefaultState());
        structure.fillWithBlocks(world, start, 89, 13, 26, 104, 13, 50, Blocks.SANDSTONE.getDefaultState());
        structure.fillWithBlocks(world, start, 89, 14, 26, 103, 14, 50, Blocks.SANDSTONE.getDefaultState());
        structure.fillWithBlocks(world, start, 89, 15, 26, 102, 15, 50, Blocks.SANDSTONE.getDefaultState());
        structure.fillWithBlocks(world, start, 89, 24, 33, 99, 24, 43, Blocks.SANDSTONE.getDefaultState());
        structure.fillWithBlocks(world, start, 89, 25, 33, 99, 25, 43, Blocks.SANDSTONE.getDefaultState());
        structure.fillWithBlocks(world, start, 89, 26, 33, 99, 26, 43, Blocks.SANDSTONE.getDefaultState());
        structure.fillWithBlocks(world, start, 89, 27, 33, 98, 27, 43, Blocks.SANDSTONE.getDefaultState());
        structure.fillWithBlocks(world, start, 89, 28, 33, 98, 28, 43, Blocks.SANDSTONE.getDefaultState());
        structure.fillWithBlocks(world, start, 89, 29, 33, 98, 29, 43, Blocks.SANDSTONE.getDefaultState());
        structure.fillWithBlocks(world, start, 89, 30, 33, 97, 30, 43, Blocks.SANDSTONE.getDefaultState());
        structure.fillWithBlocks(world, start, 89, 31, 33, 99, 31, 43, Blocks.SANDSTONE.getDefaultState());
        structure.fillWithBlocks(world, start, 89, 32, 33, 99, 32, 43, Blocks.SANDSTONE.getDefaultState());
        structure.fillWithBlocks(world, start, 89, 33, 33, 99, 33, 43, Blocks.SANDSTONE.getDefaultState());
        structure.fillWithBlocks(world, start, 89, 34, 33, 99, 34, 43, Blocks.SANDSTONE.getDefaultState());
        structure.fillWithBlocks(world, start, 89, 35, 33, 99, 35, 43, Blocks.SANDSTONE.getDefaultState());
        structure.fillWithBlocks(world, start, 89, 36, 34, 97, 36, 42, Blocks.SANDSTONE.getDefaultState());
        structure.fillWithBlocks(world, start, 89, 37, 34, 97, 37, 42, Blocks.SANDSTONE.getDefaultState());
        structure.fillWithBlocks(world, start, 90, 1, 73, 96, 1, 86, Blocks.SAND.getDefaultState());
        structure.fillWithBlocks(world, start, 90, 3, 8, 96, 3, 14, Blocks.SAND.getDefaultState());
        structure.fillWithBlocks(world, start, 90, 23, 33, 100, 23, 43, Blocks.SANDSTONE.getDefaultState());
        structure.fillWithBlocks(world, start, 90, 24, 31, 102, 24, 45, Blocks.SANDSTONE.getDefaultState());
        structure.fillWithBlocks(world, start, 90, 25, 31, 100, 25, 45, Blocks.SANDSTONE.getDefaultState());
        structure.fillWithBlocks(world, start, 90, 26, 31, 100, 26, 45, Blocks.SANDSTONE.getDefaultState());
        structure.fillWithBlocks(world, start, 90, 27, 31, 98, 27, 45, Blocks.SANDSTONE.getDefaultState());
        structure.fillWithBlocks(world, start, 90, 28, 31, 98, 28, 45, Blocks.SANDSTONE.getDefaultState());
        structure.fillWithBlocks(world, start, 90, 29, 31, 98, 29, 45, Blocks.SANDSTONE.getDefaultState());
        structure.fillWithBlocks(world, start, 90, 30, 31, 97, 30, 45, Blocks.SANDSTONE.getDefaultState());
        structure.fillWithBlocks(world, start, 90, 31, 31, 97, 31, 45, Blocks.SANDSTONE.getDefaultState());
        structure.fillWithBlocks(world, start, 90, 32, 31, 97, 32, 45, Blocks.SANDSTONE.getDefaultState());
        structure.fillWithBlocks(world, start, 90, 33, 31, 97, 33, 45, Blocks.SANDSTONE.getDefaultState());
        structure.fillWithBlocks(world, start, 90, 34, 31, 97, 34, 45, Blocks.SANDSTONE.getDefaultState());
        structure.fillWithBlocks(world, start, 90, 35, 31, 103, 35, 45, Blocks.SANDSTONE.getDefaultState());
        structure.fillWithBlocks(world, start, 90, 36, 33, 100, 36, 43, Blocks.SANDSTONE.getDefaultState());
        structure.fillWithBlocks(world, start, 90, 37, 33, 100, 37, 43, Blocks.SANDSTONE.getDefaultState());
        structure.fillWithBlocks(world, start, 90, 38, 33, 100, 38, 43, Blocks.SANDSTONE.getDefaultState());
        structure.fillWithBlocks(world, start, 90, 39, 34, 98, 39, 42, Blocks.SANDSTONE.getDefaultState());
        structure.fillWithBlocks(world, start, 91, 1, 13, 92, 1, 14, Blocks.SAND.getDefaultState());
        structure.fillWithBlocks(world, start, 91, 21, 32, 103, 21, 44, Blocks.SANDSTONE.getDefaultState());
        structure.fillWithBlocks(world, start, 91, 22, 32, 103, 22, 44, Blocks.SANDSTONE.getDefaultState());
        structure.fillWithBlocks(world, start, 91, 23, 31, 102, 23, 45, Blocks.SANDSTONE.getDefaultState());
        structure.fillWithBlocks(world, start, 91, 24, 29, 102, 24, 47, Blocks.SANDSTONE.getDefaultState());
        structure.fillWithBlocks(world, start, 91, 25, 29, 100, 25, 47, Blocks.SANDSTONE.getDefaultState());
        structure.fillWithBlocks(world, start, 91, 26, 29, 100, 26, 47, Blocks.SANDSTONE.getDefaultState());
        structure.fillWithBlocks(world, start, 91, 27, 29, 98, 27, 47, Blocks.SANDSTONE.getDefaultState());
        structure.fillWithBlocks(world, start, 91, 28, 29, 98, 28, 47, Blocks.SANDSTONE.getDefaultState());
        structure.fillWithBlocks(world, start, 91, 29, 29, 98, 29, 47, Blocks.SANDSTONE.getDefaultState());
        structure.fillWithBlocks(world, start, 91, 30, 29, 97, 30, 47, Blocks.SANDSTONE.getDefaultState());
        structure.fillWithBlocks(world, start, 91, 31, 29, 97, 31, 47, Blocks.SANDSTONE.getDefaultState());
        structure.fillWithBlocks(world, start, 91, 32, 29, 97, 32, 47, Blocks.SANDSTONE.getDefaultState());
        structure.fillWithBlocks(world, start, 91, 33, 29, 97, 33, 47, Blocks.SANDSTONE.getDefaultState());
        structure.fillWithBlocks(world, start, 91, 34, 29, 97, 34, 47, Blocks.SANDSTONE.getDefaultState());
        structure.fillWithBlocks(world, start, 91, 35, 29, 97, 35, 47, Blocks.SANDSTONE.getDefaultState());
        structure.fillWithBlocks(world, start, 91, 36, 31, 103, 36, 45, Blocks.SANDSTONE.getDefaultState());
        structure.fillWithBlocks(world, start, 91, 37, 31, 105, 37, 45, Blocks.SANDSTONE.getDefaultState());
        structure.fillWithBlocks(world, start, 91, 38, 31, 105, 38, 45, Blocks.SANDSTONE.getDefaultState());
        structure.fillWithBlocks(world, start, 91, 39, 32, 103, 39, 44, Blocks.SANDSTONE.getDefaultState());
        structure.fillWithBlocks(world, start, 91, 40, 32, 103, 40, 44, Blocks.SANDSTONE.getDefaultState());
        structure.fillWithBlocks(world, start, 91, 41, 34, 99, 41, 42, Blocks.SANDSTONE.getDefaultState());
        structure.fillWithBlocks(world, start, 92, 0, 73, 96, 0, 77, Blocks.STONE.getDefaultState());
        structure.fillWithBlocks(world, start, 92, 0, 78, 95, 0, 78, Blocks.STONE.getDefaultState());
        structure.fillWithBlocks(world, start, 92, 0, 79, 99, 0, 86, Blocks.SANDSTONE.getDefaultState());
        structure.fillWithBlocks(world, start, 92, 1, 5, 99, 1, 12, Blocks.SAND.getDefaultState());
        structure.fillWithBlocks(world, start, 92, 3, 7, 99, 3, 14, Blocks.SAND.getDefaultState());
        structure.fillWithBlocks(world, start, 92, 4, 9, 106, 4, 78, Blocks.SAND.getDefaultState());
        structure.fillWithBlocks(world, start, 92, 20, 31, 106, 20, 45, Blocks.SANDSTONE.getDefaultState());
        structure.fillWithBlocks(world, start, 92, 21, 31, 105, 21, 45, Blocks.SANDSTONE.getDefaultState());
        structure.fillWithBlocks(world, start, 92, 22, 31, 104, 22, 45, Blocks.SANDSTONE.getDefaultState());
        structure.fillWithBlocks(world, start, 92, 23, 29, 102, 23, 47, Blocks.SANDSTONE.getDefaultState());
        structure.fillWithBlocks(world, start, 92, 24, 27, 102, 24, 49, Blocks.SANDSTONE.getDefaultState());
        structure.fillWithBlocks(world, start, 92, 25, 27, 100, 25, 49, Blocks.SANDSTONE.getDefaultState());
        structure.fillWithBlocks(world, start, 92, 26, 27, 100, 26, 49, Blocks.SANDSTONE.getDefaultState());
        structure.fillWithBlocks(world, start, 92, 27, 27, 98, 27, 49, Blocks.SANDSTONE.getDefaultState());
        structure.fillWithBlocks(world, start, 92, 28, 27, 98, 28, 49, Blocks.SANDSTONE.getDefaultState());
        structure.fillWithBlocks(world, start, 92, 29, 27, 98, 29, 49, Blocks.SANDSTONE.getDefaultState());
        structure.fillWithBlocks(world, start, 92, 30, 27, 97, 30, 49, Blocks.SANDSTONE.getDefaultState());
        structure.fillWithBlocks(world, start, 92, 31, 27, 97, 31, 49, Blocks.SANDSTONE.getDefaultState());
        structure.fillWithBlocks(world, start, 92, 32, 27, 97, 32, 49, Blocks.SANDSTONE.getDefaultState());
        structure.fillWithBlocks(world, start, 92, 33, 27, 97, 33, 49, Blocks.SANDSTONE.getDefaultState());
        structure.fillWithBlocks(world, start, 92, 34, 27, 97, 34, 49, Blocks.SANDSTONE.getDefaultState());
        structure.fillWithBlocks(world, start, 92, 35, 27, 97, 35, 49, Blocks.SANDSTONE.getDefaultState());
        structure.fillWithBlocks(world, start, 92, 36, 29, 98, 36, 47, Blocks.SANDSTONE.getDefaultState());
        structure.fillWithBlocks(world, start, 92, 37, 29, 98, 37, 47, Blocks.SANDSTONE.getDefaultState());
        structure.fillWithBlocks(world, start, 92, 38, 29, 98, 38, 47, Blocks.SANDSTONE.getDefaultState());
        structure.fillWithBlocks(world, start, 92, 39, 31, 103, 39, 45, Blocks.SANDSTONE.getDefaultState());
        structure.fillWithBlocks(world, start, 92, 40, 31, 103, 40, 45, Blocks.SANDSTONE.getDefaultState());
        structure.fillWithBlocks(world, start, 92, 41, 32, 103, 41, 44, Blocks.SANDSTONE.getDefaultState());
        structure.fillWithBlocks(world, start, 92, 42, 32, 103, 42, 44, Blocks.SANDSTONE.getDefaultState());
        structure.fillWithBlocks(world, start, 92, 43, 34, 100, 43, 42, Blocks.SANDSTONE.getDefaultState());
        structure.fillWithBlocks(world, start, 92, 44, 35, 98, 44, 41, Blocks.SANDSTONE.getDefaultState());
        structure.fillWithBlocks(world, start, 93, 1, 13, 94, 1, 14, Blocks.SAND.getDefaultState());
        structure.fillWithBlocks(world, start, 93, 22, 29, 104, 22, 47, Blocks.SANDSTONE.getDefaultState());
        structure.fillWithBlocks(world, start, 93, 23, 27, 102, 23, 49, Blocks.SANDSTONE.getDefaultState());
        structure.fillWithBlocks(world, start, 93, 24, 26, 102, 24, 50, Blocks.SANDSTONE.getDefaultState());
        structure.fillWithBlocks(world, start, 93, 25, 26, 100, 25, 50, Blocks.SANDSTONE.getDefaultState());
        structure.fillWithBlocks(world, start, 93, 26, 26, 100, 26, 50, Blocks.SANDSTONE.getDefaultState());
        structure.fillWithBlocks(world, start, 93, 27, 26, 98, 27, 50, Blocks.SANDSTONE.getDefaultState());
        structure.fillWithBlocks(world, start, 93, 28, 26, 98, 28, 50, Blocks.SANDSTONE.getDefaultState());
        structure.fillWithBlocks(world, start, 93, 29, 26, 98, 29, 50, Blocks.SANDSTONE.getDefaultState());
        structure.fillWithBlocks(world, start, 93, 30, 26, 97, 30, 50, Blocks.SANDSTONE.getDefaultState());
        structure.fillWithBlocks(world, start, 93, 31, 26, 97, 31, 50, Blocks.SANDSTONE.getDefaultState());
        structure.fillWithBlocks(world, start, 93, 32, 26, 97, 32, 50, Blocks.SANDSTONE.getDefaultState());
        structure.fillWithBlocks(world, start, 93, 33, 26, 97, 33, 50, Blocks.SANDSTONE.getDefaultState());
        structure.fillWithBlocks(world, start, 93, 34, 26, 97, 34, 50, Blocks.SANDSTONE.getDefaultState());
        structure.fillWithBlocks(world, start, 93, 35, 26, 97, 35, 50, Blocks.SANDSTONE.getDefaultState());
        structure.fillWithBlocks(world, start, 93, 36, 27, 98, 36, 49, Blocks.SANDSTONE.getDefaultState());
        structure.fillWithBlocks(world, start, 93, 37, 27, 98, 37, 49, Blocks.SANDSTONE.getDefaultState());
        structure.fillWithBlocks(world, start, 93, 38, 27, 98, 38, 49, Blocks.SANDSTONE.getDefaultState());
        structure.fillWithBlocks(world, start, 93, 39, 29, 99, 39, 47, Blocks.SANDSTONE.getDefaultState());
        structure.fillWithBlocks(world, start, 93, 40, 29, 99, 40, 47, Blocks.SANDSTONE.getDefaultState());
        structure.fillWithBlocks(world, start, 93, 41, 29, 99, 41, 47, Blocks.SANDSTONE.getDefaultState());
        structure.fillWithBlocks(world, start, 93, 42, 31, 103, 42, 45, Blocks.SANDSTONE.getDefaultState());
        structure.fillWithBlocks(world, start, 93, 43, 32, 105, 43, 44, Blocks.SANDSTONE.getDefaultState());
        structure.fillWithBlocks(world, start, 93, 44, 32, 105, 44, 44, Blocks.SANDSTONE.getDefaultState());
        structure.fillWithBlocks(world, start, 93, 45, 34, 101, 45, 42, Blocks.SANDSTONE.getDefaultState());
        structure.fillWithBlocks(world, start, 94, 7, 22, 104, 7, 54, Blocks.SANDSTONE.getDefaultState());
        structure.fillWithBlocks(world, start, 94, 8, 21, 104, 8, 55, Blocks.SANDSTONE.getDefaultState());
        structure.fillWithBlocks(world, start, 94, 9, 21, 104, 9, 55, Blocks.SANDSTONE.getDefaultState());
        structure.fillWithBlocks(world, start, 94, 10, 21, 104, 10, 55, Blocks.SANDSTONE.getDefaultState());
        structure.fillWithBlocks(world, start, 94, 11, 21, 104, 11, 55, Blocks.SANDSTONE.getDefaultState());
        structure.fillWithBlocks(world, start, 94, 12, 22, 104, 12, 54, Blocks.SANDSTONE.getDefaultState());
        structure.fillWithBlocks(world, start, 94, 22, 27, 104, 22, 49, Blocks.SANDSTONE.getDefaultState());
        structure.fillWithBlocks(world, start, 94, 23, 26, 102, 23, 50, Blocks.SANDSTONE.getDefaultState());
        structure.fillWithBlocks(world, start, 94, 24, 25, 102, 24, 51, Blocks.SANDSTONE.getDefaultState());
        structure.fillWithBlocks(world, start, 94, 25, 25, 100, 25, 51, Blocks.SANDSTONE.getDefaultState());
        structure.fillWithBlocks(world, start, 94, 26, 25, 100, 26, 51, Blocks.SANDSTONE.getDefaultState());
        structure.fillWithBlocks(world, start, 94, 27, 25, 98, 27, 51, Blocks.SANDSTONE.getDefaultState());
        structure.fillWithBlocks(world, start, 94, 28, 25, 98, 28, 51, Blocks.SANDSTONE.getDefaultState());
        structure.fillWithBlocks(world, start, 94, 29, 25, 98, 29, 51, Blocks.SANDSTONE.getDefaultState());
        structure.fillWithBlocks(world, start, 94, 30, 25, 97, 30, 51, Blocks.SANDSTONE.getDefaultState());
        structure.fillWithBlocks(world, start, 94, 31, 25, 97, 31, 51, Blocks.SANDSTONE.getDefaultState());
        structure.fillWithBlocks(world, start, 94, 32, 25, 97, 32, 51, Blocks.SANDSTONE.getDefaultState());
        structure.fillWithBlocks(world, start, 94, 33, 25, 97, 33, 51, Blocks.SANDSTONE.getDefaultState());
        structure.fillWithBlocks(world, start, 94, 34, 25, 97, 34, 51, Blocks.SANDSTONE.getDefaultState());
        structure.fillWithBlocks(world, start, 94, 35, 25, 97, 35, 51, Blocks.SANDSTONE.getDefaultState());
        structure.fillWithBlocks(world, start, 94, 36, 26, 98, 36, 50, Blocks.SANDSTONE.getDefaultState());
        structure.fillWithBlocks(world, start, 94, 37, 26, 98, 37, 50, Blocks.SANDSTONE.getDefaultState());
        structure.fillWithBlocks(world, start, 94, 38, 26, 98, 38, 50, Blocks.SANDSTONE.getDefaultState());
        structure.fillWithBlocks(world, start, 94, 39, 27, 99, 39, 49, Blocks.SANDSTONE.getDefaultState());
        structure.fillWithBlocks(world, start, 94, 40, 27, 99, 40, 49, Blocks.SANDSTONE.getDefaultState());
        structure.fillWithBlocks(world, start, 94, 42, 29, 99, 42, 47, Blocks.SANDSTONE.getDefaultState());
        structure.fillWithBlocks(world, start, 94, 43, 30, 100, 43, 46, Blocks.SANDSTONE.getDefaultState());
        structure.fillWithBlocks(world, start, 94, 44, 31, 103, 44, 45, Blocks.SANDSTONE.getDefaultState());
        structure.fillWithBlocks(world, start, 94, 45, 32, 105, 45, 44, Blocks.SANDSTONE.getDefaultState());
        structure.fillWithBlocks(world, start, 94, 46, 34, 102, 46, 42, Blocks.SANDSTONE.getDefaultState());
        structure.fillWithBlocks(world, start, 95, 1, 13, 95, 2, 14, Blocks.SAND.getDefaultState());
        structure.fillWithBlocks(world, start, 95, 6, 23, 103, 6, 53, Blocks.SANDSTONE.getDefaultState());
        structure.fillWithBlocks(world, start, 95, 7, 21, 104, 7, 55, Blocks.SANDSTONE.getDefaultState());
        structure.fillWithBlocks(world, start, 95, 13, 23, 101, 13, 53, Blocks.SANDSTONE.getDefaultState());
        structure.fillWithBlocks(world, start, 95, 22, 26, 104, 22, 50, Blocks.SANDSTONE.getDefaultState());
        structure.fillWithBlocks(world, start, 95, 23, 25, 102, 23, 51, Blocks.SANDSTONE.getDefaultState());
        structure.fillWithBlocks(world, start, 95, 24, 24, 100, 24, 52, Blocks.SANDSTONE.getDefaultState());
        structure.fillWithBlocks(world, start, 95, 25, 24, 100, 25, 52, Blocks.SANDSTONE.getDefaultState());
        structure.fillWithBlocks(world, start, 95, 26, 24, 100, 26, 52, Blocks.SANDSTONE.getDefaultState());
        structure.fillWithBlocks(world, start, 95, 27, 24, 98, 27, 52, Blocks.SANDSTONE.getDefaultState());
        structure.fillWithBlocks(world, start, 95, 28, 24, 98, 28, 52, Blocks.SANDSTONE.getDefaultState());
        structure.fillWithBlocks(world, start, 95, 29, 24, 98, 29, 52, Blocks.SANDSTONE.getDefaultState());
        structure.fillWithBlocks(world, start, 95, 30, 24, 97, 30, 52, Blocks.SANDSTONE.getDefaultState());
        structure.fillWithBlocks(world, start, 95, 31, 24, 97, 31, 52, Blocks.SANDSTONE.getDefaultState());
        structure.fillWithBlocks(world, start, 95, 32, 24, 97, 32, 52, Blocks.SANDSTONE.getDefaultState());
        structure.fillWithBlocks(world, start, 95, 33, 24, 97, 33, 52, Blocks.SANDSTONE.getDefaultState());
        structure.fillWithBlocks(world, start, 95, 34, 24, 97, 34, 52, Blocks.SANDSTONE.getDefaultState());
        structure.fillWithBlocks(world, start, 95, 35, 24, 97, 35, 52, Blocks.SANDSTONE.getDefaultState());
        structure.fillWithBlocks(world, start, 95, 36, 25, 98, 36, 51, Blocks.SANDSTONE.getDefaultState());
        structure.fillWithBlocks(world, start, 95, 37, 25, 98, 37, 51, Blocks.SANDSTONE.getDefaultState());
        structure.fillWithBlocks(world, start, 95, 38, 25, 98, 38, 51, Blocks.SANDSTONE.getDefaultState());
        structure.fillWithBlocks(world, start, 95, 39, 26, 99, 39, 50, Blocks.SANDSTONE.getDefaultState());
        structure.fillWithBlocks(world, start, 95, 40, 26, 99, 40, 50, Blocks.SANDSTONE.getDefaultState());
        structure.fillWithBlocks(world, start, 95, 41, 27, 99, 41, 49, Blocks.SANDSTONE.getDefaultState());
        structure.fillWithBlocks(world, start, 95, 42, 27, 99, 42, 49, Blocks.SANDSTONE.getDefaultState());
        structure.fillWithBlocks(world, start, 95, 43, 28, 100, 43, 48, Blocks.SANDSTONE.getDefaultState());
        structure.fillWithBlocks(world, start, 95, 44, 29, 100, 44, 47, Blocks.SANDSTONE.getDefaultState());
        structure.fillWithBlocks(world, start, 95, 45, 30, 101, 45, 46, Blocks.SANDSTONE.getDefaultState());
        structure.fillWithBlocks(world, start, 95, 46, 32, 102, 46, 44, Blocks.SANDSTONE.getDefaultState());
        structure.fillWithBlocks(world, start, 96, 0, 78, 99, 0, 86, Blocks.SANDSTONE.getDefaultState());
        structure.fillWithBlocks(world, start, 96, 1, 13, 108, 1, 72, Blocks.STONE.getDefaultState());
        structure.fillWithBlocks(world, start, 96, 6, 22, 103, 6, 54, Blocks.SANDSTONE.getDefaultState());
        structure.fillWithBlocks(world, start, 96, 14, 24, 100, 14, 52, Blocks.SANDSTONE.getDefaultState());
        structure.fillWithBlocks(world, start, 96, 25, 23, 100, 25, 53, Blocks.SANDSTONE.getDefaultState());
        structure.fillWithBlocks(world, start, 96, 26, 23, 100, 26, 53, Blocks.SANDSTONE.getDefaultState());
        structure.fillWithBlocks(world, start, 96, 27, 23, 98, 27, 53, Blocks.SANDSTONE.getDefaultState());
        structure.fillWithBlocks(world, start, 96, 28, 23, 98, 28, 53, Blocks.SANDSTONE.getDefaultState());
        structure.fillWithBlocks(world, start, 96, 29, 23, 98, 29, 53, Blocks.SANDSTONE.getDefaultState());
        structure.fillWithBlocks(world, start, 96, 30, 23, 97, 30, 53, Blocks.SANDSTONE.getDefaultState());
        structure.fillWithBlocks(world, start, 96, 31, 23, 97, 31, 53, Blocks.SANDSTONE.getDefaultState());
        structure.fillWithBlocks(world, start, 96, 32, 23, 97, 32, 53, Blocks.SANDSTONE.getDefaultState());
        structure.fillWithBlocks(world, start, 96, 33, 23, 97, 33, 53, Blocks.SANDSTONE.getDefaultState());
        structure.fillWithBlocks(world, start, 96, 34, 23, 97, 34, 53, Blocks.SANDSTONE.getDefaultState());
        structure.fillWithBlocks(world, start, 96, 35, 23, 97, 35, 53, Blocks.SANDSTONE.getDefaultState());
        structure.fillWithBlocks(world, start, 96, 36, 24, 98, 36, 52, Blocks.SANDSTONE.getDefaultState());
        structure.fillWithBlocks(world, start, 96, 37, 24, 98, 37, 52, Blocks.SANDSTONE.getDefaultState());
        structure.fillWithBlocks(world, start, 96, 38, 24, 98, 38, 52, Blocks.SANDSTONE.getDefaultState());
        structure.fillWithBlocks(world, start, 96, 39, 25, 99, 39, 51, Blocks.SANDSTONE.getDefaultState());
        structure.fillWithBlocks(world, start, 96, 40, 25, 99, 40, 51, Blocks.SANDSTONE.getDefaultState());
        structure.fillWithBlocks(world, start, 96, 41, 26, 99, 41, 50, Blocks.SANDSTONE.getDefaultState());
        structure.fillWithBlocks(world, start, 96, 42, 26, 99, 42, 50, Blocks.SANDSTONE.getDefaultState());
        structure.fillWithBlocks(world, start, 96, 43, 27, 100, 43, 49, Blocks.SANDSTONE.getDefaultState());
        structure.fillWithBlocks(world, start, 96, 44, 28, 100, 44, 48, Blocks.SANDSTONE.getDefaultState());
        structure.fillWithBlocks(world, start, 96, 45, 29, 101, 45, 47, Blocks.SANDSTONE.getDefaultState());
