package mod.arcalitegames.odyssey.world.structure.town.bashkarcity;

import mod.arcalitegames.buildersaddition.Index;
import mod.arcalitegames.buildersaddition.blocks.BedsideTable;
import mod.arcalitegames.buildersaddition.blocks.Bench;
import mod.arcalitegames.buildersaddition.blocks.Cabinet;
import mod.arcalitegames.buildersaddition.blocks.Candle;
import mod.arcalitegames.buildersaddition.blocks.Counter;
import mod.arcalitegames.buildersaddition.blocks.Cupboard;
import mod.arcalitegames.buildersaddition.blocks.FireplaceGuard;
import mod.arcalitegames.buildersaddition.blocks.Hedge;
import mod.arcalitegames.buildersaddition.blocks.Pillar;
import mod.arcalitegames.buildersaddition.blocks.Shelf;
import mod.arcalitegames.buildersaddition.blocks.Sofa;
import mod.arcalitegames.buildersaddition.blocks.SupportBracket;
import mod.arcalitegames.buildersaddition.blocks.Table;
import mod.arcalitegames.buildersaddition.blocks.VerticalSlab;
import mod.arcalitegames.buildersaddition.state.BenchState;
import mod.arcalitegames.buildersaddition.state.HedgeState;
import mod.arcalitegames.buildersaddition.state.MountState;
import mod.arcalitegames.buildersaddition.state.PillarState;
import mod.arcalitegames.buildersaddition.state.SofaState;
import mod.arcalitegames.buildersaddition.state.VerticalSlabState;
import mod.arcalitegames.odyssey.blocks.ChairBlock;
import mod.arcalitegames.odyssey.blocks.ModBlocks;
import mod.arcalitegames.odyssey.blocks.ShopSignBlock;
import mod.arcalitegames.odyssey.world.structure.StructureBase;
import net.minecraft.block.AbstractFurnaceBlock;
import net.minecraft.block.AnvilBlock;
import net.minecraft.block.BarrelBlock;
import net.minecraft.block.BedBlock;
import net.minecraft.block.BellBlock;
import net.minecraft.block.Blocks;
import net.minecraft.block.BrewingStandBlock;
import net.minecraft.block.CakeBlock;
import net.minecraft.block.CampfireBlock;
import net.minecraft.block.CauldronBlock;
import net.minecraft.block.ChainBlock;
import net.minecraft.block.ChestBlock;
import net.minecraft.block.ComposterBlock;
import net.minecraft.block.DirectionalBlock;
import net.minecraft.block.DispenserBlock;
import net.minecraft.block.DoorBlock;
import net.minecraft.block.FenceGateBlock;
import net.minecraft.block.FourWayBlock;
import net.minecraft.block.HopperBlock;
import net.minecraft.block.HorizontalBlock;
import net.minecraft.block.JukeboxBlock;
import net.minecraft.block.LanternBlock;
import net.minecraft.block.LeavesBlock;
import net.minecraft.block.LecternBlock;
import net.minecraft.block.NoteBlock;
import net.minecraft.block.ObserverBlock;
import net.minecraft.block.PistonBlock;
import net.minecraft.block.RedstoneLampBlock;
import net.minecraft.block.SkullBlock;
import net.minecraft.block.SlabBlock;
import net.minecraft.block.StairsBlock;
import net.minecraft.block.StonecutterBlock;
import net.minecraft.block.TrapDoorBlock;
import net.minecraft.block.WallBannerBlock;
import net.minecraft.block.WallBlock;
import net.minecraft.block.WallHeight;
import net.minecraft.block.WallSkullBlock;
import net.minecraft.block.WallTorchBlock;
import net.minecraft.state.properties.BedPart;
import net.minecraft.state.properties.BellAttachment;
import net.minecraft.state.properties.ChestType;
import net.minecraft.state.properties.DoorHingeSide;
import net.minecraft.state.properties.DoubleBlockHalf;
import net.minecraft.state.properties.Half;
import net.minecraft.state.properties.NoteBlockInstrument;
import net.minecraft.state.properties.SlabType;
import net.minecraft.state.properties.StairsShape;
import net.minecraft.util.Direction;
import net.minecraft.util.math.BlockPos;
import net.minecraft.world.World;

public class BashkarComponent0
{

	public static BlockPos start;
    public static World world;
    public static StructureBase structure;

    public static void init(World worldIn, BlockPos blockPos, StructureBase structureIn)
    {
        world = worldIn; start = blockPos; structure = structureIn;
    }
    
    public static void generatePart1()
    {
        structure.setBlockState(world, Blocks.STONE.getDefaultState(), -35, -12, -55, start);
        structure.setBlockState(world, Blocks.STONE.getDefaultState(), -33, -11, 42, start);
        structure.setBlockState(world, Blocks.SANDSTONE_WALL.getDefaultState().with(WallBlock.WATERLOGGED, false).with(WallBlock.UP, true).with(WallBlock.WALL_HEIGHT_NORTH, WallHeight.LOW).with(WallBlock.WALL_HEIGHT_SOUTH, WallHeight.LOW).with(WallBlock.WALL_HEIGHT_EAST, WallHeight.LOW).with(WallBlock.WALL_HEIGHT_WEST, WallHeight.LOW), -31, -5, -2, start);
        structure.setBlockState(world, Blocks.LANTERN.getDefaultState().with(LanternBlock.WATERLOGGED, false).with(LanternBlock.HANGING, false), -31, -4, -2, start);
        structure.setBlockState(world, Blocks.SANDSTONE_SLAB.getDefaultState().with(SlabBlock.TYPE, SlabType.BOTTOM).with(SlabBlock.WATERLOGGED, false), -30, -5, 0, start);
        structure.setBlockState(world, Blocks.SANDSTONE_SLAB.getDefaultState().with(SlabBlock.TYPE, SlabType.BOTTOM).with(SlabBlock.WATERLOGGED, false), -29, -5, 5, start);
        structure.setBlockState(world, Blocks.BIRCH_LEAVES.getDefaultState().with(LeavesBlock.PERSISTENT, true).with(LeavesBlock.DISTANCE, 3), -28, -5, -39, start);
        structure.setBlockState(world, Blocks.CAMPFIRE.getDefaultState().with(CampfireBlock.FACING, Direction.EAST).with(CampfireBlock.LIT, true).with(CampfireBlock.SIGNAL_FIRE, false).with(CampfireBlock.WATERLOGGED, false), -28, -5, 2, start);
        structure.setBlockState(world, Blocks.STRIPPED_SPRUCE_LOG.getDefaultState(), -27, -6, -38, start);
        structure.setBlockState(world, Blocks.BIRCH_LEAVES.getDefaultState().with(LeavesBlock.PERSISTENT, true).with(LeavesBlock.DISTANCE, 1), -27, -5, -38, start);
        structure.setBlockState(world, Blocks.BIRCH_LEAVES.getDefaultState().with(LeavesBlock.PERSISTENT, true).with(LeavesBlock.DISTANCE, 2), -27, -5, -37, start);
        structure.setBlockState(world, Blocks.AIR.getDefaultState(), -27, -5, -20, start);
        structure.setBlockState(world, Blocks.AIR.getDefaultState(), -27, -5, -12, start);
        structure.setBlockState(world, Blocks.SANDSTONE_SLAB.getDefaultState().with(SlabBlock.TYPE, SlabType.BOTTOM).with(SlabBlock.WATERLOGGED, false), -27, -5, 0, start);
        structure.setBlockState(world, Blocks.SANDSTONE_SLAB.getDefaultState().with(SlabBlock.TYPE, SlabType.BOTTOM).with(SlabBlock.WATERLOGGED, false), -27, -5, 4, start);
        structure.setBlockState(world, Blocks.BIRCH_LEAVES.getDefaultState().with(LeavesBlock.PERSISTENT, true).with(LeavesBlock.DISTANCE, 2), -27, -4, -38, start);
        structure.setBlockState(world, Blocks.BIRCH_LEAVES.getDefaultState().with(LeavesBlock.PERSISTENT, true).with(LeavesBlock.DISTANCE, 3), -27, -2, -27, start);
        structure.setBlockState(world, Blocks.SPRUCE_FENCE.getDefaultState().with(FourWayBlock.WATERLOGGED, false).with(FourWayBlock.NORTH, false).with(FourWayBlock.SOUTH, true).with(FourWayBlock.EAST, false).with(FourWayBlock.WEST, false), -26, -5, -45, start);
        structure.setBlockState(world, Blocks.SPRUCE_FENCE.getDefaultState().with(FourWayBlock.WATERLOGGED, false).with(FourWayBlock.NORTH, true).with(FourWayBlock.SOUTH, false).with(FourWayBlock.EAST, true).with(FourWayBlock.WEST, false), -26, -5, -44, start);
        structure.setBlockState(world, Blocks.BIRCH_LEAVES.getDefaultState().with(LeavesBlock.PERSISTENT, true).with(LeavesBlock.DISTANCE, 3), -26, -5, -39, start);
        structure.setBlockState(world, Blocks.BIRCH_LEAVES.getDefaultState().with(LeavesBlock.PERSISTENT, true).with(LeavesBlock.DISTANCE, 2), -26, -5, -38, start);
        structure.setBlockState(world, Blocks.BIRCH_LEAVES.getDefaultState().with(LeavesBlock.PERSISTENT, true).with(LeavesBlock.DISTANCE, 3), -26, -5, -37, start);
        structure.setBlockState(world, Blocks.BIRCH_LEAVES.getDefaultState().with(LeavesBlock.PERSISTENT, true).with(LeavesBlock.DISTANCE, 3), -26, -4, -38, start);
        structure.setBlockState(world, Blocks.BIRCH_LEAVES.getDefaultState().with(LeavesBlock.PERSISTENT, true).with(LeavesBlock.DISTANCE, 4), -26, -4, -37, start);
        structure.setBlockState(world, Blocks.BIRCH_LEAVES.getDefaultState().with(LeavesBlock.PERSISTENT, true).with(LeavesBlock.DISTANCE, 3), -26, -2, -28, start);
        structure.setBlockState(world, Blocks.BIRCH_LEAVES.getDefaultState().with(LeavesBlock.PERSISTENT, true).with(LeavesBlock.DISTANCE, 2), -26, -2, -27, start);
        structure.setBlockState(world, Blocks.BIRCH_LEAVES.getDefaultState().with(LeavesBlock.PERSISTENT, true).with(LeavesBlock.DISTANCE, 3), -26, -1, -27, start);
        structure.setBlockState(world, Blocks.BIRCH_LEAVES.getDefaultState().with(LeavesBlock.PERSISTENT, true).with(LeavesBlock.DISTANCE, 3), -26, -1, -25, start);
        structure.setBlockState(world, Blocks.SPRUCE_FENCE.getDefaultState().with(FourWayBlock.WATERLOGGED, false).with(FourWayBlock.NORTH, false).with(FourWayBlock.SOUTH, false).with(FourWayBlock.EAST, false).with(FourWayBlock.WEST, true), -25, -5, -44, start);
        structure.setBlockState(world, Blocks.SANDSTONE_WALL.getDefaultState().with(WallBlock.WATERLOGGED, false).with(WallBlock.UP, true).with(WallBlock.WALL_HEIGHT_NORTH, WallHeight.LOW).with(WallBlock.WALL_HEIGHT_SOUTH, WallHeight.LOW).with(WallBlock.WALL_HEIGHT_EAST, WallHeight.LOW).with(WallBlock.WALL_HEIGHT_WEST, WallHeight.LOW), -25, -5, -19, start);
        structure.setBlockState(world, Blocks.SANDSTONE_WALL.getDefaultState().with(WallBlock.WATERLOGGED, false).with(WallBlock.UP, true).with(WallBlock.WALL_HEIGHT_NORTH, WallHeight.LOW).with(WallBlock.WALL_HEIGHT_SOUTH, WallHeight.LOW).with(WallBlock.WALL_HEIGHT_EAST, WallHeight.LOW).with(WallBlock.WALL_HEIGHT_WEST, WallHeight.LOW), -25, -5, -13, start);
        structure.setBlockState(world, Blocks.SANDSTONE_WALL.getDefaultState().with(WallBlock.WATERLOGGED, false).with(WallBlock.UP, true).with(WallBlock.WALL_HEIGHT_NORTH, WallHeight.LOW).with(WallBlock.WALL_HEIGHT_SOUTH, WallHeight.LOW).with(WallBlock.WALL_HEIGHT_EAST, WallHeight.LOW).with(WallBlock.WALL_HEIGHT_WEST, WallHeight.LOW), -25, -5, -5, start);
        structure.setBlockState(world, Blocks.LANTERN.getDefaultState().with(LanternBlock.WATERLOGGED, false).with(LanternBlock.HANGING, false), -25, -4, -19, start);
        structure.setBlockState(world, Blocks.LANTERN.getDefaultState().with(LanternBlock.WATERLOGGED, false).with(LanternBlock.HANGING, false), -25, -4, -13, start);
        structure.setBlockState(world, Blocks.LANTERN.getDefaultState().with(LanternBlock.WATERLOGGED, false).with(LanternBlock.HANGING, false), -25, -4, -5, start);
        structure.setBlockState(world, Blocks.BIRCH_LEAVES.getDefaultState().with(LeavesBlock.PERSISTENT, true).with(LeavesBlock.DISTANCE, 2), -25, -2, -28, start);
        structure.setBlockState(world, Blocks.STRIPPED_SPRUCE_LOG.getDefaultState(), -25, -2, -26, start);
        structure.setBlockState(world, Blocks.BIRCH_LEAVES.getDefaultState().with(LeavesBlock.PERSISTENT, true).with(LeavesBlock.DISTANCE, 2), -25, -1, -27, start);
        structure.setBlockState(world, Blocks.SANDSTONE_SLAB.getDefaultState().with(SlabBlock.TYPE, SlabType.BOTTOM).with(SlabBlock.WATERLOGGED, false), -25, 0, -37, start);
        structure.setBlockState(world, Blocks.SANDSTONE_SLAB.getDefaultState().with(SlabBlock.TYPE, SlabType.BOTTOM).with(SlabBlock.WATERLOGGED, false), -25, 0, -31, start);
        structure.setBlockState(world, Blocks.STONE.getDefaultState(), -24, -13, -77, start);
        structure.setBlockState(world, Blocks.STONE.getDefaultState(), -24, -11, 60, start);
        structure.setBlockState(world, Blocks.SPRUCE_FENCE.getDefaultState().with(FourWayBlock.WATERLOGGED, false).with(FourWayBlock.NORTH, false).with(FourWayBlock.SOUTH, false).with(FourWayBlock.EAST, false).with(FourWayBlock.WEST, false), -24, -5, -45, start);
        structure.setBlockState(world, Blocks.AIR.getDefaultState(), -24, -5, -42, start);
        structure.setBlockState(world, Blocks.WHITE_BED.getDefaultState().with(HorizontalBlock.HORIZONTAL_FACING, Direction.NORTH).with(BedBlock.PART, BedPart.HEAD), -24, -5, -36, start);
        structure.setBlockState(world, Blocks.WHITE_BED.getDefaultState().with(HorizontalBlock.HORIZONTAL_FACING, Direction.NORTH).with(BedBlock.PART, BedPart.FOOT), -24, -5, -35, start);
        structure.setBlockState(world, ModBlocks.CHAIR.get().getDefaultState().with(ChairBlock.FACING, Direction.EAST), -24, -5, -34, start);
        structure.setBlockState(world, Blocks.SANDSTONE.getDefaultState(), -24, -5, -31, start);
        structure.setBlockState(world, Blocks.BIRCH_LEAVES.getDefaultState().with(LeavesBlock.PERSISTENT, true).with(LeavesBlock.DISTANCE, 3), -24, -5, -10, start);
        structure.setBlockState(world, Blocks.BIRCH_LEAVES.getDefaultState().with(LeavesBlock.PERSISTENT, true).with(LeavesBlock.DISTANCE, 3), -24, -4, -11, start);
        structure.setBlockState(world, Blocks.LANTERN.getDefaultState().with(LanternBlock.WATERLOGGED, false).with(LanternBlock.HANGING, true), -24, -3, -29, start);
        structure.setBlockState(world, Blocks.STRIPPED_SPRUCE_LOG.getDefaultState(), -24, -3, -25, start);
        structure.setBlockState(world, Blocks.BIRCH_LEAVES.getDefaultState().with(LeavesBlock.PERSISTENT, true).with(LeavesBlock.DISTANCE, 1), -24, -3, -24, start);
        structure.setBlockState(world, Blocks.BIRCH_LEAVES.getDefaultState().with(LeavesBlock.PERSISTENT, true).with(LeavesBlock.DISTANCE, 2), -24, -3, -23, start);
        structure.setBlockState(world, Blocks.BIRCH_LEAVES.getDefaultState().with(LeavesBlock.PERSISTENT, true).with(LeavesBlock.DISTANCE, 2), -24, -2, -24, start);
        structure.setBlockState(world, Blocks.STONE.getDefaultState(), -23, -14, -79, start);
        structure.setBlockState(world, Blocks.STONE.getDefaultState(), -23, -11, 38, start);
        structure.setBlockState(world, Blocks.SAND.getDefaultState(), -23, -7, -31, start);
        structure.setBlockState(world, Blocks.SPRUCE_PLANKS.getDefaultState(), -23, -6, -31, start);
        structure.setBlockState(world, Blocks.STRIPPED_SPRUCE_LOG.getDefaultState(), -23, -6, -11, start);
        structure.setBlockState(world, Blocks.BIRCH_LEAVES.getDefaultState().with(LeavesBlock.PERSISTENT, true).with(LeavesBlock.DISTANCE, 3), -23, -5, -46, start);
        structure.setBlockState(world, Blocks.BIRCH_LEAVES.getDefaultState().with(LeavesBlock.PERSISTENT, true).with(LeavesBlock.DISTANCE, 2), -23, -5, -45, start);
        structure.setBlockState(world, ModBlocks.CHAIR.get().getDefaultState().with(ChairBlock.FACING, Direction.SOUTH), -23, -5, -35, start);
        structure.setBlockState(world, Index.TABLE_OAK.getDefaultState().with(Table.NE, true).with(Table.NW, true).with(Table.SE, true).with(Table.SW, true), -23, -5, -34, start);
        structure.setBlockState(world, ModBlocks.CHAIR.get().getDefaultState().with(ChairBlock.FACING, Direction.NORTH), -23, -5, -33, start);
        structure.setBlockState(world, Blocks.SPRUCE_DOOR.getDefaultState().with(DoorBlock.FACING, Direction.SOUTH).with(DoorBlock.HALF, DoubleBlockHalf.LOWER).with(DoorBlock.HINGE, DoorHingeSide.LEFT).with(DoorBlock.OPEN, false).with(DoorBlock.POWERED, false), -23, -5, -31, start);
        structure.setBlockState(world, Blocks.BIRCH_LEAVES.getDefaultState().with(LeavesBlock.PERSISTENT, true).with(LeavesBlock.DISTANCE, 1), -23, -5, -11, start);
        structure.setBlockState(world, Blocks.BIRCH_LEAVES.getDefaultState().with(LeavesBlock.PERSISTENT, true).with(LeavesBlock.DISTANCE, 2), -23, -5, -10, start);
        structure.setBlockState(world, Blocks.COMPOSTER.getDefaultState().with(ComposterBlock.LEVEL, 0), -23, -5, 18, start);
        structure.setBlockState(world, Blocks.BIRCH_LEAVES.getDefaultState().with(LeavesBlock.PERSISTENT, true).with(LeavesBlock.DISTANCE, 3), -23, -4, -45, start);
        structure.setBlockState(world, Blocks.SPRUCE_DOOR.getDefaultState().with(DoorBlock.FACING, Direction.SOUTH).with(DoorBlock.HALF, DoubleBlockHalf.UPPER).with(DoorBlock.HINGE, DoorHingeSide.LEFT).with(DoorBlock.OPEN, false).with(DoorBlock.POWERED, false), -23, -4, -31, start);
        structure.setBlockState(world, Blocks.BIRCH_LEAVES.getDefaultState().with(LeavesBlock.PERSISTENT, true).with(LeavesBlock.DISTANCE, 2), -23, -4, -11, start);
        structure.setBlockState(world, Blocks.LANTERN.getDefaultState().with(LanternBlock.WATERLOGGED, false).with(LanternBlock.HANGING, true), -23, -3, -44, start);
        structure.setBlockState(world, Blocks.LANTERN.getDefaultState().with(LanternBlock.WATERLOGGED, false).with(LanternBlock.HANGING, true), -23, -3, -40, start);
        structure.setBlockState(world, Blocks.BIRCH_LEAVES.getDefaultState().with(LeavesBlock.PERSISTENT, true).with(LeavesBlock.DISTANCE, 2), -23, -3, -24, start);
        structure.setBlockState(world, Blocks.BIRCH_LEAVES.getDefaultState().with(LeavesBlock.PERSISTENT, true).with(LeavesBlock.DISTANCE, 3), -23, -3, -23, start);
        structure.setBlockState(world, Blocks.BIRCH_LEAVES.getDefaultState().with(LeavesBlock.PERSISTENT, true).with(LeavesBlock.DISTANCE, 3), -23, -3, -11, start);
        structure.setBlockState(world, Blocks.SPRUCE_FENCE.getDefaultState().with(FourWayBlock.WATERLOGGED, false).with(FourWayBlock.NORTH, false).with(FourWayBlock.SOUTH, false).with(FourWayBlock.EAST, true).with(FourWayBlock.WEST, false), -23, -2, -44, start);
        structure.setBlockState(world, Blocks.SPRUCE_FENCE.getDefaultState().with(FourWayBlock.WATERLOGGED, false).with(FourWayBlock.NORTH, false).with(FourWayBlock.SOUTH, false).with(FourWayBlock.EAST, true).with(FourWayBlock.WEST, false), -23, -2, -40, start);
        structure.setBlockState(world, Blocks.BIRCH_LEAVES.getDefaultState().with(LeavesBlock.PERSISTENT, true).with(LeavesBlock.DISTANCE, 2), -23, -2, -25, start);
        structure.setBlockState(world, Blocks.BIRCH_LEAVES.getDefaultState().with(LeavesBlock.PERSISTENT, true).with(LeavesBlock.DISTANCE, 3), -23, -2, -24, start);
        structure.setBlockState(world, Blocks.BIRCH_LEAVES.getDefaultState().with(LeavesBlock.PERSISTENT, true).with(LeavesBlock.DISTANCE, 2), -23, -2, 42, start);
        structure.setBlockState(world, Blocks.BIRCH_LEAVES.getDefaultState().with(LeavesBlock.PERSISTENT, true).with(LeavesBlock.DISTANCE, 2), -23, -2, 44, start);
        structure.setBlockState(world, Blocks.BIRCH_LEAVES.getDefaultState().with(LeavesBlock.PERSISTENT, true).with(LeavesBlock.DISTANCE, 2), -23, -1, 43, start);
        structure.setBlockState(world, Blocks.SPRUCE_FENCE.getDefaultState().with(FourWayBlock.WATERLOGGED, false).with(FourWayBlock.NORTH, false).with(FourWayBlock.SOUTH, true).with(FourWayBlock.EAST, true).with(FourWayBlock.WEST, false), -23, 0, -37, start);
        structure.setBlockState(world, Blocks.SPRUCE_FENCE.getDefaultState().with(FourWayBlock.WATERLOGGED, false).with(FourWayBlock.NORTH, true).with(FourWayBlock.SOUTH, false).with(FourWayBlock.EAST, true).with(FourWayBlock.WEST, false), -23, 0, -33, start);
        structure.setBlockState(world, Blocks.SAND.getDefaultState(), -22, -7, -45, start);
        structure.setBlockState(world, Blocks.STRIPPED_SPRUCE_LOG.getDefaultState(), -22, -6, -45, start);
        structure.setBlockState(world, Blocks.AIR.getDefaultState(), -22, -5, -58, start);
        structure.setBlockState(world, Blocks.BIRCH_LEAVES.getDefaultState().with(LeavesBlock.PERSISTENT, true).with(LeavesBlock.DISTANCE, 1), -22, -5, -45, start);
        structure.setBlockState(world, Blocks.SPRUCE_DOOR.getDefaultState().with(DoorBlock.FACING, Direction.WEST).with(DoorBlock.HALF, DoubleBlockHalf.LOWER).with(DoorBlock.HINGE, DoorHingeSide.LEFT).with(DoorBlock.OPEN, false).with(DoorBlock.POWERED, false), -22, -5, -42, start);
        structure.setBlockState(world, ModBlocks.CHAIR.get().getDefaultState().with(ChairBlock.FACING, Direction.WEST), -22, -5, -34, start);
        structure.setBlockState(world, Blocks.BARREL.getDefaultState().with(BarrelBlock.PROPERTY_FACING, Direction.UP).with(BarrelBlock.PROPERTY_OPEN, false), -22, -5, -20, start);
        structure.setBlockState(world, Blocks.BIRCH_LEAVES.getDefaultState().with(LeavesBlock.PERSISTENT, true).with(LeavesBlock.DISTANCE, 2), -22, -5, -11, start);
        structure.setBlockState(world, Blocks.BIRCH_LEAVES.getDefaultState().with(LeavesBlock.PERSISTENT, true).with(LeavesBlock.DISTANCE, 2), -22, -4, -45, start);
        structure.setBlockState(world, Blocks.SPRUCE_DOOR.getDefaultState().with(DoorBlock.FACING, Direction.WEST).with(DoorBlock.HALF, DoubleBlockHalf.UPPER).with(DoorBlock.HINGE, DoorHingeSide.LEFT).with(DoorBlock.OPEN, false).with(DoorBlock.POWERED, false), -22, -4, -42, start);
        structure.setBlockState(world, Blocks.BIRCH_LEAVES.getDefaultState().with(LeavesBlock.PERSISTENT, true).with(LeavesBlock.DISTANCE, 3), -22, -3, -45, start);
        structure.setBlockState(world, Blocks.BIRCH_LEAVES.getDefaultState().with(LeavesBlock.PERSISTENT, true).with(LeavesBlock.DISTANCE, 2), -22, -3, -25, start);
        structure.setBlockState(world, Blocks.BIRCH_LEAVES.getDefaultState().with(LeavesBlock.PERSISTENT, true).with(LeavesBlock.DISTANCE, 3), -22, -3, -24, start);
        structure.setBlockState(world, Blocks.SPRUCE_FENCE.getDefaultState().with(FourWayBlock.WATERLOGGED, false).with(FourWayBlock.NORTH, false).with(FourWayBlock.SOUTH, true).with(FourWayBlock.EAST, true).with(FourWayBlock.WEST, false), -22, -2, -22, start);
        structure.setBlockState(world, Blocks.SPRUCE_FENCE.getDefaultState().with(FourWayBlock.WATERLOGGED, false).with(FourWayBlock.NORTH, true).with(FourWayBlock.SOUTH, false).with(FourWayBlock.EAST, true).with(FourWayBlock.WEST, false), -22, -2, -21, start);
        structure.setBlockState(world, Blocks.STRIPPED_SPRUCE_LOG.getDefaultState(), -22, -2, 43, start);
        structure.setBlockState(world, Blocks.SANDSTONE_SLAB.getDefaultState().with(SlabBlock.TYPE, SlabType.BOTTOM).with(SlabBlock.WATERLOGGED, false), -22, 0, -44, start);
        structure.setBlockState(world, Blocks.SANDSTONE_SLAB.getDefaultState().with(SlabBlock.TYPE, SlabType.BOTTOM).with(SlabBlock.WATERLOGGED, false), -22, 0, -40, start);
        structure.setBlockState(world, Blocks.BIRCH_LEAVES.getDefaultState().with(LeavesBlock.PERSISTENT, true).with(LeavesBlock.DISTANCE, 2), -22, 0, 44, start);
        structure.setBlockState(world, Blocks.BIRCH_LEAVES.getDefaultState().with(LeavesBlock.PERSISTENT, true).with(LeavesBlock.DISTANCE, 3), -22, 1, 44, start);
        structure.setBlockState(world, Blocks.BIRCH_LEAVES.getDefaultState().with(LeavesBlock.PERSISTENT, true).with(LeavesBlock.DISTANCE, 3), -22, 1, 46, start);
        structure.setBlockState(world, Blocks.BIRCH_LEAVES.getDefaultState().with(LeavesBlock.PERSISTENT, true).with(LeavesBlock.DISTANCE, 2), -21, -5, -45, start);
        structure.setBlockState(world, Blocks.BARREL.getDefaultState().with(BarrelBlock.PROPERTY_FACING, Direction.UP).with(BarrelBlock.PROPERTY_OPEN, false), -21, -5, -38, start);
        structure.setBlockState(world, Blocks.SANDSTONE_WALL.getDefaultState().with(WallBlock.WATERLOGGED, false).with(WallBlock.UP, true).with(WallBlock.WALL_HEIGHT_NORTH, WallHeight.LOW).with(WallBlock.WALL_HEIGHT_SOUTH, WallHeight.LOW).with(WallBlock.WALL_HEIGHT_EAST, WallHeight.LOW).with(WallBlock.WALL_HEIGHT_WEST, WallHeight.LOW), -21, -5, -22, start);
        structure.setBlockState(world, Blocks.BARREL.getDefaultState().with(BarrelBlock.PROPERTY_FACING, Direction.SOUTH).with(BarrelBlock.PROPERTY_OPEN, false), -21, -5, -20, start);
        structure.setBlockState(world, Blocks.SANDSTONE_WALL.getDefaultState().with(WallBlock.WATERLOGGED, false).with(WallBlock.UP, true).with(WallBlock.WALL_HEIGHT_NORTH, WallHeight.LOW).with(WallBlock.WALL_HEIGHT_SOUTH, WallHeight.LOW).with(WallBlock.WALL_HEIGHT_EAST, WallHeight.LOW).with(WallBlock.WALL_HEIGHT_WEST, WallHeight.LOW), -21, -5, 17, start);
        structure.setBlockState(world, Blocks.LANTERN.getDefaultState().with(LanternBlock.WATERLOGGED, false).with(LanternBlock.HANGING, false), -21, -4, -22, start);
        structure.setBlockState(world, Blocks.BARREL.getDefaultState().with(BarrelBlock.PROPERTY_FACING, Direction.WEST).with(BarrelBlock.PROPERTY_OPEN, false), -21, -4, -20, start);
        structure.setBlockState(world, Blocks.BIRCH_LEAVES.getDefaultState().with(LeavesBlock.PERSISTENT, true).with(LeavesBlock.DISTANCE, 3), -21, -4, 7, start);
        structure.setBlockState(world, Blocks.LANTERN.getDefaultState().with(LanternBlock.WATERLOGGED, false).with(LanternBlock.HANGING, false), -21, -4, 17, start);
        structure.setBlockState(world, ModBlocks.SHOP_SIGN_STABLES.get().getDefaultState().with(ShopSignBlock.FACING, Direction.WEST), -21, -3, -18, start);
        structure.setBlockState(world, ModBlocks.SHOP_SIGN_STABLES.get().getDefaultState().with(ShopSignBlock.FACING, Direction.WEST), -21, -3, -6, start);
        structure.setBlockState(world, Blocks.SPRUCE_FENCE.getDefaultState().with(FourWayBlock.WATERLOGGED, false).with(FourWayBlock.NORTH, false).with(FourWayBlock.SOUTH, true).with(FourWayBlock.EAST, true).with(FourWayBlock.WEST, false), -21, -2, -23, start);
        structure.setBlockState(world, Blocks.SPRUCE_FENCE.getDefaultState().with(FourWayBlock.WATERLOGGED, false).with(FourWayBlock.NORTH, true).with(FourWayBlock.SOUTH, true).with(FourWayBlock.EAST, false).with(FourWayBlock.WEST, true), -21, -2, -22, start);
        structure.setBlockState(world, Blocks.SPRUCE_FENCE.getDefaultState().with(FourWayBlock.WATERLOGGED, false).with(FourWayBlock.NORTH, true).with(FourWayBlock.SOUTH, false).with(FourWayBlock.EAST, true).with(FourWayBlock.WEST, true), -21, -2, -21, start);
        structure.setBlockState(world, Blocks.STRIPPED_SPRUCE_LOG.getDefaultState(), -21, -2, 43, start);
        structure.setBlockState(world, Blocks.OAK_TRAPDOOR.getDefaultState().with(HorizontalBlock.HORIZONTAL_FACING, Direction.SOUTH).with(TrapDoorBlock.HALF, Half.BOTTOM).with(TrapDoorBlock.WATERLOGGED, false).with(TrapDoorBlock.POWERED, false).with(TrapDoorBlock.OPEN, false), -21, -1, -35, start);
        structure.setBlockState(world, Blocks.STRIPPED_SPRUCE_LOG.getDefaultState(), -21, -1, 45, start);
        structure.setBlockState(world, Blocks.STRIPPED_SPRUCE_LOG.getDefaultState(), -21, 0, 45, start);
        structure.setBlockState(world, Blocks.BIRCH_LEAVES.getDefaultState().with(LeavesBlock.PERSISTENT, true).with(LeavesBlock.DISTANCE, 1), -21, 1, 45, start);
        structure.setBlockState(world, Blocks.BIRCH_LEAVES.getDefaultState().with(LeavesBlock.PERSISTENT, true).with(LeavesBlock.DISTANCE, 2), -21, 1, 46, start);
        structure.setBlockState(world, Blocks.BIRCH_LEAVES.getDefaultState().with(LeavesBlock.PERSISTENT, true).with(LeavesBlock.DISTANCE, 2), -21, 2, 45, start);
        structure.setBlockState(world, Blocks.FURNACE.getDefaultState().with(AbstractFurnaceBlock.FACING, Direction.WEST).with(AbstractFurnaceBlock.LIT, false), -20, -5, -34, start);
        structure.setBlockState(world, Blocks.CRAFTING_TABLE.getDefaultState(), -20, -5, -33, start);
        structure.setBlockState(world, Index.COUNTER_OAK_ANDESITE.getDefaultState().with(Counter.FACING, Direction.WEST).with(Counter.WATERLOGGED, false), -20, -5, -32, start);
        structure.setBlockState(world, Blocks.BARREL.getDefaultState().with(BarrelBlock.PROPERTY_FACING, Direction.UP).with(BarrelBlock.PROPERTY_OPEN, false), -20, -5, 24, start);
        structure.setBlockState(world, Blocks.BIRCH_LEAVES.getDefaultState().with(LeavesBlock.PERSISTENT, true).with(LeavesBlock.DISTANCE, 3), -20, -4, 6, start);
        structure.setBlockState(world, Blocks.BIRCH_LEAVES.getDefaultState().with(LeavesBlock.PERSISTENT, true).with(LeavesBlock.DISTANCE, 3), -20, -4, 10, start);
        structure.setBlockState(world, Blocks.BARREL.getDefaultState().with(BarrelBlock.PROPERTY_FACING, Direction.WEST).with(BarrelBlock.PROPERTY_OPEN, false), -20, -4, 24, start);
        structure.setBlockState(world, Blocks.SPRUCE_FENCE.getDefaultState().with(FourWayBlock.WATERLOGGED, false).with(FourWayBlock.NORTH, true).with(FourWayBlock.SOUTH, false).with(FourWayBlock.EAST, false).with(FourWayBlock.WEST, false), -20, -3, -4, start);
        structure.setBlockState(world, Blocks.LANTERN.getDefaultState().with(LanternBlock.WATERLOGGED, false).with(LanternBlock.HANGING, true), -20, -2, -42, start);
        structure.setBlockState(world, Blocks.SPRUCE_FENCE.getDefaultState().with(FourWayBlock.WATERLOGGED, false).with(FourWayBlock.NORTH, false).with(FourWayBlock.SOUTH, false).with(FourWayBlock.EAST, true).with(FourWayBlock.WEST, true), -20, -2, -23, start);
        structure.setBlockState(world, Blocks.SMOOTH_SANDSTONE_STAIRS.getDefaultState().with(StairsBlock.FACING, Direction.NORTH).with(StairsBlock.WATERLOGGED, false).with(StairsBlock.SHAPE, StairsShape.STRAIGHT).with(StairsBlock.HALF, Half.TOP), -20, -2, -17, start);
        structure.setBlockState(world, Blocks.SMOOTH_SANDSTONE_STAIRS.getDefaultState().with(StairsBlock.FACING, Direction.SOUTH).with(StairsBlock.WATERLOGGED, false).with(StairsBlock.SHAPE, StairsShape.STRAIGHT).with(StairsBlock.HALF, Half.TOP), -20, -2, -15, start);
        structure.setBlockState(world, Blocks.SMOOTH_SANDSTONE_STAIRS.getDefaultState().with(StairsBlock.FACING, Direction.NORTH).with(StairsBlock.WATERLOGGED, false).with(StairsBlock.SHAPE, StairsShape.STRAIGHT).with(StairsBlock.HALF, Half.TOP), -20, -2, -9, start);
        structure.setBlockState(world, Blocks.SMOOTH_SANDSTONE_STAIRS.getDefaultState().with(StairsBlock.FACING, Direction.SOUTH).with(StairsBlock.WATERLOGGED, false).with(StairsBlock.SHAPE, StairsShape.STRAIGHT).with(StairsBlock.HALF, Half.TOP), -20, -2, -7, start);
        structure.setBlockState(world, Blocks.BIRCH_LEAVES.getDefaultState().with(LeavesBlock.PERSISTENT, true).with(LeavesBlock.DISTANCE, 2), -20, -2, 42, start);
        structure.setBlockState(world, Blocks.CUT_SANDSTONE.getDefaultState(), -20, -1, -20, start);
        structure.setBlockState(world, Blocks.BIRCH_LEAVES.getDefaultState().with(LeavesBlock.PERSISTENT, true).with(LeavesBlock.DISTANCE, 3), -20, -1, 42, start);
        structure.setBlockState(world, Blocks.BIRCH_LEAVES.getDefaultState().with(LeavesBlock.PERSISTENT, true).with(LeavesBlock.DISTANCE, 3), -20, -1, 47, start);
        structure.setBlockState(world, Blocks.SPRUCE_FENCE.getDefaultState().with(FourWayBlock.WATERLOGGED, false).with(FourWayBlock.NORTH, true).with(FourWayBlock.SOUTH, false).with(FourWayBlock.EAST, true).with(FourWayBlock.WEST, false), -20, 0, -44, start);
        structure.setBlockState(world, Blocks.SPRUCE_FENCE.getDefaultState().with(FourWayBlock.WATERLOGGED, false).with(FourWayBlock.NORTH, false).with(FourWayBlock.SOUTH, false).with(FourWayBlock.EAST, false).with(FourWayBlock.WEST, true), -20, 0, -37, start);
        structure.setBlockState(world, Blocks.SANDSTONE_SLAB.getDefaultState().with(SlabBlock.TYPE, SlabType.BOTTOM).with(SlabBlock.WATERLOGGED, false), -20, 0, -11, start);
        structure.setBlockState(world, Blocks.SANDSTONE_SLAB.getDefaultState().with(SlabBlock.TYPE, SlabType.BOTTOM).with(SlabBlock.WATERLOGGED, false), -20, 0, -5, start);
        structure.setBlockState(world, Blocks.BIRCH_LEAVES.getDefaultState().with(LeavesBlock.PERSISTENT, true).with(LeavesBlock.DISTANCE, 2), -20, 0, 44, start);
        structure.setBlockState(world, Blocks.BIRCH_LEAVES.getDefaultState().with(LeavesBlock.PERSISTENT, true).with(LeavesBlock.DISTANCE, 1), -20, 0, 45, start);
        structure.setBlockState(world, Blocks.BIRCH_LEAVES.getDefaultState().with(LeavesBlock.PERSISTENT, true).with(LeavesBlock.DISTANCE, 2), -20, 1, 45, start);
        structure.setBlockState(world, Blocks.BARREL.getDefaultState().with(BarrelBlock.PROPERTY_FACING, Direction.UP).with(BarrelBlock.PROPERTY_OPEN, false), -19, -5, -11, start);
        structure.setBlockState(world, Blocks.BARREL.getDefaultState().with(BarrelBlock.PROPERTY_FACING, Direction.WEST).with(BarrelBlock.PROPERTY_OPEN, false), -19, -4, -38, start);
        structure.setBlockState(world, Blocks.BARREL.getDefaultState().with(BarrelBlock.PROPERTY_FACING, Direction.EAST).with(BarrelBlock.PROPERTY_OPEN, false), -19, -4, -13, start);
        structure.setBlockState(world, Blocks.BIRCH_LEAVES.getDefaultState().with(LeavesBlock.PERSISTENT, true).with(LeavesBlock.DISTANCE, 2), -19, -4, 10, start);
        structure.setBlockState(world, Blocks.LANTERN.getDefaultState().with(LanternBlock.WATERLOGGED, false).with(LanternBlock.HANGING, true), -19, -3, 0, start);
        structure.setBlockState(world, Blocks.SPRUCE_FENCE.getDefaultState().with(FourWayBlock.WATERLOGGED, false).with(FourWayBlock.NORTH, false).with(FourWayBlock.SOUTH, true).with(FourWayBlock.EAST, true).with(FourWayBlock.WEST, true), -19, -2, -23, start);
        structure.setBlockState(world, Blocks.SPRUCE_FENCE.getDefaultState().with(FourWayBlock.WATERLOGGED, false).with(FourWayBlock.NORTH, true).with(FourWayBlock.SOUTH, true).with(FourWayBlock.EAST, true).with(FourWayBlock.WEST, false), -19, -2, -22, start);
        structure.setBlockState(world, Blocks.SPRUCE_FENCE.getDefaultState().with(FourWayBlock.WATERLOGGED, false).with(FourWayBlock.NORTH, true).with(FourWayBlock.SOUTH, false).with(FourWayBlock.EAST, false).with(FourWayBlock.WEST, true), -19, 0, -44, start);
        structure.setBlockState(world, Blocks.SANDSTONE_SLAB.getDefaultState().with(SlabBlock.TYPE, SlabType.BOTTOM).with(SlabBlock.WATERLOGGED, false), -19, 0, -37, start);
        structure.setBlockState(world, Blocks.SPRUCE_FENCE.getDefaultState().with(FourWayBlock.WATERLOGGED, false).with(FourWayBlock.NORTH, false).with(FourWayBlock.SOUTH, true).with(FourWayBlock.EAST, false).with(FourWayBlock.WEST, false), -19, 0, -36, start);
        structure.setBlockState(world, Blocks.SPRUCE_FENCE.getDefaultState().with(FourWayBlock.WATERLOGGED, false).with(FourWayBlock.NORTH, true).with(FourWayBlock.SOUTH, false).with(FourWayBlock.EAST, false).with(FourWayBlock.WEST, true), -19, 0, -33, start);
        structure.setBlockState(world, Blocks.SANDSTONE_SLAB.getDefaultState().with(SlabBlock.TYPE, SlabType.BOTTOM).with(SlabBlock.WATERLOGGED, false), -19, 0, -31, start);
        structure.setBlockState(world, Blocks.BIRCH_LEAVES.getDefaultState().with(LeavesBlock.PERSISTENT, true).with(LeavesBlock.DISTANCE, 1), -19, 0, 9, start);
        structure.setBlockState(world, Blocks.SANDSTONE_SLAB.getDefaultState().with(SlabBlock.TYPE, SlabType.BOTTOM).with(SlabBlock.WATERLOGGED, false), -19, 0, 18, start);
        structure.setBlockState(world, Blocks.SANDSTONE_SLAB.getDefaultState().with(SlabBlock.TYPE, SlabType.BOTTOM).with(SlabBlock.WATERLOGGED, false), -19, 0, 24, start);
        structure.setBlockState(world, Blocks.BIRCH_LEAVES.getDefaultState().with(LeavesBlock.PERSISTENT, true).with(LeavesBlock.DISTANCE, 3), -19, 0, 46, start);
        structure.setBlockState(world, Blocks.BIRCH_LEAVES.getDefaultState().with(LeavesBlock.PERSISTENT, true).with(LeavesBlock.DISTANCE, 1), -19, 1, 8, start);
        structure.setBlockState(world, Blocks.OAK_TRAPDOOR.getDefaultState().with(HorizontalBlock.HORIZONTAL_FACING, Direction.WEST).with(TrapDoorBlock.HALF, Half.BOTTOM).with(TrapDoorBlock.WATERLOGGED, false).with(TrapDoorBlock.POWERED, false).with(TrapDoorBlock.OPEN, false), -19, 3, -6, start);
        structure.setBlockState(world, Blocks.STONE.getDefaultState(), -18, -11, 34, start);
        structure.setBlockState(world, Blocks.COMPOSTER.getDefaultState().with(ComposterBlock.LEVEL, 0), -18, -5, -4, start);
        structure.setBlockState(world, Blocks.BIRCH_LEAVES.getDefaultState().with(LeavesBlock.PERSISTENT, true).with(LeavesBlock.DISTANCE, 3), -18, -5, 15, start);
        structure.setBlockState(world, Blocks.BIRCH_LEAVES.getDefaultState().with(LeavesBlock.PERSISTENT, true).with(LeavesBlock.DISTANCE, 3), -18, -5, 17, start);
        structure.setBlockState(world, Index.COUNTER_OAK_ANDESITE.getDefaultState().with(Counter.FACING, Direction.SOUTH).with(Counter.WATERLOGGED, false), -18, -5, 19, start);
        structure.setBlockState(world, Blocks.SANDSTONE.getDefaultState(), -18, -5, 24, start);
        structure.setBlockState(world, Blocks.BIRCH_LEAVES.getDefaultState().with(LeavesBlock.PERSISTENT, true).with(LeavesBlock.DISTANCE, 3), -18, -4, 10, start);
        structure.setBlockState(world, Blocks.BIRCH_LEAVES.getDefaultState().with(LeavesBlock.PERSISTENT, true).with(LeavesBlock.DISTANCE, 4), -18, -4, 17, start);
        structure.setBlockState(world, Blocks.SPRUCE_TRAPDOOR.getDefaultState().with(HorizontalBlock.HORIZONTAL_FACING, Direction.SOUTH).with(TrapDoorBlock.HALF, Half.TOP).with(TrapDoorBlock.WATERLOGGED, false).with(TrapDoorBlock.POWERED, false).with(TrapDoorBlock.OPEN, false), -18, -4, 19, start);
        structure.setBlockState(world, Blocks.BIRCH_LEAVES.getDefaultState().with(LeavesBlock.PERSISTENT, true).with(LeavesBlock.DISTANCE, 5), -18, -3, 17, start);
        structure.setBlockState(world, Index.CUPBOARD_OAK.getDefaultState().with(Cupboard.FACING, Direction.SOUTH).with(Cupboard.HALF, DoubleBlockHalf.LOWER).with(Cupboard.MIRROR, false).with(Cupboard.WATERLOGGED, false), -18, -3, 19, start);
        structure.setBlockState(world, Blocks.SMOOTH_SANDSTONE.getDefaultState(), -18, -2, -44, start);
        structure.setBlockState(world, Index.CUPBOARD_OAK.getDefaultState().with(Cupboard.FACING, Direction.SOUTH).with(Cupboard.HALF, DoubleBlockHalf.UPPER).with(Cupboard.MIRROR, false).with(Cupboard.WATERLOGGED, false), -18, -2, 19, start);
        structure.setBlockState(world, Blocks.CUT_SANDSTONE.getDefaultState(), -18, -1, -44, start);
        structure.setBlockState(world, Blocks.CUT_SANDSTONE.getDefaultState(), -18, -1, -35, start);
        structure.setBlockState(world, Blocks.CUT_SANDSTONE.getDefaultState(), -18, -1, -21, start);
        structure.setBlockState(world, Blocks.SANDSTONE_SLAB.getDefaultState().with(SlabBlock.TYPE, SlabType.BOTTOM).with(SlabBlock.WATERLOGGED, false), -18, 0, -44, start);
        structure.setBlockState(world, Blocks.SPRUCE_FENCE.getDefaultState().with(FourWayBlock.WATERLOGGED, false).with(FourWayBlock.NORTH, false).with(FourWayBlock.SOUTH, true).with(FourWayBlock.EAST, true).with(FourWayBlock.WEST, false), -18, 0, -43, start);
        structure.setBlockState(world, Blocks.SPRUCE_FENCE.getDefaultState().with(FourWayBlock.WATERLOGGED, false).with(FourWayBlock.NORTH, true).with(FourWayBlock.SOUTH, false).with(FourWayBlock.EAST, true).with(FourWayBlock.WEST, false), -18, 0, -42, start);
        structure.setBlockState(world, Blocks.SANDSTONE_SLAB.getDefaultState().with(SlabBlock.TYPE, SlabType.BOTTOM).with(SlabBlock.WATERLOGGED, false), -18, 0, -40, start);
        structure.setBlockState(world, Blocks.SANDSTONE_WALL.getDefaultState().with(WallBlock.WATERLOGGED, false).with(WallBlock.UP, true).with(WallBlock.WALL_HEIGHT_NORTH, WallHeight.LOW).with(WallBlock.WALL_HEIGHT_SOUTH, WallHeight.LOW).with(WallBlock.WALL_HEIGHT_EAST, WallHeight.LOW).with(WallBlock.WALL_HEIGHT_WEST, WallHeight.LOW), -18, 0, -39, start);
        structure.setBlockState(world, Blocks.SANDSTONE_WALL.getDefaultState().with(WallBlock.WATERLOGGED, false).with(WallBlock.UP, true).with(WallBlock.WALL_HEIGHT_NORTH, WallHeight.LOW).with(WallBlock.WALL_HEIGHT_SOUTH, WallHeight.LOW).with(WallBlock.WALL_HEIGHT_EAST, WallHeight.LOW).with(WallBlock.WALL_HEIGHT_WEST, WallHeight.LOW), -18, 0, -35, start);
        structure.setBlockState(world, Blocks.SANDSTONE_SLAB.getDefaultState().with(SlabBlock.TYPE, SlabType.BOTTOM).with(SlabBlock.WATERLOGGED, false), -18, 0, -27, start);
        structure.setBlockState(world, Blocks.BIRCH_LEAVES.getDefaultState().with(LeavesBlock.PERSISTENT, true).with(LeavesBlock.DISTANCE, 1), -18, 0, 8, start);
        structure.setBlockState(world, Blocks.LANTERN.getDefaultState().with(LanternBlock.WATERLOGGED, false).with(LanternBlock.HANGING, false), -18, 1, -35, start);
        structure.setBlockState(world, Blocks.SAND.getDefaultState(), -17, -7, 24, start);
        structure.setBlockState(world, Blocks.STRIPPED_SPRUCE_LOG.getDefaultState(), -17, -6, 16, start);
        structure.setBlockState(world, Blocks.SPRUCE_PLANKS.getDefaultState(), -17, -6, 24, start);
        structure.setBlockState(world, Blocks.SPRUCE_DOOR.getDefaultState().with(DoorBlock.FACING, Direction.WEST).with(DoorBlock.HALF, DoubleBlockHalf.LOWER).with(DoorBlock.HINGE, DoorHingeSide.RIGHT).with(DoorBlock.OPEN, false).with(DoorBlock.POWERED, false), -17, -5, -2, start);
        structure.setBlockState(world, Blocks.BIRCH_LEAVES.getDefaultState().with(LeavesBlock.PERSISTENT, true).with(LeavesBlock.DISTANCE, 1), -17, -5, 16, start);
        structure.setBlockState(world, Blocks.BIRCH_LEAVES.getDefaultState().with(LeavesBlock.PERSISTENT, true).with(LeavesBlock.DISTANCE, 2), -17, -5, 17, start);
        structure.setBlockState(world, Blocks.FURNACE.getDefaultState().with(AbstractFurnaceBlock.FACING, Direction.SOUTH).with(AbstractFurnaceBlock.LIT, false), -17, -5, 19, start);
        structure.setBlockState(world, Blocks.SPRUCE_DOOR.getDefaultState().with(DoorBlock.FACING, Direction.SOUTH).with(DoorBlock.HALF, DoubleBlockHalf.LOWER).with(DoorBlock.HINGE, DoorHingeSide.LEFT).with(DoorBlock.OPEN, false).with(DoorBlock.POWERED, false), -17, -5, 24, start);
        structure.setBlockState(world, Blocks.SPRUCE_FENCE.getDefaultState().with(FourWayBlock.WATERLOGGED, false).with(FourWayBlock.NORTH, false).with(FourWayBlock.SOUTH, true).with(FourWayBlock.EAST, false).with(FourWayBlock.WEST, false), -17, -5, 29, start);
        structure.setBlockState(world, Blocks.SPRUCE_FENCE.getDefaultState().with(FourWayBlock.WATERLOGGED, false).with(FourWayBlock.NORTH, true).with(FourWayBlock.SOUTH, true).with(FourWayBlock.EAST, false).with(FourWayBlock.WEST, false), -17, -5, 30, start);
        structure.setBlockState(world, Blocks.SPRUCE_DOOR.getDefaultState().with(DoorBlock.FACING, Direction.WEST).with(DoorBlock.HALF, DoubleBlockHalf.UPPER).with(DoorBlock.HINGE, DoorHingeSide.RIGHT).with(DoorBlock.OPEN, false).with(DoorBlock.POWERED, false), -17, -4, -2, start);
        structure.setBlockState(world, Blocks.BIRCH_LEAVES.getDefaultState().with(LeavesBlock.PERSISTENT, true).with(LeavesBlock.DISTANCE, 3), -17, -4, 7, start);
        structure.setBlockState(world, Blocks.BIRCH_LEAVES.getDefaultState().with(LeavesBlock.PERSISTENT, true).with(LeavesBlock.DISTANCE, 2), -17, -4, 8, start);
        structure.setBlockState(world, Blocks.BIRCH_LEAVES.getDefaultState().with(LeavesBlock.PERSISTENT, true).with(LeavesBlock.DISTANCE, 3), -17, -4, 9, start);
        structure.setBlockState(world, Blocks.BIRCH_LEAVES.getDefaultState().with(LeavesBlock.PERSISTENT, true).with(LeavesBlock.DISTANCE, 2), -17, -4, 16, start);
        structure.setBlockState(world, Blocks.BIRCH_LEAVES.getDefaultState().with(LeavesBlock.PERSISTENT, true).with(LeavesBlock.DISTANCE, 3), -17, -4, 17, start);
        structure.setBlockState(world, Blocks.SPRUCE_DOOR.getDefaultState().with(DoorBlock.FACING, Direction.SOUTH).with(DoorBlock.HALF, DoubleBlockHalf.UPPER).with(DoorBlock.HINGE, DoorHingeSide.LEFT).with(DoorBlock.OPEN, false).with(DoorBlock.POWERED, false), -17, -4, 24, start);
        structure.setBlockState(world, Blocks.LANTERN.getDefaultState().with(LanternBlock.WATERLOGGED, false).with(LanternBlock.HANGING, true), -17, -3, -8, start);
        structure.setBlockState(world, Blocks.BIRCH_LEAVES.getDefaultState().with(LeavesBlock.PERSISTENT, true).with(LeavesBlock.DISTANCE, 3), -17, -3, 16, start);
        structure.setBlockState(world, Blocks.BIRCH_LEAVES.getDefaultState().with(LeavesBlock.PERSISTENT, true).with(LeavesBlock.DISTANCE, 4), -17, -3, 17, start);
        structure.setBlockState(world, Blocks.CHAIN.getDefaultState().with(ChainBlock.WATERLOGGED, false), -17, -2, -8, start);
        structure.setBlockState(world, Blocks.BIRCH_LEAVES.getDefaultState().with(LeavesBlock.PERSISTENT, true).with(LeavesBlock.DISTANCE, 5), -17, -2, 17, start);
        structure.setBlockState(world, Blocks.CUT_SANDSTONE.getDefaultState(), -17, -1, -4, start);
        structure.setBlockState(world, Blocks.SANDSTONE_SLAB.getDefaultState().with(SlabBlock.TYPE, SlabType.BOTTOM).with(SlabBlock.WATERLOGGED, false), -17, 0, -53, start);
        structure.setBlockState(world, Blocks.SPRUCE_FENCE.getDefaultState().with(FourWayBlock.WATERLOGGED, false).with(FourWayBlock.NORTH, false).with(FourWayBlock.SOUTH, true).with(FourWayBlock.EAST, false).with(FourWayBlock.WEST, false), -17, 0, -52, start);
        structure.setBlockState(world, Blocks.SPRUCE_FENCE.getDefaultState().with(FourWayBlock.WATERLOGGED, false).with(FourWayBlock.NORTH, true).with(FourWayBlock.SOUTH, false).with(FourWayBlock.EAST, false).with(FourWayBlock.WEST, false), -17, 0, -48, start);
        structure.setBlockState(world, Blocks.SANDSTONE_SLAB.getDefaultState().with(SlabBlock.TYPE, SlabType.BOTTOM).with(SlabBlock.WATERLOGGED, false), -17, 0, -47, start);
        structure.setBlockState(world, Blocks.SPRUCE_FENCE.getDefaultState().with(FourWayBlock.WATERLOGGED, false).with(FourWayBlock.NORTH, false).with(FourWayBlock.SOUTH, false).with(FourWayBlock.EAST, true).with(FourWayBlock.WEST, false), -17, 0, -11, start);
        structure.setBlockState(world, Blocks.SANDSTONE_SLAB.getDefaultState().with(SlabBlock.TYPE, SlabType.BOTTOM).with(SlabBlock.WATERLOGGED, false), -17, 0, -4, start);
        structure.setBlockState(world, Blocks.SANDSTONE_WALL.getDefaultState().with(WallBlock.WATERLOGGED, false).with(WallBlock.UP, true).with(WallBlock.WALL_HEIGHT_NORTH, WallHeight.LOW).with(WallBlock.WALL_HEIGHT_SOUTH, WallHeight.LOW).with(WallBlock.WALL_HEIGHT_EAST, WallHeight.LOW).with(WallBlock.WALL_HEIGHT_WEST, WallHeight.LOW), -17, 0, -3, start);
        structure.setBlockState(world, Blocks.SANDSTONE_WALL.getDefaultState().with(WallBlock.WATERLOGGED, false).with(WallBlock.UP, false).with(WallBlock.WALL_HEIGHT_NORTH, WallHeight.LOW).with(WallBlock.WALL_HEIGHT_SOUTH, WallHeight.LOW).with(WallBlock.WALL_HEIGHT_EAST, WallHeight.LOW).with(WallBlock.WALL_HEIGHT_WEST, WallHeight.LOW), -17, 0, -2, start);
        structure.setBlockState(world, Blocks.SANDSTONE_WALL.getDefaultState().with(WallBlock.WATERLOGGED, false).with(WallBlock.UP, true).with(WallBlock.WALL_HEIGHT_NORTH, WallHeight.LOW).with(WallBlock.WALL_HEIGHT_SOUTH, WallHeight.LOW).with(WallBlock.WALL_HEIGHT_EAST, WallHeight.LOW).with(WallBlock.WALL_HEIGHT_WEST, WallHeight.LOW), -17, 0, -1, start);
        structure.setBlockState(world, Blocks.SANDSTONE_SLAB.getDefaultState().with(SlabBlock.TYPE, SlabType.BOTTOM).with(SlabBlock.WATERLOGGED, false), -17, 0, 1, start);
        structure.setBlockState(world, Blocks.SANDSTONE_SLAB.getDefaultState().with(SlabBlock.TYPE, SlabType.BOTTOM).with(SlabBlock.WATERLOGGED, false), -17, 0, 31, start);
        structure.setBlockState(world, Blocks.SANDSTONE_WALL.getDefaultState().with(WallBlock.WATERLOGGED, false).with(WallBlock.UP, true).with(WallBlock.WALL_HEIGHT_NORTH, WallHeight.LOW).with(WallBlock.WALL_HEIGHT_SOUTH, WallHeight.LOW).with(WallBlock.WALL_HEIGHT_EAST, WallHeight.LOW).with(WallBlock.WALL_HEIGHT_WEST, WallHeight.LOW), -17, 0, 35, start);
        structure.setBlockState(world, Blocks.SANDSTONE_WALL.getDefaultState().with(WallBlock.WATERLOGGED, false).with(WallBlock.UP, false).with(WallBlock.WALL_HEIGHT_NORTH, WallHeight.LOW).with(WallBlock.WALL_HEIGHT_SOUTH, WallHeight.LOW).with(WallBlock.WALL_HEIGHT_EAST, WallHeight.LOW).with(WallBlock.WALL_HEIGHT_WEST, WallHeight.LOW), -17, 0, 36, start);
        structure.setBlockState(world, Blocks.SANDSTONE_SLAB.getDefaultState().with(SlabBlock.TYPE, SlabType.BOTTOM).with(SlabBlock.WATERLOGGED, false), -17, 0, 38, start);
        structure.setBlockState(world, Blocks.SANDSTONE_SLAB.getDefaultState().with(SlabBlock.TYPE, SlabType.BOTTOM).with(SlabBlock.WATERLOGGED, false), -17, 5, -46, start);
        structure.setBlockState(world, Blocks.SPRUCE_FENCE.getDefaultState().with(FourWayBlock.WATERLOGGED, false).with(FourWayBlock.NORTH, false).with(FourWayBlock.SOUTH, true).with(FourWayBlock.EAST, false).with(FourWayBlock.WEST, true), -17, 5, -42, start);
        structure.setBlockState(world, Blocks.SPRUCE_FENCE.getDefaultState().with(FourWayBlock.WATERLOGGED, false).with(FourWayBlock.NORTH, true).with(FourWayBlock.SOUTH, false).with(FourWayBlock.EAST, false).with(FourWayBlock.WEST, true), -17, 5, -41, start);
        structure.setBlockState(world, Blocks.SANDSTONE_SLAB.getDefaultState().with(SlabBlock.TYPE, SlabType.BOTTOM).with(SlabBlock.WATERLOGGED, false), -17, 5, -40, start);
        structure.setBlockState(world, Blocks.SANDSTONE_WALL.getDefaultState().with(WallBlock.WATERLOGGED, false).with(WallBlock.UP, true).with(WallBlock.WALL_HEIGHT_NORTH, WallHeight.LOW).with(WallBlock.WALL_HEIGHT_SOUTH, WallHeight.LOW).with(WallBlock.WALL_HEIGHT_EAST, WallHeight.LOW).with(WallBlock.WALL_HEIGHT_WEST, WallHeight.LOW), -16, -5, -61, start);
        structure.setBlockState(world, Blocks.BIRCH_LEAVES.getDefaultState().with(LeavesBlock.PERSISTENT, true).with(LeavesBlock.DISTANCE, 3), -16, -5, -59, start);
        structure.setBlockState(world, Blocks.BIRCH_LEAVES.getDefaultState().with(LeavesBlock.PERSISTENT, true).with(LeavesBlock.DISTANCE, 3), -16, -5, -57, start);
        structure.setBlockState(world, ModBlocks.CHAIR.get().getDefaultState().with(ChairBlock.FACING, Direction.EAST), -16, -5, -39, start);
        structure.setBlockState(world, Blocks.COMPOSTER.getDefaultState().with(ComposterBlock.LEVEL, 0), -16, -5, -28, start);
        structure.setBlockState(world, Index.TABLE_OAK.getDefaultState().with(Table.NE, false).with(Table.NW, true).with(Table.SE, false).with(Table.SW, true), -16, -5, -25, start);
        structure.setBlockState(world, Blocks.BIRCH_LEAVES.getDefaultState().with(LeavesBlock.PERSISTENT, true).with(LeavesBlock.DISTANCE, 2), -16, -5, 16, start);
        structure.setBlockState(world, Blocks.BIRCH_LEAVES.getDefaultState().with(LeavesBlock.PERSISTENT, true).with(LeavesBlock.DISTANCE, 3), -16, -5, 17, start);
        structure.setBlockState(world, Blocks.CAULDRON.getDefaultState().with(CauldronBlock.LEVEL, 3), -16, -5, 19, start);
        structure.setBlockState(world, Blocks.AIR.getDefaultState(), -16, -5, 27, start);
        structure.setBlockState(world, Blocks.SANDSTONE_WALL.getDefaultState().with(WallBlock.WATERLOGGED, false).with(WallBlock.UP, true).with(WallBlock.WALL_HEIGHT_NORTH, WallHeight.LOW).with(WallBlock.WALL_HEIGHT_SOUTH, WallHeight.LOW).with(WallBlock.WALL_HEIGHT_EAST, WallHeight.LOW).with(WallBlock.WALL_HEIGHT_WEST, WallHeight.LOW), -16, -5, 46, start);
        structure.setBlockState(world, Blocks.LANTERN.getDefaultState().with(LanternBlock.WATERLOGGED, false).with(LanternBlock.HANGING, false), -16, -4, -61, start);
        structure.setBlockState(world, Index.CUPBOARD_OAK.getDefaultState().with(Cupboard.FACING, Direction.SOUTH).with(Cupboard.HALF, DoubleBlockHalf.LOWER).with(Cupboard.MIRROR, false).with(Cupboard.WATERLOGGED, false), -16, -4, -46, start);
        structure.setBlockState(world, Blocks.BIRCH_LEAVES.getDefaultState().with(LeavesBlock.PERSISTENT, true).with(LeavesBlock.DISTANCE, 3), -16, -4, 16, start);
        structure.setBlockState(world, Index.CUPBOARD_OAK.getDefaultState().with(Cupboard.FACING, Direction.NORTH).with(Cupboard.HALF, DoubleBlockHalf.LOWER).with(Cupboard.MIRROR, false).with(Cupboard.WATERLOGGED, false), -16, -4, 37, start);
        structure.setBlockState(world, Blocks.LANTERN.getDefaultState().with(LanternBlock.WATERLOGGED, false).with(LanternBlock.HANGING, false), -16, -4, 46, start);
        structure.setBlockState(world, Index.CUPBOARD_OAK.getDefaultState().with(Cupboard.FACING, Direction.SOUTH).with(Cupboard.HALF, DoubleBlockHalf.UPPER).with(Cupboard.MIRROR, false).with(Cupboard.WATERLOGGED, false), -16, -3, -46, start);
        structure.setBlockState(world, Blocks.LANTERN.getDefaultState().with(LanternBlock.WATERLOGGED, false).with(LanternBlock.HANGING, true), -16, -3, -28, start);
        structure.setBlockState(world, Index.CUPBOARD_OAK.getDefaultState().with(Cupboard.FACING, Direction.NORTH).with(Cupboard.HALF, DoubleBlockHalf.UPPER).with(Cupboard.MIRROR, false).with(Cupboard.WATERLOGGED, false), -16, -3, 37, start);
        structure.setBlockState(world, Blocks.SPRUCE_FENCE.getDefaultState().with(FourWayBlock.WATERLOGGED, false).with(FourWayBlock.NORTH, false).with(FourWayBlock.SOUTH, true).with(FourWayBlock.EAST, true).with(FourWayBlock.WEST, false), -16, -2, -28, start);
        structure.setBlockState(world, Blocks.LANTERN.getDefaultState().with(LanternBlock.WATERLOGGED, false).with(LanternBlock.HANGING, true), -16, -2, 21, start);
        structure.setBlockState(world, Blocks.SPRUCE_SLAB.getDefaultState().with(SlabBlock.TYPE, SlabType.DOUBLE).with(SlabBlock.WATERLOGGED, false), -16, -1, -26, start);
        structure.setBlockState(world, Blocks.SPRUCE_SLAB.getDefaultState().with(SlabBlock.TYPE, SlabType.DOUBLE).with(SlabBlock.WATERLOGGED, false), -16, -1, -22, start);
        structure.setBlockState(world, Blocks.SPRUCE_SLAB.getDefaultState().with(SlabBlock.TYPE, SlabType.BOTTOM).with(SlabBlock.WATERLOGGED, false), -16, -1, -14, start);
        structure.setBlockState(world, Blocks.SPRUCE_FENCE.getDefaultState().with(FourWayBlock.WATERLOGGED, false).with(FourWayBlock.NORTH, false).with(FourWayBlock.SOUTH, false).with(FourWayBlock.EAST, true).with(FourWayBlock.WEST, false), -16, 0, -53, start);
        structure.setBlockState(world, Index.COUNTER_OAK_ANDESITE.getDefaultState().with(Counter.FACING, Direction.EAST).with(Counter.WATERLOGGED, false), -16, 0, -45, start);
        structure.setBlockState(world, Blocks.CAULDRON.getDefaultState().with(CauldronBlock.LEVEL, 0), -16, 0, -44, start);
        structure.setBlockState(world, Blocks.FURNACE.getDefaultState().with(AbstractFurnaceBlock.FACING, Direction.EAST).with(AbstractFurnaceBlock.LIT, false), -16, 0, -43, start);
        structure.setBlockState(world, Blocks.CRAFTING_TABLE.getDefaultState(), -16, 0, -42, start);
        structure.setBlockState(world, Index.COUNTER_OAK_ANDESITE.getDefaultState().with(Counter.FACING, Direction.EAST).with(Counter.WATERLOGGED, false), -16, 0, -41, start);
        structure.setBlockState(world, Blocks.SANDSTONE_SLAB.getDefaultState().with(SlabBlock.TYPE, SlabType.BOTTOM).with(SlabBlock.WATERLOGGED, false), -16, 0, -12, start);
        structure.setBlockState(world, Blocks.SPRUCE_FENCE.getDefaultState().with(FourWayBlock.WATERLOGGED, false).with(FourWayBlock.NORTH, false).with(FourWayBlock.SOUTH, false).with(FourWayBlock.EAST, true).with(FourWayBlock.WEST, true), -16, 0, -11, start);
        structure.setBlockState(world, Blocks.SANDSTONE_WALL.getDefaultState().with(WallBlock.WATERLOGGED, false).with(WallBlock.UP, true).with(WallBlock.WALL_HEIGHT_NORTH, WallHeight.LOW).with(WallBlock.WALL_HEIGHT_SOUTH, WallHeight.LOW).with(WallBlock.WALL_HEIGHT_EAST, WallHeight.LOW).with(WallBlock.WALL_HEIGHT_WEST, WallHeight.LOW), -16, 0, -4, start);
        structure.setBlockState(world, Blocks.SANDSTONE_WALL.getDefaultState().with(WallBlock.WATERLOGGED, false).with(WallBlock.UP, true).with(WallBlock.WALL_HEIGHT_NORTH, WallHeight.LOW).with(WallBlock.WALL_HEIGHT_SOUTH, WallHeight.LOW).with(WallBlock.WALL_HEIGHT_EAST, WallHeight.LOW).with(WallBlock.WALL_HEIGHT_WEST, WallHeight.LOW), -16, 0, 31, start);
        structure.setBlockState(world, Blocks.SANDSTONE_WALL.getDefaultState().with(WallBlock.WATERLOGGED, false).with(WallBlock.UP, true).with(WallBlock.WALL_HEIGHT_NORTH, WallHeight.LOW).with(WallBlock.WALL_HEIGHT_SOUTH, WallHeight.LOW).with(WallBlock.WALL_HEIGHT_EAST, WallHeight.LOW).with(WallBlock.WALL_HEIGHT_WEST, WallHeight.LOW), -16, 0, 38, start);
        structure.setBlockState(world, Index.SMOOTH_SANDSTONE_VERTICAL_SLAB.getDefaultState().with(VerticalSlab.TYPE, VerticalSlabState.WEST).with(VerticalSlab.WATERLOGGED, false), -16, 2, -43, start);
        structure.setBlockState(world, Blocks.SPRUCE_FENCE.getDefaultState().with(FourWayBlock.WATERLOGGED, false).with(FourWayBlock.NORTH, false).with(FourWayBlock.SOUTH, false).with(FourWayBlock.EAST, true).with(FourWayBlock.WEST, false), -16, 5, -40, start);
        structure.setBlockState(world, Blocks.STONE.getDefaultState(), -15, -11, 30, start);
        structure.setBlockState(world, Blocks.STONE.getDefaultState(), -15, -11, 58, start);
        structure.setBlockState(world, Blocks.STRIPPED_SPRUCE_LOG.getDefaultState(), -15, -6, -58, start);
        structure.setBlockState(world, Blocks.SPRUCE_FENCE.getDefaultState().with(FourWayBlock.WATERLOGGED, false).with(FourWayBlock.NORTH, false).with(FourWayBlock.SOUTH, true).with(FourWayBlock.EAST, true).with(FourWayBlock.WEST, false), -15, -5, -65, start);
        structure.setBlockState(world, Blocks.SPRUCE_FENCE.getDefaultState().with(FourWayBlock.WATERLOGGED, false).with(FourWayBlock.NORTH, true).with(FourWayBlock.SOUTH, false).with(FourWayBlock.EAST, false).with(FourWayBlock.WEST, false), -15, -5, -64, start);
        structure.setBlockState(world, Blocks.BIRCH_LEAVES.getDefaultState().with(LeavesBlock.PERSISTENT, true).with(LeavesBlock.DISTANCE, 1), -15, -5, -58, start);
        structure.setBlockState(world, Blocks.BIRCH_LEAVES.getDefaultState().with(LeavesBlock.PERSISTENT, true).with(LeavesBlock.DISTANCE, 2), -15, -5, -57, start);
        structure.setBlockState(world, Blocks.SMOOTH_SANDSTONE.getDefaultState(), -15, -5, -43, start);
        structure.setBlockState(world, ModBlocks.CHAIR.get().getDefaultState().with(ChairBlock.FACING, Direction.SOUTH), -15, -5, -40, start);
        structure.setBlockState(world, Index.TABLE_OAK.getDefaultState().with(Table.NE, true).with(Table.NW, true).with(Table.SE, true).with(Table.SW, true), -15, -5, -39, start);
        structure.setBlockState(world, ModBlocks.CHAIR.get().getDefaultState().with(ChairBlock.FACING, Direction.NORTH), -15, -5, -38, start);
        structure.setBlockState(world, Blocks.AIR.getDefaultState(), -15, -5, -26, start);
        structure.setBlockState(world, Index.TABLE_OAK.getDefaultState().with(Table.NE, false).with(Table.NW, false).with(Table.SE, false).with(Table.SW, false), -15, -5, -25, start);
        structure.setBlockState(world, Blocks.CRAFTING_TABLE.getDefaultState(), -15, -5, 19, start);
        structure.setBlockState(world, Blocks.AIR.getDefaultState(), -15, -5, 29, start);
        structure.setBlockState(world, Blocks.SPRUCE_DOOR.getDefaultState().with(DoorBlock.FACING, Direction.NORTH).with(DoorBlock.HALF, DoubleBlockHalf.LOWER).with(DoorBlock.HINGE, DoorHingeSide.LEFT).with(DoorBlock.OPEN, false).with(DoorBlock.POWERED, false), -15, -5, 31, start);
        structure.setBlockState(world, Blocks.SMOOTH_SANDSTONE_SLAB.getDefaultState().with(SlabBlock.TYPE, SlabType.TOP).with(SlabBlock.WATERLOGGED, false), -15, -5, 35, start);
        structure.setBlockState(world, Blocks.SPRUCE_FENCE.getDefaultState().with(FourWayBlock.WATERLOGGED, false).with(FourWayBlock.NORTH, true).with(FourWayBlock.SOUTH, true).with(FourWayBlock.EAST, true).with(FourWayBlock.WEST, false), -15, -5, 39, start);
        structure.setBlockState(world, Blocks.SPRUCE_FENCE.getDefaultState().with(FourWayBlock.WATERLOGGED, false).with(FourWayBlock.NORTH, true).with(FourWayBlock.SOUTH, false).with(FourWayBlock.EAST, false).with(FourWayBlock.WEST, false), -15, -5, 40, start);
        structure.setBlockState(world, Blocks.BIRCH_LEAVES.getDefaultState().with(LeavesBlock.PERSISTENT, true).with(LeavesBlock.DISTANCE, 2), -15, -4, -58, start);
        structure.setBlockState(world, Blocks.BIRCH_LEAVES.getDefaultState().with(LeavesBlock.PERSISTENT, true).with(LeavesBlock.DISTANCE, 3), -15, -4, -57, start);
        structure.setBlockState(world, Blocks.AIR.getDefaultState(), -15, -4, -25, start);
        structure.setBlockState(world, Blocks.SPRUCE_DOOR.getDefaultState().with(DoorBlock.FACING, Direction.NORTH).with(DoorBlock.HALF, DoubleBlockHalf.UPPER).with(DoorBlock.HINGE, DoorHingeSide.LEFT).with(DoorBlock.OPEN, false).with(DoorBlock.POWERED, false), -15, -4, 31, start);
        structure.setBlockState(world, Blocks.BIRCH_LEAVES.getDefaultState().with(LeavesBlock.PERSISTENT, true).with(LeavesBlock.DISTANCE, 3), -15, -3, -58, start);
        structure.setBlockState(world, Blocks.SPRUCE_FENCE.getDefaultState().with(FourWayBlock.WATERLOGGED, false).with(FourWayBlock.NORTH, false).with(FourWayBlock.SOUTH, true).with(FourWayBlock.EAST, true).with(FourWayBlock.WEST, false), -15, -2, -55, start);
        structure.setBlockState(world, Blocks.SPRUCE_FENCE.getDefaultState().with(FourWayBlock.WATERLOGGED, false).with(FourWayBlock.NORTH, true).with(FourWayBlock.SOUTH, true).with(FourWayBlock.EAST, true).with(FourWayBlock.WEST, false), -15, -2, -54, start);
        structure.setBlockState(world, Blocks.BARREL.getDefaultState().with(BarrelBlock.PROPERTY_FACING, Direction.SOUTH).with(BarrelBlock.PROPERTY_OPEN, false), -15, 0, -39, start);
        structure.setBlockState(world, Blocks.SPRUCE_FENCE.getDefaultState().with(FourWayBlock.WATERLOGGED, false).with(FourWayBlock.NORTH, false).with(FourWayBlock.SOUTH, false).with(FourWayBlock.EAST, false).with(FourWayBlock.WEST, true), -15, 0, -11, start);
        structure.setBlockState(world, Blocks.SANDSTONE_WALL.getDefaultState().with(WallBlock.WATERLOGGED, false).with(WallBlock.UP, false).with(WallBlock.WALL_HEIGHT_NORTH, WallHeight.LOW).with(WallBlock.WALL_HEIGHT_SOUTH, WallHeight.LOW).with(WallBlock.WALL_HEIGHT_EAST, WallHeight.LOW).with(WallBlock.WALL_HEIGHT_WEST, WallHeight.LOW), -15, 0, -4, start);
        structure.setBlockState(world, Blocks.SANDSTONE_SLAB.getDefaultState().with(SlabBlock.TYPE, SlabType.BOTTOM).with(SlabBlock.WATERLOGGED, false), -15, 0, 6, start);
        structure.setBlockState(world, Blocks.SANDSTONE_SLAB.getDefaultState().with(SlabBlock.TYPE, SlabType.BOTTOM).with(SlabBlock.WATERLOGGED, false), -15, 0, 12, start);
        structure.setBlockState(world, Blocks.SANDSTONE_WALL.getDefaultState().with(WallBlock.WATERLOGGED, false).with(WallBlock.UP, false).with(WallBlock.WALL_HEIGHT_NORTH, WallHeight.LOW).with(WallBlock.WALL_HEIGHT_SOUTH, WallHeight.LOW).with(WallBlock.WALL_HEIGHT_EAST, WallHeight.LOW).with(WallBlock.WALL_HEIGHT_WEST, WallHeight.LOW), -15, 0, 31, start);
        structure.setBlockState(world, Blocks.SANDSTONE_WALL.getDefaultState().with(WallBlock.WATERLOGGED, false).with(WallBlock.UP, false).with(WallBlock.WALL_HEIGHT_NORTH, WallHeight.LOW).with(WallBlock.WALL_HEIGHT_SOUTH, WallHeight.LOW).with(WallBlock.WALL_HEIGHT_EAST, WallHeight.LOW).with(WallBlock.WALL_HEIGHT_WEST, WallHeight.LOW), -15, 0, 38, start);
        structure.setBlockState(world, Blocks.LANTERN.getDefaultState().with(LanternBlock.WATERLOGGED, false).with(LanternBlock.HANGING, true), -15, 2, -35, start);
        structure.setBlockState(world, Blocks.SPRUCE_FENCE.getDefaultState().with(FourWayBlock.WATERLOGGED, false).with(FourWayBlock.NORTH, true).with(FourWayBlock.SOUTH, true).with(FourWayBlock.EAST, true).with(FourWayBlock.WEST, false), -15, 3, -39, start);
        structure.setBlockState(world, Blocks.SPRUCE_FENCE.getDefaultState().with(FourWayBlock.WATERLOGGED, false).with(FourWayBlock.NORTH, true).with(FourWayBlock.SOUTH, false).with(FourWayBlock.EAST, true).with(FourWayBlock.WEST, false), -15, 3, -38, start);
        structure.setBlockState(world, Blocks.OAK_TRAPDOOR.getDefaultState().with(HorizontalBlock.HORIZONTAL_FACING, Direction.NORTH).with(TrapDoorBlock.HALF, Half.BOTTOM).with(TrapDoorBlock.WATERLOGGED, false).with(TrapDoorBlock.POWERED, false).with(TrapDoorBlock.OPEN, false), -15, 4, -43, start);
        structure.setBlockState(world, Blocks.SPRUCE_FENCE.getDefaultState().with(FourWayBlock.WATERLOGGED, false).with(FourWayBlock.NORTH, false).with(FourWayBlock.SOUTH, false).with(FourWayBlock.EAST, true).with(FourWayBlock.WEST, true), -15, 5, -40, start);
        structure.setBlockState(world, Blocks.SANDSTONE_SLAB.getDefaultState().with(SlabBlock.TYPE, SlabType.BOTTOM).with(SlabBlock.WATERLOGGED, false), -15, 5, -32, start);
        structure.setBlockState(world, Blocks.SANDSTONE_SLAB.getDefaultState().with(SlabBlock.TYPE, SlabType.BOTTOM).with(SlabBlock.WATERLOGGED, false), -15, 5, -27, start);
        structure.setBlockState(world, Blocks.SPRUCE_FENCE.getDefaultState().with(FourWayBlock.WATERLOGGED, false).with(FourWayBlock.NORTH, false).with(FourWayBlock.SOUTH, true).with(FourWayBlock.EAST, false).with(FourWayBlock.WEST, false), -14, -5, -66, start);
        structure.setBlockState(world, Blocks.SPRUCE_FENCE.getDefaultState().with(FourWayBlock.WATERLOGGED, false).with(FourWayBlock.NORTH, true).with(FourWayBlock.SOUTH, false).with(FourWayBlock.EAST, false).with(FourWayBlock.WEST, true), -14, -5, -65, start);
        structure.setBlockState(world, Blocks.BIRCH_LEAVES.getDefaultState().with(LeavesBlock.PERSISTENT, true).with(LeavesBlock.DISTANCE, 3), -14, -5, -59, start);
        structure.setBlockState(world, Blocks.BIRCH_LEAVES.getDefaultState().with(LeavesBlock.PERSISTENT, true).with(LeavesBlock.DISTANCE, 2), -14, -5, -58, start);
        structure.setBlockState(world, ModBlocks.CHAIR.get().getDefaultState().with(ChairBlock.FACING, Direction.SOUTH), -14, -5, -51, start);
        structure.setBlockState(world, Index.TABLE_OAK.getDefaultState().with(Table.NE, true).with(Table.NW, true).with(Table.SE, true).with(Table.SW, true), -14, -5, -50, start);
        structure.setBlockState(world, ModBlocks.CHAIR.get().getDefaultState().with(ChairBlock.FACING, Direction.NORTH), -14, -5, -49, start);
        structure.setBlockState(world, Blocks.CRAFTING_TABLE.getDefaultState(), -14, -5, -46, start);
        structure.setBlockState(world, Blocks.SMOOTH_SANDSTONE_STAIRS.getDefaultState().with(StairsBlock.FACING, Direction.WEST).with(StairsBlock.WATERLOGGED, false).with(StairsBlock.SHAPE, StairsShape.STRAIGHT).with(StairsBlock.HALF, Half.TOP), -14, -5, -43, start);
        structure.setBlockState(world, ModBlocks.CHAIR.get().getDefaultState().with(ChairBlock.FACING, Direction.WEST), -14, -5, -39, start);
        structure.setBlockState(world, Index.TABLE_OAK.getDefaultState().with(Table.NE, true).with(Table.NW, false).with(Table.SE, true).with(Table.SW, false), -14, -5, -25, start);
        structure.setBlockState(world, Blocks.SANDSTONE.getDefaultState(), -14, -5, 6, start);
        structure.setBlockState(world, Index.COUNTER_OAK_ANDESITE.getDefaultState().with(Counter.FACING, Direction.NORTH).with(Counter.WATERLOGGED, false), -14, -5, 11, start);
        structure.setBlockState(world, Index.COUNTER_OAK_ANDESITE.getDefaultState().with(Counter.FACING, Direction.SOUTH).with(Counter.WATERLOGGED, false), -14, -5, 19, start);
        structure.setBlockState(world, Blocks.SPRUCE_FENCE.getDefaultState().with(FourWayBlock.WATERLOGGED, false).with(FourWayBlock.NORTH, false).with(FourWayBlock.SOUTH, false).with(FourWayBlock.EAST, true).with(FourWayBlock.WEST, false), -14, -5, 27, start);
        structure.setBlockState(world, Blocks.SMOOTH_SANDSTONE_STAIRS.getDefaultState().with(StairsBlock.FACING, Direction.EAST).with(StairsBlock.WATERLOGGED, false).with(StairsBlock.SHAPE, StairsShape.STRAIGHT).with(StairsBlock.HALF, Half.TOP), -14, -5, 35, start);
        structure.setBlockState(world, Blocks.CRAFTING_TABLE.getDefaultState(), -14, -5, 37, start);
        structure.setBlockState(world, Blocks.BARREL.getDefaultState().with(BarrelBlock.PROPERTY_FACING, Direction.UP).with(BarrelBlock.PROPERTY_OPEN, false), -14, -5, 39, start);
        structure.setBlockState(world, Blocks.BIRCH_LEAVES.getDefaultState().with(LeavesBlock.PERSISTENT, true).with(LeavesBlock.DISTANCE, 3), -14, -4, -58, start);
        structure.setBlockState(world, Blocks.SPRUCE_TRAPDOOR.getDefaultState().with(HorizontalBlock.HORIZONTAL_FACING, Direction.SOUTH).with(TrapDoorBlock.HALF, Half.TOP).with(TrapDoorBlock.WATERLOGGED, false).with(TrapDoorBlock.POWERED, false).with(TrapDoorBlock.OPEN, false), -14, -4, 19, start);
        structure.setBlockState(world, Blocks.LANTERN.getDefaultState().with(LanternBlock.WATERLOGGED, false).with(LanternBlock.HANGING, false), -14, -4, 27, start);
        structure.setBlockState(world, Blocks.LANTERN.getDefaultState().with(LanternBlock.WATERLOGGED, false).with(LanternBlock.HANGING, true), -14, -3, -55, start);
        structure.setBlockState(world, Index.CUPBOARD_OAK.getDefaultState().with(Cupboard.FACING, Direction.SOUTH).with(Cupboard.HALF, DoubleBlockHalf.LOWER).with(Cupboard.MIRROR, false).with(Cupboard.WATERLOGGED, false), -14, -3, 19, start);
        structure.setBlockState(world, Blocks.LANTERN.getDefaultState().with(LanternBlock.WATERLOGGED, false).with(LanternBlock.HANGING, true), -14, -2, -50, start);
        structure.setBlockState(world, Blocks.LANTERN.getDefaultState().with(LanternBlock.WATERLOGGED, false).with(LanternBlock.HANGING, true), -14, -2, -42, start);
        structure.setBlockState(world, Index.CUPBOARD_OAK.getDefaultState().with(Cupboard.FACING, Direction.SOUTH).with(Cupboard.HALF, DoubleBlockHalf.UPPER).with(Cupboard.MIRROR, false).with(Cupboard.WATERLOGGED, false), -14, -2, 19, start);
        structure.setBlockState(world, Blocks.SANDSTONE.getDefaultState(), -14, -1, -35, start);
        structure.setBlockState(world, Blocks.SMOOTH_SANDSTONE_SLAB.getDefaultState().with(SlabBlock.TYPE, SlabType.TOP).with(SlabBlock.WATERLOGGED, false), -14, 0, -44, start);
        structure.setBlockState(world, Blocks.SMOOTH_SANDSTONE_STAIRS.getDefaultState().with(StairsBlock.FACING, Direction.SOUTH).with(StairsBlock.WATERLOGGED, false).with(StairsBlock.SHAPE, StairsShape.STRAIGHT).with(StairsBlock.HALF, Half.TOP), -14, 0, -43, start);
        structure.setBlockState(world, Blocks.SMOOTH_SANDSTONE.getDefaultState(), -14, 0, -42, start);
        structure.setBlockState(world, Blocks.COMPOSTER.getDefaultState().with(ComposterBlock.LEVEL, 0), -14, 0, -35, start);
        structure.setBlockState(world, Index.SOFA_GRAY.getDefaultState().with(Sofa.STATE, SofaState.LEFT), -14, 0, -30, start);
        structure.setBlockState(world, Index.SOFA_GRAY.getDefaultState().with(Sofa.STATE, SofaState.RIGHT), -14, 0, -29, start);
        structure.setBlockState(world, Blocks.BIRCH_LEAVES.getDefaultState().with(LeavesBlock.PERSISTENT, true).with(LeavesBlock.DISTANCE, 2), -14, 0, -14, start);
        structure.setBlockState(world, Blocks.SANDSTONE_SLAB.getDefaultState().with(SlabBlock.TYPE, SlabType.BOTTOM).with(SlabBlock.WATERLOGGED, false), -14, 0, -11, start);
        structure.setBlockState(world, Blocks.SPRUCE_FENCE.getDefaultState().with(FourWayBlock.WATERLOGGED, false).with(FourWayBlock.NORTH, false).with(FourWayBlock.SOUTH, true).with(FourWayBlock.EAST, true).with(FourWayBlock.WEST, false), -14, 0, -10, start);
        structure.setBlockState(world, Blocks.SPRUCE_FENCE.getDefaultState().with(FourWayBlock.WATERLOGGED, false).with(FourWayBlock.NORTH, true).with(FourWayBlock.SOUTH, true).with(FourWayBlock.EAST, true).with(FourWayBlock.WEST, false), -14, 0, -9, start);
        structure.setBlockState(world, Blocks.SPRUCE_FENCE.getDefaultState().with(FourWayBlock.WATERLOGGED, false).with(FourWayBlock.NORTH, true).with(FourWayBlock.SOUTH, false).with(FourWayBlock.EAST, true).with(FourWayBlock.WEST, false), -14, 0, -8, start);
        structure.setBlockState(world, Blocks.SANDSTONE_SLAB.getDefaultState().with(SlabBlock.TYPE, SlabType.BOTTOM).with(SlabBlock.WATERLOGGED, false), -14, 0, -5, start);
        structure.setBlockState(world, Blocks.SANDSTONE_WALL.getDefaultState().with(WallBlock.WATERLOGGED, false).with(WallBlock.UP, true).with(WallBlock.WALL_HEIGHT_NORTH, WallHeight.LOW).with(WallBlock.WALL_HEIGHT_SOUTH, WallHeight.LOW).with(WallBlock.WALL_HEIGHT_EAST, WallHeight.LOW).with(WallBlock.WALL_HEIGHT_WEST, WallHeight.LOW), -14, 0, -4, start);
        structure.setBlockState(world, Blocks.SANDSTONE_WALL.getDefaultState().with(WallBlock.WATERLOGGED, false).with(WallBlock.UP, true).with(WallBlock.WALL_HEIGHT_NORTH, WallHeight.LOW).with(WallBlock.WALL_HEIGHT_SOUTH, WallHeight.LOW).with(WallBlock.WALL_HEIGHT_EAST, WallHeight.LOW).with(WallBlock.WALL_HEIGHT_WEST, WallHeight.LOW), -14, 0, 31, start);
        structure.setBlockState(world, Blocks.SANDSTONE_WALL.getDefaultState().with(WallBlock.WATERLOGGED, false).with(WallBlock.UP, true).with(WallBlock.WALL_HEIGHT_NORTH, WallHeight.LOW).with(WallBlock.WALL_HEIGHT_SOUTH, WallHeight.LOW).with(WallBlock.WALL_HEIGHT_EAST, WallHeight.LOW).with(WallBlock.WALL_HEIGHT_WEST, WallHeight.LOW), -14, 0, 38, start);
        structure.setBlockState(world, Blocks.SPRUCE_FENCE.getDefaultState().with(FourWayBlock.WATERLOGGED, false).with(FourWayBlock.NORTH, false).with(FourWayBlock.SOUTH, false).with(FourWayBlock.EAST, true).with(FourWayBlock.WEST, false), -14, 5, -46, start);
        structure.setBlockState(world, Blocks.SPRUCE_FENCE.getDefaultState().with(FourWayBlock.WATERLOGGED, false).with(FourWayBlock.NORTH, false).with(FourWayBlock.SOUTH, false).with(FourWayBlock.EAST, false).with(FourWayBlock.WEST, true), -14, 5, -40, start);
        structure.setBlockState(world, Blocks.SPRUCE_FENCE.getDefaultState().with(FourWayBlock.WATERLOGGED, false).with(FourWayBlock.NORTH, false).with(FourWayBlock.SOUTH, false).with(FourWayBlock.EAST, true).with(FourWayBlock.WEST, false), -14, 5, -32, start);
        structure.setBlockState(world, Blocks.STONE.getDefaultState(), -13, -11, 28, start);
        structure.setBlockState(world, Blocks.AIR.getDefaultState(), -13, -5, -55, start);
        structure.setBlockState(world, Blocks.SPRUCE_DOOR.getDefaultState().with(DoorBlock.FACING, Direction.NORTH).with(DoorBlock.HALF, DoubleBlockHalf.LOWER).with(DoorBlock.HINGE, DoorHingeSide.LEFT).with(DoorBlock.OPEN, false).with(DoorBlock.POWERED, false), -13, -5, -53, start);
        structure.setBlockState(world, ModBlocks.CHAIR.get().getDefaultState().with(ChairBlock.FACING, Direction.WEST), -13, -5, -50, start);
        structure.setBlockState(world, Blocks.FURNACE.getDefaultState().with(AbstractFurnaceBlock.FACING, Direction.SOUTH).with(AbstractFurnaceBlock.LIT, false), -13, -5, -46, start);
        structure.setBlockState(world, Blocks.SMOOTH_SANDSTONE_STAIRS.getDefaultState().with(StairsBlock.FACING, Direction.EAST).with(StairsBlock.WATERLOGGED, false).with(StairsBlock.SHAPE, StairsShape.STRAIGHT).with(StairsBlock.HALF, Half.TOP), -13, -5, -43, start);
        structure.setBlockState(world, Blocks.AIR.getDefaultState(), -13, -5, 2, start);
        structure.setBlockState(world, Blocks.SPRUCE_DOOR.getDefaultState().with(DoorBlock.FACING, Direction.NORTH).with(DoorBlock.HALF, DoubleBlockHalf.LOWER).with(DoorBlock.HINGE, DoorHingeSide.LEFT).with(DoorBlock.OPEN, false).with(DoorBlock.POWERED, false), -13, -5, 6, start);
        structure.setBlockState(world, Blocks.CAULDRON.getDefaultState().with(CauldronBlock.LEVEL, 0), -13, -5, 11, start);
        structure.setBlockState(world, Blocks.SANDSTONE_WALL.getDefaultState().with(WallBlock.WATERLOGGED, false).with(WallBlock.UP, true).with(WallBlock.WALL_HEIGHT_NORTH, WallHeight.LOW).with(WallBlock.WALL_HEIGHT_SOUTH, WallHeight.LOW).with(WallBlock.WALL_HEIGHT_EAST, WallHeight.LOW).with(WallBlock.WALL_HEIGHT_WEST, WallHeight.LOW), -13, -5, 13, start);
        structure.setBlockState(world, Blocks.SPRUCE_FENCE.getDefaultState().with(FourWayBlock.WATERLOGGED, false).with(FourWayBlock.NORTH, false).with(FourWayBlock.SOUTH, false).with(FourWayBlock.EAST, false).with(FourWayBlock.WEST, true), -13, -5, 27, start);
        structure.setBlockState(world, Blocks.SMOOTH_SANDSTONE.getDefaultState(), -13, -5, 35, start);
        structure.setBlockState(world, Blocks.FURNACE.getDefaultState().with(AbstractFurnaceBlock.FACING, Direction.NORTH).with(AbstractFurnaceBlock.LIT, false), -13, -5, 37, start);
        structure.setBlockState(world, Blocks.COMPOSTER.getDefaultState().with(ComposterBlock.LEVEL, 0), -13, -5, 40, start);
        structure.setBlockState(world, Blocks.SPRUCE_DOOR.getDefaultState().with(DoorBlock.FACING, Direction.NORTH).with(DoorBlock.HALF, DoubleBlockHalf.UPPER).with(DoorBlock.HINGE, DoorHingeSide.LEFT).with(DoorBlock.OPEN, false).with(DoorBlock.POWERED, false), -13, -4, -53, start);
        structure.setBlockState(world, Blocks.SPRUCE_DOOR.getDefaultState().with(DoorBlock.FACING, Direction.NORTH).with(DoorBlock.HALF, DoubleBlockHalf.UPPER).with(DoorBlock.HINGE, DoorHingeSide.LEFT).with(DoorBlock.OPEN, false).with(DoorBlock.POWERED, false), -13, -4, 6, start);
        structure.setBlockState(world, Blocks.LANTERN.getDefaultState().with(LanternBlock.WATERLOGGED, false).with(LanternBlock.HANGING, false), -13, -4, 13, start);
        structure.setBlockState(world, Blocks.LANTERN.getDefaultState().with(LanternBlock.WATERLOGGED, false).with(LanternBlock.HANGING, true), -13, -3, 41, start);
        structure.setBlockState(world, Blocks.SMOOTH_SANDSTONE_STAIRS.getDefaultState().with(StairsBlock.FACING, Direction.NORTH).with(StairsBlock.WATERLOGGED, false).with(StairsBlock.SHAPE, StairsShape.STRAIGHT).with(StairsBlock.HALF, Half.TOP), -13, -2, 20, start);
        structure.setBlockState(world, Blocks.SMOOTH_SANDSTONE_STAIRS.getDefaultState().with(StairsBlock.FACING, Direction.SOUTH).with(StairsBlock.WATERLOGGED, false).with(StairsBlock.SHAPE, StairsShape.STRAIGHT).with(StairsBlock.HALF, Half.TOP), -13, -2, 22, start);
        structure.setBlockState(world, Blocks.CUT_SANDSTONE.getDefaultState(), -13, -1, 18, start);
        structure.setBlockState(world, Blocks.CUT_SANDSTONE.getDefaultState(), -13, -1, 24, start);
        structure.setBlockState(world, Blocks.CUT_SANDSTONE.getDefaultState(), -13, -1, 31, start);
        structure.setBlockState(world, Blocks.SPRUCE_DOOR.getDefaultState().with(DoorBlock.FACING, Direction.SOUTH).with(DoorBlock.HALF, DoubleBlockHalf.LOWER).with(DoorBlock.HINGE, DoorHingeSide.LEFT).with(DoorBlock.OPEN, false).with(DoorBlock.POWERED, false), -13, 0, -40, start);
        structure.setBlockState(world, Blocks.SANDSTONE_SLAB.getDefaultState().with(SlabBlock.TYPE, SlabType.BOTTOM).with(SlabBlock.WATERLOGGED, false), -13, 0, 18, start);
        structure.setBlockState(world, Blocks.SANDSTONE_SLAB.getDefaultState().with(SlabBlock.TYPE, SlabType.BOTTOM).with(SlabBlock.WATERLOGGED, false), -13, 0, 24, start);
        structure.setBlockState(world, Blocks.SANDSTONE_SLAB.getDefaultState().with(SlabBlock.TYPE, SlabType.BOTTOM).with(SlabBlock.WATERLOGGED, false), -13, 0, 31, start);
        structure.setBlockState(world, Blocks.SANDSTONE_WALL.getDefaultState().with(WallBlock.WATERLOGGED, false).with(WallBlock.UP, true).with(WallBlock.WALL_HEIGHT_NORTH, WallHeight.LOW).with(WallBlock.WALL_HEIGHT_SOUTH, WallHeight.LOW).with(WallBlock.WALL_HEIGHT_EAST, WallHeight.LOW).with(WallBlock.WALL_HEIGHT_WEST, WallHeight.LOW), -13, 0, 35, start);
        structure.setBlockState(world, Blocks.SANDSTONE_WALL.getDefaultState().with(WallBlock.WATERLOGGED, false).with(WallBlock.UP, false).with(WallBlock.WALL_HEIGHT_NORTH, WallHeight.LOW).with(WallBlock.WALL_HEIGHT_SOUTH, WallHeight.LOW).with(WallBlock.WALL_HEIGHT_EAST, WallHeight.LOW).with(WallBlock.WALL_HEIGHT_WEST, WallHeight.LOW), -13, 0, 36, start);
        structure.setBlockState(world, Blocks.SANDSTONE_WALL.getDefaultState().with(WallBlock.WATERLOGGED, false).with(WallBlock.UP, true).with(WallBlock.WALL_HEIGHT_NORTH, WallHeight.LOW).with(WallBlock.WALL_HEIGHT_SOUTH, WallHeight.LOW).with(WallBlock.WALL_HEIGHT_EAST, WallHeight.LOW).with(WallBlock.WALL_HEIGHT_WEST, WallHeight.LOW), -13, 0, 37, start);
        structure.setBlockState(world, Blocks.SANDSTONE_SLAB.getDefaultState().with(SlabBlock.TYPE, SlabType.BOTTOM).with(SlabBlock.WATERLOGGED, false), -13, 0, 38, start);
        structure.setBlockState(world, Blocks.SPRUCE_DOOR.getDefaultState().with(DoorBlock.FACING, Direction.SOUTH).with(DoorBlock.HALF, DoubleBlockHalf.UPPER).with(DoorBlock.HINGE, DoorHingeSide.LEFT).with(DoorBlock.OPEN, false).with(DoorBlock.POWERED, false), -13, 1, -40, start);
        structure.setBlockState(world, Blocks.BIRCH_LEAVES.getDefaultState().with(LeavesBlock.PERSISTENT, true).with(LeavesBlock.DISTANCE, 1), -13, 2, -13, start);
        structure.setBlockState(world, Blocks.LANTERN.getDefaultState().with(LanternBlock.WATERLOGGED, false).with(LanternBlock.HANGING, true), -13, 3, -43, start);
        structure.setBlockState(world, Blocks.SPRUCE_FENCE.getDefaultState().with(FourWayBlock.WATERLOGGED, false).with(FourWayBlock.NORTH, false).with(FourWayBlock.SOUTH, false).with(FourWayBlock.EAST, true).with(FourWayBlock.WEST, true), -13, 5, -46, start);
        structure.setBlockState(world, Blocks.SPRUCE_FENCE.getDefaultState().with(FourWayBlock.WATERLOGGED, false).with(FourWayBlock.NORTH, false).with(FourWayBlock.SOUTH, false).with(FourWayBlock.EAST, true).with(FourWayBlock.WEST, true), -13, 5, -32, start);
        structure.setBlockState(world, Blocks.SANDSTONE_SLAB.getDefaultState().with(SlabBlock.TYPE, SlabType.BOTTOM).with(SlabBlock.WATERLOGGED, false), -13, 5, -12, start);
        structure.setBlockState(world, Blocks.SANDSTONE_SLAB.getDefaultState().with(SlabBlock.TYPE, SlabType.BOTTOM).with(SlabBlock.WATERLOGGED, false), -13, 5, -5, start);
        structure.setBlockState(world, Blocks.SMOOTH_SANDSTONE.getDefaultState(), -12, -5, -43, start);
        structure.setBlockState(world, Blocks.SANDSTONE_WALL.getDefaultState().with(WallBlock.WATERLOGGED, false).with(WallBlock.UP, true).with(WallBlock.WALL_HEIGHT_NORTH, WallHeight.LOW).with(WallBlock.WALL_HEIGHT_SOUTH, WallHeight.LOW).with(WallBlock.WALL_HEIGHT_EAST, WallHeight.LOW).with(WallBlock.WALL_HEIGHT_WEST, WallHeight.LOW), -12, -5, -26, start);
        structure.setBlockState(world, Blocks.SPRUCE_FENCE_GATE.getDefaultState().with(FenceGateBlock.IN_WALL, true).with(FenceGateBlock.OPEN, false).with(FenceGateBlock.POWERED, false), -12, -5, -25, start);
        structure.setBlockState(world, Blocks.SANDSTONE_WALL.getDefaultState().with(WallBlock.WATERLOGGED, false).with(WallBlock.UP, true).with(WallBlock.WALL_HEIGHT_NORTH, WallHeight.LOW).with(WallBlock.WALL_HEIGHT_SOUTH, WallHeight.LOW).with(WallBlock.WALL_HEIGHT_EAST, WallHeight.LOW).with(WallBlock.WALL_HEIGHT_WEST, WallHeight.LOW), -12, -5, -24, start);
        structure.setBlockState(world, Blocks.SANDSTONE_WALL.getDefaultState().with(WallBlock.WATERLOGGED, false).with(WallBlock.UP, true).with(WallBlock.WALL_HEIGHT_NORTH, WallHeight.LOW).with(WallBlock.WALL_HEIGHT_SOUTH, WallHeight.LOW).with(WallBlock.WALL_HEIGHT_EAST, WallHeight.LOW).with(WallBlock.WALL_HEIGHT_WEST, WallHeight.LOW), -12, -5, -22, start);
        structure.setBlockState(world, Blocks.SPRUCE_FENCE_GATE.getDefaultState().with(FenceGateBlock.IN_WALL, true).with(FenceGateBlock.OPEN, false).with(FenceGateBlock.POWERED, false), -12, -5, -21, start);
        structure.setBlockState(world, Blocks.SANDSTONE_WALL.getDefaultState().with(WallBlock.WATERLOGGED, false).with(WallBlock.UP, true).with(WallBlock.WALL_HEIGHT_NORTH, WallHeight.LOW).with(WallBlock.WALL_HEIGHT_SOUTH, WallHeight.LOW).with(WallBlock.WALL_HEIGHT_EAST, WallHeight.LOW).with(WallBlock.WALL_HEIGHT_WEST, WallHeight.LOW), -12, -5, -20, start);
        structure.setBlockState(world, Blocks.SANDSTONE_WALL.getDefaultState().with(WallBlock.WATERLOGGED, false).with(WallBlock.UP, true).with(WallBlock.WALL_HEIGHT_NORTH, WallHeight.LOW).with(WallBlock.WALL_HEIGHT_SOUTH, WallHeight.LOW).with(WallBlock.WALL_HEIGHT_EAST, WallHeight.LOW).with(WallBlock.WALL_HEIGHT_WEST, WallHeight.LOW), -12, -5, -18, start);
        structure.setBlockState(world, Blocks.SPRUCE_FENCE_GATE.getDefaultState().with(FenceGateBlock.IN_WALL, true).with(FenceGateBlock.OPEN, false).with(FenceGateBlock.POWERED, false), -12, -5, -17, start);
        structure.setBlockState(world, Blocks.SANDSTONE_WALL.getDefaultState().with(WallBlock.WATERLOGGED, false).with(WallBlock.UP, true).with(WallBlock.WALL_HEIGHT_NORTH, WallHeight.LOW).with(WallBlock.WALL_HEIGHT_SOUTH, WallHeight.LOW).with(WallBlock.WALL_HEIGHT_EAST, WallHeight.LOW).with(WallBlock.WALL_HEIGHT_WEST, WallHeight.LOW), -12, -5, -16, start);
        structure.setBlockState(world, Blocks.SANDSTONE_WALL.getDefaultState().with(WallBlock.WATERLOGGED, false).with(WallBlock.UP, true).with(WallBlock.WALL_HEIGHT_NORTH, WallHeight.LOW).with(WallBlock.WALL_HEIGHT_SOUTH, WallHeight.LOW).with(WallBlock.WALL_HEIGHT_EAST, WallHeight.LOW).with(WallBlock.WALL_HEIGHT_WEST, WallHeight.LOW), -12, -5, -14, start);
        structure.setBlockState(world, Blocks.SPRUCE_FENCE_GATE.getDefaultState().with(FenceGateBlock.IN_WALL, true).with(FenceGateBlock.OPEN, false).with(FenceGateBlock.POWERED, false), -12, -5, -13, start);
        structure.setBlockState(world, Blocks.SANDSTONE_WALL.getDefaultState().with(WallBlock.WATERLOGGED, false).with(WallBlock.UP, true).with(WallBlock.WALL_HEIGHT_NORTH, WallHeight.LOW).with(WallBlock.WALL_HEIGHT_SOUTH, WallHeight.LOW).with(WallBlock.WALL_HEIGHT_EAST, WallHeight.LOW).with(WallBlock.WALL_HEIGHT_WEST, WallHeight.LOW), -12, -5, -12, start);
        structure.setBlockState(world, Blocks.SANDSTONE_WALL.getDefaultState().with(WallBlock.WATERLOGGED, false).with(WallBlock.UP, true).with(WallBlock.WALL_HEIGHT_NORTH, WallHeight.LOW).with(WallBlock.WALL_HEIGHT_SOUTH, WallHeight.LOW).with(WallBlock.WALL_HEIGHT_EAST, WallHeight.LOW).with(WallBlock.WALL_HEIGHT_WEST, WallHeight.LOW), -12, -5, -10, start);
        structure.setBlockState(world, Blocks.SPRUCE_FENCE_GATE.getDefaultState().with(FenceGateBlock.IN_WALL, true).with(FenceGateBlock.OPEN, false).with(FenceGateBlock.POWERED, false), -12, -5, -9, start);
        structure.setBlockState(world, Blocks.SANDSTONE_WALL.getDefaultState().with(WallBlock.WATERLOGGED, false).with(WallBlock.UP, true).with(WallBlock.WALL_HEIGHT_NORTH, WallHeight.LOW).with(WallBlock.WALL_HEIGHT_SOUTH, WallHeight.LOW).with(WallBlock.WALL_HEIGHT_EAST, WallHeight.LOW).with(WallBlock.WALL_HEIGHT_WEST, WallHeight.LOW), -12, -5, -8, start);
        structure.setBlockState(world, Blocks.SANDSTONE_WALL.getDefaultState().with(WallBlock.WATERLOGGED, false).with(WallBlock.UP, true).with(WallBlock.WALL_HEIGHT_NORTH, WallHeight.LOW).with(WallBlock.WALL_HEIGHT_SOUTH, WallHeight.LOW).with(WallBlock.WALL_HEIGHT_EAST, WallHeight.LOW).with(WallBlock.WALL_HEIGHT_WEST, WallHeight.LOW), -12, -5, -6, start);
        structure.setBlockState(world, Blocks.SPRUCE_FENCE_GATE.getDefaultState().with(FenceGateBlock.IN_WALL, true).with(FenceGateBlock.OPEN, false).with(FenceGateBlock.POWERED, false), -12, -5, -5, start);
        structure.setBlockState(world, Blocks.SANDSTONE_WALL.getDefaultState().with(WallBlock.WATERLOGGED, false).with(WallBlock.UP, true).with(WallBlock.WALL_HEIGHT_NORTH, WallHeight.LOW).with(WallBlock.WALL_HEIGHT_SOUTH, WallHeight.LOW).with(WallBlock.WALL_HEIGHT_EAST, WallHeight.LOW).with(WallBlock.WALL_HEIGHT_WEST, WallHeight.LOW), -12, -5, -4, start);
        structure.setBlockState(world, Blocks.SANDSTONE_WALL.getDefaultState().with(WallBlock.WATERLOGGED, false).with(WallBlock.UP, true).with(WallBlock.WALL_HEIGHT_NORTH, WallHeight.LOW).with(WallBlock.WALL_HEIGHT_SOUTH, WallHeight.LOW).with(WallBlock.WALL_HEIGHT_EAST, WallHeight.LOW).with(WallBlock.WALL_HEIGHT_WEST, WallHeight.LOW), -12, -5, -2, start);
        structure.setBlockState(world, Blocks.SPRUCE_FENCE_GATE.getDefaultState().with(FenceGateBlock.IN_WALL, true).with(FenceGateBlock.OPEN, false).with(FenceGateBlock.POWERED, false), -12, -5, -1, start);
        structure.setBlockState(world, Blocks.SANDSTONE_WALL.getDefaultState().with(WallBlock.WATERLOGGED, false).with(WallBlock.UP, true).with(WallBlock.WALL_HEIGHT_NORTH, WallHeight.LOW).with(WallBlock.WALL_HEIGHT_SOUTH, WallHeight.LOW).with(WallBlock.WALL_HEIGHT_EAST, WallHeight.LOW).with(WallBlock.WALL_HEIGHT_WEST, WallHeight.LOW), -12, -5, 0, start);
        structure.setBlockState(world, Blocks.FURNACE.getDefaultState().with(AbstractFurnaceBlock.FACING, Direction.NORTH).with(AbstractFurnaceBlock.LIT, false), -12, -5, 11, start);
        structure.setBlockState(world, Blocks.BARREL.getDefaultState().with(BarrelBlock.PROPERTY_FACING, Direction.NORTH).with(BarrelBlock.PROPERTY_OPEN, false), -12, -5, 17, start);
        structure.setBlockState(world, Index.CUT_SANDSTONE_PILLAR.getDefaultState().with(Pillar.WATERLOGGED, false).with(Pillar.STATE, PillarState.BOTH), -12, -5, 19, start);
        structure.setBlockState(world, Index.CUT_SANDSTONE_PILLAR.getDefaultState().with(Pillar.WATERLOGGED, false).with(Pillar.STATE, PillarState.BOTH), -12, -5, 23, start);
        structure.setBlockState(world, Blocks.SANDSTONE_WALL.getDefaultState().with(WallBlock.WATERLOGGED, false).with(WallBlock.UP, true).with(WallBlock.WALL_HEIGHT_NORTH, WallHeight.LOW).with(WallBlock.WALL_HEIGHT_SOUTH, WallHeight.LOW).with(WallBlock.WALL_HEIGHT_EAST, WallHeight.LOW).with(WallBlock.WALL_HEIGHT_WEST, WallHeight.LOW), -12, -4, -23, start);
        structure.setBlockState(world, Blocks.SANDSTONE_WALL.getDefaultState().with(WallBlock.WATERLOGGED, false).with(WallBlock.UP, true).with(WallBlock.WALL_HEIGHT_NORTH, WallHeight.LOW).with(WallBlock.WALL_HEIGHT_SOUTH, WallHeight.LOW).with(WallBlock.WALL_HEIGHT_EAST, WallHeight.LOW).with(WallBlock.WALL_HEIGHT_WEST, WallHeight.LOW), -12, -4, -19, start);
        structure.setBlockState(world, Blocks.SANDSTONE_WALL.getDefaultState().with(WallBlock.WATERLOGGED, false).with(WallBlock.UP, true).with(WallBlock.WALL_HEIGHT_NORTH, WallHeight.LOW).with(WallBlock.WALL_HEIGHT_SOUTH, WallHeight.LOW).with(WallBlock.WALL_HEIGHT_EAST, WallHeight.LOW).with(WallBlock.WALL_HEIGHT_WEST, WallHeight.LOW), -12, -4, -15, start);
        structure.setBlockState(world, Blocks.SANDSTONE_WALL.getDefaultState().with(WallBlock.WATERLOGGED, false).with(WallBlock.UP, true).with(WallBlock.WALL_HEIGHT_NORTH, WallHeight.LOW).with(WallBlock.WALL_HEIGHT_SOUTH, WallHeight.LOW).with(WallBlock.WALL_HEIGHT_EAST, WallHeight.LOW).with(WallBlock.WALL_HEIGHT_WEST, WallHeight.LOW), -12, -4, -11, start);
        structure.setBlockState(world, Blocks.SANDSTONE_WALL.getDefaultState().with(WallBlock.WATERLOGGED, false).with(WallBlock.UP, true).with(WallBlock.WALL_HEIGHT_NORTH, WallHeight.LOW).with(WallBlock.WALL_HEIGHT_SOUTH, WallHeight.LOW).with(WallBlock.WALL_HEIGHT_EAST, WallHeight.LOW).with(WallBlock.WALL_HEIGHT_WEST, WallHeight.LOW), -12, -4, -7, start);
        structure.setBlockState(world, Blocks.SANDSTONE_WALL.getDefaultState().with(WallBlock.WATERLOGGED, false).with(WallBlock.UP, true).with(WallBlock.WALL_HEIGHT_NORTH, WallHeight.LOW).with(WallBlock.WALL_HEIGHT_SOUTH, WallHeight.LOW).with(WallBlock.WALL_HEIGHT_EAST, WallHeight.LOW).with(WallBlock.WALL_HEIGHT_WEST, WallHeight.LOW), -12, -4, -3, start);
        structure.setBlockState(world, Blocks.FLOWER_POT.getDefaultState(), -12, -4, 19, start);
        structure.setBlockState(world, Blocks.FLOWER_POT.getDefaultState(), -12, -4, 23, start);
        structure.setBlockState(world, Blocks.LANTERN.getDefaultState().with(LanternBlock.WATERLOGGED, false).with(LanternBlock.HANGING, true), -12, -2, -35, start);
        structure.setBlockState(world, Blocks.SPRUCE_SLAB.getDefaultState().with(SlabBlock.TYPE, SlabType.DOUBLE).with(SlabBlock.WATERLOGGED, false), -12, -1, -48, start);
        structure.setBlockState(world, Blocks.SPRUCE_FENCE.getDefaultState().with(FourWayBlock.WATERLOGGED, false).with(FourWayBlock.NORTH, false).with(FourWayBlock.SOUTH, false).with(FourWayBlock.EAST, false).with(FourWayBlock.WEST, true), -12, 0, -53, start);
        structure.setBlockState(world, Blocks.SPRUCE_FENCE.getDefaultState().with(FourWayBlock.WATERLOGGED, false).with(FourWayBlock.NORTH, false).with(FourWayBlock.SOUTH, false).with(FourWayBlock.EAST, true).with(FourWayBlock.WEST, false), -12, 0, -48, start);
        structure.setBlockState(world, Blocks.BARREL.getDefaultState().with(BarrelBlock.PROPERTY_FACING, Direction.UP).with(BarrelBlock.PROPERTY_OPEN, false), -12, 0, -33, start);
        structure.setBlockState(world, Index.BENCH_OAK.getDefaultState().with(Bench.STATE, BenchState.SOUTH), -12, 0, -30, start);
        structure.setBlockState(world, Index.BENCH_OAK.getDefaultState().with(Bench.STATE, BenchState.NORTH), -12, 0, -29, start);
        structure.setBlockState(world, Blocks.BIRCH_LEAVES.getDefaultState().with(LeavesBlock.PERSISTENT, true).with(LeavesBlock.DISTANCE, 2), -12, 0, -14, start);
        structure.setBlockState(world, Index.COUNTER_OAK_ANDESITE.getDefaultState().with(Counter.FACING, Direction.NORTH).with(Counter.WATERLOGGED, false), -12, 0, -6, start);
        structure.setBlockState(world, Blocks.SANDSTONE_WALL.getDefaultState().with(WallBlock.WATERLOGGED, false).with(WallBlock.UP, true).with(WallBlock.WALL_HEIGHT_NORTH, WallHeight.LOW).with(WallBlock.WALL_HEIGHT_SOUTH, WallHeight.LOW).with(WallBlock.WALL_HEIGHT_EAST, WallHeight.LOW).with(WallBlock.WALL_HEIGHT_WEST, WallHeight.LOW), -12, 0, 28, start);
        structure.setBlockState(world, Blocks.SANDSTONE_WALL.getDefaultState().with(WallBlock.WATERLOGGED, false).with(WallBlock.UP, true).with(WallBlock.WALL_HEIGHT_NORTH, WallHeight.LOW).with(WallBlock.WALL_HEIGHT_SOUTH, WallHeight.LOW).with(WallBlock.WALL_HEIGHT_EAST, WallHeight.LOW).with(WallBlock.WALL_HEIGHT_WEST, WallHeight.LOW), -12, 0, 31, start);
        structure.setBlockState(world, Blocks.FLOWER_POT.getDefaultState(), -12, 1, -11, start);
        structure.setBlockState(world, Blocks.LANTERN.getDefaultState().with(LanternBlock.WATERLOGGED, false).with(LanternBlock.HANGING, true), -12, 2, -38, start);
        structure.setBlockState(world, Index.CUPBOARD_OAK.getDefaultState().with(Cupboard.FACING, Direction.NORTH).with(Cupboard.HALF, DoubleBlockHalf.LOWER).with(Cupboard.MIRROR, false).with(Cupboard.WATERLOGGED, false), -12, 2, -6, start);
        structure.setBlockState(world, Blocks.OAK_TRAPDOOR.getDefaultState().with(HorizontalBlock.HORIZONTAL_FACING, Direction.WEST).with(TrapDoorBlock.HALF, Half.BOTTOM).with(TrapDoorBlock.WATERLOGGED, false).with(TrapDoorBlock.POWERED, false).with(TrapDoorBlock.OPEN, false), -12, 3, -48, start);
        structure.setBlockState(world, Blocks.SPRUCE_FENCE.getDefaultState().with(FourWayBlock.WATERLOGGED, false).with(FourWayBlock.NORTH, true).with(FourWayBlock.SOUTH, false).with(FourWayBlock.EAST, true).with(FourWayBlock.WEST, false), -12, 3, -37, start);
        structure.setBlockState(world, Index.CUPBOARD_OAK.getDefaultState().with(Cupboard.FACING, Direction.NORTH).with(Cupboard.HALF, DoubleBlockHalf.UPPER).with(Cupboard.MIRROR, false).with(Cupboard.WATERLOGGED, false), -12, 3, -6, start);
        structure.setBlockState(world, Blocks.SPRUCE_FENCE.getDefaultState().with(FourWayBlock.WATERLOGGED, false).with(FourWayBlock.NORTH, false).with(FourWayBlock.SOUTH, false).with(FourWayBlock.EAST, false).with(FourWayBlock.WEST, true), -12, 5, -46, start);
        structure.setBlockState(world, Blocks.SPRUCE_FENCE.getDefaultState().with(FourWayBlock.WATERLOGGED, false).with(FourWayBlock.NORTH, true).with(FourWayBlock.SOUTH, false).with(FourWayBlock.EAST, true).with(FourWayBlock.WEST, false), -12, 5, -31, start);
        structure.setBlockState(world, Blocks.SANDSTONE_SLAB.getDefaultState().with(SlabBlock.TYPE, SlabType.BOTTOM).with(SlabBlock.WATERLOGGED, false), -12, 5, 18, start);
        structure.setBlockState(world, Blocks.SPRUCE_FENCE.getDefaultState().with(FourWayBlock.WATERLOGGED, false).with(FourWayBlock.NORTH, false).with(FourWayBlock.SOUTH, true).with(FourWayBlock.EAST, false).with(FourWayBlock.WEST, false), -12, 5, 19, start);
        structure.setBlockState(world, Blocks.SPRUCE_FENCE.getDefaultState().with(FourWayBlock.WATERLOGGED, false).with(FourWayBlock.NORTH, true).with(FourWayBlock.SOUTH, false).with(FourWayBlock.EAST, false).with(FourWayBlock.WEST, false), -12, 5, 20, start);
        structure.setBlockState(world, Blocks.SANDSTONE_SLAB.getDefaultState().with(SlabBlock.TYPE, SlabType.BOTTOM).with(SlabBlock.WATERLOGGED, false), -12, 5, 22, start);
        structure.setBlockState(world, Blocks.STONE.getDefaultState(), -11, -12, -57, start);
        structure.setBlockState(world, Blocks.SAND.getDefaultState(), -11, -7, -8, start);
        structure.setBlockState(world, Blocks.SMOOTH_SANDSTONE.getDefaultState(), -11, -5, -50, start);
        structure.setBlockState(world, Blocks.CRAFTING_TABLE.getDefaultState(), -11, -5, 11, start);
        structure.setBlockState(world, Blocks.SPRUCE_FENCE.getDefaultState().with(FourWayBlock.WATERLOGGED, false).with(FourWayBlock.NORTH, false).with(FourWayBlock.SOUTH, true).with(FourWayBlock.EAST, true).with(FourWayBlock.WEST, true), -11, -5, 17, start);
        structure.setBlockState(world, Blocks.AIR.getDefaultState(), -11, -5, 51, start);
        structure.setBlockState(world, Blocks.SANDSTONE_WALL.getDefaultState().with(WallBlock.WATERLOGGED, false).with(WallBlock.UP, true).with(WallBlock.WALL_HEIGHT_NORTH, WallHeight.LOW).with(WallBlock.WALL_HEIGHT_SOUTH, WallHeight.LOW).with(WallBlock.WALL_HEIGHT_EAST, WallHeight.LOW).with(WallBlock.WALL_HEIGHT_WEST, WallHeight.LOW), -11, -5, 52, start);
        structure.setBlockState(world, Index.CUPBOARD_OAK.getDefaultState().with(Cupboard.FACING, Direction.SOUTH).with(Cupboard.HALF, DoubleBlockHalf.LOWER).with(Cupboard.MIRROR, false).with(Cupboard.WATERLOGGED, false), -11, -4, -46, start);
        structure.setBlockState(world, Index.CUPBOARD_OAK.getDefaultState().with(Cupboard.FACING, Direction.NORTH).with(Cupboard.HALF, DoubleBlockHalf.LOWER).with(Cupboard.MIRROR, false).with(Cupboard.WATERLOGGED, false), -11, -4, 37, start);
        structure.setBlockState(world, Blocks.LANTERN.getDefaultState().with(LanternBlock.WATERLOGGED, false).with(LanternBlock.HANGING, false), -11, -4, 52, start);
        structure.setBlockState(world, Index.CUPBOARD_OAK.getDefaultState().with(Cupboard.FACING, Direction.SOUTH).with(Cupboard.HALF, DoubleBlockHalf.UPPER).with(Cupboard.MIRROR, false).with(Cupboard.WATERLOGGED, false), -11, -3, -46, start);
        structure.setBlockState(world, Index.CUPBOARD_OAK.getDefaultState().with(Cupboard.FACING, Direction.NORTH).with(Cupboard.HALF, DoubleBlockHalf.UPPER).with(Cupboard.MIRROR, false).with(Cupboard.WATERLOGGED, false), -11, -3, 37, start);
        structure.setBlockState(world, Blocks.SMOOTH_SANDSTONE.getDefaultState(), -11, -2, 1, start);
        structure.setBlockState(world, Blocks.OAK_TRAPDOOR.getDefaultState().with(HorizontalBlock.HORIZONTAL_FACING, Direction.WEST).with(TrapDoorBlock.HALF, Half.BOTTOM).with(TrapDoorBlock.WATERLOGGED, false).with(TrapDoorBlock.POWERED, false).with(TrapDoorBlock.OPEN, false), -11, -1, -55, start);
        structure.setBlockState(world, Blocks.OAK_TRAPDOOR.getDefaultState().with(HorizontalBlock.HORIZONTAL_FACING, Direction.NORTH).with(TrapDoorBlock.HALF, Half.BOTTOM).with(TrapDoorBlock.WATERLOGGED, false).with(TrapDoorBlock.POWERED, false).with(TrapDoorBlock.OPEN, false), -11, -1, -54, start);
        structure.setBlockState(world, Blocks.CUT_SANDSTONE.getDefaultState(), -11, -1, -47, start);
        structure.setBlockState(world, Blocks.CUT_SANDSTONE.getDefaultState(), -11, -1, 1, start);
        structure.setBlockState(world, Blocks.CUT_SANDSTONE.getDefaultState(), -11, -1, 39, start);
        structure.setBlockState(world, Blocks.SANDSTONE_SLAB.getDefaultState().with(SlabBlock.TYPE, SlabType.BOTTOM).with(SlabBlock.WATERLOGGED, false), -11, 0, -53, start);
        structure.setBlockState(world, Blocks.SPRUCE_FENCE.getDefaultState().with(FourWayBlock.WATERLOGGED, false).with(FourWayBlock.NORTH, false).with(FourWayBlock.SOUTH, true).with(FourWayBlock.EAST, true).with(FourWayBlock.WEST, false), -11, 0, -52, start);
        structure.setBlockState(world, Blocks.SPRUCE_FENCE.getDefaultState().with(FourWayBlock.WATERLOGGED, false).with(FourWayBlock.NORTH, true).with(FourWayBlock.SOUTH, false).with(FourWayBlock.EAST, true).with(FourWayBlock.WEST, true), -11, 0, -48, start);
        structure.setBlockState(world, Blocks.SANDSTONE_SLAB.getDefaultState().with(SlabBlock.TYPE, SlabType.BOTTOM).with(SlabBlock.WATERLOGGED, false), -11, 0, -47, start);
