package mod.arcalitegames.odyssey.world.structure.town.bashkarcity;

import mod.arcalitegames.buildersaddition.Index;
import mod.arcalitegames.buildersaddition.blocks.Bookshelf;
import mod.arcalitegames.buildersaddition.blocks.Cabinet;
import mod.arcalitegames.buildersaddition.blocks.Counter;
import mod.arcalitegames.buildersaddition.blocks.Cupboard;
import mod.arcalitegames.buildersaddition.blocks.Hedge;
import mod.arcalitegames.buildersaddition.blocks.Shelf;
import mod.arcalitegames.buildersaddition.blocks.Stool;
import mod.arcalitegames.buildersaddition.blocks.VerticalSlab;
import mod.arcalitegames.buildersaddition.state.HedgeState;
import mod.arcalitegames.buildersaddition.state.StoolState;
import mod.arcalitegames.buildersaddition.state.VerticalSlabState;
import mod.arcalitegames.odyssey.blocks.ChairBlock;
import mod.arcalitegames.odyssey.blocks.ModBlocks;
import mod.arcalitegames.odyssey.world.structure.StructureBase;
import net.minecraft.block.BarrelBlock;
import net.minecraft.block.BedBlock;
import net.minecraft.block.Blocks;
import net.minecraft.block.ChainBlock;
import net.minecraft.block.FarmlandBlock;
import net.minecraft.block.FourWayBlock;
import net.minecraft.block.HorizontalBlock;
import net.minecraft.block.LeavesBlock;
import net.minecraft.block.NoteBlock;
import net.minecraft.block.SlabBlock;
import net.minecraft.block.StairsBlock;
import net.minecraft.block.TrapDoorBlock;
import net.minecraft.block.WallBlock;
import net.minecraft.block.WallHeight;
import net.minecraft.state.properties.BedPart;
import net.minecraft.state.properties.DoubleBlockHalf;
import net.minecraft.state.properties.Half;
import net.minecraft.state.properties.NoteBlockInstrument;
import net.minecraft.state.properties.SlabType;
import net.minecraft.state.properties.StairsShape;
import net.minecraft.util.Direction;
import net.minecraft.util.math.BlockPos;
import net.minecraft.world.World;

public class BashkarComponent2
{

	public static BlockPos start;
    public static World world;
    public static StructureBase structure;

    public static void init(World worldIn, BlockPos blockPos, StructureBase structureIn)
    {
        world = worldIn; start = blockPos; structure = structureIn;
    }
    
    public static void generatePart21()
    {
        structure.fillWithBlocks(world, start, 59, 4, -52, 60, 4, -48, Blocks.SPRUCE_SLAB.getDefaultState().with(SlabBlock.TYPE, SlabType.BOTTOM).with(SlabBlock.WATERLOGGED, false));
        structure.fillWithBlocks(world, start, 59, 4, -42, 59, 4, -42, Blocks.BIRCH_LEAVES.getDefaultState().with(LeavesBlock.PERSISTENT, true).with(LeavesBlock.DISTANCE, 2));
        structure.fillWithBlocks(world, start, 59, 5, -11, 60, 5, -11, Blocks.WHITE_BED.getDefaultState().with(HorizontalBlock.HORIZONTAL_FACING, Direction.NORTH).with(BedBlock.PART, BedPart.HEAD));
        structure.fillWithBlocks(world, start, 59, 5, -10, 60, 5, -10, Blocks.WHITE_BED.getDefaultState().with(HorizontalBlock.HORIZONTAL_FACING, Direction.NORTH).with(BedBlock.PART, BedPart.FOOT));
        structure.fillWithBlocks(world, start, 59, 5, -4, 60, 6, -4, Index.BOOKSHELF_OAK.getDefaultState().with(Bookshelf.FACING, Direction.NORTH).with(Bookshelf.BOOK0, false).with(Bookshelf.BOOK1, false).with(Bookshelf.BOOK2, false).with(Bookshelf.BOOK3, false).with(Bookshelf.BOOK4, false).with(Bookshelf.BOOK5, false).with(Bookshelf.BOOK6, false).with(Bookshelf.BOOK7, false));
        structure.fillWithBlocks(world, start, 59, 6, -38, 60, 7, -38, Blocks.SMOOTH_SANDSTONE.getDefaultState());
        structure.fillWithBlocks(world, start, 59, 6, -25, 64, 6, -17, Blocks.SANDSTONE.getDefaultState());
        structure.fillWithBlocks(world, start, 59, 6, -16, 62, 6, -13, Blocks.SANDSTONE.getDefaultState());
        structure.fillWithBlocks(world, start, 59, 8, -26, 65, 8, -16, Blocks.SANDSTONE.getDefaultState());
        structure.fillWithBlocks(world, start, 59, 9, -26, 62, 9, -19, Blocks.SANDSTONE.getDefaultState());
        structure.fillWithBlocks(world, start, 59, 10, -19, 61, 10, -19, Blocks.SANDSTONE.getDefaultState());
        structure.fillWithBlocks(world, start, 59, 10, -8, 59, 10, -1, Blocks.SANDSTONE.getDefaultState());
        structure.fillWithBlocks(world, start, 59, 11, -8, 59, 14, -8, Blocks.CUT_SANDSTONE.getDefaultState());
        structure.fillWithBlocks(world, start, 59, 11, -7, 59, 14, -7, Blocks.SMOOTH_SANDSTONE.getDefaultState());
        structure.fillWithBlocks(world, start, 59, 11, -6, 59, 12, -6, Blocks.SPRUCE_FENCE.getDefaultState().with(FourWayBlock.WATERLOGGED, false).with(FourWayBlock.NORTH, true).with(FourWayBlock.SOUTH, true).with(FourWayBlock.EAST, false).with(FourWayBlock.WEST, false));
        structure.fillWithBlocks(world, start, 59, 11, -5, 59, 14, -2, Blocks.SMOOTH_SANDSTONE.getDefaultState());
        structure.fillWithBlocks(world, start, 59, 11, -1, 59, 14, -1, Blocks.CUT_SANDSTONE.getDefaultState());
        structure.fillWithBlocks(world, start, 59, 11, 25, 59, 12, 25, Blocks.SPRUCE_FENCE.getDefaultState().with(FourWayBlock.WATERLOGGED, false).with(FourWayBlock.NORTH, false).with(FourWayBlock.SOUTH, false).with(FourWayBlock.EAST, true).with(FourWayBlock.WEST, true));
        structure.fillWithBlocks(world, start, 59, 13, -21, 61, 13, -21, Blocks.SPRUCE_FENCE.getDefaultState().with(FourWayBlock.WATERLOGGED, false).with(FourWayBlock.NORTH, false).with(FourWayBlock.SOUTH, true).with(FourWayBlock.EAST, true).with(FourWayBlock.WEST, true));
        structure.fillWithBlocks(world, start, 59, 13, -20, 64, 13, -20, Blocks.SPRUCE_FENCE.getDefaultState().with(FourWayBlock.WATERLOGGED, false).with(FourWayBlock.NORTH, true).with(FourWayBlock.SOUTH, true).with(FourWayBlock.EAST, true).with(FourWayBlock.WEST, true));
        structure.fillWithBlocks(world, start, 59, 13, -6, 59, 14, -2, Blocks.SMOOTH_SANDSTONE.getDefaultState());
        structure.fillWithBlocks(world, start, 59, 13, 0, 59, 13, 0, Blocks.ORANGE_WOOL.getDefaultState());
        structure.fillWithBlocks(world, start, 59, 14, -21, 60, 14, -20, Blocks.OAK_TRAPDOOR.getDefaultState().with(HorizontalBlock.HORIZONTAL_FACING, Direction.WEST).with(TrapDoorBlock.HALF, Half.BOTTOM).with(TrapDoorBlock.WATERLOGGED, false).with(TrapDoorBlock.POWERED, false).with(TrapDoorBlock.OPEN, false));
        structure.fillWithBlocks(world, start, 59, 14, -12, 60, 14, -9, Blocks.PURPLE_WOOL.getDefaultState());
        structure.fillWithBlocks(world, start, 59, 14, 23, 60, 14, 24, Blocks.SPRUCE_SLAB.getDefaultState().with(SlabBlock.TYPE, SlabType.BOTTOM).with(SlabBlock.WATERLOGGED, false));
        structure.fillWithBlocks(world, start, 60, -14, -86, 67, -14, -79, Blocks.SAND.getDefaultState());
        structure.fillWithBlocks(world, start, 60, -14, -78, 61, -14, -77, Blocks.SAND.getDefaultState());
        structure.fillWithBlocks(world, start, 60, -12, -72, 60, -12, -72, Blocks.SAND.getDefaultState());
        structure.fillWithBlocks(world, start, 60, -12, -71, 60, -12, -38, Blocks.STONE.getDefaultState());
        structure.fillWithBlocks(world, start, 60, -12, -37, 62, -12, -31, Blocks.SAND.getDefaultState());
        structure.fillWithBlocks(world, start, 60, -12, -30, 67, -12, -23, Blocks.STONE.getDefaultState());
        structure.fillWithBlocks(world, start, 60, -12, -21, 63, -12, -17, Blocks.SAND.getDefaultState());
        structure.fillWithBlocks(world, start, 60, -11, -55, 60, -11, -55, Blocks.STONE.getDefaultState());
        structure.fillWithBlocks(world, start, 60, -11, -54, 60, -9, 10, Blocks.SAND.getDefaultState());
        structure.fillWithBlocks(world, start, 60, -10, -80, 102, -10, 67, Blocks.SAND.getDefaultState());
        structure.fillWithBlocks(world, start, 60, -8, 33, 60, -8, 34, Blocks.SAND.getDefaultState());
        structure.fillWithBlocks(world, start, 60, -7, -68, 74, -7, -54, Blocks.SANDSTONE.getDefaultState());
        structure.fillWithBlocks(world, start, 60, -7, 31, 60, -5, 31, Blocks.SANDSTONE.getDefaultState());
        structure.fillWithBlocks(world, start, 60, -7, 32, 60, -7, 33, Blocks.SAND.getDefaultState());
        structure.fillWithBlocks(world, start, 60, -6, 32, 60, -6, 33, Blocks.SPRUCE_PLANKS.getDefaultState());
        structure.fillWithBlocks(world, start, 60, -6, 61, 61, -6, 62, Blocks.SAND.getDefaultState());
        structure.fillWithBlocks(world, start, 60, -5, 24, 60, -5, 34, Blocks.SANDSTONE.getDefaultState());
        structure.fillWithBlocks(world, start, 60, -5, 37, 60, -5, 37, Blocks.BIRCH_LEAVES.getDefaultState().with(LeavesBlock.PERSISTENT, true).with(LeavesBlock.DISTANCE, 2));
        structure.fillWithBlocks(world, start, 60, -4, 24, 60, -2, 31, Blocks.SMOOTH_SANDSTONE.getDefaultState());
        structure.fillWithBlocks(world, start, 60, -4, 32, 60, -4, 33, Blocks.SMOOTH_SANDSTONE.getDefaultState());
        structure.fillWithBlocks(world, start, 60, -4, 34, 60, -1, 34, Blocks.CUT_SANDSTONE.getDefaultState());
        structure.fillWithBlocks(world, start, 60, -3, 32, 60, -2, 33, Blocks.SANDSTONE.getDefaultState());
        structure.fillWithBlocks(world, start, 60, -1, -41, 73, -1, 17, Blocks.SANDSTONE.getDefaultState());
        structure.fillWithBlocks(world, start, 60, -1, 18, 66, 0, 18, Blocks.SANDSTONE.getDefaultState());
        structure.fillWithBlocks(world, start, 60, -1, 19, 66, -1, 25, Blocks.SPRUCE_PLANKS.getDefaultState());
        structure.fillWithBlocks(world, start, 60, -1, 26, 60, 0, 30, Blocks.SANDSTONE.getDefaultState());
        structure.fillWithBlocks(world, start, 60, -1, 31, 61, -1, 31, Blocks.SPRUCE_PLANKS.getDefaultState());
        structure.fillWithBlocks(world, start, 60, -1, 32, 60, -1, 33, Blocks.SANDSTONE.getDefaultState());
        structure.fillWithBlocks(world, start, 60, 0, 17, 66, 0, 25, Blocks.SANDSTONE.getDefaultState());
        structure.fillWithBlocks(world, start, 60, 0, 31, 60, 0, 33, Blocks.SANDSTONE_WALL.getDefaultState().with(WallBlock.WATERLOGGED, false).with(WallBlock.UP, false).with(WallBlock.WALL_HEIGHT_NORTH, WallHeight.LOW).with(WallBlock.WALL_HEIGHT_SOUTH, WallHeight.LOW).with(WallBlock.WALL_HEIGHT_EAST, WallHeight.LOW).with(WallBlock.WALL_HEIGHT_WEST, WallHeight.LOW));
        structure.fillWithBlocks(world, start, 60, 1, 16, 60, 1, 16, Blocks.SANDSTONE.getDefaultState());
        structure.fillWithBlocks(world, start, 60, 1, 17, 60, 3, 27, Blocks.SMOOTH_SANDSTONE.getDefaultState());
        structure.fillWithBlocks(world, start, 60, 1, 28, 60, 2, 28, Blocks.SPRUCE_FENCE.getDefaultState().with(FourWayBlock.WATERLOGGED, false).with(FourWayBlock.NORTH, true).with(FourWayBlock.SOUTH, true).with(FourWayBlock.EAST, false).with(FourWayBlock.WEST, false));
        structure.fillWithBlocks(world, start, 60, 1, 29, 60, 4, 29, Blocks.SMOOTH_SANDSTONE.getDefaultState());
        structure.fillWithBlocks(world, start, 60, 1, 30, 60, 4, 30, Blocks.CUT_SANDSTONE.getDefaultState());
        structure.fillWithBlocks(world, start, 60, 2, -43, 60, 2, -43, Blocks.BIRCH_LEAVES.getDefaultState().with(LeavesBlock.PERSISTENT, true).with(LeavesBlock.DISTANCE, 3));
        structure.fillWithBlocks(world, start, 60, 2, -42, 60, 3, -42, Blocks.BIRCH_LEAVES.getDefaultState().with(LeavesBlock.PERSISTENT, true).with(LeavesBlock.DISTANCE, 2));
        structure.fillWithBlocks(world, start, 60, 2, -41, 60, 3, -41, Blocks.BIRCH_LEAVES.getDefaultState().with(LeavesBlock.PERSISTENT, true).with(LeavesBlock.DISTANCE, 1));
        structure.fillWithBlocks(world, start, 60, 2, -40, 60, 3, -40, Blocks.BIRCH_LEAVES.getDefaultState().with(LeavesBlock.PERSISTENT, true).with(LeavesBlock.DISTANCE, 2));
        structure.fillWithBlocks(world, start, 60, 2, 16, 60, 2, 16, Blocks.SANDSTONE.getDefaultState());
        structure.fillWithBlocks(world, start, 60, 3, 16, 60, 3, 16, Blocks.SANDSTONE.getDefaultState());
        structure.fillWithBlocks(world, start, 60, 3, 28, 60, 4, 29, Blocks.SMOOTH_SANDSTONE.getDefaultState());
        structure.fillWithBlocks(world, start, 60, 4, 10, 60, 8, 25, Blocks.SANDSTONE.getDefaultState());
        structure.fillWithBlocks(world, start, 60, 4, 27, 60, 4, 29, Blocks.SMOOTH_SANDSTONE.getDefaultState());
        structure.fillWithBlocks(world, start, 60, 7, -32, 60, 7, -30, Index.CABINET_OAK.getDefaultState().with(Cabinet.FACING, Direction.WEST).with(Cabinet.WATERLOGGED, false));
        structure.fillWithBlocks(world, start, 60, 8, -32, 60, 8, -30, Blocks.SMOOTH_SANDSTONE_STAIRS.getDefaultState().with(StairsBlock.FACING, Direction.EAST).with(StairsBlock.WATERLOGGED, false).with(StairsBlock.SHAPE, StairsShape.STRAIGHT).with(StairsBlock.HALF, Half.TOP));
        structure.fillWithBlocks(world, start, 60, 9, -13, 61, 9, -12, Blocks.SANDSTONE.getDefaultState());
        structure.fillWithBlocks(world, start, 60, 9, -3, 61, 9, -2, Blocks.SPRUCE_PLANKS.getDefaultState());
        structure.fillWithBlocks(world, start, 60, 9, -1, 63, 9, 9, Blocks.SANDSTONE.getDefaultState());
        structure.fillWithBlocks(world, start, 60, 9, 20, 60, 9, 24, Blocks.SPRUCE_PLANKS.getDefaultState());
        structure.fillWithBlocks(world, start, 60, 10, -9, 61, 10, -9, Blocks.BARREL.getDefaultState().with(BarrelBlock.PROPERTY_FACING, Direction.NORTH).with(BarrelBlock.PROPERTY_OPEN, false));
        structure.fillWithBlocks(world, start, 60, 10, -8, 63, 10, -8, Blocks.SANDSTONE.getDefaultState());
        structure.fillWithBlocks(world, start, 60, 11, -8, 60, 14, -8, Blocks.SMOOTH_SANDSTONE.getDefaultState());
        structure.fillWithBlocks(world, start, 60, 11, -1, 60, 14, -1, Blocks.SMOOTH_SANDSTONE.getDefaultState());
        structure.fillWithBlocks(world, start, 60, 11, 25, 60, 14, 25, Blocks.SMOOTH_SANDSTONE.getDefaultState());
        structure.fillWithBlocks(world, start, 60, 13, -31, 60, 13, -28, Blocks.WHITE_WOOL.getDefaultState());
        structure.fillWithBlocks(world, start, 60, 13, -11, 60, 13, -9, Blocks.SPRUCE_FENCE.getDefaultState().with(FourWayBlock.WATERLOGGED, false).with(FourWayBlock.NORTH, true).with(FourWayBlock.SOUTH, true).with(FourWayBlock.EAST, false).with(FourWayBlock.WEST, false));
        structure.fillWithBlocks(world, start, 60, 13, 0, 61, 13, 1, Blocks.ORANGE_WOOL.getDefaultState());
        structure.fillWithBlocks(world, start, 60, 14, -7, 63, 14, -7, Blocks.SMOOTH_SANDSTONE.getDefaultState());
        structure.fillWithBlocks(world, start, 60, 14, -6, 60, 14, -2, Blocks.SMOOTH_SANDSTONE_SLAB.getDefaultState().with(SlabBlock.TYPE, SlabType.BOTTOM).with(SlabBlock.WATERLOGGED, false));
        structure.fillWithBlocks(world, start, 60, 14, 21, 60, 14, 22, Blocks.SPRUCE_SLAB.getDefaultState().with(SlabBlock.TYPE, SlabType.DOUBLE).with(SlabBlock.WATERLOGGED, false));
        structure.fillWithBlocks(world, start, 61, -14, 70, 67, -14, 76, Blocks.SAND.getDefaultState());
        structure.fillWithBlocks(world, start, 61, -13, -74, 62, -13, -73, Blocks.SAND.getDefaultState());
        structure.fillWithBlocks(world, start, 61, -12, -83, 71, -12, -73, Blocks.SAND.getDefaultState());
        structure.fillWithBlocks(world, start, 61, -12, -72, 62, -12, -71, Blocks.SAND.getDefaultState());
        structure.fillWithBlocks(world, start, 61, -12, -70, 62, -12, -38, Blocks.STONE.getDefaultState());
        structure.fillWithBlocks(world, start, 61, -12, -16, 62, -11, -16, Blocks.SAND.getDefaultState());
        structure.fillWithBlocks(world, start, 61, -11, -55, 63, -11, -53, Blocks.STONE.getDefaultState());
        structure.fillWithBlocks(world, start, 61, -11, -52, 61, -11, 10, Blocks.SAND.getDefaultState());
        structure.fillWithBlocks(world, start, 61, -11, 61, 72, -11, 61, Blocks.STONE.getDefaultState());
        structure.fillWithBlocks(world, start, 61, -11, 62, 65, -11, 73, Blocks.SAND.getDefaultState());
        structure.fillWithBlocks(world, start, 61, -10, 73, 63, -10, 73, Blocks.SAND.getDefaultState());
        structure.fillWithBlocks(world, start, 61, -8, 33, 64, -8, 36, Blocks.SANDSTONE.getDefaultState());
        structure.fillWithBlocks(world, start, 61, -8, 37, 61, -7, 37, Blocks.SAND.getDefaultState());
        structure.fillWithBlocks(world, start, 61, -8, 38, 78, -8, 55, Blocks.SANDSTONE.getDefaultState());
        structure.fillWithBlocks(world, start, 61, -8, 56, 74, -8, 69, Blocks.SAND.getDefaultState());
        structure.fillWithBlocks(world, start, 61, -7, 31, 68, -7, 31, Blocks.SAND.getDefaultState());
        structure.fillWithBlocks(world, start, 61, -7, 32, 64, -7, 36, Blocks.SANDSTONE.getDefaultState());
        structure.fillWithBlocks(world, start, 61, -7, 38, 78, -7, 55, Blocks.SANDSTONE.getDefaultState());
        structure.fillWithBlocks(world, start, 61, -6, -70, 62, -6, -69, Blocks.SAND.getDefaultState());
        structure.fillWithBlocks(world, start, 61, -6, -68, 76, -6, -53, Blocks.SANDSTONE.getDefaultState());
        structure.fillWithBlocks(world, start, 61, -6, 31, 68, -6, 31, Blocks.SPRUCE_PLANKS.getDefaultState());
        structure.fillWithBlocks(world, start, 61, -6, 32, 64, -6, 36, Blocks.SANDSTONE.getDefaultState());
        structure.fillWithBlocks(world, start, 61, -6, 38, 78, -6, 55, Blocks.SANDSTONE.getDefaultState());
        structure.fillWithBlocks(world, start, 61, -5, 24, 63, -5, 24, Blocks.SANDSTONE.getDefaultState());
        structure.fillWithBlocks(world, start, 61, -5, 25, 61, -5, 26, Index.COUNTER_OAK_ANDESITE.getDefaultState().with(Counter.FACING, Direction.EAST).with(Counter.WATERLOGGED, false));
        structure.fillWithBlocks(world, start, 61, -5, 30, 61, -5, 31, Index.COUNTER_OAK_ANDESITE.getDefaultState().with(Counter.FACING, Direction.EAST).with(Counter.WATERLOGGED, false));
        structure.fillWithBlocks(world, start, 61, -5, 36, 61, -5, 36, Blocks.BIRCH_LEAVES.getDefaultState().with(LeavesBlock.PERSISTENT, true).with(LeavesBlock.DISTANCE, 2));
        structure.fillWithBlocks(world, start, 61, -4, -53, 62, -3, -53, Blocks.SPRUCE_FENCE.getDefaultState().with(FourWayBlock.WATERLOGGED, false).with(FourWayBlock.NORTH, false).with(FourWayBlock.SOUTH, false).with(FourWayBlock.EAST, true).with(FourWayBlock.WEST, true));
        structure.fillWithBlocks(world, start, 61, -4, 19, 62, -4, 20, Blocks.SANDSTONE.getDefaultState());
        structure.fillWithBlocks(world, start, 61, -4, 24, 63, -2, 24, Blocks.SMOOTH_SANDSTONE.getDefaultState());
        structure.fillWithBlocks(world, start, 61, -4, 25, 61, -4, 26, Index.CABINET_OAK.getDefaultState().with(Cabinet.FACING, Direction.EAST).with(Cabinet.WATERLOGGED, false));
        structure.fillWithBlocks(world, start, 61, -4, 30, 61, -4, 31, Index.CABINET_OAK.getDefaultState().with(Cabinet.FACING, Direction.EAST).with(Cabinet.WATERLOGGED, false));
        structure.fillWithBlocks(world, start, 61, -4, 32, 62, -3, 32, Blocks.SMOOTH_SANDSTONE.getDefaultState());
        structure.fillWithBlocks(world, start, 61, -3, 19, 62, -3, 20, Blocks.SANDSTONE.getDefaultState());
        structure.fillWithBlocks(world, start, 61, -2, 19, 62, -2, 20, Blocks.SANDSTONE.getDefaultState());
        structure.fillWithBlocks(world, start, 61, -2, 25, 61, -2, 26, Blocks.OAK_TRAPDOOR.getDefaultState().with(HorizontalBlock.HORIZONTAL_FACING, Direction.EAST).with(TrapDoorBlock.HALF, Half.BOTTOM).with(TrapDoorBlock.WATERLOGGED, false).with(TrapDoorBlock.POWERED, false).with(TrapDoorBlock.OPEN, false));
        structure.fillWithBlocks(world, start, 61, -2, 30, 61, -2, 31, Blocks.OAK_TRAPDOOR.getDefaultState().with(HorizontalBlock.HORIZONTAL_FACING, Direction.EAST).with(TrapDoorBlock.HALF, Half.BOTTOM).with(TrapDoorBlock.WATERLOGGED, false).with(TrapDoorBlock.POWERED, false).with(TrapDoorBlock.OPEN, false));
        structure.fillWithBlocks(world, start, 61, -2, 32, 68, -2, 32, Blocks.SMOOTH_SANDSTONE.getDefaultState());
        structure.fillWithBlocks(world, start, 61, -1, -44, 64, -1, 18, Blocks.SANDSTONE.getDefaultState());
        structure.fillWithBlocks(world, start, 61, -1, 26, 61, -1, 31, Blocks.SPRUCE_PLANKS.getDefaultState());
        structure.fillWithBlocks(world, start, 61, 0, 15, 66, 0, 25, Blocks.SANDSTONE.getDefaultState());
        structure.fillWithBlocks(world, start, 61, 1, -53, 62, 2, -53, Blocks.SPRUCE_FENCE.getDefaultState().with(FourWayBlock.WATERLOGGED, false).with(FourWayBlock.NORTH, false).with(FourWayBlock.SOUTH, false).with(FourWayBlock.EAST, true).with(FourWayBlock.WEST, true));
        structure.fillWithBlocks(world, start, 61, 1, -47, 61, 2, -47, Blocks.SPRUCE_FENCE.getDefaultState().with(FourWayBlock.WATERLOGGED, false).with(FourWayBlock.NORTH, false).with(FourWayBlock.SOUTH, false).with(FourWayBlock.EAST, true).with(FourWayBlock.WEST, true));
        structure.fillWithBlocks(world, start, 61, 1, 16, 65, 1, 25, Blocks.SANDSTONE.getDefaultState());
        structure.fillWithBlocks(world, start, 61, 2, 16, 65, 2, 25, Blocks.SANDSTONE.getDefaultState());
        structure.fillWithBlocks(world, start, 61, 3, 16, 66, 3, 25, Blocks.SANDSTONE.getDefaultState());
        structure.fillWithBlocks(world, start, 61, 4, -52, 62, 4, -51, Blocks.SPRUCE_SLAB.getDefaultState().with(SlabBlock.TYPE, SlabType.BOTTOM).with(SlabBlock.WATERLOGGED, false));
        structure.fillWithBlocks(world, start, 61, 4, -49, 62, 4, -48, Blocks.SPRUCE_SLAB.getDefaultState().with(SlabBlock.TYPE, SlabType.BOTTOM).with(SlabBlock.WATERLOGGED, false));
        structure.fillWithBlocks(world, start, 61, 4, -37, 68, 4, -30, Blocks.SANDSTONE.getDefaultState());
        structure.fillWithBlocks(world, start, 61, 4, -29, 65, 4, -16, Blocks.SANDSTONE.getDefaultState());
        structure.fillWithBlocks(world, start, 61, 4, -15, 62, 4, -12, Blocks.SANDSTONE.getDefaultState());
        structure.fillWithBlocks(world, start, 61, 4, 10, 67, 4, 19, Blocks.SPRUCE_PLANKS.getDefaultState());
        structure.fillWithBlocks(world, start, 61, 4, 20, 66, 4, 25, Blocks.SANDSTONE.getDefaultState());
        structure.fillWithBlocks(world, start, 61, 5, -50, 61, 7, -50, Blocks.SPRUCE_FENCE.getDefaultState().with(FourWayBlock.WATERLOGGED, false).with(FourWayBlock.NORTH, false).with(FourWayBlock.SOUTH, false).with(FourWayBlock.EAST, false).with(FourWayBlock.WEST, false));
        structure.fillWithBlocks(world, start, 61, 5, -47, 61, 7, -47, Blocks.SPRUCE_FENCE.getDefaultState().with(FourWayBlock.WATERLOGGED, false).with(FourWayBlock.NORTH, false).with(FourWayBlock.SOUTH, false).with(FourWayBlock.EAST, false).with(FourWayBlock.WEST, false));
        structure.fillWithBlocks(world, start, 61, 5, -37, 61, 5, -12, Blocks.SANDSTONE.getDefaultState());
        structure.fillWithBlocks(world, start, 61, 5, 19, 61, 5, 25, Blocks.SANDSTONE.getDefaultState());
        structure.fillWithBlocks(world, start, 61, 6, -38, 61, 9, -38, Blocks.CUT_SANDSTONE.getDefaultState());
        structure.fillWithBlocks(world, start, 61, 6, -37, 61, 7, -37, Blocks.SMOOTH_SANDSTONE.getDefaultState());
        structure.fillWithBlocks(world, start, 61, 6, -36, 61, 7, -35, Blocks.SPRUCE_FENCE.getDefaultState().with(FourWayBlock.WATERLOGGED, false).with(FourWayBlock.NORTH, true).with(FourWayBlock.SOUTH, true).with(FourWayBlock.EAST, false).with(FourWayBlock.WEST, false));
        structure.fillWithBlocks(world, start, 61, 6, -34, 61, 7, -27, Blocks.SMOOTH_SANDSTONE.getDefaultState());
        structure.fillWithBlocks(world, start, 61, 6, -26, 64, 6, -17, Blocks.SANDSTONE.getDefaultState());
        structure.fillWithBlocks(world, start, 61, 6, -2, 62, 6, 9, Blocks.SANDSTONE.getDefaultState());
        structure.fillWithBlocks(world, start, 61, 6, 20, 61, 10, 25, Blocks.SANDSTONE.getDefaultState());
        structure.fillWithBlocks(world, start, 61, 7, -2, 62, 7, 9, Blocks.SANDSTONE.getDefaultState());
        structure.fillWithBlocks(world, start, 61, 8, -49, 61, 8, -47, Blocks.OAK_TRAPDOOR.getDefaultState().with(HorizontalBlock.HORIZONTAL_FACING, Direction.SOUTH).with(TrapDoorBlock.HALF, Half.BOTTOM).with(TrapDoorBlock.WATERLOGGED, false).with(TrapDoorBlock.POWERED, false).with(TrapDoorBlock.OPEN, false));
        structure.fillWithBlocks(world, start, 61, 8, -37, 61, 8, -12, Blocks.SANDSTONE.getDefaultState());
        structure.fillWithBlocks(world, start, 61, 9, -37, 61, 9, -33, Blocks.SMOOTH_SANDSTONE.getDefaultState());
        structure.fillWithBlocks(world, start, 61, 9, -31, 62, 9, -30, Blocks.SANDSTONE.getDefaultState());
        structure.fillWithBlocks(world, start, 61, 9, -29, 61, 9, -12, Blocks.SANDSTONE.getDefaultState());
        structure.fillWithBlocks(world, start, 61, 9, 10, 67, 9, 19, Blocks.SPRUCE_PLANKS.getDefaultState());
        structure.fillWithBlocks(world, start, 61, 10, -36, 61, 10, -34, Blocks.SPRUCE_FENCE.getDefaultState().with(FourWayBlock.WATERLOGGED, false).with(FourWayBlock.NORTH, true).with(FourWayBlock.SOUTH, true).with(FourWayBlock.EAST, false).with(FourWayBlock.WEST, false));
        structure.fillWithBlocks(world, start, 61, 10, -18, 61, 10, -13, Blocks.SANDSTONE.getDefaultState());
        structure.fillWithBlocks(world, start, 61, 10, 2, 61, 12, 2, Blocks.SPRUCE_FENCE.getDefaultState().with(FourWayBlock.WATERLOGGED, false).with(FourWayBlock.NORTH, false).with(FourWayBlock.SOUTH, false).with(FourWayBlock.EAST, false).with(FourWayBlock.WEST, false));
        structure.fillWithBlocks(world, start, 61, 10, 6, 61, 12, 6, Blocks.SPRUCE_FENCE.getDefaultState().with(FourWayBlock.WATERLOGGED, false).with(FourWayBlock.NORTH, false).with(FourWayBlock.SOUTH, false).with(FourWayBlock.EAST, false).with(FourWayBlock.WEST, false));
        structure.fillWithBlocks(world, start, 61, 10, 10, 62, 10, 10, Blocks.SANDSTONE.getDefaultState());
        structure.fillWithBlocks(world, start, 61, 11, -31, 61, 12, -31, Blocks.SPRUCE_FENCE.getDefaultState().with(FourWayBlock.WATERLOGGED, false).with(FourWayBlock.NORTH, false).with(FourWayBlock.SOUTH, false).with(FourWayBlock.EAST, true).with(FourWayBlock.WEST, false));
        structure.fillWithBlocks(world, start, 61, 11, -19, 61, 14, -19, Blocks.CUT_SANDSTONE.getDefaultState());
        structure.fillWithBlocks(world, start, 61, 11, -18, 61, 14, -18, Blocks.SMOOTH_SANDSTONE.getDefaultState());
        structure.fillWithBlocks(world, start, 61, 11, -17, 61, 12, -15, Blocks.SPRUCE_FENCE.getDefaultState().with(FourWayBlock.WATERLOGGED, false).with(FourWayBlock.NORTH, true).with(FourWayBlock.SOUTH, true).with(FourWayBlock.EAST, false).with(FourWayBlock.WEST, false));
        structure.fillWithBlocks(world, start, 61, 11, -14, 61, 14, -14, Blocks.SMOOTH_SANDSTONE.getDefaultState());
        structure.fillWithBlocks(world, start, 61, 11, -13, 61, 14, -13, Blocks.CUT_SANDSTONE.getDefaultState());
        structure.fillWithBlocks(world, start, 61, 11, -8, 61, 12, -8, Blocks.SPRUCE_FENCE.getDefaultState().with(FourWayBlock.WATERLOGGED, false).with(FourWayBlock.NORTH, false).with(FourWayBlock.SOUTH, false).with(FourWayBlock.EAST, true).with(FourWayBlock.WEST, true));
        structure.fillWithBlocks(world, start, 61, 11, 20, 61, 13, 22, Blocks.SMOOTH_SANDSTONE.getDefaultState());
        structure.fillWithBlocks(world, start, 61, 11, 23, 61, 12, 23, Blocks.SPRUCE_FENCE.getDefaultState().with(FourWayBlock.WATERLOGGED, false).with(FourWayBlock.NORTH, true).with(FourWayBlock.SOUTH, true).with(FourWayBlock.EAST, false).with(FourWayBlock.WEST, false));
        structure.fillWithBlocks(world, start, 61, 11, 24, 61, 14, 24, Blocks.SMOOTH_SANDSTONE.getDefaultState());
        structure.fillWithBlocks(world, start, 61, 11, 25, 61, 14, 25, Blocks.CUT_SANDSTONE.getDefaultState());
        structure.fillWithBlocks(world, start, 61, 12, -1, 62, 13, -1, Blocks.SMOOTH_SANDSTONE.getDefaultState());
        structure.fillWithBlocks(world, start, 61, 13, -17, 61, 14, -14, Blocks.SMOOTH_SANDSTONE.getDefaultState());
        structure.fillWithBlocks(world, start, 61, 13, -8, 62, 14, -8, Blocks.SMOOTH_SANDSTONE.getDefaultState());
        structure.fillWithBlocks(world, start, 61, 13, 2, 61, 13, 6, Blocks.ORANGE_WOOL.getDefaultState());
        structure.fillWithBlocks(world, start, 61, 13, 23, 61, 14, 24, Blocks.SMOOTH_SANDSTONE.getDefaultState());
        structure.fillWithBlocks(world, start, 61, 14, -31, 61, 14, -28, Blocks.WHITE_WOOL.getDefaultState());
        structure.fillWithBlocks(world, start, 61, 14, -21, 62, 14, -20, Blocks.OAK_TRAPDOOR.getDefaultState().with(HorizontalBlock.HORIZONTAL_FACING, Direction.WEST).with(TrapDoorBlock.HALF, Half.BOTTOM).with(TrapDoorBlock.WATERLOGGED, false).with(TrapDoorBlock.POWERED, false).with(TrapDoorBlock.OPEN, false));
        structure.fillWithBlocks(world, start, 61, 14, -5, 62, 14, -3, Blocks.SPRUCE_SLAB.getDefaultState().with(SlabBlock.TYPE, SlabType.BOTTOM).with(SlabBlock.WATERLOGGED, false));
        structure.fillWithBlocks(world, start, 61, 14, -2, 64, 14, -2, Blocks.SMOOTH_SANDSTONE_SLAB.getDefaultState().with(SlabBlock.TYPE, SlabType.BOTTOM).with(SlabBlock.WATERLOGGED, false));
        structure.fillWithBlocks(world, start, 61, 14, -1, 62, 14, -1, Blocks.SMOOTH_SANDSTONE.getDefaultState());
        structure.fillWithBlocks(world, start, 61, 14, 20, 61, 14, 24, Blocks.SMOOTH_SANDSTONE.getDefaultState());
        structure.fillWithBlocks(world, start, 61, 15, -6, 61, 16, -6, Blocks.SANDSTONE_WALL.getDefaultState().with(WallBlock.WATERLOGGED, false).with(WallBlock.UP, true).with(WallBlock.WALL_HEIGHT_NORTH, WallHeight.LOW).with(WallBlock.WALL_HEIGHT_SOUTH, WallHeight.LOW).with(WallBlock.WALL_HEIGHT_EAST, WallHeight.LOW).with(WallBlock.WALL_HEIGHT_WEST, WallHeight.LOW));
        structure.fillWithBlocks(world, start, 61, 15, 20, 63, 15, 20, Blocks.OAK_TRAPDOOR.getDefaultState().with(HorizontalBlock.HORIZONTAL_FACING, Direction.NORTH).with(TrapDoorBlock.HALF, Half.BOTTOM).with(TrapDoorBlock.WATERLOGGED, false).with(TrapDoorBlock.POWERED, false).with(TrapDoorBlock.OPEN, false));
        structure.fillWithBlocks(world, start, 62, -14, -78, 63, -14, -77, Blocks.SAND.getDefaultState());
        structure.fillWithBlocks(world, start, 62, -12, -22, 62, -12, -16, Blocks.SAND.getDefaultState());
        structure.fillWithBlocks(world, start, 62, -11, -52, 62, -11, -52, Blocks.STONE.getDefaultState());
        structure.fillWithBlocks(world, start, 62, -11, -51, 62, -11, 11, Blocks.SAND.getDefaultState());
        structure.fillWithBlocks(world, start, 62, -11, 12, 62, -11, 61, Blocks.STONE.getDefaultState());
        structure.fillWithBlocks(world, start, 62, -8, 37, 71, -8, 55, Blocks.SANDSTONE.getDefaultState());
        structure.fillWithBlocks(world, start, 62, -7, 37, 80, -7, 55, Blocks.SANDSTONE.getDefaultState());
        structure.fillWithBlocks(world, start, 62, -6, 37, 80, -6, 55, Blocks.SANDSTONE.getDefaultState());
        structure.fillWithBlocks(world, start, 62, -6, 61, 64, -6, 63, Blocks.SAND.getDefaultState());
        structure.fillWithBlocks(world, start, 62, -1, 26, 68, -1, 26, Blocks.SPRUCE_PLANKS.getDefaultState());
        structure.fillWithBlocks(world, start, 62, -1, 27, 62, -1, 31, Blocks.SPRUCE_SLAB.getDefaultState().with(SlabBlock.TYPE, SlabType.BOTTOM).with(SlabBlock.WATERLOGGED, false));
        structure.fillWithBlocks(world, start, 62, -1, 32, 67, -1, 32, Blocks.SMOOTH_SANDSTONE.getDefaultState());
        structure.fillWithBlocks(world, start, 62, 0, -43, 62, 1, -39, Blocks.CUT_SANDSTONE.getDefaultState());
        structure.fillWithBlocks(world, start, 62, 1, -47, 65, 3, -47, Blocks.SMOOTH_SANDSTONE.getDefaultState());
        structure.fillWithBlocks(world, start, 62, 2, -42, 62, 2, -39, Blocks.CUT_SANDSTONE.getDefaultState());
        structure.fillWithBlocks(world, start, 62, 3, -41, 62, 3, -39, Blocks.CUT_SANDSTONE.getDefaultState());
        structure.fillWithBlocks(world, start, 62, 4, -50, 64, 4, -48, Blocks.SPRUCE_SLAB.getDefaultState().with(SlabBlock.TYPE, SlabType.BOTTOM).with(SlabBlock.WATERLOGGED, false));
        structure.fillWithBlocks(world, start, 62, 4, -40, 62, 4, -39, Blocks.CUT_SANDSTONE.getDefaultState());
        structure.fillWithBlocks(world, start, 62, 4, -38, 68, 4, -30, Blocks.SANDSTONE.getDefaultState());
        structure.fillWithBlocks(world, start, 62, 5, -40, 62, 5, -39, Blocks.SANDSTONE_WALL.getDefaultState().with(WallBlock.WATERLOGGED, false).with(WallBlock.UP, true).with(WallBlock.WALL_HEIGHT_NORTH, WallHeight.LOW).with(WallBlock.WALL_HEIGHT_SOUTH, WallHeight.LOW).with(WallBlock.WALL_HEIGHT_EAST, WallHeight.LOW).with(WallBlock.WALL_HEIGHT_WEST, WallHeight.LOW));
        structure.fillWithBlocks(world, start, 62, 5, -31, 65, 5, -16, Blocks.SANDSTONE.getDefaultState());
        structure.fillWithBlocks(world, start, 62, 5, -15, 63, 5, -12, Blocks.SANDSTONE.getDefaultState());
        structure.fillWithBlocks(world, start, 62, 5, 20, 68, 10, 20, Blocks.SANDSTONE.getDefaultState());
        structure.fillWithBlocks(world, start, 62, 5, 25, 72, 5, 25, Blocks.SANDSTONE_WALL.getDefaultState().with(WallBlock.WATERLOGGED, false).with(WallBlock.UP, false).with(WallBlock.WALL_HEIGHT_NORTH, WallHeight.LOW).with(WallBlock.WALL_HEIGHT_SOUTH, WallHeight.LOW).with(WallBlock.WALL_HEIGHT_EAST, WallHeight.LOW).with(WallBlock.WALL_HEIGHT_WEST, WallHeight.LOW));
        structure.fillWithBlocks(world, start, 62, 6, -31, 64, 6, -17, Blocks.SANDSTONE.getDefaultState());
        structure.fillWithBlocks(world, start, 62, 7, -31, 64, 7, -17, Blocks.SANDSTONE.getDefaultState());
        structure.fillWithBlocks(world, start, 62, 8, -36, 62, 8, -32, Blocks.SPRUCE_FENCE.getDefaultState().with(FourWayBlock.WATERLOGGED, false).with(FourWayBlock.NORTH, true).with(FourWayBlock.SOUTH, true).with(FourWayBlock.EAST, true).with(FourWayBlock.WEST, true));
        structure.fillWithBlocks(world, start, 62, 8, -31, 64, 8, -16, Blocks.SANDSTONE.getDefaultState());
        structure.fillWithBlocks(world, start, 62, 9, -37, 63, 9, -32, Blocks.OAK_TRAPDOOR.getDefaultState().with(HorizontalBlock.HORIZONTAL_FACING, Direction.EAST).with(TrapDoorBlock.HALF, Half.BOTTOM).with(TrapDoorBlock.WATERLOGGED, false).with(TrapDoorBlock.POWERED, false).with(TrapDoorBlock.OPEN, false));
        structure.fillWithBlocks(world, start, 62, 9, -29, 62, 9, -29, Blocks.SPRUCE_PLANKS.getDefaultState());
        structure.fillWithBlocks(world, start, 62, 9, -28, 62, 10, -23, Blocks.SANDSTONE.getDefaultState());
        structure.fillWithBlocks(world, start, 62, 9, -18, 64, 9, -16, Blocks.SANDSTONE.getDefaultState());
        structure.fillWithBlocks(world, start, 62, 9, -15, 63, 9, -12, Blocks.SANDSTONE.getDefaultState());
        structure.fillWithBlocks(world, start, 62, 9, -3, 63, 9, -2, Blocks.SPRUCE_PLANKS.getDefaultState());
        structure.fillWithBlocks(world, start, 62, 10, -31, 62, 10, -30, Blocks.SANDSTONE.getDefaultState());
        structure.fillWithBlocks(world, start, 62, 10, -1, 64, 10, -1, Blocks.SANDSTONE.getDefaultState());
        structure.fillWithBlocks(world, start, 62, 10, 9, 62, 10, 10, Blocks.SANDSTONE.getDefaultState());
        structure.fillWithBlocks(world, start, 62, 11, -31, 62, 14, -31, Blocks.CUT_SANDSTONE.getDefaultState());
        structure.fillWithBlocks(world, start, 62, 11, -30, 62, 14, -30, Blocks.SMOOTH_SANDSTONE.getDefaultState());
        structure.fillWithBlocks(world, start, 62, 11, -28, 62, 14, -28, Blocks.SMOOTH_SANDSTONE.getDefaultState());
        structure.fillWithBlocks(world, start, 62, 11, -27, 62, 12, -27, Blocks.SPRUCE_FENCE.getDefaultState().with(FourWayBlock.WATERLOGGED, false).with(FourWayBlock.NORTH, true).with(FourWayBlock.SOUTH, true).with(FourWayBlock.EAST, false).with(FourWayBlock.WEST, false));
        structure.fillWithBlocks(world, start, 62, 11, -26, 62, 13, -24, Blocks.SMOOTH_SANDSTONE.getDefaultState());
        structure.fillWithBlocks(world, start, 62, 11, -23, 62, 14, -23, Blocks.CUT_SANDSTONE.getDefaultState());
        structure.fillWithBlocks(world, start, 62, 11, -8, 62, 14, -8, Blocks.SMOOTH_SANDSTONE.getDefaultState());
        structure.fillWithBlocks(world, start, 62, 11, -1, 62, 14, -1, Blocks.SMOOTH_SANDSTONE.getDefaultState());
        structure.fillWithBlocks(world, start, 62, 11, 9, 62, 14, 9, Blocks.CUT_SANDSTONE.getDefaultState());
        structure.fillWithBlocks(world, start, 62, 11, 20, 65, 14, 20, Blocks.SMOOTH_SANDSTONE.getDefaultState());
        structure.fillWithBlocks(world, start, 62, 12, -29, 62, 13, -28, Blocks.SMOOTH_SANDSTONE.getDefaultState());
        structure.fillWithBlocks(world, start, 62, 12, -2, 64, 12, -2, Index.SHELF_SPRUCE.getDefaultState().with(Shelf.FACING, Direction.NORTH));
        structure.fillWithBlocks(world, start, 62, 13, -27, 62, 14, -24, Blocks.SMOOTH_SANDSTONE.getDefaultState());
        structure.fillWithBlocks(world, start, 62, 13, -21, 63, 13, -20, Blocks.SPRUCE_FENCE.getDefaultState().with(FourWayBlock.WATERLOGGED, false).with(FourWayBlock.NORTH, true).with(FourWayBlock.SOUTH, true).with(FourWayBlock.EAST, true).with(FourWayBlock.WEST, true));
        structure.fillWithBlocks(world, start, 62, 13, -19, 64, 13, -19, Blocks.SPRUCE_FENCE.getDefaultState().with(FourWayBlock.WATERLOGGED, false).with(FourWayBlock.NORTH, true).with(FourWayBlock.SOUTH, false).with(FourWayBlock.EAST, true).with(FourWayBlock.WEST, true));
        structure.fillWithBlocks(world, start, 62, 13, 3, 62, 13, 6, Blocks.ORANGE_WOOL.getDefaultState());
        structure.fillWithBlocks(world, start, 62, 14, -29, 62, 14, -24, Blocks.SMOOTH_SANDSTONE.getDefaultState());
        structure.fillWithBlocks(world, start, 62, 14, -22, 64, 14, -19, Blocks.OAK_TRAPDOOR.getDefaultState().with(HorizontalBlock.HORIZONTAL_FACING, Direction.WEST).with(TrapDoorBlock.HALF, Half.BOTTOM).with(TrapDoorBlock.WATERLOGGED, false).with(TrapDoorBlock.POWERED, false).with(TrapDoorBlock.OPEN, false));
        structure.fillWithBlocks(world, start, 62, 14, -6, 62, 14, -3, Blocks.SPRUCE_SLAB.getDefaultState().with(SlabBlock.TYPE, SlabType.BOTTOM).with(SlabBlock.WATERLOGGED, false));
        structure.fillWithBlocks(world, start, 62, 14, 0, 63, 14, 2, Blocks.ORANGE_WOOL.getDefaultState());
        structure.fillWithBlocks(world, start, 62, 15, -29, 62, 15, -27, Blocks.SPRUCE_FENCE.getDefaultState().with(FourWayBlock.WATERLOGGED, false).with(FourWayBlock.NORTH, true).with(FourWayBlock.SOUTH, true).with(FourWayBlock.EAST, false).with(FourWayBlock.WEST, false));
        structure.fillWithBlocks(world, start, 62, 15, 9, 62, 15, 10, Blocks.SANDSTONE_SLAB.getDefaultState().with(SlabBlock.TYPE, SlabType.BOTTOM).with(SlabBlock.WATERLOGGED, false));
        structure.fillWithBlocks(world, start, 63, -13, -84, 70, -13, -77, Blocks.SAND.getDefaultState());
        structure.fillWithBlocks(world, start, 63, -13, -74, 64, -13, -73, Blocks.SAND.getDefaultState());
        structure.fillWithBlocks(world, start, 63, -12, -72, 65, -12, -70, Blocks.SAND.getDefaultState());
        structure.fillWithBlocks(world, start, 63, -12, -69, 78, -12, -53, Blocks.STONE.getDefaultState());
        structure.fillWithBlocks(world, start, 63, -12, -37, 64, -12, -36, Blocks.STONE.getDefaultState());
        structure.fillWithBlocks(world, start, 63, -12, -35, 63, -9, -32, Blocks.SAND.getDefaultState());
        structure.fillWithBlocks(world, start, 63, -12, -31, 72, -12, -22, Blocks.STONE.getDefaultState());
        structure.fillWithBlocks(world, start, 63, -12, -16, 88, -12, 9, Blocks.STONE.getDefaultState());
        structure.fillWithBlocks(world, start, 63, -12, 67, 70, -12, 74, Blocks.SAND.getDefaultState());
        structure.fillWithBlocks(world, start, 63, -11, -65, 94, -9, -65, Blocks.SAND.getDefaultState());
        structure.fillWithBlocks(world, start, 63, -11, -64, 67, -11, -51, Blocks.STONE.getDefaultState());
        structure.fillWithBlocks(world, start, 63, -11, -50, 63, -11, 13, Blocks.SAND.getDefaultState());
        structure.fillWithBlocks(world, start, 63, -11, 14, 63, -11, 61, Blocks.STONE.getDefaultState());
        structure.fillWithBlocks(world, start, 63, -8, -74, 68, -8, -69, Blocks.SAND.getDefaultState());
        structure.fillWithBlocks(world, start, 63, -7, 56, 72, -7, 65, Blocks.SAND.getDefaultState());
        structure.fillWithBlocks(world, start, 63, -6, -70, 64, -6, -69, Blocks.SAND.getDefaultState());
        structure.fillWithBlocks(world, start, 63, -6, 21, 66, -6, 31, Blocks.SPRUCE_PLANKS.getDefaultState());
        structure.fillWithBlocks(world, start, 63, -5, 35, 63, -2, 35, Blocks.SPRUCE_FENCE.getDefaultState().with(FourWayBlock.WATERLOGGED, false).with(FourWayBlock.NORTH, false).with(FourWayBlock.SOUTH, false).with(FourWayBlock.EAST, false).with(FourWayBlock.WEST, false));
        structure.fillWithBlocks(world, start, 63, -4, -53, 63, -4, -53, Blocks.SMOOTH_SANDSTONE.getDefaultState());
        structure.fillWithBlocks(world, start, 63, -4, 19, 64, -4, 20, Blocks.SANDSTONE.getDefaultState());
        structure.fillWithBlocks(world, start, 63, -4, 32, 63, -3, 32, Blocks.SPRUCE_FENCE.getDefaultState().with(FourWayBlock.WATERLOGGED, false).with(FourWayBlock.NORTH, false).with(FourWayBlock.SOUTH, false).with(FourWayBlock.EAST, true).with(FourWayBlock.WEST, true));
        structure.fillWithBlocks(world, start, 63, -3, -53, 63, -3, -53, Blocks.SMOOTH_SANDSTONE.getDefaultState());
        structure.fillWithBlocks(world, start, 63, -3, 19, 64, -3, 20, Blocks.SANDSTONE.getDefaultState());
        structure.fillWithBlocks(world, start, 63, -2, 19, 64, -2, 20, Blocks.SANDSTONE.getDefaultState());
        structure.fillWithBlocks(world, start, 63, -1, 27, 66, -1, 27, Blocks.SPRUCE_SLAB.getDefaultState().with(SlabBlock.TYPE, SlabType.BOTTOM).with(SlabBlock.WATERLOGGED, false));
        structure.fillWithBlocks(world, start, 63, -1, 28, 65, 0, 28, Blocks.SPRUCE_SLAB.getDefaultState().with(SlabBlock.TYPE, SlabType.DOUBLE).with(SlabBlock.WATERLOGGED, false));
        structure.fillWithBlocks(world, start, 63, -1, 29, 65, -1, 31, Blocks.SPRUCE_SLAB.getDefaultState().with(SlabBlock.TYPE, SlabType.BOTTOM).with(SlabBlock.WATERLOGGED, false));
        structure.fillWithBlocks(world, start, 63, -1, 33, 64, -1, 35, Blocks.WHITE_WOOL.getDefaultState());
        structure.fillWithBlocks(world, start, 63, 0, -51, 64, 0, -51, ModBlocks.CHAIR.get().getDefaultState().with(ChairBlock.FACING, Direction.SOUTH));
        structure.fillWithBlocks(world, start, 63, 0, -49, 64, 0, -49, ModBlocks.CHAIR.get().getDefaultState().with(ChairBlock.FACING, Direction.NORTH));
        structure.fillWithBlocks(world, start, 63, 0, -43, 64, 0, -43, Blocks.SANDSTONE_STAIRS.getDefaultState().with(StairsBlock.FACING, Direction.SOUTH).with(StairsBlock.WATERLOGGED, false).with(StairsBlock.SHAPE, StairsShape.STRAIGHT).with(StairsBlock.HALF, Half.BOTTOM));
        structure.fillWithBlocks(world, start, 63, 0, -42, 79, 0, -25, Blocks.SANDSTONE.getDefaultState());
        structure.fillWithBlocks(world, start, 63, 0, 26, 63, 2, 26, Blocks.SPRUCE_FENCE.getDefaultState().with(FourWayBlock.WATERLOGGED, false).with(FourWayBlock.NORTH, true).with(FourWayBlock.SOUTH, false).with(FourWayBlock.EAST, false).with(FourWayBlock.WEST, false));
        structure.fillWithBlocks(world, start, 63, 1, -53, 67, 4, -53, Blocks.SMOOTH_SANDSTONE.getDefaultState());
        structure.fillWithBlocks(world, start, 63, 1, -42, 64, 1, -42, Blocks.SANDSTONE_STAIRS.getDefaultState().with(StairsBlock.FACING, Direction.SOUTH).with(StairsBlock.WATERLOGGED, false).with(StairsBlock.SHAPE, StairsShape.STRAIGHT).with(StairsBlock.HALF, Half.BOTTOM));
        structure.fillWithBlocks(world, start, 63, 1, -41, 78, 1, -12, Blocks.SANDSTONE.getDefaultState());
        structure.fillWithBlocks(world, start, 63, 1, 28, 63, 2, 28, Blocks.SPRUCE_FENCE.getDefaultState().with(FourWayBlock.WATERLOGGED, false).with(FourWayBlock.NORTH, false).with(FourWayBlock.SOUTH, false).with(FourWayBlock.EAST, true).with(FourWayBlock.WEST, false));
        structure.fillWithBlocks(world, start, 63, 2, -46, 63, 2, -46, Blocks.SPRUCE_SLAB.getDefaultState().with(SlabBlock.TYPE, SlabType.TOP).with(SlabBlock.WATERLOGGED, false));
        structure.fillWithBlocks(world, start, 63, 2, -41, 64, 2, -41, Blocks.SANDSTONE_STAIRS.getDefaultState().with(StairsBlock.FACING, Direction.SOUTH).with(StairsBlock.WATERLOGGED, false).with(StairsBlock.SHAPE, StairsShape.STRAIGHT).with(StairsBlock.HALF, Half.BOTTOM));
        structure.fillWithBlocks(world, start, 63, 2, -40, 78, 2, -12, Blocks.SANDSTONE.getDefaultState());
        structure.fillWithBlocks(world, start, 63, 3, -40, 64, 3, -40, Blocks.SANDSTONE_STAIRS.getDefaultState().with(StairsBlock.FACING, Direction.SOUTH).with(StairsBlock.WATERLOGGED, false).with(StairsBlock.SHAPE, StairsShape.STRAIGHT).with(StairsBlock.HALF, Half.BOTTOM));
        structure.fillWithBlocks(world, start, 63, 3, -39, 78, 3, -12, Blocks.SANDSTONE.getDefaultState());
        structure.fillWithBlocks(world, start, 63, 3, 26, 65, 3, 28, Blocks.SPRUCE_SLAB.getDefaultState().with(SlabBlock.TYPE, SlabType.DOUBLE).with(SlabBlock.WATERLOGGED, false));
        structure.fillWithBlocks(world, start, 63, 4, -52, 67, 4, -48, Blocks.SPRUCE_SLAB.getDefaultState().with(SlabBlock.TYPE, SlabType.BOTTOM).with(SlabBlock.WATERLOGGED, false));
        structure.fillWithBlocks(world, start, 63, 4, -39, 64, 4, -39, Blocks.SANDSTONE_STAIRS.getDefaultState().with(StairsBlock.FACING, Direction.SOUTH).with(StairsBlock.WATERLOGGED, false).with(StairsBlock.SHAPE, StairsShape.STRAIGHT).with(StairsBlock.HALF, Half.BOTTOM));
        structure.fillWithBlocks(world, start, 63, 4, -15, 70, 4, -7, Blocks.SPRUCE_PLANKS.getDefaultState());
        structure.fillWithBlocks(world, start, 63, 4, -4, 64, 4, -3, Blocks.SANDSTONE.getDefaultState());
        structure.fillWithBlocks(world, start, 63, 4, 26, 65, 4, 28, Blocks.SPRUCE_SLAB.getDefaultState().with(SlabBlock.TYPE, SlabType.DOUBLE).with(SlabBlock.WATERLOGGED, false));
        structure.fillWithBlocks(world, start, 63, 5, -11, 63, 5, -8, Blocks.SANDSTONE.getDefaultState());
        structure.fillWithBlocks(world, start, 63, 5, -4, 64, 5, -3, Blocks.SANDSTONE.getDefaultState());
        structure.fillWithBlocks(world, start, 63, 5, 16, 65, 5, 16, Index.STOOL_OAK.getDefaultState().with(Stool.PILLOW, StoolState.NONE));
        structure.fillWithBlocks(world, start, 63, 5, 26, 63, 5, 28, Blocks.SPRUCE_SLAB.getDefaultState().with(SlabBlock.TYPE, SlabType.BOTTOM).with(SlabBlock.WATERLOGGED, false));
        structure.fillWithBlocks(world, start, 63, 6, -15, 63, 7, -8, Blocks.SMOOTH_SANDSTONE.getDefaultState());
        structure.fillWithBlocks(world, start, 63, 6, -4, 63, 6, -4, Blocks.SMOOTH_SANDSTONE.getDefaultState());
        structure.fillWithBlocks(world, start, 63, 6, -2, 63, 7, 5, Blocks.SMOOTH_SANDSTONE.getDefaultState());
        structure.fillWithBlocks(world, start, 63, 6, 6, 63, 6, 9, Blocks.SANDSTONE.getDefaultState());
        structure.fillWithBlocks(world, start, 63, 7, -16, 63, 7, -8, Blocks.SMOOTH_SANDSTONE.getDefaultState());
        structure.fillWithBlocks(world, start, 63, 7, -4, 64, 7, -3, Blocks.SMOOTH_SANDSTONE.getDefaultState());
        structure.fillWithBlocks(world, start, 63, 7, 6, 72, 7, 6, Blocks.SMOOTH_SANDSTONE.getDefaultState());
        structure.fillWithBlocks(world, start, 63, 7, 7, 65, 7, 9, Blocks.SANDSTONE.getDefaultState());
        structure.fillWithBlocks(world, start, 63, 7, 19, 65, 7, 19, Index.CABINET_OAK.getDefaultState().with(Cabinet.FACING, Direction.NORTH).with(Cabinet.WATERLOGGED, false));
        structure.fillWithBlocks(world, start, 63, 8, -36, 63, 8, -34, Blocks.SPRUCE_FENCE.getDefaultState().with(FourWayBlock.WATERLOGGED, false).with(FourWayBlock.NORTH, true).with(FourWayBlock.SOUTH, true).with(FourWayBlock.EAST, false).with(FourWayBlock.WEST, true));
        structure.fillWithBlocks(world, start, 63, 8, -33, 63, 8, -32, Blocks.SPRUCE_FENCE.getDefaultState().with(FourWayBlock.WATERLOGGED, false).with(FourWayBlock.NORTH, true).with(FourWayBlock.SOUTH, true).with(FourWayBlock.EAST, true).with(FourWayBlock.WEST, true));
        structure.fillWithBlocks(world, start, 63, 8, -11, 63, 9, -8, Blocks.SANDSTONE.getDefaultState());
        structure.fillWithBlocks(world, start, 63, 8, -4, 64, 8, -3, Blocks.SANDSTONE.getDefaultState());
        structure.fillWithBlocks(world, start, 63, 8, 19, 64, 8, 20, Blocks.SANDSTONE.getDefaultState());
        structure.fillWithBlocks(world, start, 63, 9, -31, 69, 10, -31, Blocks.SANDSTONE.getDefaultState());
        structure.fillWithBlocks(world, start, 63, 9, -30, 68, 9, -24, Blocks.SPRUCE_PLANKS.getDefaultState());
        structure.fillWithBlocks(world, start, 63, 9, -23, 65, 9, -16, Blocks.SANDSTONE.getDefaultState());
        structure.fillWithBlocks(world, start, 63, 9, -7, 66, 9, -2, Blocks.SPRUCE_PLANKS.getDefaultState());
        structure.fillWithBlocks(world, start, 63, 10, -24, 65, 12, -24, Blocks.BOOKSHELF.getDefaultState());
        structure.fillWithBlocks(world, start, 63, 10, -23, 65, 10, -23, Blocks.SANDSTONE.getDefaultState());
        structure.fillWithBlocks(world, start, 63, 10, -7, 71, 10, -7, Blocks.SANDSTONE.getDefaultState());
        structure.fillWithBlocks(world, start, 63, 10, 0, 63, 10, 1, Blocks.BARREL.getDefaultState().with(BarrelBlock.PROPERTY_FACING, Direction.WEST).with(BarrelBlock.PROPERTY_OPEN, false));
        structure.fillWithBlocks(world, start, 63, 10, 9, 68, 10, 9, Blocks.SANDSTONE.getDefaultState());
        structure.fillWithBlocks(world, start, 63, 11, -31, 63, 14, -31, Blocks.SMOOTH_SANDSTONE.getDefaultState());
        structure.fillWithBlocks(world, start, 63, 11, -23, 65, 13, -23, Blocks.SMOOTH_SANDSTONE.getDefaultState());
        structure.fillWithBlocks(world, start, 63, 11, -8, 63, 12, -7, Blocks.CUT_SANDSTONE.getDefaultState());
        structure.fillWithBlocks(world, start, 63, 11, -1, 63, 14, -1, Blocks.CUT_SANDSTONE.getDefaultState());
        structure.fillWithBlocks(world, start, 63, 11, 9, 63, 14, 9, Blocks.SMOOTH_SANDSTONE.getDefaultState());
        structure.fillWithBlocks(world, start, 63, 13, -22, 64, 13, -20, Blocks.SPRUCE_FENCE.getDefaultState().with(FourWayBlock.WATERLOGGED, false).with(FourWayBlock.NORTH, true).with(FourWayBlock.SOUTH, true).with(FourWayBlock.EAST, true).with(FourWayBlock.WEST, true));
        structure.fillWithBlocks(world, start, 63, 13, -8, 63, 13, -7, Blocks.CUT_SANDSTONE.getDefaultState());
        structure.fillWithBlocks(world, start, 63, 13, -6, 69, 13, -6, Blocks.SMOOTH_SANDSTONE_SLAB.getDefaultState().with(SlabBlock.TYPE, SlabType.TOP).with(SlabBlock.WATERLOGGED, false));
        structure.fillWithBlocks(world, start, 63, 14, -30, 68, 14, -24, Blocks.SPRUCE_SLAB.getDefaultState().with(SlabBlock.TYPE, SlabType.BOTTOM).with(SlabBlock.WATERLOGGED, false));
        structure.fillWithBlocks(world, start, 63, 14, -23, 65, 14, -23, Blocks.SMOOTH_SANDSTONE.getDefaultState());
        structure.fillWithBlocks(world, start, 63, 14, -6, 63, 14, -5, Blocks.SMOOTH_SANDSTONE.getDefaultState());
        structure.fillWithBlocks(world, start, 63, 14, -4, 64, 14, -3, Blocks.SPRUCE_SLAB.getDefaultState().with(SlabBlock.TYPE, SlabType.BOTTOM).with(SlabBlock.WATERLOGGED, false));
        structure.fillWithBlocks(world, start, 63, 14, 3, 63, 14, 6, Blocks.ORANGE_WOOL.getDefaultState());
        structure.fillWithBlocks(world, start, 63, 14, 10, 63, 14, 19, Blocks.SPRUCE_SLAB.getDefaultState().with(SlabBlock.TYPE, SlabType.BOTTOM).with(SlabBlock.WATERLOGGED, false));
        structure.fillWithBlocks(world, start, 64, -14, -78, 65, -14, -77, Blocks.SAND.getDefaultState());
        structure.fillWithBlocks(world, start, 64, -12, -35, 74, -12, 19, Blocks.STONE.getDefaultState());
        structure.fillWithBlocks(world, start, 64, -11, -81, 80, -11, -65, Blocks.SAND.getDefaultState());
        structure.fillWithBlocks(world, start, 64, -11, -50, 67, -11, -50, Blocks.STONE.getDefaultState());
        structure.fillWithBlocks(world, start, 64, -11, -49, 87, -11, -14, Blocks.SAND.getDefaultState());
        structure.fillWithBlocks(world, start, 64, -11, -11, 71, -11, -3, Blocks.SAND.getDefaultState());
        structure.fillWithBlocks(world, start, 64, -11, 11, 73, -11, 23, Blocks.SAND.getDefaultState());
        structure.fillWithBlocks(world, start, 64, -11, 24, 64, -11, 61, Blocks.STONE.getDefaultState());
        structure.fillWithBlocks(world, start, 64, -7, -53, 64, -7, -53, Blocks.SAND.getDefaultState());
        structure.fillWithBlocks(world, start, 64, -7, -52, 64, -5, -50, Blocks.SANDSTONE.getDefaultState());
        structure.fillWithBlocks(world, start, 64, -7, -49, 68, -7, -45, Blocks.SAND.getDefaultState());
        structure.fillWithBlocks(world, start, 64, -6, -71, 66, -6, -69, Blocks.SAND.getDefaultState());
        structure.fillWithBlocks(world, start, 64, -6, -49, 68, -6, -45, Blocks.SPRUCE_PLANKS.getDefaultState());
        structure.fillWithBlocks(world, start, 64, -5, 27, 64, -5, 29, Blocks.CUT_SANDSTONE_SLAB.getDefaultState().with(SlabBlock.TYPE, SlabType.TOP).with(SlabBlock.WATERLOGGED, false));
        structure.fillWithBlocks(world, start, 64, -4, -53, 64, -3, -51, Blocks.SMOOTH_SANDSTONE.getDefaultState());
        structure.fillWithBlocks(world, start, 64, -4, -50, 64, -2, -50, Blocks.CUT_SANDSTONE.getDefaultState());
        structure.fillWithBlocks(world, start, 64, -4, 32, 64, -1, 32, Blocks.SMOOTH_SANDSTONE.getDefaultState());
        structure.fillWithBlocks(world, start, 64, -2, -52, 64, -1, -51, Blocks.SMOOTH_SANDSTONE.getDefaultState());
        structure.fillWithBlocks(world, start, 64, 0, 32, 65, 0, 32, Blocks.SPRUCE_FENCE.getDefaultState().with(FourWayBlock.WATERLOGGED, false).with(FourWayBlock.NORTH, false).with(FourWayBlock.SOUTH, false).with(FourWayBlock.EAST, true).with(FourWayBlock.WEST, true));
        structure.fillWithBlocks(world, start, 64, 1, 28, 64, 2, 28, Blocks.SPRUCE_FENCE.getDefaultState().with(FourWayBlock.WATERLOGGED, false).with(FourWayBlock.NORTH, false).with(FourWayBlock.SOUTH, false).with(FourWayBlock.EAST, true).with(FourWayBlock.WEST, true));
        structure.fillWithBlocks(world, start, 64, 2, -46, 64, 2, -45, Blocks.SPRUCE_SLAB.getDefaultState().with(SlabBlock.TYPE, SlabType.TOP).with(SlabBlock.WATERLOGGED, false));
        structure.fillWithBlocks(world, start, 64, 4, -6, 65, 4, -5, Blocks.SPRUCE_PLANKS.getDefaultState());
        structure.fillWithBlocks(world, start, 64, 4, -2, 71, 4, 5, Blocks.SPRUCE_PLANKS.getDefaultState());
        structure.fillWithBlocks(world, start, 64, 4, 6, 67, 4, 9, Blocks.SANDSTONE.getDefaultState());
        structure.fillWithBlocks(world, start, 64, 5, -53, 65, 5, -53, Blocks.SANDSTONE_SLAB.getDefaultState().with(SlabBlock.TYPE, SlabType.BOTTOM).with(SlabBlock.WATERLOGGED, false));
        structure.fillWithBlocks(world, start, 64, 5, -33, 64, 7, -33, Blocks.SPRUCE_FENCE.getDefaultState().with(FourWayBlock.WATERLOGGED, false).with(FourWayBlock.NORTH, false).with(FourWayBlock.SOUTH, false).with(FourWayBlock.EAST, false).with(FourWayBlock.WEST, false));
        structure.fillWithBlocks(world, start, 64, 5, 6, 67, 5, 9, Blocks.SANDSTONE.getDefaultState());
        structure.fillWithBlocks(world, start, 64, 5, 26, 64, 5, 26, Blocks.SPRUCE_SLAB.getDefaultState().with(SlabBlock.TYPE, SlabType.BOTTOM).with(SlabBlock.WATERLOGGED, false));
        structure.fillWithBlocks(world, start, 64, 5, 28, 65, 5, 28, Blocks.SPRUCE_SLAB.getDefaultState().with(SlabBlock.TYPE, SlabType.BOTTOM).with(SlabBlock.WATERLOGGED, false));
        structure.fillWithBlocks(world, start, 64, 6, -16, 70, 7, -16, Blocks.SMOOTH_SANDSTONE.getDefaultState());
        structure.fillWithBlocks(world, start, 64, 6, -4, 65, 6, -3, Blocks.SMOOTH_SANDSTONE.getDefaultState());
        structure.fillWithBlocks(world, start, 64, 6, 6, 70, 7, 6, Blocks.SMOOTH_SANDSTONE.getDefaultState());
        structure.fillWithBlocks(world, start, 64, 6, 7, 66, 6, 9, Blocks.SANDSTONE.getDefaultState());
        structure.fillWithBlocks(world, start, 64, 7, 1, 64, 7, 2, Index.SHELF_OAK.getDefaultState().with(Shelf.FACING, Direction.EAST));
        structure.fillWithBlocks(world, start, 64, 8, 6, 64, 8, 9, Blocks.SANDSTONE.getDefaultState());
        structure.fillWithBlocks(world, start, 64, 9, -33, 64, 9, -32, Blocks.OAK_TRAPDOOR.getDefaultState().with(HorizontalBlock.HORIZONTAL_FACING, Direction.EAST).with(TrapDoorBlock.HALF, Half.BOTTOM).with(TrapDoorBlock.WATERLOGGED, false).with(TrapDoorBlock.POWERED, false).with(TrapDoorBlock.OPEN, false));
        structure.fillWithBlocks(world, start, 64, 9, -15, 70, 9, -8, Blocks.SPRUCE_PLANKS.getDefaultState());
        structure.fillWithBlocks(world, start, 64, 9, -1, 69, 9, 5, Blocks.SPRUCE_PLANKS.getDefaultState());
        structure.fillWithBlocks(world, start, 64, 9, 6, 68, 10, 6, Blocks.SANDSTONE.getDefaultState());
        structure.fillWithBlocks(world, start, 64, 9, 7, 64, 9, 8, Blocks.SANDSTONE_STAIRS.getDefaultState().with(StairsBlock.FACING, Direction.WEST).with(StairsBlock.WATERLOGGED, false).with(StairsBlock.SHAPE, StairsShape.STRAIGHT).with(StairsBlock.HALF, Half.BOTTOM));
        structure.fillWithBlocks(world, start, 64, 9, 9, 68, 10, 9, Blocks.SANDSTONE.getDefaultState());
        structure.fillWithBlocks(world, start, 64, 10, -15, 64, 10, -13, Blocks.BARREL.getDefaultState().with(BarrelBlock.PROPERTY_FACING, Direction.WEST).with(BarrelBlock.PROPERTY_OPEN, false));
        structure.fillWithBlocks(world, start, 64, 10, -6, 66, 12, -6, Blocks.BOOKSHELF.getDefaultState());
        structure.fillWithBlocks(world, start, 64, 10, 0, 64, 10, 3, Blocks.SANDSTONE.getDefaultState());
        structure.fillWithBlocks(world, start, 64, 10, 5, 64, 10, 6, Blocks.SANDSTONE.getDefaultState());
        structure.fillWithBlocks(world, start, 64, 11, -31, 66, 12, -31, Blocks.SPRUCE_FENCE.getDefaultState().with(FourWayBlock.WATERLOGGED, false).with(FourWayBlock.NORTH, false).with(FourWayBlock.SOUTH, false).with(FourWayBlock.EAST, true).with(FourWayBlock.WEST, true));
        structure.fillWithBlocks(world, start, 64, 11, -7, 66, 13, -7, Blocks.SANDSTONE.getDefaultState());
        structure.fillWithBlocks(world, start, 64, 11, -1, 64, 14, -1, Blocks.SMOOTH_SANDSTONE.getDefaultState());
        structure.fillWithBlocks(world, start, 64, 11, 0, 64, 12, 2, Blocks.SPRUCE_FENCE.getDefaultState().with(FourWayBlock.WATERLOGGED, false).with(FourWayBlock.NORTH, true).with(FourWayBlock.SOUTH, true).with(FourWayBlock.EAST, false).with(FourWayBlock.WEST, false));
        structure.fillWithBlocks(world, start, 64, 11, 3, 64, 14, 3, Blocks.SMOOTH_SANDSTONE.getDefaultState());
        structure.fillWithBlocks(world, start, 64, 11, 5, 64, 14, 5, Blocks.SMOOTH_SANDSTONE.getDefaultState());
        structure.fillWithBlocks(world, start, 64, 11, 6, 64, 14, 6, Blocks.CUT_SANDSTONE.getDefaultState());
        structure.fillWithBlocks(world, start, 64, 11, 9, 66, 12, 9, Blocks.SPRUCE_FENCE.getDefaultState().with(FourWayBlock.WATERLOGGED, false).with(FourWayBlock.NORTH, false).with(FourWayBlock.SOUTH, false).with(FourWayBlock.EAST, true).with(FourWayBlock.WEST, true));
        structure.fillWithBlocks(world, start, 64, 12, 4, 64, 13, 5, Blocks.SMOOTH_SANDSTONE.getDefaultState());
        structure.fillWithBlocks(world, start, 64, 13, -31, 68, 14, -31, Blocks.SMOOTH_SANDSTONE.getDefaultState());
        structure.fillWithBlocks(world, start, 64, 13, -10, 66, 13, -10, Blocks.PURPLE_WOOL.getDefaultState());
        structure.fillWithBlocks(world, start, 64, 13, 0, 64, 14, 5, Blocks.SMOOTH_SANDSTONE.getDefaultState());
        structure.fillWithBlocks(world, start, 64, 13, 7, 64, 13, 8, Blocks.SPRUCE_FENCE.getDefaultState().with(FourWayBlock.WATERLOGGED, false).with(FourWayBlock.NORTH, true).with(FourWayBlock.SOUTH, true).with(FourWayBlock.EAST, true).with(FourWayBlock.WEST, false));
        structure.fillWithBlocks(world, start, 64, 13, 9, 67, 14, 9, Blocks.SMOOTH_SANDSTONE.getDefaultState());
        structure.fillWithBlocks(world, start, 64, 14, -9, 66, 14, -9, Blocks.PURPLE_WOOL.getDefaultState());
        structure.fillWithBlocks(world, start, 64, 14, -8, 66, 14, -6, Blocks.SPRUCE_FENCE.getDefaultState().with(FourWayBlock.WATERLOGGED, false).with(FourWayBlock.NORTH, true).with(FourWayBlock.SOUTH, true).with(FourWayBlock.EAST, true).with(FourWayBlock.WEST, true));
        structure.fillWithBlocks(world, start, 64, 14, 7, 65, 14, 8, Blocks.OAK_TRAPDOOR.getDefaultState().with(HorizontalBlock.HORIZONTAL_FACING, Direction.WEST).with(TrapDoorBlock.HALF, Half.BOTTOM).with(TrapDoorBlock.WATERLOGGED, false).with(TrapDoorBlock.POWERED, false).with(TrapDoorBlock.OPEN, false));
        structure.fillWithBlocks(world, start, 64, 14, 10, 64, 14, 12, Blocks.SPRUCE_SLAB.getDefaultState().with(SlabBlock.TYPE, SlabType.DOUBLE).with(SlabBlock.WATERLOGGED, false));
        structure.fillWithBlocks(world, start, 64, 14, 13, 64, 14, 19, Blocks.SPRUCE_SLAB.getDefaultState().with(SlabBlock.TYPE, SlabType.BOTTOM).with(SlabBlock.WATERLOGGED, false));
        structure.fillWithBlocks(world, start, 64, 15, -31, 66, 15, -31, Blocks.SPRUCE_FENCE.getDefaultState().with(FourWayBlock.WATERLOGGED, false).with(FourWayBlock.NORTH, false).with(FourWayBlock.SOUTH, false).with(FourWayBlock.EAST, true).with(FourWayBlock.WEST, true));
        structure.fillWithBlocks(world, start, 64, 15, -8, 66, 15, -6, Blocks.OAK_TRAPDOOR.getDefaultState().with(HorizontalBlock.HORIZONTAL_FACING, Direction.NORTH).with(TrapDoorBlock.HALF, Half.BOTTOM).with(TrapDoorBlock.WATERLOGGED, false).with(TrapDoorBlock.POWERED, false).with(TrapDoorBlock.OPEN, false));
        structure.fillWithBlocks(world, start, 65, -13, -74, 65, -12, -73, Blocks.SAND.getDefaultState());
        structure.fillWithBlocks(world, start, 65, -12, -37, 74, -12, 19, Blocks.STONE.getDefaultState());
        structure.fillWithBlocks(world, start, 65, -12, 66, 73, -12, 74, Blocks.SAND.getDefaultState());
        structure.fillWithBlocks(world, start, 65, -11, 24, 67, -11, 26, Blocks.SAND.getDefaultState());
        structure.fillWithBlocks(world, start, 65, -11, 27, 65, -11, 61, Blocks.STONE.getDefaultState());
        structure.fillWithBlocks(world, start, 65, -8, 33, 71, -8, 55, Blocks.SANDSTONE.getDefaultState());
        structure.fillWithBlocks(world, start, 65, -7, -74, 70, -7, -69, Blocks.SAND.getDefaultState());
        structure.fillWithBlocks(world, start, 65, -7, -53, 71, -7, -45, Blocks.SAND.getDefaultState());
        structure.fillWithBlocks(world, start, 65, -7, -44, 65, -5, -44, Blocks.SANDSTONE.getDefaultState());
        structure.fillWithBlocks(world, start, 65, -7, -43, 79, -7, 17, Blocks.SAND.getDefaultState());
        structure.fillWithBlocks(world, start, 65, -7, 21, 66, -7, 31, Blocks.SAND.getDefaultState());
        structure.fillWithBlocks(world, start, 65, -7, 33, 72, -7, 55, Blocks.SANDSTONE.getDefaultState());
        structure.fillWithBlocks(world, start, 65, -6, -52, 70, -6, -45, Blocks.SPRUCE_PLANKS.getDefaultState());
        structure.fillWithBlocks(world, start, 65, -6, 33, 72, -6, 55, Blocks.SANDSTONE.getDefaultState());
        structure.fillWithBlocks(world, start, 65, -6, 61, 67, -6, 63, Blocks.SAND.getDefaultState());
        structure.fillWithBlocks(world, start, 65, -5, -55, 65, -5, -54, Blocks.BARREL.getDefaultState().with(BarrelBlock.PROPERTY_FACING, Direction.EAST).with(BarrelBlock.PROPERTY_OPEN, false));
        structure.fillWithBlocks(world, start, 65, -5, 27, 65, -5, 29, Index.STOOL_OAK.getDefaultState().with(Stool.PILLOW, StoolState.NONE));
        structure.fillWithBlocks(world, start, 65, -4, -53, 66, -3, -53, Blocks.SMOOTH_SANDSTONE.getDefaultState());
        structure.fillWithBlocks(world, start, 65, -4, 19, 66, -4, 20, Blocks.SANDSTONE.getDefaultState());
        structure.fillWithBlocks(world, start, 65, -3, 19, 66, -3, 20, Blocks.SANDSTONE.getDefaultState());
        structure.fillWithBlocks(world, start, 65, -3, 32, 66, -2, 32, Blocks.SMOOTH_SANDSTONE.getDefaultState());
        structure.fillWithBlocks(world, start, 65, -2, -56, 66, -2, -56, Blocks.SPRUCE_FENCE.getDefaultState().with(FourWayBlock.WATERLOGGED, false).with(FourWayBlock.NORTH, false).with(FourWayBlock.SOUTH, true).with(FourWayBlock.EAST, true).with(FourWayBlock.WEST, true));
        structure.fillWithBlocks(world, start, 65, -2, -55, 66, -2, -54, Blocks.SPRUCE_FENCE.getDefaultState().with(FourWayBlock.WATERLOGGED, false).with(FourWayBlock.NORTH, true).with(FourWayBlock.SOUTH, true).with(FourWayBlock.EAST, true).with(FourWayBlock.WEST, true));
        structure.fillWithBlocks(world, start, 65, -2, 19, 66, -2, 20, Blocks.SANDSTONE.getDefaultState());
        structure.fillWithBlocks(world, start, 65, -2, 35, 66, -2, 35, Blocks.WHITE_WOOL.getDefaultState());
        structure.fillWithBlocks(world, start, 65, -1, -56, 67, -1, -54, Blocks.OAK_TRAPDOOR.getDefaultState().with(HorizontalBlock.HORIZONTAL_FACING, Direction.NORTH).with(TrapDoorBlock.HALF, Half.BOTTOM).with(TrapDoorBlock.WATERLOGGED, false).with(TrapDoorBlock.POWERED, false).with(TrapDoorBlock.OPEN, false));
        structure.fillWithBlocks(world, start, 65, -1, -44, 65, 4, -44, Blocks.CUT_SANDSTONE.getDefaultState());
        structure.fillWithBlocks(world, start, 65, -1, -43, 73, -1, 17, Blocks.SANDSTONE.getDefaultState());
        structure.fillWithBlocks(world, start, 65, -1, 33, 65, -1, 34, Blocks.WHITE_WOOL.getDefaultState());
        structure.fillWithBlocks(world, start, 65, 0, -46, 65, 0, -45, Blocks.SANDSTONE.getDefaultState());
        structure.fillWithBlocks(world, start, 65, 0, -43, 79, 0, -25, Blocks.SANDSTONE.getDefaultState());
        structure.fillWithBlocks(world, start, 65, 0, 26, 65, 2, 26, Blocks.SPRUCE_FENCE.getDefaultState().with(FourWayBlock.WATERLOGGED, false).with(FourWayBlock.NORTH, true).with(FourWayBlock.SOUTH, false).with(FourWayBlock.EAST, false).with(FourWayBlock.WEST, false));
        structure.fillWithBlocks(world, start, 65, 1, -46, 65, 2, -45, Blocks.SMOOTH_SANDSTONE.getDefaultState());
        structure.fillWithBlocks(world, start, 65, 1, -43, 79, 1, -29, Blocks.SANDSTONE.getDefaultState());
        structure.fillWithBlocks(world, start, 65, 1, 28, 65, 2, 28, Blocks.SPRUCE_FENCE.getDefaultState().with(FourWayBlock.WATERLOGGED, false).with(FourWayBlock.NORTH, false).with(FourWayBlock.SOUTH, false).with(FourWayBlock.EAST, false).with(FourWayBlock.WEST, true));
        structure.fillWithBlocks(world, start, 65, 2, -43, 79, 2, -29, Blocks.SANDSTONE.getDefaultState());
        structure.fillWithBlocks(world, start, 65, 3, -46, 65, 4, -45, Blocks.SMOOTH_SANDSTONE.getDefaultState());
        structure.fillWithBlocks(world, start, 65, 3, -43, 79, 3, -29, Blocks.SANDSTONE.getDefaultState());
        structure.fillWithBlocks(world, start, 65, 4, -47, 65, 4, -45, Blocks.SMOOTH_SANDSTONE.getDefaultState());
        structure.fillWithBlocks(world, start, 65, 4, -43, 68, 4, -30, Blocks.SANDSTONE.getDefaultState());
        structure.fillWithBlocks(world, start, 65, 4, -4, 66, 4, -3, Blocks.SANDSTONE.getDefaultState());
        structure.fillWithBlocks(world, start, 65, 5, -42, 65, 5, -40, Blocks.SANDSTONE_WALL.getDefaultState().with(WallBlock.WATERLOGGED, false).with(WallBlock.UP, false).with(WallBlock.WALL_HEIGHT_NORTH, WallHeight.LOW).with(WallBlock.WALL_HEIGHT_SOUTH, WallHeight.LOW).with(WallBlock.WALL_HEIGHT_EAST, WallHeight.LOW).with(WallBlock.WALL_HEIGHT_WEST, WallHeight.LOW));
        structure.fillWithBlocks(world, start, 65, 5, -4, 66, 5, -3, Blocks.SANDSTONE.getDefaultState());
        structure.fillWithBlocks(world, start, 65, 5, 26, 65, 5, 28, Blocks.SPRUCE_SLAB.getDefaultState().with(SlabBlock.TYPE, SlabType.BOTTOM).with(SlabBlock.WATERLOGGED, false));
        structure.fillWithBlocks(world, start, 65, 6, -31, 65, 7, -30, Blocks.SANDSTONE.getDefaultState());
        structure.fillWithBlocks(world, start, 65, 6, -29, 65, 8, -29, Blocks.SMOOTH_SANDSTONE.getDefaultState());
        structure.fillWithBlocks(world, start, 65, 6, -28, 65, 7, -26, Index.HEDGE_OAK.getDefaultState().with(Hedge.STATE, HedgeState.STRAIGHT_X).with(Hedge.WATERLOGGED, false));
        structure.fillWithBlocks(world, start, 65, 6, -25, 65, 7, -24, Blocks.SMOOTH_SANDSTONE_STAIRS.getDefaultState().with(StairsBlock.FACING, Direction.WEST).with(StairsBlock.WATERLOGGED, false).with(StairsBlock.SHAPE, StairsShape.STRAIGHT).with(StairsBlock.HALF, Half.TOP));
        structure.fillWithBlocks(world, start, 65, 6, -23, 65, 7, -21, Blocks.BOOKSHELF.getDefaultState());
        structure.fillWithBlocks(world, start, 65, 6, -20, 65, 7, -20, Blocks.SMOOTH_SANDSTONE.getDefaultState());
        structure.fillWithBlocks(world, start, 65, 6, -19, 65, 6, -17, Blocks.SANDSTONE.getDefaultState());
        structure.fillWithBlocks(world, start, 65, 7, -19, 65, 7, -17, Blocks.SANDSTONE.getDefaultState());
        structure.fillWithBlocks(world, start, 65, 7, -4, 66, 7, -3, Blocks.SMOOTH_SANDSTONE.getDefaultState());
        structure.fillWithBlocks(world, start, 65, 8, -31, 65, 8, -30, Blocks.SANDSTONE.getDefaultState());
        structure.fillWithBlocks(world, start, 65, 8, -28, 65, 8, -16, Blocks.SANDSTONE.getDefaultState());
        structure.fillWithBlocks(world, start, 65, 8, -4, 66, 8, -3, Blocks.SANDSTONE.getDefaultState());
        structure.fillWithBlocks(world, start, 65, 8, 6, 68, 10, 6, Blocks.SANDSTONE.getDefaultState());
        structure.fillWithBlocks(world, start, 65, 8, 7, 65, 8, 8, Blocks.SANDSTONE_STAIRS.getDefaultState().with(StairsBlock.FACING, Direction.WEST).with(StairsBlock.WATERLOGGED, false).with(StairsBlock.SHAPE, StairsShape.STRAIGHT).with(StairsBlock.HALF, Half.BOTTOM));
        structure.fillWithBlocks(world, start, 65, 8, 9, 68, 10, 9, Blocks.SANDSTONE.getDefaultState());
        structure.fillWithBlocks(world, start, 65, 8, 19, 65, 8, 20, Blocks.SANDSTONE.getDefaultState());
        structure.fillWithBlocks(world, start, 65, 10, -22, 65, 10, -19, Blocks.SANDSTONE.getDefaultState());
        structure.fillWithBlocks(world, start, 65, 10, -16, 65, 10, -11, Blocks.SANDSTONE.getDefaultState());
        structure.fillWithBlocks(world, start, 65, 11, -22, 65, 13, -20, Blocks.SMOOTH_SANDSTONE.getDefaultState());
        structure.fillWithBlocks(world, start, 65, 11, -19, 65, 14, -19, Blocks.CUT_SANDSTONE.getDefaultState());
        structure.fillWithBlocks(world, start, 65, 11, -16, 65, 14, -16, Blocks.CUT_SANDSTONE.getDefaultState());
        structure.fillWithBlocks(world, start, 65, 11, -15, 65, 14, -15, Blocks.SMOOTH_SANDSTONE.getDefaultState());
        structure.fillWithBlocks(world, start, 65, 11, -14, 65, 12, -14, Blocks.SPRUCE_FENCE.getDefaultState().with(FourWayBlock.WATERLOGGED, false).with(FourWayBlock.NORTH, true).with(FourWayBlock.SOUTH, true).with(FourWayBlock.EAST, false).with(FourWayBlock.WEST, false));
        structure.fillWithBlocks(world, start, 65, 11, -13, 65, 12, -12, Blocks.SMOOTH_SANDSTONE.getDefaultState());
        structure.fillWithBlocks(world, start, 65, 11, -11, 65, 14, -11, Blocks.CUT_SANDSTONE.getDefaultState());
        structure.fillWithBlocks(world, start, 65, 11, 6, 65, 14, 6, Blocks.SMOOTH_SANDSTONE.getDefaultState());
        structure.fillWithBlocks(world, start, 65, 13, -14, 65, 14, -12, Blocks.SMOOTH_SANDSTONE.getDefaultState());
        structure.fillWithBlocks(world, start, 65, 13, 7, 66, 13, 8, Blocks.SPRUCE_FENCE.getDefaultState().with(FourWayBlock.WATERLOGGED, false).with(FourWayBlock.NORTH, true).with(FourWayBlock.SOUTH, true).with(FourWayBlock.EAST, true).with(FourWayBlock.WEST, true));
        structure.fillWithBlocks(world, start, 65, 14, -22, 65, 14, -20, Blocks.SMOOTH_SANDSTONE.getDefaultState());
        structure.fillWithBlocks(world, start, 65, 14, -5, 69, 14, -5, Blocks.SMOOTH_SANDSTONE.getDefaultState());
        structure.fillWithBlocks(world, start, 65, 14, -4, 67, 14, -2, Blocks.SPRUCE_SLAB.getDefaultState().with(SlabBlock.TYPE, SlabType.BOTTOM).with(SlabBlock.WATERLOGGED, false));
        structure.fillWithBlocks(world, start, 65, 14, -1, 65, 14, 0, Blocks.SPRUCE_SLAB.getDefaultState().with(SlabBlock.TYPE, SlabType.DOUBLE).with(SlabBlock.WATERLOGGED, false));
        structure.fillWithBlocks(world, start, 65, 14, 1, 66, 14, 2, Blocks.SPRUCE_SLAB.getDefaultState().with(SlabBlock.TYPE, SlabType.BOTTOM).with(SlabBlock.WATERLOGGED, false));
        structure.fillWithBlocks(world, start, 65, 14, 3, 65, 14, 3, Blocks.SPRUCE_SLAB.getDefaultState().with(SlabBlock.TYPE, SlabType.DOUBLE).with(SlabBlock.WATERLOGGED, false));
        structure.fillWithBlocks(world, start, 65, 14, 4, 65, 14, 5, Blocks.SPRUCE_SLAB.getDefaultState().with(SlabBlock.TYPE, SlabType.BOTTOM).with(SlabBlock.WATERLOGGED, false));
        structure.fillWithBlocks(world, start, 65, 14, 10, 67, 14, 10, Blocks.SPRUCE_SLAB.getDefaultState().with(SlabBlock.TYPE, SlabType.DOUBLE).with(SlabBlock.WATERLOGGED, false));
        structure.fillWithBlocks(world, start, 65, 14, 11, 66, 14, 12, Blocks.OAK_TRAPDOOR.getDefaultState().with(HorizontalBlock.HORIZONTAL_FACING, Direction.SOUTH).with(TrapDoorBlock.HALF, Half.BOTTOM).with(TrapDoorBlock.WATERLOGGED, false).with(TrapDoorBlock.POWERED, false).with(TrapDoorBlock.OPEN, false));
        structure.fillWithBlocks(world, start, 65, 14, 13, 67, 14, 13, Blocks.SPRUCE_SLAB.getDefaultState().with(SlabBlock.TYPE, SlabType.DOUBLE).with(SlabBlock.WATERLOGGED, false));
        structure.fillWithBlocks(world, start, 65, 14, 14, 67, 14, 19, Blocks.SPRUCE_SLAB.getDefaultState().with(SlabBlock.TYPE, SlabType.BOTTOM).with(SlabBlock.WATERLOGGED, false));
        structure.fillWithBlocks(world, start, 65, 15, -15, 65, 15, -12, Blocks.OAK_TRAPDOOR.getDefaultState().with(HorizontalBlock.HORIZONTAL_FACING, Direction.EAST).with(TrapDoorBlock.HALF, Half.BOTTOM).with(TrapDoorBlock.WATERLOGGED, false).with(TrapDoorBlock.POWERED, false).with(TrapDoorBlock.OPEN, true));
        structure.fillWithBlocks(world, start, 65, 15, -1, 65, 15, 0, Blocks.STRIPPED_SPRUCE_LOG.getDefaultState());
        structure.fillWithBlocks(world, start, 65, 15, 10, 66, 15, 10, Blocks.SPRUCE_FENCE.getDefaultState().with(FourWayBlock.WATERLOGGED, false).with(FourWayBlock.NORTH, false).with(FourWayBlock.SOUTH, false).with(FourWayBlock.EAST, true).with(FourWayBlock.WEST, true));
        structure.fillWithBlocks(world, start, 65, 16, -1, 65, 16, 0, Blocks.BIRCH_LEAVES.getDefaultState().with(LeavesBlock.PERSISTENT, true).with(LeavesBlock.DISTANCE, 1));
        structure.fillWithBlocks(world, start, 65, 17, -1, 65, 17, 0, Blocks.BIRCH_LEAVES.getDefaultState().with(LeavesBlock.PERSISTENT, true).with(LeavesBlock.DISTANCE, 2));
        structure.fillWithBlocks(world, start, 66, -14, -78, 66, -13, -77, Blocks.SAND.getDefaultState());
        structure.fillWithBlocks(world, start, 66, -13, -85, 73, -13, -77, Blocks.SAND.getDefaultState());
        structure.fillWithBlocks(world, start, 66, -13, -74, 107, -13, 62, Blocks.STONE.getDefaultState());
        structure.fillWithBlocks(world, start, 66, -13, 67, 68, -13, 75, Blocks.SAND.getDefaultState());
        structure.fillWithBlocks(world, start, 66, -12, -72, 66, -7, -72, Blocks.SAND.getDefaultState());
        structure.fillWithBlocks(world, start, 66, -12, -71, 80, -12, -56, Blocks.STONE.getDefaultState());
        structure.fillWithBlocks(world, start, 66, -11, -82, 83, -11, -65, Blocks.SAND.getDefaultState());
        structure.fillWithBlocks(world, start, 66, -11, 27, 68, -11, 29, Blocks.SAND.getDefaultState());
        structure.fillWithBlocks(world, start, 66, -11, 30, 66, -11, 62, Blocks.STONE.getDefaultState());
        structure.fillWithBlocks(world, start, 66, -11, 63, 76, -11, 73, Blocks.SAND.getDefaultState());
        structure.fillWithBlocks(world, start, 66, -7, -75, 72, -7, -69, Blocks.SAND.getDefaultState());
        structure.fillWithBlocks(world, start, 66, -7, -44, 70, -7, 20, Blocks.SAND.getDefaultState());
        structure.fillWithBlocks(world, start, 66, -7, 32, 67, -7, 55, Blocks.SANDSTONE.getDefaultState());
        structure.fillWithBlocks(world, start, 66, -6, 32, 69, -6, 55, Blocks.SANDSTONE.getDefaultState());
        structure.fillWithBlocks(world, start, 66, -5, 24, 73, -5, 24, Blocks.SANDSTONE.getDefaultState());
        structure.fillWithBlocks(world, start, 66, -5, 32, 71, -5, 32, Blocks.SANDSTONE.getDefaultState());
        structure.fillWithBlocks(world, start, 66, -5, 35, 66, -3, 35, Blocks.SPRUCE_FENCE.getDefaultState().with(FourWayBlock.WATERLOGGED, false).with(FourWayBlock.NORTH, false).with(FourWayBlock.SOUTH, false).with(FourWayBlock.EAST, false).with(FourWayBlock.WEST, false));
        structure.fillWithBlocks(world, start, 66, -4, 24, 69, -2, 24, Blocks.SMOOTH_SANDSTONE.getDefaultState());
        structure.fillWithBlocks(world, start, 66, -4, 32, 66, -1, 32, Blocks.SMOOTH_SANDSTONE.getDefaultState());
        structure.fillWithBlocks(world, start, 66, -2, 33, 66, -2, 35, Blocks.WHITE_WOOL.getDefaultState());
        structure.fillWithBlocks(world, start, 66, -1, -44, 70, -1, 17, Blocks.SANDSTONE.getDefaultState());
        structure.fillWithBlocks(world, start, 66, -1, 28, 66, -1, 31, Blocks.SPRUCE_SLAB.getDefaultState().with(SlabBlock.TYPE, SlabType.BOTTOM).with(SlabBlock.WATERLOGGED, false));
        structure.fillWithBlocks(world, start, 66, 0, -44, 70, 0, 17, Blocks.SANDSTONE.getDefaultState());
        structure.fillWithBlocks(world, start, 66, 1, -44, 70, 4, -44, Blocks.SMOOTH_SANDSTONE.getDefaultState());
        structure.fillWithBlocks(world, start, 66, 1, 15, 67, 1, 16, Blocks.SANDSTONE.getDefaultState());
        structure.fillWithBlocks(world, start, 66, 1, 18, 66, 2, 24, Blocks.SMOOTH_SANDSTONE.getDefaultState());
        structure.fillWithBlocks(world, start, 66, 1, 25, 66, 4, 25, Blocks.SANDSTONE.getDefaultState());
        structure.fillWithBlocks(world, start, 66, 2, 15, 67, 2, 16, Blocks.SANDSTONE.getDefaultState());
        structure.fillWithBlocks(world, start, 66, 4, -47, 68, 4, -45, Blocks.SPRUCE_SLAB.getDefaultState().with(SlabBlock.TYPE, SlabType.BOTTOM).with(SlabBlock.WATERLOGGED, false));
        structure.fillWithBlocks(world, start, 66, 4, -29, 73, 4, -20, Blocks.SPRUCE_PLANKS.getDefaultState());
        structure.fillWithBlocks(world, start, 66, 4, -19, 68, 4, -16, Blocks.SANDSTONE.getDefaultState());
        structure.fillWithBlocks(world, start, 66, 4, -6, 66, 4, -5, Blocks.SPRUCE_PLANKS.getDefaultState());
        structure.fillWithBlocks(world, start, 66, 5, -31, 67, 5, -30, Blocks.SANDSTONE.getDefaultState());
        structure.fillWithBlocks(world, start, 66, 5, -19, 66, 5, -16, Blocks.SANDSTONE.getDefaultState());
        structure.fillWithBlocks(world, start, 66, 6, -31, 68, 8, -31, Blocks.SANDSTONE.getDefaultState());
        structure.fillWithBlocks(world, start, 66, 6, -30, 68, 8, -30, Blocks.SMOOTH_SANDSTONE.getDefaultState());
        structure.fillWithBlocks(world, start, 66, 6, -19, 71, 7, -19, Blocks.SMOOTH_SANDSTONE.getDefaultState());
        structure.fillWithBlocks(world, start, 66, 6, -18, 66, 7, -17, Blocks.SANDSTONE.getDefaultState());
        structure.fillWithBlocks(world, start, 66, 6, -4, 67, 6, -3, Blocks.SMOOTH_SANDSTONE.getDefaultState());
        structure.fillWithBlocks(world, start, 66, 7, 7, 66, 7, 8, Blocks.SANDSTONE_STAIRS.getDefaultState().with(StairsBlock.FACING, Direction.WEST).with(StairsBlock.WATERLOGGED, false).with(StairsBlock.SHAPE, StairsShape.STRAIGHT).with(StairsBlock.HALF, Half.BOTTOM));
        structure.fillWithBlocks(world, start, 66, 7, 9, 68, 9, 9, Blocks.SANDSTONE.getDefaultState());
        structure.fillWithBlocks(world, start, 66, 8, -19, 66, 9, -16, Blocks.SANDSTONE.getDefaultState());
        structure.fillWithBlocks(world, start, 66, 9, -23, 68, 9, -20, Blocks.SPRUCE_PLANKS.getDefaultState());
        structure.fillWithBlocks(world, start, 66, 10, -19, 69, 10, -19, Blocks.SANDSTONE.getDefaultState());
        structure.fillWithBlocks(world, start, 66, 10, -18, 66, 10, -17, Blocks.SANDSTONE_WALL.getDefaultState().with(WallBlock.WATERLOGGED, false).with(WallBlock.UP, false).with(WallBlock.WALL_HEIGHT_NORTH, WallHeight.LOW).with(WallBlock.WALL_HEIGHT_SOUTH, WallHeight.LOW).with(WallBlock.WALL_HEIGHT_EAST, WallHeight.LOW).with(WallBlock.WALL_HEIGHT_WEST, WallHeight.LOW));
        structure.fillWithBlocks(world, start, 66, 10, -16, 71, 10, -16, Blocks.SANDSTONE.getDefaultState());
        structure.fillWithBlocks(world, start, 66, 10, -11, 66, 10, -11, Blocks.SANDSTONE.getDefaultState());
        structure.fillWithBlocks(world, start, 66, 11, -24, 66, 12, -24, Index.SMOOTH_SANDSTONE_VERTICAL_SLAB.getDefaultState().with(VerticalSlab.TYPE, VerticalSlabState.WEST).with(VerticalSlab.WATERLOGGED, false));
        structure.fillWithBlocks(world, start, 66, 11, -19, 68, 13, -19, Blocks.SMOOTH_SANDSTONE.getDefaultState());
        structure.fillWithBlocks(world, start, 66, 11, -16, 68, 13, -16, Blocks.SMOOTH_SANDSTONE.getDefaultState());
        structure.fillWithBlocks(world, start, 66, 11, -11, 66, 14, -11, Blocks.SMOOTH_SANDSTONE.getDefaultState());
        structure.fillWithBlocks(world, start, 66, 11, 6, 66, 12, 6, Blocks.SPRUCE_FENCE.getDefaultState().with(FourWayBlock.WATERLOGGED, false).with(FourWayBlock.NORTH, false).with(FourWayBlock.SOUTH, false).with(FourWayBlock.EAST, true).with(FourWayBlock.WEST, true));
        structure.fillWithBlocks(world, start, 66, 11, 20, 66, 12, 20, Blocks.SPRUCE_FENCE.getDefaultState().with(FourWayBlock.WATERLOGGED, false).with(FourWayBlock.NORTH, false).with(FourWayBlock.SOUTH, false).with(FourWayBlock.EAST, true).with(FourWayBlock.WEST, true));
        structure.fillWithBlocks(world, start, 66, 13, 6, 67, 14, 6, Blocks.SMOOTH_SANDSTONE.getDefaultState());
        structure.fillWithBlocks(world, start, 66, 13, 20, 67, 14, 20, Blocks.SMOOTH_SANDSTONE.getDefaultState());
        structure.fillWithBlocks(world, start, 66, 14, -23, 68, 14, -21, Blocks.SPRUCE_SLAB.getDefaultState().with(SlabBlock.TYPE, SlabType.BOTTOM).with(SlabBlock.WATERLOGGED, false));
        structure.fillWithBlocks(world, start, 66, 14, -20, 67, 14, -20, Blocks.SPRUCE_SLAB.getDefaultState().with(SlabBlock.TYPE, SlabType.BOTTOM).with(SlabBlock.WATERLOGGED, false));
        structure.fillWithBlocks(world, start, 66, 14, -19, 68, 14, -19, Blocks.SMOOTH_SANDSTONE.getDefaultState());
        structure.fillWithBlocks(world, start, 66, 14, -16, 70, 14, -16, Blocks.SMOOTH_SANDSTONE.getDefaultState());
        structure.fillWithBlocks(world, start, 66, 14, -15, 68, 14, -13, Blocks.SPRUCE_SLAB.getDefaultState().with(SlabBlock.TYPE, SlabType.BOTTOM).with(SlabBlock.WATERLOGGED, false));
        structure.fillWithBlocks(world, start, 66, 14, -12, 70, 14, -12, Blocks.SPRUCE_PLANKS.getDefaultState());
        structure.fillWithBlocks(world, start, 66, 14, -1, 67, 14, 3, Blocks.SPRUCE_SLAB.getDefaultState().with(SlabBlock.TYPE, SlabType.BOTTOM).with(SlabBlock.WATERLOGGED, false));
        structure.fillWithBlocks(world, start, 66, 14, 4, 66, 14, 5, Blocks.SPRUCE_SLAB.getDefaultState().with(SlabBlock.TYPE, SlabType.DOUBLE).with(SlabBlock.WATERLOGGED, false));
        structure.fillWithBlocks(world, start, 66, 14, 7, 67, 14, 8, Blocks.OAK_TRAPDOOR.getDefaultState().with(HorizontalBlock.HORIZONTAL_FACING, Direction.WEST).with(TrapDoorBlock.HALF, Half.BOTTOM).with(TrapDoorBlock.WATERLOGGED, false).with(TrapDoorBlock.POWERED, false).with(TrapDoorBlock.OPEN, false));
        structure.fillWithBlocks(world, start, 66, 15, -16, 70, 15, -16, Blocks.OAK_TRAPDOOR.getDefaultState().with(HorizontalBlock.HORIZONTAL_FACING, Direction.SOUTH).with(TrapDoorBlock.HALF, Half.BOTTOM).with(TrapDoorBlock.WATERLOGGED, false).with(TrapDoorBlock.POWERED, false).with(TrapDoorBlock.OPEN, true));
        structure.fillWithBlocks(world, start, 66, 15, -1, 66, 15, 0, Blocks.OAK_TRAPDOOR.getDefaultState().with(HorizontalBlock.HORIZONTAL_FACING, Direction.EAST).with(TrapDoorBlock.HALF, Half.TOP).with(TrapDoorBlock.WATERLOGGED, false).with(TrapDoorBlock.POWERED, false).with(TrapDoorBlock.OPEN, true));
        structure.fillWithBlocks(world, start, 67, -14, -78, 102, -14, 67, Blocks.STONE.getDefaultState());
        structure.fillWithBlocks(world, start, 67, -13, -76, 101, -13, 66, Blocks.STONE.getDefaultState());
        structure.fillWithBlocks(world, start, 67, -12, -72, 79, -12, -55, Blocks.STONE.getDefaultState());
        structure.fillWithBlocks(world, start, 67, -11, 30, 70, -11, 33, Blocks.SAND.getDefaultState());
        structure.fillWithBlocks(world, start, 67, -11, 34, 67, -11, 62, Blocks.STONE.getDefaultState());
        structure.fillWithBlocks(world, start, 67, -8, -76, 74, -8, -69, Blocks.SAND.getDefaultState());
        structure.fillWithBlocks(world, start, 67, -7, 21, 69, -5, 21, Blocks.SANDSTONE.getDefaultState());
        structure.fillWithBlocks(world, start, 67, -7, 22, 68, -7, 23, Blocks.SAND.getDefaultState());
        structure.fillWithBlocks(world, start, 67, -7, 24, 69, -5, 24, Blocks.SANDSTONE.getDefaultState());
        structure.fillWithBlocks(world, start, 67, -7, 25, 68, -7, 31, Blocks.SAND.getDefaultState());
        structure.fillWithBlocks(world, start, 67, -6, -71, 69, -6, -69, Blocks.SAND.getDefaultState());
        structure.fillWithBlocks(world, start, 67, -6, 22, 68, -6, 23, Blocks.SPRUCE_PLANKS.getDefaultState());
        structure.fillWithBlocks(world, start, 67, -6, 25, 68, -6, 31, Blocks.SPRUCE_PLANKS.getDefaultState());
        structure.fillWithBlocks(world, start, 67, -4, 19, 68, -4, 20, Blocks.SANDSTONE.getDefaultState());
        structure.fillWithBlocks(world, start, 67, -4, 32, 67, -3, 32, Blocks.SPRUCE_FENCE.getDefaultState().with(FourWayBlock.WATERLOGGED, false).with(FourWayBlock.NORTH, false).with(FourWayBlock.SOUTH, false).with(FourWayBlock.EAST, true).with(FourWayBlock.WEST, true));
        structure.fillWithBlocks(world, start, 67, -3, -53, 68, -3, -53, Blocks.SMOOTH_SANDSTONE.getDefaultState());
        structure.fillWithBlocks(world, start, 67, -3, 19, 68, -3, 20, Blocks.SANDSTONE.getDefaultState());
        structure.fillWithBlocks(world, start, 67, -2, -55, 67, -2, -54, Blocks.SPRUCE_FENCE.getDefaultState().with(FourWayBlock.WATERLOGGED, false).with(FourWayBlock.NORTH, true).with(FourWayBlock.SOUTH, true).with(FourWayBlock.EAST, true).with(FourWayBlock.WEST, true));
        structure.fillWithBlocks(world, start, 67, -2, 19, 68, -2, 20, Blocks.SANDSTONE.getDefaultState());
        structure.fillWithBlocks(world, start, 67, -1, -52, 70, -1, -45, Blocks.SMOOTH_SANDSTONE.getDefaultState());
        structure.fillWithBlocks(world, start, 67, -1, 18, 72, -1, 25, Blocks.SPRUCE_PLANKS.getDefaultState());
        structure.fillWithBlocks(world, start, 67, -1, 27, 68, -1, 31, Blocks.SPRUCE_PLANKS.getDefaultState());
        structure.fillWithBlocks(world, start, 67, 0, -47, 67, 0, -45, Blocks.SANDSTONE_SLAB.getDefaultState().with(SlabBlock.TYPE, SlabType.BOTTOM).with(SlabBlock.WATERLOGGED, false));
        structure.fillWithBlocks(world, start, 67, 0, 25, 67, 0, 25, Blocks.SANDSTONE.getDefaultState());
        structure.fillWithBlocks(world, start, 67, 1, 17, 73, 2, 17, Blocks.SMOOTH_SANDSTONE.getDefaultState());
        structure.fillWithBlocks(world, start, 67, 1, 25, 67, 4, 25, Blocks.SMOOTH_SANDSTONE.getDefaultState());
        structure.fillWithBlocks(world, start, 67, 3, 16, 68, 3, 17, Blocks.SANDSTONE.getDefaultState());
        structure.fillWithBlocks(world, start, 67, 3, 18, 72, 3, 24, Blocks.SMOOTH_SANDSTONE_SLAB.getDefaultState().with(SlabBlock.TYPE, SlabType.TOP).with(SlabBlock.WATERLOGGED, false));
        structure.fillWithBlocks(world, start, 67, 4, -6, 69, 4, -3, Blocks.SANDSTONE.getDefaultState());
        structure.fillWithBlocks(world, start, 67, 4, 20, 68, 5, 20, Blocks.SANDSTONE.getDefaultState());
        structure.fillWithBlocks(world, start, 67, 4, 21, 71, 4, 25, Blocks.SMOOTH_SANDSTONE.getDefaultState());
        structure.fillWithBlocks(world, start, 67, 5, -44, 69, 5, -44, Blocks.SANDSTONE_WALL.getDefaultState().with(WallBlock.WATERLOGGED, false).with(WallBlock.UP, false).with(WallBlock.WALL_HEIGHT_NORTH, WallHeight.LOW).with(WallBlock.WALL_HEIGHT_SOUTH, WallHeight.LOW).with(WallBlock.WALL_HEIGHT_EAST, WallHeight.LOW).with(WallBlock.WALL_HEIGHT_WEST, WallHeight.LOW));
        structure.fillWithBlocks(world, start, 67, 5, -19, 74, 5, -19, Blocks.SANDSTONE.getDefaultState());
        structure.fillWithBlocks(world, start, 67, 5, -17, 67, 6, -17, Blocks.BARREL.getDefaultState().with(BarrelBlock.PROPERTY_FACING, Direction.EAST).with(BarrelBlock.PROPERTY_OPEN, false));
        structure.fillWithBlocks(world, start, 67, 5, -16, 71, 5, -16, Blocks.SANDSTONE.getDefaultState());
        structure.fillWithBlocks(world, start, 67, 5, -7, 71, 5, -3, Blocks.SANDSTONE.getDefaultState());
        structure.fillWithBlocks(world, start, 67, 5, 5, 68, 6, 5, Index.BOOKSHELF_OAK.getDefaultState().with(Bookshelf.FACING, Direction.NORTH).with(Bookshelf.BOOK0, false).with(Bookshelf.BOOK1, false).with(Bookshelf.BOOK2, false).with(Bookshelf.BOOK3, false).with(Bookshelf.BOOK4, false).with(Bookshelf.BOOK5, false).with(Bookshelf.BOOK6, false).with(Bookshelf.BOOK7, false));
        structure.fillWithBlocks(world, start, 67, 5, 19, 68, 5, 20, Blocks.SANDSTONE.getDefaultState());
        structure.fillWithBlocks(world, start, 67, 6, -7, 71, 6, -3, Blocks.SMOOTH_SANDSTONE.getDefaultState());
        structure.fillWithBlocks(world, start, 67, 6, 7, 67, 6, 8, Blocks.SANDSTONE_STAIRS.getDefaultState().with(StairsBlock.FACING, Direction.WEST).with(StairsBlock.WATERLOGGED, false).with(StairsBlock.SHAPE, StairsShape.STRAIGHT).with(StairsBlock.HALF, Half.BOTTOM));
        structure.fillWithBlocks(world, start, 67, 7, -7, 71, 7, -3, Blocks.SMOOTH_SANDSTONE.getDefaultState());
        structure.fillWithBlocks(world, start, 67, 8, -19, 69, 10, -19, Blocks.SANDSTONE.getDefaultState());
        structure.fillWithBlocks(world, start, 67, 8, -7, 67, 8, -3, Blocks.SANDSTONE.getDefaultState());
        structure.fillWithBlocks(world, start, 67, 9, -18, 68, 9, -17, Blocks.SPRUCE_FENCE.getDefaultState().with(FourWayBlock.WATERLOGGED, false).with(FourWayBlock.NORTH, true).with(FourWayBlock.SOUTH, true).with(FourWayBlock.EAST, true).with(FourWayBlock.WEST, true));
        structure.fillWithBlocks(world, start, 67, 9, -16, 71, 10, -16, Blocks.SANDSTONE.getDefaultState());
        structure.fillWithBlocks(world, start, 67, 9, -7, 71, 10, -7, Blocks.SANDSTONE.getDefaultState());
        structure.fillWithBlocks(world, start, 67, 9, -6, 69, 9, 5, Blocks.SPRUCE_PLANKS.getDefaultState());
        structure.fillWithBlocks(world, start, 67, 10, -18, 68, 10, -17, Blocks.OAK_TRAPDOOR.getDefaultState().with(HorizontalBlock.HORIZONTAL_FACING, Direction.EAST).with(TrapDoorBlock.HALF, Half.BOTTOM).with(TrapDoorBlock.WATERLOGGED, false).with(TrapDoorBlock.POWERED, false).with(TrapDoorBlock.OPEN, false));
        structure.fillWithBlocks(world, start, 67, 10, -11, 67, 10, -10, Blocks.SANDSTONE.getDefaultState());
        structure.fillWithBlocks(world, start, 67, 10, -8, 67, 10, -7, Blocks.SANDSTONE.getDefaultState());
        structure.fillWithBlocks(world, start, 67, 10, -2, 67, 10, -1, Blocks.SPRUCE_SLAB.getDefaultState().with(SlabBlock.TYPE, SlabType.TOP).with(SlabBlock.WATERLOGGED, false));
        structure.fillWithBlocks(world, start, 67, 11, -31, 68, 12, -31, Blocks.SMOOTH_SANDSTONE.getDefaultState());
        structure.fillWithBlocks(world, start, 67, 11, -11, 67, 14, -11, Blocks.CUT_SANDSTONE.getDefaultState());
        structure.fillWithBlocks(world, start, 67, 11, -10, 67, 14, -10, Blocks.SMOOTH_SANDSTONE.getDefaultState());
        structure.fillWithBlocks(world, start, 67, 11, -8, 67, 14, -8, Blocks.SMOOTH_SANDSTONE.getDefaultState());
        structure.fillWithBlocks(world, start, 67, 11, -7, 67, 14, -7, Blocks.CUT_SANDSTONE.getDefaultState());
        structure.fillWithBlocks(world, start, 67, 11, 6, 67, 14, 6, Blocks.SMOOTH_SANDSTONE.getDefaultState());
        structure.fillWithBlocks(world, start, 67, 11, 9, 67, 14, 9, Blocks.SMOOTH_SANDSTONE.getDefaultState());
        structure.fillWithBlocks(world, start, 67, 11, 20, 67, 14, 20, Blocks.SMOOTH_SANDSTONE.getDefaultState());
        structure.fillWithBlocks(world, start, 67, 12, -9, 67, 13, -8, Blocks.SMOOTH_SANDSTONE.getDefaultState());
        structure.fillWithBlocks(world, start, 67, 13, 7, 67, 13, 8, Blocks.SPRUCE_FENCE.getDefaultState().with(FourWayBlock.WATERLOGGED, false).with(FourWayBlock.NORTH, true).with(FourWayBlock.SOUTH, true).with(FourWayBlock.EAST, false).with(FourWayBlock.WEST, true));
        structure.fillWithBlocks(world, start, 67, 14, -9, 67, 14, -8, Blocks.SMOOTH_SANDSTONE.getDefaultState());
        structure.fillWithBlocks(world, start, 67, 14, -6, 69, 14, -6, Blocks.SPRUCE_FENCE.getDefaultState().with(FourWayBlock.WATERLOGGED, false).with(FourWayBlock.NORTH, true).with(FourWayBlock.SOUTH, true).with(FourWayBlock.EAST, true).with(FourWayBlock.WEST, true));
        structure.fillWithBlocks(world, start, 67, 14, 11, 67, 14, 13, Blocks.SPRUCE_SLAB.getDefaultState().with(SlabBlock.TYPE, SlabType.DOUBLE).with(SlabBlock.WATERLOGGED, false));
        structure.fillWithBlocks(world, start, 67, 15, -20, 67, 15, -20, Blocks.BIRCH_LEAVES.getDefaultState().with(LeavesBlock.PERSISTENT, true).with(LeavesBlock.DISTANCE, 1));
        structure.fillWithBlocks(world, start, 67, 15, -6, 70, 15, -6, Blocks.OAK_TRAPDOOR.getDefaultState().with(HorizontalBlock.HORIZONTAL_FACING, Direction.NORTH).with(TrapDoorBlock.HALF, Half.BOTTOM).with(TrapDoorBlock.WATERLOGGED, false).with(TrapDoorBlock.POWERED, false).with(TrapDoorBlock.OPEN, false));
        structure.fillWithBlocks(world, start, 67, 15, 13, 68, 15, 13, Blocks.SPRUCE_FENCE.getDefaultState().with(FourWayBlock.WATERLOGGED, false).with(FourWayBlock.NORTH, true).with(FourWayBlock.SOUTH, false).with(FourWayBlock.EAST, true).with(FourWayBlock.WEST, true));
        structure.fillWithBlocks(world, start, 67, 16, -20, 67, 16, -20, Blocks.BIRCH_LEAVES.getDefaultState().with(LeavesBlock.PERSISTENT, true).with(LeavesBlock.DISTANCE, 2));
        structure.fillWithBlocks(world, start, 68, -14, -86, 74, -14, -80, Blocks.SAND.getDefaultState());
        structure.fillWithBlocks(world, start, 68, -14, -79, 69, -13, -79, Blocks.SAND.getDefaultState());
        structure.fillWithBlocks(world, start, 68, -14, 70, 73, -14, 76, Blocks.SAND.getDefaultState());
        structure.fillWithBlocks(world, start, 68, -11, -64, 94, -9, -64, Blocks.SAND.getDefaultState());
        structure.fillWithBlocks(world, start, 68, -11, -63, 71, -11, -54, Blocks.STONE.getDefaultState());
        structure.fillWithBlocks(world, start, 68, -11, -53, 69, -11, -52, Blocks.STONE.getDefaultState());
        structure.fillWithBlocks(world, start, 68, -11, -50, 88, -11, -29, Blocks.SAND.getDefaultState());
        structure.fillWithBlocks(world, start, 68, -11, 24, 84, -11, 40, Blocks.SAND.getDefaultState());
        structure.fillWithBlocks(world, start, 68, -11, 41, 68, -11, 62, Blocks.STONE.getDefaultState());
        structure.fillWithBlocks(world, start, 68, -7, 32, 76, -7, 32, Blocks.SAND.getDefaultState());
        structure.fillWithBlocks(world, start, 68, -6, -72, 68, -6, -69, Blocks.SAND.getDefaultState());
        structure.fillWithBlocks(world, start, 68, -6, 61, 69, -6, 63, Blocks.SAND.getDefaultState());
        structure.fillWithBlocks(world, start, 68, -5, -53, 71, -5, -53, Blocks.SANDSTONE.getDefaultState());
        structure.fillWithBlocks(world, start, 68, -5, 22, 68, -5, 23, Blocks.SANDSTONE_STAIRS.getDefaultState().with(StairsBlock.FACING, Direction.EAST).with(StairsBlock.WATERLOGGED, false).with(StairsBlock.SHAPE, StairsShape.STRAIGHT).with(StairsBlock.HALF, Half.TOP));
        structure.fillWithBlocks(world, start, 68, -4, -53, 68, -3, -53, Blocks.SMOOTH_SANDSTONE.getDefaultState());
        structure.fillWithBlocks(world, start, 68, -4, 32, 71, -3, 32, Blocks.SMOOTH_SANDSTONE.getDefaultState());
        structure.fillWithBlocks(world, start, 68, -1, -55, 69, -1, -54, Blocks.OAK_TRAPDOOR.getDefaultState().with(HorizontalBlock.HORIZONTAL_FACING, Direction.NORTH).with(TrapDoorBlock.HALF, Half.BOTTOM).with(TrapDoorBlock.WATERLOGGED, false).with(TrapDoorBlock.POWERED, false).with(TrapDoorBlock.OPEN, false));
        structure.fillWithBlocks(world, start, 68, -1, 32, 71, 0, 32, Blocks.SANDSTONE.getDefaultState());
        structure.fillWithBlocks(world, start, 68, 0, -47, 68, 0, -47, Blocks.SANDSTONE_SLAB.getDefaultState().with(SlabBlock.TYPE, SlabType.BOTTOM).with(SlabBlock.WATERLOGGED, false));
        structure.fillWithBlocks(world, start, 68, 0, 26, 68, 0, 32, Blocks.SANDSTONE.getDefaultState());
        structure.fillWithBlocks(world, start, 68, 1, -53, 70, 1, -53, Blocks.SMOOTH_SANDSTONE.getDefaultState());
        structure.fillWithBlocks(world, start, 68, 1, 15, 69, 1, 16, Blocks.SANDSTONE.getDefaultState());
        structure.fillWithBlocks(world, start, 68, 1, 26, 68, 3, 28, Blocks.SMOOTH_SANDSTONE.getDefaultState());
        structure.fillWithBlocks(world, start, 68, 1, 29, 68, 2, 29, Blocks.SPRUCE_FENCE.getDefaultState().with(FourWayBlock.WATERLOGGED, false).with(FourWayBlock.NORTH, true).with(FourWayBlock.SOUTH, true).with(FourWayBlock.EAST, false).with(FourWayBlock.WEST, false));
        structure.fillWithBlocks(world, start, 68, 1, 30, 68, 2, 31, Blocks.SMOOTH_SANDSTONE.getDefaultState());
        structure.fillWithBlocks(world, start, 68, 1, 32, 68, 4, 32, Blocks.CUT_SANDSTONE.getDefaultState());
        structure.fillWithBlocks(world, start, 68, 2, -53, 68, 3, -53, Blocks.SPRUCE_FENCE.getDefaultState().with(FourWayBlock.WATERLOGGED, false).with(FourWayBlock.NORTH, false).with(FourWayBlock.SOUTH, false).with(FourWayBlock.EAST, true).with(FourWayBlock.WEST, true));
        structure.fillWithBlocks(world, start, 68, 2, 15, 69, 2, 16, Blocks.SANDSTONE.getDefaultState());
        structure.fillWithBlocks(world, start, 68, 3, 25, 72, 3, 25, Blocks.SMOOTH_SANDSTONE_SLAB.getDefaultState().with(SlabBlock.TYPE, SlabType.TOP).with(SlabBlock.WATERLOGGED, false));
        structure.fillWithBlocks(world, start, 68, 3, 29, 68, 4, 31, Blocks.SMOOTH_SANDSTONE.getDefaultState());
        structure.fillWithBlocks(world, start, 68, 4, -53, 70, 4, -53, Blocks.SMOOTH_SANDSTONE.getDefaultState());
        structure.fillWithBlocks(world, start, 68, 4, -52, 70, 4, -45, Blocks.SPRUCE_SLAB.getDefaultState().with(SlabBlock.TYPE, SlabType.BOTTOM).with(SlabBlock.WATERLOGGED, false));
        structure.fillWithBlocks(world, start, 68, 4, 6, 70, 4, 10, Blocks.SANDSTONE.getDefaultState());
        structure.fillWithBlocks(world, start, 68, 4, 11, 68, 4, 15, Blocks.SPRUCE_PLANKS.getDefaultState());
        structure.fillWithBlocks(world, start, 68, 4, 16, 72, 4, 20, Blocks.SANDSTONE.getDefaultState());
        structure.fillWithBlocks(world, start, 68, 4, 27, 68, 4, 31, Blocks.SMOOTH_SANDSTONE.getDefaultState());
        structure.fillWithBlocks(world, start, 68, 5, -31, 68, 5, -30, Blocks.SANDSTONE.getDefaultState());
        structure.fillWithBlocks(world, start, 68, 5, 6, 70, 5, 6, Blocks.SANDSTONE.getDefaultState());
        structure.fillWithBlocks(world, start, 68, 5, 7, 68, 5, 8, Blocks.SANDSTONE_STAIRS.getDefaultState().with(StairsBlock.FACING, Direction.WEST).with(StairsBlock.WATERLOGGED, false).with(StairsBlock.SHAPE, StairsShape.STRAIGHT).with(StairsBlock.HALF, Half.BOTTOM));
        structure.fillWithBlocks(world, start, 68, 5, 10, 68, 10, 10, Blocks.SANDSTONE.getDefaultState());
        structure.fillWithBlocks(world, start, 68, 5, 16, 68, 9, 20, Blocks.SANDSTONE.getDefaultState());
        structure.fillWithBlocks(world, start, 68, 8, -7, 71, 10, -7, Blocks.SANDSTONE.getDefaultState());
        structure.fillWithBlocks(world, start, 68, 8, -6, 69, 8, -4, Blocks.SMOOTH_SANDSTONE.getDefaultState());
        structure.fillWithBlocks(world, start, 68, 8, -3, 74, 8, -3, Blocks.SANDSTONE.getDefaultState());
        structure.fillWithBlocks(world, start, 68, 8, 11, 68, 8, 15, Blocks.SANDSTONE_SLAB.getDefaultState().with(SlabBlock.TYPE, SlabType.TOP).with(SlabBlock.WATERLOGGED, false));
        structure.fillWithBlocks(world, start, 68, 9, 11, 68, 10, 20, Blocks.SANDSTONE.getDefaultState());
        structure.fillWithBlocks(world, start, 68, 10, -13, 70, 10, -13, Blocks.SANDSTONE_SLAB.getDefaultState().with(SlabBlock.TYPE, SlabType.TOP).with(SlabBlock.WATERLOGGED, false));
