package mod.arcalitegames.odyssey.world.structure.town.bashkarcity;

import mod.arcalitegames.buildersaddition.Index;
import mod.arcalitegames.buildersaddition.blocks.Bookshelf;
import mod.arcalitegames.buildersaddition.blocks.Cabinet;
import mod.arcalitegames.buildersaddition.blocks.Counter;
import mod.arcalitegames.buildersaddition.blocks.Cupboard;
import mod.arcalitegames.buildersaddition.blocks.Hedge;
import mod.arcalitegames.buildersaddition.blocks.IronFence;
import mod.arcalitegames.buildersaddition.blocks.Shelf;
import mod.arcalitegames.buildersaddition.blocks.Stool;
import mod.arcalitegames.buildersaddition.blocks.SupportBracket;
import mod.arcalitegames.buildersaddition.blocks.VerticalSlab;
import mod.arcalitegames.buildersaddition.state.HedgeState;
import mod.arcalitegames.buildersaddition.state.MountState;
import mod.arcalitegames.buildersaddition.state.StoolState;
import mod.arcalitegames.buildersaddition.state.VerticalSlabState;
import mod.arcalitegames.odyssey.blocks.ChairBlock;
import mod.arcalitegames.odyssey.blocks.ModBlocks;
import mod.arcalitegames.odyssey.world.structure.StructureBase;
import net.minecraft.block.BarrelBlock;
import net.minecraft.block.BedBlock;
import net.minecraft.block.Blocks;
import net.minecraft.block.BubbleColumnBlock;
import net.minecraft.block.CampfireBlock;
import net.minecraft.block.CauldronBlock;
import net.minecraft.block.ChainBlock;
import net.minecraft.block.ChestBlock;
import net.minecraft.block.ComposterBlock;
import net.minecraft.block.FourWayBlock;
import net.minecraft.block.HorizontalBlock;
import net.minecraft.block.LadderBlock;
import net.minecraft.block.LeavesBlock;
import net.minecraft.block.NetherWartBlock;
import net.minecraft.block.SlabBlock;
import net.minecraft.block.StairsBlock;
import net.minecraft.block.SugarCaneBlock;
import net.minecraft.block.TrapDoorBlock;
import net.minecraft.block.WallBannerBlock;
import net.minecraft.block.WallBlock;
import net.minecraft.block.WallHeight;
import net.minecraft.state.properties.BedPart;
import net.minecraft.state.properties.ChestType;
import net.minecraft.state.properties.DoubleBlockHalf;
import net.minecraft.state.properties.Half;
import net.minecraft.state.properties.SlabType;
import net.minecraft.state.properties.StairsShape;
import net.minecraft.util.Direction;
import net.minecraft.util.math.BlockPos;
import net.minecraft.world.World;

public class BashkarComponent1
{

	public static BlockPos start;
    public static World world;
    public static StructureBase structure;

    public static void init(World worldIn, BlockPos blockPos, StructureBase structureIn)
    {
        world = worldIn; start = blockPos; structure = structureIn;
    }
    
    public static void generatePart11()
    {
        structure.fillWithBlocks(world, start, -38, -12, 59, -35, -12, 62, Blocks.SAND.getDefaultState());
        structure.fillWithBlocks(world, start, -38, -11, -73, -34, -11, -45, Blocks.SAND.getDefaultState());
        structure.fillWithBlocks(world, start, -38, -11, -44, -35, -11, -39, Blocks.STONE.getDefaultState());
        structure.fillWithBlocks(world, start, -38, -11, -38, -38, -8, 37, Blocks.SAND.getDefaultState());
        structure.fillWithBlocks(world, start, -38, -11, 38, -35, -11, 41, Blocks.STONE.getDefaultState());
        structure.fillWithBlocks(world, start, -38, -11, 42, -38, -11, 61, Blocks.SAND.getDefaultState());
        structure.fillWithBlocks(world, start, -38, -10, -69, 91, -10, 60, Blocks.SAND.getDefaultState());
        structure.fillWithBlocks(world, start, -38, -9, -65, -2, -9, -29, Blocks.SAND.getDefaultState());
        structure.fillWithBlocks(world, start, -38, -9, 57, -38, -9, 57, Blocks.SAND.getDefaultState());
        structure.fillWithBlocks(world, start, -38, -8, -61, -33, -8, 54, Blocks.SAND.getDefaultState());
        structure.fillWithBlocks(world, start, -38, -7, -57, -33, -7, -39, Blocks.SAND.getDefaultState());
        structure.fillWithBlocks(world, start, -38, -7, 3, -33, -7, 44, Blocks.SAND.getDefaultState());
        structure.fillWithBlocks(world, start, -37, -14, -79, -35, -14, -77, Blocks.SAND.getDefaultState());
        structure.fillWithBlocks(world, start, -37, -14, -69, 87, -14, 55, Blocks.STONE.getDefaultState());
        structure.fillWithBlocks(world, start, -37, -14, 56, -37, -14, 66, Blocks.SAND.getDefaultState());
        structure.fillWithBlocks(world, start, -37, -13, -77, -35, -13, -73, Blocks.SAND.getDefaultState());
        structure.fillWithBlocks(world, start, -37, -13, -65, 77, -13, 49, Blocks.STONE.getDefaultState());
        structure.fillWithBlocks(world, start, -37, -13, 65, -37, -13, 65, Blocks.SAND.getDefaultState());
        structure.fillWithBlocks(world, start, -37, -12, -76, -34, -12, -73, Blocks.SAND.getDefaultState());
        structure.fillWithBlocks(world, start, -37, -12, -59, -34, -12, -56, Blocks.STONE.getDefaultState());
        structure.fillWithBlocks(world, start, -37, -12, -32, -37, -12, -32, Blocks.STONE.getDefaultState());
        structure.fillWithBlocks(world, start, -37, -12, -31, -37, -12, -21, Blocks.SAND.getDefaultState());
        structure.fillWithBlocks(world, start, -37, -12, -20, -26, -12, -2, Blocks.STONE.getDefaultState());
        structure.fillWithBlocks(world, start, -37, -12, -1, -37, -8, -1, Blocks.SAND.getDefaultState());
        structure.fillWithBlocks(world, start, -37, -12, 0, -30, -12, 8, Blocks.STONE.getDefaultState());
        structure.fillWithBlocks(world, start, -37, -12, 45, -35, -12, 47, Blocks.STONE.getDefaultState());
        structure.fillWithBlocks(world, start, -37, -12, 48, -37, -8, 55, Blocks.SAND.getDefaultState());
        structure.fillWithBlocks(world, start, -37, -12, 63, -37, -12, 63, Blocks.SAND.getDefaultState());
        structure.fillWithBlocks(world, start, -37, -11, -75, -33, -11, -70, Blocks.SAND.getDefaultState());
        structure.fillWithBlocks(world, start, -37, -11, -38, -36, -11, -37, Blocks.STONE.getDefaultState());
        structure.fillWithBlocks(world, start, -37, -11, -36, -37, -11, 37, Blocks.SAND.getDefaultState());
        structure.fillWithBlocks(world, start, -37, -11, 42, -37, -11, 42, Blocks.STONE.getDefaultState());
        structure.fillWithBlocks(world, start, -37, -11, 43, -37, -11, 62, Blocks.SAND.getDefaultState());
        structure.fillWithBlocks(world, start, -37, -10, -73, 97, -10, 61, Blocks.SAND.getDefaultState());
        structure.fillWithBlocks(world, start, -37, -9, -69, 3, -9, -29, Blocks.SAND.getDefaultState());
        structure.fillWithBlocks(world, start, -37, -9, 56, -35, -9, 58, Blocks.SAND.getDefaultState());
        structure.fillWithBlocks(world, start, -37, -8, -65, -33, -8, 55, Blocks.SAND.getDefaultState());
        structure.fillWithBlocks(world, start, -37, -7, -60, -33, -7, -37, Blocks.SAND.getDefaultState());
        structure.fillWithBlocks(world, start, -37, -7, -6, -33, -7, -2, Blocks.SAND.getDefaultState());
        structure.fillWithBlocks(world, start, -37, -7, 0, -33, -7, 47, Blocks.SAND.getDefaultState());
        structure.fillWithBlocks(world, start, -37, -6, -58, -33, -6, -54, Blocks.SAND.getDefaultState());
        structure.fillWithBlocks(world, start, -37, -6, 13, -35, -6, 15, Blocks.SAND.getDefaultState());
        structure.fillWithBlocks(world, start, -36, -14, -80, -34, -14, -78, Blocks.SAND.getDefaultState());
        structure.fillWithBlocks(world, start, -36, -14, -73, 93, -14, 56, Blocks.STONE.getDefaultState());
        structure.fillWithBlocks(world, start, -36, -14, 57, -36, -14, 67, Blocks.SAND.getDefaultState());
        structure.fillWithBlocks(world, start, -36, -13, -78, -35, -13, -73, Blocks.SAND.getDefaultState());
        structure.fillWithBlocks(world, start, -36, -13, -69, 83, -13, 50, Blocks.STONE.getDefaultState());
        structure.fillWithBlocks(world, start, -36, -13, 51, -36, -13, 66, Blocks.SAND.getDefaultState());
        structure.fillWithBlocks(world, start, -36, -12, -77, -33, -12, -73, Blocks.SAND.getDefaultState());
        structure.fillWithBlocks(world, start, -36, -12, -62, -31, -12, -57, Blocks.STONE.getDefaultState());
        structure.fillWithBlocks(world, start, -36, -12, -32, -35, -12, -31, Blocks.STONE.getDefaultState());
        structure.fillWithBlocks(world, start, -36, -12, -30, -35, -12, -21, Blocks.SAND.getDefaultState());
        structure.fillWithBlocks(world, start, -36, -12, -1, -28, -12, 7, Blocks.STONE.getDefaultState());
        structure.fillWithBlocks(world, start, -36, -12, 48, -35, -12, 49, Blocks.STONE.getDefaultState());
        structure.fillWithBlocks(world, start, -36, -12, 50, -36, -8, 56, Blocks.SAND.getDefaultState());
        structure.fillWithBlocks(world, start, -36, -12, 63, -35, -12, 64, Blocks.SAND.getDefaultState());
        structure.fillWithBlocks(world, start, -36, -11, -76, -32, -11, -72, Blocks.SAND.getDefaultState());
        structure.fillWithBlocks(world, start, -36, -11, -36, -29, -11, -36, Blocks.STONE.getDefaultState());
        structure.fillWithBlocks(world, start, -36, -11, -35, -35, -11, -6, Blocks.SAND.getDefaultState());
        structure.fillWithBlocks(world, start, -36, -11, -3, -35, -11, -2, Blocks.STONE.getDefaultState());
        structure.fillWithBlocks(world, start, -36, -11, 23, -30, -11, 31, Blocks.SAND.getDefaultState());
        structure.fillWithBlocks(world, start, -36, -11, 32, -33, -11, 35, Blocks.SAND.getDefaultState());
        structure.fillWithBlocks(world, start, -36, -11, 36, -35, -10, 36, Blocks.SAND.getDefaultState());
        structure.fillWithBlocks(world, start, -36, -11, 37, -32, -11, 41, Blocks.STONE.getDefaultState());
        structure.fillWithBlocks(world, start, -36, -11, 42, -35, -11, 43, Blocks.STONE.getDefaultState());
        structure.fillWithBlocks(world, start, -36, -11, 44, -28, -11, 53, Blocks.SAND.getDefaultState());
        structure.fillWithBlocks(world, start, -36, -11, 57, -30, -11, 63, Blocks.SAND.getDefaultState());
        structure.fillWithBlocks(world, start, -36, -10, -75, 100, -10, 61, Blocks.SAND.getDefaultState());
        structure.fillWithBlocks(world, start, -36, -9, -73, 8, -9, -29, Blocks.SAND.getDefaultState());
        structure.fillWithBlocks(world, start, -36, -9, 59, -36, -9, 59, Blocks.SAND.getDefaultState());
        structure.fillWithBlocks(world, start, -36, -8, -69, -33, -8, 56, Blocks.SAND.getDefaultState());
        structure.fillWithBlocks(world, start, -36, -7, -65, -33, -7, -22, Blocks.SAND.getDefaultState());
        structure.fillWithBlocks(world, start, -36, -7, -7, -33, -7, 49, Blocks.SAND.getDefaultState());
        structure.fillWithBlocks(world, start, -36, -6, -61, -33, -6, -52, Blocks.SAND.getDefaultState());
        structure.fillWithBlocks(world, start, -36, -6, -42, -36, -6, -42, Blocks.SAND.getDefaultState());
        structure.fillWithBlocks(world, start, -36, -6, -39, -36, -6, -39, Blocks.SAND.getDefaultState());
        structure.fillWithBlocks(world, start, -36, -6, -2, -36, -6, -2, Blocks.SAND.getDefaultState());
        structure.fillWithBlocks(world, start, -36, -6, 4, -34, -6, 6, Blocks.SAND.getDefaultState());
        structure.fillWithBlocks(world, start, -36, -6, 10, -33, -6, 33, Blocks.SAND.getDefaultState());
        structure.fillWithBlocks(world, start, -35, -14, -81, -33, -14, -79, Blocks.SAND.getDefaultState());
        structure.fillWithBlocks(world, start, -35, -14, -76, 39, -14, 57, Blocks.STONE.getDefaultState());
        structure.fillWithBlocks(world, start, -35, -14, 66, -33, -14, 68, Blocks.SAND.getDefaultState());
        structure.fillWithBlocks(world, start, -35, -13, -79, -33, -13, -77, Blocks.SAND.getDefaultState());
        structure.fillWithBlocks(world, start, -35, -13, -72, 88, -13, 51, Blocks.STONE.getDefaultState());
        structure.fillWithBlocks(world, start, -35, -13, 52, -35, -13, 66, Blocks.SAND.getDefaultState());
        structure.fillWithBlocks(world, start, -35, -12, -78, -31, -12, -74, Blocks.SAND.getDefaultState());
        structure.fillWithBlocks(world, start, -35, -12, -67, -25, -12, -57, Blocks.STONE.getDefaultState());
        structure.fillWithBlocks(world, start, -35, -12, -54, -31, -12, -50, Blocks.SAND.getDefaultState());
        structure.fillWithBlocks(world, start, -35, -12, -49, -35, -12, -31, Blocks.STONE.getDefaultState());
        structure.fillWithBlocks(world, start, -35, -12, 14, -28, -12, 22, Blocks.SAND.getDefaultState());
        structure.fillWithBlocks(world, start, -35, -12, 30, -35, -11, 31, Blocks.SAND.getDefaultState());
        structure.fillWithBlocks(world, start, -35, -12, 32, -16, -12, 51, Blocks.STONE.getDefaultState());
        structure.fillWithBlocks(world, start, -35, -12, 52, -35, -12, 65, Blocks.SAND.getDefaultState());
        structure.fillWithBlocks(world, start, -35, -11, -77, -30, -11, -72, Blocks.SAND.getDefaultState());
        structure.fillWithBlocks(world, start, -35, -11, -38, -33, -11, -36, Blocks.STONE.getDefaultState());
        structure.fillWithBlocks(world, start, -35, -11, -5, -34, -11, -4, Blocks.STONE.getDefaultState());
        structure.fillWithBlocks(world, start, -35, -11, 54, -29, -11, 64, Blocks.SAND.getDefaultState());
        structure.fillWithBlocks(world, start, -35, -10, -76, 103, -10, 62, Blocks.SAND.getDefaultState());
        structure.fillWithBlocks(world, start, -35, -9, -75, 11, -9, -29, Blocks.SAND.getDefaultState());
        structure.fillWithBlocks(world, start, -35, -9, 55, -30, -9, 60, Blocks.SAND.getDefaultState());
        structure.fillWithBlocks(world, start, -35, -8, -72, -32, -8, -69, Blocks.SAND.getDefaultState());
        structure.fillWithBlocks(world, start, -35, -8, 57, -35, -8, 57, Blocks.SAND.getDefaultState());
        structure.fillWithBlocks(world, start, -35, -7, -67, -33, -7, 53, Blocks.SAND.getDefaultState());
        structure.fillWithBlocks(world, start, -35, -6, -64, -33, -6, -50, Blocks.SAND.getDefaultState());
        structure.fillWithBlocks(world, start, -35, -6, -44, -33, -6, -28, Blocks.SAND.getDefaultState());
        structure.fillWithBlocks(world, start, -35, -6, -26, -33, -6, -22, Blocks.SAND.getDefaultState());
        structure.fillWithBlocks(world, start, -35, -6, -3, -33, -6, 42, Blocks.SAND.getDefaultState());
        structure.fillWithBlocks(world, start, -34, -14, -77, 33, -14, 58, Blocks.STONE.getDefaultState());
        structure.fillWithBlocks(world, start, -34, -14, 59, -34, -14, 69, Blocks.SAND.getDefaultState());
        structure.fillWithBlocks(world, start, -34, -13, -80, -32, -13, -78, Blocks.SAND.getDefaultState());
        structure.fillWithBlocks(world, start, -34, -13, -76, -25, -13, 52, Blocks.STONE.getDefaultState());
        structure.fillWithBlocks(world, start, -34, -13, 53, -34, -8, 58, Blocks.SAND.getDefaultState());
        structure.fillWithBlocks(world, start, -34, -13, 59, -33, -13, 67, Blocks.SAND.getDefaultState());
        structure.fillWithBlocks(world, start, -34, -12, -79, -29, -12, -74, Blocks.SAND.getDefaultState());
        structure.fillWithBlocks(world, start, -34, -12, -72, -24, -12, -57, Blocks.STONE.getDefaultState());
        structure.fillWithBlocks(world, start, -34, -12, -55, -31, -12, -49, Blocks.SAND.getDefaultState());
        structure.fillWithBlocks(world, start, -34, -12, -48, -34, -12, 13, Blocks.STONE.getDefaultState());
        structure.fillWithBlocks(world, start, -34, -12, 30, -34, -6, 30, Blocks.SAND.getDefaultState());
        structure.fillWithBlocks(world, start, -34, -12, 31, -14, -12, 52, Blocks.STONE.getDefaultState());
        structure.fillWithBlocks(world, start, -34, -12, 59, -28, -12, 66, Blocks.SAND.getDefaultState());
        structure.fillWithBlocks(world, start, -34, -11, -78, -28, -11, -72, Blocks.SAND.getDefaultState());
        structure.fillWithBlocks(world, start, -34, -11, -44, 101, -9, -44, Blocks.SAND.getDefaultState());
        structure.fillWithBlocks(world, start, -34, -11, -43, -33, -11, -31, Blocks.STONE.getDefaultState());
        structure.fillWithBlocks(world, start, -34, -11, -30, -24, -11, -20, Blocks.SAND.getDefaultState());
        structure.fillWithBlocks(world, start, -34, -11, -19, -34, -11, -4, Blocks.STONE.getDefaultState());
        structure.fillWithBlocks(world, start, -34, -11, -3, -17, -11, 25, Blocks.SAND.getDefaultState());
        structure.fillWithBlocks(world, start, -34, -11, 36, -31, -11, 40, Blocks.STONE.getDefaultState());
        structure.fillWithBlocks(world, start, -34, -11, 42, -34, -11, 43, Blocks.STONE.getDefaultState());
        structure.fillWithBlocks(world, start, -34, -10, -77, 106, -10, 63, Blocks.SAND.getDefaultState());
        structure.fillWithBlocks(world, start, -34, -9, -76, 13, -9, -29, Blocks.SAND.getDefaultState());
        structure.fillWithBlocks(world, start, -34, -9, 61, -34, -9, 61, Blocks.SAND.getDefaultState());
        structure.fillWithBlocks(world, start, -34, -8, -74, -29, -8, -69, Blocks.SAND.getDefaultState());
        structure.fillWithBlocks(world, start, -34, -7, -72, -31, -7, -69, Blocks.SAND.getDefaultState());
        structure.fillWithBlocks(world, start, -34, -7, -68, -33, -7, 55, Blocks.SAND.getDefaultState());
        structure.fillWithBlocks(world, start, -34, -6, -68, -33, -6, 47, Blocks.SAND.getDefaultState());
        structure.fillWithBlocks(world, start, -33, -14, -82, -31, -14, -80, Blocks.SAND.getDefaultState());
        structure.fillWithBlocks(world, start, -33, -14, -78, -24, -14, 59, Blocks.STONE.getDefaultState());
        structure.fillWithBlocks(world, start, -33, -14, 60, -33, -10, 64, Blocks.SAND.getDefaultState());
        structure.fillWithBlocks(world, start, -33, -14, 69, -33, -14, 69, Blocks.SAND.getDefaultState());
        structure.fillWithBlocks(world, start, -33, -13, -81, -30, -13, -78, Blocks.SAND.getDefaultState());
        structure.fillWithBlocks(world, start, -33, -13, 53, -29, -13, 57, Blocks.STONE.getDefaultState());
        structure.fillWithBlocks(world, start, -33, -13, 58, -33, -9, 62, Blocks.SAND.getDefaultState());
        structure.fillWithBlocks(world, start, -33, -13, 68, 1, -13, 68, Blocks.SAND.getDefaultState());
        structure.fillWithBlocks(world, start, -33, -12, -80, -27, -12, -74, Blocks.SAND.getDefaultState());
        structure.fillWithBlocks(world, start, -33, -12, -56, -32, -12, -48, Blocks.SAND.getDefaultState());
        structure.fillWithBlocks(world, start, -33, -12, -47, -32, -12, 10, Blocks.STONE.getDefaultState());
        structure.fillWithBlocks(world, start, -33, -12, 11, -33, -12, 12, Blocks.STONE.getDefaultState());
        structure.fillWithBlocks(world, start, -33, -12, 13, -25, -12, 21, Blocks.SAND.getDefaultState());
        structure.fillWithBlocks(world, start, -33, -12, 30, -14, -12, 53, Blocks.STONE.getDefaultState());
        structure.fillWithBlocks(world, start, -33, -12, 54, -33, -8, 59, Blocks.SAND.getDefaultState());
        structure.fillWithBlocks(world, start, -33, -11, -79, -26, -11, -72, Blocks.SAND.getDefaultState());
        structure.fillWithBlocks(world, start, -33, -11, -69, -29, -11, -64, Blocks.STONE.getDefaultState());
        structure.fillWithBlocks(world, start, -33, -11, -19, -33, -11, -19, Blocks.SAND.getDefaultState());
        structure.fillWithBlocks(world, start, -33, -11, -18, -33, -11, -6, Blocks.STONE.getDefaultState());
        structure.fillWithBlocks(world, start, -33, -11, -5, -21, -11, 26, Blocks.SAND.getDefaultState());
        structure.fillWithBlocks(world, start, -33, -11, 43, -24, -11, 52, Blocks.SAND.getDefaultState());
        structure.fillWithBlocks(world, start, -33, -11, 65, 6, -11, 65, Blocks.SAND.getDefaultState());
        structure.fillWithBlocks(world, start, -33, -10, -78, 108, -10, 64, Blocks.SAND.getDefaultState());
        structure.fillWithBlocks(world, start, -33, -8, -75, -27, -8, -69, Blocks.SAND.getDefaultState());
        structure.fillWithBlocks(world, start, -33, -7, 56, -32, -7, 57, Blocks.SAND.getDefaultState());
        structure.fillWithBlocks(world, start, -33, -6, -69, -33, -6, 53, Blocks.SAND.getDefaultState());
        structure.fillWithBlocks(world, start, -32, -14, -79, -32, -11, -79, Blocks.SAND.getDefaultState());
        structure.fillWithBlocks(world, start, -32, -14, 60, -31, -14, 61, Blocks.STONE.getDefaultState());
        structure.fillWithBlocks(world, start, -32, -14, 62, -32, -11, 65, Blocks.SAND.getDefaultState());
        structure.fillWithBlocks(world, start, -32, -14, 66, -28, -14, 70, Blocks.SAND.getDefaultState());
        structure.fillWithBlocks(world, start, -32, -13, -77, -31, -13, 60, Blocks.STONE.getDefaultState());
        structure.fillWithBlocks(world, start, -32, -13, 61, -31, -13, 68, Blocks.SAND.getDefaultState());
        structure.fillWithBlocks(world, start, -32, -12, -73, -32, -12, -57, Blocks.STONE.getDefaultState());
        structure.fillWithBlocks(world, start, -32, -12, 11, -22, -12, 21, Blocks.SAND.getDefaultState());
        structure.fillWithBlocks(world, start, -32, -12, 24, -32, -10, 26, Blocks.SAND.getDefaultState());
        structure.fillWithBlocks(world, start, -32, -12, 27, -14, -12, 56, Blocks.STONE.getDefaultState());
        structure.fillWithBlocks(world, start, -32, -12, 57, -30, -12, 67, Blocks.SAND.getDefaultState());
        structure.fillWithBlocks(world, start, -32, -11, -71, -31, -11, -63, Blocks.STONE.getDefaultState());
        structure.fillWithBlocks(world, start, -32, -11, -62, -31, -11, -43, Blocks.SAND.getDefaultState());
        structure.fillWithBlocks(world, start, -32, -11, -42, -32, -11, -32, Blocks.STONE.getDefaultState());
        structure.fillWithBlocks(world, start, -32, -11, -31, -19, -11, -18, Blocks.SAND.getDefaultState());
        structure.fillWithBlocks(world, start, -32, -11, -17, -31, -11, -8, Blocks.STONE.getDefaultState());
        structure.fillWithBlocks(world, start, -32, -11, -7, -24, -11, 26, Blocks.SAND.getDefaultState());
        structure.fillWithBlocks(world, start, -32, -11, 32, -31, -11, 33, Blocks.SAND.getDefaultState());
        structure.fillWithBlocks(world, start, -32, -11, 34, -32, -9, 34, Blocks.SAND.getDefaultState());
        structure.fillWithBlocks(world, start, -32, -11, 35, -29, -11, 39, Blocks.STONE.getDefaultState());
        structure.fillWithBlocks(world, start, -32, -11, 42, -22, -11, 52, Blocks.SAND.getDefaultState());
        structure.fillWithBlocks(world, start, -32, -9, -77, 16, -9, -29, Blocks.SAND.getDefaultState());
        structure.fillWithBlocks(world, start, -32, -9, 61, -31, -9, 62, Blocks.SAND.getDefaultState());
        structure.fillWithBlocks(world, start, -32, -8, -68, -18, -8, -46, Blocks.SANDSTONE.getDefaultState());
        structure.fillWithBlocks(world, start, -32, -8, -45, -26, -8, -39, Blocks.SANDSTONE.getDefaultState());
        structure.fillWithBlocks(world, start, -32, -8, -38, -28, -8, 55, Blocks.SANDSTONE.getDefaultState());
        structure.fillWithBlocks(world, start, -32, -8, 56, -28, -8, 60, Blocks.SAND.getDefaultState());
        structure.fillWithBlocks(world, start, -32, -7, -68, -17, -7, -47, Blocks.SANDSTONE.getDefaultState());
        structure.fillWithBlocks(world, start, -32, -7, -46, -25, -7, -39, Blocks.SANDSTONE.getDefaultState());
        structure.fillWithBlocks(world, start, -32, -7, -38, -28, -7, 55, Blocks.SANDSTONE.getDefaultState());
        structure.fillWithBlocks(world, start, -32, -7, 58, 109, -7, 58, Blocks.SAND.getDefaultState());
        structure.fillWithBlocks(world, start, -32, -6, -70, -31, -6, -69, Blocks.SAND.getDefaultState());
        structure.fillWithBlocks(world, start, -32, -6, -68, -17, -6, -47, Blocks.SANDSTONE.getDefaultState());
        structure.fillWithBlocks(world, start, -32, -6, -46, -25, -6, -39, Blocks.SANDSTONE.getDefaultState());
        structure.fillWithBlocks(world, start, -32, -6, -38, -28, -6, 55, Blocks.SANDSTONE.getDefaultState());
        structure.fillWithBlocks(world, start, -31, -14, -83, -28, -14, -80, Blocks.SAND.getDefaultState());
        structure.fillWithBlocks(world, start, -31, -14, -79, -31, -14, 63, Blocks.STONE.getDefaultState());
        structure.fillWithBlocks(world, start, -31, -14, 64, -30, -14, 71, Blocks.SAND.getDefaultState());
        structure.fillWithBlocks(world, start, -31, -13, 69, 1, -13, 69, Blocks.SAND.getDefaultState());
        structure.fillWithBlocks(world, start, -31, -12, -81, -25, -12, -75, Blocks.SAND.getDefaultState());
        structure.fillWithBlocks(world, start, -31, -12, -73, -30, -11, -73, Blocks.SAND.getDefaultState());
        structure.fillWithBlocks(world, start, -31, -12, -56, -31, -12, -56, Blocks.STONE.getDefaultState());
        structure.fillWithBlocks(world, start, -31, -12, -48, -30, -12, -47, Blocks.SAND.getDefaultState());
        structure.fillWithBlocks(world, start, -31, -12, -46, -31, -12, 9, Blocks.STONE.getDefaultState());
        structure.fillWithBlocks(world, start, -31, -12, 10, -22, -12, 21, Blocks.SAND.getDefaultState());
        structure.fillWithBlocks(world, start, -31, -12, 24, -31, -9, 24, Blocks.SAND.getDefaultState());
        structure.fillWithBlocks(world, start, -31, -12, 25, -14, -12, 56, Blocks.STONE.getDefaultState());
        structure.fillWithBlocks(world, start, -31, -11, -80, -23, -11, -72, Blocks.SAND.getDefaultState());
        structure.fillWithBlocks(world, start, -31, -11, -42, -31, -11, -42, Blocks.SAND.getDefaultState());
        structure.fillWithBlocks(world, start, -31, -11, -41, -31, -11, -32, Blocks.STONE.getDefaultState());
        structure.fillWithBlocks(world, start, -31, -11, 34, -27, -11, 38, Blocks.STONE.getDefaultState());
        structure.fillWithBlocks(world, start, -31, -11, 41, -20, -11, 52, Blocks.SAND.getDefaultState());
        structure.fillWithBlocks(world, start, -31, -11, 66, 109, -11, 66, Blocks.SAND.getDefaultState());
        structure.fillWithBlocks(world, start, -31, -10, -79, 106, -10, 65, Blocks.SAND.getDefaultState());
        structure.fillWithBlocks(world, start, -31, -9, 63, 109, -9, 63, Blocks.SAND.getDefaultState());
        structure.fillWithBlocks(world, start, -31, -7, 56, -29, -7, 58, Blocks.SAND.getDefaultState());
        structure.fillWithBlocks(world, start, -31, -6, -71, -29, -6, -69, Blocks.SAND.getDefaultState());
        structure.fillWithBlocks(world, start, -31, -6, 56, 109, -6, 56, Blocks.SAND.getDefaultState());
        structure.fillWithBlocks(world, start, -30, -14, -79, -26, -10, -79, Blocks.SAND.getDefaultState());
        structure.fillWithBlocks(world, start, -30, -14, 60, -27, -14, 63, Blocks.STONE.getDefaultState());
        structure.fillWithBlocks(world, start, -30, -13, -82, -26, -13, -78, Blocks.SAND.getDefaultState());
        structure.fillWithBlocks(world, start, -30, -13, -77, -27, -10, -77, Blocks.SAND.getDefaultState());
        structure.fillWithBlocks(world, start, -30, -13, 58, -27, -13, 61, Blocks.STONE.getDefaultState());
        structure.fillWithBlocks(world, start, -30, -13, 62, -30, -13, 69, Blocks.SAND.getDefaultState());
        structure.fillWithBlocks(world, start, -30, -12, -56, -29, -12, -55, Blocks.STONE.getDefaultState());
        structure.fillWithBlocks(world, start, -30, -12, -54, -30, -12, -46, Blocks.SAND.getDefaultState());
        structure.fillWithBlocks(world, start, -30, -12, -45, -29, -12, -29, Blocks.STONE.getDefaultState());
        structure.fillWithBlocks(world, start, -30, -12, -28, -30, -12, -27, Blocks.STONE.getDefaultState());
        structure.fillWithBlocks(world, start, -30, -12, -26, -28, -12, -24, Blocks.SAND.getDefaultState());
        structure.fillWithBlocks(world, start, -30, -12, -23, -30, -12, 8, Blocks.STONE.getDefaultState());
        structure.fillWithBlocks(world, start, -30, -12, 9, -22, -12, 21, Blocks.SAND.getDefaultState());
        structure.fillWithBlocks(world, start, -30, -12, 24, -14, -12, 56, Blocks.STONE.getDefaultState());
        structure.fillWithBlocks(world, start, -30, -12, 68, 5, -12, 68, Blocks.SAND.getDefaultState());
        structure.fillWithBlocks(world, start, -30, -11, -71, -30, -11, -71, Blocks.SAND.getDefaultState());
        structure.fillWithBlocks(world, start, -30, -11, -70, -30, -11, -62, Blocks.STONE.getDefaultState());
        structure.fillWithBlocks(world, start, -30, -11, -43, -28, -11, -41, Blocks.SAND.getDefaultState());
        structure.fillWithBlocks(world, start, -30, -11, -40, -30, -11, -33, Blocks.STONE.getDefaultState());
        structure.fillWithBlocks(world, start, -30, -11, -32, -16, -11, -18, Blocks.SAND.getDefaultState());
        structure.fillWithBlocks(world, start, -30, -11, -17, -30, -11, -17, Blocks.SAND.getDefaultState());
        structure.fillWithBlocks(world, start, -30, -11, -16, -30, -11, -9, Blocks.STONE.getDefaultState());
        structure.fillWithBlocks(world, start, -30, -11, -8, -25, -11, 26, Blocks.SAND.getDefaultState());
        structure.fillWithBlocks(world, start, -30, -11, 32, -24, -11, 38, Blocks.STONE.getDefaultState());
        structure.fillWithBlocks(world, start, -30, -11, 40, -19, -11, 52, Blocks.SAND.getDefaultState());
        structure.fillWithBlocks(world, start, -30, -9, -78, 19, -9, -29, Blocks.SAND.getDefaultState());
        structure.fillWithBlocks(world, start, -30, -9, 61, -28, -9, 63, Blocks.SAND.getDefaultState());
        structure.fillWithBlocks(world, start, -30, -8, -76, -23, -8, -69, Blocks.SAND.getDefaultState());
        structure.fillWithBlocks(world, start, -30, -8, 61, -30, -8, 61, Blocks.SAND.getDefaultState());
        structure.fillWithBlocks(world, start, -30, -7, -72, -27, -7, -69, Blocks.SAND.getDefaultState());
        structure.fillWithBlocks(world, start, -30, -7, 59, 108, -7, 59, Blocks.SAND.getDefaultState());
        structure.fillWithBlocks(world, start, -30, -5, 3, -30, -5, 4, Blocks.SANDSTONE_SLAB.getDefaultState().with(SlabBlock.TYPE, SlabType.BOTTOM).with(SlabBlock.WATERLOGGED, false));
        structure.fillWithBlocks(world, start, -29, -14, 64, -29, -14, 64, Blocks.STONE.getDefaultState());
        structure.fillWithBlocks(world, start, -29, -14, 71, -28, -14, 72, Blocks.SAND.getDefaultState());
        structure.fillWithBlocks(world, start, -29, -13, 62, 107, -13, 62, Blocks.STONE.getDefaultState());
        structure.fillWithBlocks(world, start, -29, -13, 63, -28, -13, 70, Blocks.SAND.getDefaultState());
        structure.fillWithBlocks(world, start, -29, -12, -73, -24, -12, -54, Blocks.STONE.getDefaultState());
        structure.fillWithBlocks(world, start, -29, -12, -53, -29, -12, -46, Blocks.SAND.getDefaultState());
        structure.fillWithBlocks(world, start, -29, -12, -28, -24, -12, -23, Blocks.SAND.getDefaultState());
        structure.fillWithBlocks(world, start, -29, -12, -22, -29, -12, 7, Blocks.STONE.getDefaultState());
        structure.fillWithBlocks(world, start, -29, -12, 8, -24, -12, 21, Blocks.SAND.getDefaultState());
        structure.fillWithBlocks(world, start, -29, -12, 23, -14, -12, 57, Blocks.STONE.getDefaultState());
        structure.fillWithBlocks(world, start, -29, -12, 58, -29, -12, 68, Blocks.SAND.getDefaultState());
        structure.fillWithBlocks(world, start, -29, -11, -71, -28, -11, -70, Blocks.SAND.getDefaultState());
        structure.fillWithBlocks(world, start, -29, -11, -63, -28, -11, -62, Blocks.STONE.getDefaultState());
        structure.fillWithBlocks(world, start, -29, -11, -40, -28, -11, -39, Blocks.SAND.getDefaultState());
        structure.fillWithBlocks(world, start, -29, -11, -38, -29, -11, -34, Blocks.STONE.getDefaultState());
        structure.fillWithBlocks(world, start, -29, -11, -33, -14, -11, -18, Blocks.SAND.getDefaultState());
        structure.fillWithBlocks(world, start, -29, -11, -17, -28, -11, -16, Blocks.SAND.getDefaultState());
        structure.fillWithBlocks(world, start, -29, -11, -15, -29, -11, -10, Blocks.STONE.getDefaultState());
        structure.fillWithBlocks(world, start, -29, -11, -9, -27, -11, 27, Blocks.SAND.getDefaultState());
        structure.fillWithBlocks(world, start, -29, -11, 28, -29, -10, 29, Blocks.SAND.getDefaultState());
        structure.fillWithBlocks(world, start, -29, -11, 30, -22, -11, 37, Blocks.STONE.getDefaultState());
        structure.fillWithBlocks(world, start, -29, -11, 67, 43, -11, 67, Blocks.SAND.getDefaultState());
        structure.fillWithBlocks(world, start, -29, -10, 66, 106, -10, 66, Blocks.SAND.getDefaultState());
        structure.fillWithBlocks(world, start, -29, -9, 55, -20, -9, 64, Blocks.SAND.getDefaultState());
        structure.fillWithBlocks(world, start, -29, -8, 61, -28, -8, 62, Blocks.SAND.getDefaultState());
        structure.fillWithBlocks(world, start, -29, -7, -73, -25, -7, -69, Blocks.SAND.getDefaultState());
        structure.fillWithBlocks(world, start, -29, -6, 57, 107, -6, 57, Blocks.SAND.getDefaultState());
        structure.fillWithBlocks(world, start, -28, -14, -84, -24, -14, -80, Blocks.SAND.getDefaultState());
        structure.fillWithBlocks(world, start, -28, -14, 64, -27, -14, 65, Blocks.STONE.getDefaultState());
        structure.fillWithBlocks(world, start, -28, -13, 53, -19, -13, 62, Blocks.STONE.getDefaultState());
        structure.fillWithBlocks(world, start, -28, -12, -53, -28, -12, -53, Blocks.STONE.getDefaultState());
        structure.fillWithBlocks(world, start, -28, -12, -52, -28, -12, -45, Blocks.SAND.getDefaultState());
        structure.fillWithBlocks(world, start, -28, -12, -44, -28, -12, -29, Blocks.STONE.getDefaultState());
        structure.fillWithBlocks(world, start, -28, -12, -22, -28, -12, -22, Blocks.SAND.getDefaultState());
        structure.fillWithBlocks(world, start, -28, -12, -21, -28, -12, 7, Blocks.STONE.getDefaultState());
        structure.fillWithBlocks(world, start, -28, -12, 58, -28, -12, 58, Blocks.STONE.getDefaultState());
        structure.fillWithBlocks(world, start, -28, -12, 67, -26, -12, 69, Blocks.SAND.getDefaultState());
        structure.fillWithBlocks(world, start, -28, -11, -69, -28, -11, -69, Blocks.SAND.getDefaultState());
        structure.fillWithBlocks(world, start, -28, -11, -68, -28, -11, -61, Blocks.STONE.getDefaultState());
        structure.fillWithBlocks(world, start, -28, -11, -60, -28, -11, -15, Blocks.SAND.getDefaultState());
        structure.fillWithBlocks(world, start, -28, -11, -14, -24, -11, -10, Blocks.STONE.getDefaultState());
        structure.fillWithBlocks(world, start, -28, -11, 28, -28, -9, 28, Blocks.SAND.getDefaultState());
        structure.fillWithBlocks(world, start, -28, -11, 29, -20, -11, 37, Blocks.STONE.getDefaultState());
        structure.fillWithBlocks(world, start, -28, -11, 39, -16, -11, 51, Blocks.SAND.getDefaultState());
        structure.fillWithBlocks(world, start, -28, -11, 54, -25, -11, 57, Blocks.STONE.getDefaultState());
        structure.fillWithBlocks(world, start, -28, -11, 58, -28, -11, 67, Blocks.SAND.getDefaultState());
        structure.fillWithBlocks(world, start, -28, -9, 65, 105, -9, 65, Blocks.SAND.getDefaultState());
        structure.fillWithBlocks(world, start, -28, -7, 56, -25, -7, 59, Blocks.SAND.getDefaultState());
        structure.fillWithBlocks(world, start, -28, -6, -71, -27, -6, -69, Blocks.SAND.getDefaultState());
        structure.fillWithBlocks(world, start, -28, -5, -38, -28, -5, -38, Blocks.BIRCH_LEAVES.getDefaultState().with(LeavesBlock.PERSISTENT, true).with(LeavesBlock.DISTANCE, 2));
        structure.fillWithBlocks(world, start, -28, -5, -1, -28, -5, -1, Blocks.SANDSTONE_SLAB.getDefaultState().with(SlabBlock.TYPE, SlabType.BOTTOM).with(SlabBlock.WATERLOGGED, false));
        structure.fillWithBlocks(world, start, -27, -14, 66, -27, -14, 73, Blocks.SAND.getDefaultState());
        structure.fillWithBlocks(world, start, -27, -13, -83, -22, -13, -78, Blocks.SAND.getDefaultState());
        structure.fillWithBlocks(world, start, -27, -13, 63, 106, -13, 63, Blocks.STONE.getDefaultState());
        structure.fillWithBlocks(world, start, -27, -13, 64, -26, -13, 71, Blocks.SAND.getDefaultState());
        structure.fillWithBlocks(world, start, -27, -12, -82, -20, -12, -75, Blocks.SAND.getDefaultState());
        structure.fillWithBlocks(world, start, -27, -12, -53, -26, -12, -52, Blocks.STONE.getDefaultState());
        structure.fillWithBlocks(world, start, -27, -12, -51, -27, -12, -44, Blocks.SAND.getDefaultState());
        structure.fillWithBlocks(world, start, -27, -12, -43, -27, -12, -30, Blocks.STONE.getDefaultState());
        structure.fillWithBlocks(world, start, -27, -12, -29, -20, -12, -22, Blocks.SAND.getDefaultState());
        structure.fillWithBlocks(world, start, -27, -12, -21, -21, -9, -21, Blocks.SAND.getDefaultState());
        structure.fillWithBlocks(world, start, -27, -12, -1, -20, -12, 6, Blocks.STONE.getDefaultState());
        structure.fillWithBlocks(world, start, -27, -12, 7, -26, -12, 21, Blocks.SAND.getDefaultState());
        structure.fillWithBlocks(world, start, -27, -12, 22, -13, -12, 36, Blocks.STONE.getDefaultState());
        structure.fillWithBlocks(world, start, -27, -12, 58, -26, -12, 59, Blocks.STONE.getDefaultState());
        structure.fillWithBlocks(world, start, -27, -12, 60, -25, -12, 69, Blocks.SAND.getDefaultState());
        structure.fillWithBlocks(world, start, -27, -11, -71, -24, -11, -68, Blocks.SAND.getDefaultState());
        structure.fillWithBlocks(world, start, -27, -11, -67, -27, -11, -60, Blocks.STONE.getDefaultState());
        structure.fillWithBlocks(world, start, -27, -11, -59, -27, -11, -15, Blocks.SAND.getDefaultState());
        structure.fillWithBlocks(world, start, -27, -11, 28, -19, -11, 36, Blocks.STONE.getDefaultState());
        structure.fillWithBlocks(world, start, -27, -11, 53, -22, -11, 58, Blocks.STONE.getDefaultState());
        structure.fillWithBlocks(world, start, -27, -11, 59, -27, -11, 68, Blocks.SAND.getDefaultState());
        structure.fillWithBlocks(world, start, -27, -8, -38, -27, -7, -38, Blocks.SAND.getDefaultState());
        structure.fillWithBlocks(world, start, -27, -8, -37, -26, -8, 55, Blocks.SANDSTONE.getDefaultState());
        structure.fillWithBlocks(world, start, -27, -8, 56, -20, -8, 63, Blocks.SAND.getDefaultState());
        structure.fillWithBlocks(world, start, -27, -7, -37, -25, -7, 55, Blocks.SANDSTONE.getDefaultState());
        structure.fillWithBlocks(world, start, -27, -6, -37, -25, -6, 55, Blocks.SANDSTONE.getDefaultState());
        structure.fillWithBlocks(world, start, -27, -5, -39, -27, -5, -39, Blocks.BIRCH_LEAVES.getDefaultState().with(LeavesBlock.PERSISTENT, true).with(LeavesBlock.DISTANCE, 2));
        structure.fillWithBlocks(world, start, -27, -4, -39, -27, -4, -39, Blocks.BIRCH_LEAVES.getDefaultState().with(LeavesBlock.PERSISTENT, true).with(LeavesBlock.DISTANCE, 3));
        structure.fillWithBlocks(world, start, -27, -2, -26, -27, -2, -26, Blocks.BIRCH_LEAVES.getDefaultState().with(LeavesBlock.PERSISTENT, true).with(LeavesBlock.DISTANCE, 2));
        structure.fillWithBlocks(world, start, -26, -14, 60, -20, -14, 66, Blocks.STONE.getDefaultState());
        structure.fillWithBlocks(world, start, -26, -14, 67, -24, -14, 73, Blocks.SAND.getDefaultState());
        structure.fillWithBlocks(world, start, -26, -13, -77, -25, -13, 63, Blocks.STONE.getDefaultState());
        structure.fillWithBlocks(world, start, -26, -12, -74, -26, -8, -74, Blocks.SAND.getDefaultState());
        structure.fillWithBlocks(world, start, -26, -12, -51, -26, -12, -51, Blocks.STONE.getDefaultState());
        structure.fillWithBlocks(world, start, -26, -12, -50, -26, -12, -43, Blocks.SAND.getDefaultState());
        structure.fillWithBlocks(world, start, -26, -12, -42, -26, -12, -31, Blocks.STONE.getDefaultState());
        structure.fillWithBlocks(world, start, -26, -12, -30, -20, -12, -22, Blocks.SAND.getDefaultState());
        structure.fillWithBlocks(world, start, -26, -11, -81, -12, -11, -67, Blocks.SAND.getDefaultState());
        structure.fillWithBlocks(world, start, -26, -11, -66, -25, -11, -59, Blocks.STONE.getDefaultState());
        structure.fillWithBlocks(world, start, -26, -11, -58, -26, -11, -15, Blocks.SAND.getDefaultState());
        structure.fillWithBlocks(world, start, -26, -11, -9, -8, -11, -9, Blocks.STONE.getDefaultState());
        structure.fillWithBlocks(world, start, -26, -11, 27, -25, -11, 38, Blocks.STONE.getDefaultState());
        structure.fillWithBlocks(world, start, -26, -11, 59, -16, -11, 59, Blocks.STONE.getDefaultState());
        structure.fillWithBlocks(world, start, -26, -11, 60, -25, -11, 68, Blocks.SAND.getDefaultState());
        structure.fillWithBlocks(world, start, -26, -10, -80, -5, -10, 67, Blocks.SAND.getDefaultState());
        structure.fillWithBlocks(world, start, -26, -9, 66, 102, -9, 66, Blocks.SAND.getDefaultState());
        structure.fillWithBlocks(world, start, -26, -8, -77, -18, -8, -69, Blocks.SAND.getDefaultState());
        structure.fillWithBlocks(world, start, -26, -8, -38, -26, -6, 55, Blocks.SANDSTONE.getDefaultState());
        structure.fillWithBlocks(world, start, -26, -6, -70, -25, -6, -69, Blocks.SAND.getDefaultState());
        structure.fillWithBlocks(world, start, -26, -5, 2, -26, -5, 3, Blocks.SANDSTONE_SLAB.getDefaultState().with(SlabBlock.TYPE, SlabType.BOTTOM).with(SlabBlock.WATERLOGGED, false));
        structure.fillWithBlocks(world, start, -26, -3, -25, -26, -2, -25, Blocks.BIRCH_LEAVES.getDefaultState().with(LeavesBlock.PERSISTENT, true).with(LeavesBlock.DISTANCE, 2));
        structure.fillWithBlocks(world, start, -26, -2, -26, -26, -2, -26, Blocks.BIRCH_LEAVES.getDefaultState().with(LeavesBlock.PERSISTENT, true).with(LeavesBlock.DISTANCE, 1));
        structure.fillWithBlocks(world, start, -26, -1, -26, -26, -1, -26, Blocks.BIRCH_LEAVES.getDefaultState().with(LeavesBlock.PERSISTENT, true).with(LeavesBlock.DISTANCE, 2));
        structure.fillWithBlocks(world, start, -25, -14, -79, -24, -14, 66, Blocks.STONE.getDefaultState());
        structure.fillWithBlocks(world, start, -25, -14, 74, 42, -14, 74, Blocks.SAND.getDefaultState());
        structure.fillWithBlocks(world, start, -25, -13, 64, 107, -13, 64, Blocks.STONE.getDefaultState());
        structure.fillWithBlocks(world, start, -25, -13, 65, -24, -13, 72, Blocks.SAND.getDefaultState());
        structure.fillWithBlocks(world, start, -25, -12, -74, -25, -12, -50, Blocks.STONE.getDefaultState());
        structure.fillWithBlocks(world, start, -25, -12, -49, -24, -12, -42, Blocks.SAND.getDefaultState());
        structure.fillWithBlocks(world, start, -25, -12, -41, -25, -12, -31, Blocks.STONE.getDefaultState());
        structure.fillWithBlocks(world, start, -25, -12, -20, -23, -10, -20, Blocks.SAND.getDefaultState());
        structure.fillWithBlocks(world, start, -25, -12, 7, -1, -12, 7, Blocks.STONE.getDefaultState());
        structure.fillWithBlocks(world, start, -25, -12, 58, -24, -12, 59, Blocks.STONE.getDefaultState());
        structure.fillWithBlocks(world, start, -25, -12, 70, -25, -12, 70, Blocks.SAND.getDefaultState());
        structure.fillWithBlocks(world, start, -25, -11, -58, -25, -11, -58, Blocks.STONE.getDefaultState());
        structure.fillWithBlocks(world, start, -25, -11, -57, -25, -11, -15, Blocks.SAND.getDefaultState());
        structure.fillWithBlocks(world, start, -25, -11, 69, 100, -11, 69, Blocks.SAND.getDefaultState());
        structure.fillWithBlocks(world, start, -25, -9, -79, -6, -9, -29, Blocks.SAND.getDefaultState());
        structure.fillWithBlocks(world, start, -25, -8, -45, -23, -8, -38, Blocks.SANDSTONE.getDefaultState());
        structure.fillWithBlocks(world, start, -25, -8, -37, -19, -8, -31, Blocks.SAND.getDefaultState());
        structure.fillWithBlocks(world, start, -25, -8, -30, -22, -8, -27, Blocks.SANDSTONE.getDefaultState());
        structure.fillWithBlocks(world, start, -25, -8, -26, -25, -8, 55, Blocks.SANDSTONE.getDefaultState());
        structure.fillWithBlocks(world, start, -25, -8, 64, 102, -8, 64, Blocks.SAND.getDefaultState());
        structure.fillWithBlocks(world, start, -25, -7, -74, -20, -7, -69, Blocks.SAND.getDefaultState());
        structure.fillWithBlocks(world, start, -25, -7, -38, -24, -7, -37, Blocks.SANDSTONE.getDefaultState());
        structure.fillWithBlocks(world, start, -25, -6, -38, -24, -6, -37, Blocks.SANDSTONE.getDefaultState());
        structure.fillWithBlocks(world, start, -25, -5, -40, -25, -3, -40, Blocks.SPRUCE_FENCE.getDefaultState().with(FourWayBlock.WATERLOGGED, false).with(FourWayBlock.NORTH, false).with(FourWayBlock.SOUTH, false).with(FourWayBlock.EAST, false).with(FourWayBlock.WEST, false));
        structure.fillWithBlocks(world, start, -25, -5, -37, -25, -5, -31, Blocks.SANDSTONE.getDefaultState());
        structure.fillWithBlocks(world, start, -25, -4, -44, -25, -3, -44, Blocks.SPRUCE_FENCE.getDefaultState().with(FourWayBlock.WATERLOGGED, false).with(FourWayBlock.NORTH, false).with(FourWayBlock.SOUTH, false).with(FourWayBlock.EAST, false).with(FourWayBlock.WEST, false));
        structure.fillWithBlocks(world, start, -25, -4, -37, -25, -1, -37, Blocks.CUT_SANDSTONE.getDefaultState());
        structure.fillWithBlocks(world, start, -25, -4, -36, -25, -1, -36, Blocks.SMOOTH_SANDSTONE.getDefaultState());
        structure.fillWithBlocks(world, start, -25, -4, -35, -25, -3, -34, Blocks.SPRUCE_FENCE.getDefaultState().with(FourWayBlock.WATERLOGGED, false).with(FourWayBlock.NORTH, true).with(FourWayBlock.SOUTH, true).with(FourWayBlock.EAST, false).with(FourWayBlock.WEST, false));
        structure.fillWithBlocks(world, start, -25, -4, -33, -25, -3, -32, Blocks.SMOOTH_SANDSTONE.getDefaultState());
        structure.fillWithBlocks(world, start, -25, -4, -31, -25, -1, -31, Blocks.CUT_SANDSTONE.getDefaultState());
        structure.fillWithBlocks(world, start, -25, -3, -26, -25, -3, -25, Blocks.BIRCH_LEAVES.getDefaultState().with(LeavesBlock.PERSISTENT, true).with(LeavesBlock.DISTANCE, 1));
        structure.fillWithBlocks(world, start, -25, -3, -24, -25, -3, -24, Blocks.BIRCH_LEAVES.getDefaultState().with(LeavesBlock.PERSISTENT, true).with(LeavesBlock.DISTANCE, 2));
        structure.fillWithBlocks(world, start, -25, -2, -44, -25, -2, -40, Blocks.WHITE_WOOL.getDefaultState());
        structure.fillWithBlocks(world, start, -25, -2, -35, -25, -1, -32, Blocks.SMOOTH_SANDSTONE.getDefaultState());
        structure.fillWithBlocks(world, start, -25, -2, -27, -24, -2, -27, Blocks.BIRCH_LEAVES.getDefaultState().with(LeavesBlock.PERSISTENT, true).with(LeavesBlock.DISTANCE, 1));
        structure.fillWithBlocks(world, start, -25, -2, -25, -24, -2, -25, Blocks.BIRCH_LEAVES.getDefaultState().with(LeavesBlock.PERSISTENT, true).with(LeavesBlock.DISTANCE, 1));
        structure.fillWithBlocks(world, start, -25, -1, -26, -24, -1, -26, Blocks.BIRCH_LEAVES.getDefaultState().with(LeavesBlock.PERSISTENT, true).with(LeavesBlock.DISTANCE, 1));
        structure.fillWithBlocks(world, start, -25, -1, -25, -24, -1, -25, Blocks.BIRCH_LEAVES.getDefaultState().with(LeavesBlock.PERSISTENT, true).with(LeavesBlock.DISTANCE, 2));
        structure.fillWithBlocks(world, start, -24, -13, -76, -23, -13, -75, Blocks.SAND.getDefaultState());
        structure.fillWithBlocks(world, start, -24, -13, -74, 32, -13, 64, Blocks.STONE.getDefaultState());
        structure.fillWithBlocks(world, start, -24, -12, -74, -24, -12, -74, Blocks.SAND.getDefaultState());
        structure.fillWithBlocks(world, start, -24, -12, -53, -21, -12, -50, Blocks.STONE.getDefaultState());
        structure.fillWithBlocks(world, start, -24, -12, -41, -24, -12, -41, Blocks.SAND.getDefaultState());
        structure.fillWithBlocks(world, start, -24, -12, -40, -24, -12, -32, Blocks.STONE.getDefaultState());
        structure.fillWithBlocks(world, start, -24, -12, -31, -20, -12, -22, Blocks.SAND.getDefaultState());
        structure.fillWithBlocks(world, start, -24, -12, 60, -6, -12, 60, Blocks.STONE.getDefaultState());
        structure.fillWithBlocks(world, start, -24, -12, 61, -23, -12, 71, Blocks.SAND.getDefaultState());
        structure.fillWithBlocks(world, start, -24, -11, -66, 3, -9, -66, Blocks.SAND.getDefaultState());
        structure.fillWithBlocks(world, start, -24, -11, -65, -23, -11, -57, Blocks.STONE.getDefaultState());
        structure.fillWithBlocks(world, start, -24, -11, -56, -24, -11, -15, Blocks.SAND.getDefaultState());
        structure.fillWithBlocks(world, start, -24, -11, -8, -24, -11, -8, Blocks.STONE.getDefaultState());
        structure.fillWithBlocks(world, start, -24, -11, 27, -20, -9, 27, Blocks.SAND.getDefaultState());
        structure.fillWithBlocks(world, start, -24, -11, 61, -16, -11, 69, Blocks.SAND.getDefaultState());
        structure.fillWithBlocks(world, start, -24, -10, 68, 100, -10, 68, Blocks.SAND.getDefaultState());
        structure.fillWithBlocks(world, start, -24, -8, -26, -24, -7, -26, Blocks.SAND.getDefaultState());
        structure.fillWithBlocks(world, start, -24, -8, -25, -21, -8, -12, Blocks.SANDSTONE.getDefaultState());
        structure.fillWithBlocks(world, start, -24, -8, -11, -24, -8, 55, Blocks.SANDSTONE.getDefaultState());
        structure.fillWithBlocks(world, start, -24, -7, -46, -23, -7, -37, Blocks.SANDSTONE.getDefaultState());
        structure.fillWithBlocks(world, start, -24, -7, -36, -20, -7, -32, Blocks.SAND.getDefaultState());
        structure.fillWithBlocks(world, start, -24, -7, -31, -24, -7, -27, Blocks.SANDSTONE.getDefaultState());
        structure.fillWithBlocks(world, start, -24, -7, -25, -20, -7, -18, Blocks.SANDSTONE.getDefaultState());
        structure.fillWithBlocks(world, start, -24, -7, -17, -21, -7, -12, Blocks.SANDSTONE.getDefaultState());
        structure.fillWithBlocks(world, start, -24, -7, -11, -24, -7, 55, Blocks.SANDSTONE.getDefaultState());
        structure.fillWithBlocks(world, start, -24, -7, 56, -20, -7, 60, Blocks.SAND.getDefaultState());
        structure.fillWithBlocks(world, start, -24, -6, -70, -23, -6, -69, Blocks.SAND.getDefaultState());
        structure.fillWithBlocks(world, start, -24, -6, -46, -23, -6, -37, Blocks.SANDSTONE.getDefaultState());
        structure.fillWithBlocks(world, start, -24, -6, -36, -20, -6, -32, Blocks.SPRUCE_PLANKS.getDefaultState());
        structure.fillWithBlocks(world, start, -24, -6, -31, -24, -6, -27, Blocks.SANDSTONE.getDefaultState());
        structure.fillWithBlocks(world, start, -24, -6, -26, -24, -2, -26, Blocks.STRIPPED_SPRUCE_LOG.getDefaultState());
        structure.fillWithBlocks(world, start, -24, -6, -25, -20, -6, -18, Blocks.SANDSTONE.getDefaultState());
        structure.fillWithBlocks(world, start, -24, -6, -17, -21, -6, -12, Blocks.SANDSTONE.getDefaultState());
        structure.fillWithBlocks(world, start, -24, -6, -11, -24, -6, 55, Blocks.SANDSTONE.getDefaultState());
        structure.fillWithBlocks(world, start, -24, -5, -37, -14, -5, -37, Blocks.SANDSTONE.getDefaultState());
        structure.fillWithBlocks(world, start, -24, -5, -20, -24, -2, -20, Blocks.SPRUCE_FENCE.getDefaultState().with(FourWayBlock.WATERLOGGED, false).with(FourWayBlock.NORTH, false).with(FourWayBlock.SOUTH, false).with(FourWayBlock.EAST, false).with(FourWayBlock.WEST, false));
        structure.fillWithBlocks(world, start, -24, -5, -12, -24, -2, -12, Blocks.SPRUCE_FENCE.getDefaultState().with(FourWayBlock.WATERLOGGED, false).with(FourWayBlock.NORTH, false).with(FourWayBlock.SOUTH, false).with(FourWayBlock.EAST, false).with(FourWayBlock.WEST, false));
        structure.fillWithBlocks(world, start, -24, -5, -11, -24, -5, -11, Blocks.BIRCH_LEAVES.getDefaultState().with(LeavesBlock.PERSISTENT, true).with(LeavesBlock.DISTANCE, 2));
        structure.fillWithBlocks(world, start, -24, -4, -37, -23, -3, -37, Blocks.SMOOTH_SANDSTONE.getDefaultState());
        structure.fillWithBlocks(world, start, -24, -4, -31, -24, -1, -31, Blocks.SMOOTH_SANDSTONE.getDefaultState());
        structure.fillWithBlocks(world, start, -24, -2, -37, -19, -1, -37, Blocks.SMOOTH_SANDSTONE.getDefaultState());
        structure.fillWithBlocks(world, start, -24, -2, -30, -23, -2, -29, Blocks.WHITE_WOOL.getDefaultState());
        structure.fillWithBlocks(world, start, -24, -1, -44, -23, -1, -40, Blocks.WHITE_WOOL.getDefaultState());
        structure.fillWithBlocks(world, start, -24, -1, -36, -24, -1, -32, Blocks.SPRUCE_SLAB.getDefaultState().with(SlabBlock.TYPE, SlabType.BOTTOM).with(SlabBlock.WATERLOGGED, false));
        structure.fillWithBlocks(world, start, -24, -1, -20, -21, -1, -20, Blocks.BROWN_WOOL.getDefaultState());
        structure.fillWithBlocks(world, start, -24, -1, -14, -22, -1, -12, Blocks.BROWN_WOOL.getDefaultState());
        structure.fillWithBlocks(world, start, -23, -14, -84, -19, -14, -80, Blocks.SAND.getDefaultState());
        structure.fillWithBlocks(world, start, -23, -14, -78, -17, -9, -78, Blocks.SAND.getDefaultState());
        structure.fillWithBlocks(world, start, -23, -14, 59, -16, -14, 67, Blocks.STONE.getDefaultState());
        structure.fillWithBlocks(world, start, -23, -14, 68, -21, -14, 74, Blocks.SAND.getDefaultState());
        structure.fillWithBlocks(world, start, -23, -13, -77, -21, -13, -75, Blocks.SAND.getDefaultState());
        structure.fillWithBlocks(world, start, -23, -13, 65, -11, -13, 65, Blocks.STONE.getDefaultState());
        structure.fillWithBlocks(world, start, -23, -13, 66, -20, -13, 73, Blocks.SAND.getDefaultState());
        structure.fillWithBlocks(world, start, -23, -12, -74, -21, -12, -72, Blocks.SAND.getDefaultState());
        structure.fillWithBlocks(world, start, -23, -12, -71, -23, -12, -49, Blocks.STONE.getDefaultState());
        structure.fillWithBlocks(world, start, -23, -12, -48, -21, -12, -40, Blocks.SAND.getDefaultState());
        structure.fillWithBlocks(world, start, -23, -12, -39, -23, -12, -32, Blocks.STONE.getDefaultState());
        structure.fillWithBlocks(world, start, -23, -12, 8, -1, -12, 8, Blocks.STONE.getDefaultState());
        structure.fillWithBlocks(world, start, -23, -12, 58, -21, -12, 60, Blocks.STONE.getDefaultState());
        structure.fillWithBlocks(world, start, -23, -11, -56, -23, -11, -56, Blocks.STONE.getDefaultState());
        structure.fillWithBlocks(world, start, -23, -11, -55, -23, -11, -16, Blocks.SAND.getDefaultState());
        structure.fillWithBlocks(world, start, -23, -11, -15, -15, -11, -7, Blocks.STONE.getDefaultState());
        structure.fillWithBlocks(world, start, -23, -11, -6, -22, -11, 27, Blocks.SAND.getDefaultState());
        structure.fillWithBlocks(world, start, -23, -11, 60, -14, -11, 69, Blocks.SAND.getDefaultState());
        structure.fillWithBlocks(world, start, -23, -9, 67, 99, -9, 67, Blocks.SAND.getDefaultState());
        structure.fillWithBlocks(world, start, -23, -8, -26, -19, -8, -22, Blocks.SANDSTONE.getDefaultState());
        structure.fillWithBlocks(world, start, -23, -8, -11, -23, -7, -11, Blocks.SAND.getDefaultState());
        structure.fillWithBlocks(world, start, -23, -8, -10, -21, -8, 55, Blocks.SANDSTONE.getDefaultState());
        structure.fillWithBlocks(world, start, -23, -8, 65, 100, -8, 65, Blocks.SAND.getDefaultState());
        structure.fillWithBlocks(world, start, -23, -7, -30, -18, -7, -21, Blocks.SANDSTONE.getDefaultState());
        structure.fillWithBlocks(world, start, -23, -7, -10, -21, -7, 55, Blocks.SANDSTONE.getDefaultState());
        structure.fillWithBlocks(world, start, -23, -6, -30, -18, -6, -21, Blocks.SANDSTONE.getDefaultState());
        structure.fillWithBlocks(world, start, -23, -6, -10, -21, -6, 55, Blocks.SANDSTONE.getDefaultState());
        structure.fillWithBlocks(world, start, -23, -3, -31, -22, -2, -31, Blocks.SMOOTH_SANDSTONE.getDefaultState());
        structure.fillWithBlocks(world, start, -23, -3, -26, -23, -3, -25, Blocks.BIRCH_LEAVES.getDefaultState().with(LeavesBlock.PERSISTENT, true).with(LeavesBlock.DISTANCE, 1));
        structure.fillWithBlocks(world, start, -23, -2, 43, -23, -2, 43, Blocks.BIRCH_LEAVES.getDefaultState().with(LeavesBlock.PERSISTENT, true).with(LeavesBlock.DISTANCE, 1));
        structure.fillWithBlocks(world, start, -23, -1, -36, -23, -1, -33, Blocks.SPRUCE_SLAB.getDefaultState().with(SlabBlock.TYPE, SlabType.DOUBLE).with(SlabBlock.WATERLOGGED, false));
        structure.fillWithBlocks(world, start, -23, -1, -32, -20, -1, -32, Blocks.SPRUCE_SLAB.getDefaultState().with(SlabBlock.TYPE, SlabType.BOTTOM).with(SlabBlock.WATERLOGGED, false));
        structure.fillWithBlocks(world, start, -23, -1, -31, -20, -1, -31, Blocks.SMOOTH_SANDSTONE.getDefaultState());
        structure.fillWithBlocks(world, start, -23, -1, -16, -21, -1, -12, Blocks.BROWN_WOOL.getDefaultState());
        structure.fillWithBlocks(world, start, -23, -1, 45, -23, 0, 45, Blocks.BIRCH_LEAVES.getDefaultState().with(LeavesBlock.PERSISTENT, true).with(LeavesBlock.DISTANCE, 2));
        structure.fillWithBlocks(world, start, -23, -1, 46, -23, -1, 46, Blocks.BIRCH_LEAVES.getDefaultState().with(LeavesBlock.PERSISTENT, true).with(LeavesBlock.DISTANCE, 3));
        structure.fillWithBlocks(world, start, -23, 0, -36, -23, 0, -34, Blocks.SPRUCE_FENCE.getDefaultState().with(FourWayBlock.WATERLOGGED, false).with(FourWayBlock.NORTH, true).with(FourWayBlock.SOUTH, true).with(FourWayBlock.EAST, false).with(FourWayBlock.WEST, false));
        structure.fillWithBlocks(world, start, -23, 1, -33, -23, 2, -33, Blocks.SPRUCE_FENCE.getDefaultState().with(FourWayBlock.WATERLOGGED, false).with(FourWayBlock.NORTH, false).with(FourWayBlock.SOUTH, false).with(FourWayBlock.EAST, false).with(FourWayBlock.WEST, false));
        structure.fillWithBlocks(world, start, -22, -14, -79, -21, -14, -78, Blocks.SAND.getDefaultState());
        structure.fillWithBlocks(world, start, -22, -14, 75, 90, -14, 75, Blocks.SAND.getDefaultState());
        structure.fillWithBlocks(world, start, -22, -12, -71, -22, -12, -71, Blocks.SAND.getDefaultState());
        structure.fillWithBlocks(world, start, -22, -12, -70, -22, -12, -49, Blocks.STONE.getDefaultState());
        structure.fillWithBlocks(world, start, -22, -12, -39, -20, -10, -39, Blocks.SAND.getDefaultState());
        structure.fillWithBlocks(world, start, -22, -12, -38, -17, -12, -33, Blocks.STONE.getDefaultState());
        structure.fillWithBlocks(world, start, -22, -12, -32, -21, -12, -21, Blocks.SAND.getDefaultState());
        structure.fillWithBlocks(world, start, -22, -12, -20, -3, -12, 8, Blocks.STONE.getDefaultState());
        structure.fillWithBlocks(world, start, -22, -12, 61, -7, -12, 61, Blocks.STONE.getDefaultState());
        structure.fillWithBlocks(world, start, -22, -12, 62, -20, -12, 72, Blocks.SAND.getDefaultState());
        structure.fillWithBlocks(world, start, -22, -11, -65, 3, -9, -65, Blocks.SAND.getDefaultState());
        structure.fillWithBlocks(world, start, -22, -11, -64, -21, -11, -55, Blocks.STONE.getDefaultState());
        structure.fillWithBlocks(world, start, -22, -11, -54, -22, -11, -16, Blocks.SAND.getDefaultState());
        structure.fillWithBlocks(world, start, -22, -11, 38, -11, -11, 49, Blocks.SAND.getDefaultState());
        structure.fillWithBlocks(world, start, -22, -11, 70, -22, -11, 70, Blocks.SAND.getDefaultState());
        structure.fillWithBlocks(world, start, -22, -10, 69, 96, -10, 69, Blocks.SAND.getDefaultState());
        structure.fillWithBlocks(world, start, -22, -8, -45, -22, -8, -40, Blocks.SAND.getDefaultState());
        structure.fillWithBlocks(world, start, -22, -8, -39, -21, -8, -38, Blocks.SANDSTONE.getDefaultState());
        structure.fillWithBlocks(world, start, -22, -8, -11, -21, -8, 55, Blocks.SANDSTONE.getDefaultState());
        structure.fillWithBlocks(world, start, -22, -7, -46, -22, -7, -46, Blocks.SANDSTONE.getDefaultState());
        structure.fillWithBlocks(world, start, -22, -7, -44, -22, -6, -43, Blocks.SANDSTONE.getDefaultState());
        structure.fillWithBlocks(world, start, -22, -7, -42, -22, -7, -42, Blocks.SAND.getDefaultState());
        structure.fillWithBlocks(world, start, -22, -7, -41, -22, -7, -37, Blocks.SANDSTONE.getDefaultState());
        structure.fillWithBlocks(world, start, -22, -7, -31, -18, -7, -21, Blocks.SANDSTONE.getDefaultState());
        structure.fillWithBlocks(world, start, -22, -7, -11, -21, -7, 55, Blocks.SANDSTONE.getDefaultState());
        structure.fillWithBlocks(world, start, -22, -7, 61, 100, -7, 61, Blocks.SAND.getDefaultState());
        structure.fillWithBlocks(world, start, -22, -6, -70, -21, -6, -69, Blocks.SAND.getDefaultState());
        structure.fillWithBlocks(world, start, -22, -6, -46, -22, -6, -46, Blocks.SANDSTONE.getDefaultState());
        structure.fillWithBlocks(world, start, -22, -6, -42, -22, -6, -42, Blocks.SPRUCE_PLANKS.getDefaultState());
        structure.fillWithBlocks(world, start, -22, -6, -41, -22, -6, -37, Blocks.SANDSTONE.getDefaultState());
        structure.fillWithBlocks(world, start, -22, -6, -31, -18, -6, -21, Blocks.SANDSTONE.getDefaultState());
        structure.fillWithBlocks(world, start, -22, -6, -11, -21, -6, 55, Blocks.SANDSTONE.getDefaultState());
        structure.fillWithBlocks(world, start, -22, -5, -44, -22, -5, -43, Blocks.SANDSTONE.getDefaultState());
        structure.fillWithBlocks(world, start, -22, -5, -41, -22, -5, -40, Blocks.SANDSTONE.getDefaultState());
        structure.fillWithBlocks(world, start, -22, -5, -31, -19, -5, -31, Blocks.SANDSTONE.getDefaultState());
        structure.fillWithBlocks(world, start, -22, -4, -44, -22, -1, -44, Blocks.CUT_SANDSTONE.getDefaultState());
        structure.fillWithBlocks(world, start, -22, -4, -43, -22, -1, -43, Blocks.SMOOTH_SANDSTONE.getDefaultState());
        structure.fillWithBlocks(world, start, -22, -4, -41, -22, -1, -41, Blocks.SMOOTH_SANDSTONE.getDefaultState());
        structure.fillWithBlocks(world, start, -22, -4, -40, -22, -1, -40, Blocks.CUT_SANDSTONE.getDefaultState());
        structure.fillWithBlocks(world, start, -22, -4, -37, -21, -3, -37, Blocks.SPRUCE_FENCE.getDefaultState().with(FourWayBlock.WATERLOGGED, false).with(FourWayBlock.NORTH, false).with(FourWayBlock.SOUTH, false).with(FourWayBlock.EAST, true).with(FourWayBlock.WEST, true));
        structure.fillWithBlocks(world, start, -22, -4, -31, -22, -1, -31, Blocks.SMOOTH_SANDSTONE.getDefaultState());
        structure.fillWithBlocks(world, start, -22, -3, -42, -22, -2, -41, Blocks.SMOOTH_SANDSTONE.getDefaultState());
        structure.fillWithBlocks(world, start, -22, -2, -30, -21, -2, -29, Blocks.WHITE_WOOL.getDefaultState());
        structure.fillWithBlocks(world, start, -22, -2, 41, -21, -2, 41, Blocks.BIRCH_LEAVES.getDefaultState().with(LeavesBlock.PERSISTENT, true).with(LeavesBlock.DISTANCE, 2));
        structure.fillWithBlocks(world, start, -22, -2, 42, -21, -2, 42, Blocks.BIRCH_LEAVES.getDefaultState().with(LeavesBlock.PERSISTENT, true).with(LeavesBlock.DISTANCE, 1));
        structure.fillWithBlocks(world, start, -22, -2, 44, -22, -1, 44, Blocks.BIRCH_LEAVES.getDefaultState().with(LeavesBlock.PERSISTENT, true).with(LeavesBlock.DISTANCE, 1));
        structure.fillWithBlocks(world, start, -22, -1, -42, -22, -1, -41, Blocks.SMOOTH_SANDSTONE.getDefaultState());
        structure.fillWithBlocks(world, start, -22, -1, -36, -22, -1, -34, Blocks.OAK_TRAPDOOR.getDefaultState().with(HorizontalBlock.HORIZONTAL_FACING, Direction.WEST).with(TrapDoorBlock.HALF, Half.BOTTOM).with(TrapDoorBlock.WATERLOGGED, false).with(TrapDoorBlock.POWERED, false).with(TrapDoorBlock.OPEN, false));
        structure.fillWithBlocks(world, start, -22, -1, -33, -20, -1, -33, Blocks.SPRUCE_SLAB.getDefaultState().with(SlabBlock.TYPE, SlabType.DOUBLE).with(SlabBlock.WATERLOGGED, false));
        structure.fillWithBlocks(world, start, -22, -1, -22, -21, -1, -21, Blocks.OAK_TRAPDOOR.getDefaultState().with(HorizontalBlock.HORIZONTAL_FACING, Direction.WEST).with(TrapDoorBlock.HALF, Half.BOTTOM).with(TrapDoorBlock.WATERLOGGED, false).with(TrapDoorBlock.POWERED, false).with(TrapDoorBlock.OPEN, false));
        structure.fillWithBlocks(world, start, -22, -1, -19, -21, -1, -12, Blocks.BROWN_WOOL.getDefaultState());
        structure.fillWithBlocks(world, start, -22, -1, 42, -21, -1, 42, Blocks.BIRCH_LEAVES.getDefaultState().with(LeavesBlock.PERSISTENT, true).with(LeavesBlock.DISTANCE, 2));
        structure.fillWithBlocks(world, start, -22, -1, 43, -22, -1, 45, Blocks.BIRCH_LEAVES.getDefaultState().with(LeavesBlock.PERSISTENT, true).with(LeavesBlock.DISTANCE, 1));
        structure.fillWithBlocks(world, start, -22, -1, 46, -22, 0, 46, Blocks.BIRCH_LEAVES.getDefaultState().with(LeavesBlock.PERSISTENT, true).with(LeavesBlock.DISTANCE, 2));
        structure.fillWithBlocks(world, start, -22, -1, 47, -22, 0, 47, Blocks.BIRCH_LEAVES.getDefaultState().with(LeavesBlock.PERSISTENT, true).with(LeavesBlock.DISTANCE, 3));
        structure.fillWithBlocks(world, start, -22, 0, -37, -21, 0, -37, Blocks.SPRUCE_FENCE.getDefaultState().with(FourWayBlock.WATERLOGGED, false).with(FourWayBlock.NORTH, false).with(FourWayBlock.SOUTH, false).with(FourWayBlock.EAST, true).with(FourWayBlock.WEST, true));
        structure.fillWithBlocks(world, start, -22, 0, -33, -20, 0, -33, Blocks.SPRUCE_FENCE.getDefaultState().with(FourWayBlock.WATERLOGGED, false).with(FourWayBlock.NORTH, false).with(FourWayBlock.SOUTH, false).with(FourWayBlock.EAST, true).with(FourWayBlock.WEST, true));
        structure.fillWithBlocks(world, start, -22, 0, 45, -22, 0, 45, Blocks.BIRCH_LEAVES.getDefaultState().with(LeavesBlock.PERSISTENT, true).with(LeavesBlock.DISTANCE, 1));
        structure.fillWithBlocks(world, start, -22, 1, 45, -22, 1, 45, Blocks.BIRCH_LEAVES.getDefaultState().with(LeavesBlock.PERSISTENT, true).with(LeavesBlock.DISTANCE, 2));
        structure.fillWithBlocks(world, start, -21, -13, -83, -14, -13, -76, Blocks.SAND.getDefaultState());
        structure.fillWithBlocks(world, start, -21, -13, 74, 89, -13, 74, Blocks.SAND.getDefaultState());
        structure.fillWithBlocks(world, start, -21, -12, -71, -20, -12, -70, Blocks.SAND.getDefaultState());
        structure.fillWithBlocks(world, start, -21, -12, -69, -21, -12, -49, Blocks.STONE.getDefaultState());
        structure.fillWithBlocks(world, start, -21, -12, 9, -20, -12, 10, Blocks.STONE.getDefaultState());
        structure.fillWithBlocks(world, start, -21, -12, 11, -21, -9, 21, Blocks.SAND.getDefaultState());
        structure.fillWithBlocks(world, start, -21, -11, -54, -20, -11, -54, Blocks.STONE.getDefaultState());
        structure.fillWithBlocks(world, start, -21, -11, -53, -12, -11, -43, Blocks.SAND.getDefaultState());
        structure.fillWithBlocks(world, start, -21, -11, -42, -14, -11, -18, Blocks.SAND.getDefaultState());
        structure.fillWithBlocks(world, start, -21, -11, -17, -20, -11, -16, Blocks.SAND.getDefaultState());
        structure.fillWithBlocks(world, start, -21, -11, -6, -21, -11, -6, Blocks.STONE.getDefaultState());
        structure.fillWithBlocks(world, start, -21, -11, 53, -16, -11, 59, Blocks.STONE.getDefaultState());
        structure.fillWithBlocks(world, start, -21, -11, 70, -20, -11, 71, Blocks.SAND.getDefaultState());
        structure.fillWithBlocks(world, start, -21, -8, -45, -18, -6, -45, Blocks.SANDSTONE.getDefaultState());
        structure.fillWithBlocks(world, start, -21, -8, -44, -18, -8, -41, Blocks.SAND.getDefaultState());
        structure.fillWithBlocks(world, start, -21, -8, -40, -19, -8, -40, Blocks.SAND.getDefaultState());
        structure.fillWithBlocks(world, start, -21, -8, -30, -19, -8, -22, Blocks.SANDSTONE.getDefaultState());
        structure.fillWithBlocks(world, start, -21, -7, -46, -19, -7, -44, Blocks.SANDSTONE.getDefaultState());
        structure.fillWithBlocks(world, start, -21, -7, -43, -19, -7, -41, Blocks.SAND.getDefaultState());
        structure.fillWithBlocks(world, start, -21, -7, -40, -19, -7, -37, Blocks.SANDSTONE.getDefaultState());
        structure.fillWithBlocks(world, start, -21, -6, -71, -19, -6, -69, Blocks.SAND.getDefaultState());
        structure.fillWithBlocks(world, start, -21, -6, -46, -19, -6, -44, Blocks.SANDSTONE.getDefaultState());
        structure.fillWithBlocks(world, start, -21, -6, -43, -19, -6, -41, Blocks.SPRUCE_PLANKS.getDefaultState());
        structure.fillWithBlocks(world, start, -21, -6, -40, -18, -6, -37, Blocks.SANDSTONE.getDefaultState());
        structure.fillWithBlocks(world, start, -21, -6, 58, 106, -6, 58, Blocks.SAND.getDefaultState());
        structure.fillWithBlocks(world, start, -21, -5, -44, -18, -5, -44, Blocks.SANDSTONE.getDefaultState());
        structure.fillWithBlocks(world, start, -21, -5, -40, -19, -5, -40, Blocks.SANDSTONE.getDefaultState());
        structure.fillWithBlocks(world, start, -21, -5, -29, -21, -3, -29, Blocks.SPRUCE_FENCE.getDefaultState().with(FourWayBlock.WATERLOGGED, false).with(FourWayBlock.NORTH, false).with(FourWayBlock.SOUTH, false).with(FourWayBlock.EAST, false).with(FourWayBlock.WEST, false));
        structure.fillWithBlocks(world, start, -21, -5, -14, -21, -5, -12, Blocks.BIRCH_LEAVES.getDefaultState().with(LeavesBlock.PERSISTENT, true).with(LeavesBlock.DISTANCE, 7));
        structure.fillWithBlocks(world, start, -21, -5, 44, -21, -1, 44, Blocks.STRIPPED_SPRUCE_LOG.getDefaultState());
        structure.fillWithBlocks(world, start, -21, -4, -44, -21, -1, -44, Blocks.SMOOTH_SANDSTONE.getDefaultState());
        structure.fillWithBlocks(world, start, -21, -4, -40, -21, -1, -40, Blocks.SMOOTH_SANDSTONE.getDefaultState());
        structure.fillWithBlocks(world, start, -21, -4, -31, -21, -3, -31, Blocks.SPRUCE_FENCE.getDefaultState().with(FourWayBlock.WATERLOGGED, false).with(FourWayBlock.NORTH, false).with(FourWayBlock.SOUTH, false).with(FourWayBlock.EAST, true).with(FourWayBlock.WEST, true));
        structure.fillWithBlocks(world, start, -21, -4, -13, -21, -4, -12, Blocks.BIRCH_LEAVES.getDefaultState().with(LeavesBlock.PERSISTENT, true).with(LeavesBlock.DISTANCE, 7));
        structure.fillWithBlocks(world, start, -21, -4, 8, -21, -4, 8, Blocks.BIRCH_LEAVES.getDefaultState().with(LeavesBlock.PERSISTENT, true).with(LeavesBlock.DISTANCE, 2));
        structure.fillWithBlocks(world, start, -21, -4, 9, -21, -4, 9, Blocks.BIRCH_LEAVES.getDefaultState().with(LeavesBlock.PERSISTENT, true).with(LeavesBlock.DISTANCE, 3));
        structure.fillWithBlocks(world, start, -21, -2, -31, -20, -1, -31, Blocks.SMOOTH_SANDSTONE.getDefaultState());
        structure.fillWithBlocks(world, start, -21, -1, -43, -19, -1, -41, Blocks.SPRUCE_SLAB.getDefaultState().with(SlabBlock.TYPE, SlabType.BOTTOM).with(SlabBlock.WATERLOGGED, false));
        structure.fillWithBlocks(world, start, -21, -1, -36, -21, -1, -36, Blocks.OAK_TRAPDOOR.getDefaultState().with(HorizontalBlock.HORIZONTAL_FACING, Direction.WEST).with(TrapDoorBlock.HALF, Half.BOTTOM).with(TrapDoorBlock.WATERLOGGED, false).with(TrapDoorBlock.POWERED, false).with(TrapDoorBlock.OPEN, false));
        structure.fillWithBlocks(world, start, -21, -1, -34, -20, -1, -34, Blocks.OAK_TRAPDOOR.getDefaultState().with(HorizontalBlock.HORIZONTAL_FACING, Direction.WEST).with(TrapDoorBlock.HALF, Half.BOTTOM).with(TrapDoorBlock.WATERLOGGED, false).with(TrapDoorBlock.POWERED, false).with(TrapDoorBlock.OPEN, false));
        structure.fillWithBlocks(world, start, -21, -1, -23, -19, -1, -21, Blocks.OAK_TRAPDOOR.getDefaultState().with(HorizontalBlock.HORIZONTAL_FACING, Direction.WEST).with(TrapDoorBlock.HALF, Half.BOTTOM).with(TrapDoorBlock.WATERLOGGED, false).with(TrapDoorBlock.POWERED, false).with(TrapDoorBlock.OPEN, false));
        structure.fillWithBlocks(world, start, -21, -1, 43, -21, -1, 43, Blocks.BIRCH_LEAVES.getDefaultState().with(LeavesBlock.PERSISTENT, true).with(LeavesBlock.DISTANCE, 1));
        structure.fillWithBlocks(world, start, -21, -1, 46, -21, 0, 46, Blocks.BIRCH_LEAVES.getDefaultState().with(LeavesBlock.PERSISTENT, true).with(LeavesBlock.DISTANCE, 1));
        structure.fillWithBlocks(world, start, -21, -1, 47, -21, 0, 47, Blocks.BIRCH_LEAVES.getDefaultState().with(LeavesBlock.PERSISTENT, true).with(LeavesBlock.DISTANCE, 2));
        structure.fillWithBlocks(world, start, -21, 0, 43, -21, 0, 43, Blocks.BIRCH_LEAVES.getDefaultState().with(LeavesBlock.PERSISTENT, true).with(LeavesBlock.DISTANCE, 2));
        structure.fillWithBlocks(world, start, -21, 0, 44, -21, 0, 44, Blocks.BIRCH_LEAVES.getDefaultState().with(LeavesBlock.PERSISTENT, true).with(LeavesBlock.DISTANCE, 1));
        structure.fillWithBlocks(world, start, -21, 1, 44, -21, 1, 44, Blocks.BIRCH_LEAVES.getDefaultState().with(LeavesBlock.PERSISTENT, true).with(LeavesBlock.DISTANCE, 2));
        structure.fillWithBlocks(world, start, -20, -14, -79, -19, -14, -78, Blocks.SAND.getDefaultState());
        structure.fillWithBlocks(world, start, -20, -14, 68, -18, -14, 68, Blocks.STONE.getDefaultState());
        structure.fillWithBlocks(world, start, -20, -14, 69, -14, -14, 75, Blocks.SAND.getDefaultState());
        structure.fillWithBlocks(world, start, -20, -13, -75, -19, -12, -75, Blocks.SAND.getDefaultState());
        structure.fillWithBlocks(world, start, -20, -12, -83, -18, -12, -69, Blocks.SAND.getDefaultState());
        structure.fillWithBlocks(world, start, -20, -12, -68, -20, -12, -48, Blocks.STONE.getDefaultState());
        structure.fillWithBlocks(world, start, -20, -12, -47, -19, -12, -40, Blocks.SAND.getDefaultState());
        structure.fillWithBlocks(world, start, -20, -12, -32, -20, -12, -32, Blocks.STONE.getDefaultState());
        structure.fillWithBlocks(world, start, -20, -12, -21, -3, -12, 12, Blocks.STONE.getDefaultState());
        structure.fillWithBlocks(world, start, -20, -12, 13, -20, -9, 20, Blocks.SAND.getDefaultState());
        structure.fillWithBlocks(world, start, -20, -12, 21, -9, -12, 32, Blocks.STONE.getDefaultState());
        structure.fillWithBlocks(world, start, -20, -12, 58, -17, -12, 61, Blocks.STONE.getDefaultState());
        structure.fillWithBlocks(world, start, -20, -11, -64, -20, -11, -64, Blocks.SAND.getDefaultState());
        structure.fillWithBlocks(world, start, -20, -11, -63, -20, -11, -54, Blocks.STONE.getDefaultState());
        structure.fillWithBlocks(world, start, -20, -11, -6, -19, -11, -5, Blocks.STONE.getDefaultState());
        structure.fillWithBlocks(world, start, -20, -11, -4, -19, -11, 26, Blocks.SAND.getDefaultState());
        structure.fillWithBlocks(world, start, -20, -9, 68, 95, -9, 68, Blocks.SAND.getDefaultState());
        structure.fillWithBlocks(world, start, -20, -8, -39, -19, -8, -38, Blocks.SANDSTONE.getDefaultState());
        structure.fillWithBlocks(world, start, -20, -8, -21, -20, -8, -18, Blocks.SAND.getDefaultState());
        structure.fillWithBlocks(world, start, -20, -8, -17, -18, -8, -15, Blocks.COARSE_DIRT.getDefaultState());
        structure.fillWithBlocks(world, start, -20, -8, -14, -20, -8, -10, Blocks.SAND.getDefaultState());
        structure.fillWithBlocks(world, start, -20, -8, -9, -18, -8, -7, Blocks.COARSE_DIRT.getDefaultState());
        structure.fillWithBlocks(world, start, -20, -8, -6, -20, -8, -5, Blocks.SAND.getDefaultState());
        structure.fillWithBlocks(world, start, -20, -8, -4, -18, -8, 17, Blocks.SANDSTONE.getDefaultState());
        structure.fillWithBlocks(world, start, -20, -8, 18, -20, -6, 55, Blocks.SANDSTONE.getDefaultState());
        structure.fillWithBlocks(world, start, -20, -7, -17, -18, -7, -15, Blocks.COARSE_DIRT.getDefaultState());
        structure.fillWithBlocks(world, start, -20, -7, -14, -20, -5, -10, Blocks.SANDSTONE.getDefaultState());
        structure.fillWithBlocks(world, start, -20, -7, -9, -18, -7, -7, Blocks.COARSE_DIRT.getDefaultState());
        structure.fillWithBlocks(world, start, -20, -7, -6, -20, -7, 55, Blocks.SANDSTONE.getDefaultState());
        structure.fillWithBlocks(world, start, -20, -6, -17, -18, -6, -15, Blocks.COARSE_DIRT.getDefaultState());
        structure.fillWithBlocks(world, start, -20, -6, -9, -18, -6, -7, Blocks.COARSE_DIRT.getDefaultState());
        structure.fillWithBlocks(world, start, -20, -6, -6, -20, -6, 55, Blocks.SANDSTONE.getDefaultState());
        structure.fillWithBlocks(world, start, -20, -5, -36, -20, -5, -35, Index.COUNTER_OAK_ANDESITE.getDefaultState().with(Counter.FACING, Direction.WEST).with(Counter.WATERLOGGED, false));
        structure.fillWithBlocks(world, start, -20, -5, -21, -20, -5, -18, Blocks.SANDSTONE.getDefaultState());
        structure.fillWithBlocks(world, start, -20, -5, -6, -20, -5, -5, Blocks.SANDSTONE.getDefaultState());
        structure.fillWithBlocks(world, start, -20, -5, -4, -19, -5, -4, Blocks.BARREL.getDefaultState().with(BarrelBlock.PROPERTY_FACING, Direction.SOUTH).with(BarrelBlock.PROPERTY_OPEN, false));
        structure.fillWithBlocks(world, start, -20, -5, -2, -20, -3, -2, Blocks.SPRUCE_FENCE.getDefaultState().with(FourWayBlock.WATERLOGGED, false).with(FourWayBlock.NORTH, false).with(FourWayBlock.SOUTH, false).with(FourWayBlock.EAST, false).with(FourWayBlock.WEST, false));
        structure.fillWithBlocks(world, start, -20, -5, 20, -20, -5, 22, Blocks.BARREL.getDefaultState().with(BarrelBlock.PROPERTY_FACING, Direction.WEST).with(BarrelBlock.PROPERTY_OPEN, false));
        structure.fillWithBlocks(world, start, -20, -4, -44, -20, -3, -44, Blocks.SPRUCE_FENCE.getDefaultState().with(FourWayBlock.WATERLOGGED, false).with(FourWayBlock.NORTH, false).with(FourWayBlock.SOUTH, false).with(FourWayBlock.EAST, true).with(FourWayBlock.WEST, true));
        structure.fillWithBlocks(world, start, -20, -4, -40, -20, -3, -40, Blocks.SPRUCE_FENCE.getDefaultState().with(FourWayBlock.WATERLOGGED, false).with(FourWayBlock.NORTH, false).with(FourWayBlock.SOUTH, false).with(FourWayBlock.EAST, true).with(FourWayBlock.WEST, true));
        structure.fillWithBlocks(world, start, -20, -4, -37, -20, -4, -37, Blocks.SMOOTH_SANDSTONE.getDefaultState());
        structure.fillWithBlocks(world, start, -20, -4, -34, -20, -3, -34, Index.IRON_FENCE_ROUGH.getDefaultState().with(IronFence.NORTH, false).with(IronFence.SOUTH, false).with(IronFence.EAST, true).with(IronFence.WEST, false).with(IronFence.WATERLOGGED, false));
        structure.fillWithBlocks(world, start, -20, -4, -31, -20, -1, -31, Blocks.SMOOTH_SANDSTONE.getDefaultState());
        structure.fillWithBlocks(world, start, -20, -4, -21, -20, -2, -18, Blocks.SMOOTH_SANDSTONE.getDefaultState());
        structure.fillWithBlocks(world, start, -20, -4, -14, -20, -2, -10, Blocks.SMOOTH_SANDSTONE.getDefaultState());
        structure.fillWithBlocks(world, start, -20, -4, -6, -20, -1, -6, Blocks.SMOOTH_SANDSTONE.getDefaultState());
        structure.fillWithBlocks(world, start, -20, -4, -5, -20, -1, -5, Blocks.CUT_SANDSTONE.getDefaultState());
        structure.fillWithBlocks(world, start, -20, -4, 7, -20, -3, 7, Blocks.BIRCH_LEAVES.getDefaultState().with(LeavesBlock.PERSISTENT, true).with(LeavesBlock.DISTANCE, 2));
        structure.fillWithBlocks(world, start, -20, -4, 8, -20, -2, 8, Blocks.BIRCH_LEAVES.getDefaultState().with(LeavesBlock.PERSISTENT, true).with(LeavesBlock.DISTANCE, 1));
        structure.fillWithBlocks(world, start, -20, -4, 9, -20, -3, 9, Blocks.BIRCH_LEAVES.getDefaultState().with(LeavesBlock.PERSISTENT, true).with(LeavesBlock.DISTANCE, 2));
        structure.fillWithBlocks(world, start, -20, -3, -37, -20, -3, -37, Blocks.SMOOTH_SANDSTONE.getDefaultState());
        structure.fillWithBlocks(world, start, -20, -3, -36, -20, -3, -35, Index.CABINET_OAK.getDefaultState().with(Cabinet.FACING, Direction.WEST).with(Cabinet.WATERLOGGED, false));
        structure.fillWithBlocks(world, start, -20, -3, -33, -20, -3, -32, Index.CABINET_OAK.getDefaultState().with(Cabinet.FACING, Direction.WEST).with(Cabinet.WATERLOGGED, false));
        structure.fillWithBlocks(world, start, -20, -2, -44, -19, -1, -44, Blocks.SMOOTH_SANDSTONE.getDefaultState());
        structure.fillWithBlocks(world, start, -20, -2, -40, -19, -1, -40, Blocks.SMOOTH_SANDSTONE.getDefaultState());
        structure.fillWithBlocks(world, start, -20, -2, -36, -19, -2, -32, Blocks.SMOOTH_SANDSTONE.getDefaultState());
        structure.fillWithBlocks(world, start, -20, -2, -4, -18, -2, -2, Blocks.BROWN_WOOL.getDefaultState());
        structure.fillWithBlocks(world, start, -20, -2, 43, -20, -2, 44, Blocks.BIRCH_LEAVES.getDefaultState().with(LeavesBlock.PERSISTENT, true).with(LeavesBlock.DISTANCE, 1));
        structure.fillWithBlocks(world, start, -20, -1, -45, -20, 0, -45, Blocks.SPRUCE_FENCE.getDefaultState().with(FourWayBlock.WATERLOGGED, false).with(FourWayBlock.NORTH, false).with(FourWayBlock.SOUTH, true).with(FourWayBlock.EAST, true).with(FourWayBlock.WEST, false));
        structure.fillWithBlocks(world, start, -20, -1, -36, -20, -1, -34, Blocks.OAK_TRAPDOOR.getDefaultState().with(HorizontalBlock.HORIZONTAL_FACING, Direction.WEST).with(TrapDoorBlock.HALF, Half.BOTTOM).with(TrapDoorBlock.WATERLOGGED, false).with(TrapDoorBlock.POWERED, false).with(TrapDoorBlock.OPEN, false));
        structure.fillWithBlocks(world, start, -20, -1, -19, -20, -1, -13, Blocks.SMOOTH_SANDSTONE.getDefaultState());
        structure.fillWithBlocks(world, start, -20, -1, -12, -20, -1, -11, Blocks.CUT_SANDSTONE.getDefaultState());
        structure.fillWithBlocks(world, start, -20, -1, -10, -20, -1, -6, Blocks.SMOOTH_SANDSTONE.getDefaultState());
        structure.fillWithBlocks(world, start, -20, -1, 43, -20, -1, 43, Blocks.BIRCH_LEAVES.getDefaultState().with(LeavesBlock.PERSISTENT, true).with(LeavesBlock.DISTANCE, 2));
        structure.fillWithBlocks(world, start, -20, -1, 44, -20, -1, 45, Blocks.BIRCH_LEAVES.getDefaultState().with(LeavesBlock.PERSISTENT, true).with(LeavesBlock.DISTANCE, 1));
        structure.fillWithBlocks(world, start, -20, -1, 46, -20, 0, 46, Blocks.BIRCH_LEAVES.getDefaultState().with(LeavesBlock.PERSISTENT, true).with(LeavesBlock.DISTANCE, 2));
        structure.fillWithBlocks(world, start, -20, 0, -7, -20, 2, -7, Blocks.SPRUCE_FENCE.getDefaultState().with(FourWayBlock.WATERLOGGED, false).with(FourWayBlock.NORTH, false).with(FourWayBlock.SOUTH, true).with(FourWayBlock.EAST, false).with(FourWayBlock.WEST, false));
        structure.fillWithBlocks(world, start, -20, 0, -6, -20, 2, -6, Blocks.SPRUCE_FENCE.getDefaultState().with(FourWayBlock.WATERLOGGED, false).with(FourWayBlock.NORTH, true).with(FourWayBlock.SOUTH, false).with(FourWayBlock.EAST, false).with(FourWayBlock.WEST, false));
        structure.fillWithBlocks(world, start, -20, 0, 8, -20, 0, 8, Blocks.BIRCH_LEAVES.getDefaultState().with(LeavesBlock.PERSISTENT, true).with(LeavesBlock.DISTANCE, 1));
        structure.fillWithBlocks(world, start, -20, 3, -7, -20, 3, -5, Blocks.OAK_TRAPDOOR.getDefaultState().with(HorizontalBlock.HORIZONTAL_FACING, Direction.WEST).with(TrapDoorBlock.HALF, Half.BOTTOM).with(TrapDoorBlock.WATERLOGGED, false).with(TrapDoorBlock.POWERED, false).with(TrapDoorBlock.OPEN, false));
        structure.fillWithBlocks(world, start, -19, -14, 76, 86, -14, 76, Blocks.SAND.getDefaultState());
        structure.fillWithBlocks(world, start, -19, -13, 66, -13, -13, 66, Blocks.STONE.getDefaultState());
        structure.fillWithBlocks(world, start, -19, -13, 67, -12, -13, 74, Blocks.SAND.getDefaultState());
        structure.fillWithBlocks(world, start, -19, -12, -68, -19, -12, -68, Blocks.SAND.getDefaultState());
        structure.fillWithBlocks(world, start, -19, -12, -67, -19, -12, -48, Blocks.STONE.getDefaultState());
        structure.fillWithBlocks(world, start, -19, -12, -39, -11, -12, -31, Blocks.STONE.getDefaultState());
        structure.fillWithBlocks(world, start, -19, -12, -30, -19, -9, -24, Blocks.SAND.getDefaultState());
        structure.fillWithBlocks(world, start, -19, -12, -23, -3, -12, 15, Blocks.STONE.getDefaultState());
        structure.fillWithBlocks(world, start, -19, -12, 16, -19, -11, 17, Blocks.SAND.getDefaultState());
        structure.fillWithBlocks(world, start, -19, -12, 18, -6, -12, 31, Blocks.STONE.getDefaultState());
        structure.fillWithBlocks(world, start, -19, -12, 62, -8, -12, 62, Blocks.STONE.getDefaultState());
        structure.fillWithBlocks(world, start, -19, -12, 63, -16, -12, 73, Blocks.SAND.getDefaultState());
        structure.fillWithBlocks(world, start, -19, -11, -64, -18, -11, -63, Blocks.SAND.getDefaultState());
        structure.fillWithBlocks(world, start, -19, -11, -62, -18, -11, -55, Blocks.STONE.getDefaultState());
        structure.fillWithBlocks(world, start, -19, -11, -54, -9, -11, -44, Blocks.SAND.getDefaultState());
        structure.fillWithBlocks(world, start, -19, -11, -17, -17, -9, -17, Blocks.SAND.getDefaultState());
        structure.fillWithBlocks(world, start, -19, -11, -16, -11, -11, -5, Blocks.STONE.getDefaultState());
        structure.fillWithBlocks(world, start, -19, -11, 27, -16, -11, 31, Blocks.STONE.getDefaultState());
        structure.fillWithBlocks(world, start, -19, -11, 37, -7, -11, 49, Blocks.SAND.getDefaultState());
        structure.fillWithBlocks(world, start, -19, -11, 70, -18, -11, 71, Blocks.SAND.getDefaultState());
        structure.fillWithBlocks(world, start, -19, -10, 70, 93, -10, 70, Blocks.SAND.getDefaultState());
        structure.fillWithBlocks(world, start, -19, -9, 55, -6, -9, 68, Blocks.SAND.getDefaultState());
        structure.fillWithBlocks(world, start, -19, -8, -21, -18, -8, -21, Blocks.SAND.getDefaultState());
        structure.fillWithBlocks(world, start, -19, -8, -20, -13, -8, -13, Blocks.COARSE_DIRT.getDefaultState());
        structure.fillWithBlocks(world, start, -19, -8, -12, -14, -8, -6, Blocks.COARSE_DIRT.getDefaultState());
        structure.fillWithBlocks(world, start, -19, -8, -5, -17, -8, -5, Blocks.SAND.getDefaultState());
        structure.fillWithBlocks(world, start, -19, -8, 18, -13, -8, 24, Blocks.SAND.getDefaultState());
        structure.fillWithBlocks(world, start, -19, -8, 25, -14, -8, 30, Blocks.SANDSTONE.getDefaultState());
        structure.fillWithBlocks(world, start, -19, -8, 31, -18, -8, 55, Blocks.SANDSTONE.getDefaultState());
        structure.fillWithBlocks(world, start, -19, -8, 56, -9, -8, 66, Blocks.SAND.getDefaultState());
        structure.fillWithBlocks(world, start, -19, -7, -74, -14, -7, -69, Blocks.SAND.getDefaultState());
        structure.fillWithBlocks(world, start, -19, -7, -36, -19, -5, -31, Blocks.SANDSTONE.getDefaultState());
        structure.fillWithBlocks(world, start, -19, -7, -20, -13, -7, -13, Blocks.COARSE_DIRT.getDefaultState());
        structure.fillWithBlocks(world, start, -19, -7, -12, -14, -7, -6, Blocks.COARSE_DIRT.getDefaultState());
        structure.fillWithBlocks(world, start, -19, -7, -5, -17, -7, -3, Blocks.SANDSTONE.getDefaultState());
        structure.fillWithBlocks(world, start, -19, -7, -2, -18, -7, 18, Blocks.SANDSTONE.getDefaultState());
        structure.fillWithBlocks(world, start, -19, -7, 19, -19, -5, 24, Blocks.SANDSTONE.getDefaultState());
        structure.fillWithBlocks(world, start, -19, -7, 25, -14, -7, 30, Blocks.SANDSTONE.getDefaultState());
        structure.fillWithBlocks(world, start, -19, -7, 31, -17, -7, 55, Blocks.SANDSTONE.getDefaultState());
        structure.fillWithBlocks(world, start, -19, -7, 56, -13, -7, 62, Blocks.SAND.getDefaultState());
        structure.fillWithBlocks(world, start, -19, -6, -20, -13, -6, -6, Blocks.COARSE_DIRT.getDefaultState());
        structure.fillWithBlocks(world, start, -19, -6, -5, -17, -6, -3, Blocks.SANDSTONE.getDefaultState());
        structure.fillWithBlocks(world, start, -19, -6, -2, -18, -6, 18, Blocks.SANDSTONE.getDefaultState());
        structure.fillWithBlocks(world, start, -19, -6, 25, -14, -6, 30, Blocks.SANDSTONE.getDefaultState());
        structure.fillWithBlocks(world, start, -19, -6, 31, -17, -6, 55, Blocks.SANDSTONE.getDefaultState());
        structure.fillWithBlocks(world, start, -19, -6, 59, 99, -6, 59, Blocks.SAND.getDefaultState());
        structure.fillWithBlocks(world, start, -19, -5, -39, -19, -5, -38, Blocks.BARREL.getDefaultState().with(BarrelBlock.PROPERTY_FACING, Direction.WEST).with(BarrelBlock.PROPERTY_OPEN, false));
        structure.fillWithBlocks(world, start, -19, -5, -21, -18, -5, -21, Blocks.SANDSTONE.getDefaultState());
        structure.fillWithBlocks(world, start, -19, -5, -13, -18, -5, -12, Blocks.BARREL.getDefaultState().with(BarrelBlock.PROPERTY_FACING, Direction.UP).with(BarrelBlock.PROPERTY_OPEN, false));
        structure.fillWithBlocks(world, start, -19, -5, -5, -17, -5, -5, Blocks.SANDSTONE.getDefaultState());
        structure.fillWithBlocks(world, start, -19, -5, 8, -19, 0, 8, Blocks.STRIPPED_SPRUCE_LOG.getDefaultState());
        structure.fillWithBlocks(world, start, -19, -5, 16, -19, -5, 16, Blocks.BIRCH_LEAVES.getDefaultState().with(LeavesBlock.PERSISTENT, true).with(LeavesBlock.DISTANCE, 3));
        structure.fillWithBlocks(world, start, -19, -5, 18, -19, -5, 24, Blocks.SANDSTONE.getDefaultState());
        structure.fillWithBlocks(world, start, -19, -4, -44, -18, -3, -44, Blocks.SMOOTH_SANDSTONE.getDefaultState());
        structure.fillWithBlocks(world, start, -19, -4, -40, -19, -1, -40, Blocks.SMOOTH_SANDSTONE.getDefaultState());
        structure.fillWithBlocks(world, start, -19, -4, -37, -19, -1, -32, Blocks.SMOOTH_SANDSTONE.getDefaultState());
        structure.fillWithBlocks(world, start, -19, -4, -31, -19, -1, -31, Blocks.CUT_SANDSTONE.getDefaultState());
        structure.fillWithBlocks(world, start, -19, -4, -21, -18, -3, -21, Blocks.SMOOTH_SANDSTONE.getDefaultState());
        structure.fillWithBlocks(world, start, -19, -4, -5, -17, -2, -5, Blocks.SMOOTH_SANDSTONE.getDefaultState());
        structure.fillWithBlocks(world, start, -19, -4, 6, -19, -4, 6, Blocks.BIRCH_LEAVES.getDefaultState().with(LeavesBlock.PERSISTENT, true).with(LeavesBlock.DISTANCE, 2));
        structure.fillWithBlocks(world, start, -19, -4, 7, -19, -2, 7, Blocks.BIRCH_LEAVES.getDefaultState().with(LeavesBlock.PERSISTENT, true).with(LeavesBlock.DISTANCE, 1));
        structure.fillWithBlocks(world, start, -19, -4, 9, -19, -2, 9, Blocks.BIRCH_LEAVES.getDefaultState().with(LeavesBlock.PERSISTENT, true).with(LeavesBlock.DISTANCE, 1));
        structure.fillWithBlocks(world, start, -19, -4, 18, -19, -1, 18, Blocks.CUT_SANDSTONE.getDefaultState());
        structure.fillWithBlocks(world, start, -19, -4, 19, -19, -3, 20, Blocks.SMOOTH_SANDSTONE.getDefaultState());
        structure.fillWithBlocks(world, start, -19, -4, 21, -19, -3, 21, Blocks.SPRUCE_FENCE.getDefaultState().with(FourWayBlock.WATERLOGGED, false).with(FourWayBlock.NORTH, true).with(FourWayBlock.SOUTH, true).with(FourWayBlock.EAST, false).with(FourWayBlock.WEST, false));
        structure.fillWithBlocks(world, start, -19, -4, 22, -19, -3, 23, Blocks.SMOOTH_SANDSTONE.getDefaultState());
        structure.fillWithBlocks(world, start, -19, -4, 24, -19, -1, 24, Blocks.CUT_SANDSTONE.getDefaultState());
        structure.fillWithBlocks(world, start, -19, -2, -21, -18, -2, -21, Blocks.SMOOTH_SANDSTONE.getDefaultState());
        structure.fillWithBlocks(world, start, -19, -2, -1, -18, -2, 0, Blocks.BROWN_WOOL.getDefaultState());
        structure.fillWithBlocks(world, start, -19, -2, 19, -19, -1, 23, Blocks.SMOOTH_SANDSTONE.getDefaultState());
        structure.fillWithBlocks(world, start, -19, -1, -45, -19, 0, -45, Blocks.SPRUCE_FENCE.getDefaultState().with(FourWayBlock.WATERLOGGED, false).with(FourWayBlock.NORTH, false).with(FourWayBlock.SOUTH, true).with(FourWayBlock.EAST, false).with(FourWayBlock.WEST, true));
        structure.fillWithBlocks(world, start, -19, -1, -20, -16, -1, -20, Blocks.SPRUCE_PLANKS.getDefaultState());
        structure.fillWithBlocks(world, start, -19, -1, -19, -15, -1, -15, Blocks.SPRUCE_SLAB.getDefaultState().with(SlabBlock.TYPE, SlabType.BOTTOM).with(SlabBlock.WATERLOGGED, false));
        structure.fillWithBlocks(world, start, -19, -1, -14, -17, -1, -12, Blocks.SPRUCE_SLAB.getDefaultState().with(SlabBlock.TYPE, SlabType.BOTTOM).with(SlabBlock.WATERLOGGED, false));
        structure.fillWithBlocks(world, start, -19, -1, -11, -8, -1, -11, Blocks.SPRUCE_PLANKS.getDefaultState());
        structure.fillWithBlocks(world, start, -19, -1, -10, -16, -1, -6, Blocks.SPRUCE_SLAB.getDefaultState().with(SlabBlock.TYPE, SlabType.BOTTOM).with(SlabBlock.WATERLOGGED, false));
        structure.fillWithBlocks(world, start, -19, -1, -5, -17, -1, -5, Blocks.SMOOTH_SANDSTONE.getDefaultState());
        structure.fillWithBlocks(world, start, -19, -1, 44, -19, -1, 45, Blocks.BIRCH_LEAVES.getDefaultState().with(LeavesBlock.PERSISTENT, true).with(LeavesBlock.DISTANCE, 2));
        structure.fillWithBlocks(world, start, -19, 0, -35, -19, 0, -34, Blocks.SPRUCE_FENCE.getDefaultState().with(FourWayBlock.WATERLOGGED, false).with(FourWayBlock.NORTH, true).with(FourWayBlock.SOUTH, true).with(FourWayBlock.EAST, false).with(FourWayBlock.WEST, false));
        structure.fillWithBlocks(world, start, -19, 0, -20, -16, 0, -20, Blocks.SANDSTONE_SLAB.getDefaultState().with(SlabBlock.TYPE, SlabType.BOTTOM).with(SlabBlock.WATERLOGGED, false));
        structure.fillWithBlocks(world, start, -19, 0, -5, -19, 2, -5, Blocks.SPRUCE_FENCE.getDefaultState().with(FourWayBlock.WATERLOGGED, false).with(FourWayBlock.NORTH, false).with(FourWayBlock.SOUTH, false).with(FourWayBlock.EAST, true).with(FourWayBlock.WEST, false));
        structure.fillWithBlocks(world, start, -19, 0, 7, -19, 0, 7, Blocks.BIRCH_LEAVES.getDefaultState().with(LeavesBlock.PERSISTENT, true).with(LeavesBlock.DISTANCE, 1));
        structure.fillWithBlocks(world, start, -19, 3, -7, -19, 3, -7, Blocks.OAK_TRAPDOOR.getDefaultState().with(HorizontalBlock.HORIZONTAL_FACING, Direction.NORTH).with(TrapDoorBlock.HALF, Half.BOTTOM).with(TrapDoorBlock.WATERLOGGED, false).with(TrapDoorBlock.POWERED, false).with(TrapDoorBlock.OPEN, false));
        structure.fillWithBlocks(world, start, -19, 3, -5, -18, 3, -5, Blocks.OAK_TRAPDOOR.getDefaultState().with(HorizontalBlock.HORIZONTAL_FACING, Direction.NORTH).with(TrapDoorBlock.HALF, Half.BOTTOM).with(TrapDoorBlock.WATERLOGGED, false).with(TrapDoorBlock.POWERED, false).with(TrapDoorBlock.OPEN, false));
        structure.fillWithBlocks(world, start, -18, -14, -84, -14, -14, -79, Blocks.SAND.getDefaultState());
        structure.fillWithBlocks(world, start, -18, -13, -75, 26, -13, 64, Blocks.STONE.getDefaultState());
        structure.fillWithBlocks(world, start, -18, -13, 75, 86, -13, 75, Blocks.SAND.getDefaultState());
        structure.fillWithBlocks(world, start, -18, -12, -68, -17, -12, -67, Blocks.SAND.getDefaultState());
        structure.fillWithBlocks(world, start, -18, -12, -66, -17, -12, -47, Blocks.STONE.getDefaultState());
        structure.fillWithBlocks(world, start, -18, -12, -46, -18, -9, -43, Blocks.SAND.getDefaultState());
        structure.fillWithBlocks(world, start, -18, -12, -42, -2, -12, -22, Blocks.STONE.getDefaultState());
        structure.fillWithBlocks(world, start, -18, -12, 16, -3, -12, 31, Blocks.STONE.getDefaultState());
        structure.fillWithBlocks(world, start, -18, -11, -4, 3, -11, -4, Blocks.STONE.getDefaultState());
        structure.fillWithBlocks(world, start, -18, -11, 26, -18, -9, 26, Blocks.SAND.getDefaultState());
        structure.fillWithBlocks(world, start, -18, -11, 32, -17, -11, 33, Blocks.STONE.getDefaultState());
        structure.fillWithBlocks(world, start, -18, -11, 35, -4, -11, 49, Blocks.SAND.getDefaultState());
        structure.fillWithBlocks(world, start, -18, -11, 52, -14, -11, 57, Blocks.STONE.getDefaultState());
        structure.fillWithBlocks(world, start, -18, -11, 72, 90, -11, 72, Blocks.SAND.getDefaultState());
        structure.fillWithBlocks(world, start, -18, -8, -40, -18, -6, -40, Blocks.SANDSTONE.getDefaultState());
        structure.fillWithBlocks(world, start, -18, -8, -39, -11, -8, -32, Blocks.SAND.getDefaultState());
        structure.fillWithBlocks(world, start, -18, -8, -31, -16, -8, -28, Blocks.SANDSTONE.getDefaultState());
        structure.fillWithBlocks(world, start, -18, -8, -27, -18, -8, -21, Blocks.SAND.getDefaultState());
        structure.fillWithBlocks(world, start, -18, -7, -75, -12, -7, -69, Blocks.SAND.getDefaultState());
        structure.fillWithBlocks(world, start, -18, -7, -46, -18, -6, -44, Blocks.SANDSTONE.getDefaultState());
        structure.fillWithBlocks(world, start, -18, -7, -43, -16, -7, -41, Blocks.SAND.getDefaultState());
        structure.fillWithBlocks(world, start, -18, -7, -39, -17, -7, -38, Blocks.SAND.getDefaultState());
        structure.fillWithBlocks(world, start, -18, -7, -37, -18, -7, -33, Blocks.SAND.getDefaultState());
        structure.fillWithBlocks(world, start, -18, -7, -32, -16, -7, -27, Blocks.SANDSTONE.getDefaultState());
        structure.fillWithBlocks(world, start, -18, -7, 19, -14, -7, 23, Blocks.SAND.getDefaultState());
        structure.fillWithBlocks(world, start, -18, -7, 24, -18, -7, 55, Blocks.SANDSTONE.getDefaultState());
        structure.fillWithBlocks(world, start, -18, -6, -71, -17, -6, -69, Blocks.SAND.getDefaultState());
        structure.fillWithBlocks(world, start, -18, -6, -43, -16, -6, -41, Blocks.SPRUCE_PLANKS.getDefaultState());
        structure.fillWithBlocks(world, start, -18, -6, -36, -14, -6, -27, Blocks.SANDSTONE.getDefaultState());
        structure.fillWithBlocks(world, start, -18, -6, 19, -14, -6, 23, Blocks.SPRUCE_PLANKS.getDefaultState());
        structure.fillWithBlocks(world, start, -18, -6, 24, -18, -6, 55, Blocks.SANDSTONE.getDefaultState());
        structure.fillWithBlocks(world, start, -18, -5, -40, -18, -1, -40, Blocks.CUT_SANDSTONE.getDefaultState());
        structure.fillWithBlocks(world, start, -18, -5, -39, -18, -5, -32, Blocks.SANDSTONE.getDefaultState());
        structure.fillWithBlocks(world, start, -18, -5, -31, -16, -5, -31, Blocks.SANDSTONE_STAIRS.getDefaultState().with(StairsBlock.FACING, Direction.NORTH).with(StairsBlock.WATERLOGGED, false).with(StairsBlock.SHAPE, StairsShape.STRAIGHT).with(StairsBlock.HALF, Half.BOTTOM));
        structure.fillWithBlocks(world, start, -18, -5, -27, -18, -5, -21, Blocks.SANDSTONE.getDefaultState());
        structure.fillWithBlocks(world, start, -18, -5, 16, -18, -5, 16, Blocks.BIRCH_LEAVES.getDefaultState().with(LeavesBlock.PERSISTENT, true).with(LeavesBlock.DISTANCE, 2));
        structure.fillWithBlocks(world, start, -18, -5, 18, 82, -5, 18, Blocks.SANDSTONE.getDefaultState());
        structure.fillWithBlocks(world, start, -18, -5, 26, -18, -3, 26, Blocks.SPRUCE_FENCE.getDefaultState().with(FourWayBlock.WATERLOGGED, false).with(FourWayBlock.NORTH, false).with(FourWayBlock.SOUTH, false).with(FourWayBlock.EAST, false).with(FourWayBlock.WEST, false));
        structure.fillWithBlocks(world, start, -18, -5, 35, -18, -5, 36, Blocks.BARREL.getDefaultState().with(BarrelBlock.PROPERTY_FACING, Direction.UP).with(BarrelBlock.PROPERTY_OPEN, false));
        structure.fillWithBlocks(world, start, -18, -4, -39, -18, -3, -38, Blocks.SMOOTH_SANDSTONE.getDefaultState());
        structure.fillWithBlocks(world, start, -18, -4, -37, -18, -4, -33, Blocks.SANDSTONE.getDefaultState());
        structure.fillWithBlocks(world, start, -18, -4, -32, -16, -4, -32, Blocks.SANDSTONE_STAIRS.getDefaultState().with(StairsBlock.FACING, Direction.NORTH).with(StairsBlock.WATERLOGGED, false).with(StairsBlock.SHAPE, StairsShape.STRAIGHT).with(StairsBlock.HALF, Half.BOTTOM));
        structure.fillWithBlocks(world, start, -18, -4, -27, -18, -1, -27, Blocks.CUT_SANDSTONE.getDefaultState());
        structure.fillWithBlocks(world, start, -18, -4, -26, -18, -3, -25, Blocks.SMOOTH_SANDSTONE.getDefaultState());
        structure.fillWithBlocks(world, start, -18, -4, -24, -18, -3, -23, Blocks.SPRUCE_FENCE.getDefaultState().with(FourWayBlock.WATERLOGGED, false).with(FourWayBlock.NORTH, true).with(FourWayBlock.SOUTH, true).with(FourWayBlock.EAST, false).with(FourWayBlock.WEST, false));
        structure.fillWithBlocks(world, start, -18, -4, -22, -18, -3, -21, Blocks.SMOOTH_SANDSTONE.getDefaultState());
