package mod.arcalitegames.odyssey.world.structure.structures.ruins.temple;

import mod.arcalitegames.buildersaddition.Index;
import mod.arcalitegames.buildersaddition.blocks.Bench;
import mod.arcalitegames.buildersaddition.blocks.Bookshelf;
import mod.arcalitegames.buildersaddition.blocks.Cabinet;
import mod.arcalitegames.buildersaddition.blocks.Counter;
import mod.arcalitegames.buildersaddition.blocks.LargeCandle;
import mod.arcalitegames.buildersaddition.blocks.Stool;
import mod.arcalitegames.buildersaddition.blocks.Table;
import mod.arcalitegames.buildersaddition.blocks.VerticalSlab;
import mod.arcalitegames.buildersaddition.state.BenchState;
import mod.arcalitegames.buildersaddition.state.StoolState;
import mod.arcalitegames.buildersaddition.state.VerticalSlabState;
import mod.arcalitegames.odyssey.world.structure.StructureBase;
import net.minecraft.block.AbstractFurnaceBlock;
import net.minecraft.block.BarrelBlock;
import net.minecraft.block.Blocks;
import net.minecraft.block.CakeBlock;
import net.minecraft.block.CampfireBlock;
import net.minecraft.block.CauldronBlock;
import net.minecraft.block.ChainBlock;
import net.minecraft.block.ChestBlock;
import net.minecraft.block.ComposterBlock;
import net.minecraft.block.DirectionalBlock;
import net.minecraft.block.FourWayBlock;
import net.minecraft.block.HorizontalBlock;
import net.minecraft.block.LadderBlock;
import net.minecraft.block.LanternBlock;
import net.minecraft.block.LeavesBlock;
import net.minecraft.block.PistonBlock;
import net.minecraft.block.RedstoneWireBlock;
import net.minecraft.block.SlabBlock;
import net.minecraft.block.SnowBlock;
import net.minecraft.block.SnowyDirtBlock;
import net.minecraft.block.StairsBlock;
import net.minecraft.block.TrapDoorBlock;
import net.minecraft.block.TripWireBlock;
import net.minecraft.block.VineBlock;
import net.minecraft.block.WallTorchBlock;
import net.minecraft.state.properties.ChestType;
import net.minecraft.state.properties.Half;
import net.minecraft.state.properties.RedstoneSide;
import net.minecraft.state.properties.SlabType;
import net.minecraft.state.properties.StairsShape;
import net.minecraft.util.Direction;
import net.minecraft.util.math.BlockPos;
import net.minecraft.world.World;

public class TempleComponents
{

	public static BlockPos start;
    public static World world;
    public static StructureBase structure;

    public static void init(World worldIn, BlockPos blockPos, StructureBase structureIn)
    {
        world = worldIn; start = blockPos; structure = structureIn;
    }
    
    public static void generatePart1()
    {
        structure.setBlockState(world, Blocks.STONE.getDefaultState(), 5, 0, 41, start);
        structure.setBlockState(world, Blocks.STONE.getDefaultState(), 7, 1, 37, start);
        structure.setBlockState(world, Blocks.OAK_LEAVES.getDefaultState().with(LeavesBlock.PERSISTENT, false).with(LeavesBlock.DISTANCE, 4), 9, 10, 41, start);
        structure.setBlockState(world, Blocks.DIRT.getDefaultState(), 10, 6, 37, start);
        structure.setBlockState(world, Blocks.GRASS.getDefaultState(), 10, 7, 42, start);
        structure.setBlockState(world, Blocks.OAK_LEAVES.getDefaultState().with(LeavesBlock.PERSISTENT, false).with(LeavesBlock.DISTANCE, 1), 10, 11, 37, start);
        structure.setBlockState(world, Blocks.OAK_LEAVES.getDefaultState().with(LeavesBlock.PERSISTENT, false).with(LeavesBlock.DISTANCE, 2), 10, 11, 38, start);
        structure.setBlockState(world, Blocks.DIRT.getDefaultState(), 11, 6, 43, start);
        structure.setBlockState(world, Blocks.GRASS.getDefaultState(), 11, 7, 50, start);
        structure.setBlockState(world, Blocks.OAK_LEAVES.getDefaultState().with(LeavesBlock.PERSISTENT, false).with(LeavesBlock.DISTANCE, 1), 11, 12, 43, start);
        structure.setBlockState(world, Blocks.OAK_LEAVES.getDefaultState().with(LeavesBlock.PERSISTENT, false).with(LeavesBlock.DISTANCE, 2), 11, 12, 44, start);
        structure.setBlockState(world, Blocks.GRASS_BLOCK.getDefaultState().with(SnowyDirtBlock.SNOWY, false), 12, 2, 18, start);
        structure.setBlockState(world, Blocks.GRASS_BLOCK.getDefaultState().with(SnowyDirtBlock.SNOWY, false), 12, 4, 23, start);
        structure.setBlockState(world, Blocks.GRASS.getDefaultState(), 12, 7, 39, start);
        structure.setBlockState(world, Blocks.OAK_LEAVES.getDefaultState().with(LeavesBlock.PERSISTENT, false).with(LeavesBlock.DISTANCE, 4), 12, 8, 31, start);
        structure.setBlockState(world, Blocks.OAK_LEAVES.getDefaultState().with(LeavesBlock.PERSISTENT, false).with(LeavesBlock.DISTANCE, 4), 12, 9, 29, start);
        structure.setBlockState(world, Blocks.OAK_LEAVES.getDefaultState().with(LeavesBlock.PERSISTENT, false).with(LeavesBlock.DISTANCE, 4), 12, 9, 39, start);
        structure.setBlockState(world, Blocks.OAK_LEAVES.getDefaultState().with(LeavesBlock.PERSISTENT, false).with(LeavesBlock.DISTANCE, 3), 12, 11, 37, start);
        structure.setBlockState(world, Blocks.OAK_LEAVES.getDefaultState().with(LeavesBlock.PERSISTENT, false).with(LeavesBlock.DISTANCE, 2), 12, 12, 43, start);
        structure.setBlockState(world, Blocks.GRASS_BLOCK.getDefaultState().with(SnowyDirtBlock.SNOWY, false), 13, 1, 15, start);
        structure.setBlockState(world, Blocks.GRASS.getDefaultState(), 13, 7, 41, start);
        structure.setBlockState(world, Blocks.GRASS.getDefaultState(), 13, 7, 46, start);
        structure.setBlockState(world, Blocks.GRASS.getDefaultState(), 13, 7, 54, start);
        structure.setBlockState(world, Blocks.OAK_LEAVES.getDefaultState().with(LeavesBlock.PERSISTENT, false).with(LeavesBlock.DISTANCE, 3), 13, 10, 42, start);
        structure.setBlockState(world, Blocks.OAK_LEAVES.getDefaultState().with(LeavesBlock.PERSISTENT, false).with(LeavesBlock.DISTANCE, 2), 13, 10, 43, start);
        structure.setBlockState(world, Blocks.OAK_LEAVES.getDefaultState().with(LeavesBlock.PERSISTENT, false).with(LeavesBlock.DISTANCE, 3), 13, 10, 44, start);
        structure.setBlockState(world, Blocks.OAK_LEAVES.getDefaultState().with(LeavesBlock.PERSISTENT, false).with(LeavesBlock.DISTANCE, 4), 13, 11, 49, start);
        structure.setBlockState(world, Blocks.GRASS_BLOCK.getDefaultState().with(SnowyDirtBlock.SNOWY, false), 14, 1, 14, start);
        structure.setBlockState(world, Blocks.DIRT.getDefaultState(), 14, 6, 27, start);
        structure.setBlockState(world, Blocks.DIRT.getDefaultState(), 14, 6, 33, start);
        structure.setBlockState(world, Blocks.DIRT.getDefaultState(), 14, 6, 38, start);
        structure.setBlockState(world, Blocks.GRASS.getDefaultState(), 14, 7, 32, start);
        structure.setBlockState(world, Blocks.GRASS.getDefaultState(), 14, 7, 40, start);
        structure.setBlockState(world, Blocks.GRASS.getDefaultState(), 14, 7, 49, start);
        structure.setBlockState(world, Blocks.GRASS.getDefaultState(), 14, 7, 51, start);
        structure.setBlockState(world, Blocks.OAK_LEAVES.getDefaultState().with(LeavesBlock.PERSISTENT, false).with(LeavesBlock.DISTANCE, 4), 14, 8, 45, start);
        structure.setBlockState(world, Blocks.OAK_LEAVES.getDefaultState().with(LeavesBlock.PERSISTENT, false).with(LeavesBlock.DISTANCE, 4), 14, 10, 54, start);
        structure.setBlockState(world, Blocks.OAK_LEAVES.getDefaultState().with(LeavesBlock.PERSISTENT, false).with(LeavesBlock.DISTANCE, 1), 14, 11, 27, start);
        structure.setBlockState(world, Blocks.OAK_LEAVES.getDefaultState().with(LeavesBlock.PERSISTENT, false).with(LeavesBlock.DISTANCE, 2), 14, 11, 28, start);
        structure.setBlockState(world, Blocks.OAK_LEAVES.getDefaultState().with(LeavesBlock.PERSISTENT, false).with(LeavesBlock.DISTANCE, 1), 14, 11, 33, start);
        structure.setBlockState(world, Blocks.OAK_LEAVES.getDefaultState().with(LeavesBlock.PERSISTENT, false).with(LeavesBlock.DISTANCE, 2), 14, 11, 34, start);
        structure.setBlockState(world, Blocks.OAK_LEAVES.getDefaultState().with(LeavesBlock.PERSISTENT, false).with(LeavesBlock.DISTANCE, 1), 14, 13, 38, start);
        structure.setBlockState(world, Blocks.OAK_LEAVES.getDefaultState().with(LeavesBlock.PERSISTENT, false).with(LeavesBlock.DISTANCE, 2), 14, 13, 39, start);
        structure.setBlockState(world, Blocks.GRASS_BLOCK.getDefaultState().with(SnowyDirtBlock.SNOWY, false), 15, 1, 13, start);
        structure.setBlockState(world, Blocks.DIRT.getDefaultState(), 15, 6, 51, start);
        structure.setBlockState(world, Blocks.GRASS.getDefaultState(), 15, 7, 48, start);
        structure.setBlockState(world, Blocks.GRASS.getDefaultState(), 15, 7, 54, start);
        structure.setBlockState(world, Blocks.OAK_LEAVES.getDefaultState().with(LeavesBlock.PERSISTENT, false).with(LeavesBlock.DISTANCE, 2), 15, 11, 27, start);
        structure.setBlockState(world, Blocks.OAK_LEAVES.getDefaultState().with(LeavesBlock.PERSISTENT, false).with(LeavesBlock.DISTANCE, 2), 15, 11, 33, start);
        structure.setBlockState(world, Blocks.OAK_LEAVES.getDefaultState().with(LeavesBlock.PERSISTENT, false).with(LeavesBlock.DISTANCE, 2), 15, 13, 38, start);
        structure.setBlockState(world, Blocks.OAK_LEAVES.getDefaultState().with(LeavesBlock.PERSISTENT, false).with(LeavesBlock.DISTANCE, 1), 15, 13, 51, start);
        structure.setBlockState(world, Blocks.OAK_LEAVES.getDefaultState().with(LeavesBlock.PERSISTENT, false).with(LeavesBlock.DISTANCE, 2), 15, 13, 52, start);
        structure.setBlockState(world, Blocks.DIRT.getDefaultState(), 16, 6, 43, start);
        structure.setBlockState(world, Blocks.DIRT.getDefaultState(), 16, 6, 56, start);
        structure.setBlockState(world, Blocks.GRASS.getDefaultState(), 16, 7, 36, start);
        structure.setBlockState(world, Blocks.GRASS.getDefaultState(), 16, 7, 62, start);
        structure.setBlockState(world, Blocks.OAK_LEAVES.getDefaultState().with(LeavesBlock.PERSISTENT, false).with(LeavesBlock.DISTANCE, 4), 16, 8, 25, start);
        structure.setBlockState(world, Blocks.OAK_LEAVES.getDefaultState().with(LeavesBlock.PERSISTENT, false).with(LeavesBlock.DISTANCE, 4), 16, 9, 29, start);
        structure.setBlockState(world, Blocks.OAK_LEAVES.getDefaultState().with(LeavesBlock.PERSISTENT, false).with(LeavesBlock.DISTANCE, 4), 16, 10, 40, start);
        structure.setBlockState(world, Blocks.OAK_LEAVES.getDefaultState().with(LeavesBlock.PERSISTENT, false).with(LeavesBlock.DISTANCE, 1), 16, 11, 43, start);
        structure.setBlockState(world, Blocks.OAK_LEAVES.getDefaultState().with(LeavesBlock.PERSISTENT, false).with(LeavesBlock.DISTANCE, 2), 16, 11, 44, start);
        structure.setBlockState(world, Blocks.OAK_LEAVES.getDefaultState().with(LeavesBlock.PERSISTENT, false).with(LeavesBlock.DISTANCE, 1), 16, 12, 56, start);
        structure.setBlockState(world, Blocks.OAK_LEAVES.getDefaultState().with(LeavesBlock.PERSISTENT, false).with(LeavesBlock.DISTANCE, 2), 16, 12, 57, start);
        structure.setBlockState(world, Blocks.OAK_LEAVES.getDefaultState().with(LeavesBlock.PERSISTENT, false).with(LeavesBlock.DISTANCE, 2), 16, 13, 51, start);
        structure.setBlockState(world, Blocks.GRASS_BLOCK.getDefaultState().with(SnowyDirtBlock.SNOWY, false), 17, 2, 13, start);
        structure.setBlockState(world, Blocks.GRASS.getDefaultState(), 17, 7, 35, start);
        structure.setBlockState(world, Blocks.GRASS.getDefaultState(), 17, 7, 45, start);
        structure.setBlockState(world, Blocks.GRASS.getDefaultState(), 17, 7, 56, start);
        structure.setBlockState(world, Blocks.OAK_LEAVES.getDefaultState().with(LeavesBlock.PERSISTENT, false).with(LeavesBlock.DISTANCE, 2), 17, 11, 43, start);
        structure.setBlockState(world, Blocks.OAK_LEAVES.getDefaultState().with(LeavesBlock.PERSISTENT, false).with(LeavesBlock.DISTANCE, 4), 17, 11, 49, start);
        structure.setBlockState(world, Blocks.OAK_LEAVES.getDefaultState().with(LeavesBlock.PERSISTENT, false).with(LeavesBlock.DISTANCE, 4), 17, 11, 53, start);
        structure.setBlockState(world, Blocks.OAK_LEAVES.getDefaultState().with(LeavesBlock.PERSISTENT, false).with(LeavesBlock.DISTANCE, 2), 17, 12, 56, start);
        structure.setBlockState(world, Blocks.GRASS_BLOCK.getDefaultState().with(SnowyDirtBlock.SNOWY, false), 18, 2, 12, start);
        structure.setBlockState(world, Blocks.DANDELION.getDefaultState(), 18, 7, 22, start);
        structure.setBlockState(world, Blocks.GRASS.getDefaultState(), 18, 7, 31, start);
        structure.setBlockState(world, Blocks.STONE_BRICKS.getDefaultState(), 18, 7, 32, start);
        structure.setBlockState(world, Blocks.MOSSY_STONE_BRICKS.getDefaultState(), 18, 7, 42, start);
        structure.setBlockState(world, Blocks.MOSSY_STONE_BRICKS.getDefaultState(), 18, 7, 46, start);
        structure.setBlockState(world, Blocks.MOSSY_STONE_BRICKS.getDefaultState(), 18, 7, 54, start);
        structure.setBlockState(world, Blocks.GRASS.getDefaultState(), 18, 7, 61, start);
        structure.setBlockState(world, Blocks.GRASS.getDefaultState(), 18, 7, 64, start);
        structure.setBlockState(world, Blocks.OAK_LEAVES.getDefaultState().with(LeavesBlock.PERSISTENT, false).with(LeavesBlock.DISTANCE, 3), 18, 9, 42, start);
        structure.setBlockState(world, Blocks.OAK_LEAVES.getDefaultState().with(LeavesBlock.PERSISTENT, false).with(LeavesBlock.DISTANCE, 2), 18, 9, 43, start);
        structure.setBlockState(world, Blocks.OAK_LEAVES.getDefaultState().with(LeavesBlock.PERSISTENT, false).with(LeavesBlock.DISTANCE, 3), 18, 9, 44, start);
        structure.setBlockState(world, Blocks.OAK_LEAVES.getDefaultState().with(LeavesBlock.PERSISTENT, false).with(LeavesBlock.DISTANCE, 4), 18, 10, 26, start);
        structure.setBlockState(world, Blocks.OAK_LEAVES.getDefaultState().with(LeavesBlock.PERSISTENT, false).with(LeavesBlock.DISTANCE, 4), 18, 10, 54, start);
        structure.setBlockState(world, Blocks.GRASS_BLOCK.getDefaultState().with(SnowyDirtBlock.SNOWY, false), 19, 1, 10, start);
        structure.setBlockState(world, Blocks.GRASS.getDefaultState(), 19, 7, 26, start);
        structure.setBlockState(world, Blocks.CRACKED_STONE_BRICKS.getDefaultState(), 19, 7, 54, start);
        structure.setBlockState(world, Blocks.MOSSY_COBBLESTONE.getDefaultState(), 19, 8, 35, start);
        structure.setBlockState(world, Blocks.COBBLESTONE.getDefaultState(), 19, 8, 36, start);
        structure.setBlockState(world, Blocks.MOSSY_COBBLESTONE.getDefaultState(), 19, 8, 37, start);
        structure.setBlockState(world, Blocks.MOSSY_COBBLESTONE.getDefaultState(), 19, 8, 45, start);
        structure.setBlockState(world, Blocks.COBBLESTONE.getDefaultState(), 19, 8, 46, start);
        structure.setBlockState(world, Blocks.MOSSY_COBBLESTONE.getDefaultState(), 19, 8, 47, start);
        structure.setBlockState(world, Blocks.AIR.getDefaultState(), 19, 9, 37, start);
        structure.setBlockState(world, Blocks.AIR.getDefaultState(), 19, 9, 49, start);
        structure.setBlockState(world, Blocks.OAK_LEAVES.getDefaultState().with(LeavesBlock.PERSISTENT, false).with(LeavesBlock.DISTANCE, 4), 19, 9, 66, start);
        structure.setBlockState(world, Blocks.VINE.getDefaultState().with(VineBlock.UP, false).with(VineBlock.NORTH, false).with(VineBlock.SOUTH, false).with(VineBlock.EAST, true).with(VineBlock.WEST, false), 19, 17, 46, start);
        structure.setBlockState(world, Blocks.GRASS_BLOCK.getDefaultState().with(SnowyDirtBlock.SNOWY, false), 20, 3, 12, start);
        structure.setBlockState(world, Blocks.DIRT.getDefaultState(), 20, 6, 24, start);
        structure.setBlockState(world, Blocks.GRASS_BLOCK.getDefaultState().with(SnowyDirtBlock.SNOWY, false), 20, 6, 39, start);
        structure.setBlockState(world, Blocks.GRASS_BLOCK.getDefaultState().with(SnowyDirtBlock.SNOWY, false), 20, 6, 41, start);
        structure.setBlockState(world, Blocks.GRASS.getDefaultState(), 20, 7, 21, start);
        structure.setBlockState(world, Blocks.GRASS.getDefaultState(), 20, 7, 23, start);
        structure.setBlockState(world, Blocks.STONE_BRICKS.getDefaultState(), 20, 7, 34, start);
        structure.setBlockState(world, Blocks.VINE.getDefaultState().with(VineBlock.UP, false).with(VineBlock.NORTH, false).with(VineBlock.SOUTH, false).with(VineBlock.EAST, false).with(VineBlock.WEST, true), 20, 7, 39, start);
        structure.setBlockState(world, Blocks.VINE.getDefaultState().with(VineBlock.UP, false).with(VineBlock.NORTH, false).with(VineBlock.SOUTH, false).with(VineBlock.EAST, false).with(VineBlock.WEST, true), 20, 7, 41, start);
        structure.setBlockState(world, Blocks.STONE_BRICKS.getDefaultState(), 20, 7, 52, start);
        structure.setBlockState(world, Blocks.MOSSY_STONE_BRICKS.getDefaultState(), 20, 7, 54, start);
        structure.setBlockState(world, Blocks.STONE_BRICK_STAIRS.getDefaultState().with(StairsBlock.FACING, Direction.NORTH).with(StairsBlock.WATERLOGGED, false).with(StairsBlock.SHAPE, StairsShape.STRAIGHT).with(StairsBlock.HALF, Half.TOP), 20, 8, 35, start);
        structure.setBlockState(world, Blocks.COBWEB.getDefaultState(), 20, 8, 45, start);
        structure.setBlockState(world, Blocks.STONE_BRICK_STAIRS.getDefaultState().with(StairsBlock.FACING, Direction.SOUTH).with(StairsBlock.WATERLOGGED, false).with(StairsBlock.SHAPE, StairsShape.STRAIGHT).with(StairsBlock.HALF, Half.TOP), 20, 8, 51, start);
        structure.setBlockState(world, Blocks.MOSSY_COBBLESTONE.getDefaultState(), 20, 9, 45, start);
        structure.setBlockState(world, Blocks.COBBLESTONE.getDefaultState(), 20, 9, 46, start);
        structure.setBlockState(world, Blocks.MOSSY_COBBLESTONE.getDefaultState(), 20, 9, 47, start);
        structure.setBlockState(world, Blocks.COBBLESTONE.getDefaultState(), 20, 9, 48, start);
        structure.setBlockState(world, Blocks.MOSSY_COBBLESTONE.getDefaultState(), 20, 10, 51, start);
        structure.setBlockState(world, Blocks.STONE_BRICKS.getDefaultState(), 20, 11, 36, start);
        structure.setBlockState(world, Blocks.MOSSY_STONE_BRICKS.getDefaultState(), 20, 11, 37, start);
        structure.setBlockState(world, Blocks.CRACKED_STONE_BRICKS.getDefaultState(), 20, 11, 41, start);
        structure.setBlockState(world, Blocks.STONE_BRICKS.getDefaultState(), 20, 11, 42, start);
        structure.setBlockState(world, Blocks.MOSSY_STONE_BRICKS.getDefaultState(), 20, 12, 36, start);
        structure.setBlockState(world, Blocks.STONE_BRICKS.getDefaultState(), 20, 12, 37, start);
        structure.setBlockState(world, Blocks.CRACKED_STONE_BRICKS.getDefaultState(), 20, 12, 40, start);
        structure.setBlockState(world, Blocks.STONE_BRICKS.getDefaultState(), 20, 12, 41, start);
        structure.setBlockState(world, Blocks.CRACKED_STONE_BRICKS.getDefaultState(), 20, 12, 44, start);
        structure.setBlockState(world, Blocks.STONE_BRICKS.getDefaultState(), 20, 12, 45, start);
        structure.setBlockState(world, Blocks.CRACKED_STONE_BRICKS.getDefaultState(), 20, 12, 46, start);
        structure.setBlockState(world, Blocks.MOSSY_STONE_BRICKS.getDefaultState(), 20, 12, 47, start);
        structure.setBlockState(world, Blocks.MOSSY_STONE_BRICKS.getDefaultState(), 20, 12, 50, start);
        structure.setBlockState(world, Blocks.OAK_LEAVES.getDefaultState().with(LeavesBlock.PERSISTENT, false).with(LeavesBlock.DISTANCE, 1), 20, 13, 24, start);
        structure.setBlockState(world, Blocks.OAK_LEAVES.getDefaultState().with(LeavesBlock.PERSISTENT, false).with(LeavesBlock.DISTANCE, 2), 20, 13, 25, start);
        structure.setBlockState(world, Blocks.STONE_BRICKS.getDefaultState(), 20, 13, 40, start);
        structure.setBlockState(world, Blocks.MOSSY_STONE_BRICKS.getDefaultState(), 20, 13, 42, start);
        structure.setBlockState(world, Blocks.MOSSY_STONE_BRICKS.getDefaultState(), 20, 13, 44, start);
        structure.setBlockState(world, Blocks.STONE_BRICKS.getDefaultState(), 20, 13, 46, start);
        structure.setBlockState(world, Blocks.CRACKED_STONE_BRICKS.getDefaultState(), 20, 13, 47, start);
        structure.setBlockState(world, Blocks.STONE_BRICKS.getDefaultState(), 20, 13, 50, start);
        structure.setBlockState(world, Blocks.MOSSY_STONE_BRICKS.getDefaultState(), 20, 14, 37, start);
        structure.setBlockState(world, Blocks.MOSSY_STONE_BRICKS.getDefaultState(), 20, 14, 47, start);
        structure.setBlockState(world, Blocks.MOSSY_STONE_BRICKS.getDefaultState(), 20, 14, 50, start);
        structure.setBlockState(world, Blocks.MOSSY_STONE_BRICKS.getDefaultState(), 20, 15, 36, start);
        structure.setBlockState(world, Blocks.MOSSY_STONE_BRICKS.getDefaultState(), 20, 15, 41, start);
        structure.setBlockState(world, Blocks.CRACKED_STONE_BRICKS.getDefaultState(), 20, 15, 42, start);
        structure.setBlockState(world, Blocks.MOSSY_STONE_BRICKS.getDefaultState(), 20, 15, 43, start);
        structure.setBlockState(world, Blocks.MOSSY_COBBLESTONE.getDefaultState(), 20, 15, 51, start);
        structure.setBlockState(world, Blocks.STONE_BRICKS.getDefaultState(), 20, 16, 36, start);
        structure.setBlockState(world, Blocks.MOSSY_STONE_BRICKS.getDefaultState(), 20, 16, 40, start);
        structure.setBlockState(world, Blocks.MOSSY_STONE_BRICKS.getDefaultState(), 20, 16, 46, start);
        structure.setBlockState(world, Blocks.CRACKED_STONE_BRICKS.getDefaultState(), 20, 16, 47, start);
        structure.setBlockState(world, Blocks.STONE_BRICKS.getDefaultState(), 20, 16, 48, start);
        structure.setBlockState(world, Blocks.MOSSY_STONE_BRICKS.getDefaultState(), 20, 16, 49, start);
        structure.setBlockState(world, Blocks.STONE_BRICKS.getDefaultState(), 20, 16, 50, start);
        structure.setBlockState(world, Blocks.COBBLESTONE.getDefaultState(), 20, 16, 51, start);
        structure.setBlockState(world, Blocks.MOSSY_COBBLESTONE.getDefaultState(), 20, 17, 39, start);
        structure.setBlockState(world, Blocks.COBBLESTONE.getDefaultState(), 20, 17, 40, start);
        structure.setBlockState(world, Blocks.MOSSY_COBBLESTONE.getDefaultState(), 20, 17, 41, start);
        structure.setBlockState(world, Blocks.COBBLESTONE.getDefaultState(), 20, 17, 42, start);
        structure.setBlockState(world, Blocks.MOSSY_COBBLESTONE.getDefaultState(), 20, 17, 43, start);
        structure.setBlockState(world, Blocks.MOSSY_COBBLESTONE.getDefaultState(), 20, 17, 48, start);
        structure.setBlockState(world, Blocks.MOSSY_COBBLESTONE.getDefaultState(), 20, 17, 51, start);
        structure.setBlockState(world, Blocks.VINE.getDefaultState().with(VineBlock.UP, false).with(VineBlock.NORTH, false).with(VineBlock.SOUTH, false).with(VineBlock.EAST, true).with(VineBlock.WEST, false), 20, 18, 46, start);
        structure.setBlockState(world, Blocks.VINE.getDefaultState().with(VineBlock.UP, false).with(VineBlock.NORTH, false).with(VineBlock.SOUTH, false).with(VineBlock.EAST, true).with(VineBlock.WEST, false), 20, 18, 48, start);
        structure.setBlockState(world, Blocks.GRASS_BLOCK.getDefaultState().with(SnowyDirtBlock.SNOWY, false), 21, 2, 10, start);
        structure.setBlockState(world, Blocks.DIRT.getDefaultState(), 21, 6, 64, start);
        structure.setBlockState(world, Blocks.GRASS.getDefaultState(), 21, 7, 30, start);
        structure.setBlockState(world, Blocks.VINE.getDefaultState().with(VineBlock.UP, false).with(VineBlock.NORTH, true).with(VineBlock.SOUTH, true).with(VineBlock.EAST, false).with(VineBlock.WEST, false), 21, 7, 34, start);
        structure.setBlockState(world, Blocks.SOUL_LANTERN.getDefaultState().with(LanternBlock.WATERLOGGED, false).with(LanternBlock.HANGING, true), 21, 7, 51, start);
        structure.setBlockState(world, Blocks.CRACKED_STONE_BRICKS.getDefaultState(), 21, 7, 54, start);
        structure.setBlockState(world, Blocks.GRASS.getDefaultState(), 21, 7, 56, start);
        structure.setBlockState(world, Blocks.GRASS.getDefaultState(), 21, 7, 66, start);
        structure.setBlockState(world, Blocks.STONE_BRICK_STAIRS.getDefaultState().with(StairsBlock.FACING, Direction.WEST).with(StairsBlock.WATERLOGGED, false).with(StairsBlock.SHAPE, StairsShape.STRAIGHT).with(StairsBlock.HALF, Half.TOP), 21, 8, 34, start);
        structure.setBlockState(world, Blocks.CHAIN.getDefaultState().with(ChainBlock.WATERLOGGED, false), 21, 8, 51, start);
        structure.setBlockState(world, Blocks.STONE_BRICK_STAIRS.getDefaultState().with(StairsBlock.FACING, Direction.WEST).with(StairsBlock.WATERLOGGED, false).with(StairsBlock.SHAPE, StairsShape.STRAIGHT).with(StairsBlock.HALF, Half.TOP), 21, 8, 52, start);
        structure.setBlockState(world, Blocks.MOSSY_COBBLESTONE.getDefaultState(), 21, 8, 53, start);
        structure.setBlockState(world, Blocks.MOSSY_COBBLESTONE.getDefaultState(), 21, 9, 34, start);
        structure.setBlockState(world, Blocks.STONE_BRICK_STAIRS.getDefaultState().with(StairsBlock.FACING, Direction.WEST).with(StairsBlock.WATERLOGGED, false).with(StairsBlock.SHAPE, StairsShape.STRAIGHT).with(StairsBlock.HALF, Half.TOP), 21, 10, 40, start);
        structure.setBlockState(world, Index.COUNTER_OAK_ANDESITE.getDefaultState().with(Counter.FACING, Direction.EAST).with(Counter.WATERLOGGED, false), 21, 10, 41, start);
        structure.setBlockState(world, Blocks.CAULDRON.getDefaultState().with(CauldronBlock.LEVEL, 3), 21, 10, 42, start);
        structure.setBlockState(world, Blocks.STONE_BRICK_STAIRS.getDefaultState().with(StairsBlock.FACING, Direction.WEST).with(StairsBlock.WATERLOGGED, false).with(StairsBlock.SHAPE, StairsShape.STRAIGHT).with(StairsBlock.HALF, Half.TOP), 21, 10, 43, start);
        structure.setBlockState(world, Blocks.CRAFTING_TABLE.getDefaultState(), 21, 10, 44, start);
        structure.setBlockState(world, Blocks.STONE_BRICK_STAIRS.getDefaultState().with(StairsBlock.FACING, Direction.WEST).with(StairsBlock.WATERLOGGED, false).with(StairsBlock.SHAPE, StairsShape.STRAIGHT).with(StairsBlock.HALF, Half.TOP), 21, 10, 45, start);
        structure.setBlockState(world, Blocks.CAULDRON.getDefaultState().with(CauldronBlock.LEVEL, 3), 21, 10, 46, start);
        structure.setBlockState(world, Index.COUNTER_OAK_ANDESITE.getDefaultState().with(Counter.FACING, Direction.EAST).with(Counter.WATERLOGGED, false), 21, 10, 47, start);
        structure.setBlockState(world, Blocks.STONE_BRICK_STAIRS.getDefaultState().with(StairsBlock.FACING, Direction.WEST).with(StairsBlock.WATERLOGGED, false).with(StairsBlock.SHAPE, StairsShape.STRAIGHT).with(StairsBlock.HALF, Half.TOP), 21, 10, 48, start);
        structure.setBlockState(world, Blocks.STONE.getDefaultState(), 21, 10, 49, start);
        structure.setBlockState(world, Index.LARGE_CANDLE.getDefaultState().with(LargeCandle.LIT, true), 21, 11, 45, start);
        structure.setBlockState(world, Index.LARGE_CANDLE.getDefaultState().with(LargeCandle.LIT, true), 21, 11, 49, start);
        structure.setBlockState(world, Blocks.STONE_BRICKS.getDefaultState(), 21, 11, 50, start);
        structure.setBlockState(world, Blocks.OAK_LEAVES.getDefaultState().with(LeavesBlock.PERSISTENT, false).with(LeavesBlock.DISTANCE, 4), 21, 11, 58, start);
        structure.setBlockState(world, Blocks.OAK_LEAVES.getDefaultState().with(LeavesBlock.PERSISTENT, false).with(LeavesBlock.DISTANCE, 1), 21, 11, 64, start);
        structure.setBlockState(world, Blocks.OAK_LEAVES.getDefaultState().with(LeavesBlock.PERSISTENT, false).with(LeavesBlock.DISTANCE, 2), 21, 11, 65, start);
        structure.setBlockState(world, Blocks.OAK_LEAVES.getDefaultState().with(LeavesBlock.PERSISTENT, false).with(LeavesBlock.DISTANCE, 2), 21, 13, 24, start);
        structure.setBlockState(world, Blocks.MOSSY_STONE_BRICKS.getDefaultState(), 21, 13, 36, start);
        structure.setBlockState(world, Blocks.STONE_BRICKS.getDefaultState(), 21, 15, 51, start);
        structure.setBlockState(world, Blocks.STONE_BRICKS.getDefaultState(), 21, 16, 35, start);
        structure.setBlockState(world, Blocks.MOSSY_STONE_BRICKS.getDefaultState(), 21, 16, 36, start);
        structure.setBlockState(world, Blocks.MOSSY_COBBLESTONE.getDefaultState(), 21, 18, 37, start);
        structure.setBlockState(world, Blocks.COBBLESTONE.getDefaultState(), 21, 18, 38, start);
        structure.setBlockState(world, Blocks.COBBLESTONE.getDefaultState(), 21, 18, 41, start);
        structure.setBlockState(world, Blocks.MOSSY_COBBLESTONE.getDefaultState(), 21, 18, 42, start);
        structure.setBlockState(world, Blocks.COBBLESTONE.getDefaultState(), 21, 18, 43, start);
        structure.setBlockState(world, Blocks.VINE.getDefaultState().with(VineBlock.UP, false).with(VineBlock.NORTH, false).with(VineBlock.SOUTH, false).with(VineBlock.EAST, true).with(VineBlock.WEST, false), 21, 19, 48, start);
        structure.setBlockState(world, Blocks.STONE.getDefaultState(), 22, 0, 71, start);
        structure.setBlockState(world, Blocks.GRASS_BLOCK.getDefaultState().with(SnowyDirtBlock.SNOWY, false), 22, 1, 8, start);
        structure.setBlockState(world, Blocks.GRASS.getDefaultState(), 22, 7, 19, start);
        structure.setBlockState(world, Blocks.GRASS.getDefaultState(), 22, 7, 24, start);
        structure.setBlockState(world, Blocks.VINE.getDefaultState().with(VineBlock.UP, false).with(VineBlock.NORTH, true).with(VineBlock.SOUTH, true).with(VineBlock.EAST, true).with(VineBlock.WEST, false), 22, 7, 34, start);
        structure.setBlockState(world, Blocks.VINE.getDefaultState().with(VineBlock.UP, false).with(VineBlock.NORTH, false).with(VineBlock.SOUTH, false).with(VineBlock.EAST, true).with(VineBlock.WEST, false), 22, 7, 46, start);
        structure.setBlockState(world, Blocks.VINE.getDefaultState().with(VineBlock.UP, false).with(VineBlock.NORTH, false).with(VineBlock.SOUTH, false).with(VineBlock.EAST, true).with(VineBlock.WEST, true), 22, 7, 47, start);
        structure.setBlockState(world, Blocks.GRASS.getDefaultState(), 22, 7, 60, start);
        structure.setBlockState(world, Blocks.OAK_LEAVES.getDefaultState().with(LeavesBlock.PERSISTENT, false).with(LeavesBlock.DISTANCE, 4), 22, 8, 27, start);
        structure.setBlockState(world, Blocks.VINE.getDefaultState().with(VineBlock.UP, true).with(VineBlock.NORTH, true).with(VineBlock.SOUTH, true).with(VineBlock.EAST, false).with(VineBlock.WEST, false), 22, 8, 34, start);
        structure.setBlockState(world, Blocks.STONE_BRICK_STAIRS.getDefaultState().with(StairsBlock.FACING, Direction.EAST).with(StairsBlock.WATERLOGGED, false).with(StairsBlock.SHAPE, StairsShape.STRAIGHT).with(StairsBlock.HALF, Half.TOP), 22, 8, 39, start);
        structure.setBlockState(world, Blocks.COBWEB.getDefaultState(), 22, 8, 40, start);
        structure.setBlockState(world, Blocks.VINE.getDefaultState().with(VineBlock.UP, true).with(VineBlock.NORTH, false).with(VineBlock.SOUTH, false).with(VineBlock.EAST, true).with(VineBlock.WEST, false), 22, 8, 46, start);
        structure.setBlockState(world, Blocks.VINE.getDefaultState().with(VineBlock.UP, true).with(VineBlock.NORTH, false).with(VineBlock.SOUTH, false).with(VineBlock.EAST, true).with(VineBlock.WEST, true), 22, 8, 47, start);
        structure.setBlockState(world, Blocks.STONE_BRICK_STAIRS.getDefaultState().with(StairsBlock.FACING, Direction.EAST).with(StairsBlock.WATERLOGGED, false).with(StairsBlock.SHAPE, StairsShape.STRAIGHT).with(StairsBlock.HALF, Half.TOP), 22, 8, 48, start);
        structure.setBlockState(world, Blocks.MOSSY_COBBLESTONE.getDefaultState(), 22, 9, 51, start);
        structure.setBlockState(world, Blocks.STONE_BRICKS.getDefaultState(), 22, 10, 50, start);
        structure.setBlockState(world, Blocks.OAK_LEAVES.getDefaultState().with(LeavesBlock.PERSISTENT, false).with(LeavesBlock.DISTANCE, 4), 22, 10, 55, start);
        structure.setBlockState(world, Blocks.OAK_LEAVES.getDefaultState().with(LeavesBlock.PERSISTENT, false).with(LeavesBlock.DISTANCE, 2), 22, 11, 64, start);
        structure.setBlockState(world, Blocks.MOSSY_STONE_BRICKS.getDefaultState(), 22, 12, 36, start);
        structure.setBlockState(world, Blocks.CRACKED_STONE_BRICKS.getDefaultState(), 22, 12, 50, start);
        structure.setBlockState(world, Blocks.STONE_BRICKS.getDefaultState(), 22, 13, 36, start);
        structure.setBlockState(world, Blocks.STONE_BRICKS.getDefaultState(), 22, 14, 35, start);
        structure.setBlockState(world, Blocks.STONE_BRICKS.getDefaultState(), 22, 14, 51, start);
        structure.setBlockState(world, Blocks.MOSSY_STONE_BRICKS.getDefaultState(), 22, 15, 35, start);
        structure.setBlockState(world, Blocks.COBWEB.getDefaultState(), 22, 18, 37, start);
        structure.setBlockState(world, Blocks.COBBLESTONE.getDefaultState(), 22, 19, 49, start);
        structure.setBlockState(world, Blocks.VINE.getDefaultState().with(VineBlock.UP, false).with(VineBlock.NORTH, false).with(VineBlock.SOUTH, false).with(VineBlock.EAST, true).with(VineBlock.WEST, false), 22, 20, 40, start);
        structure.setBlockState(world, Blocks.VINE.getDefaultState().with(VineBlock.UP, false).with(VineBlock.NORTH, false).with(VineBlock.SOUTH, false).with(VineBlock.EAST, true).with(VineBlock.WEST, false), 22, 20, 48, start);
        structure.setBlockState(world, Blocks.GRASS_BLOCK.getDefaultState().with(SnowyDirtBlock.SNOWY, false), 23, 3, 10, start);
        structure.setBlockState(world, Blocks.DIRT.getDefaultState(), 23, 6, 60, start);
        structure.setBlockState(world, Blocks.GRASS.getDefaultState(), 23, 7, 18, start);
        structure.setBlockState(world, Blocks.GRASS.getDefaultState(), 23, 7, 26, start);
        structure.setBlockState(world, Blocks.DANDELION.getDefaultState(), 23, 7, 28, start);
        structure.setBlockState(world, Blocks.GRASS.getDefaultState(), 23, 7, 65, start);
        structure.setBlockState(world, Blocks.MOSSY_COBBLESTONE.getDefaultState(), 23, 8, 33, start);
        structure.setBlockState(world, Blocks.VINE.getDefaultState().with(VineBlock.UP, true).with(VineBlock.NORTH, true).with(VineBlock.SOUTH, true).with(VineBlock.EAST, true).with(VineBlock.WEST, false), 23, 8, 34, start);
        structure.setBlockState(world, Blocks.STONE_BRICK_STAIRS.getDefaultState().with(StairsBlock.FACING, Direction.SOUTH).with(StairsBlock.WATERLOGGED, false).with(StairsBlock.SHAPE, StairsShape.STRAIGHT).with(StairsBlock.HALF, Half.TOP), 23, 8, 38, start);
        structure.setBlockState(world, Blocks.STONE_BRICK_SLAB.getDefaultState().with(SlabBlock.TYPE, SlabType.TOP).with(SlabBlock.WATERLOGGED, false), 23, 8, 49, start);
        structure.setBlockState(world, Blocks.OAK_LEAVES.getDefaultState().with(LeavesBlock.PERSISTENT, false).with(LeavesBlock.DISTANCE, 4), 23, 8, 62, start);
        structure.setBlockState(world, Blocks.OAK_LEAVES.getDefaultState().with(LeavesBlock.PERSISTENT, false).with(LeavesBlock.DISTANCE, 4), 23, 8, 66, start);
        structure.setBlockState(world, Blocks.CRACKED_STONE_BRICKS.getDefaultState(), 23, 11, 36, start);
        structure.setBlockState(world, Blocks.STONE_BRICKS.getDefaultState(), 23, 13, 35, start);
        structure.setBlockState(world, Blocks.MOSSY_STONE_BRICKS.getDefaultState(), 23, 13, 36, start);
        structure.setBlockState(world, Blocks.OAK_LEAVES.getDefaultState().with(LeavesBlock.PERSISTENT, false).with(LeavesBlock.DISTANCE, 1), 23, 13, 60, start);
        structure.setBlockState(world, Blocks.OAK_LEAVES.getDefaultState().with(LeavesBlock.PERSISTENT, false).with(LeavesBlock.DISTANCE, 2), 23, 13, 61, start);
        structure.setBlockState(world, Blocks.MOSSY_STONE_BRICKS.getDefaultState(), 23, 14, 35, start);
        structure.setBlockState(world, Blocks.STONE_BRICKS.getDefaultState(), 23, 16, 35, start);
        structure.setBlockState(world, Blocks.STONE_BRICKS.getDefaultState(), 23, 16, 50, start);
        structure.setBlockState(world, Blocks.MOSSY_COBBLESTONE.getDefaultState(), 23, 17, 51, start);
        structure.setBlockState(world, Blocks.VINE.getDefaultState().with(VineBlock.UP, false).with(VineBlock.NORTH, false).with(VineBlock.SOUTH, true).with(VineBlock.EAST, false).with(VineBlock.WEST, false), 23, 18, 35, start);
        structure.setBlockState(world, Blocks.DIRT.getDefaultState(), 24, 6, 29, start);
        structure.setBlockState(world, Blocks.DIRT.getDefaultState(), 24, 6, 57, start);
        structure.setBlockState(world, Blocks.COBBLESTONE.getDefaultState(), 24, 8, 33, start);
        structure.setBlockState(world, Blocks.STONE_BRICK_STAIRS.getDefaultState().with(StairsBlock.FACING, Direction.NORTH).with(StairsBlock.WATERLOGGED, false).with(StairsBlock.SHAPE, StairsShape.STRAIGHT).with(StairsBlock.HALF, Half.TOP), 24, 8, 50, start);
        structure.setBlockState(world, Blocks.STONE_BRICKS.getDefaultState(), 24, 10, 35, start);
        structure.setBlockState(world, Index.TABLE_OAK.getDefaultState().with(Table.NE, true).with(Table.NW, true).with(Table.SE, false).with(Table.SW, false), 24, 10, 42, start);
        structure.setBlockState(world, Index.TABLE_OAK.getDefaultState().with(Table.NE, false).with(Table.NW, false).with(Table.SE, true).with(Table.SW, true), 24, 10, 46, start);
        structure.setBlockState(world, Blocks.STONE_BRICKS.getDefaultState(), 24, 10, 50, start);
        structure.setBlockState(world, Blocks.MOSSY_STONE_BRICKS.getDefaultState(), 24, 10, 51, start);
        structure.setBlockState(world, Blocks.OAK_LEAVES.getDefaultState().with(LeavesBlock.PERSISTENT, false).with(LeavesBlock.DISTANCE, 1), 24, 11, 29, start);
        structure.setBlockState(world, Blocks.OAK_LEAVES.getDefaultState().with(LeavesBlock.PERSISTENT, false).with(LeavesBlock.DISTANCE, 2), 24, 11, 30, start);
        structure.setBlockState(world, Blocks.CRACKED_STONE_BRICKS.getDefaultState(), 24, 11, 35, start);
        structure.setBlockState(world, Blocks.CAKE.getDefaultState().with(CakeBlock.BITES, 0), 24, 11, 43, start);
        structure.setBlockState(world, Blocks.FLOWER_POT.getDefaultState(), 24, 11, 44, start);
        structure.setBlockState(world, Blocks.CAKE.getDefaultState().with(CakeBlock.BITES, 0), 24, 11, 45, start);
        structure.setBlockState(world, Blocks.OAK_LEAVES.getDefaultState().with(LeavesBlock.PERSISTENT, false).with(LeavesBlock.DISTANCE, 1), 24, 13, 57, start);
        structure.setBlockState(world, Blocks.OAK_LEAVES.getDefaultState().with(LeavesBlock.PERSISTENT, false).with(LeavesBlock.DISTANCE, 2), 24, 13, 58, start);
        structure.setBlockState(world, Blocks.OAK_LEAVES.getDefaultState().with(LeavesBlock.PERSISTENT, false).with(LeavesBlock.DISTANCE, 2), 24, 13, 60, start);
        structure.setBlockState(world, Blocks.CRACKED_STONE_BRICKS.getDefaultState(), 24, 14, 50, start);
        structure.setBlockState(world, Blocks.MOSSY_STONE_BRICKS.getDefaultState(), 24, 15, 35, start);
        structure.setBlockState(world, Blocks.STONE_BRICKS.getDefaultState(), 24, 15, 50, start);
        structure.setBlockState(world, Blocks.MOSSY_COBBLESTONE.getDefaultState(), 24, 17, 50, start);
        structure.setBlockState(world, Blocks.COBBLESTONE.getDefaultState(), 24, 18, 50, start);
        structure.setBlockState(world, Blocks.VINE.getDefaultState().with(VineBlock.UP, false).with(VineBlock.NORTH, true).with(VineBlock.SOUTH, false).with(VineBlock.EAST, false).with(VineBlock.WEST, false), 24, 18, 51, start);
        structure.setBlockState(world, Blocks.VINE.getDefaultState().with(VineBlock.UP, false).with(VineBlock.NORTH, true).with(VineBlock.SOUTH, false).with(VineBlock.EAST, false).with(VineBlock.WEST, false), 24, 19, 50, start);
        structure.setBlockState(world, Blocks.MOSSY_COBBLESTONE.getDefaultState(), 24, 20, 39, start);
        structure.setBlockState(world, Blocks.GRASS.getDefaultState(), 25, 7, 19, start);
        structure.setBlockState(world, Blocks.GRASS.getDefaultState(), 25, 7, 26, start);
        structure.setBlockState(world, Blocks.GRASS.getDefaultState(), 25, 7, 58, start);
        structure.setBlockState(world, Blocks.GRASS.getDefaultState(), 25, 7, 67, start);
        structure.setBlockState(world, Blocks.OAK_LEAVES.getDefaultState().with(LeavesBlock.PERSISTENT, false).with(LeavesBlock.DISTANCE, 4), 25, 8, 12, start);
        structure.setBlockState(world, Blocks.STONE_BRICK_STAIRS.getDefaultState().with(StairsBlock.FACING, Direction.SOUTH).with(StairsBlock.WATERLOGGED, false).with(StairsBlock.SHAPE, StairsShape.STRAIGHT).with(StairsBlock.HALF, Half.TOP), 25, 8, 38, start);
        structure.setBlockState(world, Blocks.COBWEB.getDefaultState(), 25, 8, 52, start);
        structure.setBlockState(world, Blocks.OAK_LEAVES.getDefaultState().with(LeavesBlock.PERSISTENT, false).with(LeavesBlock.DISTANCE, 4), 25, 9, 16, start);
        structure.setBlockState(world, Blocks.COBBLESTONE.getDefaultState(), 25, 10, 36, start);
        structure.setBlockState(world, Index.STOOL_OAK.getDefaultState().with(Stool.PILLOW, StoolState.NONE), 25, 10, 42, start);
        structure.setBlockState(world, Index.STOOL_OAK.getDefaultState().with(Stool.PILLOW, StoolState.NONE), 25, 10, 44, start);
        structure.setBlockState(world, Index.STOOL_OAK.getDefaultState().with(Stool.PILLOW, StoolState.NONE), 25, 10, 46, start);
        structure.setBlockState(world, Blocks.OAK_LEAVES.getDefaultState().with(LeavesBlock.PERSISTENT, false).with(LeavesBlock.DISTANCE, 2), 25, 11, 29, start);
        structure.setBlockState(world, Blocks.MOSSY_COBBLESTONE.getDefaultState(), 25, 11, 36, start);
        structure.setBlockState(world, Blocks.OAK_LEAVES.getDefaultState().with(LeavesBlock.PERSISTENT, false).with(LeavesBlock.DISTANCE, 4), 25, 11, 62, start);
        structure.setBlockState(world, Blocks.WALL_TORCH.getDefaultState().with(WallTorchBlock.HORIZONTAL_FACING, Direction.NORTH), 25, 13, 49, start);
        structure.setBlockState(world, Blocks.OAK_LEAVES.getDefaultState().with(LeavesBlock.PERSISTENT, false).with(LeavesBlock.DISTANCE, 2), 25, 13, 57, start);
        structure.setBlockState(world, Blocks.LANTERN.getDefaultState().with(LanternBlock.WATERLOGGED, false).with(LanternBlock.HANGING, true), 25, 14, 43, start);
        structure.setBlockState(world, Blocks.MOSSY_COBBLESTONE.getDefaultState(), 25, 15, 50, start);
        structure.setBlockState(world, Blocks.COBBLESTONE.getDefaultState(), 25, 15, 51, start);
        structure.setBlockState(world, Blocks.MOSSY_COBBLESTONE.getDefaultState(), 25, 16, 35, start);
        structure.setBlockState(world, Blocks.COBBLESTONE.getDefaultState(), 25, 16, 36, start);
        structure.setBlockState(world, Blocks.MOSSY_COBBLESTONE.getDefaultState(), 25, 16, 51, start);
        structure.setBlockState(world, Blocks.MOSSY_COBBLESTONE.getDefaultState(), 25, 18, 50, start);
        structure.setBlockState(world, Blocks.MOSSY_COBBLESTONE.getDefaultState(), 25, 20, 38, start);
        structure.setBlockState(world, Blocks.MOSSY_COBBLESTONE.getDefaultState(), 25, 20, 46, start);
        structure.setBlockState(world, Blocks.GRASS.getDefaultState(), 26, 7, 16, start);
        structure.setBlockState(world, Blocks.GRASS.getDefaultState(), 26, 7, 18, start);
        structure.setBlockState(world, Blocks.GRASS.getDefaultState(), 26, 7, 30, start);
        structure.setBlockState(world, Blocks.VINE.getDefaultState().with(VineBlock.UP, true).with(VineBlock.NORTH, true).with(VineBlock.SOUTH, false).with(VineBlock.EAST, true).with(VineBlock.WEST, true), 26, 7, 41, start);
        structure.setBlockState(world, Blocks.VINE.getDefaultState().with(VineBlock.UP, true).with(VineBlock.NORTH, false).with(VineBlock.SOUTH, false).with(VineBlock.EAST, true).with(VineBlock.WEST, true), 26, 7, 42, start);
        structure.setBlockState(world, Blocks.COBWEB.getDefaultState(), 26, 7, 46, start);
        structure.setBlockState(world, Blocks.STONE.getDefaultState(), 26, 7, 53, start);
        structure.setBlockState(world, Blocks.CRACKED_STONE_BRICKS.getDefaultState(), 26, 7, 54, start);
        structure.setBlockState(world, Blocks.GRASS.getDefaultState(), 26, 7, 57, start);
        structure.setBlockState(world, Blocks.GRASS.getDefaultState(), 26, 7, 72, start);
        structure.setBlockState(world, Blocks.STONE_BRICK_STAIRS.getDefaultState().with(StairsBlock.FACING, Direction.WEST).with(StairsBlock.WATERLOGGED, false).with(StairsBlock.SHAPE, StairsShape.STRAIGHT).with(StairsBlock.HALF, Half.TOP), 26, 8, 39, start);
        structure.setBlockState(world, Blocks.OAK_LEAVES.getDefaultState().with(LeavesBlock.PERSISTENT, false).with(LeavesBlock.DISTANCE, 4), 26, 9, 27, start);
        structure.setBlockState(world, Blocks.COBBLESTONE.getDefaultState(), 26, 9, 52, start);
        structure.setBlockState(world, Blocks.AIR.getDefaultState(), 26, 10, 43, start);
        structure.setBlockState(world, Blocks.MOSSY_STONE_BRICKS.getDefaultState(), 26, 10, 50, start);
        structure.setBlockState(world, Blocks.STONE_BRICKS.getDefaultState(), 26, 10, 51, start);
        structure.setBlockState(world, Blocks.OAK_LEAVES.getDefaultState().with(LeavesBlock.PERSISTENT, false).with(LeavesBlock.DISTANCE, 4), 26, 10, 75, start);
        structure.setBlockState(world, Blocks.STONE_BRICKS.getDefaultState(), 26, 11, 50, start);
        structure.setBlockState(world, Blocks.OAK_LEAVES.getDefaultState().with(LeavesBlock.PERSISTENT, false).with(LeavesBlock.DISTANCE, 4), 26, 11, 55, start);
        structure.setBlockState(world, Blocks.OAK_LEAVES.getDefaultState().with(LeavesBlock.PERSISTENT, false).with(LeavesBlock.DISTANCE, 4), 26, 11, 59, start);
        structure.setBlockState(world, Blocks.STONE_BRICKS.getDefaultState(), 26, 12, 35, start);
        structure.setBlockState(world, Blocks.CRACKED_STONE_BRICKS.getDefaultState(), 26, 12, 36, start);
        structure.setBlockState(world, Blocks.MOSSY_STONE_BRICKS.getDefaultState(), 26, 14, 35, start);
        structure.setBlockState(world, Blocks.MOSSY_STONE_BRICKS.getDefaultState(), 26, 15, 36, start);
        structure.setBlockState(world, Blocks.STONE_BRICKS.getDefaultState(), 26, 15, 51, start);
        structure.setBlockState(world, Blocks.STONE_BRICKS.getDefaultState(), 26, 16, 36, start);
        structure.setBlockState(world, Blocks.MOSSY_COBBLESTONE.getDefaultState(), 26, 17, 50, start);
        structure.setBlockState(world, Blocks.VINE.getDefaultState().with(VineBlock.UP, false).with(VineBlock.NORTH, false).with(VineBlock.SOUTH, true).with(VineBlock.EAST, false).with(VineBlock.WEST, false), 26, 18, 35, start);
        structure.setBlockState(world, Blocks.VINE.getDefaultState().with(VineBlock.UP, false).with(VineBlock.NORTH, false).with(VineBlock.SOUTH, true).with(VineBlock.EAST, false).with(VineBlock.WEST, false), 26, 19, 36, start);
        structure.setBlockState(world, Blocks.DIRT.getDefaultState(), 27, 6, 14, start);
        structure.setBlockState(world, Blocks.GRASS_BLOCK.getDefaultState().with(SnowyDirtBlock.SNOWY, false), 27, 6, 34, start);
        structure.setBlockState(world, Blocks.GRASS.getDefaultState(), 27, 7, 25, start);
        structure.setBlockState(world, Blocks.COBWEB.getDefaultState(), 27, 7, 34, start);
        structure.setBlockState(world, Blocks.STONE_BRICK_STAIRS.getDefaultState().with(StairsBlock.FACING, Direction.EAST).with(StairsBlock.WATERLOGGED, false).with(StairsBlock.SHAPE, StairsShape.STRAIGHT).with(StairsBlock.HALF, Half.TOP), 27, 8, 34, start);
        structure.setBlockState(world, Blocks.MOSSY_COBBLESTONE.getDefaultState(), 27, 9, 35, start);
        structure.setBlockState(world, Blocks.STONE_BRICKS.getDefaultState(), 27, 10, 36, start);
        structure.setBlockState(world, Blocks.BROWN_MUSHROOM.getDefaultState(), 27, 10, 39, start);
        structure.setBlockState(world, Blocks.OAK_LEAVES.getDefaultState().with(LeavesBlock.PERSISTENT, false).with(LeavesBlock.DISTANCE, 1), 27, 11, 14, start);
        structure.setBlockState(world, Blocks.OAK_LEAVES.getDefaultState().with(LeavesBlock.PERSISTENT, false).with(LeavesBlock.DISTANCE, 2), 27, 11, 15, start);
        structure.setBlockState(world, Blocks.MOSSY_STONE_BRICKS.getDefaultState(), 27, 12, 36, start);
        structure.setBlockState(world, Blocks.STONE_BRICKS.getDefaultState(), 27, 15, 36, start);
        structure.setBlockState(world, Blocks.STONE_BRICKS.getDefaultState(), 27, 15, 50, start);
        structure.setBlockState(world, Blocks.GRASS_BLOCK.getDefaultState().with(SnowyDirtBlock.SNOWY, false), 28, 6, 50, start);
        structure.setBlockState(world, Blocks.DIRT.getDefaultState(), 28, 6, 73, start);
        structure.setBlockState(world, Blocks.GRASS.getDefaultState(), 28, 7, 21, start);
        structure.setBlockState(world, Blocks.VINE.getDefaultState().with(VineBlock.UP, false).with(VineBlock.NORTH, true).with(VineBlock.SOUTH, false).with(VineBlock.EAST, false).with(VineBlock.WEST, false), 28, 7, 50, start);
        structure.setBlockState(world, Blocks.STONE_BRICK_STAIRS.getDefaultState().with(StairsBlock.FACING, Direction.NORTH).with(StairsBlock.WATERLOGGED, false).with(StairsBlock.SHAPE, StairsShape.STRAIGHT).with(StairsBlock.HALF, Half.TOP), 28, 8, 35, start);
        structure.setBlockState(world, Blocks.VINE.getDefaultState().with(VineBlock.UP, true).with(VineBlock.NORTH, true).with(VineBlock.SOUTH, false).with(VineBlock.EAST, false).with(VineBlock.WEST, false), 28, 8, 50, start);
        structure.setBlockState(world, Blocks.OAK_LEAVES.getDefaultState().with(LeavesBlock.PERSISTENT, false).with(LeavesBlock.DISTANCE, 4), 28, 8, 69, start);
        structure.setBlockState(world, Blocks.COBBLESTONE.getDefaultState(), 28, 9, 35, start);
        structure.setBlockState(world, Blocks.MOSSY_COBBLESTONE.getDefaultState(), 28, 9, 52, start);
        structure.setBlockState(world, Blocks.BROWN_MUSHROOM.getDefaultState(), 28, 10, 38, start);
        structure.setBlockState(world, Blocks.TRIPWIRE.getDefaultState().with(TripWireBlock.ATTACHED, false).with(TripWireBlock.DISARMED, false).with(TripWireBlock.POWERED, false).with(TripWireBlock.NORTH, false).with(TripWireBlock.SOUTH, false).with(TripWireBlock.EAST, false).with(TripWireBlock.WEST, false), 28, 10, 52, start);
        structure.setBlockState(world, Blocks.OAK_LEAVES.getDefaultState().with(LeavesBlock.PERSISTENT, false).with(LeavesBlock.DISTANCE, 4), 28, 10, 62, start);
        structure.setBlockState(world, Blocks.OAK_LEAVES.getDefaultState().with(LeavesBlock.PERSISTENT, false).with(LeavesBlock.DISTANCE, 2), 28, 11, 14, start);
        structure.setBlockState(world, Blocks.STONE_BRICKS.getDefaultState(), 28, 11, 35, start);
        structure.setBlockState(world, Blocks.VINE.getDefaultState().with(VineBlock.UP, false).with(VineBlock.NORTH, true).with(VineBlock.SOUTH, false).with(VineBlock.EAST, true).with(VineBlock.WEST, false), 28, 11, 52, start);
        structure.setBlockState(world, Blocks.OAK_LEAVES.getDefaultState().with(LeavesBlock.PERSISTENT, false).with(LeavesBlock.DISTANCE, 4), 28, 11, 58, start);
        structure.setBlockState(world, Blocks.STONE_BRICKS.getDefaultState(), 28, 12, 36, start);
        structure.setBlockState(world, Blocks.MOSSY_STONE_BRICKS.getDefaultState(), 28, 12, 50, start);
        structure.setBlockState(world, Blocks.STONE_BRICKS.getDefaultState(), 28, 13, 50, start);
        structure.setBlockState(world, Blocks.OAK_LEAVES.getDefaultState().with(LeavesBlock.PERSISTENT, false).with(LeavesBlock.DISTANCE, 1), 28, 13, 73, start);
        structure.setBlockState(world, Blocks.OAK_LEAVES.getDefaultState().with(LeavesBlock.PERSISTENT, false).with(LeavesBlock.DISTANCE, 2), 28, 13, 74, start);
        structure.setBlockState(world, Blocks.STONE_BRICKS.getDefaultState(), 28, 14, 36, start);
        structure.setBlockState(world, Blocks.CRACKED_STONE_BRICKS.getDefaultState(), 28, 15, 36, start);
        structure.setBlockState(world, Blocks.MOSSY_STONE_BRICKS.getDefaultState(), 28, 16, 36, start);
        structure.setBlockState(world, Blocks.TRIPWIRE.getDefaultState().with(TripWireBlock.ATTACHED, false).with(TripWireBlock.DISARMED, false).with(TripWireBlock.POWERED, false).with(TripWireBlock.NORTH, false).with(TripWireBlock.SOUTH, false).with(TripWireBlock.EAST, false).with(TripWireBlock.WEST, false), 28, 16, 52, start);
        structure.setBlockState(world, Blocks.MOSSY_COBBLESTONE_STAIRS.getDefaultState().with(StairsBlock.FACING, Direction.NORTH).with(StairsBlock.WATERLOGGED, false).with(StairsBlock.SHAPE, StairsShape.STRAIGHT).with(StairsBlock.HALF, Half.BOTTOM), 28, 18, 35, start);
        structure.setBlockState(world, Blocks.MOSSY_COBBLESTONE.getDefaultState(), 28, 18, 50, start);
        structure.setBlockState(world, Blocks.MOSSY_COBBLESTONE_STAIRS.getDefaultState().with(StairsBlock.FACING, Direction.NORTH).with(StairsBlock.WATERLOGGED, false).with(StairsBlock.SHAPE, StairsShape.STRAIGHT).with(StairsBlock.HALF, Half.BOTTOM), 28, 18, 51, start);
        structure.setBlockState(world, Blocks.COBBLESTONE.getDefaultState(), 28, 19, 50, start);
        structure.setBlockState(world, Blocks.VINE.getDefaultState().with(VineBlock.UP, false).with(VineBlock.NORTH, true).with(VineBlock.SOUTH, false).with(VineBlock.EAST, false).with(VineBlock.WEST, false), 28, 19, 51, start);
        structure.setBlockState(world, Blocks.MOSSY_COBBLESTONE_STAIRS.getDefaultState().with(StairsBlock.FACING, Direction.NORTH).with(StairsBlock.WATERLOGGED, false).with(StairsBlock.SHAPE, StairsShape.STRAIGHT).with(StairsBlock.HALF, Half.BOTTOM), 28, 20, 36, start);
        structure.setBlockState(world, Blocks.MOSSY_COBBLESTONE_STAIRS.getDefaultState().with(StairsBlock.FACING, Direction.NORTH).with(StairsBlock.WATERLOGGED, false).with(StairsBlock.SHAPE, StairsShape.STRAIGHT).with(StairsBlock.HALF, Half.BOTTOM), 28, 20, 50, start);
        structure.setBlockState(world, Blocks.COBBLESTONE_SLAB.getDefaultState().with(SlabBlock.TYPE, SlabType.BOTTOM).with(SlabBlock.WATERLOGGED, false), 28, 21, 37, start);
        structure.setBlockState(world, Blocks.MOSSY_COBBLESTONE_STAIRS.getDefaultState().with(StairsBlock.FACING, Direction.NORTH).with(StairsBlock.WATERLOGGED, false).with(StairsBlock.SHAPE, StairsShape.STRAIGHT).with(StairsBlock.HALF, Half.BOTTOM), 28, 21, 38, start);
        structure.setBlockState(world, Blocks.MOSSY_COBBLESTONE.getDefaultState(), 28, 21, 40, start);
        structure.setBlockState(world, Blocks.MOSSY_COBBLESTONE.getDefaultState(), 28, 21, 45, start);
        structure.setBlockState(world, Blocks.COBBLESTONE.getDefaultState(), 28, 21, 46, start);
        structure.setBlockState(world, Blocks.MOSSY_COBBLESTONE.getDefaultState(), 28, 21, 47, start);
        structure.setBlockState(world, Blocks.COBBLESTONE_STAIRS.getDefaultState().with(StairsBlock.FACING, Direction.NORTH).with(StairsBlock.WATERLOGGED, false).with(StairsBlock.SHAPE, StairsShape.STRAIGHT).with(StairsBlock.HALF, Half.BOTTOM), 28, 21, 48, start);
        structure.setBlockState(world, Blocks.COBBLESTONE_SLAB.getDefaultState().with(SlabBlock.TYPE, SlabType.BOTTOM).with(SlabBlock.WATERLOGGED, false), 28, 21, 49, start);
        structure.setBlockState(world, Blocks.GRASS.getDefaultState(), 29, 7, 16, start);
        structure.setBlockState(world, Blocks.GRASS.getDefaultState(), 29, 7, 24, start);
        structure.setBlockState(world, Blocks.GRASS.getDefaultState(), 29, 7, 27, start);
        structure.setBlockState(world, Blocks.OAK_LEAVES.getDefaultState().with(LeavesBlock.PERSISTENT, false).with(LeavesBlock.DISTANCE, 4), 29, 8, 12, start);
        structure.setBlockState(world, Blocks.OAK_LEAVES.getDefaultState().with(LeavesBlock.PERSISTENT, false).with(LeavesBlock.DISTANCE, 4), 29, 8, 16, start);
        structure.setBlockState(world, Blocks.COBWEB.getDefaultState(), 29, 8, 50, start);
        structure.setBlockState(world, Blocks.OAK_LEAVES.getDefaultState().with(LeavesBlock.PERSISTENT, false).with(LeavesBlock.DISTANCE, 4), 29, 8, 55, start);
        structure.setBlockState(world, Blocks.OAK_LEAVES.getDefaultState().with(LeavesBlock.PERSISTENT, false).with(LeavesBlock.DISTANCE, 4), 29, 10, 17, start);
        structure.setBlockState(world, Blocks.OAK_LEAVES.getDefaultState().with(LeavesBlock.PERSISTENT, false).with(LeavesBlock.DISTANCE, 4), 29, 10, 21, start);
        structure.setBlockState(world, Blocks.MOSSY_COBBLESTONE.getDefaultState(), 29, 10, 35, start);
        structure.setBlockState(world, Blocks.OAK_FENCE.getDefaultState().with(FourWayBlock.WATERLOGGED, false).with(FourWayBlock.NORTH, false).with(FourWayBlock.SOUTH, true).with(FourWayBlock.EAST, true).with(FourWayBlock.WEST, false), 29, 10, 37, start);
        structure.setBlockState(world, Blocks.MOSSY_COBBLESTONE.getDefaultState(), 29, 10, 51, start);
        structure.setBlockState(world, Blocks.CRACKED_STONE_BRICKS.getDefaultState(), 29, 10, 52, start);
        structure.setBlockState(world, Blocks.COBBLESTONE.getDefaultState(), 29, 11, 35, start);
        structure.setBlockState(world, Blocks.MOSSY_STONE_BRICKS.getDefaultState(), 29, 12, 34, start);
        structure.setBlockState(world, Blocks.MOSSY_COBBLESTONE.getDefaultState(), 29, 12, 35, start);
        structure.setBlockState(world, Blocks.OAK_SLAB.getDefaultState().with(SlabBlock.TYPE, SlabType.TOP).with(SlabBlock.WATERLOGGED, false), 29, 12, 36, start);
        structure.setBlockState(world, Blocks.OAK_SLAB.getDefaultState().with(SlabBlock.TYPE, SlabType.BOTTOM).with(SlabBlock.WATERLOGGED, false), 29, 12, 50, start);
        structure.setBlockState(world, Blocks.STONE_BRICKS.getDefaultState(), 29, 13, 52, start);
        structure.setBlockState(world, Blocks.OAK_LEAVES.getDefaultState().with(LeavesBlock.PERSISTENT, false).with(LeavesBlock.DISTANCE, 2), 29, 13, 73, start);
        structure.setBlockState(world, Blocks.WALL_TORCH.getDefaultState().with(WallTorchBlock.HORIZONTAL_FACING, Direction.EAST), 29, 14, 36, start);
        structure.setBlockState(world, Blocks.WALL_TORCH.getDefaultState().with(WallTorchBlock.HORIZONTAL_FACING, Direction.EAST), 29, 14, 50, start);
        structure.setBlockState(world, Blocks.CRACKED_STONE_BRICKS.getDefaultState(), 29, 14, 52, start);
        structure.setBlockState(world, Blocks.STONE_BRICKS.getDefaultState(), 29, 15, 34, start);
        structure.setBlockState(world, Blocks.STONE_BRICKS.getDefaultState(), 29, 15, 52, start);
        structure.setBlockState(world, Blocks.MOSSY_COBBLESTONE.getDefaultState(), 29, 16, 35, start);
        structure.setBlockState(world, Blocks.CRACKED_STONE_BRICKS.getDefaultState(), 29, 16, 52, start);
        structure.setBlockState(world, Blocks.STONE_BRICK_STAIRS.getDefaultState().with(StairsBlock.FACING, Direction.SOUTH).with(StairsBlock.WATERLOGGED, false).with(StairsBlock.SHAPE, StairsShape.STRAIGHT).with(StairsBlock.HALF, Half.BOTTOM), 29, 17, 35, start);
        structure.setBlockState(world, Blocks.COBBLESTONE.getDefaultState(), 29, 17, 36, start);
        structure.setBlockState(world, Blocks.MOSSY_COBBLESTONE.getDefaultState(), 29, 17, 50, start);
        structure.setBlockState(world, Blocks.STONE_BRICK_STAIRS.getDefaultState().with(StairsBlock.FACING, Direction.NORTH).with(StairsBlock.WATERLOGGED, false).with(StairsBlock.SHAPE, StairsShape.STRAIGHT).with(StairsBlock.HALF, Half.BOTTOM), 29, 17, 51, start);
        structure.setBlockState(world, Blocks.COBBLESTONE.getDefaultState(), 29, 18, 49, start);
        structure.setBlockState(world, Blocks.STONE_BRICK_STAIRS.getDefaultState().with(StairsBlock.FACING, Direction.NORTH).with(StairsBlock.WATERLOGGED, false).with(StairsBlock.SHAPE, StairsShape.STRAIGHT).with(StairsBlock.HALF, Half.BOTTOM), 29, 18, 50, start);
        structure.setBlockState(world, Blocks.CRACKED_STONE_BRICKS.getDefaultState(), 29, 19, 37, start);
        structure.setBlockState(world, Blocks.CRACKED_STONE_BRICKS.getDefaultState(), 29, 19, 49, start);
        structure.setBlockState(world, Blocks.VINE.getDefaultState().with(VineBlock.UP, false).with(VineBlock.NORTH, true).with(VineBlock.SOUTH, false).with(VineBlock.EAST, false).with(VineBlock.WEST, true), 29, 19, 50, start);
        structure.setBlockState(world, Blocks.STONE_BRICK_STAIRS.getDefaultState().with(StairsBlock.FACING, Direction.SOUTH).with(StairsBlock.WATERLOGGED, false).with(StairsBlock.SHAPE, StairsShape.STRAIGHT).with(StairsBlock.HALF, Half.BOTTOM), 29, 20, 37, start);
        structure.setBlockState(world, Blocks.MOSSY_COBBLESTONE.getDefaultState(), 29, 20, 45, start);
        structure.setBlockState(world, Blocks.COBBLESTONE.getDefaultState(), 29, 20, 48, start);
        structure.setBlockState(world, Blocks.MOSSY_STONE_BRICK_STAIRS.getDefaultState().with(StairsBlock.FACING, Direction.NORTH).with(StairsBlock.WATERLOGGED, false).with(StairsBlock.SHAPE, StairsShape.STRAIGHT).with(StairsBlock.HALF, Half.BOTTOM), 29, 20, 49, start);
        structure.setBlockState(world, Blocks.VINE.getDefaultState().with(VineBlock.UP, false).with(VineBlock.NORTH, true).with(VineBlock.SOUTH, false).with(VineBlock.EAST, false).with(VineBlock.WEST, false), 29, 20, 50, start);
        structure.setBlockState(world, Blocks.DIRT.getDefaultState(), 30, 6, 60, start);
        structure.setBlockState(world, Blocks.DIRT.getDefaultState(), 30, 6, 71, start);
        structure.setBlockState(world, Blocks.DANDELION.getDefaultState(), 30, 7, 19, start);
        structure.setBlockState(world, Blocks.GRASS.getDefaultState(), 30, 7, 26, start);
        structure.setBlockState(world, Blocks.GRASS.getDefaultState(), 30, 7, 29, start);
        structure.setBlockState(world, Blocks.STONE.getDefaultState(), 30, 7, 53, start);
        structure.setBlockState(world, Blocks.CRACKED_STONE_BRICKS.getDefaultState(), 30, 7, 54, start);
        structure.setBlockState(world, Blocks.GRASS.getDefaultState(), 30, 7, 57, start);
        structure.setBlockState(world, Blocks.GRASS.getDefaultState(), 30, 7, 62, start);
        structure.setBlockState(world, Blocks.STONE_BRICK_STAIRS.getDefaultState().with(StairsBlock.FACING, Direction.NORTH).with(StairsBlock.WATERLOGGED, false).with(StairsBlock.SHAPE, StairsShape.STRAIGHT).with(StairsBlock.HALF, Half.TOP), 30, 8, 50, start);
        structure.setBlockState(world, Blocks.MOSSY_COBBLESTONE.getDefaultState(), 30, 8, 53, start);
        structure.setBlockState(world, Blocks.COMPOSTER.getDefaultState().with(ComposterBlock.LEVEL, 0), 30, 10, 36, start);
        structure.setBlockState(world, Blocks.OAK_LEAVES.getDefaultState().with(LeavesBlock.PERSISTENT, false).with(LeavesBlock.DISTANCE, 4), 30, 10, 75, start);
        structure.setBlockState(world, Blocks.OAK_LEAVES.getDefaultState().with(LeavesBlock.PERSISTENT, false).with(LeavesBlock.DISTANCE, 4), 30, 11, 16, start);
        structure.setBlockState(world, Blocks.MOSSY_COBBLESTONE.getDefaultState(), 30, 11, 35, start);
        structure.setBlockState(world, Blocks.OAK_LEAVES.getDefaultState().with(LeavesBlock.PERSISTENT, false).with(LeavesBlock.DISTANCE, 1), 30, 11, 71, start);
        structure.setBlockState(world, Blocks.BARREL.getDefaultState().with(BarrelBlock.PROPERTY_FACING, Direction.SOUTH).with(BarrelBlock.PROPERTY_OPEN, false), 30, 12, 36, start);
        structure.setBlockState(world, Blocks.OAK_SLAB.getDefaultState().with(SlabBlock.TYPE, SlabType.TOP).with(SlabBlock.WATERLOGGED, false), 30, 12, 50, start);
        structure.setBlockState(world, Blocks.OAK_SLAB.getDefaultState().with(SlabBlock.TYPE, SlabType.BOTTOM).with(SlabBlock.WATERLOGGED, false), 30, 13, 36, start);
        structure.setBlockState(world, Blocks.OAK_LEAVES.getDefaultState().with(LeavesBlock.PERSISTENT, false).with(LeavesBlock.DISTANCE, 1), 30, 13, 60, start);
        structure.setBlockState(world, Blocks.OAK_LEAVES.getDefaultState().with(LeavesBlock.PERSISTENT, false).with(LeavesBlock.DISTANCE, 2), 30, 13, 61, start);
        structure.setBlockState(world, Blocks.MOSSY_STONE_BRICKS.getDefaultState(), 30, 16, 52, start);
        structure.setBlockState(world, Blocks.MOSSY_STONE_BRICK_STAIRS.getDefaultState().with(StairsBlock.FACING, Direction.SOUTH).with(StairsBlock.WATERLOGGED, false).with(StairsBlock.SHAPE, StairsShape.STRAIGHT).with(StairsBlock.HALF, Half.BOTTOM), 30, 17, 35, start);
        structure.setBlockState(world, Blocks.MOSSY_STONE_BRICKS.getDefaultState(), 30, 19, 37, start);
        structure.setBlockState(world, Blocks.STONE_BRICKS.getDefaultState(), 30, 19, 49, start);
        structure.setBlockState(world, Blocks.STONE_BRICK_STAIRS.getDefaultState().with(StairsBlock.FACING, Direction.NORTH).with(StairsBlock.WATERLOGGED, false).with(StairsBlock.SHAPE, StairsShape.STRAIGHT).with(StairsBlock.HALF, Half.BOTTOM), 30, 20, 49, start);
        structure.setBlockState(world, Blocks.STONE.getDefaultState(), 31, 3, 42, start);
        structure.setBlockState(world, Blocks.DIRT.getDefaultState(), 31, 6, 19, start);
        structure.setBlockState(world, Blocks.DIRT.getDefaultState(), 31, 6, 57, start);
        structure.setBlockState(world, Blocks.DIRT.getDefaultState(), 31, 6, 63, start);
        structure.setBlockState(world, Blocks.GRASS.getDefaultState(), 31, 7, 52, start);
        structure.setBlockState(world, Blocks.GRASS.getDefaultState(), 31, 7, 55, start);
        structure.setBlockState(world, Blocks.GRASS.getDefaultState(), 31, 7, 66, start);
        structure.setBlockState(world, Blocks.GRASS.getDefaultState(), 31, 7, 72, start);
        structure.setBlockState(world, Blocks.MOSSY_COBBLESTONE.getDefaultState(), 31, 8, 33, start);
        structure.setBlockState(world, Blocks.STONE_BRICK_SLAB.getDefaultState().with(SlabBlock.TYPE, SlabType.TOP).with(SlabBlock.WATERLOGGED, false), 31, 8, 49, start);
        structure.setBlockState(world, Blocks.COBBLESTONE.getDefaultState(), 31, 8, 53, start);
        structure.setBlockState(world, Blocks.OAK_LEAVES.getDefaultState().with(LeavesBlock.PERSISTENT, false).with(LeavesBlock.DISTANCE, 1), 31, 11, 57, start);
        structure.setBlockState(world, Blocks.OAK_LEAVES.getDefaultState().with(LeavesBlock.PERSISTENT, false).with(LeavesBlock.DISTANCE, 2), 31, 11, 71, start);
        structure.setBlockState(world, Blocks.OAK_LEAVES.getDefaultState().with(LeavesBlock.PERSISTENT, false).with(LeavesBlock.DISTANCE, 1), 31, 12, 63, start);
        structure.setBlockState(world, Blocks.OAK_LEAVES.getDefaultState().with(LeavesBlock.PERSISTENT, false).with(LeavesBlock.DISTANCE, 2), 31, 12, 64, start);
        structure.setBlockState(world, Blocks.OAK_LEAVES.getDefaultState().with(LeavesBlock.PERSISTENT, false).with(LeavesBlock.DISTANCE, 1), 31, 13, 19, start);
        structure.setBlockState(world, Blocks.OAK_LEAVES.getDefaultState().with(LeavesBlock.PERSISTENT, false).with(LeavesBlock.DISTANCE, 2), 31, 13, 20, start);
        structure.setBlockState(world, Blocks.OAK_SLAB.getDefaultState().with(SlabBlock.TYPE, SlabType.TOP).with(SlabBlock.WATERLOGGED, false), 31, 13, 36, start);
        structure.setBlockState(world, Blocks.OAK_SLAB.getDefaultState().with(SlabBlock.TYPE, SlabType.BOTTOM).with(SlabBlock.WATERLOGGED, false), 31, 13, 50, start);
        structure.setBlockState(world, Blocks.OAK_LEAVES.getDefaultState().with(LeavesBlock.PERSISTENT, false).with(LeavesBlock.DISTANCE, 2), 31, 13, 60, start);
        structure.setBlockState(world, Blocks.COBBLESTONE.getDefaultState(), 31, 16, 51, start);
        structure.setBlockState(world, Blocks.STONE_BRICKS.getDefaultState(), 31, 16, 52, start);
        structure.setBlockState(world, Blocks.STONE_BRICK_STAIRS.getDefaultState().with(StairsBlock.FACING, Direction.SOUTH).with(StairsBlock.WATERLOGGED, false).with(StairsBlock.SHAPE, StairsShape.STRAIGHT).with(StairsBlock.HALF, Half.BOTTOM), 31, 18, 36, start);
        structure.setBlockState(world, Blocks.STONE_BRICKS.getDefaultState(), 31, 19, 37, start);
        structure.setBlockState(world, Blocks.MOSSY_STONE_BRICKS.getDefaultState(), 31, 19, 49, start);
        structure.setBlockState(world, Blocks.COBBLESTONE.getDefaultState(), 31, 20, 44, start);
        structure.setBlockState(world, Blocks.COBBLESTONE.getDefaultState(), 31, 20, 48, start);
        structure.setBlockState(world, Blocks.MOSSY_STONE_BRICK_STAIRS.getDefaultState().with(StairsBlock.FACING, Direction.NORTH).with(StairsBlock.WATERLOGGED, false).with(StairsBlock.SHAPE, StairsShape.STRAIGHT).with(StairsBlock.HALF, Half.BOTTOM), 31, 20, 49, start);
        structure.setBlockState(world, Blocks.DIRT.getDefaultState(), 32, 6, 14, start);
        structure.setBlockState(world, Blocks.GRASS_BLOCK.getDefaultState().with(SnowyDirtBlock.SNOWY, false), 32, 6, 35, start);
        structure.setBlockState(world, Blocks.GRASS_BLOCK.getDefaultState().with(SnowyDirtBlock.SNOWY, false), 32, 6, 44, start);
        structure.setBlockState(world, Blocks.DANDELION.getDefaultState(), 32, 7, 19, start);
        structure.setBlockState(world, Blocks.GRASS.getDefaultState(), 32, 7, 24, start);
        structure.setBlockState(world, Blocks.GRASS.getDefaultState(), 32, 7, 28, start);
        structure.setBlockState(world, Blocks.GRASS.getDefaultState(), 32, 7, 31, start);
        structure.setBlockState(world, Blocks.COBWEB.getDefaultState(), 32, 7, 35, start);
        structure.setBlockState(world, Blocks.VINE.getDefaultState().with(VineBlock.UP, false).with(VineBlock.NORTH, false).with(VineBlock.SOUTH, false).with(VineBlock.EAST, false).with(VineBlock.WEST, true), 32, 7, 44, start);
        structure.setBlockState(world, Blocks.GRASS.getDefaultState(), 32, 7, 61, start);
        structure.setBlockState(world, Blocks.GRASS.getDefaultState(), 32, 7, 68, start);
        structure.setBlockState(world, Blocks.POPPY.getDefaultState(), 32, 7, 70, start);
        structure.setBlockState(world, Blocks.COBBLESTONE.getDefaultState(), 32, 8, 33, start);
        structure.setBlockState(world, Blocks.STONE_BRICK_STAIRS.getDefaultState().with(StairsBlock.FACING, Direction.NORTH).with(StairsBlock.WATERLOGGED, false).with(StairsBlock.SHAPE, StairsShape.STRAIGHT).with(StairsBlock.HALF, Half.TOP), 32, 8, 35, start);
        structure.setBlockState(world, Blocks.VINE.getDefaultState().with(VineBlock.UP, true).with(VineBlock.NORTH, false).with(VineBlock.SOUTH, false).with(VineBlock.EAST, false).with(VineBlock.WEST, true), 32, 8, 44, start);
        structure.setBlockState(world, Blocks.STONE_BRICK_STAIRS.getDefaultState().with(StairsBlock.FACING, Direction.WEST).with(StairsBlock.WATERLOGGED, false).with(StairsBlock.SHAPE, StairsShape.STRAIGHT).with(StairsBlock.HALF, Half.TOP), 32, 8, 48, start);
        structure.setBlockState(world, Blocks.OAK_LEAVES.getDefaultState().with(LeavesBlock.PERSISTENT, false).with(LeavesBlock.DISTANCE, 4), 32, 8, 73, start);
        structure.setBlockState(world, Blocks.OAK_LEAVES.getDefaultState().with(LeavesBlock.PERSISTENT, false).with(LeavesBlock.DISTANCE, 4), 32, 9, 69, start);
        structure.setBlockState(world, Blocks.OAK_LEAVES.getDefaultState().with(LeavesBlock.PERSISTENT, false).with(LeavesBlock.DISTANCE, 2), 32, 11, 57, start);
        structure.setBlockState(world, Blocks.BARREL.getDefaultState().with(BarrelBlock.PROPERTY_FACING, Direction.SOUTH).with(BarrelBlock.PROPERTY_OPEN, false), 32, 12, 36, start);
        structure.setBlockState(world, Blocks.OAK_LEAVES.getDefaultState().with(LeavesBlock.PERSISTENT, false).with(LeavesBlock.DISTANCE, 2), 32, 12, 63, start);
        structure.setBlockState(world, Blocks.OAK_LEAVES.getDefaultState().with(LeavesBlock.PERSISTENT, false).with(LeavesBlock.DISTANCE, 1), 32, 13, 14, start);
        structure.setBlockState(world, Blocks.OAK_LEAVES.getDefaultState().with(LeavesBlock.PERSISTENT, false).with(LeavesBlock.DISTANCE, 2), 32, 13, 15, start);
        structure.setBlockState(world, Blocks.OAK_LEAVES.getDefaultState().with(LeavesBlock.PERSISTENT, false).with(LeavesBlock.DISTANCE, 2), 32, 13, 19, start);
        structure.setBlockState(world, Blocks.OAK_SLAB.getDefaultState().with(SlabBlock.TYPE, SlabType.TOP).with(SlabBlock.WATERLOGGED, false), 32, 13, 50, start);
        structure.setBlockState(world, Blocks.OAK_SLAB.getDefaultState().with(SlabBlock.TYPE, SlabType.BOTTOM).with(SlabBlock.WATERLOGGED, false), 32, 14, 36, start);
        structure.setBlockState(world, Blocks.STONE_BRICKS.getDefaultState(), 32, 16, 34, start);
        structure.setBlockState(world, Blocks.CRACKED_STONE_BRICKS.getDefaultState(), 32, 16, 52, start);
        structure.setBlockState(world, Blocks.STONE_BRICK_STAIRS.getDefaultState().with(StairsBlock.FACING, Direction.NORTH).with(StairsBlock.WATERLOGGED, false).with(StairsBlock.SHAPE, StairsShape.STRAIGHT).with(StairsBlock.HALF, Half.BOTTOM), 32, 17, 51, start);
        structure.setBlockState(world, Blocks.CRACKED_STONE_BRICKS.getDefaultState(), 32, 19, 49, start);
        structure.setBlockState(world, Blocks.STONE_BRICK_STAIRS.getDefaultState().with(StairsBlock.FACING, Direction.NORTH).with(StairsBlock.WATERLOGGED, false).with(StairsBlock.SHAPE, StairsShape.STRAIGHT).with(StairsBlock.HALF, Half.BOTTOM), 32, 20, 49, start);
        structure.setBlockState(world, Blocks.GRASS_BLOCK.getDefaultState().with(SnowyDirtBlock.SNOWY, false), 33, 6, 30, start);
        structure.setBlockState(world, Blocks.GRASS_BLOCK.getDefaultState().with(SnowyDirtBlock.SNOWY, false), 33, 6, 38, start);
        structure.setBlockState(world, Blocks.GRASS.getDefaultState(), 33, 7, 19, start);
        structure.setBlockState(world, Blocks.GRASS.getDefaultState(), 33, 7, 22, start);
        structure.setBlockState(world, Blocks.GRASS.getDefaultState(), 33, 7, 27, start);
        structure.setBlockState(world, Blocks.SOUL_LANTERN.getDefaultState().with(LanternBlock.WATERLOGGED, false).with(LanternBlock.HANGING, true), 33, 7, 38, start);
        structure.setBlockState(world, Blocks.VINE.getDefaultState().with(VineBlock.UP, false).with(VineBlock.NORTH, false).with(VineBlock.SOUTH, true).with(VineBlock.EAST, false).with(VineBlock.WEST, false), 33, 7, 52, start);
        structure.setBlockState(world, Blocks.GRASS.getDefaultState(), 33, 7, 71, start);
        structure.setBlockState(world, Blocks.GRASS.getDefaultState(), 33, 7, 73, start);
        structure.setBlockState(world, Blocks.CHISELED_STONE_BRICKS.getDefaultState(), 33, 8, 31, start);
        structure.setBlockState(world, Blocks.COBBLESTONE.getDefaultState(), 33, 8, 32, start);
        structure.setBlockState(world, Blocks.STONE_BRICK_STAIRS.getDefaultState().with(StairsBlock.FACING, Direction.WEST).with(StairsBlock.WATERLOGGED, false).with(StairsBlock.SHAPE, StairsShape.STRAIGHT).with(StairsBlock.HALF, Half.TOP), 33, 8, 34, start);
        structure.setBlockState(world, Blocks.CHAIN.getDefaultState().with(ChainBlock.WATERLOGGED, false), 33, 8, 38, start);
        structure.setBlockState(world, Blocks.COBWEB.getDefaultState(), 33, 8, 39, start);
        structure.setBlockState(world, Blocks.VINE.getDefaultState().with(VineBlock.UP, true).with(VineBlock.NORTH, false).with(VineBlock.SOUTH, true).with(VineBlock.EAST, false).with(VineBlock.WEST, false), 33, 8, 52, start);
        structure.setBlockState(world, Blocks.OAK_LEAVES.getDefaultState().with(LeavesBlock.PERSISTENT, false).with(LeavesBlock.DISTANCE, 4), 33, 9, 55, start);
        structure.setBlockState(world, Blocks.OAK_LEAVES.getDefaultState().with(LeavesBlock.PERSISTENT, false).with(LeavesBlock.DISTANCE, 4), 33, 9, 59, start);
        structure.setBlockState(world, Blocks.OAK_LEAVES.getDefaultState().with(LeavesBlock.PERSISTENT, false).with(LeavesBlock.DISTANCE, 4), 33, 10, 21, start);
        structure.setBlockState(world, Blocks.MOSSY_COBBLESTONE.getDefaultState(), 33, 10, 51, start);
        structure.setBlockState(world, Blocks.OAK_LEAVES.getDefaultState().with(LeavesBlock.PERSISTENT, false).with(LeavesBlock.DISTANCE, 4), 33, 10, 65, start);
        structure.setBlockState(world, Blocks.OAK_LEAVES.getDefaultState().with(LeavesBlock.PERSISTENT, false).with(LeavesBlock.DISTANCE, 4), 33, 10, 69, start);
        structure.setBlockState(world, Blocks.COMPOSTER.getDefaultState().with(ComposterBlock.LEVEL, 0), 33, 12, 36, start);
        structure.setBlockState(world, Blocks.COBBLESTONE.getDefaultState(), 33, 12, 51, start);
        structure.setBlockState(world, Blocks.OAK_LEAVES.getDefaultState().with(LeavesBlock.PERSISTENT, false).with(LeavesBlock.DISTANCE, 2), 33, 13, 14, start);
        structure.setBlockState(world, Blocks.BARREL.getDefaultState().with(BarrelBlock.PROPERTY_FACING, Direction.SOUTH).with(BarrelBlock.PROPERTY_OPEN, false), 33, 13, 36, start);
        structure.setBlockState(world, Blocks.MOSSY_COBBLESTONE.getDefaultState(), 33, 13, 51, start);
        structure.setBlockState(world, Blocks.OAK_SLAB.getDefaultState().with(SlabBlock.TYPE, SlabType.TOP).with(SlabBlock.WATERLOGGED, false), 33, 14, 36, start);
        structure.setBlockState(world, Blocks.OAK_SLAB.getDefaultState().with(SlabBlock.TYPE, SlabType.BOTTOM).with(SlabBlock.WATERLOGGED, false), 33, 14, 50, start);
        structure.setBlockState(world, Blocks.MOSSY_STONE_BRICKS.getDefaultState(), 33, 16, 52, start);
        structure.setBlockState(world, Blocks.COBBLESTONE.getDefaultState(), 33, 17, 36, start);
        structure.setBlockState(world, Blocks.MOSSY_STONE_BRICK_STAIRS.getDefaultState().with(StairsBlock.FACING, Direction.NORTH).with(StairsBlock.WATERLOGGED, false).with(StairsBlock.SHAPE, StairsShape.STRAIGHT).with(StairsBlock.HALF, Half.BOTTOM), 33, 17, 51, start);
        structure.setBlockState(world, Blocks.MOSSY_COBBLESTONE.getDefaultState(), 33, 18, 37, start);
        structure.setBlockState(world, Blocks.COBBLESTONE.getDefaultState(), 33, 18, 49, start);
        structure.setBlockState(world, Blocks.MOSSY_STONE_BRICKS.getDefaultState(), 33, 19, 49, start);
        structure.setBlockState(world, Blocks.MOSSY_STONE_BRICK_STAIRS.getDefaultState().with(StairsBlock.FACING, Direction.NORTH).with(StairsBlock.WATERLOGGED, false).with(StairsBlock.SHAPE, StairsShape.STRAIGHT).with(StairsBlock.HALF, Half.BOTTOM), 33, 20, 49, start);
        structure.setBlockState(world, Blocks.GRASS.getDefaultState(), 34, 7, 11, start);
        structure.setBlockState(world, Blocks.GRASS.getDefaultState(), 34, 7, 18, start);
        structure.setBlockState(world, Blocks.MOSSY_STONE_BRICKS.getDefaultState(), 34, 7, 30, start);
        structure.setBlockState(world, Blocks.VINE.getDefaultState().with(VineBlock.UP, false).with(VineBlock.NORTH, true).with(VineBlock.SOUTH, false).with(VineBlock.EAST, false).with(VineBlock.WEST, false), 34, 7, 34, start);
        structure.setBlockState(world, Blocks.VINE.getDefaultState().with(VineBlock.UP, false).with(VineBlock.NORTH, true).with(VineBlock.SOUTH, true).with(VineBlock.EAST, false).with(VineBlock.WEST, false), 34, 7, 52, start);
        structure.setBlockState(world, Blocks.CRACKED_STONE_BRICKS.getDefaultState(), 34, 7, 54, start);
        structure.setBlockState(world, Blocks.MOSSY_STONE_BRICKS.getDefaultState(), 34, 7, 56, start);
        structure.setBlockState(world, Blocks.GRASS.getDefaultState(), 34, 7, 70, start);
        structure.setBlockState(world, Blocks.CHISELED_STONE_BRICKS.getDefaultState(), 34, 8, 30, start);
        structure.setBlockState(world, Blocks.VINE.getDefaultState().with(VineBlock.UP, true).with(VineBlock.NORTH, true).with(VineBlock.SOUTH, true).with(VineBlock.EAST, false).with(VineBlock.WEST, false), 34, 8, 52, start);
        structure.setBlockState(world, Blocks.DIRT.getDefaultState(), 34, 9, 50, start);
        structure.setBlockState(world, Blocks.CRACKED_STONE_BRICKS.getDefaultState(), 34, 10, 52, start);
        structure.setBlockState(world, Blocks.MOSSY_COBBLESTONE.getDefaultState(), 34, 11, 35, start);
        structure.setBlockState(world, Blocks.BARREL.getDefaultState().with(BarrelBlock.PROPERTY_FACING, Direction.SOUTH).with(BarrelBlock.PROPERTY_OPEN, false), 34, 12, 36, start);
        structure.setBlockState(world, Blocks.MOSSY_COBBLESTONE.getDefaultState(), 34, 12, 51, start);
        structure.setBlockState(world, Blocks.COMPOSTER.getDefaultState().with(ComposterBlock.LEVEL, 0), 34, 13, 36, start);
        structure.setBlockState(world, Blocks.MOSSY_STONE_BRICKS.getDefaultState(), 34, 14, 34, start);
        structure.setBlockState(world, Blocks.BARREL.getDefaultState().with(BarrelBlock.PROPERTY_FACING, Direction.SOUTH).with(BarrelBlock.PROPERTY_OPEN, false), 34, 14, 36, start);
        structure.setBlockState(world, Blocks.OAK_SLAB.getDefaultState().with(SlabBlock.TYPE, SlabType.TOP).with(SlabBlock.WATERLOGGED, false), 34, 14, 50, start);
        structure.setBlockState(world, Blocks.STONE_BRICKS.getDefaultState(), 34, 15, 34, start);
        structure.setBlockState(world, Blocks.OAK_SLAB.getDefaultState().with(SlabBlock.TYPE, SlabType.BOTTOM).with(SlabBlock.WATERLOGGED, false), 34, 15, 36, start);
        structure.setBlockState(world, Blocks.COBWEB.getDefaultState(), 34, 16, 36, start);
        structure.setBlockState(world, Blocks.COBBLESTONE.getDefaultState(), 34, 16, 51, start);
        structure.setBlockState(world, Blocks.STONE_BRICKS.getDefaultState(), 34, 16, 52, start);
        structure.setBlockState(world, Blocks.MOSSY_COBBLESTONE.getDefaultState(), 34, 17, 36, start);
        structure.setBlockState(world, Blocks.STONE_BRICK_STAIRS.getDefaultState().with(StairsBlock.FACING, Direction.NORTH).with(StairsBlock.WATERLOGGED, false).with(StairsBlock.SHAPE, StairsShape.STRAIGHT).with(StairsBlock.HALF, Half.BOTTOM), 34, 17, 51, start);
        structure.setBlockState(world, Blocks.STONE_BRICK_STAIRS.getDefaultState().with(StairsBlock.FACING, Direction.SOUTH).with(StairsBlock.WATERLOGGED, false).with(StairsBlock.SHAPE, StairsShape.STRAIGHT).with(StairsBlock.HALF, Half.BOTTOM), 34, 18, 36, start);
        structure.setBlockState(world, Blocks.COBBLESTONE.getDefaultState(), 34, 18, 48, start);
        structure.setBlockState(world, Blocks.MOSSY_COBBLESTONE.getDefaultState(), 34, 18, 49, start);
        structure.setBlockState(world, Blocks.STONE_BRICKS.getDefaultState(), 34, 19, 37, start);
        structure.setBlockState(world, Blocks.CRACKED_STONE_BRICKS.getDefaultState(), 34, 19, 49, start);
        structure.setBlockState(world, Blocks.STONE_BRICK_STAIRS.getDefaultState().with(StairsBlock.FACING, Direction.NORTH).with(StairsBlock.WATERLOGGED, false).with(StairsBlock.SHAPE, StairsShape.STRAIGHT).with(StairsBlock.HALF, Half.BOTTOM), 34, 20, 49, start);
        structure.setBlockState(world, Blocks.DIRT.getDefaultState(), 35, 6, 19, start);
        structure.setBlockState(world, Blocks.DIRT.getDefaultState(), 35, 6, 71, start);
        structure.setBlockState(world, Blocks.MOSSY_STONE_BRICKS.getDefaultState(), 35, 7, 29, start);
        structure.setBlockState(world, Blocks.STONE_BRICKS.getDefaultState(), 35, 7, 32, start);
        structure.setBlockState(world, Blocks.VINE.getDefaultState().with(VineBlock.UP, false).with(VineBlock.NORTH, false).with(VineBlock.SOUTH, true).with(VineBlock.EAST, false).with(VineBlock.WEST, false), 35, 7, 52, start);
        structure.setBlockState(world, Blocks.GRASS.getDefaultState(), 35, 7, 60, start);
        structure.setBlockState(world, Blocks.GRASS.getDefaultState(), 35, 7, 64, start);
        structure.setBlockState(world, Blocks.CHISELED_STONE_BRICKS.getDefaultState(), 35, 8, 29, start);
        structure.setBlockState(world, Blocks.VINE.getDefaultState().with(VineBlock.UP, true).with(VineBlock.NORTH, false).with(VineBlock.SOUTH, true).with(VineBlock.EAST, false).with(VineBlock.WEST, false), 35, 8, 52, start);
        structure.setBlockState(world, Blocks.COBBLESTONE.getDefaultState(), 35, 8, 56, start);
        structure.setBlockState(world, Blocks.MOSSY_COBBLESTONE.getDefaultState(), 35, 9, 35, start);
        structure.setBlockState(world, Blocks.CRACKED_STONE_BRICKS.getDefaultState(), 35, 10, 36, start);
        structure.setBlockState(world, Blocks.MOSSY_STONE_BRICKS.getDefaultState(), 35, 10, 50, start);
        structure.setBlockState(world, Blocks.STONE_BRICKS.getDefaultState(), 35, 10, 51, start);
        structure.setBlockState(world, Blocks.MOSSY_STONE_BRICKS.getDefaultState(), 35, 12, 35, start);
        structure.setBlockState(world, Blocks.OAK_LEAVES.getDefaultState().with(LeavesBlock.PERSISTENT, false).with(LeavesBlock.DISTANCE, 1), 35, 12, 71, start);
        structure.setBlockState(world, Blocks.OAK_LEAVES.getDefaultState().with(LeavesBlock.PERSISTENT, false).with(LeavesBlock.DISTANCE, 2), 35, 12, 72, start);
        structure.setBlockState(world, Blocks.OAK_LEAVES.getDefaultState().with(LeavesBlock.PERSISTENT, false).with(LeavesBlock.DISTANCE, 1), 35, 13, 19, start);
        structure.setBlockState(world, Blocks.OAK_LEAVES.getDefaultState().with(LeavesBlock.PERSISTENT, false).with(LeavesBlock.DISTANCE, 2), 35, 13, 20, start);
        structure.setBlockState(world, Blocks.STONE_BRICKS.getDefaultState(), 35, 14, 35, start);
        structure.setBlockState(world, Blocks.STONE_BRICKS.getDefaultState(), 35, 14, 50, start);
        structure.setBlockState(world, Blocks.MOSSY_STONE_BRICKS.getDefaultState(), 35, 15, 50, start);
        structure.setBlockState(world, Blocks.LANTERN.getDefaultState().with(LanternBlock.WATERLOGGED, false).with(LanternBlock.HANGING, true), 35, 17, 43, start);
        structure.setBlockState(world, Blocks.COBBLESTONE.getDefaultState(), 35, 17, 51, start);
        structure.setBlockState(world, Blocks.COBBLESTONE_STAIRS.getDefaultState().with(StairsBlock.FACING, Direction.NORTH).with(StairsBlock.WATERLOGGED, false).with(StairsBlock.SHAPE, StairsShape.STRAIGHT).with(StairsBlock.HALF, Half.BOTTOM), 35, 18, 35, start);
        structure.setBlockState(world, Blocks.COBWEB.getDefaultState(), 35, 18, 37, start);
        structure.setBlockState(world, Blocks.COBWEB.getDefaultState(), 35, 18, 49, start);
        structure.setBlockState(world, Blocks.MOSSY_COBBLESTONE_STAIRS.getDefaultState().with(StairsBlock.FACING, Direction.NORTH).with(StairsBlock.WATERLOGGED, false).with(StairsBlock.SHAPE, StairsShape.STRAIGHT).with(StairsBlock.HALF, Half.BOTTOM), 35, 18, 51, start);
        structure.setBlockState(world, Blocks.COBWEB.getDefaultState(), 35, 19, 42, start);
        structure.setBlockState(world, Blocks.COBBLESTONE.getDefaultState(), 35, 19, 50, start);
        structure.setBlockState(world, Blocks.MOSSY_COBBLESTONE_STAIRS.getDefaultState().with(StairsBlock.FACING, Direction.NORTH).with(StairsBlock.WATERLOGGED, false).with(StairsBlock.SHAPE, StairsShape.STRAIGHT).with(StairsBlock.HALF, Half.BOTTOM), 35, 20, 36, start);
        structure.setBlockState(world, Blocks.MOSSY_COBBLESTONE_STAIRS.getDefaultState().with(StairsBlock.FACING, Direction.NORTH).with(StairsBlock.WATERLOGGED, false).with(StairsBlock.SHAPE, StairsShape.STRAIGHT).with(StairsBlock.HALF, Half.BOTTOM), 35, 20, 50, start);
        structure.setBlockState(world, Blocks.COBBLESTONE_SLAB.getDefaultState().with(SlabBlock.TYPE, SlabType.BOTTOM).with(SlabBlock.WATERLOGGED, false), 35, 21, 37, start);
        structure.setBlockState(world, Blocks.COBBLESTONE_STAIRS.getDefaultState().with(StairsBlock.FACING, Direction.NORTH).with(StairsBlock.WATERLOGGED, false).with(StairsBlock.SHAPE, StairsShape.STRAIGHT).with(StairsBlock.HALF, Half.BOTTOM), 35, 21, 38, start);
        structure.setBlockState(world, Blocks.MOSSY_COBBLESTONE.getDefaultState(), 35, 21, 42, start);
        structure.setBlockState(world, Blocks.MOSSY_COBBLESTONE.getDefaultState(), 35, 21, 45, start);
        structure.setBlockState(world, Blocks.MOSSY_COBBLESTONE_STAIRS.getDefaultState().with(StairsBlock.FACING, Direction.NORTH).with(StairsBlock.WATERLOGGED, false).with(StairsBlock.SHAPE, StairsShape.STRAIGHT).with(StairsBlock.HALF, Half.BOTTOM), 35, 21, 48, start);
        structure.setBlockState(world, Blocks.COBBLESTONE_SLAB.getDefaultState().with(SlabBlock.TYPE, SlabType.BOTTOM).with(SlabBlock.WATERLOGGED, false), 35, 21, 49, start);
        structure.setBlockState(world, Blocks.GRASS_BLOCK.getDefaultState().with(SnowyDirtBlock.SNOWY, false), 36, 5, 10, start);
        structure.setBlockState(world, Blocks.DIRT.getDefaultState(), 36, 6, 16, start);
        structure.setBlockState(world, Blocks.MOSSY_STONE_BRICKS.getDefaultState(), 36, 7, 24, start);
        structure.setBlockState(world, Blocks.CRACKED_STONE_BRICKS.getDefaultState(), 36, 7, 25, start);
        structure.setBlockState(world, Blocks.STONE_BRICKS.getDefaultState(), 36, 7, 26, start);
        structure.setBlockState(world, Blocks.VINE.getDefaultState().with(VineBlock.UP, false).with(VineBlock.NORTH, true).with(VineBlock.SOUTH, false).with(VineBlock.EAST, false).with(VineBlock.WEST, false), 36, 7, 34, start);
        structure.setBlockState(world, Blocks.STONE_BRICKS.getDefaultState(), 36, 7, 56, start);
        structure.setBlockState(world, Blocks.MOSSY_STONE_BRICKS.getDefaultState(), 36, 7, 57, start);
        structure.setBlockState(world, Blocks.MOSSY_STONE_BRICKS.getDefaultState(), 36, 7, 63, start);
        structure.setBlockState(world, Blocks.MOSSY_COBBLESTONE.getDefaultState(), 36, 8, 32, start);
        structure.setBlockState(world, Blocks.STONE_BRICK_STAIRS.getDefaultState().with(StairsBlock.FACING, Direction.EAST).with(StairsBlock.WATERLOGGED, false).with(StairsBlock.SHAPE, StairsShape.STRAIGHT).with(StairsBlock.HALF, Half.TOP), 36, 8, 52, start);
        structure.setBlockState(world, Blocks.MOSSY_COBBLESTONE.getDefaultState(), 36, 9, 34, start);
        structure.setBlockState(world, Blocks.STONE_BRICKS.getDefaultState(), 36, 10, 36, start);
        structure.setBlockState(world, Blocks.MOSSY_STONE_BRICKS.getDefaultState(), 36, 11, 36, start);
        structure.setBlockState(world, Blocks.MOSSY_STONE_BRICKS.getDefaultState(), 36, 11, 50, start);
        structure.setBlockState(world, Blocks.OAK_LEAVES.getDefaultState().with(LeavesBlock.PERSISTENT, false).with(LeavesBlock.DISTANCE, 2), 36, 12, 71, start);
        structure.setBlockState(world, Blocks.OAK_LEAVES.getDefaultState().with(LeavesBlock.PERSISTENT, false).with(LeavesBlock.DISTANCE, 1), 36, 13, 16, start);
        structure.setBlockState(world, Blocks.OAK_LEAVES.getDefaultState().with(LeavesBlock.PERSISTENT, false).with(LeavesBlock.DISTANCE, 2), 36, 13, 17, start);
        structure.setBlockState(world, Blocks.OAK_LEAVES.getDefaultState().with(LeavesBlock.PERSISTENT, false).with(LeavesBlock.DISTANCE, 2), 36, 13, 19, start);
        structure.setBlockState(world, Blocks.CRACKED_STONE_BRICKS.getDefaultState(), 36, 13, 36, start);
        structure.setBlockState(world, Blocks.MOSSY_STONE_BRICKS.getDefaultState(), 36, 15, 35, start);
        structure.setBlockState(world, Blocks.STONE_BRICKS.getDefaultState(), 36, 16, 35, start);
        structure.setBlockState(world, Blocks.MOSSY_STONE_BRICKS.getDefaultState(), 36, 16, 36, start);
        structure.setBlockState(world, Blocks.CRACKED_STONE_BRICKS.getDefaultState(), 36, 16, 50, start);
        structure.setBlockState(world, Blocks.MOSSY_STONE_BRICKS.getDefaultState(), 36, 16, 51, start);
        structure.setBlockState(world, Blocks.MOSSY_COBBLESTONE.getDefaultState(), 36, 17, 51, start);
        structure.setBlockState(world, Blocks.MOSSY_COBBLESTONE.getDefaultState(), 36, 20, 43, start);
        structure.setBlockState(world, Blocks.GRASS.getDefaultState(), 37, 7, 30, start);
        structure.setBlockState(world, Blocks.STONE_BRICKS.getDefaultState(), 37, 7, 31, start);
        structure.setBlockState(world, Blocks.GRASS.getDefaultState(), 37, 7, 76, start);
        structure.setBlockState(world, Blocks.STONE_BRICK_STAIRS.getDefaultState().with(StairsBlock.FACING, Direction.EAST).with(StairsBlock.WATERLOGGED, false).with(StairsBlock.SHAPE, StairsShape.STRAIGHT).with(StairsBlock.HALF, Half.TOP), 37, 8, 34, start);
        structure.setBlockState(world, Blocks.STONE_BRICK_STAIRS.getDefaultState().with(StairsBlock.FACING, Direction.SOUTH).with(StairsBlock.WATERLOGGED, false).with(StairsBlock.SHAPE, StairsShape.STRAIGHT).with(StairsBlock.HALF, Half.TOP), 37, 8, 51, start);
        structure.setBlockState(world, Blocks.MOSSY_COBBLESTONE.getDefaultState(), 37, 8, 53, start);
        structure.setBlockState(world, Blocks.COBBLESTONE.getDefaultState(), 37, 8, 58, start);
        structure.setBlockState(world, Blocks.MOSSY_COBBLESTONE.getDefaultState(), 37, 8, 59, start);
        structure.setBlockState(world, Blocks.OAK_LEAVES.getDefaultState().with(LeavesBlock.PERSISTENT, false).with(LeavesBlock.DISTANCE, 4), 37, 8, 74, start);
        structure.setBlockState(world, Blocks.OAK_LEAVES.getDefaultState().with(LeavesBlock.PERSISTENT, false).with(LeavesBlock.DISTANCE, 4), 37, 8, 78, start);
        structure.setBlockState(world, Blocks.OAK_LEAVES.getDefaultState().with(LeavesBlock.PERSISTENT, false).with(LeavesBlock.DISTANCE, 3), 37, 9, 15, start);
        structure.setBlockState(world, Blocks.AIR.getDefaultState(), 37, 9, 33, start);
        structure.setBlockState(world, Blocks.AIR.getDefaultState(), 37, 9, 53, start);
        structure.setBlockState(world, Blocks.AIR.getDefaultState(), 37, 9, 62, start);
        structure.setBlockState(world, Index.BENCH_OAK.getDefaultState().with(Bench.STATE, BenchState.SOUTH), 37, 10, 41, start);
        structure.setBlockState(world, Index.BENCH_OAK.getDefaultState().with(Bench.STATE, BenchState.NORTH), 37, 10, 45, start);
        structure.setBlockState(world, Blocks.OAK_LEAVES.getDefaultState().with(LeavesBlock.PERSISTENT, false).with(LeavesBlock.DISTANCE, 4), 37, 10, 73, start);
        structure.setBlockState(world, Blocks.STONE_BRICKS.getDefaultState(), 37, 12, 51, start);
        structure.setBlockState(world, Blocks.OAK_LEAVES.getDefaultState().with(LeavesBlock.PERSISTENT, false).with(LeavesBlock.DISTANCE, 2), 37, 13, 16, start);
        structure.setBlockState(world, Blocks.CRACKED_STONE_BRICKS.getDefaultState(), 37, 13, 51, start);
        structure.setBlockState(world, Blocks.MOSSY_STONE_BRICKS.getDefaultState(), 37, 14, 35, start);
        structure.setBlockState(world, Blocks.STONE_BRICKS.getDefaultState(), 37, 15, 35, start);
        structure.setBlockState(world, Blocks.MOSSY_STONE_BRICKS.getDefaultState(), 37, 16, 50, start);
        structure.setBlockState(world, Blocks.STONE_BRICKS.getDefaultState(), 37, 16, 51, start);
        structure.setBlockState(world, Blocks.MOSSY_COBBLESTONE.getDefaultState(), 37, 17, 36, start);
        structure.setBlockState(world, Blocks.MOSSY_COBBLESTONE.getDefaultState(), 37, 18, 50, start);
        structure.setBlockState(world, Blocks.MOSSY_COBBLESTONE_STAIRS.getDefaultState().with(StairsBlock.FACING, Direction.SOUTH).with(StairsBlock.WATERLOGGED, false).with(StairsBlock.SHAPE, StairsShape.OUTER_LEFT).with(StairsBlock.HALF, Half.BOTTOM), 37, 22, 41, start);
        structure.setBlockState(world, Blocks.MOSSY_COBBLESTONE_STAIRS.getDefaultState().with(StairsBlock.FACING, Direction.SOUTH).with(StairsBlock.WATERLOGGED, false).with(StairsBlock.SHAPE, StairsShape.OUTER_LEFT).with(StairsBlock.HALF, Half.BOTTOM), 37, 25, 41, start);
        structure.setBlockState(world, Blocks.MOSSY_COBBLESTONE_STAIRS.getDefaultState().with(StairsBlock.FACING, Direction.EAST).with(StairsBlock.WATERLOGGED, false).with(StairsBlock.SHAPE, StairsShape.STRAIGHT).with(StairsBlock.HALF, Half.BOTTOM), 37, 28, 43, start);
        structure.setBlockState(world, Blocks.COBBLESTONE_STAIRS.getDefaultState().with(StairsBlock.FACING, Direction.EAST).with(StairsBlock.WATERLOGGED, false).with(StairsBlock.SHAPE, StairsShape.STRAIGHT).with(StairsBlock.HALF, Half.BOTTOM), 37, 28, 44, start);
        structure.setBlockState(world, Blocks.COBBLESTONE_STAIRS.getDefaultState().with(StairsBlock.FACING, Direction.NORTH).with(StairsBlock.WATERLOGGED, false).with(StairsBlock.SHAPE, StairsShape.OUTER_RIGHT).with(StairsBlock.HALF, Half.BOTTOM), 37, 28, 45, start);
        structure.setBlockState(world, Blocks.MOSSY_COBBLESTONE_STAIRS.getDefaultState().with(StairsBlock.FACING, Direction.SOUTH).with(StairsBlock.WATERLOGGED, false).with(StairsBlock.SHAPE, StairsShape.OUTER_LEFT).with(StairsBlock.HALF, Half.BOTTOM), 37, 31, 41, start);
        structure.setBlockState(world, Blocks.MOSSY_COBBLESTONE_STAIRS.getDefaultState().with(StairsBlock.FACING, Direction.EAST).with(StairsBlock.WATERLOGGED, false).with(StairsBlock.SHAPE, StairsShape.STRAIGHT).with(StairsBlock.HALF, Half.BOTTOM), 37, 31, 44, start);
        structure.setBlockState(world, Blocks.MOSSY_COBBLESTONE_STAIRS.getDefaultState().with(StairsBlock.FACING, Direction.NORTH).with(StairsBlock.WATERLOGGED, false).with(StairsBlock.SHAPE, StairsShape.OUTER_RIGHT).with(StairsBlock.HALF, Half.BOTTOM), 37, 31, 45, start);
        structure.setBlockState(world, Blocks.GRASS_BLOCK.getDefaultState().with(SnowyDirtBlock.SNOWY, false), 38, 6, 35, start);
        structure.setBlockState(world, Blocks.GRASS_BLOCK.getDefaultState().with(SnowyDirtBlock.SNOWY, false), 38, 6, 45, start);
        structure.setBlockState(world, Blocks.GRASS.getDefaultState(), 38, 7, 12, start);
        structure.setBlockState(world, Blocks.GRASS.getDefaultState(), 38, 7, 29, start);
        structure.setBlockState(world, Blocks.COBWEB.getDefaultState(), 38, 7, 35, start);
        structure.setBlockState(world, Blocks.VINE.getDefaultState().with(VineBlock.UP, false).with(VineBlock.NORTH, false).with(VineBlock.SOUTH, false).with(VineBlock.EAST, true).with(VineBlock.WEST, false), 38, 7, 45, start);
        structure.setBlockState(world, Blocks.STONE_BRICK_STAIRS.getDefaultState().with(StairsBlock.FACING, Direction.NORTH).with(StairsBlock.WATERLOGGED, false).with(StairsBlock.SHAPE, StairsShape.STRAIGHT).with(StairsBlock.HALF, Half.TOP), 38, 8, 35, start);
        structure.setBlockState(world, Blocks.COBWEB.getDefaultState(), 38, 8, 40, start);
        structure.setBlockState(world, Blocks.VINE.getDefaultState().with(VineBlock.UP, true).with(VineBlock.NORTH, false).with(VineBlock.SOUTH, false).with(VineBlock.EAST, true).with(VineBlock.WEST, false), 38, 8, 41, start);
        structure.setBlockState(world, Blocks.VINE.getDefaultState().with(VineBlock.UP, false).with(VineBlock.NORTH, false).with(VineBlock.SOUTH, false).with(VineBlock.EAST, true).with(VineBlock.WEST, false), 38, 8, 42, start);
        structure.setBlockState(world, Blocks.COBWEB.getDefaultState(), 38, 8, 44, start);
        structure.setBlockState(world, Blocks.VINE.getDefaultState().with(VineBlock.UP, true).with(VineBlock.NORTH, false).with(VineBlock.SOUTH, false).with(VineBlock.EAST, true).with(VineBlock.WEST, false), 38, 8, 45, start);
        structure.setBlockState(world, Blocks.STONE_BRICK_STAIRS.getDefaultState().with(StairsBlock.FACING, Direction.EAST).with(StairsBlock.WATERLOGGED, false).with(StairsBlock.SHAPE, StairsShape.STRAIGHT).with(StairsBlock.HALF, Half.TOP), 38, 8, 46, start);
        structure.setBlockState(world, Blocks.STONE_BRICK_STAIRS.getDefaultState().with(StairsBlock.FACING, Direction.WEST).with(StairsBlock.WATERLOGGED, false).with(StairsBlock.SHAPE, StairsShape.STRAIGHT).with(StairsBlock.HALF, Half.TOP), 38, 8, 52, start);
        structure.setBlockState(world, Blocks.COBWEB.getDefaultState(), 38, 8, 54, start);
        structure.setBlockState(world, Blocks.STONE_BRICK_STAIRS.getDefaultState().with(StairsBlock.FACING, Direction.SOUTH).with(StairsBlock.WATERLOGGED, false).with(StairsBlock.SHAPE, StairsShape.STRAIGHT).with(StairsBlock.HALF, Half.TOP), 38, 8, 60, start);
        structure.setBlockState(world, Blocks.OAK_LEAVES.getDefaultState().with(LeavesBlock.PERSISTENT, false).with(LeavesBlock.DISTANCE, 4), 38, 9, 15, start);
        structure.setBlockState(world, Blocks.AIR.getDefaultState(), 38, 9, 24, start);
        structure.setBlockState(world, Blocks.MOSSY_COBBLESTONE.getDefaultState(), 38, 9, 27, start);
        structure.setBlockState(world, Blocks.MOSSY_COBBLESTONE.getDefaultState(), 38, 9, 35, start);
        structure.setBlockState(world, Blocks.CRAFTING_TABLE.getDefaultState(), 38, 10, 36, start);
        structure.setBlockState(world, Blocks.AIR.getDefaultState(), 38, 10, 40, start);
        structure.setBlockState(world, Index.TABLE_OAK.getDefaultState().with(Table.NE, true).with(Table.NW, true).with(Table.SE, false).with(Table.SW, false), 38, 10, 41, start);
        structure.setBlockState(world, Index.TABLE_OAK.getDefaultState().with(Table.NE, false).with(Table.NW, false).with(Table.SE, true).with(Table.SW, true), 38, 10, 45, start);
