package mod.arcalitegames.odyssey.world.structure.structures.ruins.ancient_ruins;

import mod.arcalitegames.odyssey.world.structure.StructureBase;
import net.minecraft.block.Blocks;
import net.minecraft.block.SnowyDirtBlock;
import net.minecraft.block.StairsBlock;
import net.minecraft.block.WallBlock;
import net.minecraft.block.WallHeight;
import net.minecraft.state.properties.Half;
import net.minecraft.state.properties.StairsShape;
import net.minecraft.util.Direction;
import net.minecraft.util.math.BlockPos;
import net.minecraft.world.World;

public class AncientComponent8
{
	public static BlockPos start;
    public static World world;
    public static StructureBase structure;

    public static void init(World worldIn, BlockPos blockPos, StructureBase structureIn)
    {
        world = worldIn; start = blockPos; structure = structureIn;
    }
	
    public static void generatePart81()
    {
        structure.fillWithBlocks(world, start, 68, -55, 43, 68, -54, 43, Blocks.AIR.getDefaultState());
        structure.fillWithBlocks(world, start, 68, -54, -23, 69, -54, -22, Blocks.STONE_BRICKS.getDefaultState());
        structure.fillWithBlocks(world, start, 68, -54, -21, 68, -54, -17, Blocks.AIR.getDefaultState());
        structure.fillWithBlocks(world, start, 68, -54, 36, 71, -54, 41, Blocks.STONE_BRICKS.getDefaultState());
        structure.fillWithBlocks(world, start, 68, -54, 42, 68, -54, 42, Blocks.STONE_BRICKS.getDefaultState());
        structure.fillWithBlocks(world, start, 68, -53, -21, 68, -53, -17, Blocks.AIR.getDefaultState());
        structure.fillWithBlocks(world, start, 68, -53, 36, 71, -53, 39, Blocks.STONE_BRICKS.getDefaultState());
        structure.fillWithBlocks(world, start, 68, -53, 40, 70, -53, 44, Blocks.STONE_BRICKS.getDefaultState());
        structure.fillWithBlocks(world, start, 68, -52, -21, 72, -52, -17, Blocks.STONE_BRICKS.getDefaultState());
        structure.fillWithBlocks(world, start, 68, -52, 36, 68, -49, 56, Blocks.STONE_BRICKS.getDefaultState());
        structure.fillWithBlocks(world, start, 68, -48, 36, 69, -48, 37, Blocks.STONE_BRICKS.getDefaultState());
        structure.fillWithBlocks(world, start, 68, -48, 39, 70, -48, 41, Blocks.STONE_BRICKS.getDefaultState());
        structure.fillWithBlocks(world, start, 68, -48, 42, 68, -48, 47, Blocks.STONE_BRICKS.getDefaultState());
        structure.fillWithBlocks(world, start, 68, -48, 49, 70, -48, 51, Blocks.STONE_BRICKS.getDefaultState());
        structure.fillWithBlocks(world, start, 68, -48, 52, 68, -47, 52, Blocks.AIR.getDefaultState());
        structure.fillWithBlocks(world, start, 68, -48, 53, 69, -48, 56, Blocks.STONE_BRICKS.getDefaultState());
        structure.fillWithBlocks(world, start, 68, -47, -24, 69, -47, -23, Blocks.STONE_BRICKS.getDefaultState());
        structure.fillWithBlocks(world, start, 68, -47, -14, 69, -47, -14, Blocks.STONE_BRICKS.getDefaultState());
        structure.fillWithBlocks(world, start, 68, -47, 36, 70, -47, 38, Blocks.STONE_BRICKS.getDefaultState());
        structure.fillWithBlocks(world, start, 68, -47, 39, 68, -47, 39, Blocks.STONE_BRICKS.getDefaultState());
        structure.fillWithBlocks(world, start, 68, -47, 42, 69, -47, 44, Blocks.STONE_BRICKS.getDefaultState());
        structure.fillWithBlocks(world, start, 68, -47, 45, 68, -47, 48, Blocks.STONE_BRICKS.getDefaultState());
        structure.fillWithBlocks(world, start, 68, -47, 49, 68, -47, 50, Blocks.MOSSY_STONE_BRICKS.getDefaultState());
        structure.fillWithBlocks(world, start, 68, -47, 53, 71, -47, 56, Blocks.STONE_BRICKS.getDefaultState());
        structure.fillWithBlocks(world, start, 68, -46, -27, 68, -46, -26, Blocks.STONE_BRICKS.getDefaultState());
        structure.fillWithBlocks(world, start, 68, -46, -21, 68, -46, -21, Blocks.STONE_BRICKS.getDefaultState());
        structure.fillWithBlocks(world, start, 68, -46, -18, 68, -46, -16, Blocks.MOSSY_STONE_BRICKS.getDefaultState());
        structure.fillWithBlocks(world, start, 68, -46, 13, 68, -44, 13, Blocks.STONE_BRICKS.getDefaultState());
        structure.fillWithBlocks(world, start, 68, -46, 15, 68, -45, 16, Blocks.STONE_BRICKS.getDefaultState());
        structure.fillWithBlocks(world, start, 68, -46, 17, 68, -46, 18, Blocks.STONE_BRICKS.getDefaultState());
        structure.fillWithBlocks(world, start, 68, -46, 29, 68, -46, 33, Blocks.STONE_BRICKS.getDefaultState());
        structure.fillWithBlocks(world, start, 68, -46, 34, 68, -46, 35, Blocks.MOSSY_STONE_BRICKS.getDefaultState());
        structure.fillWithBlocks(world, start, 68, -46, 38, 71, -46, 38, Blocks.STONE_BRICKS.getDefaultState());
        structure.fillWithBlocks(world, start, 68, -46, 39, 70, -46, 41, Blocks.AIR.getDefaultState());
        structure.fillWithBlocks(world, start, 68, -46, 43, 69, -46, 45, Blocks.STONE_BRICKS.getDefaultState());
        structure.fillWithBlocks(world, start, 68, -46, 47, 68, -46, 48, Blocks.STONE_BRICKS.getDefaultState());
        structure.fillWithBlocks(world, start, 68, -46, 49, 70, -46, 51, Blocks.AIR.getDefaultState());
        structure.fillWithBlocks(world, start, 68, -46, 52, 68, -45, 53, Blocks.STONE_BRICKS.getDefaultState());
        structure.fillWithBlocks(world, start, 68, -45, -21, 71, -45, -17, Blocks.AIR.getDefaultState());
        structure.fillWithBlocks(world, start, 68, -45, -11, 69, -45, -11, Blocks.MOSSY_STONE_BRICKS.getDefaultState());
        structure.fillWithBlocks(world, start, 68, -45, 12, 68, -44, 13, Blocks.STONE_BRICKS.getDefaultState());
        structure.fillWithBlocks(world, start, 68, -45, 14, 68, -45, 16, Blocks.STONE_BRICKS.getDefaultState());
        structure.fillWithBlocks(world, start, 68, -45, 21, 68, -45, 25, Blocks.AIR.getDefaultState());
        structure.fillWithBlocks(world, start, 68, -45, 26, 70, -45, 26, Blocks.STONE_BRICKS.getDefaultState());
        structure.fillWithBlocks(world, start, 68, -45, 28, 68, -43, 28, Blocks.STONE_BRICKS.getDefaultState());
        structure.fillWithBlocks(world, start, 68, -45, 31, 68, -42, 31, Blocks.STONE_BRICKS.getDefaultState());
        structure.fillWithBlocks(world, start, 68, -45, 32, 68, -42, 32, Blocks.MOSSY_STONE_BRICKS.getDefaultState());
        structure.fillWithBlocks(world, start, 68, -45, 33, 68, -44, 35, Blocks.STONE_BRICKS.getDefaultState());
        structure.fillWithBlocks(world, start, 68, -45, 39, 70, -45, 41, Blocks.AIR.getDefaultState());
        structure.fillWithBlocks(world, start, 68, -45, 42, 68, -43, 42, Blocks.STONE_BRICKS.getDefaultState());
        structure.fillWithBlocks(world, start, 68, -45, 48, 68, -44, 48, Blocks.STONE_BRICKS.getDefaultState());
        structure.fillWithBlocks(world, start, 68, -45, 49, 70, -45, 51, Blocks.AIR.getDefaultState());
        structure.fillWithBlocks(world, start, 68, -44, -27, 69, -44, -27, Blocks.MOSSY_STONE_BRICKS.getDefaultState());
        structure.fillWithBlocks(world, start, 68, -44, -11, 70, -42, -11, Blocks.STONE_BRICKS.getDefaultState());
        structure.fillWithBlocks(world, start, 68, -44, 11, 68, -44, 13, Blocks.STONE_BRICKS.getDefaultState());
        structure.fillWithBlocks(world, start, 68, -44, 15, 68, -44, 16, Blocks.MOSSY_STONE_BRICKS.getDefaultState());
        structure.fillWithBlocks(world, start, 68, -44, 17, 68, -43, 17, Blocks.STONE_BRICKS.getDefaultState());
        structure.fillWithBlocks(world, start, 68, -44, 19, 68, -44, 20, Blocks.STONE_BRICKS.getDefaultState());
        structure.fillWithBlocks(world, start, 68, -44, 21, 68, -44, 25, Blocks.AIR.getDefaultState());
        structure.fillWithBlocks(world, start, 68, -44, 29, 68, -44, 31, Blocks.STONE_BRICKS.getDefaultState());
        structure.fillWithBlocks(world, start, 68, -44, 37, 68, -43, 38, Blocks.STONE_BRICKS.getDefaultState());
        structure.fillWithBlocks(world, start, 68, -44, 39, 70, -44, 41, Blocks.AIR.getDefaultState());
        structure.fillWithBlocks(world, start, 68, -44, 49, 70, -44, 51, Blocks.AIR.getDefaultState());
        structure.fillWithBlocks(world, start, 68, -44, 52, 68, -44, 53, Blocks.STONE_BRICKS.getDefaultState());
        structure.fillWithBlocks(world, start, 68, -43, 11, 68, -42, 11, Blocks.MOSSY_COBBLESTONE.getDefaultState());
        structure.fillWithBlocks(world, start, 68, -43, 12, 68, -42, 12, Blocks.STONE_BRICKS.getDefaultState());
        structure.fillWithBlocks(world, start, 68, -43, 20, 68, -40, 20, Blocks.STONE_BRICKS.getDefaultState());
        structure.fillWithBlocks(world, start, 68, -43, 21, 68, -43, 25, Blocks.AIR.getDefaultState());
        structure.fillWithBlocks(world, start, 68, -43, 26, 68, -43, 28, Blocks.STONE_BRICKS.getDefaultState());
        structure.fillWithBlocks(world, start, 68, -43, 30, 68, -42, 31, Blocks.STONE_BRICKS.getDefaultState());
        structure.fillWithBlocks(world, start, 68, -43, 39, 70, -43, 41, Blocks.AIR.getDefaultState());
        structure.fillWithBlocks(world, start, 68, -43, 49, 70, -43, 51, Blocks.AIR.getDefaultState());
        structure.fillWithBlocks(world, start, 68, -43, 52, 68, -42, 52, Blocks.MOSSY_STONE_BRICKS.getDefaultState());
        structure.fillWithBlocks(world, start, 68, -42, 15, 68, -39, 15, Blocks.STONE_BRICKS.getDefaultState());
        structure.fillWithBlocks(world, start, 68, -42, 16, 68, -41, 16, Blocks.MOSSY_STONE_BRICKS.getDefaultState());
        structure.fillWithBlocks(world, start, 68, -42, 18, 68, -42, 26, Blocks.STONE_BRICKS.getDefaultState());
        structure.fillWithBlocks(world, start, 68, -42, 27, 68, -42, 28, Blocks.MOSSY_STONE_BRICKS.getDefaultState());
        structure.fillWithBlocks(world, start, 68, -42, 29, 68, -42, 31, Blocks.STONE_BRICKS.getDefaultState());
        structure.fillWithBlocks(world, start, 68, -42, 34, 68, -42, 35, Blocks.STONE_BRICKS.getDefaultState());
        structure.fillWithBlocks(world, start, 68, -42, 38, 68, -39, 38, Blocks.STONE_BRICKS.getDefaultState());
        structure.fillWithBlocks(world, start, 68, -42, 39, 70, -42, 41, Blocks.AIR.getDefaultState());
        structure.fillWithBlocks(world, start, 68, -42, 49, 70, -42, 51, Blocks.AIR.getDefaultState());
        structure.fillWithBlocks(world, start, 68, -42, 53, 69, -42, 53, Blocks.STONE_BRICKS.getDefaultState());
        structure.fillWithBlocks(world, start, 68, -41, -27, 68, -39, -27, Blocks.STONE_BRICKS.getDefaultState());
        structure.fillWithBlocks(world, start, 68, -41, -26, 69, -41, -26, Blocks.MOSSY_STONE_BRICKS.getDefaultState());
        structure.fillWithBlocks(world, start, 68, -41, -16, 68, -39, -16, Blocks.STONE_BRICKS.getDefaultState());
        structure.fillWithBlocks(world, start, 68, -41, -12, 68, -38, -12, Blocks.STONE_BRICKS.getDefaultState());
        structure.fillWithBlocks(world, start, 68, -41, 21, 68, -39, 21, Blocks.STONE_BRICKS.getDefaultState());
        structure.fillWithBlocks(world, start, 68, -41, 22, 68, -39, 22, Blocks.MOSSY_STONE_BRICKS.getDefaultState());
        structure.fillWithBlocks(world, start, 68, -41, 23, 68, -38, 23, Blocks.STONE_BRICKS.getDefaultState());
        structure.fillWithBlocks(world, start, 68, -41, 25, 68, -41, 28, Blocks.STONE_BRICKS.getDefaultState());
        structure.fillWithBlocks(world, start, 68, -41, 34, 68, -41, 35, Blocks.MOSSY_STONE_BRICKS.getDefaultState());
        structure.fillWithBlocks(world, start, 68, -41, 37, 68, -41, 39, Blocks.STONE_BRICKS.getDefaultState());
        structure.fillWithBlocks(world, start, 68, -41, 41, 68, -41, 42, Blocks.MOSSY_COBBLESTONE.getDefaultState());
        structure.fillWithBlocks(world, start, 68, -41, 46, 68, -41, 49, Blocks.STONE_BRICKS.getDefaultState());
        structure.fillWithBlocks(world, start, 68, -41, 51, 68, -41, 52, Blocks.STONE_BRICKS.getDefaultState());
        structure.fillWithBlocks(world, start, 68, -40, -26, 69, -40, -24, Blocks.STONE_BRICKS.getDefaultState());
        structure.fillWithBlocks(world, start, 68, -40, -23, 69, -40, -23, Blocks.MOSSY_STONE_BRICKS.getDefaultState());
        structure.fillWithBlocks(world, start, 68, -40, -21, 68, -40, -21, Blocks.STONE_BRICKS.getDefaultState());
        structure.fillWithBlocks(world, start, 68, -40, -19, 68, -40, -18, Blocks.STONE_BRICKS.getDefaultState());
        structure.fillWithBlocks(world, start, 68, -40, -13, 68, -40, -13, Blocks.MOSSY_COBBLESTONE.getDefaultState());
        structure.fillWithBlocks(world, start, 68, -40, 13, 68, -40, 18, Blocks.STONE_BRICKS.getDefaultState());
        structure.fillWithBlocks(world, start, 68, -40, 27, 68, -40, 31, Blocks.STONE_BRICKS.getDefaultState());
        structure.fillWithBlocks(world, start, 68, -40, 32, 68, -40, 33, Blocks.MOSSY_STONE_BRICKS.getDefaultState());
        structure.fillWithBlocks(world, start, 68, -40, 34, 68, -39, 35, Blocks.STONE_BRICKS.getDefaultState());
        structure.fillWithBlocks(world, start, 68, -40, 37, 68, -40, 40, Blocks.STONE_BRICKS.getDefaultState());
        structure.fillWithBlocks(world, start, 68, -40, 41, 68, -40, 41, Blocks.AIR.getDefaultState());
        structure.fillWithBlocks(world, start, 68, -40, 42, 68, -37, 42, Blocks.STONE_BRICKS.getDefaultState());
        structure.fillWithBlocks(world, start, 68, -40, 45, 68, -40, 45, Blocks.STONE_BRICKS.getDefaultState());
        structure.fillWithBlocks(world, start, 68, -40, 46, 68, -40, 47, Blocks.MOSSY_COBBLESTONE.getDefaultState());
        structure.fillWithBlocks(world, start, 68, -40, 49, 69, -40, 50, Blocks.STONE_BRICKS.getDefaultState());
        structure.fillWithBlocks(world, start, 68, -39, -24, 68, -39, -24, Blocks.MOSSY_STONE_BRICKS.getDefaultState());
        structure.fillWithBlocks(world, start, 68, -39, -23, 68, -37, -23, Blocks.STONE_BRICKS.getDefaultState());
        structure.fillWithBlocks(world, start, 68, -39, -22, 70, -39, -22, Blocks.MOSSY_STONE_BRICKS.getDefaultState());
        structure.fillWithBlocks(world, start, 68, -39, -20, 69, -39, -20, Blocks.AIR.getDefaultState());
        structure.fillWithBlocks(world, start, 68, -39, -18, 68, -39, -16, Blocks.STONE_BRICKS.getDefaultState());
        structure.fillWithBlocks(world, start, 68, -39, -14, 68, -38, -14, Blocks.STONE_BRICKS.getDefaultState());
        structure.fillWithBlocks(world, start, 68, -39, 12, 68, -38, 13, Blocks.STONE_BRICKS.getDefaultState());
        structure.fillWithBlocks(world, start, 68, -39, 14, 68, -37, 14, Blocks.MOSSY_STONE_BRICKS.getDefaultState());
        structure.fillWithBlocks(world, start, 68, -39, 17, 68, -38, 17, Blocks.MOSSY_STONE_BRICKS.getDefaultState());
        structure.fillWithBlocks(world, start, 68, -39, 20, 68, -38, 20, Blocks.MOSSY_COBBLESTONE.getDefaultState());
        structure.fillWithBlocks(world, start, 68, -39, 24, 68, -38, 24, Blocks.MOSSY_STONE_BRICKS.getDefaultState());
        structure.fillWithBlocks(world, start, 68, -39, 26, 68, -37, 26, Blocks.STONE_BRICKS.getDefaultState());
        structure.fillWithBlocks(world, start, 68, -39, 28, 68, -39, 30, Blocks.STONE_BRICKS.getDefaultState());
        structure.fillWithBlocks(world, start, 68, -39, 32, 68, -37, 32, Blocks.STONE_BRICKS.getDefaultState());
        structure.fillWithBlocks(world, start, 68, -39, 39, 68, -37, 39, Blocks.STONE_BRICKS.getDefaultState());
        structure.fillWithBlocks(world, start, 68, -39, 40, 68, -38, 40, Blocks.MOSSY_STONE_BRICKS.getDefaultState());
        structure.fillWithBlocks(world, start, 68, -39, 41, 68, -39, 42, Blocks.STONE_BRICKS.getDefaultState());
        structure.fillWithBlocks(world, start, 68, -39, 44, 68, -39, 46, Blocks.STONE_BRICKS.getDefaultState());
        structure.fillWithBlocks(world, start, 68, -39, 47, 68, -39, 47, Blocks.MOSSY_STONE_BRICKS.getDefaultState());
        structure.fillWithBlocks(world, start, 68, -39, 48, 68, -39, 50, Blocks.STONE_BRICKS.getDefaultState());
        structure.fillWithBlocks(world, start, 68, -39, 53, 70, -37, 53, Blocks.STONE_BRICKS.getDefaultState());
        structure.fillWithBlocks(world, start, 68, -38, -27, 68, -38, -26, Blocks.MOSSY_STONE_BRICKS.getDefaultState());
        structure.fillWithBlocks(world, start, 68, -38, -22, 68, -37, -22, Blocks.STONE_BRICKS.getDefaultState());
        structure.fillWithBlocks(world, start, 68, -38, -20, 68, -37, -20, Blocks.STONE_BRICKS.getDefaultState());
        structure.fillWithBlocks(world, start, 68, -38, -18, 68, -37, -18, Blocks.STONE_BRICKS.getDefaultState());
        structure.fillWithBlocks(world, start, 68, -38, -15, 69, -38, -11, Blocks.STONE_BRICKS.getDefaultState());
        structure.fillWithBlocks(world, start, 68, -38, 11, 68, -38, 13, Blocks.STONE_BRICKS.getDefaultState());
        structure.fillWithBlocks(world, start, 68, -38, 16, 68, -37, 16, Blocks.STONE_BRICKS.getDefaultState());
        structure.fillWithBlocks(world, start, 68, -38, 18, 68, -38, 19, Blocks.MOSSY_STONE_BRICKS.getDefaultState());
        structure.fillWithBlocks(world, start, 68, -38, 25, 68, -37, 28, Blocks.STONE_BRICKS.getDefaultState());
        structure.fillWithBlocks(world, start, 68, -38, 29, 68, -37, 29, Blocks.MOSSY_STONE_BRICKS.getDefaultState());
        structure.fillWithBlocks(world, start, 68, -38, 30, 68, -38, 32, Blocks.STONE_BRICKS.getDefaultState());
        structure.fillWithBlocks(world, start, 68, -38, 37, 68, -37, 37, Blocks.STONE_BRICKS.getDefaultState());
        structure.fillWithBlocks(world, start, 68, -38, 38, 68, -37, 38, Blocks.MOSSY_STONE_BRICKS.getDefaultState());
        structure.fillWithBlocks(world, start, 68, -38, 41, 68, -37, 41, Blocks.MOSSY_STONE_BRICKS.getDefaultState());
        structure.fillWithBlocks(world, start, 68, -38, 45, 68, -38, 46, Blocks.MOSSY_STONE_BRICKS.getDefaultState());
        structure.fillWithBlocks(world, start, 68, -38, 51, 69, -38, 53, Blocks.STONE_BRICKS.getDefaultState());
        structure.fillWithBlocks(world, start, 68, -37, -27, 68, -37, -27, Blocks.STONE_BRICKS.getDefaultState());
        structure.fillWithBlocks(world, start, 68, -37, -25, 68, -37, -20, Blocks.STONE_BRICKS.getDefaultState());
        structure.fillWithBlocks(world, start, 68, -37, -15, 68, -37, -15, Blocks.STONE_BRICKS.getDefaultState());
        structure.fillWithBlocks(world, start, 68, -37, -13, 69, -37, -13, Blocks.STONE_BRICKS.getDefaultState());
        structure.fillWithBlocks(world, start, 68, -37, 19, 68, -37, 22, Blocks.STONE_BRICKS.getDefaultState());
        structure.fillWithBlocks(world, start, 68, -37, 24, 68, -37, 28, Blocks.STONE_BRICKS.getDefaultState());
        structure.fillWithBlocks(world, start, 68, -37, 31, 68, -37, 35, Blocks.STONE_BRICKS.getDefaultState());
        structure.fillWithBlocks(world, start, 68, -37, 40, 68, -37, 40, Blocks.STONE_BRICKS.getDefaultState());
        structure.fillWithBlocks(world, start, 68, -37, 43, 69, -37, 43, Blocks.MOSSY_COBBLESTONE.getDefaultState());
        structure.fillWithBlocks(world, start, 68, -37, 44, 69, -37, 46, Blocks.STONE_BRICKS.getDefaultState());
        structure.fillWithBlocks(world, start, 68, -37, 49, 68, -37, 53, Blocks.STONE_BRICKS.getDefaultState());
        structure.fillWithBlocks(world, start, 68, -26, 12, 68, -26, 12, Blocks.STONE_BRICKS.getDefaultState());
        structure.fillWithBlocks(world, start, 68, -26, 13, 68, -25, 16, Blocks.CRACKED_STONE_BRICKS.getDefaultState());
        structure.fillWithBlocks(world, start, 68, -26, 17, 68, -26, 17, Blocks.STONE_BRICKS.getDefaultState());
        structure.fillWithBlocks(world, start, 68, -26, 31, 68, -25, 32, Blocks.STONE_BRICKS.getDefaultState());
        structure.fillWithBlocks(world, start, 68, -26, 33, 69, -26, 35, Blocks.STONE_BRICKS.getDefaultState());
        structure.fillWithBlocks(world, start, 68, -26, 39, 69, -26, 39, Blocks.CRACKED_STONE_BRICKS.getDefaultState());
        structure.fillWithBlocks(world, start, 68, -26, 40, 68, -26, 41, Blocks.STONE_BRICKS.getDefaultState());
        structure.fillWithBlocks(world, start, 68, -26, 43, 68, -26, 43, Blocks.CRACKED_STONE_BRICKS.getDefaultState());
        structure.fillWithBlocks(world, start, 68, -26, 45, 75, -26, 45, Blocks.STONE_BRICKS.getDefaultState());
        structure.fillWithBlocks(world, start, 68, -26, 46, 69, -26, 46, Blocks.MOSSY_STONE_BRICKS.getDefaultState());
        structure.fillWithBlocks(world, start, 68, -26, 47, 68, -26, 47, Blocks.STONE_BRICKS.getDefaultState());
        structure.fillWithBlocks(world, start, 68, -26, 49, 68, -25, 49, Blocks.STONE_BRICKS.getDefaultState());
        structure.fillWithBlocks(world, start, 68, -26, 50, 68, -25, 50, Blocks.MOSSY_STONE_BRICKS.getDefaultState());
        structure.fillWithBlocks(world, start, 68, -26, 71, 68, -26, 74, Blocks.STONE_BRICKS.getDefaultState());
        structure.fillWithBlocks(world, start, 68, -25, 11, 68, -25, 12, Blocks.STONE_BRICKS.getDefaultState());
        structure.fillWithBlocks(world, start, 68, -25, 17, 68, -24, 18, Blocks.STONE_BRICKS.getDefaultState());
        structure.fillWithBlocks(world, start, 68, -25, 33, 69, -25, 33, Blocks.CRACKED_STONE_BRICKS.getDefaultState());
        structure.fillWithBlocks(world, start, 68, -25, 70, 68, -25, 70, Blocks.STONE_BRICKS.getDefaultState());
        structure.fillWithBlocks(world, start, 68, -25, 71, 68, -25, 75, Blocks.AIR.getDefaultState());
        structure.fillWithBlocks(world, start, 68, -25, 76, 69, -24, 76, Blocks.STONE_BRICKS.getDefaultState());
        structure.fillWithBlocks(world, start, 68, -24, 11, 68, -23, 11, Blocks.CRACKED_STONE_BRICKS.getDefaultState());
        structure.fillWithBlocks(world, start, 68, -24, 12, 68, -24, 12, Blocks.STONE_BRICKS.getDefaultState());
        structure.fillWithBlocks(world, start, 68, -24, 13, 68, -24, 13, Blocks.CRACKED_STONE_BRICKS.getDefaultState());
        structure.fillWithBlocks(world, start, 68, -24, 14, 68, -24, 19, Blocks.STONE_BRICKS.getDefaultState());
        structure.fillWithBlocks(world, start, 68, -24, 31, 68, -24, 31, Blocks.STONE_BRICKS.getDefaultState());
        structure.fillWithBlocks(world, start, 68, -24, 32, 68, -24, 33, Blocks.MOSSY_STONE_BRICKS.getDefaultState());
        structure.fillWithBlocks(world, start, 68, -24, 50, 68, -22, 50, Blocks.CRACKED_STONE_BRICKS.getDefaultState());
        structure.fillWithBlocks(world, start, 68, -24, 51, 69, -24, 51, Blocks.MOSSY_STONE_BRICKS.getDefaultState());
        structure.fillWithBlocks(world, start, 68, -24, 70, 68, -24, 70, Blocks.STONE_BRICKS.getDefaultState());
        structure.fillWithBlocks(world, start, 68, -24, 71, 68, -24, 75, Blocks.AIR.getDefaultState());
        structure.fillWithBlocks(world, start, 68, -23, 12, 68, -22, 12, Blocks.STONE_BRICKS.getDefaultState());
        structure.fillWithBlocks(world, start, 68, -23, 14, 68, -22, 14, Blocks.CRACKED_STONE_BRICKS.getDefaultState());
        structure.fillWithBlocks(world, start, 68, -23, 15, 68, -23, 17, Blocks.STONE_BRICKS.getDefaultState());
        structure.fillWithBlocks(world, start, 68, -23, 18, 68, -23, 19, Blocks.MOSSY_STONE_BRICKS.getDefaultState());
        structure.fillWithBlocks(world, start, 68, -23, 31, 68, -23, 32, Blocks.STONE_BRICKS.getDefaultState());
        structure.fillWithBlocks(world, start, 68, -23, 49, 68, -22, 49, Blocks.STONE_BRICKS.getDefaultState());
        structure.fillWithBlocks(world, start, 68, -23, 70, 69, -23, 70, Blocks.STONE_BRICKS.getDefaultState());
        structure.fillWithBlocks(world, start, 68, -23, 71, 68, -23, 75, Blocks.AIR.getDefaultState());
        structure.fillWithBlocks(world, start, 68, -23, 76, 71, -23, 76, Blocks.STONE_BRICKS.getDefaultState());
        structure.fillWithBlocks(world, start, 68, -22, 11, 68, -22, 13, Blocks.STONE_BRICKS.getDefaultState());
        structure.fillWithBlocks(world, start, 68, -22, 15, 68, -22, 15, Blocks.CRACKED_STONE_BRICKS.getDefaultState());
        structure.fillWithBlocks(world, start, 68, -22, 16, 68, -22, 19, Blocks.STONE_BRICKS.getDefaultState());
        structure.fillWithBlocks(world, start, 68, -22, 31, 69, -22, 32, Blocks.CRACKED_STONE_BRICKS.getDefaultState());
        structure.fillWithBlocks(world, start, 68, -22, 51, 69, -22, 51, Blocks.STONE_BRICKS.getDefaultState());
        structure.fillWithBlocks(world, start, 68, -22, 73, 68, -22, 75, Blocks.STONE_BRICKS.getDefaultState());
        structure.fillWithBlocks(world, start, 68, -21, 11, 71, -21, 11, Blocks.STONE_BRICKS.getDefaultState());
        structure.fillWithBlocks(world, start, 68, -21, 12, 69, -21, 12, Blocks.CRACKED_STONE_BRICKS.getDefaultState());
        structure.fillWithBlocks(world, start, 68, -21, 13, 69, -21, 14, Blocks.STONE_BRICKS.getDefaultState());
        structure.fillWithBlocks(world, start, 68, -21, 15, 68, -21, 16, Blocks.STONE_BRICKS.getDefaultState());
        structure.fillWithBlocks(world, start, 68, -21, 17, 68, -21, 18, Blocks.CRACKED_STONE_BRICKS.getDefaultState());
        structure.fillWithBlocks(world, start, 68, -21, 19, 70, -21, 19, Blocks.STONE_BRICKS.getDefaultState());
        structure.fillWithBlocks(world, start, 68, -21, 31, 68, -20, 32, Blocks.STONE_BRICKS.getDefaultState());
        structure.fillWithBlocks(world, start, 68, -21, 35, 69, -21, 35, Blocks.CRACKED_STONE_BRICKS.getDefaultState());
        structure.fillWithBlocks(world, start, 68, -21, 36, 68, -21, 36, Blocks.STONE_BRICKS.getDefaultState());
        structure.fillWithBlocks(world, start, 68, -21, 38, 70, -20, 38, Blocks.STONE_BRICKS.getDefaultState());
        structure.fillWithBlocks(world, start, 68, -21, 44, 68, -21, 45, Blocks.STONE_BRICKS.getDefaultState());
        structure.fillWithBlocks(world, start, 68, -21, 46, 68, -21, 46, Blocks.MOSSY_STONE_BRICKS.getDefaultState());
        structure.fillWithBlocks(world, start, 68, -21, 50, 68, -21, 51, Blocks.STONE_BRICKS.getDefaultState());
        structure.fillWithBlocks(world, start, 68, -20, 11, 68, -17, 11, Blocks.STONE_BRICKS.getDefaultState());
        structure.fillWithBlocks(world, start, 68, -20, 12, 68, -20, 13, Blocks.CRACKED_STONE_BRICKS.getDefaultState());
        structure.fillWithBlocks(world, start, 68, -20, 14, 68, -20, 14, Blocks.STONE_BRICKS.getDefaultState());
        structure.fillWithBlocks(world, start, 68, -20, 15, 68, -20, 17, Blocks.CRACKED_STONE_BRICKS.getDefaultState());
        structure.fillWithBlocks(world, start, 68, -20, 18, 68, -20, 18, Blocks.STONE_BRICKS.getDefaultState());
        structure.fillWithBlocks(world, start, 68, -20, 33, 68, -20, 34, Blocks.CRACKED_STONE_BRICKS.getDefaultState());
        structure.fillWithBlocks(world, start, 68, -20, 35, 68, -20, 36, Blocks.MOSSY_STONE_BRICKS.getDefaultState());
        structure.fillWithBlocks(world, start, 68, -20, 37, 69, -20, 38, Blocks.STONE_BRICKS.getDefaultState());
        structure.fillWithBlocks(world, start, 68, -20, 39, 68, -20, 40, Blocks.CRACKED_STONE_BRICKS.getDefaultState());
        structure.fillWithBlocks(world, start, 68, -20, 41, 68, -18, 41, Blocks.STONE_BRICKS.getDefaultState());
        structure.fillWithBlocks(world, start, 68, -20, 42, 68, -20, 44, Blocks.CRACKED_STONE_BRICKS.getDefaultState());
        structure.fillWithBlocks(world, start, 68, -20, 45, 68, -20, 48, Blocks.STONE_BRICKS.getDefaultState());
        structure.fillWithBlocks(world, start, 68, -20, 50, 68, -20, 50, Blocks.STONE_BRICKS.getDefaultState());
        structure.fillWithBlocks(world, start, 68, -20, 51, 68, -19, 51, Blocks.CRACKED_STONE_BRICKS.getDefaultState());
        structure.fillWithBlocks(world, start, 68, -19, 13, 69, -19, 13, Blocks.CRACKED_STONE_BRICKS.getDefaultState());
        structure.fillWithBlocks(world, start, 68, -19, 14, 68, -19, 14, Blocks.STONE_BRICKS.getDefaultState());
        structure.fillWithBlocks(world, start, 68, -19, 16, 68, -19, 16, Blocks.STONE_BRICKS.getDefaultState());
        structure.fillWithBlocks(world, start, 68, -19, 17, 68, -19, 19, Blocks.MOSSY_STONE_BRICKS.getDefaultState());
        structure.fillWithBlocks(world, start, 68, -19, 31, 68, -19, 32, Blocks.STONE_BRICKS.getDefaultState());
        structure.fillWithBlocks(world, start, 68, -19, 33, 69, -19, 33, Blocks.CRACKED_STONE_BRICKS.getDefaultState());
        structure.fillWithBlocks(world, start, 68, -19, 35, 68, -19, 35, Blocks.MOSSY_STONE_BRICKS.getDefaultState());
        structure.fillWithBlocks(world, start, 68, -19, 36, 68, -19, 37, Blocks.CRACKED_STONE_BRICKS.getDefaultState());
        structure.fillWithBlocks(world, start, 68, -19, 38, 68, -19, 39, Blocks.MOSSY_STONE_BRICKS.getDefaultState());
        structure.fillWithBlocks(world, start, 68, -19, 40, 68, -18, 41, Blocks.STONE_BRICKS.getDefaultState());
        structure.fillWithBlocks(world, start, 68, -19, 42, 68, -19, 43, Blocks.STONE_BRICKS.getDefaultState());
        structure.fillWithBlocks(world, start, 68, -19, 44, 68, -19, 45, Blocks.AIR.getDefaultState());
        structure.fillWithBlocks(world, start, 68, -19, 49, 68, -19, 50, Blocks.STONE_BRICKS.getDefaultState());
        structure.fillWithBlocks(world, start, 68, -18, 12, 69, -18, 13, Blocks.STONE_BRICKS.getDefaultState());
        structure.fillWithBlocks(world, start, 68, -18, 14, 69, -18, 14, Blocks.CRACKED_STONE_BRICKS.getDefaultState());
        structure.fillWithBlocks(world, start, 68, -18, 15, 69, -18, 16, Blocks.STONE_BRICKS.getDefaultState());
        structure.fillWithBlocks(world, start, 68, -18, 18, 69, -18, 18, Blocks.CRACKED_STONE_BRICKS.getDefaultState());
        structure.fillWithBlocks(world, start, 68, -18, 19, 69, -18, 19, Blocks.STONE_BRICKS.getDefaultState());
        structure.fillWithBlocks(world, start, 68, -18, 32, 68, -18, 32, Blocks.STONE_BRICKS.getDefaultState());
        structure.fillWithBlocks(world, start, 68, -18, 33, 68, -18, 34, Blocks.CRACKED_STONE_BRICKS.getDefaultState());
        structure.fillWithBlocks(world, start, 68, -18, 35, 68, -18, 41, Blocks.STONE_BRICKS.getDefaultState());
        structure.fillWithBlocks(world, start, 68, -18, 42, 68, -18, 43, Blocks.CRACKED_STONE_BRICKS.getDefaultState());
        structure.fillWithBlocks(world, start, 68, -18, 44, 69, -18, 44, Blocks.MOSSY_STONE_BRICKS.getDefaultState());
        structure.fillWithBlocks(world, start, 68, -18, 47, 69, -18, 48, Blocks.STONE_BRICKS.getDefaultState());
        structure.fillWithBlocks(world, start, 68, -18, 51, 69, -17, 51, Blocks.STONE_BRICKS.getDefaultState());
        structure.fillWithBlocks(world, start, 68, -17, 12, 76, -17, 12, Blocks.STONE_BRICKS.getDefaultState());
        structure.fillWithBlocks(world, start, 68, -17, 14, 68, -17, 16, Blocks.STONE_BRICKS.getDefaultState());
        structure.fillWithBlocks(world, start, 68, -17, 17, 68, -17, 18, Blocks.CRACKED_STONE_BRICKS.getDefaultState());
        structure.fillWithBlocks(world, start, 68, -17, 33, 69, -17, 34, Blocks.STONE_BRICKS.getDefaultState());
        structure.fillWithBlocks(world, start, 68, -17, 36, 70, -17, 36, Blocks.CRACKED_STONE_BRICKS.getDefaultState());
        structure.fillWithBlocks(world, start, 68, -17, 37, 68, -17, 37, Blocks.STONE_BRICKS.getDefaultState());
        structure.fillWithBlocks(world, start, 68, -17, 40, 68, -17, 41, Blocks.CRACKED_STONE_BRICKS.getDefaultState());
        structure.fillWithBlocks(world, start, 68, -17, 42, 68, -16, 42, Blocks.STONE_BRICKS.getDefaultState());
        structure.fillWithBlocks(world, start, 68, -17, 43, 68, -17, 43, Blocks.CRACKED_STONE_BRICKS.getDefaultState());
        structure.fillWithBlocks(world, start, 68, -17, 44, 68, -17, 46, Blocks.STONE_BRICKS.getDefaultState());
        structure.fillWithBlocks(world, start, 68, -17, 47, 69, -17, 47, Blocks.CRACKED_STONE_BRICKS.getDefaultState());
        structure.fillWithBlocks(world, start, 68, -17, 48, 68, -17, 49, Blocks.STONE_BRICKS.getDefaultState());
        structure.fillWithBlocks(world, start, 68, -16, 43, 85, -16, 43, Blocks.STONE_BRICKS.getDefaultState());
        structure.fillWithBlocks(world, start, 68, -15, 39, 68, -15, 43, Blocks.AIR.getDefaultState());
        structure.fillWithBlocks(world, start, 68, -14, 38, 68, -14, 38, Blocks.STONE_BRICKS.getDefaultState());
        structure.fillWithBlocks(world, start, 68, -14, 39, 68, -14, 43, Blocks.AIR.getDefaultState());
        structure.fillWithBlocks(world, start, 68, -13, 39, 68, -13, 43, Blocks.AIR.getDefaultState());
        structure.fillWithBlocks(world, start, 68, -12, 39, 68, -12, 43, Blocks.STONE_BRICKS.getDefaultState());
        structure.fillWithBlocks(world, start, 68, 0, 12, 68, 0, 13, Blocks.GRASS_BLOCK.getDefaultState().with(SnowyDirtBlock.SNOWY, false));
        structure.fillWithBlocks(world, start, 68, 0, 14, 68, 0, 15, Blocks.DIRT.getDefaultState());
        structure.fillWithBlocks(world, start, 68, 0, 16, 68, 0, 65, Blocks.STONE.getDefaultState());
        structure.fillWithBlocks(world, start, 68, 1, 14, 68, 1, 14, Blocks.GRASS_BLOCK.getDefaultState().with(SnowyDirtBlock.SNOWY, false));
        structure.fillWithBlocks(world, start, 68, 1, 15, 68, 1, 21, Blocks.DIRT.getDefaultState());
        structure.fillWithBlocks(world, start, 68, 1, 22, 68, 2, 27, Blocks.STONE.getDefaultState());
        structure.fillWithBlocks(world, start, 68, 1, 28, 71, 1, 59, Blocks.STONE.getDefaultState());
        structure.fillWithBlocks(world, start, 68, 1, 61, 70, 1, 64, Blocks.DIRT.getDefaultState());
        structure.fillWithBlocks(world, start, 68, 2, 15, 68, 2, 15, Blocks.GRASS_BLOCK.getDefaultState().with(SnowyDirtBlock.SNOWY, false));
        structure.fillWithBlocks(world, start, 68, 2, 16, 68, 2, 21, Blocks.DIRT.getDefaultState());
        structure.fillWithBlocks(world, start, 68, 2, 28, 75, 2, 52, Blocks.DIRT.getDefaultState());
        structure.fillWithBlocks(world, start, 68, 2, 53, 68, 5, 53, Blocks.DIRT.getDefaultState());
        structure.fillWithBlocks(world, start, 68, 2, 61, 69, 2, 64, Blocks.DIRT.getDefaultState());
        structure.fillWithBlocks(world, start, 68, 3, 16, 68, 3, 17, Blocks.GRASS_BLOCK.getDefaultState().with(SnowyDirtBlock.SNOWY, false));
        structure.fillWithBlocks(world, start, 68, 3, 18, 68, 3, 63, Blocks.DIRT.getDefaultState());
        structure.fillWithBlocks(world, start, 68, 3, 64, 68, 3, 65, Blocks.GRASS_BLOCK.getDefaultState().with(SnowyDirtBlock.SNOWY, false));
        structure.fillWithBlocks(world, start, 68, 4, 18, 68, 4, 18, Blocks.GRASS_BLOCK.getDefaultState().with(SnowyDirtBlock.SNOWY, false));
        structure.fillWithBlocks(world, start, 68, 4, 19, 68, 4, 62, Blocks.DIRT.getDefaultState());
        structure.fillWithBlocks(world, start, 68, 5, 19, 68, 5, 22, Blocks.GRASS_BLOCK.getDefaultState().with(SnowyDirtBlock.SNOWY, false));
        structure.fillWithBlocks(world, start, 68, 5, 23, 68, 5, 58, Blocks.DIRT.getDefaultState());
        structure.fillWithBlocks(world, start, 68, 5, 59, 69, 5, 60, Blocks.GRASS_BLOCK.getDefaultState().with(SnowyDirtBlock.SNOWY, false));
        structure.fillWithBlocks(world, start, 68, 7, 30, 68, 7, 30, Blocks.GRASS.getDefaultState());
        structure.fillWithBlocks(world, start, 68, 7, 42, 68, 7, 42, Blocks.GRASS.getDefaultState());
        structure.fillWithBlocks(world, start, 68, 7, 50, 69, 7, 50, Blocks.GRASS.getDefaultState());
        structure.fillWithBlocks(world, start, 69, -56, -22, 74, -56, -17, Blocks.STONE_BRICKS.getDefaultState());
        structure.fillWithBlocks(world, start, 69, -56, 56, 76, -52, 56, Blocks.STONE_BRICKS.getDefaultState());
        structure.fillWithBlocks(world, start, 69, -55, -23, 70, -55, -22, Blocks.STONE_BRICKS.getDefaultState());
        structure.fillWithBlocks(world, start, 69, -55, -21, 69, -52, -21, Blocks.STONE_BRICKS.getDefaultState());
        structure.fillWithBlocks(world, start, 69, -55, -17, 69, -55, -16, Blocks.STONE_BRICKS.getDefaultState());
        structure.fillWithBlocks(world, start, 69, -55, 39, 69, -55, 39, Blocks.STONE_BRICKS.getDefaultState());
        structure.fillWithBlocks(world, start, 69, -55, 41, 70, -55, 44, Blocks.STONE_BRICKS.getDefaultState());
        structure.fillWithBlocks(world, start, 69, -55, 45, 71, -55, 47, Blocks.AIR.getDefaultState());
        structure.fillWithBlocks(world, start, 69, -54, -17, 69, -54, -16, Blocks.STONE_BRICKS.getDefaultState());
        structure.fillWithBlocks(world, start, 69, -54, 42, 70, -54, 44, Blocks.STONE_BRICKS.getDefaultState());
        structure.fillWithBlocks(world, start, 69, -54, 45, 71, -54, 47, Blocks.AIR.getDefaultState());
        structure.fillWithBlocks(world, start, 69, -53, -17, 69, -53, -16, Blocks.STONE_BRICKS.getDefaultState());
        structure.fillWithBlocks(world, start, 69, -53, 45, 71, -53, 47, Blocks.AIR.getDefaultState());
        structure.fillWithBlocks(world, start, 69, -52, 36, 69, -52, 36, Blocks.STONE_BRICKS.getDefaultState());
        structure.fillWithBlocks(world, start, 69, -52, 38, 70, -52, 39, Blocks.STONE_BRICKS.getDefaultState());
        structure.fillWithBlocks(world, start, 69, -52, 40, 69, -52, 52, Blocks.STONE_BRICKS.getDefaultState());
        structure.fillWithBlocks(world, start, 69, -52, 54, 71, -52, 56, Blocks.STONE_BRICKS.getDefaultState());
        structure.fillWithBlocks(world, start, 69, -51, 36, 73, -51, 40, Blocks.STONE_BRICKS.getDefaultState());
        structure.fillWithBlocks(world, start, 69, -51, 42, 70, -51, 44, Blocks.STONE_BRICKS.getDefaultState());
        structure.fillWithBlocks(world, start, 69, -51, 45, 69, -51, 47, Blocks.STONE_BRICKS.getDefaultState());
        structure.fillWithBlocks(world, start, 69, -51, 48, 70, -51, 48, Blocks.AIR.getDefaultState());
        structure.fillWithBlocks(world, start, 69, -51, 49, 71, -51, 51, Blocks.STONE_BRICKS.getDefaultState());
        structure.fillWithBlocks(world, start, 69, -51, 52, 69, -51, 55, Blocks.STONE_BRICKS.getDefaultState());
        structure.fillWithBlocks(world, start, 69, -51, 56, 69, -50, 56, Blocks.AIR.getDefaultState());
        structure.fillWithBlocks(world, start, 69, -50, 36, 70, -50, 55, Blocks.STONE_BRICKS.getDefaultState());
        structure.fillWithBlocks(world, start, 69, -49, 36, 70, -49, 37, Blocks.STONE_BRICKS.getDefaultState());
        structure.fillWithBlocks(world, start, 69, -49, 38, 69, -49, 48, Blocks.STONE_BRICKS.getDefaultState());
        structure.fillWithBlocks(world, start, 69, -49, 50, 69, -48, 56, Blocks.STONE_BRICKS.getDefaultState());
        structure.fillWithBlocks(world, start, 69, -48, 38, 70, -48, 41, Blocks.STONE_BRICKS.getDefaultState());
        structure.fillWithBlocks(world, start, 69, -48, 43, 73, -48, 47, Blocks.STONE_BRICKS.getDefaultState());
        structure.fillWithBlocks(world, start, 69, -48, 48, 69, -48, 56, Blocks.STONE_BRICKS.getDefaultState());
        structure.fillWithBlocks(world, start, 69, -47, -25, 69, -47, -23, Blocks.STONE_BRICKS.getDefaultState());
        structure.fillWithBlocks(world, start, 69, -47, -15, 69, -47, -14, Blocks.STONE_BRICKS.getDefaultState());
        structure.fillWithBlocks(world, start, 69, -47, 40, 70, -47, 41, Blocks.STONE_BRICKS.getDefaultState());
        structure.fillWithBlocks(world, start, 69, -47, 46, 71, -47, 48, Blocks.STONE_BRICKS.getDefaultState());
        structure.fillWithBlocks(world, start, 69, -47, 49, 69, -47, 49, Blocks.STONE_BRICKS.getDefaultState());
        structure.fillWithBlocks(world, start, 69, -46, -25, 71, -46, -23, Blocks.AIR.getDefaultState());
        structure.fillWithBlocks(world, start, 69, -46, -21, 70, -46, -18, Blocks.STONE_BRICKS.getDefaultState());
        structure.fillWithBlocks(world, start, 69, -46, -17, 69, -46, -16, Blocks.STONE_BRICKS.getDefaultState());
        structure.fillWithBlocks(world, start, 69, -46, -15, 71, -46, -13, Blocks.AIR.getDefaultState());
        structure.fillWithBlocks(world, start, 69, -46, -12, 69, -46, -12, Blocks.STONE_BRICKS.getDefaultState());
        structure.fillWithBlocks(world, start, 69, -46, 21, 69, -46, 22, Blocks.MOSSY_COBBLESTONE.getDefaultState());
        structure.fillWithBlocks(world, start, 69, -46, 37, 69, -46, 38, Blocks.STONE_BRICKS.getDefaultState());
        structure.fillWithBlocks(world, start, 69, -46, 47, 74, -46, 47, Blocks.STONE_BRICKS.getDefaultState());
        structure.fillWithBlocks(world, start, 69, -46, 48, 72, -46, 48, Blocks.MOSSY_STONE_BRICKS.getDefaultState());
        structure.fillWithBlocks(world, start, 69, -46, 52, 69, -46, 53, Blocks.MOSSY_STONE_BRICKS.getDefaultState());
        structure.fillWithBlocks(world, start, 69, -45, -27, 69, -45, -26, Blocks.MOSSY_STONE_BRICKS.getDefaultState());
        structure.fillWithBlocks(world, start, 69, -45, -25, 71, -45, -23, Blocks.AIR.getDefaultState());
        structure.fillWithBlocks(world, start, 69, -45, -22, 69, -44, -22, Blocks.STONE_BRICKS.getDefaultState());
        structure.fillWithBlocks(world, start, 69, -45, -16, 69, -44, -16, Blocks.STONE_BRICKS.getDefaultState());
        structure.fillWithBlocks(world, start, 69, -45, -15, 71, -45, -13, Blocks.AIR.getDefaultState());
        structure.fillWithBlocks(world, start, 69, -45, -12, 69, -43, -12, Blocks.STONE_BRICKS.getDefaultState());
        structure.fillWithBlocks(world, start, 69, -45, 22, 71, -45, 24, Blocks.AIR.getDefaultState());
        structure.fillWithBlocks(world, start, 69, -45, 42, 73, -45, 42, Blocks.STONE_BRICK_WALL.getDefaultState().with(WallBlock.WATERLOGGED, false).with(WallBlock.UP, false).with(WallBlock.WALL_HEIGHT_NORTH, WallHeight.LOW).with(WallBlock.WALL_HEIGHT_SOUTH, WallHeight.LOW).with(WallBlock.WALL_HEIGHT_EAST, WallHeight.LOW).with(WallBlock.WALL_HEIGHT_WEST, WallHeight.LOW));
        structure.fillWithBlocks(world, start, 69, -45, 43, 69, -45, 43, Blocks.AIR.getDefaultState());
        structure.fillWithBlocks(world, start, 69, -45, 47, 73, -41, 47, Blocks.AIR.getDefaultState());
        structure.fillWithBlocks(world, start, 69, -44, -25, 71, -44, -23, Blocks.AIR.getDefaultState());
        structure.fillWithBlocks(world, start, 69, -44, -21, 73, -44, -17, Blocks.AIR.getDefaultState());
        structure.fillWithBlocks(world, start, 69, -44, -15, 71, -44, -13, Blocks.AIR.getDefaultState());
        structure.fillWithBlocks(world, start, 69, -44, 22, 71, -44, 24, Blocks.AIR.getDefaultState());
        structure.fillWithBlocks(world, start, 69, -44, 25, 69, -43, 26, Blocks.STONE_BRICKS.getDefaultState());
        structure.fillWithBlocks(world, start, 69, -44, 38, 73, -44, 52, Blocks.AIR.getDefaultState());
        structure.fillWithBlocks(world, start, 69, -43, -26, 69, -42, -26, Blocks.STONE_BRICKS.getDefaultState());
        structure.fillWithBlocks(world, start, 69, -43, -25, 71, -43, -23, Blocks.AIR.getDefaultState());
        structure.fillWithBlocks(world, start, 69, -43, -21, 73, -43, -17, Blocks.AIR.getDefaultState());
        structure.fillWithBlocks(world, start, 69, -43, -16, 69, -41, -16, Blocks.MOSSY_STONE_BRICKS.getDefaultState());
        structure.fillWithBlocks(world, start, 69, -43, -15, 71, -43, -13, Blocks.AIR.getDefaultState());
        structure.fillWithBlocks(world, start, 69, -43, 21, 69, -42, 21, Blocks.STONE_BRICKS.getDefaultState());
        structure.fillWithBlocks(world, start, 69, -43, 22, 71, -43, 24, Blocks.AIR.getDefaultState());
        structure.fillWithBlocks(world, start, 69, -43, 38, 73, -43, 52, Blocks.AIR.getDefaultState());
        structure.fillWithBlocks(world, start, 69, -42, -27, 69, -42, -26, Blocks.STONE_BRICKS.getDefaultState());
        structure.fillWithBlocks(world, start, 69, -42, -25, 71, -42, -23, Blocks.AIR.getDefaultState());
        structure.fillWithBlocks(world, start, 69, -42, -22, 69, -40, -22, Blocks.STONE_BRICKS.getDefaultState());
        structure.fillWithBlocks(world, start, 69, -42, -15, 71, -42, -13, Blocks.AIR.getDefaultState());
        structure.fillWithBlocks(world, start, 69, -42, 22, 69, -42, 23, Blocks.STONE_BRICKS.getDefaultState());
        structure.fillWithBlocks(world, start, 69, -42, 24, 69, -42, 24, Blocks.MOSSY_COBBLESTONE.getDefaultState());
        structure.fillWithBlocks(world, start, 69, -42, 38, 73, -42, 52, Blocks.AIR.getDefaultState());
        structure.fillWithBlocks(world, start, 69, -41, -25, 69, -40, -24, Blocks.STONE_BRICKS.getDefaultState());
        structure.fillWithBlocks(world, start, 69, -41, -23, 69, -39, -23, Blocks.MOSSY_STONE_BRICKS.getDefaultState());
        structure.fillWithBlocks(world, start, 69, -41, -20, 69, -40, -19, Blocks.STONE_BRICKS.getDefaultState());
        structure.fillWithBlocks(world, start, 69, -41, -14, 69, -41, -13, Blocks.STONE_BRICKS.getDefaultState());
        structure.fillWithBlocks(world, start, 69, -41, -12, 69, -41, -12, Blocks.MOSSY_STONE_BRICKS.getDefaultState());
        structure.fillWithBlocks(world, start, 69, -41, 37, 69, -41, 37, Blocks.MOSSY_STONE_BRICKS.getDefaultState());
        structure.fillWithBlocks(world, start, 69, -41, 39, 71, -41, 41, Blocks.AIR.getDefaultState());
        structure.fillWithBlocks(world, start, 69, -41, 42, 72, -41, 42, Blocks.STONE_BRICKS.getDefaultState());
        structure.fillWithBlocks(world, start, 69, -41, 43, 73, -41, 47, Blocks.AIR.getDefaultState());
        structure.fillWithBlocks(world, start, 69, -41, 48, 71, -41, 48, Blocks.STONE_BRICKS.getDefaultState());
        structure.fillWithBlocks(world, start, 69, -41, 49, 71, -41, 51, Blocks.AIR.getDefaultState());
        structure.fillWithBlocks(world, start, 69, -40, -18, 70, -40, -18, Blocks.MOSSY_STONE_BRICKS.getDefaultState());
        structure.fillWithBlocks(world, start, 69, -40, -17, 69, -40, -16, Blocks.STONE_BRICKS.getDefaultState());
        structure.fillWithBlocks(world, start, 69, -40, -14, 70, -40, -14, Blocks.STONE_BRICKS.getDefaultState());
        structure.fillWithBlocks(world, start, 69, -40, -13, 69, -40, -12, Blocks.MOSSY_COBBLESTONE.getDefaultState());
        structure.fillWithBlocks(world, start, 69, -40, 37, 69, -39, 37, Blocks.STONE_BRICKS.getDefaultState());
        structure.fillWithBlocks(world, start, 69, -40, 39, 69, -40, 40, Blocks.MOSSY_STONE_BRICKS.getDefaultState());
        structure.fillWithBlocks(world, start, 69, -40, 41, 69, -40, 41, Blocks.STONE_BRICKS.getDefaultState());
        structure.fillWithBlocks(world, start, 69, -40, 43, 69, -39, 43, Blocks.MOSSY_STONE_BRICKS.getDefaultState());
        structure.fillWithBlocks(world, start, 69, -40, 44, 70, -40, 46, Blocks.STONE_BRICKS.getDefaultState());
        structure.fillWithBlocks(world, start, 69, -40, 47, 69, -40, 47, Blocks.MOSSY_STONE_BRICKS.getDefaultState());
        structure.fillWithBlocks(world, start, 69, -40, 48, 69, -40, 52, Blocks.STONE_BRICKS.getDefaultState());
        structure.fillWithBlocks(world, start, 69, -39, -27, 69, -39, -27, Blocks.STONE_BRICKS.getDefaultState());
        structure.fillWithBlocks(world, start, 69, -39, -25, 69, -39, -25, Blocks.MOSSY_STONE_BRICKS.getDefaultState());
        structure.fillWithBlocks(world, start, 69, -39, -24, 69, -38, -24, Blocks.STONE_BRICKS.getDefaultState());
        structure.fillWithBlocks(world, start, 69, -39, -21, 69, -39, -20, Blocks.AIR.getDefaultState());
        structure.fillWithBlocks(world, start, 69, -39, -19, 69, -39, -19, Blocks.STONE_BRICKS.getDefaultState());
        structure.fillWithBlocks(world, start, 69, -39, -15, 69, -37, -15, Blocks.STONE_BRICKS.getDefaultState());
        structure.fillWithBlocks(world, start, 69, -39, -12, 70, -39, -12, Blocks.MOSSY_STONE_BRICKS.getDefaultState());
        structure.fillWithBlocks(world, start, 69, -39, 38, 69, -39, 38, Blocks.STONE_BRICKS.getDefaultState());
        structure.fillWithBlocks(world, start, 69, -39, 39, 69, -38, 39, Blocks.MOSSY_STONE_BRICKS.getDefaultState());
        structure.fillWithBlocks(world, start, 69, -39, 40, 69, -39, 41, Blocks.STONE_BRICKS.getDefaultState());
        structure.fillWithBlocks(world, start, 69, -39, 42, 69, -39, 43, Blocks.MOSSY_STONE_BRICKS.getDefaultState());
        structure.fillWithBlocks(world, start, 69, -39, 44, 70, -39, 44, Blocks.STONE_BRICKS.getDefaultState());
        structure.fillWithBlocks(world, start, 69, -39, 45, 69, -39, 45, Blocks.MOSSY_STONE_BRICKS.getDefaultState());
        structure.fillWithBlocks(world, start, 69, -39, 47, 69, -39, 47, Blocks.STONE_BRICKS.getDefaultState());
        structure.fillWithBlocks(world, start, 69, -39, 49, 69, -39, 49, Blocks.STONE_BRICKS.getDefaultState());
        structure.fillWithBlocks(world, start, 69, -38, -26, 69, -38, -24, Blocks.STONE_BRICKS.getDefaultState());
        structure.fillWithBlocks(world, start, 69, -38, -23, 70, -38, -23, Blocks.MOSSY_COBBLESTONE.getDefaultState());
        structure.fillWithBlocks(world, start, 69, -38, -22, 69, -38, -22, Blocks.MOSSY_STONE_BRICKS.getDefaultState());
        structure.fillWithBlocks(world, start, 69, -38, -20, 70, -38, -20, Blocks.MOSSY_COBBLESTONE.getDefaultState());
        structure.fillWithBlocks(world, start, 69, -38, -18, 69, -37, -18, Blocks.INFESTED_STONE_BRICKS.getDefaultState());
        structure.fillWithBlocks(world, start, 69, -38, -17, 70, -38, -17, Blocks.MOSSY_STONE_BRICKS.getDefaultState());
        structure.fillWithBlocks(world, start, 69, -38, 37, 69, -37, 37, Blocks.MOSSY_STONE_BRICKS.getDefaultState());
        structure.fillWithBlocks(world, start, 69, -38, 38, 69, -37, 38, Blocks.STONE_BRICKS.getDefaultState());
        structure.fillWithBlocks(world, start, 69, -38, 40, 71, -38, 40, Blocks.STONE_BRICKS.getDefaultState());
        structure.fillWithBlocks(world, start, 69, -38, 41, 69, -38, 41, Blocks.AIR.getDefaultState());
        structure.fillWithBlocks(world, start, 69, -38, 42, 69, -38, 45, Blocks.STONE_BRICKS.getDefaultState());
        structure.fillWithBlocks(world, start, 69, -38, 46, 69, -38, 47, Blocks.MOSSY_STONE_BRICKS.getDefaultState());
        structure.fillWithBlocks(world, start, 69, -38, 48, 69, -38, 48, Blocks.STONE_BRICKS.getDefaultState());
        structure.fillWithBlocks(world, start, 69, -37, -27, 69, -37, -26, Blocks.STONE_BRICKS.getDefaultState());
        structure.fillWithBlocks(world, start, 69, -37, -25, 69, -37, -24, Blocks.MOSSY_STONE_BRICKS.getDefaultState());
        structure.fillWithBlocks(world, start, 69, -37, -23, 69, -37, -22, Blocks.STONE_BRICKS.getDefaultState());
        structure.fillWithBlocks(world, start, 69, -37, -21, 69, -37, -20, Blocks.MOSSY_STONE_BRICKS.getDefaultState());
        structure.fillWithBlocks(world, start, 69, -37, -19, 70, -37, -19, Blocks.STONE_BRICKS.getDefaultState());
        structure.fillWithBlocks(world, start, 69, -37, -17, 69, -37, -16, Blocks.MOSSY_COBBLESTONE.getDefaultState());
        structure.fillWithBlocks(world, start, 69, -37, -14, 69, -37, -13, Blocks.STONE_BRICKS.getDefaultState());
        structure.fillWithBlocks(world, start, 69, -37, -12, 69, -37, -11, Blocks.AIR.getDefaultState());
        structure.fillWithBlocks(world, start, 69, -37, 39, 73, -37, 39, Blocks.STONE_BRICKS.getDefaultState());
        structure.fillWithBlocks(world, start, 69, -37, 40, 69, -37, 40, Blocks.MOSSY_STONE_BRICKS.getDefaultState());
        structure.fillWithBlocks(world, start, 69, -37, 42, 69, -37, 42, Blocks.MOSSY_STONE_BRICKS.getDefaultState());
        structure.fillWithBlocks(world, start, 69, -37, 47, 69, -37, 47, Blocks.MOSSY_STONE_BRICKS.getDefaultState());
        structure.fillWithBlocks(world, start, 69, -37, 48, 69, -37, 49, Blocks.STONE_BRICKS.getDefaultState());
        structure.fillWithBlocks(world, start, 69, -37, 50, 69, -37, 51, Blocks.MOSSY_STONE_BRICKS.getDefaultState());
        structure.fillWithBlocks(world, start, 69, -26, 11, 69, -26, 18, Blocks.STONE_BRICKS.getDefaultState());
        structure.fillWithBlocks(world, start, 69, -26, 31, 69, -25, 31, Blocks.MOSSY_STONE_BRICKS.getDefaultState());
        structure.fillWithBlocks(world, start, 69, -26, 37, 69, -26, 37, Blocks.STONE_BRICKS.getDefaultState());
        structure.fillWithBlocks(world, start, 69, -26, 40, 69, -26, 40, Blocks.STONE_BRICKS.getDefaultState());
        structure.fillWithBlocks(world, start, 69, -26, 41, 69, -26, 42, Blocks.CRACKED_STONE_BRICKS.getDefaultState());
        structure.fillWithBlocks(world, start, 69, -26, 43, 69, -26, 43, Blocks.STONE_BRICKS.getDefaultState());
        structure.fillWithBlocks(world, start, 69, -26, 48, 70, -26, 48, Blocks.STONE_BRICKS.getDefaultState());
        structure.fillWithBlocks(world, start, 69, -26, 50, 69, -26, 51, Blocks.STONE_BRICKS.getDefaultState());
        structure.fillWithBlocks(world, start, 69, -26, 72, 71, -26, 74, Blocks.STONE_BRICKS.getDefaultState());
        structure.fillWithBlocks(world, start, 69, -26, 75, 70, -26, 75, Blocks.STONE_BRICKS.getDefaultState());
        structure.fillWithBlocks(world, start, 69, -25, 11, 70, -25, 11, Blocks.CRACKED_STONE_BRICKS.getDefaultState());
        structure.fillWithBlocks(world, start, 69, -25, 13, 70, -24, 13, Blocks.STONE_BRICKS.getDefaultState());
        structure.fillWithBlocks(world, start, 69, -25, 14, 69, -24, 14, Blocks.CRACKED_STONE_BRICKS.getDefaultState());
        structure.fillWithBlocks(world, start, 69, -25, 16, 69, -25, 17, Blocks.STONE_BRICKS.getDefaultState());
        structure.fillWithBlocks(world, start, 69, -25, 19, 69, -24, 20, Blocks.STONE_BRICKS.getDefaultState());
        structure.fillWithBlocks(world, start, 69, -25, 23, 69, -25, 24, Blocks.MOSSY_STONE_BRICKS.getDefaultState());
        structure.fillWithBlocks(world, start, 69, -25, 26, 69, -25, 27, Blocks.STONE_BRICKS.getDefaultState());
        structure.fillWithBlocks(world, start, 69, -25, 28, 69, -25, 29, Blocks.MOSSY_STONE_BRICKS.getDefaultState());
        structure.fillWithBlocks(world, start, 69, -25, 32, 69, -25, 32, Blocks.STONE_BRICKS.getDefaultState());
        structure.fillWithBlocks(world, start, 69, -25, 34, 69, -21, 34, Blocks.STONE_BRICKS.getDefaultState());
        structure.fillWithBlocks(world, start, 69, -25, 35, 71, -25, 37, Blocks.AIR.getDefaultState());
        structure.fillWithBlocks(world, start, 69, -25, 38, 69, -20, 38, Blocks.STONE_BRICKS.getDefaultState());
        structure.fillWithBlocks(world, start, 69, -25, 44, 69, -22, 44, Blocks.STONE_BRICKS.getDefaultState());
        structure.fillWithBlocks(world, start, 69, -25, 45, 71, -25, 47, Blocks.AIR.getDefaultState());
        structure.fillWithBlocks(world, start, 69, -25, 48, 69, -25, 49, Blocks.STONE_BRICKS.getDefaultState());
        structure.fillWithBlocks(world, start, 69, -25, 50, 69, -25, 50, Blocks.CRACKED_STONE_BRICKS.getDefaultState());
        structure.fillWithBlocks(world, start, 69, -25, 70, 69, -24, 71, Blocks.STONE_BRICKS.getDefaultState());
        structure.fillWithBlocks(world, start, 69, -25, 75, 69, -25, 76, Blocks.STONE_BRICKS.getDefaultState());
        structure.fillWithBlocks(world, start, 69, -24, 11, 70, -24, 13, Blocks.STONE_BRICKS.getDefaultState());
        structure.fillWithBlocks(world, start, 69, -24, 16, 69, -24, 20, Blocks.STONE_BRICKS.getDefaultState());
        structure.fillWithBlocks(world, start, 69, -24, 22, 69, -23, 22, Blocks.STONE_BRICKS.getDefaultState());
        structure.fillWithBlocks(world, start, 69, -24, 24, 69, -23, 24, Blocks.STONE_BRICKS.getDefaultState());
        structure.fillWithBlocks(world, start, 69, -24, 26, 69, -24, 28, Blocks.STONE_BRICKS.getDefaultState());
        structure.fillWithBlocks(world, start, 69, -24, 30, 69, -24, 34, Blocks.STONE_BRICKS.getDefaultState());
        structure.fillWithBlocks(world, start, 69, -24, 35, 71, -24, 37, Blocks.AIR.getDefaultState());
        structure.fillWithBlocks(world, start, 69, -24, 45, 71, -24, 47, Blocks.AIR.getDefaultState());
        structure.fillWithBlocks(world, start, 69, -24, 48, 69, -24, 50, Blocks.STONE_BRICKS.getDefaultState());
        structure.fillWithBlocks(world, start, 69, -24, 75, 69, -23, 76, Blocks.STONE_BRICKS.getDefaultState());
        structure.fillWithBlocks(world, start, 69, -23, 11, 69, -21, 11, Blocks.STONE_BRICKS.getDefaultState());
        structure.fillWithBlocks(world, start, 69, -23, 12, 69, -21, 12, Blocks.CRACKED_STONE_BRICKS.getDefaultState());
        structure.fillWithBlocks(world, start, 69, -23, 13, 69, -22, 15, Blocks.STONE_BRICKS.getDefaultState());
        structure.fillWithBlocks(world, start, 69, -23, 16, 69, -21, 16, Blocks.CRACKED_STONE_BRICKS.getDefaultState());
        structure.fillWithBlocks(world, start, 69, -23, 17, 69, -22, 18, Blocks.STONE_BRICKS.getDefaultState());
        structure.fillWithBlocks(world, start, 69, -23, 19, 69, -23, 20, Blocks.STONE_BRICKS.getDefaultState());
        structure.fillWithBlocks(world, start, 69, -23, 26, 69, -23, 27, Blocks.STONE_BRICKS.getDefaultState());
        structure.fillWithBlocks(world, start, 69, -23, 28, 69, -23, 29, Blocks.CRACKED_STONE_BRICKS.getDefaultState());
        structure.fillWithBlocks(world, start, 69, -23, 30, 69, -23, 31, Blocks.STONE_BRICKS.getDefaultState());
        structure.fillWithBlocks(world, start, 69, -23, 32, 69, -23, 32, Blocks.CRACKED_STONE_BRICKS.getDefaultState());
        structure.fillWithBlocks(world, start, 69, -23, 33, 69, -23, 34, Blocks.STONE_BRICKS.getDefaultState());
        structure.fillWithBlocks(world, start, 69, -23, 35, 71, -23, 37, Blocks.AIR.getDefaultState());
        structure.fillWithBlocks(world, start, 69, -23, 45, 71, -23, 47, Blocks.AIR.getDefaultState());
        structure.fillWithBlocks(world, start, 69, -23, 48, 69, -22, 48, Blocks.STONE_BRICKS.getDefaultState());
        structure.fillWithBlocks(world, start, 69, -23, 50, 69, -18, 50, Blocks.STONE_BRICKS.getDefaultState());
        structure.fillWithBlocks(world, start, 69, -22, 35, 71, -22, 37, Blocks.AIR.getDefaultState());
        structure.fillWithBlocks(world, start, 69, -22, 39, 73, -22, 43, Blocks.AIR.getDefaultState());
        structure.fillWithBlocks(world, start, 69, -22, 45, 71, -22, 47, Blocks.AIR.getDefaultState());
        structure.fillWithBlocks(world, start, 69, -22, 49, 69, -22, 51, Blocks.STONE_BRICKS.getDefaultState());
        structure.fillWithBlocks(world, start, 69, -22, 71, 69, -22, 71, Blocks.CRACKED_STONE_BRICKS.getDefaultState());
        structure.fillWithBlocks(world, start, 69, -22, 73, 69, -22, 73, Blocks.MOSSY_STONE_BRICKS.getDefaultState());
        structure.fillWithBlocks(world, start, 69, -22, 74, 69, -22, 75, Blocks.STONE_BRICKS.getDefaultState());
        structure.fillWithBlocks(world, start, 69, -21, 15, 69, -21, 16, Blocks.CRACKED_STONE_BRICKS.getDefaultState());
        structure.fillWithBlocks(world, start, 69, -21, 17, 70, -21, 19, Blocks.STONE_BRICKS.getDefaultState());
        structure.fillWithBlocks(world, start, 69, -21, 31, 69, -21, 31, Blocks.STONE_BRICKS.getDefaultState());
        structure.fillWithBlocks(world, start, 69, -21, 33, 69, -21, 34, Blocks.STONE_BRICKS.getDefaultState());
        structure.fillWithBlocks(world, start, 69, -21, 36, 69, -21, 38, Blocks.STONE_BRICKS.getDefaultState());
        structure.fillWithBlocks(world, start, 69, -21, 39, 69, -21, 40, Blocks.MOSSY_STONE_BRICKS.getDefaultState());
        structure.fillWithBlocks(world, start, 69, -21, 41, 69, -21, 42, Blocks.STONE_BRICKS.getDefaultState());
        structure.fillWithBlocks(world, start, 69, -21, 44, 72, -21, 44, Blocks.CRACKED_STONE_BRICKS.getDefaultState());
        structure.fillWithBlocks(world, start, 69, -21, 48, 69, -21, 49, Blocks.CRACKED_STONE_BRICKS.getDefaultState());
        structure.fillWithBlocks(world, start, 69, -20, 11, 70, -20, 11, Blocks.CRACKED_STONE_BRICKS.getDefaultState());
        structure.fillWithBlocks(world, start, 69, -20, 12, 76, -20, 12, Blocks.STONE_BRICKS.getDefaultState());
        structure.fillWithBlocks(world, start, 69, -20, 14, 70, -20, 16, Blocks.STONE_BRICKS.getDefaultState());
        structure.fillWithBlocks(world, start, 69, -20, 18, 69, -20, 19, Blocks.STONE_BRICKS.getDefaultState());
        structure.fillWithBlocks(world, start, 69, -20, 31, 69, -20, 33, Blocks.STONE_BRICKS.getDefaultState());
        structure.fillWithBlocks(world, start, 69, -20, 35, 69, -19, 35, Blocks.STONE_BRICKS.getDefaultState());
        structure.fillWithBlocks(world, start, 69, -20, 39, 69, -20, 39, Blocks.STONE_BRICKS.getDefaultState());
        structure.fillWithBlocks(world, start, 69, -20, 41, 70, -19, 41, Blocks.CRACKED_STONE_BRICKS.getDefaultState());
        structure.fillWithBlocks(world, start, 69, -20, 42, 69, -20, 44, Blocks.STONE_BRICKS.getDefaultState());
        structure.fillWithBlocks(world, start, 69, -20, 45, 69, -20, 46, Blocks.CRACKED_STONE_BRICKS.getDefaultState());
        structure.fillWithBlocks(world, start, 69, -20, 47, 69, -20, 47, Blocks.STONE_BRICKS.getDefaultState());
        structure.fillWithBlocks(world, start, 69, -20, 49, 69, -20, 51, Blocks.STONE_BRICKS.getDefaultState());
        structure.fillWithBlocks(world, start, 69, -19, 11, 70, -19, 11, Blocks.STONE_BRICKS.getDefaultState());
        structure.fillWithBlocks(world, start, 69, -19, 12, 69, -19, 13, Blocks.CRACKED_STONE_BRICKS.getDefaultState());
        structure.fillWithBlocks(world, start, 69, -19, 14, 70, -19, 15, Blocks.STONE_BRICKS.getDefaultState());
        structure.fillWithBlocks(world, start, 69, -19, 16, 69, -19, 17, Blocks.STONE_BRICKS.getDefaultState());
        structure.fillWithBlocks(world, start, 69, -19, 18, 69, -19, 19, Blocks.CRACKED_STONE_BRICKS.getDefaultState());
        structure.fillWithBlocks(world, start, 69, -19, 31, 73, -19, 31, Blocks.STONE_BRICKS.getDefaultState());
        structure.fillWithBlocks(world, start, 69, -19, 32, 70, -19, 32, Blocks.MOSSY_STONE_BRICKS.getDefaultState());
        structure.fillWithBlocks(world, start, 69, -19, 34, 70, -19, 35, Blocks.STONE_BRICKS.getDefaultState());
        structure.fillWithBlocks(world, start, 69, -19, 37, 69, -19, 39, Blocks.CRACKED_STONE_BRICKS.getDefaultState());
        structure.fillWithBlocks(world, start, 69, -19, 40, 70, -18, 40, Blocks.STONE_BRICKS.getDefaultState());
        structure.fillWithBlocks(world, start, 69, -19, 42, 70, -19, 42, Blocks.STONE_BRICKS.getDefaultState());
        structure.fillWithBlocks(world, start, 69, -19, 43, 69, -18, 43, Blocks.CRACKED_STONE_BRICKS.getDefaultState());
        structure.fillWithBlocks(world, start, 69, -19, 44, 70, -19, 46, Blocks.STONE_BRICKS.getDefaultState());
        structure.fillWithBlocks(world, start, 69, -19, 48, 69, -19, 48, Blocks.STONE_BRICKS.getDefaultState());
        structure.fillWithBlocks(world, start, 69, -19, 51, 74, -19, 51, Blocks.STONE_BRICKS.getDefaultState());
        structure.fillWithBlocks(world, start, 69, -18, 11, 69, -18, 13, Blocks.STONE_BRICKS.getDefaultState());
        structure.fillWithBlocks(world, start, 69, -18, 17, 69, -18, 18, Blocks.CRACKED_STONE_BRICKS.getDefaultState());
        structure.fillWithBlocks(world, start, 69, -18, 31, 69, -17, 34, Blocks.STONE_BRICKS.getDefaultState());
        structure.fillWithBlocks(world, start, 69, -18, 35, 69, -18, 36, Blocks.CRACKED_STONE_BRICKS.getDefaultState());
        structure.fillWithBlocks(world, start, 69, -18, 37, 69, -17, 37, Blocks.MOSSY_STONE_BRICKS.getDefaultState());
        structure.fillWithBlocks(world, start, 69, -18, 38, 69, -18, 38, Blocks.STONE_BRICKS.getDefaultState());
        structure.fillWithBlocks(world, start, 69, -18, 41, 72, -18, 41, Blocks.STONE_BRICKS.getDefaultState());
        structure.fillWithBlocks(world, start, 69, -18, 45, 69, -18, 48, Blocks.STONE_BRICKS.getDefaultState());
        structure.fillWithBlocks(world, start, 69, -18, 49, 69, -17, 49, Blocks.MOSSY_STONE_BRICKS.getDefaultState());
        structure.fillWithBlocks(world, start, 69, -17, 11, 69, -17, 12, Blocks.STONE_BRICKS.getDefaultState());
        structure.fillWithBlocks(world, start, 69, -17, 16, 71, -17, 18, Blocks.STONE_BRICKS.getDefaultState());
        structure.fillWithBlocks(world, start, 69, -17, 19, 70, -17, 19, Blocks.CRACKED_STONE_BRICKS.getDefaultState());
        structure.fillWithBlocks(world, start, 69, -17, 38, 69, -17, 39, Blocks.STONE_BRICKS.getDefaultState());
        structure.fillWithBlocks(world, start, 69, -17, 41, 69, -16, 41, Blocks.STONE_BRICKS.getDefaultState());
        structure.fillWithBlocks(world, start, 69, -17, 45, 69, -17, 45, Blocks.STONE_BRICKS.getDefaultState());
        structure.fillWithBlocks(world, start, 69, -17, 46, 69, -17, 47, Blocks.CRACKED_STONE_BRICKS.getDefaultState());
        structure.fillWithBlocks(world, start, 69, -17, 48, 69, -17, 50, Blocks.MOSSY_STONE_BRICKS.getDefaultState());
        structure.fillWithBlocks(world, start, 69, -15, 39, 69, -12, 39, Blocks.STONE_BRICKS.getDefaultState());
        structure.fillWithBlocks(world, start, 69, -15, 43, 69, -15, 44, Blocks.STONE_BRICKS.getDefaultState());
        structure.fillWithBlocks(world, start, 69, -14, 38, 69, -13, 39, Blocks.STONE_BRICKS.getDefaultState());
        structure.fillWithBlocks(world, start, 69, -14, 43, 69, -14, 44, Blocks.STONE_BRICKS.getDefaultState());
        structure.fillWithBlocks(world, start, 69, -13, 43, 69, -13, 44, Blocks.STONE_BRICKS.getDefaultState());
        structure.fillWithBlocks(world, start, 69, -12, 41, 69, -12, 43, Blocks.STONE_BRICKS.getDefaultState());
        structure.fillWithBlocks(world, start, 69, 0, 13, 69, 0, 14, Blocks.GRASS_BLOCK.getDefaultState().with(SnowyDirtBlock.SNOWY, false));
        structure.fillWithBlocks(world, start, 69, 0, 15, 69, 0, 16, Blocks.DIRT.getDefaultState());
        structure.fillWithBlocks(world, start, 69, 0, 17, 69, 0, 64, Blocks.STONE.getDefaultState());
        structure.fillWithBlocks(world, start, 69, 0, 65, 69, 0, 66, Blocks.DIRT.getDefaultState());
        structure.fillWithBlocks(world, start, 69, 1, 15, 69, 1, 15, Blocks.GRASS_BLOCK.getDefaultState().with(SnowyDirtBlock.SNOWY, false));
        structure.fillWithBlocks(world, start, 69, 1, 16, 69, 1, 23, Blocks.DIRT.getDefaultState());
        structure.fillWithBlocks(world, start, 69, 1, 24, 69, 1, 60, Blocks.STONE.getDefaultState());
        structure.fillWithBlocks(world, start, 69, 2, 16, 69, 2, 16, Blocks.GRASS_BLOCK.getDefaultState().with(SnowyDirtBlock.SNOWY, false));
        structure.fillWithBlocks(world, start, 69, 2, 17, 69, 2, 23, Blocks.DIRT.getDefaultState());
        structure.fillWithBlocks(world, start, 69, 2, 24, 69, 2, 27, Blocks.STONE.getDefaultState());
        structure.fillWithBlocks(world, start, 69, 2, 53, 70, 2, 57, Blocks.STONE.getDefaultState());
        structure.fillWithBlocks(world, start, 69, 2, 59, 71, 2, 61, Blocks.DIRT.getDefaultState());
        structure.fillWithBlocks(world, start, 69, 3, 17, 69, 3, 18, Blocks.GRASS_BLOCK.getDefaultState().with(SnowyDirtBlock.SNOWY, false));
        structure.fillWithBlocks(world, start, 69, 3, 19, 69, 3, 62, Blocks.DIRT.getDefaultState());
        structure.fillWithBlocks(world, start, 69, 3, 63, 69, 3, 64, Blocks.GRASS_BLOCK.getDefaultState().with(SnowyDirtBlock.SNOWY, false));
        structure.fillWithBlocks(world, start, 69, 4, 19, 69, 4, 20, Blocks.GRASS_BLOCK.getDefaultState().with(SnowyDirtBlock.SNOWY, false));
        structure.fillWithBlocks(world, start, 69, 4, 21, 69, 4, 60, Blocks.DIRT.getDefaultState());
        structure.fillWithBlocks(world, start, 69, 4, 61, 69, 4, 62, Blocks.GRASS_BLOCK.getDefaultState().with(SnowyDirtBlock.SNOWY, false));
        structure.fillWithBlocks(world, start, 69, 5, 21, 69, 5, 24, Blocks.GRASS_BLOCK.getDefaultState().with(SnowyDirtBlock.SNOWY, false));
        structure.fillWithBlocks(world, start, 69, 5, 25, 69, 5, 56, Blocks.DIRT.getDefaultState());
        structure.fillWithBlocks(world, start, 69, 5, 57, 70, 5, 59, Blocks.GRASS_BLOCK.getDefaultState().with(SnowyDirtBlock.SNOWY, false));
        structure.fillWithBlocks(world, start, 69, 6, 25, 69, 6, 56, Blocks.GRASS_BLOCK.getDefaultState().with(SnowyDirtBlock.SNOWY, false));
        structure.fillWithBlocks(world, start, 69, 7, 31, 69, 7, 31, Blocks.GRASS.getDefaultState());
        structure.fillWithBlocks(world, start, 69, 7, 43, 69, 7, 46, Blocks.GRASS.getDefaultState());
        structure.fillWithBlocks(world, start, 70, -56, 58, 71, -56, 62, Blocks.STONE_BRICKS.getDefaultState());
        structure.fillWithBlocks(world, start, 70, -56, 64, 70, -56, 64, Blocks.STONE_BRICKS.getDefaultState());
        structure.fillWithBlocks(world, start, 70, -56, 66, 71, -56, 71, Blocks.STONE_BRICKS.getDefaultState());
        structure.fillWithBlocks(world, start, 70, -56, 73, 71, -56, 74, Blocks.STONE_BRICKS.getDefaultState());
        structure.fillWithBlocks(world, start, 70, -55, -21, 72, -55, -17, Blocks.AIR.getDefaultState());
        structure.fillWithBlocks(world, start, 70, -55, 36, 70, -55, 36, Blocks.STONE_BRICKS.getDefaultState());
        structure.fillWithBlocks(world, start, 70, -55, 38, 71, -55, 39, Blocks.STONE_BRICKS.getDefaultState());
        structure.fillWithBlocks(world, start, 70, -55, 40, 70, -55, 44, Blocks.STONE_BRICKS.getDefaultState());
        structure.fillWithBlocks(world, start, 70, -55, 58, 71, -55, 59, Blocks.STONE_BRICKS.getDefaultState());
        structure.fillWithBlocks(world, start, 70, -55, 60, 70, -51, 68, Blocks.STONE_BRICKS.getDefaultState());
        structure.fillWithBlocks(world, start, 70, -55, 70, 70, -51, 74, Blocks.STONE_BRICKS.getDefaultState());
        structure.fillWithBlocks(world, start, 70, -54, -23, 70, -54, -22, Blocks.STONE_BRICKS.getDefaultState());
        structure.fillWithBlocks(world, start, 70, -54, -21, 72, -54, -17, Blocks.AIR.getDefaultState());
        structure.fillWithBlocks(world, start, 70, -54, 58, 71, -54, 59, Blocks.STONE_BRICKS.getDefaultState());
        structure.fillWithBlocks(world, start, 70, -54, 69, 70, -49, 74, Blocks.STONE_BRICKS.getDefaultState());
        structure.fillWithBlocks(world, start, 70, -53, -21, 72, -53, -17, Blocks.AIR.getDefaultState());
        structure.fillWithBlocks(world, start, 70, -53, 58, 71, -53, 59, Blocks.STONE_BRICKS.getDefaultState());
        structure.fillWithBlocks(world, start, 70, -52, 36, 73, -52, 39, Blocks.STONE_BRICKS.getDefaultState());
        structure.fillWithBlocks(world, start, 70, -52, 41, 70, -49, 44, Blocks.STONE_BRICKS.getDefaultState());
        structure.fillWithBlocks(world, start, 70, -52, 45, 70, -52, 56, Blocks.STONE_BRICKS.getDefaultState());
        structure.fillWithBlocks(world, start, 70, -52, 58, 70, -52, 74, Blocks.STONE_BRICKS.getDefaultState());
        structure.fillWithBlocks(world, start, 70, -51, 46, 71, -51, 47, Blocks.STONE_BRICKS.getDefaultState());
        structure.fillWithBlocks(world, start, 70, -51, 53, 71, -51, 54, Blocks.STONE_BRICKS.getDefaultState());
        structure.fillWithBlocks(world, start, 70, -51, 56, 71, -50, 56, Blocks.STONE_BRICKS.getDefaultState());
        structure.fillWithBlocks(world, start, 70, -51, 58, 71, -51, 62, Blocks.STONE_BRICKS.getDefaultState());
        structure.fillWithBlocks(world, start, 70, -50, 58, 72, -50, 62, Blocks.STONE_BRICKS.getDefaultState());
        structure.fillWithBlocks(world, start, 70, -50, 64, 72, -50, 71, Blocks.STONE_BRICKS.getDefaultState());
        structure.fillWithBlocks(world, start, 70, -49, 39, 70, -47, 41, Blocks.STONE_BRICKS.getDefaultState());
        structure.fillWithBlocks(world, start, 70, -49, 45, 72, -49, 50, Blocks.STONE_BRICKS.getDefaultState());
        structure.fillWithBlocks(world, start, 70, -49, 52, 73, -49, 56, Blocks.STONE_BRICKS.getDefaultState());
        structure.fillWithBlocks(world, start, 70, -49, 58, 75, -49, 69, Blocks.STONE_BRICKS.getDefaultState());
        structure.fillWithBlocks(world, start, 70, -48, 36, 71, -48, 37, Blocks.STONE_BRICKS.getDefaultState());
        structure.fillWithBlocks(world, start, 70, -48, 42, 75, -48, 47, Blocks.STONE_BRICKS.getDefaultState());
        structure.fillWithBlocks(world, start, 70, -48, 52, 71, -48, 54, Blocks.STONE_BRICKS.getDefaultState());
        structure.fillWithBlocks(world, start, 70, -48, 56, 76, -47, 56, Blocks.STONE_BRICKS.getDefaultState());
        structure.fillWithBlocks(world, start, 70, -48, 58, 73, -48, 61, Blocks.STONE_BRICKS.getDefaultState());
        structure.fillWithBlocks(world, start, 70, -48, 62, 71, -48, 74, Blocks.STONE_BRICKS.getDefaultState());
        structure.fillWithBlocks(world, start, 70, -47, -24, 70, -47, -24, Blocks.STONE_BRICKS.getDefaultState());
        structure.fillWithBlocks(world, start, 70, -47, -15, 70, -47, -15, Blocks.MOSSY_STONE_BRICKS.getDefaultState());
        structure.fillWithBlocks(world, start, 70, -47, -14, 70, -47, -14, Blocks.MOSSY_COBBLESTONE.getDefaultState());
        structure.fillWithBlocks(world, start, 70, -47, 43, 71, -47, 48, Blocks.STONE_BRICKS.getDefaultState());
        structure.fillWithBlocks(world, start, 70, -47, 49, 70, -47, 49, Blocks.MOSSY_STONE_BRICKS.getDefaultState());
        structure.fillWithBlocks(world, start, 70, -47, 50, 70, -47, 56, Blocks.STONE_BRICKS.getDefaultState());
        structure.fillWithBlocks(world, start, 70, -47, 58, 86, -47, 74, Blocks.STONE_BRICKS.getDefaultState());
        structure.fillWithBlocks(world, start, 70, -46, -26, 72, -46, -26, Blocks.MOSSY_STONE_BRICKS.getDefaultState());
        structure.fillWithBlocks(world, start, 70, -46, -16, 71, -46, -16, Blocks.STONE_BRICKS.getDefaultState());
        structure.fillWithBlocks(world, start, 70, -46, -12, 70, -46, -11, Blocks.STONE_BRICKS.getDefaultState());
        structure.fillWithBlocks(world, start, 70, -46, 21, 71, -46, 21, Blocks.MOSSY_STONE_BRICKS.getDefaultState());
        structure.fillWithBlocks(world, start, 70, -46, 22, 70, -46, 23, Blocks.MOSSY_COBBLESTONE.getDefaultState());
        structure.fillWithBlocks(world, start, 70, -46, 24, 70, -46, 25, Blocks.MOSSY_STONE_BRICKS.getDefaultState());
        structure.fillWithBlocks(world, start, 70, -46, 37, 71, -46, 37, Blocks.MOSSY_STONE_BRICKS.getDefaultState());
        structure.fillWithBlocks(world, start, 70, -46, 42, 70, -46, 43, Blocks.STONE_BRICKS.getDefaultState());
        structure.fillWithBlocks(world, start, 70, -46, 44, 70, -46, 44, Blocks.MOSSY_STONE_BRICKS.getDefaultState());
        structure.fillWithBlocks(world, start, 70, -46, 46, 70, -46, 47, Blocks.STONE_BRICKS.getDefaultState());
        structure.fillWithBlocks(world, start, 70, -46, 53, 70, -45, 53, Blocks.STONE_BRICKS.getDefaultState());
        structure.fillWithBlocks(world, start, 70, -45, -26, 74, -45, -26, Blocks.STONE_BRICK_WALL.getDefaultState().with(WallBlock.WATERLOGGED, false).with(WallBlock.UP, true).with(WallBlock.WALL_HEIGHT_NORTH, WallHeight.LOW).with(WallBlock.WALL_HEIGHT_SOUTH, WallHeight.LOW).with(WallBlock.WALL_HEIGHT_EAST, WallHeight.LOW).with(WallBlock.WALL_HEIGHT_WEST, WallHeight.LOW));
        structure.fillWithBlocks(world, start, 70, -45, -16, 74, -45, -16, Blocks.STONE_BRICK_WALL.getDefaultState().with(WallBlock.WATERLOGGED, false).with(WallBlock.UP, false).with(WallBlock.WALL_HEIGHT_NORTH, WallHeight.LOW).with(WallBlock.WALL_HEIGHT_SOUTH, WallHeight.LOW).with(WallBlock.WALL_HEIGHT_EAST, WallHeight.LOW).with(WallBlock.WALL_HEIGHT_WEST, WallHeight.LOW));
        structure.fillWithBlocks(world, start, 70, -45, -12, 73, -45, -12, Blocks.STONE_BRICK_WALL.getDefaultState().with(WallBlock.WATERLOGGED, false).with(WallBlock.UP, false).with(WallBlock.WALL_HEIGHT_NORTH, WallHeight.LOW).with(WallBlock.WALL_HEIGHT_SOUTH, WallHeight.LOW).with(WallBlock.WALL_HEIGHT_EAST, WallHeight.LOW).with(WallBlock.WALL_HEIGHT_WEST, WallHeight.LOW));
        structure.fillWithBlocks(world, start, 70, -45, -11, 71, -45, -11, Blocks.STONE_BRICKS.getDefaultState());
        structure.fillWithBlocks(world, start, 70, -45, 20, 70, -44, 20, Blocks.MOSSY_STONE_BRICKS.getDefaultState());
        structure.fillWithBlocks(world, start, 70, -45, 21, 72, -45, 25, Blocks.AIR.getDefaultState());
        structure.fillWithBlocks(world, start, 70, -45, 38, 72, -45, 38, Blocks.STONE_BRICK_WALL.getDefaultState().with(WallBlock.WATERLOGGED, false).with(WallBlock.UP, true).with(WallBlock.WALL_HEIGHT_NORTH, WallHeight.LOW).with(WallBlock.WALL_HEIGHT_SOUTH, WallHeight.LOW).with(WallBlock.WALL_HEIGHT_EAST, WallHeight.LOW).with(WallBlock.WALL_HEIGHT_WEST, WallHeight.LOW));
        structure.fillWithBlocks(world, start, 70, -45, 43, 73, -45, 47, Blocks.AIR.getDefaultState());
        structure.fillWithBlocks(world, start, 70, -45, 48, 72, -45, 48, Blocks.STONE_BRICK_WALL.getDefaultState().with(WallBlock.WATERLOGGED, false).with(WallBlock.UP, false).with(WallBlock.WALL_HEIGHT_NORTH, WallHeight.LOW).with(WallBlock.WALL_HEIGHT_SOUTH, WallHeight.LOW).with(WallBlock.WALL_HEIGHT_EAST, WallHeight.LOW).with(WallBlock.WALL_HEIGHT_WEST, WallHeight.LOW));
        structure.fillWithBlocks(world, start, 70, -45, 52, 73, -45, 52, Blocks.STONE_BRICK_WALL.getDefaultState().with(WallBlock.WATERLOGGED, false).with(WallBlock.UP, false).with(WallBlock.WALL_HEIGHT_NORTH, WallHeight.LOW).with(WallBlock.WALL_HEIGHT_SOUTH, WallHeight.LOW).with(WallBlock.WALL_HEIGHT_EAST, WallHeight.LOW).with(WallBlock.WALL_HEIGHT_WEST, WallHeight.LOW));
        structure.fillWithBlocks(world, start, 70, -44, -27, 74, -43, -27, Blocks.STONE_BRICKS.getDefaultState());
        structure.fillWithBlocks(world, start, 70, -44, -26, 74, -44, -12, Blocks.AIR.getDefaultState());
        structure.fillWithBlocks(world, start, 70, -44, 21, 72, -44, 25, Blocks.AIR.getDefaultState());
        structure.fillWithBlocks(world, start, 70, -44, 26, 70, -43, 26, Blocks.MOSSY_STONE_BRICKS.getDefaultState());
        structure.fillWithBlocks(world, start, 70, -43, -26, 74, -43, -12, Blocks.AIR.getDefaultState());
        structure.fillWithBlocks(world, start, 70, -43, 20, 71, -43, 20, Blocks.STONE_BRICKS.getDefaultState());
        structure.fillWithBlocks(world, start, 70, -43, 21, 72, -43, 25, Blocks.AIR.getDefaultState());
        structure.fillWithBlocks(world, start, 70, -42, -26, 74, -42, -12, Blocks.AIR.getDefaultState());
        structure.fillWithBlocks(world, start, 70, -42, 22, 70, -42, 22, Blocks.STONE_BRICKS.getDefaultState());
        structure.fillWithBlocks(world, start, 70, -42, 23, 70, -42, 23, Blocks.MOSSY_STONE_BRICKS.getDefaultState());
        structure.fillWithBlocks(world, start, 70, -42, 37, 70, -41, 37, Blocks.MOSSY_STONE_BRICKS.getDefaultState());
        structure.fillWithBlocks(world, start, 70, -42, 53, 71, -42, 53, Blocks.MOSSY_COBBLESTONE.getDefaultState());
        structure.fillWithBlocks(world, start, 70, -41, -27, 71, -41, -27, Blocks.MOSSY_STONE_BRICKS.getDefaultState());
        structure.fillWithBlocks(world, start, 70, -41, -26, 74, -41, -26, Blocks.STONE_BRICKS.getDefaultState());
        structure.fillWithBlocks(world, start, 70, -41, -25, 72, -41, -23, Blocks.AIR.getDefaultState());
        structure.fillWithBlocks(world, start, 70, -41, -21, 74, -41, -17, Blocks.AIR.getDefaultState());
        structure.fillWithBlocks(world, start, 70, -41, -15, 72, -41, -13, Blocks.AIR.getDefaultState());
        structure.fillWithBlocks(world, start, 70, -41, -12, 70, -41, -12, Blocks.STONE_BRICKS.getDefaultState());
        structure.fillWithBlocks(world, start, 70, -41, 38, 71, -41, 38, Blocks.MOSSY_STONE_BRICKS.getDefaultState());
        structure.fillWithBlocks(world, start, 70, -41, 52, 70, -41, 53, Blocks.MOSSY_STONE_BRICKS.getDefaultState());
        structure.fillWithBlocks(world, start, 70, -40, -27, 72, -40, -27, Blocks.STONE_BRICKS.getDefaultState());
        structure.fillWithBlocks(world, start, 70, -40, -25, 71, -40, -25, Blocks.STONE_BRICKS.getDefaultState());
        structure.fillWithBlocks(world, start, 70, -40, -24, 70, -40, -24, Blocks.MOSSY_STONE_BRICKS.getDefaultState());
        structure.fillWithBlocks(world, start, 70, -40, -21, 70, -40, -21, Blocks.STONE_BRICKS.getDefaultState());
        structure.fillWithBlocks(world, start, 70, -40, -20, 70, -40, -20, Blocks.MOSSY_STONE_BRICKS.getDefaultState());
        structure.fillWithBlocks(world, start, 70, -40, -17, 70, -40, -17, Blocks.STONE_BRICKS.getDefaultState());
        structure.fillWithBlocks(world, start, 70, -40, -16, 70, -39, -16, Blocks.MOSSY_STONE_BRICKS.getDefaultState());
        structure.fillWithBlocks(world, start, 70, -40, -15, 70, -40, -14, Blocks.STONE_BRICKS.getDefaultState());
        structure.fillWithBlocks(world, start, 70, -40, -13, 70, -39, -13, Blocks.MOSSY_STONE_BRICKS.getDefaultState());
        structure.fillWithBlocks(world, start, 70, -40, -12, 70, -40, -11, Blocks.STONE_BRICKS.getDefaultState());
        structure.fillWithBlocks(world, start, 70, -40, 37, 70, -40, 38, Blocks.MOSSY_COBBLESTONE.getDefaultState());
        structure.fillWithBlocks(world, start, 70, -40, 39, 71, -39, 39, Blocks.STONE_BRICKS.getDefaultState());
        structure.fillWithBlocks(world, start, 70, -40, 40, 70, -39, 40, Blocks.MOSSY_STONE_BRICKS.getDefaultState());
        structure.fillWithBlocks(world, start, 70, -40, 41, 71, -40, 44, Blocks.STONE_BRICKS.getDefaultState());
        structure.fillWithBlocks(world, start, 70, -40, 47, 70, -40, 48, Blocks.MOSSY_STONE_BRICKS.getDefaultState());
        structure.fillWithBlocks(world, start, 70, -40, 49, 70, -37, 49, Blocks.STONE_BRICKS.getDefaultState());
        structure.fillWithBlocks(world, start, 70, -40, 50, 70, -40, 50, Blocks.AIR.getDefaultState());
        structure.fillWithBlocks(world, start, 70, -40, 51, 70, -39, 51, Blocks.STONE_BRICKS.getDefaultState());
        structure.fillWithBlocks(world, start, 70, -39, -26, 70, -38, -26, Blocks.STONE_BRICKS.getDefaultState());
        structure.fillWithBlocks(world, start, 70, -39, -25, 70, -39, -22, Blocks.MOSSY_STONE_BRICKS.getDefaultState());
        structure.fillWithBlocks(world, start, 70, -39, -21, 70, -39, -20, Blocks.STONE_BRICKS.getDefaultState());
        structure.fillWithBlocks(world, start, 70, -39, -19, 71, -39, -19, Blocks.MOSSY_STONE_BRICKS.getDefaultState());
        structure.fillWithBlocks(world, start, 70, -39, -18, 71, -38, -18, Blocks.STONE_BRICKS.getDefaultState());
        structure.fillWithBlocks(world, start, 70, -39, -17, 70, -39, -12, Blocks.MOSSY_STONE_BRICKS.getDefaultState());
        structure.fillWithBlocks(world, start, 70, -39, 37, 70, -39, 39, Blocks.STONE_BRICKS.getDefaultState());
        structure.fillWithBlocks(world, start, 70, -39, 42, 71, -39, 42, Blocks.MOSSY_COBBLESTONE.getDefaultState());
        structure.fillWithBlocks(world, start, 70, -39, 43, 70, -39, 44, Blocks.STONE_BRICKS.getDefaultState());
        structure.fillWithBlocks(world, start, 70, -39, 47, 71, -39, 50, Blocks.STONE_BRICKS.getDefaultState());
        structure.fillWithBlocks(world, start, 70, -39, 52, 70, -38, 53, Blocks.STONE_BRICKS.getDefaultState());
        structure.fillWithBlocks(world, start, 70, -38, -27, 70, -38, -26, Blocks.STONE_BRICKS.getDefaultState());
        structure.fillWithBlocks(world, start, 70, -38, -22, 70, -38, -22, Blocks.STONE_BRICKS.getDefaultState());
        structure.fillWithBlocks(world, start, 70, -38, -21, 70, -38, -21, Blocks.MOSSY_STONE_BRICKS.getDefaultState());
        structure.fillWithBlocks(world, start, 70, -38, -16, 70, -37, -15, Blocks.STONE_BRICKS.getDefaultState());
        structure.fillWithBlocks(world, start, 70, -38, -13, 70, -38, -11, Blocks.STONE_BRICKS.getDefaultState());
        structure.fillWithBlocks(world, start, 70, -38, 37, 71, -37, 37, Blocks.STONE_BRICKS.getDefaultState());
        structure.fillWithBlocks(world, start, 70, -38, 38, 70, -38, 38, Blocks.MOSSY_STONE_BRICKS.getDefaultState());
        structure.fillWithBlocks(world, start, 70, -38, 41, 70, -37, 41, Blocks.MOSSY_STONE_BRICKS.getDefaultState());
        structure.fillWithBlocks(world, start, 70, -38, 42, 71, -38, 42, Blocks.AIR.getDefaultState());
        structure.fillWithBlocks(world, start, 70, -38, 45, 70, -37, 45, Blocks.STONE_BRICKS.getDefaultState());
        structure.fillWithBlocks(world, start, 70, -38, 46, 70, -38, 46, Blocks.AIR.getDefaultState());
        structure.fillWithBlocks(world, start, 70, -38, 48, 71, -38, 49, Blocks.STONE_BRICKS.getDefaultState());
        structure.fillWithBlocks(world, start, 70, -37, -25, 71, -37, -24, Blocks.STONE_BRICKS.getDefaultState());
        structure.fillWithBlocks(world, start, 70, -37, -22, 70, -37, -22, Blocks.STONE_BRICKS.getDefaultState());
        structure.fillWithBlocks(world, start, 70, -37, -20, 70, -37, -20, Blocks.MOSSY_STONE_BRICKS.getDefaultState());
        structure.fillWithBlocks(world, start, 70, -37, -18, 70, -37, -17, Blocks.MOSSY_STONE_BRICKS.getDefaultState());
        structure.fillWithBlocks(world, start, 70, -37, -14, 75, -37, -14, Blocks.STONE_BRICKS.getDefaultState());
        structure.fillWithBlocks(world, start, 70, -37, -13, 70, -37, -13, Blocks.MOSSY_STONE_BRICKS.getDefaultState());
        structure.fillWithBlocks(world, start, 70, -37, -12, 70, -37, -11, Blocks.STONE_BRICKS.getDefaultState());
        structure.fillWithBlocks(world, start, 70, -37, 38, 70, -37, 39, Blocks.STONE_BRICKS.getDefaultState());
        structure.fillWithBlocks(world, start, 70, -37, 40, 71, -37, 40, Blocks.MOSSY_COBBLESTONE.getDefaultState());
        structure.fillWithBlocks(world, start, 70, -37, 43, 71, -37, 43, Blocks.MOSSY_STONE_BRICKS.getDefaultState());
        structure.fillWithBlocks(world, start, 70, -37, 46, 71, -37, 47, Blocks.STONE_BRICKS.getDefaultState());
        structure.fillWithBlocks(world, start, 70, -37, 51, 71, -37, 52, Blocks.STONE_BRICKS.getDefaultState());
        structure.fillWithBlocks(world, start, 70, -27, 14, 73, -26, 14, Blocks.STONE_BRICKS.getDefaultState());
        structure.fillWithBlocks(world, start, 70, -26, 12, 76, -26, 18, Blocks.STONE_BRICKS.getDefaultState());
        structure.fillWithBlocks(world, start, 70, -26, 19, 70, -26, 19, Blocks.STONE_BRICKS.getDefaultState());
        structure.fillWithBlocks(world, start, 70, -26, 21, 73, -26, 24, Blocks.STONE_BRICKS.getDefaultState());
        structure.fillWithBlocks(world, start, 70, -26, 26, 72, -26, 28, Blocks.STONE_BRICKS.getDefaultState());
        structure.fillWithBlocks(world, start, 70, -26, 29, 70, -26, 30, Blocks.MOSSY_STONE_BRICKS.getDefaultState());
        structure.fillWithBlocks(world, start, 70, -26, 31, 70, -26, 31, Blocks.STONE_BRICKS.getDefaultState());
        structure.fillWithBlocks(world, start, 70, -26, 33, 74, -26, 33, Blocks.STONE_BRICKS.getDefaultState());
        structure.fillWithBlocks(world, start, 70, -26, 34, 70, -26, 35, Blocks.CRACKED_STONE_BRICKS.getDefaultState());
        structure.fillWithBlocks(world, start, 70, -26, 36, 71, -26, 41, Blocks.STONE_BRICKS.getDefaultState());
        structure.fillWithBlocks(world, start, 70, -26, 42, 70, -26, 42, Blocks.STONE_BRICKS.getDefaultState());
        structure.fillWithBlocks(world, start, 70, -26, 43, 70, -26, 43, Blocks.CRACKED_STONE_BRICKS.getDefaultState());
        structure.fillWithBlocks(world, start, 70, -26, 44, 70, -26, 45, Blocks.STONE_BRICKS.getDefaultState());
        structure.fillWithBlocks(world, start, 70, -26, 46, 70, -26, 46, Blocks.CRACKED_STONE_BRICKS.getDefaultState());
        structure.fillWithBlocks(world, start, 70, -26, 49, 70, -26, 50, Blocks.CRACKED_STONE_BRICKS.getDefaultState());
        structure.fillWithBlocks(world, start, 70, -26, 51, 74, -26, 51, Blocks.STONE_BRICKS.getDefaultState());
        structure.fillWithBlocks(world, start, 70, -26, 71, 70, -26, 75, Blocks.STONE_BRICKS.getDefaultState());
        structure.fillWithBlocks(world, start, 70, -26, 77, 70, -25, 77, Blocks.STONE_BRICKS.getDefaultState());
        structure.fillWithBlocks(world, start, 70, -25, 12, 70, -24, 13, Blocks.STONE_BRICKS.getDefaultState());
        structure.fillWithBlocks(world, start, 70, -25, 14, 71, -25, 16, Blocks.AIR.getDefaultState());
        structure.fillWithBlocks(world, start, 70, -25, 17, 70, -24, 19, Blocks.STONE_BRICKS.getDefaultState());
        structure.fillWithBlocks(world, start, 70, -25, 20, 70, -25, 20, Blocks.AIR.getDefaultState());
        structure.fillWithBlocks(world, start, 70, -25, 21, 70, -24, 21, Blocks.STONE_BRICKS.getDefaultState());
        structure.fillWithBlocks(world, start, 70, -25, 22, 71, -25, 24, Blocks.AIR.getDefaultState());
        structure.fillWithBlocks(world, start, 70, -25, 25, 70, -22, 25, Blocks.STONE_BRICKS.getDefaultState());
        structure.fillWithBlocks(world, start, 70, -25, 26, 70, -25, 26, Blocks.AIR.getDefaultState());
        structure.fillWithBlocks(world, start, 70, -25, 27, 70, -24, 27, Blocks.STONE_BRICKS.getDefaultState());
        structure.fillWithBlocks(world, start, 70, -25, 28, 72, -25, 30, Blocks.AIR.getDefaultState());
        structure.fillWithBlocks(world, start, 70, -25, 32, 70, -25, 33, Blocks.STONE_BRICKS.getDefaultState());
        structure.fillWithBlocks(world, start, 70, -25, 34, 74, -25, 40, Blocks.AIR.getDefaultState());
        structure.fillWithBlocks(world, start, 70, -25, 41, 71, -25, 48, Blocks.AIR.getDefaultState());
        structure.fillWithBlocks(world, start, 70, -25, 49, 72, -25, 49, Blocks.STONE_BRICKS.getDefaultState());
        structure.fillWithBlocks(world, start, 70, -25, 70, 71, -25, 70, Blocks.STONE_BRICKS.getDefaultState());
        structure.fillWithBlocks(world, start, 70, -25, 71, 72, -25, 75, Blocks.AIR.getDefaultState());
        structure.fillWithBlocks(world, start, 70, -25, 76, 71, -25, 77, Blocks.STONE_BRICKS.getDefaultState());
        structure.fillWithBlocks(world, start, 70, -25, 78, 70, -25, 79, Blocks.CRACKED_STONE_BRICKS.getDefaultState());
        structure.fillWithBlocks(world, start, 70, -24, 14, 71, -24, 16, Blocks.AIR.getDefaultState());
        structure.fillWithBlocks(world, start, 70, -24, 20, 70, -24, 20, Blocks.AIR.getDefaultState());
        structure.fillWithBlocks(world, start, 70, -24, 22, 72, -24, 24, Blocks.AIR.getDefaultState());
        structure.fillWithBlocks(world, start, 70, -24, 26, 70, -24, 26, Blocks.AIR.getDefaultState());
        structure.fillWithBlocks(world, start, 70, -24, 28, 72, -24, 30, Blocks.AIR.getDefaultState());
        structure.fillWithBlocks(world, start, 70, -24, 32, 70, -23, 32, Blocks.CRACKED_STONE_BRICKS.getDefaultState());
        structure.fillWithBlocks(world, start, 70, -24, 34, 74, -24, 48, Blocks.AIR.getDefaultState());
        structure.fillWithBlocks(world, start, 70, -24, 49, 70, -24, 50, Blocks.CRACKED_STONE_BRICKS.getDefaultState());
        structure.fillWithBlocks(world, start, 70, -24, 71, 72, -24, 75, Blocks.AIR.getDefaultState());
        structure.fillWithBlocks(world, start, 70, -23, 12, 70, -23, 12, Blocks.AIR.getDefaultState());
        structure.fillWithBlocks(world, start, 70, -23, 13, 70, -22, 13, Blocks.STONE_BRICKS.getDefaultState());
        structure.fillWithBlocks(world, start, 70, -23, 14, 72, -23, 16, Blocks.AIR.getDefaultState());
        structure.fillWithBlocks(world, start, 70, -23, 18, 70, -22, 18, Blocks.CRACKED_STONE_BRICKS.getDefaultState());
        structure.fillWithBlocks(world, start, 70, -23, 20, 70, -23, 20, Blocks.AIR.getDefaultState());
        structure.fillWithBlocks(world, start, 70, -23, 22, 72, -23, 24, Blocks.AIR.getDefaultState());
        structure.fillWithBlocks(world, start, 70, -23, 26, 70, -23, 26, Blocks.AIR.getDefaultState());
        structure.fillWithBlocks(world, start, 70, -23, 28, 72, -23, 30, Blocks.AIR.getDefaultState());
        structure.fillWithBlocks(world, start, 70, -23, 33, 70, -20, 33, Blocks.CRACKED_STONE_BRICKS.getDefaultState());
        structure.fillWithBlocks(world, start, 70, -23, 34, 74, -23, 48, Blocks.AIR.getDefaultState());
        structure.fillWithBlocks(world, start, 70, -23, 49, 74, -23, 49, Blocks.STONE_BRICKS.getDefaultState());
        structure.fillWithBlocks(world, start, 70, -23, 51, 71, -23, 51, Blocks.CRACKED_STONE_BRICKS.getDefaultState());
        structure.fillWithBlocks(world, start, 70, -23, 71, 72, -23, 75, Blocks.AIR.getDefaultState());
        structure.fillWithBlocks(world, start, 70, -23, 77, 70, -23, 78, Blocks.STONE_BRICKS.getDefaultState());
        structure.fillWithBlocks(world, start, 70, -22, 11, 71, -22, 12, Blocks.STONE_BRICKS.getDefaultState());
        structure.fillWithBlocks(world, start, 70, -22, 14, 73, -22, 17, Blocks.AIR.getDefaultState());
        structure.fillWithBlocks(world, start, 70, -22, 20, 71, -22, 22, Blocks.STONE_BRICKS.getDefaultState());
        structure.fillWithBlocks(world, start, 70, -22, 26, 71, -22, 27, Blocks.STONE_BRICKS.getDefaultState());
        structure.fillWithBlocks(world, start, 70, -22, 29, 71, -22, 30, Blocks.CRACKED_STONE_BRICKS.getDefaultState());
        structure.fillWithBlocks(world, start, 70, -22, 31, 71, -22, 32, Blocks.STONE_BRICKS.getDefaultState());
        structure.fillWithBlocks(world, start, 70, -22, 34, 72, -22, 34, Blocks.CRACKED_STONE_BRICKS.getDefaultState());
        structure.fillWithBlocks(world, start, 70, -22, 38, 74, -22, 47, Blocks.AIR.getDefaultState());
        structure.fillWithBlocks(world, start, 70, -22, 48, 70, -18, 48, Blocks.STONE_BRICKS.getDefaultState());
        structure.fillWithBlocks(world, start, 70, -22, 49, 71, -22, 49, Blocks.CRACKED_STONE_BRICKS.getDefaultState());
        structure.fillWithBlocks(world, start, 70, -22, 50, 70, -22, 50, Blocks.STONE_BRICKS.getDefaultState());
        structure.fillWithBlocks(world, start, 70, -22, 51, 70, -21, 51, Blocks.CRACKED_STONE_BRICKS.getDefaultState());
        structure.fillWithBlocks(world, start, 70, -22, 71, 73, -22, 71, Blocks.STONE_BRICKS.getDefaultState());
        structure.fillWithBlocks(world, start, 70, -22, 72, 70, -22, 72, Blocks.CRACKED_STONE_BRICKS.getDefaultState());
        structure.fillWithBlocks(world, start, 70, -22, 73, 70, -22, 74, Blocks.MOSSY_STONE_BRICKS.getDefaultState());
        structure.fillWithBlocks(world, start, 70, -22, 75, 70, -22, 75, Blocks.CRACKED_STONE_BRICKS.getDefaultState());
        structure.fillWithBlocks(world, start, 70, -22, 77, 70, -22, 77, Blocks.CRACKED_STONE_BRICKS.getDefaultState());
        structure.fillWithBlocks(world, start, 70, -21, 12, 70, -20, 12, Blocks.STONE_BRICKS.getDefaultState());
        structure.fillWithBlocks(world, start, 70, -21, 13, 70, -20, 13, Blocks.CRACKED_STONE_BRICKS.getDefaultState());
        structure.fillWithBlocks(world, start, 70, -21, 15, 70, -21, 15, Blocks.STONE_BRICKS.getDefaultState());
        structure.fillWithBlocks(world, start, 70, -21, 31, 71, -21, 32, Blocks.STONE_BRICKS.getDefaultState());
        structure.fillWithBlocks(world, start, 70, -21, 34, 72, -21, 34, Blocks.STONE_BRICKS.getDefaultState());
        structure.fillWithBlocks(world, start, 70, -21, 35, 72, -21, 37, Blocks.AIR.getDefaultState());
        structure.fillWithBlocks(world, start, 70, -21, 39, 74, -21, 43, Blocks.AIR.getDefaultState());
        structure.fillWithBlocks(world, start, 70, -21, 45, 72, -21, 47, Blocks.AIR.getDefaultState());
        structure.fillWithBlocks(world, start, 70, -21, 49, 70, -21, 49, Blocks.STONE_BRICKS.getDefaultState());
        structure.fillWithBlocks(world, start, 70, -20, 17, 70, -20, 19, Blocks.CRACKED_STONE_BRICKS.getDefaultState());
        structure.fillWithBlocks(world, start, 70, -20, 31, 70, -19, 31, Blocks.STONE_BRICKS.getDefaultState());
        structure.fillWithBlocks(world, start, 70, -20, 32, 70, -20, 33, Blocks.CRACKED_STONE_BRICKS.getDefaultState());
        structure.fillWithBlocks(world, start, 70, -20, 34, 70, -17, 34, Blocks.STONE_BRICKS.getDefaultState());
        structure.fillWithBlocks(world, start, 70, -20, 36, 71, -20, 37, Blocks.STONE_BRICKS.getDefaultState());
        structure.fillWithBlocks(world, start, 70, -20, 39, 70, -20, 40, Blocks.STONE_BRICKS.getDefaultState());
        structure.fillWithBlocks(world, start, 70, -20, 43, 70, -20, 43, Blocks.STONE_BRICKS.getDefaultState());
        structure.fillWithBlocks(world, start, 70, -20, 44, 70, -20, 45, Blocks.CRACKED_STONE_BRICKS.getDefaultState());
        structure.fillWithBlocks(world, start, 70, -20, 46, 70, -20, 48, Blocks.STONE_BRICKS.getDefaultState());
        structure.fillWithBlocks(world, start, 70, -20, 49, 70, -20, 49, Blocks.CRACKED_STONE_BRICKS.getDefaultState());
        structure.fillWithBlocks(world, start, 70, -20, 50, 70, -18, 50, Blocks.STONE_BRICKS.getDefaultState());
        structure.fillWithBlocks(world, start, 70, -19, 12, 70, -19, 12, Blocks.CRACKED_STONE_BRICKS.getDefaultState());
        structure.fillWithBlocks(world, start, 70, -19, 13, 70, -18, 15, Blocks.STONE_BRICKS.getDefaultState());
        structure.fillWithBlocks(world, start, 70, -19, 17, 70, -18, 18, Blocks.STONE_BRICKS.getDefaultState());
        structure.fillWithBlocks(world, start, 70, -19, 19, 75, -19, 19, Blocks.STONE_BRICKS.getDefaultState());
        structure.fillWithBlocks(world, start, 70, -19, 33, 71, -19, 34, Blocks.STONE_BRICKS.getDefaultState());
        structure.fillWithBlocks(world, start, 70, -19, 36, 70, -18, 36, Blocks.STONE_BRICKS.getDefaultState());
        structure.fillWithBlocks(world, start, 70, -19, 37, 70, -19, 37, Blocks.CRACKED_STONE_BRICKS.getDefaultState());
        structure.fillWithBlocks(world, start, 70, -19, 38, 70, -17, 38, Blocks.STONE_BRICKS.getDefaultState());
        structure.fillWithBlocks(world, start, 70, -19, 47, 71, -19, 49, Blocks.STONE_BRICKS.getDefaultState());
        structure.fillWithBlocks(world, start, 70, -18, 11, 70, -17, 11, Blocks.CRACKED_STONE_BRICKS.getDefaultState());
        structure.fillWithBlocks(world, start, 70, -18, 12, 71, -18, 15, Blocks.STONE_BRICKS.getDefaultState());
        structure.fillWithBlocks(world, start, 70, -18, 19, 71, -18, 19, Blocks.MOSSY_STONE_BRICKS.getDefaultState());
        structure.fillWithBlocks(world, start, 70, -18, 31, 70, -18, 32, Blocks.CRACKED_STONE_BRICKS.getDefaultState());
        structure.fillWithBlocks(world, start, 70, -18, 33, 70, -17, 35, Blocks.STONE_BRICKS.getDefaultState());
        structure.fillWithBlocks(world, start, 70, -18, 37, 70, -18, 41, Blocks.STONE_BRICKS.getDefaultState());
        structure.fillWithBlocks(world, start, 70, -18, 42, 70, -18, 42, Blocks.CRACKED_STONE_BRICKS.getDefaultState());
        structure.fillWithBlocks(world, start, 70, -18, 43, 70, -18, 45, Blocks.STONE_BRICKS.getDefaultState());
        structure.fillWithBlocks(world, start, 70, -18, 46, 70, -18, 47, Blocks.CRACKED_STONE_BRICKS.getDefaultState());
        structure.fillWithBlocks(world, start, 70, -18, 49, 71, -18, 49, Blocks.CRACKED_STONE_BRICKS.getDefaultState());
        structure.fillWithBlocks(world, start, 70, -18, 51, 71, -18, 51, Blocks.MOSSY_STONE_BRICKS.getDefaultState());
        structure.fillWithBlocks(world, start, 70, -17, 13, 70, -17, 13, Blocks.STONE_BRICKS.getDefaultState());
        structure.fillWithBlocks(world, start, 70, -17, 15, 71, -17, 18, Blocks.STONE_BRICKS.getDefaultState());
        structure.fillWithBlocks(world, start, 70, -17, 31, 74, -17, 31, Blocks.STONE_BRICKS.getDefaultState());
        structure.fillWithBlocks(world, start, 70, -17, 39, 71, -17, 39, Blocks.CRACKED_STONE_BRICKS.getDefaultState());
        structure.fillWithBlocks(world, start, 70, -17, 40, 72, -16, 40, Blocks.STONE_BRICKS.getDefaultState());
        structure.fillWithBlocks(world, start, 70, -17, 41, 71, -17, 41, Blocks.MOSSY_STONE_BRICKS.getDefaultState());
        structure.fillWithBlocks(world, start, 70, -17, 42, 71, -17, 46, Blocks.STONE_BRICKS.getDefaultState());
        structure.fillWithBlocks(world, start, 70, -17, 48, 70, -17, 48, Blocks.MOSSY_STONE_BRICKS.getDefaultState());
        structure.fillWithBlocks(world, start, 70, -17, 49, 70, -17, 49, Blocks.STONE_BRICKS.getDefaultState());
        structure.fillWithBlocks(world, start, 70, -17, 51, 73, -17, 51, Blocks.STONE_BRICKS.getDefaultState());
        structure.fillWithBlocks(world, start, 70, -16, 39, 72, -16, 43, Blocks.STONE_BRICKS.getDefaultState());
        structure.fillWithBlocks(world, start, 70, -15, 39, 72, -15, 43, Blocks.AIR.getDefaultState());
        structure.fillWithBlocks(world, start, 70, -15, 45, 71, -15, 46, Blocks.STONE_BRICKS.getDefaultState());
        structure.fillWithBlocks(world, start, 70, -14, 38, 70, -13, 38, Blocks.STONE_BRICKS.getDefaultState());
        structure.fillWithBlocks(world, start, 70, -14, 39, 72, -14, 43, Blocks.AIR.getDefaultState());
        structure.fillWithBlocks(world, start, 70, -14, 45, 70, -14, 46, Blocks.STONE_BRICKS.getDefaultState());
