package mod.arcalitegames.odyssey.world.structure.structures.ruins.ancient_ruins;

import mod.arcalitegames.odyssey.world.structure.StructureBase;
import net.minecraft.block.Blocks;
import net.minecraft.block.SnowyDirtBlock;
import net.minecraft.block.WallBlock;
import net.minecraft.block.WallHeight;
import net.minecraft.util.math.BlockPos;
import net.minecraft.world.World;

public class AncientComponent3
{
	public static BlockPos start;
    public static World world;
    public static StructureBase structure;

    public static void init(World worldIn, BlockPos blockPos, StructureBase structureIn)
    {
        world = worldIn; start = blockPos; structure = structureIn;
    }
	
    public static void generatePart31()
    {
        structure.fillWithBlocks(world, start, -10, -34, -6, -8, -34, -4, Blocks.AIR.getDefaultState());
        structure.fillWithBlocks(world, start, -10, -34, -2, -8, -34, 0, Blocks.AIR.getDefaultState());
        structure.fillWithBlocks(world, start, -10, -34, 2, -8, -34, 4, Blocks.AIR.getDefaultState());
        structure.fillWithBlocks(world, start, -10, -34, 5, -10, -33, 7, Blocks.STONE_BRICKS.getDefaultState());
        structure.fillWithBlocks(world, start, -10, -34, 19, -10, -34, 20, Blocks.STONE_BRICKS.getDefaultState());
        structure.fillWithBlocks(world, start, -10, -34, 21, -7, -34, 24, Blocks.AIR.getDefaultState());
        structure.fillWithBlocks(world, start, -10, -34, 25, -10, -34, 35, Blocks.AIR.getDefaultState());
        structure.fillWithBlocks(world, start, -10, -34, 36, -9, -34, 36, Blocks.MOSSY_STONE_BRICKS.getDefaultState());
        structure.fillWithBlocks(world, start, -10, -33, -33, -10, -32, -32, Blocks.STONE_BRICKS.getDefaultState());
        structure.fillWithBlocks(world, start, -10, -33, -8, -10, -33, -8, Blocks.AIR.getDefaultState());
        structure.fillWithBlocks(world, start, -10, -33, -6, -8, -33, -4, Blocks.AIR.getDefaultState());
        structure.fillWithBlocks(world, start, -10, -33, -2, -8, -33, 0, Blocks.AIR.getDefaultState());
        structure.fillWithBlocks(world, start, -10, -33, 1, -10, -32, 1, Blocks.STONE_BRICKS.getDefaultState());
        structure.fillWithBlocks(world, start, -10, -33, 2, -8, -33, 4, Blocks.AIR.getDefaultState());
        structure.fillWithBlocks(world, start, -10, -33, 16, -10, -33, 18, Blocks.STONE_BRICKS.getDefaultState());
        structure.fillWithBlocks(world, start, -10, -33, 20, -10, -32, 20, Blocks.STONE_BRICKS.getDefaultState());
        structure.fillWithBlocks(world, start, -10, -33, 21, -6, -33, 35, Blocks.AIR.getDefaultState());
        structure.fillWithBlocks(world, start, -10, -32, -14, -9, -32, -13, Blocks.STONE_BRICKS.getDefaultState());
        structure.fillWithBlocks(world, start, -10, -32, -10, -9, -32, -10, Blocks.MOSSY_STONE_BRICKS.getDefaultState());
        structure.fillWithBlocks(world, start, -10, -32, -9, -10, -32, -8, Blocks.STONE_BRICKS.getDefaultState());
        structure.fillWithBlocks(world, start, -10, -32, -6, -9, -32, -4, Blocks.STONE_BRICKS.getDefaultState());
        structure.fillWithBlocks(world, start, -10, -32, 0, -9, -32, 3, Blocks.STONE_BRICKS.getDefaultState());
        structure.fillWithBlocks(world, start, -10, -32, 4, -10, -32, 4, Blocks.STONE_BRICKS.getDefaultState());
        structure.fillWithBlocks(world, start, -10, -32, 7, -10, -31, 7, Blocks.MOSSY_COBBLESTONE.getDefaultState());
        structure.fillWithBlocks(world, start, -10, -32, 15, -10, -32, 16, Blocks.STONE_BRICKS.getDefaultState());
        structure.fillWithBlocks(world, start, -10, -32, 18, -8, -32, 20, Blocks.STONE_BRICKS.getDefaultState());
        structure.fillWithBlocks(world, start, -10, -32, 21, -6, -32, 35, Blocks.AIR.getDefaultState());
        structure.fillWithBlocks(world, start, -10, -32, 36, -9, -32, 36, Blocks.MOSSY_STONE_BRICKS.getDefaultState());
        structure.fillWithBlocks(world, start, -10, -31, -10, -9, -31, -8, Blocks.STONE_BRICKS.getDefaultState());
        structure.fillWithBlocks(world, start, -10, -31, -7, -10, -31, -7, Blocks.MOSSY_STONE_BRICKS.getDefaultState());
        structure.fillWithBlocks(world, start, -10, -31, 4, -10, -29, 4, Blocks.MOSSY_STONE_BRICKS.getDefaultState());
        structure.fillWithBlocks(world, start, -10, -31, 5, -9, -31, 6, Blocks.STONE_BRICKS.getDefaultState());
        structure.fillWithBlocks(world, start, -10, -31, 16, -9, -31, 17, Blocks.STONE_BRICKS.getDefaultState());
        structure.fillWithBlocks(world, start, -10, -31, 18, -8, -31, 18, Blocks.MOSSY_STONE_BRICKS.getDefaultState());
        structure.fillWithBlocks(world, start, -10, -31, 22, -8, -31, 24, Blocks.AIR.getDefaultState());
        structure.fillWithBlocks(world, start, -10, -31, 25, -10, -30, 25, Blocks.CRACKED_STONE_BRICKS.getDefaultState());
        structure.fillWithBlocks(world, start, -10, -31, 26, -6, -31, 30, Blocks.AIR.getDefaultState());
        structure.fillWithBlocks(world, start, -10, -31, 31, -5, -31, 31, Blocks.STONE_BRICKS.getDefaultState());
        structure.fillWithBlocks(world, start, -10, -31, 32, -8, -31, 34, Blocks.AIR.getDefaultState());
        structure.fillWithBlocks(world, start, -10, -30, -31, -10, -30, -29, Blocks.STONE_BRICKS.getDefaultState());
        structure.fillWithBlocks(world, start, -10, -30, -28, -10, -30, -27, Blocks.MOSSY_STONE_BRICKS.getDefaultState());
        structure.fillWithBlocks(world, start, -10, -30, -26, -10, -30, -25, Blocks.STONE_BRICKS.getDefaultState());
        structure.fillWithBlocks(world, start, -10, -30, -23, -9, -30, -22, Blocks.STONE_BRICKS.getDefaultState());
        structure.fillWithBlocks(world, start, -10, -30, -17, -9, -30, -13, Blocks.STONE_BRICKS.getDefaultState());
        structure.fillWithBlocks(world, start, -10, -30, -9, -10, -28, -7, Blocks.STONE_BRICKS.getDefaultState());
        structure.fillWithBlocks(world, start, -10, -30, -6, -10, -30, -6, Blocks.MOSSY_STONE_BRICKS.getDefaultState());
        structure.fillWithBlocks(world, start, -10, -30, 5, -10, -30, 6, Blocks.CRACKED_STONE_BRICKS.getDefaultState());
        structure.fillWithBlocks(world, start, -10, -30, 7, -10, -27, 7, Blocks.STONE_BRICKS.getDefaultState());
        structure.fillWithBlocks(world, start, -10, -30, 9, -10, -30, 10, Blocks.MOSSY_COBBLESTONE.getDefaultState());
        structure.fillWithBlocks(world, start, -10, -30, 15, -10, -30, 17, Blocks.MOSSY_STONE_BRICKS.getDefaultState());
        structure.fillWithBlocks(world, start, -10, -30, 20, -10, -28, 20, Blocks.STONE_BRICKS.getDefaultState());
        structure.fillWithBlocks(world, start, -10, -30, 23, -10, -30, 24, Blocks.STONE_BRICKS.getDefaultState());
        structure.fillWithBlocks(world, start, -10, -30, 26, -10, -30, 26, Blocks.CRACKED_STONE_BRICKS.getDefaultState());
        structure.fillWithBlocks(world, start, -10, -30, 27, -10, -28, 27, Blocks.STONE_BRICKS.getDefaultState());
        structure.fillWithBlocks(world, start, -10, -30, 28, -10, -29, 28, Blocks.MOSSY_STONE_BRICKS.getDefaultState());
        structure.fillWithBlocks(world, start, -10, -30, 29, -10, -30, 29, Blocks.STONE_BRICKS.getDefaultState());
        structure.fillWithBlocks(world, start, -10, -30, 30, -10, -29, 30, Blocks.MOSSY_STONE_BRICKS.getDefaultState());
        structure.fillWithBlocks(world, start, -10, -30, 33, -10, -30, 33, Blocks.MOSSY_STONE_BRICKS.getDefaultState());
        structure.fillWithBlocks(world, start, -10, -29, -33, -9, -29, -33, Blocks.MOSSY_STONE_BRICKS.getDefaultState());
        structure.fillWithBlocks(world, start, -10, -29, -32, -9, -29, -31, Blocks.STONE_BRICKS.getDefaultState());
        structure.fillWithBlocks(world, start, -10, -29, -30, -9, -29, -30, Blocks.CRACKED_STONE_BRICKS.getDefaultState());
        structure.fillWithBlocks(world, start, -10, -29, -29, -8, -27, -29, Blocks.STONE_BRICKS.getDefaultState());
        structure.fillWithBlocks(world, start, -10, -29, -28, -9, -28, -28, Blocks.MOSSY_STONE_BRICKS.getDefaultState());
        structure.fillWithBlocks(world, start, -10, -29, -24, -10, -28, -20, Blocks.STONE_BRICKS.getDefaultState());
        structure.fillWithBlocks(world, start, -10, -29, -18, -9, -28, -18, Blocks.STONE_BRICKS.getDefaultState());
        structure.fillWithBlocks(world, start, -10, -29, -2, -9, -28, -2, Blocks.STONE_BRICKS.getDefaultState());
        structure.fillWithBlocks(world, start, -10, -29, 9, -9, -29, 9, Blocks.MOSSY_STONE_BRICKS.getDefaultState());
        structure.fillWithBlocks(world, start, -10, -29, 10, -10, -29, 10, Blocks.STONE_BRICKS.getDefaultState());
        structure.fillWithBlocks(world, start, -10, -29, 11, -10, -29, 12, Blocks.MOSSY_STONE_BRICKS.getDefaultState());
        structure.fillWithBlocks(world, start, -10, -29, 13, -9, -29, 15, Blocks.STONE_BRICKS.getDefaultState());
        structure.fillWithBlocks(world, start, -10, -29, 16, -10, -29, 18, Blocks.STONE_BRICKS.getDefaultState());
        structure.fillWithBlocks(world, start, -10, -29, 21, -9, -29, 22, Blocks.STONE_BRICKS.getDefaultState());
        structure.fillWithBlocks(world, start, -10, -29, 23, -10, -29, 23, Blocks.MOSSY_STONE_BRICKS.getDefaultState());
        structure.fillWithBlocks(world, start, -10, -29, 25, -10, -27, 25, Blocks.STONE_BRICKS.getDefaultState());
        structure.fillWithBlocks(world, start, -10, -29, 26, -9, -29, 26, Blocks.MOSSY_STONE_BRICKS.getDefaultState());
        structure.fillWithBlocks(world, start, -10, -29, 29, -9, -29, 29, Blocks.STONE_BRICKS.getDefaultState());
        structure.fillWithBlocks(world, start, -10, -29, 31, -9, -29, 32, Blocks.STONE_BRICKS.getDefaultState());
        structure.fillWithBlocks(world, start, -10, -29, 35, -10, -29, 35, Blocks.MOSSY_STONE_BRICKS.getDefaultState());
        structure.fillWithBlocks(world, start, -10, -29, 36, -10, -27, 36, Blocks.STONE_BRICKS.getDefaultState());
        structure.fillWithBlocks(world, start, -10, -28, -33, -10, -28, -33, Blocks.MOSSY_STONE_BRICKS.getDefaultState());
        structure.fillWithBlocks(world, start, -10, -28, -27, -10, -28, -26, Blocks.STONE_BRICKS.getDefaultState());
        structure.fillWithBlocks(world, start, -10, -28, -25, -10, -27, -25, Blocks.MOSSY_STONE_BRICKS.getDefaultState());
        structure.fillWithBlocks(world, start, -10, -28, -16, -10, -28, -15, Blocks.STONE_BRICKS.getDefaultState());
        structure.fillWithBlocks(world, start, -10, -28, -5, -10, -27, -2, Blocks.STONE_BRICKS.getDefaultState());
        structure.fillWithBlocks(world, start, -10, -28, 4, -10, -28, 4, Blocks.STONE_BRICKS.getDefaultState());
        structure.fillWithBlocks(world, start, -10, -28, 5, -10, -27, 5, Blocks.MOSSY_STONE_BRICKS.getDefaultState());
        structure.fillWithBlocks(world, start, -10, -28, 6, -9, -28, 7, Blocks.STONE_BRICKS.getDefaultState());
        structure.fillWithBlocks(world, start, -10, -28, 8, -10, -27, 9, Blocks.STONE_BRICKS.getDefaultState());
        structure.fillWithBlocks(world, start, -10, -28, 10, -9, -28, 10, Blocks.MOSSY_STONE_BRICKS.getDefaultState());
        structure.fillWithBlocks(world, start, -10, -28, 11, -9, -28, 15, Blocks.STONE_BRICKS.getDefaultState());
        structure.fillWithBlocks(world, start, -10, -28, 18, -10, -22, 18, Blocks.STONE_BRICKS.getDefaultState());
        structure.fillWithBlocks(world, start, -10, -28, 22, -10, -28, 34, Blocks.STONE_BRICKS.getDefaultState());
        structure.fillWithBlocks(world, start, -10, -28, 35, -10, -28, 35, Blocks.MOSSY_STONE_BRICKS.getDefaultState());
        structure.fillWithBlocks(world, start, -10, -27, -33, -9, -27, -32, Blocks.STONE_BRICKS.getDefaultState());
        structure.fillWithBlocks(world, start, -10, -27, -31, -9, -27, -31, Blocks.CRACKED_STONE_BRICKS.getDefaultState());
        structure.fillWithBlocks(world, start, -10, -27, -30, -9, -27, -29, Blocks.STONE_BRICKS.getDefaultState());
        structure.fillWithBlocks(world, start, -10, -27, -28, -10, -27, -27, Blocks.CRACKED_STONE_BRICKS.getDefaultState());
        structure.fillWithBlocks(world, start, -10, -27, -21, -9, -27, -19, Blocks.STONE_BRICKS.getDefaultState());
        structure.fillWithBlocks(world, start, -10, -27, -18, -9, -27, -18, Blocks.MOSSY_STONE_BRICKS.getDefaultState());
        structure.fillWithBlocks(world, start, -10, -27, -17, -8, -27, -17, Blocks.STONE_BRICKS.getDefaultState());
        structure.fillWithBlocks(world, start, -10, -27, -13, -8, -27, -13, Blocks.STONE_BRICKS.getDefaultState());
        structure.fillWithBlocks(world, start, -10, -27, 4, -10, -27, 4, Blocks.STONE_BRICKS.getDefaultState());
        structure.fillWithBlocks(world, start, -10, -27, 6, -10, -27, 13, Blocks.STONE_BRICKS.getDefaultState());
        structure.fillWithBlocks(world, start, -10, -27, 15, -10, -26, 15, Blocks.CRACKED_STONE_BRICKS.getDefaultState());
        structure.fillWithBlocks(world, start, -10, -27, 23, -8, -27, 25, Blocks.STONE_BRICKS.getDefaultState());
        structure.fillWithBlocks(world, start, -10, -27, 26, -10, -27, 26, Blocks.STONE_BRICKS.getDefaultState());
        structure.fillWithBlocks(world, start, -10, -27, 28, -10, -27, 29, Blocks.STONE_BRICKS.getDefaultState());
        structure.fillWithBlocks(world, start, -10, -27, 31, -9, -27, 32, Blocks.STONE_BRICKS.getDefaultState());
        structure.fillWithBlocks(world, start, -10, -27, 33, -10, -27, 34, Blocks.MOSSY_STONE_BRICKS.getDefaultState());
        structure.fillWithBlocks(world, start, -10, -26, 4, -10, -26, 6, Blocks.STONE_BRICKS.getDefaultState());
        structure.fillWithBlocks(world, start, -10, -26, 16, -10, -26, 17, Blocks.CRACKED_STONE_BRICKS.getDefaultState());
        structure.fillWithBlocks(world, start, -10, -26, 39, -9, -26, 42, Blocks.STONE_BRICKS.getDefaultState());
        structure.fillWithBlocks(world, start, -10, -26, 66, -10, -25, 66, Blocks.MOSSY_STONE_BRICKS.getDefaultState());
        structure.fillWithBlocks(world, start, -10, -26, 70, -9, -26, 76, Blocks.STONE_BRICKS.getDefaultState());
        structure.fillWithBlocks(world, start, -10, -26, 78, -10, -22, 78, Blocks.STONE_BRICKS.getDefaultState());
        structure.fillWithBlocks(world, start, -10, -26, 79, -10, -26, 81, Blocks.CRACKED_STONE_BRICKS.getDefaultState());
        structure.fillWithBlocks(world, start, -10, -26, 83, -10, -26, 83, Blocks.MOSSY_STONE_BRICKS.getDefaultState());
        structure.fillWithBlocks(world, start, -10, -26, 84, -10, -26, 86, Blocks.STONE_BRICKS.getDefaultState());
        structure.fillWithBlocks(world, start, -10, -26, 88, -9, -26, 95, Blocks.STONE_BRICKS.getDefaultState());
        structure.fillWithBlocks(world, start, -10, -26, 96, -10, -26, 98, Blocks.STONE_BRICKS.getDefaultState());
        structure.fillWithBlocks(world, start, -10, -25, 4, -10, -25, 5, Blocks.STONE_BRICKS.getDefaultState());
        structure.fillWithBlocks(world, start, -10, -25, 6, -9, -25, 16, Blocks.AIR.getDefaultState());
        structure.fillWithBlocks(world, start, -10, -25, 39, -10, -25, 43, Blocks.AIR.getDefaultState());
        structure.fillWithBlocks(world, start, -10, -25, 68, -10, -19, 68, Blocks.STONE_BRICKS.getDefaultState());
        structure.fillWithBlocks(world, start, -10, -25, 69, -8, -25, 77, Blocks.AIR.getDefaultState());
        structure.fillWithBlocks(world, start, -10, -25, 79, -10, -21, 79, Blocks.STONE_BRICKS.getDefaultState());
        structure.fillWithBlocks(world, start, -10, -25, 80, -10, -23, 80, Blocks.AIR.getDefaultState());
        structure.fillWithBlocks(world, start, -10, -25, 81, -10, -23, 81, Blocks.STONE_BRICKS.getDefaultState());
        structure.fillWithBlocks(world, start, -10, -25, 82, -10, -23, 84, Blocks.AIR.getDefaultState());
        structure.fillWithBlocks(world, start, -10, -25, 85, -10, -24, 85, Blocks.CRACKED_STONE_BRICKS.getDefaultState());
        structure.fillWithBlocks(world, start, -10, -25, 86, -10, -21, 86, Blocks.STONE_BRICKS.getDefaultState());
        structure.fillWithBlocks(world, start, -10, -25, 96, -10, -25, 98, Blocks.STONE_BRICKS.getDefaultState());
        structure.fillWithBlocks(world, start, -10, -24, 5, -9, -23, 5, Blocks.STONE_BRICKS.getDefaultState());
        structure.fillWithBlocks(world, start, -10, -24, 6, -9, -24, 16, Blocks.AIR.getDefaultState());
        structure.fillWithBlocks(world, start, -10, -24, 38, -10, -23, 38, Blocks.STONE_BRICKS.getDefaultState());
        structure.fillWithBlocks(world, start, -10, -24, 39, -10, -24, 43, Blocks.AIR.getDefaultState());
        structure.fillWithBlocks(world, start, -10, -24, 96, -10, -21, 96, Blocks.STONE_BRICKS.getDefaultState());
        structure.fillWithBlocks(world, start, -10, -23, 6, -9, -23, 16, Blocks.AIR.getDefaultState());
        structure.fillWithBlocks(world, start, -10, -23, 39, -10, -23, 43, Blocks.AIR.getDefaultState());
        structure.fillWithBlocks(world, start, -10, -23, 66, -10, -22, 66, Blocks.STONE_BRICKS.getDefaultState());
        structure.fillWithBlocks(world, start, -10, -23, 85, -10, -22, 86, Blocks.STONE_BRICKS.getDefaultState());
        structure.fillWithBlocks(world, start, -10, -23, 97, -10, -23, 98, Blocks.CRACKED_STONE_BRICKS.getDefaultState());
        structure.fillWithBlocks(world, start, -10, -22, 6, -9, -22, 16, Blocks.AIR.getDefaultState());
        structure.fillWithBlocks(world, start, -10, -22, 40, -9, -22, 40, Blocks.STONE_BRICKS.getDefaultState());
        structure.fillWithBlocks(world, start, -10, -22, 41, -10, -22, 41, Blocks.CRACKED_STONE_BRICKS.getDefaultState());
        structure.fillWithBlocks(world, start, -10, -22, 42, -10, -22, 42, Blocks.STONE_BRICKS.getDefaultState());
        structure.fillWithBlocks(world, start, -10, -22, 67, -10, -21, 67, Blocks.MOSSY_STONE_BRICKS.getDefaultState());
        structure.fillWithBlocks(world, start, -10, -21, 7, -10, -18, 7, Blocks.STONE_BRICKS.getDefaultState());
        structure.fillWithBlocks(world, start, -10, -21, 16, -9, -21, 16, Blocks.STONE_BRICKS.getDefaultState());
        structure.fillWithBlocks(world, start, -10, -21, 17, -10, -21, 18, Blocks.CRACKED_STONE_BRICKS.getDefaultState());
        structure.fillWithBlocks(world, start, -10, -21, 77, -10, -21, 78, Blocks.CRACKED_STONE_BRICKS.getDefaultState());
        structure.fillWithBlocks(world, start, -10, -21, 85, -10, -20, 85, Blocks.CRACKED_STONE_BRICKS.getDefaultState());
        structure.fillWithBlocks(world, start, -10, -21, 87, -9, -21, 87, Blocks.STONE_BRICKS.getDefaultState());
        structure.fillWithBlocks(world, start, -10, -21, 95, -9, -21, 98, Blocks.STONE_BRICKS.getDefaultState());
        structure.fillWithBlocks(world, start, -10, -20, 4, -8, -20, 4, Blocks.STONE_BRICKS.getDefaultState());
        structure.fillWithBlocks(world, start, -10, -20, 6, -9, -20, 7, Blocks.STONE_BRICKS.getDefaultState());
        structure.fillWithBlocks(world, start, -10, -20, 9, -10, -17, 9, Blocks.STONE_BRICKS.getDefaultState());
        structure.fillWithBlocks(world, start, -10, -20, 10, -10, -19, 10, Blocks.CRACKED_STONE_BRICKS.getDefaultState());
        structure.fillWithBlocks(world, start, -10, -20, 11, -10, -19, 11, Blocks.MOSSY_STONE_BRICKS.getDefaultState());
        structure.fillWithBlocks(world, start, -10, -20, 12, -10, -20, 12, Blocks.STONE_BRICKS.getDefaultState());
        structure.fillWithBlocks(world, start, -10, -20, 13, -10, -20, 17, Blocks.CRACKED_STONE_BRICKS.getDefaultState());
        structure.fillWithBlocks(world, start, -10, -20, 18, -9, -20, 18, Blocks.STONE_BRICKS.getDefaultState());
        structure.fillWithBlocks(world, start, -10, -20, 69, -10, -20, 69, Blocks.STONE_BRICKS.getDefaultState());
        structure.fillWithBlocks(world, start, -10, -20, 70, -10, -19, 70, Blocks.MOSSY_STONE_BRICKS.getDefaultState());
        structure.fillWithBlocks(world, start, -10, -20, 71, -9, -20, 71, Blocks.CRACKED_STONE_BRICKS.getDefaultState());
        structure.fillWithBlocks(world, start, -10, -20, 72, -10, -20, 72, Blocks.MOSSY_STONE_BRICKS.getDefaultState());
        structure.fillWithBlocks(world, start, -10, -20, 75, -10, -17, 75, Blocks.STONE_BRICKS.getDefaultState());
        structure.fillWithBlocks(world, start, -10, -20, 76, -10, -20, 76, Blocks.CRACKED_STONE_BRICKS.getDefaultState());
        structure.fillWithBlocks(world, start, -10, -20, 77, -10, -19, 78, Blocks.STONE_BRICKS.getDefaultState());
        structure.fillWithBlocks(world, start, -10, -20, 79, -9, -20, 79, Blocks.CRACKED_STONE_BRICKS.getDefaultState());
        structure.fillWithBlocks(world, start, -10, -20, 84, -9, -20, 84, Blocks.MOSSY_STONE_BRICKS.getDefaultState());
        structure.fillWithBlocks(world, start, -10, -20, 86, -10, -20, 87, Blocks.CRACKED_STONE_BRICKS.getDefaultState());
        structure.fillWithBlocks(world, start, -10, -20, 88, -10, -20, 90, Blocks.STONE_BRICKS.getDefaultState());
        structure.fillWithBlocks(world, start, -10, -20, 91, -10, -18, 91, Blocks.CRACKED_STONE_BRICKS.getDefaultState());
        structure.fillWithBlocks(world, start, -10, -20, 94, -9, -20, 94, Blocks.STONE_BRICKS.getDefaultState());
        structure.fillWithBlocks(world, start, -10, -20, 96, -9, -20, 96, Blocks.MOSSY_STONE_BRICKS.getDefaultState());
        structure.fillWithBlocks(world, start, -10, -19, 4, -10, -19, 7, Blocks.STONE_BRICKS.getDefaultState());
        structure.fillWithBlocks(world, start, -10, -19, 12, -10, -19, 13, Blocks.CRACKED_STONE_BRICKS.getDefaultState());
        structure.fillWithBlocks(world, start, -10, -19, 14, -10, -17, 14, Blocks.STONE_BRICKS.getDefaultState());
        structure.fillWithBlocks(world, start, -10, -19, 15, -10, -17, 15, Blocks.CRACKED_STONE_BRICKS.getDefaultState());
        structure.fillWithBlocks(world, start, -10, -19, 16, -10, -19, 17, Blocks.STONE_BRICKS.getDefaultState());
        structure.fillWithBlocks(world, start, -10, -19, 67, -9, -19, 68, Blocks.STONE_BRICKS.getDefaultState());
        structure.fillWithBlocks(world, start, -10, -19, 69, -10, -19, 70, Blocks.MOSSY_STONE_BRICKS.getDefaultState());
        structure.fillWithBlocks(world, start, -10, -19, 71, -9, -18, 71, Blocks.STONE_BRICKS.getDefaultState());
        structure.fillWithBlocks(world, start, -10, -19, 72, -9, -19, 72, Blocks.CRACKED_STONE_BRICKS.getDefaultState());
        structure.fillWithBlocks(world, start, -10, -19, 73, -9, -19, 73, Blocks.STONE_BRICKS.getDefaultState());
        structure.fillWithBlocks(world, start, -10, -19, 84, -9, -19, 85, Blocks.STONE_BRICKS.getDefaultState());
        structure.fillWithBlocks(world, start, -10, -19, 86, -8, -19, 86, Blocks.CRACKED_STONE_BRICKS.getDefaultState());
        structure.fillWithBlocks(world, start, -10, -19, 87, -10, -18, 90, Blocks.STONE_BRICKS.getDefaultState());
        structure.fillWithBlocks(world, start, -10, -19, 92, -10, -19, 92, Blocks.STONE_BRICKS.getDefaultState());
        structure.fillWithBlocks(world, start, -10, -19, 95, -10, -19, 97, Blocks.STONE_BRICKS.getDefaultState());
        structure.fillWithBlocks(world, start, -10, -18, 4, -10, -18, 7, Blocks.STONE_BRICKS.getDefaultState());
        structure.fillWithBlocks(world, start, -10, -18, 8, -10, -17, 8, Blocks.CRACKED_STONE_BRICKS.getDefaultState());
        structure.fillWithBlocks(world, start, -10, -18, 10, -9, -18, 11, Blocks.STONE_BRICKS.getDefaultState());
        structure.fillWithBlocks(world, start, -10, -18, 13, -9, -18, 14, Blocks.STONE_BRICKS.getDefaultState());
        structure.fillWithBlocks(world, start, -10, -18, 16, -10, -17, 17, Blocks.STONE_BRICKS.getDefaultState());
        structure.fillWithBlocks(world, start, -10, -18, 66, -10, -18, 66, Blocks.STONE_BRICKS.getDefaultState());
        structure.fillWithBlocks(world, start, -10, -18, 67, -10, -18, 68, Blocks.CRACKED_STONE_BRICKS.getDefaultState());
        structure.fillWithBlocks(world, start, -10, -18, 69, -10, -18, 69, Blocks.STONE_BRICKS.getDefaultState());
        structure.fillWithBlocks(world, start, -10, -18, 72, -10, -17, 72, Blocks.CRACKED_STONE_BRICKS.getDefaultState());
        structure.fillWithBlocks(world, start, -10, -18, 84, -9, -17, 84, Blocks.STONE_BRICKS.getDefaultState());
        structure.fillWithBlocks(world, start, -10, -18, 85, -9, -18, 85, Blocks.CRACKED_STONE_BRICKS.getDefaultState());
        structure.fillWithBlocks(world, start, -10, -18, 86, -9, -18, 87, Blocks.STONE_BRICKS.getDefaultState());
        structure.fillWithBlocks(world, start, -10, -18, 93, -10, -17, 93, Blocks.STONE_BRICKS.getDefaultState());
        structure.fillWithBlocks(world, start, -10, -18, 94, -10, -18, 96, Blocks.CRACKED_STONE_BRICKS.getDefaultState());
        structure.fillWithBlocks(world, start, -10, -18, 97, -10, -18, 98, Blocks.STONE_BRICKS.getDefaultState());
        structure.fillWithBlocks(world, start, -10, -17, 4, -10, -17, 5, Blocks.CRACKED_STONE_BRICKS.getDefaultState());
        structure.fillWithBlocks(world, start, -10, -17, 6, -6, -17, 6, Blocks.STONE_BRICKS.getDefaultState());
        structure.fillWithBlocks(world, start, -10, -17, 7, -10, -17, 8, Blocks.CRACKED_STONE_BRICKS.getDefaultState());
        structure.fillWithBlocks(world, start, -10, -17, 10, -8, -17, 12, Blocks.STONE_BRICKS.getDefaultState());
        structure.fillWithBlocks(world, start, -10, -17, 13, -10, -17, 13, Blocks.CRACKED_STONE_BRICKS.getDefaultState());
        structure.fillWithBlocks(world, start, -10, -17, 66, -10, -17, 67, Blocks.STONE_BRICKS.getDefaultState());
        structure.fillWithBlocks(world, start, -10, -17, 69, -10, -17, 70, Blocks.MOSSY_STONE_BRICKS.getDefaultState());
        structure.fillWithBlocks(world, start, -10, -17, 71, -10, -17, 73, Blocks.CRACKED_STONE_BRICKS.getDefaultState());
        structure.fillWithBlocks(world, start, -10, -17, 74, -10, -17, 75, Blocks.STONE_BRICKS.getDefaultState());
        structure.fillWithBlocks(world, start, -10, -17, 77, -9, -17, 78, Blocks.STONE_BRICKS.getDefaultState());
        structure.fillWithBlocks(world, start, -10, -17, 85, -10, -17, 86, Blocks.STONE_BRICKS.getDefaultState());
        structure.fillWithBlocks(world, start, -10, -17, 87, -10, -17, 88, Blocks.CRACKED_STONE_BRICKS.getDefaultState());
        structure.fillWithBlocks(world, start, -10, -17, 89, -10, -17, 94, Blocks.STONE_BRICKS.getDefaultState());
        structure.fillWithBlocks(world, start, -10, -16, 37, -9, -16, 44, Blocks.STONE_BRICKS.getDefaultState());
        structure.fillWithBlocks(world, start, -10, -16, 46, -9, -16, 48, Blocks.STONE_BRICKS.getDefaultState());
        structure.fillWithBlocks(world, start, -10, -15, 37, -9, -15, 39, Blocks.STONE_BRICKS.getDefaultState());
        structure.fillWithBlocks(world, start, -10, -15, 43, -9, -15, 46, Blocks.STONE_BRICKS.getDefaultState());
        structure.fillWithBlocks(world, start, -10, -15, 48, -9, -14, 48, Blocks.STONE_BRICKS.getDefaultState());
        structure.fillWithBlocks(world, start, -10, -14, 34, -9, -14, 39, Blocks.STONE_BRICKS.getDefaultState());
        structure.fillWithBlocks(world, start, -10, -14, 43, -9, -14, 45, Blocks.STONE_BRICKS.getDefaultState());
        structure.fillWithBlocks(world, start, -10, -14, 47, -9, -14, 48, Blocks.STONE_BRICKS.getDefaultState());
        structure.fillWithBlocks(world, start, -10, -13, 34, -9, -13, 38, Blocks.STONE_BRICKS.getDefaultState());
        structure.fillWithBlocks(world, start, -10, -13, 43, -9, -13, 48, Blocks.STONE_BRICKS.getDefaultState());
        structure.fillWithBlocks(world, start, -10, -12, 34, -9, -12, 43, Blocks.STONE_BRICKS.getDefaultState());
        structure.fillWithBlocks(world, start, -10, -12, 44, -10, -12, 48, Blocks.STONE_BRICKS.getDefaultState());
        structure.fillWithBlocks(world, start, -10, -11, 40, -9, -11, 46, Blocks.STONE_BRICKS.getDefaultState());
        structure.fillWithBlocks(world, start, -10, -10, 34, -9, -10, 41, Blocks.STONE_BRICKS.getDefaultState());
        structure.fillWithBlocks(world, start, -10, -10, 45, -9, -10, 48, Blocks.STONE_BRICKS.getDefaultState());
        structure.fillWithBlocks(world, start, -10, -8, 44, -10, -8, 48, Blocks.STONE_BRICKS.getDefaultState());
        structure.fillWithBlocks(world, start, -10, -7, 35, -9, -7, 48, Blocks.STONE_BRICKS.getDefaultState());
        structure.fillWithBlocks(world, start, -9, -55, 4, -8, -55, 10, Blocks.AIR.getDefaultState());
        structure.fillWithBlocks(world, start, -9, -55, 13, -6, -55, 16, Blocks.STONE_BRICKS.getDefaultState());
        structure.fillWithBlocks(world, start, -9, -54, -5, -9, -54, -5, Blocks.STONE_BRICKS.getDefaultState());
        structure.fillWithBlocks(world, start, -9, -54, -3, -9, -53, -2, Blocks.STONE_BRICKS.getDefaultState());
        structure.fillWithBlocks(world, start, -9, -54, 0, -6, -54, 3, Blocks.STONE_BRICKS.getDefaultState());
        structure.fillWithBlocks(world, start, -9, -54, 16, -9, -53, 16, Blocks.AIR.getDefaultState());
        structure.fillWithBlocks(world, start, -9, -53, 14, -8, -53, 14, Blocks.AIR.getDefaultState());
        structure.fillWithBlocks(world, start, -9, -53, 15, -9, -53, 15, Blocks.STONE_BRICKS.getDefaultState());
        structure.fillWithBlocks(world, start, -9, -53, 17, -8, -53, 19, Blocks.STONE_BRICKS.getDefaultState());
        structure.fillWithBlocks(world, start, -9, -52, 11, -6, -52, 14, Blocks.STONE_BRICKS.getDefaultState());
        structure.fillWithBlocks(world, start, -9, -51, -1, -9, -51, 3, Blocks.STONE_BRICKS.getDefaultState());
        structure.fillWithBlocks(world, start, -9, -51, 18, -8, -51, 19, Blocks.STONE_BRICKS.getDefaultState());
        structure.fillWithBlocks(world, start, -9, -50, -2, -9, -50, 5, Blocks.STONE_BRICKS.getDefaultState());
        structure.fillWithBlocks(world, start, -9, -50, 13, -8, -50, 19, Blocks.STONE_BRICKS.getDefaultState());
        structure.fillWithBlocks(world, start, -9, -49, -5, -6, -49, 10, Blocks.STONE_BRICKS.getDefaultState());
        structure.fillWithBlocks(world, start, -9, -49, 13, -9, -49, 13, Blocks.AIR.getDefaultState());
        structure.fillWithBlocks(world, start, -9, -49, 17, -7, -49, 19, Blocks.STONE_BRICKS.getDefaultState());
        structure.fillWithBlocks(world, start, -9, -48, -5, -7, -48, -3, Blocks.STONE_BRICKS.getDefaultState());
        structure.fillWithBlocks(world, start, -9, -47, -5, -8, -47, -4, Blocks.STONE_BRICKS.getDefaultState());
        structure.fillWithBlocks(world, start, -9, -47, -2, -6, -47, 2, Blocks.STONE_BRICKS.getDefaultState());
        structure.fillWithBlocks(world, start, -9, -47, 3, -8, -47, 5, Blocks.STONE_BRICKS.getDefaultState());
        structure.fillWithBlocks(world, start, -9, -47, 7, -5, -47, 11, Blocks.STONE_BRICKS.getDefaultState());
        structure.fillWithBlocks(world, start, -9, -47, 12, -9, -47, 13, Blocks.AIR.getDefaultState());
        structure.fillWithBlocks(world, start, -9, -47, 14, -7, -47, 17, Blocks.STONE_BRICKS.getDefaultState());
        structure.fillWithBlocks(world, start, -9, -47, 27, -8, -47, 28, Blocks.STONE_BRICKS.getDefaultState());
        structure.fillWithBlocks(world, start, -9, -46, -1, -9, -46, 3, Blocks.STONE_BRICKS.getDefaultState());
        structure.fillWithBlocks(world, start, -9, -46, 4, -9, -46, 6, Blocks.MOSSY_COBBLESTONE.getDefaultState());
        structure.fillWithBlocks(world, start, -9, -46, 7, -8, -46, 7, Blocks.STONE_BRICKS.getDefaultState());
        structure.fillWithBlocks(world, start, -9, -46, 8, -9, -46, 9, Blocks.MOSSY_STONE_BRICKS.getDefaultState());
        structure.fillWithBlocks(world, start, -9, -46, 10, -9, -46, 11, Blocks.MOSSY_COBBLESTONE.getDefaultState());
        structure.fillWithBlocks(world, start, -9, -46, 13, -6, -46, 13, Blocks.MOSSY_COBBLESTONE.getDefaultState());
        structure.fillWithBlocks(world, start, -9, -46, 14, -8, -46, 14, Blocks.MOSSY_STONE_BRICKS.getDefaultState());
        structure.fillWithBlocks(world, start, -9, -46, 20, -8, -46, 20, Blocks.MOSSY_STONE_BRICKS.getDefaultState());
        structure.fillWithBlocks(world, start, -9, -46, 21, -9, -46, 23, Blocks.STONE_BRICKS.getDefaultState());
        structure.fillWithBlocks(world, start, -9, -46, 25, -9, -46, 25, Blocks.STONE_BRICKS.getDefaultState());
        structure.fillWithBlocks(world, start, -9, -46, 30, -4, -46, 30, Blocks.MOSSY_STONE_BRICKS.getDefaultState());
        structure.fillWithBlocks(world, start, -9, -45, 1, -9, -45, 2, Blocks.STONE_BRICKS.getDefaultState());
        structure.fillWithBlocks(world, start, -9, -45, 4, -9, -43, 6, Blocks.AIR.getDefaultState());
        structure.fillWithBlocks(world, start, -9, -45, 20, -6, -45, 20, Blocks.STONE_BRICK_WALL.getDefaultState().with(WallBlock.WATERLOGGED, false).with(WallBlock.UP, false).with(WallBlock.WALL_HEIGHT_NORTH, WallHeight.LOW).with(WallBlock.WALL_HEIGHT_SOUTH, WallHeight.LOW).with(WallBlock.WALL_HEIGHT_EAST, WallHeight.LOW).with(WallBlock.WALL_HEIGHT_WEST, WallHeight.LOW));
        structure.fillWithBlocks(world, start, -9, -45, 21, -5, -45, 25, Blocks.AIR.getDefaultState());
        structure.fillWithBlocks(world, start, -9, -45, 26, -5, -45, 26, Blocks.STONE_BRICK_WALL.getDefaultState().with(WallBlock.WATERLOGGED, false).with(WallBlock.UP, false).with(WallBlock.WALL_HEIGHT_NORTH, WallHeight.LOW).with(WallBlock.WALL_HEIGHT_SOUTH, WallHeight.LOW).with(WallBlock.WALL_HEIGHT_EAST, WallHeight.LOW).with(WallBlock.WALL_HEIGHT_WEST, WallHeight.LOW));
        structure.fillWithBlocks(world, start, -9, -45, 30, -6, -45, 30, Blocks.STONE_BRICK_WALL.getDefaultState().with(WallBlock.WATERLOGGED, false).with(WallBlock.UP, false).with(WallBlock.WALL_HEIGHT_NORTH, WallHeight.LOW).with(WallBlock.WALL_HEIGHT_SOUTH, WallHeight.LOW).with(WallBlock.WALL_HEIGHT_EAST, WallHeight.LOW).with(WallBlock.WALL_HEIGHT_WEST, WallHeight.LOW));
        structure.fillWithBlocks(world, start, -9, -44, -1, -9, -44, 0, Blocks.MOSSY_STONE_BRICKS.getDefaultState());
        structure.fillWithBlocks(world, start, -9, -44, 1, -8, -44, 1, Blocks.STONE_BRICKS.getDefaultState());
        structure.fillWithBlocks(world, start, -9, -44, 2, -8, -44, 2, Blocks.AIR.getDefaultState());
        structure.fillWithBlocks(world, start, -9, -44, 15, -7, -43, 15, Blocks.STONE_BRICKS.getDefaultState());
        structure.fillWithBlocks(world, start, -9, -44, 16, -5, -44, 30, Blocks.AIR.getDefaultState());
        structure.fillWithBlocks(world, start, -9, -44, 31, -8, -43, 31, Blocks.MOSSY_STONE_BRICKS.getDefaultState());
        structure.fillWithBlocks(world, start, -9, -43, -1, -9, -43, 3, Blocks.STONE_BRICKS.getDefaultState());
        structure.fillWithBlocks(world, start, -9, -43, 7, -7, -43, 7, Blocks.STONE_BRICK_WALL.getDefaultState().with(WallBlock.WATERLOGGED, false).with(WallBlock.UP, false).with(WallBlock.WALL_HEIGHT_NORTH, WallHeight.LOW).with(WallBlock.WALL_HEIGHT_SOUTH, WallHeight.LOW).with(WallBlock.WALL_HEIGHT_EAST, WallHeight.LOW).with(WallBlock.WALL_HEIGHT_WEST, WallHeight.LOW));
        structure.fillWithBlocks(world, start, -9, -43, 16, -5, -43, 30, Blocks.AIR.getDefaultState());
        structure.fillWithBlocks(world, start, -9, -42, 0, -9, -42, 1, Blocks.MOSSY_STONE_BRICKS.getDefaultState());
        structure.fillWithBlocks(world, start, -9, -42, 3, -7, -42, 3, Blocks.STONE_BRICKS.getDefaultState());
        structure.fillWithBlocks(world, start, -9, -42, 4, -7, -42, 6, Blocks.AIR.getDefaultState());
        structure.fillWithBlocks(world, start, -9, -42, 7, -5, -42, 7, Blocks.STONE_BRICKS.getDefaultState());
        structure.fillWithBlocks(world, start, -9, -42, 15, -8, -42, 15, Blocks.STONE_BRICKS.getDefaultState());
        structure.fillWithBlocks(world, start, -9, -42, 16, -5, -42, 30, Blocks.AIR.getDefaultState());
        structure.fillWithBlocks(world, start, -9, -41, 1, -9, -41, 1, Blocks.STONE_BRICKS.getDefaultState());
        structure.fillWithBlocks(world, start, -9, -41, 4, -9, -41, 8, Blocks.STONE_BRICKS.getDefaultState());
        structure.fillWithBlocks(world, start, -9, -41, 14, -9, -39, 14, Blocks.STONE_BRICKS.getDefaultState());
        structure.fillWithBlocks(world, start, -9, -41, 15, -7, -41, 15, Blocks.MOSSY_STONE_BRICKS.getDefaultState());
        structure.fillWithBlocks(world, start, -9, -41, 16, -7, -41, 16, Blocks.STONE_BRICKS.getDefaultState());
        structure.fillWithBlocks(world, start, -9, -41, 17, -7, -41, 19, Blocks.AIR.getDefaultState());
        structure.fillWithBlocks(world, start, -9, -41, 21, -5, -41, 25, Blocks.AIR.getDefaultState());
        structure.fillWithBlocks(world, start, -9, -41, 27, -7, -41, 29, Blocks.AIR.getDefaultState());
        structure.fillWithBlocks(world, start, -9, -41, 31, -3, -41, 31, Blocks.STONE_BRICKS.getDefaultState());
        structure.fillWithBlocks(world, start, -9, -40, -1, -9, -39, -1, Blocks.AIR.getDefaultState());
        structure.fillWithBlocks(world, start, -9, -40, 1, -9, -38, 1, Blocks.MOSSY_STONE_BRICKS.getDefaultState());
        structure.fillWithBlocks(world, start, -9, -40, 2, -9, -40, 3, Blocks.STONE_BRICKS.getDefaultState());
        structure.fillWithBlocks(world, start, -9, -40, 4, -9, -39, 4, Blocks.MOSSY_STONE_BRICKS.getDefaultState());
        structure.fillWithBlocks(world, start, -9, -40, 5, -9, -39, 5, Blocks.STONE_BRICKS.getDefaultState());
        structure.fillWithBlocks(world, start, -9, -40, 6, -8, -40, 6, Blocks.MOSSY_STONE_BRICKS.getDefaultState());
        structure.fillWithBlocks(world, start, -9, -40, 7, -9, -40, 8, Blocks.STONE_BRICKS.getDefaultState());
        structure.fillWithBlocks(world, start, -9, -40, 10, -7, -40, 12, Blocks.AIR.getDefaultState());
        structure.fillWithBlocks(world, start, -9, -40, 13, -9, -39, 13, Blocks.MOSSY_STONE_BRICKS.getDefaultState());
        structure.fillWithBlocks(world, start, -9, -40, 15, -9, -40, 16, Blocks.MOSSY_STONE_BRICKS.getDefaultState());
        structure.fillWithBlocks(world, start, -9, -40, 17, -9, -39, 18, Blocks.STONE_BRICKS.getDefaultState());
        structure.fillWithBlocks(world, start, -9, -40, 19, -9, -40, 21, Blocks.STONE_BRICKS.getDefaultState());
        structure.fillWithBlocks(world, start, -9, -40, 24, -9, -40, 24, Blocks.STONE_BRICKS.getDefaultState());
        structure.fillWithBlocks(world, start, -9, -40, 25, -9, -39, 25, Blocks.MOSSY_STONE_BRICKS.getDefaultState());
        structure.fillWithBlocks(world, start, -9, -40, 26, -9, -40, 26, Blocks.STONE_BRICKS.getDefaultState());
        structure.fillWithBlocks(world, start, -9, -40, 27, -9, -40, 27, Blocks.MOSSY_STONE_BRICKS.getDefaultState());
        structure.fillWithBlocks(world, start, -9, -40, 28, -9, -40, 29, Blocks.STONE_BRICKS.getDefaultState());
        structure.fillWithBlocks(world, start, -9, -39, 0, -9, -36, 0, Blocks.STONE_BRICKS.getDefaultState());
        structure.fillWithBlocks(world, start, -9, -39, 2, -8, -39, 2, Blocks.MOSSY_COBBLESTONE.getDefaultState());
        structure.fillWithBlocks(world, start, -9, -39, 3, -9, -36, 3, Blocks.STONE_BRICKS.getDefaultState());
        structure.fillWithBlocks(world, start, -9, -39, 6, -9, -38, 6, Blocks.STONE_BRICKS.getDefaultState());
        structure.fillWithBlocks(world, start, -9, -39, 7, -9, -39, 8, Blocks.MOSSY_STONE_BRICKS.getDefaultState());
        structure.fillWithBlocks(world, start, -9, -39, 9, -9, -39, 12, Blocks.STONE_BRICKS.getDefaultState());
        structure.fillWithBlocks(world, start, -9, -39, 15, -9, -38, 16, Blocks.MOSSY_STONE_BRICKS.getDefaultState());
        structure.fillWithBlocks(world, start, -9, -39, 20, -8, -39, 21, Blocks.STONE_BRICKS.getDefaultState());
        structure.fillWithBlocks(world, start, -9, -39, 22, -9, -39, 23, Blocks.AIR.getDefaultState());
        structure.fillWithBlocks(world, start, -9, -39, 24, -9, -39, 26, Blocks.MOSSY_STONE_BRICKS.getDefaultState());
        structure.fillWithBlocks(world, start, -9, -39, 27, -9, -38, 27, Blocks.STONE_BRICKS.getDefaultState());
        structure.fillWithBlocks(world, start, -9, -39, 30, -8, -39, 30, Blocks.MOSSY_STONE_BRICKS.getDefaultState());
        structure.fillWithBlocks(world, start, -9, -39, 31, -7, -39, 31, Blocks.STONE_BRICKS.getDefaultState());
        structure.fillWithBlocks(world, start, -9, -38, 4, -9, -36, 4, Blocks.STONE_BRICKS.getDefaultState());
        structure.fillWithBlocks(world, start, -9, -38, 5, -7, -38, 5, Blocks.AIR.getDefaultState());
        structure.fillWithBlocks(world, start, -9, -38, 7, -9, -37, 7, Blocks.MOSSY_COBBLESTONE.getDefaultState());
        structure.fillWithBlocks(world, start, -9, -38, 8, -8, -38, 9, Blocks.AIR.getDefaultState());
        structure.fillWithBlocks(world, start, -9, -38, 10, -9, -37, 14, Blocks.AIR.getDefaultState());
        structure.fillWithBlocks(world, start, -9, -38, 17, -9, -36, 20, Blocks.STONE_BRICKS.getDefaultState());
        structure.fillWithBlocks(world, start, -9, -38, 21, -9, -38, 21, Blocks.STONE_BRICKS.getDefaultState());
        structure.fillWithBlocks(world, start, -9, -38, 23, -9, -38, 24, Blocks.MOSSY_STONE_BRICKS.getDefaultState());
        structure.fillWithBlocks(world, start, -9, -38, 25, -9, -37, 25, Blocks.AIR.getDefaultState());
        structure.fillWithBlocks(world, start, -9, -38, 26, -8, -38, 28, Blocks.STONE_BRICKS.getDefaultState());
        structure.fillWithBlocks(world, start, -9, -38, 29, -9, -36, 29, Blocks.STONE_BRICKS.getDefaultState());
        structure.fillWithBlocks(world, start, -9, -38, 31, -9, -36, 31, Blocks.MOSSY_STONE_BRICKS.getDefaultState());
        structure.fillWithBlocks(world, start, -9, -37, -5, -9, -36, -5, Blocks.STONE_BRICKS.getDefaultState());
        structure.fillWithBlocks(world, start, -9, -37, -1, -9, -36, 0, Blocks.STONE_BRICKS.getDefaultState());
        structure.fillWithBlocks(world, start, -9, -37, 1, -9, -37, 1, Blocks.AIR.getDefaultState());
        structure.fillWithBlocks(world, start, -9, -37, 2, -9, -36, 4, Blocks.STONE_BRICKS.getDefaultState());
        structure.fillWithBlocks(world, start, -9, -37, 8, -9, -37, 14, Blocks.AIR.getDefaultState());
        structure.fillWithBlocks(world, start, -9, -37, 16, -9, -37, 21, Blocks.STONE_BRICKS.getDefaultState());
        structure.fillWithBlocks(world, start, -9, -37, 22, -8, -37, 22, Blocks.MOSSY_STONE_BRICKS.getDefaultState());
        structure.fillWithBlocks(world, start, -9, -37, 23, -9, -37, 23, Blocks.MOSSY_COBBLESTONE.getDefaultState());
        structure.fillWithBlocks(world, start, -9, -37, 26, -9, -37, 27, Blocks.INFESTED_STONE_BRICKS.getDefaultState());
        structure.fillWithBlocks(world, start, -9, -37, 30, -9, -37, 30, Blocks.AIR.getDefaultState());
        structure.fillWithBlocks(world, start, -9, -37, 32, -8, -37, 33, Blocks.STONE_BRICKS.getDefaultState());
        structure.fillWithBlocks(world, start, -9, -36, -10, -6, -36, -5, Blocks.STONE_BRICKS.getDefaultState());
        structure.fillWithBlocks(world, start, -9, -36, 1, -7, -36, 6, Blocks.STONE_BRICKS.getDefaultState());
        structure.fillWithBlocks(world, start, -9, -36, 7, -9, -36, 14, Blocks.STONE_BRICKS.getDefaultState());
        structure.fillWithBlocks(world, start, -9, -36, 16, -7, -36, 20, Blocks.STONE_BRICKS.getDefaultState());
        structure.fillWithBlocks(world, start, -9, -36, 21, -7, -36, 21, Blocks.MOSSY_STONE_BRICKS.getDefaultState());
        structure.fillWithBlocks(world, start, -9, -36, 22, -9, -36, 25, Blocks.STONE_BRICKS.getDefaultState());
        structure.fillWithBlocks(world, start, -9, -36, 27, -9, -36, 27, Blocks.STONE_BRICKS.getDefaultState());
        structure.fillWithBlocks(world, start, -9, -36, 36, -7, -36, 36, Blocks.STONE_BRICKS.getDefaultState());
        structure.fillWithBlocks(world, start, -9, -35, -8, -7, -35, 24, Blocks.AIR.getDefaultState());
        structure.fillWithBlocks(world, start, -9, -35, 25, -9, -34, 25, Blocks.STONE_BRICKS.getDefaultState());
        structure.fillWithBlocks(world, start, -9, -35, 26, -8, -35, 27, Blocks.AIR.getDefaultState());
        structure.fillWithBlocks(world, start, -9, -35, 28, -9, -35, 30, Blocks.AIR.getDefaultState());
        structure.fillWithBlocks(world, start, -9, -35, 31, -7, -35, 31, Blocks.STONE_BRICK_WALL.getDefaultState().with(WallBlock.WATERLOGGED, false).with(WallBlock.UP, false).with(WallBlock.WALL_HEIGHT_NORTH, WallHeight.LOW).with(WallBlock.WALL_HEIGHT_SOUTH, WallHeight.LOW).with(WallBlock.WALL_HEIGHT_EAST, WallHeight.LOW).with(WallBlock.WALL_HEIGHT_WEST, WallHeight.LOW));
        structure.fillWithBlocks(world, start, -9, -34, -8, -7, -34, 24, Blocks.AIR.getDefaultState());
        structure.fillWithBlocks(world, start, -9, -34, 26, -5, -34, 30, Blocks.AIR.getDefaultState());
        structure.fillWithBlocks(world, start, -9, -34, 31, -6, -34, 35, Blocks.AIR.getDefaultState());
        structure.fillWithBlocks(world, start, -9, -33, -32, -9, -32, -32, Blocks.MOSSY_STONE_BRICKS.getDefaultState());
        structure.fillWithBlocks(world, start, -9, -33, -14, -8, -33, -13, Blocks.STONE_BRICKS.getDefaultState());
        structure.fillWithBlocks(world, start, -9, -33, -9, -7, -33, -9, Blocks.STONE_BRICKS.getDefaultState());
        structure.fillWithBlocks(world, start, -9, -33, -8, -7, -33, 35, Blocks.AIR.getDefaultState());
        structure.fillWithBlocks(world, start, -9, -32, -33, -8, -31, -33, Blocks.STONE_BRICKS.getDefaultState());
        structure.fillWithBlocks(world, start, -9, -32, -8, -9, -32, 3, Blocks.STONE_BRICKS.getDefaultState());
        structure.fillWithBlocks(world, start, -9, -32, 4, -8, -32, 4, Blocks.MOSSY_STONE_BRICKS.getDefaultState());
        structure.fillWithBlocks(world, start, -9, -32, 5, -9, -32, 5, Blocks.STONE_BRICKS.getDefaultState());
        structure.fillWithBlocks(world, start, -9, -32, 16, -7, -32, 20, Blocks.STONE_BRICKS.getDefaultState());
        structure.fillWithBlocks(world, start, -9, -31, -32, -9, -29, -32, Blocks.STONE_BRICKS.getDefaultState());
        structure.fillWithBlocks(world, start, -9, -31, -14, -8, -31, -13, Blocks.STONE_BRICKS.getDefaultState());
        structure.fillWithBlocks(world, start, -9, -31, -7, -9, -31, -5, Blocks.MOSSY_STONE_BRICKS.getDefaultState());
        structure.fillWithBlocks(world, start, -9, -31, -4, -7, -31, -2, Blocks.STONE_BRICKS.getDefaultState());
        structure.fillWithBlocks(world, start, -9, -31, 4, -7, -31, 6, Blocks.STONE_BRICKS.getDefaultState());
        structure.fillWithBlocks(world, start, -9, -31, 15, -9, -31, 17, Blocks.STONE_BRICKS.getDefaultState());
        structure.fillWithBlocks(world, start, -9, -31, 20, -4, -31, 20, Blocks.STONE_BRICKS.getDefaultState());
        structure.fillWithBlocks(world, start, -9, -31, 21, -7, -31, 24, Blocks.AIR.getDefaultState());
        structure.fillWithBlocks(world, start, -9, -31, 25, -7, -31, 25, Blocks.STONE_BRICKS.getDefaultState());
        structure.fillWithBlocks(world, start, -9, -31, 35, -9, -31, 36, Blocks.STONE_BRICKS.getDefaultState());
        structure.fillWithBlocks(world, start, -9, -30, -33, -9, -30, -32, Blocks.STONE_BRICKS.getDefaultState());
        structure.fillWithBlocks(world, start, -9, -30, -31, -9, -30, -31, Blocks.MOSSY_STONE_BRICKS.getDefaultState());
        structure.fillWithBlocks(world, start, -9, -30, -30, -9, -30, -27, Blocks.STONE_BRICKS.getDefaultState());
        structure.fillWithBlocks(world, start, -9, -30, -26, -9, -30, -26, Blocks.MOSSY_STONE_BRICKS.getDefaultState());
        structure.fillWithBlocks(world, start, -9, -30, -25, -9, -28, -25, Blocks.STONE_BRICKS.getDefaultState());
        structure.fillWithBlocks(world, start, -9, -30, -24, -9, -29, -24, Blocks.MOSSY_STONE_BRICKS.getDefaultState());
        structure.fillWithBlocks(world, start, -9, -30, -21, -9, -30, -21, Blocks.MOSSY_STONE_BRICKS.getDefaultState());
        structure.fillWithBlocks(world, start, -9, -30, -20, -9, -29, -20, Blocks.STONE_BRICKS.getDefaultState());
        structure.fillWithBlocks(world, start, -9, -30, -18, -8, -30, -17, Blocks.STONE_BRICKS.getDefaultState());
        structure.fillWithBlocks(world, start, -9, -30, -10, -9, -30, -9, Blocks.STONE_BRICKS.getDefaultState());
        structure.fillWithBlocks(world, start, -9, -30, -8, -9, -30, -7, Blocks.MOSSY_STONE_BRICKS.getDefaultState());
        structure.fillWithBlocks(world, start, -9, -30, -6, -8, -29, -6, Blocks.STONE_BRICKS.getDefaultState());
        structure.fillWithBlocks(world, start, -9, -30, -5, -8, -29, -5, Blocks.MOSSY_STONE_BRICKS.getDefaultState());
        structure.fillWithBlocks(world, start, -9, -30, -4, -9, -30, -4, Blocks.STONE_BRICKS.getDefaultState());
        structure.fillWithBlocks(world, start, -9, -30, -3, -9, -30, -2, Blocks.CRACKED_STONE_BRICKS.getDefaultState());
        structure.fillWithBlocks(world, start, -9, -30, 4, -9, -27, 4, Blocks.STONE_BRICKS.getDefaultState());
        structure.fillWithBlocks(world, start, -9, -30, 6, -9, -26, 6, Blocks.STONE_BRICKS.getDefaultState());
        structure.fillWithBlocks(world, start, -9, -30, 7, -9, -30, 7, Blocks.MOSSY_COBBLESTONE.getDefaultState());
        structure.fillWithBlocks(world, start, -9, -30, 8, -9, -30, 9, Blocks.MOSSY_STONE_BRICKS.getDefaultState());
        structure.fillWithBlocks(world, start, -9, -30, 10, -7, -30, 10, Blocks.MOSSY_COBBLESTONE.getDefaultState());
        structure.fillWithBlocks(world, start, -9, -30, 11, -9, -26, 11, Blocks.STONE_BRICKS.getDefaultState());
        structure.fillWithBlocks(world, start, -9, -30, 12, -8, -30, 13, Blocks.MOSSY_COBBLESTONE.getDefaultState());
        structure.fillWithBlocks(world, start, -9, -30, 14, -9, -29, 15, Blocks.STONE_BRICKS.getDefaultState());
        structure.fillWithBlocks(world, start, -9, -30, 16, -9, -27, 16, Blocks.MOSSY_STONE_BRICKS.getDefaultState());
        structure.fillWithBlocks(world, start, -9, -30, 17, -8, -30, 18, Blocks.STONE_BRICKS.getDefaultState());
        structure.fillWithBlocks(world, start, -9, -30, 20, -9, -30, 21, Blocks.CRACKED_STONE_BRICKS.getDefaultState());
        structure.fillWithBlocks(world, start, -9, -30, 22, -6, -29, 22, Blocks.STONE_BRICKS.getDefaultState());
        structure.fillWithBlocks(world, start, -9, -30, 23, -9, -29, 23, Blocks.MOSSY_STONE_BRICKS.getDefaultState());
        structure.fillWithBlocks(world, start, -9, -30, 25, -9, -30, 26, Blocks.STONE_BRICKS.getDefaultState());
        structure.fillWithBlocks(world, start, -9, -30, 28, -9, -30, 30, Blocks.STONE_BRICKS.getDefaultState());
        structure.fillWithBlocks(world, start, -9, -30, 31, -9, -30, 34, Blocks.MOSSY_STONE_BRICKS.getDefaultState());
        structure.fillWithBlocks(world, start, -9, -30, 35, -9, -30, 36, Blocks.STONE_BRICKS.getDefaultState());
        structure.fillWithBlocks(world, start, -9, -29, -27, -8, -29, -25, Blocks.STONE_BRICKS.getDefaultState());
        structure.fillWithBlocks(world, start, -9, -29, -22, -8, -29, -20, Blocks.STONE_BRICKS.getDefaultState());
        structure.fillWithBlocks(world, start, -9, -29, -19, -9, -28, -18, Blocks.STONE_BRICKS.getDefaultState());
        structure.fillWithBlocks(world, start, -9, -29, -17, -9, -29, -16, Blocks.CRACKED_STONE_BRICKS.getDefaultState());
        structure.fillWithBlocks(world, start, -9, -29, -15, -9, -29, -15, Blocks.STONE_BRICKS.getDefaultState());
        structure.fillWithBlocks(world, start, -9, -29, -9, -9, -29, -9, Blocks.STONE_BRICKS.getDefaultState());
        structure.fillWithBlocks(world, start, -9, -29, -7, -8, -29, -6, Blocks.STONE_BRICKS.getDefaultState());
        structure.fillWithBlocks(world, start, -9, -29, -4, -9, -29, -2, Blocks.STONE_BRICKS.getDefaultState());
        structure.fillWithBlocks(world, start, -9, -29, 5, -8, -29, 6, Blocks.STONE_BRICKS.getDefaultState());
        structure.fillWithBlocks(world, start, -9, -29, 10, -9, -29, 15, Blocks.STONE_BRICKS.getDefaultState());
        structure.fillWithBlocks(world, start, -9, -29, 17, -9, -29, 17, Blocks.STONE_BRICKS.getDefaultState());
        structure.fillWithBlocks(world, start, -9, -29, 18, -9, -28, 18, Blocks.MOSSY_STONE_BRICKS.getDefaultState());
        structure.fillWithBlocks(world, start, -9, -29, 24, -9, -29, 26, Blocks.MOSSY_STONE_BRICKS.getDefaultState());
        structure.fillWithBlocks(world, start, -9, -29, 27, -9, -27, 27, Blocks.STONE_BRICKS.getDefaultState());
        structure.fillWithBlocks(world, start, -9, -29, 30, -7, -29, 30, Blocks.MOSSY_STONE_BRICKS.getDefaultState());
        structure.fillWithBlocks(world, start, -9, -29, 33, -9, -29, 33, Blocks.MOSSY_STONE_BRICKS.getDefaultState());
        structure.fillWithBlocks(world, start, -9, -29, 34, -9, -27, 34, Blocks.STONE_BRICKS.getDefaultState());
        structure.fillWithBlocks(world, start, -9, -29, 35, -9, -29, 36, Blocks.MOSSY_STONE_BRICKS.getDefaultState());
        structure.fillWithBlocks(world, start, -9, -28, -33, -6, -27, -33, Blocks.STONE_BRICKS.getDefaultState());
        structure.fillWithBlocks(world, start, -9, -28, -32, -7, -28, -32, Blocks.MOSSY_STONE_BRICKS.getDefaultState());
        structure.fillWithBlocks(world, start, -9, -28, -31, -9, -28, -31, Blocks.STONE_BRICKS.getDefaultState());
        structure.fillWithBlocks(world, start, -9, -28, -27, -9, -27, -27, Blocks.STONE_BRICKS.getDefaultState());
        structure.fillWithBlocks(world, start, -9, -28, -26, -9, -27, -26, Blocks.MOSSY_STONE_BRICKS.getDefaultState());
        structure.fillWithBlocks(world, start, -9, -28, -24, -8, -28, -23, Blocks.STONE_BRICKS.getDefaultState());
        structure.fillWithBlocks(world, start, -9, -28, -22, -9, -28, -21, Blocks.STONE_BRICKS.getDefaultState());
        structure.fillWithBlocks(world, start, -9, -28, -20, -8, -28, -20, Blocks.MOSSY_STONE_BRICKS.getDefaultState());
        structure.fillWithBlocks(world, start, -9, -28, -17, -8, -28, -16, Blocks.STONE_BRICKS.getDefaultState());
        structure.fillWithBlocks(world, start, -9, -28, -14, -8, -28, -13, Blocks.STONE_BRICKS.getDefaultState());
        structure.fillWithBlocks(world, start, -9, -28, -10, -9, -28, -5, Blocks.STONE_BRICKS.getDefaultState());
        structure.fillWithBlocks(world, start, -9, -28, -4, -9, -28, -3, Blocks.MOSSY_STONE_BRICKS.getDefaultState());
        structure.fillWithBlocks(world, start, -9, -28, 5, -9, -28, 7, Blocks.STONE_BRICKS.getDefaultState());
        structure.fillWithBlocks(world, start, -9, -28, 8, -9, -28, 10, Blocks.MOSSY_STONE_BRICKS.getDefaultState());
        structure.fillWithBlocks(world, start, -9, -28, 20, -9, -28, 20, Blocks.MOSSY_STONE_BRICKS.getDefaultState());
        structure.fillWithBlocks(world, start, -9, -28, 23, -8, -28, 24, Blocks.STONE_BRICKS.getDefaultState());
        structure.fillWithBlocks(world, start, -9, -28, 25, -9, -28, 26, Blocks.CRACKED_STONE_BRICKS.getDefaultState());
        structure.fillWithBlocks(world, start, -9, -28, 28, -9, -28, 28, Blocks.STONE_BRICKS.getDefaultState());
        structure.fillWithBlocks(world, start, -9, -28, 30, -9, -28, 35, Blocks.STONE_BRICKS.getDefaultState());
        structure.fillWithBlocks(world, start, -9, -27, -28, -9, -27, -28, Blocks.MOSSY_STONE_BRICKS.getDefaultState());
        structure.fillWithBlocks(world, start, -9, -27, -24, -8, -27, -23, Blocks.STONE_BRICKS.getDefaultState());
        structure.fillWithBlocks(world, start, -9, -27, -22, -7, -27, -22, Blocks.MOSSY_STONE_BRICKS.getDefaultState());
        structure.fillWithBlocks(world, start, -9, -27, -15, -9, -27, -15, Blocks.STONE_BRICKS.getDefaultState());
        structure.fillWithBlocks(world, start, -9, -27, -9, -9, -27, -8, Blocks.STONE_BRICKS.getDefaultState());
        structure.fillWithBlocks(world, start, -9, -27, -7, -9, -27, -5, Blocks.MOSSY_STONE_BRICKS.getDefaultState());
        structure.fillWithBlocks(world, start, -9, -27, -4, -9, -27, -3, Blocks.STONE_BRICKS.getDefaultState());
        structure.fillWithBlocks(world, start, -9, -27, 5, -9, -26, 6, Blocks.STONE_BRICKS.getDefaultState());
        structure.fillWithBlocks(world, start, -9, -27, 8, -9, -27, 8, Blocks.STONE_BRICKS.getDefaultState());
        structure.fillWithBlocks(world, start, -9, -27, 9, -9, -27, 9, Blocks.MOSSY_STONE_BRICKS.getDefaultState());
        structure.fillWithBlocks(world, start, -9, -27, 12, -8, -27, 15, Blocks.STONE_BRICKS.getDefaultState());
        structure.fillWithBlocks(world, start, -9, -27, 18, -9, -26, 18, Blocks.STONE_BRICKS.getDefaultState());
        structure.fillWithBlocks(world, start, -9, -27, 20, -9, -27, 25, Blocks.STONE_BRICKS.getDefaultState());
        structure.fillWithBlocks(world, start, -9, -27, 28, -9, -27, 28, Blocks.STONE_BRICKS.getDefaultState());
        structure.fillWithBlocks(world, start, -9, -27, 35, -9, -27, 36, Blocks.STONE_BRICKS.getDefaultState());
        structure.fillWithBlocks(world, start, -9, -26, 4, -9, -25, 4, Blocks.CRACKED_STONE_BRICKS.getDefaultState());
        structure.fillWithBlocks(world, start, -9, -26, 7, -9, -26, 7, Blocks.STONE_BRICKS.getDefaultState());
        structure.fillWithBlocks(world, start, -9, -26, 9, -7, -26, 12, Blocks.STONE_BRICKS.getDefaultState());
        structure.fillWithBlocks(world, start, -9, -26, 13, -8, -26, 13, Blocks.CRACKED_STONE_BRICKS.getDefaultState());
        structure.fillWithBlocks(world, start, -9, -26, 14, -9, -26, 15, Blocks.STONE_BRICKS.getDefaultState());
        structure.fillWithBlocks(world, start, -9, -26, 16, -8, -26, 16, Blocks.AIR.getDefaultState());
        structure.fillWithBlocks(world, start, -9, -26, 17, -9, -26, 18, Blocks.STONE_BRICKS.getDefaultState());
        structure.fillWithBlocks(world, start, -9, -26, 43, -8, -26, 43, Blocks.MOSSY_STONE_BRICKS.getDefaultState());
        structure.fillWithBlocks(world, start, -9, -26, 66, -8, -26, 68, Blocks.STONE_BRICKS.getDefaultState());
        structure.fillWithBlocks(world, start, -9, -26, 69, -9, -26, 76, Blocks.STONE_BRICKS.getDefaultState());
        structure.fillWithBlocks(world, start, -9, -26, 77, -9, -26, 78, Blocks.CRACKED_STONE_BRICKS.getDefaultState());
        structure.fillWithBlocks(world, start, -9, -26, 79, -9, -26, 79, Blocks.STONE_BRICKS.getDefaultState());
        structure.fillWithBlocks(world, start, -9, -26, 80, -9, -25, 80, Blocks.CRACKED_STONE_BRICKS.getDefaultState());
        structure.fillWithBlocks(world, start, -9, -26, 84, -9, -25, 84, Blocks.MOSSY_STONE_BRICKS.getDefaultState());
        structure.fillWithBlocks(world, start, -9, -26, 85, -8, -26, 85, Blocks.CRACKED_STONE_BRICKS.getDefaultState());
        structure.fillWithBlocks(world, start, -9, -26, 86, -9, -26, 95, Blocks.STONE_BRICKS.getDefaultState());
        structure.fillWithBlocks(world, start, -9, -26, 97, -8, -26, 98, Blocks.STONE_BRICKS.getDefaultState());
        structure.fillWithBlocks(world, start, -9, -25, 5, -9, -21, 5, Blocks.STONE_BRICKS.getDefaultState());
        structure.fillWithBlocks(world, start, -9, -25, 17, -9, -24, 17, Blocks.STONE_BRICKS.getDefaultState());
        structure.fillWithBlocks(world, start, -9, -25, 39, -9, -24, 39, Blocks.STONE_BRICKS.getDefaultState());
        structure.fillWithBlocks(world, start, -9, -25, 43, -9, -24, 43, Blocks.STONE_BRICKS.getDefaultState());
        structure.fillWithBlocks(world, start, -9, -25, 66, -9, -25, 67, Blocks.STONE_BRICKS.getDefaultState());
        structure.fillWithBlocks(world, start, -9, -25, 68, -8, -25, 78, Blocks.AIR.getDefaultState());
        structure.fillWithBlocks(world, start, -9, -25, 79, -9, -25, 80, Blocks.CRACKED_STONE_BRICKS.getDefaultState());
        structure.fillWithBlocks(world, start, -9, -25, 85, -9, -22, 85, Blocks.STONE_BRICKS.getDefaultState());
        structure.fillWithBlocks(world, start, -9, -25, 86, -8, -25, 96, Blocks.AIR.getDefaultState());
        structure.fillWithBlocks(world, start, -9, -25, 97, -8, -25, 98, Blocks.STONE_BRICKS.getDefaultState());
        structure.fillWithBlocks(world, start, -9, -24, 66, -9, -24, 66, Blocks.STONE_BRICKS.getDefaultState());
        structure.fillWithBlocks(world, start, -9, -24, 68, -8, -24, 78, Blocks.AIR.getDefaultState());
        structure.fillWithBlocks(world, start, -9, -24, 79, -9, -24, 80, Blocks.STONE_BRICKS.getDefaultState());
        structure.fillWithBlocks(world, start, -9, -24, 84, -9, -23, 85, Blocks.STONE_BRICKS.getDefaultState());
        structure.fillWithBlocks(world, start, -9, -24, 86, -8, -24, 96, Blocks.AIR.getDefaultState());
        structure.fillWithBlocks(world, start, -9, -24, 97, -9, -23, 97, Blocks.STONE_BRICKS.getDefaultState());
        structure.fillWithBlocks(world, start, -9, -24, 98, -9, -23, 98, Blocks.CRACKED_STONE_BRICKS.getDefaultState());
        structure.fillWithBlocks(world, start, -9, -23, 4, -9, -22, 5, Blocks.STONE_BRICKS.getDefaultState());
        structure.fillWithBlocks(world, start, -9, -23, 18, -8, -23, 18, Blocks.STONE_BRICKS.getDefaultState());
        structure.fillWithBlocks(world, start, -9, -23, 67, -9, -18, 67, Blocks.STONE_BRICKS.getDefaultState());
        structure.fillWithBlocks(world, start, -9, -23, 68, -8, -23, 78, Blocks.AIR.getDefaultState());
        structure.fillWithBlocks(world, start, -9, -23, 82, -9, -23, 85, Blocks.STONE_BRICKS.getDefaultState());
        structure.fillWithBlocks(world, start, -9, -23, 86, -8, -23, 96, Blocks.AIR.getDefaultState());
        structure.fillWithBlocks(world, start, -9, -22, 17, -9, -22, 18, Blocks.STONE_BRICKS.getDefaultState());
        structure.fillWithBlocks(world, start, -9, -22, 43, -8, -22, 43, Blocks.STONE_BRICKS.getDefaultState());
        structure.fillWithBlocks(world, start, -9, -22, 66, -9, -22, 67, Blocks.STONE_BRICKS.getDefaultState());
        structure.fillWithBlocks(world, start, -9, -22, 68, -8, -22, 78, Blocks.AIR.getDefaultState());
        structure.fillWithBlocks(world, start, -9, -22, 80, -8, -22, 80, Blocks.STONE_BRICKS.getDefaultState());
        structure.fillWithBlocks(world, start, -9, -22, 84, -9, -22, 84, Blocks.CRACKED_STONE_BRICKS.getDefaultState());
        structure.fillWithBlocks(world, start, -9, -22, 86, -8, -22, 96, Blocks.AIR.getDefaultState());
        structure.fillWithBlocks(world, start, -9, -22, 97, -7, -22, 97, Blocks.CRACKED_STONE_BRICKS.getDefaultState());
        structure.fillWithBlocks(world, start, -9, -21, 7, -9, -21, 7, Blocks.CRACKED_STONE_BRICKS.getDefaultState());
        structure.fillWithBlocks(world, start, -9, -21, 9, -9, -21, 11, Blocks.CRACKED_STONE_BRICKS.getDefaultState());
        structure.fillWithBlocks(world, start, -9, -21, 12, -9, -21, 14, Blocks.STONE_BRICKS.getDefaultState());
        structure.fillWithBlocks(world, start, -9, -21, 17, -9, -20, 17, Blocks.CRACKED_STONE_BRICKS.getDefaultState());
        structure.fillWithBlocks(world, start, -9, -21, 18, -9, -19, 18, Blocks.STONE_BRICKS.getDefaultState());
        structure.fillWithBlocks(world, start, -9, -21, 66, -9, -21, 66, Blocks.MOSSY_STONE_BRICKS.getDefaultState());
        structure.fillWithBlocks(world, start, -9, -21, 68, -7, -21, 68, Blocks.CRACKED_STONE_BRICKS.getDefaultState());
        structure.fillWithBlocks(world, start, -9, -21, 77, -9, -21, 79, Blocks.STONE_BRICKS.getDefaultState());
        structure.fillWithBlocks(world, start, -9, -21, 84, -9, -21, 85, Blocks.MOSSY_STONE_BRICKS.getDefaultState());
        structure.fillWithBlocks(world, start, -9, -21, 86, -9, -20, 87, Blocks.STONE_BRICKS.getDefaultState());
        structure.fillWithBlocks(world, start, -9, -20, 8, -8, -20, 9, Blocks.CRACKED_STONE_BRICKS.getDefaultState());
        structure.fillWithBlocks(world, start, -9, -20, 10, -9, -20, 10, Blocks.STONE_BRICKS.getDefaultState());
        structure.fillWithBlocks(world, start, -9, -20, 11, -9, -20, 12, Blocks.CRACKED_STONE_BRICKS.getDefaultState());
        structure.fillWithBlocks(world, start, -9, -20, 13, -9, -18, 13, Blocks.STONE_BRICKS.getDefaultState());
        structure.fillWithBlocks(world, start, -9, -20, 15, -6, -20, 15, Blocks.STONE_BRICKS.getDefaultState());
        structure.fillWithBlocks(world, start, -9, -20, 16, -9, -20, 17, Blocks.CRACKED_STONE_BRICKS.getDefaultState());
        structure.fillWithBlocks(world, start, -9, -20, 66, -9, -19, 67, Blocks.STONE_BRICKS.getDefaultState());
        structure.fillWithBlocks(world, start, -9, -20, 68, -9, -20, 69, Blocks.MOSSY_STONE_BRICKS.getDefaultState());
        structure.fillWithBlocks(world, start, -9, -20, 70, -9, -20, 70, Blocks.STONE_BRICKS.getDefaultState());
        structure.fillWithBlocks(world, start, -9, -20, 72, -9, -20, 73, Blocks.MOSSY_STONE_BRICKS.getDefaultState());
        structure.fillWithBlocks(world, start, -9, -20, 74, -9, -20, 74, Blocks.STONE_BRICKS.getDefaultState());
        structure.fillWithBlocks(world, start, -9, -20, 76, -8, -19, 76, Blocks.STONE_BRICKS.getDefaultState());
        structure.fillWithBlocks(world, start, -9, -20, 77, -9, -19, 78, Blocks.CRACKED_STONE_BRICKS.getDefaultState());
        structure.fillWithBlocks(world, start, -9, -20, 80, -9, -19, 80, Blocks.STONE_BRICKS.getDefaultState());
        structure.fillWithBlocks(world, start, -9, -20, 85, -9, -20, 87, Blocks.STONE_BRICKS.getDefaultState());
        structure.fillWithBlocks(world, start, -9, -20, 88, -8, -19, 88, Blocks.CRACKED_STONE_BRICKS.getDefaultState());
        structure.fillWithBlocks(world, start, -9, -20, 89, -8, -20, 90, Blocks.STONE_BRICKS.getDefaultState());
        structure.fillWithBlocks(world, start, -9, -20, 91, -9, -20, 94, Blocks.STONE_BRICKS.getDefaultState());
        structure.fillWithBlocks(world, start, -9, -20, 95, -9, -20, 96, Blocks.MOSSY_STONE_BRICKS.getDefaultState());
        structure.fillWithBlocks(world, start, -9, -20, 97, -9, -20, 98, Blocks.STONE_BRICKS.getDefaultState());
        structure.fillWithBlocks(world, start, -9, -19, 5, -8, -19, 5, Blocks.STONE_BRICKS.getDefaultState());
        structure.fillWithBlocks(world, start, -9, -19, 8, -8, -19, 9, Blocks.STONE_BRICKS.getDefaultState());
        structure.fillWithBlocks(world, start, -9, -19, 11, -8, -19, 12, Blocks.STONE_BRICKS.getDefaultState());
        structure.fillWithBlocks(world, start, -9, -19, 15, -9, -19, 15, Blocks.STONE_BRICKS.getDefaultState());
        structure.fillWithBlocks(world, start, -9, -19, 17, -9, -19, 18, Blocks.STONE_BRICKS.getDefaultState());
        structure.fillWithBlocks(world, start, -9, -19, 69, -7, -19, 69, Blocks.STONE_BRICKS.getDefaultState());
        structure.fillWithBlocks(world, start, -9, -19, 70, -9, -19, 70, Blocks.CRACKED_STONE_BRICKS.getDefaultState());
        structure.fillWithBlocks(world, start, -9, -19, 74, -9, -19, 74, Blocks.MOSSY_STONE_BRICKS.getDefaultState());
        structure.fillWithBlocks(world, start, -9, -19, 75, -9, -19, 76, Blocks.STONE_BRICKS.getDefaultState());
        structure.fillWithBlocks(world, start, -9, -19, 89, -9, -18, 92, Blocks.STONE_BRICKS.getDefaultState());
        structure.fillWithBlocks(world, start, -9, -19, 93, -9, -19, 94, Blocks.STONE_BRICKS.getDefaultState());
        structure.fillWithBlocks(world, start, -9, -19, 95, -9, -19, 95, Blocks.MOSSY_STONE_BRICKS.getDefaultState());
        structure.fillWithBlocks(world, start, -9, -19, 96, -9, -19, 96, Blocks.CRACKED_STONE_BRICKS.getDefaultState());
        structure.fillWithBlocks(world, start, -9, -18, 4, -8, -17, 4, Blocks.STONE_BRICKS.getDefaultState());
        structure.fillWithBlocks(world, start, -9, -18, 5, -8, -18, 5, Blocks.CRACKED_STONE_BRICKS.getDefaultState());
        structure.fillWithBlocks(world, start, -9, -18, 6, -9, -18, 8, Blocks.STONE_BRICKS.getDefaultState());
        structure.fillWithBlocks(world, start, -9, -18, 9, -8, -18, 9, Blocks.MOSSY_STONE_BRICKS.getDefaultState());
        structure.fillWithBlocks(world, start, -9, -18, 15, -8, -18, 15, Blocks.CRACKED_STONE_BRICKS.getDefaultState());
        structure.fillWithBlocks(world, start, -9, -18, 16, -9, -17, 16, Blocks.STONE_BRICKS.getDefaultState());
        structure.fillWithBlocks(world, start, -9, -18, 17, -9, -18, 18, Blocks.CRACKED_STONE_BRICKS.getDefaultState());
        structure.fillWithBlocks(world, start, -9, -18, 66, -9, -18, 68, Blocks.STONE_BRICKS.getDefaultState());
        structure.fillWithBlocks(world, start, -9, -18, 70, -9, -18, 72, Blocks.STONE_BRICKS.getDefaultState());
        structure.fillWithBlocks(world, start, -9, -18, 73, -9, -18, 74, Blocks.CRACKED_STONE_BRICKS.getDefaultState());
        structure.fillWithBlocks(world, start, -9, -18, 75, -9, -17, 75, Blocks.STONE_BRICKS.getDefaultState());
        structure.fillWithBlocks(world, start, -9, -18, 76, -7, -18, 76, Blocks.MOSSY_STONE_BRICKS.getDefaultState());
        structure.fillWithBlocks(world, start, -9, -18, 78, -9, -17, 79, Blocks.STONE_BRICKS.getDefaultState());
        structure.fillWithBlocks(world, start, -9, -18, 88, -9, -18, 88, Blocks.CRACKED_STONE_BRICKS.getDefaultState());
        structure.fillWithBlocks(world, start, -9, -18, 93, -9, -18, 94, Blocks.CRACKED_STONE_BRICKS.getDefaultState());
        structure.fillWithBlocks(world, start, -9, -18, 95, -9, -18, 97, Blocks.STONE_BRICKS.getDefaultState());
        structure.fillWithBlocks(world, start, -9, -17, 5, -8, -17, 6, Blocks.STONE_BRICKS.getDefaultState());
        structure.fillWithBlocks(world, start, -9, -17, 8, -7, -17, 8, Blocks.STONE_BRICKS.getDefaultState());
        structure.fillWithBlocks(world, start, -9, -17, 9, -8, -17, 9, Blocks.CRACKED_STONE_BRICKS.getDefaultState());
        structure.fillWithBlocks(world, start, -9, -17, 13, -9, -17, 14, Blocks.CRACKED_STONE_BRICKS.getDefaultState());
        structure.fillWithBlocks(world, start, -9, -17, 15, -9, -17, 16, Blocks.STONE_BRICKS.getDefaultState());
        structure.fillWithBlocks(world, start, -9, -17, 17, -8, -17, 17, Blocks.MOSSY_STONE_BRICKS.getDefaultState());
        structure.fillWithBlocks(world, start, -9, -17, 18, -6, -17, 18, Blocks.STONE_BRICKS.getDefaultState());
        structure.fillWithBlocks(world, start, -9, -17, 66, -9, -17, 66, Blocks.STONE_BRICKS.getDefaultState());
        structure.fillWithBlocks(world, start, -9, -17, 68, -9, -17, 69, Blocks.STONE_BRICKS.getDefaultState());
        structure.fillWithBlocks(world, start, -9, -17, 71, -8, -17, 71, Blocks.CRACKED_STONE_BRICKS.getDefaultState());
        structure.fillWithBlocks(world, start, -9, -17, 72, -9, -17, 72, Blocks.STONE_BRICKS.getDefaultState());
        structure.fillWithBlocks(world, start, -9, -17, 74, -9, -17, 74, Blocks.CRACKED_STONE_BRICKS.getDefaultState());
        structure.fillWithBlocks(world, start, -9, -17, 76, -9, -17, 80, Blocks.STONE_BRICKS.getDefaultState());
        structure.fillWithBlocks(world, start, -9, -17, 85, -9, -17, 85, Blocks.STONE_BRICKS.getDefaultState());
        structure.fillWithBlocks(world, start, -9, -17, 88, -9, -17, 88, Blocks.STONE_BRICKS.getDefaultState());
        structure.fillWithBlocks(world, start, -9, -17, 90, -9, -17, 94, Blocks.STONE_BRICKS.getDefaultState());
        structure.fillWithBlocks(world, start, -9, -17, 96, -8, -17, 98, Blocks.STONE_BRICKS.getDefaultState());
        structure.fillWithBlocks(world, start, -9, -16, 45, -9, -13, 48, Blocks.STONE_BRICKS.getDefaultState());
        structure.fillWithBlocks(world, start, -9, -13, 39, -9, -9, 39, Blocks.STONE_BRICKS.getDefaultState());
        structure.fillWithBlocks(world, start, -9, -12, 45, -9, -9, 48, Blocks.STONE_BRICKS.getDefaultState());
        structure.fillWithBlocks(world, start, -9, -10, 43, -9, -9, 48, Blocks.STONE_BRICKS.getDefaultState());
        structure.fillWithBlocks(world, start, -9, -8, 40, -9, -7, 43, Blocks.STONE_BRICKS.getDefaultState());
        structure.fillWithBlocks(world, start, -9, -8, 45, -9, -7, 48, Blocks.STONE_BRICKS.getDefaultState());
        structure.fillWithBlocks(world, start, -9, -7, 34, -9, -7, 48, Blocks.STONE_BRICKS.getDefaultState());
        structure.fillWithBlocks(world, start, -8, -56, -5, -7, -56, -4, Blocks.STONE_BRICKS.getDefaultState());
        structure.fillWithBlocks(world, start, -8, -56, -2, -6, -56, 0, Blocks.STONE_BRICKS.getDefaultState());
        structure.fillWithBlocks(world, start, -8, -55, 1, -6, -55, 3, Blocks.STONE_BRICKS.getDefaultState());
        structure.fillWithBlocks(world, start, -8, -55, 11, -6, -55, 16, Blocks.STONE_BRICKS.getDefaultState());
        structure.fillWithBlocks(world, start, -8, -55, 18, -7, -55, 19, Blocks.STONE_BRICKS.getDefaultState());
        structure.fillWithBlocks(world, start, -8, -54, -5, -6, -54, -3, Blocks.STONE_BRICKS.getDefaultState());
        structure.fillWithBlocks(world, start, -8, -54, -1, -6, -54, 3, Blocks.STONE_BRICKS.getDefaultState());
        structure.fillWithBlocks(world, start, -8, -54, 16, -5, -54, 19, Blocks.STONE_BRICKS.getDefaultState());
        structure.fillWithBlocks(world, start, -8, -53, 11, -8, -53, 11, Blocks.STONE_BRICKS.getDefaultState());
        structure.fillWithBlocks(world, start, -8, -53, 13, -8, -53, 13, Blocks.STONE_BRICKS.getDefaultState());
        structure.fillWithBlocks(world, start, -8, -53, 15, -5, -53, 18, Blocks.STONE_BRICKS.getDefaultState());
        structure.fillWithBlocks(world, start, -8, -51, 0, -5, -51, 3, Blocks.STONE_BRICKS.getDefaultState());
        structure.fillWithBlocks(world, start, -8, -51, 17, -6, -51, 19, Blocks.STONE_BRICKS.getDefaultState());
        structure.fillWithBlocks(world, start, -8, -50, -1, -7, -50, 0, Blocks.STONE_BRICKS.getDefaultState());
        structure.fillWithBlocks(world, start, -8, -50, 6, -6, -50, 8, Blocks.AIR.getDefaultState());
        structure.fillWithBlocks(world, start, -8, -49, 11, -8, -48, 11, Blocks.AIR.getDefaultState());
        structure.fillWithBlocks(world, start, -8, -49, 12, -7, -49, 13, Blocks.STONE_BRICKS.getDefaultState());
        structure.fillWithBlocks(world, start, -8, -49, 14, -8, -48, 14, Blocks.AIR.getDefaultState());
        structure.fillWithBlocks(world, start, -8, -49, 15, -4, -49, 19, Blocks.STONE_BRICKS.getDefaultState());
        structure.fillWithBlocks(world, start, -8, -48, 9, -7, -48, 10, Blocks.STONE_BRICKS.getDefaultState());
        structure.fillWithBlocks(world, start, -8, -48, 12, -7, -48, 13, Blocks.STONE_BRICKS.getDefaultState());
        structure.fillWithBlocks(world, start, -8, -48, 15, -6, -46, 15, Blocks.STONE_BRICKS.getDefaultState());
        structure.fillWithBlocks(world, start, -8, -48, 16, -7, -48, 16, Blocks.AIR.getDefaultState());
        structure.fillWithBlocks(world, start, -8, -48, 17, -6, -48, 19, Blocks.STONE_BRICKS.getDefaultState());
        structure.fillWithBlocks(world, start, -8, -47, -3, -6, -47, 2, Blocks.STONE_BRICKS.getDefaultState());
        structure.fillWithBlocks(world, start, -8, -47, 6, -5, -47, 16, Blocks.STONE_BRICKS.getDefaultState());
        structure.fillWithBlocks(world, start, -8, -47, 21, -8, -46, 21, Blocks.STONE_BRICKS.getDefaultState());
        structure.fillWithBlocks(world, start, -8, -47, 22, -8, -47, 23, Blocks.MOSSY_STONE_BRICKS.getDefaultState());
        structure.fillWithBlocks(world, start, -8, -47, 29, -4, -47, 29, Blocks.STONE_BRICKS.getDefaultState());
        structure.fillWithBlocks(world, start, -8, -46, -1, -8, -46, 0, Blocks.MOSSY_STONE_BRICKS.getDefaultState());
        structure.fillWithBlocks(world, start, -8, -46, 1, -8, -46, 3, Blocks.STONE_BRICKS.getDefaultState());
        structure.fillWithBlocks(world, start, -8, -46, 4, -8, -46, 5, Blocks.MOSSY_STONE_BRICKS.getDefaultState());
        structure.fillWithBlocks(world, start, -8, -46, 6, -7, -46, 6, Blocks.MOSSY_COBBLESTONE.getDefaultState());
        structure.fillWithBlocks(world, start, -8, -46, 9, -8, -46, 9, Blocks.MOSSY_COBBLESTONE.getDefaultState());
        structure.fillWithBlocks(world, start, -8, -46, 10, -8, -46, 10, Blocks.MOSSY_STONE_BRICKS.getDefaultState());
        structure.fillWithBlocks(world, start, -8, -46, 11, -8, -46, 13, Blocks.MOSSY_COBBLESTONE.getDefaultState());
        structure.fillWithBlocks(world, start, -8, -46, 24, -8, -46, 25, Blocks.MOSSY_COBBLESTONE.getDefaultState());
        structure.fillWithBlocks(world, start, -8, -46, 31, -7, -46, 31, Blocks.STONE_BRICKS.getDefaultState());
        structure.fillWithBlocks(world, start, -8, -45, 0, -8, -45, 0, Blocks.MOSSY_STONE_BRICKS.getDefaultState());
        structure.fillWithBlocks(world, start, -8, -45, 1, -8, -44, 1, Blocks.STONE_BRICKS.getDefaultState());
        structure.fillWithBlocks(world, start, -8, -45, 3, -7, -45, 3, Blocks.STONE_BRICKS.getDefaultState());
        structure.fillWithBlocks(world, start, -8, -45, 4, -8, -45, 4, Blocks.AIR.getDefaultState());
        structure.fillWithBlocks(world, start, -8, -45, 6, -8, -44, 14, Blocks.AIR.getDefaultState());
        structure.fillWithBlocks(world, start, -8, -45, 16, -5, -45, 16, Blocks.STONE_BRICK_WALL.getDefaultState().with(WallBlock.WATERLOGGED, false).with(WallBlock.UP, true).with(WallBlock.WALL_HEIGHT_NORTH, WallHeight.LOW).with(WallBlock.WALL_HEIGHT_SOUTH, WallHeight.LOW).with(WallBlock.WALL_HEIGHT_EAST, WallHeight.LOW).with(WallBlock.WALL_HEIGHT_WEST, WallHeight.LOW));
        structure.fillWithBlocks(world, start, -8, -44, 3, -8, -40, 3, Blocks.STONE_BRICKS.getDefaultState());
        structure.fillWithBlocks(world, start, -8, -44, 4, -7, -44, 6, Blocks.AIR.getDefaultState());
        structure.fillWithBlocks(world, start, -8, -43, -1, -8, -40, -1, Blocks.STONE_BRICKS.getDefaultState());
        structure.fillWithBlocks(world, start, -8, -43, 1, -6, -43, 1, Blocks.AIR.getDefaultState());
        structure.fillWithBlocks(world, start, -8, -43, 2, -7, -43, 2, Blocks.MOSSY_STONE_BRICKS.getDefaultState());
        structure.fillWithBlocks(world, start, -8, -43, 4, -7, -43, 6, Blocks.AIR.getDefaultState());
        structure.fillWithBlocks(world, start, -8, -42, 0, -8, -41, 1, Blocks.STONE_BRICKS.getDefaultState());
        structure.fillWithBlocks(world, start, -8, -41, 2, -8, -41, 4, Blocks.STONE_BRICKS.getDefaultState());
        structure.fillWithBlocks(world, start, -8, -41, 6, -8, -39, 6, Blocks.MOSSY_STONE_BRICKS.getDefaultState());
        structure.fillWithBlocks(world, start, -8, -41, 8, -7, -40, 8, Blocks.STONE_BRICKS.getDefaultState());
        structure.fillWithBlocks(world, start, -8, -41, 20, -8, -39, 20, Blocks.STONE_BRICKS.getDefaultState());
        structure.fillWithBlocks(world, start, -8, -40, 0, -8, -39, 0, Blocks.MOSSY_STONE_BRICKS.getDefaultState());
        structure.fillWithBlocks(world, start, -8, -40, 1, -8, -39, 1, Blocks.STONE_BRICKS.getDefaultState());
        structure.fillWithBlocks(world, start, -8, -40, 5, -8, -40, 6, Blocks.MOSSY_STONE_BRICKS.getDefaultState());
        structure.fillWithBlocks(world, start, -8, -40, 7, -7, -40, 7, Blocks.MOSSY_COBBLESTONE.getDefaultState());
        structure.fillWithBlocks(world, start, -8, -40, 9, -6, -40, 9, Blocks.STONE_BRICKS.getDefaultState());
        structure.fillWithBlocks(world, start, -8, -40, 13, -5, -40, 13, Blocks.STONE_BRICKS.getDefaultState());
        structure.fillWithBlocks(world, start, -8, -40, 14, -8, -40, 14, Blocks.AIR.getDefaultState());
        structure.fillWithBlocks(world, start, -8, -40, 16, -8, -40, 16, Blocks.MOSSY_STONE_BRICKS.getDefaultState());
        structure.fillWithBlocks(world, start, -8, -40, 17, -8, -36, 17, Blocks.STONE_BRICKS.getDefaultState());
        structure.fillWithBlocks(world, start, -8, -40, 18, -8, -40, 19, Blocks.MOSSY_STONE_BRICKS.getDefaultState());
        structure.fillWithBlocks(world, start, -8, -40, 21, -7, -40, 22, Blocks.STONE_BRICKS.getDefaultState());
        structure.fillWithBlocks(world, start, -8, -40, 23, -8, -40, 27, Blocks.STONE_BRICKS.getDefaultState());
        structure.fillWithBlocks(world, start, -8, -40, 29, -5, -39, 29, Blocks.STONE_BRICKS.getDefaultState());
        structure.fillWithBlocks(world, start, -8, -40, 31, -7, -39, 31, Blocks.STONE_BRICKS.getDefaultState());
        structure.fillWithBlocks(world, start, -8, -39, -1, -8, -39, 0, Blocks.MOSSY_STONE_BRICKS.getDefaultState());
        structure.fillWithBlocks(world, start, -8, -39, 3, -8, -38, 4, Blocks.MOSSY_STONE_BRICKS.getDefaultState());
        structure.fillWithBlocks(world, start, -8, -39, 7, -8, -39, 8, Blocks.STONE_BRICKS.getDefaultState());
        structure.fillWithBlocks(world, start, -8, -39, 9, -8, -39, 10, Blocks.MOSSY_STONE_BRICKS.getDefaultState());
        structure.fillWithBlocks(world, start, -8, -39, 13, -8, -39, 13, Blocks.MOSSY_STONE_BRICKS.getDefaultState());
        structure.fillWithBlocks(world, start, -8, -39, 14, -8, -38, 14, Blocks.STONE_BRICKS.getDefaultState());
        structure.fillWithBlocks(world, start, -8, -39, 15, -8, -38, 15, Blocks.MOSSY_COBBLESTONE.getDefaultState());
        structure.fillWithBlocks(world, start, -8, -39, 16, -8, -38, 17, Blocks.STONE_BRICKS.getDefaultState());
        structure.fillWithBlocks(world, start, -8, -39, 18, -8, -38, 18, Blocks.MOSSY_STONE_BRICKS.getDefaultState());
        structure.fillWithBlocks(world, start, -8, -39, 19, -7, -39, 20, Blocks.STONE_BRICKS.getDefaultState());
        structure.fillWithBlocks(world, start, -8, -39, 22, -8, -39, 23, Blocks.STONE_BRICKS.getDefaultState());
        structure.fillWithBlocks(world, start, -8, -39, 25, -8, -38, 26, Blocks.STONE_BRICKS.getDefaultState());
        structure.fillWithBlocks(world, start, -8, -39, 27, -8, -39, 27, Blocks.MOSSY_STONE_BRICKS.getDefaultState());
        structure.fillWithBlocks(world, start, -8, -39, 28, -8, -39, 29, Blocks.STONE_BRICKS.getDefaultState());
        structure.fillWithBlocks(world, start, -8, -38, -1, -8, -38, 0, Blocks.STONE_BRICKS.getDefaultState());
        structure.fillWithBlocks(world, start, -8, -38, 1, -8, -37, 1, Blocks.AIR.getDefaultState());
        structure.fillWithBlocks(world, start, -8, -38, 2, -8, -38, 4, Blocks.MOSSY_STONE_BRICKS.getDefaultState());
        structure.fillWithBlocks(world, start, -8, -38, 6, -8, -38, 6, Blocks.MOSSY_COBBLESTONE.getDefaultState());
        structure.fillWithBlocks(world, start, -8, -38, 10, -8, -38, 11, Blocks.STONE_BRICKS.getDefaultState());
        structure.fillWithBlocks(world, start, -8, -38, 12, -7, -38, 13, Blocks.AIR.getDefaultState());
        structure.fillWithBlocks(world, start, -8, -38, 19, -8, -38, 20, Blocks.MOSSY_STONE_BRICKS.getDefaultState());
        structure.fillWithBlocks(world, start, -8, -38, 21, -8, -38, 22, Blocks.STONE_BRICKS.getDefaultState());
        structure.fillWithBlocks(world, start, -8, -38, 23, -7, -38, 23, Blocks.MOSSY_STONE_BRICKS.getDefaultState());
        structure.fillWithBlocks(world, start, -8, -38, 24, -7, -38, 25, Blocks.STONE_BRICKS.getDefaultState());
        structure.fillWithBlocks(world, start, -8, -38, 30, -8, -38, 31, Blocks.STONE_BRICKS.getDefaultState());
        structure.fillWithBlocks(world, start, -8, -37, -5, -7, -37, -5, Blocks.MOSSY_STONE_BRICKS.getDefaultState());
        structure.fillWithBlocks(world, start, -8, -37, -1, -6, -36, -1, Blocks.STONE_BRICKS.getDefaultState());
        structure.fillWithBlocks(world, start, -8, -37, 0, -8, -37, 4, Blocks.AIR.getDefaultState());
        structure.fillWithBlocks(world, start, -8, -37, 5, -8, -37, 6, Blocks.MOSSY_STONE_BRICKS.getDefaultState());
        structure.fillWithBlocks(world, start, -8, -37, 8, -8, -37, 8, Blocks.AIR.getDefaultState());
        structure.fillWithBlocks(world, start, -8, -37, 9, -8, -36, 9, Blocks.STONE_BRICKS.getDefaultState());
        structure.fillWithBlocks(world, start, -8, -37, 10, -7, -37, 11, Blocks.AIR.getDefaultState());
        structure.fillWithBlocks(world, start, -8, -37, 12, -8, -36, 12, Blocks.STONE_BRICKS.getDefaultState());
        structure.fillWithBlocks(world, start, -8, -37, 13, -7, -37, 14, Blocks.AIR.getDefaultState());
        structure.fillWithBlocks(world, start, -8, -37, 15, -8, -37, 16, Blocks.MOSSY_STONE_BRICKS.getDefaultState());
        structure.fillWithBlocks(world, start, -8, -37, 18, -8, -36, 19, Blocks.STONE_BRICKS.getDefaultState());
        structure.fillWithBlocks(world, start, -8, -37, 21, -6, -37, 21, Blocks.STONE_BRICKS.getDefaultState());
        structure.fillWithBlocks(world, start, -8, -37, 23, -8, -37, 23, Blocks.STONE_BRICKS.getDefaultState());
        structure.fillWithBlocks(world, start, -8, -37, 25, -7, -37, 25, Blocks.STONE_BRICKS.getDefaultState());
        structure.fillWithBlocks(world, start, -8, -37, 28, -7, -37, 29, Blocks.STONE_BRICKS.getDefaultState());
        structure.fillWithBlocks(world, start, -8, -37, 34, -2, -37, 34, Blocks.STONE_BRICKS.getDefaultState());
        structure.fillWithBlocks(world, start, -8, -36, -33, -7, -36, -24, Blocks.STONE_BRICKS.getDefaultState());
        structure.fillWithBlocks(world, start, -8, -36, -13, -7, -36, -5, Blocks.STONE_BRICKS.getDefaultState());
        structure.fillWithBlocks(world, start, -8, -36, 0, -7, -36, 6, Blocks.STONE_BRICKS.getDefaultState());
        structure.fillWithBlocks(world, start, -8, -36, 7, -7, -36, 7, Blocks.MOSSY_COBBLESTONE.getDefaultState());
        structure.fillWithBlocks(world, start, -8, -36, 8, -5, -36, 15, Blocks.STONE_BRICKS.getDefaultState());
        structure.fillWithBlocks(world, start, -8, -36, 22, -8, -36, 22, Blocks.STONE_BRICKS.getDefaultState());
        structure.fillWithBlocks(world, start, -8, -36, 24, -8, -36, 24, Blocks.STONE_BRICKS.getDefaultState());
        structure.fillWithBlocks(world, start, -8, -36, 25, -8, -36, 25, Blocks.MOSSY_STONE_BRICKS.getDefaultState());
        structure.fillWithBlocks(world, start, -8, -36, 26, -8, -36, 30, Blocks.STONE_BRICKS.getDefaultState());
        structure.fillWithBlocks(world, start, -8, -36, 32, -6, -36, 34, Blocks.AIR.getDefaultState());
        structure.fillWithBlocks(world, start, -8, -36, 35, -8, -36, 36, Blocks.STONE_BRICKS.getDefaultState());
        structure.fillWithBlocks(world, start, -8, -35, -33, -7, -35, -32, Blocks.STONE_BRICKS.getDefaultState());
        structure.fillWithBlocks(world, start, -8, -35, -22, -3, -35, -15, Blocks.AIR.getDefaultState());
        structure.fillWithBlocks(world, start, -8, -35, -14, -7, -35, -13, Blocks.STONE_BRICKS.getDefaultState());
        structure.fillWithBlocks(world, start, -8, -35, 25, -6, -35, 27, Blocks.AIR.getDefaultState());
        structure.fillWithBlocks(world, start, -8, -35, 29, -7, -35, 30, Blocks.AIR.getDefaultState());
        structure.fillWithBlocks(world, start, -8, -35, 32, -6, -35, 34, Blocks.AIR.getDefaultState());
        structure.fillWithBlocks(world, start, -8, -34, -33, -8, -33, -33, Blocks.MOSSY_STONE_BRICKS.getDefaultState());
        structure.fillWithBlocks(world, start, -8, -34, -14, -7, -34, -13, Blocks.STONE_BRICKS.getDefaultState());
        structure.fillWithBlocks(world, start, -8, -34, 25, -6, -34, 35, Blocks.AIR.getDefaultState());
        structure.fillWithBlocks(world, start, -8, -34, 36, -8, -31, 36, Blocks.STONE_BRICKS.getDefaultState());
        structure.fillWithBlocks(world, start, -8, -33, -32, -3, -33, -32, Blocks.STONE_BRICKS.getDefaultState());
        structure.fillWithBlocks(world, start, -8, -32, -32, -8, -31, -32, Blocks.CRACKED_STONE_BRICKS.getDefaultState());
        structure.fillWithBlocks(world, start, -8, -32, -9, -8, -32, -9, Blocks.STONE_BRICKS.getDefaultState());
        structure.fillWithBlocks(world, start, -8, -32, -7, -6, -32, -7, Blocks.STONE_BRICKS.getDefaultState());
        structure.fillWithBlocks(world, start, -8, -32, -6, -8, -32, -4, Blocks.MOSSY_STONE_BRICKS.getDefaultState());
        structure.fillWithBlocks(world, start, -8, -32, -3, -8, -31, -1, Blocks.STONE_BRICKS.getDefaultState());
        structure.fillWithBlocks(world, start, -8, -32, 0, -8, -32, 0, Blocks.STONE_BRICKS.getDefaultState());
        structure.fillWithBlocks(world, start, -8, -32, 3, -8, -32, 4, Blocks.MOSSY_STONE_BRICKS.getDefaultState());
        structure.fillWithBlocks(world, start, -8, -32, 5, -7, -32, 6, Blocks.STONE_BRICKS.getDefaultState());
        structure.fillWithBlocks(world, start, -8, -32, 7, -6, -32, 7, Blocks.MOSSY_COBBLESTONE.getDefaultState());
        structure.fillWithBlocks(world, start, -8, -32, 15, -8, -32, 20, Blocks.STONE_BRICKS.getDefaultState());
        structure.fillWithBlocks(world, start, -8, -31, -9, -8, -30, -9, Blocks.MOSSY_STONE_BRICKS.getDefaultState());
        structure.fillWithBlocks(world, start, -8, -31, -7, -8, -31, -7, Blocks.MOSSY_STONE_BRICKS.getDefaultState());
        structure.fillWithBlocks(world, start, -8, -31, -6, -8, -29, -6, Blocks.STONE_BRICKS.getDefaultState());
        structure.fillWithBlocks(world, start, -8, -31, 15, -8, -30, 15, Blocks.MOSSY_COBBLESTONE.getDefaultState());
        structure.fillWithBlocks(world, start, -8, -31, 17, -8, -31, 17, Blocks.STONE_BRICKS.getDefaultState());
        structure.fillWithBlocks(world, start, -8, -31, 35, -8, -30, 35, Blocks.MOSSY_STONE_BRICKS.getDefaultState());
        structure.fillWithBlocks(world, start, -8, -30, -32, -6, -29, -32, Blocks.STONE_BRICKS.getDefaultState());
        structure.fillWithBlocks(world, start, -8, -30, -31, -8, -30, -28, Blocks.MOSSY_STONE_BRICKS.getDefaultState());
        structure.fillWithBlocks(world, start, -8, -30, -27, -8, -29, -27, Blocks.STONE_BRICKS.getDefaultState());
        structure.fillWithBlocks(world, start, -8, -30, -26, -8, -30, -25, Blocks.MOSSY_STONE_BRICKS.getDefaultState());
        structure.fillWithBlocks(world, start, -8, -30, -24, -8, -30, -24, Blocks.STONE_BRICKS.getDefaultState());
        structure.fillWithBlocks(world, start, -8, -30, -22, -7, -30, -21, Blocks.STONE_BRICKS.getDefaultState());
        structure.fillWithBlocks(world, start, -8, -30, -19, -8, -30, -17, Blocks.STONE_BRICKS.getDefaultState());
        structure.fillWithBlocks(world, start, -8, -30, -15, -8, -30, -13, Blocks.STONE_BRICKS.getDefaultState());
        structure.fillWithBlocks(world, start, -8, -30, -10, -8, -30, -9, Blocks.MOSSY_STONE_BRICKS.getDefaultState());
        structure.fillWithBlocks(world, start, -8, -30, -8, -8, -29, -6, Blocks.STONE_BRICKS.getDefaultState());
        structure.fillWithBlocks(world, start, -8, -30, -4, -8, -30, -3, Blocks.STONE_BRICKS.getDefaultState());
        structure.fillWithBlocks(world, start, -8, -30, 4, -8, -30, 6, Blocks.MOSSY_STONE_BRICKS.getDefaultState());
        structure.fillWithBlocks(world, start, -8, -30, 7, -8, -30, 7, Blocks.STONE_BRICKS.getDefaultState());
        structure.fillWithBlocks(world, start, -8, -30, 8, -8, -30, 8, Blocks.MOSSY_COBBLESTONE.getDefaultState());
        structure.fillWithBlocks(world, start, -8, -30, 9, -8, -22, 9, Blocks.STONE_BRICKS.getDefaultState());
        structure.fillWithBlocks(world, start, -8, -30, 14, -8, -30, 15, Blocks.MOSSY_COBBLESTONE.getDefaultState());
        structure.fillWithBlocks(world, start, -8, -30, 16, -8, -29, 18, Blocks.STONE_BRICKS.getDefaultState());
        structure.fillWithBlocks(world, start, -8, -30, 20, -8, -30, 22, Blocks.STONE_BRICKS.getDefaultState());
        structure.fillWithBlocks(world, start, -8, -30, 24, -7, -30, 24, Blocks.STONE_BRICKS.getDefaultState());
        structure.fillWithBlocks(world, start, -8, -30, 25, -6, -30, 25, Blocks.MOSSY_STONE_BRICKS.getDefaultState());
        structure.fillWithBlocks(world, start, -8, -30, 26, -7, -30, 27, Blocks.STONE_BRICKS.getDefaultState());
        structure.fillWithBlocks(world, start, -8, -30, 29, -8, -30, 31, Blocks.STONE_BRICKS.getDefaultState());
        structure.fillWithBlocks(world, start, -8, -30, 34, -8, -30, 36, Blocks.MOSSY_STONE_BRICKS.getDefaultState());
        structure.fillWithBlocks(world, start, -8, -29, -33, -7, -29, -32, Blocks.STONE_BRICKS.getDefaultState());
        structure.fillWithBlocks(world, start, -8, -29, -31, -8, -29, -31, Blocks.MOSSY_STONE_BRICKS.getDefaultState());
        structure.fillWithBlocks(world, start, -8, -29, -30, -8, -29, -25, Blocks.STONE_BRICKS.getDefaultState());
        structure.fillWithBlocks(world, start, -8, -29, -24, -8, -29, -24, Blocks.MOSSY_STONE_BRICKS.getDefaultState());
        structure.fillWithBlocks(world, start, -8, -29, -23, -8, -29, -20, Blocks.STONE_BRICKS.getDefaultState());
        structure.fillWithBlocks(world, start, -8, -29, -19, -8, -29, -18, Blocks.MOSSY_STONE_BRICKS.getDefaultState());
        structure.fillWithBlocks(world, start, -8, -29, -16, -7, -28, -16, Blocks.STONE_BRICKS.getDefaultState());
        structure.fillWithBlocks(world, start, -8, -29, -15, -6, -29, -15, Blocks.MOSSY_STONE_BRICKS.getDefaultState());
        structure.fillWithBlocks(world, start, -8, -29, -14, -8, -28, -13, Blocks.STONE_BRICKS.getDefaultState());
        structure.fillWithBlocks(world, start, -8, -29, -10, -7, -29, -6, Blocks.STONE_BRICKS.getDefaultState());
        structure.fillWithBlocks(world, start, -8, -29, -4, -8, -29, -4, Blocks.STONE_BRICKS.getDefaultState());
        structure.fillWithBlocks(world, start, -8, -29, -3, -8, -29, -3, Blocks.MOSSY_STONE_BRICKS.getDefaultState());
        structure.fillWithBlocks(world, start, -8, -29, 4, -8, -29, 4, Blocks.MOSSY_STONE_BRICKS.getDefaultState());
        structure.fillWithBlocks(world, start, -8, -29, 7, -8, -29, 10, Blocks.STONE_BRICKS.getDefaultState());
        structure.fillWithBlocks(world, start, -8, -29, 11, -8, -28, 11, Blocks.MOSSY_STONE_BRICKS.getDefaultState());
        structure.fillWithBlocks(world, start, -8, -29, 12, -7, -29, 14, Blocks.STONE_BRICKS.getDefaultState());
        structure.fillWithBlocks(world, start, -8, -29, 21, -8, -29, 26, Blocks.STONE_BRICKS.getDefaultState());
        structure.fillWithBlocks(world, start, -8, -29, 28, -8, -27, 28, Blocks.STONE_BRICKS.getDefaultState());
        structure.fillWithBlocks(world, start, -8, -29, 31, -6, -29, 33, Blocks.STONE_BRICKS.getDefaultState());
        structure.fillWithBlocks(world, start, -8, -29, 35, -6, -29, 35, Blocks.STONE_BRICKS.getDefaultState());
        structure.fillWithBlocks(world, start, -8, -28, -31, -8, -28, -28, Blocks.STONE_BRICKS.getDefaultState());
        structure.fillWithBlocks(world, start, -8, -28, -27, -8, -27, -27, Blocks.MOSSY_STONE_BRICKS.getDefaultState());
        structure.fillWithBlocks(world, start, -8, -28, -26, -8, -28, -23, Blocks.STONE_BRICKS.getDefaultState());
        structure.fillWithBlocks(world, start, -8, -28, -22, -8, -27, -22, Blocks.MOSSY_STONE_BRICKS.getDefaultState());
        structure.fillWithBlocks(world, start, -8, -28, -21, -8, -27, -21, Blocks.STONE_BRICKS.getDefaultState());
        structure.fillWithBlocks(world, start, -8, -28, -18, -7, -28, -16, Blocks.STONE_BRICKS.getDefaultState());
        structure.fillWithBlocks(world, start, -8, -28, -15, -8, -28, -13, Blocks.STONE_BRICKS.getDefaultState());
        structure.fillWithBlocks(world, start, -8, -28, -10, -8, -27, -10, Blocks.STONE_BRICKS.getDefaultState());
        structure.fillWithBlocks(world, start, -8, -28, -9, -8, -28, -6, Blocks.MOSSY_STONE_BRICKS.getDefaultState());
        structure.fillWithBlocks(world, start, -8, -28, -5, -8, -28, -5, Blocks.STONE_BRICKS.getDefaultState());
        structure.fillWithBlocks(world, start, -8, -28, -3, -8, -28, -3, Blocks.STONE_BRICKS.getDefaultState());
        structure.fillWithBlocks(world, start, -8, -28, 4, -8, -26, 4, Blocks.STONE_BRICKS.getDefaultState());
        structure.fillWithBlocks(world, start, -8, -28, 5, -8, -28, 5, Blocks.MOSSY_STONE_BRICKS.getDefaultState());
        structure.fillWithBlocks(world, start, -8, -28, 6, -8, -28, 10, Blocks.STONE_BRICKS.getDefaultState());
        structure.fillWithBlocks(world, start, -8, -28, 12, -8, -28, 12, Blocks.STONE_BRICKS.getDefaultState());
        structure.fillWithBlocks(world, start, -8, -28, 13, -8, -28, 15, Blocks.MOSSY_STONE_BRICKS.getDefaultState());
        structure.fillWithBlocks(world, start, -8, -28, 16, -7, -28, 16, Blocks.CRACKED_STONE_BRICKS.getDefaultState());
        structure.fillWithBlocks(world, start, -8, -28, 17, -8, -28, 18, Blocks.MOSSY_STONE_BRICKS.getDefaultState());
        structure.fillWithBlocks(world, start, -8, -28, 20, -8, -28, 20, Blocks.STONE_BRICKS.getDefaultState());
        structure.fillWithBlocks(world, start, -8, -28, 22, -8, -28, 29, Blocks.STONE_BRICKS.getDefaultState());
        structure.fillWithBlocks(world, start, -8, -28, 30, -8, -28, 30, Blocks.MOSSY_STONE_BRICKS.getDefaultState());
        structure.fillWithBlocks(world, start, -8, -28, 31, -8, -28, 36, Blocks.STONE_BRICKS.getDefaultState());
        structure.fillWithBlocks(world, start, -8, -27, -32, -8, -27, -32, Blocks.STONE_BRICKS.getDefaultState());
        structure.fillWithBlocks(world, start, -8, -27, -31, -8, -27, -31, Blocks.MOSSY_STONE_BRICKS.getDefaultState());
        structure.fillWithBlocks(world, start, -8, -27, -30, -8, -27, -28, Blocks.STONE_BRICKS.getDefaultState());
        structure.fillWithBlocks(world, start, -8, -27, -26, -8, -27, -26, Blocks.STONE_BRICKS.getDefaultState());
        structure.fillWithBlocks(world, start, -8, -27, -20, -8, -27, -20, Blocks.STONE_BRICKS.getDefaultState());
        structure.fillWithBlocks(world, start, -8, -27, -19, -8, -27, -19, Blocks.MOSSY_STONE_BRICKS.getDefaultState());
        structure.fillWithBlocks(world, start, -8, -27, -18, -8, -27, -16, Blocks.STONE_BRICKS.getDefaultState());
        structure.fillWithBlocks(world, start, -8, -27, -14, -8, -27, -13, Blocks.STONE_BRICKS.getDefaultState());
        structure.fillWithBlocks(world, start, -8, -27, -8, -5, -27, -8, Blocks.STONE_BRICKS.getDefaultState());
        structure.fillWithBlocks(world, start, -8, -27, -7, -7, -27, -7, Blocks.MOSSY_STONE_BRICKS.getDefaultState());
        structure.fillWithBlocks(world, start, -8, -27, -6, -6, -27, -6, Blocks.CRACKED_STONE_BRICKS.getDefaultState());
        structure.fillWithBlocks(world, start, -8, -27, -5, -7, -27, -4, Blocks.STONE_BRICKS.getDefaultState());
        structure.fillWithBlocks(world, start, -8, -27, -2, -2, -27, -2, Blocks.STONE_BRICKS.getDefaultState());
        structure.fillWithBlocks(world, start, -8, -27, 6, -8, -27, 6, Blocks.MOSSY_STONE_BRICKS.getDefaultState());
        structure.fillWithBlocks(world, start, -8, -27, 7, -8, -27, 9, Blocks.STONE_BRICKS.getDefaultState());
        structure.fillWithBlocks(world, start, -8, -27, 11, -8, -27, 17, Blocks.STONE_BRICKS.getDefaultState());
        structure.fillWithBlocks(world, start, -8, -27, 18, -7, -27, 18, Blocks.MOSSY_STONE_BRICKS.getDefaultState());
        structure.fillWithBlocks(world, start, -8, -27, 22, -8, -27, 22, Blocks.MOSSY_STONE_BRICKS.getDefaultState());
        structure.fillWithBlocks(world, start, -8, -27, 27, -7, -27, 31, Blocks.STONE_BRICKS.getDefaultState());
        structure.fillWithBlocks(world, start, -8, -27, 32, -8, -27, 33, Blocks.STONE_BRICKS.getDefaultState());
        structure.fillWithBlocks(world, start, -8, -27, 35, -8, -27, 35, Blocks.STONE_BRICKS.getDefaultState());
        structure.fillWithBlocks(world, start, -8, -26, 5, -8, -25, 5, Blocks.CRACKED_STONE_BRICKS.getDefaultState());
        structure.fillWithBlocks(world, start, -8, -26, 8, -7, -26, 12, Blocks.STONE_BRICKS.getDefaultState());
        structure.fillWithBlocks(world, start, -8, -26, 17, -8, -26, 17, Blocks.STONE_BRICKS.getDefaultState());
        structure.fillWithBlocks(world, start, -8, -26, 40, -6, -26, 42, Blocks.STONE_BRICKS.getDefaultState());
        structure.fillWithBlocks(world, start, -8, -26, 70, -8, -26, 70, Blocks.STONE_BRICKS.getDefaultState());
        structure.fillWithBlocks(world, start, -8, -26, 72, -5, -26, 75, Blocks.STONE_BRICKS.getDefaultState());
        structure.fillWithBlocks(world, start, -8, -26, 76, -8, -26, 76, Blocks.CRACKED_STONE_BRICKS.getDefaultState());
        structure.fillWithBlocks(world, start, -8, -26, 77, -8, -26, 78, Blocks.STONE_BRICKS.getDefaultState());
        structure.fillWithBlocks(world, start, -8, -26, 84, -8, -26, 85, Blocks.CRACKED_STONE_BRICKS.getDefaultState());
        structure.fillWithBlocks(world, start, -8, -26, 86, -8, -26, 86, Blocks.STONE_BRICKS.getDefaultState());
        structure.fillWithBlocks(world, start, -8, -26, 88, -5, -26, 88, Blocks.STONE_BRICKS.getDefaultState());
        structure.fillWithBlocks(world, start, -8, -26, 89, -8, -26, 90, Blocks.CRACKED_STONE_BRICKS.getDefaultState());
        structure.fillWithBlocks(world, start, -8, -26, 91, -8, -26, 93, Blocks.STONE_BRICKS.getDefaultState());
        structure.fillWithBlocks(world, start, -8, -26, 95, -7, -26, 97, Blocks.STONE_BRICKS.getDefaultState());
        structure.fillWithBlocks(world, start, -8, -25, 6, -8, -20, 6, Blocks.STONE_BRICKS.getDefaultState());
