package mod.arcalitegames.odyssey.world.structure.structures.ruins.kagrenzal;

import mod.arcalitegames.buildersaddition.Index;
import mod.arcalitegames.buildersaddition.blocks.Bookshelf;
import mod.arcalitegames.buildersaddition.blocks.VerticalSlab;
import mod.arcalitegames.buildersaddition.state.VerticalSlabState;
import mod.arcalitegames.odyssey.world.structure.StructureBase;
import net.minecraft.block.AbstractFurnaceBlock;
import net.minecraft.block.BarrelBlock;
import net.minecraft.block.Blocks;
import net.minecraft.block.CauldronBlock;
import net.minecraft.block.ChainBlock;
import net.minecraft.block.ComposterBlock;
import net.minecraft.block.FourWayBlock;
import net.minecraft.block.HorizontalBlock;
import net.minecraft.block.LeavesBlock;
import net.minecraft.block.SlabBlock;
import net.minecraft.block.SnowyDirtBlock;
import net.minecraft.block.StairsBlock;
import net.minecraft.block.TrapDoorBlock;
import net.minecraft.block.WallBlock;
import net.minecraft.block.WallHeight;
import net.minecraft.block.WallTorchBlock;
import net.minecraft.state.properties.Half;
import net.minecraft.state.properties.SlabType;
import net.minecraft.state.properties.StairsShape;
import net.minecraft.util.Direction;
import net.minecraft.util.math.BlockPos;
import net.minecraft.world.World;

public class KagrenzalComponent1
{

	public static BlockPos start;
    public static World world;
    public static StructureBase structure;

    public static void init(World worldIn, BlockPos blockPos, StructureBase structureIn)
    {
        world = worldIn; start = blockPos; structure = structureIn;
    }
    
    public static void generatePart11()
    {
        structure.setBlockState(world, Blocks.OAK_LEAVES.getDefaultState().with(LeavesBlock.PERSISTENT, false).with(LeavesBlock.DISTANCE, 3), -204, 11, -57, start);
        structure.setBlockState(world, Blocks.OAK_LEAVES.getDefaultState().with(LeavesBlock.PERSISTENT, false).with(LeavesBlock.DISTANCE, 1), -204, 11, -49, start);
        structure.setBlockState(world, Blocks.OAK_LEAVES.getDefaultState().with(LeavesBlock.PERSISTENT, false).with(LeavesBlock.DISTANCE, 2), -204, 12, -54, start);
        structure.setBlockState(world, Blocks.OAK_LEAVES.getDefaultState().with(LeavesBlock.PERSISTENT, false).with(LeavesBlock.DISTANCE, 2), -204, 12, -33, start);
        structure.setBlockState(world, Blocks.OAK_LEAVES.getDefaultState().with(LeavesBlock.PERSISTENT, false).with(LeavesBlock.DISTANCE, 2), -204, 12, 19, start);
        structure.setBlockState(world, Blocks.OAK_LEAVES.getDefaultState().with(LeavesBlock.PERSISTENT, false).with(LeavesBlock.DISTANCE, 2), -204, 13, -59, start);
        structure.setBlockState(world, Blocks.OAK_LEAVES.getDefaultState().with(LeavesBlock.PERSISTENT, false).with(LeavesBlock.DISTANCE, 1), -204, 13, 10, start);
        structure.setBlockState(world, Blocks.OAK_LEAVES.getDefaultState().with(LeavesBlock.PERSISTENT, false).with(LeavesBlock.DISTANCE, 2), -204, 13, 11, start);
        structure.setBlockState(world, Blocks.STONE.getDefaultState(), -203, 1, -30, start);
        structure.setBlockState(world, Blocks.DIRT.getDefaultState(), -203, 6, -46, start);
        structure.setBlockState(world, Blocks.DIRT.getDefaultState(), -203, 6, -30, start);
        structure.setBlockState(world, Blocks.DIRT.getDefaultState(), -203, 6, -22, start);
        structure.setBlockState(world, Blocks.DIRT.getDefaultState(), -203, 6, -17, start);
        structure.setBlockState(world, Blocks.DIRT.getDefaultState(), -203, 6, -3, start);
        structure.setBlockState(world, Blocks.DIRT.getDefaultState(), -203, 6, 14, start);
        structure.setBlockState(world, Blocks.GRASS.getDefaultState(), -203, 7, -49, start);
        structure.setBlockState(world, Blocks.GRASS.getDefaultState(), -203, 7, -44, start);
        structure.setBlockState(world, Blocks.GRASS.getDefaultState(), -203, 7, -40, start);
        structure.setBlockState(world, Blocks.GRASS.getDefaultState(), -203, 7, -34, start);
        structure.setBlockState(world, Blocks.GRASS.getDefaultState(), -203, 7, -28, start);
        structure.setBlockState(world, Blocks.GRASS.getDefaultState(), -203, 7, -23, start);
        structure.setBlockState(world, Blocks.GRASS.getDefaultState(), -203, 7, -12, start);
        structure.setBlockState(world, Blocks.GRASS.getDefaultState(), -203, 7, -7, start);
        structure.setBlockState(world, Blocks.GRASS.getDefaultState(), -203, 7, -4, start);
        structure.setBlockState(world, Blocks.GRASS.getDefaultState(), -203, 7, 1, start);
        structure.setBlockState(world, Blocks.GRASS.getDefaultState(), -203, 7, 13, start);
        structure.setBlockState(world, Blocks.GRASS.getDefaultState(), -203, 7, 24, start);
        structure.setBlockState(world, Blocks.OAK_LEAVES.getDefaultState().with(LeavesBlock.PERSISTENT, false).with(LeavesBlock.DISTANCE, 4), -203, 10, -52, start);
        structure.setBlockState(world, Blocks.OAK_LEAVES.getDefaultState().with(LeavesBlock.PERSISTENT, false).with(LeavesBlock.DISTANCE, 4), -203, 10, 17, start);
        structure.setBlockState(world, Blocks.OAK_LEAVES.getDefaultState().with(LeavesBlock.PERSISTENT, false).with(LeavesBlock.DISTANCE, 3), -203, 10, 18, start);
        structure.setBlockState(world, Blocks.OAK_LEAVES.getDefaultState().with(LeavesBlock.PERSISTENT, false).with(LeavesBlock.DISTANCE, 1), -203, 11, -22, start);
        structure.setBlockState(world, Blocks.OAK_LEAVES.getDefaultState().with(LeavesBlock.PERSISTENT, false).with(LeavesBlock.DISTANCE, 2), -203, 11, -21, start);
        structure.setBlockState(world, Blocks.OAK_LEAVES.getDefaultState().with(LeavesBlock.PERSISTENT, false).with(LeavesBlock.DISTANCE, 1), -203, 11, -17, start);
        structure.setBlockState(world, Blocks.OAK_LEAVES.getDefaultState().with(LeavesBlock.PERSISTENT, false).with(LeavesBlock.DISTANCE, 2), -203, 11, -16, start);
        structure.setBlockState(world, Blocks.OAK_LEAVES.getDefaultState().with(LeavesBlock.PERSISTENT, false).with(LeavesBlock.DISTANCE, 3), -203, 11, 12, start);
        structure.setBlockState(world, Blocks.OAK_LEAVES.getDefaultState().with(LeavesBlock.PERSISTENT, false).with(LeavesBlock.DISTANCE, 1), -203, 11, 14, start);
        structure.setBlockState(world, Blocks.OAK_LEAVES.getDefaultState().with(LeavesBlock.PERSISTENT, false).with(LeavesBlock.DISTANCE, 2), -203, 11, 15, start);
        structure.setBlockState(world, Blocks.OAK_LEAVES.getDefaultState().with(LeavesBlock.PERSISTENT, false).with(LeavesBlock.DISTANCE, 1), -203, 12, -3, start);
        structure.setBlockState(world, Blocks.OAK_LEAVES.getDefaultState().with(LeavesBlock.PERSISTENT, false).with(LeavesBlock.DISTANCE, 2), -203, 12, -2, start);
        structure.setBlockState(world, Blocks.OAK_LEAVES.getDefaultState().with(LeavesBlock.PERSISTENT, false).with(LeavesBlock.DISTANCE, 1), -203, 13, -46, start);
        structure.setBlockState(world, Blocks.OAK_LEAVES.getDefaultState().with(LeavesBlock.PERSISTENT, false).with(LeavesBlock.DISTANCE, 2), -203, 13, -45, start);
        structure.setBlockState(world, Blocks.OAK_LEAVES.getDefaultState().with(LeavesBlock.PERSISTENT, false).with(LeavesBlock.DISTANCE, 1), -203, 13, -30, start);
        structure.setBlockState(world, Blocks.OAK_LEAVES.getDefaultState().with(LeavesBlock.PERSISTENT, false).with(LeavesBlock.DISTANCE, 2), -203, 13, -29, start);
        structure.setBlockState(world, Blocks.OAK_LEAVES.getDefaultState().with(LeavesBlock.PERSISTENT, false).with(LeavesBlock.DISTANCE, 2), -203, 13, 10, start);
        structure.setBlockState(world, Blocks.STONE.getDefaultState(), -202, 1, -61, start);
        structure.setBlockState(world, Blocks.GRASS.getDefaultState(), -202, 7, -35, start);
        structure.setBlockState(world, Blocks.GRASS.getDefaultState(), -202, 7, -24, start);
        structure.setBlockState(world, Blocks.GRASS.getDefaultState(), -202, 7, -19, start);
        structure.setBlockState(world, Blocks.GRASS.getDefaultState(), -202, 7, 3, start);
        structure.setBlockState(world, Blocks.GRASS.getDefaultState(), -202, 7, 10, start);
        structure.setBlockState(world, Blocks.OAK_LEAVES.getDefaultState().with(LeavesBlock.PERSISTENT, false).with(LeavesBlock.DISTANCE, 4), -202, 8, -51, start);
        structure.setBlockState(world, Blocks.OAK_LEAVES.getDefaultState().with(LeavesBlock.PERSISTENT, false).with(LeavesBlock.DISTANCE, 2), -202, 8, -47, start);
        structure.setBlockState(world, Blocks.OAK_LEAVES.getDefaultState().with(LeavesBlock.PERSISTENT, false).with(LeavesBlock.DISTANCE, 2), -202, 11, -22, start);
        structure.setBlockState(world, Blocks.OAK_LEAVES.getDefaultState().with(LeavesBlock.PERSISTENT, false).with(LeavesBlock.DISTANCE, 2), -202, 11, -17, start);
        structure.setBlockState(world, Blocks.OAK_LEAVES.getDefaultState().with(LeavesBlock.PERSISTENT, false).with(LeavesBlock.DISTANCE, 3), -202, 11, 11, start);
        structure.setBlockState(world, Blocks.OAK_LEAVES.getDefaultState().with(LeavesBlock.PERSISTENT, false).with(LeavesBlock.DISTANCE, 2), -202, 11, 14, start);
        structure.setBlockState(world, Blocks.OAK_LEAVES.getDefaultState().with(LeavesBlock.PERSISTENT, false).with(LeavesBlock.DISTANCE, 2), -202, 12, -3, start);
        structure.setBlockState(world, Blocks.OAK_LEAVES.getDefaultState().with(LeavesBlock.PERSISTENT, false).with(LeavesBlock.DISTANCE, 2), -202, 13, -46, start);
        structure.setBlockState(world, Blocks.OAK_LEAVES.getDefaultState().with(LeavesBlock.PERSISTENT, false).with(LeavesBlock.DISTANCE, 2), -202, 13, -30, start);
        structure.setBlockState(world, Blocks.OAK_LEAVES.getDefaultState().with(LeavesBlock.PERSISTENT, false).with(LeavesBlock.DISTANCE, 4), -201, 8, -19, start);
        structure.setBlockState(world, Blocks.OAK_LEAVES.getDefaultState().with(LeavesBlock.PERSISTENT, false).with(LeavesBlock.DISTANCE, 4), -201, 9, -24, start);
        structure.setBlockState(world, Blocks.OAK_LEAVES.getDefaultState().with(LeavesBlock.PERSISTENT, false).with(LeavesBlock.DISTANCE, 4), -201, 9, -15, start);
        structure.setBlockState(world, Blocks.OAK_LEAVES.getDefaultState().with(LeavesBlock.PERSISTENT, false).with(LeavesBlock.DISTANCE, 4), -201, 9, -5, start);
        structure.setBlockState(world, Blocks.OAK_LEAVES.getDefaultState().with(LeavesBlock.PERSISTENT, false).with(LeavesBlock.DISTANCE, 4), -201, 9, -1, start);
        structure.setBlockState(world, Blocks.OAK_LEAVES.getDefaultState().with(LeavesBlock.PERSISTENT, false).with(LeavesBlock.DISTANCE, 4), -201, 9, 12, start);
        structure.setBlockState(world, Blocks.OAK_LEAVES.getDefaultState().with(LeavesBlock.PERSISTENT, false).with(LeavesBlock.DISTANCE, 4), -201, 10, -48, start);
        structure.setBlockState(world, Blocks.OAK_LEAVES.getDefaultState().with(LeavesBlock.PERSISTENT, false).with(LeavesBlock.DISTANCE, 4), -201, 10, -28, start);
        structure.setBlockState(world, Blocks.OAK_LEAVES.getDefaultState().with(LeavesBlock.PERSISTENT, false).with(LeavesBlock.DISTANCE, 4), -201, 11, -32, start);
        structure.setBlockState(world, Blocks.STONE.getDefaultState(), -200, 1, -9, start);
        structure.setBlockState(world, Blocks.STONE.getDefaultState(), -196, 1, 33, start);
        structure.setBlockState(world, Blocks.DIRT.getDefaultState(), -196, 5, 33, start);
        structure.setBlockState(world, Blocks.DIRT.getDefaultState(), -194, 3, 37, start);
        structure.setBlockState(world, Blocks.DIRT.getDefaultState(), -193, 5, 31, start);
        structure.setBlockState(world, Blocks.STONE.getDefaultState(), -192, 1, 30, start);
        structure.setBlockState(world, Blocks.DIRT.getDefaultState(), -192, 5, 30, start);
        structure.setBlockState(world, Blocks.DIRT.getDefaultState(), -191, 0, 39, start);
        structure.setBlockState(world, Blocks.GRASS_BLOCK.getDefaultState().with(SnowyDirtBlock.SNOWY, false), -191, 1, 39, start);
        structure.setBlockState(world, Blocks.GRASS_BLOCK.getDefaultState().with(SnowyDirtBlock.SNOWY, false), -191, 3, 36, start);
        structure.setBlockState(world, Blocks.STONE.getDefaultState(), -190, 0, 32, start);
        structure.setBlockState(world, Blocks.GRASS_BLOCK.getDefaultState().with(SnowyDirtBlock.SNOWY, false), -190, 3, 35, start);
        structure.setBlockState(world, Blocks.DIRT.getDefaultState(), -189, 1, 36, start);
        structure.setBlockState(world, Blocks.DIRT.getDefaultState(), -188, 0, 37, start);
        structure.setBlockState(world, Blocks.GRASS_BLOCK.getDefaultState().with(SnowyDirtBlock.SNOWY, false), -188, 2, 35, start);
        structure.setBlockState(world, Blocks.GRASS_BLOCK.getDefaultState().with(SnowyDirtBlock.SNOWY, false), -188, 4, 32, start);
        structure.setBlockState(world, Blocks.GRASS_BLOCK.getDefaultState().with(SnowyDirtBlock.SNOWY, false), -187, 3, 32, start);
        structure.setBlockState(world, Blocks.DIRT.getDefaultState(), -186, 1, 33, start);
        structure.setBlockState(world, Blocks.DIRT.getDefaultState(), -185, 0, 34, start);
        structure.setBlockState(world, Blocks.DIRT.getDefaultState(), -185, 2, 30, start);
        structure.setBlockState(world, Blocks.STONE.getDefaultState(), -184, 2, -32, start);
        structure.setBlockState(world, Blocks.STONE.getDefaultState(), -181, 0, 4, start);
        structure.fillWithBlocks(world, start, -296, 0, 11, -295, 0, 21, Blocks.GRASS_BLOCK.getDefaultState().with(SnowyDirtBlock.SNOWY, false));
        structure.fillWithBlocks(world, start, -295, 0, 7, -294, 0, 9, Blocks.GRASS_BLOCK.getDefaultState().with(SnowyDirtBlock.SNOWY, false));
        structure.fillWithBlocks(world, start, -295, 0, 10, -295, 0, 25, Blocks.GRASS_BLOCK.getDefaultState().with(SnowyDirtBlock.SNOWY, false));
        structure.fillWithBlocks(world, start, -294, 0, 4, -293, 0, 6, Blocks.GRASS_BLOCK.getDefaultState().with(SnowyDirtBlock.SNOWY, false));
        structure.fillWithBlocks(world, start, -294, 0, 10, -289, 0, 16, Blocks.DIRT.getDefaultState());
        structure.fillWithBlocks(world, start, -294, 0, 17, -291, 0, 22, Blocks.DIRT.getDefaultState());
        structure.fillWithBlocks(world, start, -294, 0, 23, -294, 0, 28, Blocks.GRASS_BLOCK.getDefaultState().with(SnowyDirtBlock.SNOWY, false));
        structure.fillWithBlocks(world, start, -294, 1, 10, -293, 1, 12, Blocks.GRASS_BLOCK.getDefaultState().with(SnowyDirtBlock.SNOWY, false));
        structure.fillWithBlocks(world, start, -294, 1, 13, -294, 1, 22, Blocks.GRASS_BLOCK.getDefaultState().with(SnowyDirtBlock.SNOWY, false));
        structure.fillWithBlocks(world, start, -293, 0, -49, -292, 0, -45, Blocks.GRASS_BLOCK.getDefaultState().with(SnowyDirtBlock.SNOWY, false));
        structure.fillWithBlocks(world, start, -293, 0, -23, -293, 0, -9, Blocks.GRASS_BLOCK.getDefaultState().with(SnowyDirtBlock.SNOWY, false));
        structure.fillWithBlocks(world, start, -293, 0, 2, -292, 0, 3, Blocks.GRASS_BLOCK.getDefaultState().with(SnowyDirtBlock.SNOWY, false));
        structure.fillWithBlocks(world, start, -293, 0, 7, -288, 0, 13, Blocks.DIRT.getDefaultState());
        structure.fillWithBlocks(world, start, -293, 0, 23, -291, 0, 25, Blocks.DIRT.getDefaultState());
        structure.fillWithBlocks(world, start, -293, 0, 26, -293, 0, 30, Blocks.GRASS_BLOCK.getDefaultState().with(SnowyDirtBlock.SNOWY, false));
        structure.fillWithBlocks(world, start, -293, 1, 7, -293, 1, 12, Blocks.GRASS_BLOCK.getDefaultState().with(SnowyDirtBlock.SNOWY, false));
        structure.fillWithBlocks(world, start, -293, 1, 13, -289, 1, 19, Blocks.DIRT.getDefaultState());
        structure.fillWithBlocks(world, start, -293, 1, 20, -293, 1, 25, Blocks.GRASS_BLOCK.getDefaultState().with(SnowyDirtBlock.SNOWY, false));
        structure.fillWithBlocks(world, start, -293, 2, 13, -292, 2, 19, Blocks.GRASS_BLOCK.getDefaultState().with(SnowyDirtBlock.SNOWY, false));
        structure.fillWithBlocks(world, start, -292, 0, -55, -291, 0, -54, Blocks.GRASS_BLOCK.getDefaultState().with(SnowyDirtBlock.SNOWY, false));
        structure.fillWithBlocks(world, start, -292, 0, -53, -292, 0, -38, Blocks.GRASS_BLOCK.getDefaultState().with(SnowyDirtBlock.SNOWY, false));
        structure.fillWithBlocks(world, start, -292, 0, -30, -292, 0, -24, Blocks.GRASS_BLOCK.getDefaultState().with(SnowyDirtBlock.SNOWY, false));
        structure.fillWithBlocks(world, start, -292, 0, -23, -289, 0, -19, Blocks.DIRT.getDefaultState());
        structure.fillWithBlocks(world, start, -292, 0, -18, -290, 0, -10, Blocks.DIRT.getDefaultState());
        structure.fillWithBlocks(world, start, -292, 0, -9, -292, 0, 3, Blocks.GRASS_BLOCK.getDefaultState().with(SnowyDirtBlock.SNOWY, false));
        structure.fillWithBlocks(world, start, -292, 0, 4, -288, 0, 13, Blocks.DIRT.getDefaultState());
        structure.fillWithBlocks(world, start, -292, 0, 26, -290, 0, 28, Blocks.DIRT.getDefaultState());
        structure.fillWithBlocks(world, start, -292, 0, 29, -292, 0, 31, Blocks.GRASS_BLOCK.getDefaultState().with(SnowyDirtBlock.SNOWY, false));
        structure.fillWithBlocks(world, start, -292, 1, -23, -292, 1, -10, Blocks.GRASS_BLOCK.getDefaultState().with(SnowyDirtBlock.SNOWY, false));
        structure.fillWithBlocks(world, start, -292, 1, 4, -291, 1, 5, Blocks.GRASS_BLOCK.getDefaultState().with(SnowyDirtBlock.SNOWY, false));
        structure.fillWithBlocks(world, start, -292, 1, 6, -292, 1, 7, Blocks.GRASS_BLOCK.getDefaultState().with(SnowyDirtBlock.SNOWY, false));
        structure.fillWithBlocks(world, start, -292, 1, 8, -285, 1, 15, Blocks.DIRT.getDefaultState());
        structure.fillWithBlocks(world, start, -292, 1, 20, -288, 1, 24, Blocks.DIRT.getDefaultState());
        structure.fillWithBlocks(world, start, -292, 1, 25, -292, 1, 28, Blocks.GRASS_BLOCK.getDefaultState().with(SnowyDirtBlock.SNOWY, false));
        structure.fillWithBlocks(world, start, -292, 2, 8, -291, 2, 9, Blocks.GRASS_BLOCK.getDefaultState().with(SnowyDirtBlock.SNOWY, false));
        structure.fillWithBlocks(world, start, -292, 2, 10, -292, 2, 24, Blocks.GRASS_BLOCK.getDefaultState().with(SnowyDirtBlock.SNOWY, false));
        structure.fillWithBlocks(world, start, -291, 0, -58, -290, 0, -57, Blocks.GRASS_BLOCK.getDefaultState().with(SnowyDirtBlock.SNOWY, false));
        structure.fillWithBlocks(world, start, -291, 0, -56, -291, 0, -54, Blocks.GRASS_BLOCK.getDefaultState().with(SnowyDirtBlock.SNOWY, false));
        structure.fillWithBlocks(world, start, -291, 0, -53, -287, 0, -49, Blocks.DIRT.getDefaultState());
        structure.fillWithBlocks(world, start, -291, 0, -48, -288, 0, -38, Blocks.DIRT.getDefaultState());
        structure.fillWithBlocks(world, start, -291, 0, -37, -291, 0, -31, Blocks.GRASS_BLOCK.getDefaultState().with(SnowyDirtBlock.SNOWY, false));
        structure.fillWithBlocks(world, start, -291, 0, -30, -286, 0, -23, Blocks.DIRT.getDefaultState());
        structure.fillWithBlocks(world, start, -291, 0, -9, -289, 0, 16, Blocks.DIRT.getDefaultState());
        structure.fillWithBlocks(world, start, -291, 0, 29, -290, 0, 30, Blocks.DIRT.getDefaultState());
        structure.fillWithBlocks(world, start, -291, 0, 31, -291, 0, 33, Blocks.GRASS_BLOCK.getDefaultState().with(SnowyDirtBlock.SNOWY, false));
        structure.fillWithBlocks(world, start, -291, 1, -53, -291, 1, -38, Blocks.GRASS_BLOCK.getDefaultState().with(SnowyDirtBlock.SNOWY, false));
        structure.fillWithBlocks(world, start, -291, 1, -30, -291, 1, -25, Blocks.GRASS_BLOCK.getDefaultState().with(SnowyDirtBlock.SNOWY, false));
        structure.fillWithBlocks(world, start, -291, 1, -24, -286, 1, -18, Blocks.DIRT.getDefaultState());
        structure.fillWithBlocks(world, start, -291, 1, -17, -289, 1, -10, Blocks.DIRT.getDefaultState());
        structure.fillWithBlocks(world, start, -291, 1, -9, -291, 1, 5, Blocks.GRASS_BLOCK.getDefaultState().with(SnowyDirtBlock.SNOWY, false));
        structure.fillWithBlocks(world, start, -291, 1, 6, -285, 1, 15, Blocks.DIRT.getDefaultState());
        structure.fillWithBlocks(world, start, -291, 1, 25, -290, 1, 26, Blocks.DIRT.getDefaultState());
        structure.fillWithBlocks(world, start, -291, 1, 27, -291, 1, 30, Blocks.GRASS_BLOCK.getDefaultState().with(SnowyDirtBlock.SNOWY, false));
        structure.fillWithBlocks(world, start, -291, 2, -24, -291, 2, -10, Blocks.GRASS_BLOCK.getDefaultState().with(SnowyDirtBlock.SNOWY, false));
        structure.fillWithBlocks(world, start, -291, 2, 6, -291, 2, 9, Blocks.GRASS_BLOCK.getDefaultState().with(SnowyDirtBlock.SNOWY, false));
        structure.fillWithBlocks(world, start, -291, 2, 10, -285, 2, 22, Blocks.DIRT.getDefaultState());
        structure.fillWithBlocks(world, start, -291, 2, 23, -291, 2, 26, Blocks.GRASS_BLOCK.getDefaultState().with(SnowyDirtBlock.SNOWY, false));
        structure.fillWithBlocks(world, start, -291, 3, 10, -290, 3, 13, Blocks.GRASS_BLOCK.getDefaultState().with(SnowyDirtBlock.SNOWY, false));
        structure.fillWithBlocks(world, start, -291, 3, 14, -291, 3, 22, Blocks.GRASS_BLOCK.getDefaultState().with(SnowyDirtBlock.SNOWY, false));
        structure.fillWithBlocks(world, start, -290, 0, -61, -289, 0, -60, Blocks.GRASS_BLOCK.getDefaultState().with(SnowyDirtBlock.SNOWY, false));
        structure.fillWithBlocks(world, start, -290, 0, -59, -290, 0, -57, Blocks.GRASS_BLOCK.getDefaultState().with(SnowyDirtBlock.SNOWY, false));
        structure.fillWithBlocks(world, start, -290, 0, -56, -287, 0, -49, Blocks.DIRT.getDefaultState());
        structure.fillWithBlocks(world, start, -290, 0, -37, -288, 0, -22, Blocks.DIRT.getDefaultState());
        structure.fillWithBlocks(world, start, -290, 0, 17, -289, 0, 18, Blocks.STONE.getDefaultState());
        structure.fillWithBlocks(world, start, -290, 0, 19, -290, 2, 25, Blocks.DIRT.getDefaultState());
        structure.fillWithBlocks(world, start, -290, 0, 31, -290, 0, 31, Blocks.DIRT.getDefaultState());
        structure.fillWithBlocks(world, start, -290, 0, 32, -290, 0, 34, Blocks.GRASS_BLOCK.getDefaultState().with(SnowyDirtBlock.SNOWY, false));
        structure.fillWithBlocks(world, start, -290, 1, -56, -290, 1, -53, Blocks.GRASS_BLOCK.getDefaultState().with(SnowyDirtBlock.SNOWY, false));
        structure.fillWithBlocks(world, start, -290, 1, -52, -285, 1, -45, Blocks.DIRT.getDefaultState());
        structure.fillWithBlocks(world, start, -290, 1, -44, -286, 1, -18, Blocks.DIRT.getDefaultState());
        structure.fillWithBlocks(world, start, -290, 1, -9, -288, 1, 15, Blocks.DIRT.getDefaultState());
        structure.fillWithBlocks(world, start, -290, 1, 27, -288, 1, 29, Blocks.DIRT.getDefaultState());
        structure.fillWithBlocks(world, start, -290, 1, 30, -290, 1, 31, Blocks.GRASS_BLOCK.getDefaultState().with(SnowyDirtBlock.SNOWY, false));
        structure.fillWithBlocks(world, start, -290, 2, -52, -290, 2, -26, Blocks.GRASS_BLOCK.getDefaultState().with(SnowyDirtBlock.SNOWY, false));
        structure.fillWithBlocks(world, start, -290, 2, -25, -275, 2, -10, Blocks.DIRT.getDefaultState());
        structure.fillWithBlocks(world, start, -290, 2, -9, -290, 2, 5, Blocks.GRASS_BLOCK.getDefaultState().with(SnowyDirtBlock.SNOWY, false));
        structure.fillWithBlocks(world, start, -290, 2, 6, -281, 2, 15, Blocks.DIRT.getDefaultState());
        structure.fillWithBlocks(world, start, -290, 2, 26, -290, 2, 29, Blocks.GRASS_BLOCK.getDefaultState().with(SnowyDirtBlock.SNOWY, false));
        structure.fillWithBlocks(world, start, -290, 3, -25, -290, 3, -10, Blocks.GRASS_BLOCK.getDefaultState().with(SnowyDirtBlock.SNOWY, false));
        structure.fillWithBlocks(world, start, -290, 3, 6, -289, 3, 7, Blocks.GRASS_BLOCK.getDefaultState().with(SnowyDirtBlock.SNOWY, false));
        structure.fillWithBlocks(world, start, -290, 3, 8, -290, 3, 13, Blocks.GRASS_BLOCK.getDefaultState().with(SnowyDirtBlock.SNOWY, false));
        structure.fillWithBlocks(world, start, -290, 3, 14, -286, 3, 18, Blocks.DIRT.getDefaultState());
        structure.fillWithBlocks(world, start, -290, 3, 19, -290, 3, 25, Blocks.GRASS_BLOCK.getDefaultState().with(SnowyDirtBlock.SNOWY, false));
        structure.fillWithBlocks(world, start, -290, 4, 14, -289, 4, 18, Blocks.GRASS_BLOCK.getDefaultState().with(SnowyDirtBlock.SNOWY, false));
        structure.fillWithBlocks(world, start, -289, 0, -63, -288, 0, -62, Blocks.GRASS_BLOCK.getDefaultState().with(SnowyDirtBlock.SNOWY, false));
        structure.fillWithBlocks(world, start, -289, 0, -59, -283, 0, -53, Blocks.DIRT.getDefaultState());
        structure.fillWithBlocks(world, start, -289, 0, -18, -281, 0, -10, Blocks.STONE.getDefaultState());
        structure.fillWithBlocks(world, start, -289, 0, 19, -286, 0, 22, Blocks.STONE.getDefaultState());
        structure.fillWithBlocks(world, start, -289, 0, 23, -289, 0, 33, Blocks.DIRT.getDefaultState());
        structure.fillWithBlocks(world, start, -289, 0, 34, -289, 0, 36, Blocks.GRASS_BLOCK.getDefaultState().with(SnowyDirtBlock.SNOWY, false));
        structure.fillWithBlocks(world, start, -289, 1, -59, -289, 1, -56, Blocks.GRASS_BLOCK.getDefaultState().with(SnowyDirtBlock.SNOWY, false));
        structure.fillWithBlocks(world, start, -289, 1, -55, -283, 1, -49, Blocks.DIRT.getDefaultState());
        structure.fillWithBlocks(world, start, -289, 1, 25, -286, 1, 30, Blocks.DIRT.getDefaultState());
        structure.fillWithBlocks(world, start, -289, 1, 31, -289, 1, 33, Blocks.GRASS_BLOCK.getDefaultState().with(SnowyDirtBlock.SNOWY, false));
        structure.fillWithBlocks(world, start, -289, 2, -55, -289, 2, -52, Blocks.GRASS_BLOCK.getDefaultState().with(SnowyDirtBlock.SNOWY, false));
        structure.fillWithBlocks(world, start, -289, 2, -51, -279, 2, 15, Blocks.DIRT.getDefaultState());
        structure.fillWithBlocks(world, start, -289, 2, 23, -285, 2, 27, Blocks.DIRT.getDefaultState());
        structure.fillWithBlocks(world, start, -289, 2, 28, -289, 2, 30, Blocks.GRASS_BLOCK.getDefaultState().with(SnowyDirtBlock.SNOWY, false));
        structure.fillWithBlocks(world, start, -289, 3, -51, -289, 3, -26, Blocks.GRASS_BLOCK.getDefaultState().with(SnowyDirtBlock.SNOWY, false));
        structure.fillWithBlocks(world, start, -289, 3, -25, -274, 3, -10, Blocks.DIRT.getDefaultState());
        structure.fillWithBlocks(world, start, -289, 3, -9, -289, 3, 7, Blocks.GRASS_BLOCK.getDefaultState().with(SnowyDirtBlock.SNOWY, false));
        structure.fillWithBlocks(world, start, -289, 3, 8, -274, 3, 23, Blocks.DIRT.getDefaultState());
        structure.fillWithBlocks(world, start, -289, 3, 24, -289, 3, 27, Blocks.GRASS_BLOCK.getDefaultState().with(SnowyDirtBlock.SNOWY, false));
        structure.fillWithBlocks(world, start, -289, 4, -25, -288, 4, -22, Blocks.GRASS_BLOCK.getDefaultState().with(SnowyDirtBlock.SNOWY, false));
        structure.fillWithBlocks(world, start, -289, 4, -21, -289, 4, -10, Blocks.GRASS_BLOCK.getDefaultState().with(SnowyDirtBlock.SNOWY, false));
        structure.fillWithBlocks(world, start, -289, 4, 8, -288, 4, 13, Blocks.GRASS_BLOCK.getDefaultState().with(SnowyDirtBlock.SNOWY, false));
        structure.fillWithBlocks(world, start, -289, 4, 19, -288, 4, 23, Blocks.GRASS_BLOCK.getDefaultState().with(SnowyDirtBlock.SNOWY, false));
        structure.fillWithBlocks(world, start, -288, 0, -64, -287, 0, -63, Blocks.GRASS_BLOCK.getDefaultState().with(SnowyDirtBlock.SNOWY, false));
        structure.fillWithBlocks(world, start, -288, 0, -61, -283, 0, -53, Blocks.DIRT.getDefaultState());
        structure.fillWithBlocks(world, start, -288, 0, -21, -276, 0, -9, Blocks.STONE.getDefaultState());
        structure.fillWithBlocks(world, start, -288, 0, -8, -288, 3, 13, Blocks.DIRT.getDefaultState());
        structure.fillWithBlocks(world, start, -288, 0, 14, -279, 0, 23, Blocks.STONE.getDefaultState());
        structure.fillWithBlocks(world, start, -288, 0, 24, -287, 0, 34, Blocks.DIRT.getDefaultState());
        structure.fillWithBlocks(world, start, -288, 0, 35, -288, 0, 37, Blocks.GRASS_BLOCK.getDefaultState().with(SnowyDirtBlock.SNOWY, false));
        structure.fillWithBlocks(world, start, -288, 1, -61, -288, 1, -59, Blocks.GRASS_BLOCK.getDefaultState().with(SnowyDirtBlock.SNOWY, false));
        structure.fillWithBlocks(world, start, -288, 1, -58, -280, 1, -50, Blocks.DIRT.getDefaultState());
        structure.fillWithBlocks(world, start, -288, 1, -17, -287, 1, -16, Blocks.STONE.getDefaultState());
        structure.fillWithBlocks(world, start, -288, 1, -15, -288, 3, 15, Blocks.DIRT.getDefaultState());
        structure.fillWithBlocks(world, start, -288, 1, 16, -286, 1, 18, Blocks.STONE.getDefaultState());
        structure.fillWithBlocks(world, start, -288, 1, 19, -288, 3, 26, Blocks.DIRT.getDefaultState());
        structure.fillWithBlocks(world, start, -288, 1, 31, -287, 1, 32, Blocks.DIRT.getDefaultState());
        structure.fillWithBlocks(world, start, -288, 1, 33, -288, 1, 34, Blocks.GRASS_BLOCK.getDefaultState().with(SnowyDirtBlock.SNOWY, false));
        structure.fillWithBlocks(world, start, -288, 2, -58, -288, 2, -56, Blocks.GRASS_BLOCK.getDefaultState().with(SnowyDirtBlock.SNOWY, false));
        structure.fillWithBlocks(world, start, -288, 2, -55, -276, 2, -43, Blocks.DIRT.getDefaultState());
        structure.fillWithBlocks(world, start, -288, 2, 28, -287, 2, 29, Blocks.DIRT.getDefaultState());
        structure.fillWithBlocks(world, start, -288, 2, 30, -288, 2, 32, Blocks.GRASS_BLOCK.getDefaultState().with(SnowyDirtBlock.SNOWY, false));
        structure.fillWithBlocks(world, start, -288, 3, -55, -288, 3, -51, Blocks.GRASS_BLOCK.getDefaultState().with(SnowyDirtBlock.SNOWY, false));
        structure.fillWithBlocks(world, start, -288, 3, -50, -212, 3, 26, Blocks.DIRT.getDefaultState());
        structure.fillWithBlocks(world, start, -288, 3, 27, -288, 3, 29, Blocks.GRASS_BLOCK.getDefaultState().with(SnowyDirtBlock.SNOWY, false));
        structure.fillWithBlocks(world, start, -288, 4, -50, -287, 4, -49, Blocks.GRASS_BLOCK.getDefaultState().with(SnowyDirtBlock.SNOWY, false));
        structure.fillWithBlocks(world, start, -288, 4, -48, -288, 4, -22, Blocks.GRASS_BLOCK.getDefaultState().with(SnowyDirtBlock.SNOWY, false));
        structure.fillWithBlocks(world, start, -288, 4, -21, -283, 4, -16, Blocks.DIRT.getDefaultState());
        structure.fillWithBlocks(world, start, -288, 4, -15, -288, 4, 13, Blocks.GRASS_BLOCK.getDefaultState().with(SnowyDirtBlock.SNOWY, false));
        structure.fillWithBlocks(world, start, -288, 4, 14, -284, 4, 18, Blocks.DIRT.getDefaultState());
        structure.fillWithBlocks(world, start, -288, 4, 24, -287, 4, 26, Blocks.GRASS_BLOCK.getDefaultState().with(SnowyDirtBlock.SNOWY, false));
        structure.fillWithBlocks(world, start, -288, 5, -21, -286, 5, -16, Blocks.GRASS_BLOCK.getDefaultState().with(SnowyDirtBlock.SNOWY, false));
        structure.fillWithBlocks(world, start, -288, 5, 14, -285, 5, 18, Blocks.GRASS_BLOCK.getDefaultState().with(SnowyDirtBlock.SNOWY, false));
        structure.fillWithBlocks(world, start, -287, 0, -66, -286, 0, -65, Blocks.GRASS_BLOCK.getDefaultState().with(SnowyDirtBlock.SNOWY, false));
        structure.fillWithBlocks(world, start, -287, 0, -62, -282, 0, -56, Blocks.DIRT.getDefaultState());
        structure.fillWithBlocks(world, start, -287, 0, -48, -276, 0, -37, Blocks.STONE.getDefaultState());
        structure.fillWithBlocks(world, start, -287, 0, -36, -287, 0, -23, Blocks.DIRT.getDefaultState());
        structure.fillWithBlocks(world, start, -287, 0, -22, -259, 0, 6, Blocks.STONE.getDefaultState());
        structure.fillWithBlocks(world, start, -287, 0, 7, -287, 2, 9, Blocks.DIRT.getDefaultState());
        structure.fillWithBlocks(world, start, -287, 0, 10, -274, 0, 23, Blocks.STONE.getDefaultState());
        structure.fillWithBlocks(world, start, -287, 0, 35, -287, 0, 35, Blocks.DIRT.getDefaultState());
        structure.fillWithBlocks(world, start, -287, 0, 36, -287, 0, 38, Blocks.GRASS_BLOCK.getDefaultState().with(SnowyDirtBlock.SNOWY, false));
        structure.fillWithBlocks(world, start, -287, 1, -62, -287, 1, -61, Blocks.GRASS_BLOCK.getDefaultState().with(SnowyDirtBlock.SNOWY, false));
        structure.fillWithBlocks(world, start, -287, 1, -60, -278, 1, -51, Blocks.DIRT.getDefaultState());
        structure.fillWithBlocks(world, start, -287, 1, -15, -285, 1, -13, Blocks.STONE.getDefaultState());
        structure.fillWithBlocks(world, start, -287, 1, -12, -287, 1, -9, Blocks.STONE.getDefaultState());
        structure.fillWithBlocks(world, start, -287, 1, -8, -285, 1, 15, Blocks.DIRT.getDefaultState());
        structure.fillWithBlocks(world, start, -287, 1, 19, -283, 1, 23, Blocks.STONE.getDefaultState());
        structure.fillWithBlocks(world, start, -287, 1, 24, -287, 1, 33, Blocks.DIRT.getDefaultState());
        structure.fillWithBlocks(world, start, -287, 1, 34, -287, 1, 35, Blocks.GRASS_BLOCK.getDefaultState().with(SnowyDirtBlock.SNOWY, false));
        structure.fillWithBlocks(world, start, -287, 2, -60, -287, 2, -58, Blocks.GRASS_BLOCK.getDefaultState().with(SnowyDirtBlock.SNOWY, false));
        structure.fillWithBlocks(world, start, -287, 2, -57, -274, 2, -44, Blocks.DIRT.getDefaultState());
        structure.fillWithBlocks(world, start, -287, 2, 30, -286, 2, 31, Blocks.DIRT.getDefaultState());
        structure.fillWithBlocks(world, start, -287, 2, 32, -287, 2, 33, Blocks.GRASS_BLOCK.getDefaultState().with(SnowyDirtBlock.SNOWY, false));
        structure.fillWithBlocks(world, start, -287, 3, -57, -287, 3, -55, Blocks.GRASS_BLOCK.getDefaultState().with(SnowyDirtBlock.SNOWY, false));
        structure.fillWithBlocks(world, start, -287, 3, -54, -205, 3, 28, Blocks.DIRT.getDefaultState());
        structure.fillWithBlocks(world, start, -287, 3, 29, -287, 3, 31, Blocks.GRASS_BLOCK.getDefaultState().with(SnowyDirtBlock.SNOWY, false));
        structure.fillWithBlocks(world, start, -287, 4, -54, -286, 4, -53, Blocks.GRASS_BLOCK.getDefaultState().with(SnowyDirtBlock.SNOWY, false));
        structure.fillWithBlocks(world, start, -287, 4, -52, -287, 4, -49, Blocks.GRASS_BLOCK.getDefaultState().with(SnowyDirtBlock.SNOWY, false));
        structure.fillWithBlocks(world, start, -287, 4, -48, -216, 4, 23, Blocks.DIRT.getDefaultState());
        structure.fillWithBlocks(world, start, -287, 4, 27, -286, 4, 28, Blocks.GRASS_BLOCK.getDefaultState().with(SnowyDirtBlock.SNOWY, false));
        structure.fillWithBlocks(world, start, -287, 5, -48, -285, 5, -45, Blocks.GRASS_BLOCK.getDefaultState().with(SnowyDirtBlock.SNOWY, false));
        structure.fillWithBlocks(world, start, -287, 5, -44, -286, 5, 23, Blocks.GRASS_BLOCK.getDefaultState().with(SnowyDirtBlock.SNOWY, false));
        structure.fillWithBlocks(world, start, -286, 0, -67, -285, 0, -66, Blocks.GRASS_BLOCK.getDefaultState().with(SnowyDirtBlock.SNOWY, false));
        structure.fillWithBlocks(world, start, -286, 0, -64, -281, 0, -58, Blocks.DIRT.getDefaultState());
        structure.fillWithBlocks(world, start, -286, 0, -52, -286, 0, -36, Blocks.STONE.getDefaultState());
        structure.fillWithBlocks(world, start, -286, 0, -35, -286, 4, -23, Blocks.DIRT.getDefaultState());
        structure.fillWithBlocks(world, start, -286, 0, 7, -268, 0, 25, Blocks.STONE.getDefaultState());
        structure.fillWithBlocks(world, start, -286, 0, 26, -286, 3, 29, Blocks.DIRT.getDefaultState());
        structure.fillWithBlocks(world, start, -286, 0, 30, -284, 0, 36, Blocks.DIRT.getDefaultState());
        structure.fillWithBlocks(world, start, -286, 0, 37, -286, 0, 39, Blocks.GRASS_BLOCK.getDefaultState().with(SnowyDirtBlock.SNOWY, false));
        structure.fillWithBlocks(world, start, -286, 1, -64, -286, 1, -63, Blocks.GRASS_BLOCK.getDefaultState().with(SnowyDirtBlock.SNOWY, false));
        structure.fillWithBlocks(world, start, -286, 1, -62, -276, 1, -52, Blocks.DIRT.getDefaultState());
        structure.fillWithBlocks(world, start, -286, 1, -17, -286, 4, -17, Blocks.DIRT.getDefaultState());
        structure.fillWithBlocks(world, start, -286, 1, -16, -283, 1, -13, Blocks.STONE.getDefaultState());
        structure.fillWithBlocks(world, start, -286, 1, -11, -285, 1, 15, Blocks.DIRT.getDefaultState());
        structure.fillWithBlocks(world, start, -286, 1, 24, -286, 1, 24, Blocks.STONE.getDefaultState());
        structure.fillWithBlocks(world, start, -286, 1, 31, -283, 1, 34, Blocks.DIRT.getDefaultState());
        structure.fillWithBlocks(world, start, -286, 1, 35, -286, 1, 36, Blocks.GRASS_BLOCK.getDefaultState().with(SnowyDirtBlock.SNOWY, false));
        structure.fillWithBlocks(world, start, -286, 2, -62, -286, 2, -60, Blocks.GRASS_BLOCK.getDefaultState().with(SnowyDirtBlock.SNOWY, false));
        structure.fillWithBlocks(world, start, -286, 2, -59, -272, 2, -45, Blocks.DIRT.getDefaultState());
        structure.fillWithBlocks(world, start, -286, 2, 32, -286, 2, 32, Blocks.DIRT.getDefaultState());
        structure.fillWithBlocks(world, start, -286, 2, 33, -286, 2, 34, Blocks.GRASS_BLOCK.getDefaultState().with(SnowyDirtBlock.SNOWY, false));
        structure.fillWithBlocks(world, start, -286, 3, -59, -286, 3, -58, Blocks.GRASS_BLOCK.getDefaultState().with(SnowyDirtBlock.SNOWY, false));
        structure.fillWithBlocks(world, start, -286, 3, -57, -200, 3, 29, Blocks.DIRT.getDefaultState());
        structure.fillWithBlocks(world, start, -286, 3, 30, -286, 3, 32, Blocks.GRASS_BLOCK.getDefaultState().with(SnowyDirtBlock.SNOWY, false));
        structure.fillWithBlocks(world, start, -286, 4, -57, -285, 4, -56, Blocks.GRASS_BLOCK.getDefaultState().with(SnowyDirtBlock.SNOWY, false));
        structure.fillWithBlocks(world, start, -286, 4, -55, -286, 4, -53, Blocks.GRASS_BLOCK.getDefaultState().with(SnowyDirtBlock.SNOWY, false));
        structure.fillWithBlocks(world, start, -286, 4, -52, -209, 4, 25, Blocks.DIRT.getDefaultState());
        structure.fillWithBlocks(world, start, -286, 4, 26, -286, 4, 29, Blocks.GRASS_BLOCK.getDefaultState().with(SnowyDirtBlock.SNOWY, false));
        structure.fillWithBlocks(world, start, -286, 5, -52, -284, 5, -50, Blocks.GRASS_BLOCK.getDefaultState().with(SnowyDirtBlock.SNOWY, false));
        structure.fillWithBlocks(world, start, -286, 5, -49, -285, 5, -45, Blocks.GRASS_BLOCK.getDefaultState().with(SnowyDirtBlock.SNOWY, false));
        structure.fillWithBlocks(world, start, -286, 5, 24, -285, 5, 25, Blocks.GRASS_BLOCK.getDefaultState().with(SnowyDirtBlock.SNOWY, false));
        structure.fillWithBlocks(world, start, -285, 0, -68, -284, 0, -67, Blocks.GRASS_BLOCK.getDefaultState().with(SnowyDirtBlock.SNOWY, false));
        structure.fillWithBlocks(world, start, -285, 0, -65, -280, 0, -59, Blocks.DIRT.getDefaultState());
        structure.fillWithBlocks(world, start, -285, 0, -52, -285, 0, -52, Blocks.DIRT.getDefaultState());
        structure.fillWithBlocks(world, start, -285, 0, -51, -285, 0, 27, Blocks.STONE.getDefaultState());
        structure.fillWithBlocks(world, start, -285, 0, 28, -285, 3, 31, Blocks.DIRT.getDefaultState());
        structure.fillWithBlocks(world, start, -285, 0, 37, -285, 0, 37, Blocks.DIRT.getDefaultState());
        structure.fillWithBlocks(world, start, -285, 0, 38, -285, 0, 39, Blocks.GRASS_BLOCK.getDefaultState().with(SnowyDirtBlock.SNOWY, false));
        structure.fillWithBlocks(world, start, -285, 1, -65, -285, 1, -64, Blocks.GRASS_BLOCK.getDefaultState().with(SnowyDirtBlock.SNOWY, false));
        structure.fillWithBlocks(world, start, -285, 1, -63, -275, 1, -53, Blocks.DIRT.getDefaultState());
        structure.fillWithBlocks(world, start, -285, 1, -44, -275, 1, -34, Blocks.STONE.getDefaultState());
        structure.fillWithBlocks(world, start, -285, 1, -33, -285, 1, -22, Blocks.DIRT.getDefaultState());
        structure.fillWithBlocks(world, start, -285, 1, -21, -284, 1, -13, Blocks.STONE.getDefaultState());
        structure.fillWithBlocks(world, start, -285, 1, -12, -285, 4, 15, Blocks.DIRT.getDefaultState());
        structure.fillWithBlocks(world, start, -285, 1, 16, -276, 1, 25, Blocks.STONE.getDefaultState());
        structure.fillWithBlocks(world, start, -285, 1, 26, -284, 1, 35, Blocks.DIRT.getDefaultState());
        structure.fillWithBlocks(world, start, -285, 1, 36, -285, 1, 37, Blocks.GRASS_BLOCK.getDefaultState().with(SnowyDirtBlock.SNOWY, false));
        structure.fillWithBlocks(world, start, -285, 2, -63, -285, 2, -62, Blocks.GRASS_BLOCK.getDefaultState().with(SnowyDirtBlock.SNOWY, false));
        structure.fillWithBlocks(world, start, -285, 2, -61, -269, 2, -45, Blocks.DIRT.getDefaultState());
        structure.fillWithBlocks(world, start, -285, 2, 32, -284, 2, 33, Blocks.DIRT.getDefaultState());
        structure.fillWithBlocks(world, start, -285, 2, 34, -285, 2, 35, Blocks.GRASS_BLOCK.getDefaultState().with(SnowyDirtBlock.SNOWY, false));
        structure.fillWithBlocks(world, start, -285, 3, -61, -285, 3, -60, Blocks.GRASS_BLOCK.getDefaultState().with(SnowyDirtBlock.SNOWY, false));
        structure.fillWithBlocks(world, start, -285, 3, -59, -195, 3, 31, Blocks.DIRT.getDefaultState());
        structure.fillWithBlocks(world, start, -285, 3, 32, -285, 3, 33, Blocks.GRASS_BLOCK.getDefaultState().with(SnowyDirtBlock.SNOWY, false));
        structure.fillWithBlocks(world, start, -285, 4, -59, -284, 4, -58, Blocks.GRASS_BLOCK.getDefaultState().with(SnowyDirtBlock.SNOWY, false));
        structure.fillWithBlocks(world, start, -285, 4, -55, -203, 4, 27, Blocks.DIRT.getDefaultState());
        structure.fillWithBlocks(world, start, -285, 4, 28, -285, 4, 31, Blocks.GRASS_BLOCK.getDefaultState().with(SnowyDirtBlock.SNOWY, false));
        structure.fillWithBlocks(world, start, -285, 5, -55, -283, 5, -53, Blocks.GRASS_BLOCK.getDefaultState().with(SnowyDirtBlock.SNOWY, false));
        structure.fillWithBlocks(world, start, -285, 5, -44, -254, 5, -13, Blocks.DIRT.getDefaultState());
        structure.fillWithBlocks(world, start, -285, 5, -12, -285, 5, 27, Blocks.GRASS_BLOCK.getDefaultState().with(SnowyDirtBlock.SNOWY, false));
        structure.fillWithBlocks(world, start, -285, 6, -44, -275, 6, -13, Blocks.GRASS_BLOCK.getDefaultState().with(SnowyDirtBlock.SNOWY, false));
        structure.fillWithBlocks(world, start, -284, 0, -69, -283, 0, -68, Blocks.GRASS_BLOCK.getDefaultState().with(SnowyDirtBlock.SNOWY, false));
        structure.fillWithBlocks(world, start, -284, 0, -66, -279, 0, -61, Blocks.DIRT.getDefaultState());
        structure.fillWithBlocks(world, start, -284, 0, -52, -284, 1, -51, Blocks.DIRT.getDefaultState());
        structure.fillWithBlocks(world, start, -284, 0, -50, -205, 0, 29, Blocks.STONE.getDefaultState());
        structure.fillWithBlocks(world, start, -284, 0, 37, -283, 0, 38, Blocks.DIRT.getDefaultState());
        structure.fillWithBlocks(world, start, -284, 0, 39, -284, 0, 40, Blocks.GRASS_BLOCK.getDefaultState().with(SnowyDirtBlock.SNOWY, false));
        structure.fillWithBlocks(world, start, -284, 1, -66, -284, 1, -65, Blocks.GRASS_BLOCK.getDefaultState().with(SnowyDirtBlock.SNOWY, false));
        structure.fillWithBlocks(world, start, -284, 1, -64, -275, 1, -53, Blocks.DIRT.getDefaultState());
        structure.fillWithBlocks(world, start, -284, 1, -48, -269, 1, -33, Blocks.STONE.getDefaultState());
        structure.fillWithBlocks(world, start, -284, 1, -32, -280, 1, -22, Blocks.DIRT.getDefaultState());
        structure.fillWithBlocks(world, start, -284, 1, -12, -282, 1, 25, Blocks.STONE.getDefaultState());
        structure.fillWithBlocks(world, start, -284, 1, 36, -284, 1, 36, Blocks.DIRT.getDefaultState());
        structure.fillWithBlocks(world, start, -284, 1, 37, -284, 1, 38, Blocks.GRASS_BLOCK.getDefaultState().with(SnowyDirtBlock.SNOWY, false));
        structure.fillWithBlocks(world, start, -284, 2, -64, -284, 2, -63, Blocks.GRASS_BLOCK.getDefaultState().with(SnowyDirtBlock.SNOWY, false));
        structure.fillWithBlocks(world, start, -284, 2, -62, -270, 2, -45, Blocks.DIRT.getDefaultState());
        structure.fillWithBlocks(world, start, -284, 2, 16, -281, 2, 19, Blocks.STONE.getDefaultState());
        structure.fillWithBlocks(world, start, -284, 2, 20, -284, 4, 29, Blocks.DIRT.getDefaultState());
        structure.fillWithBlocks(world, start, -284, 2, 30, -280, 2, 34, Blocks.DIRT.getDefaultState());
        structure.fillWithBlocks(world, start, -284, 2, 35, -284, 2, 36, Blocks.GRASS_BLOCK.getDefaultState().with(SnowyDirtBlock.SNOWY, false));
        structure.fillWithBlocks(world, start, -284, 3, -62, -284, 3, -61, Blocks.GRASS_BLOCK.getDefaultState().with(SnowyDirtBlock.SNOWY, false));
        structure.fillWithBlocks(world, start, -284, 3, -60, -192, 3, 32, Blocks.DIRT.getDefaultState());
        structure.fillWithBlocks(world, start, -284, 3, 33, -284, 3, 34, Blocks.GRASS_BLOCK.getDefaultState().with(SnowyDirtBlock.SNOWY, false));
        structure.fillWithBlocks(world, start, -284, 4, -60, -284, 4, -58, Blocks.GRASS_BLOCK.getDefaultState().with(SnowyDirtBlock.SNOWY, false));
        structure.fillWithBlocks(world, start, -284, 4, -57, -198, 4, 29, Blocks.DIRT.getDefaultState());
        structure.fillWithBlocks(world, start, -284, 4, 30, -284, 4, 32, Blocks.GRASS_BLOCK.getDefaultState().with(SnowyDirtBlock.SNOWY, false));
        structure.fillWithBlocks(world, start, -284, 5, -57, -283, 5, -53, Blocks.GRASS_BLOCK.getDefaultState().with(SnowyDirtBlock.SNOWY, false));
        structure.fillWithBlocks(world, start, -284, 5, -49, -216, 5, 19, Blocks.DIRT.getDefaultState());
        structure.fillWithBlocks(world, start, -284, 5, 20, -284, 5, 29, Blocks.GRASS_BLOCK.getDefaultState().with(SnowyDirtBlock.SNOWY, false));
        structure.fillWithBlocks(world, start, -284, 6, -49, -275, 6, 19, Blocks.GRASS_BLOCK.getDefaultState().with(SnowyDirtBlock.SNOWY, false));
        structure.fillWithBlocks(world, start, -283, 0, -70, -282, 0, -69, Blocks.GRASS_BLOCK.getDefaultState().with(SnowyDirtBlock.SNOWY, false));
        structure.fillWithBlocks(world, start, -283, 0, -67, -278, 0, -62, Blocks.DIRT.getDefaultState());
        structure.fillWithBlocks(world, start, -283, 0, -52, -201, 0, 30, Blocks.STONE.getDefaultState());
        structure.fillWithBlocks(world, start, -283, 0, 31, -283, 0, 39, Blocks.DIRT.getDefaultState());
        structure.fillWithBlocks(world, start, -283, 0, 40, -283, 0, 41, Blocks.GRASS_BLOCK.getDefaultState().with(SnowyDirtBlock.SNOWY, false));
        structure.fillWithBlocks(world, start, -283, 1, -66, -275, 1, -53, Blocks.DIRT.getDefaultState());
        structure.fillWithBlocks(world, start, -283, 1, -21, -275, 5, -21, Blocks.DIRT.getDefaultState());
        structure.fillWithBlocks(world, start, -283, 1, -20, -275, 1, -12, Blocks.STONE.getDefaultState());
        structure.fillWithBlocks(world, start, -283, 1, 26, -283, 1, 26, Blocks.STONE.getDefaultState());
        structure.fillWithBlocks(world, start, -283, 1, 27, -283, 1, 37, Blocks.DIRT.getDefaultState());
        structure.fillWithBlocks(world, start, -283, 1, 38, -283, 1, 39, Blocks.GRASS_BLOCK.getDefaultState().with(SnowyDirtBlock.SNOWY, false));
        structure.fillWithBlocks(world, start, -283, 2, -66, -283, 2, -65, Blocks.GRASS_BLOCK.getDefaultState().with(SnowyDirtBlock.SNOWY, false));
        structure.fillWithBlocks(world, start, -283, 2, -64, -270, 2, -45, Blocks.DIRT.getDefaultState());
        structure.fillWithBlocks(world, start, -283, 2, 20, -281, 2, 22, Blocks.STONE.getDefaultState());
        structure.fillWithBlocks(world, start, -283, 2, 23, -283, 4, 30, Blocks.DIRT.getDefaultState());
        structure.fillWithBlocks(world, start, -283, 2, 35, -283, 2, 35, Blocks.DIRT.getDefaultState());
        structure.fillWithBlocks(world, start, -283, 2, 36, -283, 2, 37, Blocks.GRASS_BLOCK.getDefaultState().with(SnowyDirtBlock.SNOWY, false));
        structure.fillWithBlocks(world, start, -283, 3, -64, -283, 3, -63, Blocks.GRASS_BLOCK.getDefaultState().with(SnowyDirtBlock.SNOWY, false));
        structure.fillWithBlocks(world, start, -283, 3, -62, -189, 3, 33, Blocks.DIRT.getDefaultState());
        structure.fillWithBlocks(world, start, -283, 3, 34, -283, 3, 35, Blocks.GRASS_BLOCK.getDefaultState().with(SnowyDirtBlock.SNOWY, false));
        structure.fillWithBlocks(world, start, -283, 4, -62, -282, 4, -61, Blocks.GRASS_BLOCK.getDefaultState().with(SnowyDirtBlock.SNOWY, false));
        structure.fillWithBlocks(world, start, -283, 4, -59, -194, 4, 30, Blocks.DIRT.getDefaultState());
        structure.fillWithBlocks(world, start, -283, 4, 31, -283, 4, 33, Blocks.GRASS_BLOCK.getDefaultState().with(SnowyDirtBlock.SNOWY, false));
        structure.fillWithBlocks(world, start, -283, 5, -59, -282, 5, -56, Blocks.GRASS_BLOCK.getDefaultState().with(SnowyDirtBlock.SNOWY, false));
        structure.fillWithBlocks(world, start, -283, 5, -52, -209, 5, 22, Blocks.DIRT.getDefaultState());
        structure.fillWithBlocks(world, start, -283, 5, 23, -283, 5, 30, Blocks.GRASS_BLOCK.getDefaultState().with(SnowyDirtBlock.SNOWY, false));
        structure.fillWithBlocks(world, start, -283, 6, -52, -275, 6, 22, Blocks.GRASS_BLOCK.getDefaultState().with(SnowyDirtBlock.SNOWY, false));
        structure.fillWithBlocks(world, start, -282, 0, -71, -281, 0, -70, Blocks.GRASS_BLOCK.getDefaultState().with(SnowyDirtBlock.SNOWY, false));
        structure.fillWithBlocks(world, start, -282, 0, -68, -277, 0, -63, Blocks.DIRT.getDefaultState());
        structure.fillWithBlocks(world, start, -282, 0, -55, -196, 0, 31, Blocks.STONE.getDefaultState());
        structure.fillWithBlocks(world, start, -282, 0, 32, -282, 0, 40, Blocks.DIRT.getDefaultState());
        structure.fillWithBlocks(world, start, -282, 0, 41, -282, 0, 41, Blocks.GRASS_BLOCK.getDefaultState().with(SnowyDirtBlock.SNOWY, false));
        structure.fillWithBlocks(world, start, -282, 1, -67, -275, 1, -53, Blocks.DIRT.getDefaultState());
        structure.fillWithBlocks(world, start, -282, 1, -49, -282, 5, -49, Blocks.DIRT.getDefaultState());
        structure.fillWithBlocks(world, start, -282, 1, 26, -281, 1, 27, Blocks.STONE.getDefaultState());
        structure.fillWithBlocks(world, start, -282, 1, 28, -281, 1, 38, Blocks.DIRT.getDefaultState());
        structure.fillWithBlocks(world, start, -282, 1, 39, -281, 1, 40, Blocks.GRASS_BLOCK.getDefaultState().with(SnowyDirtBlock.SNOWY, false));
        structure.fillWithBlocks(world, start, -282, 2, -67, -282, 2, -66, Blocks.GRASS_BLOCK.getDefaultState().with(SnowyDirtBlock.SNOWY, false));
        structure.fillWithBlocks(world, start, -282, 2, -65, -270, 2, -45, Blocks.DIRT.getDefaultState());
        structure.fillWithBlocks(world, start, -282, 2, 23, -280, 2, 25, Blocks.STONE.getDefaultState());
        structure.fillWithBlocks(world, start, -282, 2, 26, -282, 2, 36, Blocks.DIRT.getDefaultState());
        structure.fillWithBlocks(world, start, -282, 2, 37, -282, 2, 38, Blocks.GRASS_BLOCK.getDefaultState().with(SnowyDirtBlock.SNOWY, false));
        structure.fillWithBlocks(world, start, -282, 3, -65, -282, 3, -64, Blocks.GRASS_BLOCK.getDefaultState().with(SnowyDirtBlock.SNOWY, false));
        structure.fillWithBlocks(world, start, -282, 3, -63, -189, 3, 33, Blocks.DIRT.getDefaultState());
        structure.fillWithBlocks(world, start, -282, 3, 34, -282, 3, 34, Blocks.DIRT.getDefaultState());
        structure.fillWithBlocks(world, start, -282, 3, 35, -282, 3, 36, Blocks.GRASS_BLOCK.getDefaultState().with(SnowyDirtBlock.SNOWY, false));
        structure.fillWithBlocks(world, start, -282, 4, -63, -282, 4, -61, Blocks.GRASS_BLOCK.getDefaultState().with(SnowyDirtBlock.SNOWY, false));
        structure.fillWithBlocks(world, start, -282, 4, -60, -191, 4, 31, Blocks.DIRT.getDefaultState());
        structure.fillWithBlocks(world, start, -282, 4, 32, -282, 4, 34, Blocks.GRASS_BLOCK.getDefaultState().with(SnowyDirtBlock.SNOWY, false));
        structure.fillWithBlocks(world, start, -282, 5, -60, -281, 5, -58, Blocks.GRASS_BLOCK.getDefaultState().with(SnowyDirtBlock.SNOWY, false));
        structure.fillWithBlocks(world, start, -282, 5, -55, -202, 5, 25, Blocks.DIRT.getDefaultState());
        structure.fillWithBlocks(world, start, -282, 5, 26, -282, 5, 31, Blocks.GRASS_BLOCK.getDefaultState().with(SnowyDirtBlock.SNOWY, false));
        structure.fillWithBlocks(world, start, -282, 6, -55, -275, 6, 25, Blocks.GRASS_BLOCK.getDefaultState().with(SnowyDirtBlock.SNOWY, false));
        structure.fillWithBlocks(world, start, -281, 0, -72, -280, 0, -71, Blocks.GRASS_BLOCK.getDefaultState().with(SnowyDirtBlock.SNOWY, false));
        structure.fillWithBlocks(world, start, -281, 0, -69, -276, 0, -64, Blocks.DIRT.getDefaultState());
        structure.fillWithBlocks(world, start, -281, 0, -57, -192, 0, 32, Blocks.STONE.getDefaultState());
        structure.fillWithBlocks(world, start, -281, 0, 33, -281, 0, 40, Blocks.DIRT.getDefaultState());
        structure.fillWithBlocks(world, start, -281, 0, 41, -281, 0, 42, Blocks.GRASS_BLOCK.getDefaultState().with(SnowyDirtBlock.SNOWY, false));
        structure.fillWithBlocks(world, start, -281, 1, -69, -280, 1, -69, Blocks.GRASS_BLOCK.getDefaultState().with(SnowyDirtBlock.SNOWY, false));
        structure.fillWithBlocks(world, start, -281, 1, -68, -275, 1, -53, Blocks.DIRT.getDefaultState());
        structure.fillWithBlocks(world, start, -281, 1, -49, -265, 1, -33, Blocks.STONE.getDefaultState());
        structure.fillWithBlocks(world, start, -281, 1, -10, -277, 1, -6, Blocks.DIRT.getDefaultState());
        structure.fillWithBlocks(world, start, -281, 1, -5, -280, 1, 27, Blocks.STONE.getDefaultState());
        structure.fillWithBlocks(world, start, -281, 2, -68, -281, 2, -67, Blocks.GRASS_BLOCK.getDefaultState().with(SnowyDirtBlock.SNOWY, false));
        structure.fillWithBlocks(world, start, -281, 2, -66, -270, 2, -45, Blocks.DIRT.getDefaultState());
        structure.fillWithBlocks(world, start, -281, 2, 26, -280, 2, 26, Blocks.STONE.getDefaultState());
        structure.fillWithBlocks(world, start, -281, 2, 27, -271, 2, 37, Blocks.DIRT.getDefaultState());
        structure.fillWithBlocks(world, start, -281, 2, 38, -281, 2, 38, Blocks.GRASS_BLOCK.getDefaultState().with(SnowyDirtBlock.SNOWY, false));
        structure.fillWithBlocks(world, start, -281, 3, -66, -281, 3, -65, Blocks.GRASS_BLOCK.getDefaultState().with(SnowyDirtBlock.SNOWY, false));
        structure.fillWithBlocks(world, start, -281, 3, -64, -190, 3, 34, Blocks.DIRT.getDefaultState());
        structure.fillWithBlocks(world, start, -281, 3, 35, -281, 3, 35, Blocks.DIRT.getDefaultState());
        structure.fillWithBlocks(world, start, -281, 3, 36, -281, 3, 37, Blocks.GRASS_BLOCK.getDefaultState().with(SnowyDirtBlock.SNOWY, false));
        structure.fillWithBlocks(world, start, -281, 4, -64, -281, 4, -63, Blocks.GRASS_BLOCK.getDefaultState().with(SnowyDirtBlock.SNOWY, false));
        structure.fillWithBlocks(world, start, -281, 4, -62, -190, 4, 32, Blocks.DIRT.getDefaultState());
        structure.fillWithBlocks(world, start, -281, 4, 33, -281, 4, 35, Blocks.GRASS_BLOCK.getDefaultState().with(SnowyDirtBlock.SNOWY, false));
        structure.fillWithBlocks(world, start, -281, 5, -62, -280, 5, -59, Blocks.GRASS_BLOCK.getDefaultState().with(SnowyDirtBlock.SNOWY, false));
        structure.fillWithBlocks(world, start, -281, 5, -57, -198, 5, 26, Blocks.DIRT.getDefaultState());
        structure.fillWithBlocks(world, start, -281, 5, 27, -281, 5, 32, Blocks.GRASS_BLOCK.getDefaultState().with(SnowyDirtBlock.SNOWY, false));
        structure.fillWithBlocks(world, start, -281, 6, -57, -275, 6, 26, Blocks.GRASS_BLOCK.getDefaultState().with(SnowyDirtBlock.SNOWY, false));
        structure.fillWithBlocks(world, start, -280, 0, -70, -276, 0, -64, Blocks.DIRT.getDefaultState());
        structure.fillWithBlocks(world, start, -280, 0, -58, -191, 0, 33, Blocks.STONE.getDefaultState());
        structure.fillWithBlocks(world, start, -280, 0, 34, -280, 0, 41, Blocks.DIRT.getDefaultState());
        structure.fillWithBlocks(world, start, -280, 0, 42, -279, 0, 43, Blocks.GRASS_BLOCK.getDefaultState().with(SnowyDirtBlock.SNOWY, false));
        structure.fillWithBlocks(world, start, -280, 1, -70, -280, 1, -69, Blocks.GRASS_BLOCK.getDefaultState().with(SnowyDirtBlock.SNOWY, false));
        structure.fillWithBlocks(world, start, -280, 1, -11, -278, 1, -6, Blocks.DIRT.getDefaultState());
        structure.fillWithBlocks(world, start, -280, 1, 28, -280, 1, 28, Blocks.STONE.getDefaultState());
        structure.fillWithBlocks(world, start, -280, 1, 29, -280, 1, 39, Blocks.DIRT.getDefaultState());
        structure.fillWithBlocks(world, start, -280, 1, 40, -280, 1, 41, Blocks.GRASS_BLOCK.getDefaultState().with(SnowyDirtBlock.SNOWY, false));
        structure.fillWithBlocks(world, start, -280, 2, -67, -270, 2, -45, Blocks.DIRT.getDefaultState());
        structure.fillWithBlocks(world, start, -280, 2, 16, -280, 2, 26, Blocks.STONE.getDefaultState());
        structure.fillWithBlocks(world, start, -280, 2, 38, -280, 2, 39, Blocks.GRASS_BLOCK.getDefaultState().with(SnowyDirtBlock.SNOWY, false));
        structure.fillWithBlocks(world, start, -280, 3, -67, -280, 3, -66, Blocks.GRASS_BLOCK.getDefaultState().with(SnowyDirtBlock.SNOWY, false));
        structure.fillWithBlocks(world, start, -280, 3, -65, -191, 3, 35, Blocks.DIRT.getDefaultState());
        structure.fillWithBlocks(world, start, -280, 3, 36, -193, 3, 36, Blocks.DIRT.getDefaultState());
        structure.fillWithBlocks(world, start, -280, 3, 37, -280, 3, 37, Blocks.GRASS_BLOCK.getDefaultState().with(SnowyDirtBlock.SNOWY, false));
        structure.fillWithBlocks(world, start, -280, 4, -65, -280, 4, -64, Blocks.GRASS_BLOCK.getDefaultState().with(SnowyDirtBlock.SNOWY, false));
        structure.fillWithBlocks(world, start, -280, 4, -63, -191, 4, 33, Blocks.DIRT.getDefaultState());
        structure.fillWithBlocks(world, start, -280, 4, 34, -280, 4, 36, Blocks.GRASS_BLOCK.getDefaultState().with(SnowyDirtBlock.SNOWY, false));
        structure.fillWithBlocks(world, start, -280, 5, -63, -279, 5, -61, Blocks.GRASS_BLOCK.getDefaultState().with(SnowyDirtBlock.SNOWY, false));
        structure.fillWithBlocks(world, start, -280, 5, -58, -194, 5, 28, Blocks.DIRT.getDefaultState());
        structure.fillWithBlocks(world, start, -280, 5, 29, -280, 5, 33, Blocks.GRASS_BLOCK.getDefaultState().with(SnowyDirtBlock.SNOWY, false));
        structure.fillWithBlocks(world, start, -280, 6, -58, -273, 6, -51, Blocks.GRASS_BLOCK.getDefaultState().with(SnowyDirtBlock.SNOWY, false));
        structure.fillWithBlocks(world, start, -280, 6, 27, -279, 6, 28, Blocks.GRASS_BLOCK.getDefaultState().with(SnowyDirtBlock.SNOWY, false));
        structure.fillWithBlocks(world, start, -279, 0, -73, -278, 0, -72, Blocks.GRASS_BLOCK.getDefaultState().with(SnowyDirtBlock.SNOWY, false));
        structure.fillWithBlocks(world, start, -279, 0, -71, -276, 0, -64, Blocks.DIRT.getDefaultState());
        structure.fillWithBlocks(world, start, -279, 0, -60, -191, 0, 33, Blocks.STONE.getDefaultState());
        structure.fillWithBlocks(world, start, -279, 0, 34, -279, 0, 34, Blocks.STONE.getDefaultState());
        structure.fillWithBlocks(world, start, -279, 0, 35, -279, 0, 41, Blocks.DIRT.getDefaultState());
        structure.fillWithBlocks(world, start, -279, 1, -71, -279, 1, -70, Blocks.GRASS_BLOCK.getDefaultState().with(SnowyDirtBlock.SNOWY, false));
        structure.fillWithBlocks(world, start, -279, 1, -69, -275, 1, -53, Blocks.DIRT.getDefaultState());
        structure.fillWithBlocks(world, start, -279, 1, -50, -279, 5, -50, Blocks.DIRT.getDefaultState());
        structure.fillWithBlocks(world, start, -279, 1, -32, -184, 1, -32, Blocks.STONE.getDefaultState());
        structure.fillWithBlocks(world, start, -279, 1, -31, -271, 1, -23, Blocks.DIRT.getDefaultState());
        structure.fillWithBlocks(world, start, -279, 1, -22, -278, 1, -21, Blocks.DIRT.getDefaultState());
        structure.fillWithBlocks(world, start, -279, 1, -5, -278, 2, -5, Blocks.DIRT.getDefaultState());
        structure.fillWithBlocks(world, start, -279, 1, -4, -270, 1, 5, Blocks.STONE.getDefaultState());
        structure.fillWithBlocks(world, start, -279, 1, 6, -274, 1, 29, Blocks.STONE.getDefaultState());
        structure.fillWithBlocks(world, start, -279, 1, 30, -279, 1, 40, Blocks.DIRT.getDefaultState());
        structure.fillWithBlocks(world, start, -279, 1, 41, -279, 1, 41, Blocks.GRASS_BLOCK.getDefaultState().with(SnowyDirtBlock.SNOWY, false));
        structure.fillWithBlocks(world, start, -279, 2, -69, -278, 2, -69, Blocks.GRASS_BLOCK.getDefaultState().with(SnowyDirtBlock.SNOWY, false));
        structure.fillWithBlocks(world, start, -279, 2, -68, -270, 2, -45, Blocks.DIRT.getDefaultState());
        structure.fillWithBlocks(world, start, -279, 2, 16, -249, 5, 16, Blocks.DIRT.getDefaultState());
        structure.fillWithBlocks(world, start, -279, 2, 17, -277, 2, 22, Blocks.STONE.getDefaultState());
        structure.fillWithBlocks(world, start, -279, 2, 23, -279, 2, 25, Blocks.STONE.getDefaultState());
        structure.fillWithBlocks(world, start, -279, 2, 26, -267, 2, 38, Blocks.DIRT.getDefaultState());
        structure.fillWithBlocks(world, start, -279, 2, 39, -279, 2, 40, Blocks.GRASS_BLOCK.getDefaultState().with(SnowyDirtBlock.SNOWY, false));
        structure.fillWithBlocks(world, start, -279, 3, -68, -279, 3, -67, Blocks.GRASS_BLOCK.getDefaultState().with(SnowyDirtBlock.SNOWY, false));
        structure.fillWithBlocks(world, start, -279, 3, -66, -192, 3, 35, Blocks.DIRT.getDefaultState());
        structure.fillWithBlocks(world, start, -279, 3, 37, -279, 3, 38, Blocks.GRASS_BLOCK.getDefaultState().with(SnowyDirtBlock.SNOWY, false));
        structure.fillWithBlocks(world, start, -279, 4, -66, -279, 4, -65, Blocks.GRASS_BLOCK.getDefaultState().with(SnowyDirtBlock.SNOWY, false));
        structure.fillWithBlocks(world, start, -279, 4, -64, -192, 4, 33, Blocks.DIRT.getDefaultState());
        structure.fillWithBlocks(world, start, -279, 4, 34, -279, 4, 34, Blocks.DIRT.getDefaultState());
        structure.fillWithBlocks(world, start, -279, 4, 35, -279, 4, 36, Blocks.GRASS_BLOCK.getDefaultState().with(SnowyDirtBlock.SNOWY, false));
        structure.fillWithBlocks(world, start, -279, 5, -64, -278, 5, -62, Blocks.GRASS_BLOCK.getDefaultState().with(SnowyDirtBlock.SNOWY, false));
        structure.fillWithBlocks(world, start, -279, 5, -60, -192, 5, 29, Blocks.DIRT.getDefaultState());
        structure.fillWithBlocks(world, start, -279, 5, 30, -279, 5, 34, Blocks.GRASS_BLOCK.getDefaultState().with(SnowyDirtBlock.SNOWY, false));
        structure.fillWithBlocks(world, start, -279, 6, -60, -273, 6, -51, Blocks.GRASS_BLOCK.getDefaultState().with(SnowyDirtBlock.SNOWY, false));
        structure.fillWithBlocks(world, start, -279, 6, 29, -279, 6, 29, Blocks.GRASS_BLOCK.getDefaultState().with(SnowyDirtBlock.SNOWY, false));
        structure.fillWithBlocks(world, start, -278, 0, -74, -277, 0, -73, Blocks.GRASS_BLOCK.getDefaultState().with(SnowyDirtBlock.SNOWY, false));
        structure.fillWithBlocks(world, start, -278, 0, -61, -190, 0, 27, Blocks.STONE.getDefaultState());
        structure.fillWithBlocks(world, start, -278, 0, 34, -277, 0, 35, Blocks.STONE.getDefaultState());
        structure.fillWithBlocks(world, start, -278, 0, 36, -277, 0, 42, Blocks.DIRT.getDefaultState());
        structure.fillWithBlocks(world, start, -278, 0, 43, -277, 0, 44, Blocks.GRASS_BLOCK.getDefaultState().with(SnowyDirtBlock.SNOWY, false));
        structure.fillWithBlocks(world, start, -278, 1, -70, -274, 1, -65, Blocks.DIRT.getDefaultState());
        structure.fillWithBlocks(world, start, -278, 1, -50, -260, 1, -32, Blocks.STONE.getDefaultState());
        structure.fillWithBlocks(world, start, -278, 1, 30, -278, 1, 30, Blocks.STONE.getDefaultState());
        structure.fillWithBlocks(world, start, -278, 1, 31, -278, 1, 40, Blocks.DIRT.getDefaultState());
        structure.fillWithBlocks(world, start, -278, 1, 41, -278, 1, 42, Blocks.GRASS_BLOCK.getDefaultState().with(SnowyDirtBlock.SNOWY, false));
        structure.fillWithBlocks(world, start, -278, 2, -70, -278, 2, -69, Blocks.GRASS_BLOCK.getDefaultState().with(SnowyDirtBlock.SNOWY, false));
        structure.fillWithBlocks(world, start, -278, 2, -42, -278, 3, -41, Blocks.DIRT.getDefaultState());
        structure.fillWithBlocks(world, start, -278, 2, -40, -277, 2, -39, Blocks.STONE.getDefaultState());
        structure.fillWithBlocks(world, start, -278, 2, -38, -278, 2, 16, Blocks.DIRT.getDefaultState());
        structure.fillWithBlocks(world, start, -278, 2, 24, -264, 2, 39, Blocks.DIRT.getDefaultState());
        structure.fillWithBlocks(world, start, -278, 2, 40, -278, 2, 40, Blocks.GRASS_BLOCK.getDefaultState().with(SnowyDirtBlock.SNOWY, false));
        structure.fillWithBlocks(world, start, -278, 3, -67, -193, 3, 36, Blocks.DIRT.getDefaultState());
        structure.fillWithBlocks(world, start, -278, 3, 37, -278, 3, 37, Blocks.DIRT.getDefaultState());
        structure.fillWithBlocks(world, start, -278, 3, 38, -278, 3, 39, Blocks.GRASS_BLOCK.getDefaultState().with(SnowyDirtBlock.SNOWY, false));
        structure.fillWithBlocks(world, start, -278, 4, -67, -278, 4, -66, Blocks.GRASS_BLOCK.getDefaultState().with(SnowyDirtBlock.SNOWY, false));
        structure.fillWithBlocks(world, start, -278, 4, -65, -193, 4, 34, Blocks.DIRT.getDefaultState());
        structure.fillWithBlocks(world, start, -278, 4, 35, -194, 4, 35, Blocks.DIRT.getDefaultState());
        structure.fillWithBlocks(world, start, -278, 4, 36, -277, 4, 37, Blocks.GRASS_BLOCK.getDefaultState().with(SnowyDirtBlock.SNOWY, false));
        structure.fillWithBlocks(world, start, -278, 5, -65, -277, 5, -63, Blocks.GRASS_BLOCK.getDefaultState().with(SnowyDirtBlock.SNOWY, false));
        structure.fillWithBlocks(world, start, -278, 5, -61, -193, 5, 30, Blocks.DIRT.getDefaultState());
        structure.fillWithBlocks(world, start, -278, 5, 31, -278, 5, 35, Blocks.GRASS_BLOCK.getDefaultState().with(SnowyDirtBlock.SNOWY, false));
        structure.fillWithBlocks(world, start, -278, 6, -61, -273, 6, -51, Blocks.GRASS_BLOCK.getDefaultState().with(SnowyDirtBlock.SNOWY, false));
        structure.fillWithBlocks(world, start, -278, 6, 27, -275, 6, 30, Blocks.GRASS_BLOCK.getDefaultState().with(SnowyDirtBlock.SNOWY, false));
        structure.fillWithBlocks(world, start, -277, 0, -72, -274, 0, -69, Blocks.DIRT.getDefaultState());
        structure.fillWithBlocks(world, start, -277, 0, -62, -190, 0, 27, Blocks.STONE.getDefaultState());
        structure.fillWithBlocks(world, start, -277, 1, -72, -276, 1, -72, Blocks.GRASS_BLOCK.getDefaultState().with(SnowyDirtBlock.SNOWY, false));
        structure.fillWithBlocks(world, start, -277, 1, -71, -273, 1, -66, Blocks.DIRT.getDefaultState());
        structure.fillWithBlocks(world, start, -277, 1, -51, -277, 5, -51, Blocks.DIRT.getDefaultState());
        structure.fillWithBlocks(world, start, -277, 1, -22, -276, 1, -21, Blocks.DIRT.getDefaultState());
        structure.fillWithBlocks(world, start, -277, 1, -11, -277, 1, -11, Blocks.STONE.getDefaultState());
        structure.fillWithBlocks(world, start, -277, 1, -5, -268, 1, 4, Blocks.STONE.getDefaultState());
        structure.fillWithBlocks(world, start, -277, 1, 30, -276, 1, 31, Blocks.STONE.getDefaultState());
        structure.fillWithBlocks(world, start, -277, 1, 32, -277, 1, 41, Blocks.DIRT.getDefaultState());
        structure.fillWithBlocks(world, start, -277, 1, 42, -277, 1, 42, Blocks.GRASS_BLOCK.getDefaultState().with(SnowyDirtBlock.SNOWY, false));
        structure.fillWithBlocks(world, start, -277, 2, -71, -277, 2, -70, Blocks.GRASS_BLOCK.getDefaultState().with(SnowyDirtBlock.SNOWY, false));
        structure.fillWithBlocks(world, start, -277, 2, -69, -270, 2, -45, Blocks.DIRT.getDefaultState());
        structure.fillWithBlocks(world, start, -277, 2, -42, -273, 2, -38, Blocks.STONE.getDefaultState());
        structure.fillWithBlocks(world, start, -277, 2, -37, -260, 2, -20, Blocks.DIRT.getDefaultState());
        structure.fillWithBlocks(world, start, -277, 2, -9, -258, 2, 16, Blocks.DIRT.getDefaultState());
        structure.fillWithBlocks(world, start, -277, 2, 23, -264, 2, 39, Blocks.DIRT.getDefaultState());
        structure.fillWithBlocks(world, start, -277, 2, 40, -277, 2, 41, Blocks.GRASS_BLOCK.getDefaultState().with(SnowyDirtBlock.SNOWY, false));
        structure.fillWithBlocks(world, start, -277, 3, -69, -276, 3, -69, Blocks.GRASS_BLOCK.getDefaultState().with(SnowyDirtBlock.SNOWY, false));
        structure.fillWithBlocks(world, start, -277, 3, -68, -195, 3, 37, Blocks.DIRT.getDefaultState());
        structure.fillWithBlocks(world, start, -277, 3, 38, -196, 3, 38, Blocks.DIRT.getDefaultState());
        structure.fillWithBlocks(world, start, -277, 3, 39, -277, 3, 39, Blocks.GRASS_BLOCK.getDefaultState().with(SnowyDirtBlock.SNOWY, false));
        structure.fillWithBlocks(world, start, -277, 4, -68, -276, 4, -67, Blocks.GRASS_BLOCK.getDefaultState().with(SnowyDirtBlock.SNOWY, false));
        structure.fillWithBlocks(world, start, -277, 4, -66, -194, 4, 35, Blocks.DIRT.getDefaultState());
        structure.fillWithBlocks(world, start, -277, 4, 38, -273, 4, 38, Blocks.GRASS_BLOCK.getDefaultState().with(SnowyDirtBlock.SNOWY, false));
        structure.fillWithBlocks(world, start, -277, 5, -66, -276, 5, -64, Blocks.GRASS_BLOCK.getDefaultState().with(SnowyDirtBlock.SNOWY, false));
        structure.fillWithBlocks(world, start, -277, 5, -62, -194, 5, 31, Blocks.DIRT.getDefaultState());
        structure.fillWithBlocks(world, start, -277, 5, 32, -277, 5, 35, Blocks.GRASS_BLOCK.getDefaultState().with(SnowyDirtBlock.SNOWY, false));
        structure.fillWithBlocks(world, start, -277, 6, -62, -273, 6, -51, Blocks.GRASS_BLOCK.getDefaultState().with(SnowyDirtBlock.SNOWY, false));
        structure.fillWithBlocks(world, start, -277, 6, 31, -277, 6, 31, Blocks.GRASS_BLOCK.getDefaultState().with(SnowyDirtBlock.SNOWY, false));
        structure.fillWithBlocks(world, start, -276, 0, -75, -275, 0, -74, Blocks.GRASS_BLOCK.getDefaultState().with(SnowyDirtBlock.SNOWY, false));
        structure.fillWithBlocks(world, start, -276, 0, -73, -273, 0, -69, Blocks.DIRT.getDefaultState());
        structure.fillWithBlocks(world, start, -276, 0, -63, -191, 0, 33, Blocks.STONE.getDefaultState());
        structure.fillWithBlocks(world, start, -276, 0, 34, -274, 0, 36, Blocks.STONE.getDefaultState());
        structure.fillWithBlocks(world, start, -276, 0, 37, -276, 0, 43, Blocks.DIRT.getDefaultState());
        structure.fillWithBlocks(world, start, -276, 0, 44, -276, 0, 44, Blocks.GRASS_BLOCK.getDefaultState().with(SnowyDirtBlock.SNOWY, false));
        structure.fillWithBlocks(world, start, -276, 1, -73, -276, 1, -72, Blocks.GRASS_BLOCK.getDefaultState().with(SnowyDirtBlock.SNOWY, false));
        structure.fillWithBlocks(world, start, -276, 1, -51, -257, 1, -32, Blocks.STONE.getDefaultState());
        structure.fillWithBlocks(world, start, -276, 1, -11, -275, 1, -10, Blocks.STONE.getDefaultState());
        structure.fillWithBlocks(world, start, -276, 1, -9, -276, 1, -6, Blocks.DIRT.getDefaultState());
        structure.fillWithBlocks(world, start, -276, 1, 32, -195, 1, 32, Blocks.STONE.getDefaultState());
        structure.fillWithBlocks(world, start, -276, 1, 33, -275, 1, 41, Blocks.DIRT.getDefaultState());
        structure.fillWithBlocks(world, start, -276, 1, 42, -276, 1, 43, Blocks.GRASS_BLOCK.getDefaultState().with(SnowyDirtBlock.SNOWY, false));
        structure.fillWithBlocks(world, start, -276, 2, -71, -275, 2, -71, Blocks.GRASS_BLOCK.getDefaultState().with(SnowyDirtBlock.SNOWY, false));
        structure.fillWithBlocks(world, start, -276, 2, -70, -270, 2, -45, Blocks.DIRT.getDefaultState());
        structure.fillWithBlocks(world, start, -276, 2, 17, -276, 2, 17, Blocks.DIRT.getDefaultState());
        structure.fillWithBlocks(world, start, -276, 2, 18, -276, 2, 22, Blocks.STONE.getDefaultState());
        structure.fillWithBlocks(world, start, -276, 2, 40, -197, 2, 40, Blocks.DIRT.getDefaultState());
        structure.fillWithBlocks(world, start, -276, 2, 41, -276, 2, 41, Blocks.GRASS_BLOCK.getDefaultState().with(SnowyDirtBlock.SNOWY, false));
        structure.fillWithBlocks(world, start, -276, 3, -70, -276, 3, -69, Blocks.GRASS_BLOCK.getDefaultState().with(SnowyDirtBlock.SNOWY, false));
        structure.fillWithBlocks(world, start, -276, 3, 39, -276, 3, 40, Blocks.GRASS_BLOCK.getDefaultState().with(SnowyDirtBlock.SNOWY, false));
        structure.fillWithBlocks(world, start, -276, 4, 36, -276, 4, 36, Blocks.DIRT.getDefaultState());
        structure.fillWithBlocks(world, start, -276, 4, 37, -276, 4, 38, Blocks.GRASS_BLOCK.getDefaultState().with(SnowyDirtBlock.SNOWY, false));
        structure.fillWithBlocks(world, start, -276, 5, -63, -195, 5, 32, Blocks.DIRT.getDefaultState());
        structure.fillWithBlocks(world, start, -276, 5, 33, -275, 5, 36, Blocks.GRASS_BLOCK.getDefaultState().with(SnowyDirtBlock.SNOWY, false));
        structure.fillWithBlocks(world, start, -276, 6, -63, -273, 6, -51, Blocks.GRASS_BLOCK.getDefaultState().with(SnowyDirtBlock.SNOWY, false));
        structure.fillWithBlocks(world, start, -276, 6, 31, -275, 6, 32, Blocks.GRASS_BLOCK.getDefaultState().with(SnowyDirtBlock.SNOWY, false));
        structure.fillWithBlocks(world, start, -276, 8, -42, -276, 8, -41, Blocks.OAK_LEAVES.getDefaultState().with(LeavesBlock.PERSISTENT, false).with(LeavesBlock.DISTANCE, 3));
        structure.fillWithBlocks(world, start, -276, 8, -40, -276, 9, -40, Blocks.OAK_LEAVES.getDefaultState().with(LeavesBlock.PERSISTENT, false).with(LeavesBlock.DISTANCE, 2));
        structure.fillWithBlocks(world, start, -276, 8, -39, -276, 9, -38, Blocks.OAK_LEAVES.getDefaultState().with(LeavesBlock.PERSISTENT, false).with(LeavesBlock.DISTANCE, 3));
        structure.fillWithBlocks(world, start, -276, 8, -37, -276, 9, -37, Blocks.OAK_LEAVES.getDefaultState().with(LeavesBlock.PERSISTENT, false).with(LeavesBlock.DISTANCE, 2));
        structure.fillWithBlocks(world, start, -276, 8, -36, -276, 9, -36, Blocks.OAK_LEAVES.getDefaultState().with(LeavesBlock.PERSISTENT, false).with(LeavesBlock.DISTANCE, 3));
        structure.fillWithBlocks(world, start, -276, 9, -51, -276, 10, -51, Blocks.OAK_LEAVES.getDefaultState().with(LeavesBlock.PERSISTENT, false).with(LeavesBlock.DISTANCE, 3));
        structure.fillWithBlocks(world, start, -276, 9, -50, -276, 10, -50, Blocks.OAK_LEAVES.getDefaultState().with(LeavesBlock.PERSISTENT, false).with(LeavesBlock.DISTANCE, 2));
        structure.fillWithBlocks(world, start, -276, 9, -49, -276, 10, -49, Blocks.OAK_LEAVES.getDefaultState().with(LeavesBlock.PERSISTENT, false).with(LeavesBlock.DISTANCE, 3));
        structure.fillWithBlocks(world, start, -276, 9, 6, -276, 10, 6, Blocks.OAK_LEAVES.getDefaultState().with(LeavesBlock.PERSISTENT, false).with(LeavesBlock.DISTANCE, 4));
        structure.fillWithBlocks(world, start, -276, 9, 7, -276, 10, 7, Blocks.OAK_LEAVES.getDefaultState().with(LeavesBlock.PERSISTENT, false).with(LeavesBlock.DISTANCE, 3));
        structure.fillWithBlocks(world, start, -276, 9, 8, -276, 10, 8, Blocks.OAK_LEAVES.getDefaultState().with(LeavesBlock.PERSISTENT, false).with(LeavesBlock.DISTANCE, 2));
        structure.fillWithBlocks(world, start, -276, 9, 9, -276, 10, 9, Blocks.OAK_LEAVES.getDefaultState().with(LeavesBlock.PERSISTENT, false).with(LeavesBlock.DISTANCE, 3));
        structure.fillWithBlocks(world, start, -276, 10, -45, -276, 11, -45, Blocks.OAK_LEAVES.getDefaultState().with(LeavesBlock.PERSISTENT, false).with(LeavesBlock.DISTANCE, 4));
        structure.fillWithBlocks(world, start, -276, 10, -44, -276, 11, -44, Blocks.OAK_LEAVES.getDefaultState().with(LeavesBlock.PERSISTENT, false).with(LeavesBlock.DISTANCE, 3));
        structure.fillWithBlocks(world, start, -276, 10, -43, -276, 11, -43, Blocks.OAK_LEAVES.getDefaultState().with(LeavesBlock.PERSISTENT, false).with(LeavesBlock.DISTANCE, 2));
        structure.fillWithBlocks(world, start, -276, 10, -42, -276, 11, -42, Blocks.OAK_LEAVES.getDefaultState().with(LeavesBlock.PERSISTENT, false).with(LeavesBlock.DISTANCE, 3));
        structure.fillWithBlocks(world, start, -275, 0, -68, -275, 3, -68, Blocks.DIRT.getDefaultState());
        structure.fillWithBlocks(world, start, -275, 0, -67, -274, 0, -66, Blocks.STONE.getDefaultState());
        structure.fillWithBlocks(world, start, -275, 0, -65, -275, 4, -65, Blocks.DIRT.getDefaultState());
        structure.fillWithBlocks(world, start, -275, 0, -64, -192, 0, 33, Blocks.STONE.getDefaultState());
        structure.fillWithBlocks(world, start, -275, 0, 37, -197, 0, 37, Blocks.STONE.getDefaultState());
        structure.fillWithBlocks(world, start, -275, 0, 38, -273, 0, 43, Blocks.DIRT.getDefaultState());
        structure.fillWithBlocks(world, start, -275, 0, 44, -274, 0, 45, Blocks.GRASS_BLOCK.getDefaultState().with(SnowyDirtBlock.SNOWY, false));
        structure.fillWithBlocks(world, start, -275, 1, -73, -274, 1, -73, Blocks.GRASS_BLOCK.getDefaultState().with(SnowyDirtBlock.SNOWY, false));
        structure.fillWithBlocks(world, start, -275, 1, -72, -271, 1, -67, Blocks.DIRT.getDefaultState());
        structure.fillWithBlocks(world, start, -275, 1, -52, -255, 1, -32, Blocks.STONE.getDefaultState());
        structure.fillWithBlocks(world, start, -275, 1, -22, -275, 2, -21, Blocks.DIRT.getDefaultState());
        structure.fillWithBlocks(world, start, -275, 1, -9, -275, 1, -9, Blocks.STONE.getDefaultState());
        structure.fillWithBlocks(world, start, -275, 1, -8, -275, 2, -7, Blocks.DIRT.getDefaultState());
        structure.fillWithBlocks(world, start, -275, 1, -6, -266, 1, 3, Blocks.STONE.getDefaultState());
        structure.fillWithBlocks(world, start, -275, 1, 30, -273, 1, 32, Blocks.STONE.getDefaultState());
        structure.fillWithBlocks(world, start, -275, 1, 42, -199, 1, 42, Blocks.DIRT.getDefaultState());
        structure.fillWithBlocks(world, start, -275, 1, 43, -273, 1, 43, Blocks.GRASS_BLOCK.getDefaultState().with(SnowyDirtBlock.SNOWY, false));
        structure.fillWithBlocks(world, start, -275, 2, -72, -275, 2, -71, Blocks.GRASS_BLOCK.getDefaultState().with(SnowyDirtBlock.SNOWY, false));
        structure.fillWithBlocks(world, start, -275, 2, -43, -270, 2, -38, Blocks.STONE.getDefaultState());
        structure.fillWithBlocks(world, start, -275, 2, 17, -274, 2, 18, Blocks.DIRT.getDefaultState());
        structure.fillWithBlocks(world, start, -275, 2, 19, -275, 2, 21, Blocks.STONE.getDefaultState());
        structure.fillWithBlocks(world, start, -275, 2, 22, -264, 2, 40, Blocks.DIRT.getDefaultState());
        structure.fillWithBlocks(world, start, -275, 2, 41, -275, 2, 42, Blocks.GRASS_BLOCK.getDefaultState().with(SnowyDirtBlock.SNOWY, false));
        structure.fillWithBlocks(world, start, -275, 3, -70, -274, 3, -70, Blocks.GRASS_BLOCK.getDefaultState().with(SnowyDirtBlock.SNOWY, false));
        structure.fillWithBlocks(world, start, -275, 3, -69, -196, 3, 38, Blocks.DIRT.getDefaultState());
        structure.fillWithBlocks(world, start, -275, 3, 39, -198, 3, 39, Blocks.DIRT.getDefaultState());
        structure.fillWithBlocks(world, start, -275, 3, 40, -275, 3, 40, Blocks.GRASS_BLOCK.getDefaultState().with(SnowyDirtBlock.SNOWY, false));
        structure.fillWithBlocks(world, start, -275, 4, -69, -275, 4, -68, Blocks.GRASS_BLOCK.getDefaultState().with(SnowyDirtBlock.SNOWY, false));
        structure.fillWithBlocks(world, start, -275, 4, -67, -196, 4, 36, Blocks.DIRT.getDefaultState());
        structure.fillWithBlocks(world, start, -275, 4, 37, -197, 4, 37, Blocks.DIRT.getDefaultState());
        structure.fillWithBlocks(world, start, -275, 4, 39, -271, 4, 39, Blocks.GRASS_BLOCK.getDefaultState().with(SnowyDirtBlock.SNOWY, false));
        structure.fillWithBlocks(world, start, -275, 5, -67, -274, 5, -65, Blocks.GRASS_BLOCK.getDefaultState().with(SnowyDirtBlock.SNOWY, false));
        structure.fillWithBlocks(world, start, -275, 5, -64, -196, 5, 32, Blocks.DIRT.getDefaultState());
        structure.fillWithBlocks(world, start, -275, 5, 37, -265, 5, 37, Blocks.GRASS_BLOCK.getDefaultState().with(SnowyDirtBlock.SNOWY, false));
        structure.fillWithBlocks(world, start, -275, 6, -64, -272, 6, -61, Blocks.GRASS_BLOCK.getDefaultState().with(SnowyDirtBlock.SNOWY, false));
        structure.fillWithBlocks(world, start, -275, 8, -42, -275, 9, -41, Blocks.OAK_LEAVES.getDefaultState().with(LeavesBlock.PERSISTENT, false).with(LeavesBlock.DISTANCE, 2));
        structure.fillWithBlocks(world, start, -275, 8, -40, -275, 10, -40, Blocks.OAK_LEAVES.getDefaultState().with(LeavesBlock.PERSISTENT, false).with(LeavesBlock.DISTANCE, 1));
        structure.fillWithBlocks(world, start, -275, 8, -39, -275, 9, -38, Blocks.OAK_LEAVES.getDefaultState().with(LeavesBlock.PERSISTENT, false).with(LeavesBlock.DISTANCE, 2));
        structure.fillWithBlocks(world, start, -275, 8, -37, -275, 10, -37, Blocks.OAK_LEAVES.getDefaultState().with(LeavesBlock.PERSISTENT, false).with(LeavesBlock.DISTANCE, 1));
        structure.fillWithBlocks(world, start, -275, 8, -36, -275, 10, -36, Blocks.OAK_LEAVES.getDefaultState().with(LeavesBlock.PERSISTENT, false).with(LeavesBlock.DISTANCE, 2));
        structure.fillWithBlocks(world, start, -275, 8, -35, -275, 9, -35, Blocks.OAK_LEAVES.getDefaultState().with(LeavesBlock.PERSISTENT, false).with(LeavesBlock.DISTANCE, 3));
        structure.fillWithBlocks(world, start, -275, 8, -2, -275, 9, -2, Blocks.OAK_LEAVES.getDefaultState().with(LeavesBlock.PERSISTENT, false).with(LeavesBlock.DISTANCE, 3));
        structure.fillWithBlocks(world, start, -275, 8, -1, -275, 9, -1, Blocks.OAK_LEAVES.getDefaultState().with(LeavesBlock.PERSISTENT, false).with(LeavesBlock.DISTANCE, 2));
        structure.fillWithBlocks(world, start, -275, 8, 0, -275, 8, 1, Blocks.OAK_LEAVES.getDefaultState().with(LeavesBlock.PERSISTENT, false).with(LeavesBlock.DISTANCE, 3));
        structure.fillWithBlocks(world, start, -275, 9, -52, -275, 10, -52, Blocks.OAK_LEAVES.getDefaultState().with(LeavesBlock.PERSISTENT, false).with(LeavesBlock.DISTANCE, 3));
        structure.fillWithBlocks(world, start, -275, 9, -51, -275, 10, -51, Blocks.OAK_LEAVES.getDefaultState().with(LeavesBlock.PERSISTENT, false).with(LeavesBlock.DISTANCE, 2));
        structure.fillWithBlocks(world, start, -275, 9, -50, -275, 11, -50, Blocks.OAK_LEAVES.getDefaultState().with(LeavesBlock.PERSISTENT, false).with(LeavesBlock.DISTANCE, 1));
        structure.fillWithBlocks(world, start, -275, 9, -49, -275, 11, -49, Blocks.OAK_LEAVES.getDefaultState().with(LeavesBlock.PERSISTENT, false).with(LeavesBlock.DISTANCE, 2));
        structure.fillWithBlocks(world, start, -275, 9, -48, -275, 10, -48, Blocks.OAK_LEAVES.getDefaultState().with(LeavesBlock.PERSISTENT, false).with(LeavesBlock.DISTANCE, 3));
        structure.fillWithBlocks(world, start, -275, 9, 0, -275, 10, 0, Blocks.OAK_LEAVES.getDefaultState().with(LeavesBlock.PERSISTENT, false).with(LeavesBlock.DISTANCE, 3));
        structure.fillWithBlocks(world, start, -275, 9, 4, -275, 10, 4, Blocks.OAK_LEAVES.getDefaultState().with(LeavesBlock.PERSISTENT, false).with(LeavesBlock.DISTANCE, 3));
        structure.fillWithBlocks(world, start, -275, 9, 5, -275, 10, 5, Blocks.OAK_LEAVES.getDefaultState().with(LeavesBlock.PERSISTENT, false).with(LeavesBlock.DISTANCE, 2));
        structure.fillWithBlocks(world, start, -275, 9, 6, -275, 10, 6, Blocks.OAK_LEAVES.getDefaultState().with(LeavesBlock.PERSISTENT, false).with(LeavesBlock.DISTANCE, 3));
        structure.fillWithBlocks(world, start, -275, 9, 7, -275, 10, 7, Blocks.OAK_LEAVES.getDefaultState().with(LeavesBlock.PERSISTENT, false).with(LeavesBlock.DISTANCE, 2));
        structure.fillWithBlocks(world, start, -275, 9, 8, -275, 11, 8, Blocks.OAK_LEAVES.getDefaultState().with(LeavesBlock.PERSISTENT, false).with(LeavesBlock.DISTANCE, 1));
        structure.fillWithBlocks(world, start, -275, 9, 9, -275, 10, 9, Blocks.OAK_LEAVES.getDefaultState().with(LeavesBlock.PERSISTENT, false).with(LeavesBlock.DISTANCE, 2));
        structure.fillWithBlocks(world, start, -275, 9, 10, -275, 10, 10, Blocks.OAK_LEAVES.getDefaultState().with(LeavesBlock.PERSISTENT, false).with(LeavesBlock.DISTANCE, 3));
        structure.fillWithBlocks(world, start, -275, 10, -45, -275, 11, -45, Blocks.OAK_LEAVES.getDefaultState().with(LeavesBlock.PERSISTENT, false).with(LeavesBlock.DISTANCE, 3));
        structure.fillWithBlocks(world, start, -275, 10, -44, -275, 11, -44, Blocks.OAK_LEAVES.getDefaultState().with(LeavesBlock.PERSISTENT, false).with(LeavesBlock.DISTANCE, 2));
        structure.fillWithBlocks(world, start, -275, 10, -43, -275, 12, -43, Blocks.OAK_LEAVES.getDefaultState().with(LeavesBlock.PERSISTENT, false).with(LeavesBlock.DISTANCE, 1));
        structure.fillWithBlocks(world, start, -275, 10, -42, -275, 10, -41, Blocks.OAK_LEAVES.getDefaultState().with(LeavesBlock.PERSISTENT, false).with(LeavesBlock.DISTANCE, 2));
        structure.fillWithBlocks(world, start, -275, 10, 1, -275, 11, 1, Blocks.OAK_LEAVES.getDefaultState().with(LeavesBlock.PERSISTENT, false).with(LeavesBlock.DISTANCE, 3));
        structure.fillWithBlocks(world, start, -275, 10, 2, -275, 11, 2, Blocks.OAK_LEAVES.getDefaultState().with(LeavesBlock.PERSISTENT, false).with(LeavesBlock.DISTANCE, 2));
        structure.fillWithBlocks(world, start, -275, 10, 3, -275, 10, 4, Blocks.OAK_LEAVES.getDefaultState().with(LeavesBlock.PERSISTENT, false).with(LeavesBlock.DISTANCE, 3));
        structure.fillWithBlocks(world, start, -275, 11, -42, -275, 11, -42, Blocks.OAK_LEAVES.getDefaultState().with(LeavesBlock.PERSISTENT, false).with(LeavesBlock.DISTANCE, 2));
        structure.fillWithBlocks(world, start, -275, 11, -40, -275, 11, -40, Blocks.OAK_LEAVES.getDefaultState().with(LeavesBlock.PERSISTENT, false).with(LeavesBlock.DISTANCE, 2));
        structure.fillWithBlocks(world, start, -275, 11, -37, -275, 11, -37, Blocks.OAK_LEAVES.getDefaultState().with(LeavesBlock.PERSISTENT, false).with(LeavesBlock.DISTANCE, 2));
        structure.fillWithBlocks(world, start, -275, 12, -50, -275, 12, -50, Blocks.OAK_LEAVES.getDefaultState().with(LeavesBlock.PERSISTENT, false).with(LeavesBlock.DISTANCE, 2));
        structure.fillWithBlocks(world, start, -275, 12, 8, -275, 12, 8, Blocks.OAK_LEAVES.getDefaultState().with(LeavesBlock.PERSISTENT, false).with(LeavesBlock.DISTANCE, 2));
        structure.fillWithBlocks(world, start, -275, 13, -43, -275, 13, -43, Blocks.OAK_LEAVES.getDefaultState().with(LeavesBlock.PERSISTENT, false).with(LeavesBlock.DISTANCE, 2));
        structure.fillWithBlocks(world, start, -274, 0, -76, -273, 0, -75, Blocks.GRASS_BLOCK.getDefaultState().with(SnowyDirtBlock.SNOWY, false));
        structure.fillWithBlocks(world, start, -274, 0, -74, -271, 0, -70, Blocks.DIRT.getDefaultState());
        structure.fillWithBlocks(world, start, -274, 0, -68, -197, 0, 37, Blocks.STONE.getDefaultState());
        structure.fillWithBlocks(world, start, -274, 1, -74, -274, 1, -73, Blocks.GRASS_BLOCK.getDefaultState().with(SnowyDirtBlock.SNOWY, false));
        structure.fillWithBlocks(world, start, -274, 1, -64, -274, 1, -64, Blocks.STONE.getDefaultState());
        structure.fillWithBlocks(world, start, -274, 1, -63, -274, 5, -54, Blocks.DIRT.getDefaultState());
        structure.fillWithBlocks(world, start, -274, 1, -53, -253, 1, -32, Blocks.STONE.getDefaultState());
        structure.fillWithBlocks(world, start, -274, 1, -22, -272, 3, -22, Blocks.DIRT.getDefaultState());
        structure.fillWithBlocks(world, start, -274, 1, -21, -250, 1, 3, Blocks.STONE.getDefaultState());
        structure.fillWithBlocks(world, start, -274, 1, 33, -274, 1, 33, Blocks.STONE.getDefaultState());
        structure.fillWithBlocks(world, start, -274, 1, 34, -274, 1, 42, Blocks.DIRT.getDefaultState());
        structure.fillWithBlocks(world, start, -274, 2, -72, -273, 2, -72, Blocks.GRASS_BLOCK.getDefaultState().with(SnowyDirtBlock.SNOWY, false));
        structure.fillWithBlocks(world, start, -274, 2, -71, -270, 2, -45, Blocks.DIRT.getDefaultState());
        structure.fillWithBlocks(world, start, -274, 2, -19, -262, 2, 30, Blocks.DIRT.getDefaultState());
        structure.fillWithBlocks(world, start, -274, 2, 41, -200, 2, 41, Blocks.DIRT.getDefaultState());
        structure.fillWithBlocks(world, start, -274, 2, 42, -272, 2, 42, Blocks.GRASS_BLOCK.getDefaultState().with(SnowyDirtBlock.SNOWY, false));
        structure.fillWithBlocks(world, start, -274, 3, -71, -274, 3, -70, Blocks.GRASS_BLOCK.getDefaultState().with(SnowyDirtBlock.SNOWY, false));
        structure.fillWithBlocks(world, start, -274, 3, 40, -273, 3, 41, Blocks.GRASS_BLOCK.getDefaultState().with(SnowyDirtBlock.SNOWY, false));
        structure.fillWithBlocks(world, start, -274, 4, -69, -273, 4, -69, Blocks.GRASS_BLOCK.getDefaultState().with(SnowyDirtBlock.SNOWY, false));
        structure.fillWithBlocks(world, start, -274, 4, -68, -197, 4, 37, Blocks.DIRT.getDefaultState());
        structure.fillWithBlocks(world, start, -274, 5, -68, -273, 5, -66, Blocks.GRASS_BLOCK.getDefaultState().with(SnowyDirtBlock.SNOWY, false));
        structure.fillWithBlocks(world, start, -274, 5, 33, -274, 5, 33, Blocks.DIRT.getDefaultState());
        structure.fillWithBlocks(world, start, -274, 5, 34, -274, 5, 37, Blocks.GRASS_BLOCK.getDefaultState().with(SnowyDirtBlock.SNOWY, false));
        structure.fillWithBlocks(world, start, -274, 6, -49, -269, 6, -44, Blocks.GRASS_BLOCK.getDefaultState().with(SnowyDirtBlock.SNOWY, false));
        structure.fillWithBlocks(world, start, -274, 6, -42, -273, 6, -41, Blocks.GRASS_BLOCK.getDefaultState().with(SnowyDirtBlock.SNOWY, false));
        structure.fillWithBlocks(world, start, -274, 6, -39, -273, 6, -38, Blocks.GRASS_BLOCK.getDefaultState().with(SnowyDirtBlock.SNOWY, false));
        structure.fillWithBlocks(world, start, -274, 6, -36, -273, 6, -2, Blocks.GRASS_BLOCK.getDefaultState().with(SnowyDirtBlock.SNOWY, false));
        structure.fillWithBlocks(world, start, -274, 6, -1, -274, 6, 7, Blocks.GRASS_BLOCK.getDefaultState().with(SnowyDirtBlock.SNOWY, false));
        structure.fillWithBlocks(world, start, -274, 6, 9, -271, 6, 12, Blocks.GRASS_BLOCK.getDefaultState().with(SnowyDirtBlock.SNOWY, false));
        structure.fillWithBlocks(world, start, -274, 6, 13, -273, 6, 33, Blocks.GRASS_BLOCK.getDefaultState().with(SnowyDirtBlock.SNOWY, false));
        structure.fillWithBlocks(world, start, -274, 7, -57, -273, 7, -57, Blocks.GRASS.getDefaultState());
        structure.fillWithBlocks(world, start, -274, 7, -54, -274, 7, -53, Blocks.GRASS.getDefaultState());
        structure.fillWithBlocks(world, start, -274, 7, -50, -274, 11, -50, Blocks.OAK_LOG.getDefaultState());
        structure.fillWithBlocks(world, start, -274, 7, -43, -274, 12, -43, Blocks.OAK_LOG.getDefaultState());
        structure.fillWithBlocks(world, start, -274, 7, -40, -274, 10, -40, Blocks.OAK_LOG.getDefaultState());
        structure.fillWithBlocks(world, start, -274, 7, -37, -274, 10, -37, Blocks.OAK_LOG.getDefaultState());
        structure.fillWithBlocks(world, start, -274, 7, -31, -273, 7, -31, Blocks.GRASS.getDefaultState());
        structure.fillWithBlocks(world, start, -274, 7, -23, -274, 7, -23, Blocks.GRASS.getDefaultState());
        structure.fillWithBlocks(world, start, -274, 7, -20, -274, 7, -19, Blocks.GRASS.getDefaultState());
        structure.fillWithBlocks(world, start, -274, 7, -11, -274, 7, -11, Blocks.GRASS.getDefaultState());
        structure.fillWithBlocks(world, start, -274, 7, 8, -274, 11, 8, Blocks.OAK_LOG.getDefaultState());
        structure.fillWithBlocks(world, start, -274, 8, -56, -274, 9, -56, Blocks.OAK_LEAVES.getDefaultState().with(LeavesBlock.PERSISTENT, false).with(LeavesBlock.DISTANCE, 3));
        structure.fillWithBlocks(world, start, -274, 8, -55, -274, 9, -55, Blocks.OAK_LEAVES.getDefaultState().with(LeavesBlock.PERSISTENT, false).with(LeavesBlock.DISTANCE, 2));
        structure.fillWithBlocks(world, start, -274, 8, -54, -274, 9, -54, Blocks.OAK_LEAVES.getDefaultState().with(LeavesBlock.PERSISTENT, false).with(LeavesBlock.DISTANCE, 3));
        structure.fillWithBlocks(world, start, -274, 8, -42, -274, 9, -41, Blocks.OAK_LEAVES.getDefaultState().with(LeavesBlock.PERSISTENT, false).with(LeavesBlock.DISTANCE, 1));
        structure.fillWithBlocks(world, start, -274, 8, -39, -274, 9, -38, Blocks.OAK_LEAVES.getDefaultState().with(LeavesBlock.PERSISTENT, false).with(LeavesBlock.DISTANCE, 1));
        structure.fillWithBlocks(world, start, -274, 8, -36, -274, 10, -36, Blocks.OAK_LEAVES.getDefaultState().with(LeavesBlock.PERSISTENT, false).with(LeavesBlock.DISTANCE, 1));
        structure.fillWithBlocks(world, start, -274, 8, -35, -274, 10, -35, Blocks.OAK_LEAVES.getDefaultState().with(LeavesBlock.PERSISTENT, false).with(LeavesBlock.DISTANCE, 2));
        structure.fillWithBlocks(world, start, -274, 8, -24, -274, 9, -24, Blocks.OAK_LEAVES.getDefaultState().with(LeavesBlock.PERSISTENT, false).with(LeavesBlock.DISTANCE, 3));
        structure.fillWithBlocks(world, start, -274, 8, -23, -274, 9, -23, Blocks.OAK_LEAVES.getDefaultState().with(LeavesBlock.PERSISTENT, false).with(LeavesBlock.DISTANCE, 2));
        structure.fillWithBlocks(world, start, -274, 8, -22, -274, 9, -22, Blocks.OAK_LEAVES.getDefaultState().with(LeavesBlock.PERSISTENT, false).with(LeavesBlock.DISTANCE, 3));
        structure.fillWithBlocks(world, start, -274, 8, -3, -274, 10, -3, Blocks.OAK_LEAVES.getDefaultState().with(LeavesBlock.PERSISTENT, false).with(LeavesBlock.DISTANCE, 3));
        structure.fillWithBlocks(world, start, -274, 8, -2, -274, 10, -2, Blocks.OAK_LEAVES.getDefaultState().with(LeavesBlock.PERSISTENT, false).with(LeavesBlock.DISTANCE, 2));
        structure.fillWithBlocks(world, start, -274, 8, -1, -274, 10, -1, Blocks.OAK_LEAVES.getDefaultState().with(LeavesBlock.PERSISTENT, false).with(LeavesBlock.DISTANCE, 1));
        structure.fillWithBlocks(world, start, -274, 8, 0, -274, 9, 1, Blocks.OAK_LEAVES.getDefaultState().with(LeavesBlock.PERSISTENT, false).with(LeavesBlock.DISTANCE, 2));
        structure.fillWithBlocks(world, start, -274, 9, -61, -274, 10, -61, Blocks.OAK_LEAVES.getDefaultState().with(LeavesBlock.PERSISTENT, false).with(LeavesBlock.DISTANCE, 3));
        structure.fillWithBlocks(world, start, -274, 9, -60, -274, 10, -60, Blocks.OAK_LEAVES.getDefaultState().with(LeavesBlock.PERSISTENT, false).with(LeavesBlock.DISTANCE, 2));
        structure.fillWithBlocks(world, start, -274, 9, -59, -274, 10, -59, Blocks.OAK_LEAVES.getDefaultState().with(LeavesBlock.PERSISTENT, false).with(LeavesBlock.DISTANCE, 3));
        structure.fillWithBlocks(world, start, -274, 9, -58, -274, 10, -58, Blocks.OAK_LEAVES.getDefaultState().with(LeavesBlock.PERSISTENT, false).with(LeavesBlock.DISTANCE, 4));
        structure.fillWithBlocks(world, start, -274, 9, -52, -274, 10, -52, Blocks.OAK_LEAVES.getDefaultState().with(LeavesBlock.PERSISTENT, false).with(LeavesBlock.DISTANCE, 2));
        structure.fillWithBlocks(world, start, -274, 9, -51, -274, 11, -51, Blocks.OAK_LEAVES.getDefaultState().with(LeavesBlock.PERSISTENT, false).with(LeavesBlock.DISTANCE, 1));
        structure.fillWithBlocks(world, start, -274, 9, -49, -274, 11, -49, Blocks.OAK_LEAVES.getDefaultState().with(LeavesBlock.PERSISTENT, false).with(LeavesBlock.DISTANCE, 1));
        structure.fillWithBlocks(world, start, -274, 9, -48, -274, 10, -48, Blocks.OAK_LEAVES.getDefaultState().with(LeavesBlock.PERSISTENT, false).with(LeavesBlock.DISTANCE, 2));
        structure.fillWithBlocks(world, start, -274, 9, -5, -274, 10, -5, Blocks.OAK_LEAVES.getDefaultState().with(LeavesBlock.PERSISTENT, false).with(LeavesBlock.DISTANCE, 3));
        structure.fillWithBlocks(world, start, -274, 9, -4, -274, 10, -4, Blocks.OAK_LEAVES.getDefaultState().with(LeavesBlock.PERSISTENT, false).with(LeavesBlock.DISTANCE, 2));
        structure.fillWithBlocks(world, start, -274, 9, 3, -274, 10, 4, Blocks.OAK_LEAVES.getDefaultState().with(LeavesBlock.PERSISTENT, false).with(LeavesBlock.DISTANCE, 2));
        structure.fillWithBlocks(world, start, -274, 9, 5, -274, 11, 5, Blocks.OAK_LEAVES.getDefaultState().with(LeavesBlock.PERSISTENT, false).with(LeavesBlock.DISTANCE, 1));
        structure.fillWithBlocks(world, start, -274, 9, 6, -274, 11, 6, Blocks.OAK_LEAVES.getDefaultState().with(LeavesBlock.PERSISTENT, false).with(LeavesBlock.DISTANCE, 2));
        structure.fillWithBlocks(world, start, -274, 9, 7, -274, 11, 7, Blocks.OAK_LEAVES.getDefaultState().with(LeavesBlock.PERSISTENT, false).with(LeavesBlock.DISTANCE, 1));
        structure.fillWithBlocks(world, start, -274, 9, 9, -274, 11, 9, Blocks.OAK_LEAVES.getDefaultState().with(LeavesBlock.PERSISTENT, false).with(LeavesBlock.DISTANCE, 1));
        structure.fillWithBlocks(world, start, -274, 9, 10, -274, 10, 10, Blocks.OAK_LEAVES.getDefaultState().with(LeavesBlock.PERSISTENT, false).with(LeavesBlock.DISTANCE, 2));
        structure.fillWithBlocks(world, start, -274, 10, -45, -274, 11, -45, Blocks.OAK_LEAVES.getDefaultState().with(LeavesBlock.PERSISTENT, false).with(LeavesBlock.DISTANCE, 2));
        structure.fillWithBlocks(world, start, -274, 10, -44, -274, 12, -44, Blocks.OAK_LEAVES.getDefaultState().with(LeavesBlock.PERSISTENT, false).with(LeavesBlock.DISTANCE, 1));
        structure.fillWithBlocks(world, start, -274, 10, -42, -274, 10, -41, Blocks.OAK_LEAVES.getDefaultState().with(LeavesBlock.PERSISTENT, false).with(LeavesBlock.DISTANCE, 1));
        structure.fillWithBlocks(world, start, -274, 10, -39, -274, 10, -38, Blocks.OAK_LEAVES.getDefaultState().with(LeavesBlock.PERSISTENT, false).with(LeavesBlock.DISTANCE, 1));
        structure.fillWithBlocks(world, start, -274, 10, -34, -274, 11, -34, Blocks.OAK_LEAVES.getDefaultState().with(LeavesBlock.PERSISTENT, false).with(LeavesBlock.DISTANCE, 2));
        structure.fillWithBlocks(world, start, -274, 10, -33, -274, 11, -33, Blocks.OAK_LEAVES.getDefaultState().with(LeavesBlock.PERSISTENT, false).with(LeavesBlock.DISTANCE, 3));
        structure.fillWithBlocks(world, start, -274, 10, -32, -274, 11, -32, Blocks.OAK_LEAVES.getDefaultState().with(LeavesBlock.PERSISTENT, false).with(LeavesBlock.DISTANCE, 4));
        structure.fillWithBlocks(world, start, -274, 10, 0, -274, 10, 1, Blocks.OAK_LEAVES.getDefaultState().with(LeavesBlock.PERSISTENT, false).with(LeavesBlock.DISTANCE, 2));
        structure.fillWithBlocks(world, start, -274, 10, 2, -274, 12, 2, Blocks.OAK_LEAVES.getDefaultState().with(LeavesBlock.PERSISTENT, false).with(LeavesBlock.DISTANCE, 1));
        structure.fillWithBlocks(world, start, -274, 10, 11, -274, 10, 12, Blocks.OAK_LEAVES.getDefaultState().with(LeavesBlock.PERSISTENT, false).with(LeavesBlock.DISTANCE, 3));
        structure.fillWithBlocks(world, start, -274, 10, 13, -274, 11, 13, Blocks.OAK_LEAVES.getDefaultState().with(LeavesBlock.PERSISTENT, false).with(LeavesBlock.DISTANCE, 2));
        structure.fillWithBlocks(world, start, -274, 10, 14, -274, 11, 14, Blocks.OAK_LEAVES.getDefaultState().with(LeavesBlock.PERSISTENT, false).with(LeavesBlock.DISTANCE, 3));
        structure.fillWithBlocks(world, start, -274, 11, -42, -274, 12, -42, Blocks.OAK_LEAVES.getDefaultState().with(LeavesBlock.PERSISTENT, false).with(LeavesBlock.DISTANCE, 1));
        structure.fillWithBlocks(world, start, -274, 11, -41, -274, 11, -41, Blocks.OAK_LEAVES.getDefaultState().with(LeavesBlock.PERSISTENT, false).with(LeavesBlock.DISTANCE, 2));
        structure.fillWithBlocks(world, start, -274, 11, -39, -274, 11, -38, Blocks.OAK_LEAVES.getDefaultState().with(LeavesBlock.PERSISTENT, false).with(LeavesBlock.DISTANCE, 2));
        structure.fillWithBlocks(world, start, -274, 11, -36, -274, 11, -36, Blocks.OAK_LEAVES.getDefaultState().with(LeavesBlock.PERSISTENT, false).with(LeavesBlock.DISTANCE, 2));
