package mod.arcalitegames.odyssey.world.structure.structures.ruins.kagrenzal;

import mod.arcalitegames.odyssey.world.structure.StructureBase;
import net.minecraft.block.Blocks;
import net.minecraft.block.HorizontalBlock;
import net.minecraft.block.LeavesBlock;
import net.minecraft.block.SlabBlock;
import net.minecraft.block.SnowyDirtBlock;
import net.minecraft.block.StairsBlock;
import net.minecraft.block.TrapDoorBlock;
import net.minecraft.block.WallBlock;
import net.minecraft.block.WallHeight;
import net.minecraft.state.properties.Half;
import net.minecraft.state.properties.SlabType;
import net.minecraft.state.properties.StairsShape;
import net.minecraft.util.Direction;
import net.minecraft.util.math.BlockPos;
import net.minecraft.world.World;

public class KagrenzalComponent2
{

	public static BlockPos start;
    public static World world;
    public static StructureBase structure;

    public static void init(World worldIn, BlockPos blockPos, StructureBase structureIn)
    {
        world = worldIn; start = blockPos; structure = structureIn;
    }
    
    public static void generatePart21()
    {
        structure.fillWithBlocks(world, start, -220, 7, 8, -220, 11, 8, Blocks.OAK_LOG.getDefaultState());
        structure.fillWithBlocks(world, start, -220, 7, 9, -220, 7, 9, Blocks.GRASS.getDefaultState());
        structure.fillWithBlocks(world, start, -220, 7, 19, -220, 7, 21, Blocks.GRASS.getDefaultState());
        structure.fillWithBlocks(world, start, -220, 8, -53, -220, 10, -53, Blocks.OAK_LEAVES.getDefaultState().with(LeavesBlock.PERSISTENT, false).with(LeavesBlock.DISTANCE, 3));
        structure.fillWithBlocks(world, start, -220, 8, -52, -220, 10, -52, Blocks.OAK_LEAVES.getDefaultState().with(LeavesBlock.PERSISTENT, false).with(LeavesBlock.DISTANCE, 2));
        structure.fillWithBlocks(world, start, -220, 8, -51, -220, 10, -51, Blocks.OAK_LEAVES.getDefaultState().with(LeavesBlock.PERSISTENT, false).with(LeavesBlock.DISTANCE, 1));
        structure.fillWithBlocks(world, start, -220, 8, -50, -220, 10, -50, Blocks.OAK_LEAVES.getDefaultState().with(LeavesBlock.PERSISTENT, false).with(LeavesBlock.DISTANCE, 2));
        structure.fillWithBlocks(world, start, -220, 8, -49, -220, 9, -49, Blocks.OAK_LEAVES.getDefaultState().with(LeavesBlock.PERSISTENT, false).with(LeavesBlock.DISTANCE, 3));
        structure.fillWithBlocks(world, start, -220, 8, -41, -220, 8, -41, Blocks.STONE_BRICKS.getDefaultState());
        structure.fillWithBlocks(world, start, -220, 8, 13, -220, 9, 14, Blocks.OAK_LEAVES.getDefaultState().with(LeavesBlock.PERSISTENT, false).with(LeavesBlock.DISTANCE, 3));
        structure.fillWithBlocks(world, start, -220, 8, 15, -220, 9, 15, Blocks.OAK_LEAVES.getDefaultState().with(LeavesBlock.PERSISTENT, false).with(LeavesBlock.DISTANCE, 2));
        structure.fillWithBlocks(world, start, -220, 8, 16, -220, 9, 16, Blocks.OAK_LEAVES.getDefaultState().with(LeavesBlock.PERSISTENT, false).with(LeavesBlock.DISTANCE, 3));
        structure.fillWithBlocks(world, start, -220, 8, 17, -220, 9, 17, Blocks.OAK_LEAVES.getDefaultState().with(LeavesBlock.PERSISTENT, false).with(LeavesBlock.DISTANCE, 2));
        structure.fillWithBlocks(world, start, -220, 8, 18, -220, 9, 18, Blocks.OAK_LEAVES.getDefaultState().with(LeavesBlock.PERSISTENT, false).with(LeavesBlock.DISTANCE, 3));
        structure.fillWithBlocks(world, start, -220, 8, 19, -220, 9, 19, Blocks.OAK_LEAVES.getDefaultState().with(LeavesBlock.PERSISTENT, false).with(LeavesBlock.DISTANCE, 4));
        structure.fillWithBlocks(world, start, -220, 9, -47, -220, 10, -47, Blocks.OAK_LEAVES.getDefaultState().with(LeavesBlock.PERSISTENT, false).with(LeavesBlock.DISTANCE, 3));
        structure.fillWithBlocks(world, start, -220, 9, -46, -220, 10, -46, Blocks.OAK_LEAVES.getDefaultState().with(LeavesBlock.PERSISTENT, false).with(LeavesBlock.DISTANCE, 2));
        structure.fillWithBlocks(world, start, -220, 9, -45, -220, 11, -45, Blocks.OAK_LEAVES.getDefaultState().with(LeavesBlock.PERSISTENT, false).with(LeavesBlock.DISTANCE, 1));
        structure.fillWithBlocks(world, start, -220, 9, -44, -220, 10, -44, Blocks.OAK_LEAVES.getDefaultState().with(LeavesBlock.PERSISTENT, false).with(LeavesBlock.DISTANCE, 2));
        structure.fillWithBlocks(world, start, -220, 9, -43, -220, 10, -43, Blocks.OAK_LEAVES.getDefaultState().with(LeavesBlock.PERSISTENT, false).with(LeavesBlock.DISTANCE, 3));
        structure.fillWithBlocks(world, start, -220, 9, -24, -220, 10, -24, Blocks.OAK_LEAVES.getDefaultState().with(LeavesBlock.PERSISTENT, false).with(LeavesBlock.DISTANCE, 3));
        structure.fillWithBlocks(world, start, -220, 9, -23, -220, 10, -23, Blocks.OAK_LEAVES.getDefaultState().with(LeavesBlock.PERSISTENT, false).with(LeavesBlock.DISTANCE, 2));
        structure.fillWithBlocks(world, start, -220, 9, -22, -220, 10, -22, Blocks.OAK_LEAVES.getDefaultState().with(LeavesBlock.PERSISTENT, false).with(LeavesBlock.DISTANCE, 3));
        structure.fillWithBlocks(world, start, -220, 9, 2, -220, 10, 2, Blocks.OAK_LEAVES.getDefaultState().with(LeavesBlock.PERSISTENT, false).with(LeavesBlock.DISTANCE, 3));
        structure.fillWithBlocks(world, start, -220, 9, 3, -220, 10, 3, Blocks.OAK_LEAVES.getDefaultState().with(LeavesBlock.PERSISTENT, false).with(LeavesBlock.DISTANCE, 2));
        structure.fillWithBlocks(world, start, -220, 9, 4, -220, 10, 4, Blocks.OAK_LEAVES.getDefaultState().with(LeavesBlock.PERSISTENT, false).with(LeavesBlock.DISTANCE, 3));
        structure.fillWithBlocks(world, start, -220, 9, 6, -220, 10, 6, Blocks.OAK_LEAVES.getDefaultState().with(LeavesBlock.PERSISTENT, false).with(LeavesBlock.DISTANCE, 2));
        structure.fillWithBlocks(world, start, -220, 9, 7, -220, 11, 7, Blocks.OAK_LEAVES.getDefaultState().with(LeavesBlock.PERSISTENT, false).with(LeavesBlock.DISTANCE, 1));
        structure.fillWithBlocks(world, start, -220, 9, 9, -220, 11, 9, Blocks.OAK_LEAVES.getDefaultState().with(LeavesBlock.PERSISTENT, false).with(LeavesBlock.DISTANCE, 1));
        structure.fillWithBlocks(world, start, -220, 9, 10, -220, 10, 10, Blocks.OAK_LEAVES.getDefaultState().with(LeavesBlock.PERSISTENT, false).with(LeavesBlock.DISTANCE, 2));
        structure.fillWithBlocks(world, start, -220, 9, 11, -220, 10, 11, Blocks.OAK_LEAVES.getDefaultState().with(LeavesBlock.PERSISTENT, false).with(LeavesBlock.DISTANCE, 3));
        structure.fillWithBlocks(world, start, -220, 9, 12, -220, 10, 12, Blocks.OAK_LEAVES.getDefaultState().with(LeavesBlock.PERSISTENT, false).with(LeavesBlock.DISTANCE, 2));
        structure.fillWithBlocks(world, start, -220, 10, -41, -220, 11, -41, Blocks.STONE_BRICK_STAIRS.getDefaultState().with(StairsBlock.FACING, Direction.SOUTH).with(StairsBlock.WATERLOGGED, false).with(StairsBlock.SHAPE, StairsShape.STRAIGHT).with(StairsBlock.HALF, Half.TOP));
        structure.fillWithBlocks(world, start, -220, 10, -29, -220, 11, -29, Blocks.STONE_BRICK_STAIRS.getDefaultState().with(StairsBlock.FACING, Direction.NORTH).with(StairsBlock.WATERLOGGED, false).with(StairsBlock.SHAPE, StairsShape.STRAIGHT).with(StairsBlock.HALF, Half.TOP));
        structure.fillWithBlocks(world, start, -220, 10, -13, -220, 11, -13, Blocks.OAK_LEAVES.getDefaultState().with(LeavesBlock.PERSISTENT, false).with(LeavesBlock.DISTANCE, 2));
        structure.fillWithBlocks(world, start, -220, 10, -12, -220, 12, -12, Blocks.OAK_LEAVES.getDefaultState().with(LeavesBlock.PERSISTENT, false).with(LeavesBlock.DISTANCE, 1));
        structure.fillWithBlocks(world, start, -220, 10, -10, -220, 12, -10, Blocks.OAK_LEAVES.getDefaultState().with(LeavesBlock.PERSISTENT, false).with(LeavesBlock.DISTANCE, 1));
        structure.fillWithBlocks(world, start, -220, 10, -9, -220, 11, -9, Blocks.OAK_LEAVES.getDefaultState().with(LeavesBlock.PERSISTENT, false).with(LeavesBlock.DISTANCE, 2));
        structure.fillWithBlocks(world, start, -220, 10, -5, -220, 11, -5, Blocks.OAK_LEAVES.getDefaultState().with(LeavesBlock.PERSISTENT, false).with(LeavesBlock.DISTANCE, 3));
        structure.fillWithBlocks(world, start, -220, 10, -4, -220, 11, -4, Blocks.OAK_LEAVES.getDefaultState().with(LeavesBlock.PERSISTENT, false).with(LeavesBlock.DISTANCE, 2));
        structure.fillWithBlocks(world, start, -220, 10, -3, -220, 12, -3, Blocks.OAK_LEAVES.getDefaultState().with(LeavesBlock.PERSISTENT, false).with(LeavesBlock.DISTANCE, 1));
        structure.fillWithBlocks(world, start, -220, 10, -2, -220, 11, -2, Blocks.OAK_LEAVES.getDefaultState().with(LeavesBlock.PERSISTENT, false).with(LeavesBlock.DISTANCE, 2));
        structure.fillWithBlocks(world, start, -220, 10, -1, -220, 11, -1, Blocks.OAK_LEAVES.getDefaultState().with(LeavesBlock.PERSISTENT, false).with(LeavesBlock.DISTANCE, 3));
        structure.fillWithBlocks(world, start, -220, 11, -51, -220, 11, -51, Blocks.OAK_LEAVES.getDefaultState().with(LeavesBlock.PERSISTENT, false).with(LeavesBlock.DISTANCE, 2));
        structure.fillWithBlocks(world, start, -220, 12, -45, -220, 12, -45, Blocks.OAK_LEAVES.getDefaultState().with(LeavesBlock.PERSISTENT, false).with(LeavesBlock.DISTANCE, 2));
        structure.fillWithBlocks(world, start, -220, 12, 7, -220, 12, 7, Blocks.OAK_LEAVES.getDefaultState().with(LeavesBlock.PERSISTENT, false).with(LeavesBlock.DISTANCE, 2));
        structure.fillWithBlocks(world, start, -220, 13, -12, -220, 13, -12, Blocks.OAK_LEAVES.getDefaultState().with(LeavesBlock.PERSISTENT, false).with(LeavesBlock.DISTANCE, 2));
        structure.fillWithBlocks(world, start, -220, 13, -3, -220, 13, -3, Blocks.OAK_LEAVES.getDefaultState().with(LeavesBlock.PERSISTENT, false).with(LeavesBlock.DISTANCE, 2));
        structure.fillWithBlocks(world, start, -220, 16, -41, -220, 16, -29, Blocks.STONE_BRICKS.getDefaultState());
        structure.fillWithBlocks(world, start, -220, 18, -41, -220, 19, -41, Blocks.STONE_BRICK_STAIRS.getDefaultState().with(StairsBlock.FACING, Direction.SOUTH).with(StairsBlock.WATERLOGGED, false).with(StairsBlock.SHAPE, StairsShape.STRAIGHT).with(StairsBlock.HALF, Half.TOP));
        structure.fillWithBlocks(world, start, -220, 18, -29, -220, 19, -29, Blocks.STONE_BRICK_STAIRS.getDefaultState().with(StairsBlock.FACING, Direction.NORTH).with(StairsBlock.WATERLOGGED, false).with(StairsBlock.SHAPE, StairsShape.STRAIGHT).with(StairsBlock.HALF, Half.TOP));
        structure.fillWithBlocks(world, start, -220, 23, -41, -220, 23, -29, Blocks.STONE_BRICKS.getDefaultState());
        structure.fillWithBlocks(world, start, -220, 24, -40, -220, 26, -30, Blocks.STONE_BRICKS.getDefaultState());
        structure.fillWithBlocks(world, start, -220, 25, -41, -220, 25, -29, Blocks.STONE_BRICKS.getDefaultState());
        structure.fillWithBlocks(world, start, -220, 29, -40, -220, 29, -30, Blocks.STONE_BRICKS.getDefaultState());
        structure.fillWithBlocks(world, start, -220, 30, -39, -220, 30, -38, Blocks.STONE_BRICKS.getDefaultState());
        structure.fillWithBlocks(world, start, -220, 30, -32, -220, 31, -31, Blocks.STONE_BRICKS.getDefaultState());
        structure.fillWithBlocks(world, start, -220, 32, -41, -220, 32, -41, Blocks.STONE_BRICK_STAIRS.getDefaultState().with(StairsBlock.FACING, Direction.SOUTH).with(StairsBlock.WATERLOGGED, false).with(StairsBlock.SHAPE, StairsShape.STRAIGHT).with(StairsBlock.HALF, Half.TOP));
        structure.fillWithBlocks(world, start, -220, 34, -31, -219, 34, -30, Blocks.STONE_BRICKS.getDefaultState());
        structure.fillWithBlocks(world, start, -220, 35, -40, -220, 35, -39, Blocks.DARK_OAK_PLANKS.getDefaultState());
        structure.fillWithBlocks(world, start, -220, 35, -31, -220, 35, -30, Blocks.DARK_OAK_PLANKS.getDefaultState());
        structure.fillWithBlocks(world, start, -220, 36, -39, -220, 36, -38, Blocks.DARK_OAK_PLANKS.getDefaultState());
        structure.fillWithBlocks(world, start, -220, 36, -37, -219, 36, -36, Blocks.STONE_BRICKS.getDefaultState());
        structure.fillWithBlocks(world, start, -220, 36, -34, -219, 36, -33, Blocks.STONE_BRICKS.getDefaultState());
        structure.fillWithBlocks(world, start, -220, 36, -32, -220, 36, -31, Blocks.DARK_OAK_PLANKS.getDefaultState());
        structure.fillWithBlocks(world, start, -220, 37, -37, -220, 37, -37, Blocks.DARK_OAK_PLANKS.getDefaultState());
        structure.fillWithBlocks(world, start, -220, 37, -33, -219, 37, -33, Blocks.DARK_OAK_PLANKS.getDefaultState());
        structure.fillWithBlocks(world, start, -220, 38, -36, -220, 38, -34, Blocks.DARK_OAK_PLANKS.getDefaultState());
        structure.fillWithBlocks(world, start, -220, 39, -36, -220, 39, -34, Blocks.DARK_OAK_PLANKS.getDefaultState());
        structure.fillWithBlocks(world, start, -219, 0, 40, -219, 0, 40, Blocks.STONE.getDefaultState());
        structure.fillWithBlocks(world, start, -219, 0, 41, -219, 0, 44, Blocks.DIRT.getDefaultState());
        structure.fillWithBlocks(world, start, -219, 1, -58, -214, 1, -53, Blocks.STONE.getDefaultState());
        structure.fillWithBlocks(world, start, -219, 1, -20, -201, 1, 12, Blocks.STONE.getDefaultState());
        structure.fillWithBlocks(world, start, -219, 1, 22, -210, 1, 37, Blocks.STONE.getDefaultState());
        structure.fillWithBlocks(world, start, -219, 1, 43, -203, 1, 43, Blocks.DIRT.getDefaultState());
        structure.fillWithBlocks(world, start, -219, 2, -74, -215, 2, -70, Blocks.DIRT.getDefaultState());
        structure.fillWithBlocks(world, start, -219, 2, -66, -219, 2, -66, Blocks.STONE.getDefaultState());
        structure.fillWithBlocks(world, start, -219, 2, -45, -219, 2, -45, Blocks.DIRT.getDefaultState());
        structure.fillWithBlocks(world, start, -219, 2, -44, -219, 2, -25, Blocks.STONE.getDefaultState());
        structure.fillWithBlocks(world, start, -219, 2, -24, -219, 5, 37, Blocks.DIRT.getDefaultState());
        structure.fillWithBlocks(world, start, -219, 2, 42, -204, 2, 42, Blocks.DIRT.getDefaultState());
        structure.fillWithBlocks(world, start, -219, 2, 43, -203, 2, 43, Blocks.GRASS_BLOCK.getDefaultState().with(SnowyDirtBlock.SNOWY, false));
        structure.fillWithBlocks(world, start, -219, 3, 42, -204, 3, 42, Blocks.GRASS_BLOCK.getDefaultState().with(SnowyDirtBlock.SNOWY, false));
        structure.fillWithBlocks(world, start, -219, 4, -73, -218, 4, -72, Blocks.GRASS_BLOCK.getDefaultState().with(SnowyDirtBlock.SNOWY, false));
        structure.fillWithBlocks(world, start, -219, 5, -71, -218, 5, -70, Blocks.GRASS_BLOCK.getDefaultState().with(SnowyDirtBlock.SNOWY, false));
        structure.fillWithBlocks(world, start, -219, 5, 38, -218, 5, 39, Blocks.GRASS_BLOCK.getDefaultState().with(SnowyDirtBlock.SNOWY, false));
        structure.fillWithBlocks(world, start, -219, 6, -52, -219, 6, -52, Blocks.GRASS_BLOCK.getDefaultState().with(SnowyDirtBlock.SNOWY, false));
        structure.fillWithBlocks(world, start, -219, 6, -50, -218, 6, -46, Blocks.GRASS_BLOCK.getDefaultState().with(SnowyDirtBlock.SNOWY, false));
        structure.fillWithBlocks(world, start, -219, 6, -44, -217, 6, -42, Blocks.GRASS_BLOCK.getDefaultState().with(SnowyDirtBlock.SNOWY, false));
        structure.fillWithBlocks(world, start, -219, 6, -40, -217, 6, -40, Blocks.DIRT.getDefaultState());
        structure.fillWithBlocks(world, start, -219, 6, -39, -218, 6, -31, Blocks.COBBLESTONE.getDefaultState());
        structure.fillWithBlocks(world, start, -219, 6, -30, -219, 6, -29, Blocks.DIRT.getDefaultState());
        structure.fillWithBlocks(world, start, -219, 6, -11, -212, 6, -4, Blocks.GRASS_BLOCK.getDefaultState().with(SnowyDirtBlock.SNOWY, false));
        structure.fillWithBlocks(world, start, -219, 6, -2, -215, 6, 2, Blocks.GRASS_BLOCK.getDefaultState().with(SnowyDirtBlock.SNOWY, false));
        structure.fillWithBlocks(world, start, -219, 6, 8, -217, 6, 16, Blocks.GRASS_BLOCK.getDefaultState().with(SnowyDirtBlock.SNOWY, false));
        structure.fillWithBlocks(world, start, -219, 7, -51, -219, 10, -51, Blocks.OAK_LOG.getDefaultState());
        structure.fillWithBlocks(world, start, -219, 7, -45, -219, 11, -45, Blocks.OAK_LOG.getDefaultState());
        structure.fillWithBlocks(world, start, -219, 7, -40, -218, 8, -40, Blocks.STONE_BRICKS.getDefaultState());
        structure.fillWithBlocks(world, start, -219, 7, -30, -218, 8, -30, Blocks.STONE_BRICKS.getDefaultState());
        structure.fillWithBlocks(world, start, -219, 7, -15, -219, 7, -15, Blocks.GRASS.getDefaultState());
        structure.fillWithBlocks(world, start, -219, 7, -5, -219, 7, -4, Blocks.GRASS.getDefaultState());
        structure.fillWithBlocks(world, start, -219, 7, -3, -219, 12, -3, Blocks.OAK_LOG.getDefaultState());
        structure.fillWithBlocks(world, start, -219, 8, -53, -219, 9, -53, Blocks.OAK_LEAVES.getDefaultState().with(LeavesBlock.PERSISTENT, false).with(LeavesBlock.DISTANCE, 2));
        structure.fillWithBlocks(world, start, -219, 8, -52, -219, 10, -52, Blocks.OAK_LEAVES.getDefaultState().with(LeavesBlock.PERSISTENT, false).with(LeavesBlock.DISTANCE, 1));
        structure.fillWithBlocks(world, start, -219, 8, -50, -219, 10, -50, Blocks.OAK_LEAVES.getDefaultState().with(LeavesBlock.PERSISTENT, false).with(LeavesBlock.DISTANCE, 1));
        structure.fillWithBlocks(world, start, -219, 8, -49, -219, 10, -49, Blocks.OAK_LEAVES.getDefaultState().with(LeavesBlock.PERSISTENT, false).with(LeavesBlock.DISTANCE, 2));
        structure.fillWithBlocks(world, start, -219, 8, 15, -219, 9, 15, Blocks.OAK_LEAVES.getDefaultState().with(LeavesBlock.PERSISTENT, false).with(LeavesBlock.DISTANCE, 3));
        structure.fillWithBlocks(world, start, -219, 8, 16, -219, 10, 16, Blocks.OAK_LEAVES.getDefaultState().with(LeavesBlock.PERSISTENT, false).with(LeavesBlock.DISTANCE, 2));
        structure.fillWithBlocks(world, start, -219, 8, 17, -219, 10, 17, Blocks.OAK_LEAVES.getDefaultState().with(LeavesBlock.PERSISTENT, false).with(LeavesBlock.DISTANCE, 1));
        structure.fillWithBlocks(world, start, -219, 8, 18, -219, 10, 18, Blocks.OAK_LEAVES.getDefaultState().with(LeavesBlock.PERSISTENT, false).with(LeavesBlock.DISTANCE, 2));
        structure.fillWithBlocks(world, start, -219, 8, 19, -219, 9, 19, Blocks.OAK_LEAVES.getDefaultState().with(LeavesBlock.PERSISTENT, false).with(LeavesBlock.DISTANCE, 3));
        structure.fillWithBlocks(world, start, -219, 8, 23, -219, 9, 23, Blocks.OAK_LEAVES.getDefaultState().with(LeavesBlock.PERSISTENT, false).with(LeavesBlock.DISTANCE, 3));
        structure.fillWithBlocks(world, start, -219, 8, 24, -219, 9, 24, Blocks.OAK_LEAVES.getDefaultState().with(LeavesBlock.PERSISTENT, false).with(LeavesBlock.DISTANCE, 2));
        structure.fillWithBlocks(world, start, -219, 8, 25, -219, 9, 25, Blocks.OAK_LEAVES.getDefaultState().with(LeavesBlock.PERSISTENT, false).with(LeavesBlock.DISTANCE, 3));
        structure.fillWithBlocks(world, start, -219, 9, -47, -219, 11, -47, Blocks.OAK_LEAVES.getDefaultState().with(LeavesBlock.PERSISTENT, false).with(LeavesBlock.DISTANCE, 2));
        structure.fillWithBlocks(world, start, -219, 9, -46, -219, 11, -46, Blocks.OAK_LEAVES.getDefaultState().with(LeavesBlock.PERSISTENT, false).with(LeavesBlock.DISTANCE, 1));
        structure.fillWithBlocks(world, start, -219, 9, -44, -219, 11, -44, Blocks.OAK_LEAVES.getDefaultState().with(LeavesBlock.PERSISTENT, false).with(LeavesBlock.DISTANCE, 1));
        structure.fillWithBlocks(world, start, -219, 9, -43, -219, 10, -43, Blocks.OAK_LEAVES.getDefaultState().with(LeavesBlock.PERSISTENT, false).with(LeavesBlock.DISTANCE, 2));
        structure.fillWithBlocks(world, start, -219, 9, -40, -218, 10, -40, Blocks.STONE_BRICKS.getDefaultState());
        structure.fillWithBlocks(world, start, -219, 9, -30, -218, 10, -30, Blocks.STONE_BRICKS.getDefaultState());
        structure.fillWithBlocks(world, start, -219, 9, -25, -219, 10, -25, Blocks.OAK_LEAVES.getDefaultState().with(LeavesBlock.PERSISTENT, false).with(LeavesBlock.DISTANCE, 3));
        structure.fillWithBlocks(world, start, -219, 9, -24, -219, 10, -24, Blocks.OAK_LEAVES.getDefaultState().with(LeavesBlock.PERSISTENT, false).with(LeavesBlock.DISTANCE, 2));
        structure.fillWithBlocks(world, start, -219, 9, -23, -219, 11, -23, Blocks.OAK_LEAVES.getDefaultState().with(LeavesBlock.PERSISTENT, false).with(LeavesBlock.DISTANCE, 1));
        structure.fillWithBlocks(world, start, -219, 9, -22, -219, 10, -22, Blocks.OAK_LEAVES.getDefaultState().with(LeavesBlock.PERSISTENT, false).with(LeavesBlock.DISTANCE, 2));
        structure.fillWithBlocks(world, start, -219, 9, -21, -219, 10, -21, Blocks.OAK_LEAVES.getDefaultState().with(LeavesBlock.PERSISTENT, false).with(LeavesBlock.DISTANCE, 3));
        structure.fillWithBlocks(world, start, -219, 9, 1, -219, 10, 1, Blocks.OAK_LEAVES.getDefaultState().with(LeavesBlock.PERSISTENT, false).with(LeavesBlock.DISTANCE, 3));
        structure.fillWithBlocks(world, start, -219, 9, 2, -219, 11, 2, Blocks.OAK_LEAVES.getDefaultState().with(LeavesBlock.PERSISTENT, false).with(LeavesBlock.DISTANCE, 2));
        structure.fillWithBlocks(world, start, -219, 9, 3, -219, 11, 3, Blocks.OAK_LEAVES.getDefaultState().with(LeavesBlock.PERSISTENT, false).with(LeavesBlock.DISTANCE, 1));
        structure.fillWithBlocks(world, start, -219, 9, 4, -219, 11, 4, Blocks.OAK_LEAVES.getDefaultState().with(LeavesBlock.PERSISTENT, false).with(LeavesBlock.DISTANCE, 2));
        structure.fillWithBlocks(world, start, -219, 9, 5, -219, 10, 6, Blocks.OAK_LEAVES.getDefaultState().with(LeavesBlock.PERSISTENT, false).with(LeavesBlock.DISTANCE, 3));
        structure.fillWithBlocks(world, start, -219, 9, 7, -219, 11, 7, Blocks.OAK_LEAVES.getDefaultState().with(LeavesBlock.PERSISTENT, false).with(LeavesBlock.DISTANCE, 2));
        structure.fillWithBlocks(world, start, -219, 9, 8, -219, 11, 8, Blocks.OAK_LEAVES.getDefaultState().with(LeavesBlock.PERSISTENT, false).with(LeavesBlock.DISTANCE, 1));
        structure.fillWithBlocks(world, start, -219, 9, 9, -219, 10, 9, Blocks.OAK_LEAVES.getDefaultState().with(LeavesBlock.PERSISTENT, false).with(LeavesBlock.DISTANCE, 2));
        structure.fillWithBlocks(world, start, -219, 9, 10, -219, 10, 10, Blocks.OAK_LEAVES.getDefaultState().with(LeavesBlock.PERSISTENT, false).with(LeavesBlock.DISTANCE, 3));
        structure.fillWithBlocks(world, start, -219, 10, -48, -219, 10, -47, Blocks.OAK_LEAVES.getDefaultState().with(LeavesBlock.PERSISTENT, false).with(LeavesBlock.DISTANCE, 2));
        structure.fillWithBlocks(world, start, -219, 10, -13, -219, 11, -13, Blocks.OAK_LEAVES.getDefaultState().with(LeavesBlock.PERSISTENT, false).with(LeavesBlock.DISTANCE, 3));
        structure.fillWithBlocks(world, start, -219, 10, -12, -219, 11, -12, Blocks.OAK_LEAVES.getDefaultState().with(LeavesBlock.PERSISTENT, false).with(LeavesBlock.DISTANCE, 2));
        structure.fillWithBlocks(world, start, -219, 10, -11, -219, 12, -11, Blocks.OAK_LEAVES.getDefaultState().with(LeavesBlock.PERSISTENT, false).with(LeavesBlock.DISTANCE, 1));
        structure.fillWithBlocks(world, start, -219, 10, -10, -219, 12, -10, Blocks.OAK_LEAVES.getDefaultState().with(LeavesBlock.PERSISTENT, false).with(LeavesBlock.DISTANCE, 2));
        structure.fillWithBlocks(world, start, -219, 10, -9, -219, 11, -9, Blocks.OAK_LEAVES.getDefaultState().with(LeavesBlock.PERSISTENT, false).with(LeavesBlock.DISTANCE, 3));
        structure.fillWithBlocks(world, start, -219, 10, -5, -219, 11, -5, Blocks.OAK_LEAVES.getDefaultState().with(LeavesBlock.PERSISTENT, false).with(LeavesBlock.DISTANCE, 2));
        structure.fillWithBlocks(world, start, -219, 10, -4, -219, 12, -4, Blocks.OAK_LEAVES.getDefaultState().with(LeavesBlock.PERSISTENT, false).with(LeavesBlock.DISTANCE, 1));
        structure.fillWithBlocks(world, start, -219, 10, -2, -219, 12, -2, Blocks.OAK_LEAVES.getDefaultState().with(LeavesBlock.PERSISTENT, false).with(LeavesBlock.DISTANCE, 1));
        structure.fillWithBlocks(world, start, -219, 10, -1, -219, 11, -1, Blocks.OAK_LEAVES.getDefaultState().with(LeavesBlock.PERSISTENT, false).with(LeavesBlock.DISTANCE, 2));
        structure.fillWithBlocks(world, start, -219, 11, -52, -219, 11, -52, Blocks.OAK_LEAVES.getDefaultState().with(LeavesBlock.PERSISTENT, false).with(LeavesBlock.DISTANCE, 2));
        structure.fillWithBlocks(world, start, -219, 11, -50, -219, 11, -50, Blocks.OAK_LEAVES.getDefaultState().with(LeavesBlock.PERSISTENT, false).with(LeavesBlock.DISTANCE, 2));
        structure.fillWithBlocks(world, start, -219, 11, -48, -219, 11, -47, Blocks.OAK_LEAVES.getDefaultState().with(LeavesBlock.PERSISTENT, false).with(LeavesBlock.DISTANCE, 2));
        structure.fillWithBlocks(world, start, -219, 11, -40, -218, 12, -40, Blocks.STONE_BRICKS.getDefaultState());
        structure.fillWithBlocks(world, start, -219, 11, -30, -218, 12, -30, Blocks.STONE_BRICKS.getDefaultState());
        structure.fillWithBlocks(world, start, -219, 11, 17, -219, 11, 17, Blocks.OAK_LEAVES.getDefaultState().with(LeavesBlock.PERSISTENT, false).with(LeavesBlock.DISTANCE, 2));
        structure.fillWithBlocks(world, start, -219, 12, -46, -219, 12, -46, Blocks.OAK_LEAVES.getDefaultState().with(LeavesBlock.PERSISTENT, false).with(LeavesBlock.DISTANCE, 2));
        structure.fillWithBlocks(world, start, -219, 12, -41, -219, 12, -29, Blocks.STONE_BRICKS.getDefaultState());
        structure.fillWithBlocks(world, start, -219, 12, -23, -219, 12, -23, Blocks.OAK_LEAVES.getDefaultState().with(LeavesBlock.PERSISTENT, false).with(LeavesBlock.DISTANCE, 2));
        structure.fillWithBlocks(world, start, -219, 12, 3, -219, 12, 3, Blocks.OAK_LEAVES.getDefaultState().with(LeavesBlock.PERSISTENT, false).with(LeavesBlock.DISTANCE, 2));
        structure.fillWithBlocks(world, start, -219, 13, -41, -219, 13, -29, Blocks.STONE_BRICKS.getDefaultState());
        structure.fillWithBlocks(world, start, -219, 13, -4, -219, 13, -4, Blocks.OAK_LEAVES.getDefaultState().with(LeavesBlock.PERSISTENT, false).with(LeavesBlock.DISTANCE, 2));
        structure.fillWithBlocks(world, start, -219, 15, -40, -218, 15, -36, Blocks.STONE_BRICKS.getDefaultState());
        structure.fillWithBlocks(world, start, -219, 15, -30, -218, 16, -30, Blocks.STONE_BRICKS.getDefaultState());
        structure.fillWithBlocks(world, start, -219, 16, -40, -218, 16, -30, Blocks.STONE_BRICKS.getDefaultState());
        structure.fillWithBlocks(world, start, -219, 20, -41, -219, 20, -29, Blocks.STONE_BRICKS.getDefaultState());
        structure.fillWithBlocks(world, start, -219, 21, -41, -219, 21, -29, Blocks.STONE_BRICKS.getDefaultState());
        structure.fillWithBlocks(world, start, -219, 23, -40, -218, 23, -39, Blocks.STONE_BRICKS.getDefaultState());
        structure.fillWithBlocks(world, start, -219, 23, -31, -218, 23, -30, Blocks.STONE_BRICKS.getDefaultState());
        structure.fillWithBlocks(world, start, -219, 24, -40, -219, 29, -40, Blocks.STONE_BRICKS.getDefaultState());
        structure.fillWithBlocks(world, start, -219, 24, -30, -219, 29, -30, Blocks.STONE_BRICKS.getDefaultState());
        structure.fillWithBlocks(world, start, -219, 26, -39, -219, 26, -39, Blocks.STONE_BRICKS.getDefaultState());
        structure.fillWithBlocks(world, start, -219, 26, -31, -219, 26, -30, Blocks.STONE_BRICKS.getDefaultState());
        structure.fillWithBlocks(world, start, -219, 28, -39, -219, 28, -39, Blocks.STONE_BRICKS.getDefaultState());
        structure.fillWithBlocks(world, start, -219, 28, -38, -219, 28, -38, Blocks.CHISELED_STONE_BRICKS.getDefaultState());
        structure.fillWithBlocks(world, start, -219, 28, -36, -218, 28, -34, Blocks.STONE_BRICKS.getDefaultState());
        structure.fillWithBlocks(world, start, -219, 28, -31, -219, 28, -30, Blocks.STONE_BRICKS.getDefaultState());
        structure.fillWithBlocks(world, start, -219, 29, -39, -219, 30, -39, Blocks.CHISELED_STONE_BRICKS.getDefaultState());
        structure.fillWithBlocks(world, start, -219, 29, -38, -219, 35, -38, Blocks.STONE_BRICKS.getDefaultState());
        structure.fillWithBlocks(world, start, -219, 29, -36, -219, 29, -34, Blocks.STONE_BRICKS.getDefaultState());
        structure.fillWithBlocks(world, start, -219, 29, -33, -219, 29, -33, Blocks.DARK_OAK_PLANKS.getDefaultState());
        structure.fillWithBlocks(world, start, -219, 29, -32, -219, 31, -32, Blocks.STONE_BRICKS.getDefaultState());
        structure.fillWithBlocks(world, start, -219, 29, -31, -219, 30, -31, Blocks.CHISELED_STONE_BRICKS.getDefaultState());
        structure.fillWithBlocks(world, start, -219, 30, -37, -219, 30, -37, Blocks.STONE_BRICKS.getDefaultState());
        structure.fillWithBlocks(world, start, -219, 30, -35, -219, 30, -35, Blocks.STONE_BRICKS.getDefaultState());
        structure.fillWithBlocks(world, start, -219, 30, -33, -218, 30, -32, Blocks.STONE_BRICKS.getDefaultState());
        structure.fillWithBlocks(world, start, -219, 31, -40, -219, 31, -40, Blocks.STONE_BRICKS.getDefaultState());
        structure.fillWithBlocks(world, start, -219, 32, -39, -218, 32, -38, Blocks.STONE_BRICKS.getDefaultState());
        structure.fillWithBlocks(world, start, -219, 32, -31, -219, 32, -31, Blocks.STONE_BRICKS.getDefaultState());
        structure.fillWithBlocks(world, start, -219, 34, -40, -219, 34, -30, Blocks.STONE_BRICKS.getDefaultState());
        structure.fillWithBlocks(world, start, -219, 35, -31, -217, 35, -31, Blocks.DARK_OAK_PLANKS.getDefaultState());
        structure.fillWithBlocks(world, start, -219, 36, -38, -219, 36, -38, Blocks.DARK_OAK_PLANKS.getDefaultState());
        structure.fillWithBlocks(world, start, -219, 37, -37, -219, 37, -36, Blocks.DARK_OAK_PLANKS.getDefaultState());
        structure.fillWithBlocks(world, start, -219, 37, -34, -219, 37, -33, Blocks.DARK_OAK_PLANKS.getDefaultState());
        structure.fillWithBlocks(world, start, -218, 0, -78, -217, 0, -77, Blocks.GRASS_BLOCK.getDefaultState().with(SnowyDirtBlock.SNOWY, false));
        structure.fillWithBlocks(world, start, -218, 0, 40, -217, 0, 41, Blocks.STONE.getDefaultState());
        structure.fillWithBlocks(world, start, -218, 0, 42, -216, 0, 44, Blocks.DIRT.getDefaultState());
        structure.fillWithBlocks(world, start, -218, 1, -75, -213, 1, -70, Blocks.DIRT.getDefaultState());
        structure.fillWithBlocks(world, start, -218, 1, -69, -208, 1, -54, Blocks.STONE.getDefaultState());
        structure.fillWithBlocks(world, start, -218, 1, 38, -218, 1, 38, Blocks.STONE.getDefaultState());
        structure.fillWithBlocks(world, start, -218, 1, 39, -218, 1, 43, Blocks.DIRT.getDefaultState());
        structure.fillWithBlocks(world, start, -218, 2, -69, -216, 2, -65, Blocks.STONE.getDefaultState());
        structure.fillWithBlocks(world, start, -218, 2, -47, -214, 2, -43, Blocks.DIRT.getDefaultState());
        structure.fillWithBlocks(world, start, -218, 2, -42, -218, 2, -23, Blocks.STONE.getDefaultState());
        structure.fillWithBlocks(world, start, -218, 2, -22, -218, 5, -1, Blocks.DIRT.getDefaultState());
        structure.fillWithBlocks(world, start, -218, 2, 0, -214, 2, 4, Blocks.STONE.getDefaultState());
        structure.fillWithBlocks(world, start, -218, 2, 5, -218, 5, 37, Blocks.DIRT.getDefaultState());
        structure.fillWithBlocks(world, start, -218, 2, 38, -214, 2, 42, Blocks.DIRT.getDefaultState());
        structure.fillWithBlocks(world, start, -218, 3, 41, -205, 3, 41, Blocks.DIRT.getDefaultState());
        structure.fillWithBlocks(world, start, -218, 4, 41, -205, 4, 41, Blocks.GRASS_BLOCK.getDefaultState().with(SnowyDirtBlock.SNOWY, false));
        structure.fillWithBlocks(world, start, -218, 6, -54, -217, 6, -49, Blocks.GRASS_BLOCK.getDefaultState().with(SnowyDirtBlock.SNOWY, false));
        structure.fillWithBlocks(world, start, -218, 6, -45, -214, 6, -41, Blocks.GRASS_BLOCK.getDefaultState().with(SnowyDirtBlock.SNOWY, false));
        structure.fillWithBlocks(world, start, -218, 6, -30, -217, 6, -30, Blocks.DIRT.getDefaultState());
        structure.fillWithBlocks(world, start, -218, 6, -29, -215, 6, -24, Blocks.GRASS_BLOCK.getDefaultState().with(SnowyDirtBlock.SNOWY, false));
        structure.fillWithBlocks(world, start, -218, 6, -22, -215, 6, 2, Blocks.GRASS_BLOCK.getDefaultState().with(SnowyDirtBlock.SNOWY, false));
        structure.fillWithBlocks(world, start, -218, 6, 4, -213, 6, 9, Blocks.GRASS_BLOCK.getDefaultState().with(SnowyDirtBlock.SNOWY, false));
        structure.fillWithBlocks(world, start, -218, 7, -60, -218, 7, -58, Blocks.GRASS.getDefaultState());
        structure.fillWithBlocks(world, start, -218, 7, -24, -218, 7, -24, Blocks.GRASS.getDefaultState());
        structure.fillWithBlocks(world, start, -218, 7, -23, -218, 11, -23, Blocks.OAK_LOG.getDefaultState());
        structure.fillWithBlocks(world, start, -218, 7, -14, -218, 7, -13, Blocks.GRASS.getDefaultState());
        structure.fillWithBlocks(world, start, -218, 7, 1, -218, 7, 1, Blocks.GRASS.getDefaultState());
        structure.fillWithBlocks(world, start, -218, 7, 3, -218, 11, 3, Blocks.OAK_LOG.getDefaultState());
        structure.fillWithBlocks(world, start, -218, 7, 17, -218, 10, 17, Blocks.OAK_LOG.getDefaultState());
        structure.fillWithBlocks(world, start, -218, 8, -53, -218, 8, -53, Blocks.OAK_LEAVES.getDefaultState().with(LeavesBlock.PERSISTENT, false).with(LeavesBlock.DISTANCE, 3));
        structure.fillWithBlocks(world, start, -218, 8, -52, -218, 10, -52, Blocks.OAK_LEAVES.getDefaultState().with(LeavesBlock.PERSISTENT, false).with(LeavesBlock.DISTANCE, 2));
        structure.fillWithBlocks(world, start, -218, 8, -51, -218, 10, -51, Blocks.OAK_LEAVES.getDefaultState().with(LeavesBlock.PERSISTENT, false).with(LeavesBlock.DISTANCE, 1));
        structure.fillWithBlocks(world, start, -218, 8, -50, -218, 10, -50, Blocks.OAK_LEAVES.getDefaultState().with(LeavesBlock.PERSISTENT, false).with(LeavesBlock.DISTANCE, 2));
        structure.fillWithBlocks(world, start, -218, 8, -49, -218, 9, -49, Blocks.OAK_LEAVES.getDefaultState().with(LeavesBlock.PERSISTENT, false).with(LeavesBlock.DISTANCE, 3));
        structure.fillWithBlocks(world, start, -218, 8, 15, -218, 9, 15, Blocks.OAK_LEAVES.getDefaultState().with(LeavesBlock.PERSISTENT, false).with(LeavesBlock.DISTANCE, 2));
        structure.fillWithBlocks(world, start, -218, 8, 16, -218, 10, 16, Blocks.OAK_LEAVES.getDefaultState().with(LeavesBlock.PERSISTENT, false).with(LeavesBlock.DISTANCE, 1));
        structure.fillWithBlocks(world, start, -218, 8, 18, -218, 10, 18, Blocks.OAK_LEAVES.getDefaultState().with(LeavesBlock.PERSISTENT, false).with(LeavesBlock.DISTANCE, 1));
        structure.fillWithBlocks(world, start, -218, 8, 19, -218, 9, 19, Blocks.OAK_LEAVES.getDefaultState().with(LeavesBlock.PERSISTENT, false).with(LeavesBlock.DISTANCE, 2));
        structure.fillWithBlocks(world, start, -218, 8, 22, -218, 9, 22, Blocks.OAK_LEAVES.getDefaultState().with(LeavesBlock.PERSISTENT, false).with(LeavesBlock.DISTANCE, 3));
        structure.fillWithBlocks(world, start, -218, 8, 23, -218, 9, 23, Blocks.OAK_LEAVES.getDefaultState().with(LeavesBlock.PERSISTENT, false).with(LeavesBlock.DISTANCE, 2));
        structure.fillWithBlocks(world, start, -218, 8, 24, -218, 10, 24, Blocks.OAK_LEAVES.getDefaultState().with(LeavesBlock.PERSISTENT, false).with(LeavesBlock.DISTANCE, 1));
        structure.fillWithBlocks(world, start, -218, 8, 25, -218, 9, 25, Blocks.OAK_LEAVES.getDefaultState().with(LeavesBlock.PERSISTENT, false).with(LeavesBlock.DISTANCE, 2));
        structure.fillWithBlocks(world, start, -218, 9, -54, -218, 10, -54, Blocks.OAK_LEAVES.getDefaultState().with(LeavesBlock.PERSISTENT, false).with(LeavesBlock.DISTANCE, 3));
        structure.fillWithBlocks(world, start, -218, 9, -53, -218, 9, -52, Blocks.OAK_LEAVES.getDefaultState().with(LeavesBlock.PERSISTENT, false).with(LeavesBlock.DISTANCE, 2));
        structure.fillWithBlocks(world, start, -218, 9, -47, -218, 9, -47, Blocks.OAK_LEAVES.getDefaultState().with(LeavesBlock.PERSISTENT, false).with(LeavesBlock.DISTANCE, 3));
        structure.fillWithBlocks(world, start, -218, 9, -46, -218, 11, -46, Blocks.OAK_LEAVES.getDefaultState().with(LeavesBlock.PERSISTENT, false).with(LeavesBlock.DISTANCE, 2));
        structure.fillWithBlocks(world, start, -218, 9, -45, -218, 11, -45, Blocks.OAK_LEAVES.getDefaultState().with(LeavesBlock.PERSISTENT, false).with(LeavesBlock.DISTANCE, 1));
        structure.fillWithBlocks(world, start, -218, 9, -44, -218, 10, -44, Blocks.OAK_LEAVES.getDefaultState().with(LeavesBlock.PERSISTENT, false).with(LeavesBlock.DISTANCE, 2));
        structure.fillWithBlocks(world, start, -218, 9, -43, -218, 10, -43, Blocks.OAK_LEAVES.getDefaultState().with(LeavesBlock.PERSISTENT, false).with(LeavesBlock.DISTANCE, 3));
        structure.fillWithBlocks(world, start, -218, 9, -25, -218, 10, -25, Blocks.OAK_LEAVES.getDefaultState().with(LeavesBlock.PERSISTENT, false).with(LeavesBlock.DISTANCE, 2));
        structure.fillWithBlocks(world, start, -218, 9, -24, -218, 11, -24, Blocks.OAK_LEAVES.getDefaultState().with(LeavesBlock.PERSISTENT, false).with(LeavesBlock.DISTANCE, 1));
        structure.fillWithBlocks(world, start, -218, 9, -22, -218, 11, -22, Blocks.OAK_LEAVES.getDefaultState().with(LeavesBlock.PERSISTENT, false).with(LeavesBlock.DISTANCE, 1));
        structure.fillWithBlocks(world, start, -218, 9, -21, -218, 10, -21, Blocks.OAK_LEAVES.getDefaultState().with(LeavesBlock.PERSISTENT, false).with(LeavesBlock.DISTANCE, 2));
        structure.fillWithBlocks(world, start, -218, 9, 1, -218, 10, 1, Blocks.OAK_LEAVES.getDefaultState().with(LeavesBlock.PERSISTENT, false).with(LeavesBlock.DISTANCE, 2));
        structure.fillWithBlocks(world, start, -218, 9, 2, -218, 11, 2, Blocks.OAK_LEAVES.getDefaultState().with(LeavesBlock.PERSISTENT, false).with(LeavesBlock.DISTANCE, 1));
        structure.fillWithBlocks(world, start, -218, 9, 4, -218, 11, 4, Blocks.OAK_LEAVES.getDefaultState().with(LeavesBlock.PERSISTENT, false).with(LeavesBlock.DISTANCE, 1));
        structure.fillWithBlocks(world, start, -218, 9, 5, -218, 10, 5, Blocks.OAK_LEAVES.getDefaultState().with(LeavesBlock.PERSISTENT, false).with(LeavesBlock.DISTANCE, 2));
        structure.fillWithBlocks(world, start, -218, 9, 7, -218, 10, 7, Blocks.OAK_LEAVES.getDefaultState().with(LeavesBlock.PERSISTENT, false).with(LeavesBlock.DISTANCE, 3));
        structure.fillWithBlocks(world, start, -218, 9, 8, -218, 10, 8, Blocks.OAK_LEAVES.getDefaultState().with(LeavesBlock.PERSISTENT, false).with(LeavesBlock.DISTANCE, 2));
        structure.fillWithBlocks(world, start, -218, 9, 9, -218, 11, 9, Blocks.OAK_LEAVES.getDefaultState().with(LeavesBlock.PERSISTENT, false).with(LeavesBlock.DISTANCE, 3));
        structure.fillWithBlocks(world, start, -218, 10, -53, -218, 10, -52, Blocks.OAK_LEAVES.getDefaultState().with(LeavesBlock.PERSISTENT, false).with(LeavesBlock.DISTANCE, 2));
        structure.fillWithBlocks(world, start, -218, 10, -49, -218, 11, -49, Blocks.OAK_LEAVES.getDefaultState().with(LeavesBlock.PERSISTENT, false).with(LeavesBlock.DISTANCE, 2));
        structure.fillWithBlocks(world, start, -218, 10, -48, -218, 12, -48, Blocks.OAK_LEAVES.getDefaultState().with(LeavesBlock.PERSISTENT, false).with(LeavesBlock.DISTANCE, 1));
        structure.fillWithBlocks(world, start, -218, 10, -47, -218, 10, -46, Blocks.OAK_LEAVES.getDefaultState().with(LeavesBlock.PERSISTENT, false).with(LeavesBlock.DISTANCE, 2));
        structure.fillWithBlocks(world, start, -218, 10, -12, -218, 11, -12, Blocks.OAK_LEAVES.getDefaultState().with(LeavesBlock.PERSISTENT, false).with(LeavesBlock.DISTANCE, 3));
        structure.fillWithBlocks(world, start, -218, 10, -11, -218, 11, -11, Blocks.OAK_LEAVES.getDefaultState().with(LeavesBlock.PERSISTENT, false).with(LeavesBlock.DISTANCE, 2));
        structure.fillWithBlocks(world, start, -218, 10, -10, -218, 11, -10, Blocks.OAK_LEAVES.getDefaultState().with(LeavesBlock.PERSISTENT, false).with(LeavesBlock.DISTANCE, 3));
        structure.fillWithBlocks(world, start, -218, 10, -9, -218, 11, -9, Blocks.OAK_LEAVES.getDefaultState().with(LeavesBlock.PERSISTENT, false).with(LeavesBlock.DISTANCE, 4));
        structure.fillWithBlocks(world, start, -218, 10, -5, -218, 11, -5, Blocks.OAK_LEAVES.getDefaultState().with(LeavesBlock.PERSISTENT, false).with(LeavesBlock.DISTANCE, 3));
        structure.fillWithBlocks(world, start, -218, 10, -4, -218, 11, -4, Blocks.OAK_LEAVES.getDefaultState().with(LeavesBlock.PERSISTENT, false).with(LeavesBlock.DISTANCE, 2));
        structure.fillWithBlocks(world, start, -218, 10, -3, -218, 12, -3, Blocks.OAK_LEAVES.getDefaultState().with(LeavesBlock.PERSISTENT, false).with(LeavesBlock.DISTANCE, 1));
        structure.fillWithBlocks(world, start, -218, 10, -2, -218, 11, -2, Blocks.OAK_LEAVES.getDefaultState().with(LeavesBlock.PERSISTENT, false).with(LeavesBlock.DISTANCE, 2));
        structure.fillWithBlocks(world, start, -218, 10, -1, -218, 11, -1, Blocks.OAK_LEAVES.getDefaultState().with(LeavesBlock.PERSISTENT, false).with(LeavesBlock.DISTANCE, 3));
        structure.fillWithBlocks(world, start, -218, 10, 10, -218, 11, 10, Blocks.OAK_LEAVES.getDefaultState().with(LeavesBlock.PERSISTENT, false).with(LeavesBlock.DISTANCE, 2));
        structure.fillWithBlocks(world, start, -218, 10, 11, -218, 11, 11, Blocks.OAK_LEAVES.getDefaultState().with(LeavesBlock.PERSISTENT, false).with(LeavesBlock.DISTANCE, 3));
        structure.fillWithBlocks(world, start, -218, 11, -51, -218, 11, -51, Blocks.OAK_LEAVES.getDefaultState().with(LeavesBlock.PERSISTENT, false).with(LeavesBlock.DISTANCE, 2));
        structure.fillWithBlocks(world, start, -218, 11, -47, -218, 11, -46, Blocks.OAK_LEAVES.getDefaultState().with(LeavesBlock.PERSISTENT, false).with(LeavesBlock.DISTANCE, 2));
        structure.fillWithBlocks(world, start, -218, 11, 16, -218, 11, 16, Blocks.OAK_LEAVES.getDefaultState().with(LeavesBlock.PERSISTENT, false).with(LeavesBlock.DISTANCE, 2));
        structure.fillWithBlocks(world, start, -218, 11, 24, -218, 11, 24, Blocks.OAK_LEAVES.getDefaultState().with(LeavesBlock.PERSISTENT, false).with(LeavesBlock.DISTANCE, 2));
        structure.fillWithBlocks(world, start, -218, 12, -24, -218, 12, -24, Blocks.OAK_LEAVES.getDefaultState().with(LeavesBlock.PERSISTENT, false).with(LeavesBlock.DISTANCE, 2));
        structure.fillWithBlocks(world, start, -218, 12, 2, -218, 12, 2, Blocks.OAK_LEAVES.getDefaultState().with(LeavesBlock.PERSISTENT, false).with(LeavesBlock.DISTANCE, 2));
        structure.fillWithBlocks(world, start, -218, 13, -48, -218, 13, -48, Blocks.OAK_LEAVES.getDefaultState().with(LeavesBlock.PERSISTENT, false).with(LeavesBlock.DISTANCE, 2));
        structure.fillWithBlocks(world, start, -218, 15, -35, -218, 15, -34, Blocks.STONE.getDefaultState());
        structure.fillWithBlocks(world, start, -218, 15, -33, -218, 15, -30, Blocks.STONE_BRICKS.getDefaultState());
        structure.fillWithBlocks(world, start, -218, 23, -38, -218, 23, -38, Blocks.STONE_BRICKS.getDefaultState());
        structure.fillWithBlocks(world, start, -218, 23, -36, -218, 25, -34, Blocks.STONE_BRICKS.getDefaultState());
        structure.fillWithBlocks(world, start, -218, 23, -32, -217, 23, -31, Blocks.STONE_BRICKS.getDefaultState());
        structure.fillWithBlocks(world, start, -218, 24, -39, -218, 27, -39, Blocks.STONE_BRICKS.getDefaultState());
        structure.fillWithBlocks(world, start, -218, 24, -38, -218, 25, -38, Blocks.DARK_OAK_PLANKS.getDefaultState());
        structure.fillWithBlocks(world, start, -218, 24, -37, -218, 25, -33, Blocks.STONE_BRICKS.getDefaultState());
        structure.fillWithBlocks(world, start, -218, 24, -32, -218, 25, -32, Blocks.DARK_OAK_PLANKS.getDefaultState());
        structure.fillWithBlocks(world, start, -218, 24, -31, -218, 27, -31, Blocks.STONE_BRICKS.getDefaultState());
        structure.fillWithBlocks(world, start, -218, 26, -38, -217, 27, -38, Blocks.STONE_BRICKS.getDefaultState());
        structure.fillWithBlocks(world, start, -218, 26, -36, -218, 28, -34, Blocks.STONE_BRICKS.getDefaultState());
        structure.fillWithBlocks(world, start, -218, 26, -32, -218, 27, -31, Blocks.STONE_BRICKS.getDefaultState());
        structure.fillWithBlocks(world, start, -218, 27, -40, -218, 27, -38, Blocks.STONE_BRICKS.getDefaultState());
        structure.fillWithBlocks(world, start, -218, 28, -40, -218, 30, -40, Blocks.STONE_BRICKS.getDefaultState());
        structure.fillWithBlocks(world, start, -218, 28, -38, -218, 28, -38, Blocks.STONE_BRICKS.getDefaultState());
        structure.fillWithBlocks(world, start, -218, 28, -32, -218, 28, -32, Blocks.STONE_BRICKS.getDefaultState());
        structure.fillWithBlocks(world, start, -218, 29, -37, -218, 29, -36, Blocks.STONE_BRICKS.getDefaultState());
        structure.fillWithBlocks(world, start, -218, 29, -34, -218, 30, -33, Blocks.STONE_BRICKS.getDefaultState());
        structure.fillWithBlocks(world, start, -218, 30, -38, -218, 31, -32, Blocks.STONE_BRICKS.getDefaultState());
        structure.fillWithBlocks(world, start, -218, 31, -39, -218, 31, -31, Blocks.STONE_BRICKS.getDefaultState());
        structure.fillWithBlocks(world, start, -218, 32, -40, -218, 32, -38, Blocks.STONE_BRICKS.getDefaultState());
        structure.fillWithBlocks(world, start, -218, 32, -36, -216, 32, -34, Blocks.STONE_BRICKS.getDefaultState());
        structure.fillWithBlocks(world, start, -218, 32, -33, -217, 32, -31, Blocks.STONE_BRICKS.getDefaultState());
        structure.fillWithBlocks(world, start, -218, 32, -30, -218, 33, -30, Blocks.STONE_BRICKS.getDefaultState());
        structure.fillWithBlocks(world, start, -218, 34, -40, -218, 34, -40, Blocks.DARK_OAK_PLANKS.getDefaultState());
        structure.fillWithBlocks(world, start, -218, 34, -39, -218, 34, -37, Blocks.STONE_BRICKS.getDefaultState());
        structure.fillWithBlocks(world, start, -218, 34, -35, -218, 34, -35, Blocks.STONE_BRICKS.getDefaultState());
        structure.fillWithBlocks(world, start, -218, 34, -33, -217, 34, -32, Blocks.STONE_BRICKS.getDefaultState());
        structure.fillWithBlocks(world, start, -218, 34, -31, -218, 34, -30, Blocks.DARK_OAK_PLANKS.getDefaultState());
        structure.fillWithBlocks(world, start, -218, 35, -38, -218, 35, -38, Blocks.DARK_OAK_PLANKS.getDefaultState());
        structure.fillWithBlocks(world, start, -218, 35, -32, -217, 35, -31, Blocks.DARK_OAK_PLANKS.getDefaultState());
        structure.fillWithBlocks(world, start, -218, 36, -37, -218, 36, -36, Blocks.DARK_OAK_PLANKS.getDefaultState());
        structure.fillWithBlocks(world, start, -218, 36, -34, -218, 36, -33, Blocks.DARK_OAK_PLANKS.getDefaultState());
        structure.fillWithBlocks(world, start, -217, 0, -76, -214, 0, -73, Blocks.DIRT.getDefaultState());
        structure.fillWithBlocks(world, start, -217, 0, -72, -210, 0, 40, Blocks.STONE.getDefaultState());
        structure.fillWithBlocks(world, start, -217, 1, 38, -216, 1, 39, Blocks.STONE.getDefaultState());
        structure.fillWithBlocks(world, start, -217, 1, 40, -214, 1, 43, Blocks.DIRT.getDefaultState());
        structure.fillWithBlocks(world, start, -217, 2, -64, -217, 2, -64, Blocks.STONE.getDefaultState());
        structure.fillWithBlocks(world, start, -217, 2, -63, -217, 5, -42, Blocks.DIRT.getDefaultState());
        structure.fillWithBlocks(world, start, -217, 2, -41, -217, 2, -21, Blocks.STONE.getDefaultState());
        structure.fillWithBlocks(world, start, -217, 2, -20, -217, 5, -1, Blocks.DIRT.getDefaultState());
        structure.fillWithBlocks(world, start, -217, 2, 5, -215, 2, 7, Blocks.STONE.getDefaultState());
        structure.fillWithBlocks(world, start, -217, 2, 8, -217, 5, 11, Blocks.DIRT.getDefaultState());
        structure.fillWithBlocks(world, start, -217, 2, 12, -215, 2, 14, Blocks.STONE.getDefaultState());
        structure.fillWithBlocks(world, start, -217, 2, 15, -217, 5, 33, Blocks.DIRT.getDefaultState());
        structure.fillWithBlocks(world, start, -217, 2, 34, -214, 2, 37, Blocks.STONE.getDefaultState());
        structure.fillWithBlocks(world, start, -217, 4, -73, -207, 4, -73, Blocks.GRASS_BLOCK.getDefaultState().with(SnowyDirtBlock.SNOWY, false));
        structure.fillWithBlocks(world, start, -217, 4, -72, -210, 4, 39, Blocks.DIRT.getDefaultState());
        structure.fillWithBlocks(world, start, -217, 5, -72, -215, 5, -70, Blocks.GRASS_BLOCK.getDefaultState().with(SnowyDirtBlock.SNOWY, false));
        structure.fillWithBlocks(world, start, -217, 5, 38, -216, 5, 39, Blocks.GRASS_BLOCK.getDefaultState().with(SnowyDirtBlock.SNOWY, false));
        structure.fillWithBlocks(world, start, -217, 6, -47, -214, 6, -41, Blocks.GRASS_BLOCK.getDefaultState().with(SnowyDirtBlock.SNOWY, false));
        structure.fillWithBlocks(world, start, -217, 6, -39, -217, 6, -39, Blocks.DIRT.getDefaultState());
        structure.fillWithBlocks(world, start, -217, 6, -38, -217, 6, -32, Blocks.COBBLESTONE.getDefaultState());
        structure.fillWithBlocks(world, start, -217, 6, -31, -217, 6, -30, Blocks.DIRT.getDefaultState());
        structure.fillWithBlocks(world, start, -217, 6, -23, -215, 6, 9, Blocks.GRASS_BLOCK.getDefaultState().with(SnowyDirtBlock.SNOWY, false));
        structure.fillWithBlocks(world, start, -217, 6, 17, -216, 6, 23, Blocks.GRASS_BLOCK.getDefaultState().with(SnowyDirtBlock.SNOWY, false));
        structure.fillWithBlocks(world, start, -217, 6, 25, -206, 6, 36, Blocks.GRASS_BLOCK.getDefaultState().with(SnowyDirtBlock.SNOWY, false));
        structure.fillWithBlocks(world, start, -217, 7, -48, -217, 12, -48, Blocks.OAK_LOG.getDefaultState());
        structure.fillWithBlocks(world, start, -217, 7, -39, -217, 9, -39, Blocks.STONE_BRICKS.getDefaultState());
        structure.fillWithBlocks(world, start, -217, 7, -31, -217, 9, -31, Blocks.STONE_BRICKS.getDefaultState());
        structure.fillWithBlocks(world, start, -217, 7, -23, -216, 7, -23, Blocks.GRASS.getDefaultState());
        structure.fillWithBlocks(world, start, -217, 7, 16, -217, 7, 16, Blocks.GRASS.getDefaultState());
        structure.fillWithBlocks(world, start, -217, 7, 24, -217, 10, 24, Blocks.OAK_LOG.getDefaultState());
        structure.fillWithBlocks(world, start, -217, 8, -51, -217, 10, -51, Blocks.OAK_LEAVES.getDefaultState().with(LeavesBlock.PERSISTENT, false).with(LeavesBlock.DISTANCE, 2));
        structure.fillWithBlocks(world, start, -217, 8, -50, -217, 9, -50, Blocks.OAK_LEAVES.getDefaultState().with(LeavesBlock.PERSISTENT, false).with(LeavesBlock.DISTANCE, 3));
        structure.fillWithBlocks(world, start, -217, 8, 15, -217, 10, 15, Blocks.OAK_LEAVES.getDefaultState().with(LeavesBlock.PERSISTENT, false).with(LeavesBlock.DISTANCE, 3));
        structure.fillWithBlocks(world, start, -217, 8, 16, -216, 9, 16, Blocks.OAK_LEAVES.getDefaultState().with(LeavesBlock.PERSISTENT, false).with(LeavesBlock.DISTANCE, 2));
        structure.fillWithBlocks(world, start, -217, 8, 17, -216, 9, 17, Blocks.OAK_LEAVES.getDefaultState().with(LeavesBlock.PERSISTENT, false).with(LeavesBlock.DISTANCE, 1));
        structure.fillWithBlocks(world, start, -217, 8, 18, -216, 9, 18, Blocks.OAK_LEAVES.getDefaultState().with(LeavesBlock.PERSISTENT, false).with(LeavesBlock.DISTANCE, 2));
        structure.fillWithBlocks(world, start, -217, 8, 19, -216, 9, 19, Blocks.OAK_LEAVES.getDefaultState().with(LeavesBlock.PERSISTENT, false).with(LeavesBlock.DISTANCE, 3));
        structure.fillWithBlocks(world, start, -217, 8, 22, -217, 9, 22, Blocks.OAK_LEAVES.getDefaultState().with(LeavesBlock.PERSISTENT, false).with(LeavesBlock.DISTANCE, 2));
        structure.fillWithBlocks(world, start, -217, 8, 23, -217, 10, 23, Blocks.OAK_LEAVES.getDefaultState().with(LeavesBlock.PERSISTENT, false).with(LeavesBlock.DISTANCE, 1));
        structure.fillWithBlocks(world, start, -217, 8, 25, -217, 10, 25, Blocks.OAK_LEAVES.getDefaultState().with(LeavesBlock.PERSISTENT, false).with(LeavesBlock.DISTANCE, 1));
        structure.fillWithBlocks(world, start, -217, 9, -55, -217, 10, -55, Blocks.OAK_LEAVES.getDefaultState().with(LeavesBlock.PERSISTENT, false).with(LeavesBlock.DISTANCE, 3));
        structure.fillWithBlocks(world, start, -217, 9, -54, -217, 10, -54, Blocks.OAK_LEAVES.getDefaultState().with(LeavesBlock.PERSISTENT, false).with(LeavesBlock.DISTANCE, 2));
        structure.fillWithBlocks(world, start, -217, 9, -53, -217, 11, -53, Blocks.OAK_LEAVES.getDefaultState().with(LeavesBlock.PERSISTENT, false).with(LeavesBlock.DISTANCE, 1));
        structure.fillWithBlocks(world, start, -217, 9, -52, -217, 9, -51, Blocks.OAK_LEAVES.getDefaultState().with(LeavesBlock.PERSISTENT, false).with(LeavesBlock.DISTANCE, 2));
        structure.fillWithBlocks(world, start, -217, 9, -45, -217, 10, -45, Blocks.OAK_LEAVES.getDefaultState().with(LeavesBlock.PERSISTENT, false).with(LeavesBlock.DISTANCE, 2));
        structure.fillWithBlocks(world, start, -217, 9, -44, -217, 10, -44, Blocks.OAK_LEAVES.getDefaultState().with(LeavesBlock.PERSISTENT, false).with(LeavesBlock.DISTANCE, 3));
        structure.fillWithBlocks(world, start, -217, 9, -43, -217, 10, -43, Blocks.OAK_LEAVES.getDefaultState().with(LeavesBlock.PERSISTENT, false).with(LeavesBlock.DISTANCE, 4));
        structure.fillWithBlocks(world, start, -217, 9, -25, -217, 9, -25, Blocks.OAK_LEAVES.getDefaultState().with(LeavesBlock.PERSISTENT, false).with(LeavesBlock.DISTANCE, 3));
        structure.fillWithBlocks(world, start, -217, 9, -24, -217, 10, -24, Blocks.OAK_LEAVES.getDefaultState().with(LeavesBlock.PERSISTENT, false).with(LeavesBlock.DISTANCE, 2));
        structure.fillWithBlocks(world, start, -217, 9, -23, -217, 11, -23, Blocks.OAK_LEAVES.getDefaultState().with(LeavesBlock.PERSISTENT, false).with(LeavesBlock.DISTANCE, 1));
        structure.fillWithBlocks(world, start, -217, 9, -22, -216, 10, -22, Blocks.OAK_LEAVES.getDefaultState().with(LeavesBlock.PERSISTENT, false).with(LeavesBlock.DISTANCE, 2));
        structure.fillWithBlocks(world, start, -217, 9, -21, -216, 10, -21, Blocks.OAK_LEAVES.getDefaultState().with(LeavesBlock.PERSISTENT, false).with(LeavesBlock.DISTANCE, 3));
        structure.fillWithBlocks(world, start, -217, 9, 1, -217, 10, 1, Blocks.OAK_LEAVES.getDefaultState().with(LeavesBlock.PERSISTENT, false).with(LeavesBlock.DISTANCE, 3));
        structure.fillWithBlocks(world, start, -217, 9, 2, -217, 11, 2, Blocks.OAK_LEAVES.getDefaultState().with(LeavesBlock.PERSISTENT, false).with(LeavesBlock.DISTANCE, 2));
        structure.fillWithBlocks(world, start, -217, 9, 3, -217, 11, 3, Blocks.OAK_LEAVES.getDefaultState().with(LeavesBlock.PERSISTENT, false).with(LeavesBlock.DISTANCE, 1));
        structure.fillWithBlocks(world, start, -217, 9, 4, -217, 10, 4, Blocks.OAK_LEAVES.getDefaultState().with(LeavesBlock.PERSISTENT, false).with(LeavesBlock.DISTANCE, 2));
        structure.fillWithBlocks(world, start, -217, 9, 5, -217, 10, 5, Blocks.OAK_LEAVES.getDefaultState().with(LeavesBlock.PERSISTENT, false).with(LeavesBlock.DISTANCE, 3));
        structure.fillWithBlocks(world, start, -217, 10, -52, -217, 10, -50, Blocks.OAK_LEAVES.getDefaultState().with(LeavesBlock.PERSISTENT, false).with(LeavesBlock.DISTANCE, 2));
        structure.fillWithBlocks(world, start, -217, 10, -49, -217, 12, -49, Blocks.OAK_LEAVES.getDefaultState().with(LeavesBlock.PERSISTENT, false).with(LeavesBlock.DISTANCE, 1));
        structure.fillWithBlocks(world, start, -217, 10, -47, -217, 12, -47, Blocks.OAK_LEAVES.getDefaultState().with(LeavesBlock.PERSISTENT, false).with(LeavesBlock.DISTANCE, 1));
        structure.fillWithBlocks(world, start, -217, 10, -46, -217, 10, -45, Blocks.OAK_LEAVES.getDefaultState().with(LeavesBlock.PERSISTENT, false).with(LeavesBlock.DISTANCE, 2));
        structure.fillWithBlocks(world, start, -217, 10, -25, -217, 10, -25, Blocks.OAK_LEAVES.getDefaultState().with(LeavesBlock.PERSISTENT, false).with(LeavesBlock.DISTANCE, 3));
        structure.fillWithBlocks(world, start, -217, 10, -5, -217, 11, -5, Blocks.OAK_LEAVES.getDefaultState().with(LeavesBlock.PERSISTENT, false).with(LeavesBlock.DISTANCE, 4));
        structure.fillWithBlocks(world, start, -217, 10, -4, -217, 11, -4, Blocks.OAK_LEAVES.getDefaultState().with(LeavesBlock.PERSISTENT, false).with(LeavesBlock.DISTANCE, 3));
        structure.fillWithBlocks(world, start, -217, 10, -3, -217, 11, -3, Blocks.OAK_LEAVES.getDefaultState().with(LeavesBlock.PERSISTENT, false).with(LeavesBlock.DISTANCE, 2));
        structure.fillWithBlocks(world, start, -217, 10, -2, -217, 11, -2, Blocks.OAK_LEAVES.getDefaultState().with(LeavesBlock.PERSISTENT, false).with(LeavesBlock.DISTANCE, 3));
        structure.fillWithBlocks(world, start, -217, 10, 8, -217, 11, 8, Blocks.OAK_LEAVES.getDefaultState().with(LeavesBlock.PERSISTENT, false).with(LeavesBlock.DISTANCE, 3));
        structure.fillWithBlocks(world, start, -217, 10, 9, -217, 12, 9, Blocks.OAK_LEAVES.getDefaultState().with(LeavesBlock.PERSISTENT, false).with(LeavesBlock.DISTANCE, 2));
        structure.fillWithBlocks(world, start, -217, 10, 10, -217, 12, 10, Blocks.OAK_LEAVES.getDefaultState().with(LeavesBlock.PERSISTENT, false).with(LeavesBlock.DISTANCE, 1));
        structure.fillWithBlocks(world, start, -217, 10, 11, -217, 12, 11, Blocks.OAK_LEAVES.getDefaultState().with(LeavesBlock.PERSISTENT, false).with(LeavesBlock.DISTANCE, 2));
        structure.fillWithBlocks(world, start, -217, 10, 12, -217, 11, 12, Blocks.OAK_LEAVES.getDefaultState().with(LeavesBlock.PERSISTENT, false).with(LeavesBlock.DISTANCE, 3));
        structure.fillWithBlocks(world, start, -217, 10, 16, -216, 10, 16, Blocks.OAK_LEAVES.getDefaultState().with(LeavesBlock.PERSISTENT, false).with(LeavesBlock.DISTANCE, 2));
        structure.fillWithBlocks(world, start, -217, 10, 17, -216, 10, 17, Blocks.OAK_LEAVES.getDefaultState().with(LeavesBlock.PERSISTENT, false).with(LeavesBlock.DISTANCE, 1));
        structure.fillWithBlocks(world, start, -217, 10, 18, -216, 10, 18, Blocks.OAK_LEAVES.getDefaultState().with(LeavesBlock.PERSISTENT, false).with(LeavesBlock.DISTANCE, 2));
        structure.fillWithBlocks(world, start, -217, 10, 19, -216, 10, 19, Blocks.OAK_LEAVES.getDefaultState().with(LeavesBlock.PERSISTENT, false).with(LeavesBlock.DISTANCE, 3));
        structure.fillWithBlocks(world, start, -217, 11, -50, -217, 11, -50, Blocks.OAK_LEAVES.getDefaultState().with(LeavesBlock.PERSISTENT, false).with(LeavesBlock.DISTANCE, 2));
        structure.fillWithBlocks(world, start, -217, 11, -39, -217, 13, -39, Blocks.STONE_BRICKS.getDefaultState());
        structure.fillWithBlocks(world, start, -217, 11, -31, -217, 13, -31, Blocks.STONE_BRICKS.getDefaultState());
        structure.fillWithBlocks(world, start, -217, 11, 17, -217, 11, 17, Blocks.OAK_LEAVES.getDefaultState().with(LeavesBlock.PERSISTENT, false).with(LeavesBlock.DISTANCE, 2));
        structure.fillWithBlocks(world, start, -217, 11, 23, -217, 11, 23, Blocks.OAK_LEAVES.getDefaultState().with(LeavesBlock.PERSISTENT, false).with(LeavesBlock.DISTANCE, 2));
        structure.fillWithBlocks(world, start, -217, 12, -53, -217, 12, -53, Blocks.OAK_LEAVES.getDefaultState().with(LeavesBlock.PERSISTENT, false).with(LeavesBlock.DISTANCE, 2));
        structure.fillWithBlocks(world, start, -217, 12, -40, -217, 12, -40, Blocks.COBBLESTONE_WALL.getDefaultState().with(WallBlock.WATERLOGGED, false).with(WallBlock.UP, true).with(WallBlock.WALL_HEIGHT_NORTH, WallHeight.LOW).with(WallBlock.WALL_HEIGHT_SOUTH, WallHeight.LOW).with(WallBlock.WALL_HEIGHT_EAST, WallHeight.LOW).with(WallBlock.WALL_HEIGHT_WEST, WallHeight.LOW));
        structure.fillWithBlocks(world, start, -217, 12, -37, -216, 12, -32, Blocks.STONE_BRICKS.getDefaultState());
        structure.fillWithBlocks(world, start, -217, 13, -49, -217, 13, -49, Blocks.OAK_LEAVES.getDefaultState().with(LeavesBlock.PERSISTENT, false).with(LeavesBlock.DISTANCE, 2));
        structure.fillWithBlocks(world, start, -217, 13, -38, -216, 13, -32, Blocks.STONE_BRICKS.getDefaultState());
        structure.fillWithBlocks(world, start, -217, 13, 10, -217, 13, 10, Blocks.OAK_LEAVES.getDefaultState().with(LeavesBlock.PERSISTENT, false).with(LeavesBlock.DISTANCE, 2));
        structure.fillWithBlocks(world, start, -217, 14, -38, -216, 14, -32, Blocks.STONE_BRICKS.getDefaultState());
        structure.fillWithBlocks(world, start, -217, 15, -39, -217, 15, -34, Blocks.STONE_BRICKS.getDefaultState());
        structure.fillWithBlocks(world, start, -217, 15, -32, -217, 16, -31, Blocks.STONE_BRICKS.getDefaultState());
        structure.fillWithBlocks(world, start, -217, 16, -39, -217, 16, -31, Blocks.STONE_BRICKS.getDefaultState());
        structure.fillWithBlocks(world, start, -217, 17, -39, -217, 17, -31, Blocks.STONE_BRICKS.getDefaultState());
        structure.fillWithBlocks(world, start, -217, 18, -38, -216, 18, -32, Blocks.STONE_BRICKS.getDefaultState());
        structure.fillWithBlocks(world, start, -217, 19, -39, -217, 19, -31, Blocks.STONE_BRICKS.getDefaultState());
        structure.fillWithBlocks(world, start, -217, 20, -39, -217, 20, -31, Blocks.STONE_BRICKS.getDefaultState());
        structure.fillWithBlocks(world, start, -217, 21, -39, -217, 21, -31, Blocks.STONE_BRICKS.getDefaultState());
        structure.fillWithBlocks(world, start, -217, 22, -38, -216, 22, -32, Blocks.STONE_BRICKS.getDefaultState());
        structure.fillWithBlocks(world, start, -217, 23, -39, -217, 23, -37, Blocks.STONE_BRICKS.getDefaultState());
        structure.fillWithBlocks(world, start, -217, 23, -33, -216, 23, -32, Blocks.STONE_BRICKS.getDefaultState());
        structure.fillWithBlocks(world, start, -217, 24, -38, -217, 27, -38, Blocks.STONE_BRICKS.getDefaultState());
        structure.fillWithBlocks(world, start, -217, 24, -32, -217, 27, -32, Blocks.STONE_BRICKS.getDefaultState());
        structure.fillWithBlocks(world, start, -217, 28, -37, -217, 28, -36, Blocks.STONE_BRICKS.getDefaultState());
        structure.fillWithBlocks(world, start, -217, 28, -34, -217, 28, -33, Blocks.STONE_BRICKS.getDefaultState());
        structure.fillWithBlocks(world, start, -217, 29, -37, -217, 30, -37, Blocks.CHISELED_STONE_BRICKS.getDefaultState());
        structure.fillWithBlocks(world, start, -217, 29, -36, -216, 29, -34, Blocks.STONE_BRICKS.getDefaultState());
        structure.fillWithBlocks(world, start, -217, 29, -33, -217, 30, -33, Blocks.CHISELED_STONE_BRICKS.getDefaultState());
        structure.fillWithBlocks(world, start, -217, 30, -36, -217, 32, -34, Blocks.STONE_BRICKS.getDefaultState());
        structure.fillWithBlocks(world, start, -217, 31, -38, -217, 33, -38, Blocks.STONE_BRICKS.getDefaultState());
        structure.fillWithBlocks(world, start, -217, 31, -32, -217, 34, -32, Blocks.STONE_BRICKS.getDefaultState());
        structure.fillWithBlocks(world, start, -217, 32, -40, -217, 32, -40, Blocks.STONE_BRICK_SLAB.getDefaultState().with(SlabBlock.TYPE, SlabType.TOP).with(SlabBlock.WATERLOGGED, false));
        structure.fillWithBlocks(world, start, -217, 32, -39, -217, 32, -31, Blocks.STONE_BRICKS.getDefaultState());
        structure.fillWithBlocks(world, start, -217, 33, -39, -217, 36, -39, Blocks.DARK_OAK_PLANKS.getDefaultState());
        structure.fillWithBlocks(world, start, -217, 33, -37, -216, 33, -32, Blocks.STONE_BRICKS.getDefaultState());
        structure.fillWithBlocks(world, start, -217, 33, -31, -217, 36, -31, Blocks.DARK_OAK_PLANKS.getDefaultState());
        structure.fillWithBlocks(world, start, -217, 34, -38, -216, 34, -38, Blocks.DARK_OAK_PLANKS.getDefaultState());
        structure.fillWithBlocks(world, start, -217, 34, -37, -216, 34, -33, Blocks.STONE_BRICKS.getDefaultState());
        structure.fillWithBlocks(world, start, -217, 35, -38, -217, 35, -31, Blocks.DARK_OAK_PLANKS.getDefaultState());
        structure.fillWithBlocks(world, start, -217, 36, -36, -217, 36, -34, Blocks.DARK_OAK_PLANKS.getDefaultState());
        structure.fillWithBlocks(world, start, -216, 0, -78, -216, 0, -77, Blocks.GRASS_BLOCK.getDefaultState().with(SnowyDirtBlock.SNOWY, false));
        structure.fillWithBlocks(world, start, -216, 0, 41, -211, 0, 41, Blocks.STONE.getDefaultState());
        structure.fillWithBlocks(world, start, -216, 1, -51, -215, 1, -50, Blocks.DIRT.getDefaultState());
        structure.fillWithBlocks(world, start, -216, 1, -49, -216, 1, 39, Blocks.STONE.getDefaultState());
        structure.fillWithBlocks(world, start, -216, 2, -64, -214, 2, -62, Blocks.STONE.getDefaultState());
        structure.fillWithBlocks(world, start, -216, 2, -61, -216, 5, -41, Blocks.DIRT.getDefaultState());
        structure.fillWithBlocks(world, start, -216, 2, -40, -216, 2, -19, Blocks.STONE.getDefaultState());
        structure.fillWithBlocks(world, start, -216, 2, -18, -216, 5, -1, Blocks.DIRT.getDefaultState());
        structure.fillWithBlocks(world, start, -216, 2, 8, -209, 2, 15, Blocks.STONE.getDefaultState());
        structure.fillWithBlocks(world, start, -216, 2, 16, -215, 2, 17, Blocks.STONE.getDefaultState());
        structure.fillWithBlocks(world, start, -216, 2, 18, -216, 5, 33, Blocks.DIRT.getDefaultState());
        structure.fillWithBlocks(world, start, -216, 6, -54, -216, 6, -54, Blocks.GRASS_BLOCK.getDefaultState().with(SnowyDirtBlock.SNOWY, false));
        structure.fillWithBlocks(world, start, -216, 6, -52, -209, 6, -45, Blocks.GRASS_BLOCK.getDefaultState().with(SnowyDirtBlock.SNOWY, false));
        structure.fillWithBlocks(world, start, -216, 6, -40, -216, 6, -40, Blocks.GRASS_BLOCK.getDefaultState().with(SnowyDirtBlock.SNOWY, false));
        structure.fillWithBlocks(world, start, -216, 6, -39, -216, 6, -37, Blocks.DIRT.getDefaultState());
        structure.fillWithBlocks(world, start, -216, 6, -36, -216, 6, -34, Blocks.COBBLESTONE.getDefaultState());
        structure.fillWithBlocks(world, start, -216, 6, -33, -216, 6, -31, Blocks.DIRT.getDefaultState());
        structure.fillWithBlocks(world, start, -216, 6, -30, -213, 6, -27, Blocks.GRASS_BLOCK.getDefaultState().with(SnowyDirtBlock.SNOWY, false));
        structure.fillWithBlocks(world, start, -216, 6, 11, -213, 6, 16, Blocks.GRASS_BLOCK.getDefaultState().with(SnowyDirtBlock.SNOWY, false));
        structure.fillWithBlocks(world, start, -216, 6, 24, -204, 6, 36, Blocks.GRASS_BLOCK.getDefaultState().with(SnowyDirtBlock.SNOWY, false));
        structure.fillWithBlocks(world, start, -216, 7, -53, -216, 11, -53, Blocks.OAK_LOG.getDefaultState());
        structure.fillWithBlocks(world, start, -216, 7, -38, -216, 8, -37, Blocks.STONE_BRICKS.getDefaultState());
        structure.fillWithBlocks(world, start, -216, 7, -33, -216, 8, -32, Blocks.STONE_BRICKS.getDefaultState());
        structure.fillWithBlocks(world, start, -216, 7, -29, -216, 7, -28, Blocks.GRASS.getDefaultState());
        structure.fillWithBlocks(world, start, -216, 7, 10, -216, 12, 10, Blocks.OAK_LOG.getDefaultState());
        structure.fillWithBlocks(world, start, -216, 7, 20, -216, 7, 20, Blocks.GRASS.getDefaultState());
        structure.fillWithBlocks(world, start, -216, 8, -36, -216, 8, -34, Blocks.SPRUCE_TRAPDOOR.getDefaultState().with(HorizontalBlock.HORIZONTAL_FACING, Direction.WEST).with(TrapDoorBlock.HALF, Half.TOP).with(TrapDoorBlock.WATERLOGGED, false).with(TrapDoorBlock.POWERED, false).with(TrapDoorBlock.OPEN, false));
        structure.fillWithBlocks(world, start, -216, 8, 22, -216, 9, 22, Blocks.OAK_LEAVES.getDefaultState().with(LeavesBlock.PERSISTENT, false).with(LeavesBlock.DISTANCE, 3));
        structure.fillWithBlocks(world, start, -216, 8, 23, -216, 10, 23, Blocks.OAK_LEAVES.getDefaultState().with(LeavesBlock.PERSISTENT, false).with(LeavesBlock.DISTANCE, 2));
        structure.fillWithBlocks(world, start, -216, 8, 24, -216, 10, 24, Blocks.OAK_LEAVES.getDefaultState().with(LeavesBlock.PERSISTENT, false).with(LeavesBlock.DISTANCE, 1));
        structure.fillWithBlocks(world, start, -216, 8, 25, -216, 10, 25, Blocks.OAK_LEAVES.getDefaultState().with(LeavesBlock.PERSISTENT, false).with(LeavesBlock.DISTANCE, 2));
        structure.fillWithBlocks(world, start, -216, 9, -55, -216, 10, -55, Blocks.OAK_LEAVES.getDefaultState().with(LeavesBlock.PERSISTENT, false).with(LeavesBlock.DISTANCE, 2));
        structure.fillWithBlocks(world, start, -216, 9, -54, -216, 11, -54, Blocks.OAK_LEAVES.getDefaultState().with(LeavesBlock.PERSISTENT, false).with(LeavesBlock.DISTANCE, 1));
        structure.fillWithBlocks(world, start, -216, 9, -52, -216, 11, -52, Blocks.OAK_LEAVES.getDefaultState().with(LeavesBlock.PERSISTENT, false).with(LeavesBlock.DISTANCE, 1));
        structure.fillWithBlocks(world, start, -216, 9, -51, -216, 10, -51, Blocks.OAK_LEAVES.getDefaultState().with(LeavesBlock.PERSISTENT, false).with(LeavesBlock.DISTANCE, 2));
        structure.fillWithBlocks(world, start, -216, 9, -38, -216, 10, -37, Blocks.STONE_BRICKS.getDefaultState());
        structure.fillWithBlocks(world, start, -216, 9, -33, -216, 10, -32, Blocks.STONE_BRICKS.getDefaultState());
        structure.fillWithBlocks(world, start, -216, 9, -27, -216, 10, -27, Blocks.OAK_LEAVES.getDefaultState().with(LeavesBlock.PERSISTENT, false).with(LeavesBlock.DISTANCE, 3));
        structure.fillWithBlocks(world, start, -216, 9, -26, -216, 10, -26, Blocks.OAK_LEAVES.getDefaultState().with(LeavesBlock.PERSISTENT, false).with(LeavesBlock.DISTANCE, 2));
        structure.fillWithBlocks(world, start, -216, 9, -25, -216, 9, -24, Blocks.OAK_LEAVES.getDefaultState().with(LeavesBlock.PERSISTENT, false).with(LeavesBlock.DISTANCE, 3));
        structure.fillWithBlocks(world, start, -216, 9, -23, -216, 10, -22, Blocks.OAK_LEAVES.getDefaultState().with(LeavesBlock.PERSISTENT, false).with(LeavesBlock.DISTANCE, 2));
        structure.fillWithBlocks(world, start, -216, 9, 2, -216, 10, 2, Blocks.OAK_LEAVES.getDefaultState().with(LeavesBlock.PERSISTENT, false).with(LeavesBlock.DISTANCE, 3));
        structure.fillWithBlocks(world, start, -216, 9, 3, -216, 10, 3, Blocks.OAK_LEAVES.getDefaultState().with(LeavesBlock.PERSISTENT, false).with(LeavesBlock.DISTANCE, 2));
        structure.fillWithBlocks(world, start, -216, 9, 4, -216, 10, 4, Blocks.OAK_LEAVES.getDefaultState().with(LeavesBlock.PERSISTENT, false).with(LeavesBlock.DISTANCE, 3));
        structure.fillWithBlocks(world, start, -216, 9, 15, -216, 10, 15, Blocks.OAK_LEAVES.getDefaultState().with(LeavesBlock.PERSISTENT, false).with(LeavesBlock.DISTANCE, 3));
        structure.fillWithBlocks(world, start, -216, 10, -50, -216, 11, -50, Blocks.OAK_LEAVES.getDefaultState().with(LeavesBlock.PERSISTENT, false).with(LeavesBlock.DISTANCE, 3));
        structure.fillWithBlocks(world, start, -216, 10, -49, -216, 11, -49, Blocks.OAK_LEAVES.getDefaultState().with(LeavesBlock.PERSISTENT, false).with(LeavesBlock.DISTANCE, 2));
        structure.fillWithBlocks(world, start, -216, 10, -48, -216, 12, -48, Blocks.OAK_LEAVES.getDefaultState().with(LeavesBlock.PERSISTENT, false).with(LeavesBlock.DISTANCE, 1));
        structure.fillWithBlocks(world, start, -216, 10, -47, -216, 12, -47, Blocks.OAK_LEAVES.getDefaultState().with(LeavesBlock.PERSISTENT, false).with(LeavesBlock.DISTANCE, 2));
        structure.fillWithBlocks(world, start, -216, 10, -46, -216, 11, -46, Blocks.OAK_LEAVES.getDefaultState().with(LeavesBlock.PERSISTENT, false).with(LeavesBlock.DISTANCE, 3));
        structure.fillWithBlocks(world, start, -216, 10, -25, -216, 10, -24, Blocks.OAK_LEAVES.getDefaultState().with(LeavesBlock.PERSISTENT, false).with(LeavesBlock.DISTANCE, 3));
        structure.fillWithBlocks(world, start, -216, 10, 8, -216, 11, 8, Blocks.OAK_LEAVES.getDefaultState().with(LeavesBlock.PERSISTENT, false).with(LeavesBlock.DISTANCE, 2));
        structure.fillWithBlocks(world, start, -216, 10, 9, -216, 12, 9, Blocks.OAK_LEAVES.getDefaultState().with(LeavesBlock.PERSISTENT, false).with(LeavesBlock.DISTANCE, 1));
        structure.fillWithBlocks(world, start, -216, 10, 11, -216, 12, 11, Blocks.OAK_LEAVES.getDefaultState().with(LeavesBlock.PERSISTENT, false).with(LeavesBlock.DISTANCE, 1));
        structure.fillWithBlocks(world, start, -216, 10, 12, -216, 11, 12, Blocks.OAK_LEAVES.getDefaultState().with(LeavesBlock.PERSISTENT, false).with(LeavesBlock.DISTANCE, 2));
        structure.fillWithBlocks(world, start, -216, 11, -38, -216, 12, -37, Blocks.STONE_BRICKS.getDefaultState());
        structure.fillWithBlocks(world, start, -216, 11, -33, -216, 12, -32, Blocks.STONE_BRICKS.getDefaultState());
        structure.fillWithBlocks(world, start, -216, 11, 17, -216, 11, 17, Blocks.OAK_LEAVES.getDefaultState().with(LeavesBlock.PERSISTENT, false).with(LeavesBlock.DISTANCE, 1));
        structure.fillWithBlocks(world, start, -216, 12, -54, -216, 12, -54, Blocks.OAK_LEAVES.getDefaultState().with(LeavesBlock.PERSISTENT, false).with(LeavesBlock.DISTANCE, 2));
        structure.fillWithBlocks(world, start, -216, 12, 17, -216, 12, 17, Blocks.OAK_LEAVES.getDefaultState().with(LeavesBlock.PERSISTENT, false).with(LeavesBlock.DISTANCE, 2));
        structure.fillWithBlocks(world, start, -216, 13, 9, -216, 13, 9, Blocks.OAK_LEAVES.getDefaultState().with(LeavesBlock.PERSISTENT, false).with(LeavesBlock.DISTANCE, 2));
        structure.fillWithBlocks(world, start, -216, 15, -38, -216, 16, -37, Blocks.STONE_BRICKS.getDefaultState());
        structure.fillWithBlocks(world, start, -216, 15, -33, -216, 16, -32, Blocks.STONE_BRICKS.getDefaultState());
        structure.fillWithBlocks(world, start, -216, 16, -36, -215, 16, -36, Blocks.STONE_BRICKS.getDefaultState());
        structure.fillWithBlocks(world, start, -216, 16, -34, -216, 18, -32, Blocks.STONE_BRICKS.getDefaultState());
        structure.fillWithBlocks(world, start, -216, 17, -38, -216, 22, -32, Blocks.STONE_BRICKS.getDefaultState());
        structure.fillWithBlocks(world, start, -216, 23, -38, -216, 23, -36, Blocks.STONE_BRICKS.getDefaultState());
        structure.fillWithBlocks(world, start, -216, 23, -34, -216, 24, -33, Blocks.STONE_BRICKS.getDefaultState());
        structure.fillWithBlocks(world, start, -216, 24, -37, -216, 25, -36, Blocks.STONE_BRICKS.getDefaultState());
        structure.fillWithBlocks(world, start, -216, 24, -35, -216, 25, -35, Blocks.DARK_OAK_PLANKS.getDefaultState());
        structure.fillWithBlocks(world, start, -216, 25, -34, -216, 26, -33, Blocks.STONE_BRICKS.getDefaultState());
        structure.fillWithBlocks(world, start, -216, 26, -37, -216, 26, -36, Blocks.STONE_BRICKS.getDefaultState());
        structure.fillWithBlocks(world, start, -216, 27, -37, -216, 29, -37, Blocks.STONE_BRICKS.getDefaultState());
        structure.fillWithBlocks(world, start, -216, 27, -35, -216, 29, -35, Blocks.STONE_BRICKS.getDefaultState());
        structure.fillWithBlocks(world, start, -216, 27, -33, -216, 29, -33, Blocks.STONE_BRICKS.getDefaultState());
        structure.fillWithBlocks(world, start, -216, 28, -36, -216, 28, -36, Blocks.STONE_BRICK_STAIRS.getDefaultState().with(StairsBlock.FACING, Direction.WEST).with(StairsBlock.WATERLOGGED, false).with(StairsBlock.SHAPE, StairsShape.STRAIGHT).with(StairsBlock.HALF, Half.TOP));
        structure.fillWithBlocks(world, start, -216, 32, -38, -216, 33, -38, Blocks.STONE_BRICKS.getDefaultState());
        structure.fillWithBlocks(world, start, -216, 32, -37, -216, 32, -37, Blocks.STONE_BRICK_STAIRS.getDefaultState().with(StairsBlock.FACING, Direction.WEST).with(StairsBlock.WATERLOGGED, false).with(StairsBlock.SHAPE, StairsShape.STRAIGHT).with(StairsBlock.HALF, Half.TOP));
        structure.fillWithBlocks(world, start, -216, 32, -32, -216, 33, -32, Blocks.STONE_BRICKS.getDefaultState());
        structure.fillWithBlocks(world, start, -216, 35, -36, -216, 35, -34, Blocks.DARK_OAK_PLANKS.getDefaultState());
        structure.fillWithBlocks(world, start, -215, 0, -78, -207, 0, -78, Blocks.GRASS_BLOCK.getDefaultState().with(SnowyDirtBlock.SNOWY, false));
        structure.fillWithBlocks(world, start, -215, 0, -77, -211, 0, -73, Blocks.DIRT.getDefaultState());
        structure.fillWithBlocks(world, start, -215, 0, 42, -213, 0, 44, Blocks.DIRT.getDefaultState());
        structure.fillWithBlocks(world, start, -215, 1, -77, -214, 1, -76, Blocks.GRASS_BLOCK.getDefaultState().with(SnowyDirtBlock.SNOWY, false));
        structure.fillWithBlocks(world, start, -215, 1, -52, -211, 1, -48, Blocks.DIRT.getDefaultState());
        structure.fillWithBlocks(world, start, -215, 1, -47, -215, 1, 39, Blocks.STONE.getDefaultState());
        structure.fillWithBlocks(world, start, -215, 2, -69, -208, 5, -69, Blocks.DIRT.getDefaultState());
        structure.fillWithBlocks(world, start, -215, 2, -68, -213, 2, -60, Blocks.STONE.getDefaultState());
        structure.fillWithBlocks(world, start, -215, 2, -59, -215, 2, -40, Blocks.DIRT.getDefaultState());
        structure.fillWithBlocks(world, start, -215, 2, -39, -215, 2, -17, Blocks.STONE.getDefaultState());
        structure.fillWithBlocks(world, start, -215, 2, -16, -215, 2, -2, Blocks.DIRT.getDefaultState());
        structure.fillWithBlocks(world, start, -215, 2, -1, -206, 2, 9, Blocks.STONE.getDefaultState());
        structure.fillWithBlocks(world, start, -215, 2, 18, -214, 2, 19, Blocks.STONE.getDefaultState());
        structure.fillWithBlocks(world, start, -215, 2, 20, -203, 2, 32, Blocks.DIRT.getDefaultState());
        structure.fillWithBlocks(world, start, -215, 2, 33, -214, 2, 37, Blocks.STONE.getDefaultState());
        structure.fillWithBlocks(world, start, -215, 5, 38, -214, 5, 39, Blocks.GRASS_BLOCK.getDefaultState().with(SnowyDirtBlock.SNOWY, false));
        structure.fillWithBlocks(world, start, -215, 6, -54, -213, 6, -45, Blocks.GRASS_BLOCK.getDefaultState().with(SnowyDirtBlock.SNOWY, false));
        structure.fillWithBlocks(world, start, -215, 6, -40, -213, 6, -38, Blocks.GRASS_BLOCK.getDefaultState().with(SnowyDirtBlock.SNOWY, false));
        structure.fillWithBlocks(world, start, -215, 6, -37, -215, 6, -33, Blocks.DIRT.getDefaultState());
        structure.fillWithBlocks(world, start, -215, 6, -32, -212, 6, -27, Blocks.GRASS_BLOCK.getDefaultState().with(SnowyDirtBlock.SNOWY, false));
        structure.fillWithBlocks(world, start, -215, 6, 10, -212, 6, 13, Blocks.GRASS_BLOCK.getDefaultState().with(SnowyDirtBlock.SNOWY, false));
        structure.fillWithBlocks(world, start, -215, 6, 18, -213, 6, 37, Blocks.GRASS_BLOCK.getDefaultState().with(SnowyDirtBlock.SNOWY, false));
        structure.fillWithBlocks(world, start, -215, 7, -49, -215, 7, -48, Blocks.GRASS.getDefaultState());
        structure.fillWithBlocks(world, start, -215, 7, -45, -215, 7, -44, Blocks.GRASS.getDefaultState());
        structure.fillWithBlocks(world, start, -215, 7, -38, -214, 7, -38, Blocks.GRASS.getDefaultState());
        structure.fillWithBlocks(world, start, -215, 7, -12, -215, 7, -12, Blocks.GRASS.getDefaultState());
        structure.fillWithBlocks(world, start, -215, 7, 16, -215, 7, 16, Blocks.GRASS.getDefaultState());
        structure.fillWithBlocks(world, start, -215, 7, 17, -215, 11, 17, Blocks.OAK_LOG.getDefaultState());
        structure.fillWithBlocks(world, start, -215, 7, 19, -214, 7, 19, Blocks.GRASS.getDefaultState());
        structure.fillWithBlocks(world, start, -215, 7, 21, -215, 7, 22, Blocks.GRASS.getDefaultState());
        structure.fillWithBlocks(world, start, -215, 8, -37, -215, 9, -37, Blocks.OAK_LEAVES.getDefaultState().with(LeavesBlock.PERSISTENT, false).with(LeavesBlock.DISTANCE, 3));
        structure.fillWithBlocks(world, start, -215, 8, 23, -215, 9, 23, Blocks.OAK_LEAVES.getDefaultState().with(LeavesBlock.PERSISTENT, false).with(LeavesBlock.DISTANCE, 3));
        structure.fillWithBlocks(world, start, -215, 8, 24, -215, 9, 24, Blocks.OAK_LEAVES.getDefaultState().with(LeavesBlock.PERSISTENT, false).with(LeavesBlock.DISTANCE, 2));
        structure.fillWithBlocks(world, start, -215, 8, 25, -215, 9, 25, Blocks.OAK_LEAVES.getDefaultState().with(LeavesBlock.PERSISTENT, false).with(LeavesBlock.DISTANCE, 3));
        structure.fillWithBlocks(world, start, -215, 9, -55, -214, 10, -55, Blocks.OAK_LEAVES.getDefaultState().with(LeavesBlock.PERSISTENT, false).with(LeavesBlock.DISTANCE, 3));
        structure.fillWithBlocks(world, start, -215, 9, -54, -215, 9, -54, Blocks.OAK_LEAVES.getDefaultState().with(LeavesBlock.PERSISTENT, false).with(LeavesBlock.DISTANCE, 2));
        structure.fillWithBlocks(world, start, -215, 9, -53, -215, 11, -53, Blocks.OAK_LEAVES.getDefaultState().with(LeavesBlock.PERSISTENT, false).with(LeavesBlock.DISTANCE, 1));
        structure.fillWithBlocks(world, start, -215, 9, -52, -215, 11, -52, Blocks.OAK_LEAVES.getDefaultState().with(LeavesBlock.PERSISTENT, false).with(LeavesBlock.DISTANCE, 2));
        structure.fillWithBlocks(world, start, -215, 9, -51, -215, 10, -51, Blocks.OAK_LEAVES.getDefaultState().with(LeavesBlock.PERSISTENT, false).with(LeavesBlock.DISTANCE, 3));
        structure.fillWithBlocks(world, start, -215, 9, -45, -215, 10, -45, Blocks.OAK_LEAVES.getDefaultState().with(LeavesBlock.PERSISTENT, false).with(LeavesBlock.DISTANCE, 3));
        structure.fillWithBlocks(world, start, -215, 9, -44, -215, 10, -44, Blocks.OAK_LEAVES.getDefaultState().with(LeavesBlock.PERSISTENT, false).with(LeavesBlock.DISTANCE, 2));
        structure.fillWithBlocks(world, start, -215, 9, -43, -215, 10, -43, Blocks.OAK_LEAVES.getDefaultState().with(LeavesBlock.PERSISTENT, false).with(LeavesBlock.DISTANCE, 3));
        structure.fillWithBlocks(world, start, -215, 9, -28, -215, 10, -28, Blocks.OAK_LEAVES.getDefaultState().with(LeavesBlock.PERSISTENT, false).with(LeavesBlock.DISTANCE, 3));
        structure.fillWithBlocks(world, start, -215, 9, -27, -215, 11, -27, Blocks.OAK_LEAVES.getDefaultState().with(LeavesBlock.PERSISTENT, false).with(LeavesBlock.DISTANCE, 2));
        structure.fillWithBlocks(world, start, -215, 9, -26, -215, 11, -26, Blocks.OAK_LEAVES.getDefaultState().with(LeavesBlock.PERSISTENT, false).with(LeavesBlock.DISTANCE, 1));
        structure.fillWithBlocks(world, start, -215, 9, -25, -215, 10, -25, Blocks.OAK_LEAVES.getDefaultState().with(LeavesBlock.PERSISTENT, false).with(LeavesBlock.DISTANCE, 2));
        structure.fillWithBlocks(world, start, -215, 9, -24, -215, 10, -24, Blocks.OAK_LEAVES.getDefaultState().with(LeavesBlock.PERSISTENT, false).with(LeavesBlock.DISTANCE, 3));
        structure.fillWithBlocks(world, start, -215, 9, -23, -215, 10, -23, Blocks.OAK_LEAVES.getDefaultState().with(LeavesBlock.PERSISTENT, false).with(LeavesBlock.DISTANCE, 2));
        structure.fillWithBlocks(world, start, -215, 9, -22, -215, 11, -22, Blocks.OAK_LEAVES.getDefaultState().with(LeavesBlock.PERSISTENT, false).with(LeavesBlock.DISTANCE, 1));
        structure.fillWithBlocks(world, start, -215, 9, -21, -215, 10, -21, Blocks.OAK_LEAVES.getDefaultState().with(LeavesBlock.PERSISTENT, false).with(LeavesBlock.DISTANCE, 2));
        structure.fillWithBlocks(world, start, -215, 9, -20, -215, 10, -19, Blocks.OAK_LEAVES.getDefaultState().with(LeavesBlock.PERSISTENT, false).with(LeavesBlock.DISTANCE, 3));
        structure.fillWithBlocks(world, start, -215, 9, -18, -215, 10, -18, Blocks.OAK_LEAVES.getDefaultState().with(LeavesBlock.PERSISTENT, false).with(LeavesBlock.DISTANCE, 2));
        structure.fillWithBlocks(world, start, -215, 9, -17, -215, 10, -17, Blocks.OAK_LEAVES.getDefaultState().with(LeavesBlock.PERSISTENT, false).with(LeavesBlock.DISTANCE, 3));
        structure.fillWithBlocks(world, start, -215, 9, 15, -215, 10, 15, Blocks.OAK_LEAVES.getDefaultState().with(LeavesBlock.PERSISTENT, false).with(LeavesBlock.DISTANCE, 2));
        structure.fillWithBlocks(world, start, -215, 9, 16, -215, 11, 16, Blocks.OAK_LEAVES.getDefaultState().with(LeavesBlock.PERSISTENT, false).with(LeavesBlock.DISTANCE, 1));
        structure.fillWithBlocks(world, start, -215, 9, 18, -215, 11, 18, Blocks.OAK_LEAVES.getDefaultState().with(LeavesBlock.PERSISTENT, false).with(LeavesBlock.DISTANCE, 1));
        structure.fillWithBlocks(world, start, -215, 9, 19, -214, 10, 19, Blocks.OAK_LEAVES.getDefaultState().with(LeavesBlock.PERSISTENT, false).with(LeavesBlock.DISTANCE, 2));
        structure.fillWithBlocks(world, start, -215, 10, -54, -215, 10, -54, Blocks.OAK_LEAVES.getDefaultState().with(LeavesBlock.PERSISTENT, false).with(LeavesBlock.DISTANCE, 2));
        structure.fillWithBlocks(world, start, -215, 10, -49, -215, 11, -49, Blocks.OAK_LEAVES.getDefaultState().with(LeavesBlock.PERSISTENT, false).with(LeavesBlock.DISTANCE, 3));
        structure.fillWithBlocks(world, start, -215, 10, -48, -215, 11, -48, Blocks.OAK_LEAVES.getDefaultState().with(LeavesBlock.PERSISTENT, false).with(LeavesBlock.DISTANCE, 2));
        structure.fillWithBlocks(world, start, -215, 10, -47, -215, 11, -47, Blocks.OAK_LEAVES.getDefaultState().with(LeavesBlock.PERSISTENT, false).with(LeavesBlock.DISTANCE, 3));
        structure.fillWithBlocks(world, start, -215, 10, -36, -215, 11, -36, Blocks.STONE_BRICK_STAIRS.getDefaultState().with(StairsBlock.FACING, Direction.WEST).with(StairsBlock.WATERLOGGED, false).with(StairsBlock.SHAPE, StairsShape.STRAIGHT).with(StairsBlock.HALF, Half.TOP));
        structure.fillWithBlocks(world, start, -215, 10, -34, -215, 11, -34, Blocks.STONE_BRICK_STAIRS.getDefaultState().with(StairsBlock.FACING, Direction.WEST).with(StairsBlock.WATERLOGGED, false).with(StairsBlock.SHAPE, StairsShape.STRAIGHT).with(StairsBlock.HALF, Half.TOP));
        structure.fillWithBlocks(world, start, -215, 10, 8, -215, 11, 8, Blocks.OAK_LEAVES.getDefaultState().with(LeavesBlock.PERSISTENT, false).with(LeavesBlock.DISTANCE, 3));
        structure.fillWithBlocks(world, start, -215, 10, 9, -215, 11, 9, Blocks.OAK_LEAVES.getDefaultState().with(LeavesBlock.PERSISTENT, false).with(LeavesBlock.DISTANCE, 2));
        structure.fillWithBlocks(world, start, -215, 10, 10, -215, 12, 10, Blocks.OAK_LEAVES.getDefaultState().with(LeavesBlock.PERSISTENT, false).with(LeavesBlock.DISTANCE, 1));
        structure.fillWithBlocks(world, start, -215, 10, 11, -215, 11, 11, Blocks.OAK_LEAVES.getDefaultState().with(LeavesBlock.PERSISTENT, false).with(LeavesBlock.DISTANCE, 2));
        structure.fillWithBlocks(world, start, -215, 10, 12, -215, 11, 12, Blocks.OAK_LEAVES.getDefaultState().with(LeavesBlock.PERSISTENT, false).with(LeavesBlock.DISTANCE, 3));
        structure.fillWithBlocks(world, start, -215, 12, -37, -215, 14, -37, Blocks.STONE_BRICKS.getDefaultState());
        structure.fillWithBlocks(world, start, -215, 12, -33, -215, 14, -33, Blocks.STONE_BRICKS.getDefaultState());
        structure.fillWithBlocks(world, start, -215, 12, -26, -215, 12, -26, Blocks.OAK_LEAVES.getDefaultState().with(LeavesBlock.PERSISTENT, false).with(LeavesBlock.DISTANCE, 2));
        structure.fillWithBlocks(world, start, -215, 12, -22, -215, 12, -22, Blocks.OAK_LEAVES.getDefaultState().with(LeavesBlock.PERSISTENT, false).with(LeavesBlock.DISTANCE, 2));
        structure.fillWithBlocks(world, start, -215, 12, 16, -215, 12, 16, Blocks.OAK_LEAVES.getDefaultState().with(LeavesBlock.PERSISTENT, false).with(LeavesBlock.DISTANCE, 2));
        structure.fillWithBlocks(world, start, -215, 13, -35, -215, 15, -35, Blocks.STONE_BRICKS.getDefaultState());
        structure.fillWithBlocks(world, start, -215, 14, -36, -215, 14, -33, Blocks.STONE_BRICKS.getDefaultState());
        structure.fillWithBlocks(world, start, -215, 18, -36, -215, 19, -36, Blocks.STONE_BRICK_STAIRS.getDefaultState().with(StairsBlock.FACING, Direction.WEST).with(StairsBlock.WATERLOGGED, false).with(StairsBlock.SHAPE, StairsShape.STRAIGHT).with(StairsBlock.HALF, Half.TOP));
        structure.fillWithBlocks(world, start, -215, 18, -34, -215, 19, -34, Blocks.STONE_BRICK_STAIRS.getDefaultState().with(StairsBlock.FACING, Direction.WEST).with(StairsBlock.WATERLOGGED, false).with(StairsBlock.SHAPE, StairsShape.STRAIGHT).with(StairsBlock.HALF, Half.TOP));
        structure.fillWithBlocks(world, start, -215, 20, -37, -215, 22, -37, Blocks.STONE_BRICKS.getDefaultState());
        structure.fillWithBlocks(world, start, -215, 20, -33, -215, 22, -33, Blocks.STONE_BRICKS.getDefaultState());
        structure.fillWithBlocks(world, start, -215, 21, -35, -215, 22, -35, Blocks.STONE_BRICKS.getDefaultState());
        structure.fillWithBlocks(world, start, -215, 22, -36, -215, 22, -33, Blocks.STONE_BRICKS.getDefaultState());
        structure.fillWithBlocks(world, start, -215, 29, -35, -215, 31, -35, Blocks.STONE_BRICKS.getDefaultState());
        structure.fillWithBlocks(world, start, -215, 34, -36, -215, 34, -34, Blocks.DARK_OAK_PLANKS.getDefaultState());
        structure.fillWithBlocks(world, start, -214, 1, -47, -213, 1, -46, Blocks.DIRT.getDefaultState());
        structure.fillWithBlocks(world, start, -214, 1, -45, -214, 1, 39, Blocks.STONE.getDefaultState());
        structure.fillWithBlocks(world, start, -214, 2, -74, -209, 2, -69, Blocks.DIRT.getDefaultState());
        structure.fillWithBlocks(world, start, -214, 2, -59, -212, 2, -59, Blocks.STONE.getDefaultState());
        structure.fillWithBlocks(world, start, -214, 2, -58, -200, 2, -39, Blocks.DIRT.getDefaultState());
        structure.fillWithBlocks(world, start, -214, 2, -38, -213, 2, -16, Blocks.STONE.getDefaultState());
        structure.fillWithBlocks(world, start, -214, 2, -15, -214, 2, -2, Blocks.DIRT.getDefaultState());
        structure.fillWithBlocks(world, start, -214, 2, 16, -212, 2, 18, Blocks.STONE.getDefaultState());
        structure.fillWithBlocks(world, start, -214, 5, -72, -212, 5, -70, Blocks.GRASS_BLOCK.getDefaultState().with(SnowyDirtBlock.SNOWY, false));
        structure.fillWithBlocks(world, start, -214, 6, -37, -214, 6, -27, Blocks.GRASS_BLOCK.getDefaultState().with(SnowyDirtBlock.SNOWY, false));
        structure.fillWithBlocks(world, start, -214, 6, -25, -212, 6, -23, Blocks.GRASS_BLOCK.getDefaultState().with(SnowyDirtBlock.SNOWY, false));
        structure.fillWithBlocks(world, start, -214, 6, -21, -212, 6, -19, Blocks.GRASS_BLOCK.getDefaultState().with(SnowyDirtBlock.SNOWY, false));
        structure.fillWithBlocks(world, start, -214, 6, -18, -214, 6, 37, Blocks.GRASS_BLOCK.getDefaultState().with(SnowyDirtBlock.SNOWY, false));
        structure.fillWithBlocks(world, start, -214, 7, -47, -214, 7, -47, Blocks.GRASS.getDefaultState());
        structure.fillWithBlocks(world, start, -214, 7, -33, -213, 7, -33, Blocks.GRASS.getDefaultState());
        structure.fillWithBlocks(world, start, -214, 7, -26, -214, 11, -26, Blocks.OAK_LOG.getDefaultState());
        structure.fillWithBlocks(world, start, -214, 7, -22, -214, 11, -22, Blocks.OAK_LOG.getDefaultState());
        structure.fillWithBlocks(world, start, -214, 8, -55, -214, 10, -55, Blocks.OAK_LEAVES.getDefaultState().with(LeavesBlock.PERSISTENT, false).with(LeavesBlock.DISTANCE, 3));
        structure.fillWithBlocks(world, start, -214, 8, -54, -214, 10, -54, Blocks.OAK_LEAVES.getDefaultState().with(LeavesBlock.PERSISTENT, false).with(LeavesBlock.DISTANCE, 2));
        structure.fillWithBlocks(world, start, -214, 8, -53, -214, 8, -53, Blocks.OAK_LEAVES.getDefaultState().with(LeavesBlock.PERSISTENT, false).with(LeavesBlock.DISTANCE, 3));
        structure.fillWithBlocks(world, start, -214, 8, -38, -214, 9, -38, Blocks.OAK_LEAVES.getDefaultState().with(LeavesBlock.PERSISTENT, false).with(LeavesBlock.DISTANCE, 3));
        structure.fillWithBlocks(world, start, -214, 8, -37, -214, 10, -37, Blocks.OAK_LEAVES.getDefaultState().with(LeavesBlock.PERSISTENT, false).with(LeavesBlock.DISTANCE, 2));
        structure.fillWithBlocks(world, start, -214, 8, -36, -214, 10, -36, Blocks.OAK_LEAVES.getDefaultState().with(LeavesBlock.PERSISTENT, false).with(LeavesBlock.DISTANCE, 1));
        structure.fillWithBlocks(world, start, -214, 8, -35, -214, 9, -35, Blocks.OAK_LEAVES.getDefaultState().with(LeavesBlock.PERSISTENT, false).with(LeavesBlock.DISTANCE, 2));
        structure.fillWithBlocks(world, start, -214, 8, -34, -214, 9, -34, Blocks.OAK_LEAVES.getDefaultState().with(LeavesBlock.PERSISTENT, false).with(LeavesBlock.DISTANCE, 3));
        structure.fillWithBlocks(world, start, -214, 9, -53, -213, 10, -53, Blocks.OAK_LEAVES.getDefaultState().with(LeavesBlock.PERSISTENT, false).with(LeavesBlock.DISTANCE, 2));
        structure.fillWithBlocks(world, start, -214, 9, -52, -213, 9, -52, Blocks.OAK_LEAVES.getDefaultState().with(LeavesBlock.PERSISTENT, false).with(LeavesBlock.DISTANCE, 3));
        structure.fillWithBlocks(world, start, -214, 9, -51, -214, 10, -51, Blocks.OAK_LEAVES.getDefaultState().with(LeavesBlock.PERSISTENT, false).with(LeavesBlock.DISTANCE, 4));
        structure.fillWithBlocks(world, start, -214, 9, -46, -214, 10, -46, Blocks.OAK_LEAVES.getDefaultState().with(LeavesBlock.PERSISTENT, false).with(LeavesBlock.DISTANCE, 3));
        structure.fillWithBlocks(world, start, -214, 9, -45, -214, 11, -45, Blocks.OAK_LEAVES.getDefaultState().with(LeavesBlock.PERSISTENT, false).with(LeavesBlock.DISTANCE, 2));
        structure.fillWithBlocks(world, start, -214, 9, -44, -214, 11, -44, Blocks.OAK_LEAVES.getDefaultState().with(LeavesBlock.PERSISTENT, false).with(LeavesBlock.DISTANCE, 1));
        structure.fillWithBlocks(world, start, -214, 9, -43, -214, 10, -43, Blocks.OAK_LEAVES.getDefaultState().with(LeavesBlock.PERSISTENT, false).with(LeavesBlock.DISTANCE, 2));
        structure.fillWithBlocks(world, start, -214, 9, -42, -214, 10, -42, Blocks.OAK_LEAVES.getDefaultState().with(LeavesBlock.PERSISTENT, false).with(LeavesBlock.DISTANCE, 3));
        structure.fillWithBlocks(world, start, -214, 9, -28, -214, 10, -28, Blocks.OAK_LEAVES.getDefaultState().with(LeavesBlock.PERSISTENT, false).with(LeavesBlock.DISTANCE, 2));
        structure.fillWithBlocks(world, start, -214, 9, -27, -214, 11, -27, Blocks.OAK_LEAVES.getDefaultState().with(LeavesBlock.PERSISTENT, false).with(LeavesBlock.DISTANCE, 1));
        structure.fillWithBlocks(world, start, -214, 9, -25, -214, 11, -25, Blocks.OAK_LEAVES.getDefaultState().with(LeavesBlock.PERSISTENT, false).with(LeavesBlock.DISTANCE, 1));
        structure.fillWithBlocks(world, start, -214, 9, -24, -214, 10, -24, Blocks.OAK_LEAVES.getDefaultState().with(LeavesBlock.PERSISTENT, false).with(LeavesBlock.DISTANCE, 2));
        structure.fillWithBlocks(world, start, -214, 9, -23, -214, 11, -23, Blocks.OAK_LEAVES.getDefaultState().with(LeavesBlock.PERSISTENT, false).with(LeavesBlock.DISTANCE, 1));
        structure.fillWithBlocks(world, start, -214, 9, -21, -214, 11, -21, Blocks.OAK_LEAVES.getDefaultState().with(LeavesBlock.PERSISTENT, false).with(LeavesBlock.DISTANCE, 1));
        structure.fillWithBlocks(world, start, -214, 9, -20, -214, 10, -19, Blocks.OAK_LEAVES.getDefaultState().with(LeavesBlock.PERSISTENT, false).with(LeavesBlock.DISTANCE, 2));
        structure.fillWithBlocks(world, start, -214, 9, -18, -214, 11, -18, Blocks.OAK_LEAVES.getDefaultState().with(LeavesBlock.PERSISTENT, false).with(LeavesBlock.DISTANCE, 1));
        structure.fillWithBlocks(world, start, -214, 9, -17, -214, 11, -17, Blocks.OAK_LEAVES.getDefaultState().with(LeavesBlock.PERSISTENT, false).with(LeavesBlock.DISTANCE, 2));
        structure.fillWithBlocks(world, start, -214, 9, -16, -214, 10, -16, Blocks.OAK_LEAVES.getDefaultState().with(LeavesBlock.PERSISTENT, false).with(LeavesBlock.DISTANCE, 3));
        structure.fillWithBlocks(world, start, -214, 9, 13, -214, 10, 13, Blocks.OAK_LEAVES.getDefaultState().with(LeavesBlock.PERSISTENT, false).with(LeavesBlock.DISTANCE, 3));
        structure.fillWithBlocks(world, start, -214, 9, 14, -214, 10, 14, Blocks.OAK_LEAVES.getDefaultState().with(LeavesBlock.PERSISTENT, false).with(LeavesBlock.DISTANCE, 2));
        structure.fillWithBlocks(world, start, -214, 9, 15, -214, 10, 15, Blocks.OAK_LEAVES.getDefaultState().with(LeavesBlock.PERSISTENT, false).with(LeavesBlock.DISTANCE, 3));
        structure.fillWithBlocks(world, start, -214, 9, 16, -214, 10, 16, Blocks.OAK_LEAVES.getDefaultState().with(LeavesBlock.PERSISTENT, false).with(LeavesBlock.DISTANCE, 2));
        structure.fillWithBlocks(world, start, -214, 9, 17, -214, 11, 17, Blocks.OAK_LEAVES.getDefaultState().with(LeavesBlock.PERSISTENT, false).with(LeavesBlock.DISTANCE, 1));
        structure.fillWithBlocks(world, start, -214, 9, 18, -214, 10, 19, Blocks.OAK_LEAVES.getDefaultState().with(LeavesBlock.PERSISTENT, false).with(LeavesBlock.DISTANCE, 2));
        structure.fillWithBlocks(world, start, -214, 9, 20, -214, 10, 20, Blocks.OAK_LEAVES.getDefaultState().with(LeavesBlock.PERSISTENT, false).with(LeavesBlock.DISTANCE, 3));
        structure.fillWithBlocks(world, start, -214, 9, 21, -214, 10, 21, Blocks.OAK_LEAVES.getDefaultState().with(LeavesBlock.PERSISTENT, false).with(LeavesBlock.DISTANCE, 4));
        structure.fillWithBlocks(world, start, -214, 10, 9, -214, 11, 9, Blocks.OAK_LEAVES.getDefaultState().with(LeavesBlock.PERSISTENT, false).with(LeavesBlock.DISTANCE, 3));
        structure.fillWithBlocks(world, start, -214, 10, 10, -214, 11, 10, Blocks.OAK_LEAVES.getDefaultState().with(LeavesBlock.PERSISTENT, false).with(LeavesBlock.DISTANCE, 2));
        structure.fillWithBlocks(world, start, -214, 10, 11, -214, 11, 11, Blocks.OAK_LEAVES.getDefaultState().with(LeavesBlock.PERSISTENT, false).with(LeavesBlock.DISTANCE, 3));
        structure.fillWithBlocks(world, start, -214, 11, -36, -214, 11, -36, Blocks.OAK_LEAVES.getDefaultState().with(LeavesBlock.PERSISTENT, false).with(LeavesBlock.DISTANCE, 2));
        structure.fillWithBlocks(world, start, -214, 12, -44, -214, 12, -44, Blocks.OAK_LEAVES.getDefaultState().with(LeavesBlock.PERSISTENT, false).with(LeavesBlock.DISTANCE, 2));
        structure.fillWithBlocks(world, start, -214, 12, -27, -214, 12, -27, Blocks.OAK_LEAVES.getDefaultState().with(LeavesBlock.PERSISTENT, false).with(LeavesBlock.DISTANCE, 2));
        structure.fillWithBlocks(world, start, -214, 12, -23, -214, 12, -23, Blocks.OAK_LEAVES.getDefaultState().with(LeavesBlock.PERSISTENT, false).with(LeavesBlock.DISTANCE, 2));
        structure.fillWithBlocks(world, start, -214, 12, -18, -214, 12, -18, Blocks.OAK_LEAVES.getDefaultState().with(LeavesBlock.PERSISTENT, false).with(LeavesBlock.DISTANCE, 2));
        structure.fillWithBlocks(world, start, -213, 1, -77, -212, 1, -76, Blocks.GRASS_BLOCK.getDefaultState().with(SnowyDirtBlock.SNOWY, false));
        structure.fillWithBlocks(world, start, -213, 1, -53, -212, 1, -53, Blocks.STONE.getDefaultState());
        structure.fillWithBlocks(world, start, -213, 1, -45, -206, 5, -45, Blocks.DIRT.getDefaultState());
        structure.fillWithBlocks(world, start, -213, 1, -44, -212, 1, 39, Blocks.STONE.getDefaultState());
        structure.fillWithBlocks(world, start, -213, 1, 40, -210, 1, 43, Blocks.DIRT.getDefaultState());
        structure.fillWithBlocks(world, start, -213, 2, -15, -213, 2, -15, Blocks.STONE.getDefaultState());
        structure.fillWithBlocks(world, start, -213, 2, -14, -213, 2, -2, Blocks.DIRT.getDefaultState());
        structure.fillWithBlocks(world, start, -213, 2, 33, -213, 2, 33, Blocks.DIRT.getDefaultState());
        structure.fillWithBlocks(world, start, -213, 2, 34, -213, 2, 37, Blocks.STONE.getDefaultState());
        structure.fillWithBlocks(world, start, -213, 2, 38, -209, 2, 42, Blocks.DIRT.getDefaultState());
        structure.fillWithBlocks(world, start, -213, 5, 38, -212, 5, 39, Blocks.GRASS_BLOCK.getDefaultState().with(SnowyDirtBlock.SNOWY, false));
        structure.fillWithBlocks(world, start, -213, 6, -43, -209, 6, -39, Blocks.GRASS_BLOCK.getDefaultState().with(SnowyDirtBlock.SNOWY, false));
        structure.fillWithBlocks(world, start, -213, 6, -37, -213, 6, -37, Blocks.GRASS_BLOCK.getDefaultState().with(SnowyDirtBlock.SNOWY, false));
        structure.fillWithBlocks(world, start, -213, 6, -35, -210, 6, -32, Blocks.GRASS_BLOCK.getDefaultState().with(SnowyDirtBlock.SNOWY, false));
        structure.fillWithBlocks(world, start, -213, 6, -26, -211, 6, -24, Blocks.GRASS_BLOCK.getDefaultState().with(SnowyDirtBlock.SNOWY, false));
        structure.fillWithBlocks(world, start, -213, 6, -22, -211, 6, -19, Blocks.GRASS_BLOCK.getDefaultState().with(SnowyDirtBlock.SNOWY, false));
