package mod.arcalitegames.odyssey.world.structure.structures.towers.dark_tower;

import mod.arcalitegames.odyssey.world.structure.StructureBase;
import net.minecraft.block.Blocks;
import net.minecraft.block.ChestBlock;
import net.minecraft.block.SlabBlock;
import net.minecraft.block.SnowyDirtBlock;
import net.minecraft.block.StairsBlock;
import net.minecraft.block.WallBlock;
import net.minecraft.block.WallHeight;
import net.minecraft.state.properties.ChestType;
import net.minecraft.state.properties.Half;
import net.minecraft.state.properties.SlabType;
import net.minecraft.state.properties.StairsShape;
import net.minecraft.util.Direction;
import net.minecraft.util.math.BlockPos;
import net.minecraft.world.World;

public class DarkTowerComponents
{

	public static BlockPos start;
    public static World world;
    public static StructureBase structure;

    public static void init(World worldIn, BlockPos blockPos, StructureBase structureIn)
    {
        world = worldIn; start = blockPos; structure = structureIn;
    }
    
    public static void generatePart1()
    {
        structure.setBlockState(world, Blocks.GRASS_BLOCK.getDefaultState().with(SnowyDirtBlock.SNOWY, false), 3, 0, 8, start);
        structure.setBlockState(world, Blocks.GRASS_BLOCK.getDefaultState().with(SnowyDirtBlock.SNOWY, false), 4, 1, 8, start);
        structure.setBlockState(world, Blocks.GRASS_BLOCK.getDefaultState().with(SnowyDirtBlock.SNOWY, false), 4, 1, 22, start);
        structure.setBlockState(world, Blocks.GRASS_BLOCK.getDefaultState().with(SnowyDirtBlock.SNOWY, false), 4, 2, 9, start);
        structure.setBlockState(world, Blocks.GRASS_BLOCK.getDefaultState().with(SnowyDirtBlock.SNOWY, false), 4, 2, 21, start);
        structure.setBlockState(world, Blocks.GRASS_BLOCK.getDefaultState().with(SnowyDirtBlock.SNOWY, false), 4, 3, 10, start);
        structure.setBlockState(world, Blocks.GRASS_BLOCK.getDefaultState().with(SnowyDirtBlock.SNOWY, false), 4, 3, 20, start);
        structure.setBlockState(world, Blocks.GRASS_BLOCK.getDefaultState().with(SnowyDirtBlock.SNOWY, false), 5, 0, 5, start);
        structure.setBlockState(world, Blocks.GRASS_BLOCK.getDefaultState().with(SnowyDirtBlock.SNOWY, false), 5, 1, 6, start);
        structure.setBlockState(world, Blocks.GRASS_BLOCK.getDefaultState().with(SnowyDirtBlock.SNOWY, false), 5, 2, 7, start);
        structure.setBlockState(world, Blocks.GRASS_BLOCK.getDefaultState().with(SnowyDirtBlock.SNOWY, false), 5, 3, 8, start);
        structure.setBlockState(world, Blocks.GRASS_BLOCK.getDefaultState().with(SnowyDirtBlock.SNOWY, false), 5, 4, 9, start);
        structure.setBlockState(world, Blocks.GRASS_BLOCK.getDefaultState().with(SnowyDirtBlock.SNOWY, false), 6, 1, 5, start);
        structure.setBlockState(world, Blocks.GRASS_BLOCK.getDefaultState().with(SnowyDirtBlock.SNOWY, false), 6, 1, 25, start);
        structure.setBlockState(world, Blocks.GRASS_BLOCK.getDefaultState().with(SnowyDirtBlock.SNOWY, false), 6, 2, 6, start);
        structure.setBlockState(world, Blocks.GRASS_BLOCK.getDefaultState().with(SnowyDirtBlock.SNOWY, false), 6, 3, 7, start);
        structure.setBlockState(world, Blocks.GRASS_BLOCK.getDefaultState().with(SnowyDirtBlock.SNOWY, false), 6, 4, 8, start);
        structure.setBlockState(world, Blocks.GRASS_BLOCK.getDefaultState().with(SnowyDirtBlock.SNOWY, false), 7, 2, 5, start);
        structure.setBlockState(world, Blocks.GRASS_BLOCK.getDefaultState().with(SnowyDirtBlock.SNOWY, false), 7, 2, 25, start);
        structure.setBlockState(world, Blocks.GRASS_BLOCK.getDefaultState().with(SnowyDirtBlock.SNOWY, false), 7, 3, 6, start);
        structure.setBlockState(world, Blocks.GRASS_BLOCK.getDefaultState().with(SnowyDirtBlock.SNOWY, false), 7, 4, 7, start);
        structure.setBlockState(world, Blocks.GRASS_BLOCK.getDefaultState().with(SnowyDirtBlock.SNOWY, false), 7, 5, 8, start);
        structure.setBlockState(world, Blocks.GRASS_BLOCK.getDefaultState().with(SnowyDirtBlock.SNOWY, false), 8, 0, 3, start);
        structure.setBlockState(world, Blocks.GRASS_BLOCK.getDefaultState().with(SnowyDirtBlock.SNOWY, false), 8, 1, 4, start);
        structure.setBlockState(world, Blocks.GRASS_BLOCK.getDefaultState().with(SnowyDirtBlock.SNOWY, false), 8, 3, 5, start);
        structure.setBlockState(world, Blocks.GRASS_BLOCK.getDefaultState().with(SnowyDirtBlock.SNOWY, false), 8, 3, 25, start);
        structure.setBlockState(world, Blocks.GRASS_BLOCK.getDefaultState().with(SnowyDirtBlock.SNOWY, false), 8, 4, 6, start);
        structure.setBlockState(world, Blocks.GRASS_BLOCK.getDefaultState().with(SnowyDirtBlock.SNOWY, false), 8, 5, 7, start);
        structure.setBlockState(world, Blocks.AIR.getDefaultState(), 8, 7, 13, start);
        structure.setBlockState(world, Blocks.AIR.getDefaultState(), 8, 7, 18, start);
        structure.setBlockState(world, Blocks.COBBLESTONE_WALL.getDefaultState().with(WallBlock.WATERLOGGED, false).with(WallBlock.UP, true).with(WallBlock.WALL_HEIGHT_NORTH, WallHeight.LOW).with(WallBlock.WALL_HEIGHT_SOUTH, WallHeight.LOW).with(WallBlock.WALL_HEIGHT_EAST, WallHeight.LOW).with(WallBlock.WALL_HEIGHT_WEST, WallHeight.LOW), 8, 14, 11, start);
        structure.setBlockState(world, Blocks.COBBLESTONE_WALL.getDefaultState().with(WallBlock.WATERLOGGED, false).with(WallBlock.UP, true).with(WallBlock.WALL_HEIGHT_NORTH, WallHeight.LOW).with(WallBlock.WALL_HEIGHT_SOUTH, WallHeight.LOW).with(WallBlock.WALL_HEIGHT_EAST, WallHeight.LOW).with(WallBlock.WALL_HEIGHT_WEST, WallHeight.LOW), 8, 14, 20, start);
        structure.setBlockState(world, Blocks.STONE_BRICK_STAIRS.getDefaultState().with(StairsBlock.FACING, Direction.EAST).with(StairsBlock.WATERLOGGED, false).with(StairsBlock.SHAPE, StairsShape.STRAIGHT).with(StairsBlock.HALF, Half.TOP), 8, 15, 10, start);
        structure.setBlockState(world, Blocks.COBBLESTONE_WALL.getDefaultState().with(WallBlock.WATERLOGGED, false).with(WallBlock.UP, true).with(WallBlock.WALL_HEIGHT_NORTH, WallHeight.LOW).with(WallBlock.WALL_HEIGHT_SOUTH, WallHeight.LOW).with(WallBlock.WALL_HEIGHT_EAST, WallHeight.LOW).with(WallBlock.WALL_HEIGHT_WEST, WallHeight.LOW), 8, 15, 11, start);
        structure.setBlockState(world, Blocks.COBBLESTONE_WALL.getDefaultState().with(WallBlock.WATERLOGGED, false).with(WallBlock.UP, true).with(WallBlock.WALL_HEIGHT_NORTH, WallHeight.LOW).with(WallBlock.WALL_HEIGHT_SOUTH, WallHeight.LOW).with(WallBlock.WALL_HEIGHT_EAST, WallHeight.LOW).with(WallBlock.WALL_HEIGHT_WEST, WallHeight.LOW), 8, 15, 20, start);
        structure.setBlockState(world, Blocks.STONE_BRICK_STAIRS.getDefaultState().with(StairsBlock.FACING, Direction.EAST).with(StairsBlock.WATERLOGGED, false).with(StairsBlock.SHAPE, StairsShape.STRAIGHT).with(StairsBlock.HALF, Half.TOP), 8, 15, 21, start);
        structure.setBlockState(world, Blocks.COBBLESTONE_WALL.getDefaultState().with(WallBlock.WATERLOGGED, false).with(WallBlock.UP, false).with(WallBlock.WALL_HEIGHT_NORTH, WallHeight.LOW).with(WallBlock.WALL_HEIGHT_SOUTH, WallHeight.LOW).with(WallBlock.WALL_HEIGHT_EAST, WallHeight.LOW).with(WallBlock.WALL_HEIGHT_WEST, WallHeight.LOW), 8, 16, 10, start);
        structure.setBlockState(world, Blocks.COBBLESTONE_WALL.getDefaultState().with(WallBlock.WATERLOGGED, false).with(WallBlock.UP, false).with(WallBlock.WALL_HEIGHT_NORTH, WallHeight.LOW).with(WallBlock.WALL_HEIGHT_SOUTH, WallHeight.LOW).with(WallBlock.WALL_HEIGHT_EAST, WallHeight.LOW).with(WallBlock.WALL_HEIGHT_WEST, WallHeight.LOW), 8, 16, 21, start);
        structure.setBlockState(world, Blocks.GRASS_BLOCK.getDefaultState().with(SnowyDirtBlock.SNOWY, false), 9, 2, 4, start);
        structure.setBlockState(world, Blocks.GRASS_BLOCK.getDefaultState().with(SnowyDirtBlock.SNOWY, false), 9, 2, 26, start);
        structure.setBlockState(world, Blocks.GRASS_BLOCK.getDefaultState().with(SnowyDirtBlock.SNOWY, false), 9, 4, 5, start);
        structure.setBlockState(world, Blocks.GRASS_BLOCK.getDefaultState().with(SnowyDirtBlock.SNOWY, false), 9, 4, 25, start);
        structure.setBlockState(world, Blocks.COBBLESTONE_WALL.getDefaultState().with(WallBlock.WATERLOGGED, false).with(WallBlock.UP, true).with(WallBlock.WALL_HEIGHT_NORTH, WallHeight.LOW).with(WallBlock.WALL_HEIGHT_SOUTH, WallHeight.LOW).with(WallBlock.WALL_HEIGHT_EAST, WallHeight.LOW).with(WallBlock.WALL_HEIGHT_WEST, WallHeight.LOW), 9, 7, 10, start);
        structure.setBlockState(world, Blocks.COBBLESTONE_STAIRS.getDefaultState().with(StairsBlock.FACING, Direction.EAST).with(StairsBlock.WATERLOGGED, false).with(StairsBlock.SHAPE, StairsShape.STRAIGHT).with(StairsBlock.HALF, Half.BOTTOM), 9, 7, 11, start);
        structure.setBlockState(world, Blocks.COBBLESTONE_STAIRS.getDefaultState().with(StairsBlock.FACING, Direction.EAST).with(StairsBlock.WATERLOGGED, false).with(StairsBlock.SHAPE, StairsShape.STRAIGHT).with(StairsBlock.HALF, Half.BOTTOM), 9, 7, 20, start);
        structure.setBlockState(world, Blocks.COBBLESTONE_WALL.getDefaultState().with(WallBlock.WATERLOGGED, false).with(WallBlock.UP, true).with(WallBlock.WALL_HEIGHT_NORTH, WallHeight.LOW).with(WallBlock.WALL_HEIGHT_SOUTH, WallHeight.LOW).with(WallBlock.WALL_HEIGHT_EAST, WallHeight.LOW).with(WallBlock.WALL_HEIGHT_WEST, WallHeight.LOW), 9, 7, 21, start);
        structure.setBlockState(world, Blocks.COBBLESTONE_WALL.getDefaultState().with(WallBlock.WATERLOGGED, false).with(WallBlock.UP, true).with(WallBlock.WALL_HEIGHT_NORTH, WallHeight.LOW).with(WallBlock.WALL_HEIGHT_SOUTH, WallHeight.LOW).with(WallBlock.WALL_HEIGHT_EAST, WallHeight.LOW).with(WallBlock.WALL_HEIGHT_WEST, WallHeight.LOW), 9, 11, 10, start);
        structure.setBlockState(world, Blocks.COBBLESTONE_STAIRS.getDefaultState().with(StairsBlock.FACING, Direction.EAST).with(StairsBlock.WATERLOGGED, false).with(StairsBlock.SHAPE, StairsShape.STRAIGHT).with(StairsBlock.HALF, Half.TOP), 9, 12, 10, start);
        structure.setBlockState(world, Blocks.COBBLESTONE_STAIRS.getDefaultState().with(StairsBlock.FACING, Direction.EAST).with(StairsBlock.WATERLOGGED, false).with(StairsBlock.SHAPE, StairsShape.STRAIGHT).with(StairsBlock.HALF, Half.TOP), 9, 12, 21, start);
        structure.setBlockState(world, Blocks.COBBLESTONE_WALL.getDefaultState().with(WallBlock.WATERLOGGED, false).with(WallBlock.UP, true).with(WallBlock.WALL_HEIGHT_NORTH, WallHeight.LOW).with(WallBlock.WALL_HEIGHT_SOUTH, WallHeight.LOW).with(WallBlock.WALL_HEIGHT_EAST, WallHeight.LOW).with(WallBlock.WALL_HEIGHT_WEST, WallHeight.LOW), 9, 13, 10, start);
        structure.setBlockState(world, Blocks.COBBLESTONE_STAIRS.getDefaultState().with(StairsBlock.FACING, Direction.EAST).with(StairsBlock.WATERLOGGED, false).with(StairsBlock.SHAPE, StairsShape.STRAIGHT).with(StairsBlock.HALF, Half.TOP), 9, 13, 11, start);
        structure.setBlockState(world, Blocks.COBBLESTONE_STAIRS.getDefaultState().with(StairsBlock.FACING, Direction.EAST).with(StairsBlock.WATERLOGGED, false).with(StairsBlock.SHAPE, StairsShape.STRAIGHT).with(StairsBlock.HALF, Half.TOP), 9, 13, 20, start);
        structure.setBlockState(world, Blocks.COBBLESTONE_WALL.getDefaultState().with(WallBlock.WATERLOGGED, false).with(WallBlock.UP, true).with(WallBlock.WALL_HEIGHT_NORTH, WallHeight.LOW).with(WallBlock.WALL_HEIGHT_SOUTH, WallHeight.LOW).with(WallBlock.WALL_HEIGHT_EAST, WallHeight.LOW).with(WallBlock.WALL_HEIGHT_WEST, WallHeight.LOW), 9, 13, 21, start);
        structure.setBlockState(world, Blocks.COBBLESTONE_STAIRS.getDefaultState().with(StairsBlock.FACING, Direction.SOUTH).with(StairsBlock.WATERLOGGED, false).with(StairsBlock.SHAPE, StairsShape.STRAIGHT).with(StairsBlock.HALF, Half.TOP), 9, 14, 10, start);
        structure.setBlockState(world, Blocks.CHISELED_STONE_BRICKS.getDefaultState(), 9, 14, 11, start);
        structure.setBlockState(world, Blocks.COBBLESTONE_STAIRS.getDefaultState().with(StairsBlock.FACING, Direction.NORTH).with(StairsBlock.WATERLOGGED, false).with(StairsBlock.SHAPE, StairsShape.STRAIGHT).with(StairsBlock.HALF, Half.TOP), 9, 14, 12, start);
        structure.setBlockState(world, Blocks.COBBLESTONE_WALL.getDefaultState().with(WallBlock.WATERLOGGED, false).with(WallBlock.UP, true).with(WallBlock.WALL_HEIGHT_NORTH, WallHeight.LOW).with(WallBlock.WALL_HEIGHT_SOUTH, WallHeight.LOW).with(WallBlock.WALL_HEIGHT_EAST, WallHeight.LOW).with(WallBlock.WALL_HEIGHT_WEST, WallHeight.LOW), 9, 14, 15, start);
        structure.setBlockState(world, Blocks.COBBLESTONE_WALL.getDefaultState().with(WallBlock.WATERLOGGED, false).with(WallBlock.UP, true).with(WallBlock.WALL_HEIGHT_NORTH, WallHeight.LOW).with(WallBlock.WALL_HEIGHT_SOUTH, WallHeight.LOW).with(WallBlock.WALL_HEIGHT_EAST, WallHeight.LOW).with(WallBlock.WALL_HEIGHT_WEST, WallHeight.LOW), 9, 14, 16, start);
        structure.setBlockState(world, Blocks.COBBLESTONE_STAIRS.getDefaultState().with(StairsBlock.FACING, Direction.SOUTH).with(StairsBlock.WATERLOGGED, false).with(StairsBlock.SHAPE, StairsShape.STRAIGHT).with(StairsBlock.HALF, Half.TOP), 9, 14, 19, start);
        structure.setBlockState(world, Blocks.CHISELED_STONE_BRICKS.getDefaultState(), 9, 14, 20, start);
        structure.setBlockState(world, Blocks.COBBLESTONE_STAIRS.getDefaultState().with(StairsBlock.FACING, Direction.NORTH).with(StairsBlock.WATERLOGGED, false).with(StairsBlock.SHAPE, StairsShape.STRAIGHT).with(StairsBlock.HALF, Half.TOP), 9, 14, 21, start);
        structure.setBlockState(world, Blocks.COBBLESTONE_STAIRS.getDefaultState().with(StairsBlock.FACING, Direction.WEST).with(StairsBlock.WATERLOGGED, false).with(StairsBlock.SHAPE, StairsShape.STRAIGHT).with(StairsBlock.HALF, Half.BOTTOM), 9, 15, 10, start);
        structure.setBlockState(world, Blocks.COBBLESTONE_STAIRS.getDefaultState().with(StairsBlock.FACING, Direction.WEST).with(StairsBlock.WATERLOGGED, false).with(StairsBlock.SHAPE, StairsShape.STRAIGHT).with(StairsBlock.HALF, Half.BOTTOM), 9, 15, 21, start);
        structure.setBlockState(world, Blocks.SMOOTH_STONE_SLAB.getDefaultState().with(SlabBlock.TYPE, SlabType.BOTTOM).with(SlabBlock.WATERLOGGED, false), 9, 35, 11, start);
        structure.setBlockState(world, Blocks.GRASS_BLOCK.getDefaultState().with(SnowyDirtBlock.SNOWY, false), 10, 3, 4, start);
        structure.setBlockState(world, Blocks.GRASS_BLOCK.getDefaultState().with(SnowyDirtBlock.SNOWY, false), 10, 3, 26, start);
        structure.setBlockState(world, Blocks.GRASS_BLOCK.getDefaultState().with(SnowyDirtBlock.SNOWY, false), 10, 6, 12, start);
        structure.setBlockState(world, Blocks.GLOWSTONE.getDefaultState(), 10, 6, 13, start);
        structure.setBlockState(world, Blocks.GLOWSTONE.getDefaultState(), 10, 6, 18, start);
        structure.setBlockState(world, Blocks.GRASS_BLOCK.getDefaultState().with(SnowyDirtBlock.SNOWY, false), 10, 6, 19, start);
        structure.setBlockState(world, Blocks.COBBLESTONE_WALL.getDefaultState().with(WallBlock.WATERLOGGED, false).with(WallBlock.UP, false).with(WallBlock.WALL_HEIGHT_NORTH, WallHeight.LOW).with(WallBlock.WALL_HEIGHT_SOUTH, WallHeight.LOW).with(WallBlock.WALL_HEIGHT_EAST, WallHeight.LOW).with(WallBlock.WALL_HEIGHT_WEST, WallHeight.LOW), 10, 7, 9, start);
        structure.setBlockState(world, Blocks.GLOWSTONE.getDefaultState(), 10, 7, 10, start);
        structure.setBlockState(world, Blocks.CHISELED_STONE_BRICKS.getDefaultState(), 10, 7, 11, start);
        structure.setBlockState(world, Blocks.COBBLESTONE_STAIRS.getDefaultState().with(StairsBlock.FACING, Direction.NORTH).with(StairsBlock.WATERLOGGED, false).with(StairsBlock.SHAPE, StairsShape.STRAIGHT).with(StairsBlock.HALF, Half.TOP), 10, 7, 12, start);
        structure.setBlockState(world, Blocks.COBBLESTONE_WALL.getDefaultState().with(WallBlock.WATERLOGGED, false).with(WallBlock.UP, true).with(WallBlock.WALL_HEIGHT_NORTH, WallHeight.LOW).with(WallBlock.WALL_HEIGHT_SOUTH, WallHeight.LOW).with(WallBlock.WALL_HEIGHT_EAST, WallHeight.LOW).with(WallBlock.WALL_HEIGHT_WEST, WallHeight.LOW), 10, 7, 13, start);
        structure.setBlockState(world, Blocks.COBBLESTONE_WALL.getDefaultState().with(WallBlock.WATERLOGGED, false).with(WallBlock.UP, true).with(WallBlock.WALL_HEIGHT_NORTH, WallHeight.LOW).with(WallBlock.WALL_HEIGHT_SOUTH, WallHeight.LOW).with(WallBlock.WALL_HEIGHT_EAST, WallHeight.LOW).with(WallBlock.WALL_HEIGHT_WEST, WallHeight.LOW), 10, 7, 18, start);
        structure.setBlockState(world, Blocks.COBBLESTONE_STAIRS.getDefaultState().with(StairsBlock.FACING, Direction.SOUTH).with(StairsBlock.WATERLOGGED, false).with(StairsBlock.SHAPE, StairsShape.STRAIGHT).with(StairsBlock.HALF, Half.TOP), 10, 7, 19, start);
        structure.setBlockState(world, Blocks.GLOWSTONE.getDefaultState(), 10, 7, 21, start);
        structure.setBlockState(world, Blocks.COBBLESTONE_WALL.getDefaultState().with(WallBlock.WATERLOGGED, false).with(WallBlock.UP, true).with(WallBlock.WALL_HEIGHT_NORTH, WallHeight.LOW).with(WallBlock.WALL_HEIGHT_SOUTH, WallHeight.LOW).with(WallBlock.WALL_HEIGHT_EAST, WallHeight.LOW).with(WallBlock.WALL_HEIGHT_WEST, WallHeight.LOW), 10, 7, 22, start);
        structure.setBlockState(world, Blocks.SMOOTH_STONE_SLAB.getDefaultState().with(SlabBlock.TYPE, SlabType.BOTTOM).with(SlabBlock.WATERLOGGED, false), 10, 8, 10, start);
        structure.setBlockState(world, Blocks.COBBLESTONE_WALL.getDefaultState().with(WallBlock.WATERLOGGED, false).with(WallBlock.UP, true).with(WallBlock.WALL_HEIGHT_NORTH, WallHeight.LOW).with(WallBlock.WALL_HEIGHT_SOUTH, WallHeight.LOW).with(WallBlock.WALL_HEIGHT_EAST, WallHeight.LOW).with(WallBlock.WALL_HEIGHT_WEST, WallHeight.LOW), 10, 8, 11, start);
        structure.setBlockState(world, Blocks.COBBLESTONE_WALL.getDefaultState().with(WallBlock.WATERLOGGED, false).with(WallBlock.UP, true).with(WallBlock.WALL_HEIGHT_NORTH, WallHeight.LOW).with(WallBlock.WALL_HEIGHT_SOUTH, WallHeight.LOW).with(WallBlock.WALL_HEIGHT_EAST, WallHeight.LOW).with(WallBlock.WALL_HEIGHT_WEST, WallHeight.LOW), 10, 8, 12, start);
        structure.setBlockState(world, Blocks.COBBLESTONE_STAIRS.getDefaultState().with(StairsBlock.FACING, Direction.EAST).with(StairsBlock.WATERLOGGED, false).with(StairsBlock.SHAPE, StairsShape.STRAIGHT).with(StairsBlock.HALF, Half.BOTTOM), 10, 8, 13, start);
        structure.setBlockState(world, Blocks.COBBLESTONE_STAIRS.getDefaultState().with(StairsBlock.FACING, Direction.EAST).with(StairsBlock.WATERLOGGED, false).with(StairsBlock.SHAPE, StairsShape.STRAIGHT).with(StairsBlock.HALF, Half.BOTTOM), 10, 8, 18, start);
        structure.setBlockState(world, Blocks.COBBLESTONE_WALL.getDefaultState().with(WallBlock.WATERLOGGED, false).with(WallBlock.UP, true).with(WallBlock.WALL_HEIGHT_NORTH, WallHeight.LOW).with(WallBlock.WALL_HEIGHT_SOUTH, WallHeight.LOW).with(WallBlock.WALL_HEIGHT_EAST, WallHeight.LOW).with(WallBlock.WALL_HEIGHT_WEST, WallHeight.LOW), 10, 8, 19, start);
        structure.setBlockState(world, Blocks.SMOOTH_STONE_SLAB.getDefaultState().with(SlabBlock.TYPE, SlabType.BOTTOM).with(SlabBlock.WATERLOGGED, false), 10, 8, 21, start);
        structure.setBlockState(world, Blocks.SMOOTH_STONE_SLAB.getDefaultState().with(SlabBlock.TYPE, SlabType.TOP).with(SlabBlock.WATERLOGGED, false), 10, 9, 10, start);
        structure.setBlockState(world, Blocks.COBBLESTONE_STAIRS.getDefaultState().with(StairsBlock.FACING, Direction.EAST).with(StairsBlock.WATERLOGGED, false).with(StairsBlock.SHAPE, StairsShape.STRAIGHT).with(StairsBlock.HALF, Half.TOP), 10, 9, 11, start);
        structure.setBlockState(world, Blocks.SMOOTH_STONE_SLAB.getDefaultState().with(SlabBlock.TYPE, SlabType.TOP).with(SlabBlock.WATERLOGGED, false), 10, 9, 13, start);
        structure.setBlockState(world, Blocks.SMOOTH_STONE_SLAB.getDefaultState().with(SlabBlock.TYPE, SlabType.TOP).with(SlabBlock.WATERLOGGED, false), 10, 9, 18, start);
        structure.setBlockState(world, Blocks.COBBLESTONE_STAIRS.getDefaultState().with(StairsBlock.FACING, Direction.EAST).with(StairsBlock.WATERLOGGED, false).with(StairsBlock.SHAPE, StairsShape.STRAIGHT).with(StairsBlock.HALF, Half.TOP), 10, 9, 20, start);
        structure.setBlockState(world, Blocks.SMOOTH_STONE_SLAB.getDefaultState().with(SlabBlock.TYPE, SlabType.TOP).with(SlabBlock.WATERLOGGED, false), 10, 9, 21, start);
        structure.setBlockState(world, Blocks.COBBLESTONE_WALL.getDefaultState().with(WallBlock.WATERLOGGED, false).with(WallBlock.UP, true).with(WallBlock.WALL_HEIGHT_NORTH, WallHeight.LOW).with(WallBlock.WALL_HEIGHT_SOUTH, WallHeight.LOW).with(WallBlock.WALL_HEIGHT_EAST, WallHeight.LOW).with(WallBlock.WALL_HEIGHT_WEST, WallHeight.LOW), 10, 10, 10, start);
        structure.setBlockState(world, Blocks.COBBLESTONE_WALL.getDefaultState().with(WallBlock.WATERLOGGED, false).with(WallBlock.UP, true).with(WallBlock.WALL_HEIGHT_NORTH, WallHeight.LOW).with(WallBlock.WALL_HEIGHT_SOUTH, WallHeight.LOW).with(WallBlock.WALL_HEIGHT_EAST, WallHeight.LOW).with(WallBlock.WALL_HEIGHT_WEST, WallHeight.LOW), 10, 10, 13, start);
        structure.setBlockState(world, Blocks.SMOOTH_STONE_SLAB.getDefaultState().with(SlabBlock.TYPE, SlabType.TOP).with(SlabBlock.WATERLOGGED, false), 10, 10, 14, start);
        structure.setBlockState(world, Blocks.SMOOTH_STONE_SLAB.getDefaultState().with(SlabBlock.TYPE, SlabType.TOP).with(SlabBlock.WATERLOGGED, false), 10, 10, 17, start);
        structure.setBlockState(world, Blocks.COBBLESTONE_WALL.getDefaultState().with(WallBlock.WATERLOGGED, false).with(WallBlock.UP, true).with(WallBlock.WALL_HEIGHT_NORTH, WallHeight.LOW).with(WallBlock.WALL_HEIGHT_SOUTH, WallHeight.LOW).with(WallBlock.WALL_HEIGHT_EAST, WallHeight.LOW).with(WallBlock.WALL_HEIGHT_WEST, WallHeight.LOW), 10, 10, 18, start);
        structure.setBlockState(world, Blocks.COBBLESTONE_WALL.getDefaultState().with(WallBlock.WATERLOGGED, false).with(WallBlock.UP, true).with(WallBlock.WALL_HEIGHT_NORTH, WallHeight.LOW).with(WallBlock.WALL_HEIGHT_SOUTH, WallHeight.LOW).with(WallBlock.WALL_HEIGHT_EAST, WallHeight.LOW).with(WallBlock.WALL_HEIGHT_WEST, WallHeight.LOW), 10, 10, 21, start);
        structure.setBlockState(world, Blocks.COBBLESTONE_WALL.getDefaultState().with(WallBlock.WATERLOGGED, false).with(WallBlock.UP, true).with(WallBlock.WALL_HEIGHT_NORTH, WallHeight.LOW).with(WallBlock.WALL_HEIGHT_SOUTH, WallHeight.LOW).with(WallBlock.WALL_HEIGHT_EAST, WallHeight.LOW).with(WallBlock.WALL_HEIGHT_WEST, WallHeight.LOW), 10, 11, 9, start);
        structure.setBlockState(world, Blocks.SMOOTH_STONE_SLAB.getDefaultState().with(SlabBlock.TYPE, SlabType.DOUBLE).with(SlabBlock.WATERLOGGED, false), 10, 11, 10, start);
        structure.setBlockState(world, Blocks.CHISELED_STONE_BRICKS.getDefaultState(), 10, 11, 11, start);
        structure.setBlockState(world, Blocks.COBBLESTONE_WALL.getDefaultState().with(WallBlock.WATERLOGGED, false).with(WallBlock.UP, true).with(WallBlock.WALL_HEIGHT_NORTH, WallHeight.LOW).with(WallBlock.WALL_HEIGHT_SOUTH, WallHeight.LOW).with(WallBlock.WALL_HEIGHT_EAST, WallHeight.LOW).with(WallBlock.WALL_HEIGHT_WEST, WallHeight.LOW), 10, 11, 12, start);
        structure.setBlockState(world, Blocks.COBBLESTONE_STAIRS.getDefaultState().with(StairsBlock.FACING, Direction.SOUTH).with(StairsBlock.WATERLOGGED, false).with(StairsBlock.SHAPE, StairsShape.STRAIGHT).with(StairsBlock.HALF, Half.TOP), 10, 11, 17, start);
        structure.setBlockState(world, Blocks.COBBLESTONE_WALL.getDefaultState().with(WallBlock.WATERLOGGED, false).with(WallBlock.UP, true).with(WallBlock.WALL_HEIGHT_NORTH, WallHeight.LOW).with(WallBlock.WALL_HEIGHT_SOUTH, WallHeight.LOW).with(WallBlock.WALL_HEIGHT_EAST, WallHeight.LOW).with(WallBlock.WALL_HEIGHT_WEST, WallHeight.LOW), 10, 11, 19, start);
        structure.setBlockState(world, Blocks.SMOOTH_STONE_SLAB.getDefaultState().with(SlabBlock.TYPE, SlabType.DOUBLE).with(SlabBlock.WATERLOGGED, false), 10, 11, 21, start);
        structure.setBlockState(world, Blocks.COBBLESTONE_WALL.getDefaultState().with(WallBlock.WATERLOGGED, false).with(WallBlock.UP, true).with(WallBlock.WALL_HEIGHT_NORTH, WallHeight.LOW).with(WallBlock.WALL_HEIGHT_SOUTH, WallHeight.LOW).with(WallBlock.WALL_HEIGHT_EAST, WallHeight.LOW).with(WallBlock.WALL_HEIGHT_WEST, WallHeight.LOW), 10, 11, 22, start);
        structure.setBlockState(world, Blocks.COBBLESTONE_STAIRS.getDefaultState().with(StairsBlock.FACING, Direction.SOUTH).with(StairsBlock.WATERLOGGED, false).with(StairsBlock.SHAPE, StairsShape.STRAIGHT).with(StairsBlock.HALF, Half.TOP), 10, 12, 9, start);
        structure.setBlockState(world, Blocks.CHISELED_STONE_BRICKS.getDefaultState(), 10, 12, 12, start);
        structure.setBlockState(world, Blocks.COBBLESTONE_STAIRS.getDefaultState().with(StairsBlock.FACING, Direction.NORTH).with(StairsBlock.WATERLOGGED, false).with(StairsBlock.SHAPE, StairsShape.STRAIGHT).with(StairsBlock.HALF, Half.TOP), 10, 12, 13, start);
        structure.setBlockState(world, Blocks.COBBLESTONE_WALL.getDefaultState().with(WallBlock.WATERLOGGED, false).with(WallBlock.UP, true).with(WallBlock.WALL_HEIGHT_NORTH, WallHeight.LOW).with(WallBlock.WALL_HEIGHT_SOUTH, WallHeight.LOW).with(WallBlock.WALL_HEIGHT_EAST, WallHeight.LOW).with(WallBlock.WALL_HEIGHT_WEST, WallHeight.LOW), 10, 12, 14, start);
        structure.setBlockState(world, Blocks.COBBLESTONE_STAIRS.getDefaultState().with(StairsBlock.FACING, Direction.NORTH).with(StairsBlock.WATERLOGGED, false).with(StairsBlock.SHAPE, StairsShape.STRAIGHT).with(StairsBlock.HALF, Half.TOP), 10, 12, 15, start);
        structure.setBlockState(world, Blocks.COBBLESTONE_STAIRS.getDefaultState().with(StairsBlock.FACING, Direction.SOUTH).with(StairsBlock.WATERLOGGED, false).with(StairsBlock.SHAPE, StairsShape.STRAIGHT).with(StairsBlock.HALF, Half.TOP), 10, 12, 16, start);
        structure.setBlockState(world, Blocks.COBBLESTONE_WALL.getDefaultState().with(WallBlock.WATERLOGGED, false).with(WallBlock.UP, true).with(WallBlock.WALL_HEIGHT_NORTH, WallHeight.LOW).with(WallBlock.WALL_HEIGHT_SOUTH, WallHeight.LOW).with(WallBlock.WALL_HEIGHT_EAST, WallHeight.LOW).with(WallBlock.WALL_HEIGHT_WEST, WallHeight.LOW), 10, 12, 17, start);
        structure.setBlockState(world, Blocks.COBBLESTONE_STAIRS.getDefaultState().with(StairsBlock.FACING, Direction.SOUTH).with(StairsBlock.WATERLOGGED, false).with(StairsBlock.SHAPE, StairsShape.STRAIGHT).with(StairsBlock.HALF, Half.TOP), 10, 12, 18, start);
        structure.setBlockState(world, Blocks.CHISELED_STONE_BRICKS.getDefaultState(), 10, 12, 19, start);
        structure.setBlockState(world, Blocks.COBBLESTONE_STAIRS.getDefaultState().with(StairsBlock.FACING, Direction.NORTH).with(StairsBlock.WATERLOGGED, false).with(StairsBlock.SHAPE, StairsShape.STRAIGHT).with(StairsBlock.HALF, Half.TOP), 10, 12, 22, start);
        structure.setBlockState(world, Blocks.COBBLESTONE_WALL.getDefaultState().with(WallBlock.WATERLOGGED, false).with(WallBlock.UP, true).with(WallBlock.WALL_HEIGHT_NORTH, WallHeight.LOW).with(WallBlock.WALL_HEIGHT_SOUTH, WallHeight.LOW).with(WallBlock.WALL_HEIGHT_EAST, WallHeight.LOW).with(WallBlock.WALL_HEIGHT_WEST, WallHeight.LOW), 10, 13, 9, start);
        structure.setBlockState(world, Blocks.GLOWSTONE.getDefaultState(), 10, 13, 10, start);
        structure.setBlockState(world, Blocks.COBBLESTONE_WALL.getDefaultState().with(WallBlock.WATERLOGGED, false).with(WallBlock.UP, true).with(WallBlock.WALL_HEIGHT_NORTH, WallHeight.LOW).with(WallBlock.WALL_HEIGHT_SOUTH, WallHeight.LOW).with(WallBlock.WALL_HEIGHT_EAST, WallHeight.LOW).with(WallBlock.WALL_HEIGHT_WEST, WallHeight.LOW), 10, 13, 12, start);
        structure.setBlockState(world, Blocks.SMOOTH_STONE_SLAB.getDefaultState().with(SlabBlock.TYPE, SlabType.DOUBLE).with(SlabBlock.WATERLOGGED, false), 10, 13, 13, start);
        structure.setBlockState(world, Blocks.SMOOTH_STONE_SLAB.getDefaultState().with(SlabBlock.TYPE, SlabType.BOTTOM).with(SlabBlock.WATERLOGGED, false), 10, 13, 14, start);
        structure.setBlockState(world, Blocks.SMOOTH_STONE_SLAB.getDefaultState().with(SlabBlock.TYPE, SlabType.BOTTOM).with(SlabBlock.WATERLOGGED, false), 10, 13, 17, start);
        structure.setBlockState(world, Blocks.SMOOTH_STONE_SLAB.getDefaultState().with(SlabBlock.TYPE, SlabType.DOUBLE).with(SlabBlock.WATERLOGGED, false), 10, 13, 18, start);
        structure.setBlockState(world, Blocks.COBBLESTONE_WALL.getDefaultState().with(WallBlock.WATERLOGGED, false).with(WallBlock.UP, true).with(WallBlock.WALL_HEIGHT_NORTH, WallHeight.LOW).with(WallBlock.WALL_HEIGHT_SOUTH, WallHeight.LOW).with(WallBlock.WALL_HEIGHT_EAST, WallHeight.LOW).with(WallBlock.WALL_HEIGHT_WEST, WallHeight.LOW), 10, 13, 19, start);
        structure.setBlockState(world, Blocks.GLOWSTONE.getDefaultState(), 10, 13, 21, start);
        structure.setBlockState(world, Blocks.COBBLESTONE_WALL.getDefaultState().with(WallBlock.WATERLOGGED, false).with(WallBlock.UP, true).with(WallBlock.WALL_HEIGHT_NORTH, WallHeight.LOW).with(WallBlock.WALL_HEIGHT_SOUTH, WallHeight.LOW).with(WallBlock.WALL_HEIGHT_EAST, WallHeight.LOW).with(WallBlock.WALL_HEIGHT_WEST, WallHeight.LOW), 10, 13, 22, start);
        structure.setBlockState(world, Blocks.COBBLESTONE_STAIRS.getDefaultState().with(StairsBlock.FACING, Direction.EAST).with(StairsBlock.WATERLOGGED, false).with(StairsBlock.SHAPE, StairsShape.STRAIGHT).with(StairsBlock.HALF, Half.TOP), 10, 14, 9, start);
        structure.setBlockState(world, Blocks.OBSIDIAN.getDefaultState(), 10, 14, 10, start);
        structure.setBlockState(world, Blocks.GLOWSTONE.getDefaultState(), 10, 14, 12, start);
        structure.setBlockState(world, Blocks.COBBLESTONE_STAIRS.getDefaultState().with(StairsBlock.FACING, Direction.NORTH).with(StairsBlock.WATERLOGGED, false).with(StairsBlock.SHAPE, StairsShape.STRAIGHT).with(StairsBlock.HALF, Half.BOTTOM), 10, 14, 13, start);
        structure.setBlockState(world, Blocks.COBBLESTONE_STAIRS.getDefaultState().with(StairsBlock.FACING, Direction.SOUTH).with(StairsBlock.WATERLOGGED, false).with(StairsBlock.SHAPE, StairsShape.STRAIGHT).with(StairsBlock.HALF, Half.TOP), 10, 14, 14, start);
        structure.setBlockState(world, Blocks.COBBLESTONE_STAIRS.getDefaultState().with(StairsBlock.FACING, Direction.NORTH).with(StairsBlock.WATERLOGGED, false).with(StairsBlock.SHAPE, StairsShape.STRAIGHT).with(StairsBlock.HALF, Half.TOP), 10, 14, 17, start);
        structure.setBlockState(world, Blocks.COBBLESTONE_STAIRS.getDefaultState().with(StairsBlock.FACING, Direction.SOUTH).with(StairsBlock.WATERLOGGED, false).with(StairsBlock.SHAPE, StairsShape.STRAIGHT).with(StairsBlock.HALF, Half.BOTTOM), 10, 14, 18, start);
        structure.setBlockState(world, Blocks.GLOWSTONE.getDefaultState(), 10, 14, 19, start);
        structure.setBlockState(world, Blocks.OBSIDIAN.getDefaultState(), 10, 14, 21, start);
        structure.setBlockState(world, Blocks.COBBLESTONE_STAIRS.getDefaultState().with(StairsBlock.FACING, Direction.EAST).with(StairsBlock.WATERLOGGED, false).with(StairsBlock.SHAPE, StairsShape.STRAIGHT).with(StairsBlock.HALF, Half.TOP), 10, 14, 22, start);
        structure.setBlockState(world, Blocks.STONE_BRICK_STAIRS.getDefaultState().with(StairsBlock.FACING, Direction.SOUTH).with(StairsBlock.WATERLOGGED, false).with(StairsBlock.SHAPE, StairsShape.STRAIGHT).with(StairsBlock.HALF, Half.TOP), 10, 15, 8, start);
        structure.setBlockState(world, Blocks.COBBLESTONE_STAIRS.getDefaultState().with(StairsBlock.FACING, Direction.NORTH).with(StairsBlock.WATERLOGGED, false).with(StairsBlock.SHAPE, StairsShape.STRAIGHT).with(StairsBlock.HALF, Half.BOTTOM), 10, 15, 9, start);
        structure.setBlockState(world, Blocks.AIR.getDefaultState(), 10, 15, 10, start);
        structure.setBlockState(world, Blocks.COBBLESTONE_SLAB.getDefaultState().with(SlabBlock.TYPE, SlabType.BOTTOM).with(SlabBlock.WATERLOGGED, false), 10, 15, 11, start);
        structure.setBlockState(world, Blocks.COBBLESTONE_WALL.getDefaultState().with(WallBlock.WATERLOGGED, false).with(WallBlock.UP, true).with(WallBlock.WALL_HEIGHT_NORTH, WallHeight.LOW).with(WallBlock.WALL_HEIGHT_SOUTH, WallHeight.LOW).with(WallBlock.WALL_HEIGHT_EAST, WallHeight.LOW).with(WallBlock.WALL_HEIGHT_WEST, WallHeight.LOW), 10, 15, 12, start);
        structure.setBlockState(world, Blocks.COBBLESTONE_WALL.getDefaultState().with(WallBlock.WATERLOGGED, false).with(WallBlock.UP, true).with(WallBlock.WALL_HEIGHT_NORTH, WallHeight.LOW).with(WallBlock.WALL_HEIGHT_SOUTH, WallHeight.LOW).with(WallBlock.WALL_HEIGHT_EAST, WallHeight.LOW).with(WallBlock.WALL_HEIGHT_WEST, WallHeight.LOW), 10, 15, 19, start);
        structure.setBlockState(world, Blocks.AIR.getDefaultState(), 10, 15, 21, start);
        structure.setBlockState(world, Blocks.COBBLESTONE_STAIRS.getDefaultState().with(StairsBlock.FACING, Direction.SOUTH).with(StairsBlock.WATERLOGGED, false).with(StairsBlock.SHAPE, StairsShape.STRAIGHT).with(StairsBlock.HALF, Half.BOTTOM), 10, 15, 22, start);
        structure.setBlockState(world, Blocks.COBBLESTONE_WALL.getDefaultState().with(WallBlock.WATERLOGGED, false).with(WallBlock.UP, false).with(WallBlock.WALL_HEIGHT_NORTH, WallHeight.LOW).with(WallBlock.WALL_HEIGHT_SOUTH, WallHeight.LOW).with(WallBlock.WALL_HEIGHT_EAST, WallHeight.LOW).with(WallBlock.WALL_HEIGHT_WEST, WallHeight.LOW), 10, 16, 8, start);
        structure.setBlockState(world, Blocks.COBBLESTONE_STAIRS.getDefaultState().with(StairsBlock.FACING, Direction.EAST).with(StairsBlock.WATERLOGGED, false).with(StairsBlock.SHAPE, StairsShape.STRAIGHT).with(StairsBlock.HALF, Half.TOP), 10, 21, 13, start);
        structure.setBlockState(world, Blocks.COBBLESTONE_STAIRS.getDefaultState().with(StairsBlock.FACING, Direction.EAST).with(StairsBlock.WATERLOGGED, false).with(StairsBlock.SHAPE, StairsShape.STRAIGHT).with(StairsBlock.HALF, Half.TOP), 10, 21, 18, start);
        structure.setBlockState(world, Blocks.COBBLESTONE_WALL.getDefaultState().with(WallBlock.WATERLOGGED, false).with(WallBlock.UP, true).with(WallBlock.WALL_HEIGHT_NORTH, WallHeight.LOW).with(WallBlock.WALL_HEIGHT_SOUTH, WallHeight.LOW).with(WallBlock.WALL_HEIGHT_EAST, WallHeight.LOW).with(WallBlock.WALL_HEIGHT_WEST, WallHeight.LOW), 10, 22, 13, start);
        structure.setBlockState(world, Blocks.STONE_BRICK_STAIRS.getDefaultState().with(StairsBlock.FACING, Direction.NORTH).with(StairsBlock.WATERLOGGED, false).with(StairsBlock.SHAPE, StairsShape.STRAIGHT).with(StairsBlock.HALF, Half.TOP), 10, 22, 14, start);
        structure.setBlockState(world, Blocks.STONE_BRICK_STAIRS.getDefaultState().with(StairsBlock.FACING, Direction.SOUTH).with(StairsBlock.WATERLOGGED, false).with(StairsBlock.SHAPE, StairsShape.STRAIGHT).with(StairsBlock.HALF, Half.TOP), 10, 22, 17, start);
        structure.setBlockState(world, Blocks.COBBLESTONE_WALL.getDefaultState().with(WallBlock.WATERLOGGED, false).with(WallBlock.UP, true).with(WallBlock.WALL_HEIGHT_NORTH, WallHeight.LOW).with(WallBlock.WALL_HEIGHT_SOUTH, WallHeight.LOW).with(WallBlock.WALL_HEIGHT_EAST, WallHeight.LOW).with(WallBlock.WALL_HEIGHT_WEST, WallHeight.LOW), 10, 22, 18, start);
        structure.setBlockState(world, Blocks.COBBLESTONE_WALL.getDefaultState().with(WallBlock.WATERLOGGED, false).with(WallBlock.UP, true).with(WallBlock.WALL_HEIGHT_NORTH, WallHeight.LOW).with(WallBlock.WALL_HEIGHT_SOUTH, WallHeight.LOW).with(WallBlock.WALL_HEIGHT_EAST, WallHeight.LOW).with(WallBlock.WALL_HEIGHT_WEST, WallHeight.LOW), 10, 23, 14, start);
        structure.setBlockState(world, Blocks.COBBLESTONE_WALL.getDefaultState().with(WallBlock.WATERLOGGED, false).with(WallBlock.UP, true).with(WallBlock.WALL_HEIGHT_NORTH, WallHeight.LOW).with(WallBlock.WALL_HEIGHT_SOUTH, WallHeight.LOW).with(WallBlock.WALL_HEIGHT_EAST, WallHeight.LOW).with(WallBlock.WALL_HEIGHT_WEST, WallHeight.LOW), 10, 23, 17, start);
        structure.setBlockState(world, Blocks.COBBLESTONE_STAIRS.getDefaultState().with(StairsBlock.FACING, Direction.EAST).with(StairsBlock.WATERLOGGED, false).with(StairsBlock.SHAPE, StairsShape.STRAIGHT).with(StairsBlock.HALF, Half.TOP), 10, 24, 13, start);
        structure.setBlockState(world, Blocks.SMOOTH_STONE_SLAB.getDefaultState().with(SlabBlock.TYPE, SlabType.BOTTOM).with(SlabBlock.WATERLOGGED, false), 10, 24, 14, start);
        structure.setBlockState(world, Blocks.SMOOTH_STONE_SLAB.getDefaultState().with(SlabBlock.TYPE, SlabType.BOTTOM).with(SlabBlock.WATERLOGGED, false), 10, 24, 17, start);
        structure.setBlockState(world, Blocks.COBBLESTONE_STAIRS.getDefaultState().with(StairsBlock.FACING, Direction.EAST).with(StairsBlock.WATERLOGGED, false).with(StairsBlock.SHAPE, StairsShape.STRAIGHT).with(StairsBlock.HALF, Half.TOP), 10, 24, 18, start);
        structure.setBlockState(world, Blocks.COBBLESTONE_WALL.getDefaultState().with(WallBlock.WATERLOGGED, false).with(WallBlock.UP, true).with(WallBlock.WALL_HEIGHT_NORTH, WallHeight.LOW).with(WallBlock.WALL_HEIGHT_SOUTH, WallHeight.LOW).with(WallBlock.WALL_HEIGHT_EAST, WallHeight.LOW).with(WallBlock.WALL_HEIGHT_WEST, WallHeight.LOW), 10, 25, 13, start);
        structure.setBlockState(world, Blocks.STONE_BRICK_STAIRS.getDefaultState().with(StairsBlock.FACING, Direction.NORTH).with(StairsBlock.WATERLOGGED, false).with(StairsBlock.SHAPE, StairsShape.STRAIGHT).with(StairsBlock.HALF, Half.TOP), 10, 25, 14, start);
        structure.setBlockState(world, Blocks.STONE_BRICK_STAIRS.getDefaultState().with(StairsBlock.FACING, Direction.SOUTH).with(StairsBlock.WATERLOGGED, false).with(StairsBlock.SHAPE, StairsShape.STRAIGHT).with(StairsBlock.HALF, Half.TOP), 10, 25, 17, start);
        structure.setBlockState(world, Blocks.COBBLESTONE_WALL.getDefaultState().with(WallBlock.WATERLOGGED, false).with(WallBlock.UP, true).with(WallBlock.WALL_HEIGHT_NORTH, WallHeight.LOW).with(WallBlock.WALL_HEIGHT_SOUTH, WallHeight.LOW).with(WallBlock.WALL_HEIGHT_EAST, WallHeight.LOW).with(WallBlock.WALL_HEIGHT_WEST, WallHeight.LOW), 10, 25, 18, start);
        structure.setBlockState(world, Blocks.COBBLESTONE_WALL.getDefaultState().with(WallBlock.WATERLOGGED, false).with(WallBlock.UP, true).with(WallBlock.WALL_HEIGHT_NORTH, WallHeight.LOW).with(WallBlock.WALL_HEIGHT_SOUTH, WallHeight.LOW).with(WallBlock.WALL_HEIGHT_EAST, WallHeight.LOW).with(WallBlock.WALL_HEIGHT_WEST, WallHeight.LOW), 10, 26, 14, start);
        structure.setBlockState(world, Blocks.COBBLESTONE_WALL.getDefaultState().with(WallBlock.WATERLOGGED, false).with(WallBlock.UP, true).with(WallBlock.WALL_HEIGHT_NORTH, WallHeight.LOW).with(WallBlock.WALL_HEIGHT_SOUTH, WallHeight.LOW).with(WallBlock.WALL_HEIGHT_EAST, WallHeight.LOW).with(WallBlock.WALL_HEIGHT_WEST, WallHeight.LOW), 10, 26, 17, start);
        structure.setBlockState(world, Blocks.STONE_BRICK_STAIRS.getDefaultState().with(StairsBlock.FACING, Direction.EAST).with(StairsBlock.WATERLOGGED, false).with(StairsBlock.SHAPE, StairsShape.STRAIGHT).with(StairsBlock.HALF, Half.TOP), 10, 27, 13, start);
        structure.setBlockState(world, Blocks.SMOOTH_STONE_SLAB.getDefaultState().with(SlabBlock.TYPE, SlabType.BOTTOM).with(SlabBlock.WATERLOGGED, false), 10, 27, 14, start);
        structure.setBlockState(world, Blocks.SMOOTH_STONE_SLAB.getDefaultState().with(SlabBlock.TYPE, SlabType.BOTTOM).with(SlabBlock.WATERLOGGED, false), 10, 27, 17, start);
        structure.setBlockState(world, Blocks.STONE_BRICK_STAIRS.getDefaultState().with(StairsBlock.FACING, Direction.EAST).with(StairsBlock.WATERLOGGED, false).with(StairsBlock.SHAPE, StairsShape.STRAIGHT).with(StairsBlock.HALF, Half.TOP), 10, 27, 18, start);
        structure.setBlockState(world, Blocks.COBBLESTONE_WALL.getDefaultState().with(WallBlock.WATERLOGGED, false).with(WallBlock.UP, true).with(WallBlock.WALL_HEIGHT_NORTH, WallHeight.LOW).with(WallBlock.WALL_HEIGHT_SOUTH, WallHeight.LOW).with(WallBlock.WALL_HEIGHT_EAST, WallHeight.LOW).with(WallBlock.WALL_HEIGHT_WEST, WallHeight.LOW), 10, 28, 13, start);
        structure.setBlockState(world, Blocks.COBBLESTONE_WALL.getDefaultState().with(WallBlock.WATERLOGGED, false).with(WallBlock.UP, true).with(WallBlock.WALL_HEIGHT_NORTH, WallHeight.LOW).with(WallBlock.WALL_HEIGHT_SOUTH, WallHeight.LOW).with(WallBlock.WALL_HEIGHT_EAST, WallHeight.LOW).with(WallBlock.WALL_HEIGHT_WEST, WallHeight.LOW), 10, 28, 18, start);
        structure.setBlockState(world, Blocks.COBBLESTONE_WALL.getDefaultState().with(WallBlock.WATERLOGGED, false).with(WallBlock.UP, true).with(WallBlock.WALL_HEIGHT_NORTH, WallHeight.LOW).with(WallBlock.WALL_HEIGHT_SOUTH, WallHeight.LOW).with(WallBlock.WALL_HEIGHT_EAST, WallHeight.LOW).with(WallBlock.WALL_HEIGHT_WEST, WallHeight.LOW), 10, 29, 13, start);
        structure.setBlockState(world, Blocks.COBBLESTONE_WALL.getDefaultState().with(WallBlock.WATERLOGGED, false).with(WallBlock.UP, true).with(WallBlock.WALL_HEIGHT_NORTH, WallHeight.LOW).with(WallBlock.WALL_HEIGHT_SOUTH, WallHeight.LOW).with(WallBlock.WALL_HEIGHT_EAST, WallHeight.LOW).with(WallBlock.WALL_HEIGHT_WEST, WallHeight.LOW), 10, 29, 18, start);
        structure.setBlockState(world, Blocks.COBBLESTONE_WALL.getDefaultState().with(WallBlock.WATERLOGGED, false).with(WallBlock.UP, true).with(WallBlock.WALL_HEIGHT_NORTH, WallHeight.LOW).with(WallBlock.WALL_HEIGHT_SOUTH, WallHeight.LOW).with(WallBlock.WALL_HEIGHT_EAST, WallHeight.LOW).with(WallBlock.WALL_HEIGHT_WEST, WallHeight.LOW), 10, 30, 13, start);
        structure.setBlockState(world, Blocks.COBBLESTONE_STAIRS.getDefaultState().with(StairsBlock.FACING, Direction.NORTH).with(StairsBlock.WATERLOGGED, false).with(StairsBlock.SHAPE, StairsShape.STRAIGHT).with(StairsBlock.HALF, Half.TOP), 10, 30, 14, start);
        structure.setBlockState(world, Blocks.COBBLESTONE_STAIRS.getDefaultState().with(StairsBlock.FACING, Direction.SOUTH).with(StairsBlock.WATERLOGGED, false).with(StairsBlock.SHAPE, StairsShape.STRAIGHT).with(StairsBlock.HALF, Half.TOP), 10, 30, 17, start);
        structure.setBlockState(world, Blocks.COBBLESTONE_WALL.getDefaultState().with(WallBlock.WATERLOGGED, false).with(WallBlock.UP, true).with(WallBlock.WALL_HEIGHT_NORTH, WallHeight.LOW).with(WallBlock.WALL_HEIGHT_SOUTH, WallHeight.LOW).with(WallBlock.WALL_HEIGHT_EAST, WallHeight.LOW).with(WallBlock.WALL_HEIGHT_WEST, WallHeight.LOW), 10, 30, 18, start);
        structure.setBlockState(world, Blocks.COBBLESTONE_STAIRS.getDefaultState().with(StairsBlock.FACING, Direction.EAST).with(StairsBlock.WATERLOGGED, false).with(StairsBlock.SHAPE, StairsShape.STRAIGHT).with(StairsBlock.HALF, Half.TOP), 10, 31, 12, start);
        structure.setBlockState(world, Blocks.CHISELED_STONE_BRICKS.getDefaultState(), 10, 31, 13, start);
        structure.setBlockState(world, Blocks.STONE_BRICKS.getDefaultState(), 10, 31, 14, start);
        structure.setBlockState(world, Blocks.COBBLESTONE_STAIRS.getDefaultState().with(StairsBlock.FACING, Direction.NORTH).with(StairsBlock.WATERLOGGED, false).with(StairsBlock.SHAPE, StairsShape.STRAIGHT).with(StairsBlock.HALF, Half.BOTTOM), 10, 31, 15, start);
        structure.setBlockState(world, Blocks.COBBLESTONE_STAIRS.getDefaultState().with(StairsBlock.FACING, Direction.SOUTH).with(StairsBlock.WATERLOGGED, false).with(StairsBlock.SHAPE, StairsShape.STRAIGHT).with(StairsBlock.HALF, Half.BOTTOM), 10, 31, 16, start);
        structure.setBlockState(world, Blocks.STONE_BRICKS.getDefaultState(), 10, 31, 17, start);
        structure.setBlockState(world, Blocks.CHISELED_STONE_BRICKS.getDefaultState(), 10, 31, 18, start);
        structure.setBlockState(world, Blocks.COBBLESTONE_STAIRS.getDefaultState().with(StairsBlock.FACING, Direction.EAST).with(StairsBlock.WATERLOGGED, false).with(StairsBlock.SHAPE, StairsShape.STRAIGHT).with(StairsBlock.HALF, Half.TOP), 10, 31, 19, start);
        structure.setBlockState(world, Blocks.COBBLESTONE_WALL.getDefaultState().with(WallBlock.WATERLOGGED, false).with(WallBlock.UP, true).with(WallBlock.WALL_HEIGHT_NORTH, WallHeight.LOW).with(WallBlock.WALL_HEIGHT_SOUTH, WallHeight.LOW).with(WallBlock.WALL_HEIGHT_EAST, WallHeight.LOW).with(WallBlock.WALL_HEIGHT_WEST, WallHeight.LOW), 10, 32, 12, start);
        structure.setBlockState(world, Blocks.STONE_BRICK_STAIRS.getDefaultState().with(StairsBlock.FACING, Direction.NORTH).with(StairsBlock.WATERLOGGED, false).with(StairsBlock.SHAPE, StairsShape.STRAIGHT).with(StairsBlock.HALF, Half.TOP), 10, 32, 13, start);
        structure.setBlockState(world, Blocks.COBBLESTONE_SLAB.getDefaultState().with(SlabBlock.TYPE, SlabType.BOTTOM).with(SlabBlock.WATERLOGGED, false), 10, 32, 14, start);
        structure.setBlockState(world, Blocks.COBBLESTONE_SLAB.getDefaultState().with(SlabBlock.TYPE, SlabType.BOTTOM).with(SlabBlock.WATERLOGGED, false), 10, 32, 17, start);
        structure.setBlockState(world, Blocks.STONE_BRICK_STAIRS.getDefaultState().with(StairsBlock.FACING, Direction.SOUTH).with(StairsBlock.WATERLOGGED, false).with(StairsBlock.SHAPE, StairsShape.STRAIGHT).with(StairsBlock.HALF, Half.TOP), 10, 32, 18, start);
        structure.setBlockState(world, Blocks.COBBLESTONE_WALL.getDefaultState().with(WallBlock.WATERLOGGED, false).with(WallBlock.UP, true).with(WallBlock.WALL_HEIGHT_NORTH, WallHeight.LOW).with(WallBlock.WALL_HEIGHT_SOUTH, WallHeight.LOW).with(WallBlock.WALL_HEIGHT_EAST, WallHeight.LOW).with(WallBlock.WALL_HEIGHT_WEST, WallHeight.LOW), 10, 32, 19, start);
        structure.setBlockState(world, Blocks.SMOOTH_STONE_SLAB.getDefaultState().with(SlabBlock.TYPE, SlabType.BOTTOM).with(SlabBlock.WATERLOGGED, false), 10, 33, 12, start);
        structure.setBlockState(world, Blocks.COBBLESTONE_WALL.getDefaultState().with(WallBlock.WATERLOGGED, false).with(WallBlock.UP, true).with(WallBlock.WALL_HEIGHT_NORTH, WallHeight.LOW).with(WallBlock.WALL_HEIGHT_SOUTH, WallHeight.LOW).with(WallBlock.WALL_HEIGHT_EAST, WallHeight.LOW).with(WallBlock.WALL_HEIGHT_WEST, WallHeight.LOW), 10, 33, 13, start);
        structure.setBlockState(world, Blocks.COBBLESTONE_WALL.getDefaultState().with(WallBlock.WATERLOGGED, false).with(WallBlock.UP, true).with(WallBlock.WALL_HEIGHT_NORTH, WallHeight.LOW).with(WallBlock.WALL_HEIGHT_SOUTH, WallHeight.LOW).with(WallBlock.WALL_HEIGHT_EAST, WallHeight.LOW).with(WallBlock.WALL_HEIGHT_WEST, WallHeight.LOW), 10, 33, 18, start);
        structure.setBlockState(world, Blocks.SMOOTH_STONE_SLAB.getDefaultState().with(SlabBlock.TYPE, SlabType.BOTTOM).with(SlabBlock.WATERLOGGED, false), 10, 33, 19, start);
        structure.setBlockState(world, Blocks.SMOOTH_STONE_SLAB.getDefaultState().with(SlabBlock.TYPE, SlabType.TOP).with(SlabBlock.WATERLOGGED, false), 10, 34, 11, start);
        structure.setBlockState(world, Blocks.COBBLESTONE_SLAB.getDefaultState().with(SlabBlock.TYPE, SlabType.TOP).with(SlabBlock.WATERLOGGED, false), 10, 34, 12, start);
        structure.setBlockState(world, Blocks.SMOOTH_STONE_SLAB.getDefaultState().with(SlabBlock.TYPE, SlabType.DOUBLE).with(SlabBlock.WATERLOGGED, false), 10, 34, 13, start);
        structure.setBlockState(world, Blocks.COBBLESTONE_STAIRS.getDefaultState().with(StairsBlock.FACING, Direction.NORTH).with(StairsBlock.WATERLOGGED, false).with(StairsBlock.SHAPE, StairsShape.STRAIGHT).with(StairsBlock.HALF, Half.TOP), 10, 34, 14, start);
        structure.setBlockState(world, Blocks.COBBLESTONE_STAIRS.getDefaultState().with(StairsBlock.FACING, Direction.SOUTH).with(StairsBlock.WATERLOGGED, false).with(StairsBlock.SHAPE, StairsShape.STRAIGHT).with(StairsBlock.HALF, Half.TOP), 10, 34, 17, start);
        structure.setBlockState(world, Blocks.SMOOTH_STONE_SLAB.getDefaultState().with(SlabBlock.TYPE, SlabType.DOUBLE).with(SlabBlock.WATERLOGGED, false), 10, 34, 18, start);
        structure.setBlockState(world, Blocks.COBBLESTONE_SLAB.getDefaultState().with(SlabBlock.TYPE, SlabType.TOP).with(SlabBlock.WATERLOGGED, false), 10, 34, 19, start);
        structure.setBlockState(world, Blocks.SMOOTH_STONE_SLAB.getDefaultState().with(SlabBlock.TYPE, SlabType.BOTTOM).with(SlabBlock.WATERLOGGED, false), 10, 35, 10, start);
        structure.setBlockState(world, Blocks.COBBLESTONE_SLAB.getDefaultState().with(SlabBlock.TYPE, SlabType.TOP).with(SlabBlock.WATERLOGGED, false), 10, 35, 11, start);
        structure.setBlockState(world, Blocks.SMOOTH_STONE_SLAB.getDefaultState().with(SlabBlock.TYPE, SlabType.BOTTOM).with(SlabBlock.WATERLOGGED, false), 10, 36, 12, start);
        structure.setBlockState(world, Blocks.COBBLESTONE_STAIRS.getDefaultState().with(StairsBlock.FACING, Direction.EAST).with(StairsBlock.WATERLOGGED, false).with(StairsBlock.SHAPE, StairsShape.STRAIGHT).with(StairsBlock.HALF, Half.BOTTOM), 10, 36, 13, start);
        structure.setBlockState(world, Blocks.COBBLESTONE_SLAB.getDefaultState().with(SlabBlock.TYPE, SlabType.BOTTOM).with(SlabBlock.WATERLOGGED, false), 10, 36, 14, start);
        structure.setBlockState(world, Blocks.COBBLESTONE_SLAB.getDefaultState().with(SlabBlock.TYPE, SlabType.BOTTOM).with(SlabBlock.WATERLOGGED, false), 10, 36, 17, start);
        structure.setBlockState(world, Blocks.COBBLESTONE_STAIRS.getDefaultState().with(StairsBlock.FACING, Direction.SOUTH).with(StairsBlock.WATERLOGGED, false).with(StairsBlock.SHAPE, StairsShape.STRAIGHT).with(StairsBlock.HALF, Half.BOTTOM), 11, 7, 9, start);
        structure.setBlockState(world, Blocks.CHISELED_STONE_BRICKS.getDefaultState(), 11, 7, 10, start);
        structure.setBlockState(world, Blocks.CHISELED_STONE_BRICKS.getDefaultState(), 11, 7, 21, start);
        structure.setBlockState(world, Blocks.COBBLESTONE_STAIRS.getDefaultState().with(StairsBlock.FACING, Direction.NORTH).with(StairsBlock.WATERLOGGED, false).with(StairsBlock.SHAPE, StairsShape.STRAIGHT).with(StairsBlock.HALF, Half.BOTTOM), 11, 7, 22, start);
        structure.setBlockState(world, Blocks.COBBLESTONE_WALL.getDefaultState().with(WallBlock.WATERLOGGED, false).with(WallBlock.UP, true).with(WallBlock.WALL_HEIGHT_NORTH, WallHeight.LOW).with(WallBlock.WALL_HEIGHT_SOUTH, WallHeight.LOW).with(WallBlock.WALL_HEIGHT_EAST, WallHeight.LOW).with(WallBlock.WALL_HEIGHT_WEST, WallHeight.LOW), 11, 8, 10, start);
        structure.setBlockState(world, Blocks.COBBLESTONE_WALL.getDefaultState().with(WallBlock.WATERLOGGED, false).with(WallBlock.UP, true).with(WallBlock.WALL_HEIGHT_NORTH, WallHeight.LOW).with(WallBlock.WALL_HEIGHT_SOUTH, WallHeight.LOW).with(WallBlock.WALL_HEIGHT_EAST, WallHeight.LOW).with(WallBlock.WALL_HEIGHT_WEST, WallHeight.LOW), 11, 8, 21, start);
        structure.setBlockState(world, Blocks.COBBLESTONE_STAIRS.getDefaultState().with(StairsBlock.FACING, Direction.SOUTH).with(StairsBlock.WATERLOGGED, false).with(StairsBlock.SHAPE, StairsShape.STRAIGHT).with(StairsBlock.HALF, Half.TOP), 11, 9, 10, start);
        structure.setBlockState(world, Blocks.COBBLESTONE_STAIRS.getDefaultState().with(StairsBlock.FACING, Direction.NORTH).with(StairsBlock.WATERLOGGED, false).with(StairsBlock.SHAPE, StairsShape.STRAIGHT).with(StairsBlock.HALF, Half.TOP), 11, 9, 14, start);
        structure.setBlockState(world, Blocks.COBBLESTONE_STAIRS.getDefaultState().with(StairsBlock.FACING, Direction.SOUTH).with(StairsBlock.WATERLOGGED, false).with(StairsBlock.SHAPE, StairsShape.STRAIGHT).with(StairsBlock.HALF, Half.TOP), 11, 9, 17, start);
        structure.setBlockState(world, Blocks.COBBLESTONE_STAIRS.getDefaultState().with(StairsBlock.FACING, Direction.NORTH).with(StairsBlock.WATERLOGGED, false).with(StairsBlock.SHAPE, StairsShape.STRAIGHT).with(StairsBlock.HALF, Half.TOP), 11, 9, 21, start);
        structure.setBlockState(world, Blocks.STONE_BRICKS.getDefaultState(), 11, 10, 21, start);
        structure.setBlockState(world, Blocks.CHISELED_STONE_BRICKS.getDefaultState(), 11, 11, 10, start);
        structure.setBlockState(world, Blocks.COBBLESTONE_STAIRS.getDefaultState().with(StairsBlock.FACING, Direction.NORTH).with(StairsBlock.WATERLOGGED, false).with(StairsBlock.SHAPE, StairsShape.STRAIGHT).with(StairsBlock.HALF, Half.TOP), 11, 11, 15, start);
        structure.setBlockState(world, Blocks.COBBLESTONE_STAIRS.getDefaultState().with(StairsBlock.FACING, Direction.SOUTH).with(StairsBlock.WATERLOGGED, false).with(StairsBlock.SHAPE, StairsShape.STRAIGHT).with(StairsBlock.HALF, Half.TOP), 11, 11, 16, start);
        structure.setBlockState(world, Blocks.CHISELED_STONE_BRICKS.getDefaultState(), 11, 11, 21, start);
        structure.setBlockState(world, Blocks.COBBLESTONE_STAIRS.getDefaultState().with(StairsBlock.FACING, Direction.SOUTH).with(StairsBlock.WATERLOGGED, false).with(StairsBlock.SHAPE, StairsShape.STRAIGHT).with(StairsBlock.HALF, Half.TOP), 11, 13, 9, start);
        structure.setBlockState(world, Blocks.COBBLESTONE_STAIRS.getDefaultState().with(StairsBlock.FACING, Direction.NORTH).with(StairsBlock.WATERLOGGED, false).with(StairsBlock.SHAPE, StairsShape.STRAIGHT).with(StairsBlock.HALF, Half.TOP), 11, 13, 22, start);
        structure.setBlockState(world, Blocks.CHISELED_STONE_BRICKS.getDefaultState(), 11, 14, 9, start);
        structure.setBlockState(world, Blocks.CHISELED_STONE_BRICKS.getDefaultState(), 11, 14, 22, start);
        structure.setBlockState(world, Blocks.COBBLESTONE_SLAB.getDefaultState().with(SlabBlock.TYPE, SlabType.BOTTOM).with(SlabBlock.WATERLOGGED, false), 11, 15, 10, start);
        structure.setBlockState(world, Blocks.SMOOTH_STONE_SLAB.getDefaultState().with(SlabBlock.TYPE, SlabType.DOUBLE).with(SlabBlock.WATERLOGGED, false), 11, 15, 11, start);
        structure.setBlockState(world, Blocks.COBBLESTONE_STAIRS.getDefaultState().with(StairsBlock.FACING, Direction.NORTH).with(StairsBlock.WATERLOGGED, false).with(StairsBlock.SHAPE, StairsShape.STRAIGHT).with(StairsBlock.HALF, Half.TOP), 11, 15, 13, start);
        structure.setBlockState(world, Blocks.STONE_BRICK_STAIRS.getDefaultState().with(StairsBlock.FACING, Direction.SOUTH).with(StairsBlock.WATERLOGGED, false).with(StairsBlock.SHAPE, StairsShape.STRAIGHT).with(StairsBlock.HALF, Half.TOP), 11, 15, 14, start);
        structure.setBlockState(world, Blocks.STONE_BRICK_STAIRS.getDefaultState().with(StairsBlock.FACING, Direction.NORTH).with(StairsBlock.WATERLOGGED, false).with(StairsBlock.SHAPE, StairsShape.STRAIGHT).with(StairsBlock.HALF, Half.TOP), 11, 15, 17, start);
        structure.setBlockState(world, Blocks.COBBLESTONE_STAIRS.getDefaultState().with(StairsBlock.FACING, Direction.SOUTH).with(StairsBlock.WATERLOGGED, false).with(StairsBlock.SHAPE, StairsShape.STRAIGHT).with(StairsBlock.HALF, Half.TOP), 11, 15, 18, start);
        structure.setBlockState(world, Blocks.SMOOTH_STONE_SLAB.getDefaultState().with(SlabBlock.TYPE, SlabType.DOUBLE).with(SlabBlock.WATERLOGGED, false), 11, 15, 20, start);
        structure.setBlockState(world, Blocks.COBBLESTONE_SLAB.getDefaultState().with(SlabBlock.TYPE, SlabType.BOTTOM).with(SlabBlock.WATERLOGGED, false), 11, 15, 21, start);
        structure.setBlockState(world, Blocks.COBBLESTONE_WALL.getDefaultState().with(WallBlock.WATERLOGGED, false).with(WallBlock.UP, true).with(WallBlock.WALL_HEIGHT_NORTH, WallHeight.LOW).with(WallBlock.WALL_HEIGHT_SOUTH, WallHeight.LOW).with(WallBlock.WALL_HEIGHT_EAST, WallHeight.LOW).with(WallBlock.WALL_HEIGHT_WEST, WallHeight.LOW), 11, 16, 11, start);
        structure.setBlockState(world, Blocks.STONE_BRICK_STAIRS.getDefaultState().with(StairsBlock.FACING, Direction.EAST).with(StairsBlock.WATERLOGGED, false).with(StairsBlock.SHAPE, StairsShape.STRAIGHT).with(StairsBlock.HALF, Half.TOP), 11, 16, 12, start);
        structure.setBlockState(world, Blocks.COBBLESTONE_WALL.getDefaultState().with(WallBlock.WATERLOGGED, false).with(WallBlock.UP, true).with(WallBlock.WALL_HEIGHT_NORTH, WallHeight.LOW).with(WallBlock.WALL_HEIGHT_SOUTH, WallHeight.LOW).with(WallBlock.WALL_HEIGHT_EAST, WallHeight.LOW).with(WallBlock.WALL_HEIGHT_WEST, WallHeight.LOW), 11, 16, 13, start);
        structure.setBlockState(world, Blocks.COBBLESTONE_WALL.getDefaultState().with(WallBlock.WATERLOGGED, false).with(WallBlock.UP, true).with(WallBlock.WALL_HEIGHT_NORTH, WallHeight.LOW).with(WallBlock.WALL_HEIGHT_SOUTH, WallHeight.LOW).with(WallBlock.WALL_HEIGHT_EAST, WallHeight.LOW).with(WallBlock.WALL_HEIGHT_WEST, WallHeight.LOW), 11, 16, 18, start);
        structure.setBlockState(world, Blocks.STONE_BRICK_STAIRS.getDefaultState().with(StairsBlock.FACING, Direction.EAST).with(StairsBlock.WATERLOGGED, false).with(StairsBlock.SHAPE, StairsShape.STRAIGHT).with(StairsBlock.HALF, Half.TOP), 11, 16, 19, start);
        structure.setBlockState(world, Blocks.COBBLESTONE_WALL.getDefaultState().with(WallBlock.WATERLOGGED, false).with(WallBlock.UP, true).with(WallBlock.WALL_HEIGHT_NORTH, WallHeight.LOW).with(WallBlock.WALL_HEIGHT_SOUTH, WallHeight.LOW).with(WallBlock.WALL_HEIGHT_EAST, WallHeight.LOW).with(WallBlock.WALL_HEIGHT_WEST, WallHeight.LOW), 11, 16, 20, start);
        structure.setBlockState(world, Blocks.COBBLESTONE_WALL.getDefaultState().with(WallBlock.WATERLOGGED, false).with(WallBlock.UP, true).with(WallBlock.WALL_HEIGHT_NORTH, WallHeight.LOW).with(WallBlock.WALL_HEIGHT_SOUTH, WallHeight.LOW).with(WallBlock.WALL_HEIGHT_EAST, WallHeight.LOW).with(WallBlock.WALL_HEIGHT_WEST, WallHeight.LOW), 11, 17, 12, start);
        structure.setBlockState(world, Blocks.COBBLESTONE_WALL.getDefaultState().with(WallBlock.WATERLOGGED, false).with(WallBlock.UP, true).with(WallBlock.WALL_HEIGHT_NORTH, WallHeight.LOW).with(WallBlock.WALL_HEIGHT_SOUTH, WallHeight.LOW).with(WallBlock.WALL_HEIGHT_EAST, WallHeight.LOW).with(WallBlock.WALL_HEIGHT_WEST, WallHeight.LOW), 11, 17, 13, start);
        structure.setBlockState(world, Blocks.COBBLESTONE_WALL.getDefaultState().with(WallBlock.WATERLOGGED, false).with(WallBlock.UP, true).with(WallBlock.WALL_HEIGHT_NORTH, WallHeight.LOW).with(WallBlock.WALL_HEIGHT_SOUTH, WallHeight.LOW).with(WallBlock.WALL_HEIGHT_EAST, WallHeight.LOW).with(WallBlock.WALL_HEIGHT_WEST, WallHeight.LOW), 11, 17, 18, start);
        structure.setBlockState(world, Blocks.COBBLESTONE_WALL.getDefaultState().with(WallBlock.WATERLOGGED, false).with(WallBlock.UP, true).with(WallBlock.WALL_HEIGHT_NORTH, WallHeight.LOW).with(WallBlock.WALL_HEIGHT_SOUTH, WallHeight.LOW).with(WallBlock.WALL_HEIGHT_EAST, WallHeight.LOW).with(WallBlock.WALL_HEIGHT_WEST, WallHeight.LOW), 11, 17, 19, start);
        structure.setBlockState(world, Blocks.COBBLESTONE_WALL.getDefaultState().with(WallBlock.WATERLOGGED, false).with(WallBlock.UP, true).with(WallBlock.WALL_HEIGHT_NORTH, WallHeight.LOW).with(WallBlock.WALL_HEIGHT_SOUTH, WallHeight.LOW).with(WallBlock.WALL_HEIGHT_EAST, WallHeight.LOW).with(WallBlock.WALL_HEIGHT_WEST, WallHeight.LOW), 11, 18, 13, start);
        structure.setBlockState(world, Blocks.COBBLESTONE_STAIRS.getDefaultState().with(StairsBlock.FACING, Direction.EAST).with(StairsBlock.WATERLOGGED, false).with(StairsBlock.SHAPE, StairsShape.STRAIGHT).with(StairsBlock.HALF, Half.TOP), 11, 18, 14, start);
        structure.setBlockState(world, Blocks.COBBLESTONE_STAIRS.getDefaultState().with(StairsBlock.FACING, Direction.EAST).with(StairsBlock.WATERLOGGED, false).with(StairsBlock.SHAPE, StairsShape.STRAIGHT).with(StairsBlock.HALF, Half.TOP), 11, 18, 17, start);
        structure.setBlockState(world, Blocks.COBBLESTONE_WALL.getDefaultState().with(WallBlock.WATERLOGGED, false).with(WallBlock.UP, true).with(WallBlock.WALL_HEIGHT_NORTH, WallHeight.LOW).with(WallBlock.WALL_HEIGHT_SOUTH, WallHeight.LOW).with(WallBlock.WALL_HEIGHT_EAST, WallHeight.LOW).with(WallBlock.WALL_HEIGHT_WEST, WallHeight.LOW), 11, 18, 18, start);
        structure.setBlockState(world, Blocks.STONE_BRICK_STAIRS.getDefaultState().with(StairsBlock.FACING, Direction.EAST).with(StairsBlock.WATERLOGGED, false).with(StairsBlock.SHAPE, StairsShape.STRAIGHT).with(StairsBlock.HALF, Half.TOP), 11, 19, 13, start);
        structure.setBlockState(world, Blocks.COBBLESTONE_WALL.getDefaultState().with(WallBlock.WATERLOGGED, false).with(WallBlock.UP, true).with(WallBlock.WALL_HEIGHT_NORTH, WallHeight.LOW).with(WallBlock.WALL_HEIGHT_SOUTH, WallHeight.LOW).with(WallBlock.WALL_HEIGHT_EAST, WallHeight.LOW).with(WallBlock.WALL_HEIGHT_WEST, WallHeight.LOW), 11, 19, 14, start);
        structure.setBlockState(world, Blocks.COBBLESTONE_WALL.getDefaultState().with(WallBlock.WATERLOGGED, false).with(WallBlock.UP, true).with(WallBlock.WALL_HEIGHT_NORTH, WallHeight.LOW).with(WallBlock.WALL_HEIGHT_SOUTH, WallHeight.LOW).with(WallBlock.WALL_HEIGHT_EAST, WallHeight.LOW).with(WallBlock.WALL_HEIGHT_WEST, WallHeight.LOW), 11, 19, 17, start);
        structure.setBlockState(world, Blocks.STONE_BRICK_STAIRS.getDefaultState().with(StairsBlock.FACING, Direction.EAST).with(StairsBlock.WATERLOGGED, false).with(StairsBlock.SHAPE, StairsShape.STRAIGHT).with(StairsBlock.HALF, Half.TOP), 11, 19, 18, start);
        structure.setBlockState(world, Blocks.COBBLESTONE_STAIRS.getDefaultState().with(StairsBlock.FACING, Direction.EAST).with(StairsBlock.WATERLOGGED, false).with(StairsBlock.SHAPE, StairsShape.STRAIGHT).with(StairsBlock.HALF, Half.TOP), 11, 20, 12, start);
        structure.setBlockState(world, Blocks.COBBLESTONE_WALL.getDefaultState().with(WallBlock.WATERLOGGED, false).with(WallBlock.UP, true).with(WallBlock.WALL_HEIGHT_NORTH, WallHeight.LOW).with(WallBlock.WALL_HEIGHT_SOUTH, WallHeight.LOW).with(WallBlock.WALL_HEIGHT_EAST, WallHeight.LOW).with(WallBlock.WALL_HEIGHT_WEST, WallHeight.LOW), 11, 20, 14, start);
        structure.setBlockState(world, Blocks.COBBLESTONE_STAIRS.getDefaultState().with(StairsBlock.FACING, Direction.NORTH).with(StairsBlock.WATERLOGGED, false).with(StairsBlock.SHAPE, StairsShape.STRAIGHT).with(StairsBlock.HALF, Half.TOP), 11, 20, 15, start);
        structure.setBlockState(world, Blocks.COBBLESTONE_STAIRS.getDefaultState().with(StairsBlock.FACING, Direction.SOUTH).with(StairsBlock.WATERLOGGED, false).with(StairsBlock.SHAPE, StairsShape.STRAIGHT).with(StairsBlock.HALF, Half.TOP), 11, 20, 16, start);
        structure.setBlockState(world, Blocks.COBBLESTONE_WALL.getDefaultState().with(WallBlock.WATERLOGGED, false).with(WallBlock.UP, true).with(WallBlock.WALL_HEIGHT_NORTH, WallHeight.LOW).with(WallBlock.WALL_HEIGHT_SOUTH, WallHeight.LOW).with(WallBlock.WALL_HEIGHT_EAST, WallHeight.LOW).with(WallBlock.WALL_HEIGHT_WEST, WallHeight.LOW), 11, 20, 17, start);
        structure.setBlockState(world, Blocks.COBBLESTONE_STAIRS.getDefaultState().with(StairsBlock.FACING, Direction.EAST).with(StairsBlock.WATERLOGGED, false).with(StairsBlock.SHAPE, StairsShape.STRAIGHT).with(StairsBlock.HALF, Half.TOP), 11, 20, 19, start);
        structure.setBlockState(world, Blocks.COBBLESTONE_WALL.getDefaultState().with(WallBlock.WATERLOGGED, false).with(WallBlock.UP, true).with(WallBlock.WALL_HEIGHT_NORTH, WallHeight.LOW).with(WallBlock.WALL_HEIGHT_SOUTH, WallHeight.LOW).with(WallBlock.WALL_HEIGHT_EAST, WallHeight.LOW).with(WallBlock.WALL_HEIGHT_WEST, WallHeight.LOW), 11, 21, 12, start);
        structure.setBlockState(world, Blocks.CHISELED_STONE_BRICKS.getDefaultState(), 11, 21, 13, start);
        structure.setBlockState(world, Blocks.COBBLESTONE_STAIRS.getDefaultState().with(StairsBlock.FACING, Direction.NORTH).with(StairsBlock.WATERLOGGED, false).with(StairsBlock.SHAPE, StairsShape.STRAIGHT).with(StairsBlock.HALF, Half.BOTTOM), 11, 21, 15, start);
        structure.setBlockState(world, Blocks.COBBLESTONE_STAIRS.getDefaultState().with(StairsBlock.FACING, Direction.SOUTH).with(StairsBlock.WATERLOGGED, false).with(StairsBlock.SHAPE, StairsShape.STRAIGHT).with(StairsBlock.HALF, Half.BOTTOM), 11, 21, 16, start);
        structure.setBlockState(world, Blocks.COBBLESTONE_WALL.getDefaultState().with(WallBlock.WATERLOGGED, false).with(WallBlock.UP, true).with(WallBlock.WALL_HEIGHT_NORTH, WallHeight.LOW).with(WallBlock.WALL_HEIGHT_SOUTH, WallHeight.LOW).with(WallBlock.WALL_HEIGHT_EAST, WallHeight.LOW).with(WallBlock.WALL_HEIGHT_WEST, WallHeight.LOW), 11, 21, 19, start);
        structure.setBlockState(world, Blocks.STONE_BRICK_STAIRS.getDefaultState().with(StairsBlock.FACING, Direction.EAST).with(StairsBlock.WATERLOGGED, false).with(StairsBlock.SHAPE, StairsShape.STRAIGHT).with(StairsBlock.HALF, Half.TOP), 11, 22, 12, start);
        structure.setBlockState(world, Blocks.STONE_BRICK_STAIRS.getDefaultState().with(StairsBlock.FACING, Direction.EAST).with(StairsBlock.WATERLOGGED, false).with(StairsBlock.SHAPE, StairsShape.STRAIGHT).with(StairsBlock.HALF, Half.TOP), 11, 22, 19, start);
        structure.setBlockState(world, Blocks.COBBLESTONE_WALL.getDefaultState().with(WallBlock.WATERLOGGED, false).with(WallBlock.UP, true).with(WallBlock.WALL_HEIGHT_NORTH, WallHeight.LOW).with(WallBlock.WALL_HEIGHT_SOUTH, WallHeight.LOW).with(WallBlock.WALL_HEIGHT_EAST, WallHeight.LOW).with(WallBlock.WALL_HEIGHT_WEST, WallHeight.LOW), 11, 23, 12, start);
        structure.setBlockState(world, Blocks.COBBLESTONE_STAIRS.getDefaultState().with(StairsBlock.FACING, Direction.NORTH).with(StairsBlock.WATERLOGGED, false).with(StairsBlock.SHAPE, StairsShape.STRAIGHT).with(StairsBlock.HALF, Half.TOP), 11, 23, 15, start);
        structure.setBlockState(world, Blocks.COBBLESTONE_STAIRS.getDefaultState().with(StairsBlock.FACING, Direction.SOUTH).with(StairsBlock.WATERLOGGED, false).with(StairsBlock.SHAPE, StairsShape.STRAIGHT).with(StairsBlock.HALF, Half.TOP), 11, 23, 16, start);
        structure.setBlockState(world, Blocks.COBBLESTONE_WALL.getDefaultState().with(WallBlock.WATERLOGGED, false).with(WallBlock.UP, true).with(WallBlock.WALL_HEIGHT_NORTH, WallHeight.LOW).with(WallBlock.WALL_HEIGHT_SOUTH, WallHeight.LOW).with(WallBlock.WALL_HEIGHT_EAST, WallHeight.LOW).with(WallBlock.WALL_HEIGHT_WEST, WallHeight.LOW), 11, 24, 12, start);
        structure.setBlockState(world, Blocks.CHISELED_STONE_BRICKS.getDefaultState(), 11, 24, 13, start);
        structure.setBlockState(world, Blocks.COBBLESTONE_STAIRS.getDefaultState().with(StairsBlock.FACING, Direction.NORTH).with(StairsBlock.WATERLOGGED, false).with(StairsBlock.SHAPE, StairsShape.STRAIGHT).with(StairsBlock.HALF, Half.BOTTOM), 11, 24, 15, start);
        structure.setBlockState(world, Blocks.COBBLESTONE_STAIRS.getDefaultState().with(StairsBlock.FACING, Direction.SOUTH).with(StairsBlock.WATERLOGGED, false).with(StairsBlock.SHAPE, StairsShape.STRAIGHT).with(StairsBlock.HALF, Half.BOTTOM), 11, 24, 16, start);
        structure.setBlockState(world, Blocks.CHISELED_STONE_BRICKS.getDefaultState(), 11, 24, 18, start);
        structure.setBlockState(world, Blocks.COBBLESTONE_STAIRS.getDefaultState().with(StairsBlock.FACING, Direction.NORTH).with(StairsBlock.WATERLOGGED, false).with(StairsBlock.SHAPE, StairsShape.STRAIGHT).with(StairsBlock.HALF, Half.TOP), 11, 26, 15, start);
        structure.setBlockState(world, Blocks.COBBLESTONE_STAIRS.getDefaultState().with(StairsBlock.FACING, Direction.SOUTH).with(StairsBlock.WATERLOGGED, false).with(StairsBlock.SHAPE, StairsShape.STRAIGHT).with(StairsBlock.HALF, Half.TOP), 11, 26, 16, start);
        structure.setBlockState(world, Blocks.COBBLESTONE_WALL.getDefaultState().with(WallBlock.WATERLOGGED, false).with(WallBlock.UP, true).with(WallBlock.WALL_HEIGHT_NORTH, WallHeight.LOW).with(WallBlock.WALL_HEIGHT_SOUTH, WallHeight.LOW).with(WallBlock.WALL_HEIGHT_EAST, WallHeight.LOW).with(WallBlock.WALL_HEIGHT_WEST, WallHeight.LOW), 11, 26, 19, start);
        structure.setBlockState(world, Blocks.CHISELED_STONE_BRICKS.getDefaultState(), 11, 27, 13, start);
        structure.setBlockState(world, Blocks.COBBLESTONE_STAIRS.getDefaultState().with(StairsBlock.FACING, Direction.NORTH).with(StairsBlock.WATERLOGGED, false).with(StairsBlock.SHAPE, StairsShape.STRAIGHT).with(StairsBlock.HALF, Half.BOTTOM), 11, 27, 15, start);
        structure.setBlockState(world, Blocks.COBBLESTONE_STAIRS.getDefaultState().with(StairsBlock.FACING, Direction.SOUTH).with(StairsBlock.WATERLOGGED, false).with(StairsBlock.SHAPE, StairsShape.STRAIGHT).with(StairsBlock.HALF, Half.BOTTOM), 11, 27, 16, start);
        structure.setBlockState(world, Blocks.CHISELED_STONE_BRICKS.getDefaultState(), 11, 27, 18, start);
        structure.setBlockState(world, Blocks.COBBLESTONE_WALL.getDefaultState().with(WallBlock.WATERLOGGED, false).with(WallBlock.UP, true).with(WallBlock.WALL_HEIGHT_NORTH, WallHeight.LOW).with(WallBlock.WALL_HEIGHT_SOUTH, WallHeight.LOW).with(WallBlock.WALL_HEIGHT_EAST, WallHeight.LOW).with(WallBlock.WALL_HEIGHT_WEST, WallHeight.LOW), 11, 27, 19, start);
        structure.setBlockState(world, Blocks.SMOOTH_STONE_SLAB.getDefaultState().with(SlabBlock.TYPE, SlabType.DOUBLE).with(SlabBlock.WATERLOGGED, false), 11, 28, 12, start);
        structure.setBlockState(world, Blocks.COBBLESTONE_WALL.getDefaultState().with(WallBlock.WATERLOGGED, false).with(WallBlock.UP, true).with(WallBlock.WALL_HEIGHT_NORTH, WallHeight.LOW).with(WallBlock.WALL_HEIGHT_SOUTH, WallHeight.LOW).with(WallBlock.WALL_HEIGHT_EAST, WallHeight.LOW).with(WallBlock.WALL_HEIGHT_WEST, WallHeight.LOW), 11, 29, 12, start);
        structure.setBlockState(world, Blocks.CHISELED_STONE_BRICKS.getDefaultState(), 11, 29, 14, start);
        structure.setBlockState(world, Blocks.COBBLESTONE_STAIRS.getDefaultState().with(StairsBlock.FACING, Direction.NORTH).with(StairsBlock.WATERLOGGED, false).with(StairsBlock.SHAPE, StairsShape.STRAIGHT).with(StairsBlock.HALF, Half.TOP), 11, 29, 15, start);
        structure.setBlockState(world, Blocks.COBBLESTONE_STAIRS.getDefaultState().with(StairsBlock.FACING, Direction.SOUTH).with(StairsBlock.WATERLOGGED, false).with(StairsBlock.SHAPE, StairsShape.STRAIGHT).with(StairsBlock.HALF, Half.TOP), 11, 29, 16, start);
        structure.setBlockState(world, Blocks.CHISELED_STONE_BRICKS.getDefaultState(), 11, 29, 17, start);
        structure.setBlockState(world, Blocks.COBBLESTONE_WALL.getDefaultState().with(WallBlock.WATERLOGGED, false).with(WallBlock.UP, true).with(WallBlock.WALL_HEIGHT_NORTH, WallHeight.LOW).with(WallBlock.WALL_HEIGHT_SOUTH, WallHeight.LOW).with(WallBlock.WALL_HEIGHT_EAST, WallHeight.LOW).with(WallBlock.WALL_HEIGHT_WEST, WallHeight.LOW), 11, 29, 19, start);
        structure.setBlockState(world, Blocks.SMOOTH_STONE_SLAB.getDefaultState().with(SlabBlock.TYPE, SlabType.TOP).with(SlabBlock.WATERLOGGED, false), 11, 30, 11, start);
        structure.setBlockState(world, Blocks.COBBLESTONE_STAIRS.getDefaultState().with(StairsBlock.FACING, Direction.EAST).with(StairsBlock.WATERLOGGED, false).with(StairsBlock.SHAPE, StairsShape.STRAIGHT).with(StairsBlock.HALF, Half.TOP), 11, 30, 12, start);
        structure.setBlockState(world, Blocks.CHISELED_STONE_BRICKS.getDefaultState(), 11, 30, 13, start);
        structure.setBlockState(world, Blocks.CHISELED_STONE_BRICKS.getDefaultState(), 11, 30, 18, start);
        structure.setBlockState(world, Blocks.COBBLESTONE_STAIRS.getDefaultState().with(StairsBlock.FACING, Direction.EAST).with(StairsBlock.WATERLOGGED, false).with(StairsBlock.SHAPE, StairsShape.STRAIGHT).with(StairsBlock.HALF, Half.TOP), 11, 30, 19, start);
        structure.setBlockState(world, Blocks.COBBLESTONE_WALL.getDefaultState().with(WallBlock.WATERLOGGED, false).with(WallBlock.UP, true).with(WallBlock.WALL_HEIGHT_NORTH, WallHeight.LOW).with(WallBlock.WALL_HEIGHT_SOUTH, WallHeight.LOW).with(WallBlock.WALL_HEIGHT_EAST, WallHeight.LOW).with(WallBlock.WALL_HEIGHT_WEST, WallHeight.LOW), 11, 31, 11, start);
        structure.setBlockState(world, Blocks.STONE_BRICKS.getDefaultState(), 11, 31, 12, start);
        structure.setBlockState(world, Blocks.COBBLESTONE_WALL.getDefaultState().with(WallBlock.WATERLOGGED, false).with(WallBlock.UP, true).with(WallBlock.WALL_HEIGHT_NORTH, WallHeight.LOW).with(WallBlock.WALL_HEIGHT_SOUTH, WallHeight.LOW).with(WallBlock.WALL_HEIGHT_EAST, WallHeight.LOW).with(WallBlock.WALL_HEIGHT_WEST, WallHeight.LOW), 11, 31, 13, start);
        structure.setBlockState(world, Blocks.COBBLESTONE_WALL.getDefaultState().with(WallBlock.WATERLOGGED, false).with(WallBlock.UP, true).with(WallBlock.WALL_HEIGHT_NORTH, WallHeight.LOW).with(WallBlock.WALL_HEIGHT_SOUTH, WallHeight.LOW).with(WallBlock.WALL_HEIGHT_EAST, WallHeight.LOW).with(WallBlock.WALL_HEIGHT_WEST, WallHeight.LOW), 11, 31, 20, start);
        structure.setBlockState(world, Blocks.COBBLESTONE_WALL.getDefaultState().with(WallBlock.WATERLOGGED, false).with(WallBlock.UP, true).with(WallBlock.WALL_HEIGHT_NORTH, WallHeight.LOW).with(WallBlock.WALL_HEIGHT_SOUTH, WallHeight.LOW).with(WallBlock.WALL_HEIGHT_EAST, WallHeight.LOW).with(WallBlock.WALL_HEIGHT_WEST, WallHeight.LOW), 11, 32, 11, start);
        structure.setBlockState(world, Blocks.STONE_BRICK_STAIRS.getDefaultState().with(StairsBlock.FACING, Direction.NORTH).with(StairsBlock.WATERLOGGED, false).with(StairsBlock.SHAPE, StairsShape.STRAIGHT).with(StairsBlock.HALF, Half.BOTTOM), 11, 32, 13, start);
        structure.setBlockState(world, Blocks.STONE_BRICK_STAIRS.getDefaultState().with(StairsBlock.FACING, Direction.SOUTH).with(StairsBlock.WATERLOGGED, false).with(StairsBlock.SHAPE, StairsShape.STRAIGHT).with(StairsBlock.HALF, Half.BOTTOM), 11, 32, 18, start);
        structure.setBlockState(world, Blocks.COBBLESTONE_WALL.getDefaultState().with(WallBlock.WATERLOGGED, false).with(WallBlock.UP, true).with(WallBlock.WALL_HEIGHT_NORTH, WallHeight.LOW).with(WallBlock.WALL_HEIGHT_SOUTH, WallHeight.LOW).with(WallBlock.WALL_HEIGHT_EAST, WallHeight.LOW).with(WallBlock.WALL_HEIGHT_WEST, WallHeight.LOW), 11, 32, 20, start);
        structure.setBlockState(world, Blocks.COBBLESTONE_WALL.getDefaultState().with(WallBlock.WATERLOGGED, false).with(WallBlock.UP, true).with(WallBlock.WALL_HEIGHT_NORTH, WallHeight.LOW).with(WallBlock.WALL_HEIGHT_SOUTH, WallHeight.LOW).with(WallBlock.WALL_HEIGHT_EAST, WallHeight.LOW).with(WallBlock.WALL_HEIGHT_WEST, WallHeight.LOW), 11, 33, 11, start);
        structure.setBlockState(world, Blocks.COBBLESTONE_WALL.getDefaultState().with(WallBlock.WATERLOGGED, false).with(WallBlock.UP, true).with(WallBlock.WALL_HEIGHT_NORTH, WallHeight.LOW).with(WallBlock.WALL_HEIGHT_SOUTH, WallHeight.LOW).with(WallBlock.WALL_HEIGHT_EAST, WallHeight.LOW).with(WallBlock.WALL_HEIGHT_WEST, WallHeight.LOW), 11, 33, 20, start);
        structure.setBlockState(world, Blocks.SMOOTH_STONE_SLAB.getDefaultState().with(SlabBlock.TYPE, SlabType.TOP).with(SlabBlock.WATERLOGGED, false), 11, 34, 10, start);
        structure.setBlockState(world, Blocks.COBBLESTONE_WALL.getDefaultState().with(WallBlock.WATERLOGGED, false).with(WallBlock.UP, true).with(WallBlock.WALL_HEIGHT_NORTH, WallHeight.LOW).with(WallBlock.WALL_HEIGHT_SOUTH, WallHeight.LOW).with(WallBlock.WALL_HEIGHT_EAST, WallHeight.LOW).with(WallBlock.WALL_HEIGHT_WEST, WallHeight.LOW), 11, 34, 11, start);
        structure.setBlockState(world, Blocks.STONE_BRICKS.getDefaultState(), 11, 34, 12, start);
        structure.setBlockState(world, Blocks.COBBLESTONE_WALL.getDefaultState().with(WallBlock.WATERLOGGED, false).with(WallBlock.UP, true).with(WallBlock.WALL_HEIGHT_NORTH, WallHeight.LOW).with(WallBlock.WALL_HEIGHT_SOUTH, WallHeight.LOW).with(WallBlock.WALL_HEIGHT_EAST, WallHeight.LOW).with(WallBlock.WALL_HEIGHT_WEST, WallHeight.LOW), 11, 34, 20, start);
        structure.setBlockState(world, Blocks.SMOOTH_STONE_SLAB.getDefaultState().with(SlabBlock.TYPE, SlabType.BOTTOM).with(SlabBlock.WATERLOGGED, false), 11, 35, 9, start);
        structure.setBlockState(world, Blocks.COBBLESTONE_SLAB.getDefaultState().with(SlabBlock.TYPE, SlabType.TOP).with(SlabBlock.WATERLOGGED, false), 11, 35, 10, start);
        structure.setBlockState(world, Blocks.STONE_BRICKS.getDefaultState(), 11, 35, 11, start);
        structure.setBlockState(world, Blocks.GLOWSTONE.getDefaultState(), 11, 35, 12, start);
        structure.setBlockState(world, Blocks.COBBLESTONE_SLAB.getDefaultState().with(SlabBlock.TYPE, SlabType.TOP).with(SlabBlock.WATERLOGGED, false), 11, 35, 21, start);
        structure.setBlockState(world, Blocks.SMOOTH_STONE_SLAB.getDefaultState().with(SlabBlock.TYPE, SlabType.BOTTOM).with(SlabBlock.WATERLOGGED, false), 11, 35, 22, start);
        structure.setBlockState(world, Blocks.SMOOTH_STONE_SLAB.getDefaultState().with(SlabBlock.TYPE, SlabType.BOTTOM).with(SlabBlock.WATERLOGGED, false), 11, 36, 11, start);
        structure.setBlockState(world, Blocks.COBBLESTONE_STAIRS.getDefaultState().with(StairsBlock.FACING, Direction.EAST).with(StairsBlock.WATERLOGGED, false).with(StairsBlock.SHAPE, StairsShape.STRAIGHT).with(StairsBlock.HALF, Half.BOTTOM), 11, 36, 12, start);
        structure.setBlockState(world, Blocks.COBBLESTONE_SLAB.getDefaultState().with(SlabBlock.TYPE, SlabType.TOP).with(SlabBlock.WATERLOGGED, false), 11, 36, 13, start);
        structure.setBlockState(world, Blocks.SMOOTH_STONE_SLAB.getDefaultState().with(SlabBlock.TYPE, SlabType.TOP).with(SlabBlock.WATERLOGGED, false), 11, 36, 14, start);
        structure.setBlockState(world, Blocks.SMOOTH_STONE_SLAB.getDefaultState().with(SlabBlock.TYPE, SlabType.TOP).with(SlabBlock.WATERLOGGED, false), 11, 36, 17, start);
        structure.setBlockState(world, Blocks.COBBLESTONE_STAIRS.getDefaultState().with(StairsBlock.FACING, Direction.EAST).with(StairsBlock.WATERLOGGED, false).with(StairsBlock.SHAPE, StairsShape.STRAIGHT).with(StairsBlock.HALF, Half.BOTTOM), 11, 36, 19, start);
        structure.setBlockState(world, Blocks.STONE_BRICK_STAIRS.getDefaultState().with(StairsBlock.FACING, Direction.EAST).with(StairsBlock.WATERLOGGED, false).with(StairsBlock.SHAPE, StairsShape.STRAIGHT).with(StairsBlock.HALF, Half.BOTTOM), 11, 37, 13, start);
        structure.setBlockState(world, Blocks.COBBLESTONE_WALL.getDefaultState().with(WallBlock.WATERLOGGED, false).with(WallBlock.UP, true).with(WallBlock.WALL_HEIGHT_NORTH, WallHeight.LOW).with(WallBlock.WALL_HEIGHT_SOUTH, WallHeight.LOW).with(WallBlock.WALL_HEIGHT_EAST, WallHeight.LOW).with(WallBlock.WALL_HEIGHT_WEST, WallHeight.LOW), 11, 37, 14, start);
        structure.setBlockState(world, Blocks.COBBLESTONE_WALL.getDefaultState().with(WallBlock.WATERLOGGED, false).with(WallBlock.UP, true).with(WallBlock.WALL_HEIGHT_NORTH, WallHeight.LOW).with(WallBlock.WALL_HEIGHT_SOUTH, WallHeight.LOW).with(WallBlock.WALL_HEIGHT_EAST, WallHeight.LOW).with(WallBlock.WALL_HEIGHT_WEST, WallHeight.LOW), 11, 37, 17, start);
        structure.setBlockState(world, Blocks.STONE_BRICK_STAIRS.getDefaultState().with(StairsBlock.FACING, Direction.EAST).with(StairsBlock.WATERLOGGED, false).with(StairsBlock.SHAPE, StairsShape.STRAIGHT).with(StairsBlock.HALF, Half.BOTTOM), 11, 37, 18, start);
        structure.setBlockState(world, Blocks.COBBLESTONE_WALL.getDefaultState().with(WallBlock.WATERLOGGED, false).with(WallBlock.UP, true).with(WallBlock.WALL_HEIGHT_NORTH, WallHeight.LOW).with(WallBlock.WALL_HEIGHT_SOUTH, WallHeight.LOW).with(WallBlock.WALL_HEIGHT_EAST, WallHeight.LOW).with(WallBlock.WALL_HEIGHT_WEST, WallHeight.LOW), 11, 38, 13, start);
        structure.setBlockState(world, Blocks.SMOOTH_STONE_SLAB.getDefaultState().with(SlabBlock.TYPE, SlabType.BOTTOM).with(SlabBlock.WATERLOGGED, false), 11, 38, 14, start);
        structure.setBlockState(world, Blocks.COBBLESTONE_WALL.getDefaultState().with(WallBlock.WATERLOGGED, false).with(WallBlock.UP, true).with(WallBlock.WALL_HEIGHT_NORTH, WallHeight.LOW).with(WallBlock.WALL_HEIGHT_SOUTH, WallHeight.LOW).with(WallBlock.WALL_HEIGHT_EAST, WallHeight.LOW).with(WallBlock.WALL_HEIGHT_WEST, WallHeight.LOW), 11, 38, 15, start);
        structure.setBlockState(world, Blocks.COBBLESTONE_WALL.getDefaultState().with(WallBlock.WATERLOGGED, false).with(WallBlock.UP, true).with(WallBlock.WALL_HEIGHT_NORTH, WallHeight.LOW).with(WallBlock.WALL_HEIGHT_SOUTH, WallHeight.LOW).with(WallBlock.WALL_HEIGHT_EAST, WallHeight.LOW).with(WallBlock.WALL_HEIGHT_WEST, WallHeight.LOW), 11, 38, 16, start);
        structure.setBlockState(world, Blocks.SMOOTH_STONE_SLAB.getDefaultState().with(SlabBlock.TYPE, SlabType.BOTTOM).with(SlabBlock.WATERLOGGED, false), 11, 38, 17, start);
        structure.setBlockState(world, Blocks.COBBLESTONE_WALL.getDefaultState().with(WallBlock.WATERLOGGED, false).with(WallBlock.UP, true).with(WallBlock.WALL_HEIGHT_NORTH, WallHeight.LOW).with(WallBlock.WALL_HEIGHT_SOUTH, WallHeight.LOW).with(WallBlock.WALL_HEIGHT_EAST, WallHeight.LOW).with(WallBlock.WALL_HEIGHT_WEST, WallHeight.LOW), 11, 38, 18, start);
        structure.setBlockState(world, Blocks.COBBLESTONE_STAIRS.getDefaultState().with(StairsBlock.FACING, Direction.EAST).with(StairsBlock.WATERLOGGED, false).with(StairsBlock.SHAPE, StairsShape.STRAIGHT).with(StairsBlock.HALF, Half.BOTTOM), 11, 39, 13, start);
        structure.setBlockState(world, Blocks.COBBLESTONE_STAIRS.getDefaultState().with(StairsBlock.FACING, Direction.EAST).with(StairsBlock.WATERLOGGED, false).with(StairsBlock.SHAPE, StairsShape.STRAIGHT).with(StairsBlock.HALF, Half.BOTTOM), 11, 39, 18, start);
        structure.setBlockState(world, Blocks.COBBLESTONE_STAIRS.getDefaultState().with(StairsBlock.FACING, Direction.WEST).with(StairsBlock.WATERLOGGED, false).with(StairsBlock.SHAPE, StairsShape.STRAIGHT).with(StairsBlock.HALF, Half.TOP), 12, 7, 10, start);
        structure.setBlockState(world, Blocks.STONE_BRICK_STAIRS.getDefaultState().with(StairsBlock.FACING, Direction.NORTH).with(StairsBlock.WATERLOGGED, false).with(StairsBlock.SHAPE, StairsShape.STRAIGHT).with(StairsBlock.HALF, Half.TOP), 12, 7, 13, start);
        structure.setBlockState(world, Blocks.STONE_BRICK_STAIRS.getDefaultState().with(StairsBlock.FACING, Direction.SOUTH).with(StairsBlock.WATERLOGGED, false).with(StairsBlock.SHAPE, StairsShape.STRAIGHT).with(StairsBlock.HALF, Half.TOP), 12, 7, 18, start);
        structure.setBlockState(world, Blocks.COBBLESTONE_STAIRS.getDefaultState().with(StairsBlock.FACING, Direction.WEST).with(StairsBlock.WATERLOGGED, false).with(StairsBlock.SHAPE, StairsShape.STRAIGHT).with(StairsBlock.HALF, Half.TOP), 12, 7, 21, start);
        structure.setBlockState(world, Blocks.COBBLESTONE_WALL.getDefaultState().with(WallBlock.WATERLOGGED, false).with(WallBlock.UP, true).with(WallBlock.WALL_HEIGHT_NORTH, WallHeight.LOW).with(WallBlock.WALL_HEIGHT_SOUTH, WallHeight.LOW).with(WallBlock.WALL_HEIGHT_EAST, WallHeight.LOW).with(WallBlock.WALL_HEIGHT_WEST, WallHeight.LOW), 12, 8, 10, start);
        structure.setBlockState(world, Blocks.CHISELED_STONE_BRICKS.getDefaultState(), 12, 8, 12, start);
        structure.setBlockState(world, Blocks.COBBLESTONE_WALL.getDefaultState().with(WallBlock.WATERLOGGED, false).with(WallBlock.UP, true).with(WallBlock.WALL_HEIGHT_NORTH, WallHeight.LOW).with(WallBlock.WALL_HEIGHT_SOUTH, WallHeight.LOW).with(WallBlock.WALL_HEIGHT_EAST, WallHeight.LOW).with(WallBlock.WALL_HEIGHT_WEST, WallHeight.LOW), 12, 8, 13, start);
        structure.setBlockState(world, Blocks.CHISELED_STONE_BRICKS.getDefaultState(), 12, 8, 19, start);
        structure.setBlockState(world, Blocks.COBBLESTONE_WALL.getDefaultState().with(WallBlock.WATERLOGGED, false).with(WallBlock.UP, true).with(WallBlock.WALL_HEIGHT_NORTH, WallHeight.LOW).with(WallBlock.WALL_HEIGHT_SOUTH, WallHeight.LOW).with(WallBlock.WALL_HEIGHT_EAST, WallHeight.LOW).with(WallBlock.WALL_HEIGHT_WEST, WallHeight.LOW), 12, 8, 21, start);
        structure.setBlockState(world, Blocks.GLOWSTONE.getDefaultState(), 12, 9, 12, start);
        structure.setBlockState(world, Blocks.GLOWSTONE.getDefaultState(), 12, 9, 19, start);
        structure.setBlockState(world, Blocks.COBBLESTONE_WALL.getDefaultState().with(WallBlock.WATERLOGGED, false).with(WallBlock.UP, true).with(WallBlock.WALL_HEIGHT_NORTH, WallHeight.LOW).with(WallBlock.WALL_HEIGHT_SOUTH, WallHeight.LOW).with(WallBlock.WALL_HEIGHT_EAST, WallHeight.LOW).with(WallBlock.WALL_HEIGHT_WEST, WallHeight.LOW), 12, 10, 12, start);
        structure.setBlockState(world, Blocks.COBBLESTONE_WALL.getDefaultState().with(WallBlock.WATERLOGGED, false).with(WallBlock.UP, true).with(WallBlock.WALL_HEIGHT_NORTH, WallHeight.LOW).with(WallBlock.WALL_HEIGHT_SOUTH, WallHeight.LOW).with(WallBlock.WALL_HEIGHT_EAST, WallHeight.LOW).with(WallBlock.WALL_HEIGHT_WEST, WallHeight.LOW), 12, 10, 19, start);
        structure.setBlockState(world, Blocks.COBBLESTONE_WALL.getDefaultState().with(WallBlock.WATERLOGGED, false).with(WallBlock.UP, true).with(WallBlock.WALL_HEIGHT_NORTH, WallHeight.LOW).with(WallBlock.WALL_HEIGHT_SOUTH, WallHeight.LOW).with(WallBlock.WALL_HEIGHT_EAST, WallHeight.LOW).with(WallBlock.WALL_HEIGHT_WEST, WallHeight.LOW), 12, 11, 10, start);
        structure.setBlockState(world, Blocks.COBBLESTONE_WALL.getDefaultState().with(WallBlock.WATERLOGGED, false).with(WallBlock.UP, true).with(WallBlock.WALL_HEIGHT_NORTH, WallHeight.LOW).with(WallBlock.WALL_HEIGHT_SOUTH, WallHeight.LOW).with(WallBlock.WALL_HEIGHT_EAST, WallHeight.LOW).with(WallBlock.WALL_HEIGHT_WEST, WallHeight.LOW), 12, 11, 12, start);
        structure.setBlockState(world, Blocks.COBBLESTONE_WALL.getDefaultState().with(WallBlock.WATERLOGGED, false).with(WallBlock.UP, true).with(WallBlock.WALL_HEIGHT_NORTH, WallHeight.LOW).with(WallBlock.WALL_HEIGHT_SOUTH, WallHeight.LOW).with(WallBlock.WALL_HEIGHT_EAST, WallHeight.LOW).with(WallBlock.WALL_HEIGHT_WEST, WallHeight.LOW), 12, 11, 19, start);
        structure.setBlockState(world, Blocks.COBBLESTONE_WALL.getDefaultState().with(WallBlock.WATERLOGGED, false).with(WallBlock.UP, true).with(WallBlock.WALL_HEIGHT_NORTH, WallHeight.LOW).with(WallBlock.WALL_HEIGHT_SOUTH, WallHeight.LOW).with(WallBlock.WALL_HEIGHT_EAST, WallHeight.LOW).with(WallBlock.WALL_HEIGHT_WEST, WallHeight.LOW), 12, 11, 21, start);
        structure.setBlockState(world, Blocks.CHISELED_STONE_BRICKS.getDefaultState(), 12, 12, 10, start);
        structure.setBlockState(world, Blocks.COBBLESTONE_WALL.getDefaultState().with(WallBlock.WATERLOGGED, false).with(WallBlock.UP, true).with(WallBlock.WALL_HEIGHT_NORTH, WallHeight.LOW).with(WallBlock.WALL_HEIGHT_SOUTH, WallHeight.LOW).with(WallBlock.WALL_HEIGHT_EAST, WallHeight.LOW).with(WallBlock.WALL_HEIGHT_WEST, WallHeight.LOW), 12, 12, 15, start);
        structure.setBlockState(world, Blocks.COBBLESTONE_WALL.getDefaultState().with(WallBlock.WATERLOGGED, false).with(WallBlock.UP, true).with(WallBlock.WALL_HEIGHT_NORTH, WallHeight.LOW).with(WallBlock.WALL_HEIGHT_SOUTH, WallHeight.LOW).with(WallBlock.WALL_HEIGHT_EAST, WallHeight.LOW).with(WallBlock.WALL_HEIGHT_WEST, WallHeight.LOW), 12, 12, 16, start);
        structure.setBlockState(world, Blocks.CHISELED_STONE_BRICKS.getDefaultState(), 12, 12, 21, start);
        structure.setBlockState(world, Blocks.COBBLESTONE_WALL.getDefaultState().with(WallBlock.WATERLOGGED, false).with(WallBlock.UP, true).with(WallBlock.WALL_HEIGHT_NORTH, WallHeight.LOW).with(WallBlock.WALL_HEIGHT_SOUTH, WallHeight.LOW).with(WallBlock.WALL_HEIGHT_EAST, WallHeight.LOW).with(WallBlock.WALL_HEIGHT_WEST, WallHeight.LOW), 12, 13, 10, start);
        structure.setBlockState(world, Blocks.COBBLESTONE_WALL.getDefaultState().with(WallBlock.WATERLOGGED, false).with(WallBlock.UP, true).with(WallBlock.WALL_HEIGHT_NORTH, WallHeight.LOW).with(WallBlock.WALL_HEIGHT_SOUTH, WallHeight.LOW).with(WallBlock.WALL_HEIGHT_EAST, WallHeight.LOW).with(WallBlock.WALL_HEIGHT_WEST, WallHeight.LOW), 12, 13, 21, start);
        structure.setBlockState(world, Blocks.COBBLESTONE_STAIRS.getDefaultState().with(StairsBlock.FACING, Direction.WEST).with(StairsBlock.WATERLOGGED, false).with(StairsBlock.SHAPE, StairsShape.STRAIGHT).with(StairsBlock.HALF, Half.TOP), 12, 14, 9, start);
        structure.setBlockState(world, Blocks.GLOWSTONE.getDefaultState(), 12, 14, 10, start);
        structure.setBlockState(world, Blocks.GLOWSTONE.getDefaultState(), 12, 14, 21, start);
        structure.setBlockState(world, Blocks.COBBLESTONE_STAIRS.getDefaultState().with(StairsBlock.FACING, Direction.WEST).with(StairsBlock.WATERLOGGED, false).with(StairsBlock.SHAPE, StairsShape.STRAIGHT).with(StairsBlock.HALF, Half.TOP), 12, 14, 22, start);
        structure.setBlockState(world, Blocks.COBBLESTONE_WALL.getDefaultState().with(WallBlock.WATERLOGGED, false).with(WallBlock.UP, true).with(WallBlock.WALL_HEIGHT_NORTH, WallHeight.LOW).with(WallBlock.WALL_HEIGHT_SOUTH, WallHeight.LOW).with(WallBlock.WALL_HEIGHT_EAST, WallHeight.LOW).with(WallBlock.WALL_HEIGHT_WEST, WallHeight.LOW), 12, 15, 10, start);
        structure.setBlockState(world, Blocks.COBBLESTONE_WALL.getDefaultState().with(WallBlock.WATERLOGGED, false).with(WallBlock.UP, true).with(WallBlock.WALL_HEIGHT_NORTH, WallHeight.LOW).with(WallBlock.WALL_HEIGHT_SOUTH, WallHeight.LOW).with(WallBlock.WALL_HEIGHT_EAST, WallHeight.LOW).with(WallBlock.WALL_HEIGHT_WEST, WallHeight.LOW), 12, 15, 21, start);
        structure.setBlockState(world, Blocks.STONE_BRICK_STAIRS.getDefaultState().with(StairsBlock.FACING, Direction.SOUTH).with(StairsBlock.WATERLOGGED, false).with(StairsBlock.SHAPE, StairsShape.STRAIGHT).with(StairsBlock.HALF, Half.TOP), 12, 16, 11, start);
        structure.setBlockState(world, Blocks.COBBLESTONE_WALL.getDefaultState().with(WallBlock.WATERLOGGED, false).with(WallBlock.UP, true).with(WallBlock.WALL_HEIGHT_NORTH, WallHeight.LOW).with(WallBlock.WALL_HEIGHT_SOUTH, WallHeight.LOW).with(WallBlock.WALL_HEIGHT_EAST, WallHeight.LOW).with(WallBlock.WALL_HEIGHT_WEST, WallHeight.LOW), 12, 16, 14, start);
        structure.setBlockState(world, Blocks.STONE_BRICK_STAIRS.getDefaultState().with(StairsBlock.FACING, Direction.NORTH).with(StairsBlock.WATERLOGGED, false).with(StairsBlock.SHAPE, StairsShape.STRAIGHT).with(StairsBlock.HALF, Half.TOP), 12, 16, 20, start);
        structure.setBlockState(world, Blocks.COBBLESTONE_WALL.getDefaultState().with(WallBlock.WATERLOGGED, false).with(WallBlock.UP, true).with(WallBlock.WALL_HEIGHT_NORTH, WallHeight.LOW).with(WallBlock.WALL_HEIGHT_SOUTH, WallHeight.LOW).with(WallBlock.WALL_HEIGHT_EAST, WallHeight.LOW).with(WallBlock.WALL_HEIGHT_WEST, WallHeight.LOW), 12, 17, 11, start);
        structure.setBlockState(world, Blocks.COBBLESTONE_WALL.getDefaultState().with(WallBlock.WATERLOGGED, false).with(WallBlock.UP, true).with(WallBlock.WALL_HEIGHT_NORTH, WallHeight.LOW).with(WallBlock.WALL_HEIGHT_SOUTH, WallHeight.LOW).with(WallBlock.WALL_HEIGHT_EAST, WallHeight.LOW).with(WallBlock.WALL_HEIGHT_WEST, WallHeight.LOW), 12, 17, 14, start);
        structure.setBlockState(world, Blocks.COBBLESTONE_WALL.getDefaultState().with(WallBlock.WATERLOGGED, false).with(WallBlock.UP, true).with(WallBlock.WALL_HEIGHT_NORTH, WallHeight.LOW).with(WallBlock.WALL_HEIGHT_SOUTH, WallHeight.LOW).with(WallBlock.WALL_HEIGHT_EAST, WallHeight.LOW).with(WallBlock.WALL_HEIGHT_WEST, WallHeight.LOW), 12, 17, 20, start);
        structure.setBlockState(world, Blocks.CHISELED_STONE_BRICKS.getDefaultState(), 12, 18, 14, start);
        structure.setBlockState(world, Blocks.CHISELED_STONE_BRICKS.getDefaultState(), 12, 18, 17, start);
        structure.setBlockState(world, Blocks.SMOOTH_STONE_SLAB.getDefaultState().with(SlabBlock.TYPE, SlabType.DOUBLE).with(SlabBlock.WATERLOGGED, false), 12, 19, 12, start);
        structure.setBlockState(world, Blocks.SMOOTH_STONE_SLAB.getDefaultState().with(SlabBlock.TYPE, SlabType.DOUBLE).with(SlabBlock.WATERLOGGED, false), 12, 19, 19, start);
        structure.setBlockState(world, Blocks.COBBLESTONE_STAIRS.getDefaultState().with(StairsBlock.FACING, Direction.SOUTH).with(StairsBlock.WATERLOGGED, false).with(StairsBlock.SHAPE, StairsShape.STRAIGHT).with(StairsBlock.HALF, Half.TOP), 12, 20, 11, start);
        structure.setBlockState(world, Blocks.COBBLESTONE_WALL.getDefaultState().with(WallBlock.WATERLOGGED, false).with(WallBlock.UP, true).with(WallBlock.WALL_HEIGHT_NORTH, WallHeight.LOW).with(WallBlock.WALL_HEIGHT_SOUTH, WallHeight.LOW).with(WallBlock.WALL_HEIGHT_EAST, WallHeight.LOW).with(WallBlock.WALL_HEIGHT_WEST, WallHeight.LOW), 12, 20, 12, start);
        structure.setBlockState(world, Blocks.COBBLESTONE_WALL.getDefaultState().with(WallBlock.WATERLOGGED, false).with(WallBlock.UP, false).with(WallBlock.WALL_HEIGHT_NORTH, WallHeight.LOW).with(WallBlock.WALL_HEIGHT_SOUTH, WallHeight.LOW).with(WallBlock.WALL_HEIGHT_EAST, WallHeight.LOW).with(WallBlock.WALL_HEIGHT_WEST, WallHeight.LOW), 12, 20, 19, start);
        structure.setBlockState(world, Blocks.COBBLESTONE_STAIRS.getDefaultState().with(StairsBlock.FACING, Direction.NORTH).with(StairsBlock.WATERLOGGED, false).with(StairsBlock.SHAPE, StairsShape.STRAIGHT).with(StairsBlock.HALF, Half.TOP), 12, 20, 20, start);
        structure.setBlockState(world, Blocks.COBBLESTONE_WALL.getDefaultState().with(WallBlock.WATERLOGGED, false).with(WallBlock.UP, true).with(WallBlock.WALL_HEIGHT_NORTH, WallHeight.LOW).with(WallBlock.WALL_HEIGHT_SOUTH, WallHeight.LOW).with(WallBlock.WALL_HEIGHT_EAST, WallHeight.LOW).with(WallBlock.WALL_HEIGHT_WEST, WallHeight.LOW), 12, 21, 11, start);
        structure.setBlockState(world, Blocks.CHISELED_STONE_BRICKS.getDefaultState(), 12, 21, 12, start);
        structure.setBlockState(world, Blocks.COBBLESTONE_WALL.getDefaultState().with(WallBlock.WATERLOGGED, false).with(WallBlock.UP, true).with(WallBlock.WALL_HEIGHT_NORTH, WallHeight.LOW).with(WallBlock.WALL_HEIGHT_SOUTH, WallHeight.LOW).with(WallBlock.WALL_HEIGHT_EAST, WallHeight.LOW).with(WallBlock.WALL_HEIGHT_WEST, WallHeight.LOW), 12, 21, 20, start);
        structure.setBlockState(world, Blocks.STONE_BRICK_STAIRS.getDefaultState().with(StairsBlock.FACING, Direction.SOUTH).with(StairsBlock.WATERLOGGED, false).with(StairsBlock.SHAPE, StairsShape.STRAIGHT).with(StairsBlock.HALF, Half.TOP), 12, 22, 11, start);
        structure.setBlockState(world, Blocks.STONE_BRICK_STAIRS.getDefaultState().with(StairsBlock.FACING, Direction.NORTH).with(StairsBlock.WATERLOGGED, false).with(StairsBlock.SHAPE, StairsShape.STRAIGHT).with(StairsBlock.HALF, Half.TOP), 12, 22, 20, start);
        structure.setBlockState(world, Blocks.COBBLESTONE_WALL.getDefaultState().with(WallBlock.WATERLOGGED, false).with(WallBlock.UP, true).with(WallBlock.WALL_HEIGHT_NORTH, WallHeight.LOW).with(WallBlock.WALL_HEIGHT_SOUTH, WallHeight.LOW).with(WallBlock.WALL_HEIGHT_EAST, WallHeight.LOW).with(WallBlock.WALL_HEIGHT_WEST, WallHeight.LOW), 12, 23, 11, start);
        structure.setBlockState(world, Blocks.COBBLESTONE_WALL.getDefaultState().with(WallBlock.WATERLOGGED, false).with(WallBlock.UP, true).with(WallBlock.WALL_HEIGHT_NORTH, WallHeight.LOW).with(WallBlock.WALL_HEIGHT_SOUTH, WallHeight.LOW).with(WallBlock.WALL_HEIGHT_EAST, WallHeight.LOW).with(WallBlock.WALL_HEIGHT_WEST, WallHeight.LOW), 12, 24, 11, start);
        structure.setBlockState(world, Blocks.COBBLESTONE_WALL.getDefaultState().with(WallBlock.WATERLOGGED, false).with(WallBlock.UP, true).with(WallBlock.WALL_HEIGHT_NORTH, WallHeight.LOW).with(WallBlock.WALL_HEIGHT_SOUTH, WallHeight.LOW).with(WallBlock.WALL_HEIGHT_EAST, WallHeight.LOW).with(WallBlock.WALL_HEIGHT_WEST, WallHeight.LOW), 12, 25, 11, start);
        structure.setBlockState(world, Blocks.COBBLESTONE_WALL.getDefaultState().with(WallBlock.WATERLOGGED, false).with(WallBlock.UP, true).with(WallBlock.WALL_HEIGHT_NORTH, WallHeight.LOW).with(WallBlock.WALL_HEIGHT_SOUTH, WallHeight.LOW).with(WallBlock.WALL_HEIGHT_EAST, WallHeight.LOW).with(WallBlock.WALL_HEIGHT_WEST, WallHeight.LOW), 12, 25, 20, start);
        structure.setBlockState(world, Blocks.COBBLESTONE_WALL.getDefaultState().with(WallBlock.WATERLOGGED, false).with(WallBlock.UP, true).with(WallBlock.WALL_HEIGHT_NORTH, WallHeight.LOW).with(WallBlock.WALL_HEIGHT_SOUTH, WallHeight.LOW).with(WallBlock.WALL_HEIGHT_EAST, WallHeight.LOW).with(WallBlock.WALL_HEIGHT_WEST, WallHeight.LOW), 12, 26, 11, start);
        structure.setBlockState(world, Blocks.COBBLESTONE_WALL.getDefaultState().with(WallBlock.WATERLOGGED, false).with(WallBlock.UP, true).with(WallBlock.WALL_HEIGHT_NORTH, WallHeight.LOW).with(WallBlock.WALL_HEIGHT_SOUTH, WallHeight.LOW).with(WallBlock.WALL_HEIGHT_EAST, WallHeight.LOW).with(WallBlock.WALL_HEIGHT_WEST, WallHeight.LOW), 12, 26, 20, start);
        structure.setBlockState(world, Blocks.COBBLESTONE_WALL.getDefaultState().with(WallBlock.WATERLOGGED, false).with(WallBlock.UP, true).with(WallBlock.WALL_HEIGHT_NORTH, WallHeight.LOW).with(WallBlock.WALL_HEIGHT_SOUTH, WallHeight.LOW).with(WallBlock.WALL_HEIGHT_EAST, WallHeight.LOW).with(WallBlock.WALL_HEIGHT_WEST, WallHeight.LOW), 12, 27, 11, start);
        structure.setBlockState(world, Blocks.COBBLESTONE_WALL.getDefaultState().with(WallBlock.WATERLOGGED, false).with(WallBlock.UP, true).with(WallBlock.WALL_HEIGHT_NORTH, WallHeight.LOW).with(WallBlock.WALL_HEIGHT_SOUTH, WallHeight.LOW).with(WallBlock.WALL_HEIGHT_EAST, WallHeight.LOW).with(WallBlock.WALL_HEIGHT_WEST, WallHeight.LOW), 12, 27, 20, start);
        structure.setBlockState(world, Blocks.SMOOTH_STONE_SLAB.getDefaultState().with(SlabBlock.TYPE, SlabType.DOUBLE).with(SlabBlock.WATERLOGGED, false), 12, 28, 11, start);
        structure.setBlockState(world, Blocks.SMOOTH_STONE_SLAB.getDefaultState().with(SlabBlock.TYPE, SlabType.DOUBLE).with(SlabBlock.WATERLOGGED, false), 12, 28, 20, start);
        structure.setBlockState(world, Blocks.COBBLESTONE_WALL.getDefaultState().with(WallBlock.WATERLOGGED, false).with(WallBlock.UP, true).with(WallBlock.WALL_HEIGHT_NORTH, WallHeight.LOW).with(WallBlock.WALL_HEIGHT_SOUTH, WallHeight.LOW).with(WallBlock.WALL_HEIGHT_EAST, WallHeight.LOW).with(WallBlock.WALL_HEIGHT_WEST, WallHeight.LOW), 12, 29, 11, start);
        structure.setBlockState(world, Blocks.CHISELED_STONE_BRICKS.getDefaultState(), 12, 29, 12, start);
        structure.setBlockState(world, Blocks.CHISELED_STONE_BRICKS.getDefaultState(), 12, 29, 19, start);
        structure.setBlockState(world, Blocks.COBBLESTONE_WALL.getDefaultState().with(WallBlock.WATERLOGGED, false).with(WallBlock.UP, true).with(WallBlock.WALL_HEIGHT_NORTH, WallHeight.LOW).with(WallBlock.WALL_HEIGHT_SOUTH, WallHeight.LOW).with(WallBlock.WALL_HEIGHT_EAST, WallHeight.LOW).with(WallBlock.WALL_HEIGHT_WEST, WallHeight.LOW), 12, 29, 20, start);
        structure.setBlockState(world, Blocks.COBBLESTONE_STAIRS.getDefaultState().with(StairsBlock.FACING, Direction.SOUTH).with(StairsBlock.WATERLOGGED, false).with(StairsBlock.SHAPE, StairsShape.STRAIGHT).with(StairsBlock.HALF, Half.TOP), 12, 30, 11, start);
        structure.setBlockState(world, Blocks.COBBLESTONE_STAIRS.getDefaultState().with(StairsBlock.FACING, Direction.NORTH).with(StairsBlock.WATERLOGGED, false).with(StairsBlock.SHAPE, StairsShape.STRAIGHT).with(StairsBlock.HALF, Half.TOP), 12, 30, 20, start);
        structure.setBlockState(world, Blocks.COBBLESTONE_STAIRS.getDefaultState().with(StairsBlock.FACING, Direction.SOUTH).with(StairsBlock.WATERLOGGED, false).with(StairsBlock.SHAPE, StairsShape.STRAIGHT).with(StairsBlock.HALF, Half.TOP), 12, 31, 10, start);
        structure.setBlockState(world, Blocks.STONE_BRICKS.getDefaultState(), 12, 31, 11, start);
        structure.setBlockState(world, Blocks.COBBLESTONE_WALL.getDefaultState().with(WallBlock.WATERLOGGED, false).with(WallBlock.UP, true).with(WallBlock.WALL_HEIGHT_NORTH, WallHeight.LOW).with(WallBlock.WALL_HEIGHT_SOUTH, WallHeight.LOW).with(WallBlock.WALL_HEIGHT_EAST, WallHeight.LOW).with(WallBlock.WALL_HEIGHT_WEST, WallHeight.LOW), 12, 31, 12, start);
        structure.setBlockState(world, Blocks.STONE_BRICKS.getDefaultState(), 12, 31, 20, start);
        structure.setBlockState(world, Blocks.COBBLESTONE_STAIRS.getDefaultState().with(StairsBlock.FACING, Direction.NORTH).with(StairsBlock.WATERLOGGED, false).with(StairsBlock.SHAPE, StairsShape.STRAIGHT).with(StairsBlock.HALF, Half.TOP), 12, 31, 21, start);
        structure.setBlockState(world, Blocks.COBBLESTONE_WALL.getDefaultState().with(WallBlock.WATERLOGGED, false).with(WallBlock.UP, true).with(WallBlock.WALL_HEIGHT_NORTH, WallHeight.LOW).with(WallBlock.WALL_HEIGHT_SOUTH, WallHeight.LOW).with(WallBlock.WALL_HEIGHT_EAST, WallHeight.LOW).with(WallBlock.WALL_HEIGHT_WEST, WallHeight.LOW), 12, 32, 10, start);
        structure.setBlockState(world, Blocks.COBBLESTONE_WALL.getDefaultState().with(WallBlock.WATERLOGGED, false).with(WallBlock.UP, true).with(WallBlock.WALL_HEIGHT_NORTH, WallHeight.LOW).with(WallBlock.WALL_HEIGHT_SOUTH, WallHeight.LOW).with(WallBlock.WALL_HEIGHT_EAST, WallHeight.LOW).with(WallBlock.WALL_HEIGHT_WEST, WallHeight.LOW), 12, 32, 12, start);
