package mod.arcalitegames.odyssey.world.structure.structures.dungeons.mayan_pyramid;

import mod.arcalitegames.odyssey.world.structure.StructureBase;
import net.minecraft.block.Blocks;
import net.minecraft.block.SnowyDirtBlock;
import net.minecraft.block.StairsBlock;
import net.minecraft.block.WallBlock;
import net.minecraft.block.WallHeight;
import net.minecraft.state.properties.Half;
import net.minecraft.state.properties.StairsShape;
import net.minecraft.util.Direction;
import net.minecraft.util.math.BlockPos;
import net.minecraft.world.World;

public class PyramidComponent7
{
	public static BlockPos start;
    public static World world;
    public static StructureBase structure;

    public static void init(World worldIn, BlockPos blockPos, StructureBase structureIn)
    {
        world = worldIn; start = blockPos; structure = structureIn;
    }
    
    public static void generatePart71()
    {
        structure.fillWithBlocks(world, start, 70, -54, 8, 70, -54, 11, Blocks.AIR.getDefaultState());
        structure.fillWithBlocks(world, start, 70, -54, 14, 71, -54, 15, Blocks.AIR.getDefaultState());
        structure.fillWithBlocks(world, start, 70, -54, 16, 70, -54, 19, Blocks.AIR.getDefaultState());
        structure.fillWithBlocks(world, start, 70, -54, 24, 71, -54, 50, Blocks.AIR.getDefaultState());
        structure.fillWithBlocks(world, start, 70, -54, 52, 71, -54, 72, Blocks.AIR.getDefaultState());
        structure.fillWithBlocks(world, start, 70, -54, 74, 71, -54, 78, Blocks.AIR.getDefaultState());
        structure.fillWithBlocks(world, start, 70, -54, 80, 72, -54, 82, Blocks.AIR.getDefaultState());
        structure.fillWithBlocks(world, start, 70, -53, -58, 72, -53, -56, Blocks.STONE_BRICKS.getDefaultState());
        structure.fillWithBlocks(world, start, 70, -53, 8, 70, -53, 11, Blocks.AIR.getDefaultState());
        structure.fillWithBlocks(world, start, 70, -53, 16, 70, -53, 82, Blocks.AIR.getDefaultState());
        structure.fillWithBlocks(world, start, 70, -53, 84, 71, -53, 85, Blocks.STONE_BRICKS.getDefaultState());
        structure.fillWithBlocks(world, start, 70, -52, 9, 71, -52, 10, Blocks.AIR.getDefaultState());
        structure.fillWithBlocks(world, start, 70, -52, 83, 72, -52, 85, Blocks.STONE_BRICKS.getDefaultState());
        structure.fillWithBlocks(world, start, 70, -51, -13, 75, -51, -8, Blocks.STONE_BRICKS.getDefaultState());
        structure.fillWithBlocks(world, start, 70, -51, 9, 71, -51, 10, Blocks.AIR.getDefaultState());
        structure.fillWithBlocks(world, start, 70, -51, 13, 72, -51, 15, Blocks.AIR.getDefaultState());
        structure.fillWithBlocks(world, start, 70, -51, 21, 70, -51, 21, Blocks.AIR.getDefaultState());
        structure.fillWithBlocks(world, start, 70, -51, 22, 70, -51, 22, Blocks.STONE_BRICKS.getDefaultState());
        structure.fillWithBlocks(world, start, 70, -51, 24, 72, -51, 41, Blocks.STONE_BRICKS.getDefaultState());
        structure.fillWithBlocks(world, start, 70, -51, 63, 71, -51, 63, Blocks.AIR.getDefaultState());
        structure.fillWithBlocks(world, start, 70, -51, 64, 72, -51, 75, Blocks.STONE_BRICKS.getDefaultState());
        structure.fillWithBlocks(world, start, 70, -51, 83, 71, -51, 84, Blocks.STONE_BRICKS.getDefaultState());
        structure.fillWithBlocks(world, start, 70, -51, 85, 70, -46, 85, Blocks.STONE_BRICKS.getDefaultState());
        structure.fillWithBlocks(world, start, 70, -50, -57, 71, -50, -56, Blocks.STONE_BRICKS.getDefaultState());
        structure.fillWithBlocks(world, start, 70, -50, -40, 72, -50, -38, Blocks.STONE_BRICKS.getDefaultState());
        structure.fillWithBlocks(world, start, 70, -50, -18, 75, -50, -12, Blocks.STONE_BRICKS.getDefaultState());
        structure.fillWithBlocks(world, start, 70, -50, 14, 71, -50, 15, Blocks.AIR.getDefaultState());
        structure.fillWithBlocks(world, start, 70, -50, 42, 70, -50, 42, Blocks.STONE_BRICKS.getDefaultState());
        structure.fillWithBlocks(world, start, 70, -50, 44, 72, -50, 46, Blocks.STONE_BRICKS.getDefaultState());
        structure.fillWithBlocks(world, start, 70, -50, 48, 72, -50, 50, Blocks.STONE_BRICKS.getDefaultState());
        structure.fillWithBlocks(world, start, 70, -50, 52, 72, -50, 54, Blocks.STONE_BRICKS.getDefaultState());
        structure.fillWithBlocks(world, start, 70, -50, 56, 72, -50, 58, Blocks.STONE_BRICKS.getDefaultState());
        structure.fillWithBlocks(world, start, 70, -50, 60, 71, -50, 61, Blocks.STONE_BRICKS.getDefaultState());
        structure.fillWithBlocks(world, start, 70, -50, 73, 70, -50, 78, Blocks.STONE_BRICKS.getDefaultState());
        structure.fillWithBlocks(world, start, 70, -50, 80, 75, -50, 85, Blocks.STONE_BRICKS.getDefaultState());
        structure.fillWithBlocks(world, start, 70, -49, -54, 72, -49, -52, Blocks.STONE_BRICKS.getDefaultState());
        structure.fillWithBlocks(world, start, 70, -49, 47, 72, -49, 50, Blocks.STONE_BRICKS.getDefaultState());
        structure.fillWithBlocks(world, start, 70, -49, 58, 73, -49, 61, Blocks.STONE_BRICKS.getDefaultState());
        structure.fillWithBlocks(world, start, 70, -49, 77, 73, -49, 83, Blocks.STONE_BRICKS.getDefaultState());
        structure.fillWithBlocks(world, start, 70, -48, -58, 72, -48, -55, Blocks.STONE_BRICKS.getDefaultState());
        structure.fillWithBlocks(world, start, 70, -48, -39, 70, -48, -38, Blocks.STONE_BRICKS.getDefaultState());
        structure.fillWithBlocks(world, start, 70, -48, -12, 74, -48, -8, Blocks.STONE_BRICKS.getDefaultState());
        structure.fillWithBlocks(world, start, 70, -48, 9, 71, -48, 10, Blocks.AIR.getDefaultState());
        structure.fillWithBlocks(world, start, 70, -48, 42, 72, -48, 44, Blocks.STONE_BRICKS.getDefaultState());
        structure.fillWithBlocks(world, start, 70, -48, 46, 73, -48, 51, Blocks.STONE_BRICKS.getDefaultState());
        structure.fillWithBlocks(world, start, 70, -48, 60, 70, -48, 60, Blocks.MOSSY_COBBLESTONE.getDefaultState());
        structure.fillWithBlocks(world, start, 70, -48, 61, 70, -46, 61, Blocks.AIR.getDefaultState());
        structure.fillWithBlocks(world, start, 70, -47, -16, 70, -47, -16, Blocks.STONE_BRICKS.getDefaultState());
        structure.fillWithBlocks(world, start, 70, -47, -14, 76, -47, -8, Blocks.STONE_BRICKS.getDefaultState());
        structure.fillWithBlocks(world, start, 70, -47, 9, 71, -47, 10, Blocks.AIR.getDefaultState());
        structure.fillWithBlocks(world, start, 70, -47, 13, 72, -47, 15, Blocks.AIR.getDefaultState());
        structure.fillWithBlocks(world, start, 70, -47, 42, 70, -47, 53, Blocks.STONE_BRICKS.getDefaultState());
        structure.fillWithBlocks(world, start, 70, -47, 54, 70, -47, 57, Blocks.AIR.getDefaultState());
        structure.fillWithBlocks(world, start, 70, -47, 73, 71, -47, 85, Blocks.STONE_BRICKS.getDefaultState());
        structure.fillWithBlocks(world, start, 70, -46, -58, 71, -46, -57, Blocks.STONE_BRICKS.getDefaultState());
        structure.fillWithBlocks(world, start, 70, -46, -56, 70, -46, -56, Blocks.AIR.getDefaultState());
        structure.fillWithBlocks(world, start, 70, -46, -55, 70, -46, -38, Blocks.STONE_BRICKS.getDefaultState());
        structure.fillWithBlocks(world, start, 70, -46, 14, 71, -46, 15, Blocks.AIR.getDefaultState());
        structure.fillWithBlocks(world, start, 70, -46, 50, 72, -46, 52, Blocks.STONE_BRICKS.getDefaultState());
        structure.fillWithBlocks(world, start, 70, -46, 54, 70, -45, 54, Blocks.MOSSY_COBBLESTONE.getDefaultState());
        structure.fillWithBlocks(world, start, 70, -46, 55, 73, -46, 55, Blocks.AIR.getDefaultState());
        structure.fillWithBlocks(world, start, 70, -46, 56, 70, -46, 57, Blocks.MOSSY_COBBLESTONE.getDefaultState());
        structure.fillWithBlocks(world, start, 70, -46, 62, 71, -46, 62, Blocks.MOSSY_COBBLESTONE.getDefaultState());
        structure.fillWithBlocks(world, start, 70, -46, 73, 73, -46, 78, Blocks.STONE_BRICKS.getDefaultState());
        structure.fillWithBlocks(world, start, 70, -45, -17, 70, -45, -16, Blocks.STONE_BRICKS.getDefaultState());
        structure.fillWithBlocks(world, start, 70, -45, -14, 71, -45, -13, Blocks.MOSSY_COBBLESTONE.getDefaultState());
        structure.fillWithBlocks(world, start, 70, -45, -12, 70, -45, -11, Blocks.STONE_BRICKS.getDefaultState());
        structure.fillWithBlocks(world, start, 70, -45, 17, 70, -45, 18, Blocks.MOSSY_COBBLESTONE.getDefaultState());
        structure.fillWithBlocks(world, start, 70, -45, 20, 71, -45, 20, Blocks.MOSSY_STONE_BRICKS.getDefaultState());
        structure.fillWithBlocks(world, start, 70, -45, 21, 70, -45, 26, Blocks.MOSSY_COBBLESTONE.getDefaultState());
        structure.fillWithBlocks(world, start, 70, -45, 27, 71, -45, 27, Blocks.STONE_BRICKS.getDefaultState());
        structure.fillWithBlocks(world, start, 70, -45, 28, 71, -45, 29, Blocks.MOSSY_COBBLESTONE.getDefaultState());
        structure.fillWithBlocks(world, start, 70, -45, 32, 70, -45, 32, Blocks.MOSSY_STONE_BRICKS.getDefaultState());
        structure.fillWithBlocks(world, start, 70, -45, 33, 70, -45, 38, Blocks.MOSSY_COBBLESTONE.getDefaultState());
        structure.fillWithBlocks(world, start, 70, -45, 39, 70, -45, 41, Blocks.MOSSY_STONE_BRICKS.getDefaultState());
        structure.fillWithBlocks(world, start, 70, -45, 42, 70, -45, 42, Blocks.STONE_BRICKS.getDefaultState());
        structure.fillWithBlocks(world, start, 70, -45, 43, 70, -45, 47, Blocks.MOSSY_COBBLESTONE.getDefaultState());
        structure.fillWithBlocks(world, start, 70, -45, 49, 70, -45, 51, Blocks.MOSSY_COBBLESTONE.getDefaultState());
        structure.fillWithBlocks(world, start, 70, -45, 53, 70, -45, 54, Blocks.MOSSY_COBBLESTONE.getDefaultState());
        structure.fillWithBlocks(world, start, 70, -45, 55, 72, -45, 57, Blocks.STONE_BRICKS.getDefaultState());
        structure.fillWithBlocks(world, start, 70, -45, 63, 70, -45, 63, Blocks.STONE_BRICKS.getDefaultState());
        structure.fillWithBlocks(world, start, 70, -44, -17, 70, -44, -17, Blocks.STONE_BRICKS.getDefaultState());
        structure.fillWithBlocks(world, start, 70, -44, -16, 70, -44, -12, Blocks.AIR.getDefaultState());
        structure.fillWithBlocks(world, start, 70, -44, -11, 70, -42, -11, Blocks.STONE_BRICKS.getDefaultState());
        structure.fillWithBlocks(world, start, 70, -44, 6, 70, -44, 8, Blocks.STONE_BRICKS.getDefaultState());
        structure.fillWithBlocks(world, start, 70, -44, 59, 72, -44, 61, Blocks.AIR.getDefaultState());
        structure.fillWithBlocks(world, start, 70, -44, 62, 70, -44, 62, Blocks.STONE_BRICKS.getDefaultState());
        structure.fillWithBlocks(world, start, 70, -44, 63, 70, -44, 64, Blocks.MOSSY_STONE_BRICKS.getDefaultState());
        structure.fillWithBlocks(world, start, 70, -43, -17, 70, -43, -17, Blocks.STONE_BRICKS.getDefaultState());
        structure.fillWithBlocks(world, start, 70, -43, -16, 70, -43, -12, Blocks.AIR.getDefaultState());
        structure.fillWithBlocks(world, start, 70, -43, 6, 70, -42, 6, Blocks.STONE_BRICKS.getDefaultState());
        structure.fillWithBlocks(world, start, 70, -43, 7, 70, -43, 8, Blocks.SHROOMLIGHT.getDefaultState());
        structure.fillWithBlocks(world, start, 70, -43, 59, 72, -43, 61, Blocks.AIR.getDefaultState());
        structure.fillWithBlocks(world, start, 70, -43, 62, 70, -43, 63, Blocks.SHROOMLIGHT.getDefaultState());
        structure.fillWithBlocks(world, start, 70, -43, 65, 71, -43, 65, Blocks.STONE_BRICKS.getDefaultState());
        structure.fillWithBlocks(world, start, 70, -42, -17, 74, -42, -17, Blocks.STONE_BRICKS.getDefaultState());
        structure.fillWithBlocks(world, start, 70, -42, -16, 70, -42, -12, Blocks.AIR.getDefaultState());
        structure.fillWithBlocks(world, start, 70, -42, 62, 71, -42, 63, Blocks.STONE_BRICKS.getDefaultState());
        structure.fillWithBlocks(world, start, 70, -41, -16, 71, -41, -16, Blocks.MOSSY_STONE_BRICKS.getDefaultState());
        structure.fillWithBlocks(world, start, 70, -41, -15, 71, -41, -14, Blocks.STONE_BRICKS.getDefaultState());
        structure.fillWithBlocks(world, start, 70, -41, -13, 70, -41, -12, Blocks.STONE_BRICKS.getDefaultState());
        structure.fillWithBlocks(world, start, 70, -41, 6, 72, -41, 6, Blocks.MOSSY_STONE_BRICKS.getDefaultState());
        structure.fillWithBlocks(world, start, 70, -41, 7, 71, -41, 8, Blocks.STONE_BRICKS.getDefaultState());
        structure.fillWithBlocks(world, start, 70, -41, 16, 70, -40, 17, Blocks.STONE_BRICKS.getDefaultState());
        structure.fillWithBlocks(world, start, 70, -41, 46, 70, -41, 47, Blocks.MOSSY_STONE_BRICKS.getDefaultState());
        structure.fillWithBlocks(world, start, 70, -41, 48, 70, -41, 49, Blocks.STONE_BRICKS.getDefaultState());
        structure.fillWithBlocks(world, start, 70, -41, 51, 70, -40, 51, Blocks.MOSSY_STONE_BRICKS.getDefaultState());
        structure.fillWithBlocks(world, start, 70, -41, 53, 70, -41, 53, Blocks.STONE_BRICKS.getDefaultState());
        structure.fillWithBlocks(world, start, 70, -41, 62, 70, -41, 64, Blocks.STONE_BRICKS.getDefaultState());
        structure.fillWithBlocks(world, start, 70, -41, 65, 71, -41, 65, Blocks.MOSSY_STONE_BRICKS.getDefaultState());
        structure.fillWithBlocks(world, start, 70, -40, 7, 70, -40, 9, Blocks.STONE_BRICKS.getDefaultState());
        structure.fillWithBlocks(world, start, 70, -40, 15, 71, -40, 16, Blocks.STONE_BRICKS.getDefaultState());
        structure.fillWithBlocks(world, start, 70, -40, 37, 71, -40, 38, Blocks.STONE_BRICKS.getDefaultState());
        structure.fillWithBlocks(world, start, 70, -40, 39, 70, -40, 39, Blocks.MOSSY_STONE_BRICKS.getDefaultState());
        structure.fillWithBlocks(world, start, 70, -40, 40, 70, -39, 40, Blocks.STONE_BRICKS.getDefaultState());
        structure.fillWithBlocks(world, start, 70, -40, 53, 70, -40, 54, Blocks.MOSSY_STONE_BRICKS.getDefaultState());
        structure.fillWithBlocks(world, start, 70, -40, 63, 70, -39, 63, Blocks.MOSSY_STONE_BRICKS.getDefaultState());
        structure.fillWithBlocks(world, start, 70, -40, 64, 71, -40, 65, Blocks.STONE_BRICKS.getDefaultState());
        structure.fillWithBlocks(world, start, 70, -39, 13, 73, -39, 16, Blocks.STONE_BRICKS.getDefaultState());
        structure.fillWithBlocks(world, start, 70, -39, 17, 70, -39, 18, Blocks.STONE_BRICKS.getDefaultState());
        structure.fillWithBlocks(world, start, 70, -39, 20, 71, -38, 20, Blocks.STONE_BRICKS.getDefaultState());
        structure.fillWithBlocks(world, start, 70, -39, 36, 70, -39, 36, Blocks.STONE_BRICKS.getDefaultState());
        structure.fillWithBlocks(world, start, 70, -39, 38, 70, -39, 38, Blocks.MOSSY_STONE_BRICKS.getDefaultState());
        structure.fillWithBlocks(world, start, 70, -39, 39, 70, -39, 40, Blocks.STONE_BRICKS.getDefaultState());
        structure.fillWithBlocks(world, start, 70, -39, 51, 70, -39, 51, Blocks.STONE_BRICKS.getDefaultState());
        structure.fillWithBlocks(world, start, 70, -39, 52, 70, -39, 52, Blocks.MOSSY_STONE_BRICKS.getDefaultState());
        structure.fillWithBlocks(world, start, 70, -39, 56, 70, -38, 56, Blocks.MOSSY_COBBLESTONE.getDefaultState());
        structure.fillWithBlocks(world, start, 70, -39, 59, 73, -39, 59, Blocks.STONE_BRICKS.getDefaultState());
        structure.fillWithBlocks(world, start, 70, -39, 60, 71, -39, 60, Blocks.MOSSY_COBBLESTONE.getDefaultState());
        structure.fillWithBlocks(world, start, 70, -39, 61, 70, -38, 61, Blocks.MOSSY_STONE_BRICKS.getDefaultState());
        structure.fillWithBlocks(world, start, 70, -39, 62, 70, -39, 62, Blocks.STONE_BRICKS.getDefaultState());
        structure.fillWithBlocks(world, start, 70, -39, 64, 70, -39, 65, Blocks.STONE_BRICKS.getDefaultState());
        structure.fillWithBlocks(world, start, 70, -38, 10, 70, -37, 11, Blocks.MOSSY_COBBLESTONE.getDefaultState());
        structure.fillWithBlocks(world, start, 70, -38, 12, 70, -38, 12, Blocks.STONE_BRICKS.getDefaultState());
        structure.fillWithBlocks(world, start, 70, -38, 13, 70, -36, 13, Blocks.MOSSY_STONE_BRICKS.getDefaultState());
        structure.fillWithBlocks(world, start, 70, -38, 14, 70, -36, 14, Blocks.STONE_BRICKS.getDefaultState());
        structure.fillWithBlocks(world, start, 70, -38, 15, 71, -38, 15, Blocks.MOSSY_STONE_BRICKS.getDefaultState());
        structure.fillWithBlocks(world, start, 70, -38, 16, 72, -38, 16, Blocks.STONE_BRICKS.getDefaultState());
        structure.fillWithBlocks(world, start, 70, -38, 18, 70, -38, 18, Blocks.STONE_BRICKS.getDefaultState());
        structure.fillWithBlocks(world, start, 70, -38, 21, 70, -36, 21, Blocks.STONE_BRICKS.getDefaultState());
        structure.fillWithBlocks(world, start, 70, -38, 23, 71, -38, 24, Blocks.STONE_BRICKS.getDefaultState());
        structure.fillWithBlocks(world, start, 70, -38, 25, 70, -38, 26, Blocks.MOSSY_STONE_BRICKS.getDefaultState());
        structure.fillWithBlocks(world, start, 70, -38, 27, 70, -38, 27, Blocks.STONE_BRICKS.getDefaultState());
        structure.fillWithBlocks(world, start, 70, -38, 29, 70, -38, 31, Blocks.STONE_BRICKS.getDefaultState());
        structure.fillWithBlocks(world, start, 70, -38, 35, 71, -38, 36, Blocks.STONE_BRICKS.getDefaultState());
        structure.fillWithBlocks(world, start, 70, -38, 37, 70, -37, 37, Blocks.MOSSY_STONE_BRICKS.getDefaultState());
        structure.fillWithBlocks(world, start, 70, -38, 51, 70, -36, 51, Blocks.MOSSY_STONE_BRICKS.getDefaultState());
        structure.fillWithBlocks(world, start, 70, -38, 52, 70, -38, 52, Blocks.AIR.getDefaultState());
        structure.fillWithBlocks(world, start, 70, -38, 54, 72, -38, 54, Blocks.STONE_BRICKS.getDefaultState());
        structure.fillWithBlocks(world, start, 70, -38, 55, 70, -38, 56, Blocks.MOSSY_COBBLESTONE.getDefaultState());
        structure.fillWithBlocks(world, start, 70, -38, 57, 70, -38, 60, Blocks.STONE_BRICKS.getDefaultState());
        structure.fillWithBlocks(world, start, 70, -37, 8, 70, -37, 8, Blocks.STONE_BRICKS.getDefaultState());
        structure.fillWithBlocks(world, start, 70, -37, 12, 71, -37, 12, Blocks.STONE_BRICKS.getDefaultState());
        structure.fillWithBlocks(world, start, 70, -37, 16, 71, -37, 16, Blocks.MOSSY_STONE_BRICKS.getDefaultState());
        structure.fillWithBlocks(world, start, 70, -37, 17, 73, -37, 17, Blocks.STONE_BRICKS.getDefaultState());
        structure.fillWithBlocks(world, start, 70, -37, 18, 71, -37, 20, Blocks.MOSSY_STONE_BRICKS.getDefaultState());
        structure.fillWithBlocks(world, start, 70, -37, 23, 70, -36, 24, Blocks.STONE_BRICKS.getDefaultState());
        structure.fillWithBlocks(world, start, 70, -37, 26, 71, -37, 26, Blocks.AIR.getDefaultState());
        structure.fillWithBlocks(world, start, 70, -37, 27, 71, -37, 28, Blocks.STONE_BRICKS.getDefaultState());
        structure.fillWithBlocks(world, start, 70, -37, 30, 71, -37, 31, Blocks.STONE_BRICKS.getDefaultState());
        structure.fillWithBlocks(world, start, 70, -37, 33, 70, -37, 34, Blocks.MOSSY_STONE_BRICKS.getDefaultState());
        structure.fillWithBlocks(world, start, 70, -37, 35, 70, -37, 36, Blocks.STONE_BRICKS.getDefaultState());
        structure.fillWithBlocks(world, start, 70, -37, 38, 70, -37, 40, Blocks.STONE_BRICKS.getDefaultState());
        structure.fillWithBlocks(world, start, 70, -37, 53, 70, -36, 53, Blocks.MOSSY_COBBLESTONE.getDefaultState());
        structure.fillWithBlocks(world, start, 70, -37, 54, 71, -37, 54, Blocks.AIR.getDefaultState());
        structure.fillWithBlocks(world, start, 70, -37, 57, 70, -37, 58, Blocks.AIR.getDefaultState());
        structure.fillWithBlocks(world, start, 70, -37, 59, 70, -37, 59, Blocks.MOSSY_STONE_BRICKS.getDefaultState());
        structure.fillWithBlocks(world, start, 70, -37, 60, 70, -36, 61, Blocks.STONE_BRICKS.getDefaultState());
        structure.fillWithBlocks(world, start, 70, -37, 62, 70, -37, 62, Blocks.MOSSY_COBBLESTONE.getDefaultState());
        structure.fillWithBlocks(world, start, 70, -36, 8, 71, -36, 8, Blocks.MOSSY_STONE_BRICKS.getDefaultState());
        structure.fillWithBlocks(world, start, 70, -36, 9, 70, -36, 10, Blocks.STONE_BRICKS.getDefaultState());
        structure.fillWithBlocks(world, start, 70, -36, 11, 70, -36, 13, Blocks.MOSSY_STONE_BRICKS.getDefaultState());
        structure.fillWithBlocks(world, start, 70, -36, 15, 70, -36, 15, Blocks.MOSSY_STONE_BRICKS.getDefaultState());
        structure.fillWithBlocks(world, start, 70, -36, 16, 70, -35, 16, Blocks.STONE_BRICKS.getDefaultState());
        structure.fillWithBlocks(world, start, 70, -36, 18, 70, -36, 18, Blocks.STONE_BRICKS.getDefaultState());
        structure.fillWithBlocks(world, start, 70, -36, 19, 70, -36, 19, Blocks.MOSSY_STONE_BRICKS.getDefaultState());
        structure.fillWithBlocks(world, start, 70, -36, 20, 70, -36, 24, Blocks.STONE_BRICKS.getDefaultState());
        structure.fillWithBlocks(world, start, 70, -36, 26, 70, -36, 27, Blocks.MOSSY_STONE_BRICKS.getDefaultState());
        structure.fillWithBlocks(world, start, 70, -36, 28, 71, -36, 29, Blocks.STONE_BRICKS.getDefaultState());
        structure.fillWithBlocks(world, start, 70, -36, 30, 70, -36, 31, Blocks.MOSSY_STONE_BRICKS.getDefaultState());
        structure.fillWithBlocks(world, start, 70, -36, 36, 70, -36, 38, Blocks.STONE_BRICKS.getDefaultState());
        structure.fillWithBlocks(world, start, 70, -36, 52, 70, -36, 52, Blocks.MOSSY_STONE_BRICKS.getDefaultState());
        structure.fillWithBlocks(world, start, 70, -36, 54, 70, -36, 54, Blocks.STONE_BRICKS.getDefaultState());
        structure.fillWithBlocks(world, start, 70, -36, 56, 72, -36, 56, Blocks.STONE_BRICKS.getDefaultState());
        structure.fillWithBlocks(world, start, 70, -36, 58, 70, -36, 62, Blocks.STONE_BRICKS.getDefaultState());
        structure.fillWithBlocks(world, start, 70, -36, 64, 75, -36, 64, Blocks.STONE_BRICKS.getDefaultState());
        structure.fillWithBlocks(world, start, 70, -25, 37, 70, -25, 39, Blocks.STONE_BRICKS.getDefaultState());
        structure.fillWithBlocks(world, start, 70, -25, 41, 70, -24, 41, Blocks.STONE_BRICKS.getDefaultState());
        structure.fillWithBlocks(world, start, 70, -25, 42, 70, -24, 42, Blocks.CRACKED_STONE_BRICKS.getDefaultState());
        structure.fillWithBlocks(world, start, 70, -25, 43, 70, -25, 47, Blocks.STONE_BRICKS.getDefaultState());
        structure.fillWithBlocks(world, start, 70, -25, 48, 71, -25, 48, Blocks.CRACKED_STONE_BRICKS.getDefaultState());
        structure.fillWithBlocks(world, start, 70, -25, 49, 70, -24, 49, Blocks.STONE_BRICKS.getDefaultState());
        structure.fillWithBlocks(world, start, 70, -25, 51, 70, -25, 52, Blocks.CRACKED_STONE_BRICKS.getDefaultState());
        structure.fillWithBlocks(world, start, 70, -25, 55, 70, -23, 55, Blocks.STONE_BRICKS.getDefaultState());
        structure.fillWithBlocks(world, start, 70, -25, 77, 72, -25, 80, Blocks.STONE_BRICKS.getDefaultState());
        structure.fillWithBlocks(world, start, 70, -24, 39, 70, -23, 40, Blocks.STONE_BRICKS.getDefaultState());
        structure.fillWithBlocks(world, start, 70, -24, 43, 70, -24, 43, Blocks.STONE_BRICKS.getDefaultState());
        structure.fillWithBlocks(world, start, 70, -24, 44, 70, -24, 48, Blocks.AIR.getDefaultState());
        structure.fillWithBlocks(world, start, 70, -24, 51, 70, -21, 51, Blocks.STONE_BRICKS.getDefaultState());
        structure.fillWithBlocks(world, start, 70, -23, 37, 70, -22, 37, Blocks.CRACKED_STONE_BRICKS.getDefaultState());
        structure.fillWithBlocks(world, start, 70, -23, 41, 70, -22, 41, Blocks.CRACKED_STONE_BRICKS.getDefaultState());
        structure.fillWithBlocks(world, start, 70, -23, 44, 70, -23, 48, Blocks.AIR.getDefaultState());
        structure.fillWithBlocks(world, start, 70, -23, 49, 70, -23, 50, Blocks.CRACKED_STONE_BRICKS.getDefaultState());
        structure.fillWithBlocks(world, start, 70, -23, 52, 70, -23, 55, Blocks.STONE_BRICKS.getDefaultState());
        structure.fillWithBlocks(world, start, 70, -23, 75, 70, -22, 75, Blocks.STONE_BRICKS.getDefaultState());
        structure.fillWithBlocks(world, start, 70, -23, 81, 70, -22, 81, Blocks.STONE_BRICKS.getDefaultState());
        structure.fillWithBlocks(world, start, 70, -22, 40, 70, -22, 43, Blocks.CRACKED_STONE_BRICKS.getDefaultState());
        structure.fillWithBlocks(world, start, 70, -22, 44, 70, -22, 48, Blocks.AIR.getDefaultState());
        structure.fillWithBlocks(world, start, 70, -22, 53, 70, -22, 55, Blocks.CRACKED_STONE_BRICKS.getDefaultState());
        structure.fillWithBlocks(world, start, 70, -21, 37, 70, -15, 37, Blocks.STONE_BRICKS.getDefaultState());
        structure.fillWithBlocks(world, start, 70, -21, 38, 70, -21, 39, Blocks.CRACKED_STONE_BRICKS.getDefaultState());
        structure.fillWithBlocks(world, start, 70, -21, 42, 70, -19, 42, Blocks.STONE_BRICKS.getDefaultState());
        structure.fillWithBlocks(world, start, 70, -21, 43, 70, -21, 44, Blocks.CRACKED_STONE_BRICKS.getDefaultState());
        structure.fillWithBlocks(world, start, 70, -21, 45, 71, -21, 48, Blocks.STONE_BRICKS.getDefaultState());
        structure.fillWithBlocks(world, start, 70, -21, 50, 70, -21, 55, Blocks.STONE_BRICKS.getDefaultState());
        structure.fillWithBlocks(world, start, 70, -21, 76, 70, -21, 76, Blocks.STONE_BRICKS.getDefaultState());
        structure.fillWithBlocks(world, start, 70, -21, 78, 70, -21, 78, Blocks.STONE_BRICKS.getDefaultState());
        structure.fillWithBlocks(world, start, 70, -21, 80, 71, -21, 80, Blocks.STONE_BRICKS.getDefaultState());
        structure.fillWithBlocks(world, start, 70, -20, 40, 70, -19, 40, Blocks.STONE_BRICKS.getDefaultState());
        structure.fillWithBlocks(world, start, 70, -20, 41, 70, -17, 41, Blocks.MOSSY_STONE_BRICKS.getDefaultState());
        structure.fillWithBlocks(world, start, 70, -20, 43, 70, -19, 44, Blocks.STONE_BRICKS.getDefaultState());
        structure.fillWithBlocks(world, start, 70, -20, 48, 70, -20, 49, Blocks.STONE_BRICKS.getDefaultState());
        structure.fillWithBlocks(world, start, 70, -20, 54, 70, -19, 55, Blocks.STONE_BRICKS.getDefaultState());
        structure.fillWithBlocks(world, start, 70, -19, 38, 70, -19, 39, Blocks.CRACKED_STONE_BRICKS.getDefaultState());
        structure.fillWithBlocks(world, start, 70, -19, 49, 70, -19, 51, Blocks.STONE_BRICKS.getDefaultState());
        structure.fillWithBlocks(world, start, 70, -18, 38, 70, -17, 39, Blocks.STONE_BRICKS.getDefaultState());
        structure.fillWithBlocks(world, start, 70, -18, 42, 70, -18, 43, Blocks.MOSSY_STONE_BRICKS.getDefaultState());
        structure.fillWithBlocks(world, start, 70, -18, 45, 70, -17, 46, Blocks.STONE_BRICKS.getDefaultState());
        structure.fillWithBlocks(world, start, 70, -18, 51, 70, -18, 55, Blocks.STONE_BRICKS.getDefaultState());
        structure.fillWithBlocks(world, start, 70, -17, 42, 70, -17, 46, Blocks.STONE_BRICKS.getDefaultState());
        structure.fillWithBlocks(world, start, 70, -17, 50, 70, -16, 50, Blocks.STONE_BRICKS.getDefaultState());
        structure.fillWithBlocks(world, start, 70, -17, 51, 70, -17, 54, Blocks.MOSSY_STONE_BRICKS.getDefaultState());
        structure.fillWithBlocks(world, start, 70, -17, 55, 70, -15, 55, Blocks.STONE_BRICKS.getDefaultState());
        structure.fillWithBlocks(world, start, 70, -16, 38, 70, -15, 39, Blocks.STONE_BRICKS.getDefaultState());
        structure.fillWithBlocks(world, start, 70, -16, 40, 70, -16, 42, Blocks.CRACKED_STONE_BRICKS.getDefaultState());
        structure.fillWithBlocks(world, start, 70, -16, 48, 70, -16, 51, Blocks.STONE_BRICKS.getDefaultState());
        structure.fillWithBlocks(world, start, 70, -15, 33, 70, -15, 40, Blocks.STONE_BRICKS.getDefaultState());
        structure.fillWithBlocks(world, start, 70, -15, 54, 71, -15, 56, Blocks.STONE_BRICKS.getDefaultState());
        structure.fillWithBlocks(world, start, 70, -14, 33, 70, -14, 33, Blocks.STONE_BRICKS.getDefaultState());
        structure.fillWithBlocks(world, start, 70, -14, 34, 70, -12, 38, Blocks.AIR.getDefaultState());
        structure.fillWithBlocks(world, start, 70, -14, 39, 71, -14, 40, Blocks.STONE_BRICKS.getDefaultState());
        structure.fillWithBlocks(world, start, 70, -14, 43, 70, -14, 43, Blocks.STONE_BRICKS.getDefaultState());
        structure.fillWithBlocks(world, start, 70, -14, 44, 70, -14, 48, Blocks.AIR.getDefaultState());
        structure.fillWithBlocks(world, start, 70, -14, 49, 72, -12, 49, Blocks.STONE_BRICKS.getDefaultState());
        structure.fillWithBlocks(world, start, 70, -14, 52, 71, -14, 53, Blocks.STONE_BRICKS.getDefaultState());
        structure.fillWithBlocks(world, start, 70, -14, 54, 70, -12, 58, Blocks.AIR.getDefaultState());
        structure.fillWithBlocks(world, start, 70, -14, 59, 71, -14, 60, Blocks.STONE_BRICKS.getDefaultState());
        structure.fillWithBlocks(world, start, 70, -13, 33, 70, -13, 33, Blocks.STONE_BRICKS.getDefaultState());
        structure.fillWithBlocks(world, start, 70, -13, 39, 71, -13, 40, Blocks.STONE_BRICKS.getDefaultState());
        structure.fillWithBlocks(world, start, 70, -13, 43, 70, -13, 43, Blocks.STONE_BRICKS.getDefaultState());
        structure.fillWithBlocks(world, start, 70, -13, 44, 70, -13, 48, Blocks.AIR.getDefaultState());
        structure.fillWithBlocks(world, start, 70, -13, 52, 70, -13, 53, Blocks.STONE_BRICKS.getDefaultState());
        structure.fillWithBlocks(world, start, 70, -13, 59, 71, -13, 60, Blocks.STONE_BRICKS.getDefaultState());
        structure.fillWithBlocks(world, start, 70, -12, 33, 70, -12, 33, Blocks.STONE_BRICKS.getDefaultState());
        structure.fillWithBlocks(world, start, 70, -12, 39, 71, -12, 40, Blocks.STONE_BRICKS.getDefaultState());
        structure.fillWithBlocks(world, start, 70, -12, 44, 70, -12, 48, Blocks.AIR.getDefaultState());
        structure.fillWithBlocks(world, start, 70, -12, 52, 70, -12, 53, Blocks.STONE_BRICKS.getDefaultState());
        structure.fillWithBlocks(world, start, 70, -12, 59, 71, -12, 60, Blocks.STONE_BRICKS.getDefaultState());
        structure.fillWithBlocks(world, start, 70, -11, 34, 71, -11, 38, Blocks.STONE_BRICKS.getDefaultState());
        structure.fillWithBlocks(world, start, 70, -11, 40, 71, -10, 40, Blocks.STONE_BRICKS.getDefaultState());
        structure.fillWithBlocks(world, start, 70, -11, 52, 70, -11, 52, Blocks.STONE_BRICKS.getDefaultState());
        structure.fillWithBlocks(world, start, 70, -11, 54, 71, -11, 58, Blocks.STONE_BRICKS.getDefaultState());
        structure.fillWithBlocks(world, start, 70, -10, 33, 70, -10, 34, Blocks.STONE_BRICKS.getDefaultState());
        structure.fillWithBlocks(world, start, 70, -10, 53, 71, -10, 55, Blocks.STONE_BRICKS.getDefaultState());
        structure.fillWithBlocks(world, start, 70, 0, 5, 72, 0, 8, Blocks.DIRT.getDefaultState());
        structure.fillWithBlocks(world, start, 70, 1, 10, 71, 2, 10, Blocks.DIRT.getDefaultState());
        structure.fillWithBlocks(world, start, 70, 1, 11, 77, 1, 78, Blocks.STONE.getDefaultState());
        structure.fillWithBlocks(world, start, 70, 1, 79, 70, 5, 87, Blocks.DIRT.getDefaultState());
        structure.fillWithBlocks(world, start, 70, 1, 89, 72, 1, 92, Blocks.DIRT.getDefaultState());
        structure.fillWithBlocks(world, start, 70, 1, 93, 70, 1, 94, Blocks.GRASS_BLOCK.getDefaultState().with(SnowyDirtBlock.SNOWY, false));
        structure.fillWithBlocks(world, start, 70, 2, 7, 70, 2, 13, Blocks.DIRT.getDefaultState());
        structure.fillWithBlocks(world, start, 70, 2, 14, 73, 2, 17, Blocks.STONE.getDefaultState());
        structure.fillWithBlocks(world, start, 70, 2, 18, 70, 2, 22, Blocks.COARSE_DIRT.getDefaultState());
        structure.fillWithBlocks(world, start, 70, 3, 18, 74, 3, 22, Blocks.COARSE_DIRT.getDefaultState());
        structure.fillWithBlocks(world, start, 70, 4, 10, 77, 4, 10, Blocks.GRASS_BLOCK.getDefaultState().with(SnowyDirtBlock.SNOWY, false));
        structure.fillWithBlocks(world, start, 70, 4, 11, 73, 4, 17, Blocks.DIRT.getDefaultState());
        structure.fillWithBlocks(world, start, 70, 4, 18, 74, 4, 22, Blocks.COARSE_DIRT.getDefaultState());
        structure.fillWithBlocks(world, start, 70, 5, 12, 71, 5, 13, Blocks.GRASS_BLOCK.getDefaultState().with(SnowyDirtBlock.SNOWY, false));
        structure.fillWithBlocks(world, start, 70, 5, 14, 73, 5, 17, Blocks.DIRT.getDefaultState());
        structure.fillWithBlocks(world, start, 70, 5, 18, 74, 5, 22, Blocks.COARSE_DIRT.getDefaultState());
        structure.fillWithBlocks(world, start, 70, 5, 88, 71, 5, 89, Blocks.GRASS_BLOCK.getDefaultState().with(SnowyDirtBlock.SNOWY, false));
        structure.fillWithBlocks(world, start, 70, 6, 14, 73, 6, 17, Blocks.GRASS_BLOCK.getDefaultState().with(SnowyDirtBlock.SNOWY, false));
        structure.fillWithBlocks(world, start, 70, 8, 18, 70, 8, 19, Blocks.GRASS.getDefaultState());
        structure.fillWithBlocks(world, start, 70, 8, 73, 71, 8, 74, Blocks.GRASS.getDefaultState());
        structure.fillWithBlocks(world, start, 70, 8, 76, 71, 8, 76, Blocks.GRASS.getDefaultState());
        structure.fillWithBlocks(world, start, 70, 10, 68, 71, 10, 70, Blocks.STONE_BRICKS.getDefaultState());
        structure.fillWithBlocks(world, start, 70, 12, 26, 72, 12, 26, Blocks.STONE_BRICK_STAIRS.getDefaultState().with(StairsBlock.FACING, Direction.SOUTH).with(StairsBlock.WATERLOGGED, false).with(StairsBlock.SHAPE, StairsShape.STRAIGHT).with(StairsBlock.HALF, Half.TOP));
        structure.fillWithBlocks(world, start, 70, 12, 28, 73, 12, 66, Blocks.STONE.getDefaultState());
        structure.fillWithBlocks(world, start, 70, 12, 68, 72, 12, 68, Blocks.STONE_BRICK_STAIRS.getDefaultState().with(StairsBlock.FACING, Direction.NORTH).with(StairsBlock.WATERLOGGED, false).with(StairsBlock.SHAPE, StairsShape.STRAIGHT).with(StairsBlock.HALF, Half.TOP));
        structure.fillWithBlocks(world, start, 70, 16, 30, 71, 16, 31, Blocks.STONE_BRICKS.getDefaultState());
        structure.fillWithBlocks(world, start, 70, 16, 32, 70, 16, 64, Blocks.STONE_BRICKS.getDefaultState());
        structure.fillWithBlocks(world, start, 70, 18, 44, 70, 18, 50, Blocks.STONE_BRICK_STAIRS.getDefaultState().with(StairsBlock.FACING, Direction.WEST).with(StairsBlock.WATERLOGGED, false).with(StairsBlock.SHAPE, StairsShape.STRAIGHT).with(StairsBlock.HALF, Half.BOTTOM));
        structure.fillWithBlocks(world, start, 71, -58, 50, 76, -58, 58, Blocks.STONE_BRICKS.getDefaultState());
        structure.fillWithBlocks(world, start, 71, -58, 60, 72, -58, 61, Blocks.STONE_BRICKS.getDefaultState());
        structure.fillWithBlocks(world, start, 71, -57, -48, 74, -57, -45, Blocks.STONE_BRICKS.getDefaultState());
        structure.fillWithBlocks(world, start, 71, -57, 40, 75, -57, 44, Blocks.STONE_BRICKS.getDefaultState());
        structure.fillWithBlocks(world, start, 71, -57, 46, 71, -56, 48, Blocks.SHROOMLIGHT.getDefaultState());
        structure.fillWithBlocks(world, start, 71, -57, 54, 71, -56, 56, Blocks.SHROOMLIGHT.getDefaultState());
        structure.fillWithBlocks(world, start, 71, -57, 57, 72, -57, 62, Blocks.STONE_BRICKS.getDefaultState());
        structure.fillWithBlocks(world, start, 71, -56, -48, 72, -56, -46, Blocks.AIR.getDefaultState());
        structure.fillWithBlocks(world, start, 71, -56, 49, 71, -55, 53, Blocks.STONE_BRICKS.getDefaultState());
        structure.fillWithBlocks(world, start, 71, -55, -58, 73, -55, -56, Blocks.STONE_BRICKS.getDefaultState());
        structure.fillWithBlocks(world, start, 71, -55, -54, 72, -55, -53, Blocks.STONE_BRICKS.getDefaultState());
        structure.fillWithBlocks(world, start, 71, -55, -48, 73, -55, -45, Blocks.AIR.getDefaultState());
        structure.fillWithBlocks(world, start, 71, -55, 12, 74, -55, 15, Blocks.STONE_BRICKS.getDefaultState());
        structure.fillWithBlocks(world, start, 71, -55, 79, 74, -55, 82, Blocks.STONE_BRICKS.getDefaultState());
        structure.fillWithBlocks(world, start, 71, -55, 85, 73, -53, 85, Blocks.STONE_BRICKS.getDefaultState());
        structure.fillWithBlocks(world, start, 71, -54, -58, 73, -54, -56, Blocks.STONE_BRICKS.getDefaultState());
        structure.fillWithBlocks(world, start, 71, -54, -14, 72, -54, -13, Blocks.AIR.getDefaultState());
        structure.fillWithBlocks(world, start, 71, -54, 4, 72, -54, 5, Blocks.AIR.getDefaultState());
        structure.fillWithBlocks(world, start, 71, -54, 9, 72, -54, 11, Blocks.AIR.getDefaultState());
        structure.fillWithBlocks(world, start, 71, -54, 17, 72, -54, 19, Blocks.AIR.getDefaultState());
        structure.fillWithBlocks(world, start, 71, -54, 20, 71, -54, 82, Blocks.AIR.getDefaultState());
        structure.fillWithBlocks(world, start, 71, -53, 8, 71, -52, 8, Blocks.STONE_BRICK_WALL.getDefaultState().with(WallBlock.WATERLOGGED, false).with(WallBlock.UP, true).with(WallBlock.WALL_HEIGHT_NORTH, WallHeight.LOW).with(WallBlock.WALL_HEIGHT_SOUTH, WallHeight.LOW).with(WallBlock.WALL_HEIGHT_EAST, WallHeight.LOW).with(WallBlock.WALL_HEIGHT_WEST, WallHeight.LOW));
        structure.fillWithBlocks(world, start, 71, -53, 9, 72, -53, 15, Blocks.AIR.getDefaultState());
        structure.fillWithBlocks(world, start, 71, -53, 17, 72, -53, 19, Blocks.AIR.getDefaultState());
        structure.fillWithBlocks(world, start, 71, -53, 83, 72, -53, 85, Blocks.STONE_BRICKS.getDefaultState());
        structure.fillWithBlocks(world, start, 71, -52, -57, 72, -52, -56, Blocks.STONE_BRICKS.getDefaultState());
        structure.fillWithBlocks(world, start, 71, -52, 11, 73, -52, 14, Blocks.AIR.getDefaultState());
        structure.fillWithBlocks(world, start, 71, -52, 17, 72, -52, 19, Blocks.AIR.getDefaultState());
        structure.fillWithBlocks(world, start, 71, -51, -58, 73, -51, -56, Blocks.STONE_BRICKS.getDefaultState());
        structure.fillWithBlocks(world, start, 71, -51, -14, 76, -51, -8, Blocks.STONE_BRICKS.getDefaultState());
        structure.fillWithBlocks(world, start, 71, -51, 16, 71, -51, 16, Blocks.STONE_BRICKS.getDefaultState());
        structure.fillWithBlocks(world, start, 71, -51, 18, 72, -51, 19, Blocks.STONE_BRICKS.getDefaultState());
        structure.fillWithBlocks(world, start, 71, -51, 21, 71, -51, 21, Blocks.STONE_BRICKS.getDefaultState());
        structure.fillWithBlocks(world, start, 71, -51, 23, 72, -51, 41, Blocks.STONE_BRICKS.getDefaultState());
        structure.fillWithBlocks(world, start, 71, -51, 45, 71, -51, 45, Blocks.STONE_BRICKS.getDefaultState());
        structure.fillWithBlocks(world, start, 71, -51, 53, 71, -51, 53, Blocks.STONE_BRICKS.getDefaultState());
        structure.fillWithBlocks(world, start, 71, -51, 61, 72, -51, 62, Blocks.STONE_BRICKS.getDefaultState());
        structure.fillWithBlocks(world, start, 71, -50, -58, 73, -50, -56, Blocks.STONE_BRICKS.getDefaultState());
        structure.fillWithBlocks(world, start, 71, -50, -20, 75, -50, -12, Blocks.STONE_BRICKS.getDefaultState());
        structure.fillWithBlocks(world, start, 71, -50, 6, 72, -50, 8, Blocks.STONE_BRICKS.getDefaultState());
        structure.fillWithBlocks(world, start, 71, -50, 9, 72, -50, 11, Blocks.AIR.getDefaultState());
        structure.fillWithBlocks(world, start, 71, -50, 42, 73, -50, 59, Blocks.STONE_BRICKS.getDefaultState());
        structure.fillWithBlocks(world, start, 71, -50, 74, 76, -50, 85, Blocks.STONE_BRICKS.getDefaultState());
        structure.fillWithBlocks(world, start, 71, -49, -57, 71, -48, -56, Blocks.STONE_BRICKS.getDefaultState());
        structure.fillWithBlocks(world, start, 71, -49, -44, 73, -49, -42, Blocks.STONE_BRICKS.getDefaultState());
        structure.fillWithBlocks(world, start, 71, -49, -19, 73, -49, -16, Blocks.STONE_BRICKS.getDefaultState());
        structure.fillWithBlocks(world, start, 71, -49, -15, 72, -49, -8, Blocks.STONE_BRICKS.getDefaultState());
        structure.fillWithBlocks(world, start, 71, -49, 6, 73, -49, 8, Blocks.STONE_BRICKS.getDefaultState());
        structure.fillWithBlocks(world, start, 71, -49, 9, 72, -49, 15, Blocks.AIR.getDefaultState());
        structure.fillWithBlocks(world, start, 71, -49, 56, 72, -49, 61, Blocks.STONE_BRICKS.getDefaultState());
        structure.fillWithBlocks(world, start, 71, -49, 73, 74, -49, 80, Blocks.STONE_BRICKS.getDefaultState());
        structure.fillWithBlocks(world, start, 71, -48, -53, 75, -48, -49, Blocks.STONE_BRICKS.getDefaultState());
        structure.fillWithBlocks(world, start, 71, -48, -48, 73, -48, -46, Blocks.STONE_BRICKS.getDefaultState());
        structure.fillWithBlocks(world, start, 71, -48, -38, 73, -46, -38, Blocks.STONE_BRICKS.getDefaultState());
        structure.fillWithBlocks(world, start, 71, -48, 6, 72, -48, 8, Blocks.STONE_BRICKS.getDefaultState());
        structure.fillWithBlocks(world, start, 71, -48, 11, 73, -48, 14, Blocks.AIR.getDefaultState());
        structure.fillWithBlocks(world, start, 71, -48, 61, 71, -48, 61, Blocks.MOSSY_COBBLESTONE.getDefaultState());
        structure.fillWithBlocks(world, start, 71, -47, -20, 75, -47, -16, Blocks.STONE_BRICKS.getDefaultState());
        structure.fillWithBlocks(world, start, 71, -47, -15, 74, -47, -8, Blocks.STONE_BRICKS.getDefaultState());
        structure.fillWithBlocks(world, start, 71, -47, 6, 73, -47, 8, Blocks.STONE_BRICKS.getDefaultState());
        structure.fillWithBlocks(world, start, 71, -47, 43, 74, -47, 46, Blocks.STONE_BRICKS.getDefaultState());
        structure.fillWithBlocks(world, start, 71, -47, 47, 71, -47, 54, Blocks.STONE_BRICKS.getDefaultState());
        structure.fillWithBlocks(world, start, 71, -47, 56, 72, -47, 57, Blocks.AIR.getDefaultState());
        structure.fillWithBlocks(world, start, 71, -47, 58, 71, -47, 59, Blocks.AIR.getDefaultState());
        structure.fillWithBlocks(world, start, 71, -47, 62, 72, -47, 62, Blocks.STONE_BRICKS.getDefaultState());
        structure.fillWithBlocks(world, start, 71, -46, -56, 71, -46, -56, Blocks.STONE_BRICKS.getDefaultState());
        structure.fillWithBlocks(world, start, 71, -46, -54, 72, -46, -45, Blocks.STONE_BRICKS.getDefaultState());
        structure.fillWithBlocks(world, start, 71, -46, -43, 75, -46, -38, Blocks.STONE_BRICKS.getDefaultState());
        structure.fillWithBlocks(world, start, 71, -46, -20, 71, -46, -20, Blocks.STONE_BRICKS.getDefaultState());
        structure.fillWithBlocks(world, start, 71, -46, -18, 74, -46, -15, Blocks.STONE_BRICKS.getDefaultState());
        structure.fillWithBlocks(world, start, 71, -46, 6, 73, -46, 8, Blocks.STONE_BRICKS.getDefaultState());
        structure.fillWithBlocks(world, start, 71, -46, 9, 72, -46, 11, Blocks.AIR.getDefaultState());
        structure.fillWithBlocks(world, start, 71, -46, 26, 71, -46, 29, Blocks.STONE_BRICKS.getDefaultState());
        structure.fillWithBlocks(world, start, 71, -46, 42, 72, -46, 43, Blocks.STONE_BRICKS.getDefaultState());
        structure.fillWithBlocks(world, start, 71, -46, 45, 73, -46, 52, Blocks.STONE_BRICKS.getDefaultState());
        structure.fillWithBlocks(world, start, 71, -46, 57, 73, -46, 61, Blocks.AIR.getDefaultState());
        structure.fillWithBlocks(world, start, 71, -46, 80, 74, -46, 85, Blocks.STONE_BRICKS.getDefaultState());
        structure.fillWithBlocks(world, start, 71, -45, -16, 71, -45, -15, Blocks.MOSSY_STONE_BRICKS.getDefaultState());
        structure.fillWithBlocks(world, start, 71, -45, 6, 72, -45, 6, Blocks.STONE_BRICKS.getDefaultState());
        structure.fillWithBlocks(world, start, 71, -45, 8, 72, -45, 10, Blocks.STONE_BRICKS.getDefaultState());
        structure.fillWithBlocks(world, start, 71, -45, 12, 71, -44, 13, Blocks.AIR.getDefaultState());
        structure.fillWithBlocks(world, start, 71, -45, 21, 72, -45, 21, Blocks.MOSSY_COBBLESTONE.getDefaultState());
        structure.fillWithBlocks(world, start, 71, -45, 22, 72, -45, 22, Blocks.STONE_BRICKS.getDefaultState());
        structure.fillWithBlocks(world, start, 71, -45, 23, 71, -45, 26, Blocks.MOSSY_COBBLESTONE.getDefaultState());
        structure.fillWithBlocks(world, start, 71, -45, 31, 72, -45, 32, Blocks.MOSSY_COBBLESTONE.getDefaultState());
        structure.fillWithBlocks(world, start, 71, -45, 33, 74, -45, 33, Blocks.MOSSY_STONE_BRICKS.getDefaultState());
        structure.fillWithBlocks(world, start, 71, -45, 34, 71, -45, 35, Blocks.MOSSY_COBBLESTONE.getDefaultState());
        structure.fillWithBlocks(world, start, 71, -45, 37, 71, -45, 38, Blocks.MOSSY_COBBLESTONE.getDefaultState());
        structure.fillWithBlocks(world, start, 71, -45, 43, 71, -45, 43, Blocks.STONE_BRICKS.getDefaultState());
        structure.fillWithBlocks(world, start, 71, -45, 44, 71, -45, 44, Blocks.MOSSY_COBBLESTONE.getDefaultState());
        structure.fillWithBlocks(world, start, 71, -45, 45, 71, -45, 45, Blocks.MOSSY_STONE_BRICKS.getDefaultState());
        structure.fillWithBlocks(world, start, 71, -45, 46, 71, -45, 47, Blocks.MOSSY_COBBLESTONE.getDefaultState());
        structure.fillWithBlocks(world, start, 71, -45, 49, 71, -45, 49, Blocks.MOSSY_COBBLESTONE.getDefaultState());
        structure.fillWithBlocks(world, start, 71, -45, 52, 72, -45, 53, Blocks.STONE_BRICKS.getDefaultState());
        structure.fillWithBlocks(world, start, 71, -45, 54, 71, -45, 64, Blocks.STONE_BRICKS.getDefaultState());
        structure.fillWithBlocks(world, start, 71, -44, -17, 71, -43, -16, Blocks.STONE_BRICKS.getDefaultState());
        structure.fillWithBlocks(world, start, 71, -44, -15, 73, -44, -13, Blocks.AIR.getDefaultState());
        structure.fillWithBlocks(world, start, 71, -44, -12, 71, -43, -12, Blocks.MOSSY_COBBLESTONE.getDefaultState());
        structure.fillWithBlocks(world, start, 71, -44, 7, 72, -44, 8, Blocks.STONE_BRICKS.getDefaultState());
        structure.fillWithBlocks(world, start, 71, -44, 57, 73, -44, 61, Blocks.AIR.getDefaultState());
        structure.fillWithBlocks(world, start, 71, -44, 62, 71, -44, 65, Blocks.STONE_BRICKS.getDefaultState());
        structure.fillWithBlocks(world, start, 71, -43, -15, 73, -43, -13, Blocks.AIR.getDefaultState());
        structure.fillWithBlocks(world, start, 71, -43, 6, 74, -43, 6, Blocks.AIR.getDefaultState());
        structure.fillWithBlocks(world, start, 71, -43, 7, 72, -43, 8, Blocks.STONE_BRICKS.getDefaultState());
        structure.fillWithBlocks(world, start, 71, -43, 58, 73, -43, 61, Blocks.AIR.getDefaultState());
        structure.fillWithBlocks(world, start, 71, -43, 62, 71, -41, 62, Blocks.STONE_BRICKS.getDefaultState());
        structure.fillWithBlocks(world, start, 71, -42, -16, 71, -41, -16, Blocks.MOSSY_STONE_BRICKS.getDefaultState());
        structure.fillWithBlocks(world, start, 71, -42, -15, 73, -42, -13, Blocks.AIR.getDefaultState());
        structure.fillWithBlocks(world, start, 71, -42, 8, 74, -39, 8, Blocks.STONE_BRICKS.getDefaultState());
        structure.fillWithBlocks(world, start, 71, -42, 64, 71, -42, 64, Blocks.STONE_BRICKS.getDefaultState());
        structure.fillWithBlocks(world, start, 71, -41, -13, 72, -41, -13, Blocks.MOSSY_STONE_BRICKS.getDefaultState());
        structure.fillWithBlocks(world, start, 71, -41, 16, 74, -39, 16, Blocks.STONE_BRICKS.getDefaultState());
        structure.fillWithBlocks(world, start, 71, -41, 17, 71, -41, 18, Blocks.MOSSY_STONE_BRICKS.getDefaultState());
        structure.fillWithBlocks(world, start, 71, -41, 40, 74, -41, 40, Blocks.STONE_BRICKS.getDefaultState());
        structure.fillWithBlocks(world, start, 71, -41, 41, 71, -41, 41, Blocks.MOSSY_STONE_BRICKS.getDefaultState());
        structure.fillWithBlocks(world, start, 71, -41, 42, 71, -41, 43, Blocks.STONE_BRICKS.getDefaultState());
        structure.fillWithBlocks(world, start, 71, -41, 46, 71, -41, 46, Blocks.STONE_BRICKS.getDefaultState());
        structure.fillWithBlocks(world, start, 71, -41, 49, 72, -41, 49, Blocks.STONE_BRICKS.getDefaultState());
        structure.fillWithBlocks(world, start, 71, -41, 51, 71, -41, 51, Blocks.STONE_BRICKS.getDefaultState());
        structure.fillWithBlocks(world, start, 71, -41, 52, 71, -40, 52, Blocks.MOSSY_STONE_BRICKS.getDefaultState());
        structure.fillWithBlocks(world, start, 71, -41, 53, 71, -41, 54, Blocks.STONE_BRICKS.getDefaultState());
        structure.fillWithBlocks(world, start, 71, -41, 63, 71, -41, 63, Blocks.MOSSY_STONE_BRICKS.getDefaultState());
        structure.fillWithBlocks(world, start, 71, -40, 6, 71, -40, 6, Blocks.STONE_BRICKS.getDefaultState());
        structure.fillWithBlocks(world, start, 71, -40, 18, 72, -40, 19, Blocks.STONE_BRICKS.getDefaultState());
        structure.fillWithBlocks(world, start, 71, -40, 39, 71, -40, 39, Blocks.STONE_BRICKS.getDefaultState());
        structure.fillWithBlocks(world, start, 71, -40, 51, 71, -40, 51, Blocks.AIR.getDefaultState());
        structure.fillWithBlocks(world, start, 71, -40, 53, 71, -39, 53, Blocks.MOSSY_STONE_BRICKS.getDefaultState());
        structure.fillWithBlocks(world, start, 71, -40, 54, 72, -39, 54, Blocks.MOSSY_COBBLESTONE.getDefaultState());
        structure.fillWithBlocks(world, start, 71, -40, 63, 71, -40, 65, Blocks.STONE_BRICKS.getDefaultState());
        structure.fillWithBlocks(world, start, 71, -39, 12, 73, -39, 16, Blocks.STONE_BRICKS.getDefaultState());
        structure.fillWithBlocks(world, start, 71, -39, 19, 72, -39, 20, Blocks.STONE_BRICKS.getDefaultState());
        structure.fillWithBlocks(world, start, 71, -39, 36, 73, -39, 38, Blocks.STONE_BRICKS.getDefaultState());
        structure.fillWithBlocks(world, start, 71, -39, 52, 72, -38, 52, Blocks.STONE_BRICKS.getDefaultState());
        structure.fillWithBlocks(world, start, 71, -39, 55, 71, -39, 55, Blocks.MOSSY_COBBLESTONE.getDefaultState());
        structure.fillWithBlocks(world, start, 71, -39, 56, 71, -38, 56, Blocks.STONE_BRICKS.getDefaultState());
        structure.fillWithBlocks(world, start, 71, -39, 57, 71, -39, 58, Blocks.MOSSY_COBBLESTONE.getDefaultState());
        structure.fillWithBlocks(world, start, 71, -39, 61, 72, -39, 63, Blocks.STONE_BRICKS.getDefaultState());
        structure.fillWithBlocks(world, start, 71, -39, 64, 71, -38, 64, Blocks.AIR.getDefaultState());
        structure.fillWithBlocks(world, start, 71, -39, 65, 72, -39, 65, Blocks.MOSSY_STONE_BRICKS.getDefaultState());
        structure.fillWithBlocks(world, start, 71, -38, 8, 71, -38, 9, Blocks.STONE_BRICKS.getDefaultState());
        structure.fillWithBlocks(world, start, 71, -38, 11, 71, -38, 13, Blocks.STONE_BRICKS.getDefaultState());
        structure.fillWithBlocks(world, start, 71, -38, 14, 71, -38, 14, Blocks.MOSSY_COBBLESTONE.getDefaultState());
        structure.fillWithBlocks(world, start, 71, -38, 17, 71, -38, 18, Blocks.MOSSY_STONE_BRICKS.getDefaultState());
        structure.fillWithBlocks(world, start, 71, -38, 19, 71, -38, 20, Blocks.STONE_BRICKS.getDefaultState());
        structure.fillWithBlocks(world, start, 71, -38, 25, 73, -38, 29, Blocks.STONE_BRICKS.getDefaultState());
        structure.fillWithBlocks(world, start, 71, -38, 32, 71, -38, 33, Blocks.STONE_BRICKS.getDefaultState());
        structure.fillWithBlocks(world, start, 71, -38, 37, 71, -37, 38, Blocks.STONE_BRICKS.getDefaultState());
        structure.fillWithBlocks(world, start, 71, -38, 39, 71, -38, 40, Blocks.MOSSY_COBBLESTONE.getDefaultState());
        structure.fillWithBlocks(world, start, 71, -38, 51, 71, -37, 51, Blocks.AIR.getDefaultState());
        structure.fillWithBlocks(world, start, 71, -38, 58, 71, -38, 59, Blocks.MOSSY_STONE_BRICKS.getDefaultState());
        structure.fillWithBlocks(world, start, 71, -38, 60, 71, -38, 61, Blocks.AIR.getDefaultState());
        structure.fillWithBlocks(world, start, 71, -38, 63, 71, -38, 63, Blocks.STONE_BRICKS.getDefaultState());
        structure.fillWithBlocks(world, start, 71, -37, 6, 71, -37, 7, Blocks.STONE_BRICKS.getDefaultState());
        structure.fillWithBlocks(world, start, 71, -37, 8, 71, -36, 8, Blocks.MOSSY_STONE_BRICKS.getDefaultState());
        structure.fillWithBlocks(world, start, 71, -37, 9, 72, -37, 10, Blocks.STONE_BRICKS.getDefaultState());
        structure.fillWithBlocks(world, start, 71, -37, 11, 71, -37, 11, Blocks.MOSSY_STONE_BRICKS.getDefaultState());
        structure.fillWithBlocks(world, start, 71, -37, 14, 71, -36, 16, Blocks.MOSSY_STONE_BRICKS.getDefaultState());
        structure.fillWithBlocks(world, start, 71, -37, 21, 71, -37, 21, Blocks.STONE_BRICKS.getDefaultState());
        structure.fillWithBlocks(world, start, 71, -37, 23, 73, -37, 23, Blocks.STONE_BRICKS.getDefaultState());
        structure.fillWithBlocks(world, start, 71, -37, 24, 72, -37, 24, Blocks.MOSSY_STONE_BRICKS.getDefaultState());
        structure.fillWithBlocks(world, start, 71, -37, 25, 71, -37, 26, Blocks.AIR.getDefaultState());
        structure.fillWithBlocks(world, start, 71, -37, 32, 71, -37, 35, Blocks.STONE_BRICKS.getDefaultState());
        structure.fillWithBlocks(world, start, 71, -37, 36, 71, -36, 36, Blocks.MOSSY_COBBLESTONE.getDefaultState());
        structure.fillWithBlocks(world, start, 71, -37, 40, 71, -36, 40, Blocks.MOSSY_STONE_BRICKS.getDefaultState());
        structure.fillWithBlocks(world, start, 71, -37, 53, 71, -36, 53, Blocks.MOSSY_STONE_BRICKS.getDefaultState());
        structure.fillWithBlocks(world, start, 71, -37, 55, 71, -37, 56, Blocks.MOSSY_STONE_BRICKS.getDefaultState());
        structure.fillWithBlocks(world, start, 71, -37, 57, 71, -37, 57, Blocks.STONE_BRICKS.getDefaultState());
        structure.fillWithBlocks(world, start, 71, -37, 59, 71, -36, 60, Blocks.MOSSY_STONE_BRICKS.getDefaultState());
        structure.fillWithBlocks(world, start, 71, -37, 61, 71, -37, 62, Blocks.MOSSY_STONE_BRICKS.getDefaultState());
        structure.fillWithBlocks(world, start, 71, -36, 6, 71, -36, 8, Blocks.MOSSY_STONE_BRICKS.getDefaultState());
        structure.fillWithBlocks(world, start, 71, -36, 10, 72, -36, 10, Blocks.MOSSY_STONE_BRICKS.getDefaultState());
        structure.fillWithBlocks(world, start, 71, -36, 11, 71, -36, 11, Blocks.STONE_BRICKS.getDefaultState());
        structure.fillWithBlocks(world, start, 71, -36, 17, 71, -36, 19, Blocks.STONE_BRICKS.getDefaultState());
        structure.fillWithBlocks(world, start, 71, -36, 20, 71, -36, 21, Blocks.MOSSY_STONE_BRICKS.getDefaultState());
        structure.fillWithBlocks(world, start, 71, -36, 22, 71, -36, 22, Blocks.STONE_BRICKS.getDefaultState());
        structure.fillWithBlocks(world, start, 71, -36, 23, 71, -36, 23, Blocks.MOSSY_STONE_BRICKS.getDefaultState());
        structure.fillWithBlocks(world, start, 71, -36, 25, 71, -36, 26, Blocks.STONE_BRICKS.getDefaultState());
        structure.fillWithBlocks(world, start, 71, -36, 30, 72, -36, 30, Blocks.MOSSY_STONE_BRICKS.getDefaultState());
        structure.fillWithBlocks(world, start, 71, -36, 31, 71, -36, 31, Blocks.STONE_BRICKS.getDefaultState());
        structure.fillWithBlocks(world, start, 71, -36, 33, 72, -36, 33, Blocks.MOSSY_STONE_BRICKS.getDefaultState());
        structure.fillWithBlocks(world, start, 71, -36, 35, 72, -36, 35, Blocks.STONE_BRICKS.getDefaultState());
        structure.fillWithBlocks(world, start, 71, -36, 37, 72, -36, 37, Blocks.STONE_BRICKS.getDefaultState());
        structure.fillWithBlocks(world, start, 71, -36, 39, 75, -36, 39, Blocks.STONE_BRICKS.getDefaultState());
        structure.fillWithBlocks(world, start, 71, -36, 52, 71, -36, 53, Blocks.MOSSY_STONE_BRICKS.getDefaultState());
        structure.fillWithBlocks(world, start, 71, -36, 54, 71, -36, 56, Blocks.STONE_BRICKS.getDefaultState());
        structure.fillWithBlocks(world, start, 71, -36, 58, 71, -36, 58, Blocks.STONE_BRICKS.getDefaultState());
        structure.fillWithBlocks(world, start, 71, -36, 62, 71, -36, 63, Blocks.MOSSY_STONE_BRICKS.getDefaultState());
        structure.fillWithBlocks(world, start, 71, -25, 44, 73, -25, 47, Blocks.STONE_BRICKS.getDefaultState());
        structure.fillWithBlocks(world, start, 71, -24, 43, 71, -23, 44, Blocks.STONE_BRICKS.getDefaultState());
        structure.fillWithBlocks(world, start, 71, -24, 45, 73, -24, 47, Blocks.AIR.getDefaultState());
        structure.fillWithBlocks(world, start, 71, -24, 48, 71, -21, 48, Blocks.STONE_BRICKS.getDefaultState());
        structure.fillWithBlocks(world, start, 71, -24, 76, 71, -23, 76, Blocks.STONE_BRICKS.getDefaultState());
        structure.fillWithBlocks(world, start, 71, -24, 77, 73, -24, 79, Blocks.AIR.getDefaultState());
        structure.fillWithBlocks(world, start, 71, -24, 80, 71, -23, 80, Blocks.STONE_BRICKS.getDefaultState());
        structure.fillWithBlocks(world, start, 71, -23, 45, 73, -23, 47, Blocks.AIR.getDefaultState());
        structure.fillWithBlocks(world, start, 71, -23, 77, 73, -23, 79, Blocks.AIR.getDefaultState());
        structure.fillWithBlocks(world, start, 71, -22, 43, 73, -22, 43, Blocks.STONE_BRICKS.getDefaultState());
        structure.fillWithBlocks(world, start, 71, -22, 45, 73, -22, 47, Blocks.AIR.getDefaultState());
        structure.fillWithBlocks(world, start, 71, -22, 76, 71, -21, 76, Blocks.CRACKED_STONE_BRICKS.getDefaultState());
        structure.fillWithBlocks(world, start, 71, -22, 77, 73, -22, 79, Blocks.AIR.getDefaultState());
        structure.fillWithBlocks(world, start, 71, -22, 80, 71, -22, 80, Blocks.CRACKED_STONE_BRICKS.getDefaultState());
        structure.fillWithBlocks(world, start, 71, -21, 44, 72, -21, 45, Blocks.STONE_BRICKS.getDefaultState());
        structure.fillWithBlocks(world, start, 71, -21, 77, 72, -21, 78, Blocks.STONE_BRICKS.getDefaultState());
        structure.fillWithBlocks(world, start, 71, -21, 79, 71, -21, 80, Blocks.STONE_BRICKS.getDefaultState());
        structure.fillWithBlocks(world, start, 71, -15, 33, 71, -10, 33, Blocks.STONE_BRICKS.getDefaultState());
        structure.fillWithBlocks(world, start, 71, -15, 36, 71, -14, 40, Blocks.STONE_BRICKS.getDefaultState());
        structure.fillWithBlocks(world, start, 71, -15, 52, 71, -14, 56, Blocks.STONE_BRICKS.getDefaultState());
        structure.fillWithBlocks(world, start, 71, -15, 58, 71, -13, 60, Blocks.STONE_BRICKS.getDefaultState());
        structure.fillWithBlocks(world, start, 71, -14, 34, 71, -13, 35, Blocks.STONE_BRICKS.getDefaultState());
        structure.fillWithBlocks(world, start, 71, -14, 43, 71, -13, 44, Blocks.STONE_BRICKS.getDefaultState());
        structure.fillWithBlocks(world, start, 71, -14, 48, 71, -14, 49, Blocks.STONE_BRICKS.getDefaultState());
        structure.fillWithBlocks(world, start, 71, -14, 57, 71, -11, 60, Blocks.STONE_BRICKS.getDefaultState());
        structure.fillWithBlocks(world, start, 71, -13, 37, 71, -10, 40, Blocks.STONE_BRICKS.getDefaultState());
        structure.fillWithBlocks(world, start, 71, -13, 48, 71, -13, 49, Blocks.STONE_BRICKS.getDefaultState());
        structure.fillWithBlocks(world, start, 71, -13, 53, 71, -13, 55, Blocks.STONE_BRICKS.getDefaultState());
        structure.fillWithBlocks(world, start, 71, -12, 34, 71, -11, 40, Blocks.STONE_BRICKS.getDefaultState());
        structure.fillWithBlocks(world, start, 71, -12, 44, 71, -11, 44, Blocks.STONE_BRICKS.getDefaultState());
        structure.fillWithBlocks(world, start, 71, -12, 48, 71, -12, 49, Blocks.STONE_BRICKS.getDefaultState());
        structure.fillWithBlocks(world, start, 71, -12, 53, 71, -10, 53, Blocks.STONE_BRICKS.getDefaultState());
        structure.fillWithBlocks(world, start, 71, -12, 55, 71, -10, 60, Blocks.STONE_BRICKS.getDefaultState());
        structure.fillWithBlocks(world, start, 71, -11, 47, 72, -11, 48, Blocks.STONE_BRICKS.getDefaultState());
        structure.fillWithBlocks(world, start, 71, -11, 52, 71, -10, 60, Blocks.STONE_BRICKS.getDefaultState());
        structure.fillWithBlocks(world, start, 71, -10, 35, 71, -10, 40, Blocks.STONE_BRICKS.getDefaultState());
        structure.fillWithBlocks(world, start, 71, 0, 88, 72, 0, 89, Blocks.STONE.getDefaultState());
        structure.fillWithBlocks(world, start, 71, 0, 93, 75, 0, 93, Blocks.DIRT.getDefaultState());
        structure.fillWithBlocks(world, start, 71, 0, 94, 72, 0, 95, Blocks.GRASS_BLOCK.getDefaultState().with(SnowyDirtBlock.SNOWY, false));
        structure.fillWithBlocks(world, start, 71, 1, 6, 76, 1, 6, Blocks.GRASS_BLOCK.getDefaultState().with(SnowyDirtBlock.SNOWY, false));
        structure.fillWithBlocks(world, start, 71, 1, 7, 72, 1, 8, Blocks.DIRT.getDefaultState());
        structure.fillWithBlocks(world, start, 71, 1, 79, 77, 1, 86, Blocks.STONE.getDefaultState());
        structure.fillWithBlocks(world, start, 71, 1, 87, 73, 1, 87, Blocks.STONE.getDefaultState());
        structure.fillWithBlocks(world, start, 71, 1, 88, 74, 1, 91, Blocks.DIRT.getDefaultState());
        structure.fillWithBlocks(world, start, 71, 1, 93, 75, 1, 93, Blocks.GRASS_BLOCK.getDefaultState().with(SnowyDirtBlock.SNOWY, false));
        structure.fillWithBlocks(world, start, 71, 2, 7, 75, 2, 7, Blocks.GRASS_BLOCK.getDefaultState().with(SnowyDirtBlock.SNOWY, false));
        structure.fillWithBlocks(world, start, 71, 2, 11, 72, 2, 13, Blocks.DIRT.getDefaultState());
        structure.fillWithBlocks(world, start, 71, 2, 18, 71, 2, 18, Blocks.STONE.getDefaultState());
        structure.fillWithBlocks(world, start, 71, 2, 19, 71, 2, 22, Blocks.COARSE_DIRT.getDefaultState());
        structure.fillWithBlocks(world, start, 71, 6, 18, 75, 6, 22, Blocks.DIRT.getDefaultState());
        structure.fillWithBlocks(world, start, 71, 7, 18, 75, 7, 22, Blocks.GRASS_BLOCK.getDefaultState().with(SnowyDirtBlock.SNOWY, false));
        structure.fillWithBlocks(world, start, 71, 8, 18, 71, 8, 18, Blocks.GRASS.getDefaultState());
        structure.fillWithBlocks(world, start, 71, 8, 20, 72, 8, 21, Blocks.GRASS.getDefaultState());
        structure.fillWithBlocks(world, start, 71, 8, 24, 73, 8, 26, Blocks.STONE_BRICKS.getDefaultState());
        structure.fillWithBlocks(world, start, 71, 8, 27, 74, 8, 67, Blocks.STONE.getDefaultState());
        structure.fillWithBlocks(world, start, 71, 8, 68, 73, 8, 70, Blocks.STONE_BRICKS.getDefaultState());
        structure.fillWithBlocks(world, start, 71, 8, 72, 73, 8, 74, Blocks.GRASS.getDefaultState());
        structure.fillWithBlocks(world, start, 71, 8, 75, 71, 8, 76, Blocks.GRASS.getDefaultState());
        structure.fillWithBlocks(world, start, 71, 9, 25, 72, 9, 26, Blocks.STONE_BRICKS.getDefaultState());
        structure.fillWithBlocks(world, start, 71, 9, 27, 74, 9, 67, Blocks.STONE.getDefaultState());
        structure.fillWithBlocks(world, start, 71, 9, 68, 72, 9, 69, Blocks.STONE_BRICKS.getDefaultState());
        structure.fillWithBlocks(world, start, 71, 10, 27, 74, 10, 67, Blocks.STONE.getDefaultState());
        structure.fillWithBlocks(world, start, 71, 11, 27, 74, 11, 67, Blocks.STONE.getDefaultState());
        structure.fillWithBlocks(world, start, 71, 14, 28, 72, 14, 29, Blocks.STONE_BRICKS.getDefaultState());
        structure.fillWithBlocks(world, start, 71, 14, 66, 73, 14, 66, Blocks.STONE_BRICKS.getDefaultState());
        structure.fillWithBlocks(world, start, 71, 15, 31, 71, 15, 42, Blocks.STONE_BRICK_STAIRS.getDefaultState().with(StairsBlock.FACING, Direction.WEST).with(StairsBlock.WATERLOGGED, false).with(StairsBlock.SHAPE, StairsShape.STRAIGHT).with(StairsBlock.HALF, Half.BOTTOM));
        structure.fillWithBlocks(world, start, 71, 15, 43, 72, 15, 51, Blocks.STONE_BRICKS.getDefaultState());
        structure.fillWithBlocks(world, start, 71, 15, 52, 71, 15, 63, Blocks.STONE_BRICK_STAIRS.getDefaultState().with(StairsBlock.FACING, Direction.WEST).with(StairsBlock.WATERLOGGED, false).with(StairsBlock.SHAPE, StairsShape.STRAIGHT).with(StairsBlock.HALF, Half.BOTTOM));
        structure.fillWithBlocks(world, start, 71, 16, 32, 71, 16, 33, Blocks.STONE_BRICK_STAIRS.getDefaultState().with(StairsBlock.FACING, Direction.WEST).with(StairsBlock.WATERLOGGED, false).with(StairsBlock.SHAPE, StairsShape.STRAIGHT).with(StairsBlock.HALF, Half.TOP));
        structure.fillWithBlocks(world, start, 71, 16, 34, 71, 16, 35, Blocks.STONE_BRICKS.getDefaultState());
        structure.fillWithBlocks(world, start, 71, 16, 36, 71, 16, 37, Blocks.STONE_BRICK_STAIRS.getDefaultState().with(StairsBlock.FACING, Direction.WEST).with(StairsBlock.WATERLOGGED, false).with(StairsBlock.SHAPE, StairsShape.STRAIGHT).with(StairsBlock.HALF, Half.TOP));
        structure.fillWithBlocks(world, start, 71, 16, 38, 71, 16, 39, Blocks.STONE_BRICKS.getDefaultState());
        structure.fillWithBlocks(world, start, 71, 16, 40, 71, 16, 41, Blocks.STONE_BRICK_STAIRS.getDefaultState().with(StairsBlock.FACING, Direction.WEST).with(StairsBlock.WATERLOGGED, false).with(StairsBlock.SHAPE, StairsShape.STRAIGHT).with(StairsBlock.HALF, Half.TOP));
        structure.fillWithBlocks(world, start, 71, 16, 42, 71, 16, 52, Blocks.STONE_BRICKS.getDefaultState());
        structure.fillWithBlocks(world, start, 71, 16, 53, 71, 16, 54, Blocks.STONE_BRICK_STAIRS.getDefaultState().with(StairsBlock.FACING, Direction.WEST).with(StairsBlock.WATERLOGGED, false).with(StairsBlock.SHAPE, StairsShape.STRAIGHT).with(StairsBlock.HALF, Half.TOP));
        structure.fillWithBlocks(world, start, 71, 16, 55, 71, 16, 56, Blocks.STONE_BRICKS.getDefaultState());
        structure.fillWithBlocks(world, start, 71, 16, 57, 71, 16, 58, Blocks.STONE_BRICK_STAIRS.getDefaultState().with(StairsBlock.FACING, Direction.WEST).with(StairsBlock.WATERLOGGED, false).with(StairsBlock.SHAPE, StairsShape.STRAIGHT).with(StairsBlock.HALF, Half.TOP));
        structure.fillWithBlocks(world, start, 71, 16, 59, 71, 16, 60, Blocks.STONE_BRICKS.getDefaultState());
        structure.fillWithBlocks(world, start, 71, 16, 61, 71, 16, 62, Blocks.STONE_BRICK_STAIRS.getDefaultState().with(StairsBlock.FACING, Direction.WEST).with(StairsBlock.WATERLOGGED, false).with(StairsBlock.SHAPE, StairsShape.STRAIGHT).with(StairsBlock.HALF, Half.TOP));
        structure.fillWithBlocks(world, start, 71, 17, 44, 71, 17, 50, Blocks.STONE_BRICK_STAIRS.getDefaultState().with(StairsBlock.FACING, Direction.WEST).with(StairsBlock.WATERLOGGED, false).with(StairsBlock.SHAPE, StairsShape.STRAIGHT).with(StairsBlock.HALF, Half.BOTTOM));
        structure.fillWithBlocks(world, start, 72, -58, 59, 72, -58, 61, Blocks.STONE_BRICKS.getDefaultState());
        structure.fillWithBlocks(world, start, 72, -57, -44, 74, -56, -44, Blocks.STONE_BRICKS.getDefaultState());
        structure.fillWithBlocks(world, start, 72, -57, 46, 73, -57, 48, Blocks.AIR.getDefaultState());
        structure.fillWithBlocks(world, start, 72, -57, 54, 73, -57, 56, Blocks.AIR.getDefaultState());
        structure.fillWithBlocks(world, start, 72, -56, -50, 72, -52, -46, Blocks.AIR.getDefaultState());
        structure.fillWithBlocks(world, start, 72, -56, 44, 72, -56, 45, Blocks.STONE_BRICKS.getDefaultState());
        structure.fillWithBlocks(world, start, 72, -56, 46, 74, -56, 48, Blocks.AIR.getDefaultState());
        structure.fillWithBlocks(world, start, 72, -56, 49, 72, -46, 49, Blocks.STONE_BRICKS.getDefaultState());
        structure.fillWithBlocks(world, start, 72, -56, 51, 72, -55, 53, Blocks.STONE_BRICKS.getDefaultState());
        structure.fillWithBlocks(world, start, 72, -56, 54, 74, -56, 56, Blocks.AIR.getDefaultState());
        structure.fillWithBlocks(world, start, 72, -55, -55, 72, -55, -53, Blocks.STONE_BRICKS.getDefaultState());
        structure.fillWithBlocks(world, start, 72, -55, 41, 79, -55, 41, Blocks.STONE_BRICKS.getDefaultState());
        structure.fillWithBlocks(world, start, 72, -55, 42, 72, -55, 44, Blocks.STONE_BRICK_STAIRS.getDefaultState().with(StairsBlock.FACING, Direction.WEST).with(StairsBlock.WATERLOGGED, false).with(StairsBlock.SHAPE, StairsShape.STRAIGHT).with(StairsBlock.HALF, Half.BOTTOM));
        structure.fillWithBlocks(world, start, 72, -55, 58, 72, -55, 60, Blocks.STONE_BRICK_STAIRS.getDefaultState().with(StairsBlock.FACING, Direction.WEST).with(StairsBlock.WATERLOGGED, false).with(StairsBlock.SHAPE, StairsShape.STRAIGHT).with(StairsBlock.HALF, Half.BOTTOM));
        structure.fillWithBlocks(world, start, 72, -55, 75, 72, -55, 85, Blocks.STONE_BRICKS.getDefaultState());
        structure.fillWithBlocks(world, start, 72, -54, -55, 72, -46, -55, Blocks.STONE_BRICKS.getDefaultState());
        structure.fillWithBlocks(world, start, 72, -54, -41, 72, -54, -40, Blocks.STONE_BRICKS.getDefaultState());
        structure.fillWithBlocks(world, start, 72, -54, -39, 72, -52, -37, Blocks.AIR.getDefaultState());
        structure.fillWithBlocks(world, start, 72, -54, -36, 72, -54, -36, Blocks.STONE_BRICKS.getDefaultState());
        structure.fillWithBlocks(world, start, 72, -54, -35, 72, -52, -35, Blocks.AIR.getDefaultState());
        structure.fillWithBlocks(world, start, 72, -54, -34, 72, -54, -34, Blocks.STONE_BRICKS.getDefaultState());
        structure.fillWithBlocks(world, start, 72, -54, -33, 72, -52, -31, Blocks.AIR.getDefaultState());
        structure.fillWithBlocks(world, start, 72, -54, -30, 72, -54, -30, Blocks.STONE_BRICKS.getDefaultState());
        structure.fillWithBlocks(world, start, 72, -54, -29, 72, -52, -27, Blocks.AIR.getDefaultState());
        structure.fillWithBlocks(world, start, 72, -54, -26, 72, -54, -26, Blocks.STONE_BRICKS.getDefaultState());
        structure.fillWithBlocks(world, start, 72, -54, -25, 72, -52, -23, Blocks.AIR.getDefaultState());
        structure.fillWithBlocks(world, start, 72, -54, -22, 72, -54, -22, Blocks.STONE_BRICKS.getDefaultState());
        structure.fillWithBlocks(world, start, 72, -54, -21, 72, -52, -19, Blocks.AIR.getDefaultState());
        structure.fillWithBlocks(world, start, 72, -54, -18, 72, -54, -18, Blocks.STONE_BRICKS.getDefaultState());
        structure.fillWithBlocks(world, start, 72, -54, -17, 72, -52, -17, Blocks.AIR.getDefaultState());
        structure.fillWithBlocks(world, start, 72, -54, -16, 72, -49, -16, Blocks.STONE_BRICKS.getDefaultState());
        structure.fillWithBlocks(world, start, 72, -54, -15, 74, -54, -13, Blocks.AIR.getDefaultState());
        structure.fillWithBlocks(world, start, 72, -54, -12, 72, -45, -12, Blocks.STONE_BRICKS.getDefaultState());
        structure.fillWithBlocks(world, start, 72, -54, -11, 72, -52, -11, Blocks.AIR.getDefaultState());
        structure.fillWithBlocks(world, start, 72, -54, -10, 72, -54, -10, Blocks.STONE_BRICKS.getDefaultState());
        structure.fillWithBlocks(world, start, 72, -54, -9, 72, -52, -7, Blocks.AIR.getDefaultState());
        structure.fillWithBlocks(world, start, 72, -54, -6, 72, -54, -6, Blocks.STONE_BRICKS.getDefaultState());
        structure.fillWithBlocks(world, start, 72, -54, -5, 72, -52, -5, Blocks.AIR.getDefaultState());
        structure.fillWithBlocks(world, start, 72, -54, -4, 72, -54, -4, Blocks.STONE_BRICKS.getDefaultState());
        structure.fillWithBlocks(world, start, 72, -54, -3, 72, -52, -1, Blocks.AIR.getDefaultState());
        structure.fillWithBlocks(world, start, 72, -54, 0, 72, -54, 0, Blocks.STONE_BRICKS.getDefaultState());
        structure.fillWithBlocks(world, start, 72, -54, 1, 72, -52, 1, Blocks.AIR.getDefaultState());
        structure.fillWithBlocks(world, start, 72, -54, 2, 72, -54, 2, Blocks.STONE_BRICKS.getDefaultState());
        structure.fillWithBlocks(world, start, 72, -54, 3, 72, -52, 5, Blocks.AIR.getDefaultState());
        structure.fillWithBlocks(world, start, 72, -54, 6, 72, -54, 8, Blocks.STONE_BRICKS.getDefaultState());
        structure.fillWithBlocks(world, start, 72, -54, 12, 73, -54, 14, Blocks.AIR.getDefaultState());
        structure.fillWithBlocks(world, start, 72, -54, 16, 72, -54, 16, Blocks.STONE_BRICKS.getDefaultState());
        structure.fillWithBlocks(world, start, 72, -54, 20, 72, -54, 20, Blocks.STONE_BRICKS.getDefaultState());
        structure.fillWithBlocks(world, start, 72, -54, 21, 72, -52, 23, Blocks.AIR.getDefaultState());
        structure.fillWithBlocks(world, start, 72, -54, 24, 72, -54, 24, Blocks.STONE_BRICKS.getDefaultState());
        structure.fillWithBlocks(world, start, 72, -54, 25, 72, -52, 25, Blocks.AIR.getDefaultState());
        structure.fillWithBlocks(world, start, 72, -54, 26, 72, -54, 26, Blocks.STONE_BRICKS.getDefaultState());
        structure.fillWithBlocks(world, start, 72, -54, 27, 72, -52, 29, Blocks.AIR.getDefaultState());
        structure.fillWithBlocks(world, start, 72, -54, 30, 72, -54, 30, Blocks.STONE_BRICKS.getDefaultState());
        structure.fillWithBlocks(world, start, 72, -54, 31, 72, -52, 31, Blocks.AIR.getDefaultState());
        structure.fillWithBlocks(world, start, 72, -54, 32, 72, -54, 32, Blocks.STONE_BRICKS.getDefaultState());
        structure.fillWithBlocks(world, start, 72, -54, 33, 72, -52, 35, Blocks.AIR.getDefaultState());
        structure.fillWithBlocks(world, start, 72, -54, 36, 72, -54, 36, Blocks.STONE_BRICKS.getDefaultState());
        structure.fillWithBlocks(world, start, 72, -54, 37, 72, -52, 39, Blocks.AIR.getDefaultState());
        structure.fillWithBlocks(world, start, 72, -54, 40, 72, -53, 41, Blocks.STONE_BRICKS.getDefaultState());
        structure.fillWithBlocks(world, start, 72, -54, 42, 74, -54, 44, Blocks.AIR.getDefaultState());
        structure.fillWithBlocks(world, start, 72, -54, 45, 72, -46, 45, Blocks.STONE_BRICKS.getDefaultState());
        structure.fillWithBlocks(world, start, 72, -54, 46, 74, -54, 48, Blocks.AIR.getDefaultState());
        structure.fillWithBlocks(world, start, 72, -54, 50, 74, -54, 52, Blocks.AIR.getDefaultState());
        structure.fillWithBlocks(world, start, 72, -54, 53, 72, -42, 53, Blocks.STONE_BRICKS.getDefaultState());
        structure.fillWithBlocks(world, start, 72, -54, 54, 74, -54, 56, Blocks.AIR.getDefaultState());
        structure.fillWithBlocks(world, start, 72, -54, 57, 72, -48, 57, Blocks.STONE_BRICKS.getDefaultState());
        structure.fillWithBlocks(world, start, 72, -54, 58, 74, -54, 60, Blocks.AIR.getDefaultState());
        structure.fillWithBlocks(world, start, 72, -54, 61, 72, -54, 62, Blocks.STONE_BRICKS.getDefaultState());
        structure.fillWithBlocks(world, start, 72, -54, 63, 72, -52, 65, Blocks.AIR.getDefaultState());
        structure.fillWithBlocks(world, start, 72, -54, 66, 72, -54, 66, Blocks.STONE_BRICKS.getDefaultState());
        structure.fillWithBlocks(world, start, 72, -54, 67, 72, -52, 67, Blocks.AIR.getDefaultState());
        structure.fillWithBlocks(world, start, 72, -54, 68, 72, -54, 68, Blocks.STONE_BRICKS.getDefaultState());
        structure.fillWithBlocks(world, start, 72, -54, 69, 72, -52, 71, Blocks.AIR.getDefaultState());
        structure.fillWithBlocks(world, start, 72, -54, 72, 72, -54, 75, Blocks.STONE_BRICKS.getDefaultState());
        structure.fillWithBlocks(world, start, 72, -54, 76, 73, -54, 82, Blocks.AIR.getDefaultState());
        structure.fillWithBlocks(world, start, 72, -54, 83, 72, -52, 85, Blocks.STONE_BRICKS.getDefaultState());
        structure.fillWithBlocks(world, start, 72, -53, -41, 72, -53, -40, Blocks.STONE_BRICKS.getDefaultState());
        structure.fillWithBlocks(world, start, 72, -53, -36, 72, -53, -36, Blocks.STONE_BRICKS.getDefaultState());
        structure.fillWithBlocks(world, start, 72, -53, -34, 72, -53, -34, Blocks.STONE_BRICKS.getDefaultState());
        structure.fillWithBlocks(world, start, 72, -53, -30, 72, -53, -30, Blocks.STONE_BRICKS.getDefaultState());
        structure.fillWithBlocks(world, start, 72, -53, -26, 72, -53, -26, Blocks.STONE_BRICKS.getDefaultState());
        structure.fillWithBlocks(world, start, 72, -53, -22, 72, -53, -22, Blocks.STONE_BRICKS.getDefaultState());
        structure.fillWithBlocks(world, start, 72, -53, -18, 72, -53, -18, Blocks.STONE_BRICKS.getDefaultState());
        structure.fillWithBlocks(world, start, 72, -53, -15, 74, -53, -13, Blocks.AIR.getDefaultState());
        structure.fillWithBlocks(world, start, 72, -53, -10, 72, -53, -10, Blocks.STONE_BRICKS.getDefaultState());
        structure.fillWithBlocks(world, start, 72, -53, -6, 72, -53, -6, Blocks.STONE_BRICKS.getDefaultState());
        structure.fillWithBlocks(world, start, 72, -53, -4, 72, -53, -4, Blocks.STONE_BRICKS.getDefaultState());
        structure.fillWithBlocks(world, start, 72, -53, 0, 72, -53, 0, Blocks.STONE_BRICKS.getDefaultState());
        structure.fillWithBlocks(world, start, 72, -53, 2, 72, -53, 2, Blocks.STONE_BRICKS.getDefaultState());
        structure.fillWithBlocks(world, start, 72, -53, 6, 74, -53, 8, Blocks.STONE_BRICKS.getDefaultState());
        structure.fillWithBlocks(world, start, 72, -53, 16, 72, -53, 16, Blocks.STONE_BRICKS.getDefaultState());
        structure.fillWithBlocks(world, start, 72, -53, 20, 72, -53, 20, Blocks.STONE_BRICKS.getDefaultState());
        structure.fillWithBlocks(world, start, 72, -53, 24, 72, -53, 24, Blocks.STONE_BRICKS.getDefaultState());
        structure.fillWithBlocks(world, start, 72, -53, 26, 72, -53, 26, Blocks.STONE_BRICKS.getDefaultState());
        structure.fillWithBlocks(world, start, 72, -53, 30, 72, -53, 30, Blocks.STONE_BRICKS.getDefaultState());
        structure.fillWithBlocks(world, start, 72, -53, 32, 72, -53, 32, Blocks.STONE_BRICKS.getDefaultState());
        structure.fillWithBlocks(world, start, 72, -53, 36, 72, -53, 36, Blocks.STONE_BRICKS.getDefaultState());
        structure.fillWithBlocks(world, start, 72, -53, 42, 74, -53, 44, Blocks.AIR.getDefaultState());
        structure.fillWithBlocks(world, start, 72, -53, 46, 74, -53, 48, Blocks.AIR.getDefaultState());
        structure.fillWithBlocks(world, start, 72, -53, 50, 74, -53, 52, Blocks.AIR.getDefaultState());
        structure.fillWithBlocks(world, start, 72, -53, 54, 74, -53, 56, Blocks.AIR.getDefaultState());
        structure.fillWithBlocks(world, start, 72, -53, 58, 74, -53, 60, Blocks.AIR.getDefaultState());
        structure.fillWithBlocks(world, start, 72, -53, 61, 72, -53, 62, Blocks.STONE_BRICKS.getDefaultState());
        structure.fillWithBlocks(world, start, 72, -53, 66, 72, -53, 66, Blocks.STONE_BRICKS.getDefaultState());
        structure.fillWithBlocks(world, start, 72, -53, 68, 72, -53, 68, Blocks.STONE_BRICKS.getDefaultState());
        structure.fillWithBlocks(world, start, 72, -53, 72, 72, -53, 75, Blocks.STONE_BRICKS.getDefaultState());
        structure.fillWithBlocks(world, start, 72, -52, -58, 74, -52, -56, Blocks.STONE_BRICKS.getDefaultState());
        structure.fillWithBlocks(world, start, 72, -52, -41, 72, -52, -40, Blocks.STONE_BRICKS.getDefaultState());
        structure.fillWithBlocks(world, start, 72, -52, -36, 72, -52, -36, Blocks.STONE_BRICKS.getDefaultState());
        structure.fillWithBlocks(world, start, 72, -52, -34, 72, -52, -34, Blocks.STONE_BRICKS.getDefaultState());
        structure.fillWithBlocks(world, start, 72, -52, -30, 72, -51, -30, Blocks.STONE_BRICKS.getDefaultState());
        structure.fillWithBlocks(world, start, 72, -52, -26, 72, -52, -26, Blocks.STONE_BRICKS.getDefaultState());
        structure.fillWithBlocks(world, start, 72, -52, -22, 72, -52, -22, Blocks.STONE_BRICKS.getDefaultState());
        structure.fillWithBlocks(world, start, 72, -52, -18, 72, -52, -18, Blocks.STONE_BRICKS.getDefaultState());
        structure.fillWithBlocks(world, start, 72, -52, -15, 74, -52, -13, Blocks.AIR.getDefaultState());
        structure.fillWithBlocks(world, start, 72, -52, -10, 72, -52, -10, Blocks.STONE_BRICKS.getDefaultState());
        structure.fillWithBlocks(world, start, 72, -52, -6, 72, -52, -6, Blocks.STONE_BRICKS.getDefaultState());
        structure.fillWithBlocks(world, start, 72, -52, -4, 72, -52, -4, Blocks.STONE_BRICKS.getDefaultState());
        structure.fillWithBlocks(world, start, 72, -52, 0, 72, -51, 0, Blocks.STONE_BRICKS.getDefaultState());
        structure.fillWithBlocks(world, start, 72, -52, 2, 72, -51, 2, Blocks.STONE_BRICKS.getDefaultState());
        structure.fillWithBlocks(world, start, 72, -52, 6, 74, -52, 8, Blocks.STONE_BRICKS.getDefaultState());
        structure.fillWithBlocks(world, start, 72, -52, 9, 72, -52, 15, Blocks.AIR.getDefaultState());
        structure.fillWithBlocks(world, start, 72, -52, 16, 72, -52, 16, Blocks.STONE_BRICKS.getDefaultState());
        structure.fillWithBlocks(world, start, 72, -52, 20, 72, -52, 20, Blocks.STONE_BRICKS.getDefaultState());
        structure.fillWithBlocks(world, start, 72, -52, 24, 72, -52, 24, Blocks.STONE_BRICKS.getDefaultState());
        structure.fillWithBlocks(world, start, 72, -52, 26, 72, -52, 26, Blocks.STONE_BRICKS.getDefaultState());
        structure.fillWithBlocks(world, start, 72, -52, 30, 72, -52, 30, Blocks.STONE_BRICKS.getDefaultState());
        structure.fillWithBlocks(world, start, 72, -52, 32, 72, -52, 32, Blocks.STONE_BRICKS.getDefaultState());
        structure.fillWithBlocks(world, start, 72, -52, 36, 72, -52, 36, Blocks.STONE_BRICKS.getDefaultState());
        structure.fillWithBlocks(world, start, 72, -52, 40, 72, -51, 41, Blocks.STONE_BRICKS.getDefaultState());
        structure.fillWithBlocks(world, start, 72, -52, 42, 74, -52, 44, Blocks.AIR.getDefaultState());
        structure.fillWithBlocks(world, start, 72, -52, 46, 74, -52, 48, Blocks.AIR.getDefaultState());
        structure.fillWithBlocks(world, start, 72, -52, 50, 74, -52, 52, Blocks.AIR.getDefaultState());
        structure.fillWithBlocks(world, start, 72, -52, 54, 74, -52, 56, Blocks.AIR.getDefaultState());
        structure.fillWithBlocks(world, start, 72, -52, 58, 74, -52, 60, Blocks.AIR.getDefaultState());
        structure.fillWithBlocks(world, start, 72, -52, 61, 72, -52, 62, Blocks.STONE_BRICKS.getDefaultState());
        structure.fillWithBlocks(world, start, 72, -52, 66, 72, -51, 66, Blocks.STONE_BRICKS.getDefaultState());
        structure.fillWithBlocks(world, start, 72, -52, 68, 72, -51, 68, Blocks.STONE_BRICKS.getDefaultState());
        structure.fillWithBlocks(world, start, 72, -52, 72, 72, -52, 75, Blocks.STONE_BRICKS.getDefaultState());
        structure.fillWithBlocks(world, start, 72, -51, -41, 72, -51, 8, Blocks.STONE_BRICKS.getDefaultState());
        structure.fillWithBlocks(world, start, 72, -51, 9, 72, -51, 15, Blocks.AIR.getDefaultState());
        structure.fillWithBlocks(world, start, 72, -51, 16, 74, -51, 18, Blocks.STONE_BRICKS.getDefaultState());
        structure.fillWithBlocks(world, start, 72, -51, 20, 72, -51, 75, Blocks.STONE_BRICKS.getDefaultState());
        structure.fillWithBlocks(world, start, 72, -51, 83, 74, -51, 85, Blocks.STONE_BRICKS.getDefaultState());
        structure.fillWithBlocks(world, start, 72, -50, -41, 72, -50, -38, Blocks.STONE_BRICKS.getDefaultState());
        structure.fillWithBlocks(world, start, 72, -50, 12, 73, -50, 14, Blocks.AIR.getDefaultState());
        structure.fillWithBlocks(world, start, 72, -50, 16, 74, -50, 18, Blocks.STONE_BRICKS.getDefaultState());
        structure.fillWithBlocks(world, start, 72, -50, 60, 72, -50, 61, Blocks.STONE_BRICKS.getDefaultState());
        structure.fillWithBlocks(world, start, 72, -50, 73, 76, -50, 85, Blocks.STONE_BRICKS.getDefaultState());
        structure.fillWithBlocks(world, start, 72, -49, -58, 73, -49, -57, Blocks.STONE_BRICKS.getDefaultState());
        structure.fillWithBlocks(world, start, 72, -49, -41, 72, -49, -39, Blocks.STONE_BRICKS.getDefaultState());
        structure.fillWithBlocks(world, start, 72, -49, -20, 75, -49, -17, Blocks.STONE_BRICKS.getDefaultState());
        structure.fillWithBlocks(world, start, 72, -49, 16, 73, -49, 18, Blocks.STONE_BRICKS.getDefaultState());
        structure.fillWithBlocks(world, start, 72, -49, 42, 73, -49, 45, Blocks.STONE_BRICKS.getDefaultState());
        structure.fillWithBlocks(world, start, 72, -49, 46, 72, -48, 50, Blocks.STONE_BRICKS.getDefaultState());
        structure.fillWithBlocks(world, start, 72, -49, 51, 72, -49, 51, Blocks.AIR.getDefaultState());
        structure.fillWithBlocks(world, start, 72, -49, 52, 72, -49, 61, Blocks.STONE_BRICKS.getDefaultState());
        structure.fillWithBlocks(world, start, 72, -48, -54, 77, -48, -49, Blocks.STONE_BRICKS.getDefaultState());
        structure.fillWithBlocks(world, start, 72, -48, -39, 73, -48, -38, Blocks.STONE_BRICKS.getDefaultState());
        structure.fillWithBlocks(world, start, 72, -48, -20, 72, -46, -17, Blocks.STONE_BRICKS.getDefaultState());
        structure.fillWithBlocks(world, start, 72, -48, -16, 73, -48, -16, Blocks.AIR.getDefaultState());
        structure.fillWithBlocks(world, start, 72, -48, -15, 76, -48, -11, Blocks.STONE_BRICKS.getDefaultState());
        structure.fillWithBlocks(world, start, 72, -48, 9, 72, -48, 15, Blocks.AIR.getDefaultState());
        structure.fillWithBlocks(world, start, 72, -48, 16, 74, -48, 18, Blocks.STONE_BRICKS.getDefaultState());
        structure.fillWithBlocks(world, start, 72, -48, 54, 75, -48, 57, Blocks.STONE_BRICKS.getDefaultState());
        structure.fillWithBlocks(world, start, 72, -48, 59, 72, -48, 61, Blocks.STONE_BRICKS.getDefaultState());
        structure.fillWithBlocks(world, start, 72, -48, 62, 74, -48, 62, Blocks.MOSSY_COBBLESTONE.getDefaultState());
        structure.fillWithBlocks(world, start, 72, -48, 73, 72, -47, 73, Blocks.AIR.getDefaultState());
        structure.fillWithBlocks(world, start, 72, -48, 80, 76, -48, 85, Blocks.STONE_BRICKS.getDefaultState());
        structure.fillWithBlocks(world, start, 72, -47, 9, 72, -47, 15, Blocks.AIR.getDefaultState());
        structure.fillWithBlocks(world, start, 72, -47, 16, 74, -47, 18, Blocks.STONE_BRICKS.getDefaultState());
        structure.fillWithBlocks(world, start, 72, -47, 42, 74, -47, 46, Blocks.STONE_BRICKS.getDefaultState());
        structure.fillWithBlocks(world, start, 72, -47, 54, 72, -47, 55, Blocks.STONE_BRICKS.getDefaultState());
        structure.fillWithBlocks(world, start, 72, -47, 59, 72, -46, 61, Blocks.AIR.getDefaultState());
        structure.fillWithBlocks(world, start, 72, -47, 74, 73, -47, 75, Blocks.STONE_BRICKS.getDefaultState());
        structure.fillWithBlocks(world, start, 72, -47, 77, 76, -47, 82, Blocks.STONE_BRICKS.getDefaultState());
        structure.fillWithBlocks(world, start, 72, -47, 83, 74, -47, 85, Blocks.STONE_BRICKS.getDefaultState());
        structure.fillWithBlocks(world, start, 72, -46, -58, 73, -46, -55, Blocks.STONE_BRICKS.getDefaultState());
        structure.fillWithBlocks(world, start, 72, -46, -44, 75, -46, -38, Blocks.STONE_BRICKS.getDefaultState());
        structure.fillWithBlocks(world, start, 72, -46, -11, 75, -46, -8, Blocks.STONE_BRICKS.getDefaultState());
        structure.fillWithBlocks(world, start, 72, -46, 12, 73, -46, 14, Blocks.AIR.getDefaultState());
        structure.fillWithBlocks(world, start, 72, -46, 16, 74, -46, 18, Blocks.STONE_BRICKS.getDefaultState());
        structure.fillWithBlocks(world, start, 72, -46, 44, 74, -46, 47, Blocks.STONE_BRICKS.getDefaultState());
        structure.fillWithBlocks(world, start, 72, -46, 54, 73, -46, 54, Blocks.MOSSY_COBBLESTONE.getDefaultState());
        structure.fillWithBlocks(world, start, 72, -46, 56, 73, -46, 61, Blocks.AIR.getDefaultState());
        structure.fillWithBlocks(world, start, 72, -46, 62, 72, -45, 62, Blocks.MOSSY_STONE_BRICKS.getDefaultState());
        structure.fillWithBlocks(world, start, 72, -46, 79, 75, -46, 82, Blocks.STONE_BRICKS.getDefaultState());
        structure.fillWithBlocks(world, start, 72, -45, -16, 72, -45, -15, Blocks.STONE_BRICKS.getDefaultState());
        structure.fillWithBlocks(world, start, 72, -45, -14, 72, -45, -13, Blocks.MOSSY_COBBLESTONE.getDefaultState());
        structure.fillWithBlocks(world, start, 72, -45, 11, 74, -45, 16, Blocks.STONE_BRICKS.getDefaultState());
        structure.fillWithBlocks(world, start, 72, -45, 17, 72, -45, 18, Blocks.STONE_BRICKS.getDefaultState());
        structure.fillWithBlocks(world, start, 72, -45, 23, 72, -45, 23, Blocks.MOSSY_STONE_BRICKS.getDefaultState());
        structure.fillWithBlocks(world, start, 72, -45, 25, 72, -45, 26, Blocks.MOSSY_COBBLESTONE.getDefaultState());
        structure.fillWithBlocks(world, start, 72, -45, 27, 72, -45, 27, Blocks.MOSSY_STONE_BRICKS.getDefaultState());
        structure.fillWithBlocks(world, start, 72, -45, 28, 72, -45, 28, Blocks.STONE_BRICKS.getDefaultState());
        structure.fillWithBlocks(world, start, 72, -45, 29, 72, -45, 32, Blocks.MOSSY_COBBLESTONE.getDefaultState());
        structure.fillWithBlocks(world, start, 72, -45, 36, 72, -45, 37, Blocks.MOSSY_COBBLESTONE.getDefaultState());
        structure.fillWithBlocks(world, start, 72, -45, 38, 72, -45, 40, Blocks.STONE_BRICKS.getDefaultState());
        structure.fillWithBlocks(world, start, 72, -45, 43, 72, -45, 44, Blocks.STONE_BRICKS.getDefaultState());
        structure.fillWithBlocks(world, start, 72, -45, 46, 72, -45, 48, Blocks.MOSSY_STONE_BRICKS.getDefaultState());
        structure.fillWithBlocks(world, start, 72, -45, 49, 72, -45, 51, Blocks.MOSSY_COBBLESTONE.getDefaultState());
        structure.fillWithBlocks(world, start, 72, -45, 58, 72, -45, 61, Blocks.STONE_BRICKS.getDefaultState());
        structure.fillWithBlocks(world, start, 72, -45, 63, 72, -44, 63, Blocks.MOSSY_STONE_BRICKS.getDefaultState());
        structure.fillWithBlocks(world, start, 72, -45, 64, 72, -45, 65, Blocks.STONE_BRICKS.getDefaultState());
        structure.fillWithBlocks(world, start, 72, -44, -17, 74, -44, -17, Blocks.STONE_BRICKS.getDefaultState());
        structure.fillWithBlocks(world, start, 72, -44, -16, 74, -44, -12, Blocks.AIR.getDefaultState());
        structure.fillWithBlocks(world, start, 72, -44, 6, 72, -44, 8, Blocks.STONE_BRICKS.getDefaultState());
        structure.fillWithBlocks(world, start, 72, -44, 16, 72, -44, 16, Blocks.STONE_BRICKS.getDefaultState());
        structure.fillWithBlocks(world, start, 72, -44, 18, 72, -43, 18, Blocks.MOSSY_COBBLESTONE.getDefaultState());
        structure.fillWithBlocks(world, start, 72, -44, 38, 72, -44, 38, Blocks.STONE_BRICKS.getDefaultState());
        structure.fillWithBlocks(world, start, 72, -44, 39, 72, -42, 41, Blocks.AIR.getDefaultState());
        structure.fillWithBlocks(world, start, 72, -44, 42, 72, -44, 42, Blocks.STONE_BRICKS.getDefaultState());
        structure.fillWithBlocks(world, start, 72, -44, 43, 72, -42, 43, Blocks.AIR.getDefaultState());
        structure.fillWithBlocks(world, start, 72, -44, 45, 72, -43, 46, Blocks.AIR.getDefaultState());
        structure.fillWithBlocks(world, start, 72, -44, 47, 74, -44, 47, Blocks.STONE_BRICKS.getDefaultState());
        structure.fillWithBlocks(world, start, 72, -44, 48, 74, -44, 52, Blocks.AIR.getDefaultState());
        structure.fillWithBlocks(world, start, 72, -44, 55, 73, -44, 61, Blocks.AIR.getDefaultState());
        structure.fillWithBlocks(world, start, 72, -44, 62, 73, -44, 62, Blocks.MOSSY_COBBLESTONE.getDefaultState());
        structure.fillWithBlocks(world, start, 72, -44, 64, 72, -42, 64, Blocks.STONE_BRICKS.getDefaultState());
        structure.fillWithBlocks(world, start, 72, -44, 65, 72, -43, 65, Blocks.MOSSY_STONE_BRICKS.getDefaultState());
        structure.fillWithBlocks(world, start, 72, -43, -17, 72, -42, -17, Blocks.STONE_BRICKS.getDefaultState());
        structure.fillWithBlocks(world, start, 72, -43, -16, 74, -43, -12, Blocks.AIR.getDefaultState());
        structure.fillWithBlocks(world, start, 72, -43, -11, 72, -42, -11, Blocks.STONE_BRICKS.getDefaultState());
        structure.fillWithBlocks(world, start, 72, -43, 16, 73, -43, 17, Blocks.STONE_BRICKS.getDefaultState());
        structure.fillWithBlocks(world, start, 72, -43, 38, 72, -43, 38, Blocks.STONE_BRICKS.getDefaultState());
        structure.fillWithBlocks(world, start, 72, -43, 44, 72, -41, 44, Blocks.STONE_BRICKS.getDefaultState());
        structure.fillWithBlocks(world, start, 72, -43, 48, 74, -43, 52, Blocks.AIR.getDefaultState());
        structure.fillWithBlocks(world, start, 72, -43, 54, 74, -43, 54, Blocks.MOSSY_COBBLESTONE.getDefaultState());
        structure.fillWithBlocks(world, start, 72, -43, 55, 73, -43, 61, Blocks.AIR.getDefaultState());
        structure.fillWithBlocks(world, start, 72, -43, 63, 73, -43, 64, Blocks.STONE_BRICKS.getDefaultState());
        structure.fillWithBlocks(world, start, 72, -42, -16, 74, -42, -12, Blocks.AIR.getDefaultState());
        structure.fillWithBlocks(world, start, 72, -42, 6, 72, -42, 6, Blocks.MOSSY_COBBLESTONE.getDefaultState());
        structure.fillWithBlocks(world, start, 72, -42, 7, 72, -41, 7, Blocks.MOSSY_STONE_BRICKS.getDefaultState());
        structure.fillWithBlocks(world, start, 72, -42, 16, 74, -40, 16, Blocks.STONE_BRICKS.getDefaultState());
        structure.fillWithBlocks(world, start, 72, -42, 17, 72, -42, 17, Blocks.MOSSY_STONE_BRICKS.getDefaultState());
        structure.fillWithBlocks(world, start, 72, -42, 18, 72, -42, 18, Blocks.STONE_BRICKS.getDefaultState());
        structure.fillWithBlocks(world, start, 72, -42, 38, 72, -42, 38, Blocks.STONE_BRICKS.getDefaultState());
        structure.fillWithBlocks(world, start, 72, -42, 42, 72, -42, 42, Blocks.STONE_BRICKS.getDefaultState());
        structure.fillWithBlocks(world, start, 72, -42, 45, 72, -42, 46, Blocks.AIR.getDefaultState());
        structure.fillWithBlocks(world, start, 72, -42, 47, 74, -42, 47, Blocks.STONE_BRICKS.getDefaultState());
        structure.fillWithBlocks(world, start, 72, -42, 48, 74, -42, 52, Blocks.AIR.getDefaultState());
        structure.fillWithBlocks(world, start, 72, -42, 62, 72, -42, 62, Blocks.STONE_BRICKS.getDefaultState());
        structure.fillWithBlocks(world, start, 72, -42, 65, 73, -41, 65, Blocks.STONE_BRICKS.getDefaultState());
        structure.fillWithBlocks(world, start, 72, -41, -16, 72, -41, -15, Blocks.STONE_BRICKS.getDefaultState());
        structure.fillWithBlocks(world, start, 72, -41, -14, 72, -41, -13, Blocks.MOSSY_STONE_BRICKS.getDefaultState());
        structure.fillWithBlocks(world, start, 72, -41, 9, 72, -41, 9, Blocks.STONE_BRICKS.getDefaultState());
        structure.fillWithBlocks(world, start, 72, -41, 15, 73, -41, 16, Blocks.STONE_BRICKS.getDefaultState());
        structure.fillWithBlocks(world, start, 72, -41, 39, 73, -41, 39, Blocks.MOSSY_COBBLESTONE.getDefaultState());
        structure.fillWithBlocks(world, start, 72, -41, 41, 72, -41, 43, Blocks.MOSSY_STONE_BRICKS.getDefaultState());
        structure.fillWithBlocks(world, start, 72, -41, 47, 72, -41, 49, Blocks.STONE_BRICKS.getDefaultState());
        structure.fillWithBlocks(world, start, 72, -41, 52, 76, -41, 52, Blocks.STONE_BRICKS.getDefaultState());
        structure.fillWithBlocks(world, start, 72, -41, 53, 72, -41, 54, Blocks.MOSSY_COBBLESTONE.getDefaultState());
        structure.fillWithBlocks(world, start, 72, -41, 62, 72, -41, 63, Blocks.MOSSY_COBBLESTONE.getDefaultState());
        structure.fillWithBlocks(world, start, 72, -40, 6, 72, -40, 6, Blocks.MOSSY_STONE_BRICKS.getDefaultState());
        structure.fillWithBlocks(world, start, 72, -40, 7, 72, -40, 9, Blocks.STONE_BRICKS.getDefaultState());
        structure.fillWithBlocks(world, start, 72, -40, 11, 72, -40, 13, Blocks.STONE_BRICK_STAIRS.getDefaultState().with(StairsBlock.FACING, Direction.EAST).with(StairsBlock.WATERLOGGED, false).with(StairsBlock.SHAPE, StairsShape.STRAIGHT).with(StairsBlock.HALF, Half.TOP));
        structure.fillWithBlocks(world, start, 72, -40, 15, 73, -40, 16, Blocks.STONE_BRICKS.getDefaultState());
        structure.fillWithBlocks(world, start, 72, -40, 17, 72, -38, 17, Blocks.MOSSY_STONE_BRICKS.getDefaultState());
        structure.fillWithBlocks(world, start, 72, -40, 37, 72, -38, 37, Blocks.STONE_BRICKS.getDefaultState());
        structure.fillWithBlocks(world, start, 72, -40, 40, 72, -38, 40, Blocks.STONE_BRICKS.getDefaultState());
        structure.fillWithBlocks(world, start, 72, -40, 53, 73, -40, 53, Blocks.STONE_BRICKS.getDefaultState());
        structure.fillWithBlocks(world, start, 72, -40, 62, 72, -39, 62, Blocks.STONE_BRICKS.getDefaultState());
        structure.fillWithBlocks(world, start, 72, -40, 63, 72, -40, 63, Blocks.MOSSY_STONE_BRICKS.getDefaultState());
        structure.fillWithBlocks(world, start, 72, -40, 65, 72, -39, 65, Blocks.MOSSY_STONE_BRICKS.getDefaultState());
        structure.fillWithBlocks(world, start, 72, -39, 6, 72, -39, 7, Blocks.MOSSY_STONE_BRICKS.getDefaultState());
        structure.fillWithBlocks(world, start, 72, -39, 18, 72, -39, 18, Blocks.MOSSY_STONE_BRICKS.getDefaultState());
        structure.fillWithBlocks(world, start, 72, -39, 21, 73, -39, 23, Blocks.STONE_BRICKS.getDefaultState());
        structure.fillWithBlocks(world, start, 72, -39, 24, 73, -39, 24, Blocks.MOSSY_STONE_BRICKS.getDefaultState());
        structure.fillWithBlocks(world, start, 72, -39, 27, 74, -39, 29, Blocks.AIR.getDefaultState());
        structure.fillWithBlocks(world, start, 72, -39, 30, 73, -39, 31, Blocks.STONE_BRICKS.getDefaultState());
        structure.fillWithBlocks(world, start, 72, -39, 32, 72, -39, 33, Blocks.STONE_BRICKS.getDefaultState());
        structure.fillWithBlocks(world, start, 72, -39, 34, 72, -39, 35, Blocks.MOSSY_STONE_BRICKS.getDefaultState());
        structure.fillWithBlocks(world, start, 72, -39, 39, 73, -39, 40, Blocks.STONE_BRICKS.getDefaultState());
        structure.fillWithBlocks(world, start, 72, -39, 55, 72, -39, 55, Blocks.STONE_BRICKS.getDefaultState());
        structure.fillWithBlocks(world, start, 72, -39, 57, 73, -38, 57, Blocks.STONE_BRICKS.getDefaultState());
        structure.fillWithBlocks(world, start, 72, -39, 60, 72, -39, 63, Blocks.STONE_BRICKS.getDefaultState());
        structure.fillWithBlocks(world, start, 72, -39, 64, 72, -39, 65, Blocks.MOSSY_STONE_BRICKS.getDefaultState());
        structure.fillWithBlocks(world, start, 72, -38, 6, 72, -38, 6, Blocks.STONE_BRICKS.getDefaultState());
        structure.fillWithBlocks(world, start, 72, -38, 9, 72, -37, 10, Blocks.STONE_BRICKS.getDefaultState());
        structure.fillWithBlocks(world, start, 72, -38, 11, 72, -38, 12, Blocks.MOSSY_STONE_BRICKS.getDefaultState());
        structure.fillWithBlocks(world, start, 72, -38, 13, 72, -38, 14, Blocks.STONE_BRICKS.getDefaultState());
        structure.fillWithBlocks(world, start, 72, -38, 18, 72, -38, 18, Blocks.STONE_BRICKS.getDefaultState());
        structure.fillWithBlocks(world, start, 72, -38, 19, 72, -38, 20, Blocks.MOSSY_STONE_BRICKS.getDefaultState());
        structure.fillWithBlocks(world, start, 72, -38, 22, 72, -37, 23, Blocks.STONE_BRICKS.getDefaultState());
        structure.fillWithBlocks(world, start, 72, -38, 24, 73, -38, 30, Blocks.STONE_BRICKS.getDefaultState());
        structure.fillWithBlocks(world, start, 72, -38, 32, 72, -37, 32, Blocks.AIR.getDefaultState());
        structure.fillWithBlocks(world, start, 72, -38, 33, 72, -38, 35, Blocks.STONE_BRICKS.getDefaultState());
        structure.fillWithBlocks(world, start, 72, -38, 36, 73, -38, 36, Blocks.MOSSY_STONE_BRICKS.getDefaultState());
        structure.fillWithBlocks(world, start, 72, -38, 51, 72, -38, 52, Blocks.STONE_BRICKS.getDefaultState());
        structure.fillWithBlocks(world, start, 72, -38, 53, 72, -38, 53, Blocks.MOSSY_STONE_BRICKS.getDefaultState());
        structure.fillWithBlocks(world, start, 72, -38, 55, 73, -38, 55, Blocks.STONE_BRICKS.getDefaultState());
        structure.fillWithBlocks(world, start, 72, -38, 56, 73, -38, 56, Blocks.MOSSY_STONE_BRICKS.getDefaultState());
        structure.fillWithBlocks(world, start, 72, -38, 58, 72, -37, 60, Blocks.STONE_BRICKS.getDefaultState());
        structure.fillWithBlocks(world, start, 72, -38, 62, 72, -37, 62, Blocks.MOSSY_STONE_BRICKS.getDefaultState());
        structure.fillWithBlocks(world, start, 72, -38, 63, 72, -38, 65, Blocks.STONE_BRICKS.getDefaultState());
        structure.fillWithBlocks(world, start, 72, -37, 6, 72, -37, 6, Blocks.MOSSY_STONE_BRICKS.getDefaultState());
