package mod.arcalitegames.odyssey.world.structure.structures.dungeons.mayan_pyramid;

import mod.arcalitegames.odyssey.world.structure.StructureBase;
import net.minecraft.block.Blocks;
import net.minecraft.block.WallBlock;
import net.minecraft.block.WallHeight;
import net.minecraft.util.math.BlockPos;
import net.minecraft.world.World;

public class PyramidComponent8
{
	public static BlockPos start;
    public static World world;
    public static StructureBase structure;

    public static void init(World worldIn, BlockPos blockPos, StructureBase structureIn)
    {
        world = worldIn; start = blockPos; structure = structureIn;
    }
    
    public static void generatePart81()
    {
        structure.fillWithBlocks(world, start, 104, -40, 30, 104, -40, 33, Blocks.AIR.getDefaultState());
        structure.fillWithBlocks(world, start, 104, -40, 34, 104, -39, 34, Blocks.STONE_BRICKS.getDefaultState());
        structure.fillWithBlocks(world, start, 104, -40, 35, 105, -40, 35, Blocks.MOSSY_COBBLESTONE.getDefaultState());
        structure.fillWithBlocks(world, start, 104, -40, 36, 104, -36, 36, Blocks.STONE_BRICKS.getDefaultState());
        structure.fillWithBlocks(world, start, 104, -40, 37, 104, -40, 38, Blocks.MOSSY_STONE_BRICKS.getDefaultState());
        structure.fillWithBlocks(world, start, 104, -39, 19, 104, -39, 26, Blocks.STONE_BRICKS.getDefaultState());
        structure.fillWithBlocks(world, start, 104, -39, 30, 104, -39, 31, Blocks.MOSSY_STONE_BRICKS.getDefaultState());
        structure.fillWithBlocks(world, start, 104, -39, 32, 104, -38, 33, Blocks.STONE_BRICKS.getDefaultState());
        structure.fillWithBlocks(world, start, 104, -39, 35, 104, -38, 35, Blocks.MOSSY_STONE_BRICKS.getDefaultState());
        structure.fillWithBlocks(world, start, 104, -39, 37, 104, -38, 37, Blocks.STONE_BRICKS.getDefaultState());
        structure.fillWithBlocks(world, start, 104, -38, 20, 104, -38, 20, Blocks.MOSSY_STONE_BRICKS.getDefaultState());
        structure.fillWithBlocks(world, start, 104, -38, 21, 104, -38, 24, Blocks.STONE_BRICKS.getDefaultState());
        structure.fillWithBlocks(world, start, 104, -38, 26, 104, -38, 28, Blocks.STONE_BRICKS.getDefaultState());
        structure.fillWithBlocks(world, start, 104, -38, 30, 105, -38, 33, Blocks.STONE_BRICKS.getDefaultState());
        structure.fillWithBlocks(world, start, 104, -38, 34, 105, -38, 34, Blocks.AIR.getDefaultState());
        structure.fillWithBlocks(world, start, 104, -37, 19, 105, -37, 20, Blocks.STONE_BRICKS.getDefaultState());
        structure.fillWithBlocks(world, start, 104, -37, 24, 104, -37, 25, Blocks.STONE_BRICKS.getDefaultState());
        structure.fillWithBlocks(world, start, 104, -37, 26, 104, -37, 26, Blocks.MOSSY_STONE_BRICKS.getDefaultState());
        structure.fillWithBlocks(world, start, 104, -37, 29, 104, -37, 30, Blocks.STONE_BRICKS.getDefaultState());
        structure.fillWithBlocks(world, start, 104, -37, 33, 104, -37, 33, Blocks.STONE_BRICKS.getDefaultState());
        structure.fillWithBlocks(world, start, 104, -37, 35, 104, -37, 36, Blocks.STONE_BRICKS.getDefaultState());
        structure.fillWithBlocks(world, start, 104, -37, 37, 105, -37, 37, Blocks.MOSSY_STONE_BRICKS.getDefaultState());
        structure.fillWithBlocks(world, start, 104, -36, 18, 105, -36, 19, Blocks.STONE_BRICKS.getDefaultState());
        structure.fillWithBlocks(world, start, 104, -36, 23, 105, -36, 23, Blocks.MOSSY_COBBLESTONE.getDefaultState());
        structure.fillWithBlocks(world, start, 104, -36, 27, 105, -36, 27, Blocks.MOSSY_STONE_BRICKS.getDefaultState());
        structure.fillWithBlocks(world, start, 104, -36, 29, 105, -36, 30, Blocks.STONE_BRICKS.getDefaultState());
        structure.fillWithBlocks(world, start, 104, -36, 32, 104, -36, 33, Blocks.STONE_BRICKS.getDefaultState());
        structure.fillWithBlocks(world, start, 104, -36, 37, 104, -36, 37, Blocks.STONE_BRICKS.getDefaultState());
        structure.fillWithBlocks(world, start, 104, -24, 43, 104, -23, 43, Blocks.CRACKED_STONE_BRICKS.getDefaultState());
        structure.fillWithBlocks(world, start, 104, -21, 45, 104, -21, 45, Blocks.CRACKED_STONE_BRICKS.getDefaultState());
        structure.fillWithBlocks(world, start, 104, -21, 46, 104, -21, 48, Blocks.STONE_BRICKS.getDefaultState());
        structure.fillWithBlocks(world, start, 104, -15, 44, 106, -15, 48, Blocks.STONE_BRICKS.getDefaultState());
        structure.fillWithBlocks(world, start, 104, -14, 43, 104, -14, 43, Blocks.STONE_BRICKS.getDefaultState());
        structure.fillWithBlocks(world, start, 104, -14, 49, 104, -14, 49, Blocks.STONE_BRICKS.getDefaultState());
        structure.fillWithBlocks(world, start, 104, -13, 43, 104, -13, 43, Blocks.STONE_BRICKS.getDefaultState());
        structure.fillWithBlocks(world, start, 104, -13, 49, 104, -13, 49, Blocks.STONE_BRICKS.getDefaultState());
        structure.fillWithBlocks(world, start, 104, -12, 43, 104, -12, 43, Blocks.STONE_BRICKS.getDefaultState());
        structure.fillWithBlocks(world, start, 104, -12, 49, 104, -12, 49, Blocks.STONE_BRICKS.getDefaultState());
        structure.fillWithBlocks(world, start, 104, -11, 44, 105, -11, 45, Blocks.STONE_BRICKS.getDefaultState());
        structure.fillWithBlocks(world, start, 104, -11, 47, 105, -11, 48, Blocks.STONE_BRICKS.getDefaultState());
        structure.fillWithBlocks(world, start, 105, -55, -22, 106, -55, -21, Blocks.STONE_BRICKS.getDefaultState());
        structure.fillWithBlocks(world, start, 105, -54, -16, 109, -54, -12, Blocks.AIR.getDefaultState());
        structure.fillWithBlocks(world, start, 105, -54, -6, 109, -50, -6, Blocks.STONE_BRICKS.getDefaultState());
        structure.fillWithBlocks(world, start, 105, -53, -21, 109, -53, -7, Blocks.AIR.getDefaultState());
        structure.fillWithBlocks(world, start, 105, -52, -21, 109, -52, -7, Blocks.AIR.getDefaultState());
        structure.fillWithBlocks(world, start, 105, -51, -21, 109, -51, -7, Blocks.AIR.getDefaultState());
        structure.fillWithBlocks(world, start, 105, -50, -20, 107, -50, -18, Blocks.AIR.getDefaultState());
        structure.fillWithBlocks(world, start, 105, -50, -16, 109, -50, -12, Blocks.AIR.getDefaultState());
        structure.fillWithBlocks(world, start, 105, -50, -11, 128, -50, -11, Blocks.STONE_BRICKS.getDefaultState());
        structure.fillWithBlocks(world, start, 105, -50, -10, 107, -50, -8, Blocks.AIR.getDefaultState());
        structure.fillWithBlocks(world, start, 105, -50, -7, 106, -50, -6, Blocks.STONE_BRICKS.getDefaultState());
        structure.fillWithBlocks(world, start, 105, -49, -15, 106, -49, -12, Blocks.STONE_BRICKS.getDefaultState());
        structure.fillWithBlocks(world, start, 105, -48, -22, 109, -48, -18, Blocks.STONE_BRICKS.getDefaultState());
        structure.fillWithBlocks(world, start, 105, -48, -16, 106, -48, -15, Blocks.STONE_BRICKS.getDefaultState());
        structure.fillWithBlocks(world, start, 105, -48, -14, 105, -48, -6, Blocks.STONE_BRICKS.getDefaultState());
        structure.fillWithBlocks(world, start, 105, -47, -16, 106, -47, -13, Blocks.STONE_BRICKS.getDefaultState());
        structure.fillWithBlocks(world, start, 105, -47, -6, 115, -46, -6, Blocks.STONE_BRICKS.getDefaultState());
        structure.fillWithBlocks(world, start, 105, -46, -22, 105, -46, -21, Blocks.STONE_BRICKS.getDefaultState());
        structure.fillWithBlocks(world, start, 105, -45, 18, 105, -44, 19, Blocks.STONE_BRICKS.getDefaultState());
        structure.fillWithBlocks(world, start, 105, -45, 20, 105, -45, 24, Blocks.STONE_BRICKS.getDefaultState());
        structure.fillWithBlocks(world, start, 105, -45, 27, 106, -45, 27, Blocks.STONE_BRICKS.getDefaultState());
        structure.fillWithBlocks(world, start, 105, -45, 29, 106, -45, 30, Blocks.STONE_BRICKS.getDefaultState());
        structure.fillWithBlocks(world, start, 105, -45, 33, 105, -45, 33, Blocks.MOSSY_STONE_BRICKS.getDefaultState());
        structure.fillWithBlocks(world, start, 105, -45, 34, 105, -45, 34, Blocks.STONE_BRICKS.getDefaultState());
        structure.fillWithBlocks(world, start, 105, -45, 36, 105, -45, 37, Blocks.STONE_BRICKS.getDefaultState());
        structure.fillWithBlocks(world, start, 105, -44, 23, 105, -44, 26, Blocks.STONE_BRICKS.getDefaultState());
        structure.fillWithBlocks(world, start, 105, -44, 27, 105, -42, 29, Blocks.AIR.getDefaultState());
        structure.fillWithBlocks(world, start, 105, -44, 30, 105, -44, 33, Blocks.STONE_BRICKS.getDefaultState());
        structure.fillWithBlocks(world, start, 105, -44, 35, 105, -44, 36, Blocks.MOSSY_COBBLESTONE.getDefaultState());
        structure.fillWithBlocks(world, start, 105, -44, 37, 105, -44, 37, Blocks.STONE_BRICKS.getDefaultState());
        structure.fillWithBlocks(world, start, 105, -43, 20, 106, -43, 20, Blocks.STONE_BRICKS.getDefaultState());
        structure.fillWithBlocks(world, start, 105, -43, 22, 107, -43, 22, Blocks.AIR.getDefaultState());
        structure.fillWithBlocks(world, start, 105, -43, 23, 106, -43, 23, Blocks.STONE_BRICKS.getDefaultState());
        structure.fillWithBlocks(world, start, 105, -43, 25, 106, -43, 26, Blocks.STONE_BRICKS.getDefaultState());
        structure.fillWithBlocks(world, start, 105, -43, 31, 105, -43, 31, Blocks.STONE_BRICKS.getDefaultState());
        structure.fillWithBlocks(world, start, 105, -43, 34, 105, -42, 34, Blocks.AIR.getDefaultState());
        structure.fillWithBlocks(world, start, 105, -43, 36, 105, -43, 37, Blocks.MOSSY_STONE_BRICKS.getDefaultState());
        structure.fillWithBlocks(world, start, 105, -42, 18, 106, -41, 18, Blocks.STONE_BRICKS.getDefaultState());
        structure.fillWithBlocks(world, start, 105, -42, 19, 106, -42, 19, Blocks.MOSSY_STONE_BRICKS.getDefaultState());
        structure.fillWithBlocks(world, start, 105, -42, 22, 105, -42, 23, Blocks.MOSSY_STONE_BRICKS.getDefaultState());
        structure.fillWithBlocks(world, start, 105, -42, 24, 105, -42, 24, Blocks.STONE_BRICKS.getDefaultState());
        structure.fillWithBlocks(world, start, 105, -42, 30, 105, -42, 32, Blocks.STONE_BRICKS.getDefaultState());
        structure.fillWithBlocks(world, start, 105, -42, 35, 108, -41, 35, Blocks.STONE_BRICKS.getDefaultState());
        structure.fillWithBlocks(world, start, 105, -41, 19, 105, -41, 20, Blocks.STONE_BRICKS.getDefaultState());
        structure.fillWithBlocks(world, start, 105, -41, 22, 105, -41, 25, Blocks.STONE_BRICKS.getDefaultState());
        structure.fillWithBlocks(world, start, 105, -41, 27, 105, -39, 27, Blocks.MOSSY_STONE_BRICKS.getDefaultState());
        structure.fillWithBlocks(world, start, 105, -41, 28, 107, -41, 30, Blocks.STONE_BRICKS.getDefaultState());
        structure.fillWithBlocks(world, start, 105, -41, 31, 105, -41, 31, Blocks.STONE_BRICKS.getDefaultState());
        structure.fillWithBlocks(world, start, 105, -41, 32, 105, -41, 32, Blocks.MOSSY_COBBLESTONE.getDefaultState());
        structure.fillWithBlocks(world, start, 105, -41, 33, 105, -41, 37, Blocks.STONE_BRICKS.getDefaultState());
        structure.fillWithBlocks(world, start, 105, -41, 38, 107, -41, 38, Blocks.MOSSY_COBBLESTONE.getDefaultState());
        structure.fillWithBlocks(world, start, 105, -40, 18, 105, -40, 18, Blocks.STONE_BRICKS.getDefaultState());
        structure.fillWithBlocks(world, start, 105, -40, 22, 105, -39, 22, Blocks.MOSSY_STONE_BRICKS.getDefaultState());
        structure.fillWithBlocks(world, start, 105, -40, 23, 106, -40, 24, Blocks.STONE_BRICKS.getDefaultState());
        structure.fillWithBlocks(world, start, 105, -40, 25, 105, -40, 26, Blocks.STONE_BRICKS.getDefaultState());
        structure.fillWithBlocks(world, start, 105, -40, 28, 107, -40, 28, Blocks.STONE_BRICKS.getDefaultState());
        structure.fillWithBlocks(world, start, 105, -40, 29, 106, -40, 29, Blocks.AIR.getDefaultState());
        structure.fillWithBlocks(world, start, 105, -40, 31, 106, -40, 31, Blocks.STONE_BRICKS.getDefaultState());
        structure.fillWithBlocks(world, start, 105, -40, 32, 105, -39, 32, Blocks.MOSSY_STONE_BRICKS.getDefaultState());
        structure.fillWithBlocks(world, start, 105, -40, 33, 105, -40, 33, Blocks.STONE_BRICKS.getDefaultState());
        structure.fillWithBlocks(world, start, 105, -40, 34, 105, -40, 34, Blocks.MOSSY_STONE_BRICKS.getDefaultState());
        structure.fillWithBlocks(world, start, 105, -40, 37, 105, -40, 37, Blocks.STONE_BRICKS.getDefaultState());
        structure.fillWithBlocks(world, start, 105, -40, 38, 105, -39, 38, Blocks.MOSSY_STONE_BRICKS.getDefaultState());
        structure.fillWithBlocks(world, start, 105, -39, 18, 106, -39, 19, Blocks.MOSSY_STONE_BRICKS.getDefaultState());
        structure.fillWithBlocks(world, start, 105, -39, 20, 105, -39, 20, Blocks.STONE_BRICKS.getDefaultState());
        structure.fillWithBlocks(world, start, 105, -39, 23, 105, -39, 23, Blocks.STONE_BRICKS.getDefaultState());
        structure.fillWithBlocks(world, start, 105, -39, 25, 106, -39, 26, Blocks.STONE_BRICKS.getDefaultState());
        structure.fillWithBlocks(world, start, 105, -39, 30, 105, -38, 31, Blocks.STONE_BRICKS.getDefaultState());
        structure.fillWithBlocks(world, start, 105, -39, 34, 105, -39, 36, Blocks.STONE_BRICKS.getDefaultState());
        structure.fillWithBlocks(world, start, 105, -38, 18, 105, -38, 18, Blocks.STONE_BRICKS.getDefaultState());
        structure.fillWithBlocks(world, start, 105, -38, 19, 105, -38, 21, Blocks.MOSSY_STONE_BRICKS.getDefaultState());
        structure.fillWithBlocks(world, start, 105, -38, 22, 105, -37, 22, Blocks.STONE_BRICKS.getDefaultState());
        structure.fillWithBlocks(world, start, 105, -38, 23, 105, -37, 23, Blocks.AIR.getDefaultState());
        structure.fillWithBlocks(world, start, 105, -38, 25, 106, -38, 25, Blocks.STONE_BRICKS.getDefaultState());
        structure.fillWithBlocks(world, start, 105, -38, 26, 105, -36, 26, Blocks.MOSSY_STONE_BRICKS.getDefaultState());
        structure.fillWithBlocks(world, start, 105, -38, 36, 105, -37, 36, Blocks.MOSSY_STONE_BRICKS.getDefaultState());
        structure.fillWithBlocks(world, start, 105, -38, 37, 105, -38, 38, Blocks.STONE_BRICKS.getDefaultState());
        structure.fillWithBlocks(world, start, 105, -37, 18, 105, -36, 19, Blocks.STONE_BRICKS.getDefaultState());
        structure.fillWithBlocks(world, start, 105, -37, 24, 105, -37, 24, Blocks.STONE_BRICKS.getDefaultState());
        structure.fillWithBlocks(world, start, 105, -37, 25, 105, -37, 27, Blocks.MOSSY_STONE_BRICKS.getDefaultState());
        structure.fillWithBlocks(world, start, 105, -37, 28, 108, -36, 28, Blocks.STONE_BRICKS.getDefaultState());
        structure.fillWithBlocks(world, start, 105, -37, 30, 105, -36, 30, Blocks.STONE_BRICKS.getDefaultState());
        structure.fillWithBlocks(world, start, 105, -37, 32, 105, -37, 35, Blocks.STONE_BRICKS.getDefaultState());
        structure.fillWithBlocks(world, start, 105, -36, 21, 106, -36, 21, Blocks.STONE_BRICKS.getDefaultState());
        structure.fillWithBlocks(world, start, 105, -36, 22, 105, -36, 22, Blocks.MOSSY_STONE_BRICKS.getDefaultState());
        structure.fillWithBlocks(world, start, 105, -36, 24, 105, -36, 25, Blocks.STONE_BRICKS.getDefaultState());
        structure.fillWithBlocks(world, start, 105, -36, 31, 105, -36, 32, Blocks.STONE_BRICKS.getDefaultState());
        structure.fillWithBlocks(world, start, 105, -36, 34, 105, -36, 38, Blocks.STONE_BRICKS.getDefaultState());
        structure.fillWithBlocks(world, start, 105, -25, 45, 108, -25, 48, Blocks.STONE_BRICKS.getDefaultState());
        structure.fillWithBlocks(world, start, 105, -24, 43, 105, -23, 44, Blocks.STONE_BRICKS.getDefaultState());
        structure.fillWithBlocks(world, start, 105, -24, 45, 107, -24, 47, Blocks.AIR.getDefaultState());
        structure.fillWithBlocks(world, start, 105, -24, 48, 105, -24, 49, Blocks.STONE_BRICKS.getDefaultState());
        structure.fillWithBlocks(world, start, 105, -23, 45, 107, -23, 47, Blocks.AIR.getDefaultState());
        structure.fillWithBlocks(world, start, 105, -23, 48, 105, -23, 49, Blocks.STONE_BRICKS.getDefaultState());
        structure.fillWithBlocks(world, start, 105, -22, 43, 105, -22, 44, Blocks.STONE_BRICKS.getDefaultState());
        structure.fillWithBlocks(world, start, 105, -22, 45, 107, -22, 47, Blocks.AIR.getDefaultState());
        structure.fillWithBlocks(world, start, 105, -22, 48, 105, -22, 49, Blocks.STONE_BRICKS.getDefaultState());
        structure.fillWithBlocks(world, start, 105, -21, 44, 105, -21, 46, Blocks.CRACKED_STONE_BRICKS.getDefaultState());
        structure.fillWithBlocks(world, start, 105, -21, 47, 106, -21, 48, Blocks.STONE_BRICKS.getDefaultState());
        structure.fillWithBlocks(world, start, 105, -15, 40, 108, -15, 43, Blocks.STONE_BRICKS.getDefaultState());
        structure.fillWithBlocks(world, start, 105, -15, 49, 106, -15, 50, Blocks.STONE_BRICKS.getDefaultState());
        structure.fillWithBlocks(world, start, 105, -15, 51, 105, -15, 53, Blocks.STONE_BRICKS.getDefaultState());
        structure.fillWithBlocks(world, start, 105, -14, 39, 107, -14, 41, Blocks.STONE_BRICKS.getDefaultState());
        structure.fillWithBlocks(world, start, 105, -14, 42, 106, -14, 44, Blocks.STONE_BRICKS.getDefaultState());
        structure.fillWithBlocks(world, start, 105, -14, 45, 107, -14, 47, Blocks.AIR.getDefaultState());
        structure.fillWithBlocks(world, start, 105, -14, 48, 106, -14, 53, Blocks.STONE_BRICKS.getDefaultState());
        structure.fillWithBlocks(world, start, 105, -13, 39, 107, -13, 41, Blocks.STONE_BRICKS.getDefaultState());
        structure.fillWithBlocks(world, start, 105, -13, 42, 106, -13, 44, Blocks.STONE_BRICKS.getDefaultState());
        structure.fillWithBlocks(world, start, 105, -13, 45, 107, -13, 47, Blocks.AIR.getDefaultState());
        structure.fillWithBlocks(world, start, 105, -13, 48, 106, -13, 50, Blocks.STONE_BRICKS.getDefaultState());
        structure.fillWithBlocks(world, start, 105, -13, 51, 105, -6, 51, Blocks.STONE_BRICKS.getDefaultState());
        structure.fillWithBlocks(world, start, 105, -13, 53, 108, -10, 53, Blocks.STONE_BRICKS.getDefaultState());
        structure.fillWithBlocks(world, start, 105, -12, 39, 105, -12, 39, Blocks.STONE_BRICKS.getDefaultState());
        structure.fillWithBlocks(world, start, 105, -12, 41, 106, -12, 44, Blocks.STONE_BRICKS.getDefaultState());
        structure.fillWithBlocks(world, start, 105, -12, 45, 107, -12, 47, Blocks.AIR.getDefaultState());
        structure.fillWithBlocks(world, start, 105, -12, 48, 106, -12, 50, Blocks.STONE_BRICKS.getDefaultState());
        structure.fillWithBlocks(world, start, 105, -12, 52, 106, -12, 53, Blocks.STONE_BRICKS.getDefaultState());
        structure.fillWithBlocks(world, start, 105, -11, 39, 107, -11, 41, Blocks.STONE_BRICKS.getDefaultState());
        structure.fillWithBlocks(world, start, 105, -11, 42, 106, -11, 45, Blocks.STONE_BRICKS.getDefaultState());
        structure.fillWithBlocks(world, start, 105, -11, 46, 105, -11, 49, Blocks.STONE_BRICKS.getDefaultState());
        structure.fillWithBlocks(world, start, 105, -11, 50, 105, -11, 50, Blocks.MOSSY_STONE_BRICKS.getDefaultState());
        structure.fillWithBlocks(world, start, 105, -11, 52, 106, -11, 53, Blocks.STONE_BRICKS.getDefaultState());
        structure.fillWithBlocks(world, start, 105, -10, 39, 105, -8, 43, Blocks.STONE_BRICKS.getDefaultState());
        structure.fillWithBlocks(world, start, 105, -10, 44, 105, -10, 44, Blocks.STONE_BRICKS.getDefaultState());
        structure.fillWithBlocks(world, start, 105, -10, 46, 105, -10, 46, Blocks.STONE_BRICKS.getDefaultState());
        structure.fillWithBlocks(world, start, 105, -10, 48, 106, -10, 49, Blocks.STONE_BRICKS.getDefaultState());
        structure.fillWithBlocks(world, start, 105, -10, 50, 105, -10, 53, Blocks.STONE_BRICKS.getDefaultState());
        structure.fillWithBlocks(world, start, 105, -9, 45, 111, -9, 53, Blocks.STONE_BRICKS.getDefaultState());
        structure.fillWithBlocks(world, start, 105, -8, 44, 111, -8, 53, Blocks.STONE_BRICKS.getDefaultState());
        structure.fillWithBlocks(world, start, 105, -7, 39, 107, -7, 41, Blocks.STONE_BRICKS.getDefaultState());
        structure.fillWithBlocks(world, start, 105, -7, 43, 106, -7, 44, Blocks.STONE_BRICKS.getDefaultState());
        structure.fillWithBlocks(world, start, 105, -7, 45, 105, -7, 48, Blocks.STONE_BRICKS.getDefaultState());
        structure.fillWithBlocks(world, start, 105, -7, 50, 106, -7, 53, Blocks.STONE_BRICKS.getDefaultState());
        structure.fillWithBlocks(world, start, 105, -6, 39, 105, -6, 40, Blocks.MOSSY_STONE_BRICKS.getDefaultState());
        structure.fillWithBlocks(world, start, 105, -6, 41, 108, -6, 51, Blocks.STONE_BRICKS.getDefaultState());
        structure.fillWithBlocks(world, start, 105, -6, 53, 108, -6, 53, Blocks.STONE_BRICKS.getDefaultState());
        structure.fillWithBlocks(world, start, 106, -55, -7, 107, -55, -6, Blocks.STONE_BRICKS.getDefaultState());
        structure.fillWithBlocks(world, start, 106, -54, -17, 109, -54, -17, Blocks.STONE_BRICK_WALL.getDefaultState().with(WallBlock.WATERLOGGED, false).with(WallBlock.UP, false).with(WallBlock.WALL_HEIGHT_NORTH, WallHeight.LOW).with(WallBlock.WALL_HEIGHT_SOUTH, WallHeight.LOW).with(WallBlock.WALL_HEIGHT_EAST, WallHeight.LOW).with(WallBlock.WALL_HEIGHT_WEST, WallHeight.LOW));
        structure.fillWithBlocks(world, start, 106, -54, -11, 108, -54, -11, Blocks.STONE_BRICK_WALL.getDefaultState().with(WallBlock.WATERLOGGED, false).with(WallBlock.UP, false).with(WallBlock.WALL_HEIGHT_NORTH, WallHeight.LOW).with(WallBlock.WALL_HEIGHT_SOUTH, WallHeight.LOW).with(WallBlock.WALL_HEIGHT_EAST, WallHeight.LOW).with(WallBlock.WALL_HEIGHT_WEST, WallHeight.LOW));
        structure.fillWithBlocks(world, start, 106, -54, -7, 109, -54, -7, Blocks.STONE_BRICK_WALL.getDefaultState().with(WallBlock.WATERLOGGED, false).with(WallBlock.UP, false).with(WallBlock.WALL_HEIGHT_NORTH, WallHeight.LOW).with(WallBlock.WALL_HEIGHT_SOUTH, WallHeight.LOW).with(WallBlock.WALL_HEIGHT_EAST, WallHeight.LOW).with(WallBlock.WALL_HEIGHT_WEST, WallHeight.LOW));
        structure.fillWithBlocks(world, start, 106, -50, -22, 106, -49, -22, Blocks.AIR.getDefaultState());
        structure.fillWithBlocks(world, start, 106, -50, -21, 113, -47, -21, Blocks.STONE_BRICKS.getDefaultState());
        structure.fillWithBlocks(world, start, 106, -49, -20, 106, -46, -17, Blocks.STONE_BRICKS.getDefaultState());
        structure.fillWithBlocks(world, start, 106, -49, -10, 106, -46, -6, Blocks.STONE_BRICKS.getDefaultState());
        structure.fillWithBlocks(world, start, 106, -48, -13, 107, -48, -6, Blocks.STONE_BRICKS.getDefaultState());
        structure.fillWithBlocks(world, start, 106, -47, -11, 111, -47, -6, Blocks.STONE_BRICKS.getDefaultState());
        structure.fillWithBlocks(world, start, 106, -46, -22, 106, -46, -22, Blocks.STONE_BRICKS.getDefaultState());
        structure.fillWithBlocks(world, start, 106, -46, -15, 111, -46, -10, Blocks.STONE_BRICKS.getDefaultState());
        structure.fillWithBlocks(world, start, 106, -45, 18, 106, -44, 18, Blocks.MOSSY_STONE_BRICKS.getDefaultState());
        structure.fillWithBlocks(world, start, 106, -45, 20, 106, -43, 20, Blocks.STONE_BRICKS.getDefaultState());
        structure.fillWithBlocks(world, start, 106, -45, 21, 106, -45, 21, Blocks.MOSSY_STONE_BRICKS.getDefaultState());
        structure.fillWithBlocks(world, start, 106, -45, 22, 106, -45, 23, Blocks.STONE_BRICKS.getDefaultState());
        structure.fillWithBlocks(world, start, 106, -45, 24, 106, -45, 24, Blocks.MOSSY_STONE_BRICKS.getDefaultState());
        structure.fillWithBlocks(world, start, 106, -45, 25, 106, -42, 25, Blocks.STONE_BRICKS.getDefaultState());
        structure.fillWithBlocks(world, start, 106, -45, 26, 106, -45, 26, Blocks.MOSSY_STONE_BRICKS.getDefaultState());
        structure.fillWithBlocks(world, start, 106, -45, 28, 107, -45, 28, Blocks.AIR.getDefaultState());
        structure.fillWithBlocks(world, start, 106, -45, 31, 107, -45, 33, Blocks.STONE_BRICKS.getDefaultState());
        structure.fillWithBlocks(world, start, 106, -45, 35, 107, -45, 36, Blocks.STONE_BRICKS.getDefaultState());
        structure.fillWithBlocks(world, start, 106, -45, 37, 106, -45, 38, Blocks.MOSSY_STONE_BRICKS.getDefaultState());
        structure.fillWithBlocks(world, start, 106, -44, 22, 106, -44, 22, Blocks.STONE_BRICKS.getDefaultState());
        structure.fillWithBlocks(world, start, 106, -44, 24, 106, -44, 26, Blocks.STONE_BRICKS.getDefaultState());
        structure.fillWithBlocks(world, start, 106, -44, 28, 106, -44, 29, Blocks.STONE_BRICKS.getDefaultState());
        structure.fillWithBlocks(world, start, 106, -44, 30, 107, -44, 30, Blocks.AIR.getDefaultState());
        structure.fillWithBlocks(world, start, 106, -44, 31, 107, -44, 32, Blocks.STONE_BRICKS.getDefaultState());
        structure.fillWithBlocks(world, start, 106, -44, 36, 106, -44, 38, Blocks.STONE_BRICKS.getDefaultState());
        structure.fillWithBlocks(world, start, 106, -43, 18, 106, -43, 18, Blocks.MOSSY_COBBLESTONE.getDefaultState());
        structure.fillWithBlocks(world, start, 106, -43, 19, 106, -43, 20, Blocks.STONE_BRICKS.getDefaultState());
        structure.fillWithBlocks(world, start, 106, -43, 21, 106, -43, 22, Blocks.AIR.getDefaultState());
        structure.fillWithBlocks(world, start, 106, -43, 24, 108, -43, 24, Blocks.MOSSY_STONE_BRICKS.getDefaultState());
        structure.fillWithBlocks(world, start, 106, -43, 27, 106, -42, 27, Blocks.STONE_BRICKS.getDefaultState());
        structure.fillWithBlocks(world, start, 106, -43, 29, 106, -41, 29, Blocks.STONE_BRICKS.getDefaultState());
        structure.fillWithBlocks(world, start, 106, -43, 31, 106, -43, 32, Blocks.STONE_BRICKS.getDefaultState());
        structure.fillWithBlocks(world, start, 106, -43, 35, 106, -41, 35, Blocks.STONE_BRICKS.getDefaultState());
        structure.fillWithBlocks(world, start, 106, -43, 37, 107, -43, 38, Blocks.STONE_BRICKS.getDefaultState());
        structure.fillWithBlocks(world, start, 106, -42, 22, 107, -42, 22, Blocks.STONE_BRICKS.getDefaultState());
        structure.fillWithBlocks(world, start, 106, -42, 23, 106, -42, 23, Blocks.AIR.getDefaultState());
        structure.fillWithBlocks(world, start, 106, -42, 24, 106, -42, 29, Blocks.STONE_BRICKS.getDefaultState());
        structure.fillWithBlocks(world, start, 106, -42, 31, 106, -42, 31, Blocks.STONE_BRICKS.getDefaultState());
        structure.fillWithBlocks(world, start, 106, -42, 33, 106, -42, 35, Blocks.STONE_BRICKS.getDefaultState());
        structure.fillWithBlocks(world, start, 106, -42, 37, 106, -42, 38, Blocks.STONE_BRICKS.getDefaultState());
        structure.fillWithBlocks(world, start, 106, -41, 22, 106, -41, 26, Blocks.MOSSY_STONE_BRICKS.getDefaultState());
        structure.fillWithBlocks(world, start, 106, -41, 31, 106, -41, 32, Blocks.STONE_BRICKS.getDefaultState());
        structure.fillWithBlocks(world, start, 106, -41, 33, 106, -40, 33, Blocks.MOSSY_COBBLESTONE.getDefaultState());
        structure.fillWithBlocks(world, start, 106, -41, 34, 106, -41, 35, Blocks.STONE_BRICKS.getDefaultState());
        structure.fillWithBlocks(world, start, 106, -41, 36, 107, -41, 36, Blocks.MOSSY_STONE_BRICKS.getDefaultState());
        structure.fillWithBlocks(world, start, 106, -40, 18, 106, -40, 18, Blocks.MOSSY_STONE_BRICKS.getDefaultState());
        structure.fillWithBlocks(world, start, 106, -40, 19, 106, -40, 20, Blocks.STONE_BRICKS.getDefaultState());
        structure.fillWithBlocks(world, start, 106, -40, 27, 107, -40, 28, Blocks.STONE_BRICKS.getDefaultState());
        structure.fillWithBlocks(world, start, 106, -40, 30, 106, -40, 31, Blocks.STONE_BRICKS.getDefaultState());
        structure.fillWithBlocks(world, start, 106, -40, 32, 107, -39, 32, Blocks.AIR.getDefaultState());
        structure.fillWithBlocks(world, start, 106, -40, 34, 106, -40, 34, Blocks.STONE_BRICKS.getDefaultState());
        structure.fillWithBlocks(world, start, 106, -40, 36, 106, -40, 36, Blocks.STONE_BRICKS.getDefaultState());
        structure.fillWithBlocks(world, start, 106, -40, 37, 106, -39, 37, Blocks.MOSSY_STONE_BRICKS.getDefaultState());
        structure.fillWithBlocks(world, start, 106, -39, 20, 106, -39, 21, Blocks.STONE_BRICKS.getDefaultState());
        structure.fillWithBlocks(world, start, 106, -39, 22, 106, -38, 22, Blocks.MOSSY_STONE_BRICKS.getDefaultState());
        structure.fillWithBlocks(world, start, 106, -39, 23, 106, -39, 26, Blocks.STONE_BRICKS.getDefaultState());
        structure.fillWithBlocks(world, start, 106, -39, 28, 106, -39, 28, Blocks.STONE_BRICKS.getDefaultState());
        structure.fillWithBlocks(world, start, 106, -39, 30, 106, -39, 30, Blocks.MOSSY_STONE_BRICKS.getDefaultState());
        structure.fillWithBlocks(world, start, 106, -39, 31, 106, -39, 32, Blocks.AIR.getDefaultState());
        structure.fillWithBlocks(world, start, 106, -39, 33, 106, -39, 33, Blocks.MOSSY_STONE_BRICKS.getDefaultState());
        structure.fillWithBlocks(world, start, 106, -39, 34, 106, -39, 34, Blocks.STONE_BRICKS.getDefaultState());
        structure.fillWithBlocks(world, start, 106, -39, 36, 106, -39, 36, Blocks.STONE_BRICKS.getDefaultState());
        structure.fillWithBlocks(world, start, 106, -39, 38, 106, -37, 38, Blocks.MOSSY_STONE_BRICKS.getDefaultState());
        structure.fillWithBlocks(world, start, 106, -38, 18, 107, -38, 19, Blocks.STONE_BRICKS.getDefaultState());
        structure.fillWithBlocks(world, start, 106, -38, 20, 106, -38, 21, Blocks.AIR.getDefaultState());
        structure.fillWithBlocks(world, start, 106, -38, 23, 106, -38, 23, Blocks.STONE_BRICKS.getDefaultState());
        structure.fillWithBlocks(world, start, 106, -38, 27, 106, -38, 28, Blocks.STONE_BRICKS.getDefaultState());
        structure.fillWithBlocks(world, start, 106, -38, 29, 106, -38, 29, Blocks.MOSSY_STONE_BRICKS.getDefaultState());
        structure.fillWithBlocks(world, start, 106, -38, 30, 106, -38, 31, Blocks.STONE_BRICKS.getDefaultState());
        structure.fillWithBlocks(world, start, 106, -38, 33, 106, -38, 33, Blocks.STONE_BRICKS.getDefaultState());
        structure.fillWithBlocks(world, start, 106, -38, 34, 106, -38, 34, Blocks.MOSSY_STONE_BRICKS.getDefaultState());
        structure.fillWithBlocks(world, start, 106, -38, 36, 106, -38, 37, Blocks.MOSSY_COBBLESTONE.getDefaultState());
        structure.fillWithBlocks(world, start, 106, -37, 18, 108, -36, 18, Blocks.STONE_BRICKS.getDefaultState());
        structure.fillWithBlocks(world, start, 106, -37, 20, 106, -37, 20, Blocks.AIR.getDefaultState());
        structure.fillWithBlocks(world, start, 106, -37, 21, 106, -36, 21, Blocks.STONE_BRICKS.getDefaultState());
        structure.fillWithBlocks(world, start, 106, -37, 22, 106, -37, 23, Blocks.MOSSY_COBBLESTONE.getDefaultState());
        structure.fillWithBlocks(world, start, 106, -37, 24, 107, -37, 25, Blocks.STONE_BRICKS.getDefaultState());
        structure.fillWithBlocks(world, start, 106, -37, 30, 106, -36, 30, Blocks.MOSSY_STONE_BRICKS.getDefaultState());
        structure.fillWithBlocks(world, start, 106, -37, 31, 106, -37, 31, Blocks.STONE_BRICKS.getDefaultState());
        structure.fillWithBlocks(world, start, 106, -37, 32, 106, -36, 32, Blocks.MOSSY_STONE_BRICKS.getDefaultState());
        structure.fillWithBlocks(world, start, 106, -37, 33, 107, -37, 34, Blocks.STONE_BRICKS.getDefaultState());
        structure.fillWithBlocks(world, start, 106, -37, 35, 106, -36, 35, Blocks.MOSSY_COBBLESTONE.getDefaultState());
        structure.fillWithBlocks(world, start, 106, -37, 36, 107, -37, 37, Blocks.STONE_BRICKS.getDefaultState());
        structure.fillWithBlocks(world, start, 106, -36, 19, 107, -36, 20, Blocks.STONE_BRICKS.getDefaultState());
        structure.fillWithBlocks(world, start, 106, -36, 22, 106, -36, 25, Blocks.MOSSY_STONE_BRICKS.getDefaultState());
        structure.fillWithBlocks(world, start, 106, -36, 26, 107, -36, 28, Blocks.STONE_BRICKS.getDefaultState());
        structure.fillWithBlocks(world, start, 106, -36, 29, 106, -36, 30, Blocks.MOSSY_STONE_BRICKS.getDefaultState());
        structure.fillWithBlocks(world, start, 106, -36, 31, 108, -36, 31, Blocks.STONE_BRICKS.getDefaultState());
        structure.fillWithBlocks(world, start, 106, -36, 33, 106, -36, 34, Blocks.STONE_BRICKS.getDefaultState());
        structure.fillWithBlocks(world, start, 106, -36, 36, 106, -36, 38, Blocks.STONE_BRICKS.getDefaultState());
        structure.fillWithBlocks(world, start, 106, -25, 44, 107, -25, 48, Blocks.STONE_BRICKS.getDefaultState());
        structure.fillWithBlocks(world, start, 106, -24, 43, 106, -22, 43, Blocks.STONE_BRICKS.getDefaultState());
        structure.fillWithBlocks(world, start, 106, -24, 44, 106, -24, 48, Blocks.AIR.getDefaultState());
        structure.fillWithBlocks(world, start, 106, -24, 49, 106, -22, 49, Blocks.STONE_BRICKS.getDefaultState());
        structure.fillWithBlocks(world, start, 106, -23, 44, 106, -23, 48, Blocks.AIR.getDefaultState());
        structure.fillWithBlocks(world, start, 106, -22, 44, 106, -22, 48, Blocks.AIR.getDefaultState());
        structure.fillWithBlocks(world, start, 106, -21, 44, 106, -21, 44, Blocks.STONE_BRICKS.getDefaultState());
        structure.fillWithBlocks(world, start, 106, -21, 46, 106, -21, 48, Blocks.STONE_BRICKS.getDefaultState());
        structure.fillWithBlocks(world, start, 106, -15, 39, 110, -15, 43, Blocks.STONE_BRICKS.getDefaultState());
        structure.fillWithBlocks(world, start, 106, -15, 51, 107, -15, 51, Blocks.MOSSY_STONE_BRICKS.getDefaultState());
        structure.fillWithBlocks(world, start, 106, -15, 52, 106, -14, 53, Blocks.STONE_BRICKS.getDefaultState());
        structure.fillWithBlocks(world, start, 106, -13, 52, 107, -13, 53, Blocks.STONE_BRICKS.getDefaultState());
        structure.fillWithBlocks(world, start, 106, -12, 39, 107, -12, 41, Blocks.STONE_BRICKS.getDefaultState());
        structure.fillWithBlocks(world, start, 106, -11, 46, 106, -11, 47, Blocks.MOSSY_STONE_BRICKS.getDefaultState());
        structure.fillWithBlocks(world, start, 106, -11, 48, 106, -10, 49, Blocks.STONE_BRICKS.getDefaultState());
        structure.fillWithBlocks(world, start, 106, -11, 50, 106, -11, 50, Blocks.STONE_BRICKS.getDefaultState());
        structure.fillWithBlocks(world, start, 106, -10, 41, 107, -10, 46, Blocks.STONE_BRICKS.getDefaultState());
        structure.fillWithBlocks(world, start, 106, -10, 47, 106, -10, 49, Blocks.STONE_BRICKS.getDefaultState());
        structure.fillWithBlocks(world, start, 106, -10, 51, 106, -8, 53, Blocks.STONE_BRICKS.getDefaultState());
        structure.fillWithBlocks(world, start, 106, -9, 39, 108, -9, 53, Blocks.STONE_BRICKS.getDefaultState());
        structure.fillWithBlocks(world, start, 106, -8, 39, 108, -8, 53, Blocks.STONE_BRICKS.getDefaultState());
        structure.fillWithBlocks(world, start, 106, -7, 42, 108, -7, 44, Blocks.STONE_BRICKS.getDefaultState());
        structure.fillWithBlocks(world, start, 106, -7, 46, 109, -7, 49, Blocks.STONE_BRICKS.getDefaultState());
        structure.fillWithBlocks(world, start, 106, -6, 39, 108, -6, 51, Blocks.STONE_BRICKS.getDefaultState());
        structure.fillWithBlocks(world, start, 107, -56, -20, 109, -56, -18, Blocks.STONE_BRICKS.getDefaultState());
        structure.fillWithBlocks(world, start, 107, -56, -10, 109, -56, -8, Blocks.STONE_BRICKS.getDefaultState());
        structure.fillWithBlocks(world, start, 107, -55, -22, 108, -55, -21, Blocks.STONE_BRICKS.getDefaultState());
        structure.fillWithBlocks(world, start, 107, -55, -20, 109, -55, -18, Blocks.AIR.getDefaultState());
        structure.fillWithBlocks(world, start, 107, -55, -10, 109, -55, -8, Blocks.AIR.getDefaultState());
        structure.fillWithBlocks(world, start, 107, -54, -21, 108, -54, -21, Blocks.STONE_BRICK_WALL.getDefaultState().with(WallBlock.WATERLOGGED, false).with(WallBlock.UP, true).with(WallBlock.WALL_HEIGHT_NORTH, WallHeight.LOW).with(WallBlock.WALL_HEIGHT_SOUTH, WallHeight.LOW).with(WallBlock.WALL_HEIGHT_EAST, WallHeight.LOW).with(WallBlock.WALL_HEIGHT_WEST, WallHeight.LOW));
        structure.fillWithBlocks(world, start, 107, -54, -20, 109, -54, -18, Blocks.AIR.getDefaultState());
        structure.fillWithBlocks(world, start, 107, -54, -10, 109, -54, -8, Blocks.AIR.getDefaultState());
        structure.fillWithBlocks(world, start, 107, -50, -22, 108, -50, -21, Blocks.STONE_BRICKS.getDefaultState());
        structure.fillWithBlocks(world, start, 107, -50, -7, 108, -50, -6, Blocks.STONE_BRICKS.getDefaultState());
        structure.fillWithBlocks(world, start, 107, -49, -22, 108, -49, -20, Blocks.STONE_BRICKS.getDefaultState());
        structure.fillWithBlocks(world, start, 107, -49, -18, 110, -49, -15, Blocks.STONE_BRICKS.getDefaultState());
        structure.fillWithBlocks(world, start, 107, -49, -13, 109, -49, -10, Blocks.STONE_BRICKS.getDefaultState());
        structure.fillWithBlocks(world, start, 107, -49, -8, 109, -49, -6, Blocks.STONE_BRICKS.getDefaultState());
        structure.fillWithBlocks(world, start, 107, -48, -17, 108, -48, -16, Blocks.STONE_BRICKS.getDefaultState());
        structure.fillWithBlocks(world, start, 107, -48, -15, 107, -47, -15, Blocks.AIR.getDefaultState());
        structure.fillWithBlocks(world, start, 107, -48, -14, 108, -48, -12, Blocks.STONE_BRICKS.getDefaultState());
        structure.fillWithBlocks(world, start, 107, -47, -16, 111, -46, -16, Blocks.STONE_BRICKS.getDefaultState());
        structure.fillWithBlocks(world, start, 107, -47, -13, 114, -47, -6, Blocks.STONE_BRICKS.getDefaultState());
        structure.fillWithBlocks(world, start, 107, -46, -22, 112, -46, -17, Blocks.STONE_BRICKS.getDefaultState());
        structure.fillWithBlocks(world, start, 107, -46, -9, 108, -46, -6, Blocks.STONE_BRICKS.getDefaultState());
        structure.fillWithBlocks(world, start, 107, -45, 18, 107, -45, 19, Blocks.STONE_BRICKS.getDefaultState());
        structure.fillWithBlocks(world, start, 107, -45, 21, 107, -44, 21, Blocks.AIR.getDefaultState());
        structure.fillWithBlocks(world, start, 107, -45, 22, 107, -45, 23, Blocks.MOSSY_STONE_BRICKS.getDefaultState());
        structure.fillWithBlocks(world, start, 107, -45, 24, 107, -44, 24, Blocks.STONE_BRICKS.getDefaultState());
        structure.fillWithBlocks(world, start, 107, -45, 25, 108, -45, 25, Blocks.MOSSY_STONE_BRICKS.getDefaultState());
        structure.fillWithBlocks(world, start, 107, -45, 26, 107, -45, 26, Blocks.STONE_BRICKS.getDefaultState());
        structure.fillWithBlocks(world, start, 107, -45, 29, 107, -45, 30, Blocks.MOSSY_STONE_BRICKS.getDefaultState());
        structure.fillWithBlocks(world, start, 107, -45, 34, 107, -45, 37, Blocks.STONE_BRICKS.getDefaultState());
        structure.fillWithBlocks(world, start, 107, -45, 38, 107, -44, 38, Blocks.MOSSY_STONE_BRICKS.getDefaultState());
        structure.fillWithBlocks(world, start, 107, -44, 20, 107, -44, 20, Blocks.STONE_BRICKS.getDefaultState());
        structure.fillWithBlocks(world, start, 107, -44, 22, 107, -44, 22, Blocks.MOSSY_STONE_BRICKS.getDefaultState());
        structure.fillWithBlocks(world, start, 107, -44, 23, 107, -44, 24, Blocks.STONE_BRICKS.getDefaultState());
        structure.fillWithBlocks(world, start, 107, -44, 27, 107, -44, 28, Blocks.STONE_BRICKS.getDefaultState());
        structure.fillWithBlocks(world, start, 107, -44, 29, 107, -44, 30, Blocks.AIR.getDefaultState());
        structure.fillWithBlocks(world, start, 107, -44, 34, 108, -44, 34, Blocks.MOSSY_COBBLESTONE.getDefaultState());
        structure.fillWithBlocks(world, start, 107, -44, 35, 107, -44, 35, Blocks.STONE_BRICKS.getDefaultState());
        structure.fillWithBlocks(world, start, 107, -44, 36, 107, -44, 38, Blocks.MOSSY_STONE_BRICKS.getDefaultState());
        structure.fillWithBlocks(world, start, 107, -43, 20, 108, -43, 20, Blocks.MOSSY_STONE_BRICKS.getDefaultState());
        structure.fillWithBlocks(world, start, 107, -43, 21, 107, -43, 21, Blocks.STONE_BRICKS.getDefaultState());
        structure.fillWithBlocks(world, start, 107, -43, 25, 107, -43, 25, Blocks.STONE_BRICKS.getDefaultState());
        structure.fillWithBlocks(world, start, 107, -43, 27, 107, -42, 27, Blocks.AIR.getDefaultState());
        structure.fillWithBlocks(world, start, 107, -43, 28, 107, -42, 29, Blocks.MOSSY_STONE_BRICKS.getDefaultState());
        structure.fillWithBlocks(world, start, 107, -43, 30, 108, -43, 30, Blocks.STONE_BRICKS.getDefaultState());
        structure.fillWithBlocks(world, start, 107, -43, 32, 108, -43, 33, Blocks.STONE_BRICKS.getDefaultState());
        structure.fillWithBlocks(world, start, 107, -43, 34, 107, -42, 34, Blocks.AIR.getDefaultState());
        structure.fillWithBlocks(world, start, 107, -43, 36, 107, -43, 38, Blocks.STONE_BRICKS.getDefaultState());
        structure.fillWithBlocks(world, start, 107, -42, 18, 107, -42, 22, Blocks.STONE_BRICKS.getDefaultState());
        structure.fillWithBlocks(world, start, 107, -42, 25, 107, -40, 25, Blocks.MOSSY_STONE_BRICKS.getDefaultState());
        structure.fillWithBlocks(world, start, 107, -42, 30, 107, -42, 33, Blocks.STONE_BRICKS.getDefaultState());
        structure.fillWithBlocks(world, start, 107, -42, 36, 107, -42, 37, Blocks.MOSSY_STONE_BRICKS.getDefaultState());
        structure.fillWithBlocks(world, start, 107, -41, 18, 108, -41, 18, Blocks.MOSSY_STONE_BRICKS.getDefaultState());
        structure.fillWithBlocks(world, start, 107, -41, 20, 108, -41, 20, Blocks.STONE_BRICKS.getDefaultState());
        structure.fillWithBlocks(world, start, 107, -41, 23, 107, -41, 23, Blocks.STONE_BRICKS.getDefaultState());
        structure.fillWithBlocks(world, start, 107, -41, 24, 107, -41, 25, Blocks.MOSSY_STONE_BRICKS.getDefaultState());
        structure.fillWithBlocks(world, start, 107, -41, 27, 107, -41, 27, Blocks.MOSSY_STONE_BRICKS.getDefaultState());
        structure.fillWithBlocks(world, start, 107, -41, 31, 107, -41, 32, Blocks.AIR.getDefaultState());
        structure.fillWithBlocks(world, start, 107, -41, 33, 107, -41, 34, Blocks.MOSSY_STONE_BRICKS.getDefaultState());
        structure.fillWithBlocks(world, start, 107, -40, 18, 107, -40, 19, Blocks.MOSSY_STONE_BRICKS.getDefaultState());
        structure.fillWithBlocks(world, start, 107, -40, 20, 107, -40, 22, Blocks.STONE_BRICKS.getDefaultState());
        structure.fillWithBlocks(world, start, 107, -40, 23, 107, -40, 23, Blocks.MOSSY_STONE_BRICKS.getDefaultState());
        structure.fillWithBlocks(world, start, 107, -40, 24, 107, -40, 24, Blocks.STONE_BRICKS.getDefaultState());
        structure.fillWithBlocks(world, start, 107, -40, 26, 107, -40, 28, Blocks.STONE_BRICKS.getDefaultState());
        structure.fillWithBlocks(world, start, 107, -40, 30, 107, -39, 31, Blocks.MOSSY_STONE_BRICKS.getDefaultState());
        structure.fillWithBlocks(world, start, 107, -40, 33, 107, -40, 37, Blocks.STONE_BRICKS.getDefaultState());
        structure.fillWithBlocks(world, start, 107, -39, 18, 107, -39, 18, Blocks.STONE_BRICKS.getDefaultState());
        structure.fillWithBlocks(world, start, 107, -39, 20, 107, -39, 20, Blocks.STONE_BRICKS.getDefaultState());
        structure.fillWithBlocks(world, start, 107, -39, 22, 108, -39, 23, Blocks.STONE_BRICKS.getDefaultState());
        structure.fillWithBlocks(world, start, 107, -39, 25, 107, -39, 25, Blocks.STONE_BRICKS.getDefaultState());
        structure.fillWithBlocks(world, start, 107, -39, 26, 107, -39, 27, Blocks.AIR.getDefaultState());
        structure.fillWithBlocks(world, start, 107, -39, 28, 107, -39, 29, Blocks.STONE_BRICKS.getDefaultState());
        structure.fillWithBlocks(world, start, 107, -39, 33, 107, -37, 33, Blocks.STONE_BRICKS.getDefaultState());
        structure.fillWithBlocks(world, start, 107, -39, 35, 108, -39, 38, Blocks.STONE_BRICKS.getDefaultState());
        structure.fillWithBlocks(world, start, 107, -38, 20, 107, -36, 20, Blocks.STONE_BRICKS.getDefaultState());
        structure.fillWithBlocks(world, start, 107, -38, 21, 107, -37, 21, Blocks.AIR.getDefaultState());
        structure.fillWithBlocks(world, start, 107, -38, 22, 108, -38, 23, Blocks.STONE_BRICKS.getDefaultState());
        structure.fillWithBlocks(world, start, 107, -38, 24, 107, -36, 24, Blocks.STONE_BRICKS.getDefaultState());
        structure.fillWithBlocks(world, start, 107, -38, 26, 107, -38, 27, Blocks.STONE_BRICKS.getDefaultState());
        structure.fillWithBlocks(world, start, 107, -38, 29, 107, -37, 29, Blocks.STONE_BRICKS.getDefaultState());
        structure.fillWithBlocks(world, start, 107, -38, 30, 108, -38, 31, Blocks.MOSSY_STONE_BRICKS.getDefaultState());
        structure.fillWithBlocks(world, start, 107, -38, 32, 107, -38, 32, Blocks.MOSSY_STONE_BRICKS.getDefaultState());
        structure.fillWithBlocks(world, start, 107, -38, 34, 108, -37, 34, Blocks.STONE_BRICKS.getDefaultState());
        structure.fillWithBlocks(world, start, 107, -38, 38, 108, -38, 38, Blocks.STONE_BRICKS.getDefaultState());
        structure.fillWithBlocks(world, start, 107, -37, 22, 108, -37, 22, Blocks.STONE_BRICKS.getDefaultState());
        structure.fillWithBlocks(world, start, 107, -37, 26, 107, -37, 26, Blocks.STONE_BRICKS.getDefaultState());
        structure.fillWithBlocks(world, start, 107, -37, 30, 107, -37, 37, Blocks.STONE_BRICKS.getDefaultState());
        structure.fillWithBlocks(world, start, 107, -36, 21, 107, -36, 21, Blocks.MOSSY_STONE_BRICKS.getDefaultState());
        structure.fillWithBlocks(world, start, 107, -36, 22, 107, -36, 28, Blocks.STONE_BRICKS.getDefaultState());
        structure.fillWithBlocks(world, start, 107, -36, 32, 107, -36, 32, Blocks.MOSSY_STONE_BRICKS.getDefaultState());
        structure.fillWithBlocks(world, start, 107, -36, 34, 107, -36, 35, Blocks.MOSSY_STONE_BRICKS.getDefaultState());
        structure.fillWithBlocks(world, start, 107, -36, 36, 107, -36, 36, Blocks.STONE_BRICKS.getDefaultState());
        structure.fillWithBlocks(world, start, 107, -36, 37, 107, -36, 37, Blocks.MOSSY_STONE_BRICKS.getDefaultState());
        structure.fillWithBlocks(world, start, 107, -24, 44, 107, -23, 44, Blocks.STONE_BRICKS.getDefaultState());
        structure.fillWithBlocks(world, start, 107, -24, 48, 107, -23, 48, Blocks.STONE_BRICKS.getDefaultState());
        structure.fillWithBlocks(world, start, 107, -22, 48, 107, -21, 48, Blocks.CRACKED_STONE_BRICKS.getDefaultState());
        structure.fillWithBlocks(world, start, 107, -21, 44, 107, -21, 45, Blocks.STONE_BRICKS.getDefaultState());
        structure.fillWithBlocks(world, start, 107, -21, 47, 109, -21, 47, Blocks.STONE_BRICKS.getDefaultState());
        structure.fillWithBlocks(world, start, 107, -15, 45, 111, -15, 50, Blocks.STONE_BRICKS.getDefaultState());
        structure.fillWithBlocks(world, start, 107, -15, 52, 107, -15, 52, Blocks.STONE_BRICKS.getDefaultState());
        structure.fillWithBlocks(world, start, 107, -14, 42, 108, -14, 43, Blocks.AIR.getDefaultState());
        structure.fillWithBlocks(world, start, 107, -14, 44, 107, -6, 44, Blocks.STONE_BRICKS.getDefaultState());
        structure.fillWithBlocks(world, start, 107, -14, 48, 107, -6, 48, Blocks.STONE_BRICKS.getDefaultState());
        structure.fillWithBlocks(world, start, 107, -14, 49, 108, -14, 50, Blocks.AIR.getDefaultState());
        structure.fillWithBlocks(world, start, 107, -14, 51, 107, -14, 53, Blocks.STONE_BRICKS.getDefaultState());
        structure.fillWithBlocks(world, start, 107, -13, 42, 108, -13, 43, Blocks.AIR.getDefaultState());
        structure.fillWithBlocks(world, start, 107, -13, 49, 108, -13, 50, Blocks.AIR.getDefaultState());
        structure.fillWithBlocks(world, start, 107, -13, 51, 107, -13, 53, Blocks.STONE_BRICKS.getDefaultState());
        structure.fillWithBlocks(world, start, 107, -12, 42, 108, -12, 43, Blocks.AIR.getDefaultState());
        structure.fillWithBlocks(world, start, 107, -12, 49, 108, -12, 50, Blocks.AIR.getDefaultState());
        structure.fillWithBlocks(world, start, 107, -12, 51, 107, -12, 53, Blocks.STONE_BRICKS.getDefaultState());
        structure.fillWithBlocks(world, start, 107, -11, 42, 108, -11, 43, Blocks.AIR.getDefaultState());
        structure.fillWithBlocks(world, start, 107, -11, 45, 109, -11, 47, Blocks.AIR.getDefaultState());
        structure.fillWithBlocks(world, start, 107, -11, 49, 108, -11, 50, Blocks.AIR.getDefaultState());
        structure.fillWithBlocks(world, start, 107, -11, 51, 107, -11, 53, Blocks.STONE_BRICKS.getDefaultState());
        structure.fillWithBlocks(world, start, 107, -10, 39, 109, -10, 42, Blocks.STONE_BRICKS.getDefaultState());
        structure.fillWithBlocks(world, start, 107, -10, 49, 108, -10, 51, Blocks.STONE_BRICKS.getDefaultState());
        structure.fillWithBlocks(world, start, 107, -7, 45, 111, -7, 49, Blocks.STONE_BRICKS.getDefaultState());
        structure.fillWithBlocks(world, start, 107, -7, 50, 108, -7, 51, Blocks.STONE_BRICKS.getDefaultState());
        structure.fillWithBlocks(world, start, 107, -7, 53, 108, -6, 53, Blocks.STONE_BRICKS.getDefaultState());
        structure.fillWithBlocks(world, start, 107, -6, 52, 108, -6, 53, Blocks.STONE_BRICKS.getDefaultState());
        structure.fillWithBlocks(world, start, 108, -56, -16, 108, -55, -12, Blocks.STONE_BRICKS.getDefaultState());
        structure.fillWithBlocks(world, start, 108, -55, -17, 114, -55, -11, Blocks.STONE_BRICKS.getDefaultState());
        structure.fillWithBlocks(world, start, 108, -55, -7, 109, -55, -6, Blocks.STONE_BRICKS.getDefaultState());
        structure.fillWithBlocks(world, start, 108, -50, -20, 109, -50, -18, Blocks.AIR.getDefaultState());
        structure.fillWithBlocks(world, start, 108, -50, -10, 109, -50, -8, Blocks.AIR.getDefaultState());
        structure.fillWithBlocks(world, start, 108, -49, -19, 111, -49, -14, Blocks.STONE_BRICKS.getDefaultState());
        structure.fillWithBlocks(world, start, 108, -49, -9, 111, -49, -6, Blocks.STONE_BRICKS.getDefaultState());
        structure.fillWithBlocks(world, start, 108, -48, -15, 110, -48, -13, Blocks.STONE_BRICKS.getDefaultState());
        structure.fillWithBlocks(world, start, 108, -48, -10, 111, -48, -6, Blocks.STONE_BRICKS.getDefaultState());
        structure.fillWithBlocks(world, start, 108, -47, -22, 110, -47, -16, Blocks.STONE_BRICKS.getDefaultState());
        structure.fillWithBlocks(world, start, 108, -47, -14, 115, -47, -6, Blocks.STONE_BRICKS.getDefaultState());
        structure.fillWithBlocks(world, start, 108, -45, 18, 108, -44, 18, Blocks.MOSSY_STONE_BRICKS.getDefaultState());
        structure.fillWithBlocks(world, start, 108, -45, 19, 108, -44, 22, Blocks.STONE_BRICKS.getDefaultState());
        structure.fillWithBlocks(world, start, 108, -45, 23, 108, -45, 25, Blocks.MOSSY_STONE_BRICKS.getDefaultState());
        structure.fillWithBlocks(world, start, 108, -45, 26, 108, -45, 31, Blocks.STONE_BRICKS.getDefaultState());
        structure.fillWithBlocks(world, start, 108, -45, 32, 108, -45, 33, Blocks.MOSSY_STONE_BRICKS.getDefaultState());
        structure.fillWithBlocks(world, start, 108, -45, 35, 108, -45, 36, Blocks.MOSSY_STONE_BRICKS.getDefaultState());
        structure.fillWithBlocks(world, start, 108, -45, 37, 108, -44, 38, Blocks.STONE_BRICKS.getDefaultState());
        structure.fillWithBlocks(world, start, 108, -44, 23, 108, -43, 23, Blocks.MOSSY_STONE_BRICKS.getDefaultState());
        structure.fillWithBlocks(world, start, 108, -44, 24, 108, -44, 26, Blocks.STONE_BRICKS.getDefaultState());
        structure.fillWithBlocks(world, start, 108, -44, 28, 108, -43, 30, Blocks.STONE_BRICKS.getDefaultState());
        structure.fillWithBlocks(world, start, 108, -44, 31, 108, -44, 33, Blocks.STONE_BRICKS.getDefaultState());
        structure.fillWithBlocks(world, start, 108, -44, 35, 108, -44, 38, Blocks.STONE_BRICKS.getDefaultState());
        structure.fillWithBlocks(world, start, 108, -43, 21, 108, -43, 22, Blocks.STONE_BRICKS.getDefaultState());
        structure.fillWithBlocks(world, start, 108, -43, 25, 108, -41, 27, Blocks.STONE_BRICKS.getDefaultState());
        structure.fillWithBlocks(world, start, 108, -43, 31, 108, -42, 31, Blocks.MOSSY_COBBLESTONE.getDefaultState());
        structure.fillWithBlocks(world, start, 108, -43, 34, 108, -43, 35, Blocks.MOSSY_COBBLESTONE.getDefaultState());
        structure.fillWithBlocks(world, start, 108, -43, 37, 108, -42, 38, Blocks.STONE_BRICKS.getDefaultState());
        structure.fillWithBlocks(world, start, 108, -42, 19, 108, -42, 22, Blocks.MOSSY_STONE_BRICKS.getDefaultState());
        structure.fillWithBlocks(world, start, 108, -42, 29, 108, -42, 30, Blocks.MOSSY_STONE_BRICKS.getDefaultState());
        structure.fillWithBlocks(world, start, 108, -42, 33, 108, -41, 38, Blocks.STONE_BRICKS.getDefaultState());
        structure.fillWithBlocks(world, start, 108, -41, 19, 108, -41, 20, Blocks.STONE_BRICKS.getDefaultState());
        structure.fillWithBlocks(world, start, 108, -41, 21, 108, -41, 22, Blocks.MOSSY_COBBLESTONE.getDefaultState());
        structure.fillWithBlocks(world, start, 108, -41, 24, 108, -41, 27, Blocks.STONE_BRICKS.getDefaultState());
        structure.fillWithBlocks(world, start, 108, -41, 28, 108, -39, 28, Blocks.MOSSY_STONE_BRICKS.getDefaultState());
        structure.fillWithBlocks(world, start, 108, -41, 29, 108, -40, 30, Blocks.STONE_BRICKS.getDefaultState());
        structure.fillWithBlocks(world, start, 108, -41, 32, 108, -41, 38, Blocks.STONE_BRICKS.getDefaultState());
        structure.fillWithBlocks(world, start, 108, -40, 18, 108, -39, 18, Blocks.STONE_BRICKS.getDefaultState());
        structure.fillWithBlocks(world, start, 108, -40, 19, 108, -40, 20, Blocks.MOSSY_STONE_BRICKS.getDefaultState());
        structure.fillWithBlocks(world, start, 108, -40, 23, 108, -38, 23, Blocks.STONE_BRICKS.getDefaultState());
        structure.fillWithBlocks(world, start, 108, -40, 25, 108, -39, 26, Blocks.STONE_BRICKS.getDefaultState());
        structure.fillWithBlocks(world, start, 108, -40, 27, 108, -39, 28, Blocks.MOSSY_STONE_BRICKS.getDefaultState());
        structure.fillWithBlocks(world, start, 108, -40, 31, 108, -40, 32, Blocks.STONE_BRICKS.getDefaultState());
        structure.fillWithBlocks(world, start, 108, -40, 33, 108, -38, 33, Blocks.MOSSY_STONE_BRICKS.getDefaultState());
        structure.fillWithBlocks(world, start, 108, -40, 35, 108, -39, 38, Blocks.STONE_BRICKS.getDefaultState());
        structure.fillWithBlocks(world, start, 108, -39, 19, 108, -39, 26, Blocks.STONE_BRICKS.getDefaultState());
        structure.fillWithBlocks(world, start, 108, -39, 29, 108, -39, 30, Blocks.STONE_BRICKS.getDefaultState());
        structure.fillWithBlocks(world, start, 108, -39, 31, 108, -38, 31, Blocks.MOSSY_STONE_BRICKS.getDefaultState());
        structure.fillWithBlocks(world, start, 108, -39, 34, 108, -39, 38, Blocks.STONE_BRICKS.getDefaultState());
        structure.fillWithBlocks(world, start, 108, -38, 19, 108, -37, 19, Blocks.STONE_BRICKS.getDefaultState());
        structure.fillWithBlocks(world, start, 108, -38, 21, 108, -38, 23, Blocks.STONE_BRICKS.getDefaultState());
        structure.fillWithBlocks(world, start, 108, -38, 28, 108, -36, 28, Blocks.STONE_BRICKS.getDefaultState());
        structure.fillWithBlocks(world, start, 108, -38, 32, 108, -37, 32, Blocks.MOSSY_COBBLESTONE.getDefaultState());
        structure.fillWithBlocks(world, start, 108, -38, 36, 108, -37, 37, Blocks.STONE_BRICKS.getDefaultState());
        structure.fillWithBlocks(world, start, 108, -37, 20, 108, -36, 20, Blocks.STONE_BRICKS.getDefaultState());
        structure.fillWithBlocks(world, start, 108, -37, 26, 108, -37, 28, Blocks.STONE_BRICKS.getDefaultState());
        structure.fillWithBlocks(world, start, 108, -37, 29, 108, -37, 30, Blocks.MOSSY_STONE_BRICKS.getDefaultState());
        structure.fillWithBlocks(world, start, 108, -37, 31, 108, -36, 31, Blocks.STONE_BRICKS.getDefaultState());
        structure.fillWithBlocks(world, start, 108, -37, 33, 108, -37, 37, Blocks.STONE_BRICKS.getDefaultState());
        structure.fillWithBlocks(world, start, 108, -37, 38, 108, -36, 38, Blocks.MOSSY_STONE_BRICKS.getDefaultState());
        structure.fillWithBlocks(world, start, 108, -36, 25, 108, -36, 26, Blocks.STONE_BRICKS.getDefaultState());
        structure.fillWithBlocks(world, start, 108, -36, 29, 108, -36, 31, Blocks.STONE_BRICKS.getDefaultState());
        structure.fillWithBlocks(world, start, 108, -36, 32, 108, -36, 33, Blocks.MOSSY_STONE_BRICKS.getDefaultState());
        structure.fillWithBlocks(world, start, 108, -36, 35, 108, -36, 36, Blocks.INFESTED_CRACKED_STONE_BRICKS.getDefaultState());
        structure.fillWithBlocks(world, start, 108, -24, 43, 112, -24, 43, Blocks.STONE_BRICKS.getDefaultState());
        structure.fillWithBlocks(world, start, 108, -24, 44, 109, -24, 45, Blocks.AIR.getDefaultState());
        structure.fillWithBlocks(world, start, 108, -24, 46, 108, -24, 48, Blocks.AIR.getDefaultState());
        structure.fillWithBlocks(world, start, 108, -24, 49, 111, -24, 49, Blocks.STONE_BRICKS.getDefaultState());
        structure.fillWithBlocks(world, start, 108, -23, 44, 110, -23, 48, Blocks.AIR.getDefaultState());
        structure.fillWithBlocks(world, start, 108, -23, 49, 108, -22, 49, Blocks.CRACKED_STONE_BRICKS.getDefaultState());
        structure.fillWithBlocks(world, start, 108, -22, 44, 110, -22, 48, Blocks.AIR.getDefaultState());
        structure.fillWithBlocks(world, start, 108, -21, 44, 108, -21, 44, Blocks.STONE_BRICKS.getDefaultState());
        structure.fillWithBlocks(world, start, 108, -21, 46, 109, -21, 47, Blocks.STONE_BRICKS.getDefaultState());
        structure.fillWithBlocks(world, start, 108, -15, 44, 111, -15, 50, Blocks.STONE_BRICKS.getDefaultState());
        structure.fillWithBlocks(world, start, 108, -15, 51, 108, -15, 53, Blocks.STONE_BRICKS.getDefaultState());
        structure.fillWithBlocks(world, start, 108, -14, 39, 109, -14, 40, Blocks.STONE_BRICKS.getDefaultState());
        structure.fillWithBlocks(world, start, 108, -14, 41, 109, -14, 51, Blocks.AIR.getDefaultState());
        structure.fillWithBlocks(world, start, 108, -14, 52, 109, -14, 53, Blocks.STONE_BRICKS.getDefaultState());
        structure.fillWithBlocks(world, start, 108, -13, 39, 109, -13, 40, Blocks.STONE_BRICKS.getDefaultState());
        structure.fillWithBlocks(world, start, 108, -13, 41, 109, -13, 51, Blocks.AIR.getDefaultState());
        structure.fillWithBlocks(world, start, 108, -13, 52, 108, -12, 53, Blocks.STONE_BRICKS.getDefaultState());
        structure.fillWithBlocks(world, start, 108, -12, 39, 109, -12, 40, Blocks.STONE_BRICKS.getDefaultState());
        structure.fillWithBlocks(world, start, 108, -12, 41, 109, -12, 51, Blocks.AIR.getDefaultState());
        structure.fillWithBlocks(world, start, 108, -11, 39, 109, -11, 40, Blocks.STONE_BRICKS.getDefaultState());
        structure.fillWithBlocks(world, start, 108, -11, 41, 109, -11, 51, Blocks.AIR.getDefaultState());
        structure.fillWithBlocks(world, start, 108, -11, 52, 109, -11, 53, Blocks.STONE_BRICKS.getDefaultState());
        structure.fillWithBlocks(world, start, 108, -10, 44, 108, -6, 53, Blocks.STONE_BRICKS.getDefaultState());
        structure.fillWithBlocks(world, start, 108, -7, 39, 111, -7, 42, Blocks.STONE_BRICKS.getDefaultState());
        structure.fillWithBlocks(world, start, 109, -55, -22, 110, -55, -21, Blocks.STONE_BRICKS.getDefaultState());
        structure.fillWithBlocks(world, start, 109, -50, -22, 110, -50, -21, Blocks.STONE_BRICKS.getDefaultState());
        structure.fillWithBlocks(world, start, 109, -50, -7, 110, -50, -6, Blocks.STONE_BRICKS.getDefaultState());
        structure.fillWithBlocks(world, start, 109, -49, -20, 111, -49, -14, Blocks.STONE_BRICKS.getDefaultState());
        structure.fillWithBlocks(world, start, 109, -48, -17, 109, -48, -13, Blocks.STONE_BRICKS.getDefaultState());
        structure.fillWithBlocks(world, start, 109, -48, -11, 111, -48, -6, Blocks.STONE_BRICKS.getDefaultState());
        structure.fillWithBlocks(world, start, 109, -47, -15, 112, -47, -6, Blocks.STONE_BRICKS.getDefaultState());
        structure.fillWithBlocks(world, start, 109, -46, -8, 109, -46, -6, Blocks.STONE_BRICKS.getDefaultState());
        structure.fillWithBlocks(world, start, 109, -25, 45, 111, -25, 47, Blocks.STONE_BRICKS.getDefaultState());
        structure.fillWithBlocks(world, start, 109, -24, 47, 110, -24, 48, Blocks.AIR.getDefaultState());
        structure.fillWithBlocks(world, start, 109, -22, 43, 110, -22, 43, Blocks.STONE_BRICKS.getDefaultState());
        structure.fillWithBlocks(world, start, 109, -21, 45, 109, -21, 48, Blocks.STONE_BRICKS.getDefaultState());
        structure.fillWithBlocks(world, start, 109, -15, 52, 110, -15, 53, Blocks.STONE_BRICKS.getDefaultState());
        structure.fillWithBlocks(world, start, 109, -13, 52, 109, -13, 52, Blocks.STONE_BRICKS.getDefaultState());
        structure.fillWithBlocks(world, start, 109, -12, 52, 110, -12, 53, Blocks.STONE_BRICKS.getDefaultState());
        structure.fillWithBlocks(world, start, 109, -10, 43, 115, -10, 49, Blocks.AIR.getDefaultState());
        structure.fillWithBlocks(world, start, 109, -10, 50, 110, -10, 53, Blocks.STONE_BRICKS.getDefaultState());
        structure.fillWithBlocks(world, start, 109, -9, 39, 110, -9, 40, Blocks.STONE_BRICKS.getDefaultState());
        structure.fillWithBlocks(world, start, 109, -9, 41, 109, -6, 41, Blocks.STONE_BRICKS.getDefaultState());
        structure.fillWithBlocks(world, start, 109, -9, 42, 110, -9, 42, Blocks.MOSSY_STONE_BRICKS.getDefaultState());
        structure.fillWithBlocks(world, start, 109, -9, 43, 110, -9, 53, Blocks.STONE_BRICKS.getDefaultState());
        structure.fillWithBlocks(world, start, 109, -8, 39, 109, -8, 39, Blocks.STONE_BRICKS.getDefaultState());
        structure.fillWithBlocks(world, start, 109, -8, 42, 114, -8, 48, Blocks.STONE_BRICKS.getDefaultState());
        structure.fillWithBlocks(world, start, 109, -7, 43, 110, -7, 49, Blocks.STONE_BRICKS.getDefaultState());
        structure.fillWithBlocks(world, start, 109, -7, 51, 110, -7, 52, Blocks.STONE_BRICKS.getDefaultState());
        structure.fillWithBlocks(world, start, 109, -7, 53, 109, -6, 53, Blocks.MOSSY_STONE_BRICKS.getDefaultState());
        structure.fillWithBlocks(world, start, 109, -6, 39, 111, -6, 41, Blocks.STONE_BRICKS.getDefaultState());
        structure.fillWithBlocks(world, start, 109, -6, 43, 110, -6, 44, Blocks.STONE_BRICKS.getDefaultState());
        structure.fillWithBlocks(world, start, 109, -6, 45, 109, -6, 52, Blocks.STONE_BRICKS.getDefaultState());
        structure.fillWithBlocks(world, start, 110, -56, -20, 112, -56, -18, Blocks.STONE_BRICKS.getDefaultState());
        structure.fillWithBlocks(world, start, 110, -56, -10, 112, -56, -8, Blocks.STONE_BRICKS.getDefaultState());
        structure.fillWithBlocks(world, start, 110, -55, -20, 112, -55, -18, Blocks.AIR.getDefaultState());
        structure.fillWithBlocks(world, start, 110, -55, -10, 112, -55, -8, Blocks.AIR.getDefaultState());
        structure.fillWithBlocks(world, start, 110, -55, -7, 111, -55, -6, Blocks.STONE_BRICKS.getDefaultState());
        structure.fillWithBlocks(world, start, 110, -54, -22, 110, -54, -21, Blocks.STONE_BRICKS.getDefaultState());
        structure.fillWithBlocks(world, start, 110, -54, -20, 112, -54, -18, Blocks.AIR.getDefaultState());
        structure.fillWithBlocks(world, start, 110, -54, -17, 110, -49, -17, Blocks.STONE_BRICKS.getDefaultState());
        structure.fillWithBlocks(world, start, 110, -54, -16, 114, -54, -12, Blocks.AIR.getDefaultState());
        structure.fillWithBlocks(world, start, 110, -54, -11, 110, -46, -11, Blocks.STONE_BRICKS.getDefaultState());
        structure.fillWithBlocks(world, start, 110, -54, -10, 112, -54, -8, Blocks.AIR.getDefaultState());
        structure.fillWithBlocks(world, start, 110, -54, -7, 110, -54, -6, Blocks.STONE_BRICKS.getDefaultState());
        structure.fillWithBlocks(world, start, 110, -53, -22, 110, -53, -22, Blocks.AIR.getDefaultState());
        structure.fillWithBlocks(world, start, 110, -53, -21, 110, -46, -21, Blocks.STONE_BRICKS.getDefaultState());
        structure.fillWithBlocks(world, start, 110, -53, -20, 112, -53, -18, Blocks.AIR.getDefaultState());
        structure.fillWithBlocks(world, start, 110, -53, -16, 114, -53, -12, Blocks.AIR.getDefaultState());
        structure.fillWithBlocks(world, start, 110, -53, -10, 112, -53, -8, Blocks.AIR.getDefaultState());
        structure.fillWithBlocks(world, start, 110, -53, -7, 110, -53, -6, Blocks.STONE_BRICKS.getDefaultState());
        structure.fillWithBlocks(world, start, 110, -52, -22, 110, -52, -21, Blocks.STONE_BRICKS.getDefaultState());
        structure.fillWithBlocks(world, start, 110, -52, -20, 112, -52, -18, Blocks.AIR.getDefaultState());
        structure.fillWithBlocks(world, start, 110, -52, -16, 114, -52, -12, Blocks.AIR.getDefaultState());
        structure.fillWithBlocks(world, start, 110, -52, -10, 112, -52, -8, Blocks.AIR.getDefaultState());
        structure.fillWithBlocks(world, start, 110, -52, -7, 110, -52, -6, Blocks.STONE_BRICKS.getDefaultState());
        structure.fillWithBlocks(world, start, 110, -51, -22, 110, -51, -22, Blocks.AIR.getDefaultState());
        structure.fillWithBlocks(world, start, 110, -51, -20, 112, -51, -18, Blocks.AIR.getDefaultState());
        structure.fillWithBlocks(world, start, 110, -51, -16, 114, -51, -12, Blocks.AIR.getDefaultState());
        structure.fillWithBlocks(world, start, 110, -51, -10, 112, -51, -8, Blocks.AIR.getDefaultState());
        structure.fillWithBlocks(world, start, 110, -51, -7, 110, -47, -7, Blocks.STONE_BRICKS.getDefaultState());
        structure.fillWithBlocks(world, start, 110, -50, -20, 110, -48, -18, Blocks.STONE_BRICKS.getDefaultState());
        structure.fillWithBlocks(world, start, 110, -50, -16, 110, -48, -14, Blocks.STONE_BRICKS.getDefaultState());
        structure.fillWithBlocks(world, start, 110, -50, -13, 110, -50, -6, Blocks.STONE_BRICKS.getDefaultState());
        structure.fillWithBlocks(world, start, 110, -49, -22, 111, -49, -14, Blocks.STONE_BRICKS.getDefaultState());
        structure.fillWithBlocks(world, start, 110, -49, -12, 112, -49, -10, Blocks.STONE_BRICKS.getDefaultState());
        structure.fillWithBlocks(world, start, 110, -48, -22, 112, -48, -18, Blocks.STONE_BRICKS.getDefaultState());
        structure.fillWithBlocks(world, start, 110, -48, -17, 111, -48, -17, Blocks.AIR.getDefaultState());
        structure.fillWithBlocks(world, start, 110, -48, -12, 113, -48, -9, Blocks.STONE_BRICKS.getDefaultState());
        structure.fillWithBlocks(world, start, 110, -46, -9, 111, -46, -8, Blocks.STONE_BRICKS.getDefaultState());
        structure.fillWithBlocks(world, start, 110, -25, 44, 113, -25, 47, Blocks.STONE_BRICKS.getDefaultState());
        structure.fillWithBlocks(world, start, 110, -24, 44, 110, -24, 48, Blocks.AIR.getDefaultState());
        structure.fillWithBlocks(world, start, 110, -23, 43, 110, -23, 43, Blocks.STONE_BRICKS.getDefaultState());
        structure.fillWithBlocks(world, start, 110, -23, 49, 110, -23, 49, Blocks.STONE_BRICKS.getDefaultState());
        structure.fillWithBlocks(world, start, 110, -21, 44, 111, -21, 44, Blocks.STONE_BRICKS.getDefaultState());
        structure.fillWithBlocks(world, start, 110, -21, 45, 111, -21, 45, Blocks.MOSSY_STONE_BRICKS.getDefaultState());
        structure.fillWithBlocks(world, start, 110, -21, 48, 110, -21, 48, Blocks.CRACKED_STONE_BRICKS.getDefaultState());
        structure.fillWithBlocks(world, start, 110, -15, 51, 111, -15, 52, Blocks.STONE_BRICKS.getDefaultState());
        structure.fillWithBlocks(world, start, 110, -14, 39, 110, -14, 41, Blocks.STONE_BRICKS.getDefaultState());
        structure.fillWithBlocks(world, start, 110, -14, 42, 111, -14, 50, Blocks.AIR.getDefaultState());
        structure.fillWithBlocks(world, start, 110, -14, 51, 110, -7, 51, Blocks.STONE_BRICKS.getDefaultState());
        structure.fillWithBlocks(world, start, 110, -14, 53, 114, -10, 53, Blocks.STONE_BRICKS.getDefaultState());
        structure.fillWithBlocks(world, start, 110, -13, 39, 110, -13, 41, Blocks.STONE_BRICKS.getDefaultState());
        structure.fillWithBlocks(world, start, 110, -13, 42, 116, -13, 50, Blocks.AIR.getDefaultState());
        structure.fillWithBlocks(world, start, 110, -13, 52, 111, -13, 53, Blocks.STONE_BRICKS.getDefaultState());
        structure.fillWithBlocks(world, start, 110, -12, 39, 110, -12, 39, Blocks.STONE_BRICKS.getDefaultState());
        structure.fillWithBlocks(world, start, 110, -12, 41, 110, -10, 41, Blocks.STONE_BRICKS.getDefaultState());
        structure.fillWithBlocks(world, start, 110, -12, 42, 116, -12, 50, Blocks.AIR.getDefaultState());
        structure.fillWithBlocks(world, start, 110, -11, 39, 111, -11, 40, Blocks.STONE_BRICKS.getDefaultState());
        structure.fillWithBlocks(world, start, 110, -11, 42, 116, -11, 50, Blocks.AIR.getDefaultState());
        structure.fillWithBlocks(world, start, 110, -11, 52, 111, -11, 53, Blocks.STONE_BRICKS.getDefaultState());
        structure.fillWithBlocks(world, start, 110, -10, 39, 110, -10, 39, Blocks.STONE_BRICKS.getDefaultState());
        structure.fillWithBlocks(world, start, 110, -10, 42, 114, -10, 42, Blocks.STONE_BRICKS.getDefaultState());
        structure.fillWithBlocks(world, start, 110, -9, 41, 110, -9, 42, Blocks.MOSSY_STONE_BRICKS.getDefaultState());
        structure.fillWithBlocks(world, start, 110, -8, 39, 114, -8, 48, Blocks.STONE_BRICKS.getDefaultState());
        structure.fillWithBlocks(world, start, 110, -7, 50, 112, -7, 53, Blocks.STONE_BRICKS.getDefaultState());
        structure.fillWithBlocks(world, start, 110, -6, 42, 112, -6, 44, Blocks.STONE_BRICKS.getDefaultState());
        structure.fillWithBlocks(world, start, 110, -6, 46, 110, -6, 46, Blocks.STONE_BRICKS.getDefaultState());
        structure.fillWithBlocks(world, start, 110, -6, 48, 112, -6, 50, Blocks.STONE_BRICKS.getDefaultState());
        structure.fillWithBlocks(world, start, 110, -6, 52, 111, -6, 53, Blocks.STONE_BRICKS.getDefaultState());
        structure.fillWithBlocks(world, start, 111, -55, -22, 112, -55, -21, Blocks.STONE_BRICKS.getDefaultState());
        structure.fillWithBlocks(world, start, 111, -54, -22, 115, -50, -22, Blocks.STONE_BRICKS.getDefaultState());
        structure.fillWithBlocks(world, start, 111, -54, -17, 113, -54, -17, Blocks.STONE_BRICK_WALL.getDefaultState().with(WallBlock.WATERLOGGED, false).with(WallBlock.UP, false).with(WallBlock.WALL_HEIGHT_NORTH, WallHeight.LOW).with(WallBlock.WALL_HEIGHT_SOUTH, WallHeight.LOW).with(WallBlock.WALL_HEIGHT_EAST, WallHeight.LOW).with(WallBlock.WALL_HEIGHT_WEST, WallHeight.LOW));
        structure.fillWithBlocks(world, start, 111, -54, -7, 113, -54, -7, Blocks.STONE_BRICK_WALL.getDefaultState().with(WallBlock.WATERLOGGED, false).with(WallBlock.UP, false).with(WallBlock.WALL_HEIGHT_NORTH, WallHeight.LOW).with(WallBlock.WALL_HEIGHT_SOUTH, WallHeight.LOW).with(WallBlock.WALL_HEIGHT_EAST, WallHeight.LOW).with(WallBlock.WALL_HEIGHT_WEST, WallHeight.LOW));
        structure.fillWithBlocks(world, start, 111, -54, -6, 115, -50, -6, Blocks.STONE_BRICKS.getDefaultState());
        structure.fillWithBlocks(world, start, 111, -53, -21, 113, -53, -7, Blocks.AIR.getDefaultState());
        structure.fillWithBlocks(world, start, 111, -52, -21, 113, -52, -7, Blocks.AIR.getDefaultState());
        structure.fillWithBlocks(world, start, 111, -51, -21, 113, -51, -7, Blocks.AIR.getDefaultState());
        structure.fillWithBlocks(world, start, 111, -50, -20, 113, -50, -18, Blocks.AIR.getDefaultState());
        structure.fillWithBlocks(world, start, 111, -50, -16, 113, -50, -12, Blocks.AIR.getDefaultState());
        structure.fillWithBlocks(world, start, 111, -50, -10, 113, -50, -8, Blocks.AIR.getDefaultState());
        structure.fillWithBlocks(world, start, 111, -50, -7, 112, -50, -6, Blocks.STONE_BRICKS.getDefaultState());
        structure.fillWithBlocks(world, start, 111, -49, -13, 114, -49, -10, Blocks.STONE_BRICKS.getDefaultState());
        structure.fillWithBlocks(world, start, 111, -48, -16, 114, -48, -13, Blocks.STONE_BRICKS.getDefaultState());
        structure.fillWithBlocks(world, start, 111, -47, -20, 114, -47, -16, Blocks.STONE_BRICKS.getDefaultState());
        structure.fillWithBlocks(world, start, 111, -46, -7, 112, -46, -6, Blocks.STONE_BRICKS.getDefaultState());
        structure.fillWithBlocks(world, start, 111, -25, 42, 114, -25, 49, Blocks.STONE_BRICKS.getDefaultState());
        structure.fillWithBlocks(world, start, 111, -25, 50, 111, -21, 50, Blocks.STONE_BRICKS.getDefaultState());
        structure.fillWithBlocks(world, start, 111, -24, 42, 112, -24, 43, Blocks.STONE_BRICKS.getDefaultState());
        structure.fillWithBlocks(world, start, 111, -24, 45, 113, -24, 47, Blocks.AIR.getDefaultState());
        structure.fillWithBlocks(world, start, 111, -24, 48, 111, -24, 50, Blocks.STONE_BRICKS.getDefaultState());
        structure.fillWithBlocks(world, start, 111, -23, 42, 111, -23, 42, Blocks.CRACKED_STONE_BRICKS.getDefaultState());
        structure.fillWithBlocks(world, start, 111, -23, 43, 111, -23, 44, Blocks.STONE_BRICKS.getDefaultState());
        structure.fillWithBlocks(world, start, 111, -23, 45, 113, -23, 47, Blocks.AIR.getDefaultState());
        structure.fillWithBlocks(world, start, 111, -23, 48, 111, -23, 48, Blocks.STONE_BRICKS.getDefaultState());
        structure.fillWithBlocks(world, start, 111, -23, 49, 111, -17, 49, Blocks.CRACKED_STONE_BRICKS.getDefaultState());
        structure.fillWithBlocks(world, start, 111, -22, 42, 111, -22, 42, Blocks.STONE_BRICKS.getDefaultState());
        structure.fillWithBlocks(world, start, 111, -22, 43, 111, -22, 44, Blocks.MOSSY_STONE_BRICKS.getDefaultState());
        structure.fillWithBlocks(world, start, 111, -22, 45, 113, -22, 47, Blocks.AIR.getDefaultState());
        structure.fillWithBlocks(world, start, 111, -22, 48, 111, -22, 49, Blocks.CRACKED_STONE_BRICKS.getDefaultState());
        structure.fillWithBlocks(world, start, 111, -21, 42, 111, -20, 42, Blocks.STONE_BRICKS.getDefaultState());
        structure.fillWithBlocks(world, start, 111, -21, 43, 111, -21, 43, Blocks.CRACKED_STONE_BRICKS.getDefaultState());
        structure.fillWithBlocks(world, start, 111, -21, 46, 112, -21, 47, Blocks.STONE_BRICKS.getDefaultState());
        structure.fillWithBlocks(world, start, 111, -20, 43, 114, -20, 43, Blocks.STONE_BRICKS.getDefaultState());
        structure.fillWithBlocks(world, start, 111, -20, 44, 111, -20, 44, Blocks.CRACKED_STONE_BRICKS.getDefaultState());
        structure.fillWithBlocks(world, start, 111, -20, 47, 111, -20, 47, Blocks.STONE_BRICKS.getDefaultState());
        structure.fillWithBlocks(world, start, 111, -20, 48, 111, -19, 48, Blocks.MOSSY_STONE_BRICKS.getDefaultState());
        structure.fillWithBlocks(world, start, 111, -20, 50, 112, -20, 50, Blocks.CRACKED_STONE_BRICKS.getDefaultState());
        structure.fillWithBlocks(world, start, 111, -19, 42, 111, -19, 43, Blocks.MOSSY_STONE_BRICKS.getDefaultState());
        structure.fillWithBlocks(world, start, 111, -19, 44, 111, -19, 44, Blocks.STONE_BRICKS.getDefaultState());
        structure.fillWithBlocks(world, start, 111, -19, 47, 111, -19, 47, Blocks.CRACKED_STONE_BRICKS.getDefaultState());
        structure.fillWithBlocks(world, start, 111, -18, 42, 111, -18, 43, Blocks.STONE_BRICKS.getDefaultState());
        structure.fillWithBlocks(world, start, 111, -18, 45, 111, -17, 45, Blocks.MOSSY_STONE_BRICKS.getDefaultState());
        structure.fillWithBlocks(world, start, 111, -18, 46, 111, -18, 46, Blocks.STONE_BRICKS.getDefaultState());
        structure.fillWithBlocks(world, start, 111, -18, 48, 111, -18, 48, Blocks.STONE_BRICKS.getDefaultState());
        structure.fillWithBlocks(world, start, 111, -18, 50, 112, -18, 50, Blocks.STONE_BRICKS.getDefaultState());
        structure.fillWithBlocks(world, start, 111, -17, 42, 111, -17, 42, Blocks.STONE_BRICKS.getDefaultState());
        structure.fillWithBlocks(world, start, 111, -17, 44, 111, -15, 44, Blocks.STONE_BRICKS.getDefaultState());
        structure.fillWithBlocks(world, start, 111, -17, 46, 111, -17, 48, Blocks.STONE_BRICKS.getDefaultState());
        structure.fillWithBlocks(world, start, 111, -17, 50, 111, -15, 50, Blocks.STONE_BRICKS.getDefaultState());
        structure.fillWithBlocks(world, start, 111, -16, 42, 111, -16, 42, Blocks.CRACKED_STONE_BRICKS.getDefaultState());
        structure.fillWithBlocks(world, start, 111, -16, 43, 111, -15, 47, Blocks.STONE_BRICKS.getDefaultState());
        structure.fillWithBlocks(world, start, 111, -16, 48, 112, -16, 48, Blocks.CRACKED_STONE_BRICKS.getDefaultState());
        structure.fillWithBlocks(world, start, 111, -16, 49, 112, -16, 50, Blocks.STONE_BRICKS.getDefaultState());
        structure.fillWithBlocks(world, start, 111, -15, 39, 112, -15, 40, Blocks.STONE_BRICKS.getDefaultState());
        structure.fillWithBlocks(world, start, 111, -15, 42, 114, -15, 45, Blocks.STONE_BRICKS.getDefaultState());
        structure.fillWithBlocks(world, start, 111, -14, 40, 119, -14, 40, Blocks.STONE_BRICKS.getDefaultState());
        structure.fillWithBlocks(world, start, 111, -14, 41, 111, -14, 51, Blocks.AIR.getDefaultState());
        structure.fillWithBlocks(world, start, 111, -14, 52, 112, -14, 53, Blocks.STONE_BRICKS.getDefaultState());
        structure.fillWithBlocks(world, start, 111, -13, 39, 114, -10, 39, Blocks.STONE_BRICKS.getDefaultState());
        structure.fillWithBlocks(world, start, 111, -13, 41, 113, -13, 51, Blocks.AIR.getDefaultState());
        structure.fillWithBlocks(world, start, 111, -12, 40, 117, -6, 40, Blocks.STONE_BRICKS.getDefaultState());
        structure.fillWithBlocks(world, start, 111, -12, 41, 113, -12, 51, Blocks.AIR.getDefaultState());
        structure.fillWithBlocks(world, start, 111, -12, 52, 112, -12, 53, Blocks.STONE_BRICKS.getDefaultState());
        structure.fillWithBlocks(world, start, 111, -11, 41, 113, -11, 51, Blocks.AIR.getDefaultState());
        structure.fillWithBlocks(world, start, 111, -10, 41, 112, -10, 42, Blocks.STONE_BRICKS.getDefaultState());
        structure.fillWithBlocks(world, start, 111, -10, 50, 111, -6, 50, Blocks.STONE_BRICKS.getDefaultState());
        structure.fillWithBlocks(world, start, 111, -10, 52, 112, -10, 53, Blocks.STONE_BRICKS.getDefaultState());
        structure.fillWithBlocks(world, start, 111, -9, 39, 114, -9, 42, Blocks.STONE_BRICKS.getDefaultState());
        structure.fillWithBlocks(world, start, 111, -9, 44, 112, -9, 45, Blocks.STONE_BRICKS.getDefaultState());
        structure.fillWithBlocks(world, start, 111, -7, 44, 116, -7, 49, Blocks.STONE_BRICKS.getDefaultState());
        structure.fillWithBlocks(world, start, 111, -6, 45, 111, -6, 53, Blocks.STONE_BRICKS.getDefaultState());
        structure.fillWithBlocks(world, start, 112, -55, -7, 113, -55, -6, Blocks.STONE_BRICKS.getDefaultState());
        structure.fillWithBlocks(world, start, 112, -49, -22, 113, -49, -22, Blocks.AIR.getDefaultState());
        structure.fillWithBlocks(world, start, 112, -49, -20, 112, -49, -20, Blocks.STONE_BRICKS.getDefaultState());
        structure.fillWithBlocks(world, start, 112, -49, -18, 115, -49, -15, Blocks.STONE_BRICKS.getDefaultState());
        structure.fillWithBlocks(world, start, 112, -49, -8, 112, -49, -6, Blocks.STONE_BRICKS.getDefaultState());
        structure.fillWithBlocks(world, start, 112, -48, -17, 113, -48, -9, Blocks.STONE_BRICKS.getDefaultState());
        structure.fillWithBlocks(world, start, 112, -48, -8, 112, -48, -8, Blocks.AIR.getDefaultState());
        structure.fillWithBlocks(world, start, 112, -48, -7, 112, -48, -6, Blocks.STONE_BRICKS.getDefaultState());
        structure.fillWithBlocks(world, start, 112, -47, -22, 113, -47, -16, Blocks.STONE_BRICKS.getDefaultState());
        structure.fillWithBlocks(world, start, 112, -46, -15, 113, -46, -14, Blocks.STONE_BRICKS.getDefaultState());
        structure.fillWithBlocks(world, start, 112, -46, -12, 112, -46, -6, Blocks.STONE_BRICKS.getDefaultState());
        structure.fillWithBlocks(world, start, 112, -25, 50, 113, -25, 50, Blocks.MOSSY_STONE_BRICKS.getDefaultState());
        structure.fillWithBlocks(world, start, 112, -24, 44, 113, -24, 44, Blocks.STONE_BRICKS.getDefaultState());
        structure.fillWithBlocks(world, start, 112, -24, 49, 112, -24, 49, Blocks.MOSSY_STONE_BRICKS.getDefaultState());
        structure.fillWithBlocks(world, start, 112, -23, 42, 112, -22, 42, Blocks.STONE_BRICKS.getDefaultState());
        structure.fillWithBlocks(world, start, 112, -23, 43, 112, -23, 44, Blocks.CRACKED_STONE_BRICKS.getDefaultState());
        structure.fillWithBlocks(world, start, 112, -23, 48, 113, -23, 49, Blocks.STONE_BRICKS.getDefaultState());
        structure.fillWithBlocks(world, start, 112, -23, 50, 113, -23, 50, Blocks.CRACKED_STONE_BRICKS.getDefaultState());
        structure.fillWithBlocks(world, start, 112, -22, 43, 112, -22, 43, Blocks.STONE_BRICKS.getDefaultState());
        structure.fillWithBlocks(world, start, 112, -22, 48, 113, -22, 48, Blocks.STONE_BRICKS.getDefaultState());
        structure.fillWithBlocks(world, start, 112, -22, 49, 113, -22, 49, Blocks.CRACKED_STONE_BRICKS.getDefaultState());
        structure.fillWithBlocks(world, start, 112, -22, 50, 115, -22, 50, Blocks.STONE_BRICKS.getDefaultState());
        structure.fillWithBlocks(world, start, 112, -21, 42, 112, -20, 42, Blocks.MOSSY_STONE_BRICKS.getDefaultState());
        structure.fillWithBlocks(world, start, 112, -21, 43, 112, -21, 44, Blocks.CRACKED_STONE_BRICKS.getDefaultState());
        structure.fillWithBlocks(world, start, 112, -21, 45, 112, -21, 47, Blocks.STONE_BRICKS.getDefaultState());
        structure.fillWithBlocks(world, start, 112, -21, 49, 112, -21, 50, Blocks.STONE_BRICKS.getDefaultState());
        structure.fillWithBlocks(world, start, 112, -20, 45, 112, -20, 46, Blocks.CRACKED_STONE_BRICKS.getDefaultState());
        structure.fillWithBlocks(world, start, 112, -20, 47, 113, -20, 49, Blocks.STONE_BRICKS.getDefaultState());
        structure.fillWithBlocks(world, start, 112, -19, 42, 112, -19, 44, Blocks.CRACKED_STONE_BRICKS.getDefaultState());
        structure.fillWithBlocks(world, start, 112, -19, 45, 112, -19, 47, Blocks.STONE_BRICKS.getDefaultState());
        structure.fillWithBlocks(world, start, 112, -19, 48, 112, -19, 48, Blocks.CRACKED_STONE_BRICKS.getDefaultState());
        structure.fillWithBlocks(world, start, 112, -19, 49, 112, -19, 50, Blocks.STONE_BRICKS.getDefaultState());
        structure.fillWithBlocks(world, start, 112, -18, 42, 112, -18, 42, Blocks.CRACKED_STONE_BRICKS.getDefaultState());
        structure.fillWithBlocks(world, start, 112, -18, 43, 112, -17, 43, Blocks.STONE_BRICKS.getDefaultState());
        structure.fillWithBlocks(world, start, 112, -18, 45, 112, -18, 50, Blocks.STONE_BRICKS.getDefaultState());
        structure.fillWithBlocks(world, start, 112, -17, 42, 113, -17, 43, Blocks.STONE_BRICKS.getDefaultState());
        structure.fillWithBlocks(world, start, 112, -17, 44, 112, -16, 44, Blocks.CRACKED_STONE_BRICKS.getDefaultState());
        structure.fillWithBlocks(world, start, 112, -17, 45, 112, -17, 45, Blocks.STONE_BRICKS.getDefaultState());
        structure.fillWithBlocks(world, start, 112, -17, 47, 112, -17, 48, Blocks.STONE_BRICKS.getDefaultState());
        structure.fillWithBlocks(world, start, 112, -17, 49, 112, -17, 50, Blocks.CRACKED_STONE_BRICKS.getDefaultState());
        structure.fillWithBlocks(world, start, 112, -16, 42, 112, -16, 45, Blocks.CRACKED_STONE_BRICKS.getDefaultState());
        structure.fillWithBlocks(world, start, 112, -16, 46, 113, -16, 47, Blocks.STONE_BRICKS.getDefaultState());
        structure.fillWithBlocks(world, start, 112, -15, 41, 116, -15, 45, Blocks.STONE_BRICKS.getDefaultState());
        structure.fillWithBlocks(world, start, 112, -15, 47, 115, -15, 50, Blocks.STONE_BRICKS.getDefaultState());
        structure.fillWithBlocks(world, start, 112, -15, 52, 113, -15, 53, Blocks.STONE_BRICKS.getDefaultState());
        structure.fillWithBlocks(world, start, 112, -14, 39, 113, -14, 40, Blocks.STONE_BRICKS.getDefaultState());
        structure.fillWithBlocks(world, start, 112, -14, 42, 113, -14, 43, Blocks.AIR.getDefaultState());
        structure.fillWithBlocks(world, start, 112, -14, 45, 114, -14, 47, Blocks.AIR.getDefaultState());
        structure.fillWithBlocks(world, start, 112, -14, 49, 113, -14, 50, Blocks.AIR.getDefaultState());
        structure.fillWithBlocks(world, start, 112, -11, 52, 113, -11, 53, Blocks.STONE_BRICKS.getDefaultState());
        structure.fillWithBlocks(world, start, 112, -10, 51, 114, -10, 53, Blocks.STONE_BRICKS.getDefaultState());
        structure.fillWithBlocks(world, start, 112, -9, 43, 113, -9, 45, Blocks.STONE_BRICKS.getDefaultState());
        structure.fillWithBlocks(world, start, 112, -9, 47, 115, -9, 52, Blocks.STONE_BRICKS.getDefaultState());
        structure.fillWithBlocks(world, start, 112, -8, 50, 113, -8, 53, Blocks.STONE_BRICKS.getDefaultState());
        structure.fillWithBlocks(world, start, 112, -7, 39, 115, -7, 49, Blocks.STONE_BRICKS.getDefaultState());
        structure.fillWithBlocks(world, start, 112, -6, 39, 117, -6, 45, Blocks.STONE_BRICKS.getDefaultState());
        structure.fillWithBlocks(world, start, 112, -6, 47, 112, -6, 53, Blocks.STONE_BRICKS.getDefaultState());
        structure.fillWithBlocks(world, start, 113, -56, -20, 113, -56, -18, Blocks.STONE_BRICKS.getDefaultState());
        structure.fillWithBlocks(world, start, 113, -56, -10, 113, -56, -8, Blocks.STONE_BRICKS.getDefaultState());
        structure.fillWithBlocks(world, start, 113, -55, -22, 114, -55, -21, Blocks.STONE_BRICKS.getDefaultState());
        structure.fillWithBlocks(world, start, 113, -55, -20, 113, -53, -18, Blocks.AIR.getDefaultState());
        structure.fillWithBlocks(world, start, 113, -55, -10, 113, -53, -8, Blocks.AIR.getDefaultState());
        structure.fillWithBlocks(world, start, 113, -50, -7, 113, -50, -6, Blocks.STONE_BRICKS.getDefaultState());
        structure.fillWithBlocks(world, start, 113, -49, -20, 116, -49, -16, Blocks.STONE_BRICKS.getDefaultState());
        structure.fillWithBlocks(world, start, 113, -49, -14, 116, -49, -11, Blocks.STONE_BRICKS.getDefaultState());
        structure.fillWithBlocks(world, start, 113, -49, -9, 114, -49, -8, Blocks.STONE_BRICKS.getDefaultState());
        structure.fillWithBlocks(world, start, 113, -49, -7, 113, -48, -7, Blocks.AIR.getDefaultState());
        structure.fillWithBlocks(world, start, 113, -49, -6, 115, -47, -6, Blocks.STONE_BRICKS.getDefaultState());
        structure.fillWithBlocks(world, start, 113, -48, -20, 113, -46, -18, Blocks.STONE_BRICKS.getDefaultState());
        structure.fillWithBlocks(world, start, 113, -48, -8, 113, -48, -8, Blocks.STONE_BRICKS.getDefaultState());
        structure.fillWithBlocks(world, start, 113, -46, -22, 115, -46, -18, Blocks.STONE_BRICKS.getDefaultState());
        structure.fillWithBlocks(world, start, 113, -46, -16, 116, -46, -12, Blocks.STONE_BRICKS.getDefaultState());
        structure.fillWithBlocks(world, start, 113, -46, -10, 115, -46, -6, Blocks.STONE_BRICKS.getDefaultState());
        structure.fillWithBlocks(world, start, 113, -24, 42, 113, -24, 42, Blocks.STONE_BRICKS.getDefaultState());
        structure.fillWithBlocks(world, start, 113, -24, 48, 113, -24, 49, Blocks.STONE_BRICKS.getDefaultState());
        structure.fillWithBlocks(world, start, 113, -23, 43, 113, -23, 44, Blocks.STONE_BRICKS.getDefaultState());
        structure.fillWithBlocks(world, start, 113, -22, 42, 113, -22, 42, Blocks.STONE_BRICKS.getDefaultState());
        structure.fillWithBlocks(world, start, 113, -22, 44, 113, -15, 44, Blocks.STONE_BRICKS.getDefaultState());
        structure.fillWithBlocks(world, start, 113, -21, 42, 113, -21, 43, Blocks.CRACKED_STONE_BRICKS.getDefaultState());
        structure.fillWithBlocks(world, start, 113, -21, 45, 115, -21, 47, Blocks.AIR.getDefaultState());
        structure.fillWithBlocks(world, start, 113, -21, 48, 113, -21, 49, Blocks.STONE_BRICKS.getDefaultState());
        structure.fillWithBlocks(world, start, 113, -20, 46, 114, -20, 47, Blocks.STONE_BRICKS.getDefaultState());
        structure.fillWithBlocks(world, start, 113, -20, 50, 114, -20, 50, Blocks.STONE_BRICKS.getDefaultState());
        structure.fillWithBlocks(world, start, 113, -19, 42, 117, -18, 42, Blocks.STONE_BRICKS.getDefaultState());
        structure.fillWithBlocks(world, start, 113, -19, 43, 113, -18, 43, Blocks.CRACKED_STONE_BRICKS.getDefaultState());
        structure.fillWithBlocks(world, start, 113, -19, 46, 115, -19, 48, Blocks.STONE_BRICKS.getDefaultState());
        structure.fillWithBlocks(world, start, 113, -19, 49, 113, -19, 49, Blocks.CRACKED_STONE_BRICKS.getDefaultState());
        structure.fillWithBlocks(world, start, 113, -18, 45, 113, -18, 45, Blocks.CRACKED_STONE_BRICKS.getDefaultState());
        structure.fillWithBlocks(world, start, 113, -18, 46, 113, -18, 48, Blocks.STONE_BRICKS.getDefaultState());
        structure.fillWithBlocks(world, start, 113, -18, 49, 113, -18, 50, Blocks.MOSSY_STONE_BRICKS.getDefaultState());
        structure.fillWithBlocks(world, start, 113, -17, 45, 114, -17, 46, Blocks.STONE_BRICKS.getDefaultState());
        structure.fillWithBlocks(world, start, 113, -17, 47, 113, -17, 47, Blocks.CRACKED_STONE_BRICKS.getDefaultState());
        structure.fillWithBlocks(world, start, 113, -17, 48, 113, -15, 48, Blocks.STONE_BRICKS.getDefaultState());
        structure.fillWithBlocks(world, start, 113, -16, 42, 114, -16, 45, Blocks.STONE_BRICKS.getDefaultState());
        structure.fillWithBlocks(world, start, 113, -16, 50, 115, -15, 50, Blocks.STONE_BRICKS.getDefaultState());
        structure.fillWithBlocks(world, start, 113, -15, 39, 117, -15, 47, Blocks.STONE_BRICKS.getDefaultState());
        structure.fillWithBlocks(world, start, 113, -15, 51, 115, -15, 53, Blocks.STONE_BRICKS.getDefaultState());
        structure.fillWithBlocks(world, start, 113, -14, 41, 113, -14, 51, Blocks.AIR.getDefaultState());
        structure.fillWithBlocks(world, start, 113, -14, 52, 114, -14, 53, Blocks.STONE_BRICKS.getDefaultState());
        structure.fillWithBlocks(world, start, 113, -13, 40, 113, -13, 40, Blocks.STONE_BRICKS.getDefaultState());
        structure.fillWithBlocks(world, start, 113, -13, 52, 114, -13, 53, Blocks.STONE_BRICKS.getDefaultState());
        structure.fillWithBlocks(world, start, 113, -12, 52, 114, -12, 53, Blocks.STONE_BRICKS.getDefaultState());
        structure.fillWithBlocks(world, start, 113, -10, 41, 114, -10, 42, Blocks.STONE_BRICKS.getDefaultState());
        structure.fillWithBlocks(world, start, 113, -10, 50, 114, -10, 53, Blocks.STONE_BRICKS.getDefaultState());
        structure.fillWithBlocks(world, start, 113, -9, 46, 115, -9, 53, Blocks.STONE_BRICKS.getDefaultState());
        structure.fillWithBlocks(world, start, 113, -8, 49, 115, -8, 51, Blocks.STONE_BRICKS.getDefaultState());
        structure.fillWithBlocks(world, start, 113, -7, 51, 115, -7, 53, Blocks.STONE_BRICKS.getDefaultState());
        structure.fillWithBlocks(world, start, 113, -6, 46, 113, -6, 46, Blocks.STONE_BRICKS.getDefaultState());
        structure.fillWithBlocks(world, start, 113, -6, 48, 115, -6, 53, Blocks.STONE_BRICKS.getDefaultState());
        structure.fillWithBlocks(world, start, 114, -55, -20, 120, -55, -10, Blocks.STONE_BRICKS.getDefaultState());
        structure.fillWithBlocks(world, start, 114, -55, -9, 115, -55, -6, Blocks.STONE_BRICKS.getDefaultState());
        structure.fillWithBlocks(world, start, 114, -54, -21, 114, -54, -21, Blocks.STONE_BRICKS.getDefaultState());
        structure.fillWithBlocks(world, start, 114, -54, -19, 114, -54, -18, Blocks.STONE_BRICK_WALL.getDefaultState().with(WallBlock.WATERLOGGED, false).with(WallBlock.UP, true).with(WallBlock.WALL_HEIGHT_NORTH, WallHeight.LOW).with(WallBlock.WALL_HEIGHT_SOUTH, WallHeight.LOW).with(WallBlock.WALL_HEIGHT_EAST, WallHeight.LOW).with(WallBlock.WALL_HEIGHT_WEST, WallHeight.LOW));
        structure.fillWithBlocks(world, start, 114, -54, -17, 114, -54, -17, Blocks.STONE_BRICKS.getDefaultState());
        structure.fillWithBlocks(world, start, 114, -54, -11, 114, -54, -11, Blocks.STONE_BRICKS.getDefaultState());
        structure.fillWithBlocks(world, start, 114, -54, -9, 114, -54, -8, Blocks.STONE_BRICK_WALL.getDefaultState().with(WallBlock.WATERLOGGED, false).with(WallBlock.UP, true).with(WallBlock.WALL_HEIGHT_NORTH, WallHeight.LOW).with(WallBlock.WALL_HEIGHT_SOUTH, WallHeight.LOW).with(WallBlock.WALL_HEIGHT_EAST, WallHeight.LOW).with(WallBlock.WALL_HEIGHT_WEST, WallHeight.LOW));
        structure.fillWithBlocks(world, start, 114, -54, -7, 115, -54, -6, Blocks.STONE_BRICKS.getDefaultState());
        structure.fillWithBlocks(world, start, 114, -53, -21, 114, -48, -21, Blocks.STONE_BRICKS.getDefaultState());
        structure.fillWithBlocks(world, start, 114, -53, -20, 114, -51, -18, Blocks.AIR.getDefaultState());
        structure.fillWithBlocks(world, start, 114, -53, -17, 114, -53, -17, Blocks.STONE_BRICKS.getDefaultState());
        structure.fillWithBlocks(world, start, 114, -53, -11, 114, -53, -11, Blocks.STONE_BRICKS.getDefaultState());
        structure.fillWithBlocks(world, start, 114, -53, -10, 114, -51, -8, Blocks.AIR.getDefaultState());
        structure.fillWithBlocks(world, start, 114, -53, -7, 115, -53, -6, Blocks.STONE_BRICKS.getDefaultState());
        structure.fillWithBlocks(world, start, 114, -52, -17, 114, -52, -17, Blocks.STONE_BRICKS.getDefaultState());
        structure.fillWithBlocks(world, start, 114, -52, -11, 114, -52, -11, Blocks.STONE_BRICKS.getDefaultState());
        structure.fillWithBlocks(world, start, 114, -52, -7, 115, -52, -6, Blocks.STONE_BRICKS.getDefaultState());
        structure.fillWithBlocks(world, start, 114, -51, -17, 114, -51, -17, Blocks.STONE_BRICKS.getDefaultState());
        structure.fillWithBlocks(world, start, 114, -51, -11, 114, -51, -11, Blocks.STONE_BRICKS.getDefaultState());
        structure.fillWithBlocks(world, start, 114, -51, -7, 115, -51, -6, Blocks.STONE_BRICKS.getDefaultState());
        structure.fillWithBlocks(world, start, 114, -50, -20, 116, -50, -18, Blocks.STONE_BRICKS.getDefaultState());
        structure.fillWithBlocks(world, start, 114, -50, -16, 119, -50, -11, Blocks.STONE_BRICKS.getDefaultState());
        structure.fillWithBlocks(world, start, 114, -50, -10, 116, -50, -8, Blocks.STONE_BRICKS.getDefaultState());
        structure.fillWithBlocks(world, start, 114, -49, -22, 115, -49, -11, Blocks.STONE_BRICKS.getDefaultState());
        structure.fillWithBlocks(world, start, 114, -49, -7, 115, -49, -6, Blocks.STONE_BRICKS.getDefaultState());
        structure.fillWithBlocks(world, start, 114, -48, -22, 115, -48, -20, Blocks.STONE_BRICKS.getDefaultState());
        structure.fillWithBlocks(world, start, 114, -48, -19, 115, -48, -19, Blocks.AIR.getDefaultState());
        structure.fillWithBlocks(world, start, 114, -48, -18, 114, -48, -18, Blocks.STONE_BRICKS.getDefaultState());
        structure.fillWithBlocks(world, start, 114, -48, -17, 114, -48, -17, Blocks.AIR.getDefaultState());
        structure.fillWithBlocks(world, start, 114, -48, -11, 117, -48, -8, Blocks.STONE_BRICKS.getDefaultState());
        structure.fillWithBlocks(world, start, 114, -48, -7, 115, -48, -6, Blocks.STONE_BRICKS.getDefaultState());
        structure.fillWithBlocks(world, start, 114, -47, -22, 114, -47, -22, Blocks.STONE_BRICKS.getDefaultState());
        structure.fillWithBlocks(world, start, 114, -47, -15, 116, -47, -13, Blocks.STONE_BRICKS.getDefaultState());
        structure.fillWithBlocks(world, start, 114, -46, -17, 116, -46, -8, Blocks.STONE_BRICKS.getDefaultState());
        structure.fillWithBlocks(world, start, 114, -25, 50, 114, -24, 50, Blocks.STONE_BRICKS.getDefaultState());
        structure.fillWithBlocks(world, start, 114, -24, 42, 114, -23, 43, Blocks.STONE_BRICKS.getDefaultState());
        structure.fillWithBlocks(world, start, 114, -24, 44, 115, -24, 45, Blocks.AIR.getDefaultState());
        structure.fillWithBlocks(world, start, 114, -24, 46, 114, -24, 48, Blocks.AIR.getDefaultState());
        structure.fillWithBlocks(world, start, 114, -24, 49, 114, -24, 50, Blocks.STONE_BRICKS.getDefaultState());
        structure.fillWithBlocks(world, start, 114, -23, 44, 115, -23, 45, Blocks.AIR.getDefaultState());
        structure.fillWithBlocks(world, start, 114, -23, 46, 114, -23, 48, Blocks.AIR.getDefaultState());
        structure.fillWithBlocks(world, start, 114, -23, 49, 114, -23, 50, Blocks.MOSSY_STONE_BRICKS.getDefaultState());
        structure.fillWithBlocks(world, start, 114, -22, 42, 115, -22, 43, Blocks.STONE_BRICKS.getDefaultState());
        structure.fillWithBlocks(world, start, 114, -22, 44, 116, -22, 48, Blocks.AIR.getDefaultState());
        structure.fillWithBlocks(world, start, 114, -22, 49, 115, -22, 50, Blocks.STONE_BRICKS.getDefaultState());
        structure.fillWithBlocks(world, start, 114, -21, 43, 115, -21, 43, Blocks.STONE_BRICKS.getDefaultState());
        structure.fillWithBlocks(world, start, 114, -21, 44, 116, -21, 48, Blocks.AIR.getDefaultState());
        structure.fillWithBlocks(world, start, 114, -21, 49, 114, -20, 50, Blocks.STONE_BRICKS.getDefaultState());
        structure.fillWithBlocks(world, start, 114, -20, 42, 114, -20, 43, Blocks.STONE_BRICKS.getDefaultState());
        structure.fillWithBlocks(world, start, 114, -20, 45, 114, -20, 47, Blocks.STONE_BRICKS.getDefaultState());
        structure.fillWithBlocks(world, start, 114, -19, 43, 115, -19, 43, Blocks.MOSSY_STONE_BRICKS.getDefaultState());
        structure.fillWithBlocks(world, start, 114, -19, 44, 114, -18, 44, Blocks.STONE_BRICKS.getDefaultState());
        structure.fillWithBlocks(world, start, 114, -19, 49, 119, -19, 49, Blocks.STONE_BRICKS.getDefaultState());
        structure.fillWithBlocks(world, start, 114, -19, 50, 116, -19, 50, Blocks.CRACKED_STONE_BRICKS.getDefaultState());
        structure.fillWithBlocks(world, start, 114, -18, 48, 117, -18, 48, Blocks.STONE_BRICKS.getDefaultState());
        structure.fillWithBlocks(world, start, 114, -18, 49, 114, -17, 49, Blocks.CRACKED_STONE_BRICKS.getDefaultState());
        structure.fillWithBlocks(world, start, 114, -18, 50, 114, -15, 50, Blocks.STONE_BRICKS.getDefaultState());
        structure.fillWithBlocks(world, start, 114, -17, 42, 115, -17, 42, Blocks.CRACKED_STONE_BRICKS.getDefaultState());
        structure.fillWithBlocks(world, start, 114, -17, 43, 114, -17, 43, Blocks.STONE_BRICKS.getDefaultState());
        structure.fillWithBlocks(world, start, 114, -17, 47, 115, -17, 47, Blocks.STONE_BRICKS.getDefaultState());
        structure.fillWithBlocks(world, start, 114, -17, 48, 114, -17, 49, Blocks.CRACKED_STONE_BRICKS.getDefaultState());
        structure.fillWithBlocks(world, start, 114, -16, 46, 114, -16, 46, Blocks.MOSSY_STONE_BRICKS.getDefaultState());
        structure.fillWithBlocks(world, start, 114, -16, 47, 114, -15, 47, Blocks.STONE_BRICKS.getDefaultState());
        structure.fillWithBlocks(world, start, 114, -16, 48, 114, -16, 48, Blocks.CRACKED_STONE_BRICKS.getDefaultState());
        structure.fillWithBlocks(world, start, 114, -16, 49, 114, -16, 50, Blocks.STONE_BRICKS.getDefaultState());
