package mod.arcalitegames.odyssey.world.structure.structures.dungeons.shrine;

import mod.arcalitegames.odyssey.world.structure.StructureBase;
import net.minecraft.block.Blocks;
import net.minecraft.block.FourWayBlock;
import net.minecraft.block.SlabBlock;
import net.minecraft.block.StairsBlock;
import net.minecraft.state.properties.Half;
import net.minecraft.state.properties.SlabType;
import net.minecraft.state.properties.StairsShape;
import net.minecraft.util.Direction;
import net.minecraft.util.math.BlockPos;
import net.minecraft.world.World;

public class ShrineComponent2
{

	public static BlockPos start;
    public static World world;
    public static StructureBase structure;

    public static void init(World worldIn, BlockPos blockPos, StructureBase structureIn)
    {
        world = worldIn; start = blockPos; structure = structureIn;
    }
    
    public static void generatePart21()
    {
        structure.fillWithBlocks(world, start, 29, -36, 64, 31, -36, 66, Blocks.STONE_BRICKS.getDefaultState());
        structure.fillWithBlocks(world, start, 29, -36, 74, 33, -36, 78, Blocks.STONE_BRICKS.getDefaultState());
        structure.fillWithBlocks(world, start, 29, -36, 82, 32, -36, 85, Blocks.STONE_BRICKS.getDefaultState());
        structure.fillWithBlocks(world, start, 29, -36, 86, 31, -36, 86, Blocks.AIR.getDefaultState());
        structure.fillWithBlocks(world, start, 29, -35, 30, 40, -31, 30, Blocks.STONE_BRICKS.getDefaultState());
        structure.fillWithBlocks(world, start, 29, -35, 54, 30, -35, 55, Blocks.STONE_BRICKS.getDefaultState());
        structure.fillWithBlocks(world, start, 29, -35, 58, 29, -35, 58, Blocks.STONE_BRICKS.getDefaultState());
        structure.fillWithBlocks(world, start, 29, -35, 60, 31, -35, 64, Blocks.STONE_BRICKS.getDefaultState());
        structure.fillWithBlocks(world, start, 29, -35, 66, 30, -35, 67, Blocks.STONE_BRICKS.getDefaultState());
        structure.fillWithBlocks(world, start, 29, -35, 79, 31, -35, 81, Blocks.STONE_BRICKS.getDefaultState());
        structure.fillWithBlocks(world, start, 29, -35, 86, 30, -35, 89, Blocks.STONE_BRICKS.getDefaultState());
        structure.fillWithBlocks(world, start, 29, -35, 97, 29, -35, 97, Blocks.STONE_BRICKS.getDefaultState());
        structure.fillWithBlocks(world, start, 29, -35, 98, 29, -35, 98, Blocks.AIR.getDefaultState());
        structure.fillWithBlocks(world, start, 29, -35, 99, 29, -34, 100, Blocks.STONE_BRICKS.getDefaultState());
        structure.fillWithBlocks(world, start, 29, -34, 22, 32, -34, 25, Blocks.STONE_BRICKS.getDefaultState());
        structure.fillWithBlocks(world, start, 29, -34, 43, 36, -31, 43, Blocks.STONE_BRICKS.getDefaultState());
        structure.fillWithBlocks(world, start, 29, -34, 48, 29, -34, 51, Blocks.STONE_BRICKS.getDefaultState());
        structure.fillWithBlocks(world, start, 29, -34, 55, 37, -31, 55, Blocks.STONE_BRICKS.getDefaultState());
        structure.fillWithBlocks(world, start, 29, -34, 59, 31, -34, 62, Blocks.STONE_BRICKS.getDefaultState());
        structure.fillWithBlocks(world, start, 29, -34, 64, 31, -34, 68, Blocks.STONE_BRICKS.getDefaultState());
        structure.fillWithBlocks(world, start, 29, -34, 74, 30, -34, 77, Blocks.STONE_BRICKS.getDefaultState());
        structure.fillWithBlocks(world, start, 29, -34, 86, 29, -34, 86, Blocks.STONE_BRICKS.getDefaultState());
        structure.fillWithBlocks(world, start, 29, -34, 88, 30, -34, 92, Blocks.STONE_BRICKS.getDefaultState());
        structure.fillWithBlocks(world, start, 29, -34, 96, 33, -34, 100, Blocks.STONE_BRICKS.getDefaultState());
        structure.fillWithBlocks(world, start, 29, -33, 10, 29, -33, 10, Blocks.STONE_BRICKS.getDefaultState());
        structure.fillWithBlocks(world, start, 29, -33, 12, 29, -33, 13, Blocks.STONE_BRICKS.getDefaultState());
        structure.fillWithBlocks(world, start, 29, -33, 14, 30, -33, 14, Blocks.AIR.getDefaultState());
        structure.fillWithBlocks(world, start, 29, -33, 19, 32, -33, 22, Blocks.STONE_BRICKS.getDefaultState());
        structure.fillWithBlocks(world, start, 29, -33, 24, 30, -33, 27, Blocks.STONE_BRICKS.getDefaultState());
        structure.fillWithBlocks(world, start, 29, -33, 29, 30, -33, 30, Blocks.STONE_BRICKS.getDefaultState());
        structure.fillWithBlocks(world, start, 29, -33, 42, 31, -33, 44, Blocks.STONE_BRICKS.getDefaultState());
        structure.fillWithBlocks(world, start, 29, -33, 45, 29, -33, 45, Blocks.STONE_BRICKS.getDefaultState());
        structure.fillWithBlocks(world, start, 29, -33, 48, 29, -33, 51, Blocks.AIR.getDefaultState());
        structure.fillWithBlocks(world, start, 29, -33, 58, 32, -33, 61, Blocks.STONE_BRICKS.getDefaultState());
        structure.fillWithBlocks(world, start, 29, -33, 71, 30, -33, 72, Blocks.STONE_BRICKS.getDefaultState());
        structure.fillWithBlocks(world, start, 29, -33, 73, 29, -33, 78, Blocks.STONE_BRICKS.getDefaultState());
        structure.fillWithBlocks(world, start, 29, -33, 89, 31, -33, 98, Blocks.STONE_BRICKS.getDefaultState());
        structure.fillWithBlocks(world, start, 29, -33, 99, 29, -33, 100, Blocks.STONE_BRICKS.getDefaultState());
        structure.fillWithBlocks(world, start, 29, -32, 19, 30, -32, 21, Blocks.STONE_BRICKS.getDefaultState());
        structure.fillWithBlocks(world, start, 29, -32, 23, 30, -32, 26, Blocks.STONE_BRICKS.getDefaultState());
        structure.fillWithBlocks(world, start, 29, -32, 27, 29, -32, 30, Blocks.STONE_BRICKS.getDefaultState());
        structure.fillWithBlocks(world, start, 29, -32, 42, 30, -32, 44, Blocks.STONE_BRICKS.getDefaultState());
        structure.fillWithBlocks(world, start, 29, -32, 45, 30, -32, 46, Blocks.AIR.getDefaultState());
        structure.fillWithBlocks(world, start, 29, -32, 49, 29, -32, 55, Blocks.STONE_BRICKS.getDefaultState());
        structure.fillWithBlocks(world, start, 29, -32, 58, 29, -32, 58, Blocks.STONE_BRICKS.getDefaultState());
        structure.fillWithBlocks(world, start, 29, -32, 59, 29, -32, 60, Blocks.AIR.getDefaultState());
        structure.fillWithBlocks(world, start, 29, -32, 61, 30, -32, 77, Blocks.STONE_BRICKS.getDefaultState());
        structure.fillWithBlocks(world, start, 29, -32, 81, 30, -32, 82, Blocks.STONE_BRICKS.getDefaultState());
        structure.fillWithBlocks(world, start, 29, -31, 16, 29, -31, 20, Blocks.STONE_BRICKS.getDefaultState());
        structure.fillWithBlocks(world, start, 29, -31, 22, 33, -31, 26, Blocks.STONE_BRICKS.getDefaultState());
        structure.fillWithBlocks(world, start, 29, -31, 28, 29, -31, 30, Blocks.STONE_BRICKS.getDefaultState());
        structure.fillWithBlocks(world, start, 29, -31, 45, 29, -30, 45, Blocks.SANDSTONE.getDefaultState());
        structure.fillWithBlocks(world, start, 29, -31, 46, 29, -31, 48, Blocks.STONE_BRICKS.getDefaultState());
        structure.fillWithBlocks(world, start, 29, -31, 49, 29, -30, 49, Blocks.SANDSTONE.getDefaultState());
        structure.fillWithBlocks(world, start, 29, -31, 50, 29, -31, 50, Blocks.STONE_BRICKS.getDefaultState());
        structure.fillWithBlocks(world, start, 29, -31, 51, 29, -30, 51, Blocks.SANDSTONE.getDefaultState());
        structure.fillWithBlocks(world, start, 29, -31, 66, 31, -31, 73, Blocks.STONE_BRICKS.getDefaultState());
        structure.fillWithBlocks(world, start, 29, -31, 74, 29, -31, 82, Blocks.STONE_BRICKS.getDefaultState());
        structure.fillWithBlocks(world, start, 29, -31, 90, 36, -31, 100, Blocks.STONE_BRICKS.getDefaultState());
        structure.fillWithBlocks(world, start, 29, -30, 6, 30, -30, 7, Blocks.STONE_BRICKS.getDefaultState());
        structure.fillWithBlocks(world, start, 29, -30, 21, 31, -30, 23, Blocks.SANDSTONE.getDefaultState());
        structure.fillWithBlocks(world, start, 29, -30, 28, 29, -30, 29, Blocks.DIRT.getDefaultState());
        structure.fillWithBlocks(world, start, 29, -30, 30, 32, -30, 33, Blocks.SANDSTONE.getDefaultState());
        structure.fillWithBlocks(world, start, 29, -30, 34, 29, -30, 36, Blocks.SANDSTONE.getDefaultState());
        structure.fillWithBlocks(world, start, 29, -30, 44, 29, -30, 52, Blocks.SANDSTONE.getDefaultState());
        structure.fillWithBlocks(world, start, 29, -30, 54, 31, -30, 56, Blocks.SANDSTONE.getDefaultState());
        structure.fillWithBlocks(world, start, 29, -30, 58, 29, -29, 58, Blocks.DIRT.getDefaultState());
        structure.fillWithBlocks(world, start, 29, -30, 59, 30, -29, 59, Blocks.SANDSTONE.getDefaultState());
        structure.fillWithBlocks(world, start, 29, -30, 61, 35, -30, 67, Blocks.SANDSTONE.getDefaultState());
        structure.fillWithBlocks(world, start, 29, -30, 68, 29, -30, 70, Blocks.SANDSTONE.getDefaultState());
        structure.fillWithBlocks(world, start, 29, -30, 71, 30, -30, 71, Blocks.DIRT.getDefaultState());
        structure.fillWithBlocks(world, start, 29, -30, 72, 29, -30, 73, Blocks.SANDSTONE.getDefaultState());
        structure.fillWithBlocks(world, start, 29, -29, 4, 29, -28, 5, Blocks.STONE_BRICKS.getDefaultState());
        structure.fillWithBlocks(world, start, 29, -29, 7, 29, -28, 8, Blocks.SANDSTONE.getDefaultState());
        structure.fillWithBlocks(world, start, 29, -29, 20, 29, -29, 24, Blocks.SANDSTONE.getDefaultState());
        structure.fillWithBlocks(world, start, 29, -29, 25, 29, -27, 25, Blocks.DARK_OAK_LOG.getDefaultState());
        structure.fillWithBlocks(world, start, 29, -29, 26, 29, -27, 26, Blocks.AIR.getDefaultState());
        structure.fillWithBlocks(world, start, 29, -29, 27, 29, -27, 27, Blocks.DARK_OAK_LOG.getDefaultState());
        structure.fillWithBlocks(world, start, 29, -29, 28, 29, -28, 29, Blocks.SANDSTONE.getDefaultState());
        structure.fillWithBlocks(world, start, 29, -29, 30, 31, -29, 32, Blocks.AIR.getDefaultState());
        structure.fillWithBlocks(world, start, 29, -29, 33, 29, -22, 33, Blocks.SANDSTONE.getDefaultState());
        structure.fillWithBlocks(world, start, 29, -29, 34, 29, -27, 36, Blocks.AIR.getDefaultState());
        structure.fillWithBlocks(world, start, 29, -29, 37, 29, -27, 37, Blocks.DARK_OAK_LOG.getDefaultState());
        structure.fillWithBlocks(world, start, 29, -29, 38, 29, -27, 38, Blocks.AIR.getDefaultState());
        structure.fillWithBlocks(world, start, 29, -29, 39, 29, -27, 39, Blocks.DARK_OAK_LOG.getDefaultState());
        structure.fillWithBlocks(world, start, 29, -29, 40, 29, -27, 42, Blocks.AIR.getDefaultState());
        structure.fillWithBlocks(world, start, 29, -29, 43, 30, -29, 44, Blocks.SANDSTONE.getDefaultState());
        structure.fillWithBlocks(world, start, 29, -29, 48, 30, -29, 50, Blocks.AIR.getDefaultState());
        structure.fillWithBlocks(world, start, 29, -29, 52, 30, -29, 55, Blocks.SANDSTONE.getDefaultState());
        structure.fillWithBlocks(world, start, 29, -29, 56, 29, -29, 57, Blocks.SANDSTONE.getDefaultState());
        structure.fillWithBlocks(world, start, 29, -29, 69, 29, -29, 69, Blocks.SANDSTONE.getDefaultState());
        structure.fillWithBlocks(world, start, 29, -29, 71, 29, -29, 71, Blocks.SANDSTONE.getDefaultState());
        structure.fillWithBlocks(world, start, 29, -29, 72, 29, -29, 73, Blocks.DIRT.getDefaultState());
        structure.fillWithBlocks(world, start, 29, -29, 74, 30, -29, 75, Blocks.SANDSTONE.getDefaultState());
        structure.fillWithBlocks(world, start, 29, -28, 6, 29, -28, 8, Blocks.SANDSTONE.getDefaultState());
        structure.fillWithBlocks(world, start, 29, -28, 20, 29, -25, 23, Blocks.SANDSTONE.getDefaultState());
        structure.fillWithBlocks(world, start, 29, -28, 24, 31, -26, 24, Blocks.SANDSTONE.getDefaultState());
        structure.fillWithBlocks(world, start, 29, -28, 30, 31, -28, 32, Blocks.AIR.getDefaultState());
        structure.fillWithBlocks(world, start, 29, -28, 43, 30, -28, 44, Blocks.SANDSTONE.getDefaultState());
        structure.fillWithBlocks(world, start, 29, -28, 52, 32, -28, 55, Blocks.SANDSTONE.getDefaultState());
        structure.fillWithBlocks(world, start, 29, -28, 56, 29, -28, 57, Blocks.AIR.getDefaultState());
        structure.fillWithBlocks(world, start, 29, -28, 58, 29, -28, 58, Blocks.SANDSTONE.getDefaultState());
        structure.fillWithBlocks(world, start, 29, -28, 59, 29, -27, 60, Blocks.AIR.getDefaultState());
        structure.fillWithBlocks(world, start, 29, -28, 70, 29, -27, 71, Blocks.AIR.getDefaultState());
        structure.fillWithBlocks(world, start, 29, -27, 4, 29, -27, 6, Blocks.STONE_BRICKS.getDefaultState());
        structure.fillWithBlocks(world, start, 29, -27, 7, 29, -27, 8, Blocks.SANDSTONE.getDefaultState());
        structure.fillWithBlocks(world, start, 29, -27, 28, 29, -26, 29, Blocks.SANDSTONE.getDefaultState());
        structure.fillWithBlocks(world, start, 29, -27, 30, 31, -27, 32, Blocks.AIR.getDefaultState());
        structure.fillWithBlocks(world, start, 29, -27, 43, 30, -27, 44, Blocks.SANDSTONE.getDefaultState());
        structure.fillWithBlocks(world, start, 29, -27, 45, 29, -27, 51, Blocks.AIR.getDefaultState());
        structure.fillWithBlocks(world, start, 29, -27, 52, 30, -27, 58, Blocks.SANDSTONE.getDefaultState());
        structure.fillWithBlocks(world, start, 29, -27, 69, 29, -27, 69, Blocks.SANDSTONE.getDefaultState());
        structure.fillWithBlocks(world, start, 29, -27, 72, 30, -27, 75, Blocks.SANDSTONE.getDefaultState());
        structure.fillWithBlocks(world, start, 29, -26, 4, 29, -25, 4, Blocks.SANDSTONE.getDefaultState());
        structure.fillWithBlocks(world, start, 29, -26, 7, 29, -23, 7, Blocks.STONE_BRICKS.getDefaultState());
        structure.fillWithBlocks(world, start, 29, -26, 8, 29, -25, 9, Blocks.SANDSTONE.getDefaultState());
        structure.fillWithBlocks(world, start, 29, -26, 19, 29, -25, 23, Blocks.SANDSTONE.getDefaultState());
        structure.fillWithBlocks(world, start, 29, -26, 26, 29, -26, 29, Blocks.SANDSTONE.getDefaultState());
        structure.fillWithBlocks(world, start, 29, -26, 30, 29, -26, 32, Blocks.AIR.getDefaultState());
        structure.fillWithBlocks(world, start, 29, -26, 45, 29, -26, 51, Blocks.AIR.getDefaultState());
        structure.fillWithBlocks(world, start, 29, -26, 54, 30, -26, 55, Blocks.SANDSTONE.getDefaultState());
        structure.fillWithBlocks(world, start, 29, -26, 59, 29, -25, 60, Blocks.AIR.getDefaultState());
        structure.fillWithBlocks(world, start, 29, -26, 70, 29, -25, 71, Blocks.AIR.getDefaultState());
        structure.fillWithBlocks(world, start, 29, -26, 72, 29, -26, 73, Blocks.SANDSTONE.getDefaultState());
        structure.fillWithBlocks(world, start, 29, -26, 75, 38, -26, 75, Blocks.SANDSTONE.getDefaultState());
        structure.fillWithBlocks(world, start, 29, -25, 10, 29, -23, 10, Blocks.SANDSTONE.getDefaultState());
        structure.fillWithBlocks(world, start, 29, -25, 18, 29, -23, 20, Blocks.SANDSTONE.getDefaultState());
        structure.fillWithBlocks(world, start, 29, -25, 27, 30, -25, 28, Blocks.SANDSTONE.getDefaultState());
        structure.fillWithBlocks(world, start, 29, -25, 35, 30, -24, 35, Blocks.SANDSTONE.getDefaultState());
        structure.fillWithBlocks(world, start, 29, -25, 43, 30, -25, 44, Blocks.SANDSTONE.getDefaultState());
        structure.fillWithBlocks(world, start, 29, -25, 48, 30, -25, 50, Blocks.AIR.getDefaultState());
        structure.fillWithBlocks(world, start, 29, -25, 55, 31, -25, 57, Blocks.SANDSTONE.getDefaultState());
        structure.fillWithBlocks(world, start, 29, -25, 58, 29, -25, 58, Blocks.SANDSTONE.getDefaultState());
        structure.fillWithBlocks(world, start, 29, -25, 61, 29, -25, 61, Blocks.SANDSTONE.getDefaultState());
        structure.fillWithBlocks(world, start, 29, -25, 69, 29, -25, 69, Blocks.SANDSTONE.getDefaultState());
        structure.fillWithBlocks(world, start, 29, -25, 73, 30, -25, 74, Blocks.SANDSTONE.getDefaultState());
        structure.fillWithBlocks(world, start, 29, -24, 4, 29, -24, 7, Blocks.STONE_BRICKS.getDefaultState());
        structure.fillWithBlocks(world, start, 29, -24, 8, 30, -24, 20, Blocks.SANDSTONE.getDefaultState());
        structure.fillWithBlocks(world, start, 29, -24, 22, 29, -24, 22, Blocks.SANDSTONE.getDefaultState());
        structure.fillWithBlocks(world, start, 29, -24, 24, 34, -23, 24, Blocks.SANDSTONE.getDefaultState());
        structure.fillWithBlocks(world, start, 29, -24, 27, 31, -24, 30, Blocks.SANDSTONE.getDefaultState());
        structure.fillWithBlocks(world, start, 29, -24, 42, 30, -24, 44, Blocks.SANDSTONE.getDefaultState());
        structure.fillWithBlocks(world, start, 29, -24, 52, 31, -24, 55, Blocks.SANDSTONE.getDefaultState());
        structure.fillWithBlocks(world, start, 29, -24, 57, 29, -20, 57, Blocks.SANDSTONE.getDefaultState());
        structure.fillWithBlocks(world, start, 29, -24, 59, 29, -24, 75, Blocks.SANDSTONE.getDefaultState());
        structure.fillWithBlocks(world, start, 29, -23, 4, 29, -23, 4, Blocks.STONE_BRICKS.getDefaultState());
        structure.fillWithBlocks(world, start, 29, -23, 6, 29, -23, 8, Blocks.STONE_BRICKS.getDefaultState());
        structure.fillWithBlocks(world, start, 29, -23, 9, 29, -23, 10, Blocks.SANDSTONE.getDefaultState());
        structure.fillWithBlocks(world, start, 29, -23, 11, 29, -21, 11, Blocks.DIRT.getDefaultState());
        structure.fillWithBlocks(world, start, 29, -23, 12, 29, -21, 12, Blocks.STONE_BRICKS.getDefaultState());
        structure.fillWithBlocks(world, start, 29, -23, 13, 29, -23, 15, Blocks.SANDSTONE.getDefaultState());
        structure.fillWithBlocks(world, start, 29, -23, 16, 29, -23, 17, Blocks.STONE_BRICKS.getDefaultState());
        structure.fillWithBlocks(world, start, 29, -23, 21, 29, -21, 24, Blocks.SANDSTONE.getDefaultState());
        structure.fillWithBlocks(world, start, 29, -23, 28, 31, -21, 28, Blocks.SANDSTONE.getDefaultState());
        structure.fillWithBlocks(world, start, 29, -23, 29, 29, -23, 30, Blocks.DIRT.getDefaultState());
        structure.fillWithBlocks(world, start, 29, -23, 31, 29, -23, 31, Blocks.SANDSTONE.getDefaultState());
        structure.fillWithBlocks(world, start, 29, -23, 34, 30, -23, 35, Blocks.SANDSTONE.getDefaultState());
        structure.fillWithBlocks(world, start, 29, -23, 42, 29, -21, 44, Blocks.SANDSTONE.getDefaultState());
        structure.fillWithBlocks(world, start, 29, -23, 45, 29, -23, 51, Blocks.AIR.getDefaultState());
        structure.fillWithBlocks(world, start, 29, -23, 55, 29, -23, 56, Blocks.DIRT.getDefaultState());
        structure.fillWithBlocks(world, start, 29, -23, 58, 29, -23, 58, Blocks.SANDSTONE.getDefaultState());
        structure.fillWithBlocks(world, start, 29, -23, 60, 30, -23, 64, Blocks.SANDSTONE.getDefaultState());
        structure.fillWithBlocks(world, start, 29, -23, 67, 29, -22, 68, Blocks.SANDSTONE.getDefaultState());
        structure.fillWithBlocks(world, start, 29, -23, 74, 29, -23, 75, Blocks.SANDSTONE.getDefaultState());
        structure.fillWithBlocks(world, start, 29, -22, 4, 30, -22, 5, Blocks.STONE_BRICKS.getDefaultState());
        structure.fillWithBlocks(world, start, 29, -22, 7, 30, -22, 7, Blocks.SANDSTONE.getDefaultState());
        structure.fillWithBlocks(world, start, 29, -22, 10, 29, -21, 10, Blocks.STONE_BRICKS.getDefaultState());
        structure.fillWithBlocks(world, start, 29, -22, 14, 29, -21, 14, Blocks.DIRT.getDefaultState());
        structure.fillWithBlocks(world, start, 29, -22, 15, 29, -22, 16, Blocks.STONE_BRICKS.getDefaultState());
        structure.fillWithBlocks(world, start, 29, -22, 18, 30, -22, 22, Blocks.SANDSTONE.getDefaultState());
        structure.fillWithBlocks(world, start, 29, -22, 32, 29, -22, 35, Blocks.SANDSTONE.getDefaultState());
        structure.fillWithBlocks(world, start, 29, -22, 45, 29, -22, 51, Blocks.AIR.getDefaultState());
        structure.fillWithBlocks(world, start, 29, -22, 58, 29, -22, 58, Blocks.SANDSTONE.getDefaultState());
        structure.fillWithBlocks(world, start, 29, -22, 60, 30, -22, 62, Blocks.SANDSTONE.getDefaultState());
        structure.fillWithBlocks(world, start, 29, -22, 65, 32, -22, 68, Blocks.SANDSTONE.getDefaultState());
        structure.fillWithBlocks(world, start, 29, -22, 70, 30, -22, 71, Blocks.SANDSTONE.getDefaultState());
        structure.fillWithBlocks(world, start, 29, -22, 72, 31, -22, 72, Blocks.AIR.getDefaultState());
        structure.fillWithBlocks(world, start, 29, -22, 73, 29, -22, 75, Blocks.SANDSTONE.getDefaultState());
        structure.fillWithBlocks(world, start, 29, -21, 4, 29, -21, 4, Blocks.STONE_BRICKS.getDefaultState());
        structure.fillWithBlocks(world, start, 29, -21, 13, 29, -21, 13, Blocks.STONE_BRICKS.getDefaultState());
        structure.fillWithBlocks(world, start, 29, -21, 15, 29, -21, 16, Blocks.STONE_BRICKS.getDefaultState());
        structure.fillWithBlocks(world, start, 29, -21, 19, 30, -21, 21, Blocks.SANDSTONE.getDefaultState());
        structure.fillWithBlocks(world, start, 29, -21, 29, 29, -21, 29, Blocks.SANDSTONE.getDefaultState());
        structure.fillWithBlocks(world, start, 29, -21, 31, 30, -21, 32, Blocks.SANDSTONE.getDefaultState());
        structure.fillWithBlocks(world, start, 29, -21, 33, 29, -21, 33, Blocks.AIR.getDefaultState());
        structure.fillWithBlocks(world, start, 29, -21, 34, 29, -21, 34, Blocks.SANDSTONE.getDefaultState());
        structure.fillWithBlocks(world, start, 29, -21, 48, 30, -21, 50, Blocks.AIR.getDefaultState());
        structure.fillWithBlocks(world, start, 29, -21, 55, 30, -21, 55, Blocks.DIRT.getDefaultState());
        structure.fillWithBlocks(world, start, 29, -21, 59, 29, -21, 59, Blocks.SANDSTONE.getDefaultState());
        structure.fillWithBlocks(world, start, 29, -21, 61, 30, -21, 63, Blocks.SANDSTONE.getDefaultState());
        structure.fillWithBlocks(world, start, 29, -21, 65, 29, -21, 65, Blocks.DIRT.getDefaultState());
        structure.fillWithBlocks(world, start, 29, -21, 66, 29, -21, 69, Blocks.SANDSTONE.getDefaultState());
        structure.fillWithBlocks(world, start, 29, -21, 71, 29, -21, 73, Blocks.SANDSTONE.getDefaultState());
        structure.fillWithBlocks(world, start, 29, -20, 25, 30, -20, 26, Blocks.SANDSTONE.getDefaultState());
        structure.fillWithBlocks(world, start, 29, -20, 28, 29, -20, 28, Blocks.OAK_PLANKS.getDefaultState());
        structure.fillWithBlocks(world, start, 29, -20, 34, 30, -20, 35, Blocks.OAK_PLANKS.getDefaultState());
        structure.fillWithBlocks(world, start, 29, -20, 36, 30, -20, 38, Blocks.SANDSTONE.getDefaultState());
        structure.fillWithBlocks(world, start, 29, -20, 47, 33, -20, 51, Blocks.SANDSTONE.getDefaultState());
        structure.fillWithBlocks(world, start, 29, -20, 52, 30, -20, 52, Blocks.AIR.getDefaultState());
        structure.fillWithBlocks(world, start, 29, -20, 61, 29, -20, 72, Blocks.SANDSTONE.getDefaultState());
        structure.fillWithBlocks(world, start, 29, -20, 73, 30, -20, 73, Blocks.STONE.getDefaultState());
        structure.fillWithBlocks(world, start, 29, -20, 76, 29, -20, 79, Blocks.SANDSTONE.getDefaultState());
        structure.fillWithBlocks(world, start, 29, -20, 81, 32, -20, 90, Blocks.SANDSTONE.getDefaultState());
        structure.fillWithBlocks(world, start, 29, -19, 25, 30, -19, 26, Blocks.SANDSTONE.getDefaultState());
        structure.fillWithBlocks(world, start, 29, -19, 27, 29, -19, 27, Blocks.OAK_PLANKS.getDefaultState());
        structure.fillWithBlocks(world, start, 29, -19, 28, 29, -16, 28, Blocks.STONE.getDefaultState());
        structure.fillWithBlocks(world, start, 29, -19, 29, 29, -19, 33, Blocks.AIR.getDefaultState());
        structure.fillWithBlocks(world, start, 29, -19, 34, 29, -16, 34, Blocks.STONE.getDefaultState());
        structure.fillWithBlocks(world, start, 29, -19, 35, 29, -19, 36, Blocks.SANDSTONE.getDefaultState());
        structure.fillWithBlocks(world, start, 29, -19, 37, 29, -17, 37, Blocks.STONE.getDefaultState());
        structure.fillWithBlocks(world, start, 29, -19, 38, 29, -17, 38, Blocks.AIR.getDefaultState());
        structure.fillWithBlocks(world, start, 29, -19, 39, 29, -17, 39, Blocks.STONE.getDefaultState());
        structure.fillWithBlocks(world, start, 29, -19, 40, 29, -17, 42, Blocks.AIR.getDefaultState());
        structure.fillWithBlocks(world, start, 29, -19, 43, 30, -19, 44, Blocks.SANDSTONE.getDefaultState());
        structure.fillWithBlocks(world, start, 29, -19, 52, 31, -19, 54, Blocks.SANDSTONE.getDefaultState());
        structure.fillWithBlocks(world, start, 29, -19, 55, 29, -17, 55, Blocks.STONE.getDefaultState());
        structure.fillWithBlocks(world, start, 29, -19, 56, 29, -17, 56, Blocks.AIR.getDefaultState());
        structure.fillWithBlocks(world, start, 29, -19, 57, 29, -17, 57, Blocks.STONE.getDefaultState());
        structure.fillWithBlocks(world, start, 29, -19, 58, 29, -17, 60, Blocks.AIR.getDefaultState());
        structure.fillWithBlocks(world, start, 29, -19, 61, 29, -17, 61, Blocks.STONE.getDefaultState());
        structure.fillWithBlocks(world, start, 29, -19, 62, 29, -17, 62, Blocks.AIR.getDefaultState());
        structure.fillWithBlocks(world, start, 29, -19, 63, 29, -17, 63, Blocks.STONE.getDefaultState());
        structure.fillWithBlocks(world, start, 29, -19, 64, 29, -17, 66, Blocks.AIR.getDefaultState());
        structure.fillWithBlocks(world, start, 29, -19, 67, 29, -17, 67, Blocks.STONE.getDefaultState());
        structure.fillWithBlocks(world, start, 29, -19, 68, 29, -17, 68, Blocks.AIR.getDefaultState());
        structure.fillWithBlocks(world, start, 29, -19, 69, 29, -17, 69, Blocks.STONE.getDefaultState());
        structure.fillWithBlocks(world, start, 29, -19, 70, 29, -17, 72, Blocks.AIR.getDefaultState());
        structure.fillWithBlocks(world, start, 29, -19, 73, 29, -17, 73, Blocks.STONE.getDefaultState());
        structure.fillWithBlocks(world, start, 29, -19, 74, 29, -17, 74, Blocks.AIR.getDefaultState());
        structure.fillWithBlocks(world, start, 29, -19, 75, 29, -17, 75, Blocks.STONE.getDefaultState());
        structure.fillWithBlocks(world, start, 29, -19, 76, 29, -17, 78, Blocks.AIR.getDefaultState());
        structure.fillWithBlocks(world, start, 29, -19, 79, 31, -19, 81, Blocks.SANDSTONE.getDefaultState());
        structure.fillWithBlocks(world, start, 29, -19, 82, 29, -19, 88, Blocks.AIR.getDefaultState());
        structure.fillWithBlocks(world, start, 29, -18, 25, 30, -18, 26, Blocks.SANDSTONE.getDefaultState());
        structure.fillWithBlocks(world, start, 29, -18, 27, 29, -18, 27, Blocks.OAK_PLANKS.getDefaultState());
        structure.fillWithBlocks(world, start, 29, -18, 35, 29, -18, 36, Blocks.SANDSTONE.getDefaultState());
        structure.fillWithBlocks(world, start, 29, -18, 43, 30, -18, 44, Blocks.SANDSTONE.getDefaultState());
        structure.fillWithBlocks(world, start, 29, -18, 52, 31, -18, 54, Blocks.SANDSTONE.getDefaultState());
        structure.fillWithBlocks(world, start, 29, -18, 79, 31, -18, 81, Blocks.SANDSTONE.getDefaultState());
        structure.fillWithBlocks(world, start, 29, -18, 82, 29, -18, 88, Blocks.AIR.getDefaultState());
        structure.fillWithBlocks(world, start, 29, -17, 25, 30, -17, 26, Blocks.SANDSTONE.getDefaultState());
        structure.fillWithBlocks(world, start, 29, -17, 27, 29, -17, 27, Blocks.OAK_PLANKS.getDefaultState());
        structure.fillWithBlocks(world, start, 29, -17, 35, 29, -17, 36, Blocks.SANDSTONE.getDefaultState());
        structure.fillWithBlocks(world, start, 29, -17, 43, 29, -17, 44, Blocks.SANDSTONE.getDefaultState());
        structure.fillWithBlocks(world, start, 29, -17, 52, 31, -17, 54, Blocks.SANDSTONE.getDefaultState());
        structure.fillWithBlocks(world, start, 29, -17, 79, 31, -17, 81, Blocks.SANDSTONE.getDefaultState());
        structure.fillWithBlocks(world, start, 29, -17, 89, 31, -17, 91, Blocks.SANDSTONE.getDefaultState());
        structure.fillWithBlocks(world, start, 29, -16, 25, 30, -16, 26, Blocks.SANDSTONE.getDefaultState());
        structure.fillWithBlocks(world, start, 29, -16, 27, 29, -16, 27, Blocks.OAK_PLANKS.getDefaultState());
        structure.fillWithBlocks(world, start, 29, -16, 35, 30, -15, 35, Blocks.OAK_PLANKS.getDefaultState());
        structure.fillWithBlocks(world, start, 29, -16, 36, 30, -16, 38, Blocks.SANDSTONE.getDefaultState());
        structure.fillWithBlocks(world, start, 29, -16, 45, 29, -16, 45, Blocks.SANDSTONE.getDefaultState());
        structure.fillWithBlocks(world, start, 29, -16, 51, 30, -16, 54, Blocks.SANDSTONE.getDefaultState());
        structure.fillWithBlocks(world, start, 29, -16, 79, 29, -16, 80, Blocks.AIR.getDefaultState());
        structure.fillWithBlocks(world, start, 29, -16, 81, 29, -16, 81, Blocks.SANDSTONE.getDefaultState());
        structure.fillWithBlocks(world, start, 29, -15, 25, 29, -15, 25, Blocks.AIR.getDefaultState());
        structure.fillWithBlocks(world, start, 29, -15, 28, 29, -15, 28, Blocks.OAK_PLANKS.getDefaultState());
        structure.fillWithBlocks(world, start, 29, -15, 29, 29, -13, 31, Blocks.SANDSTONE.getDefaultState());
        structure.fillWithBlocks(world, start, 29, -15, 34, 30, -15, 35, Blocks.OAK_PLANKS.getDefaultState());
        structure.fillWithBlocks(world, start, 29, -15, 36, 30, -15, 37, Blocks.SANDSTONE.getDefaultState());
        structure.fillWithBlocks(world, start, 29, -15, 51, 30, -15, 52, Blocks.SANDSTONE.getDefaultState());
        structure.fillWithBlocks(world, start, 29, -15, 84, 32, -15, 91, Blocks.SANDSTONE.getDefaultState());
        structure.fillWithBlocks(world, start, 29, -14, 33, 29, -14, 33, Blocks.SANDSTONE.getDefaultState());
        structure.fillWithBlocks(world, start, 29, -14, 35, 29, -14, 35, Blocks.SANDSTONE.getDefaultState());
        structure.fillWithBlocks(world, start, 29, -14, 42, 30, -14, 43, Blocks.SANDSTONE.getDefaultState());
        structure.fillWithBlocks(world, start, 29, -14, 52, 29, -14, 54, Blocks.SANDSTONE.getDefaultState());
        structure.fillWithBlocks(world, start, 29, -13, 46, 29, -13, 46, Blocks.AIR.getDefaultState());
        structure.fillWithBlocks(world, start, 29, -13, 47, 29, -13, 48, Blocks.SANDSTONE.getDefaultState());
        structure.fillWithBlocks(world, start, 29, -13, 50, 31, -13, 53, Blocks.SANDSTONE.getDefaultState());
        structure.fillWithBlocks(world, start, 29, -13, 79, 32, -13, 82, Blocks.SANDSTONE.getDefaultState());
        structure.fillWithBlocks(world, start, 29, -13, 84, 31, -13, 86, Blocks.SANDSTONE.getDefaultState());
        structure.fillWithBlocks(world, start, 29, -13, 88, 32, -13, 91, Blocks.SANDSTONE.getDefaultState());
        structure.fillWithBlocks(world, start, 29, -12, 82, 29, -11, 86, Blocks.SANDSTONE.getDefaultState());
        structure.fillWithBlocks(world, start, 29, -12, 90, 30, -12, 91, Blocks.SANDSTONE.getDefaultState());
        structure.fillWithBlocks(world, start, 29, -11, 32, 30, -11, 37, Blocks.SANDSTONE.getDefaultState());
        structure.fillWithBlocks(world, start, 29, -11, 50, 32, -11, 53, Blocks.SANDSTONE.getDefaultState());
        structure.fillWithBlocks(world, start, 29, -11, 79, 29, -11, 79, Blocks.AIR.getDefaultState());
        structure.fillWithBlocks(world, start, 29, -11, 88, 32, -11, 91, Blocks.SANDSTONE.getDefaultState());
        structure.fillWithBlocks(world, start, 29, -9, 46, 29, -7, 46, Blocks.STONE.getDefaultState());
        structure.fillWithBlocks(world, start, 29, -9, 50, 29, -7, 50, Blocks.STONE.getDefaultState());
        structure.fillWithBlocks(world, start, 29, 0, 3, 34, 0, 9, Blocks.SANDSTONE.getDefaultState());
        structure.fillWithBlocks(world, start, 29, 0, 159, 89, 0, 159, Blocks.SANDSTONE.getDefaultState());
        structure.fillWithBlocks(world, start, 30, -52, 42, 30, -52, 42, Blocks.SANDSTONE.getDefaultState());
        structure.fillWithBlocks(world, start, 30, -52, 43, 30, -50, 45, Blocks.AIR.getDefaultState());
        structure.fillWithBlocks(world, start, 30, -52, 47, 30, -51, 49, Blocks.SHROOMLIGHT.getDefaultState());
        structure.fillWithBlocks(world, start, 30, -52, 54, 34, -52, 59, Blocks.SANDSTONE.getDefaultState());
        structure.fillWithBlocks(world, start, 30, -51, 41, 31, -51, 42, Blocks.SANDSTONE.getDefaultState());
        structure.fillWithBlocks(world, start, 30, -51, 54, 34, -51, 59, Blocks.SANDSTONE.getDefaultState());
        structure.fillWithBlocks(world, start, 30, -50, 42, 30, -41, 42, Blocks.SANDSTONE.getDefaultState());
        structure.fillWithBlocks(world, start, 30, -50, 54, 30, -41, 54, Blocks.SANDSTONE.getDefaultState());
        structure.fillWithBlocks(world, start, 30, -50, 86, 35, -50, 92, Blocks.SANDSTONE.getDefaultState());
        structure.fillWithBlocks(world, start, 30, -49, 25, 31, -49, 37, Blocks.SANDSTONE.getDefaultState());
        structure.fillWithBlocks(world, start, 30, -49, 38, 30, -41, 38, Blocks.SANDSTONE.getDefaultState());
        structure.fillWithBlocks(world, start, 30, -49, 39, 32, -49, 41, Blocks.AIR.getDefaultState());
        structure.fillWithBlocks(world, start, 30, -49, 43, 30, -49, 53, Blocks.AIR.getDefaultState());
        structure.fillWithBlocks(world, start, 30, -49, 55, 32, -49, 57, Blocks.AIR.getDefaultState());
        structure.fillWithBlocks(world, start, 30, -49, 58, 30, -49, 59, Blocks.SANDSTONE.getDefaultState());
        structure.fillWithBlocks(world, start, 30, -49, 75, 30, -49, 77, Blocks.SANDSTONE.getDefaultState());
        structure.fillWithBlocks(world, start, 30, -49, 78, 31, -49, 86, Blocks.AIR.getDefaultState());
        structure.fillWithBlocks(world, start, 30, -49, 87, 30, -49, 92, Blocks.SANDSTONE.getDefaultState());
        structure.fillWithBlocks(world, start, 30, -48, 28, 31, -48, 37, Blocks.SANDSTONE.getDefaultState());
        structure.fillWithBlocks(world, start, 30, -48, 39, 32, -48, 41, Blocks.AIR.getDefaultState());
        structure.fillWithBlocks(world, start, 30, -48, 43, 30, -48, 53, Blocks.AIR.getDefaultState());
        structure.fillWithBlocks(world, start, 30, -48, 55, 32, -48, 57, Blocks.AIR.getDefaultState());
        structure.fillWithBlocks(world, start, 30, -48, 58, 30, -48, 59, Blocks.SANDSTONE.getDefaultState());
        structure.fillWithBlocks(world, start, 30, -48, 75, 30, -41, 75, Blocks.SANDSTONE.getDefaultState());
        structure.fillWithBlocks(world, start, 30, -48, 76, 30, -48, 76, Blocks.IRON_BARS.getDefaultState().with(FourWayBlock.WATERLOGGED, false).with(FourWayBlock.NORTH, true).with(FourWayBlock.SOUTH, true).with(FourWayBlock.EAST, true).with(FourWayBlock.WEST, true));
        structure.fillWithBlocks(world, start, 30, -48, 77, 30, -41, 77, Blocks.SANDSTONE.getDefaultState());
        structure.fillWithBlocks(world, start, 30, -48, 78, 31, -48, 86, Blocks.AIR.getDefaultState());
        structure.fillWithBlocks(world, start, 30, -48, 87, 30, -41, 87, Blocks.SANDSTONE.getDefaultState());
        structure.fillWithBlocks(world, start, 30, -48, 88, 30, -48, 88, Blocks.IRON_BARS.getDefaultState().with(FourWayBlock.WATERLOGGED, false).with(FourWayBlock.NORTH, true).with(FourWayBlock.SOUTH, true).with(FourWayBlock.EAST, true).with(FourWayBlock.WEST, true));
        structure.fillWithBlocks(world, start, 30, -48, 89, 30, -48, 92, Blocks.SANDSTONE.getDefaultState());
        structure.fillWithBlocks(world, start, 30, -47, 39, 32, -47, 41, Blocks.AIR.getDefaultState());
        structure.fillWithBlocks(world, start, 30, -47, 43, 30, -47, 53, Blocks.AIR.getDefaultState());
        structure.fillWithBlocks(world, start, 30, -47, 55, 32, -47, 57, Blocks.AIR.getDefaultState());
        structure.fillWithBlocks(world, start, 30, -47, 58, 30, -47, 59, Blocks.SANDSTONE.getDefaultState());
        structure.fillWithBlocks(world, start, 30, -47, 76, 31, -47, 77, Blocks.SANDSTONE.getDefaultState());
        structure.fillWithBlocks(world, start, 30, -47, 78, 31, -47, 86, Blocks.AIR.getDefaultState());
        structure.fillWithBlocks(world, start, 30, -47, 88, 31, -47, 92, Blocks.SANDSTONE.getDefaultState());
        structure.fillWithBlocks(world, start, 30, -46, 47, 30, -44, 49, Blocks.AIR.getDefaultState());
        structure.fillWithBlocks(world, start, 30, -46, 58, 31, -46, 59, Blocks.SANDSTONE.getDefaultState());
        structure.fillWithBlocks(world, start, 30, -46, 76, 31, -46, 77, Blocks.SANDSTONE.getDefaultState());
        structure.fillWithBlocks(world, start, 30, -46, 78, 31, -46, 86, Blocks.AIR.getDefaultState());
        structure.fillWithBlocks(world, start, 30, -46, 88, 34, -46, 92, Blocks.SANDSTONE.getDefaultState());
        structure.fillWithBlocks(world, start, 30, -45, 40, 32, -45, 46, Blocks.SANDSTONE.getDefaultState());
        structure.fillWithBlocks(world, start, 30, -45, 55, 32, -45, 58, Blocks.SANDSTONE.getDefaultState());
        structure.fillWithBlocks(world, start, 30, -45, 72, 36, -45, 78, Blocks.SANDSTONE.getDefaultState());
        structure.fillWithBlocks(world, start, 30, -44, 43, 30, -44, 45, Blocks.AIR.getDefaultState());
        structure.fillWithBlocks(world, start, 30, -44, 51, 30, -44, 53, Blocks.AIR.getDefaultState());
        structure.fillWithBlocks(world, start, 30, -44, 72, 36, -44, 78, Blocks.SANDSTONE.getDefaultState());
        structure.fillWithBlocks(world, start, 30, -43, 93, 31, -43, 94, Blocks.STONE_BRICKS.getDefaultState());
        structure.fillWithBlocks(world, start, 30, -43, 96, 31, -43, 97, Blocks.STONE_BRICKS.getDefaultState());
        structure.fillWithBlocks(world, start, 30, -42, 91, 30, -42, 92, Blocks.AIR.getDefaultState());
        structure.fillWithBlocks(world, start, 30, -41, 46, 35, -41, 58, Blocks.SANDSTONE.getDefaultState());
        structure.fillWithBlocks(world, start, 30, -41, 72, 41, -41, 85, Blocks.SANDSTONE.getDefaultState());
        structure.fillWithBlocks(world, start, 30, -41, 89, 34, -40, 89, Blocks.STONE_BRICKS.getDefaultState());
        structure.fillWithBlocks(world, start, 30, -41, 90, 31, -41, 91, Blocks.AIR.getDefaultState());
        structure.fillWithBlocks(world, start, 30, -41, 92, 30, -40, 92, Blocks.STONE_BRICKS.getDefaultState());
        structure.fillWithBlocks(world, start, 30, -41, 95, 30, -40, 97, Blocks.STONE_BRICKS.getDefaultState());
        structure.fillWithBlocks(world, start, 30, -40, 15, 36, -40, 29, Blocks.STONE_BRICKS.getDefaultState());
        structure.fillWithBlocks(world, start, 30, -39, 14, 40, -39, 14, Blocks.STONE_BRICKS.getDefaultState());
        structure.fillWithBlocks(world, start, 30, -39, 16, 33, -39, 16, Blocks.STONE_BRICKS.getDefaultState());
        structure.fillWithBlocks(world, start, 30, -39, 21, 32, -39, 28, Blocks.AIR.getDefaultState());
        structure.fillWithBlocks(world, start, 30, -39, 94, 32, -39, 96, Blocks.AIR.getDefaultState());
        structure.fillWithBlocks(world, start, 30, -39, 100, 43, -36, 100, Blocks.STONE_BRICKS.getDefaultState());
        structure.fillWithBlocks(world, start, 30, -38, 12, 31, -38, 13, Blocks.STONE_BRICKS.getDefaultState());
        structure.fillWithBlocks(world, start, 30, -38, 14, 30, -38, 16, Blocks.SHROOMLIGHT.getDefaultState());
        structure.fillWithBlocks(world, start, 30, -38, 21, 32, -38, 28, Blocks.AIR.getDefaultState());
        structure.fillWithBlocks(world, start, 30, -38, 94, 32, -38, 96, Blocks.AIR.getDefaultState());
        structure.fillWithBlocks(world, start, 30, -38, 98, 30, -38, 100, Blocks.STONE_BRICKS.getDefaultState());
        structure.fillWithBlocks(world, start, 30, -37, 10, 40, -33, 10, Blocks.STONE_BRICKS.getDefaultState());
        structure.fillWithBlocks(world, start, 30, -37, 11, 30, -37, 11, Blocks.AIR.getDefaultState());
        structure.fillWithBlocks(world, start, 30, -37, 12, 30, -37, 13, Blocks.STONE_BRICKS.getDefaultState());
        structure.fillWithBlocks(world, start, 30, -37, 14, 30, -37, 15, Blocks.AIR.getDefaultState());
        structure.fillWithBlocks(world, start, 30, -36, 11, 31, -36, 13, Blocks.STONE_BRICKS.getDefaultState());
        structure.fillWithBlocks(world, start, 30, -36, 14, 30, -36, 16, Blocks.SHROOMLIGHT.getDefaultState());
        structure.fillWithBlocks(world, start, 30, -36, 81, 32, -36, 85, Blocks.STONE_BRICKS.getDefaultState());
        structure.fillWithBlocks(world, start, 30, -35, 11, 31, -35, 13, Blocks.STONE_BRICKS.getDefaultState());
        structure.fillWithBlocks(world, start, 30, -35, 14, 30, -35, 15, Blocks.AIR.getDefaultState());
        structure.fillWithBlocks(world, start, 30, -35, 29, 31, -35, 30, Blocks.STONE_BRICKS.getDefaultState());
        structure.fillWithBlocks(world, start, 30, -35, 41, 30, -35, 41, Blocks.STONE_BRICKS.getDefaultState());
        structure.fillWithBlocks(world, start, 30, -35, 42, 30, -35, 43, Blocks.AIR.getDefaultState());
        structure.fillWithBlocks(world, start, 30, -35, 45, 32, -35, 47, Blocks.STONE_BRICKS.getDefaultState());
        structure.fillWithBlocks(world, start, 30, -35, 48, 30, -34, 48, Blocks.SHROOMLIGHT.getDefaultState());
        structure.fillWithBlocks(world, start, 30, -35, 49, 32, -35, 51, Blocks.STONE_BRICKS.getDefaultState());
        structure.fillWithBlocks(world, start, 30, -35, 53, 32, -35, 55, Blocks.STONE_BRICKS.getDefaultState());
        structure.fillWithBlocks(world, start, 30, -35, 58, 31, -35, 67, Blocks.STONE_BRICKS.getDefaultState());
        structure.fillWithBlocks(world, start, 30, -35, 78, 33, -35, 81, Blocks.STONE_BRICKS.getDefaultState());
        structure.fillWithBlocks(world, start, 30, -35, 97, 31, -35, 98, Blocks.STONE_BRICKS.getDefaultState());
        structure.fillWithBlocks(world, start, 30, -34, 11, 30, -34, 11, Blocks.STONE_BRICKS.getDefaultState());
        structure.fillWithBlocks(world, start, 30, -34, 12, 30, -34, 13, Blocks.AIR.getDefaultState());
        structure.fillWithBlocks(world, start, 30, -34, 14, 30, -34, 14, Blocks.STONE_BRICKS.getDefaultState());
        structure.fillWithBlocks(world, start, 30, -34, 17, 32, -34, 25, Blocks.STONE_BRICKS.getDefaultState());
        structure.fillWithBlocks(world, start, 30, -34, 27, 33, -34, 30, Blocks.STONE_BRICKS.getDefaultState());
        structure.fillWithBlocks(world, start, 30, -34, 42, 30, -34, 43, Blocks.STONE_BRICKS.getDefaultState());
        structure.fillWithBlocks(world, start, 30, -34, 45, 31, -34, 46, Blocks.AIR.getDefaultState());
        structure.fillWithBlocks(world, start, 30, -34, 47, 30, -33, 47, Blocks.STONE_BRICKS.getDefaultState());
        structure.fillWithBlocks(world, start, 30, -34, 49, 33, -34, 49, Blocks.STONE_BRICKS.getDefaultState());
        structure.fillWithBlocks(world, start, 30, -34, 50, 30, -34, 51, Blocks.AIR.getDefaultState());
        structure.fillWithBlocks(world, start, 30, -34, 53, 32, -33, 53, Blocks.STONE_BRICKS.getDefaultState());
        structure.fillWithBlocks(world, start, 30, -34, 63, 31, -34, 68, Blocks.STONE_BRICKS.getDefaultState());
        structure.fillWithBlocks(world, start, 30, -34, 72, 30, -34, 77, Blocks.STONE_BRICKS.getDefaultState());
        structure.fillWithBlocks(world, start, 30, -34, 79, 30, -34, 79, Blocks.STONE_BRICKS.getDefaultState());
        structure.fillWithBlocks(world, start, 30, -34, 80, 30, -34, 80, Blocks.AIR.getDefaultState());
        structure.fillWithBlocks(world, start, 30, -34, 81, 30, -34, 82, Blocks.STONE_BRICKS.getDefaultState());
        structure.fillWithBlocks(world, start, 30, -34, 86, 31, -34, 87, Blocks.STONE_BRICKS.getDefaultState());
        structure.fillWithBlocks(world, start, 30, -34, 94, 33, -34, 100, Blocks.STONE_BRICKS.getDefaultState());
        structure.fillWithBlocks(world, start, 30, -33, 11, 30, -33, 11, Blocks.STONE_BRICKS.getDefaultState());
        structure.fillWithBlocks(world, start, 30, -33, 13, 30, -33, 13, Blocks.STONE_BRICKS.getDefaultState());
        structure.fillWithBlocks(world, start, 30, -33, 23, 31, -33, 25, Blocks.STONE_BRICKS.getDefaultState());
        structure.fillWithBlocks(world, start, 30, -33, 28, 30, -32, 30, Blocks.STONE_BRICKS.getDefaultState());
        structure.fillWithBlocks(world, start, 30, -33, 45, 30, -32, 45, Blocks.AIR.getDefaultState());
        structure.fillWithBlocks(world, start, 30, -33, 46, 31, -33, 47, Blocks.STONE_BRICKS.getDefaultState());
        structure.fillWithBlocks(world, start, 30, -33, 48, 30, -31, 48, Blocks.STONE_BRICKS.getDefaultState());
        structure.fillWithBlocks(world, start, 30, -33, 49, 30, -33, 50, Blocks.AIR.getDefaultState());
        structure.fillWithBlocks(world, start, 30, -33, 51, 31, -33, 55, Blocks.STONE_BRICKS.getDefaultState());
        structure.fillWithBlocks(world, start, 30, -33, 63, 32, -33, 67, Blocks.STONE_BRICKS.getDefaultState());
        structure.fillWithBlocks(world, start, 30, -33, 70, 31, -33, 72, Blocks.STONE_BRICKS.getDefaultState());
        structure.fillWithBlocks(world, start, 30, -33, 74, 34, -33, 78, Blocks.STONE_BRICKS.getDefaultState());
        structure.fillWithBlocks(world, start, 30, -33, 79, 30, -33, 82, Blocks.STONE_BRICKS.getDefaultState());
        structure.fillWithBlocks(world, start, 30, -33, 86, 30, -33, 87, Blocks.STONE_BRICKS.getDefaultState());
        structure.fillWithBlocks(world, start, 30, -33, 100, 35, -31, 100, Blocks.STONE_BRICKS.getDefaultState());
        structure.fillWithBlocks(world, start, 30, -32, 11, 30, -32, 11, Blocks.STONE_BRICKS.getDefaultState());
        structure.fillWithBlocks(world, start, 30, -32, 13, 30, -32, 26, Blocks.STONE_BRICKS.getDefaultState());
        structure.fillWithBlocks(world, start, 30, -32, 27, 30, -32, 27, Blocks.AIR.getDefaultState());
        structure.fillWithBlocks(world, start, 30, -32, 40, 30, -31, 40, Blocks.SANDSTONE.getDefaultState());
        structure.fillWithBlocks(world, start, 30, -32, 47, 31, -32, 47, Blocks.AIR.getDefaultState());
        structure.fillWithBlocks(world, start, 30, -32, 49, 30, -32, 49, Blocks.AIR.getDefaultState());
        structure.fillWithBlocks(world, start, 30, -32, 50, 30, -30, 50, Blocks.SANDSTONE.getDefaultState());
        structure.fillWithBlocks(world, start, 30, -32, 51, 30, -32, 52, Blocks.STONE_BRICKS.getDefaultState());
        structure.fillWithBlocks(world, start, 30, -32, 54, 31, -32, 55, Blocks.STONE_BRICKS.getDefaultState());
        structure.fillWithBlocks(world, start, 30, -32, 58, 33, -32, 62, Blocks.STONE_BRICKS.getDefaultState());
        structure.fillWithBlocks(world, start, 30, -32, 79, 30, -31, 82, Blocks.STONE_BRICKS.getDefaultState());
        structure.fillWithBlocks(world, start, 30, -32, 90, 40, -31, 90, Blocks.STONE_BRICKS.getDefaultState());
        structure.fillWithBlocks(world, start, 30, -32, 91, 31, -32, 91, Blocks.AIR.getDefaultState());
        structure.fillWithBlocks(world, start, 30, -32, 92, 30, -32, 92, Blocks.STONE_BRICKS.getDefaultState());
        structure.fillWithBlocks(world, start, 30, -32, 93, 30, -32, 94, Blocks.AIR.getDefaultState());
        structure.fillWithBlocks(world, start, 30, -32, 95, 31, -32, 96, Blocks.STONE_BRICKS.getDefaultState());
        structure.fillWithBlocks(world, start, 30, -32, 98, 32, -32, 100, Blocks.STONE_BRICKS.getDefaultState());
        structure.fillWithBlocks(world, start, 30, -31, 12, 30, -31, 13, Blocks.STONE_BRICKS.getDefaultState());
        structure.fillWithBlocks(world, start, 30, -31, 14, 30, -31, 15, Blocks.AIR.getDefaultState());
        structure.fillWithBlocks(world, start, 30, -31, 16, 30, -31, 16, Blocks.STONE_BRICKS.getDefaultState());
        structure.fillWithBlocks(world, start, 30, -31, 18, 31, -31, 27, Blocks.STONE_BRICKS.getDefaultState());
        structure.fillWithBlocks(world, start, 30, -31, 28, 30, -31, 28, Blocks.STONE_BRICKS.getDefaultState());
        structure.fillWithBlocks(world, start, 30, -31, 38, 30, -31, 40, Blocks.SANDSTONE.getDefaultState());
        structure.fillWithBlocks(world, start, 30, -31, 45, 30, -31, 45, Blocks.STONE_BRICKS.getDefaultState());
        structure.fillWithBlocks(world, start, 30, -31, 47, 30, -31, 49, Blocks.STONE_BRICKS.getDefaultState());
        structure.fillWithBlocks(world, start, 30, -31, 51, 30, -31, 55, Blocks.STONE_BRICKS.getDefaultState());
        structure.fillWithBlocks(world, start, 30, -31, 75, 31, -31, 82, Blocks.STONE_BRICKS.getDefaultState());
        structure.fillWithBlocks(world, start, 30, -31, 86, 40, -31, 96, Blocks.STONE_BRICKS.getDefaultState());
        structure.fillWithBlocks(world, start, 30, -30, 5, 30, -30, 7, Blocks.STONE_BRICKS.getDefaultState());
        structure.fillWithBlocks(world, start, 30, -30, 8, 32, -30, 23, Blocks.SANDSTONE.getDefaultState());
        structure.fillWithBlocks(world, start, 30, -30, 27, 32, -30, 33, Blocks.SANDSTONE.getDefaultState());
        structure.fillWithBlocks(world, start, 30, -30, 35, 30, -29, 36, Blocks.SANDSTONE.getDefaultState());
        structure.fillWithBlocks(world, start, 30, -30, 38, 30, -27, 38, Blocks.SANDSTONE.getDefaultState());
        structure.fillWithBlocks(world, start, 30, -30, 42, 31, -30, 44, Blocks.SANDSTONE.getDefaultState());
        structure.fillWithBlocks(world, start, 30, -30, 45, 30, -30, 45, Blocks.DIRT.getDefaultState());
        structure.fillWithBlocks(world, start, 30, -30, 46, 30, -30, 51, Blocks.SANDSTONE.getDefaultState());
        structure.fillWithBlocks(world, start, 30, -30, 52, 31, -30, 52, Blocks.AIR.getDefaultState());
        structure.fillWithBlocks(world, start, 30, -30, 53, 31, -30, 56, Blocks.SANDSTONE.getDefaultState());
        structure.fillWithBlocks(world, start, 30, -30, 57, 30, -30, 59, Blocks.SANDSTONE.getDefaultState());
        structure.fillWithBlocks(world, start, 30, -30, 70, 30, -30, 71, Blocks.DIRT.getDefaultState());
        structure.fillWithBlocks(world, start, 30, -30, 72, 30, -30, 72, Blocks.SANDSTONE.getDefaultState());
        structure.fillWithBlocks(world, start, 30, -30, 73, 30, -30, 74, Blocks.AIR.getDefaultState());
        structure.fillWithBlocks(world, start, 30, -29, 4, 30, -29, 4, Blocks.STONE_BRICKS.getDefaultState());
        structure.fillWithBlocks(world, start, 30, -29, 6, 30, -29, 7, Blocks.SANDSTONE.getDefaultState());
        structure.fillWithBlocks(world, start, 30, -29, 8, 32, -29, 13, Blocks.AIR.getDefaultState());
        structure.fillWithBlocks(world, start, 30, -29, 20, 32, -27, 20, Blocks.AIR.getDefaultState());
        structure.fillWithBlocks(world, start, 30, -29, 21, 31, -29, 23, Blocks.SANDSTONE.getDefaultState());
        structure.fillWithBlocks(world, start, 30, -29, 26, 30, -29, 28, Blocks.SANDSTONE.getDefaultState());
        structure.fillWithBlocks(world, start, 30, -29, 29, 32, -29, 33, Blocks.AIR.getDefaultState());
        structure.fillWithBlocks(world, start, 30, -29, 34, 30, -29, 36, Blocks.SANDSTONE.getDefaultState());
        structure.fillWithBlocks(world, start, 30, -29, 40, 30, -29, 45, Blocks.SANDSTONE.getDefaultState());
        structure.fillWithBlocks(world, start, 30, -29, 46, 30, -25, 50, Blocks.AIR.getDefaultState());
        structure.fillWithBlocks(world, start, 30, -29, 51, 32, -29, 53, Blocks.SANDSTONE.getDefaultState());
        structure.fillWithBlocks(world, start, 30, -29, 58, 30, -25, 62, Blocks.SANDSTONE.getDefaultState());
        structure.fillWithBlocks(world, start, 30, -29, 63, 32, -29, 67, Blocks.AIR.getDefaultState());
        structure.fillWithBlocks(world, start, 30, -29, 68, 30, -25, 72, Blocks.SANDSTONE.getDefaultState());
        structure.fillWithBlocks(world, start, 30, -29, 73, 31, -29, 74, Blocks.SANDSTONE.getDefaultState());
        structure.fillWithBlocks(world, start, 30, -28, 4, 32, -28, 4, Blocks.STONE_BRICKS.getDefaultState());
        structure.fillWithBlocks(world, start, 30, -28, 6, 31, -28, 6, Blocks.STONE_BRICKS.getDefaultState());
        structure.fillWithBlocks(world, start, 30, -28, 8, 32, -28, 20, Blocks.AIR.getDefaultState());
        structure.fillWithBlocks(world, start, 30, -28, 22, 30, -28, 23, Blocks.AIR.getDefaultState());
        structure.fillWithBlocks(world, start, 30, -28, 26, 30, -28, 28, Blocks.SANDSTONE.getDefaultState());
        structure.fillWithBlocks(world, start, 30, -28, 29, 32, -28, 33, Blocks.AIR.getDefaultState());
        structure.fillWithBlocks(world, start, 30, -28, 34, 30, -26, 34, Blocks.SANDSTONE.getDefaultState());
        structure.fillWithBlocks(world, start, 30, -28, 36, 30, -27, 36, Blocks.SANDSTONE.getDefaultState());
        structure.fillWithBlocks(world, start, 30, -28, 40, 30, -27, 40, Blocks.SANDSTONE.getDefaultState());
        structure.fillWithBlocks(world, start, 30, -28, 42, 32, -28, 45, Blocks.SANDSTONE.getDefaultState());
        structure.fillWithBlocks(world, start, 30, -28, 51, 33, -28, 55, Blocks.SANDSTONE.getDefaultState());
        structure.fillWithBlocks(world, start, 30, -28, 57, 30, -25, 62, Blocks.SANDSTONE.getDefaultState());
        structure.fillWithBlocks(world, start, 30, -28, 63, 34, -28, 67, Blocks.AIR.getDefaultState());
        structure.fillWithBlocks(world, start, 30, -28, 73, 31, -28, 74, Blocks.SANDSTONE.getDefaultState());
        structure.fillWithBlocks(world, start, 30, -27, 4, 30, -27, 5, Blocks.SANDSTONE.getDefaultState());
        structure.fillWithBlocks(world, start, 30, -27, 6, 30, -26, 6, Blocks.STONE_BRICKS.getDefaultState());
        structure.fillWithBlocks(world, start, 30, -27, 7, 32, -27, 7, Blocks.SANDSTONE.getDefaultState());
        structure.fillWithBlocks(world, start, 30, -27, 8, 32, -27, 20, Blocks.AIR.getDefaultState());
        structure.fillWithBlocks(world, start, 30, -27, 21, 32, -27, 24, Blocks.SANDSTONE.getDefaultState());
        structure.fillWithBlocks(world, start, 30, -27, 26, 30, -27, 28, Blocks.SANDSTONE.getDefaultState());
        structure.fillWithBlocks(world, start, 30, -27, 29, 32, -27, 33, Blocks.AIR.getDefaultState());
        structure.fillWithBlocks(world, start, 30, -27, 35, 30, -27, 36, Blocks.SANDSTONE.getDefaultState());
        structure.fillWithBlocks(world, start, 30, -27, 41, 30, -27, 45, Blocks.SANDSTONE.getDefaultState());
        structure.fillWithBlocks(world, start, 30, -27, 51, 32, -27, 53, Blocks.SANDSTONE.getDefaultState());
        structure.fillWithBlocks(world, start, 30, -27, 63, 34, -27, 67, Blocks.AIR.getDefaultState());
        structure.fillWithBlocks(world, start, 30, -26, 4, 31, -26, 6, Blocks.STONE_BRICKS.getDefaultState());
        structure.fillWithBlocks(world, start, 30, -26, 8, 32, -26, 11, Blocks.AIR.getDefaultState());
        structure.fillWithBlocks(world, start, 30, -26, 19, 31, -26, 20, Blocks.AIR.getDefaultState());
        structure.fillWithBlocks(world, start, 30, -26, 22, 31, -26, 24, Blocks.SANDSTONE.getDefaultState());
        structure.fillWithBlocks(world, start, 30, -26, 27, 31, -26, 35, Blocks.SANDSTONE.getDefaultState());
        structure.fillWithBlocks(world, start, 30, -26, 42, 30, -26, 45, Blocks.SANDSTONE.getDefaultState());
        structure.fillWithBlocks(world, start, 30, -26, 51, 31, -26, 52, Blocks.SANDSTONE.getDefaultState());
        structure.fillWithBlocks(world, start, 30, -26, 53, 30, -26, 53, Blocks.AIR.getDefaultState());
        structure.fillWithBlocks(world, start, 30, -26, 63, 34, -26, 67, Blocks.AIR.getDefaultState());
        structure.fillWithBlocks(world, start, 30, -26, 73, 30, -26, 73, Blocks.AIR.getDefaultState());
        structure.fillWithBlocks(world, start, 30, -26, 74, 30, -26, 75, Blocks.SANDSTONE.getDefaultState());
        structure.fillWithBlocks(world, start, 30, -25, 4, 31, -25, 5, Blocks.STONE_BRICKS.getDefaultState());
        structure.fillWithBlocks(world, start, 30, -25, 7, 32, -25, 7, Blocks.SANDSTONE.getDefaultState());
        structure.fillWithBlocks(world, start, 30, -25, 8, 32, -25, 11, Blocks.AIR.getDefaultState());
        structure.fillWithBlocks(world, start, 30, -25, 18, 32, -25, 20, Blocks.AIR.getDefaultState());
        structure.fillWithBlocks(world, start, 30, -25, 21, 32, -23, 21, Blocks.SANDSTONE.getDefaultState());
        structure.fillWithBlocks(world, start, 30, -25, 23, 30, -24, 24, Blocks.SANDSTONE.getDefaultState());
        structure.fillWithBlocks(world, start, 30, -25, 30, 31, -25, 32, Blocks.SANDSTONE.getDefaultState());
        structure.fillWithBlocks(world, start, 30, -25, 33, 30, -25, 34, Blocks.DIRT.getDefaultState());
        structure.fillWithBlocks(world, start, 30, -25, 42, 32, -25, 45, Blocks.SANDSTONE.getDefaultState());
        structure.fillWithBlocks(world, start, 30, -25, 51, 32, -25, 57, Blocks.SANDSTONE.getDefaultState());
        structure.fillWithBlocks(world, start, 30, -25, 63, 34, -25, 67, Blocks.AIR.getDefaultState());
        structure.fillWithBlocks(world, start, 30, -24, 7, 37, -24, 7, Blocks.STONE_BRICKS.getDefaultState());
        structure.fillWithBlocks(world, start, 30, -24, 22, 32, -24, 24, Blocks.SANDSTONE.getDefaultState());
        structure.fillWithBlocks(world, start, 30, -24, 32, 30, -23, 35, Blocks.SANDSTONE.getDefaultState());
        structure.fillWithBlocks(world, start, 30, -24, 45, 30, -24, 45, Blocks.SANDSTONE.getDefaultState());
        structure.fillWithBlocks(world, start, 30, -24, 46, 30, -21, 50, Blocks.AIR.getDefaultState());
        structure.fillWithBlocks(world, start, 30, -24, 51, 31, -24, 56, Blocks.SANDSTONE.getDefaultState());
        structure.fillWithBlocks(world, start, 30, -24, 57, 31, -24, 57, Blocks.DIRT.getDefaultState());
        structure.fillWithBlocks(world, start, 30, -24, 58, 31, -24, 59, Blocks.SANDSTONE.getDefaultState());
        structure.fillWithBlocks(world, start, 30, -24, 61, 30, -24, 61, Blocks.SANDSTONE.getDefaultState());
        structure.fillWithBlocks(world, start, 30, -24, 63, 34, -24, 67, Blocks.SANDSTONE.getDefaultState());
        structure.fillWithBlocks(world, start, 30, -24, 68, 30, -23, 68, Blocks.AIR.getDefaultState());
        structure.fillWithBlocks(world, start, 30, -24, 70, 33, -24, 73, Blocks.SANDSTONE.getDefaultState());
        structure.fillWithBlocks(world, start, 30, -24, 74, 30, -24, 74, Blocks.AIR.getDefaultState());
        structure.fillWithBlocks(world, start, 30, -23, 4, 31, -23, 6, Blocks.STONE_BRICKS.getDefaultState());
        structure.fillWithBlocks(world, start, 30, -23, 7, 30, -22, 7, Blocks.SANDSTONE.getDefaultState());
        structure.fillWithBlocks(world, start, 30, -23, 8, 32, -23, 10, Blocks.STONE_BRICKS.getDefaultState());
        structure.fillWithBlocks(world, start, 30, -23, 12, 30, -23, 12, Blocks.AIR.getDefaultState());
        structure.fillWithBlocks(world, start, 30, -23, 13, 30, -23, 14, Blocks.STONE_BRICKS.getDefaultState());
        structure.fillWithBlocks(world, start, 30, -23, 17, 31, -23, 18, Blocks.STONE_BRICKS.getDefaultState());
        structure.fillWithBlocks(world, start, 30, -23, 20, 31, -23, 21, Blocks.SANDSTONE.getDefaultState());
        structure.fillWithBlocks(world, start, 30, -23, 23, 31, -23, 24, Blocks.SANDSTONE.getDefaultState());
        structure.fillWithBlocks(world, start, 30, -23, 27, 31, -23, 28, Blocks.SANDSTONE.getDefaultState());
        structure.fillWithBlocks(world, start, 30, -23, 30, 31, -23, 33, Blocks.SANDSTONE.getDefaultState());
        structure.fillWithBlocks(world, start, 30, -23, 42, 30, -20, 42, Blocks.SANDSTONE.getDefaultState());
        structure.fillWithBlocks(world, start, 30, -23, 45, 30, -23, 45, Blocks.SANDSTONE.getDefaultState());
        structure.fillWithBlocks(world, start, 30, -23, 51, 32, -23, 56, Blocks.SANDSTONE.getDefaultState());
        structure.fillWithBlocks(world, start, 30, -23, 57, 30, -23, 64, Blocks.SANDSTONE.getDefaultState());
        structure.fillWithBlocks(world, start, 30, -23, 66, 31, -23, 67, Blocks.SANDSTONE.getDefaultState());
        structure.fillWithBlocks(world, start, 30, -23, 69, 30, -22, 71, Blocks.SANDSTONE.getDefaultState());
        structure.fillWithBlocks(world, start, 30, -23, 72, 31, -23, 73, Blocks.SANDSTONE.getDefaultState());
        structure.fillWithBlocks(world, start, 30, -23, 75, 31, -22, 75, Blocks.SANDSTONE.getDefaultState());
        structure.fillWithBlocks(world, start, 30, -22, 9, 30, -22, 9, Blocks.STONE_BRICKS.getDefaultState());
        structure.fillWithBlocks(world, start, 30, -22, 11, 32, -22, 11, Blocks.SANDSTONE.getDefaultState());
        structure.fillWithBlocks(world, start, 30, -22, 12, 33, -22, 12, Blocks.STONE_BRICKS.getDefaultState());
        structure.fillWithBlocks(world, start, 30, -22, 13, 30, -21, 13, Blocks.AIR.getDefaultState());
        structure.fillWithBlocks(world, start, 30, -22, 14, 32, -21, 14, Blocks.STONE_BRICKS.getDefaultState());
        structure.fillWithBlocks(world, start, 30, -22, 15, 30, -22, 15, Blocks.SANDSTONE.getDefaultState());
        structure.fillWithBlocks(world, start, 30, -22, 17, 30, -22, 22, Blocks.SANDSTONE.getDefaultState());
        structure.fillWithBlocks(world, start, 30, -22, 23, 30, -22, 24, Blocks.AIR.getDefaultState());
        structure.fillWithBlocks(world, start, 30, -22, 27, 31, -22, 30, Blocks.SANDSTONE.getDefaultState());
        structure.fillWithBlocks(world, start, 30, -22, 31, 30, -20, 31, Blocks.SANDSTONE.getDefaultState());
        structure.fillWithBlocks(world, start, 30, -22, 34, 31, -22, 35, Blocks.SANDSTONE.getDefaultState());
        structure.fillWithBlocks(world, start, 30, -22, 43, 32, -22, 45, Blocks.SANDSTONE.getDefaultState());
        structure.fillWithBlocks(world, start, 30, -22, 51, 31, -22, 52, Blocks.SANDSTONE.getDefaultState());
        structure.fillWithBlocks(world, start, 30, -22, 58, 31, -22, 60, Blocks.SANDSTONE.getDefaultState());
        structure.fillWithBlocks(world, start, 30, -22, 63, 30, -22, 64, Blocks.DIRT.getDefaultState());
        structure.fillWithBlocks(world, start, 30, -22, 74, 31, -22, 75, Blocks.SANDSTONE.getDefaultState());
        structure.fillWithBlocks(world, start, 30, -21, 5, 30, -21, 7, Blocks.STONE_BRICKS.getDefaultState());
        structure.fillWithBlocks(world, start, 30, -21, 8, 30, -21, 9, Blocks.SANDSTONE.getDefaultState());
        structure.fillWithBlocks(world, start, 30, -21, 18, 31, -21, 18, Blocks.STONE_BRICKS.getDefaultState());
        structure.fillWithBlocks(world, start, 30, -21, 23, 31, -21, 24, Blocks.SANDSTONE.getDefaultState());
        structure.fillWithBlocks(world, start, 30, -21, 27, 30, -21, 33, Blocks.SANDSTONE.getDefaultState());
        structure.fillWithBlocks(world, start, 30, -21, 35, 31, -21, 35, Blocks.SANDSTONE.getDefaultState());
        structure.fillWithBlocks(world, start, 30, -21, 45, 30, -21, 45, Blocks.SANDSTONE.getDefaultState());
        structure.fillWithBlocks(world, start, 30, -21, 51, 31, -21, 52, Blocks.SANDSTONE.getDefaultState());
        structure.fillWithBlocks(world, start, 30, -21, 57, 34, -21, 62, Blocks.SANDSTONE.getDefaultState());
        structure.fillWithBlocks(world, start, 30, -21, 64, 30, -21, 65, Blocks.SANDSTONE.getDefaultState());
        structure.fillWithBlocks(world, start, 30, -21, 67, 30, -21, 67, Blocks.SANDSTONE.getDefaultState());
        structure.fillWithBlocks(world, start, 30, -21, 70, 30, -21, 70, Blocks.SANDSTONE.getDefaultState());
        structure.fillWithBlocks(world, start, 30, -21, 72, 31, -21, 73, Blocks.SANDSTONE.getDefaultState());
        structure.fillWithBlocks(world, start, 30, -21, 74, 30, -21, 75, Blocks.SANDSTONE.getDefaultState());
        structure.fillWithBlocks(world, start, 30, -20, 28, 30, -20, 29, Blocks.OAK_PLANKS.getDefaultState());
        structure.fillWithBlocks(world, start, 30, -20, 30, 32, -20, 32, Blocks.SANDSTONE.getDefaultState());
        structure.fillWithBlocks(world, start, 30, -20, 33, 30, -20, 35, Blocks.OAK_PLANKS.getDefaultState());
        structure.fillWithBlocks(world, start, 30, -20, 43, 32, -20, 45, Blocks.SANDSTONE.getDefaultState());
        structure.fillWithBlocks(world, start, 30, -20, 46, 30, -20, 51, Blocks.SANDSTONE.getDefaultState());
        structure.fillWithBlocks(world, start, 30, -20, 53, 31, -20, 54, Blocks.SANDSTONE.getDefaultState());
        structure.fillWithBlocks(world, start, 30, -20, 62, 30, -17, 62, Blocks.SANDSTONE.getDefaultState());
        structure.fillWithBlocks(world, start, 30, -20, 68, 30, -17, 68, Blocks.SANDSTONE.getDefaultState());
        structure.fillWithBlocks(world, start, 30, -20, 79, 32, -20, 90, Blocks.SANDSTONE.getDefaultState());
        structure.fillWithBlocks(world, start, 30, -19, 27, 30, -18, 28, Blocks.OAK_PLANKS.getDefaultState());
        structure.fillWithBlocks(world, start, 30, -19, 29, 32, -17, 29, Blocks.SANDSTONE.getDefaultState());
        structure.fillWithBlocks(world, start, 30, -19, 30, 32, -19, 32, Blocks.AIR.getDefaultState());
        structure.fillWithBlocks(world, start, 30, -19, 33, 30, -19, 33, Blocks.SANDSTONE.getDefaultState());
        structure.fillWithBlocks(world, start, 30, -19, 34, 30, -18, 35, Blocks.OAK_PLANKS.getDefaultState());
        structure.fillWithBlocks(world, start, 30, -19, 36, 31, -19, 37, Blocks.SANDSTONE.getDefaultState());
        structure.fillWithBlocks(world, start, 30, -19, 38, 30, -16, 38, Blocks.SANDSTONE.getDefaultState());
        structure.fillWithBlocks(world, start, 30, -19, 40, 30, -19, 42, Blocks.STONE_BRICKS.getDefaultState());
        structure.fillWithBlocks(world, start, 30, -19, 45, 30, -19, 45, Blocks.SANDSTONE.getDefaultState());
        structure.fillWithBlocks(world, start, 30, -19, 46, 30, -19, 50, Blocks.AIR.getDefaultState());
        structure.fillWithBlocks(world, start, 30, -19, 51, 33, -19, 54, Blocks.SANDSTONE.getDefaultState());
        structure.fillWithBlocks(world, start, 30, -19, 56, 30, -17, 56, Blocks.SANDSTONE.getDefaultState());
        structure.fillWithBlocks(world, start, 30, -19, 58, 30, -19, 60, Blocks.STONE_BRICKS.getDefaultState());
        structure.fillWithBlocks(world, start, 30, -19, 64, 30, -19, 66, Blocks.STONE_BRICKS.getDefaultState());
        structure.fillWithBlocks(world, start, 30, -19, 70, 30, -19, 72, Blocks.STONE_BRICKS.getDefaultState());
        structure.fillWithBlocks(world, start, 30, -19, 74, 30, -16, 74, Blocks.SANDSTONE.getDefaultState());
        structure.fillWithBlocks(world, start, 30, -19, 76, 30, -19, 78, Blocks.STONE_BRICKS.getDefaultState());
        structure.fillWithBlocks(world, start, 30, -19, 82, 30, -19, 82, Blocks.SANDSTONE.getDefaultState());
        structure.fillWithBlocks(world, start, 30, -19, 88, 30, -16, 91, Blocks.SANDSTONE.getDefaultState());
        structure.fillWithBlocks(world, start, 30, -18, 30, 32, -18, 32, Blocks.AIR.getDefaultState());
        structure.fillWithBlocks(world, start, 30, -18, 33, 30, -18, 33, Blocks.SANDSTONE.getDefaultState());
        structure.fillWithBlocks(world, start, 30, -18, 36, 31, -18, 37, Blocks.SANDSTONE.getDefaultState());
        structure.fillWithBlocks(world, start, 30, -18, 40, 30, -17, 40, Blocks.STONE_BRICKS.getDefaultState());
        structure.fillWithBlocks(world, start, 30, -18, 42, 30, -17, 42, Blocks.STONE_BRICKS.getDefaultState());
        structure.fillWithBlocks(world, start, 30, -18, 45, 30, -18, 45, Blocks.SANDSTONE.getDefaultState());
        structure.fillWithBlocks(world, start, 30, -18, 46, 30, -18, 50, Blocks.AIR.getDefaultState());
        structure.fillWithBlocks(world, start, 30, -18, 51, 32, -18, 54, Blocks.SANDSTONE.getDefaultState());
        structure.fillWithBlocks(world, start, 30, -18, 58, 30, -17, 58, Blocks.STONE_BRICKS.getDefaultState());
        structure.fillWithBlocks(world, start, 30, -18, 60, 30, -17, 60, Blocks.STONE_BRICKS.getDefaultState());
        structure.fillWithBlocks(world, start, 30, -18, 64, 30, -17, 64, Blocks.STONE_BRICKS.getDefaultState());
        structure.fillWithBlocks(world, start, 30, -18, 66, 30, -17, 66, Blocks.STONE_BRICKS.getDefaultState());
        structure.fillWithBlocks(world, start, 30, -18, 70, 30, -17, 70, Blocks.STONE_BRICKS.getDefaultState());
        structure.fillWithBlocks(world, start, 30, -18, 72, 30, -17, 72, Blocks.STONE_BRICKS.getDefaultState());
        structure.fillWithBlocks(world, start, 30, -18, 76, 30, -17, 76, Blocks.STONE_BRICKS.getDefaultState());
        structure.fillWithBlocks(world, start, 30, -18, 78, 30, -17, 78, Blocks.STONE_BRICKS.getDefaultState());
        structure.fillWithBlocks(world, start, 30, -18, 82, 30, -18, 82, Blocks.SANDSTONE.getDefaultState());
        structure.fillWithBlocks(world, start, 30, -18, 83, 30, -16, 87, Blocks.AIR.getDefaultState());
        structure.fillWithBlocks(world, start, 30, -17, 27, 30, -16, 28, Blocks.OAK_PLANKS.getDefaultState());
        structure.fillWithBlocks(world, start, 30, -17, 30, 32, -17, 32, Blocks.AIR.getDefaultState());
        structure.fillWithBlocks(world, start, 30, -17, 33, 30, -17, 33, Blocks.SANDSTONE.getDefaultState());
        structure.fillWithBlocks(world, start, 30, -17, 34, 30, -16, 35, Blocks.OAK_PLANKS.getDefaultState());
        structure.fillWithBlocks(world, start, 30, -17, 36, 31, -17, 37, Blocks.SANDSTONE.getDefaultState());
        structure.fillWithBlocks(world, start, 30, -17, 41, 30, -17, 43, Blocks.STONE_BRICKS.getDefaultState());
        structure.fillWithBlocks(world, start, 30, -17, 44, 31, -17, 45, Blocks.SANDSTONE.getDefaultState());
        structure.fillWithBlocks(world, start, 30, -17, 46, 30, -17, 50, Blocks.AIR.getDefaultState());
        structure.fillWithBlocks(world, start, 30, -17, 51, 33, -17, 54, Blocks.SANDSTONE.getDefaultState());
        structure.fillWithBlocks(world, start, 30, -17, 59, 30, -17, 60, Blocks.STONE_BRICKS.getDefaultState());
        structure.fillWithBlocks(world, start, 30, -17, 65, 30, -17, 66, Blocks.STONE_BRICKS.getDefaultState());
        structure.fillWithBlocks(world, start, 30, -17, 71, 30, -17, 72, Blocks.STONE_BRICKS.getDefaultState());
        structure.fillWithBlocks(world, start, 30, -17, 77, 30, -17, 78, Blocks.STONE_BRICKS.getDefaultState());
        structure.fillWithBlocks(world, start, 30, -17, 82, 30, -17, 82, Blocks.SANDSTONE.getDefaultState());
        structure.fillWithBlocks(world, start, 30, -16, 29, 30, -16, 33, Blocks.SANDSTONE.getDefaultState());
        structure.fillWithBlocks(world, start, 30, -16, 42, 32, -16, 45, Blocks.SANDSTONE.getDefaultState());
        structure.fillWithBlocks(world, start, 30, -16, 46, 30, -10, 46, Blocks.SANDSTONE.getDefaultState());
        structure.fillWithBlocks(world, start, 30, -16, 47, 30, -16, 49, Blocks.AIR.getDefaultState());
        structure.fillWithBlocks(world, start, 30, -16, 50, 32, -16, 52, Blocks.SANDSTONE.getDefaultState());
        structure.fillWithBlocks(world, start, 30, -16, 79, 31, -16, 82, Blocks.SANDSTONE.getDefaultState());
        structure.fillWithBlocks(world, start, 30, -15, 25, 32, -13, 25, Blocks.SANDSTONE.getDefaultState());
        structure.fillWithBlocks(world, start, 30, -15, 26, 31, -15, 26, Blocks.AIR.getDefaultState());
        structure.fillWithBlocks(world, start, 30, -15, 28, 30, -15, 35, Blocks.OAK_PLANKS.getDefaultState());
        structure.fillWithBlocks(world, start, 30, -15, 42, 30, -15, 52, Blocks.SANDSTONE.getDefaultState());
        structure.fillWithBlocks(world, start, 30, -15, 54, 33, -12, 54, Blocks.SANDSTONE.getDefaultState());
        structure.fillWithBlocks(world, start, 30, -15, 79, 32, -15, 81, Blocks.SANDSTONE.getDefaultState());
        structure.fillWithBlocks(world, start, 30, -15, 83, 32, -15, 91, Blocks.SANDSTONE.getDefaultState());
        structure.fillWithBlocks(world, start, 30, -14, 32, 33, -14, 37, Blocks.SANDSTONE.getDefaultState());
        structure.fillWithBlocks(world, start, 30, -14, 45, 32, -14, 47, Blocks.SANDSTONE.getDefaultState());
        structure.fillWithBlocks(world, start, 30, -14, 48, 30, -14, 49, Blocks.AIR.getDefaultState());
        structure.fillWithBlocks(world, start, 30, -14, 51, 33, -11, 51, Blocks.SANDSTONE.getDefaultState());
        structure.fillWithBlocks(world, start, 30, -14, 53, 31, -14, 54, Blocks.SANDSTONE.getDefaultState());
        structure.fillWithBlocks(world, start, 30, -14, 79, 33, -14, 82, Blocks.SANDSTONE.getDefaultState());
        structure.fillWithBlocks(world, start, 30, -13, 48, 32, -13, 51, Blocks.SANDSTONE.getDefaultState());
        structure.fillWithBlocks(world, start, 30, -13, 83, 33, -13, 91, Blocks.SANDSTONE.getDefaultState());
        structure.fillWithBlocks(world, start, 30, -12, 25, 30, -12, 25, Blocks.SANDSTONE.getDefaultState());
        structure.fillWithBlocks(world, start, 30, -12, 27, 31, -12, 36, Blocks.SANDSTONE.getDefaultState());
        structure.fillWithBlocks(world, start, 30, -12, 82, 30, -12, 82, Blocks.SANDSTONE.getDefaultState());
        structure.fillWithBlocks(world, start, 30, -12, 84, 31, -12, 85, Blocks.SANDSTONE.getDefaultState());
        structure.fillWithBlocks(world, start, 30, -12, 87, 32, -12, 89, Blocks.SANDSTONE.getDefaultState());
        structure.fillWithBlocks(world, start, 30, -11, 31, 30, -11, 37, Blocks.SANDSTONE.getDefaultState());
        structure.fillWithBlocks(world, start, 30, -11, 49, 33, -11, 53, Blocks.SANDSTONE.getDefaultState());
        structure.fillWithBlocks(world, start, 30, -11, 79, 30, -11, 79, Blocks.SANDSTONE.getDefaultState());
        structure.fillWithBlocks(world, start, 30, -11, 81, 31, -11, 91, Blocks.SANDSTONE.getDefaultState());
        structure.fillWithBlocks(world, start, 30, -10, 45, 32, -9, 45, Blocks.STONE_BRICKS.getDefaultState());
        structure.fillWithBlocks(world, start, 30, -9, 46, 32, -9, 50, Blocks.AIR.getDefaultState());
        structure.fillWithBlocks(world, start, 30, -9, 51, 32, -9, 51, Blocks.STONE_BRICKS.getDefaultState());
        structure.fillWithBlocks(world, start, 30, -8, 45, 30, -7, 45, Blocks.STONE_BRICKS.getDefaultState());
        structure.fillWithBlocks(world, start, 30, -8, 46, 32, -8, 50, Blocks.AIR.getDefaultState());
        structure.fillWithBlocks(world, start, 30, -8, 51, 30, -7, 51, Blocks.STONE_BRICKS.getDefaultState());
        structure.fillWithBlocks(world, start, 30, -7, 46, 32, -7, 50, Blocks.AIR.getDefaultState());
        structure.fillWithBlocks(world, start, 30, -6, 47, 33, -6, 50, Blocks.SANDSTONE.getDefaultState());
        structure.fillWithBlocks(world, start, 30, 5, 11, 32, 5, 13, Blocks.SANDSTONE.getDefaultState());
        structure.fillWithBlocks(world, start, 31, -52, 42, 32, -52, 43, Blocks.SANDSTONE.getDefaultState());
        structure.fillWithBlocks(world, start, 31, -52, 44, 31, -52, 45, Blocks.SANDSTONE_STAIRS.getDefaultState().with(StairsBlock.FACING, Direction.EAST).with(StairsBlock.WATERLOGGED, false).with(StairsBlock.SHAPE, StairsShape.STRAIGHT).with(StairsBlock.HALF, Half.BOTTOM));
        structure.fillWithBlocks(world, start, 31, -52, 46, 31, -52, 50, Blocks.SANDSTONE.getDefaultState());
        structure.fillWithBlocks(world, start, 31, -52, 51, 31, -52, 52, Blocks.SANDSTONE_STAIRS.getDefaultState().with(StairsBlock.FACING, Direction.EAST).with(StairsBlock.WATERLOGGED, false).with(StairsBlock.SHAPE, StairsShape.STRAIGHT).with(StairsBlock.HALF, Half.BOTTOM));
        structure.fillWithBlocks(world, start, 31, -52, 53, 35, -52, 57, Blocks.SANDSTONE.getDefaultState());
        structure.fillWithBlocks(world, start, 31, -51, 43, 36, -51, 43, Blocks.SANDSTONE.getDefaultState());
        structure.fillWithBlocks(world, start, 31, -51, 44, 31, -50, 45, Blocks.AIR.getDefaultState());
        structure.fillWithBlocks(world, start, 31, -51, 46, 31, -51, 50, Blocks.SANDSTONE.getDefaultState());
        structure.fillWithBlocks(world, start, 31, -51, 51, 31, -50, 52, Blocks.AIR.getDefaultState());
        structure.fillWithBlocks(world, start, 31, -51, 53, 35, -51, 57, Blocks.SANDSTONE.getDefaultState());
        structure.fillWithBlocks(world, start, 31, -50, 39, 34, -50, 42, Blocks.AIR.getDefaultState());
        structure.fillWithBlocks(world, start, 31, -50, 43, 31, -41, 43, Blocks.SANDSTONE.getDefaultState());
        structure.fillWithBlocks(world, start, 31, -50, 53, 31, -41, 53, Blocks.SANDSTONE.getDefaultState());
        structure.fillWithBlocks(world, start, 31, -50, 54, 34, -50, 57, Blocks.AIR.getDefaultState());
        structure.fillWithBlocks(world, start, 31, -50, 58, 32, -50, 59, Blocks.SANDSTONE.getDefaultState());
        structure.fillWithBlocks(world, start, 31, -49, 38, 32, -49, 42, Blocks.AIR.getDefaultState());
        structure.fillWithBlocks(world, start, 31, -49, 44, 32, -49, 45, Blocks.AIR.getDefaultState());
        structure.fillWithBlocks(world, start, 31, -49, 46, 31, -41, 46, Blocks.SANDSTONE.getDefaultState());
        structure.fillWithBlocks(world, start, 31, -49, 47, 33, -49, 49, Blocks.AIR.getDefaultState());
        structure.fillWithBlocks(world, start, 31, -49, 50, 31, -41, 50, Blocks.SANDSTONE.getDefaultState());
        structure.fillWithBlocks(world, start, 31, -49, 51, 32, -49, 52, Blocks.AIR.getDefaultState());
        structure.fillWithBlocks(world, start, 31, -49, 54, 34, -49, 57, Blocks.AIR.getDefaultState());
        structure.fillWithBlocks(world, start, 31, -49, 58, 32, -48, 58, Blocks.AIR.getDefaultState());
        structure.fillWithBlocks(world, start, 31, -49, 75, 31, -49, 76, Blocks.SHROOMLIGHT.getDefaultState());
        structure.fillWithBlocks(world, start, 31, -49, 77, 36, -49, 77, Blocks.SANDSTONE.getDefaultState());
        structure.fillWithBlocks(world, start, 31, -49, 87, 35, -49, 87, Blocks.SANDSTONE.getDefaultState());
        structure.fillWithBlocks(world, start, 31, -49, 88, 32, -49, 88, Blocks.SHROOMLIGHT.getDefaultState());
        structure.fillWithBlocks(world, start, 31, -49, 90, 33, -49, 92, Blocks.SANDSTONE.getDefaultState());
        structure.fillWithBlocks(world, start, 31, -48, 38, 32, -48, 42, Blocks.AIR.getDefaultState());
        structure.fillWithBlocks(world, start, 31, -48, 44, 32, -48, 45, Blocks.AIR.getDefaultState());
        structure.fillWithBlocks(world, start, 31, -48, 47, 33, -48, 49, Blocks.AIR.getDefaultState());
        structure.fillWithBlocks(world, start, 31, -48, 51, 32, -48, 52, Blocks.AIR.getDefaultState());
        structure.fillWithBlocks(world, start, 31, -48, 54, 34, -48, 57, Blocks.AIR.getDefaultState());
        structure.fillWithBlocks(world, start, 31, -48, 72, 33, -48, 74, Blocks.SANDSTONE.getDefaultState());
        structure.fillWithBlocks(world, start, 31, -48, 75, 31, -48, 75, Blocks.IRON_BARS.getDefaultState().with(FourWayBlock.WATERLOGGED, false).with(FourWayBlock.NORTH, true).with(FourWayBlock.SOUTH, true).with(FourWayBlock.EAST, true).with(FourWayBlock.WEST, true));
        structure.fillWithBlocks(world, start, 31, -48, 87, 31, -48, 87, Blocks.IRON_BARS.getDefaultState().with(FourWayBlock.WATERLOGGED, false).with(FourWayBlock.NORTH, true).with(FourWayBlock.SOUTH, true).with(FourWayBlock.EAST, true).with(FourWayBlock.WEST, true));
        structure.fillWithBlocks(world, start, 31, -47, 25, 31, -41, 37, Blocks.SANDSTONE.getDefaultState());
        structure.fillWithBlocks(world, start, 31, -47, 38, 32, -47, 42, Blocks.AIR.getDefaultState());
        structure.fillWithBlocks(world, start, 31, -47, 44, 32, -47, 45, Blocks.AIR.getDefaultState());
        structure.fillWithBlocks(world, start, 31, -47, 47, 33, -47, 49, Blocks.AIR.getDefaultState());
        structure.fillWithBlocks(world, start, 31, -47, 51, 32, -47, 52, Blocks.AIR.getDefaultState());
        structure.fillWithBlocks(world, start, 31, -47, 54, 34, -47, 57, Blocks.AIR.getDefaultState());
        structure.fillWithBlocks(world, start, 31, -47, 58, 32, -47, 58, Blocks.AIR.getDefaultState());
        structure.fillWithBlocks(world, start, 31, -47, 87, 31, -44, 92, Blocks.SANDSTONE.getDefaultState());
        structure.fillWithBlocks(world, start, 31, -46, 39, 31, -41, 58, Blocks.SANDSTONE.getDefaultState());
        structure.fillWithBlocks(world, start, 31, -46, 72, 35, -46, 77, Blocks.SANDSTONE.getDefaultState());
        structure.fillWithBlocks(world, start, 31, -43, 77, 37, -43, 85, Blocks.SANDSTONE.getDefaultState());
        structure.fillWithBlocks(world, start, 31, -43, 91, 34, -43, 97, Blocks.STONE_BRICKS.getDefaultState());
        structure.fillWithBlocks(world, start, 31, -42, 91, 31, -41, 91, Blocks.AIR.getDefaultState());
        structure.fillWithBlocks(world, start, 31, -42, 95, 31, -40, 95, Blocks.STONE_BRICKS.getDefaultState());
        structure.fillWithBlocks(world, start, 31, -41, 92, 32, -41, 92, Blocks.AIR.getDefaultState());
        structure.fillWithBlocks(world, start, 31, -41, 94, 31, -41, 95, Blocks.STONE_BRICKS.getDefaultState());
        structure.fillWithBlocks(world, start, 31, -40, 14, 33, -40, 29, Blocks.STONE_BRICKS.getDefaultState());
        structure.fillWithBlocks(world, start, 31, -40, 30, 32, -40, 43, Blocks.STONE_BRICKS.getDefaultState());
        structure.fillWithBlocks(world, start, 31, -39, 10, 33, -39, 14, Blocks.STONE_BRICKS.getDefaultState());
        structure.fillWithBlocks(world, start, 31, -39, 17, 32, -39, 28, Blocks.AIR.getDefaultState());
        structure.fillWithBlocks(world, start, 31, -39, 92, 33, -39, 96, Blocks.AIR.getDefaultState());
        structure.fillWithBlocks(world, start, 31, -39, 98, 31, -39, 100, Blocks.STONE_BRICKS.getDefaultState());
        structure.fillWithBlocks(world, start, 31, -38, 10, 40, -33, 10, Blocks.STONE_BRICKS.getDefaultState());
        structure.fillWithBlocks(world, start, 31, -38, 11, 32, -37, 11, Blocks.AIR.getDefaultState());
        structure.fillWithBlocks(world, start, 31, -38, 14, 31, -36, 16, Blocks.STONE_BRICKS.getDefaultState());
        structure.fillWithBlocks(world, start, 31, -38, 17, 32, -38, 28, Blocks.AIR.getDefaultState());
        structure.fillWithBlocks(world, start, 31, -38, 93, 33, -38, 96, Blocks.AIR.getDefaultState());
        structure.fillWithBlocks(world, start, 31, -38, 97, 31, -38, 97, Blocks.STONE_BRICKS.getDefaultState());
        structure.fillWithBlocks(world, start, 31, -38, 99, 32, -38, 100, Blocks.STONE_BRICKS.getDefaultState());
        structure.fillWithBlocks(world, start, 31, -37, 12, 31, -37, 12, Blocks.AIR.getDefaultState());
        structure.fillWithBlocks(world, start, 31, -36, 80, 33, -36, 82, Blocks.STONE_BRICKS.getDefaultState());
        structure.fillWithBlocks(world, start, 31, -36, 87, 32, -36, 89, Blocks.STONE_BRICKS.getDefaultState());
        structure.fillWithBlocks(world, start, 31, -36, 97, 32, -36, 98, Blocks.STONE_BRICKS.getDefaultState());
        structure.fillWithBlocks(world, start, 31, -36, 99, 31, -36, 100, Blocks.STONE_BRICKS.getDefaultState());
        structure.fillWithBlocks(world, start, 31, -35, 14, 31, -33, 16, Blocks.STONE_BRICKS.getDefaultState());
        structure.fillWithBlocks(world, start, 31, -35, 41, 32, -35, 43, Blocks.STONE_BRICKS.getDefaultState());
        structure.fillWithBlocks(world, start, 31, -35, 48, 33, -35, 51, Blocks.STONE_BRICKS.getDefaultState());
        structure.fillWithBlocks(world, start, 31, -35, 82, 37, -31, 82, Blocks.STONE_BRICKS.getDefaultState());
        structure.fillWithBlocks(world, start, 31, -35, 86, 31, -34, 87, Blocks.STONE_BRICKS.getDefaultState());
        structure.fillWithBlocks(world, start, 31, -35, 88, 31, -34, 88, Blocks.AIR.getDefaultState());
        structure.fillWithBlocks(world, start, 31, -35, 89, 34, -34, 89, Blocks.STONE_BRICKS.getDefaultState());
        structure.fillWithBlocks(world, start, 31, -35, 99, 32, -35, 100, Blocks.STONE_BRICKS.getDefaultState());
        structure.fillWithBlocks(world, start, 31, -34, 11, 31, -33, 25, Blocks.STONE_BRICKS.getDefaultState());
        structure.fillWithBlocks(world, start, 31, -34, 26, 34, -34, 30, Blocks.STONE_BRICKS.getDefaultState());
        structure.fillWithBlocks(world, start, 31, -34, 48, 31, -34, 49, Blocks.STONE_BRICKS.getDefaultState());
        structure.fillWithBlocks(world, start, 31, -34, 50, 31, -34, 50, Blocks.AIR.getDefaultState());
        structure.fillWithBlocks(world, start, 31, -34, 51, 31, -33, 51, Blocks.STONE_BRICKS.getDefaultState());
        structure.fillWithBlocks(world, start, 31, -34, 69, 33, -34, 71, Blocks.AIR.getDefaultState());
        structure.fillWithBlocks(world, start, 31, -34, 72, 31, -34, 72, Blocks.STONE_BRICKS.getDefaultState());
        structure.fillWithBlocks(world, start, 31, -34, 73, 31, -34, 74, Blocks.AIR.getDefaultState());
        structure.fillWithBlocks(world, start, 31, -34, 75, 32, -34, 78, Blocks.STONE_BRICKS.getDefaultState());
        structure.fillWithBlocks(world, start, 31, -34, 79, 31, -34, 80, Blocks.STONE_BRICKS.getDefaultState());
        structure.fillWithBlocks(world, start, 31, -34, 90, 33, -34, 100, Blocks.STONE_BRICKS.getDefaultState());
        structure.fillWithBlocks(world, start, 31, -33, 26, 31, -32, 26, Blocks.AIR.getDefaultState());
        structure.fillWithBlocks(world, start, 31, -33, 27, 31, -33, 27, Blocks.STONE_BRICKS.getDefaultState());
        structure.fillWithBlocks(world, start, 31, -33, 28, 31, -33, 29, Blocks.AIR.getDefaultState());
        structure.fillWithBlocks(world, start, 31, -33, 45, 31, -33, 47, Blocks.STONE_BRICKS.getDefaultState());
        structure.fillWithBlocks(world, start, 31, -33, 48, 32, -33, 48, Blocks.AIR.getDefaultState());
        structure.fillWithBlocks(world, start, 31, -33, 49, 32, -33, 49, Blocks.STONE_BRICKS.getDefaultState());
        structure.fillWithBlocks(world, start, 31, -33, 62, 32, -33, 67, Blocks.STONE_BRICKS.getDefaultState());
        structure.fillWithBlocks(world, start, 31, -33, 73, 33, -33, 78, Blocks.STONE_BRICKS.getDefaultState());
        structure.fillWithBlocks(world, start, 31, -33, 80, 33, -33, 82, Blocks.STONE_BRICKS.getDefaultState());
        structure.fillWithBlocks(world, start, 31, -33, 87, 31, -33, 100, Blocks.STONE_BRICKS.getDefaultState());
        structure.fillWithBlocks(world, start, 31, -32, 11, 31, -31, 11, Blocks.AIR.getDefaultState());
        structure.fillWithBlocks(world, start, 31, -32, 12, 32, -32, 13, Blocks.STONE_BRICKS.getDefaultState());
        structure.fillWithBlocks(world, start, 31, -32, 15, 31, -32, 15, Blocks.STONE_BRICKS.getDefaultState());
        structure.fillWithBlocks(world, start, 31, -32, 17, 31, -32, 17, Blocks.STONE_BRICKS.getDefaultState());
        structure.fillWithBlocks(world, start, 31, -32, 18, 31, -32, 19, Blocks.AIR.getDefaultState());
        structure.fillWithBlocks(world, start, 31, -32, 20, 33, -32, 22, Blocks.STONE_BRICKS.getDefaultState());
        structure.fillWithBlocks(world, start, 31, -32, 23, 31, -32, 23, Blocks.STONE_BRICKS.getDefaultState());
        structure.fillWithBlocks(world, start, 31, -32, 25, 31, -32, 25, Blocks.STONE_BRICKS.getDefaultState());
        structure.fillWithBlocks(world, start, 31, -32, 27, 31, -32, 27, Blocks.STONE_BRICKS.getDefaultState());
        structure.fillWithBlocks(world, start, 31, -32, 28, 31, -31, 28, Blocks.AIR.getDefaultState());
        structure.fillWithBlocks(world, start, 31, -32, 29, 32, -32, 30, Blocks.STONE_BRICKS.getDefaultState());
        structure.fillWithBlocks(world, start, 31, -32, 44, 31, -32, 44, Blocks.STONE_BRICKS.getDefaultState());
        structure.fillWithBlocks(world, start, 31, -32, 45, 31, -32, 45, Blocks.AIR.getDefaultState());
        structure.fillWithBlocks(world, start, 31, -32, 46, 31, -31, 46, Blocks.STONE_BRICKS.getDefaultState());
        structure.fillWithBlocks(world, start, 31, -32, 48, 31, -32, 49, Blocks.STONE_BRICKS.getDefaultState());
        structure.fillWithBlocks(world, start, 31, -32, 50, 31, -32, 51, Blocks.AIR.getDefaultState());
        structure.fillWithBlocks(world, start, 31, -32, 52, 31, -32, 55, Blocks.STONE_BRICKS.getDefaultState());
        structure.fillWithBlocks(world, start, 31, -32, 64, 37, -31, 64, Blocks.STONE_BRICKS.getDefaultState());
        structure.fillWithBlocks(world, start, 31, -32, 65, 32, -32, 65, Blocks.AIR.getDefaultState());
        structure.fillWithBlocks(world, start, 31, -32, 66, 33, -32, 69, Blocks.STONE_BRICKS.getDefaultState());
        structure.fillWithBlocks(world, start, 31, -32, 78, 31, -31, 79, Blocks.STONE_BRICKS.getDefaultState());
        structure.fillWithBlocks(world, start, 31, -32, 81, 32, -32, 82, Blocks.STONE_BRICKS.getDefaultState());
        structure.fillWithBlocks(world, start, 31, -32, 86, 49, -31, 86, Blocks.STONE_BRICKS.getDefaultState());
        structure.fillWithBlocks(world, start, 31, -32, 87, 32, -32, 87, Blocks.AIR.getDefaultState());
        structure.fillWithBlocks(world, start, 31, -32, 88, 33, -32, 90, Blocks.STONE_BRICKS.getDefaultState());
        structure.fillWithBlocks(world, start, 31, -32, 92, 32, -32, 100, Blocks.STONE_BRICKS.getDefaultState());
        structure.fillWithBlocks(world, start, 31, -31, 10, 31, -31, 10, Blocks.STONE_BRICKS.getDefaultState());
        structure.fillWithBlocks(world, start, 31, -31, 12, 31, -31, 12, Blocks.STONE_BRICKS.getDefaultState());
        structure.fillWithBlocks(world, start, 31, -31, 14, 31, -30, 14, Blocks.SANDSTONE.getDefaultState());
        structure.fillWithBlocks(world, start, 31, -31, 15, 33, -31, 17, Blocks.STONE_BRICKS.getDefaultState());
        structure.fillWithBlocks(world, start, 31, -31, 29, 32, -31, 30, Blocks.STONE_BRICKS.getDefaultState());
        structure.fillWithBlocks(world, start, 31, -31, 41, 33, -31, 44, Blocks.STONE_BRICKS.getDefaultState());
        structure.fillWithBlocks(world, start, 31, -31, 47, 31, -31, 47, Blocks.SANDSTONE.getDefaultState());
        structure.fillWithBlocks(world, start, 31, -31, 50, 40, -31, 50, Blocks.STONE_BRICKS.getDefaultState());
        structure.fillWithBlocks(world, start, 31, -31, 52, 34, -31, 55, Blocks.STONE_BRICKS.getDefaultState());
        structure.fillWithBlocks(world, start, 31, -31, 58, 33, -31, 61, Blocks.STONE_BRICKS.getDefaultState());
        structure.fillWithBlocks(world, start, 31, -31, 62, 32, -31, 65, Blocks.STONE_BRICKS.getDefaultState());
        structure.fillWithBlocks(world, start, 31, -31, 74, 31, -31, 82, Blocks.STONE_BRICKS.getDefaultState());
        structure.fillWithBlocks(world, start, 31, -30, 4, 31, -28, 4, Blocks.STONE_BRICKS.getDefaultState());
        structure.fillWithBlocks(world, start, 31, -30, 6, 32, -30, 7, Blocks.STONE_BRICKS.getDefaultState());
        structure.fillWithBlocks(world, start, 31, -30, 34, 31, -30, 35, Blocks.SANDSTONE.getDefaultState());
        structure.fillWithBlocks(world, start, 31, -30, 45, 31, -30, 47, Blocks.DIRT.getDefaultState());
        structure.fillWithBlocks(world, start, 31, -30, 48, 31, -30, 48, Blocks.SANDSTONE.getDefaultState());
        structure.fillWithBlocks(world, start, 31, -30, 50, 31, -15, 50, Blocks.SANDSTONE.getDefaultState());
        structure.fillWithBlocks(world, start, 31, -30, 58, 35, -30, 73, Blocks.SANDSTONE.getDefaultState());
        structure.fillWithBlocks(world, start, 31, -30, 74, 32, -30, 74, Blocks.DIRT.getDefaultState());
        structure.fillWithBlocks(world, start, 31, -30, 75, 33, -30, 75, Blocks.SANDSTONE.getDefaultState());
        structure.fillWithBlocks(world, start, 31, -29, 5, 32, -29, 6, Blocks.STONE_BRICKS.getDefaultState());
        structure.fillWithBlocks(world, start, 31, -29, 7, 32, -29, 7, Blocks.SANDSTONE.getDefaultState());
        structure.fillWithBlocks(world, start, 31, -29, 24, 32, -28, 24, Blocks.SANDSTONE.getDefaultState());
        structure.fillWithBlocks(world, start, 31, -29, 27, 31, -29, 28, Blocks.SANDSTONE.getDefaultState());
        structure.fillWithBlocks(world, start, 31, -29, 34, 32, -29, 34, Blocks.SANDSTONE.getDefaultState());
        structure.fillWithBlocks(world, start, 31, -29, 42, 31, -29, 53, Blocks.SANDSTONE.getDefaultState());
        structure.fillWithBlocks(world, start, 31, -29, 55, 33, -29, 57, Blocks.SANDSTONE.getDefaultState());
        structure.fillWithBlocks(world, start, 31, -29, 58, 32, -29, 72, Blocks.AIR.getDefaultState());
        structure.fillWithBlocks(world, start, 31, -28, 7, 31, -25, 7, Blocks.SANDSTONE.getDefaultState());
        structure.fillWithBlocks(world, start, 31, -28, 21, 31, -28, 24, Blocks.SANDSTONE.getDefaultState());
        structure.fillWithBlocks(world, start, 31, -28, 27, 31, -22, 27, Blocks.SANDSTONE.getDefaultState());
        structure.fillWithBlocks(world, start, 31, -28, 35, 31, -26, 35, Blocks.SANDSTONE.getDefaultState());
        structure.fillWithBlocks(world, start, 31, -28, 46, 31, -27, 47, Blocks.SANDSTONE.getDefaultState());
        structure.fillWithBlocks(world, start, 31, -28, 49, 32, -28, 56, Blocks.SANDSTONE.getDefaultState());
        structure.fillWithBlocks(world, start, 31, -28, 57, 31, -25, 57, Blocks.SANDSTONE.getDefaultState());
        structure.fillWithBlocks(world, start, 31, -28, 58, 35, -28, 72, Blocks.AIR.getDefaultState());
        structure.fillWithBlocks(world, start, 31, -28, 75, 32, -27, 75, Blocks.SANDSTONE.getDefaultState());
        structure.fillWithBlocks(world, start, 31, -27, 4, 31, -27, 4, Blocks.SANDSTONE.getDefaultState());
        structure.fillWithBlocks(world, start, 31, -27, 5, 31, -25, 5, Blocks.STONE_BRICKS.getDefaultState());
        structure.fillWithBlocks(world, start, 31, -27, 6, 31, -27, 7, Blocks.SANDSTONE.getDefaultState());
        structure.fillWithBlocks(world, start, 31, -27, 28, 32, -27, 28, Blocks.SANDSTONE.getDefaultState());
        structure.fillWithBlocks(world, start, 31, -27, 34, 31, -26, 35, Blocks.SANDSTONE.getDefaultState());
        structure.fillWithBlocks(world, start, 31, -27, 42, 32, -27, 53, Blocks.SANDSTONE.getDefaultState());
        structure.fillWithBlocks(world, start, 31, -27, 54, 31, -26, 54, Blocks.AIR.getDefaultState());
        structure.fillWithBlocks(world, start, 31, -27, 55, 31, -27, 56, Blocks.DIRT.getDefaultState());
        structure.fillWithBlocks(world, start, 31, -27, 58, 35, -27, 72, Blocks.AIR.getDefaultState());
        structure.fillWithBlocks(world, start, 31, -27, 73, 31, -27, 75, Blocks.SANDSTONE.getDefaultState());
        structure.fillWithBlocks(world, start, 31, -26, 21, 31, -26, 24, Blocks.SANDSTONE.getDefaultState());
        structure.fillWithBlocks(world, start, 31, -26, 43, 31, -22, 47, Blocks.SANDSTONE.getDefaultState());
        structure.fillWithBlocks(world, start, 31, -26, 48, 32, -26, 53, Blocks.SANDSTONE.getDefaultState());
        structure.fillWithBlocks(world, start, 31, -26, 55, 32, -26, 56, Blocks.SANDSTONE.getDefaultState());
        structure.fillWithBlocks(world, start, 31, -26, 58, 35, -26, 72, Blocks.AIR.getDefaultState());
        structure.fillWithBlocks(world, start, 31, -26, 73, 31, -21, 73, Blocks.SANDSTONE.getDefaultState());
        structure.fillWithBlocks(world, start, 31, -25, 6, 32, -25, 6, Blocks.STONE_BRICKS.getDefaultState());
        structure.fillWithBlocks(world, start, 31, -25, 12, 34, -25, 12, Blocks.SANDSTONE.getDefaultState());
        structure.fillWithBlocks(world, start, 31, -25, 13, 32, -25, 15, Blocks.AIR.getDefaultState());
        structure.fillWithBlocks(world, start, 31, -25, 16, 34, -25, 16, Blocks.SANDSTONE.getDefaultState());
        structure.fillWithBlocks(world, start, 31, -25, 17, 33, -25, 19, Blocks.AIR.getDefaultState());
        structure.fillWithBlocks(world, start, 31, -25, 22, 31, -25, 22, Blocks.DIRT.getDefaultState());
        structure.fillWithBlocks(world, start, 31, -25, 23, 31, -21, 23, Blocks.SANDSTONE.getDefaultState());
        structure.fillWithBlocks(world, start, 31, -25, 33, 31, -25, 34, Blocks.SANDSTONE.getDefaultState());
        structure.fillWithBlocks(world, start, 31, -25, 48, 32, -25, 57, Blocks.SANDSTONE.getDefaultState());
        structure.fillWithBlocks(world, start, 31, -25, 58, 35, -25, 72, Blocks.AIR.getDefaultState());
        structure.fillWithBlocks(world, start, 31, -25, 74, 32, -25, 75, Blocks.SANDSTONE.getDefaultState());
        structure.fillWithBlocks(world, start, 31, -24, 4, 31, -22, 4, Blocks.STONE_BRICKS.getDefaultState());
        structure.fillWithBlocks(world, start, 31, -24, 8, 32, -24, 9, Blocks.SANDSTONE.getDefaultState());
        structure.fillWithBlocks(world, start, 31, -24, 11, 33, -24, 11, Blocks.SANDSTONE.getDefaultState());
        structure.fillWithBlocks(world, start, 31, -24, 12, 37, -24, 12, Blocks.STONE_BRICKS.getDefaultState());
        structure.fillWithBlocks(world, start, 31, -24, 13, 31, -24, 13, Blocks.SANDSTONE.getDefaultState());
        structure.fillWithBlocks(world, start, 31, -24, 15, 31, -24, 17, Blocks.SANDSTONE.getDefaultState());
        structure.fillWithBlocks(world, start, 31, -24, 19, 32, -24, 24, Blocks.SANDSTONE.getDefaultState());
        structure.fillWithBlocks(world, start, 31, -24, 31, 31, -23, 32, Blocks.SANDSTONE.getDefaultState());
        structure.fillWithBlocks(world, start, 31, -24, 48, 32, -24, 52, Blocks.SANDSTONE.getDefaultState());
        structure.fillWithBlocks(world, start, 31, -24, 60, 35, -24, 74, Blocks.SANDSTONE.getDefaultState());
        structure.fillWithBlocks(world, start, 31, -23, 11, 31, -23, 12, Blocks.SANDSTONE.getDefaultState());
        structure.fillWithBlocks(world, start, 31, -23, 15, 32, -23, 16, Blocks.STONE_BRICKS.getDefaultState());
        structure.fillWithBlocks(world, start, 31, -23, 19, 33, -23, 21, Blocks.SANDSTONE.getDefaultState());
        structure.fillWithBlocks(world, start, 31, -23, 22, 31, -23, 24, Blocks.SANDSTONE.getDefaultState());
        structure.fillWithBlocks(world, start, 31, -23, 29, 31, -22, 30, Blocks.SANDSTONE.getDefaultState());
        structure.fillWithBlocks(world, start, 31, -23, 48, 33, -23, 50, Blocks.SANDSTONE.getDefaultState());
        structure.fillWithBlocks(world, start, 31, -23, 58, 31, -22, 59, Blocks.SANDSTONE.getDefaultState());
        structure.fillWithBlocks(world, start, 31, -23, 60, 32, -23, 60, Blocks.AIR.getDefaultState());
        structure.fillWithBlocks(world, start, 31, -23, 61, 32, -23, 62, Blocks.SANDSTONE.getDefaultState());
        structure.fillWithBlocks(world, start, 31, -23, 63, 31, -23, 64, Blocks.SANDSTONE.getDefaultState());
        structure.fillWithBlocks(world, start, 31, -23, 68, 31, -23, 68, Blocks.SANDSTONE.getDefaultState());
        structure.fillWithBlocks(world, start, 31, -23, 69, 31, -23, 70, Blocks.AIR.getDefaultState());
        structure.fillWithBlocks(world, start, 31, -23, 71, 33, -23, 73, Blocks.SANDSTONE.getDefaultState());
        structure.fillWithBlocks(world, start, 31, -23, 74, 31, -23, 74, Blocks.AIR.getDefaultState());
        structure.fillWithBlocks(world, start, 31, -22, 5, 32, -22, 6, Blocks.STONE_BRICKS.getDefaultState());
        structure.fillWithBlocks(world, start, 31, -22, 8, 32, -22, 9, Blocks.STONE_BRICKS.getDefaultState());
        structure.fillWithBlocks(world, start, 31, -22, 16, 32, -22, 16, Blocks.SANDSTONE.getDefaultState());
        structure.fillWithBlocks(world, start, 31, -22, 17, 31, -21, 17, Blocks.DIRT.getDefaultState());
        structure.fillWithBlocks(world, start, 31, -22, 18, 31, -21, 18, Blocks.STONE_BRICKS.getDefaultState());
        structure.fillWithBlocks(world, start, 31, -22, 19, 31, -22, 21, Blocks.SANDSTONE.getDefaultState());
        structure.fillWithBlocks(world, start, 31, -22, 32, 31, -20, 35, Blocks.SANDSTONE.getDefaultState());
        structure.fillWithBlocks(world, start, 31, -22, 48, 32, -22, 48, Blocks.SHROOMLIGHT.getDefaultState());
        structure.fillWithBlocks(world, start, 31, -22, 49, 31, -22, 60, Blocks.SANDSTONE.getDefaultState());
        structure.fillWithBlocks(world, start, 31, -22, 62, 33, -22, 67, Blocks.SANDSTONE.getDefaultState());
        structure.fillWithBlocks(world, start, 31, -22, 69, 32, -22, 71, Blocks.SANDSTONE.getDefaultState());
        structure.fillWithBlocks(world, start, 31, -21, 6, 31, -21, 7, Blocks.DIRT.getDefaultState());
        structure.fillWithBlocks(world, start, 31, -21, 8, 31, -21, 9, Blocks.STONE_BRICKS.getDefaultState());
        structure.fillWithBlocks(world, start, 31, -21, 12, 33, -21, 14, Blocks.STONE_BRICKS.getDefaultState());
        structure.fillWithBlocks(world, start, 31, -21, 15, 31, -21, 16, Blocks.STONE_BRICKS.getDefaultState());
        structure.fillWithBlocks(world, start, 31, -21, 20, 33, -21, 24, Blocks.SANDSTONE.getDefaultState());
        structure.fillWithBlocks(world, start, 31, -21, 29, 31, -21, 30, Blocks.DIRT.getDefaultState());
