package mod.arcalitegames.odyssey.world.structure.structures.dungeons.shrine;

import mod.arcalitegames.odyssey.world.structure.StructureBase;
import net.minecraft.block.Blocks;
import net.minecraft.block.CactusBlock;
import net.minecraft.block.FourWayBlock;
import net.minecraft.block.RedstoneWireBlock;
import net.minecraft.block.StairsBlock;
import net.minecraft.state.properties.Half;
import net.minecraft.state.properties.RedstoneSide;
import net.minecraft.state.properties.StairsShape;
import net.minecraft.util.Direction;
import net.minecraft.util.math.BlockPos;
import net.minecraft.world.World;

public class ShrineComponent1
{

	public static BlockPos start;
    public static World world;
    public static StructureBase structure;

    public static void init(World worldIn, BlockPos blockPos, StructureBase structureIn)
    {
        world = worldIn; start = blockPos; structure = structureIn;
    }
    
    public static void generatePart11()
    {
        structure.fillWithBlocks(world, start, -12, -22, 67, -11, -22, 67, Blocks.DIRT.getDefaultState());
        structure.fillWithBlocks(world, start, -12, -22, 68, -12, -22, 69, Blocks.SANDSTONE.getDefaultState());
        structure.fillWithBlocks(world, start, -12, -22, 70, -11, -22, 70, Blocks.DIRT.getDefaultState());
        structure.fillWithBlocks(world, start, -12, -22, 71, -11, -22, 72, Blocks.SANDSTONE.getDefaultState());
        structure.fillWithBlocks(world, start, -12, -22, 73, -12, -22, 75, Blocks.SANDSTONE.getDefaultState());
        structure.fillWithBlocks(world, start, -12, -21, 4, -12, -21, 5, Blocks.STONE_BRICKS.getDefaultState());
        structure.fillWithBlocks(world, start, -12, -21, 6, -11, -21, 6, Blocks.SANDSTONE.getDefaultState());
        structure.fillWithBlocks(world, start, -12, -21, 9, -12, -21, 11, Blocks.STONE_BRICKS.getDefaultState());
        structure.fillWithBlocks(world, start, -12, -21, 14, -12, -21, 14, Blocks.STONE_BRICKS.getDefaultState());
        structure.fillWithBlocks(world, start, -12, -21, 15, -12, -21, 16, Blocks.SANDSTONE.getDefaultState());
        structure.fillWithBlocks(world, start, -12, -21, 18, -11, -21, 18, Blocks.STONE_BRICKS.getDefaultState());
        structure.fillWithBlocks(world, start, -12, -21, 19, -11, -21, 26, Blocks.SANDSTONE.getDefaultState());
        structure.fillWithBlocks(world, start, -12, -21, 27, -12, -21, 32, Blocks.SANDSTONE.getDefaultState());
        structure.fillWithBlocks(world, start, -12, -21, 34, -12, -21, 39, Blocks.SANDSTONE.getDefaultState());
        structure.fillWithBlocks(world, start, -12, -21, 41, -12, -21, 44, Blocks.SANDSTONE.getDefaultState());
        structure.fillWithBlocks(world, start, -12, -21, 46, -11, -21, 47, Blocks.SANDSTONE.getDefaultState());
        structure.fillWithBlocks(world, start, -12, -21, 48, -12, -21, 59, Blocks.SANDSTONE.getDefaultState());
        structure.fillWithBlocks(world, start, -12, -21, 61, -12, -21, 72, Blocks.SANDSTONE.getDefaultState());
        structure.fillWithBlocks(world, start, -12, -21, 73, -11, -21, 73, Blocks.AIR.getDefaultState());
        structure.fillWithBlocks(world, start, -12, -21, 74, -4, -21, 74, Blocks.SANDSTONE.getDefaultState());
        structure.fillWithBlocks(world, start, -12, -21, 75, -11, -21, 75, Blocks.AIR.getDefaultState());
        structure.fillWithBlocks(world, start, -12, -19, 49, -10, -19, 51, Blocks.AIR.getDefaultState());
        structure.fillWithBlocks(world, start, -12, -18, 43, -11, -18, 44, Blocks.SANDSTONE.getDefaultState());
        structure.fillWithBlocks(world, start, -12, -18, 49, -10, -18, 51, Blocks.AIR.getDefaultState());
        structure.fillWithBlocks(world, start, -12, -14, 49, -10, -14, 51, Blocks.SANDSTONE.getDefaultState());
        structure.fillWithBlocks(world, start, -12, -14, 53, -11, -14, 54, Blocks.SANDSTONE.getDefaultState());
        structure.fillWithBlocks(world, start, -12, -13, 51, -9, -13, 54, Blocks.SANDSTONE.getDefaultState());
        structure.fillWithBlocks(world, start, -11, -49, 46, -9, -49, 50, Blocks.AIR.getDefaultState());
        structure.fillWithBlocks(world, start, -11, -44, 42, -11, -44, 42, Blocks.SANDSTONE.getDefaultState());
        structure.fillWithBlocks(world, start, -11, -44, 44, -8, -44, 47, Blocks.SANDSTONE.getDefaultState());
        structure.fillWithBlocks(world, start, -11, -44, 49, -8, -44, 52, Blocks.SANDSTONE.getDefaultState());
        structure.fillWithBlocks(world, start, -11, -44, 54, -9, -44, 56, Blocks.SANDSTONE.getDefaultState());
        structure.fillWithBlocks(world, start, -11, -41, 55, -10, -41, 56, Blocks.SANDSTONE.getDefaultState());
        structure.fillWithBlocks(world, start, -11, -40, 36, -8, -40, 41, Blocks.STONE_BRICKS.getDefaultState());
        structure.fillWithBlocks(world, start, -11, -40, 55, -11, -40, 55, Blocks.STONE_BRICKS.getDefaultState());
        structure.fillWithBlocks(world, start, -11, -40, 57, -9, -40, 60, Blocks.STONE_BRICKS.getDefaultState());
        structure.fillWithBlocks(world, start, -11, -39, 36, -10, -39, 40, Blocks.STONE_BRICKS.getDefaultState());
        structure.fillWithBlocks(world, start, -11, -39, 56, -11, -37, 60, Blocks.STONE_BRICKS.getDefaultState());
        structure.fillWithBlocks(world, start, -11, -38, 36, -9, -38, 38, Blocks.STONE_BRICKS.getDefaultState());
        structure.fillWithBlocks(world, start, -11, -38, 39, -11, -38, 40, Blocks.STONE_BRICKS.getDefaultState());
        structure.fillWithBlocks(world, start, -11, -37, 36, -8, -37, 40, Blocks.STONE_BRICKS.getDefaultState());
        structure.fillWithBlocks(world, start, -11, -36, 36, -9, -36, 38, Blocks.STONE_BRICKS.getDefaultState());
        structure.fillWithBlocks(world, start, -11, -36, 39, -10, -36, 40, Blocks.STONE_BRICKS.getDefaultState());
        structure.fillWithBlocks(world, start, -11, -36, 57, -8, -36, 60, Blocks.STONE_BRICKS.getDefaultState());
        structure.fillWithBlocks(world, start, -11, -35, 36, -10, -35, 41, Blocks.STONE_BRICKS.getDefaultState());
        structure.fillWithBlocks(world, start, -11, -35, 55, -2, -35, 55, Blocks.STONE_BRICKS.getDefaultState());
        structure.fillWithBlocks(world, start, -11, -35, 56, -10, -35, 56, Blocks.AIR.getDefaultState());
        structure.fillWithBlocks(world, start, -11, -35, 57, -9, -35, 60, Blocks.STONE_BRICKS.getDefaultState());
        structure.fillWithBlocks(world, start, -11, -34, 36, -10, -34, 37, Blocks.STONE_BRICKS.getDefaultState());
        structure.fillWithBlocks(world, start, -11, -34, 38, -11, -34, 60, Blocks.STONE_BRICKS.getDefaultState());
        structure.fillWithBlocks(world, start, -11, -33, 36, -9, -33, 38, Blocks.STONE_BRICKS.getDefaultState());
        structure.fillWithBlocks(world, start, -11, -33, 39, -11, -31, 39, Blocks.STONE_BRICKS.getDefaultState());
        structure.fillWithBlocks(world, start, -11, -33, 41, -8, -33, 44, Blocks.STONE_BRICKS.getDefaultState());
        structure.fillWithBlocks(world, start, -11, -33, 50, -9, -33, 53, Blocks.STONE_BRICKS.getDefaultState());
        structure.fillWithBlocks(world, start, -11, -33, 57, -11, -33, 60, Blocks.STONE_BRICKS.getDefaultState());
        structure.fillWithBlocks(world, start, -11, -32, 36, -8, -32, 39, Blocks.STONE_BRICKS.getDefaultState());
        structure.fillWithBlocks(world, start, -11, -32, 40, -11, -32, 44, Blocks.STONE_BRICKS.getDefaultState());
        structure.fillWithBlocks(world, start, -11, -32, 45, -11, -32, 45, Blocks.AIR.getDefaultState());
        structure.fillWithBlocks(world, start, -11, -32, 46, -11, -32, 54, Blocks.STONE_BRICKS.getDefaultState());
        structure.fillWithBlocks(world, start, -11, -32, 56, -9, -32, 60, Blocks.STONE_BRICKS.getDefaultState());
        structure.fillWithBlocks(world, start, -11, -31, 36, -10, -31, 37, Blocks.STONE_BRICKS.getDefaultState());
        structure.fillWithBlocks(world, start, -11, -31, 38, -11, -31, 60, Blocks.STONE_BRICKS.getDefaultState());
        structure.fillWithBlocks(world, start, -11, -30, 4, -11, -30, 6, Blocks.AIR.getDefaultState());
        structure.fillWithBlocks(world, start, -11, -30, 8, -11, -30, 9, Blocks.DIRT.getDefaultState());
        structure.fillWithBlocks(world, start, -11, -30, 10, -10, -30, 13, Blocks.SANDSTONE.getDefaultState());
        structure.fillWithBlocks(world, start, -11, -30, 15, -5, -30, 27, Blocks.SANDSTONE.getDefaultState());
        structure.fillWithBlocks(world, start, -11, -30, 28, -11, -30, 30, Blocks.SANDSTONE.getDefaultState());
        structure.fillWithBlocks(world, start, -11, -30, 31, -11, -30, 32, Blocks.AIR.getDefaultState());
        structure.fillWithBlocks(world, start, -11, -30, 33, -11, -30, 46, Blocks.SANDSTONE.getDefaultState());
        structure.fillWithBlocks(world, start, -11, -30, 49, -11, -30, 49, Blocks.SANDSTONE.getDefaultState());
        structure.fillWithBlocks(world, start, -11, -30, 50, -11, -30, 50, Blocks.DIRT.getDefaultState());
        structure.fillWithBlocks(world, start, -11, -30, 51, -11, -20, 51, Blocks.SANDSTONE.getDefaultState());
        structure.fillWithBlocks(world, start, -11, -30, 52, -11, -29, 52, Blocks.AIR.getDefaultState());
        structure.fillWithBlocks(world, start, -11, -30, 54, -11, -29, 56, Blocks.SANDSTONE.getDefaultState());
        structure.fillWithBlocks(world, start, -11, -30, 57, -11, -30, 57, Blocks.SANDSTONE.getDefaultState());
        structure.fillWithBlocks(world, start, -11, -30, 59, -10, -30, 60, Blocks.SANDSTONE.getDefaultState());
        structure.fillWithBlocks(world, start, -11, -30, 61, -11, -29, 61, Blocks.AIR.getDefaultState());
        structure.fillWithBlocks(world, start, -11, -30, 64, -8, -30, 67, Blocks.SANDSTONE.getDefaultState());
        structure.fillWithBlocks(world, start, -11, -30, 68, -11, -30, 69, Blocks.AIR.getDefaultState());
        structure.fillWithBlocks(world, start, -11, -30, 71, -11, -30, 71, Blocks.AIR.getDefaultState());
        structure.fillWithBlocks(world, start, -11, -30, 73, -11, -29, 73, Blocks.DIRT.getDefaultState());
        structure.fillWithBlocks(world, start, -11, -30, 74, -11, -30, 75, Blocks.SANDSTONE.getDefaultState());
        structure.fillWithBlocks(world, start, -11, -29, 4, -10, -28, 4, Blocks.SANDSTONE.getDefaultState());
        structure.fillWithBlocks(world, start, -11, -29, 6, -11, -29, 6, Blocks.STONE_BRICKS.getDefaultState());
        structure.fillWithBlocks(world, start, -11, -29, 8, -11, -29, 11, Blocks.STONE_BRICKS.getDefaultState());
        structure.fillWithBlocks(world, start, -11, -29, 12, -11, -29, 17, Blocks.SANDSTONE.getDefaultState());
        structure.fillWithBlocks(world, start, -11, -29, 24, -11, -27, 24, Blocks.IRON_BARS.getDefaultState().with(FourWayBlock.WATERLOGGED, false).with(FourWayBlock.NORTH, true).with(FourWayBlock.SOUTH, true).with(FourWayBlock.EAST, true).with(FourWayBlock.WEST, true));
        structure.fillWithBlocks(world, start, -11, -29, 25, -11, -29, 25, Blocks.AIR.getDefaultState());
        structure.fillWithBlocks(world, start, -11, -29, 26, -11, -27, 26, Blocks.IRON_BARS.getDefaultState().with(FourWayBlock.WATERLOGGED, false).with(FourWayBlock.NORTH, true).with(FourWayBlock.SOUTH, true).with(FourWayBlock.EAST, true).with(FourWayBlock.WEST, true));
        structure.fillWithBlocks(world, start, -11, -29, 27, -11, -29, 33, Blocks.SANDSTONE.getDefaultState());
        structure.fillWithBlocks(world, start, -11, -29, 34, -11, -29, 34, Blocks.AIR.getDefaultState());
        structure.fillWithBlocks(world, start, -11, -29, 35, -11, -25, 35, Blocks.SANDSTONE.getDefaultState());
        structure.fillWithBlocks(world, start, -11, -29, 36, -11, -27, 36, Blocks.IRON_BARS.getDefaultState().with(FourWayBlock.WATERLOGGED, false).with(FourWayBlock.NORTH, true).with(FourWayBlock.SOUTH, true).with(FourWayBlock.EAST, true).with(FourWayBlock.WEST, true));
        structure.fillWithBlocks(world, start, -11, -29, 37, -11, -29, 37, Blocks.AIR.getDefaultState());
        structure.fillWithBlocks(world, start, -11, -29, 38, -11, -27, 38, Blocks.IRON_BARS.getDefaultState().with(FourWayBlock.WATERLOGGED, false).with(FourWayBlock.NORTH, true).with(FourWayBlock.SOUTH, true).with(FourWayBlock.EAST, true).with(FourWayBlock.WEST, true));
        structure.fillWithBlocks(world, start, -11, -29, 53, -9, -29, 55, Blocks.SANDSTONE.getDefaultState());
        structure.fillWithBlocks(world, start, -11, -29, 58, -11, -29, 60, Blocks.SANDSTONE.getDefaultState());
        structure.fillWithBlocks(world, start, -11, -29, 69, -10, -29, 70, Blocks.SANDSTONE.getDefaultState());
        structure.fillWithBlocks(world, start, -11, -29, 71, -11, -29, 72, Blocks.SANDSTONE.getDefaultState());
        structure.fillWithBlocks(world, start, -11, -29, 74, -11, -29, 74, Blocks.SANDSTONE.getDefaultState());
        structure.fillWithBlocks(world, start, -11, -28, 8, -10, -28, 10, Blocks.STONE_BRICKS.getDefaultState());
        structure.fillWithBlocks(world, start, -11, -28, 11, -10, -28, 11, Blocks.SANDSTONE.getDefaultState());
        structure.fillWithBlocks(world, start, -11, -28, 13, -11, -25, 13, Blocks.SANDSTONE.getDefaultState());
        structure.fillWithBlocks(world, start, -11, -28, 25, -11, -28, 25, Blocks.AIR.getDefaultState());
        structure.fillWithBlocks(world, start, -11, -28, 32, -11, -25, 35, Blocks.SANDSTONE.getDefaultState());
        structure.fillWithBlocks(world, start, -11, -28, 37, -11, -28, 37, Blocks.AIR.getDefaultState());
        structure.fillWithBlocks(world, start, -11, -28, 53, -11, -28, 53, Blocks.AIR.getDefaultState());
        structure.fillWithBlocks(world, start, -11, -28, 54, -11, -27, 54, Blocks.SANDSTONE.getDefaultState());
        structure.fillWithBlocks(world, start, -11, -28, 55, -11, -28, 56, Blocks.AIR.getDefaultState());
        structure.fillWithBlocks(world, start, -11, -28, 57, -11, -28, 57, Blocks.SANDSTONE.getDefaultState());
        structure.fillWithBlocks(world, start, -11, -28, 58, -11, -28, 59, Blocks.AIR.getDefaultState());
        structure.fillWithBlocks(world, start, -11, -28, 60, -10, -28, 61, Blocks.SANDSTONE.getDefaultState());
        structure.fillWithBlocks(world, start, -11, -28, 64, -11, -22, 64, Blocks.SANDSTONE.getDefaultState());
        structure.fillWithBlocks(world, start, -11, -28, 66, -11, -23, 66, Blocks.SANDSTONE.getDefaultState());
        structure.fillWithBlocks(world, start, -11, -28, 68, -10, -28, 68, Blocks.SANDSTONE.getDefaultState());
        structure.fillWithBlocks(world, start, -11, -28, 69, -11, -28, 70, Blocks.AIR.getDefaultState());
        structure.fillWithBlocks(world, start, -11, -28, 71, -10, -28, 73, Blocks.SANDSTONE.getDefaultState());
        structure.fillWithBlocks(world, start, -11, -28, 74, -11, -28, 75, Blocks.AIR.getDefaultState());
        structure.fillWithBlocks(world, start, -11, -27, 6, -11, -27, 8, Blocks.STONE_BRICKS.getDefaultState());
        structure.fillWithBlocks(world, start, -11, -27, 10, -11, -27, 11, Blocks.STONE_BRICKS.getDefaultState());
        structure.fillWithBlocks(world, start, -11, -27, 12, -11, -27, 17, Blocks.SANDSTONE.getDefaultState());
        structure.fillWithBlocks(world, start, -11, -27, 25, -11, -27, 26, Blocks.IRON_BARS.getDefaultState().with(FourWayBlock.WATERLOGGED, false).with(FourWayBlock.NORTH, true).with(FourWayBlock.SOUTH, true).with(FourWayBlock.EAST, true).with(FourWayBlock.WEST, true));
        structure.fillWithBlocks(world, start, -11, -27, 27, -11, -27, 35, Blocks.SANDSTONE.getDefaultState());
        structure.fillWithBlocks(world, start, -11, -27, 37, -11, -27, 38, Blocks.IRON_BARS.getDefaultState().with(FourWayBlock.WATERLOGGED, false).with(FourWayBlock.NORTH, true).with(FourWayBlock.SOUTH, true).with(FourWayBlock.EAST, true).with(FourWayBlock.WEST, true));
        structure.fillWithBlocks(world, start, -11, -27, 46, -11, -27, 54, Blocks.SANDSTONE.getDefaultState());
        structure.fillWithBlocks(world, start, -11, -27, 56, -10, -27, 57, Blocks.SANDSTONE.getDefaultState());
        structure.fillWithBlocks(world, start, -11, -27, 58, -11, -27, 60, Blocks.SANDSTONE.getDefaultState());
        structure.fillWithBlocks(world, start, -11, -27, 62, -11, -27, 67, Blocks.SANDSTONE.getDefaultState());
        structure.fillWithBlocks(world, start, -11, -27, 68, -11, -27, 68, Blocks.DIRT.getDefaultState());
        structure.fillWithBlocks(world, start, -11, -27, 69, -11, -27, 70, Blocks.SANDSTONE.getDefaultState());
        structure.fillWithBlocks(world, start, -11, -27, 71, -11, -27, 71, Blocks.AIR.getDefaultState());
        structure.fillWithBlocks(world, start, -11, -26, 5, -11, -26, 5, Blocks.STONE_BRICKS.getDefaultState());
        structure.fillWithBlocks(world, start, -11, -26, 8, -10, -26, 8, Blocks.DIRT.getDefaultState());
        structure.fillWithBlocks(world, start, -11, -26, 9, -11, -26, 10, Blocks.STONE_BRICKS.getDefaultState());
        structure.fillWithBlocks(world, start, -11, -26, 15, -11, -25, 15, Blocks.SANDSTONE.getDefaultState());
        structure.fillWithBlocks(world, start, -11, -26, 24, -11, -24, 27, Blocks.SANDSTONE.getDefaultState());
        structure.fillWithBlocks(world, start, -11, -26, 28, -11, -25, 35, Blocks.SANDSTONE.getDefaultState());
        structure.fillWithBlocks(world, start, -11, -26, 36, -11, -26, 39, Blocks.SANDSTONE.getDefaultState());
        structure.fillWithBlocks(world, start, -11, -26, 47, -11, -23, 47, Blocks.SANDSTONE.getDefaultState());
        structure.fillWithBlocks(world, start, -11, -26, 56, -10, -26, 57, Blocks.SANDSTONE.getDefaultState());
        structure.fillWithBlocks(world, start, -11, -26, 58, -11, -26, 59, Blocks.DIRT.getDefaultState());
        structure.fillWithBlocks(world, start, -11, -26, 60, -10, -26, 62, Blocks.SANDSTONE.getDefaultState());
        structure.fillWithBlocks(world, start, -11, -26, 69, -10, -26, 71, Blocks.SANDSTONE.getDefaultState());
        structure.fillWithBlocks(world, start, -11, -26, 72, -11, -26, 73, Blocks.AIR.getDefaultState());
        structure.fillWithBlocks(world, start, -11, -26, 74, -10, -26, 75, Blocks.SANDSTONE.getDefaultState());
        structure.fillWithBlocks(world, start, -11, -25, 7, -11, -21, 7, Blocks.STONE_BRICKS.getDefaultState());
        structure.fillWithBlocks(world, start, -11, -25, 8, -10, -25, 8, Blocks.SANDSTONE.getDefaultState());
        structure.fillWithBlocks(world, start, -11, -25, 9, -11, -25, 9, Blocks.AIR.getDefaultState());
        structure.fillWithBlocks(world, start, -11, -25, 11, -11, -25, 17, Blocks.SANDSTONE.getDefaultState());
        structure.fillWithBlocks(world, start, -11, -25, 22, -10, -25, 28, Blocks.SANDSTONE.getDefaultState());
        structure.fillWithBlocks(world, start, -11, -25, 37, -10, -25, 39, Blocks.SANDSTONE.getDefaultState());
        structure.fillWithBlocks(world, start, -11, -25, 46, -11, -23, 53, Blocks.SANDSTONE.getDefaultState());
        structure.fillWithBlocks(world, start, -11, -25, 54, -10, -25, 62, Blocks.SANDSTONE.getDefaultState());
        structure.fillWithBlocks(world, start, -11, -25, 63, -11, -23, 68, Blocks.SANDSTONE.getDefaultState());
        structure.fillWithBlocks(world, start, -11, -25, 74, -11, -25, 74, Blocks.DIRT.getDefaultState());
        structure.fillWithBlocks(world, start, -11, -25, 75, -11, -22, 75, Blocks.SANDSTONE.getDefaultState());
        structure.fillWithBlocks(world, start, -11, -24, 4, -11, -24, 4, Blocks.AIR.getDefaultState());
        structure.fillWithBlocks(world, start, -11, -24, 6, -11, -24, 9, Blocks.STONE_BRICKS.getDefaultState());
        structure.fillWithBlocks(world, start, -11, -24, 11, -11, -24, 13, Blocks.STONE_BRICKS.getDefaultState());
        structure.fillWithBlocks(world, start, -11, -24, 14, -11, -24, 14, Blocks.SANDSTONE.getDefaultState());
        structure.fillWithBlocks(world, start, -11, -24, 15, -11, -24, 17, Blocks.STONE_BRICKS.getDefaultState());
        structure.fillWithBlocks(world, start, -11, -24, 29, -9, -24, 31, Blocks.SANDSTONE.getDefaultState());
        structure.fillWithBlocks(world, start, -11, -24, 33, -10, -24, 34, Blocks.SANDSTONE.getDefaultState());
        structure.fillWithBlocks(world, start, -11, -24, 35, -11, -24, 35, Blocks.AIR.getDefaultState());
        structure.fillWithBlocks(world, start, -11, -24, 54, -11, -24, 55, Blocks.DIRT.getDefaultState());
        structure.fillWithBlocks(world, start, -11, -24, 56, -10, -24, 58, Blocks.SANDSTONE.getDefaultState());
        structure.fillWithBlocks(world, start, -11, -24, 60, -10, -24, 75, Blocks.SANDSTONE.getDefaultState());
        structure.fillWithBlocks(world, start, -11, -23, 4, -11, -23, 4, Blocks.STONE_BRICKS.getDefaultState());
        structure.fillWithBlocks(world, start, -11, -23, 5, -11, -22, 6, Blocks.SANDSTONE.getDefaultState());
        structure.fillWithBlocks(world, start, -11, -23, 8, -11, -22, 8, Blocks.SANDSTONE.getDefaultState());
        structure.fillWithBlocks(world, start, -11, -23, 10, -11, -23, 11, Blocks.SANDSTONE.getDefaultState());
        structure.fillWithBlocks(world, start, -11, -23, 12, -10, -23, 12, Blocks.DIRT.getDefaultState());
        structure.fillWithBlocks(world, start, -11, -23, 13, -11, -23, 14, Blocks.STONE_BRICKS.getDefaultState());
        structure.fillWithBlocks(world, start, -11, -23, 15, -11, -22, 15, Blocks.SANDSTONE.getDefaultState());
        structure.fillWithBlocks(world, start, -11, -23, 16, -11, -23, 18, Blocks.STONE_BRICKS.getDefaultState());
        structure.fillWithBlocks(world, start, -11, -23, 19, -11, -22, 20, Blocks.SANDSTONE.getDefaultState());
        structure.fillWithBlocks(world, start, -11, -23, 26, -11, -23, 27, Blocks.AIR.getDefaultState());
        structure.fillWithBlocks(world, start, -11, -23, 28, -10, -23, 31, Blocks.SANDSTONE.getDefaultState());
        structure.fillWithBlocks(world, start, -11, -23, 32, -11, -23, 34, Blocks.SANDSTONE.getDefaultState());
        structure.fillWithBlocks(world, start, -11, -23, 35, -10, -23, 35, Blocks.DIRT.getDefaultState());
        structure.fillWithBlocks(world, start, -11, -23, 36, -11, -23, 36, Blocks.SANDSTONE.getDefaultState());
        structure.fillWithBlocks(world, start, -11, -23, 38, -10, -23, 39, Blocks.SANDSTONE.getDefaultState());
        structure.fillWithBlocks(world, start, -11, -23, 40, -11, -23, 54, Blocks.SANDSTONE.getDefaultState());
        structure.fillWithBlocks(world, start, -11, -23, 56, -10, -23, 58, Blocks.SANDSTONE.getDefaultState());
        structure.fillWithBlocks(world, start, -11, -23, 59, -11, -23, 59, Blocks.AIR.getDefaultState());
        structure.fillWithBlocks(world, start, -11, -23, 60, -11, -23, 61, Blocks.SANDSTONE.getDefaultState());
        structure.fillWithBlocks(world, start, -11, -23, 69, -10, -23, 72, Blocks.SANDSTONE.getDefaultState());
        structure.fillWithBlocks(world, start, -11, -23, 74, -10, -23, 75, Blocks.SANDSTONE.getDefaultState());
        structure.fillWithBlocks(world, start, -11, -22, 9, -11, -22, 10, Blocks.SANDSTONE.getDefaultState());
        structure.fillWithBlocks(world, start, -11, -22, 11, -10, -22, 12, Blocks.STONE_BRICKS.getDefaultState());
        structure.fillWithBlocks(world, start, -11, -22, 16, -11, -22, 17, Blocks.SANDSTONE.getDefaultState());
        structure.fillWithBlocks(world, start, -11, -22, 29, -11, -22, 30, Blocks.AIR.getDefaultState());
        structure.fillWithBlocks(world, start, -11, -22, 31, -10, -22, 32, Blocks.SANDSTONE.getDefaultState());
        structure.fillWithBlocks(world, start, -11, -22, 37, -11, -21, 37, Blocks.AIR.getDefaultState());
        structure.fillWithBlocks(world, start, -11, -22, 38, -11, -22, 41, Blocks.SANDSTONE.getDefaultState());
        structure.fillWithBlocks(world, start, -11, -22, 43, -10, -22, 44, Blocks.SANDSTONE.getDefaultState());
        structure.fillWithBlocks(world, start, -11, -22, 45, -11, -22, 46, Blocks.SANDSTONE.getDefaultState());
        structure.fillWithBlocks(world, start, -11, -22, 56, -11, -22, 56, Blocks.SANDSTONE.getDefaultState());
        structure.fillWithBlocks(world, start, -11, -22, 62, -11, -22, 62, Blocks.SANDSTONE.getDefaultState());
        structure.fillWithBlocks(world, start, -11, -22, 65, -11, -22, 65, Blocks.SANDSTONE.getDefaultState());
        structure.fillWithBlocks(world, start, -11, -22, 66, -11, -22, 67, Blocks.DIRT.getDefaultState());
        structure.fillWithBlocks(world, start, -11, -22, 69, -11, -22, 69, Blocks.SANDSTONE.getDefaultState());
        structure.fillWithBlocks(world, start, -11, -22, 74, -11, -22, 75, Blocks.SANDSTONE.getDefaultState());
        structure.fillWithBlocks(world, start, -11, -21, 8, -11, -21, 8, Blocks.STONE_BRICKS.getDefaultState());
        structure.fillWithBlocks(world, start, -11, -21, 10, -11, -21, 11, Blocks.STONE_BRICKS.getDefaultState());
        structure.fillWithBlocks(world, start, -11, -21, 14, -10, -21, 16, Blocks.STONE_BRICKS.getDefaultState());
        structure.fillWithBlocks(world, start, -11, -21, 28, -10, -21, 33, Blocks.SANDSTONE.getDefaultState());
        structure.fillWithBlocks(world, start, -11, -21, 35, -10, -21, 36, Blocks.SANDSTONE.getDefaultState());
        structure.fillWithBlocks(world, start, -11, -21, 40, -7, -21, 40, Blocks.SANDSTONE.getDefaultState());
        structure.fillWithBlocks(world, start, -11, -21, 41, -10, -21, 41, Blocks.AIR.getDefaultState());
        structure.fillWithBlocks(world, start, -11, -21, 42, -10, -21, 46, Blocks.SANDSTONE.getDefaultState());
        structure.fillWithBlocks(world, start, -11, -21, 49, -9, -21, 54, Blocks.SANDSTONE.getDefaultState());
        structure.fillWithBlocks(world, start, -11, -21, 58, -10, -21, 59, Blocks.SANDSTONE.getDefaultState());
        structure.fillWithBlocks(world, start, -11, -21, 60, -11, -21, 61, Blocks.SANDSTONE.getDefaultState());
        structure.fillWithBlocks(world, start, -11, -21, 63, -11, -21, 63, Blocks.SANDSTONE.getDefaultState());
        structure.fillWithBlocks(world, start, -11, -21, 65, -10, -21, 66, Blocks.SANDSTONE.getDefaultState());
        structure.fillWithBlocks(world, start, -11, -21, 68, -9, -21, 70, Blocks.SANDSTONE.getDefaultState());
        structure.fillWithBlocks(world, start, -11, -21, 71, -11, -21, 72, Blocks.SANDSTONE.getDefaultState());
        structure.fillWithBlocks(world, start, -11, -20, 54, -6, -18, 54, Blocks.SANDSTONE.getDefaultState());
        structure.fillWithBlocks(world, start, -11, -19, 42, -9, -19, 44, Blocks.SANDSTONE.getDefaultState());
        structure.fillWithBlocks(world, start, -11, -19, 45, -10, -19, 51, Blocks.AIR.getDefaultState());
        structure.fillWithBlocks(world, start, -11, -19, 52, -10, -19, 54, Blocks.SANDSTONE.getDefaultState());
        structure.fillWithBlocks(world, start, -11, -18, 42, -10, -18, 44, Blocks.SANDSTONE.getDefaultState());
        structure.fillWithBlocks(world, start, -11, -18, 45, -10, -18, 51, Blocks.AIR.getDefaultState());
        structure.fillWithBlocks(world, start, -11, -18, 52, -9, -18, 54, Blocks.SANDSTONE.getDefaultState());
        structure.fillWithBlocks(world, start, -11, -17, 42, -11, -14, 42, Blocks.SANDSTONE.getDefaultState());
        structure.fillWithBlocks(world, start, -11, -17, 44, -6, -15, 44, Blocks.SANDSTONE.getDefaultState());
        structure.fillWithBlocks(world, start, -11, -17, 52, -11, -17, 52, Blocks.SANDSTONE.getDefaultState());
        structure.fillWithBlocks(world, start, -11, -16, 52, -9, -16, 54, Blocks.SANDSTONE.getDefaultState());
        structure.fillWithBlocks(world, start, -11, -15, 45, -11, -15, 45, Blocks.SANDSTONE.getDefaultState());
        structure.fillWithBlocks(world, start, -11, -15, 51, -11, -15, 51, Blocks.SANDSTONE.getDefaultState());
        structure.fillWithBlocks(world, start, -11, -15, 53, -10, -15, 54, Blocks.SANDSTONE.getDefaultState());
        structure.fillWithBlocks(world, start, -11, -14, 43, -9, -12, 43, Blocks.SANDSTONE.getDefaultState());
        structure.fillWithBlocks(world, start, -11, -14, 44, -9, -14, 44, Blocks.AIR.getDefaultState());
        structure.fillWithBlocks(world, start, -11, -14, 45, -8, -14, 48, Blocks.SANDSTONE.getDefaultState());
        structure.fillWithBlocks(world, start, -11, -14, 52, -10, -14, 54, Blocks.SANDSTONE.getDefaultState());
        structure.fillWithBlocks(world, start, -11, -13, 44, -8, -13, 48, Blocks.SANDSTONE.getDefaultState());
        structure.fillWithBlocks(world, start, -11, -13, 50, -9, -13, 54, Blocks.SANDSTONE.getDefaultState());
        structure.fillWithBlocks(world, start, -10, -51, 42, -10, -51, 44, Blocks.SANDSTONE.getDefaultState());
        structure.fillWithBlocks(world, start, -10, -51, 52, -10, -51, 54, Blocks.SANDSTONE.getDefaultState());
        structure.fillWithBlocks(world, start, -10, -50, 40, -9, -50, 41, Blocks.SANDSTONE.getDefaultState());
        structure.fillWithBlocks(world, start, -10, -50, 42, -10, -48, 44, Blocks.AIR.getDefaultState());
        structure.fillWithBlocks(world, start, -10, -50, 52, -10, -48, 54, Blocks.AIR.getDefaultState());
        structure.fillWithBlocks(world, start, -10, -50, 55, -9, -50, 56, Blocks.SANDSTONE.getDefaultState());
        structure.fillWithBlocks(world, start, -10, -45, 55, -9, -45, 56, Blocks.SANDSTONE.getDefaultState());
        structure.fillWithBlocks(world, start, -10, -44, 42, -8, -44, 56, Blocks.SANDSTONE.getDefaultState());
        structure.fillWithBlocks(world, start, -10, -41, 42, -9, -41, 43, Blocks.STONE_BRICKS.getDefaultState());
        structure.fillWithBlocks(world, start, -10, -41, 52, -8, -41, 54, Blocks.STONE_BRICKS.getDefaultState());
        structure.fillWithBlocks(world, start, -10, -40, 42, -10, -40, 42, Blocks.AIR.getDefaultState());
        structure.fillWithBlocks(world, start, -10, -40, 52, -10, -40, 52, Blocks.AIR.getDefaultState());
        structure.fillWithBlocks(world, start, -10, -40, 55, -9, -40, 60, Blocks.STONE_BRICKS.getDefaultState());
        structure.fillWithBlocks(world, start, -10, -39, 41, -10, -35, 41, Blocks.STONE_BRICKS.getDefaultState());
        structure.fillWithBlocks(world, start, -10, -39, 42, -8, -39, 44, Blocks.AIR.getDefaultState());
        structure.fillWithBlocks(world, start, -10, -39, 45, -10, -34, 45, Blocks.STONE_BRICKS.getDefaultState());
        structure.fillWithBlocks(world, start, -10, -39, 46, -7, -39, 50, Blocks.AIR.getDefaultState());
        structure.fillWithBlocks(world, start, -10, -39, 51, -10, -33, 51, Blocks.STONE_BRICKS.getDefaultState());
        structure.fillWithBlocks(world, start, -10, -39, 52, -8, -39, 54, Blocks.AIR.getDefaultState());
        structure.fillWithBlocks(world, start, -10, -39, 55, -10, -39, 56, Blocks.STONE_BRICKS.getDefaultState());
        structure.fillWithBlocks(world, start, -10, -39, 57, -10, -38, 57, Blocks.AIR.getDefaultState());
        structure.fillWithBlocks(world, start, -10, -39, 58, -8, -39, 60, Blocks.STONE_BRICKS.getDefaultState());
        structure.fillWithBlocks(world, start, -10, -38, 40, -10, -37, 41, Blocks.STONE_BRICKS.getDefaultState());
        structure.fillWithBlocks(world, start, -10, -38, 42, -8, -38, 44, Blocks.AIR.getDefaultState());
        structure.fillWithBlocks(world, start, -10, -38, 46, -6, -38, 50, Blocks.AIR.getDefaultState());
        structure.fillWithBlocks(world, start, -10, -38, 52, -8, -38, 54, Blocks.AIR.getDefaultState());
        structure.fillWithBlocks(world, start, -10, -38, 55, -10, -38, 56, Blocks.STONE_BRICKS.getDefaultState());
        structure.fillWithBlocks(world, start, -10, -38, 58, -10, -38, 58, Blocks.STONE_BRICKS.getDefaultState());
        structure.fillWithBlocks(world, start, -10, -38, 60, -8, -36, 60, Blocks.STONE_BRICKS.getDefaultState());
        structure.fillWithBlocks(world, start, -10, -37, 42, -8, -37, 44, Blocks.AIR.getDefaultState());
        structure.fillWithBlocks(world, start, -10, -37, 46, -6, -37, 50, Blocks.AIR.getDefaultState());
        structure.fillWithBlocks(world, start, -10, -37, 52, -8, -37, 54, Blocks.AIR.getDefaultState());
        structure.fillWithBlocks(world, start, -10, -37, 55, -10, -37, 60, Blocks.STONE_BRICKS.getDefaultState());
        structure.fillWithBlocks(world, start, -10, -36, 42, -8, -36, 44, Blocks.AIR.getDefaultState());
        structure.fillWithBlocks(world, start, -10, -36, 46, -6, -36, 50, Blocks.AIR.getDefaultState());
        structure.fillWithBlocks(world, start, -10, -36, 52, -8, -36, 54, Blocks.AIR.getDefaultState());
        structure.fillWithBlocks(world, start, -10, -36, 55, -10, -36, 60, Blocks.STONE_BRICKS.getDefaultState());
        structure.fillWithBlocks(world, start, -10, -35, 42, -10, -35, 55, Blocks.STONE_BRICKS.getDefaultState());
        structure.fillWithBlocks(world, start, -10, -34, 39, -9, -34, 40, Blocks.STONE_BRICKS.getDefaultState());
        structure.fillWithBlocks(world, start, -10, -34, 42, -10, -34, 42, Blocks.STONE_BRICKS.getDefaultState());
        structure.fillWithBlocks(world, start, -10, -34, 53, -10, -34, 54, Blocks.STONE_BRICKS.getDefaultState());
        structure.fillWithBlocks(world, start, -10, -34, 56, -8, -34, 58, Blocks.STONE_BRICKS.getDefaultState());
        structure.fillWithBlocks(world, start, -10, -34, 59, -9, -34, 60, Blocks.STONE_BRICKS.getDefaultState());
        structure.fillWithBlocks(world, start, -10, -33, 40, -6, -33, 44, Blocks.STONE_BRICKS.getDefaultState());
        structure.fillWithBlocks(world, start, -10, -33, 46, -8, -33, 50, Blocks.STONE_BRICKS.getDefaultState());
        structure.fillWithBlocks(world, start, -10, -33, 54, -10, -33, 54, Blocks.AIR.getDefaultState());
        structure.fillWithBlocks(world, start, -10, -33, 55, -10, -31, 55, Blocks.STONE_BRICKS.getDefaultState());
        structure.fillWithBlocks(world, start, -10, -33, 56, -10, -33, 57, Blocks.AIR.getDefaultState());
        structure.fillWithBlocks(world, start, -10, -33, 58, -8, -33, 60, Blocks.STONE_BRICKS.getDefaultState());
        structure.fillWithBlocks(world, start, -10, -32, 41, -7, -32, 45, Blocks.STONE_BRICKS.getDefaultState());
        structure.fillWithBlocks(world, start, -10, -32, 47, -10, -32, 50, Blocks.STONE_BRICKS.getDefaultState());
        structure.fillWithBlocks(world, start, -10, -32, 51, -10, -32, 53, Blocks.AIR.getDefaultState());
        structure.fillWithBlocks(world, start, -10, -32, 54, -10, -32, 60, Blocks.STONE_BRICKS.getDefaultState());
        structure.fillWithBlocks(world, start, -10, -31, 39, -10, -31, 42, Blocks.STONE_BRICKS.getDefaultState());
        structure.fillWithBlocks(world, start, -10, -31, 44, -8, -31, 48, Blocks.STONE_BRICKS.getDefaultState());
        structure.fillWithBlocks(world, start, -10, -31, 49, -9, -31, 55, Blocks.STONE_BRICKS.getDefaultState());
        structure.fillWithBlocks(world, start, -10, -31, 57, -9, -31, 58, Blocks.STONE_BRICKS.getDefaultState());
        structure.fillWithBlocks(world, start, -10, -31, 60, -7, -31, 60, Blocks.STONE_BRICKS.getDefaultState());
        structure.fillWithBlocks(world, start, -10, -30, 4, -8, -30, 4, Blocks.STONE_BRICKS.getDefaultState());
        structure.fillWithBlocks(world, start, -10, -30, 5, -10, -30, 5, Blocks.DIRT.getDefaultState());
        structure.fillWithBlocks(world, start, -10, -30, 6, -10, -30, 6, Blocks.SANDSTONE.getDefaultState());
        structure.fillWithBlocks(world, start, -10, -30, 7, -10, -30, 8, Blocks.DIRT.getDefaultState());
        structure.fillWithBlocks(world, start, -10, -30, 9, -9, -30, 9, Blocks.AIR.getDefaultState());
        structure.fillWithBlocks(world, start, -10, -30, 14, -5, -30, 27, Blocks.SANDSTONE.getDefaultState());
        structure.fillWithBlocks(world, start, -10, -30, 29, -6, -30, 33, Blocks.SANDSTONE.getDefaultState());
        structure.fillWithBlocks(world, start, -10, -30, 39, -5, -30, 50, Blocks.SANDSTONE.getDefaultState());
        structure.fillWithBlocks(world, start, -10, -30, 52, -10, -29, 54, Blocks.SANDSTONE.getDefaultState());
        structure.fillWithBlocks(world, start, -10, -30, 55, -10, -30, 55, Blocks.DIRT.getDefaultState());
        structure.fillWithBlocks(world, start, -10, -30, 56, -10, -29, 56, Blocks.AIR.getDefaultState());
        structure.fillWithBlocks(world, start, -10, -30, 57, -10, -30, 57, Blocks.DIRT.getDefaultState());
        structure.fillWithBlocks(world, start, -10, -30, 58, -10, -30, 60, Blocks.SANDSTONE.getDefaultState());
        structure.fillWithBlocks(world, start, -10, -30, 61, -9, -30, 61, Blocks.DIRT.getDefaultState());
        structure.fillWithBlocks(world, start, -10, -30, 62, -5, -30, 67, Blocks.SANDSTONE.getDefaultState());
        structure.fillWithBlocks(world, start, -10, -30, 69, -10, -29, 70, Blocks.SANDSTONE.getDefaultState());
        structure.fillWithBlocks(world, start, -10, -30, 71, -9, -30, 71, Blocks.SANDSTONE.getDefaultState());
        structure.fillWithBlocks(world, start, -10, -30, 72, -10, -30, 74, Blocks.AIR.getDefaultState());
        structure.fillWithBlocks(world, start, -10, -30, 75, -6, -27, 75, Blocks.SANDSTONE.getDefaultState());
        structure.fillWithBlocks(world, start, -10, -29, 6, -9, -29, 7, Blocks.STONE_BRICKS.getDefaultState());
        structure.fillWithBlocks(world, start, -10, -29, 9, -10, -28, 10, Blocks.STONE_BRICKS.getDefaultState());
        structure.fillWithBlocks(world, start, -10, -29, 11, -10, -25, 11, Blocks.SANDSTONE.getDefaultState());
        structure.fillWithBlocks(world, start, -10, -29, 12, -7, -29, 16, Blocks.AIR.getDefaultState());
        structure.fillWithBlocks(world, start, -10, -29, 23, -6, -29, 27, Blocks.AIR.getDefaultState());
        structure.fillWithBlocks(world, start, -10, -29, 28, -10, -21, 28, Blocks.SANDSTONE.getDefaultState());
        structure.fillWithBlocks(world, start, -10, -29, 29, -6, -29, 33, Blocks.AIR.getDefaultState());
        structure.fillWithBlocks(world, start, -10, -29, 34, -10, -21, 34, Blocks.SANDSTONE.getDefaultState());
        structure.fillWithBlocks(world, start, -10, -29, 35, -8, -29, 44, Blocks.AIR.getDefaultState());
        structure.fillWithBlocks(world, start, -10, -29, 45, -10, -23, 45, Blocks.SANDSTONE.getDefaultState());
        structure.fillWithBlocks(world, start, -10, -29, 46, -8, -29, 50, Blocks.AIR.getDefaultState());
        structure.fillWithBlocks(world, start, -10, -29, 51, -10, -29, 55, Blocks.SANDSTONE.getDefaultState());
        structure.fillWithBlocks(world, start, -10, -29, 57, -9, -29, 58, Blocks.SANDSTONE.getDefaultState());
        structure.fillWithBlocks(world, start, -10, -29, 60, -10, -29, 60, Blocks.SANDSTONE.getDefaultState());
        structure.fillWithBlocks(world, start, -10, -29, 62, -10, -21, 62, Blocks.SANDSTONE.getDefaultState());
        structure.fillWithBlocks(world, start, -10, -29, 63, -8, -29, 67, Blocks.AIR.getDefaultState());
        structure.fillWithBlocks(world, start, -10, -29, 68, -10, -29, 70, Blocks.SANDSTONE.getDefaultState());
        structure.fillWithBlocks(world, start, -10, -29, 72, -9, -29, 75, Blocks.SANDSTONE.getDefaultState());
        structure.fillWithBlocks(world, start, -10, -28, 6, -10, -28, 10, Blocks.STONE_BRICKS.getDefaultState());
        structure.fillWithBlocks(world, start, -10, -28, 12, -6, -28, 16, Blocks.AIR.getDefaultState());
        structure.fillWithBlocks(world, start, -10, -28, 23, -6, -28, 27, Blocks.AIR.getDefaultState());
        structure.fillWithBlocks(world, start, -10, -28, 29, -6, -28, 33, Blocks.AIR.getDefaultState());
        structure.fillWithBlocks(world, start, -10, -28, 35, -4, -28, 44, Blocks.AIR.getDefaultState());
        structure.fillWithBlocks(world, start, -10, -28, 46, -8, -28, 50, Blocks.AIR.getDefaultState());
        structure.fillWithBlocks(world, start, -10, -28, 51, -10, -20, 51, Blocks.SANDSTONE.getDefaultState());
        structure.fillWithBlocks(world, start, -10, -28, 53, -10, -28, 53, Blocks.SANDSTONE.getDefaultState());
        structure.fillWithBlocks(world, start, -10, -28, 54, -10, -28, 55, Blocks.AIR.getDefaultState());
        structure.fillWithBlocks(world, start, -10, -28, 56, -9, -28, 57, Blocks.SANDSTONE.getDefaultState());
        structure.fillWithBlocks(world, start, -10, -28, 58, -10, -28, 62, Blocks.SANDSTONE.getDefaultState());
        structure.fillWithBlocks(world, start, -10, -28, 63, -8, -28, 67, Blocks.AIR.getDefaultState());
        structure.fillWithBlocks(world, start, -10, -28, 70, -10, -27, 71, Blocks.SANDSTONE.getDefaultState());
        structure.fillWithBlocks(world, start, -10, -28, 74, -10, -28, 75, Blocks.SANDSTONE.getDefaultState());
        structure.fillWithBlocks(world, start, -10, -27, 5, -10, -27, 6, Blocks.STONE_BRICKS.getDefaultState());
        structure.fillWithBlocks(world, start, -10, -27, 10, -10, -27, 10, Blocks.AIR.getDefaultState());
        structure.fillWithBlocks(world, start, -10, -27, 12, -6, -27, 16, Blocks.AIR.getDefaultState());
        structure.fillWithBlocks(world, start, -10, -27, 23, -6, -27, 27, Blocks.AIR.getDefaultState());
        structure.fillWithBlocks(world, start, -10, -27, 29, -6, -27, 33, Blocks.AIR.getDefaultState());
        structure.fillWithBlocks(world, start, -10, -27, 35, -4, -27, 44, Blocks.AIR.getDefaultState());
        structure.fillWithBlocks(world, start, -10, -27, 46, -6, -27, 50, Blocks.AIR.getDefaultState());
        structure.fillWithBlocks(world, start, -10, -27, 52, -10, -27, 52, Blocks.SANDSTONE.getDefaultState());
        structure.fillWithBlocks(world, start, -10, -27, 53, -10, -27, 53, Blocks.DIRT.getDefaultState());
        structure.fillWithBlocks(world, start, -10, -27, 54, -10, -27, 57, Blocks.SANDSTONE.getDefaultState());
        structure.fillWithBlocks(world, start, -10, -27, 59, -10, -24, 62, Blocks.SANDSTONE.getDefaultState());
        structure.fillWithBlocks(world, start, -10, -27, 63, -6, -27, 67, Blocks.AIR.getDefaultState());
        structure.fillWithBlocks(world, start, -10, -27, 68, -10, -24, 68, Blocks.SANDSTONE.getDefaultState());
        structure.fillWithBlocks(world, start, -10, -27, 73, -8, -27, 75, Blocks.SANDSTONE.getDefaultState());
        structure.fillWithBlocks(world, start, -10, -26, 4, -9, -26, 7, Blocks.STONE_BRICKS.getDefaultState());
        structure.fillWithBlocks(world, start, -10, -26, 9, -10, -26, 11, Blocks.SANDSTONE.getDefaultState());
        structure.fillWithBlocks(world, start, -10, -26, 12, -6, -26, 16, Blocks.AIR.getDefaultState());
        structure.fillWithBlocks(world, start, -10, -26, 23, -6, -26, 27, Blocks.AIR.getDefaultState());
        structure.fillWithBlocks(world, start, -10, -26, 29, -6, -26, 33, Blocks.AIR.getDefaultState());
        structure.fillWithBlocks(world, start, -10, -26, 35, -4, -26, 44, Blocks.AIR.getDefaultState());
        structure.fillWithBlocks(world, start, -10, -26, 46, -6, -26, 50, Blocks.AIR.getDefaultState());
        structure.fillWithBlocks(world, start, -10, -26, 52, -10, -23, 52, Blocks.SANDSTONE.getDefaultState());
        structure.fillWithBlocks(world, start, -10, -26, 53, -10, -26, 54, Blocks.SHROOMLIGHT.getDefaultState());
        structure.fillWithBlocks(world, start, -10, -26, 55, -9, -26, 58, Blocks.SANDSTONE.getDefaultState());
        structure.fillWithBlocks(world, start, -10, -26, 63, -6, -26, 67, Blocks.AIR.getDefaultState());
        structure.fillWithBlocks(world, start, -10, -26, 72, -10, -26, 72, Blocks.SANDSTONE.getDefaultState());
        structure.fillWithBlocks(world, start, -10, -25, 4, -8, -25, 4, Blocks.STONE_BRICKS.getDefaultState());
        structure.fillWithBlocks(world, start, -10, -25, 6, -9, -24, 6, Blocks.STONE_BRICKS.getDefaultState());
        structure.fillWithBlocks(world, start, -10, -25, 7, -10, -25, 8, Blocks.SANDSTONE.getDefaultState());
        structure.fillWithBlocks(world, start, -10, -25, 10, -10, -24, 10, Blocks.AIR.getDefaultState());
        structure.fillWithBlocks(world, start, -10, -25, 12, -6, -25, 16, Blocks.AIR.getDefaultState());
        structure.fillWithBlocks(world, start, -10, -25, 18, -7, -25, 21, Blocks.AIR.getDefaultState());
        structure.fillWithBlocks(world, start, -10, -25, 29, -6, -25, 33, Blocks.AIR.getDefaultState());
        structure.fillWithBlocks(world, start, -10, -25, 35, -10, -25, 39, Blocks.SANDSTONE.getDefaultState());
        structure.fillWithBlocks(world, start, -10, -25, 46, -6, -25, 50, Blocks.AIR.getDefaultState());
        structure.fillWithBlocks(world, start, -10, -25, 53, -10, -22, 57, Blocks.SANDSTONE.getDefaultState());
        structure.fillWithBlocks(world, start, -10, -25, 63, -6, -25, 67, Blocks.AIR.getDefaultState());
        structure.fillWithBlocks(world, start, -10, -25, 69, -10, -22, 73, Blocks.SANDSTONE.getDefaultState());
        structure.fillWithBlocks(world, start, -10, -25, 74, -10, -25, 74, Blocks.SANDSTONE.getDefaultState());
        structure.fillWithBlocks(world, start, -10, -24, 4, -10, -23, 4, Blocks.SANDSTONE.getDefaultState());
        structure.fillWithBlocks(world, start, -10, -24, 7, -9, -24, 7, Blocks.DIRT.getDefaultState());
        structure.fillWithBlocks(world, start, -10, -24, 8, -10, -23, 9, Blocks.STONE_BRICKS.getDefaultState());
        structure.fillWithBlocks(world, start, -10, -24, 11, -10, -23, 11, Blocks.DIRT.getDefaultState());
        structure.fillWithBlocks(world, start, -10, -24, 12, -6, -24, 16, Blocks.SANDSTONE.getDefaultState());
        structure.fillWithBlocks(world, start, -10, -24, 32, -9, -24, 35, Blocks.SANDSTONE.getDefaultState());
        structure.fillWithBlocks(world, start, -10, -23, 5, -10, -23, 5, Blocks.STONE_BRICKS.getDefaultState());
        structure.fillWithBlocks(world, start, -10, -23, 6, -10, -22, 6, Blocks.AIR.getDefaultState());
        structure.fillWithBlocks(world, start, -10, -23, 7, -9, -23, 10, Blocks.STONE_BRICKS.getDefaultState());
        structure.fillWithBlocks(world, start, -10, -23, 13, -7, -23, 13, Blocks.STONE_BRICKS.getDefaultState());
        structure.fillWithBlocks(world, start, -10, -23, 15, -9, -23, 16, Blocks.STONE_BRICKS.getDefaultState());
        structure.fillWithBlocks(world, start, -10, -23, 18, -5, -23, 18, Blocks.STONE_BRICKS.getDefaultState());
        structure.fillWithBlocks(world, start, -10, -23, 19, -10, -23, 19, Blocks.SANDSTONE.getDefaultState());
        structure.fillWithBlocks(world, start, -10, -23, 21, -8, -23, 24, Blocks.SANDSTONE.getDefaultState());
        structure.fillWithBlocks(world, start, -10, -23, 26, -9, -23, 27, Blocks.SANDSTONE.getDefaultState());
        structure.fillWithBlocks(world, start, -10, -23, 33, -9, -23, 34, Blocks.SANDSTONE.getDefaultState());
        structure.fillWithBlocks(world, start, -10, -23, 36, -8, -23, 39, Blocks.SANDSTONE.getDefaultState());
        structure.fillWithBlocks(world, start, -10, -23, 41, -9, -23, 43, Blocks.SANDSTONE.getDefaultState());
        structure.fillWithBlocks(world, start, -10, -23, 44, -9, -23, 44, Blocks.AIR.getDefaultState());
        structure.fillWithBlocks(world, start, -10, -23, 46, -8, -22, 46, Blocks.SANDSTONE.getDefaultState());
        structure.fillWithBlocks(world, start, -10, -23, 48, -10, -23, 59, Blocks.SANDSTONE.getDefaultState());
        structure.fillWithBlocks(world, start, -10, -23, 60, -10, -21, 60, Blocks.AIR.getDefaultState());
        structure.fillWithBlocks(world, start, -10, -23, 61, -9, -23, 64, Blocks.SANDSTONE.getDefaultState());
        structure.fillWithBlocks(world, start, -10, -22, 4, -9, -22, 5, Blocks.STONE_BRICKS.getDefaultState());
        structure.fillWithBlocks(world, start, -10, -22, 7, -9, -22, 10, Blocks.STONE_BRICKS.getDefaultState());
        structure.fillWithBlocks(world, start, -10, -22, 13, -10, -21, 13, Blocks.STONE_BRICKS.getDefaultState());
        structure.fillWithBlocks(world, start, -10, -22, 14, -10, -22, 15, Blocks.AIR.getDefaultState());
        structure.fillWithBlocks(world, start, -10, -22, 16, -10, -22, 16, Blocks.SANDSTONE.getDefaultState());
        structure.fillWithBlocks(world, start, -10, -22, 17, -10, -22, 18, Blocks.STONE_BRICKS.getDefaultState());
        structure.fillWithBlocks(world, start, -10, -22, 19, -10, -22, 23, Blocks.SANDSTONE.getDefaultState());
        structure.fillWithBlocks(world, start, -10, -22, 29, -9, -22, 30, Blocks.SANDSTONE.getDefaultState());
        structure.fillWithBlocks(world, start, -10, -22, 33, -10, -22, 33, Blocks.AIR.getDefaultState());
        structure.fillWithBlocks(world, start, -10, -22, 35, -9, -22, 38, Blocks.SANDSTONE.getDefaultState());
        structure.fillWithBlocks(world, start, -10, -22, 40, -10, -22, 40, Blocks.SANDSTONE.getDefaultState());
        structure.fillWithBlocks(world, start, -10, -22, 41, -10, -21, 41, Blocks.AIR.getDefaultState());
        structure.fillWithBlocks(world, start, -10, -22, 42, -9, -22, 43, Blocks.SANDSTONE.getDefaultState());
        structure.fillWithBlocks(world, start, -10, -22, 47, -10, -22, 51, Blocks.SANDSTONE.getDefaultState());
        structure.fillWithBlocks(world, start, -10, -22, 59, -10, -22, 59, Blocks.SANDSTONE.getDefaultState());
        structure.fillWithBlocks(world, start, -10, -22, 61, -9, -22, 65, Blocks.SANDSTONE.getDefaultState());
        structure.fillWithBlocks(world, start, -10, -22, 66, -10, -22, 73, Blocks.SANDSTONE.getDefaultState());
        structure.fillWithBlocks(world, start, -10, -21, 4, -10, -21, 4, Blocks.STONE_BRICKS.getDefaultState());
        structure.fillWithBlocks(world, start, -10, -21, 6, -8, -21, 6, Blocks.STONE_BRICKS.getDefaultState());
        structure.fillWithBlocks(world, start, -10, -21, 7, -10, -21, 7, Blocks.SANDSTONE.getDefaultState());
        structure.fillWithBlocks(world, start, -10, -21, 8, -10, -21, 10, Blocks.STONE_BRICKS.getDefaultState());
        structure.fillWithBlocks(world, start, -10, -21, 12, -10, -21, 16, Blocks.STONE_BRICKS.getDefaultState());
        structure.fillWithBlocks(world, start, -10, -21, 17, -9, -21, 17, Blocks.AIR.getDefaultState());
        structure.fillWithBlocks(world, start, -10, -21, 19, -10, -21, 19, Blocks.SANDSTONE.getDefaultState());
        structure.fillWithBlocks(world, start, -10, -21, 22, -8, -21, 22, Blocks.DIRT.getDefaultState());
        structure.fillWithBlocks(world, start, -10, -21, 23, -9, -21, 26, Blocks.SANDSTONE.getDefaultState());
        structure.fillWithBlocks(world, start, -10, -21, 27, -10, -21, 37, Blocks.SANDSTONE.getDefaultState());
        structure.fillWithBlocks(world, start, -10, -21, 39, -9, -21, 40, Blocks.SANDSTONE.getDefaultState());
        structure.fillWithBlocks(world, start, -10, -21, 48, -9, -21, 54, Blocks.SANDSTONE.getDefaultState());
        structure.fillWithBlocks(world, start, -10, -21, 56, -10, -21, 59, Blocks.SANDSTONE.getDefaultState());
        structure.fillWithBlocks(world, start, -10, -21, 61, -7, -21, 64, Blocks.SANDSTONE.getDefaultState());
        structure.fillWithBlocks(world, start, -10, -21, 72, -10, -21, 72, Blocks.SANDSTONE.getDefaultState());
        structure.fillWithBlocks(world, start, -10, -21, 75, -8, -21, 75, Blocks.SANDSTONE.getDefaultState());
        structure.fillWithBlocks(world, start, -10, -20, 42, -9, -20, 43, Blocks.SANDSTONE.getDefaultState());
        structure.fillWithBlocks(world, start, -10, -20, 44, -10, -20, 44, Blocks.AIR.getDefaultState());
        structure.fillWithBlocks(world, start, -10, -20, 45, -10, -20, 54, Blocks.SANDSTONE.getDefaultState());
        structure.fillWithBlocks(world, start, -10, -17, 43, -9, -17, 44, Blocks.SANDSTONE.getDefaultState());
        structure.fillWithBlocks(world, start, -10, -17, 52, -9, -17, 53, Blocks.SANDSTONE.getDefaultState());
        structure.fillWithBlocks(world, start, -10, -16, 42, -8, -16, 44, Blocks.SANDSTONE.getDefaultState());
        structure.fillWithBlocks(world, start, -10, -15, 42, -6, -15, 46, Blocks.SANDSTONE.getDefaultState());
        structure.fillWithBlocks(world, start, -10, -15, 47, -10, -15, 49, Blocks.AIR.getDefaultState());
        structure.fillWithBlocks(world, start, -10, -15, 50, -9, -15, 51, Blocks.SANDSTONE.getDefaultState());
        structure.fillWithBlocks(world, start, -10, -15, 52, -10, -15, 54, Blocks.SANDSTONE.getDefaultState());
        structure.fillWithBlocks(world, start, -10, -14, 42, -10, -14, 43, Blocks.SANDSTONE.getDefaultState());
        structure.fillWithBlocks(world, start, -10, -13, 42, -8, -13, 50, Blocks.SANDSTONE.getDefaultState());
        structure.fillWithBlocks(world, start, -10, -12, 42, -9, -12, 45, Blocks.SANDSTONE.getDefaultState());
        structure.fillWithBlocks(world, start, -10, -12, 47, -7, -12, 54, Blocks.SANDSTONE.getDefaultState());
        structure.fillWithBlocks(world, start, -9, -50, 42, -8, -50, 56, Blocks.SANDSTONE.getDefaultState());
        structure.fillWithBlocks(world, start, -9, -49, 41, -9, -49, 41, Blocks.SANDSTONE.getDefaultState());
        structure.fillWithBlocks(world, start, -9, -49, 42, -9, -49, 44, Blocks.IRON_BARS.getDefaultState().with(FourWayBlock.WATERLOGGED, false).with(FourWayBlock.NORTH, true).with(FourWayBlock.SOUTH, true).with(FourWayBlock.EAST, true).with(FourWayBlock.WEST, true));
        structure.fillWithBlocks(world, start, -9, -49, 45, -9, -49, 45, Blocks.SANDSTONE.getDefaultState());
        structure.fillWithBlocks(world, start, -9, -49, 51, -9, -49, 51, Blocks.SANDSTONE.getDefaultState());
        structure.fillWithBlocks(world, start, -9, -49, 52, -9, -49, 54, Blocks.IRON_BARS.getDefaultState().with(FourWayBlock.WATERLOGGED, false).with(FourWayBlock.NORTH, true).with(FourWayBlock.SOUTH, true).with(FourWayBlock.EAST, true).with(FourWayBlock.WEST, true));
        structure.fillWithBlocks(world, start, -9, -49, 55, -8, -49, 56, Blocks.SANDSTONE.getDefaultState());
        structure.fillWithBlocks(world, start, -9, -48, 41, -9, -48, 41, Blocks.SANDSTONE.getDefaultState());
        structure.fillWithBlocks(world, start, -9, -48, 42, -9, -46, 44, Blocks.AIR.getDefaultState());
        structure.fillWithBlocks(world, start, -9, -48, 45, -9, -48, 45, Blocks.SANDSTONE.getDefaultState());
        structure.fillWithBlocks(world, start, -9, -48, 51, -9, -48, 51, Blocks.SANDSTONE.getDefaultState());
        structure.fillWithBlocks(world, start, -9, -48, 52, -9, -46, 54, Blocks.AIR.getDefaultState());
        structure.fillWithBlocks(world, start, -9, -48, 55, -8, -48, 56, Blocks.SANDSTONE.getDefaultState());
        structure.fillWithBlocks(world, start, -9, -47, 41, -9, -47, 41, Blocks.SANDSTONE.getDefaultState());
        structure.fillWithBlocks(world, start, -9, -47, 45, -9, -47, 45, Blocks.SANDSTONE.getDefaultState());
        structure.fillWithBlocks(world, start, -9, -47, 51, -9, -47, 51, Blocks.SANDSTONE.getDefaultState());
        structure.fillWithBlocks(world, start, -9, -47, 55, -8, -47, 56, Blocks.SANDSTONE.getDefaultState());
        structure.fillWithBlocks(world, start, -9, -46, 41, -9, -46, 41, Blocks.SANDSTONE.getDefaultState());
        structure.fillWithBlocks(world, start, -9, -46, 45, -9, -46, 45, Blocks.SANDSTONE.getDefaultState());
        structure.fillWithBlocks(world, start, -9, -46, 51, -9, -46, 51, Blocks.SANDSTONE.getDefaultState());
        structure.fillWithBlocks(world, start, -9, -46, 55, -8, -46, 56, Blocks.SANDSTONE.getDefaultState());
        structure.fillWithBlocks(world, start, -9, -45, 42, -8, -45, 56, Blocks.SANDSTONE.getDefaultState());
        structure.fillWithBlocks(world, start, -9, -41, 55, -8, -41, 56, Blocks.SANDSTONE.getDefaultState());
        structure.fillWithBlocks(world, start, -9, -40, 21, -6, -40, 25, Blocks.STONE_BRICKS.getDefaultState());
        structure.fillWithBlocks(world, start, -9, -40, 26, -8, -40, 28, Blocks.STONE_BRICKS.getDefaultState());
        structure.fillWithBlocks(world, start, -9, -40, 29, -9, -40, 41, Blocks.STONE_BRICKS.getDefaultState());
        structure.fillWithBlocks(world, start, -9, -40, 42, -7, -40, 44, Blocks.AIR.getDefaultState());
        structure.fillWithBlocks(world, start, -9, -40, 45, -5, -40, 49, Blocks.STONE_BRICKS.getDefaultState());
        structure.fillWithBlocks(world, start, -9, -40, 51, 13, -40, 51, Blocks.STONE_BRICKS.getDefaultState());
        structure.fillWithBlocks(world, start, -9, -40, 52, -7, -40, 54, Blocks.AIR.getDefaultState());
        structure.fillWithBlocks(world, start, -9, -39, 21, -7, -39, 23, Blocks.STONE_BRICKS.getDefaultState());
        structure.fillWithBlocks(world, start, -9, -39, 24, -8, -39, 26, Blocks.STONE_BRICKS.getDefaultState());
        structure.fillWithBlocks(world, start, -9, -39, 27, -9, -37, 36, Blocks.STONE_BRICKS.getDefaultState());
        structure.fillWithBlocks(world, start, -9, -39, 37, -8, -39, 37, Blocks.AIR.getDefaultState());
        structure.fillWithBlocks(world, start, -9, -39, 38, -7, -39, 40, Blocks.STONE_BRICKS.getDefaultState());
        structure.fillWithBlocks(world, start, -9, -39, 41, -7, -39, 41, Blocks.IRON_BARS.getDefaultState().with(FourWayBlock.WATERLOGGED, false).with(FourWayBlock.NORTH, true).with(FourWayBlock.SOUTH, true).with(FourWayBlock.EAST, true).with(FourWayBlock.WEST, true));
        structure.fillWithBlocks(world, start, -9, -39, 45, -7, -39, 45, Blocks.IRON_BARS.getDefaultState().with(FourWayBlock.WATERLOGGED, false).with(FourWayBlock.NORTH, true).with(FourWayBlock.SOUTH, true).with(FourWayBlock.EAST, true).with(FourWayBlock.WEST, true));
        structure.fillWithBlocks(world, start, -9, -39, 51, -7, -39, 51, Blocks.IRON_BARS.getDefaultState().with(FourWayBlock.WATERLOGGED, false).with(FourWayBlock.NORTH, true).with(FourWayBlock.SOUTH, true).with(FourWayBlock.EAST, true).with(FourWayBlock.WEST, true));
        structure.fillWithBlocks(world, start, -9, -39, 55, -7, -39, 55, Blocks.IRON_BARS.getDefaultState().with(FourWayBlock.WATERLOGGED, false).with(FourWayBlock.NORTH, true).with(FourWayBlock.SOUTH, true).with(FourWayBlock.EAST, true).with(FourWayBlock.WEST, true));
        structure.fillWithBlocks(world, start, -9, -39, 56, -7, -39, 60, Blocks.STONE_BRICKS.getDefaultState());
        structure.fillWithBlocks(world, start, -9, -38, 21, -8, -38, 24, Blocks.STONE_BRICKS.getDefaultState());
        structure.fillWithBlocks(world, start, -9, -38, 25, -9, -38, 40, Blocks.STONE_BRICKS.getDefaultState());
        structure.fillWithBlocks(world, start, -9, -38, 41, -7, -38, 55, Blocks.AIR.getDefaultState());
        structure.fillWithBlocks(world, start, -9, -38, 56, -9, -34, 60, Blocks.STONE_BRICKS.getDefaultState());
        structure.fillWithBlocks(world, start, -9, -37, 21, -7, -37, 23, Blocks.STONE_BRICKS.getDefaultState());
        structure.fillWithBlocks(world, start, -9, -37, 24, -9, -35, 26, Blocks.STONE_BRICKS.getDefaultState());
        structure.fillWithBlocks(world, start, -9, -37, 41, -7, -37, 55, Blocks.AIR.getDefaultState());
        structure.fillWithBlocks(world, start, -9, -36, 21, -9, -32, 26, Blocks.STONE_BRICKS.getDefaultState());
        structure.fillWithBlocks(world, start, -9, -36, 28, -7, -36, 36, Blocks.STONE_BRICKS.getDefaultState());
        structure.fillWithBlocks(world, start, -9, -36, 40, -4, -32, 40, Blocks.STONE_BRICKS.getDefaultState());
        structure.fillWithBlocks(world, start, -9, -36, 41, -7, -36, 55, Blocks.AIR.getDefaultState());
        structure.fillWithBlocks(world, start, -9, -35, 27, -8, -35, 37, Blocks.STONE_BRICKS.getDefaultState());
        structure.fillWithBlocks(world, start, -9, -35, 39, -7, -35, 41, Blocks.STONE_BRICKS.getDefaultState());
        structure.fillWithBlocks(world, start, -9, -35, 42, -7, -35, 44, Blocks.AIR.getDefaultState());
        structure.fillWithBlocks(world, start, -9, -35, 45, -8, -35, 45, Blocks.STONE_BRICKS.getDefaultState());
        structure.fillWithBlocks(world, start, -9, -35, 46, -7, -35, 50, Blocks.AIR.getDefaultState());
        structure.fillWithBlocks(world, start, -9, -35, 52, -7, -35, 54, Blocks.AIR.getDefaultState());
        structure.fillWithBlocks(world, start, -9, -34, 27, -8, -34, 28, Blocks.STONE_BRICKS.getDefaultState());
        structure.fillWithBlocks(world, start, -9, -34, 30, -9, -31, 39, Blocks.STONE_BRICKS.getDefaultState());
        structure.fillWithBlocks(world, start, -9, -34, 41, -8, -34, 42, Blocks.STONE_BRICKS.getDefaultState());
        structure.fillWithBlocks(world, start, -9, -34, 43, -9, -34, 44, Blocks.STONE_BRICKS.getDefaultState());
        structure.fillWithBlocks(world, start, -9, -34, 46, -8, -34, 47, Blocks.STONE_BRICKS.getDefaultState());
        structure.fillWithBlocks(world, start, -9, -34, 48, -9, -34, 50, Blocks.STONE_BRICKS.getDefaultState());
        structure.fillWithBlocks(world, start, -9, -34, 51, -8, -34, 51, Blocks.AIR.getDefaultState());
        structure.fillWithBlocks(world, start, -9, -34, 52, -8, -33, 52, Blocks.STONE_BRICKS.getDefaultState());
        structure.fillWithBlocks(world, start, -9, -34, 54, -9, -34, 60, Blocks.STONE_BRICKS.getDefaultState());
        structure.fillWithBlocks(world, start, -9, -33, 27, -8, -33, 28, Blocks.STONE_BRICKS.getDefaultState());
        structure.fillWithBlocks(world, start, -9, -33, 29, -9, -33, 53, Blocks.STONE_BRICKS.getDefaultState());
        structure.fillWithBlocks(world, start, -9, -33, 54, -9, -33, 55, Blocks.AIR.getDefaultState());
        structure.fillWithBlocks(world, start, -9, -33, 56, -9, -32, 56, Blocks.STONE_BRICKS.getDefaultState());
        structure.fillWithBlocks(world, start, -9, -33, 57, -8, -33, 57, Blocks.AIR.getDefaultState());
        structure.fillWithBlocks(world, start, -9, -32, 27, -6, -32, 30, Blocks.STONE_BRICKS.getDefaultState());
        structure.fillWithBlocks(world, start, -9, -32, 46, -9, -32, 46, Blocks.STONE_BRICKS.getDefaultState());
        structure.fillWithBlocks(world, start, -9, -32, 48, -8, -32, 50, Blocks.STONE_BRICKS.getDefaultState());
        structure.fillWithBlocks(world, start, -9, -32, 52, -8, -32, 53, Blocks.STONE_BRICKS.getDefaultState());
        structure.fillWithBlocks(world, start, -9, -32, 54, -8, -32, 54, Blocks.AIR.getDefaultState());
        structure.fillWithBlocks(world, start, -9, -32, 55, -7, -32, 58, Blocks.STONE_BRICKS.getDefaultState());
        structure.fillWithBlocks(world, start, -9, -31, 21, -9, -31, 22, Blocks.AIR.getDefaultState());
        structure.fillWithBlocks(world, start, -9, -31, 23, -6, -31, 26, Blocks.STONE_BRICKS.getDefaultState());
        structure.fillWithBlocks(world, start, -9, -31, 27, -9, -31, 39, Blocks.STONE_BRICKS.getDefaultState());
        structure.fillWithBlocks(world, start, -9, -31, 41, -9, -31, 55, Blocks.STONE_BRICKS.getDefaultState());
        structure.fillWithBlocks(world, start, -9, -31, 59, -8, -31, 60, Blocks.STONE_BRICKS.getDefaultState());
        structure.fillWithBlocks(world, start, -9, -30, 7, -8, -30, 7, Blocks.SANDSTONE.getDefaultState());
        structure.fillWithBlocks(world, start, -9, -30, 8, -9, -30, 9, Blocks.AIR.getDefaultState());
        structure.fillWithBlocks(world, start, -9, -30, 11, -5, -30, 51, Blocks.SANDSTONE.getDefaultState());
        structure.fillWithBlocks(world, start, -9, -30, 52, -7, -29, 52, Blocks.SANDSTONE.getDefaultState());
        structure.fillWithBlocks(world, start, -9, -30, 54, -8, -30, 54, Blocks.AIR.getDefaultState());
        structure.fillWithBlocks(world, start, -9, -30, 55, -8, -30, 55, Blocks.SANDSTONE.getDefaultState());
        structure.fillWithBlocks(world, start, -9, -30, 56, -9, -30, 56, Blocks.DIRT.getDefaultState());
        structure.fillWithBlocks(world, start, -9, -30, 57, -9, -22, 57, Blocks.SANDSTONE.getDefaultState());
        structure.fillWithBlocks(world, start, -9, -30, 58, -8, -30, 58, Blocks.DIRT.getDefaultState());
        structure.fillWithBlocks(world, start, -9, -30, 59, -9, -30, 59, Blocks.AIR.getDefaultState());
        structure.fillWithBlocks(world, start, -9, -30, 68, -8, -30, 69, Blocks.SANDSTONE.getDefaultState());
        structure.fillWithBlocks(world, start, -9, -30, 73, -9, -29, 75, Blocks.SANDSTONE.getDefaultState());
        structure.fillWithBlocks(world, start, -9, -29, 4, -9, -29, 8, Blocks.STONE_BRICKS.getDefaultState());
        structure.fillWithBlocks(world, start, -9, -29, 9, -8, -29, 9, Blocks.AIR.getDefaultState());
        structure.fillWithBlocks(world, start, -9, -29, 10, -4, -29, 10, Blocks.SANDSTONE.getDefaultState());
        structure.fillWithBlocks(world, start, -9, -29, 11, -7, -29, 36, Blocks.AIR.getDefaultState());
        structure.fillWithBlocks(world, start, -9, -29, 45, -7, -29, 47, Blocks.AIR.getDefaultState());
        structure.fillWithBlocks(world, start, -9, -29, 51, -5, -25, 51, Blocks.AIR.getDefaultState());
        structure.fillWithBlocks(world, start, -9, -29, 56, -8, -29, 59, Blocks.SANDSTONE.getDefaultState());
        structure.fillWithBlocks(world, start, -9, -29, 60, -9, -29, 61, Blocks.SANDSTONE.getDefaultState());
        structure.fillWithBlocks(world, start, -9, -29, 62, -7, -29, 64, Blocks.AIR.getDefaultState());
        structure.fillWithBlocks(world, start, -9, -29, 68, -5, -25, 68, Blocks.AIR.getDefaultState());
        structure.fillWithBlocks(world, start, -9, -29, 69, -9, -29, 75, Blocks.SANDSTONE.getDefaultState());
        structure.fillWithBlocks(world, start, -9, -28, 4, -9, -24, 4, Blocks.STONE_BRICKS.getDefaultState());
        structure.fillWithBlocks(world, start, -9, -28, 6, -6, -26, 6, Blocks.STONE_BRICKS.getDefaultState());
        structure.fillWithBlocks(world, start, -9, -28, 7, -9, -27, 9, Blocks.AIR.getDefaultState());
        structure.fillWithBlocks(world, start, -9, -28, 11, -5, -28, 47, Blocks.AIR.getDefaultState());
        structure.fillWithBlocks(world, start, -9, -28, 52, -9, -28, 53, Blocks.SHROOMLIGHT.getDefaultState());
        structure.fillWithBlocks(world, start, -9, -28, 54, -9, -28, 57, Blocks.SANDSTONE.getDefaultState());
        structure.fillWithBlocks(world, start, -9, -28, 59, -8, -28, 60, Blocks.AIR.getDefaultState());
        structure.fillWithBlocks(world, start, -9, -28, 62, -7, -28, 64, Blocks.AIR.getDefaultState());
        structure.fillWithBlocks(world, start, -9, -28, 69, -9, -28, 71, Blocks.SHROOMLIGHT.getDefaultState());
        structure.fillWithBlocks(world, start, -9, -28, 72, -8, -28, 73, Blocks.SANDSTONE.getDefaultState());
        structure.fillWithBlocks(world, start, -9, -27, 10, -4, -27, 10, Blocks.SANDSTONE.getDefaultState());
        structure.fillWithBlocks(world, start, -9, -27, 11, -5, -27, 51, Blocks.AIR.getDefaultState());
        structure.fillWithBlocks(world, start, -9, -27, 52, -8, -27, 53, Blocks.SANDSTONE.getDefaultState());
        structure.fillWithBlocks(world, start, -9, -27, 55, -9, -24, 55, Blocks.SANDSTONE.getDefaultState());
        structure.fillWithBlocks(world, start, -9, -27, 58, -4, -24, 58, Blocks.SANDSTONE.getDefaultState());
        structure.fillWithBlocks(world, start, -9, -27, 59, -9, -27, 60, Blocks.AIR.getDefaultState());
        structure.fillWithBlocks(world, start, -9, -27, 61, -4, -27, 61, Blocks.SANDSTONE.getDefaultState());
        structure.fillWithBlocks(world, start, -9, -27, 62, -5, -27, 68, Blocks.AIR.getDefaultState());
        structure.fillWithBlocks(world, start, -9, -27, 69, -9, -27, 69, Blocks.SANDSTONE.getDefaultState());
        structure.fillWithBlocks(world, start, -9, -27, 70, -9, -27, 71, Blocks.AIR.getDefaultState());
        structure.fillWithBlocks(world, start, -9, -27, 72, -8, -27, 72, Blocks.DIRT.getDefaultState());
        structure.fillWithBlocks(world, start, -9, -26, 8, -9, -25, 9, Blocks.AIR.getDefaultState());
        structure.fillWithBlocks(world, start, -9, -26, 11, -5, -26, 51, Blocks.AIR.getDefaultState());
        structure.fillWithBlocks(world, start, -9, -26, 52, -9, -26, 53, Blocks.SHROOMLIGHT.getDefaultState());
        structure.fillWithBlocks(world, start, -9, -26, 54, -9, -25, 54, Blocks.AIR.getDefaultState());
        structure.fillWithBlocks(world, start, -9, -26, 59, -9, -26, 61, Blocks.SHROOMLIGHT.getDefaultState());
        structure.fillWithBlocks(world, start, -9, -26, 62, -5, -26, 68, Blocks.AIR.getDefaultState());
        structure.fillWithBlocks(world, start, -9, -26, 69, -9, -26, 71, Blocks.SHROOMLIGHT.getDefaultState());
        structure.fillWithBlocks(world, start, -9, -26, 72, -9, -24, 75, Blocks.SANDSTONE.getDefaultState());
        structure.fillWithBlocks(world, start, -9, -25, 7, -7, -25, 7, Blocks.DIRT.getDefaultState());
        structure.fillWithBlocks(world, start, -9, -25, 10, -4, -25, 10, Blocks.SANDSTONE.getDefaultState());
        structure.fillWithBlocks(world, start, -9, -25, 11, -5, -25, 51, Blocks.AIR.getDefaultState());
        structure.fillWithBlocks(world, start, -9, -25, 52, -9, -25, 52, Blocks.SANDSTONE.getDefaultState());
        structure.fillWithBlocks(world, start, -9, -25, 53, -9, -25, 54, Blocks.AIR.getDefaultState());
        structure.fillWithBlocks(world, start, -9, -25, 56, -7, -25, 58, Blocks.SANDSTONE.getDefaultState());
        structure.fillWithBlocks(world, start, -9, -25, 59, -9, -25, 60, Blocks.AIR.getDefaultState());
        structure.fillWithBlocks(world, start, -9, -25, 61, -7, -24, 61, Blocks.SANDSTONE.getDefaultState());
        structure.fillWithBlocks(world, start, -9, -25, 62, -5, -25, 68, Blocks.AIR.getDefaultState());
        structure.fillWithBlocks(world, start, -9, -25, 69, -9, -25, 69, Blocks.SANDSTONE.getDefaultState());
        structure.fillWithBlocks(world, start, -9, -25, 70, -9, -25, 71, Blocks.AIR.getDefaultState());
        structure.fillWithBlocks(world, start, -9, -24, 5, -9, -24, 6, Blocks.STONE_BRICKS.getDefaultState());
        structure.fillWithBlocks(world, start, -9, -24, 9, -9, -24, 9, Blocks.SANDSTONE.getDefaultState());
        structure.fillWithBlocks(world, start, -9, -24, 10, -9, -21, 10, Blocks.STONE_BRICKS.getDefaultState());
        structure.fillWithBlocks(world, start, -9, -24, 11, -5, -24, 23, Blocks.SANDSTONE.getDefaultState());
        structure.fillWithBlocks(world, start, -9, -24, 28, -9, -24, 52, Blocks.SANDSTONE.getDefaultState());
        structure.fillWithBlocks(world, start, -9, -24, 54, -9, -24, 55, Blocks.SANDSTONE.getDefaultState());
        structure.fillWithBlocks(world, start, -9, -24, 59, -9, -24, 59, Blocks.SANDSTONE.getDefaultState());
        structure.fillWithBlocks(world, start, -9, -24, 62, -2, -24, 69, Blocks.SANDSTONE.getDefaultState());
        structure.fillWithBlocks(world, start, -9, -23, 5, -9, -22, 10, Blocks.STONE_BRICKS.getDefaultState());
        structure.fillWithBlocks(world, start, -9, -23, 11, -8, -23, 11, Blocks.STONE_BRICKS.getDefaultState());
        structure.fillWithBlocks(world, start, -9, -23, 17, -8, -23, 17, Blocks.SANDSTONE.getDefaultState());
        structure.fillWithBlocks(world, start, -9, -23, 19, -9, -23, 27, Blocks.SANDSTONE.getDefaultState());
        structure.fillWithBlocks(world, start, -9, -23, 29, -6, -23, 36, Blocks.SANDSTONE.getDefaultState());
        structure.fillWithBlocks(world, start, -9, -23, 40, -9, -23, 43, Blocks.SANDSTONE.getDefaultState());
        structure.fillWithBlocks(world, start, -9, -23, 45, -9, -21, 45, Blocks.DIRT.getDefaultState());
        structure.fillWithBlocks(world, start, -9, -23, 47, -9, -23, 48, Blocks.AIR.getDefaultState());
        structure.fillWithBlocks(world, start, -9, -23, 49, -7, -23, 51, Blocks.SANDSTONE.getDefaultState());
        structure.fillWithBlocks(world, start, -9, -23, 52, -9, -23, 54, Blocks.SANDSTONE.getDefaultState());
        structure.fillWithBlocks(world, start, -9, -23, 56, -8, -23, 57, Blocks.SANDSTONE.getDefaultState());
        structure.fillWithBlocks(world, start, -9, -23, 59, -9, -21, 64, Blocks.SANDSTONE.getDefaultState());
        structure.fillWithBlocks(world, start, -9, -23, 65, -9, -23, 65, Blocks.DIRT.getDefaultState());
        structure.fillWithBlocks(world, start, -9, -23, 66, -9, -23, 69, Blocks.SANDSTONE.getDefaultState());
        structure.fillWithBlocks(world, start, -9, -23, 71, -8, -23, 72, Blocks.SANDSTONE.getDefaultState());
        structure.fillWithBlocks(world, start, -9, -23, 73, -8, -23, 73, Blocks.DIRT.getDefaultState());
        structure.fillWithBlocks(world, start, -9, -23, 74, -5, -21, 74, Blocks.SANDSTONE.getDefaultState());
        structure.fillWithBlocks(world, start, -9, -22, 11, -9, -22, 13, Blocks.DIRT.getDefaultState());
        structure.fillWithBlocks(world, start, -9, -22, 14, -9, -22, 14, Blocks.STONE_BRICKS.getDefaultState());
        structure.fillWithBlocks(world, start, -9, -22, 16, -9, -22, 16, Blocks.STONE_BRICKS.getDefaultState());
        structure.fillWithBlocks(world, start, -9, -22, 18, -9, -22, 19, Blocks.DIRT.getDefaultState());
        structure.fillWithBlocks(world, start, -9, -22, 20, -8, -22, 30, Blocks.SANDSTONE.getDefaultState());
        structure.fillWithBlocks(world, start, -9, -22, 32, -8, -22, 33, Blocks.SANDSTONE.getDefaultState());
        structure.fillWithBlocks(world, start, -9, -22, 34, -8, -22, 34, Blocks.AIR.getDefaultState());
        structure.fillWithBlocks(world, start, -9, -22, 39, -7, -22, 42, Blocks.SANDSTONE.getDefaultState());
        structure.fillWithBlocks(world, start, -9, -22, 48, -8, -22, 49, Blocks.SANDSTONE.getDefaultState());
        structure.fillWithBlocks(world, start, -9, -22, 50, -9, -20, 50, Blocks.SANDSTONE.getDefaultState());
        structure.fillWithBlocks(world, start, -9, -22, 52, -9, -20, 54, Blocks.SANDSTONE.getDefaultState());
        structure.fillWithBlocks(world, start, -9, -22, 56, -8, -22, 57, Blocks.SANDSTONE.getDefaultState());
        structure.fillWithBlocks(world, start, -9, -22, 58, -9, -22, 65, Blocks.SANDSTONE.getDefaultState());
        structure.fillWithBlocks(world, start, -9, -22, 66, -8, -22, 66, Blocks.AIR.getDefaultState());
        structure.fillWithBlocks(world, start, -9, -22, 68, -9, -21, 75, Blocks.SANDSTONE.getDefaultState());
        structure.fillWithBlocks(world, start, -9, -21, 4, -9, -21, 6, Blocks.STONE_BRICKS.getDefaultState());
        structure.fillWithBlocks(world, start, -9, -21, 9, -8, -21, 10, Blocks.STONE_BRICKS.getDefaultState());
        structure.fillWithBlocks(world, start, -9, -21, 12, -9, -21, 12, Blocks.STONE_BRICKS.getDefaultState());
        structure.fillWithBlocks(world, start, -9, -21, 14, -9, -21, 14, Blocks.STONE_BRICKS.getDefaultState());
        structure.fillWithBlocks(world, start, -9, -21, 18, -6, -21, 18, Blocks.STONE_BRICKS.getDefaultState());
        structure.fillWithBlocks(world, start, -9, -21, 19, -9, -21, 20, Blocks.SANDSTONE.getDefaultState());
        structure.fillWithBlocks(world, start, -9, -21, 21, -9, -21, 22, Blocks.DIRT.getDefaultState());
        structure.fillWithBlocks(world, start, -9, -21, 28, -8, -21, 29, Blocks.SANDSTONE.getDefaultState());
        structure.fillWithBlocks(world, start, -9, -21, 32, -9, -21, 43, Blocks.SANDSTONE.getDefaultState());
        structure.fillWithBlocks(world, start, -9, -21, 44, -9, -21, 45, Blocks.DIRT.getDefaultState());
        structure.fillWithBlocks(world, start, -9, -21, 46, -9, -20, 46, Blocks.SANDSTONE.getDefaultState());
        structure.fillWithBlocks(world, start, -9, -21, 55, -9, -21, 56, Blocks.SANDSTONE.getDefaultState());
        structure.fillWithBlocks(world, start, -9, -21, 58, -8, -21, 59, Blocks.SANDSTONE.getDefaultState());
        structure.fillWithBlocks(world, start, -9, -21, 65, -9, -21, 65, Blocks.SANDSTONE.getDefaultState());
        structure.fillWithBlocks(world, start, -9, -21, 67, -9, -21, 75, Blocks.SANDSTONE.getDefaultState());
        structure.fillWithBlocks(world, start, -9, -20, 44, -9, -20, 44, Blocks.SANDSTONE.getDefaultState());
        structure.fillWithBlocks(world, start, -9, -20, 47, -6, -20, 50, Blocks.SANDSTONE.getDefaultState());
        structure.fillWithBlocks(world, start, -9, -20, 51, -9, -20, 54, Blocks.SANDSTONE.getDefaultState());
        structure.fillWithBlocks(world, start, -9, -19, 45, -9, -19, 45, Blocks.SANDSTONE.getDefaultState());
        structure.fillWithBlocks(world, start, -9, -19, 46, -9, -19, 50, Blocks.AIR.getDefaultState());
        structure.fillWithBlocks(world, start, -9, -19, 51, -8, -19, 52, Blocks.SANDSTONE.getDefaultState());
        structure.fillWithBlocks(world, start, -9, -18, 42, -8, -18, 43, Blocks.SANDSTONE.getDefaultState());
        structure.fillWithBlocks(world, start, -9, -18, 45, -9, -18, 45, Blocks.SANDSTONE.getDefaultState());
        structure.fillWithBlocks(world, start, -9, -18, 46, -9, -18, 50, Blocks.AIR.getDefaultState());
        structure.fillWithBlocks(world, start, -9, -18, 51, -7, -18, 54, Blocks.SANDSTONE.getDefaultState());
        structure.fillWithBlocks(world, start, -9, -17, 42, -7, -17, 45, Blocks.SANDSTONE.getDefaultState());
        structure.fillWithBlocks(world, start, -9, -17, 46, -9, -17, 50, Blocks.AIR.getDefaultState());
        structure.fillWithBlocks(world, start, -9, -17, 51, -8, -17, 53, Blocks.SANDSTONE.getDefaultState());
        structure.fillWithBlocks(world, start, -9, -16, 45, -9, -16, 45, Blocks.SANDSTONE.getDefaultState());
        structure.fillWithBlocks(world, start, -9, -16, 46, -9, -16, 50, Blocks.AIR.getDefaultState());
        structure.fillWithBlocks(world, start, -9, -16, 51, -9, -16, 54, Blocks.SANDSTONE.getDefaultState());
        structure.fillWithBlocks(world, start, -9, -15, 47, -6, -15, 51, Blocks.SANDSTONE.getDefaultState());
        structure.fillWithBlocks(world, start, -9, -15, 52, -9, -14, 52, Blocks.AIR.getDefaultState());
        structure.fillWithBlocks(world, start, -9, -15, 53, -8, -15, 54, Blocks.SANDSTONE.getDefaultState());
        structure.fillWithBlocks(world, start, -9, -14, 49, -9, -14, 50, Blocks.AIR.getDefaultState());
        structure.fillWithBlocks(world, start, -9, -14, 51, -9, -14, 51, Blocks.SANDSTONE.getDefaultState());
        structure.fillWithBlocks(world, start, -9, -14, 53, -8, -14, 54, Blocks.SANDSTONE.getDefaultState());
        structure.fillWithBlocks(world, start, -9, -12, 46, -7, -12, 54, Blocks.SANDSTONE.getDefaultState());
        structure.fillWithBlocks(world, start, -9, -11, 42, -7, -11, 53, Blocks.SANDSTONE.getDefaultState());
        structure.fillWithBlocks(world, start, -8, -50, 40, -8, -44, 46, Blocks.SANDSTONE.getDefaultState());
        structure.fillWithBlocks(world, start, -8, -49, 47, -6, -49, 49, Blocks.AIR.getDefaultState());
        structure.fillWithBlocks(world, start, -8, -49, 50, -7, -49, 51, Blocks.SANDSTONE.getDefaultState());
        structure.fillWithBlocks(world, start, -8, -49, 52, -8, -45, 56, Blocks.SANDSTONE.getDefaultState());
        structure.fillWithBlocks(world, start, -8, -48, 47, -6, -48, 49, Blocks.AIR.getDefaultState());
        structure.fillWithBlocks(world, start, -8, -48, 50, -7, -48, 51, Blocks.SANDSTONE.getDefaultState());
        structure.fillWithBlocks(world, start, -8, -47, 47, -6, -47, 49, Blocks.AIR.getDefaultState());
        structure.fillWithBlocks(world, start, -8, -47, 50, -7, -47, 51, Blocks.SANDSTONE.getDefaultState());
        structure.fillWithBlocks(world, start, -8, -46, 47, -5, -46, 50, Blocks.SANDSTONE.getDefaultState());
        structure.fillWithBlocks(world, start, -8, -46, 51, -8, -42, 56, Blocks.SANDSTONE.getDefaultState());
        structure.fillWithBlocks(world, start, -8, -41, 42, -7, -41, 43, Blocks.STONE_BRICKS.getDefaultState());
        structure.fillWithBlocks(world, start, -8, -40, 30, -6, -40, 34, Blocks.STONE_BRICKS.getDefaultState());
        structure.fillWithBlocks(world, start, -8, -40, 50, -7, -40, 51, Blocks.STONE_BRICKS.getDefaultState());
        structure.fillWithBlocks(world, start, -8, -40, 55, -8, -40, 56, Blocks.STONE_BRICKS.getDefaultState());
        structure.fillWithBlocks(world, start, -8, -40, 58, -6, -38, 58, Blocks.STONE_BRICKS.getDefaultState());
        structure.fillWithBlocks(world, start, -8, -40, 59, -7, -40, 59, Blocks.AIR.getDefaultState());
        structure.fillWithBlocks(world, start, -8, -40, 60, -8, -40, 60, Blocks.STONE_BRICKS.getDefaultState());
        structure.fillWithBlocks(world, start, -8, -39, 27, -8, -39, 28, Blocks.AIR.getDefaultState());
        structure.fillWithBlocks(world, start, -8, -39, 29, -7, -39, 31, Blocks.STONE_BRICKS.getDefaultState());
        structure.fillWithBlocks(world, start, -8, -39, 33, -6, -39, 36, Blocks.STONE_BRICKS.getDefaultState());
        structure.fillWithBlocks(world, start, -8, -38, 25, -8, -37, 25, Blocks.AIR.getDefaultState());
        structure.fillWithBlocks(world, start, -8, -38, 26, -7, -38, 30, Blocks.STONE_BRICKS.getDefaultState());
        structure.fillWithBlocks(world, start, -8, -38, 31, -8, -38, 40, Blocks.STONE_BRICKS.getDefaultState());
        structure.fillWithBlocks(world, start, -8, -38, 56, -8, -38, 56, Blocks.STONE_BRICKS.getDefaultState());
        structure.fillWithBlocks(world, start, -8, -38, 59, -7, -38, 60, Blocks.STONE_BRICKS.getDefaultState());
        structure.fillWithBlocks(world, start, -8, -37, 24, -8, -37, 25, Blocks.AIR.getDefaultState());
        structure.fillWithBlocks(world, start, -8, -37, 26, -6, -37, 28, Blocks.STONE_BRICKS.getDefaultState());
        structure.fillWithBlocks(world, start, -8, -37, 30, -7, -37, 32, Blocks.STONE_BRICKS.getDefaultState());
        structure.fillWithBlocks(world, start, -8, -37, 33, -8, -37, 34, Blocks.AIR.getDefaultState());
        structure.fillWithBlocks(world, start, -8, -37, 35, -7, -37, 36, Blocks.STONE_BRICKS.getDefaultState());
        structure.fillWithBlocks(world, start, -8, -37, 56, -7, -37, 57, Blocks.STONE_BRICKS.getDefaultState());
        structure.fillWithBlocks(world, start, -8, -37, 58, -8, -37, 60, Blocks.STONE_BRICKS.getDefaultState());
        structure.fillWithBlocks(world, start, -8, -36, 21, -8, -36, 21, Blocks.STONE_BRICKS.getDefaultState());
        structure.fillWithBlocks(world, start, -8, -36, 23, -8, -36, 23, Blocks.STONE_BRICKS.getDefaultState());
        structure.fillWithBlocks(world, start, -8, -36, 25, -7, -36, 36, Blocks.STONE_BRICKS.getDefaultState());
        structure.fillWithBlocks(world, start, -8, -36, 38, -6, -36, 40, Blocks.STONE_BRICKS.getDefaultState());
        structure.fillWithBlocks(world, start, -8, -36, 56, -6, -36, 58, Blocks.STONE_BRICKS.getDefaultState());
        structure.fillWithBlocks(world, start, -8, -35, 21, -7, -35, 22, Blocks.STONE_BRICKS.getDefaultState());
        structure.fillWithBlocks(world, start, -8, -35, 24, -7, -35, 25, Blocks.STONE_BRICKS.getDefaultState());
        structure.fillWithBlocks(world, start, -8, -35, 38, -7, -35, 41, Blocks.STONE_BRICKS.getDefaultState());
        structure.fillWithBlocks(world, start, -8, -35, 56, -7, -35, 57, Blocks.STONE_BRICKS.getDefaultState());
        structure.fillWithBlocks(world, start, -8, -35, 58, -8, -35, 59, Blocks.AIR.getDefaultState());
        structure.fillWithBlocks(world, start, -8, -35, 60, -8, -35, 60, Blocks.STONE_BRICKS.getDefaultState());
        structure.fillWithBlocks(world, start, -8, -34, 21, -6, -34, 23, Blocks.STONE_BRICKS.getDefaultState());
        structure.fillWithBlocks(world, start, -8, -34, 24, -8, -31, 24, Blocks.STONE_BRICKS.getDefaultState());
        structure.fillWithBlocks(world, start, -8, -34, 26, -6, -34, 30, Blocks.STONE_BRICKS.getDefaultState());
        structure.fillWithBlocks(world, start, -8, -34, 31, -8, -34, 32, Blocks.AIR.getDefaultState());
        structure.fillWithBlocks(world, start, -8, -34, 33, -4, -34, 37, Blocks.STONE_BRICKS.getDefaultState());
        structure.fillWithBlocks(world, start, -8, -34, 38, -8, -31, 41, Blocks.STONE_BRICKS.getDefaultState());
        structure.fillWithBlocks(world, start, -8, -34, 44, -7, -34, 47, Blocks.STONE_BRICKS.getDefaultState());
        structure.fillWithBlocks(world, start, -8, -34, 49, -7, -34, 50, Blocks.STONE_BRICKS.getDefaultState());
        structure.fillWithBlocks(world, start, -8, -34, 54, -1, -33, 54, Blocks.STONE_BRICKS.getDefaultState());
        structure.fillWithBlocks(world, start, -8, -34, 60, -8, -34, 60, Blocks.STONE_BRICKS.getDefaultState());
        structure.fillWithBlocks(world, start, -8, -33, 21, -7, -33, 28, Blocks.STONE_BRICKS.getDefaultState());
        structure.fillWithBlocks(world, start, -8, -33, 30, -7, -33, 31, Blocks.STONE_BRICKS.getDefaultState());
        structure.fillWithBlocks(world, start, -8, -33, 32, -8, -33, 35, Blocks.STONE_BRICKS.getDefaultState());
        structure.fillWithBlocks(world, start, -8, -33, 36, -8, -33, 36, Blocks.AIR.getDefaultState());
        structure.fillWithBlocks(world, start, -8, -33, 37, -8, -32, 50, Blocks.STONE_BRICKS.getDefaultState());
        structure.fillWithBlocks(world, start, -8, -33, 51, -8, -33, 51, Blocks.AIR.getDefaultState());
        structure.fillWithBlocks(world, start, -8, -33, 53, -8, -33, 54, Blocks.STONE_BRICKS.getDefaultState());
        structure.fillWithBlocks(world, start, -8, -33, 55, -8, -33, 57, Blocks.AIR.getDefaultState());
        structure.fillWithBlocks(world, start, -8, -32, 21, -7, -32, 30, Blocks.STONE_BRICKS.getDefaultState());
        structure.fillWithBlocks(world, start, -8, -32, 31, -8, -32, 33, Blocks.STONE_BRICKS.getDefaultState());
        structure.fillWithBlocks(world, start, -8, -32, 35, -5, -32, 43, Blocks.STONE_BRICKS.getDefaultState());
        structure.fillWithBlocks(world, start, -8, -32, 51, -6, -32, 53, Blocks.STONE_BRICKS.getDefaultState());
        structure.fillWithBlocks(world, start, -8, -32, 60, -8, -32, 60, Blocks.STONE_BRICKS.getDefaultState());
        structure.fillWithBlocks(world, start, -8, -31, 21, -4, -31, 25, Blocks.STONE_BRICKS.getDefaultState());
        structure.fillWithBlocks(world, start, -8, -31, 28, -6, -31, 31, Blocks.STONE_BRICKS.getDefaultState());
        structure.fillWithBlocks(world, start, -8, -31, 32, -8, -31, 33, Blocks.STONE_BRICKS.getDefaultState());
        structure.fillWithBlocks(world, start, -8, -31, 34, -7, -31, 34, Blocks.AIR.getDefaultState());
        structure.fillWithBlocks(world, start, -8, -31, 35, -7, -31, 36, Blocks.STONE_BRICKS.getDefaultState());
        structure.fillWithBlocks(world, start, -8, -31, 43, -6, -31, 45, Blocks.STONE_BRICKS.getDefaultState());
        structure.fillWithBlocks(world, start, -8, -31, 50, -8, -31, 50, Blocks.STONE_BRICKS.getDefaultState());
        structure.fillWithBlocks(world, start, -8, -31, 52, -8, -31, 53, Blocks.STONE_BRICKS.getDefaultState());
        structure.fillWithBlocks(world, start, -8, -31, 54, -8, -30, 54, Blocks.AIR.getDefaultState());
        structure.fillWithBlocks(world, start, -8, -31, 55, -6, -31, 58, Blocks.STONE_BRICKS.getDefaultState());
        structure.fillWithBlocks(world, start, -8, -30, 5, -8, -30, 6, Blocks.AIR.getDefaultState());
        structure.fillWithBlocks(world, start, -8, -30, 8, -8, -30, 9, Blocks.DIRT.getDefaultState());
        structure.fillWithBlocks(world, start, -8, -30, 10, -7, -30, 52, Blocks.SANDSTONE.getDefaultState());
        structure.fillWithBlocks(world, start, -8, -30, 53, -8, -30, 54, Blocks.AIR.getDefaultState());
        structure.fillWithBlocks(world, start, -8, -30, 56, -8, -30, 56, Blocks.AIR.getDefaultState());
        structure.fillWithBlocks(world, start, -8, -30, 57, -8, -30, 58, Blocks.DIRT.getDefaultState());
        structure.fillWithBlocks(world, start, -8, -30, 59, -8, -30, 61, Blocks.AIR.getDefaultState());
        structure.fillWithBlocks(world, start, -8, -30, 70, -7, -30, 70, Blocks.SANDSTONE.getDefaultState());
        structure.fillWithBlocks(world, start, -8, -30, 73, -8, -30, 73, Blocks.SANDSTONE.getDefaultState());
        structure.fillWithBlocks(world, start, -8, -30, 74, -8, -29, 74, Blocks.AIR.getDefaultState());
        structure.fillWithBlocks(world, start, -8, -29, 4, -8, -27, 4, Blocks.SANDSTONE.getDefaultState());
        structure.fillWithBlocks(world, start, -8, -29, 5, -8, -27, 5, Blocks.STONE_BRICKS.getDefaultState());
        structure.fillWithBlocks(world, start, -8, -29, 7, -8, -29, 7, Blocks.STONE_BRICKS.getDefaultState());
        structure.fillWithBlocks(world, start, -8, -29, 8, -8, -29, 8, Blocks.SANDSTONE.getDefaultState());
        structure.fillWithBlocks(world, start, -8, -29, 53, -7, -29, 54, Blocks.SANDSTONE.getDefaultState());
        structure.fillWithBlocks(world, start, -8, -29, 61, -4, -29, 61, Blocks.SANDSTONE.getDefaultState());
        structure.fillWithBlocks(world, start, -8, -29, 69, -8, -29, 69, Blocks.SANDSTONE.getDefaultState());
        structure.fillWithBlocks(world, start, -8, -29, 71, -8, -29, 73, Blocks.SANDSTONE.getDefaultState());
        structure.fillWithBlocks(world, start, -8, -28, 7, -8, -28, 7, Blocks.AIR.getDefaultState());
        structure.fillWithBlocks(world, start, -8, -28, 8, -8, -28, 9, Blocks.STONE_BRICKS.getDefaultState());
        structure.fillWithBlocks(world, start, -8, -28, 10, -8, -24, 10, Blocks.SANDSTONE.getDefaultState());
        structure.fillWithBlocks(world, start, -8, -28, 52, -8, -27, 53, Blocks.SANDSTONE.getDefaultState());
        structure.fillWithBlocks(world, start, -8, -28, 55, -7, -28, 56, Blocks.SANDSTONE.getDefaultState());
        structure.fillWithBlocks(world, start, -8, -28, 58, -4, -24, 58, Blocks.SANDSTONE.getDefaultState());
        structure.fillWithBlocks(world, start, -8, -28, 61, -8, -24, 61, Blocks.SANDSTONE.getDefaultState());
        structure.fillWithBlocks(world, start, -8, -28, 69, -8, -28, 70, Blocks.SANDSTONE.getDefaultState());
        structure.fillWithBlocks(world, start, -8, -28, 74, -8, -28, 75, Blocks.SANDSTONE.getDefaultState());
        structure.fillWithBlocks(world, start, -8, -27, 7, -8, -26, 7, Blocks.STONE_BRICKS.getDefaultState());
        structure.fillWithBlocks(world, start, -8, -27, 9, -8, -24, 9, Blocks.STONE_BRICKS.getDefaultState());
        structure.fillWithBlocks(world, start, -8, -27, 54, -8, -27, 55, Blocks.AIR.getDefaultState());
        structure.fillWithBlocks(world, start, -8, -27, 56, -8, -25, 58, Blocks.SANDSTONE.getDefaultState());
        structure.fillWithBlocks(world, start, -8, -27, 60, -7, -27, 60, Blocks.AIR.getDefaultState());
        structure.fillWithBlocks(world, start, -8, -27, 69, -8, -26, 70, Blocks.SANDSTONE.getDefaultState());
        structure.fillWithBlocks(world, start, -8, -27, 71, -8, -27, 71, Blocks.SANDSTONE.getDefaultState());
        structure.fillWithBlocks(world, start, -8, -26, 4, -8, -25, 4, Blocks.STONE_BRICKS.getDefaultState());
        structure.fillWithBlocks(world, start, -8, -26, 5, -8, -25, 5, Blocks.AIR.getDefaultState());
        structure.fillWithBlocks(world, start, -8, -26, 8, -8, -25, 8, Blocks.SANDSTONE.getDefaultState());
        structure.fillWithBlocks(world, start, -8, -26, 52, -8, -24, 52, Blocks.SANDSTONE.getDefaultState());
        structure.fillWithBlocks(world, start, -8, -26, 54, -8, -26, 54, Blocks.SANDSTONE.getDefaultState());
        structure.fillWithBlocks(world, start, -8, -26, 59, -8, -24, 61, Blocks.SANDSTONE.getDefaultState());
        structure.fillWithBlocks(world, start, -8, -26, 72, -8, -26, 72, Blocks.SANDSTONE.getDefaultState());
        structure.fillWithBlocks(world, start, -8, -26, 74, -8, -25, 75, Blocks.SANDSTONE.getDefaultState());
        structure.fillWithBlocks(world, start, -8, -25, 6, -8, -25, 7, Blocks.DIRT.getDefaultState());
        structure.fillWithBlocks(world, start, -8, -25, 53, -8, -23, 53, Blocks.SANDSTONE.getDefaultState());
        structure.fillWithBlocks(world, start, -8, -25, 54, -7, -25, 54, Blocks.AIR.getDefaultState());
        structure.fillWithBlocks(world, start, -8, -25, 55, -6, -25, 58, Blocks.SANDSTONE.getDefaultState());
        structure.fillWithBlocks(world, start, -8, -25, 69, -8, -23, 72, Blocks.SANDSTONE.getDefaultState());
        structure.fillWithBlocks(world, start, -8, -25, 73, -7, -25, 75, Blocks.SANDSTONE.getDefaultState());
        structure.fillWithBlocks(world, start, -8, -24, 4, -8, -24, 4, Blocks.AIR.getDefaultState());
        structure.fillWithBlocks(world, start, -8, -24, 5, -8, -23, 5, Blocks.DIRT.getDefaultState());
        structure.fillWithBlocks(world, start, -8, -24, 6, -8, -24, 9, Blocks.STONE_BRICKS.getDefaultState());
        structure.fillWithBlocks(world, start, -8, -24, 24, -6, -24, 38, Blocks.AIR.getDefaultState());
        structure.fillWithBlocks(world, start, -8, -24, 39, -2, -24, 47, Blocks.SANDSTONE.getDefaultState());
        structure.fillWithBlocks(world, start, -8, -24, 48, -5, -24, 52, Blocks.SANDSTONE.getDefaultState());
        structure.fillWithBlocks(world, start, -8, -24, 54, -8, -22, 54, Blocks.AIR.getDefaultState());
        structure.fillWithBlocks(world, start, -8, -24, 55, -8, -24, 75, Blocks.SANDSTONE.getDefaultState());
        structure.fillWithBlocks(world, start, -8, -23, 4, -8, -23, 4, Blocks.STONE_BRICKS.getDefaultState());
        structure.fillWithBlocks(world, start, -8, -23, 6, -8, -22, 6, Blocks.SANDSTONE.getDefaultState());
        structure.fillWithBlocks(world, start, -8, -23, 7, -8, -23, 7, Blocks.STONE_BRICKS.getDefaultState());
        structure.fillWithBlocks(world, start, -8, -23, 9, -7, -23, 9, Blocks.SANDSTONE.getDefaultState());
        structure.fillWithBlocks(world, start, -8, -23, 10, -8, -22, 11, Blocks.STONE_BRICKS.getDefaultState());
        structure.fillWithBlocks(world, start, -8, -23, 14, -8, -21, 14, Blocks.STONE_BRICKS.getDefaultState());
        structure.fillWithBlocks(world, start, -8, -23, 16, -8, -21, 16, Blocks.STONE_BRICKS.getDefaultState());
        structure.fillWithBlocks(world, start, -8, -23, 19, -8, -23, 20, Blocks.DIRT.getDefaultState());
        structure.fillWithBlocks(world, start, -8, -23, 25, -8, -23, 39, Blocks.SANDSTONE.getDefaultState());
        structure.fillWithBlocks(world, start, -8, -23, 41, -3, -22, 41, Blocks.SANDSTONE.getDefaultState());
        structure.fillWithBlocks(world, start, -8, -23, 42, -7, -23, 42, Blocks.DIRT.getDefaultState());
        structure.fillWithBlocks(world, start, -8, -23, 43, -7, -23, 45, Blocks.SANDSTONE.getDefaultState());
        structure.fillWithBlocks(world, start, -8, -23, 48, -7, -23, 51, Blocks.SANDSTONE.getDefaultState());
        structure.fillWithBlocks(world, start, -8, -23, 55, -7, -23, 56, Blocks.SANDSTONE.getDefaultState());
        structure.fillWithBlocks(world, start, -8, -23, 58, -7, -23, 59, Blocks.SANDSTONE.getDefaultState());
        structure.fillWithBlocks(world, start, -8, -23, 60, -8, -23, 61, Blocks.DIRT.getDefaultState());
        structure.fillWithBlocks(world, start, -8, -23, 62, -8, -23, 64, Blocks.SANDSTONE.getDefaultState());
        structure.fillWithBlocks(world, start, -8, -23, 65, -8, -23, 66, Blocks.DIRT.getDefaultState());
        structure.fillWithBlocks(world, start, -8, -23, 67, -7, -23, 69, Blocks.SANDSTONE.getDefaultState());
        structure.fillWithBlocks(world, start, -8, -22, 5, -8, -22, 5, Blocks.STONE_BRICKS.getDefaultState());
        structure.fillWithBlocks(world, start, -8, -22, 7, -8, -22, 8, Blocks.SANDSTONE.getDefaultState());
        structure.fillWithBlocks(world, start, -8, -22, 12, -7, -22, 15, Blocks.STONE_BRICKS.getDefaultState());
        structure.fillWithBlocks(world, start, -8, -22, 17, -7, -22, 18, Blocks.STONE_BRICKS.getDefaultState());
        structure.fillWithBlocks(world, start, -8, -22, 19, -8, -22, 33, Blocks.SANDSTONE.getDefaultState());
        structure.fillWithBlocks(world, start, -8, -22, 35, -8, -21, 35, Blocks.DIRT.getDefaultState());
        structure.fillWithBlocks(world, start, -8, -22, 36, -8, -22, 42, Blocks.SANDSTONE.getDefaultState());
        structure.fillWithBlocks(world, start, -8, -22, 44, -7, -22, 44, Blocks.SANDSTONE.getDefaultState());
        structure.fillWithBlocks(world, start, -8, -22, 45, -7, -22, 45, Blocks.DIRT.getDefaultState());
        structure.fillWithBlocks(world, start, -8, -22, 47, -6, -22, 49, Blocks.SANDSTONE.getDefaultState());
        structure.fillWithBlocks(world, start, -8, -22, 51, -7, -22, 52, Blocks.SANDSTONE.getDefaultState());
        structure.fillWithBlocks(world, start, -8, -22, 53, -7, -22, 53, Blocks.DIRT.getDefaultState());
        structure.fillWithBlocks(world, start, -8, -22, 59, -8, -22, 62, Blocks.SANDSTONE.getDefaultState());
        structure.fillWithBlocks(world, start, -8, -22, 65, -8, -21, 65, Blocks.DIRT.getDefaultState());
        structure.fillWithBlocks(world, start, -8, -22, 67, -8, -22, 67, Blocks.SANDSTONE.getDefaultState());
        structure.fillWithBlocks(world, start, -8, -22, 68, -8, -22, 69, Blocks.AIR.getDefaultState());
        structure.fillWithBlocks(world, start, -8, -22, 71, -6, -21, 71, Blocks.SANDSTONE.getDefaultState());
        structure.fillWithBlocks(world, start, -8, -22, 72, -8, -22, 73, Blocks.AIR.getDefaultState());
        structure.fillWithBlocks(world, start, -8, -22, 75, -2, -22, 75, Blocks.SANDSTONE.getDefaultState());
        structure.fillWithBlocks(world, start, -8, -21, 4, -8, -21, 4, Blocks.STONE_BRICKS.getDefaultState());
        structure.fillWithBlocks(world, start, -8, -21, 7, -8, -21, 11, Blocks.STONE_BRICKS.getDefaultState());
        structure.fillWithBlocks(world, start, -8, -21, 13, -7, -21, 16, Blocks.STONE_BRICKS.getDefaultState());
        structure.fillWithBlocks(world, start, -8, -21, 17, -8, -21, 18, Blocks.STONE_BRICKS.getDefaultState());
        structure.fillWithBlocks(world, start, -8, -21, 19, -8, -21, 19, Blocks.SANDSTONE.getDefaultState());
        structure.fillWithBlocks(world, start, -8, -21, 21, -8, -21, 21, Blocks.SANDSTONE.getDefaultState());
        structure.fillWithBlocks(world, start, -8, -21, 23, -8, -21, 23, Blocks.SANDSTONE.getDefaultState());
        structure.fillWithBlocks(world, start, -8, -21, 25, -7, -21, 30, Blocks.SANDSTONE.getDefaultState());
        structure.fillWithBlocks(world, start, -8, -21, 31, -8, -21, 32, Blocks.AIR.getDefaultState());
        structure.fillWithBlocks(world, start, -8, -21, 33, -7, -21, 34, Blocks.SANDSTONE.getDefaultState());
        structure.fillWithBlocks(world, start, -8, -21, 37, -7, -21, 40, Blocks.SANDSTONE.getDefaultState());
        structure.fillWithBlocks(world, start, -8, -21, 41, -8, -21, 43, Blocks.SANDSTONE.getDefaultState());
        structure.fillWithBlocks(world, start, -8, -21, 44, -8, -21, 44, Blocks.DIRT.getDefaultState());
        structure.fillWithBlocks(world, start, -8, -21, 45, -8, -11, 45, Blocks.SANDSTONE.getDefaultState());
        structure.fillWithBlocks(world, start, -8, -21, 46, -8, -21, 46, Blocks.AIR.getDefaultState());
        structure.fillWithBlocks(world, start, -8, -21, 47, -8, -21, 49, Blocks.SANDSTONE.getDefaultState());
        structure.fillWithBlocks(world, start, -8, -21, 51, -7, -21, 55, Blocks.SANDSTONE.getDefaultState());
        structure.fillWithBlocks(world, start, -8, -21, 57, -6, -21, 59, Blocks.SANDSTONE.getDefaultState());
        structure.fillWithBlocks(world, start, -8, -21, 60, -7, -21, 60, Blocks.AIR.getDefaultState());
        structure.fillWithBlocks(world, start, -8, -21, 66, -8, -21, 66, Blocks.SANDSTONE.getDefaultState());
        structure.fillWithBlocks(world, start, -8, -21, 68, -7, -21, 68, Blocks.SANDSTONE.getDefaultState());
        structure.fillWithBlocks(world, start, -8, -21, 69, -8, -21, 69, Blocks.AIR.getDefaultState());
        structure.fillWithBlocks(world, start, -8, -21, 70, -8, -21, 75, Blocks.SANDSTONE.getDefaultState());
        structure.fillWithBlocks(world, start, -8, -20, 42, -6, -20, 50, Blocks.SANDSTONE.getDefaultState());
        structure.fillWithBlocks(world, start, -8, -20, 52, -6, -20, 54, Blocks.SANDSTONE.getDefaultState());
        structure.fillWithBlocks(world, start, -8, -19, 42, -6, -19, 44, Blocks.SANDSTONE.getDefaultState());
        structure.fillWithBlocks(world, start, -8, -19, 46, -7, -18, 46, Blocks.SANDSTONE.getDefaultState());
        structure.fillWithBlocks(world, start, -8, -19, 47, -8, -17, 49, Blocks.AIR.getDefaultState());
        structure.fillWithBlocks(world, start, -8, -19, 50, -7, -19, 54, Blocks.SANDSTONE.getDefaultState());
        structure.fillWithBlocks(world, start, -8, -18, 44, -7, -18, 46, Blocks.SANDSTONE.getDefaultState());
        structure.fillWithBlocks(world, start, -8, -18, 50, -7, -18, 54, Blocks.SANDSTONE.getDefaultState());
        structure.fillWithBlocks(world, start, -8, -17, 46, -7, -16, 46, Blocks.SANDSTONE.getDefaultState());
        structure.fillWithBlocks(world, start, -8, -17, 50, -7, -17, 51, Blocks.SANDSTONE.getDefaultState());
