package mod.arcalitegames.odyssey.world.structure.structures.dungeons.shrine;

import mod.arcalitegames.odyssey.world.structure.StructureBase;
import net.minecraft.block.Blocks;
import net.minecraft.block.CactusBlock;
import net.minecraft.block.FourWayBlock;
import net.minecraft.block.SlabBlock;
import net.minecraft.block.StairsBlock;
import net.minecraft.block.WallSkullBlock;
import net.minecraft.state.properties.Half;
import net.minecraft.state.properties.SlabType;
import net.minecraft.state.properties.StairsShape;
import net.minecraft.util.Direction;
import net.minecraft.util.math.BlockPos;
import net.minecraft.world.World;

public class ShrineComponent4
{

	public static BlockPos start;
    public static World world;
    public static StructureBase structure;

    public static void init(World worldIn, BlockPos blockPos, StructureBase structureIn)
    {
        world = worldIn; start = blockPos; structure = structureIn;
    }
    
    public static void generatePart41()
    {
        structure.fillWithBlocks(world, start, 75, 1, 153, 81, 1, 160, Blocks.SANDSTONE.getDefaultState());
        structure.fillWithBlocks(world, start, 75, 3, 6, 82, 3, 13, Blocks.SANDSTONE.getDefaultState());
        structure.fillWithBlocks(world, start, 75, 8, 26, 76, 8, 27, Blocks.SANDSTONE.getDefaultState());
        structure.fillWithBlocks(world, start, 75, 8, 28, 75, 8, 29, Blocks.SANDSTONE.getDefaultState());
        structure.fillWithBlocks(world, start, 75, 8, 30, 76, 9, 30, Blocks.ANDESITE.getDefaultState());
        structure.fillWithBlocks(world, start, 75, 8, 31, 75, 8, 31, Blocks.SANDSTONE.getDefaultState());
        structure.fillWithBlocks(world, start, 75, 8, 33, 89, 8, 47, Blocks.SANDSTONE.getDefaultState());
        structure.fillWithBlocks(world, start, 75, 8, 110, 75, 8, 110, Blocks.STONE.getDefaultState());
        structure.fillWithBlocks(world, start, 75, 8, 111, 75, 8, 116, Blocks.ANDESITE.getDefaultState());
        structure.fillWithBlocks(world, start, 75, 8, 117, 76, 8, 118, Blocks.SANDSTONE.getDefaultState());
        structure.fillWithBlocks(world, start, 75, 9, 25, 76, 9, 26, Blocks.SAND.getDefaultState());
        structure.fillWithBlocks(world, start, 75, 9, 31, 75, 9, 31, Blocks.SANDSTONE.getDefaultState());
        structure.fillWithBlocks(world, start, 75, 9, 32, 75, 11, 32, Blocks.STONE.getDefaultState());
        structure.fillWithBlocks(world, start, 75, 9, 33, 89, 9, 47, Blocks.SANDSTONE.getDefaultState());
        structure.fillWithBlocks(world, start, 75, 9, 109, 77, 9, 111, Blocks.STONE.getDefaultState());
        structure.fillWithBlocks(world, start, 75, 9, 117, 76, 9, 118, Blocks.SANDSTONE.getDefaultState());
        structure.fillWithBlocks(world, start, 75, 10, 27, 75, 10, 29, Blocks.SANDSTONE.getDefaultState());
        structure.fillWithBlocks(world, start, 75, 10, 30, 76, 11, 30, Blocks.ANDESITE.getDefaultState());
        structure.fillWithBlocks(world, start, 75, 10, 31, 75, 10, 31, Blocks.SANDSTONE.getDefaultState());
        structure.fillWithBlocks(world, start, 75, 10, 33, 89, 10, 47, Blocks.SANDSTONE.getDefaultState());
        structure.fillWithBlocks(world, start, 75, 10, 113, 76, 10, 116, Blocks.STONE.getDefaultState());
        structure.fillWithBlocks(world, start, 75, 10, 117, 76, 10, 118, Blocks.SANDSTONE.getDefaultState());
        structure.fillWithBlocks(world, start, 75, 11, 28, 75, 11, 29, Blocks.SANDSTONE.getDefaultState());
        structure.fillWithBlocks(world, start, 75, 11, 31, 75, 11, 31, Blocks.SANDSTONE.getDefaultState());
        structure.fillWithBlocks(world, start, 75, 11, 33, 89, 11, 47, Blocks.SANDSTONE.getDefaultState());
        structure.fillWithBlocks(world, start, 75, 11, 115, 76, 11, 116, Blocks.STONE.getDefaultState());
        structure.fillWithBlocks(world, start, 75, 11, 117, 76, 11, 118, Blocks.SANDSTONE.getDefaultState());
        structure.fillWithBlocks(world, start, 75, 12, 30, 76, 13, 30, Blocks.STONE.getDefaultState());
        structure.fillWithBlocks(world, start, 75, 12, 31, 75, 12, 31, Blocks.SANDSTONE.getDefaultState());
        structure.fillWithBlocks(world, start, 75, 12, 32, 75, 14, 32, Blocks.DIORITE.getDefaultState());
        structure.fillWithBlocks(world, start, 75, 12, 33, 89, 12, 47, Blocks.SANDSTONE.getDefaultState());
        structure.fillWithBlocks(world, start, 75, 12, 72, 75, 12, 73, Blocks.SANDSTONE_STAIRS.getDefaultState().with(StairsBlock.FACING, Direction.WEST).with(StairsBlock.WATERLOGGED, false).with(StairsBlock.SHAPE, StairsShape.STRAIGHT).with(StairsBlock.HALF, Half.BOTTOM));
        structure.fillWithBlocks(world, start, 75, 12, 83, 75, 12, 84, Blocks.SANDSTONE_STAIRS.getDefaultState().with(StairsBlock.FACING, Direction.WEST).with(StairsBlock.WATERLOGGED, false).with(StairsBlock.SHAPE, StairsShape.STRAIGHT).with(StairsBlock.HALF, Half.BOTTOM));
        structure.fillWithBlocks(world, start, 75, 12, 115, 76, 12, 116, Blocks.STONE.getDefaultState());
        structure.fillWithBlocks(world, start, 75, 12, 117, 76, 12, 118, Blocks.SANDSTONE.getDefaultState());
        structure.fillWithBlocks(world, start, 75, 13, 29, 77, 13, 29, Blocks.SANDSTONE.getDefaultState());
        structure.fillWithBlocks(world, start, 75, 13, 31, 75, 13, 31, Blocks.SANDSTONE.getDefaultState());
        structure.fillWithBlocks(world, start, 75, 13, 33, 89, 13, 47, Blocks.SANDSTONE.getDefaultState());
        structure.fillWithBlocks(world, start, 75, 13, 114, 76, 13, 116, Blocks.STONE.getDefaultState());
        structure.fillWithBlocks(world, start, 75, 13, 117, 76, 13, 118, Blocks.SANDSTONE.getDefaultState());
        structure.fillWithBlocks(world, start, 75, 14, 29, 77, 16, 29, Blocks.SAND.getDefaultState());
        structure.fillWithBlocks(world, start, 75, 14, 30, 76, 14, 30, Blocks.STONE.getDefaultState());
        structure.fillWithBlocks(world, start, 75, 14, 31, 75, 14, 31, Blocks.SANDSTONE.getDefaultState());
        structure.fillWithBlocks(world, start, 75, 14, 33, 89, 14, 47, Blocks.SANDSTONE.getDefaultState());
        structure.fillWithBlocks(world, start, 75, 14, 114, 76, 14, 116, Blocks.STONE.getDefaultState());
        structure.fillWithBlocks(world, start, 75, 14, 117, 76, 14, 118, Blocks.SANDSTONE.getDefaultState());
        structure.fillWithBlocks(world, start, 75, 15, 31, 75, 15, 31, Blocks.SANDSTONE.getDefaultState());
        structure.fillWithBlocks(world, start, 75, 15, 32, 75, 18, 32, Blocks.STONE.getDefaultState());
        structure.fillWithBlocks(world, start, 75, 15, 33, 89, 15, 47, Blocks.SANDSTONE.getDefaultState());
        structure.fillWithBlocks(world, start, 75, 15, 117, 76, 15, 118, Blocks.SANDSTONE.getDefaultState());
        structure.fillWithBlocks(world, start, 75, 16, 31, 75, 16, 31, Blocks.SANDSTONE.getDefaultState());
        structure.fillWithBlocks(world, start, 75, 16, 33, 86, 16, 47, Blocks.SANDSTONE.getDefaultState());
        structure.fillWithBlocks(world, start, 75, 16, 117, 76, 16, 118, Blocks.SANDSTONE.getDefaultState());
        structure.fillWithBlocks(world, start, 75, 17, 33, 81, 17, 47, Blocks.SANDSTONE.getDefaultState());
        structure.fillWithBlocks(world, start, 75, 17, 117, 76, 17, 118, Blocks.SANDSTONE.getDefaultState());
        structure.fillWithBlocks(world, start, 75, 18, 33, 78, 18, 47, Blocks.SANDSTONE.getDefaultState());
        structure.fillWithBlocks(world, start, 75, 18, 112, 78, 19, 112, Blocks.GRANITE.getDefaultState());
        structure.fillWithBlocks(world, start, 75, 18, 113, 76, 18, 116, Blocks.STONE.getDefaultState());
        structure.fillWithBlocks(world, start, 75, 18, 117, 76, 18, 118, Blocks.SANDSTONE.getDefaultState());
        structure.fillWithBlocks(world, start, 75, 19, 72, 76, 19, 73, Blocks.CUT_SANDSTONE.getDefaultState());
        structure.fillWithBlocks(world, start, 75, 19, 83, 76, 19, 84, Blocks.CUT_SANDSTONE.getDefaultState());
        structure.fillWithBlocks(world, start, 75, 19, 113, 76, 19, 116, Blocks.STONE.getDefaultState());
        structure.fillWithBlocks(world, start, 75, 19, 117, 76, 19, 118, Blocks.SANDSTONE.getDefaultState());
        structure.fillWithBlocks(world, start, 75, 20, 72, 76, 20, 73, Blocks.CUT_SANDSTONE.getDefaultState());
        structure.fillWithBlocks(world, start, 75, 20, 83, 76, 20, 84, Blocks.CUT_SANDSTONE.getDefaultState());
        structure.fillWithBlocks(world, start, 75, 20, 117, 76, 20, 118, Blocks.SANDSTONE.getDefaultState());
        structure.fillWithBlocks(world, start, 75, 21, 117, 76, 21, 118, Blocks.SANDSTONE.getDefaultState());
        structure.fillWithBlocks(world, start, 75, 21, 129, 76, 21, 130, Blocks.SAND.getDefaultState());
        structure.fillWithBlocks(world, start, 75, 22, 37, 76, 22, 38, Blocks.SAND.getDefaultState());
        structure.fillWithBlocks(world, start, 75, 22, 39, 75, 22, 47, Blocks.SANDSTONE.getDefaultState());
        structure.fillWithBlocks(world, start, 75, 22, 117, 76, 22, 118, Blocks.SANDSTONE.getDefaultState());
        structure.fillWithBlocks(world, start, 75, 23, 115, 76, 23, 116, Blocks.STONE.getDefaultState());
        structure.fillWithBlocks(world, start, 75, 23, 117, 76, 23, 118, Blocks.SANDSTONE.getDefaultState());
        structure.fillWithBlocks(world, start, 75, 23, 128, 76, 23, 129, Blocks.SAND.getDefaultState());
        structure.fillWithBlocks(world, start, 75, 24, 35, 75, 24, 39, Blocks.SAND.getDefaultState());
        structure.fillWithBlocks(world, start, 75, 24, 117, 76, 24, 118, Blocks.SANDSTONE.getDefaultState());
        structure.fillWithBlocks(world, start, 75, 25, 117, 76, 25, 118, Blocks.SANDSTONE.getDefaultState());
        structure.fillWithBlocks(world, start, 75, 26, 115, 76, 26, 116, Blocks.STONE.getDefaultState());
        structure.fillWithBlocks(world, start, 75, 26, 117, 76, 26, 118, Blocks.SANDSTONE.getDefaultState());
        structure.fillWithBlocks(world, start, 75, 27, 38, 75, 27, 41, Blocks.SAND.getDefaultState());
        structure.fillWithBlocks(world, start, 75, 27, 115, 76, 27, 116, Blocks.STONE.getDefaultState());
        structure.fillWithBlocks(world, start, 75, 27, 117, 76, 27, 118, Blocks.SANDSTONE.getDefaultState());
        structure.fillWithBlocks(world, start, 75, 28, 39, 75, 28, 41, Blocks.SAND.getDefaultState());
        structure.fillWithBlocks(world, start, 75, 28, 115, 76, 28, 116, Blocks.STONE.getDefaultState());
        structure.fillWithBlocks(world, start, 75, 28, 117, 76, 28, 118, Blocks.SANDSTONE.getDefaultState());
        structure.fillWithBlocks(world, start, 75, 29, 40, 75, 29, 42, Blocks.SAND.getDefaultState());
        structure.fillWithBlocks(world, start, 75, 29, 115, 76, 29, 116, Blocks.STONE.getDefaultState());
        structure.fillWithBlocks(world, start, 75, 29, 117, 76, 29, 118, Blocks.SANDSTONE.getDefaultState());
        structure.fillWithBlocks(world, start, 75, 30, 115, 76, 30, 116, Blocks.STONE.getDefaultState());
        structure.fillWithBlocks(world, start, 75, 30, 117, 76, 30, 118, Blocks.SANDSTONE.getDefaultState());
        structure.fillWithBlocks(world, start, 75, 31, 115, 76, 31, 116, Blocks.STONE.getDefaultState());
        structure.fillWithBlocks(world, start, 75, 31, 117, 76, 31, 118, Blocks.SANDSTONE.getDefaultState());
        structure.fillWithBlocks(world, start, 75, 32, 115, 76, 32, 116, Blocks.STONE.getDefaultState());
        structure.fillWithBlocks(world, start, 75, 32, 117, 76, 32, 118, Blocks.SANDSTONE.getDefaultState());
        structure.fillWithBlocks(world, start, 75, 33, 115, 76, 33, 116, Blocks.STONE.getDefaultState());
        structure.fillWithBlocks(world, start, 75, 33, 117, 76, 33, 118, Blocks.SANDSTONE.getDefaultState());
        structure.fillWithBlocks(world, start, 75, 33, 124, 75, 33, 125, Blocks.SAND.getDefaultState());
        structure.fillWithBlocks(world, start, 75, 34, 43, 76, 34, 44, Blocks.SAND.getDefaultState());
        structure.fillWithBlocks(world, start, 75, 34, 45, 76, 34, 47, Blocks.SANDSTONE.getDefaultState());
        structure.fillWithBlocks(world, start, 75, 34, 115, 76, 34, 116, Blocks.STONE.getDefaultState());
        structure.fillWithBlocks(world, start, 75, 34, 117, 76, 34, 118, Blocks.SANDSTONE.getDefaultState());
        structure.fillWithBlocks(world, start, 75, 34, 124, 76, 34, 124, Blocks.SAND.getDefaultState());
        structure.fillWithBlocks(world, start, 75, 35, 44, 75, 35, 44, Blocks.SAND.getDefaultState());
        structure.fillWithBlocks(world, start, 75, 35, 45, 75, 35, 47, Blocks.SANDSTONE.getDefaultState());
        structure.fillWithBlocks(world, start, 75, 35, 117, 76, 35, 118, Blocks.SANDSTONE.getDefaultState());
        structure.fillWithBlocks(world, start, 75, 35, 123, 75, 35, 124, Blocks.SAND.getDefaultState());
        structure.fillWithBlocks(world, start, 75, 36, 44, 76, 36, 45, Blocks.SAND.getDefaultState());
        structure.fillWithBlocks(world, start, 75, 36, 46, 76, 36, 47, Blocks.SANDSTONE.getDefaultState());
        structure.fillWithBlocks(world, start, 75, 36, 117, 76, 36, 118, Blocks.SANDSTONE.getDefaultState());
        structure.fillWithBlocks(world, start, 75, 36, 123, 76, 36, 123, Blocks.SAND.getDefaultState());
        structure.fillWithBlocks(world, start, 75, 37, 44, 75, 37, 45, Blocks.SAND.getDefaultState());
        structure.fillWithBlocks(world, start, 75, 37, 46, 75, 37, 47, Blocks.SANDSTONE.getDefaultState());
        structure.fillWithBlocks(world, start, 75, 37, 117, 76, 37, 118, Blocks.SANDSTONE.getDefaultState());
        structure.fillWithBlocks(world, start, 75, 38, 45, 76, 38, 46, Blocks.SAND.getDefaultState());
        structure.fillWithBlocks(world, start, 75, 38, 117, 76, 38, 118, Blocks.SANDSTONE.getDefaultState());
        structure.fillWithBlocks(world, start, 75, 38, 120, 76, 38, 121, Blocks.SANDSTONE.getDefaultState());
        structure.fillWithBlocks(world, start, 75, 38, 122, 76, 39, 122, Blocks.SAND.getDefaultState());
        structure.fillWithBlocks(world, start, 75, 39, 117, 76, 39, 118, Blocks.SANDSTONE.getDefaultState());
        structure.fillWithBlocks(world, start, 75, 39, 120, 76, 39, 121, Blocks.SANDSTONE.getDefaultState());
        structure.fillWithBlocks(world, start, 75, 40, 47, 75, 40, 47, Blocks.SAND.getDefaultState());
        structure.fillWithBlocks(world, start, 75, 40, 117, 76, 40, 118, Blocks.SANDSTONE.getDefaultState());
        structure.fillWithBlocks(world, start, 75, 40, 120, 75, 40, 121, Blocks.SANDSTONE.getDefaultState());
        structure.fillWithBlocks(world, start, 75, 41, 47, 76, 41, 48, Blocks.SAND.getDefaultState());
        structure.fillWithBlocks(world, start, 75, 41, 117, 76, 41, 118, Blocks.SANDSTONE.getDefaultState());
        structure.fillWithBlocks(world, start, 75, 41, 120, 77, 42, 120, Blocks.SANDSTONE.getDefaultState());
        structure.fillWithBlocks(world, start, 75, 41, 121, 76, 42, 121, Blocks.SAND.getDefaultState());
        structure.fillWithBlocks(world, start, 75, 42, 117, 76, 42, 118, Blocks.SANDSTONE.getDefaultState());
        structure.fillWithBlocks(world, start, 75, 43, 117, 76, 43, 118, Blocks.SANDSTONE.getDefaultState());
        structure.fillWithBlocks(world, start, 75, 44, 53, 75, 44, 53, Blocks.SAND.getDefaultState());
        structure.fillWithBlocks(world, start, 75, 44, 54, 75, 44, 57, Blocks.SANDSTONE.getDefaultState());
        structure.fillWithBlocks(world, start, 75, 44, 58, 77, 44, 61, Blocks.SAND.getDefaultState());
        structure.fillWithBlocks(world, start, 75, 44, 62, 75, 45, 62, Blocks.SANDSTONE.getDefaultState());
        structure.fillWithBlocks(world, start, 75, 44, 63, 77, 44, 69, Blocks.SAND.getDefaultState());
        structure.fillWithBlocks(world, start, 75, 44, 71, 77, 44, 77, Blocks.SAND.getDefaultState());
        structure.fillWithBlocks(world, start, 75, 44, 79, 77, 44, 85, Blocks.SAND.getDefaultState());
        structure.fillWithBlocks(world, start, 75, 44, 93, 75, 44, 93, Blocks.SAND.getDefaultState());
        structure.fillWithBlocks(world, start, 75, 44, 98, 75, 44, 98, Blocks.SAND.getDefaultState());
        structure.fillWithBlocks(world, start, 75, 44, 99, 75, 44, 102, Blocks.SANDSTONE.getDefaultState());
        structure.fillWithBlocks(world, start, 75, 44, 103, 77, 44, 108, Blocks.SAND.getDefaultState());
        structure.fillWithBlocks(world, start, 75, 44, 116, 76, 45, 116, Blocks.STONE.getDefaultState());
        structure.fillWithBlocks(world, start, 75, 44, 117, 76, 44, 118, Blocks.SANDSTONE.getDefaultState());
        structure.fillWithBlocks(world, start, 75, 45, 53, 75, 45, 53, Blocks.SAND.getDefaultState());
        structure.fillWithBlocks(world, start, 75, 45, 55, 77, 45, 61, Blocks.SAND.getDefaultState());
        structure.fillWithBlocks(world, start, 75, 45, 63, 77, 45, 68, Blocks.SAND.getDefaultState());
        structure.fillWithBlocks(world, start, 75, 45, 69, 76, 45, 100, Blocks.SAND.getDefaultState());
        structure.fillWithBlocks(world, start, 75, 45, 103, 77, 45, 108, Blocks.SAND.getDefaultState());
        structure.fillWithBlocks(world, start, 75, 45, 117, 76, 45, 118, Blocks.SANDSTONE.getDefaultState());
        structure.fillWithBlocks(world, start, 75, 45, 120, 76, 46, 120, Blocks.SAND.getDefaultState());
        structure.fillWithBlocks(world, start, 75, 46, 117, 76, 46, 118, Blocks.SANDSTONE.getDefaultState());
        structure.fillWithBlocks(world, start, 75, 47, 111, 75, 47, 111, Blocks.SAND.getDefaultState());
        structure.fillWithBlocks(world, start, 75, 47, 112, 75, 47, 116, Blocks.STONE.getDefaultState());
        structure.fillWithBlocks(world, start, 75, 47, 117, 75, 47, 118, Blocks.SANDSTONE.getDefaultState());
        structure.fillWithBlocks(world, start, 75, 48, 50, 76, 48, 50, Blocks.SAND.getDefaultState());
        structure.fillWithBlocks(world, start, 75, 48, 52, 75, 50, 54, Blocks.SAND.getDefaultState());
        structure.fillWithBlocks(world, start, 75, 48, 61, 75, 48, 67, Blocks.SAND.getDefaultState());
        structure.fillWithBlocks(world, start, 75, 48, 115, 75, 48, 115, Blocks.SAND.getDefaultState());
        structure.fillWithBlocks(world, start, 75, 48, 118, 76, 48, 119, Blocks.SAND.getDefaultState());
        structure.fillWithBlocks(world, start, 75, 49, 63, 75, 49, 67, Blocks.SAND.getDefaultState());
        structure.fillWithBlocks(world, start, 75, 49, 116, 76, 49, 118, Blocks.SAND.getDefaultState());
        structure.fillWithBlocks(world, start, 75, 50, 64, 75, 51, 66, Blocks.SAND.getDefaultState());
        structure.fillWithBlocks(world, start, 75, 50, 107, 77, 50, 116, Blocks.SAND.getDefaultState());
        structure.fillWithBlocks(world, start, 75, 51, 109, 75, 51, 117, Blocks.SAND.getDefaultState());
        structure.fillWithBlocks(world, start, 75, 52, 110, 75, 52, 116, Blocks.SAND.getDefaultState());
        structure.fillWithBlocks(world, start, 76, -51, 46, 76, -50, 50, Blocks.SANDSTONE.getDefaultState());
        structure.fillWithBlocks(world, start, 76, -50, -18, 78, -50, -16, Blocks.AIR.getDefaultState());
        structure.fillWithBlocks(world, start, 76, -50, 24, 77, -50, 32, Blocks.AIR.getDefaultState());
        structure.fillWithBlocks(world, start, 76, -49, -19, 77, -49, -19, Blocks.IRON_BARS.getDefaultState().with(FourWayBlock.WATERLOGGED, false).with(FourWayBlock.NORTH, true).with(FourWayBlock.SOUTH, true).with(FourWayBlock.EAST, true).with(FourWayBlock.WEST, true));
        structure.fillWithBlocks(world, start, 76, -49, 75, 80, -49, 79, Blocks.AIR.getDefaultState());
        structure.fillWithBlocks(world, start, 76, -48, 83, 78, -48, 85, Blocks.SANDSTONE.getDefaultState());
        structure.fillWithBlocks(world, start, 76, -45, -18, 77, -45, -16, Blocks.AIR.getDefaultState());
        structure.fillWithBlocks(world, start, 76, -45, -8, 77, -45, -6, Blocks.AIR.getDefaultState());
        structure.fillWithBlocks(world, start, 76, -45, 55, 78, -45, 57, Blocks.SANDSTONE.getDefaultState());
        structure.fillWithBlocks(world, start, 76, -45, 65, 79, -45, 68, Blocks.SANDSTONE.getDefaultState());
        structure.fillWithBlocks(world, start, 76, -45, 82, 79, -45, 85, Blocks.SANDSTONE.getDefaultState());
        structure.fillWithBlocks(world, start, 76, -44, -18, 79, -44, -4, Blocks.SANDSTONE.getDefaultState());
        structure.fillWithBlocks(world, start, 76, -44, 18, 80, -44, 22, Blocks.SANDSTONE.getDefaultState());
        structure.fillWithBlocks(world, start, 76, -44, 55, 78, -44, 57, Blocks.SANDSTONE.getDefaultState());
        structure.fillWithBlocks(world, start, 76, -44, 65, 79, -44, 68, Blocks.SANDSTONE.getDefaultState());
        structure.fillWithBlocks(world, start, 76, -44, 82, 79, -44, 85, Blocks.SANDSTONE.getDefaultState());
        structure.fillWithBlocks(world, start, 76, -42, 18, 83, -42, 25, Blocks.SANDSTONE.getDefaultState());
        structure.fillWithBlocks(world, start, 76, -41, 67, 78, -41, 76, Blocks.STONE_BRICKS.getDefaultState());
        structure.fillWithBlocks(world, start, 76, -41, 78, 78, -41, 90, Blocks.STONE_BRICKS.getDefaultState());
        structure.fillWithBlocks(world, start, 76, -40, 42, 77, -40, 43, Blocks.STONE_BRICKS.getDefaultState());
        structure.fillWithBlocks(world, start, 76, -40, 46, 76, -40, 50, Blocks.STONE_BRICKS.getDefaultState());
        structure.fillWithBlocks(world, start, 76, -40, 51, 77, -40, 52, Blocks.SANDSTONE.getDefaultState());
        structure.fillWithBlocks(world, start, 76, -40, 62, 77, -40, 63, Blocks.STONE_BRICKS.getDefaultState());
        structure.fillWithBlocks(world, start, 76, -40, 64, 77, -40, 69, Blocks.AIR.getDefaultState());
        structure.fillWithBlocks(world, start, 76, -40, 70, 76, -40, 76, Blocks.AIR.getDefaultState());
        structure.fillWithBlocks(world, start, 76, -40, 77, 88, -40, 77, Blocks.STONE_BRICKS.getDefaultState());
        structure.fillWithBlocks(world, start, 76, -40, 78, 78, -40, 80, Blocks.AIR.getDefaultState());
        structure.fillWithBlocks(world, start, 76, -40, 81, 76, -40, 90, Blocks.AIR.getDefaultState());
        structure.fillWithBlocks(world, start, 76, -39, 44, 76, -39, 45, Blocks.STONE_BRICKS.getDefaultState());
        structure.fillWithBlocks(world, start, 76, -39, 46, 76, -39, 50, Blocks.AIR.getDefaultState());
        structure.fillWithBlocks(world, start, 76, -39, 63, 77, -39, 63, Blocks.IRON_BARS.getDefaultState().with(FourWayBlock.WATERLOGGED, false).with(FourWayBlock.NORTH, true).with(FourWayBlock.SOUTH, true).with(FourWayBlock.EAST, true).with(FourWayBlock.WEST, true));
        structure.fillWithBlocks(world, start, 76, -39, 67, 77, -39, 76, Blocks.AIR.getDefaultState());
        structure.fillWithBlocks(world, start, 76, -39, 77, 78, -39, 77, Blocks.IRON_BARS.getDefaultState().with(FourWayBlock.WATERLOGGED, false).with(FourWayBlock.NORTH, true).with(FourWayBlock.SOUTH, true).with(FourWayBlock.EAST, true).with(FourWayBlock.WEST, true));
        structure.fillWithBlocks(world, start, 76, -39, 78, 78, -39, 90, Blocks.AIR.getDefaultState());
        structure.fillWithBlocks(world, start, 76, -39, 91, 78, -39, 91, Blocks.IRON_BARS.getDefaultState().with(FourWayBlock.WATERLOGGED, false).with(FourWayBlock.NORTH, true).with(FourWayBlock.SOUTH, true).with(FourWayBlock.EAST, true).with(FourWayBlock.WEST, true));
        structure.fillWithBlocks(world, start, 76, -38, 42, 77, -38, 43, Blocks.STONE_BRICKS.getDefaultState());
        structure.fillWithBlocks(world, start, 76, -38, 44, 76, -38, 44, Blocks.AIR.getDefaultState());
        structure.fillWithBlocks(world, start, 76, -38, 45, 76, -36, 45, Blocks.STONE_BRICKS.getDefaultState());
        structure.fillWithBlocks(world, start, 76, -38, 46, 76, -38, 50, Blocks.AIR.getDefaultState());
        structure.fillWithBlocks(world, start, 76, -38, 63, 77, -38, 91, Blocks.AIR.getDefaultState());
        structure.fillWithBlocks(world, start, 76, -37, 42, 77, -37, 43, Blocks.STONE_BRICKS.getDefaultState());
        structure.fillWithBlocks(world, start, 76, -37, 44, 76, -36, 45, Blocks.STONE_BRICKS.getDefaultState());
        structure.fillWithBlocks(world, start, 76, -37, 46, 76, -37, 50, Blocks.AIR.getDefaultState());
        structure.fillWithBlocks(world, start, 76, -37, 63, 77, -37, 91, Blocks.AIR.getDefaultState());
        structure.fillWithBlocks(world, start, 76, -36, 63, 77, -36, 91, Blocks.AIR.getDefaultState());
        structure.fillWithBlocks(world, start, 76, -35, 63, 95, -34, 63, Blocks.STONE_BRICKS.getDefaultState());
        structure.fillWithBlocks(world, start, 76, -35, 64, 78, -35, 66, Blocks.AIR.getDefaultState());
        structure.fillWithBlocks(world, start, 76, -35, 67, 83, -35, 67, Blocks.STONE_BRICKS.getDefaultState());
        structure.fillWithBlocks(world, start, 76, -35, 68, 78, -35, 72, Blocks.AIR.getDefaultState());
        structure.fillWithBlocks(world, start, 76, -35, 74, 78, -35, 76, Blocks.AIR.getDefaultState());
        structure.fillWithBlocks(world, start, 76, -35, 78, 78, -35, 80, Blocks.AIR.getDefaultState());
        structure.fillWithBlocks(world, start, 76, -35, 81, 80, -34, 81, Blocks.STONE_BRICKS.getDefaultState());
        structure.fillWithBlocks(world, start, 76, -35, 82, 78, -35, 86, Blocks.AIR.getDefaultState());
        structure.fillWithBlocks(world, start, 76, -35, 88, 78, -35, 90, Blocks.AIR.getDefaultState());
        structure.fillWithBlocks(world, start, 76, -35, 91, 77, -35, 92, Blocks.STONE_BRICKS.getDefaultState());
        structure.fillWithBlocks(world, start, 76, -34, 64, 76, -34, 66, Blocks.STONE_BRICKS.getDefaultState());
        structure.fillWithBlocks(world, start, 76, -34, 67, 76, -33, 67, Blocks.AIR.getDefaultState());
        structure.fillWithBlocks(world, start, 76, -34, 68, 77, -34, 69, Blocks.STONE_BRICKS.getDefaultState());
        structure.fillWithBlocks(world, start, 76, -34, 70, 76, -34, 72, Blocks.STONE_BRICKS.getDefaultState());
        structure.fillWithBlocks(world, start, 76, -34, 74, 76, -34, 92, Blocks.STONE_BRICKS.getDefaultState());
        structure.fillWithBlocks(world, start, 76, -33, 63, 76, -33, 63, Blocks.STONE_BRICKS.getDefaultState());
        structure.fillWithBlocks(world, start, 76, -33, 64, 76, -33, 65, Blocks.AIR.getDefaultState());
        structure.fillWithBlocks(world, start, 76, -33, 66, 76, -33, 66, Blocks.STONE_BRICKS.getDefaultState());
        structure.fillWithBlocks(world, start, 76, -33, 68, 76, -33, 68, Blocks.STONE_BRICKS.getDefaultState());
        structure.fillWithBlocks(world, start, 76, -33, 69, 76, -33, 69, Blocks.AIR.getDefaultState());
        structure.fillWithBlocks(world, start, 76, -33, 70, 76, -33, 73, Blocks.STONE_BRICKS.getDefaultState());
        structure.fillWithBlocks(world, start, 76, -33, 74, 76, -32, 74, Blocks.AIR.getDefaultState());
        structure.fillWithBlocks(world, start, 76, -33, 75, 77, -33, 76, Blocks.STONE_BRICKS.getDefaultState());
        structure.fillWithBlocks(world, start, 76, -33, 78, 78, -33, 80, Blocks.STONE_BRICKS.getDefaultState());
        structure.fillWithBlocks(world, start, 76, -33, 81, 76, -31, 81, Blocks.STONE_BRICKS.getDefaultState());
        structure.fillWithBlocks(world, start, 76, -33, 82, 76, -32, 82, Blocks.AIR.getDefaultState());
        structure.fillWithBlocks(world, start, 76, -33, 90, 78, -33, 92, Blocks.STONE_BRICKS.getDefaultState());
        structure.fillWithBlocks(world, start, 76, -32, 68, 78, -32, 70, Blocks.STONE_BRICKS.getDefaultState());
        structure.fillWithBlocks(world, start, 76, -32, 72, 77, -32, 73, Blocks.STONE_BRICKS.getDefaultState());
        structure.fillWithBlocks(world, start, 76, -32, 75, 76, -32, 81, Blocks.STONE_BRICKS.getDefaultState());
        structure.fillWithBlocks(world, start, 76, -32, 83, 76, -32, 83, Blocks.STONE_BRICKS.getDefaultState());
        structure.fillWithBlocks(world, start, 76, -32, 84, 76, -32, 84, Blocks.AIR.getDefaultState());
        structure.fillWithBlocks(world, start, 76, -32, 85, 76, -32, 92, Blocks.STONE_BRICKS.getDefaultState());
        structure.fillWithBlocks(world, start, 76, -31, 79, 80, -31, 92, Blocks.STONE_BRICKS.getDefaultState());
        structure.fillWithBlocks(world, start, 76, -21, 80, 76, -20, 84, Blocks.SANDSTONE.getDefaultState());
        structure.fillWithBlocks(world, start, 76, -20, 45, 76, -20, 51, Blocks.SANDSTONE.getDefaultState());
        structure.fillWithBlocks(world, start, 76, -19, 45, 76, -16, 45, Blocks.SANDSTONE.getDefaultState());
        structure.fillWithBlocks(world, start, 76, -19, 46, 76, -19, 50, Blocks.AIR.getDefaultState());
        structure.fillWithBlocks(world, start, 76, -19, 51, 76, -16, 51, Blocks.SANDSTONE.getDefaultState());
        structure.fillWithBlocks(world, start, 76, -19, 70, 78, -19, 75, Blocks.SANDSTONE.getDefaultState());
        structure.fillWithBlocks(world, start, 76, -19, 77, 77, -19, 78, Blocks.SANDSTONE.getDefaultState());
        structure.fillWithBlocks(world, start, 76, -19, 79, 77, -19, 85, Blocks.AIR.getDefaultState());
        structure.fillWithBlocks(world, start, 76, -19, 86, 78, -19, 88, Blocks.SANDSTONE.getDefaultState());
        structure.fillWithBlocks(world, start, 76, -19, 92, 78, -19, 94, Blocks.SANDSTONE.getDefaultState());
        structure.fillWithBlocks(world, start, 76, -18, 46, 76, -18, 50, Blocks.AIR.getDefaultState());
        structure.fillWithBlocks(world, start, 76, -18, 70, 77, -18, 71, Blocks.SANDSTONE.getDefaultState());
        structure.fillWithBlocks(world, start, 76, -18, 72, 76, -17, 72, Blocks.AIR.getDefaultState());
        structure.fillWithBlocks(world, start, 76, -18, 73, 77, -18, 74, Blocks.SANDSTONE.getDefaultState());
        structure.fillWithBlocks(world, start, 76, -18, 79, 77, -18, 85, Blocks.AIR.getDefaultState());
        structure.fillWithBlocks(world, start, 76, -18, 86, 77, -18, 87, Blocks.SANDSTONE.getDefaultState());
        structure.fillWithBlocks(world, start, 76, -18, 89, 77, -18, 92, Blocks.SANDSTONE.getDefaultState());
        structure.fillWithBlocks(world, start, 76, -18, 93, 76, -18, 94, Blocks.SANDSTONE.getDefaultState());
        structure.fillWithBlocks(world, start, 76, -17, 46, 76, -17, 50, Blocks.AIR.getDefaultState());
        structure.fillWithBlocks(world, start, 76, -17, 86, 76, -17, 86, Blocks.SANDSTONE.getDefaultState());
        structure.fillWithBlocks(world, start, 76, -17, 88, 78, -17, 94, Blocks.SANDSTONE.getDefaultState());
        structure.fillWithBlocks(world, start, 76, -16, 75, 79, -16, 78, Blocks.SANDSTONE.getDefaultState());
        structure.fillWithBlocks(world, start, 76, -14, 71, 77, -14, 80, Blocks.SANDSTONE.getDefaultState());
        structure.fillWithBlocks(world, start, 76, -14, 92, 77, -14, 94, Blocks.SANDSTONE.getDefaultState());
        structure.fillWithBlocks(world, start, 76, -13, 75, 80, -13, 81, Blocks.SANDSTONE.getDefaultState());
        structure.fillWithBlocks(world, start, 76, -13, 82, 77, -13, 94, Blocks.SANDSTONE.getDefaultState());
        structure.fillWithBlocks(world, start, 76, -12, 76, 80, -12, 83, Blocks.SANDSTONE.getDefaultState());
        structure.fillWithBlocks(world, start, 76, -11, 70, 78, -11, 76, Blocks.SANDSTONE.getDefaultState());
        structure.fillWithBlocks(world, start, 76, -11, 77, 77, -11, 77, Blocks.AIR.getDefaultState());
        structure.fillWithBlocks(world, start, 76, -11, 78, 77, -11, 79, Blocks.SANDSTONE.getDefaultState());
        structure.fillWithBlocks(world, start, 76, -11, 81, 77, -11, 84, Blocks.SANDSTONE.getDefaultState());
        structure.fillWithBlocks(world, start, 76, -11, 86, 80, -11, 94, Blocks.SANDSTONE.getDefaultState());
        structure.fillWithBlocks(world, start, 76, -10, 75, 76, -10, 81, Blocks.SANDSTONE.getDefaultState());
        structure.fillWithBlocks(world, start, 76, -9, 75, 76, -7, 75, Blocks.SANDSTONE.getDefaultState());
        structure.fillWithBlocks(world, start, 76, -9, 76, 76, -9, 80, Blocks.AIR.getDefaultState());
        structure.fillWithBlocks(world, start, 76, -9, 81, 76, -9, 82, Blocks.SANDSTONE.getDefaultState());
        structure.fillWithBlocks(world, start, 76, -8, 49, 78, -8, 51, Blocks.AIR.getDefaultState());
        structure.fillWithBlocks(world, start, 76, -8, 76, 76, -8, 80, Blocks.AIR.getDefaultState());
        structure.fillWithBlocks(world, start, 76, -8, 81, 76, -7, 81, Blocks.SANDSTONE.getDefaultState());
        structure.fillWithBlocks(world, start, 76, -7, 76, 76, -7, 80, Blocks.AIR.getDefaultState());
        structure.fillWithBlocks(world, start, 76, -4, 49, 80, -4, 54, Blocks.SANDSTONE.getDefaultState());
        structure.fillWithBlocks(world, start, 76, -3, 43, 77, -3, 53, Blocks.SANDSTONE.getDefaultState());
        structure.fillWithBlocks(world, start, 76, -1, 42, 82, -1, 48, Blocks.SANDSTONE.getDefaultState());
        structure.fillWithBlocks(world, start, 76, 0, 3, 79, 0, 6, Blocks.SANDSTONE.getDefaultState());
        structure.fillWithBlocks(world, start, 76, 0, 7, 78, 0, 9, Blocks.SANDSTONE.getDefaultState());
        structure.fillWithBlocks(world, start, 76, 1, 11, 76, 6, 11, Blocks.SANDSTONE.getDefaultState());
        structure.fillWithBlocks(world, start, 76, 1, 12, 109, 1, 142, Blocks.STONE.getDefaultState());
        structure.fillWithBlocks(world, start, 76, 2, 143, 76, 2, 143, Blocks.STONE.getDefaultState());
        structure.fillWithBlocks(world, start, 76, 2, 144, 76, 2, 159, Blocks.SANDSTONE.getDefaultState());
        structure.fillWithBlocks(world, start, 76, 3, 5, 84, 3, 13, Blocks.SANDSTONE.getDefaultState());
        structure.fillWithBlocks(world, start, 76, 4, 143, 90, 4, 157, Blocks.SANDSTONE.getDefaultState());
        structure.fillWithBlocks(world, start, 76, 5, 7, 82, 5, 13, Blocks.SANDSTONE.getDefaultState());
        structure.fillWithBlocks(world, start, 76, 8, 28, 76, 11, 28, Blocks.ANDESITE.getDefaultState());
        structure.fillWithBlocks(world, start, 76, 8, 29, 76, 8, 29, Blocks.SANDSTONE.getDefaultState());
        structure.fillWithBlocks(world, start, 76, 8, 31, 92, 8, 47, Blocks.SANDSTONE.getDefaultState());
        structure.fillWithBlocks(world, start, 76, 8, 109, 80, 8, 113, Blocks.STONE.getDefaultState());
        structure.fillWithBlocks(world, start, 76, 8, 115, 76, 9, 116, Blocks.STONE.getDefaultState());
        structure.fillWithBlocks(world, start, 76, 8, 119, 89, 8, 132, Blocks.SANDSTONE.getDefaultState());
        structure.fillWithBlocks(world, start, 76, 9, 27, 76, 9, 27, Blocks.SANDSTONE.getDefaultState());
        structure.fillWithBlocks(world, start, 76, 9, 29, 76, 9, 29, Blocks.SANDSTONE.getDefaultState());
        structure.fillWithBlocks(world, start, 76, 9, 31, 92, 9, 47, Blocks.SANDSTONE.getDefaultState());
        structure.fillWithBlocks(world, start, 76, 9, 112, 78, 9, 114, Blocks.STONE.getDefaultState());
        structure.fillWithBlocks(world, start, 76, 9, 119, 89, 9, 132, Blocks.SANDSTONE.getDefaultState());
        structure.fillWithBlocks(world, start, 76, 10, 27, 76, 10, 27, Blocks.SANDSTONE.getDefaultState());
        structure.fillWithBlocks(world, start, 76, 10, 29, 76, 10, 29, Blocks.SANDSTONE.getDefaultState());
        structure.fillWithBlocks(world, start, 76, 10, 31, 92, 10, 47, Blocks.SANDSTONE.getDefaultState());
        structure.fillWithBlocks(world, start, 76, 10, 119, 88, 10, 131, Blocks.SANDSTONE.getDefaultState());
        structure.fillWithBlocks(world, start, 76, 11, 29, 76, 11, 29, Blocks.SANDSTONE.getDefaultState());
        structure.fillWithBlocks(world, start, 76, 11, 31, 92, 11, 47, Blocks.SANDSTONE.getDefaultState());
        structure.fillWithBlocks(world, start, 76, 11, 119, 88, 11, 131, Blocks.SANDSTONE.getDefaultState());
        structure.fillWithBlocks(world, start, 76, 12, 29, 76, 12, 29, Blocks.SANDSTONE.getDefaultState());
        structure.fillWithBlocks(world, start, 76, 12, 31, 92, 12, 47, Blocks.SANDSTONE.getDefaultState());
        structure.fillWithBlocks(world, start, 76, 12, 119, 87, 12, 130, Blocks.SANDSTONE.getDefaultState());
        structure.fillWithBlocks(world, start, 76, 13, 31, 90, 13, 47, Blocks.SANDSTONE.getDefaultState());
        structure.fillWithBlocks(world, start, 76, 13, 112, 78, 13, 114, Blocks.STONE.getDefaultState());
        structure.fillWithBlocks(world, start, 76, 13, 119, 87, 13, 130, Blocks.SANDSTONE.getDefaultState());
        structure.fillWithBlocks(world, start, 76, 13, 133, 77, 13, 134, Blocks.SAND.getDefaultState());
        structure.fillWithBlocks(world, start, 76, 14, 31, 87, 14, 47, Blocks.SANDSTONE.getDefaultState());
        structure.fillWithBlocks(world, start, 76, 14, 112, 78, 14, 114, Blocks.STONE.getDefaultState());
        structure.fillWithBlocks(world, start, 76, 14, 119, 86, 14, 130, Blocks.SANDSTONE.getDefaultState());
        structure.fillWithBlocks(world, start, 76, 15, 30, 78, 17, 30, Blocks.SAND.getDefaultState());
        structure.fillWithBlocks(world, start, 76, 15, 31, 79, 15, 47, Blocks.SANDSTONE.getDefaultState());
        structure.fillWithBlocks(world, start, 76, 15, 109, 76, 15, 109, Blocks.GRAVEL.getDefaultState());
        structure.fillWithBlocks(world, start, 76, 15, 110, 76, 15, 116, Blocks.STONE.getDefaultState());
        structure.fillWithBlocks(world, start, 76, 15, 119, 86, 15, 129, Blocks.SANDSTONE.getDefaultState());
        structure.fillWithBlocks(world, start, 76, 16, 31, 76, 16, 47, Blocks.SANDSTONE.getDefaultState());
        structure.fillWithBlocks(world, start, 76, 16, 109, 77, 16, 110, Blocks.GRAVEL.getDefaultState());
        structure.fillWithBlocks(world, start, 76, 16, 111, 76, 16, 116, Blocks.STONE.getDefaultState());
        structure.fillWithBlocks(world, start, 76, 16, 119, 85, 16, 129, Blocks.SANDSTONE.getDefaultState());
        structure.fillWithBlocks(world, start, 76, 17, 32, 77, 17, 47, Blocks.SANDSTONE.getDefaultState());
        structure.fillWithBlocks(world, start, 76, 17, 109, 77, 17, 110, Blocks.GRAVEL.getDefaultState());
        structure.fillWithBlocks(world, start, 76, 17, 111, 76, 20, 111, Blocks.GRANITE.getDefaultState());
        structure.fillWithBlocks(world, start, 76, 17, 119, 85, 17, 128, Blocks.SANDSTONE.getDefaultState());
        structure.fillWithBlocks(world, start, 76, 17, 131, 77, 17, 132, Blocks.SAND.getDefaultState());
        structure.fillWithBlocks(world, start, 76, 18, 32, 80, 19, 32, Blocks.SAND.getDefaultState());
        structure.fillWithBlocks(world, start, 76, 18, 109, 76, 18, 109, Blocks.GRAVEL.getDefaultState());
        structure.fillWithBlocks(world, start, 76, 18, 110, 76, 18, 112, Blocks.GRANITE.getDefaultState());
        structure.fillWithBlocks(world, start, 76, 18, 119, 84, 18, 128, Blocks.SANDSTONE.getDefaultState());
        structure.fillWithBlocks(world, start, 76, 19, 33, 78, 21, 33, Blocks.SAND.getDefaultState());
        structure.fillWithBlocks(world, start, 76, 19, 34, 77, 19, 47, Blocks.SANDSTONE.getDefaultState());
        structure.fillWithBlocks(world, start, 76, 19, 119, 84, 19, 127, Blocks.SANDSTONE.getDefaultState());
        structure.fillWithBlocks(world, start, 76, 19, 130, 77, 19, 131, Blocks.SAND.getDefaultState());
        structure.fillWithBlocks(world, start, 76, 20, 32, 77, 20, 34, Blocks.SAND.getDefaultState());
        structure.fillWithBlocks(world, start, 76, 20, 35, 77, 20, 47, Blocks.SANDSTONE.getDefaultState());
        structure.fillWithBlocks(world, start, 76, 20, 75, 76, 20, 81, Blocks.SANDSTONE_STAIRS.getDefaultState().with(StairsBlock.FACING, Direction.EAST).with(StairsBlock.WATERLOGGED, false).with(StairsBlock.SHAPE, StairsShape.STRAIGHT).with(StairsBlock.HALF, Half.TOP));
        structure.fillWithBlocks(world, start, 76, 20, 119, 83, 20, 127, Blocks.SANDSTONE.getDefaultState());
        structure.fillWithBlocks(world, start, 76, 21, 35, 80, 22, 35, Blocks.SAND.getDefaultState());
        structure.fillWithBlocks(world, start, 76, 21, 36, 77, 21, 47, Blocks.SANDSTONE.getDefaultState());
        structure.fillWithBlocks(world, start, 76, 21, 119, 83, 21, 126, Blocks.SANDSTONE.getDefaultState());
        structure.fillWithBlocks(world, start, 76, 22, 36, 79, 22, 39, Blocks.SAND.getDefaultState());
        structure.fillWithBlocks(world, start, 76, 22, 40, 78, 22, 47, Blocks.SANDSTONE.getDefaultState());
        structure.fillWithBlocks(world, start, 76, 22, 119, 83, 22, 126, Blocks.SANDSTONE.getDefaultState());
        structure.fillWithBlocks(world, start, 76, 23, 39, 79, 26, 39, Blocks.SAND.getDefaultState());
        structure.fillWithBlocks(world, start, 76, 23, 119, 82, 23, 126, Blocks.SANDSTONE.getDefaultState());
        structure.fillWithBlocks(world, start, 76, 24, 36, 77, 24, 39, Blocks.SAND.getDefaultState());
        structure.fillWithBlocks(world, start, 76, 24, 115, 76, 25, 116, Blocks.STONE.getDefaultState());
        structure.fillWithBlocks(world, start, 76, 24, 119, 82, 24, 125, Blocks.SANDSTONE.getDefaultState());
        structure.fillWithBlocks(world, start, 76, 25, 37, 77, 25, 40, Blocks.SAND.getDefaultState());
        structure.fillWithBlocks(world, start, 76, 25, 119, 81, 25, 125, Blocks.SANDSTONE.getDefaultState());
        structure.fillWithBlocks(world, start, 76, 25, 127, 77, 25, 128, Blocks.SAND.getDefaultState());
        structure.fillWithBlocks(world, start, 76, 26, 38, 77, 26, 40, Blocks.SAND.getDefaultState());
        structure.fillWithBlocks(world, start, 76, 26, 119, 81, 26, 124, Blocks.SANDSTONE.getDefaultState());
        structure.fillWithBlocks(world, start, 76, 27, 39, 77, 27, 40, Blocks.SAND.getDefaultState());
        structure.fillWithBlocks(world, start, 76, 27, 41, 77, 27, 47, Blocks.SANDSTONE.getDefaultState());
        structure.fillWithBlocks(world, start, 76, 27, 119, 80, 27, 124, Blocks.SANDSTONE.getDefaultState());
        structure.fillWithBlocks(world, start, 76, 28, 40, 77, 28, 41, Blocks.SAND.getDefaultState());
        structure.fillWithBlocks(world, start, 76, 28, 119, 80, 28, 123, Blocks.SANDSTONE.getDefaultState());
        structure.fillWithBlocks(world, start, 76, 28, 126, 77, 29, 126, Blocks.SAND.getDefaultState());
        structure.fillWithBlocks(world, start, 76, 29, 41, 77, 29, 42, Blocks.SAND.getDefaultState());
        structure.fillWithBlocks(world, start, 76, 29, 119, 80, 29, 123, Blocks.SANDSTONE.getDefaultState());
        structure.fillWithBlocks(world, start, 76, 30, 41, 77, 30, 42, Blocks.SAND.getDefaultState());
        structure.fillWithBlocks(world, start, 76, 30, 43, 77, 30, 47, Blocks.SANDSTONE.getDefaultState());
        structure.fillWithBlocks(world, start, 76, 30, 119, 79, 30, 123, Blocks.SANDSTONE.getDefaultState());
        structure.fillWithBlocks(world, start, 76, 30, 125, 76, 30, 126, Blocks.SAND.getDefaultState());
        structure.fillWithBlocks(world, start, 76, 31, 42, 77, 31, 43, Blocks.SAND.getDefaultState());
        structure.fillWithBlocks(world, start, 76, 31, 119, 79, 31, 122, Blocks.SANDSTONE.getDefaultState());
        structure.fillWithBlocks(world, start, 76, 32, 42, 77, 32, 43, Blocks.SAND.getDefaultState());
        structure.fillWithBlocks(world, start, 76, 32, 119, 79, 32, 122, Blocks.SANDSTONE.getDefaultState());
        structure.fillWithBlocks(world, start, 76, 32, 124, 76, 32, 125, Blocks.SAND.getDefaultState());
        structure.fillWithBlocks(world, start, 76, 33, 44, 80, 34, 44, Blocks.SAND.getDefaultState());
        structure.fillWithBlocks(world, start, 76, 33, 45, 77, 33, 47, Blocks.SANDSTONE.getDefaultState());
        structure.fillWithBlocks(world, start, 76, 33, 119, 78, 33, 122, Blocks.SANDSTONE.getDefaultState());
        structure.fillWithBlocks(world, start, 76, 33, 124, 77, 33, 124, Blocks.SAND.getDefaultState());
        structure.fillWithBlocks(world, start, 76, 34, 119, 78, 34, 121, Blocks.SANDSTONE.getDefaultState());
        structure.fillWithBlocks(world, start, 76, 34, 122, 77, 35, 122, Blocks.SANDSTONE.getDefaultState());
        structure.fillWithBlocks(world, start, 76, 34, 123, 76, 34, 124, Blocks.SAND.getDefaultState());
        structure.fillWithBlocks(world, start, 76, 35, 44, 77, 35, 45, Blocks.SAND.getDefaultState());
        structure.fillWithBlocks(world, start, 76, 35, 46, 77, 35, 47, Blocks.SANDSTONE.getDefaultState());
        structure.fillWithBlocks(world, start, 76, 35, 119, 78, 35, 121, Blocks.SANDSTONE.getDefaultState());
        structure.fillWithBlocks(world, start, 76, 35, 123, 77, 35, 123, Blocks.SAND.getDefaultState());
        structure.fillWithBlocks(world, start, 76, 36, 119, 77, 36, 121, Blocks.SANDSTONE.getDefaultState());
        structure.fillWithBlocks(world, start, 76, 37, 45, 77, 37, 46, Blocks.SAND.getDefaultState());
        structure.fillWithBlocks(world, start, 76, 37, 47, 76, 38, 47, Blocks.SANDSTONE.getDefaultState());
        structure.fillWithBlocks(world, start, 76, 37, 119, 77, 37, 121, Blocks.SANDSTONE.getDefaultState());
        structure.fillWithBlocks(world, start, 76, 37, 122, 77, 38, 122, Blocks.SAND.getDefaultState());
        structure.fillWithBlocks(world, start, 76, 38, 53, 76, 38, 53, Blocks.SANDSTONE.getDefaultState());
        structure.fillWithBlocks(world, start, 76, 38, 54, 76, 38, 57, Blocks.STONE.getDefaultState());
        structure.fillWithBlocks(world, start, 76, 38, 58, 80, 40, 58, Blocks.SANDSTONE.getDefaultState());
        structure.fillWithBlocks(world, start, 76, 38, 59, 77, 38, 61, Blocks.STONE.getDefaultState());
        structure.fillWithBlocks(world, start, 76, 38, 63, 77, 39, 63, Blocks.SANDSTONE.getDefaultState());
        structure.fillWithBlocks(world, start, 76, 38, 64, 77, 38, 69, Blocks.STONE.getDefaultState());
        structure.fillWithBlocks(world, start, 76, 38, 71, 77, 39, 71, Blocks.SANDSTONE.getDefaultState());
        structure.fillWithBlocks(world, start, 76, 38, 72, 77, 38, 76, Blocks.STONE.getDefaultState());
        structure.fillWithBlocks(world, start, 76, 38, 77, 76, 38, 77, Blocks.SANDSTONE.getDefaultState());
        structure.fillWithBlocks(world, start, 76, 38, 79, 77, 39, 79, Blocks.SANDSTONE.getDefaultState());
        structure.fillWithBlocks(world, start, 76, 38, 80, 77, 38, 84, Blocks.STONE.getDefaultState());
        structure.fillWithBlocks(world, start, 76, 38, 85, 76, 38, 85, Blocks.SANDSTONE.getDefaultState());
        structure.fillWithBlocks(world, start, 76, 38, 86, 76, 38, 92, Blocks.STONE.getDefaultState());
        structure.fillWithBlocks(world, start, 76, 38, 93, 76, 38, 93, Blocks.SANDSTONE.getDefaultState());
        structure.fillWithBlocks(world, start, 76, 38, 94, 76, 38, 97, Blocks.STONE.getDefaultState());
        structure.fillWithBlocks(world, start, 76, 38, 98, 76, 38, 98, Blocks.SANDSTONE.getDefaultState());
        structure.fillWithBlocks(world, start, 76, 38, 99, 76, 38, 102, Blocks.STONE.getDefaultState());
        structure.fillWithBlocks(world, start, 76, 38, 103, 77, 39, 103, Blocks.SANDSTONE.getDefaultState());
        structure.fillWithBlocks(world, start, 76, 38, 104, 77, 38, 114, Blocks.STONE.getDefaultState());
        structure.fillWithBlocks(world, start, 76, 38, 119, 77, 38, 121, Blocks.SANDSTONE.getDefaultState());
        structure.fillWithBlocks(world, start, 76, 39, 47, 77, 39, 48, Blocks.SAND.getDefaultState());
        structure.fillWithBlocks(world, start, 76, 39, 49, 77, 39, 52, Blocks.STONE.getDefaultState());
        structure.fillWithBlocks(world, start, 76, 39, 53, 77, 39, 54, Blocks.SANDSTONE.getDefaultState());
        structure.fillWithBlocks(world, start, 76, 39, 55, 76, 39, 56, Blocks.STONE.getDefaultState());
        structure.fillWithBlocks(world, start, 76, 39, 57, 77, 39, 58, Blocks.SANDSTONE.getDefaultState());
        structure.fillWithBlocks(world, start, 76, 39, 59, 77, 39, 61, Blocks.STONE.getDefaultState());
        structure.fillWithBlocks(world, start, 76, 39, 62, 77, 39, 63, Blocks.SANDSTONE.getDefaultState());
        structure.fillWithBlocks(world, start, 76, 39, 64, 77, 39, 69, Blocks.STONE.getDefaultState());
        structure.fillWithBlocks(world, start, 76, 39, 70, 77, 39, 71, Blocks.SANDSTONE.getDefaultState());
        structure.fillWithBlocks(world, start, 76, 39, 72, 77, 39, 76, Blocks.STONE.getDefaultState());
        structure.fillWithBlocks(world, start, 76, 39, 77, 77, 39, 79, Blocks.SANDSTONE.getDefaultState());
        structure.fillWithBlocks(world, start, 76, 39, 80, 77, 39, 84, Blocks.STONE.getDefaultState());
        structure.fillWithBlocks(world, start, 76, 39, 85, 77, 39, 86, Blocks.SANDSTONE.getDefaultState());
        structure.fillWithBlocks(world, start, 76, 39, 87, 77, 39, 92, Blocks.STONE.getDefaultState());
        structure.fillWithBlocks(world, start, 76, 39, 93, 77, 39, 94, Blocks.SANDSTONE.getDefaultState());
        structure.fillWithBlocks(world, start, 76, 39, 95, 77, 39, 97, Blocks.STONE.getDefaultState());
        structure.fillWithBlocks(world, start, 76, 39, 98, 77, 39, 99, Blocks.SANDSTONE.getDefaultState());
        structure.fillWithBlocks(world, start, 76, 39, 100, 76, 39, 101, Blocks.STONE.getDefaultState());
        structure.fillWithBlocks(world, start, 76, 39, 102, 77, 39, 103, Blocks.SANDSTONE.getDefaultState());
        structure.fillWithBlocks(world, start, 76, 39, 104, 77, 39, 114, Blocks.STONE.getDefaultState());
        structure.fillWithBlocks(world, start, 76, 39, 119, 77, 39, 120, Blocks.SANDSTONE.getDefaultState());
        structure.fillWithBlocks(world, start, 76, 40, 47, 77, 40, 48, Blocks.SAND.getDefaultState());
        structure.fillWithBlocks(world, start, 76, 40, 62, 77, 40, 108, Blocks.SANDSTONE.getDefaultState());
        structure.fillWithBlocks(world, start, 76, 40, 115, 76, 41, 116, Blocks.STONE.getDefaultState());
        structure.fillWithBlocks(world, start, 76, 40, 119, 77, 40, 120, Blocks.SANDSTONE.getDefaultState());
        structure.fillWithBlocks(world, start, 76, 40, 121, 77, 41, 121, Blocks.SAND.getDefaultState());
        structure.fillWithBlocks(world, start, 76, 41, 119, 77, 41, 120, Blocks.SANDSTONE.getDefaultState());
        structure.fillWithBlocks(world, start, 76, 42, 47, 77, 42, 48, Blocks.SAND.getDefaultState());
        structure.fillWithBlocks(world, start, 76, 42, 50, 77, 42, 52, Blocks.SANDSTONE.getDefaultState());
        structure.fillWithBlocks(world, start, 76, 42, 53, 76, 42, 53, Blocks.SAND.getDefaultState());
        structure.fillWithBlocks(world, start, 76, 42, 54, 76, 42, 57, Blocks.SANDSTONE.getDefaultState());
        structure.fillWithBlocks(world, start, 76, 42, 58, 77, 43, 58, Blocks.SAND.getDefaultState());
        structure.fillWithBlocks(world, start, 76, 42, 59, 77, 42, 61, Blocks.SANDSTONE.getDefaultState());
        structure.fillWithBlocks(world, start, 76, 42, 63, 77, 43, 63, Blocks.SAND.getDefaultState());
        structure.fillWithBlocks(world, start, 76, 42, 64, 77, 42, 68, Blocks.SANDSTONE.getDefaultState());
        structure.fillWithBlocks(world, start, 76, 42, 69, 76, 42, 70, Blocks.SANDSTONE.getDefaultState());
        structure.fillWithBlocks(world, start, 76, 42, 71, 77, 43, 71, Blocks.SAND.getDefaultState());
        structure.fillWithBlocks(world, start, 76, 42, 72, 77, 42, 75, Blocks.SANDSTONE.getDefaultState());
        structure.fillWithBlocks(world, start, 76, 42, 76, 76, 43, 76, Blocks.SANDSTONE.getDefaultState());
        structure.fillWithBlocks(world, start, 76, 42, 77, 76, 42, 77, Blocks.SAND.getDefaultState());
        structure.fillWithBlocks(world, start, 76, 42, 79, 77, 43, 79, Blocks.SAND.getDefaultState());
        structure.fillWithBlocks(world, start, 76, 42, 80, 77, 42, 84, Blocks.SANDSTONE.getDefaultState());
        structure.fillWithBlocks(world, start, 76, 42, 85, 76, 42, 85, Blocks.SAND.getDefaultState());
        structure.fillWithBlocks(world, start, 76, 42, 86, 76, 42, 92, Blocks.SANDSTONE.getDefaultState());
        structure.fillWithBlocks(world, start, 76, 42, 93, 76, 42, 93, Blocks.SAND.getDefaultState());
        structure.fillWithBlocks(world, start, 76, 42, 94, 76, 42, 97, Blocks.SANDSTONE.getDefaultState());
        structure.fillWithBlocks(world, start, 76, 42, 98, 76, 42, 98, Blocks.SAND.getDefaultState());
        structure.fillWithBlocks(world, start, 76, 42, 99, 76, 42, 102, Blocks.SANDSTONE.getDefaultState());
        structure.fillWithBlocks(world, start, 76, 42, 103, 78, 43, 103, Blocks.SAND.getDefaultState());
        structure.fillWithBlocks(world, start, 76, 42, 104, 77, 42, 108, Blocks.SANDSTONE.getDefaultState());
        structure.fillWithBlocks(world, start, 76, 42, 115, 76, 43, 116, Blocks.STONE.getDefaultState());
        structure.fillWithBlocks(world, start, 76, 42, 119, 77, 42, 120, Blocks.SANDSTONE.getDefaultState());
        structure.fillWithBlocks(world, start, 76, 43, 46, 78, 43, 48, Blocks.SAND.getDefaultState());
        structure.fillWithBlocks(world, start, 76, 43, 50, 77, 43, 52, Blocks.SANDSTONE.getDefaultState());
        structure.fillWithBlocks(world, start, 76, 43, 53, 77, 43, 54, Blocks.SAND.getDefaultState());
        structure.fillWithBlocks(world, start, 76, 43, 55, 76, 43, 56, Blocks.SANDSTONE.getDefaultState());
        structure.fillWithBlocks(world, start, 76, 43, 57, 77, 43, 58, Blocks.SAND.getDefaultState());
        structure.fillWithBlocks(world, start, 76, 43, 59, 76, 43, 61, Blocks.SANDSTONE.getDefaultState());
        structure.fillWithBlocks(world, start, 76, 43, 62, 77, 43, 63, Blocks.SAND.getDefaultState());
        structure.fillWithBlocks(world, start, 76, 43, 64, 77, 43, 66, Blocks.SANDSTONE.getDefaultState());
        structure.fillWithBlocks(world, start, 76, 43, 67, 76, 43, 69, Blocks.SANDSTONE.getDefaultState());
        structure.fillWithBlocks(world, start, 76, 43, 70, 77, 43, 71, Blocks.SAND.getDefaultState());
        structure.fillWithBlocks(world, start, 76, 43, 72, 77, 43, 73, Blocks.SANDSTONE.getDefaultState());
        structure.fillWithBlocks(world, start, 76, 43, 77, 77, 43, 79, Blocks.SAND.getDefaultState());
        structure.fillWithBlocks(world, start, 76, 43, 80, 76, 43, 84, Blocks.SANDSTONE.getDefaultState());
        structure.fillWithBlocks(world, start, 76, 43, 85, 77, 43, 86, Blocks.SAND.getDefaultState());
        structure.fillWithBlocks(world, start, 76, 43, 87, 76, 43, 92, Blocks.SANDSTONE.getDefaultState());
        structure.fillWithBlocks(world, start, 76, 43, 93, 77, 43, 94, Blocks.SAND.getDefaultState());
        structure.fillWithBlocks(world, start, 76, 43, 95, 76, 43, 97, Blocks.SANDSTONE.getDefaultState());
        structure.fillWithBlocks(world, start, 76, 43, 98, 77, 43, 99, Blocks.SAND.getDefaultState());
        structure.fillWithBlocks(world, start, 76, 43, 100, 76, 43, 101, Blocks.SANDSTONE.getDefaultState());
        structure.fillWithBlocks(world, start, 76, 43, 102, 77, 43, 103, Blocks.SAND.getDefaultState());
        structure.fillWithBlocks(world, start, 76, 43, 104, 77, 43, 108, Blocks.SANDSTONE.getDefaultState());
        structure.fillWithBlocks(world, start, 76, 43, 119, 76, 43, 120, Blocks.SANDSTONE.getDefaultState());
        structure.fillWithBlocks(world, start, 76, 44, 53, 77, 44, 108, Blocks.SAND.getDefaultState());
        structure.fillWithBlocks(world, start, 76, 44, 119, 77, 44, 119, Blocks.SANDSTONE.getDefaultState());
        structure.fillWithBlocks(world, start, 76, 44, 120, 77, 45, 120, Blocks.SAND.getDefaultState());
        structure.fillWithBlocks(world, start, 76, 45, 53, 76, 46, 108, Blocks.SAND.getDefaultState());
        structure.fillWithBlocks(world, start, 76, 46, 109, 76, 46, 109, Blocks.SAND.getDefaultState());
        structure.fillWithBlocks(world, start, 76, 46, 110, 76, 46, 116, Blocks.STONE.getDefaultState());
        structure.fillWithBlocks(world, start, 76, 46, 119, 76, 46, 120, Blocks.SAND.getDefaultState());
        structure.fillWithBlocks(world, start, 76, 47, 55, 76, 47, 56, Blocks.SAND.getDefaultState());
        structure.fillWithBlocks(world, start, 76, 47, 61, 76, 47, 67, Blocks.SAND.getDefaultState());
        structure.fillWithBlocks(world, start, 76, 47, 71, 76, 47, 74, Blocks.SAND.getDefaultState());
        structure.fillWithBlocks(world, start, 76, 47, 82, 76, 47, 85, Blocks.SAND.getDefaultState());
        structure.fillWithBlocks(world, start, 76, 47, 89, 76, 47, 95, Blocks.SAND.getDefaultState());
        structure.fillWithBlocks(world, start, 76, 47, 108, 79, 47, 113, Blocks.SAND.getDefaultState());
        structure.fillWithBlocks(world, start, 76, 47, 114, 76, 47, 116, Blocks.STONE.getDefaultState());
        structure.fillWithBlocks(world, start, 76, 47, 117, 77, 47, 119, Blocks.SAND.getDefaultState());
        structure.fillWithBlocks(world, start, 76, 48, 64, 76, 49, 66, Blocks.SAND.getDefaultState());
        structure.fillWithBlocks(world, start, 76, 48, 102, 76, 48, 119, Blocks.SAND.getDefaultState());
        structure.fillWithBlocks(world, start, 76, 49, 103, 76, 49, 118, Blocks.SAND.getDefaultState());
        structure.fillWithBlocks(world, start, 76, 51, 110, 76, 51, 115, Blocks.SAND.getDefaultState());
        structure.fillWithBlocks(world, start, 76, 52, 111, 76, 52, 115, Blocks.SAND.getDefaultState());
        structure.fillWithBlocks(world, start, 76, 54, 112, 76, 54, 114, Blocks.SAND.getDefaultState());
        structure.fillWithBlocks(world, start, 77, -50, -20, 78, -50, -19, Blocks.SANDSTONE.getDefaultState());
        structure.fillWithBlocks(world, start, 77, -50, 48, 84, -50, 57, Blocks.SANDSTONE.getDefaultState());
        structure.fillWithBlocks(world, start, 77, -49, -4, 78, -49, -3, Blocks.SANDSTONE.getDefaultState());
        structure.fillWithBlocks(world, start, 77, -49, -2, 77, -47, 0, Blocks.AIR.getDefaultState());
        structure.fillWithBlocks(world, start, 77, -49, 1, 77, -49, 1, Blocks.SANDSTONE.getDefaultState());
        structure.fillWithBlocks(world, start, 77, -49, 2, 77, -47, 2, Blocks.AIR.getDefaultState());
        structure.fillWithBlocks(world, start, 77, -49, 3, 77, -49, 3, Blocks.SANDSTONE.getDefaultState());
        structure.fillWithBlocks(world, start, 77, -49, 4, 77, -47, 6, Blocks.AIR.getDefaultState());
        structure.fillWithBlocks(world, start, 77, -49, 7, 77, -49, 7, Blocks.SANDSTONE.getDefaultState());
        structure.fillWithBlocks(world, start, 77, -49, 8, 77, -47, 8, Blocks.AIR.getDefaultState());
        structure.fillWithBlocks(world, start, 77, -49, 9, 77, -49, 9, Blocks.SANDSTONE.getDefaultState());
        structure.fillWithBlocks(world, start, 77, -49, 10, 77, -47, 12, Blocks.AIR.getDefaultState());
        structure.fillWithBlocks(world, start, 77, -49, 13, 77, -49, 13, Blocks.SANDSTONE.getDefaultState());
        structure.fillWithBlocks(world, start, 77, -49, 14, 77, -47, 14, Blocks.AIR.getDefaultState());
        structure.fillWithBlocks(world, start, 77, -49, 15, 77, -49, 15, Blocks.SANDSTONE.getDefaultState());
        structure.fillWithBlocks(world, start, 77, -49, 16, 77, -47, 18, Blocks.AIR.getDefaultState());
        structure.fillWithBlocks(world, start, 77, -49, 19, 78, -49, 20, Blocks.SANDSTONE.getDefaultState());
        structure.fillWithBlocks(world, start, 77, -49, 21, 77, -41, 21, Blocks.SANDSTONE.getDefaultState());
        structure.fillWithBlocks(world, start, 77, -49, 35, 77, -49, 36, Blocks.SANDSTONE.getDefaultState());
        structure.fillWithBlocks(world, start, 77, -49, 37, 77, -47, 39, Blocks.AIR.getDefaultState());
        structure.fillWithBlocks(world, start, 77, -49, 40, 78, -49, 41, Blocks.SANDSTONE.getDefaultState());
        structure.fillWithBlocks(world, start, 77, -49, 55, 79, -49, 57, Blocks.SANDSTONE.getDefaultState());
        structure.fillWithBlocks(world, start, 77, -49, 58, 77, -47, 60, Blocks.AIR.getDefaultState());
        structure.fillWithBlocks(world, start, 77, -49, 61, 77, -49, 61, Blocks.SANDSTONE.getDefaultState());
        structure.fillWithBlocks(world, start, 77, -49, 62, 77, -47, 62, Blocks.AIR.getDefaultState());
        structure.fillWithBlocks(world, start, 77, -49, 63, 77, -49, 63, Blocks.SANDSTONE.getDefaultState());
        structure.fillWithBlocks(world, start, 77, -49, 64, 77, -47, 66, Blocks.AIR.getDefaultState());
        structure.fillWithBlocks(world, start, 77, -49, 67, 77, -48, 68, Blocks.SANDSTONE.getDefaultState());
        structure.fillWithBlocks(world, start, 77, -49, 82, 77, -49, 85, Blocks.SANDSTONE.getDefaultState());
        structure.fillWithBlocks(world, start, 77, -48, -4, 78, -48, -3, Blocks.SANDSTONE.getDefaultState());
        structure.fillWithBlocks(world, start, 77, -48, 1, 77, -48, 1, Blocks.SANDSTONE.getDefaultState());
        structure.fillWithBlocks(world, start, 77, -48, 3, 77, -48, 3, Blocks.SANDSTONE.getDefaultState());
        structure.fillWithBlocks(world, start, 77, -48, 7, 77, -48, 7, Blocks.SANDSTONE.getDefaultState());
        structure.fillWithBlocks(world, start, 77, -48, 9, 77, -48, 9, Blocks.SANDSTONE.getDefaultState());
        structure.fillWithBlocks(world, start, 77, -48, 13, 77, -48, 13, Blocks.SANDSTONE.getDefaultState());
        structure.fillWithBlocks(world, start, 77, -48, 15, 77, -48, 15, Blocks.SANDSTONE.getDefaultState());
        structure.fillWithBlocks(world, start, 77, -48, 19, 78, -48, 20, Blocks.SANDSTONE.getDefaultState());
        structure.fillWithBlocks(world, start, 77, -48, 35, 77, -48, 36, Blocks.SANDSTONE.getDefaultState());
        structure.fillWithBlocks(world, start, 77, -48, 40, 78, -48, 41, Blocks.SANDSTONE.getDefaultState());
        structure.fillWithBlocks(world, start, 77, -48, 55, 79, -48, 57, Blocks.SANDSTONE.getDefaultState());
        structure.fillWithBlocks(world, start, 77, -48, 61, 77, -48, 61, Blocks.SANDSTONE.getDefaultState());
        structure.fillWithBlocks(world, start, 77, -48, 63, 77, -48, 63, Blocks.SANDSTONE.getDefaultState());
        structure.fillWithBlocks(world, start, 77, -48, 82, 77, -48, 85, Blocks.SANDSTONE.getDefaultState());
        structure.fillWithBlocks(world, start, 77, -47, -4, 78, -47, -3, Blocks.SANDSTONE.getDefaultState());
        structure.fillWithBlocks(world, start, 77, -47, 1, 77, -47, 1, Blocks.SANDSTONE.getDefaultState());
        structure.fillWithBlocks(world, start, 77, -47, 3, 77, -47, 3, Blocks.SANDSTONE.getDefaultState());
        structure.fillWithBlocks(world, start, 77, -47, 7, 77, -47, 7, Blocks.SANDSTONE.getDefaultState());
        structure.fillWithBlocks(world, start, 77, -47, 9, 77, -47, 9, Blocks.SANDSTONE.getDefaultState());
        structure.fillWithBlocks(world, start, 77, -47, 13, 77, -47, 13, Blocks.SANDSTONE.getDefaultState());
        structure.fillWithBlocks(world, start, 77, -47, 15, 77, -47, 15, Blocks.SANDSTONE.getDefaultState());
        structure.fillWithBlocks(world, start, 77, -47, 19, 78, -47, 20, Blocks.SANDSTONE.getDefaultState());
        structure.fillWithBlocks(world, start, 77, -47, 35, 77, -47, 36, Blocks.SANDSTONE.getDefaultState());
        structure.fillWithBlocks(world, start, 77, -47, 40, 78, -47, 41, Blocks.SANDSTONE.getDefaultState());
        structure.fillWithBlocks(world, start, 77, -47, 55, 79, -47, 57, Blocks.SANDSTONE.getDefaultState());
        structure.fillWithBlocks(world, start, 77, -47, 61, 77, -47, 61, Blocks.SANDSTONE.getDefaultState());
        structure.fillWithBlocks(world, start, 77, -47, 63, 77, -47, 63, Blocks.SANDSTONE.getDefaultState());
        structure.fillWithBlocks(world, start, 77, -47, 67, 77, -46, 68, Blocks.SANDSTONE.getDefaultState());
        structure.fillWithBlocks(world, start, 77, -47, 82, 77, -47, 85, Blocks.SANDSTONE.getDefaultState());
        structure.fillWithBlocks(world, start, 77, -46, 35, 77, -46, 41, Blocks.SANDSTONE.getDefaultState());
        structure.fillWithBlocks(world, start, 77, -46, 82, 77, -46, 85, Blocks.SANDSTONE.getDefaultState());
        structure.fillWithBlocks(world, start, 77, -45, -5, 78, -45, -4, Blocks.SANDSTONE.getDefaultState());
        structure.fillWithBlocks(world, start, 77, -45, 18, 79, -45, 20, Blocks.SANDSTONE.getDefaultState());
        structure.fillWithBlocks(world, start, 77, -45, 35, 77, -45, 41, Blocks.SANDSTONE.getDefaultState());
        structure.fillWithBlocks(world, start, 77, -43, 65, 81, -43, 69, Blocks.SANDSTONE.getDefaultState());
        structure.fillWithBlocks(world, start, 77, -43, 81, 81, -43, 85, Blocks.SANDSTONE.getDefaultState());
        structure.fillWithBlocks(world, start, 77, -41, 46, 77, -41, 47, Blocks.AIR.getDefaultState());
        structure.fillWithBlocks(world, start, 77, -41, 48, 77, -40, 48, Blocks.STONE_BRICKS.getDefaultState());
        structure.fillWithBlocks(world, start, 77, -41, 49, 77, -41, 50, Blocks.AIR.getDefaultState());
        structure.fillWithBlocks(world, start, 77, -40, 44, 79, -40, 46, Blocks.SANDSTONE.getDefaultState());
        structure.fillWithBlocks(world, start, 77, -40, 50, 79, -40, 52, Blocks.SANDSTONE.getDefaultState());
        structure.fillWithBlocks(world, start, 77, -40, 71, 77, -36, 76, Blocks.AIR.getDefaultState());
        structure.fillWithBlocks(world, start, 77, -40, 82, 78, -40, 86, Blocks.AIR.getDefaultState());
        structure.fillWithBlocks(world, start, 77, -40, 88, 78, -40, 90, Blocks.AIR.getDefaultState());
        structure.fillWithBlocks(world, start, 77, -40, 91, 78, -40, 92, Blocks.STONE_BRICKS.getDefaultState());
        structure.fillWithBlocks(world, start, 77, -39, 42, 78, -39, 43, Blocks.STONE_BRICKS.getDefaultState());
        structure.fillWithBlocks(world, start, 77, -39, 44, 78, -39, 45, Blocks.AIR.getDefaultState());
        structure.fillWithBlocks(world, start, 77, -39, 46, 79, -37, 46, Blocks.STONE_BRICKS.getDefaultState());
        structure.fillWithBlocks(world, start, 77, -39, 50, 78, -39, 51, Blocks.STONE_BRICKS.getDefaultState());
        structure.fillWithBlocks(world, start, 77, -38, 44, 78, -38, 45, Blocks.AIR.getDefaultState());
        structure.fillWithBlocks(world, start, 77, -38, 50, 78, -38, 51, Blocks.STONE_BRICKS.getDefaultState());
        structure.fillWithBlocks(world, start, 77, -37, 44, 78, -37, 45, Blocks.AIR.getDefaultState());
        structure.fillWithBlocks(world, start, 77, -37, 50, 78, -37, 51, Blocks.STONE_BRICKS.getDefaultState());
        structure.fillWithBlocks(world, start, 77, -34, 64, 77, -34, 64, Blocks.STONE_BRICKS.getDefaultState());
        structure.fillWithBlocks(world, start, 77, -34, 66, 79, -34, 69, Blocks.STONE_BRICKS.getDefaultState());
        structure.fillWithBlocks(world, start, 77, -34, 71, 78, -34, 74, Blocks.STONE_BRICKS.getDefaultState());
        structure.fillWithBlocks(world, start, 77, -34, 76, 79, -34, 78, Blocks.STONE_BRICKS.getDefaultState());
        structure.fillWithBlocks(world, start, 77, -34, 80, 80, -34, 83, Blocks.STONE_BRICKS.getDefaultState());
        structure.fillWithBlocks(world, start, 77, -34, 85, 78, -34, 88, Blocks.STONE_BRICKS.getDefaultState());
        structure.fillWithBlocks(world, start, 77, -34, 90, 78, -34, 91, Blocks.STONE_BRICKS.getDefaultState());
        structure.fillWithBlocks(world, start, 77, -33, 63, 77, -33, 69, Blocks.STONE_BRICKS.getDefaultState());
        structure.fillWithBlocks(world, start, 77, -33, 70, 78, -33, 70, Blocks.AIR.getDefaultState());
        structure.fillWithBlocks(world, start, 77, -33, 71, 77, -31, 74, Blocks.STONE_BRICKS.getDefaultState());
        structure.fillWithBlocks(world, start, 77, -33, 77, 78, -33, 80, Blocks.STONE_BRICKS.getDefaultState());
        structure.fillWithBlocks(world, start, 77, -33, 82, 80, -33, 92, Blocks.STONE_BRICKS.getDefaultState());
        structure.fillWithBlocks(world, start, 77, -32, 76, 78, -32, 77, Blocks.STONE_BRICKS.getDefaultState());
        structure.fillWithBlocks(world, start, 77, -32, 78, 78, -32, 78, Blocks.AIR.getDefaultState());
        structure.fillWithBlocks(world, start, 77, -32, 79, 77, -32, 79, Blocks.STONE_BRICKS.getDefaultState());
        structure.fillWithBlocks(world, start, 77, -32, 81, 77, -31, 84, Blocks.STONE_BRICKS.getDefaultState());
        structure.fillWithBlocks(world, start, 77, -20, 46, 81, -20, 50, Blocks.SANDSTONE.getDefaultState());
        structure.fillWithBlocks(world, start, 77, -19, 46, 77, -17, 46, Blocks.STONE.getDefaultState());
        structure.fillWithBlocks(world, start, 77, -19, 50, 77, -17, 50, Blocks.STONE.getDefaultState());
        structure.fillWithBlocks(world, start, 77, -19, 76, 78, -19, 77, Blocks.SANDSTONE.getDefaultState());
        structure.fillWithBlocks(world, start, 77, -19, 90, 79, -19, 94, Blocks.SANDSTONE.getDefaultState());
        structure.fillWithBlocks(world, start, 77, -18, 72, 77, -18, 78, Blocks.SANDSTONE.getDefaultState());
        structure.fillWithBlocks(world, start, 77, -18, 88, 78, -18, 90, Blocks.SANDSTONE.getDefaultState());
        structure.fillWithBlocks(world, start, 77, -18, 94, 81, -14, 94, Blocks.SANDSTONE.getDefaultState());
        structure.fillWithBlocks(world, start, 77, -17, 70, 80, -17, 73, Blocks.SANDSTONE.getDefaultState());
        structure.fillWithBlocks(world, start, 77, -17, 86, 79, -17, 89, Blocks.SANDSTONE.getDefaultState());
        structure.fillWithBlocks(world, start, 77, -16, 93, 78, -16, 94, Blocks.SANDSTONE.getDefaultState());
        structure.fillWithBlocks(world, start, 77, -15, 80, 77, -15, 84, Blocks.AIR.getDefaultState());
        structure.fillWithBlocks(world, start, 77, -14, 70, 77, -14, 86, Blocks.SANDSTONE.getDefaultState());
        structure.fillWithBlocks(world, start, 77, -14, 88, 79, -14, 90, Blocks.SANDSTONE.getDefaultState());
        structure.fillWithBlocks(world, start, 77, -14, 91, 77, -14, 94, Blocks.SANDSTONE.getDefaultState());
        structure.fillWithBlocks(world, start, 77, -12, 75, 80, -12, 83, Blocks.SANDSTONE.getDefaultState());
        structure.fillWithBlocks(world, start, 77, -12, 89, 78, -12, 90, Blocks.SANDSTONE.getDefaultState());
        structure.fillWithBlocks(world, start, 77, -12, 92, 79, -12, 94, Blocks.SANDSTONE.getDefaultState());
        structure.fillWithBlocks(world, start, 77, -11, 46, 77, -10, 50, Blocks.SANDSTONE.getDefaultState());
        structure.fillWithBlocks(world, start, 77, -11, 80, 79, -11, 82, Blocks.SANDSTONE.getDefaultState());
        structure.fillWithBlocks(world, start, 77, -11, 85, 77, -11, 94, Blocks.SANDSTONE.getDefaultState());
        structure.fillWithBlocks(world, start, 77, -10, 42, 77, -10, 42, Blocks.SANDSTONE.getDefaultState());
        structure.fillWithBlocks(world, start, 77, -10, 43, 77, -10, 44, Blocks.AIR.getDefaultState());
        structure.fillWithBlocks(world, start, 77, -10, 45, 82, -10, 53, Blocks.SANDSTONE.getDefaultState());
        structure.fillWithBlocks(world, start, 77, -10, 54, 81, -6, 54, Blocks.SANDSTONE.getDefaultState());
        structure.fillWithBlocks(world, start, 77, -10, 76, 81, -10, 80, Blocks.SANDSTONE.getDefaultState());
        structure.fillWithBlocks(world, start, 77, -9, 42, 77, -9, 44, Blocks.SANDSTONE.getDefaultState());
        structure.fillWithBlocks(world, start, 77, -9, 45, 78, -9, 51, Blocks.AIR.getDefaultState());
        structure.fillWithBlocks(world, start, 77, -9, 52, 79, -9, 54, Blocks.SANDSTONE.getDefaultState());
        structure.fillWithBlocks(world, start, 77, -9, 76, 77, -7, 76, Blocks.STONE.getDefaultState());
        structure.fillWithBlocks(world, start, 77, -9, 80, 77, -7, 80, Blocks.STONE.getDefaultState());
        structure.fillWithBlocks(world, start, 77, -8, 42, 79, -8, 44, Blocks.SANDSTONE.getDefaultState());
        structure.fillWithBlocks(world, start, 77, -8, 45, 78, -8, 51, Blocks.AIR.getDefaultState());
        structure.fillWithBlocks(world, start, 77, -8, 52, 79, -8, 54, Blocks.SANDSTONE.getDefaultState());
        structure.fillWithBlocks(world, start, 77, -7, 42, 79, -7, 44, Blocks.SANDSTONE.getDefaultState());
        structure.fillWithBlocks(world, start, 77, -7, 52, 79, -7, 54, Blocks.SANDSTONE.getDefaultState());
        structure.fillWithBlocks(world, start, 77, -6, 52, 79, -6, 54, Blocks.SANDSTONE.getDefaultState());
        structure.fillWithBlocks(world, start, 77, -6, 76, 81, -6, 80, Blocks.SANDSTONE.getDefaultState());
        structure.fillWithBlocks(world, start, 77, -5, 42, 77, -4, 42, Blocks.AIR.getDefaultState());
        structure.fillWithBlocks(world, start, 77, -5, 43, 79, -5, 45, Blocks.SANDSTONE.getDefaultState());
        structure.fillWithBlocks(world, start, 77, -4, 43, 80, -4, 54, Blocks.SANDSTONE.getDefaultState());
        structure.fillWithBlocks(world, start, 77, -3, 42, 77, -3, 53, Blocks.SANDSTONE.getDefaultState());
        structure.fillWithBlocks(world, start, 77, -3, 54, 77, -2, 54, Blocks.AIR.getDefaultState());
        structure.fillWithBlocks(world, start, 77, -2, 43, 78, -2, 44, Blocks.SANDSTONE.getDefaultState());
        structure.fillWithBlocks(world, start, 77, -2, 46, 77, -2, 46, Blocks.SANDSTONE.getDefaultState());
        structure.fillWithBlocks(world, start, 77, -2, 48, 82, -2, 53, Blocks.SANDSTONE.getDefaultState());
        structure.fillWithBlocks(world, start, 77, -1, 52, 79, -1, 54, Blocks.SANDSTONE.getDefaultState());
        structure.fillWithBlocks(world, start, 77, 1, 11, 109, 1, 142, Blocks.STONE.getDefaultState());
        structure.fillWithBlocks(world, start, 77, 2, 5, 84, 2, 12, Blocks.SANDSTONE.getDefaultState());
        structure.fillWithBlocks(world, start, 77, 2, 13, 82, 6, 13, Blocks.SANDSTONE.getDefaultState());
        structure.fillWithBlocks(world, start, 77, 2, 143, 78, 2, 144, Blocks.STONE.getDefaultState());
        structure.fillWithBlocks(world, start, 77, 2, 145, 77, 2, 159, Blocks.SANDSTONE.getDefaultState());
        structure.fillWithBlocks(world, start, 77, 8, 26, 77, 8, 47, Blocks.SANDSTONE.getDefaultState());
        structure.fillWithBlocks(world, start, 77, 8, 114, 78, 9, 114, Blocks.STONE.getDefaultState());
        structure.fillWithBlocks(world, start, 77, 8, 115, 77, 8, 135, Blocks.SANDSTONE.getDefaultState());
        structure.fillWithBlocks(world, start, 77, 8, 136, 83, 8, 142, Blocks.SAND.getDefaultState());
        structure.fillWithBlocks(world, start, 77, 9, 23, 77, 11, 23, Blocks.CACTUS.getDefaultState().with(CactusBlock.AGE, 0));
        structure.fillWithBlocks(world, start, 77, 9, 25, 78, 9, 26, Blocks.SAND.getDefaultState());
        structure.fillWithBlocks(world, start, 77, 9, 27, 81, 9, 47, Blocks.SANDSTONE.getDefaultState());
        structure.fillWithBlocks(world, start, 77, 9, 115, 77, 9, 134, Blocks.SANDSTONE.getDefaultState());
        structure.fillWithBlocks(world, start, 77, 9, 135, 78, 9, 137, Blocks.SAND.getDefaultState());
        structure.fillWithBlocks(world, start, 77, 10, 27, 78, 10, 47, Blocks.SANDSTONE.getDefaultState());
        structure.fillWithBlocks(world, start, 77, 10, 109, 81, 10, 113, Blocks.STONE.getDefaultState());
        structure.fillWithBlocks(world, start, 77, 10, 114, 77, 10, 114, Blocks.STONE.getDefaultState());
        structure.fillWithBlocks(world, start, 77, 10, 115, 77, 10, 134, Blocks.SANDSTONE.getDefaultState());
        structure.fillWithBlocks(world, start, 77, 11, 28, 83, 11, 47, Blocks.SANDSTONE.getDefaultState());
        structure.fillWithBlocks(world, start, 77, 11, 115, 77, 11, 133, Blocks.SANDSTONE.getDefaultState());
        structure.fillWithBlocks(world, start, 77, 12, 28, 77, 12, 47, Blocks.SANDSTONE.getDefaultState());
        structure.fillWithBlocks(world, start, 77, 12, 70, 77, 16, 74, Blocks.CUT_SANDSTONE.getDefaultState());
        structure.fillWithBlocks(world, start, 77, 12, 76, 82, 12, 76, Blocks.CUT_SANDSTONE.getDefaultState());
        structure.fillWithBlocks(world, start, 77, 12, 80, 82, 12, 80, Blocks.CUT_SANDSTONE.getDefaultState());
        structure.fillWithBlocks(world, start, 77, 12, 82, 77, 17, 87, Blocks.CUT_SANDSTONE.getDefaultState());
        structure.fillWithBlocks(world, start, 77, 12, 115, 77, 12, 133, Blocks.SANDSTONE.getDefaultState());
        structure.fillWithBlocks(world, start, 77, 13, 30, 87, 13, 47, Blocks.SANDSTONE.getDefaultState());
        structure.fillWithBlocks(world, start, 77, 13, 75, 77, 13, 75, Blocks.CUT_SANDSTONE.getDefaultState());
        structure.fillWithBlocks(world, start, 77, 13, 81, 77, 13, 87, Blocks.CUT_SANDSTONE.getDefaultState());
        structure.fillWithBlocks(world, start, 77, 13, 115, 77, 13, 132, Blocks.SANDSTONE.getDefaultState());
        structure.fillWithBlocks(world, start, 77, 14, 30, 78, 14, 47, Blocks.SANDSTONE.getDefaultState());
        structure.fillWithBlocks(world, start, 77, 14, 76, 82, 14, 76, Blocks.CUT_SANDSTONE.getDefaultState());
        structure.fillWithBlocks(world, start, 77, 14, 80, 82, 14, 80, Blocks.CUT_SANDSTONE.getDefaultState());
        structure.fillWithBlocks(world, start, 77, 14, 109, 77, 14, 109, Blocks.GRANITE.getDefaultState());
        structure.fillWithBlocks(world, start, 77, 14, 110, 77, 14, 114, Blocks.STONE.getDefaultState());
        structure.fillWithBlocks(world, start, 77, 14, 115, 77, 14, 132, Blocks.SANDSTONE.getDefaultState());
        structure.fillWithBlocks(world, start, 77, 15, 75, 77, 15, 75, Blocks.CUT_SANDSTONE.getDefaultState());
        structure.fillWithBlocks(world, start, 77, 15, 81, 77, 15, 87, Blocks.CUT_SANDSTONE.getDefaultState());
        structure.fillWithBlocks(world, start, 77, 15, 109, 78, 15, 110, Blocks.GRAVEL.getDefaultState());
        structure.fillWithBlocks(world, start, 77, 15, 111, 77, 15, 112, Blocks.GRANITE.getDefaultState());
        structure.fillWithBlocks(world, start, 77, 15, 113, 77, 15, 114, Blocks.STONE.getDefaultState());
        structure.fillWithBlocks(world, start, 77, 15, 115, 77, 15, 131, Blocks.SANDSTONE.getDefaultState());
        structure.fillWithBlocks(world, start, 77, 16, 31, 79, 18, 31, Blocks.SAND.getDefaultState());
        structure.fillWithBlocks(world, start, 77, 16, 32, 80, 16, 47, Blocks.SANDSTONE.getDefaultState());
        structure.fillWithBlocks(world, start, 77, 16, 76, 82, 16, 76, Blocks.CUT_SANDSTONE.getDefaultState());
        structure.fillWithBlocks(world, start, 77, 16, 80, 82, 16, 80, Blocks.CUT_SANDSTONE.getDefaultState());
        structure.fillWithBlocks(world, start, 77, 16, 111, 77, 16, 111, Blocks.GRAVEL.getDefaultState());
        structure.fillWithBlocks(world, start, 77, 16, 112, 77, 16, 113, Blocks.GRANITE.getDefaultState());
        structure.fillWithBlocks(world, start, 77, 16, 114, 77, 46, 114, Blocks.STONE.getDefaultState());
        structure.fillWithBlocks(world, start, 77, 16, 115, 77, 16, 131, Blocks.SANDSTONE.getDefaultState());
        structure.fillWithBlocks(world, start, 77, 17, 70, 77, 21, 74, Blocks.CUT_SANDSTONE.getDefaultState());
        structure.fillWithBlocks(world, start, 77, 17, 75, 77, 17, 75, Blocks.CUT_SANDSTONE.getDefaultState());
        structure.fillWithBlocks(world, start, 77, 17, 81, 77, 17, 87, Blocks.CUT_SANDSTONE.getDefaultState());
        structure.fillWithBlocks(world, start, 77, 17, 111, 77, 17, 111, Blocks.GRAVEL.getDefaultState());
        structure.fillWithBlocks(world, start, 77, 17, 112, 77, 17, 113, Blocks.GRANITE.getDefaultState());
        structure.fillWithBlocks(world, start, 77, 17, 115, 77, 17, 130, Blocks.SANDSTONE.getDefaultState());
        structure.fillWithBlocks(world, start, 77, 18, 76, 77, 18, 76, Blocks.CUT_SANDSTONE.getDefaultState());
        structure.fillWithBlocks(world, start, 77, 18, 78, 77, 18, 78, Blocks.CUT_SANDSTONE.getDefaultState());
        structure.fillWithBlocks(world, start, 77, 18, 80, 80, 18, 80, Blocks.CUT_SANDSTONE.getDefaultState());
        structure.fillWithBlocks(world, start, 77, 18, 82, 77, 21, 87, Blocks.CUT_SANDSTONE.getDefaultState());
        structure.fillWithBlocks(world, start, 77, 18, 109, 78, 18, 110, Blocks.GRAVEL.getDefaultState());
        structure.fillWithBlocks(world, start, 77, 18, 113, 77, 18, 114, Blocks.STONE.getDefaultState());
        structure.fillWithBlocks(world, start, 77, 18, 115, 77, 18, 130, Blocks.SANDSTONE.getDefaultState());
        structure.fillWithBlocks(world, start, 77, 19, 75, 77, 21, 75, Blocks.CUT_SANDSTONE.getDefaultState());
        structure.fillWithBlocks(world, start, 77, 19, 77, 77, 21, 77, Blocks.CUT_SANDSTONE.getDefaultState());
        structure.fillWithBlocks(world, start, 77, 19, 79, 77, 21, 79, Blocks.CUT_SANDSTONE.getDefaultState());
        structure.fillWithBlocks(world, start, 77, 19, 81, 77, 21, 87, Blocks.CUT_SANDSTONE.getDefaultState());
        structure.fillWithBlocks(world, start, 77, 19, 109, 77, 19, 112, Blocks.GRANITE.getDefaultState());
        structure.fillWithBlocks(world, start, 77, 19, 113, 78, 19, 114, Blocks.STONE.getDefaultState());
        structure.fillWithBlocks(world, start, 77, 19, 115, 77, 19, 129, Blocks.SANDSTONE.getDefaultState());
        structure.fillWithBlocks(world, start, 77, 20, 76, 77, 21, 87, Blocks.CUT_SANDSTONE.getDefaultState());
        structure.fillWithBlocks(world, start, 77, 20, 109, 81, 24, 109, Blocks.STONE.getDefaultState());
        structure.fillWithBlocks(world, start, 77, 20, 110, 78, 20, 111, Blocks.GRANITE.getDefaultState());
        structure.fillWithBlocks(world, start, 77, 20, 112, 77, 20, 114, Blocks.STONE.getDefaultState());
        structure.fillWithBlocks(world, start, 77, 20, 115, 77, 20, 129, Blocks.SANDSTONE.getDefaultState());
        structure.fillWithBlocks(world, start, 77, 21, 115, 77, 21, 128, Blocks.SANDSTONE.getDefaultState());
        structure.fillWithBlocks(world, start, 77, 21, 129, 77, 21, 130, Blocks.SAND.getDefaultState());
        structure.fillWithBlocks(world, start, 77, 22, 115, 77, 22, 128, Blocks.SANDSTONE.getDefaultState());
        structure.fillWithBlocks(world, start, 77, 23, 35, 77, 23, 39, Blocks.SAND.getDefaultState());
        structure.fillWithBlocks(world, start, 77, 23, 115, 77, 23, 127, Blocks.SANDSTONE.getDefaultState());
        structure.fillWithBlocks(world, start, 77, 23, 128, 77, 23, 129, Blocks.SAND.getDefaultState());
        structure.fillWithBlocks(world, start, 77, 24, 115, 77, 24, 127, Blocks.SANDSTONE.getDefaultState());
        structure.fillWithBlocks(world, start, 77, 25, 115, 77, 25, 126, Blocks.SANDSTONE.getDefaultState());
        structure.fillWithBlocks(world, start, 77, 26, 115, 77, 26, 126, Blocks.SANDSTONE.getDefaultState());
        structure.fillWithBlocks(world, start, 77, 27, 115, 77, 27, 125, Blocks.SANDSTONE.getDefaultState());
        structure.fillWithBlocks(world, start, 77, 27, 126, 77, 27, 127, Blocks.SAND.getDefaultState());
        structure.fillWithBlocks(world, start, 77, 28, 115, 77, 28, 125, Blocks.SANDSTONE.getDefaultState());
        structure.fillWithBlocks(world, start, 77, 29, 115, 77, 29, 124, Blocks.SANDSTONE.getDefaultState());
        structure.fillWithBlocks(world, start, 77, 29, 125, 77, 29, 126, Blocks.SAND.getDefaultState());
        structure.fillWithBlocks(world, start, 77, 30, 115, 77, 30, 124, Blocks.SANDSTONE.getDefaultState());
        structure.fillWithBlocks(world, start, 77, 30, 125, 79, 30, 125, Blocks.SAND.getDefaultState());
        structure.fillWithBlocks(world, start, 77, 31, 44, 77, 31, 47, Blocks.SANDSTONE.getDefaultState());
        structure.fillWithBlocks(world, start, 77, 31, 115, 77, 31, 123, Blocks.SANDSTONE.getDefaultState());
        structure.fillWithBlocks(world, start, 77, 31, 124, 77, 31, 125, Blocks.SAND.getDefaultState());
        structure.fillWithBlocks(world, start, 77, 32, 44, 80, 34, 44, Blocks.SAND.getDefaultState());
        structure.fillWithBlocks(world, start, 77, 32, 45, 78, 32, 47, Blocks.SANDSTONE.getDefaultState());
        structure.fillWithBlocks(world, start, 77, 32, 115, 77, 32, 123, Blocks.SANDSTONE.getDefaultState());
        structure.fillWithBlocks(world, start, 77, 32, 124, 78, 32, 124, Blocks.SAND.getDefaultState());
        structure.fillWithBlocks(world, start, 77, 33, 115, 77, 33, 122, Blocks.SANDSTONE.getDefaultState());
        structure.fillWithBlocks(world, start, 77, 33, 123, 77, 33, 124, Blocks.SAND.getDefaultState());
        structure.fillWithBlocks(world, start, 77, 34, 43, 77, 34, 45, Blocks.SAND.getDefaultState());
        structure.fillWithBlocks(world, start, 77, 34, 46, 77, 35, 47, Blocks.SANDSTONE.getDefaultState());
        structure.fillWithBlocks(world, start, 77, 34, 115, 77, 34, 122, Blocks.SANDSTONE.getDefaultState());
        structure.fillWithBlocks(world, start, 77, 34, 123, 78, 34, 123, Blocks.SAND.getDefaultState());
        structure.fillWithBlocks(world, start, 77, 35, 115, 77, 35, 122, Blocks.SANDSTONE.getDefaultState());
        structure.fillWithBlocks(world, start, 77, 36, 45, 79, 36, 47, Blocks.SAND.getDefaultState());
        structure.fillWithBlocks(world, start, 77, 36, 115, 77, 36, 121, Blocks.SANDSTONE.getDefaultState());
        structure.fillWithBlocks(world, start, 77, 36, 122, 78, 36, 122, Blocks.SAND.getDefaultState());
        structure.fillWithBlocks(world, start, 77, 37, 47, 78, 37, 48, Blocks.SAND.getDefaultState());
        structure.fillWithBlocks(world, start, 77, 37, 49, 78, 37, 52, Blocks.STONE.getDefaultState());
        structure.fillWithBlocks(world, start, 77, 37, 53, 78, 37, 54, Blocks.SANDSTONE.getDefaultState());
        structure.fillWithBlocks(world, start, 77, 37, 55, 77, 37, 101, Blocks.STONE.getDefaultState());
        structure.fillWithBlocks(world, start, 77, 37, 102, 78, 37, 103, Blocks.SANDSTONE.getDefaultState());
        structure.fillWithBlocks(world, start, 77, 37, 104, 78, 37, 114, Blocks.STONE.getDefaultState());
        structure.fillWithBlocks(world, start, 77, 37, 115, 77, 37, 121, Blocks.SANDSTONE.getDefaultState());
        structure.fillWithBlocks(world, start, 77, 38, 47, 78, 38, 48, Blocks.SAND.getDefaultState());
        structure.fillWithBlocks(world, start, 77, 38, 49, 78, 38, 50, Blocks.STONE.getDefaultState());
        structure.fillWithBlocks(world, start, 77, 38, 51, 77, 39, 52, Blocks.STONE.getDefaultState());
        structure.fillWithBlocks(world, start, 77, 38, 53, 78, 38, 58, Blocks.SANDSTONE.getDefaultState());
        structure.fillWithBlocks(world, start, 77, 38, 62, 77, 39, 63, Blocks.SANDSTONE.getDefaultState());
        structure.fillWithBlocks(world, start, 77, 38, 70, 77, 39, 71, Blocks.SANDSTONE.getDefaultState());
        structure.fillWithBlocks(world, start, 77, 38, 77, 77, 40, 79, Blocks.SANDSTONE.getDefaultState());
        structure.fillWithBlocks(world, start, 77, 38, 85, 77, 39, 86, Blocks.SANDSTONE.getDefaultState());
        structure.fillWithBlocks(world, start, 77, 38, 87, 77, 39, 92, Blocks.STONE.getDefaultState());
        structure.fillWithBlocks(world, start, 77, 38, 93, 77, 39, 94, Blocks.SANDSTONE.getDefaultState());
        structure.fillWithBlocks(world, start, 77, 38, 95, 77, 39, 97, Blocks.STONE.getDefaultState());
        structure.fillWithBlocks(world, start, 77, 38, 98, 78, 38, 103, Blocks.SANDSTONE.getDefaultState());
        structure.fillWithBlocks(world, start, 77, 38, 115, 77, 38, 121, Blocks.SANDSTONE.getDefaultState());
        structure.fillWithBlocks(world, start, 77, 39, 55, 78, 39, 58, Blocks.SANDSTONE.getDefaultState());
        structure.fillWithBlocks(world, start, 77, 39, 100, 78, 39, 101, Blocks.SANDSTONE.getDefaultState());
        structure.fillWithBlocks(world, start, 77, 39, 115, 77, 39, 120, Blocks.SANDSTONE.getDefaultState());
        structure.fillWithBlocks(world, start, 77, 39, 121, 77, 41, 121, Blocks.SAND.getDefaultState());
        structure.fillWithBlocks(world, start, 77, 40, 115, 77, 40, 120, Blocks.SANDSTONE.getDefaultState());
        structure.fillWithBlocks(world, start, 77, 41, 47, 78, 41, 48, Blocks.SAND.getDefaultState());
        structure.fillWithBlocks(world, start, 77, 41, 49, 78, 41, 52, Blocks.SANDSTONE.getDefaultState());
        structure.fillWithBlocks(world, start, 77, 41, 53, 78, 41, 54, Blocks.SAND.getDefaultState());
        structure.fillWithBlocks(world, start, 77, 41, 55, 77, 41, 56, Blocks.SANDSTONE.getDefaultState());
        structure.fillWithBlocks(world, start, 77, 41, 57, 77, 42, 58, Blocks.SAND.getDefaultState());
        structure.fillWithBlocks(world, start, 77, 41, 59, 78, 41, 60, Blocks.SANDSTONE.getDefaultState());
        structure.fillWithBlocks(world, start, 77, 41, 61, 77, 42, 61, Blocks.SANDSTONE.getDefaultState());
        structure.fillWithBlocks(world, start, 77, 41, 62, 77, 42, 63, Blocks.SAND.getDefaultState());
        structure.fillWithBlocks(world, start, 77, 41, 64, 77, 43, 66, Blocks.SANDSTONE.getDefaultState());
        structure.fillWithBlocks(world, start, 77, 41, 67, 77, 42, 68, Blocks.SANDSTONE.getDefaultState());
        structure.fillWithBlocks(world, start, 77, 41, 70, 77, 42, 71, Blocks.SAND.getDefaultState());
        structure.fillWithBlocks(world, start, 77, 41, 72, 77, 42, 75, Blocks.SANDSTONE.getDefaultState());
        structure.fillWithBlocks(world, start, 77, 41, 77, 77, 43, 79, Blocks.SAND.getDefaultState());
        structure.fillWithBlocks(world, start, 77, 41, 80, 77, 42, 84, Blocks.SANDSTONE.getDefaultState());
        structure.fillWithBlocks(world, start, 77, 41, 85, 77, 42, 86, Blocks.SAND.getDefaultState());
        structure.fillWithBlocks(world, start, 77, 41, 87, 77, 41, 92, Blocks.SANDSTONE.getDefaultState());
        structure.fillWithBlocks(world, start, 77, 41, 93, 77, 42, 94, Blocks.SAND.getDefaultState());
        structure.fillWithBlocks(world, start, 77, 41, 95, 77, 41, 97, Blocks.SANDSTONE.getDefaultState());
        structure.fillWithBlocks(world, start, 77, 41, 98, 77, 42, 99, Blocks.SAND.getDefaultState());
        structure.fillWithBlocks(world, start, 77, 41, 100, 77, 41, 101, Blocks.SANDSTONE.getDefaultState());
        structure.fillWithBlocks(world, start, 77, 41, 102, 78, 41, 103, Blocks.SAND.getDefaultState());
        structure.fillWithBlocks(world, start, 77, 41, 104, 78, 41, 108, Blocks.SANDSTONE.getDefaultState());
        structure.fillWithBlocks(world, start, 77, 41, 115, 77, 41, 120, Blocks.SANDSTONE.getDefaultState());
        structure.fillWithBlocks(world, start, 77, 42, 49, 78, 42, 50, Blocks.SANDSTONE.getDefaultState());
        structure.fillWithBlocks(world, start, 77, 42, 53, 78, 42, 56, Blocks.SAND.getDefaultState());
        structure.fillWithBlocks(world, start, 77, 42, 69, 77, 44, 71, Blocks.SAND.getDefaultState());
        structure.fillWithBlocks(world, start, 77, 42, 76, 77, 44, 79, Blocks.SAND.getDefaultState());
        structure.fillWithBlocks(world, start, 77, 42, 87, 77, 44, 87, Blocks.SAND.getDefaultState());
        structure.fillWithBlocks(world, start, 77, 42, 88, 77, 42, 92, Blocks.SANDSTONE.getDefaultState());
        structure.fillWithBlocks(world, start, 77, 42, 95, 77, 42, 97, Blocks.SANDSTONE.getDefaultState());
        structure.fillWithBlocks(world, start, 77, 42, 100, 78, 42, 103, Blocks.SAND.getDefaultState());
        structure.fillWithBlocks(world, start, 77, 42, 115, 77, 42, 120, Blocks.SANDSTONE.getDefaultState());
        structure.fillWithBlocks(world, start, 77, 43, 49, 78, 43, 50, Blocks.SANDSTONE.getDefaultState());
        structure.fillWithBlocks(world, start, 77, 43, 55, 78, 43, 56, Blocks.SAND.getDefaultState());
        structure.fillWithBlocks(world, start, 77, 43, 59, 77, 45, 61, Blocks.SAND.getDefaultState());
        structure.fillWithBlocks(world, start, 77, 43, 67, 77, 44, 71, Blocks.SAND.getDefaultState());
        structure.fillWithBlocks(world, start, 77, 43, 74, 77, 44, 82, Blocks.SAND.getDefaultState());
        structure.fillWithBlocks(world, start, 77, 43, 83, 77, 43, 84, Blocks.SANDSTONE.getDefaultState());
        structure.fillWithBlocks(world, start, 77, 43, 88, 77, 44, 89, Blocks.SAND.getDefaultState());
        structure.fillWithBlocks(world, start, 77, 43, 90, 77, 43, 92, Blocks.SANDSTONE.getDefaultState());
        structure.fillWithBlocks(world, start, 77, 43, 95, 77, 45, 101, Blocks.SAND.getDefaultState());
        structure.fillWithBlocks(world, start, 77, 43, 115, 77, 45, 117, Blocks.SANDSTONE.getDefaultState());
        structure.fillWithBlocks(world, start, 77, 43, 119, 77, 44, 119, Blocks.SANDSTONE.getDefaultState());
        structure.fillWithBlocks(world, start, 77, 43, 120, 77, 45, 120, Blocks.SAND.getDefaultState());
        structure.fillWithBlocks(world, start, 77, 44, 47, 77, 44, 108, Blocks.SAND.getDefaultState());
        structure.fillWithBlocks(world, start, 77, 45, 71, 77, 45, 75, Blocks.SAND.getDefaultState());
        structure.fillWithBlocks(world, start, 77, 45, 78, 77, 45, 85, Blocks.SAND.getDefaultState());
        structure.fillWithBlocks(world, start, 77, 45, 88, 77, 45, 93, Blocks.SAND.getDefaultState());
        structure.fillWithBlocks(world, start, 77, 45, 109, 79, 47, 109, Blocks.SAND.getDefaultState());
        structure.fillWithBlocks(world, start, 77, 45, 110, 79, 45, 113, Blocks.STONE.getDefaultState());
        structure.fillWithBlocks(world, start, 77, 45, 118, 77, 46, 119, Blocks.SAND.getDefaultState());
        structure.fillWithBlocks(world, start, 77, 46, 64, 77, 46, 66, Blocks.SAND.getDefaultState());
        structure.fillWithBlocks(world, start, 77, 46, 72, 77, 46, 73, Blocks.SAND.getDefaultState());
        structure.fillWithBlocks(world, start, 77, 46, 83, 77, 46, 84, Blocks.SAND.getDefaultState());
        structure.fillWithBlocks(world, start, 77, 46, 90, 77, 46, 92, Blocks.SAND.getDefaultState());
        structure.fillWithBlocks(world, start, 77, 46, 104, 78, 46, 113, Blocks.SAND.getDefaultState());
        structure.fillWithBlocks(world, start, 77, 46, 115, 77, 48, 117, Blocks.SAND.getDefaultState());
        structure.fillWithBlocks(world, start, 77, 47, 48, 77, 47, 50, Blocks.SAND.getDefaultState());
        structure.fillWithBlocks(world, start, 77, 47, 104, 77, 47, 119, Blocks.SAND.getDefaultState());
        structure.fillWithBlocks(world, start, 77, 48, 104, 77, 48, 117, Blocks.SAND.getDefaultState());
        structure.fillWithBlocks(world, start, 77, 49, 106, 77, 49, 116, Blocks.SAND.getDefaultState());
        structure.fillWithBlocks(world, start, 77, 51, 111, 77, 51, 115, Blocks.SAND.getDefaultState());
        structure.fillWithBlocks(world, start, 77, 52, 112, 77, 53, 114, Blocks.SAND.getDefaultState());
        structure.fillWithBlocks(world, start, 78, -51, -18, 80, -51, -16, Blocks.SANDSTONE.getDefaultState());
        structure.fillWithBlocks(world, start, 78, -50, 18, 84, -50, 24, Blocks.SANDSTONE.getDefaultState());
        structure.fillWithBlocks(world, start, 78, -50, 25, 78, -50, 31, Blocks.AIR.getDefaultState());
        structure.fillWithBlocks(world, start, 78, -50, 32, 84, -50, 57, Blocks.SANDSTONE.getDefaultState());
        structure.fillWithBlocks(world, start, 78, -50, 80, 83, -50, 85, Blocks.SANDSTONE.getDefaultState());
        structure.fillWithBlocks(world, start, 78, -49, -19, 78, -41, -19, Blocks.SANDSTONE.getDefaultState());
        structure.fillWithBlocks(world, start, 78, -49, -18, 80, -49, -16, Blocks.AIR.getDefaultState());
        structure.fillWithBlocks(world, start, 78, -49, -15, 78, -41, -15, Blocks.SANDSTONE.getDefaultState());
        structure.fillWithBlocks(world, start, 78, -49, -14, 78, -49, -10, Blocks.IRON_BARS.getDefaultState().with(FourWayBlock.WATERLOGGED, false).with(FourWayBlock.NORTH, true).with(FourWayBlock.SOUTH, true).with(FourWayBlock.EAST, true).with(FourWayBlock.WEST, true));
        structure.fillWithBlocks(world, start, 78, -49, -9, 78, -41, -9, Blocks.SANDSTONE.getDefaultState());
        structure.fillWithBlocks(world, start, 78, -49, -8, 78, -49, -6, Blocks.IRON_BARS.getDefaultState().with(FourWayBlock.WATERLOGGED, false).with(FourWayBlock.NORTH, true).with(FourWayBlock.SOUTH, true).with(FourWayBlock.EAST, true).with(FourWayBlock.WEST, true));
        structure.fillWithBlocks(world, start, 78, -49, -5, 78, -49, 20, Blocks.SANDSTONE.getDefaultState());
        structure.fillWithBlocks(world, start, 78, -49, 21, 79, -49, 22, Blocks.AIR.getDefaultState());
        structure.fillWithBlocks(world, start, 78, -49, 23, 78, -45, 23, Blocks.AIR.getDefaultState());
        structure.fillWithBlocks(world, start, 78, -49, 24, 78, -41, 24, Blocks.SANDSTONE.getDefaultState());
        structure.fillWithBlocks(world, start, 78, -49, 32, 78, -41, 32, Blocks.SANDSTONE.getDefaultState());
        structure.fillWithBlocks(world, start, 78, -49, 33, 78, -49, 35, Blocks.AIR.getDefaultState());
        structure.fillWithBlocks(world, start, 78, -49, 36, 83, -49, 41, Blocks.SANDSTONE.getDefaultState());
        structure.fillWithBlocks(world, start, 78, -49, 42, 78, -41, 42, Blocks.SANDSTONE.getDefaultState());
        structure.fillWithBlocks(world, start, 78, -49, 54, 78, -49, 67, Blocks.SANDSTONE.getDefaultState());
        structure.fillWithBlocks(world, start, 78, -49, 68, 79, -49, 82, Blocks.AIR.getDefaultState());
        structure.fillWithBlocks(world, start, 78, -49, 83, 80, -49, 85, Blocks.SANDSTONE.getDefaultState());
        structure.fillWithBlocks(world, start, 78, -48, -18, 80, -48, -16, Blocks.AIR.getDefaultState());
        structure.fillWithBlocks(world, start, 78, -48, -14, 82, -48, -10, Blocks.AIR.getDefaultState());
        structure.fillWithBlocks(world, start, 78, -48, -8, 80, -48, -6, Blocks.AIR.getDefaultState());
        structure.fillWithBlocks(world, start, 78, -48, -5, 78, -48, -2, Blocks.SANDSTONE.getDefaultState());
        structure.fillWithBlocks(world, start, 78, -48, 0, 78, -47, 4, Blocks.SANDSTONE.getDefaultState());
        structure.fillWithBlocks(world, start, 78, -48, 6, 78, -47, 10, Blocks.SANDSTONE.getDefaultState());
        structure.fillWithBlocks(world, start, 78, -48, 12, 78, -47, 16, Blocks.SANDSTONE.getDefaultState());
        structure.fillWithBlocks(world, start, 78, -48, 18, 80, -48, 20, Blocks.SANDSTONE.getDefaultState());
        structure.fillWithBlocks(world, start, 78, -48, 21, 79, -48, 22, Blocks.AIR.getDefaultState());
        structure.fillWithBlocks(world, start, 78, -48, 33, 78, -48, 35, Blocks.AIR.getDefaultState());
        structure.fillWithBlocks(world, start, 78, -48, 36, 79, -48, 37, Blocks.SANDSTONE.getDefaultState());
        structure.fillWithBlocks(world, start, 78, -48, 39, 80, -48, 41, Blocks.SANDSTONE.getDefaultState());
        structure.fillWithBlocks(world, start, 78, -48, 54, 78, -48, 58, Blocks.SANDSTONE.getDefaultState());
        structure.fillWithBlocks(world, start, 78, -48, 60, 78, -47, 64, Blocks.SANDSTONE.getDefaultState());
        structure.fillWithBlocks(world, start, 78, -48, 66, 79, -48, 67, Blocks.SANDSTONE.getDefaultState());
        structure.fillWithBlocks(world, start, 78, -48, 68, 79, -48, 82, Blocks.AIR.getDefaultState());
        structure.fillWithBlocks(world, start, 78, -47, -18, 80, -47, -16, Blocks.AIR.getDefaultState());
        structure.fillWithBlocks(world, start, 78, -47, -14, 82, -47, -10, Blocks.AIR.getDefaultState());
        structure.fillWithBlocks(world, start, 78, -47, -8, 80, -47, -6, Blocks.AIR.getDefaultState());
        structure.fillWithBlocks(world, start, 78, -47, -5, 78, -47, 20, Blocks.SANDSTONE.getDefaultState());
        structure.fillWithBlocks(world, start, 78, -47, 21, 79, -47, 22, Blocks.AIR.getDefaultState());
        structure.fillWithBlocks(world, start, 78, -47, 33, 78, -47, 35, Blocks.AIR.getDefaultState());
        structure.fillWithBlocks(world, start, 78, -47, 36, 83, -47, 41, Blocks.SANDSTONE.getDefaultState());
        structure.fillWithBlocks(world, start, 78, -47, 54, 78, -47, 67, Blocks.SANDSTONE.getDefaultState());
        structure.fillWithBlocks(world, start, 78, -47, 68, 79, -47, 82, Blocks.AIR.getDefaultState());
        structure.fillWithBlocks(world, start, 78, -47, 83, 80, -47, 85, Blocks.SANDSTONE.getDefaultState());
        structure.fillWithBlocks(world, start, 78, -46, -18, 80, -46, -16, Blocks.AIR.getDefaultState());
        structure.fillWithBlocks(world, start, 78, -46, -14, 82, -46, -10, Blocks.AIR.getDefaultState());
        structure.fillWithBlocks(world, start, 78, -46, -8, 80, -46, -6, Blocks.AIR.getDefaultState());
        structure.fillWithBlocks(world, start, 78, -46, -5, 78, -46, -4, Blocks.SANDSTONE.getDefaultState());
        structure.fillWithBlocks(world, start, 78, -46, 18, 80, -46, 20, Blocks.SANDSTONE.getDefaultState());
        structure.fillWithBlocks(world, start, 78, -46, 21, 79, -46, 22, Blocks.AIR.getDefaultState());
