package mod.arcalitegames.odyssey.world.structure.structures.towers.witch_tower;

import mod.arcalitegames.odyssey.world.structure.StructureBase;
import net.minecraft.block.BarrelBlock;
import net.minecraft.block.BedBlock;
import net.minecraft.block.Blocks;
import net.minecraft.block.BrewingStandBlock;
import net.minecraft.block.CauldronBlock;
import net.minecraft.block.ChainBlock;
import net.minecraft.block.DoorBlock;
import net.minecraft.block.HorizontalBlock;
import net.minecraft.block.LadderBlock;
import net.minecraft.block.LanternBlock;
import net.minecraft.block.LecternBlock;
import net.minecraft.block.RedstoneOreBlock;
import net.minecraft.block.ScaffoldingBlock;
import net.minecraft.block.SlabBlock;
import net.minecraft.block.SnowyDirtBlock;
import net.minecraft.block.StairsBlock;
import net.minecraft.state.properties.BedPart;
import net.minecraft.state.properties.DoorHingeSide;
import net.minecraft.state.properties.DoubleBlockHalf;
import net.minecraft.state.properties.Half;
import net.minecraft.state.properties.SlabType;
import net.minecraft.state.properties.StairsShape;
import net.minecraft.util.Direction;
import net.minecraft.util.math.BlockPos;
import net.minecraft.world.World;

public class WitchTowerComponents
{

	public static BlockPos start;
    public static World world;
    public static StructureBase structure;

    public static void init(World worldIn, BlockPos blockPos, StructureBase structureIn)
    {
        world = worldIn; start = blockPos; structure = structureIn;
    }
    
    public static void generatePart1()
    {
        structure.setBlockState(world, Blocks.GRASS_BLOCK.getDefaultState().with(SnowyDirtBlock.SNOWY, false), 2, 0, 6, start);
        structure.setBlockState(world, Blocks.GRASS_BLOCK.getDefaultState().with(SnowyDirtBlock.SNOWY, false), 2, 0, 16, start);
        structure.setBlockState(world, Blocks.GRASS_BLOCK.getDefaultState().with(SnowyDirtBlock.SNOWY, false), 3, 0, 4, start);
        structure.setBlockState(world, Blocks.GRASS_BLOCK.getDefaultState().with(SnowyDirtBlock.SNOWY, false), 3, 2, 7, start);
        structure.setBlockState(world, Blocks.GRASS_BLOCK.getDefaultState().with(SnowyDirtBlock.SNOWY, false), 3, 2, 15, start);
        structure.setBlockState(world, Blocks.GRASS_BLOCK.getDefaultState().with(SnowyDirtBlock.SNOWY, false), 4, 0, 3, start);
        structure.setBlockState(world, Blocks.STONE.getDefaultState(), 4, 0, 9, start);
        structure.setBlockState(world, Blocks.GRASS_BLOCK.getDefaultState().with(SnowyDirtBlock.SNOWY, false), 4, 0, 19, start);
        structure.setBlockState(world, Blocks.GRASS_BLOCK.getDefaultState().with(SnowyDirtBlock.SNOWY, false), 4, 1, 4, start);
        structure.setBlockState(world, Blocks.GRASS_BLOCK.getDefaultState().with(SnowyDirtBlock.SNOWY, false), 4, 2, 5, start);
        structure.setBlockState(world, Blocks.GRASS_BLOCK.getDefaultState().with(SnowyDirtBlock.SNOWY, false), 4, 3, 6, start);
        structure.setBlockState(world, Blocks.GRASS_BLOCK.getDefaultState().with(SnowyDirtBlock.SNOWY, false), 5, 2, 4, start);
        structure.setBlockState(world, Blocks.GRASS_BLOCK.getDefaultState().with(SnowyDirtBlock.SNOWY, false), 5, 2, 18, start);
        structure.setBlockState(world, Blocks.GRASS_BLOCK.getDefaultState().with(SnowyDirtBlock.SNOWY, false), 5, 3, 5, start);
        structure.setBlockState(world, Blocks.GRASS_BLOCK.getDefaultState().with(SnowyDirtBlock.SNOWY, false), 5, 4, 6, start);
        structure.setBlockState(world, Blocks.CAVE_AIR.getDefaultState(), 5, 5, 6, start);
        structure.setBlockState(world, Blocks.GRASS.getDefaultState(), 5, 5, 16, start);
        structure.setBlockState(world, Blocks.POPPY.getDefaultState(), 5, 6, 12, start);
        structure.setBlockState(world, Blocks.GRASS_BLOCK.getDefaultState().with(SnowyDirtBlock.SNOWY, false), 6, 0, 2, start);
        structure.setBlockState(world, Blocks.GRASS_BLOCK.getDefaultState().with(SnowyDirtBlock.SNOWY, false), 6, 0, 20, start);
        structure.setBlockState(world, Blocks.STONE.getDefaultState(), 6, 1, 16, start);
        structure.setBlockState(world, Blocks.GRASS_BLOCK.getDefaultState().with(SnowyDirtBlock.SNOWY, false), 6, 3, 4, start);
        structure.setBlockState(world, Blocks.GRASS_BLOCK.getDefaultState().with(SnowyDirtBlock.SNOWY, false), 6, 3, 18, start);
        structure.setBlockState(world, Blocks.GRASS_BLOCK.getDefaultState().with(SnowyDirtBlock.SNOWY, false), 6, 4, 5, start);
        structure.setBlockState(world, Blocks.CAVE_AIR.getDefaultState(), 6, 5, 5, start);
        structure.setBlockState(world, Blocks.GRASS.getDefaultState(), 6, 6, 8, start);
        structure.setBlockState(world, Blocks.AIR.getDefaultState(), 6, 6, 11, start);
        structure.setBlockState(world, Blocks.SPRUCE_SLAB.getDefaultState().with(SlabBlock.TYPE, SlabType.BOTTOM).with(SlabBlock.WATERLOGGED, false), 6, 24, 9, start);
        structure.setBlockState(world, Blocks.SPRUCE_STAIRS.getDefaultState().with(StairsBlock.FACING, Direction.EAST).with(StairsBlock.WATERLOGGED, false).with(StairsBlock.SHAPE, StairsShape.STRAIGHT).with(StairsBlock.HALF, Half.BOTTOM), 6, 24, 10, start);
        structure.setBlockState(world, Blocks.OAK_STAIRS.getDefaultState().with(StairsBlock.FACING, Direction.EAST).with(StairsBlock.WATERLOGGED, false).with(StairsBlock.SHAPE, StairsShape.STRAIGHT).with(StairsBlock.HALF, Half.BOTTOM), 6, 24, 11, start);
        structure.setBlockState(world, Blocks.GRASS_BLOCK.getDefaultState().with(SnowyDirtBlock.SNOWY, false), 7, 2, 3, start);
        structure.setBlockState(world, Blocks.GRASS_BLOCK.getDefaultState().with(SnowyDirtBlock.SNOWY, false), 7, 2, 19, start);
        structure.setBlockState(world, Blocks.GRASS.getDefaultState(), 7, 6, 7, start);
        structure.setBlockState(world, Blocks.CORNFLOWER.getDefaultState(), 7, 6, 8, start);
        structure.setBlockState(world, Blocks.GRASS.getDefaultState(), 7, 6, 11, start);
        structure.setBlockState(world, Blocks.GRASS.getDefaultState(), 7, 6, 17, start);
        structure.setBlockState(world, Blocks.COBBLESTONE.getDefaultState(), 7, 17, 8, start);
        structure.setBlockState(world, Blocks.ANDESITE.getDefaultState(), 7, 17, 9, start);
        structure.setBlockState(world, Blocks.SMOOTH_STONE.getDefaultState(), 7, 18, 10, start);
        structure.setBlockState(world, Blocks.COBBLESTONE.getDefaultState(), 7, 19, 7, start);
        structure.setBlockState(world, Blocks.LANTERN.getDefaultState().with(LanternBlock.WATERLOGGED, false).with(LanternBlock.HANGING, false), 7, 20, 8, start);
        structure.setBlockState(world, Blocks.OAK_PLANKS.getDefaultState(), 7, 24, 12, start);
        structure.setBlockState(world, Blocks.SPRUCE_STAIRS.getDefaultState().with(StairsBlock.FACING, Direction.EAST).with(StairsBlock.WATERLOGGED, false).with(StairsBlock.SHAPE, StairsShape.STRAIGHT).with(StairsBlock.HALF, Half.BOTTOM), 7, 25, 10, start);
        structure.setBlockState(world, Blocks.ANDESITE.getDefaultState(), 8, 6, 8, start);
        structure.setBlockState(world, Blocks.LANTERN.getDefaultState().with(LanternBlock.WATERLOGGED, false).with(LanternBlock.HANGING, false), 8, 6, 11, start);
        structure.setBlockState(world, Blocks.DANDELION.getDefaultState(), 8, 6, 13, start);
        structure.setBlockState(world, Blocks.POPPY.getDefaultState(), 8, 6, 17, start);
        structure.setBlockState(world, Blocks.COBBLESTONE.getDefaultState(), 8, 8, 8, start);
        structure.setBlockState(world, Blocks.ANDESITE.getDefaultState(), 8, 8, 9, start);
        structure.setBlockState(world, Blocks.COBBLESTONE.getDefaultState(), 8, 10, 9, start);
        structure.setBlockState(world, Blocks.SMOOTH_STONE.getDefaultState(), 8, 10, 10, start);
        structure.setBlockState(world, Blocks.LANTERN.getDefaultState().with(LanternBlock.WATERLOGGED, false).with(LanternBlock.HANGING, false), 8, 11, 10, start);
        structure.setBlockState(world, Blocks.ANDESITE.getDefaultState(), 8, 14, 9, start);
        structure.setBlockState(world, Blocks.REDSTONE_ORE.getDefaultState().with(RedstoneOreBlock.LIT, false), 8, 16, 8, start);
        structure.setBlockState(world, Blocks.COBBLESTONE.getDefaultState(), 8, 16, 9, start);
        structure.setBlockState(world, Blocks.SMOOTH_STONE.getDefaultState(), 8, 16, 10, start);
        structure.setBlockState(world, Blocks.MOSSY_COBBLESTONE.getDefaultState(), 8, 17, 7, start);
        structure.setBlockState(world, Blocks.OAK_SLAB.getDefaultState().with(SlabBlock.TYPE, SlabType.BOTTOM).with(SlabBlock.WATERLOGGED, false), 8, 17, 8, start);
        structure.setBlockState(world, Blocks.SPRUCE_SLAB.getDefaultState().with(SlabBlock.TYPE, SlabType.BOTTOM).with(SlabBlock.WATERLOGGED, false), 8, 17, 9, start);
        structure.setBlockState(world, Blocks.COBBLESTONE.getDefaultState(), 8, 18, 7, start);
        structure.setBlockState(world, Blocks.STONE.getDefaultState(), 8, 19, 6, start);
        structure.setBlockState(world, Blocks.LANTERN.getDefaultState().with(LanternBlock.WATERLOGGED, false).with(LanternBlock.HANGING, true), 8, 19, 8, start);
        structure.setBlockState(world, Blocks.ANDESITE.getDefaultState(), 8, 19, 11, start);
        structure.setBlockState(world, Blocks.LANTERN.getDefaultState().with(LanternBlock.WATERLOGGED, false).with(LanternBlock.HANGING, false), 8, 20, 11, start);
        structure.setBlockState(world, Blocks.STONE.getDefaultState(), 8, 21, 8, start);
        structure.setBlockState(world, Blocks.ANDESITE.getDefaultState(), 8, 21, 10, start);
        structure.setBlockState(world, Blocks.SPRUCE_SLAB.getDefaultState().with(SlabBlock.TYPE, SlabType.TOP).with(SlabBlock.WATERLOGGED, false), 8, 22, 8, start);
        structure.setBlockState(world, Blocks.SMOOTH_STONE.getDefaultState(), 8, 22, 10, start);
        structure.setBlockState(world, Blocks.SMOOTH_STONE.getDefaultState(), 8, 22, 12, start);
        structure.setBlockState(world, Blocks.SPRUCE_STAIRS.getDefaultState().with(StairsBlock.FACING, Direction.NORTH).with(StairsBlock.WATERLOGGED, false).with(StairsBlock.SHAPE, StairsShape.STRAIGHT).with(StairsBlock.HALF, Half.TOP), 8, 22, 13, start);
        structure.setBlockState(world, Blocks.SMOOTH_STONE.getDefaultState(), 8, 23, 9, start);
        structure.setBlockState(world, Blocks.OAK_PLANKS.getDefaultState(), 8, 24, 7, start);
        structure.setBlockState(world, Blocks.LANTERN.getDefaultState().with(LanternBlock.WATERLOGGED, false).with(LanternBlock.HANGING, true), 8, 24, 12, start);
        structure.setBlockState(world, Blocks.SPRUCE_PLANKS.getDefaultState(), 8, 24, 13, start);
        structure.setBlockState(world, Blocks.OAK_STAIRS.getDefaultState().with(StairsBlock.FACING, Direction.EAST).with(StairsBlock.WATERLOGGED, false).with(StairsBlock.SHAPE, StairsShape.STRAIGHT).with(StairsBlock.HALF, Half.BOTTOM), 8, 25, 7, start);
        structure.setBlockState(world, Blocks.SPRUCE_SLAB.getDefaultState().with(SlabBlock.TYPE, SlabType.BOTTOM).with(SlabBlock.WATERLOGGED, false), 8, 25, 13, start);
        structure.setBlockState(world, Blocks.LANTERN.getDefaultState().with(LanternBlock.WATERLOGGED, false).with(LanternBlock.HANGING, false), 8, 26, 8, start);
        structure.setBlockState(world, Blocks.OAK_PLANKS.getDefaultState(), 8, 26, 9, start);
        structure.setBlockState(world, Blocks.SPRUCE_PLANKS.getDefaultState(), 8, 26, 10, start);
        structure.setBlockState(world, Blocks.SPRUCE_STAIRS.getDefaultState().with(StairsBlock.FACING, Direction.EAST).with(StairsBlock.WATERLOGGED, false).with(StairsBlock.SHAPE, StairsShape.STRAIGHT).with(StairsBlock.HALF, Half.BOTTOM), 8, 27, 9, start);
        structure.setBlockState(world, Blocks.OAK_STAIRS.getDefaultState().with(StairsBlock.FACING, Direction.EAST).with(StairsBlock.WATERLOGGED, false).with(StairsBlock.SHAPE, StairsShape.STRAIGHT).with(StairsBlock.HALF, Half.BOTTOM), 8, 27, 11, start);
        structure.setBlockState(world, Blocks.SPRUCE_STAIRS.getDefaultState().with(StairsBlock.FACING, Direction.EAST).with(StairsBlock.WATERLOGGED, false).with(StairsBlock.SHAPE, StairsShape.STRAIGHT).with(StairsBlock.HALF, Half.BOTTOM), 8, 28, 10, start);
        structure.setBlockState(world, Blocks.STONE.getDefaultState(), 9, 0, 18, start);
        structure.setBlockState(world, Blocks.GRASS_BLOCK.getDefaultState().with(SnowyDirtBlock.SNOWY, false), 9, 5, 6, start);
        structure.setBlockState(world, Blocks.DIRT.getDefaultState(), 9, 5, 7, start);
        structure.setBlockState(world, Blocks.SPRUCE_PLANKS.getDefaultState(), 9, 5, 10, start);
        structure.setBlockState(world, Blocks.GRASS.getDefaultState(), 9, 6, 5, start);
        structure.setBlockState(world, Blocks.BARREL.getDefaultState().with(BarrelBlock.PROPERTY_FACING, Direction.UP).with(BarrelBlock.PROPERTY_OPEN, false), 9, 6, 10, start);
        structure.setBlockState(world, Blocks.ANDESITE.getDefaultState(), 9, 6, 12, start);
        structure.setBlockState(world, Blocks.GRASS.getDefaultState(), 9, 6, 13, start);
        structure.setBlockState(world, Blocks.BARREL.getDefaultState().with(BarrelBlock.PROPERTY_FACING, Direction.UP).with(BarrelBlock.PROPERTY_OPEN, false), 9, 7, 8, start);
        structure.setBlockState(world, Blocks.BARREL.getDefaultState().with(BarrelBlock.PROPERTY_FACING, Direction.NORTH).with(BarrelBlock.PROPERTY_OPEN, false), 9, 7, 10, start);
        structure.setBlockState(world, Blocks.SPRUCE_SLAB.getDefaultState().with(SlabBlock.TYPE, SlabType.TOP).with(SlabBlock.WATERLOGGED, false), 9, 8, 9, start);
        structure.setBlockState(world, Blocks.OAK_SLAB.getDefaultState().with(SlabBlock.TYPE, SlabType.BOTTOM).with(SlabBlock.WATERLOGGED, false), 9, 8, 10, start);
        structure.setBlockState(world, Blocks.LANTERN.getDefaultState().with(LanternBlock.WATERLOGGED, false).with(LanternBlock.HANGING, false), 9, 10, 7, start);
        structure.setBlockState(world, Blocks.LANTERN.getDefaultState().with(LanternBlock.WATERLOGGED, false).with(LanternBlock.HANGING, true), 9, 10, 9, start);
        structure.setBlockState(world, Blocks.ANDESITE.getDefaultState(), 9, 11, 11, start);
        structure.setBlockState(world, Blocks.STONE.getDefaultState(), 9, 12, 7, start);
        structure.setBlockState(world, Blocks.COBBLESTONE.getDefaultState(), 9, 16, 7, start);
        structure.setBlockState(world, Blocks.OAK_SLAB.getDefaultState().with(SlabBlock.TYPE, SlabType.TOP).with(SlabBlock.WATERLOGGED, false), 9, 16, 9, start);
        structure.setBlockState(world, Blocks.SPRUCE_SLAB.getDefaultState().with(SlabBlock.TYPE, SlabType.BOTTOM).with(SlabBlock.WATERLOGGED, false), 9, 16, 10, start);
        structure.setBlockState(world, Blocks.SPRUCE_SLAB.getDefaultState().with(SlabBlock.TYPE, SlabType.BOTTOM).with(SlabBlock.WATERLOGGED, false), 9, 17, 8, start);
        structure.setBlockState(world, Blocks.REDSTONE_ORE.getDefaultState().with(RedstoneOreBlock.LIT, false), 9, 17, 12, start);
        structure.setBlockState(world, Blocks.AIR.getDefaultState(), 9, 18, 7, start);
        structure.setBlockState(world, Blocks.MOSSY_COBBLESTONE.getDefaultState(), 9, 18, 12, start);
        structure.setBlockState(world, Blocks.SMOOTH_STONE.getDefaultState(), 9, 19, 12, start);
        structure.setBlockState(world, Blocks.SMOOTH_STONE.getDefaultState(), 9, 20, 6, start);
        structure.setBlockState(world, Blocks.LANTERN.getDefaultState().with(LanternBlock.WATERLOGGED, false).with(LanternBlock.HANGING, true), 9, 22, 6, start);
        structure.setBlockState(world, Blocks.OAK_STAIRS.getDefaultState().with(StairsBlock.FACING, Direction.SOUTH).with(StairsBlock.WATERLOGGED, false).with(StairsBlock.SHAPE, StairsShape.STRAIGHT).with(StairsBlock.HALF, Half.TOP), 9, 22, 7, start);
        structure.setBlockState(world, Blocks.COBBLESTONE.getDefaultState(), 9, 22, 8, start);
        structure.setBlockState(world, Blocks.AIR.getDefaultState(), 9, 22, 9, start);
        structure.setBlockState(world, Blocks.OAK_SLAB.getDefaultState().with(SlabBlock.TYPE, SlabType.BOTTOM).with(SlabBlock.WATERLOGGED, false), 9, 22, 11, start);
        structure.setBlockState(world, Blocks.SPRUCE_SLAB.getDefaultState().with(SlabBlock.TYPE, SlabType.BOTTOM).with(SlabBlock.WATERLOGGED, false), 9, 22, 12, start);
        structure.setBlockState(world, Blocks.CHAIN.getDefaultState().with(ChainBlock.WATERLOGGED, false), 9, 23, 6, start);
        structure.setBlockState(world, Blocks.SPRUCE_SLAB.getDefaultState().with(SlabBlock.TYPE, SlabType.TOP).with(SlabBlock.WATERLOGGED, false), 9, 23, 9, start);
        structure.setBlockState(world, Blocks.OAK_PLANKS.getDefaultState(), 9, 24, 6, start);
        structure.setBlockState(world, Blocks.SCAFFOLDING.getDefaultState().with(ScaffoldingBlock.WATERLOGGED, false).with(ScaffoldingBlock.DISTANCE, 0).with(ScaffoldingBlock.BOTTOM, false), 9, 24, 9, start);
        structure.setBlockState(world, Blocks.OAK_PLANKS.getDefaultState(), 9, 24, 15, start);
        structure.setBlockState(world, Blocks.BROWN_BED.getDefaultState().with(HorizontalBlock.HORIZONTAL_FACING, Direction.WEST).with(BedBlock.PART, BedPart.HEAD), 9, 25, 8, start);
        structure.setBlockState(world, Blocks.OAK_SLAB.getDefaultState().with(SlabBlock.TYPE, SlabType.TOP).with(SlabBlock.WATERLOGGED, false), 9, 25, 10, start);
        structure.setBlockState(world, Blocks.OAK_STAIRS.getDefaultState().with(StairsBlock.FACING, Direction.NORTH).with(StairsBlock.WATERLOGGED, false).with(StairsBlock.SHAPE, StairsShape.STRAIGHT).with(StairsBlock.HALF, Half.BOTTOM), 9, 25, 15, start);
        structure.setBlockState(world, Blocks.OAK_STAIRS.getDefaultState().with(StairsBlock.FACING, Direction.EAST).with(StairsBlock.WATERLOGGED, false).with(StairsBlock.SHAPE, StairsShape.STRAIGHT).with(StairsBlock.HALF, Half.BOTTOM), 9, 26, 7, start);
        structure.setBlockState(world, Blocks.OAK_PLANKS.getDefaultState(), 9, 26, 8, start);
        structure.setBlockState(world, Blocks.SPRUCE_PLANKS.getDefaultState(), 9, 26, 14, start);
        structure.setBlockState(world, Blocks.SPRUCE_PLANKS.getDefaultState(), 9, 27, 8, start);
        structure.setBlockState(world, Blocks.OAK_PLANKS.getDefaultState(), 9, 27, 13, start);
        structure.setBlockState(world, Blocks.OAK_STAIRS.getDefaultState().with(StairsBlock.FACING, Direction.SOUTH).with(StairsBlock.WATERLOGGED, false).with(StairsBlock.SHAPE, StairsShape.STRAIGHT).with(StairsBlock.HALF, Half.BOTTOM), 9, 28, 8, start);
        structure.setBlockState(world, Blocks.SPRUCE_SLAB.getDefaultState().with(SlabBlock.TYPE, SlabType.BOTTOM).with(SlabBlock.WATERLOGGED, false), 9, 29, 9, start);
        structure.setBlockState(world, Blocks.OAK_PLANKS.getDefaultState(), 9, 29, 10, start);
        structure.setBlockState(world, Blocks.SPRUCE_PLANKS.getDefaultState(), 9, 29, 11, start);
        structure.setBlockState(world, Blocks.OAK_STAIRS.getDefaultState().with(StairsBlock.FACING, Direction.NORTH).with(StairsBlock.WATERLOGGED, false).with(StairsBlock.SHAPE, StairsShape.STRAIGHT).with(StairsBlock.HALF, Half.BOTTOM), 9, 29, 12, start);
        structure.setBlockState(world, Blocks.SPRUCE_STAIRS.getDefaultState().with(StairsBlock.FACING, Direction.EAST).with(StairsBlock.WATERLOGGED, false).with(StairsBlock.SHAPE, StairsShape.STRAIGHT).with(StairsBlock.HALF, Half.BOTTOM), 9, 33, 10, start);
        structure.setBlockState(world, Blocks.LODESTONE.getDefaultState(), 10, 6, 7, start);
        structure.setBlockState(world, Blocks.BARREL.getDefaultState().with(BarrelBlock.PROPERTY_FACING, Direction.NORTH).with(BarrelBlock.PROPERTY_OPEN, false), 10, 6, 11, start);
        structure.setBlockState(world, Blocks.COBBLESTONE.getDefaultState(), 10, 7, 6, start);
        structure.setBlockState(world, Blocks.POTTED_WITHER_ROSE.getDefaultState(), 10, 7, 7, start);
        structure.setBlockState(world, Blocks.OAK_SLAB.getDefaultState().with(SlabBlock.TYPE, SlabType.TOP).with(SlabBlock.WATERLOGGED, false), 10, 7, 11, start);
        structure.setBlockState(world, Blocks.REDSTONE_ORE.getDefaultState().with(RedstoneOreBlock.LIT, false), 10, 8, 6, start);
        structure.setBlockState(world, Blocks.LANTERN.getDefaultState().with(LanternBlock.WATERLOGGED, false).with(LanternBlock.HANGING, true), 10, 8, 7, start);
        structure.setBlockState(world, Blocks.OAK_SLAB.getDefaultState().with(SlabBlock.TYPE, SlabType.BOTTOM).with(SlabBlock.WATERLOGGED, false), 10, 8, 9, start);
        structure.setBlockState(world, Blocks.LANTERN.getDefaultState().with(LanternBlock.WATERLOGGED, false).with(LanternBlock.HANGING, true), 10, 11, 6, start);
        structure.setBlockState(world, Blocks.ANDESITE.getDefaultState(), 10, 11, 7, start);
        structure.setBlockState(world, Blocks.SMOOTH_STONE.getDefaultState(), 10, 12, 7, start);
        structure.setBlockState(world, Blocks.OAK_SLAB.getDefaultState().with(SlabBlock.TYPE, SlabType.TOP).with(SlabBlock.WATERLOGGED, false), 10, 12, 9, start);
        structure.setBlockState(world, Blocks.SPRUCE_SLAB.getDefaultState().with(SlabBlock.TYPE, SlabType.BOTTOM).with(SlabBlock.WATERLOGGED, false), 10, 12, 10, start);
        structure.setBlockState(world, Blocks.ANDESITE.getDefaultState(), 10, 12, 11, start);
        structure.setBlockState(world, Blocks.SPRUCE_SLAB.getDefaultState().with(SlabBlock.TYPE, SlabType.BOTTOM).with(SlabBlock.WATERLOGGED, false), 10, 13, 8, start);
        structure.setBlockState(world, Blocks.LANTERN.getDefaultState().with(LanternBlock.WATERLOGGED, false).with(LanternBlock.HANGING, false), 10, 14, 7, start);
        structure.setBlockState(world, Blocks.LANTERN.getDefaultState().with(LanternBlock.WATERLOGGED, false).with(LanternBlock.HANGING, false), 10, 15, 11, start);
        structure.setBlockState(world, Blocks.SPRUCE_SLAB.getDefaultState().with(SlabBlock.TYPE, SlabType.BOTTOM).with(SlabBlock.WATERLOGGED, false), 10, 16, 9, start);
        structure.setBlockState(world, Blocks.OAK_SLAB.getDefaultState().with(SlabBlock.TYPE, SlabType.BOTTOM).with(SlabBlock.WATERLOGGED, false), 10, 16, 11, start);
        structure.setBlockState(world, Blocks.LANTERN.getDefaultState().with(LanternBlock.WATERLOGGED, false).with(LanternBlock.HANGING, true), 10, 16, 13, start);
        structure.setBlockState(world, Blocks.SMOOTH_STONE.getDefaultState(), 10, 17, 6, start);
        structure.setBlockState(world, Blocks.SPRUCE_SLAB.getDefaultState().with(SlabBlock.TYPE, SlabType.TOP).with(SlabBlock.WATERLOGGED, false), 10, 17, 8, start);
        structure.setBlockState(world, Blocks.ANDESITE.getDefaultState(), 10, 18, 6, start);
        structure.setBlockState(world, Blocks.SMOOTH_STONE.getDefaultState(), 10, 18, 12, start);
        structure.setBlockState(world, Blocks.COBBLESTONE.getDefaultState(), 10, 20, 12, start);
        structure.setBlockState(world, Blocks.SPRUCE_SLAB.getDefaultState().with(SlabBlock.TYPE, SlabType.TOP).with(SlabBlock.WATERLOGGED, false), 10, 21, 12, start);
        structure.setBlockState(world, Blocks.CAULDRON.getDefaultState().with(CauldronBlock.LEVEL, 3), 10, 22, 8, start);
        structure.setBlockState(world, Blocks.OAK_SLAB.getDefaultState().with(SlabBlock.TYPE, SlabType.TOP).with(SlabBlock.WATERLOGGED, false), 10, 22, 15, start);
        structure.setBlockState(world, Blocks.SPRUCE_SLAB.getDefaultState().with(SlabBlock.TYPE, SlabType.TOP).with(SlabBlock.WATERLOGGED, false), 10, 23, 13, start);
        structure.setBlockState(world, Blocks.POTTED_BAMBOO.getDefaultState(), 10, 23, 15, start);
        structure.setBlockState(world, Blocks.SPRUCE_PLANKS.getDefaultState(), 10, 24, 6, start);
        structure.setBlockState(world, Blocks.BREWING_STAND.getDefaultState().with(BrewingStandBlock.HAS_BOTTLE[0], false).with(BrewingStandBlock.HAS_BOTTLE[1], false).with(BrewingStandBlock.HAS_BOTTLE[2], false), 10, 24, 13, start);
        structure.setBlockState(world, Blocks.SPRUCE_PLANKS.getDefaultState(), 10, 24, 16, start);
        structure.setBlockState(world, Blocks.SPRUCE_STAIRS.getDefaultState().with(StairsBlock.FACING, Direction.SOUTH).with(StairsBlock.WATERLOGGED, false).with(StairsBlock.SHAPE, StairsShape.STRAIGHT).with(StairsBlock.HALF, Half.BOTTOM), 10, 25, 6, start);
        structure.setBlockState(world, Blocks.BROWN_BED.getDefaultState().with(HorizontalBlock.HORIZONTAL_FACING, Direction.WEST).with(BedBlock.PART, BedPart.FOOT), 10, 25, 8, start);
        structure.setBlockState(world, Blocks.OAK_SLAB.getDefaultState().with(SlabBlock.TYPE, SlabType.BOTTOM).with(SlabBlock.WATERLOGGED, false), 10, 25, 16, start);
        structure.setBlockState(world, Blocks.SPRUCE_PLANKS.getDefaultState(), 10, 27, 7, start);
        structure.setBlockState(world, Blocks.SPRUCE_PLANKS.getDefaultState(), 10, 27, 14, start);
        structure.setBlockState(world, Blocks.OAK_PLANKS.getDefaultState(), 10, 28, 13, start);
        structure.setBlockState(world, Blocks.LANTERN.getDefaultState().with(LanternBlock.WATERLOGGED, false).with(LanternBlock.HANGING, false), 10, 28, 14, start);
        structure.setBlockState(world, Blocks.OAK_STAIRS.getDefaultState().with(StairsBlock.FACING, Direction.SOUTH).with(StairsBlock.WATERLOGGED, false).with(StairsBlock.SHAPE, StairsShape.STRAIGHT).with(StairsBlock.HALF, Half.BOTTOM), 10, 29, 8, start);
        structure.setBlockState(world, Blocks.SPRUCE_PLANKS.getDefaultState(), 10, 29, 9, start);
        structure.setBlockState(world, Blocks.OAK_PLANKS.getDefaultState(), 10, 29, 12, start);
        structure.setBlockState(world, Blocks.OAK_PLANKS.getDefaultState(), 10, 30, 11, start);
        structure.setBlockState(world, Blocks.SPRUCE_PLANKS.getDefaultState(), 10, 31, 9, start);
        structure.setBlockState(world, Blocks.LANTERN.getDefaultState().with(LanternBlock.WATERLOGGED, false).with(LanternBlock.HANGING, false), 10, 32, 9, start);
        structure.setBlockState(world, Blocks.SPRUCE_PLANKS.getDefaultState(), 10, 33, 10, start);
        structure.setBlockState(world, Blocks.OAK_PLANKS.getDefaultState(), 10, 34, 10, start);
        structure.setBlockState(world, Blocks.SPRUCE_SLAB.getDefaultState().with(SlabBlock.TYPE, SlabType.BOTTOM).with(SlabBlock.WATERLOGGED, false), 10, 35, 10, start);
        structure.setBlockState(world, Blocks.SPRUCE_PLANKS.getDefaultState(), 11, 5, 7, start);
        structure.setBlockState(world, Blocks.OAK_PLANKS.getDefaultState(), 11, 5, 11, start);
        structure.setBlockState(world, Blocks.AIR.getDefaultState(), 11, 6, 9, start);
        structure.setBlockState(world, Blocks.LILY_PAD.getDefaultState(), 11, 6, 16, start);
        structure.setBlockState(world, Blocks.ANDESITE.getDefaultState(), 11, 7, 6, start);
        structure.setBlockState(world, Blocks.SPRUCE_SLAB.getDefaultState().with(SlabBlock.TYPE, SlabType.BOTTOM).with(SlabBlock.WATERLOGGED, false), 11, 7, 10, start);
        structure.setBlockState(world, Blocks.SPRUCE_SLAB.getDefaultState().with(SlabBlock.TYPE, SlabType.TOP).with(SlabBlock.WATERLOGGED, false), 11, 7, 11, start);
        structure.setBlockState(world, Blocks.OAK_SLAB.getDefaultState().with(SlabBlock.TYPE, SlabType.TOP).with(SlabBlock.WATERLOGGED, false), 11, 8, 9, start);
        structure.setBlockState(world, Blocks.MOSSY_COBBLESTONE.getDefaultState(), 11, 8, 12, start);
        structure.setBlockState(world, Blocks.SPRUCE_SLAB.getDefaultState().with(SlabBlock.TYPE, SlabType.BOTTOM).with(SlabBlock.WATERLOGGED, false), 11, 9, 8, start);
        structure.setBlockState(world, Blocks.COBBLESTONE.getDefaultState(), 11, 10, 7, start);
        structure.setBlockState(world, Blocks.SMOOTH_STONE.getDefaultState(), 11, 11, 7, start);
        structure.setBlockState(world, Blocks.OAK_SLAB.getDefaultState().with(SlabBlock.TYPE, SlabType.BOTTOM).with(SlabBlock.WATERLOGGED, false), 11, 12, 11, start);
        structure.setBlockState(world, Blocks.SPRUCE_SLAB.getDefaultState().with(SlabBlock.TYPE, SlabType.TOP).with(SlabBlock.WATERLOGGED, false), 11, 13, 8, start);
        structure.setBlockState(world, Blocks.SMOOTH_STONE.getDefaultState(), 11, 13, 12, start);
        structure.setBlockState(world, Blocks.ANDESITE.getDefaultState(), 11, 14, 6, start);
        structure.setBlockState(world, Blocks.COBBLESTONE.getDefaultState(), 11, 14, 12, start);
        structure.setBlockState(world, Blocks.SPRUCE_SLAB.getDefaultState().with(SlabBlock.TYPE, SlabType.BOTTOM).with(SlabBlock.WATERLOGGED, false), 11, 15, 10, start);
        structure.setBlockState(world, Blocks.OAK_SLAB.getDefaultState().with(SlabBlock.TYPE, SlabType.TOP).with(SlabBlock.WATERLOGGED, false), 11, 15, 11, start);
        structure.setBlockState(world, Blocks.SMOOTH_STONE.getDefaultState(), 11, 15, 12, start);
        structure.setBlockState(world, Blocks.STONE.getDefaultState(), 11, 16, 6, start);
        structure.setBlockState(world, Blocks.ANDESITE.getDefaultState(), 11, 17, 6, start);
        structure.setBlockState(world, Blocks.REDSTONE_ORE.getDefaultState().with(RedstoneOreBlock.LIT, false), 11, 18, 6, start);
        structure.setBlockState(world, Blocks.COBBLESTONE.getDefaultState(), 11, 18, 11, start);
        structure.setBlockState(world, Blocks.STONE.getDefaultState(), 11, 20, 12, start);
        structure.setBlockState(world, Blocks.MOSSY_COBBLESTONE.getDefaultState(), 11, 22, 7, start);
        structure.setBlockState(world, Blocks.AIR.getDefaultState(), 11, 22, 11, start);
        structure.setBlockState(world, Blocks.SPRUCE_SLAB.getDefaultState().with(SlabBlock.TYPE, SlabType.TOP).with(SlabBlock.WATERLOGGED, false), 11, 22, 15, start);
        structure.setBlockState(world, Blocks.OAK_PLANKS.getDefaultState(), 11, 24, 16, start);
        structure.setBlockState(world, Blocks.SPRUCE_SLAB.getDefaultState().with(SlabBlock.TYPE, SlabType.BOTTOM).with(SlabBlock.WATERLOGGED, false), 11, 25, 10, start);
        structure.setBlockState(world, Blocks.SPRUCE_PLANKS.getDefaultState(), 11, 25, 15, start);
        structure.setBlockState(world, Blocks.LANTERN.getDefaultState().with(LanternBlock.WATERLOGGED, false).with(LanternBlock.HANGING, true), 11, 26, 13, start);
        structure.setBlockState(world, Blocks.OAK_PLANKS.getDefaultState(), 11, 26, 14, start);
        structure.setBlockState(world, Blocks.SPRUCE_STAIRS.getDefaultState().with(StairsBlock.FACING, Direction.WEST).with(StairsBlock.WATERLOGGED, false).with(StairsBlock.SHAPE, StairsShape.STRAIGHT).with(StairsBlock.HALF, Half.BOTTOM), 11, 26, 15, start);
        structure.setBlockState(world, Blocks.OAK_PLANKS.getDefaultState(), 11, 27, 13, start);
        structure.setBlockState(world, Blocks.SPRUCE_SLAB.getDefaultState().with(SlabBlock.TYPE, SlabType.BOTTOM).with(SlabBlock.WATERLOGGED, false), 11, 27, 14, start);
        structure.setBlockState(world, Blocks.SPRUCE_STAIRS.getDefaultState().with(StairsBlock.FACING, Direction.NORTH).with(StairsBlock.WATERLOGGED, false).with(StairsBlock.SHAPE, StairsShape.STRAIGHT).with(StairsBlock.HALF, Half.BOTTOM), 11, 28, 13, start);
        structure.setBlockState(world, Blocks.LANTERN.getDefaultState().with(LanternBlock.WATERLOGGED, false).with(LanternBlock.HANGING, true), 11, 29, 10, start);
        structure.setBlockState(world, Blocks.OAK_PLANKS.getDefaultState(), 11, 29, 11, start);
        structure.setBlockState(world, Blocks.SPRUCE_PLANKS.getDefaultState(), 11, 29, 12, start);
        structure.setBlockState(world, Blocks.LANTERN.getDefaultState().with(LanternBlock.WATERLOGGED, false).with(LanternBlock.HANGING, false), 11, 30, 8, start);
        structure.setBlockState(world, Blocks.SPRUCE_SLAB.getDefaultState().with(SlabBlock.TYPE, SlabType.BOTTOM).with(SlabBlock.WATERLOGGED, false), 11, 30, 11, start);
        structure.setBlockState(world, Blocks.SPRUCE_STAIRS.getDefaultState().with(StairsBlock.FACING, Direction.WEST).with(StairsBlock.WATERLOGGED, false).with(StairsBlock.SHAPE, StairsShape.STRAIGHT).with(StairsBlock.HALF, Half.BOTTOM), 11, 31, 10, start);
        structure.setBlockState(world, Blocks.BARREL.getDefaultState().with(BarrelBlock.PROPERTY_FACING, Direction.SOUTH).with(BarrelBlock.PROPERTY_OPEN, false), 12, 6, 7, start);
        structure.setBlockState(world, Blocks.SPRUCE_SLAB.getDefaultState().with(SlabBlock.TYPE, SlabType.TOP).with(SlabBlock.WATERLOGGED, false), 12, 6, 10, start);
        structure.setBlockState(world, Blocks.SCAFFOLDING.getDefaultState().with(ScaffoldingBlock.WATERLOGGED, false).with(ScaffoldingBlock.DISTANCE, 0).with(ScaffoldingBlock.BOTTOM, false), 12, 7, 7, start);
        structure.setBlockState(world, Blocks.OAK_SLAB.getDefaultState().with(SlabBlock.TYPE, SlabType.BOTTOM).with(SlabBlock.WATERLOGGED, false), 12, 7, 11, start);
        structure.setBlockState(world, Blocks.STONE.getDefaultState(), 12, 8, 12, start);
        structure.setBlockState(world, Blocks.ANDESITE.getDefaultState(), 12, 9, 6, start);
        structure.setBlockState(world, Blocks.COBBLESTONE.getDefaultState(), 12, 11, 7, start);
        structure.setBlockState(world, Blocks.SPRUCE_SLAB.getDefaultState().with(SlabBlock.TYPE, SlabType.TOP).with(SlabBlock.WATERLOGGED, false), 12, 11, 10, start);
        structure.setBlockState(world, Blocks.OAK_SLAB.getDefaultState().with(SlabBlock.TYPE, SlabType.TOP).with(SlabBlock.WATERLOGGED, false), 12, 11, 11, start);
        structure.setBlockState(world, Blocks.COBBLESTONE.getDefaultState(), 12, 11, 12, start);
        structure.setBlockState(world, Blocks.ANDESITE.getDefaultState(), 12, 12, 6, start);
        structure.setBlockState(world, Blocks.ANDESITE.getDefaultState(), 12, 13, 12, start);
        structure.setBlockState(world, Blocks.STONE.getDefaultState(), 12, 14, 6, start);
        structure.setBlockState(world, Blocks.SPRUCE_SLAB.getDefaultState().with(SlabBlock.TYPE, SlabType.BOTTOM).with(SlabBlock.WATERLOGGED, false), 12, 14, 8, start);
        structure.setBlockState(world, Blocks.COBBLESTONE.getDefaultState(), 12, 14, 11, start);
        structure.setBlockState(world, Blocks.OAK_SLAB.getDefaultState().with(SlabBlock.TYPE, SlabType.BOTTOM).with(SlabBlock.WATERLOGGED, false), 12, 15, 10, start);
        structure.setBlockState(world, Blocks.SPRUCE_SLAB.getDefaultState().with(SlabBlock.TYPE, SlabType.TOP).with(SlabBlock.WATERLOGGED, false), 12, 15, 11, start);
        structure.setBlockState(world, Blocks.COBBLESTONE.getDefaultState(), 12, 15, 12, start);
        structure.setBlockState(world, Blocks.MOSSY_COBBLESTONE.getDefaultState(), 12, 16, 6, start);
        structure.setBlockState(world, Blocks.STONE.getDefaultState(), 12, 16, 12, start);
        structure.setBlockState(world, Blocks.COBBLESTONE.getDefaultState(), 12, 17, 11, start);
        structure.setBlockState(world, Blocks.SPRUCE_SLAB.getDefaultState().with(SlabBlock.TYPE, SlabType.BOTTOM).with(SlabBlock.WATERLOGGED, false), 12, 18, 8, start);
        structure.setBlockState(world, Blocks.OAK_SLAB.getDefaultState().with(SlabBlock.TYPE, SlabType.BOTTOM).with(SlabBlock.WATERLOGGED, false), 12, 18, 9, start);
        structure.setBlockState(world, Blocks.SPRUCE_SLAB.getDefaultState().with(SlabBlock.TYPE, SlabType.BOTTOM).with(SlabBlock.WATERLOGGED, false), 12, 18, 10, start);
        structure.setBlockState(world, Blocks.STONE.getDefaultState(), 12, 18, 11, start);
        structure.setBlockState(world, Blocks.COBBLESTONE.getDefaultState(), 12, 19, 11, start);
        structure.setBlockState(world, Blocks.LANTERN.getDefaultState().with(LanternBlock.WATERLOGGED, false).with(LanternBlock.HANGING, false), 12, 20, 11, start);
        structure.setBlockState(world, Blocks.COBBLESTONE.getDefaultState(), 12, 20, 12, start);
        structure.setBlockState(world, Blocks.OAK_SLAB.getDefaultState().with(SlabBlock.TYPE, SlabType.TOP).with(SlabBlock.WATERLOGGED, false), 12, 21, 10, start);
        structure.setBlockState(world, Blocks.SMOOTH_STONE.getDefaultState(), 12, 21, 13, start);
        structure.setBlockState(world, Blocks.POTTED_BAMBOO.getDefaultState(), 12, 22, 12, start);
        structure.setBlockState(world, Blocks.LECTERN.getDefaultState().with(LecternBlock.FACING, Direction.NORTH).with(LecternBlock.HAS_BOOK, false).with(LecternBlock.POWERED, false), 12, 22, 13, start);
        structure.setBlockState(world, Blocks.SPRUCE_STAIRS.getDefaultState().with(StairsBlock.FACING, Direction.NORTH).with(StairsBlock.WATERLOGGED, false).with(StairsBlock.SHAPE, StairsShape.STRAIGHT).with(StairsBlock.HALF, Half.TOP), 12, 22, 15, start);
        structure.setBlockState(world, Blocks.ANDESITE.getDefaultState(), 12, 23, 8, start);
        structure.setBlockState(world, Blocks.LANTERN.getDefaultState().with(LanternBlock.WATERLOGGED, false).with(LanternBlock.HANGING, true), 12, 23, 13, start);
        structure.setBlockState(world, Blocks.LANTERN.getDefaultState().with(LanternBlock.WATERLOGGED, false).with(LanternBlock.HANGING, true), 12, 23, 15, start);
        structure.setBlockState(world, Blocks.SPRUCE_PLANKS.getDefaultState(), 12, 24, 6, start);
        structure.setBlockState(world, Blocks.OAK_SLAB.getDefaultState().with(SlabBlock.TYPE, SlabType.TOP).with(SlabBlock.WATERLOGGED, false), 12, 24, 12, start);
        structure.setBlockState(world, Blocks.SPRUCE_PLANKS.getDefaultState(), 12, 24, 15, start);
        structure.setBlockState(world, Blocks.SPRUCE_SLAB.getDefaultState().with(SlabBlock.TYPE, SlabType.BOTTOM).with(SlabBlock.WATERLOGGED, false), 12, 25, 6, start);
        structure.setBlockState(world, Blocks.SPRUCE_SLAB.getDefaultState().with(SlabBlock.TYPE, SlabType.BOTTOM).with(SlabBlock.WATERLOGGED, false), 12, 25, 8, start);
        structure.setBlockState(world, Blocks.AIR.getDefaultState(), 12, 25, 13, start);
        structure.setBlockState(world, Blocks.SPRUCE_PLANKS.getDefaultState(), 12, 25, 14, start);
        structure.setBlockState(world, Blocks.SPRUCE_STAIRS.getDefaultState().with(StairsBlock.FACING, Direction.NORTH).with(StairsBlock.WATERLOGGED, false).with(StairsBlock.SHAPE, StairsShape.STRAIGHT).with(StairsBlock.HALF, Half.BOTTOM), 12, 25, 15, start);
        structure.setBlockState(world, Blocks.SPRUCE_PLANKS.getDefaultState(), 12, 26, 7, start);
        structure.setBlockState(world, Blocks.SPRUCE_PLANKS.getDefaultState(), 12, 26, 13, start);
        structure.setBlockState(world, Blocks.OAK_SLAB.getDefaultState().with(SlabBlock.TYPE, SlabType.BOTTOM).with(SlabBlock.WATERLOGGED, false), 12, 26, 14, start);
        structure.setBlockState(world, Blocks.OAK_STAIRS.getDefaultState().with(StairsBlock.FACING, Direction.SOUTH).with(StairsBlock.WATERLOGGED, false).with(StairsBlock.SHAPE, StairsShape.STRAIGHT).with(StairsBlock.HALF, Half.BOTTOM), 12, 27, 7, start);
        structure.setBlockState(world, Blocks.SPRUCE_PLANKS.getDefaultState(), 12, 27, 12, start);
        structure.setBlockState(world, Blocks.SPRUCE_STAIRS.getDefaultState().with(StairsBlock.FACING, Direction.SOUTH).with(StairsBlock.WATERLOGGED, false).with(StairsBlock.SHAPE, StairsShape.STRAIGHT).with(StairsBlock.HALF, Half.BOTTOM), 12, 28, 8, start);
        structure.setBlockState(world, Blocks.OAK_STAIRS.getDefaultState().with(StairsBlock.FACING, Direction.WEST).with(StairsBlock.WATERLOGGED, false).with(StairsBlock.SHAPE, StairsShape.STRAIGHT).with(StairsBlock.HALF, Half.BOTTOM), 12, 28, 12, start);
        structure.setBlockState(world, Blocks.SPRUCE_PLANKS.getDefaultState(), 12, 29, 10, start);
        structure.setBlockState(world, Blocks.OAK_STAIRS.getDefaultState().with(StairsBlock.FACING, Direction.WEST).with(StairsBlock.WATERLOGGED, false).with(StairsBlock.SHAPE, StairsShape.STRAIGHT).with(StairsBlock.HALF, Half.BOTTOM), 12, 29, 11, start);
        structure.setBlockState(world, Blocks.OAK_STAIRS.getDefaultState().with(StairsBlock.FACING, Direction.WEST).with(StairsBlock.WATERLOGGED, false).with(StairsBlock.SHAPE, StairsShape.STRAIGHT).with(StairsBlock.HALF, Half.BOTTOM), 12, 30, 9, start);
        structure.setBlockState(world, Blocks.STONE.getDefaultState(), 13, 0, 4, start);
        structure.setBlockState(world, Blocks.STONE.getDefaultState(), 13, 0, 18, start);
        structure.setBlockState(world, Blocks.OAK_PLANKS.getDefaultState(), 13, 5, 10, start);
        structure.setBlockState(world, Blocks.DIRT.getDefaultState(), 13, 5, 11, start);
        structure.setBlockState(world, Blocks.DIRT.getDefaultState(), 13, 5, 16, start);
        structure.setBlockState(world, Blocks.GRASS.getDefaultState(), 13, 6, 5, start);
        structure.setBlockState(world, Blocks.OAK_SLAB.getDefaultState().with(SlabBlock.TYPE, SlabType.BOTTOM).with(SlabBlock.WATERLOGGED, false), 13, 6, 10, start);
        structure.setBlockState(world, Blocks.DANDELION.getDefaultState(), 13, 6, 13, start);
        structure.setBlockState(world, Blocks.MOSSY_COBBLESTONE.getDefaultState(), 13, 8, 6, start);
        structure.setBlockState(world, Blocks.LANTERN.getDefaultState().with(LanternBlock.WATERLOGGED, false).with(LanternBlock.HANGING, true), 13, 8, 12, start);
        structure.setBlockState(world, Blocks.OAK_SLAB.getDefaultState().with(SlabBlock.TYPE, SlabType.BOTTOM).with(SlabBlock.WATERLOGGED, false), 13, 10, 7, start);
        structure.setBlockState(world, Blocks.SPRUCE_SLAB.getDefaultState().with(SlabBlock.TYPE, SlabType.BOTTOM).with(SlabBlock.WATERLOGGED, false), 13, 10, 8, start);
        structure.setBlockState(world, Blocks.OAK_SLAB.getDefaultState().with(SlabBlock.TYPE, SlabType.TOP).with(SlabBlock.WATERLOGGED, false), 13, 10, 9, start);
        structure.setBlockState(world, Blocks.ANDESITE.getDefaultState(), 13, 11, 6, start);
        structure.setBlockState(world, Blocks.OAK_SLAB.getDefaultState().with(SlabBlock.TYPE, SlabType.BOTTOM).with(SlabBlock.WATERLOGGED, false), 13, 11, 10, start);
        structure.setBlockState(world, Blocks.COBBLESTONE.getDefaultState(), 13, 11, 11, start);
        structure.setBlockState(world, Blocks.AIR.getDefaultState(), 13, 12, 10, start);
        structure.setBlockState(world, Blocks.OAK_SLAB.getDefaultState().with(SlabBlock.TYPE, SlabType.BOTTOM).with(SlabBlock.WATERLOGGED, false), 13, 14, 8, start);
        structure.setBlockState(world, Blocks.STONE.getDefaultState(), 13, 14, 11, start);
        structure.setBlockState(world, Blocks.STONE.getDefaultState(), 13, 15, 6, start);
        structure.setBlockState(world, Blocks.AIR.getDefaultState(), 13, 15, 7, start);
        structure.setBlockState(world, Blocks.SPRUCE_SLAB.getDefaultState().with(SlabBlock.TYPE, SlabType.BOTTOM).with(SlabBlock.WATERLOGGED, false), 13, 15, 10, start);
        structure.setBlockState(world, Blocks.COBBLESTONE.getDefaultState(), 13, 15, 11, start);
        structure.setBlockState(world, Blocks.MOSSY_COBBLESTONE.getDefaultState(), 13, 16, 11, start);
        structure.setBlockState(world, Blocks.ANDESITE.getDefaultState(), 13, 17, 7, start);
        structure.setBlockState(world, Blocks.LANTERN.getDefaultState().with(LanternBlock.WATERLOGGED, false).with(LanternBlock.HANGING, false), 13, 18, 7, start);
        structure.setBlockState(world, Blocks.COBBLESTONE.getDefaultState(), 13, 18, 8, start);
        structure.setBlockState(world, Blocks.LANTERN.getDefaultState().with(LanternBlock.WATERLOGGED, false).with(LanternBlock.HANGING, true), 13, 18, 11, start);
        structure.setBlockState(world, Blocks.CHAIN.getDefaultState().with(ChainBlock.WATERLOGGED, false), 13, 19, 11, start);
        structure.setBlockState(world, Blocks.REDSTONE_ORE.getDefaultState().with(RedstoneOreBlock.LIT, false), 13, 21, 10, start);
        structure.setBlockState(world, Blocks.SMOOTH_STONE.getDefaultState(), 13, 23, 9, start);
        structure.setBlockState(world, Blocks.STONE.getDefaultState(), 13, 23, 12, start);
        structure.setBlockState(world, Blocks.OAK_PLANKS.getDefaultState(), 13, 24, 7, start);
        structure.setBlockState(world, Blocks.SPRUCE_PLANKS.getDefaultState(), 13, 26, 9, start);
        structure.setBlockState(world, Blocks.OAK_STAIRS.getDefaultState().with(StairsBlock.FACING, Direction.NORTH).with(StairsBlock.WATERLOGGED, false).with(StairsBlock.SHAPE, StairsShape.STRAIGHT).with(StairsBlock.HALF, Half.BOTTOM), 13, 26, 13, start);
        structure.setBlockState(world, Blocks.SPRUCE_STAIRS.getDefaultState().with(StairsBlock.FACING, Direction.WEST).with(StairsBlock.WATERLOGGED, false).with(StairsBlock.SHAPE, StairsShape.STRAIGHT).with(StairsBlock.HALF, Half.BOTTOM), 13, 27, 9, start);
        structure.setBlockState(world, Blocks.SPRUCE_PLANKS.getDefaultState(), 13, 27, 10, start);
        structure.setBlockState(world, Blocks.OAK_SLAB.getDefaultState().with(SlabBlock.TYPE, SlabType.BOTTOM).with(SlabBlock.WATERLOGGED, false), 13, 27, 12, start);
        structure.setBlockState(world, Blocks.OAK_SLAB.getDefaultState().with(SlabBlock.TYPE, SlabType.BOTTOM).with(SlabBlock.WATERLOGGED, false), 13, 28, 10, start);
        structure.setBlockState(world, Blocks.SPRUCE_PLANKS.getDefaultState(), 13, 28, 11, start);
        structure.setBlockState(world, Blocks.LANTERN.getDefaultState().with(LanternBlock.WATERLOGGED, false).with(LanternBlock.HANGING, false), 13, 29, 11, start);
        structure.setBlockState(world, Blocks.DIRT.getDefaultState(), 14, 5, 8, start);
        structure.setBlockState(world, Blocks.OAK_PLANKS.getDefaultState(), 14, 5, 9, start);
        structure.setBlockState(world, Blocks.DIRT.getDefaultState(), 14, 5, 10, start);
        structure.setBlockState(world, Blocks.LANTERN.getDefaultState().with(LanternBlock.WATERLOGGED, false).with(LanternBlock.HANGING, false), 14, 6, 6, start);
        structure.setBlockState(world, Blocks.SPRUCE_DOOR.getDefaultState().with(DoorBlock.FACING, Direction.WEST).with(DoorBlock.HALF, DoubleBlockHalf.LOWER).with(DoorBlock.HINGE, DoorHingeSide.LEFT).with(DoorBlock.OPEN, false).with(DoorBlock.POWERED, false), 14, 6, 9, start);
        structure.setBlockState(world, Blocks.LANTERN.getDefaultState().with(LanternBlock.WATERLOGGED, false).with(LanternBlock.HANGING, false), 14, 6, 12, start);
        structure.setBlockState(world, Blocks.SPRUCE_DOOR.getDefaultState().with(DoorBlock.FACING, Direction.WEST).with(DoorBlock.HALF, DoubleBlockHalf.UPPER).with(DoorBlock.HINGE, DoorHingeSide.LEFT).with(DoorBlock.OPEN, false).with(DoorBlock.POWERED, false), 14, 7, 9, start);
        structure.setBlockState(world, Blocks.SMOOTH_STONE.getDefaultState(), 14, 8, 7, start);
        structure.setBlockState(world, Blocks.AIR.getDefaultState(), 14, 10, 7, start);
        structure.setBlockState(world, Blocks.OAK_SLAB.getDefaultState().with(SlabBlock.TYPE, SlabType.TOP).with(SlabBlock.WATERLOGGED, false), 14, 10, 8, start);
        structure.setBlockState(world, Blocks.COBBLESTONE.getDefaultState(), 14, 11, 6, start);
        structure.setBlockState(world, Blocks.SPRUCE_SLAB.getDefaultState().with(SlabBlock.TYPE, SlabType.BOTTOM).with(SlabBlock.WATERLOGGED, false), 14, 11, 9, start);
        structure.setBlockState(world, Blocks.REDSTONE_ORE.getDefaultState().with(RedstoneOreBlock.LIT, false), 14, 11, 11, start);
        structure.setBlockState(world, Blocks.SMOOTH_STONE.getDefaultState(), 14, 12, 6, start);
        structure.setBlockState(world, Blocks.LANTERN.getDefaultState().with(LanternBlock.WATERLOGGED, false).with(LanternBlock.HANGING, false), 14, 13, 6, start);
        structure.setBlockState(world, Blocks.LANTERN.getDefaultState().with(LanternBlock.WATERLOGGED, false).with(LanternBlock.HANGING, true), 14, 13, 9, start);
        structure.setBlockState(world, Blocks.POTTED_BAMBOO.getDefaultState(), 14, 13, 10, start);
        structure.setBlockState(world, Blocks.STONE.getDefaultState(), 14, 14, 7, start);
        structure.setBlockState(world, Blocks.ANDESITE.getDefaultState(), 14, 15, 7, start);
        structure.setBlockState(world, Blocks.REDSTONE_ORE.getDefaultState().with(RedstoneOreBlock.LIT, false), 14, 15, 8, start);
        structure.setBlockState(world, Blocks.STONE.getDefaultState(), 14, 16, 8, start);
        structure.setBlockState(world, Blocks.COBBLESTONE.getDefaultState(), 14, 16, 9, start);
        structure.setBlockState(world, Blocks.OAK_SLAB.getDefaultState().with(SlabBlock.TYPE, SlabType.TOP).with(SlabBlock.WATERLOGGED, false), 14, 22, 9, start);
        structure.setBlockState(world, Blocks.SPRUCE_STAIRS.getDefaultState().with(StairsBlock.FACING, Direction.WEST).with(StairsBlock.WATERLOGGED, false).with(StairsBlock.SHAPE, StairsShape.STRAIGHT).with(StairsBlock.HALF, Half.TOP), 14, 22, 10, start);
        structure.setBlockState(world, Blocks.SPRUCE_SLAB.getDefaultState().with(SlabBlock.TYPE, SlabType.TOP).with(SlabBlock.WATERLOGGED, false), 14, 22, 11, start);
        structure.setBlockState(world, Blocks.SPRUCE_STAIRS.getDefaultState().with(StairsBlock.FACING, Direction.WEST).with(StairsBlock.WATERLOGGED, false).with(StairsBlock.SHAPE, StairsShape.STRAIGHT).with(StairsBlock.HALF, Half.BOTTOM), 14, 24, 7, start);
        structure.setBlockState(world, Blocks.SPRUCE_PLANKS.getDefaultState(), 14, 24, 8, start);
        structure.setBlockState(world, Blocks.SPRUCE_SLAB.getDefaultState().with(SlabBlock.TYPE, SlabType.BOTTOM).with(SlabBlock.WATERLOGGED, false), 14, 24, 14, start);
        structure.setBlockState(world, Blocks.OAK_STAIRS.getDefaultState().with(StairsBlock.FACING, Direction.SOUTH).with(StairsBlock.WATERLOGGED, false).with(StairsBlock.SHAPE, StairsShape.STRAIGHT).with(StairsBlock.HALF, Half.BOTTOM), 14, 25, 8, start);
        structure.setBlockState(world, Blocks.SPRUCE_STAIRS.getDefaultState().with(StairsBlock.FACING, Direction.WEST).with(StairsBlock.WATERLOGGED, false).with(StairsBlock.SHAPE, StairsShape.STRAIGHT).with(StairsBlock.HALF, Half.BOTTOM), 14, 25, 12, start);
        structure.setBlockState(world, Blocks.OAK_STAIRS.getDefaultState().with(StairsBlock.FACING, Direction.WEST).with(StairsBlock.WATERLOGGED, false).with(StairsBlock.SHAPE, StairsShape.STRAIGHT).with(StairsBlock.HALF, Half.BOTTOM), 14, 26, 10, start);
        structure.setBlockState(world, Blocks.STONE.getDefaultState(), 15, 0, 5, start);
        structure.setBlockState(world, Blocks.STONE.getDefaultState(), 15, 0, 17, start);
        structure.setBlockState(world, Blocks.GRASS_BLOCK.getDefaultState().with(SnowyDirtBlock.SNOWY, false), 15, 2, 3, start);
        structure.setBlockState(world, Blocks.GRASS_BLOCK.getDefaultState().with(SnowyDirtBlock.SNOWY, false), 15, 2, 19, start);
        structure.setBlockState(world, Blocks.PODZOL.getDefaultState().with(SnowyDirtBlock.SNOWY, false), 15, 5, 11, start);
        structure.setBlockState(world, Blocks.GRASS.getDefaultState(), 15, 6, 8, start);
        structure.setBlockState(world, Blocks.AIR.getDefaultState(), 15, 6, 11, start);
        structure.setBlockState(world, Blocks.SMOOTH_STONE.getDefaultState(), 15, 11, 7, start);
        structure.setBlockState(world, Blocks.COBBLESTONE.getDefaultState(), 15, 11, 8, start);
        structure.setBlockState(world, Blocks.STONE.getDefaultState(), 15, 12, 8, start);
        structure.setBlockState(world, Blocks.ANDESITE.getDefaultState(), 15, 13, 8, start);
        structure.setBlockState(world, Blocks.SMOOTH_STONE.getDefaultState(), 15, 13, 10, start);
        structure.setBlockState(world, Blocks.LANTERN.getDefaultState().with(LanternBlock.WATERLOGGED, false).with(LanternBlock.HANGING, false), 15, 15, 9, start);
        structure.setBlockState(world, Blocks.SPRUCE_STAIRS.getDefaultState().with(StairsBlock.FACING, Direction.WEST).with(StairsBlock.WATERLOGGED, false).with(StairsBlock.SHAPE, StairsShape.STRAIGHT).with(StairsBlock.HALF, Half.BOTTOM), 15, 24, 11, start);
        structure.setBlockState(world, Blocks.GRASS_BLOCK.getDefaultState().with(SnowyDirtBlock.SNOWY, false), 16, 0, 2, start);
        structure.setBlockState(world, Blocks.GRASS_BLOCK.getDefaultState().with(SnowyDirtBlock.SNOWY, false), 16, 0, 20, start);
        structure.setBlockState(world, Blocks.GRASS_BLOCK.getDefaultState().with(SnowyDirtBlock.SNOWY, false), 16, 3, 18, start);
        structure.setBlockState(world, Blocks.GRASS_BLOCK.getDefaultState().with(SnowyDirtBlock.SNOWY, false), 16, 4, 17, start);
        structure.setBlockState(world, Blocks.AIR.getDefaultState(), 16, 6, 8, start);
        structure.setBlockState(world, Blocks.DANDELION.getDefaultState(), 16, 6, 13, start);
        structure.setBlockState(world, Blocks.LANTERN.getDefaultState().with(LanternBlock.WATERLOGGED, false).with(LanternBlock.HANGING, true), 16, 21, 9, start);
        structure.setBlockState(world, Blocks.OAK_STAIRS.getDefaultState().with(StairsBlock.FACING, Direction.WEST).with(StairsBlock.WATERLOGGED, false).with(StairsBlock.SHAPE, StairsShape.STRAIGHT).with(StairsBlock.HALF, Half.BOTTOM), 16, 24, 9, start);
        structure.setBlockState(world, Blocks.STONE.getDefaultState(), 17, 0, 15, start);
        structure.setBlockState(world, Blocks.GRASS_BLOCK.getDefaultState().with(SnowyDirtBlock.SNOWY, false), 17, 2, 18, start);
        structure.setBlockState(world, Blocks.GRASS_BLOCK.getDefaultState().with(SnowyDirtBlock.SNOWY, false), 17, 3, 17, start);
        structure.setBlockState(world, Blocks.GRASS_BLOCK.getDefaultState().with(SnowyDirtBlock.SNOWY, false), 17, 4, 16, start);
        structure.setBlockState(world, Blocks.POPPY.getDefaultState(), 17, 6, 13, start);
        structure.setBlockState(world, Blocks.GRASS_BLOCK.getDefaultState().with(SnowyDirtBlock.SNOWY, false), 18, 0, 19, start);
        structure.setBlockState(world, Blocks.GRASS_BLOCK.getDefaultState().with(SnowyDirtBlock.SNOWY, false), 18, 1, 18, start);
        structure.setBlockState(world, Blocks.GRASS_BLOCK.getDefaultState().with(SnowyDirtBlock.SNOWY, false), 18, 2, 5, start);
        structure.setBlockState(world, Blocks.GRASS_BLOCK.getDefaultState().with(SnowyDirtBlock.SNOWY, false), 18, 2, 17, start);
        structure.setBlockState(world, Blocks.GRASS_BLOCK.getDefaultState().with(SnowyDirtBlock.SNOWY, false), 18, 3, 6, start);
        structure.setBlockState(world, Blocks.GRASS_BLOCK.getDefaultState().with(SnowyDirtBlock.SNOWY, false), 18, 3, 16, start);
        structure.setBlockState(world, Blocks.GRASS_BLOCK.getDefaultState().with(SnowyDirtBlock.SNOWY, false), 19, 0, 4, start);
        structure.setBlockState(world, Blocks.GRASS_BLOCK.getDefaultState().with(SnowyDirtBlock.SNOWY, false), 19, 0, 18, start);
        structure.setBlockState(world, Blocks.GRASS_BLOCK.getDefaultState().with(SnowyDirtBlock.SNOWY, false), 19, 2, 7, start);
        structure.setBlockState(world, Blocks.GRASS_BLOCK.getDefaultState().with(SnowyDirtBlock.SNOWY, false), 19, 2, 15, start);
        structure.setBlockState(world, Blocks.GRASS_BLOCK.getDefaultState().with(SnowyDirtBlock.SNOWY, false), 20, 0, 6, start);
        structure.setBlockState(world, Blocks.GRASS_BLOCK.getDefaultState().with(SnowyDirtBlock.SNOWY, false), 20, 0, 16, start);
        structure.fillWithBlocks(world, start, 1, 0, 8, 1, 0, 9, Blocks.GRASS_BLOCK.getDefaultState().with(SnowyDirtBlock.SNOWY, false));
        structure.fillWithBlocks(world, start, 1, 0, 10, 2, 0, 12, Blocks.DIRT.getDefaultState());
        structure.fillWithBlocks(world, start, 1, 0, 13, 1, 0, 14, Blocks.GRASS_BLOCK.getDefaultState().with(SnowyDirtBlock.SNOWY, false));
        structure.fillWithBlocks(world, start, 1, 1, 10, 1, 1, 12, Blocks.GRASS_BLOCK.getDefaultState().with(SnowyDirtBlock.SNOWY, false));
        structure.fillWithBlocks(world, start, 2, 0, 7, 3, 0, 10, Blocks.DIRT.getDefaultState());
        structure.fillWithBlocks(world, start, 2, 0, 13, 3, 0, 15, Blocks.DIRT.getDefaultState());
        structure.fillWithBlocks(world, start, 2, 1, 7, 2, 1, 8, Blocks.GRASS_BLOCK.getDefaultState().with(SnowyDirtBlock.SNOWY, false));
        structure.fillWithBlocks(world, start, 2, 1, 9, 4, 1, 11, Blocks.DIRT.getDefaultState());
        structure.fillWithBlocks(world, start, 2, 1, 12, 3, 1, 13, Blocks.DIRT.getDefaultState());
        structure.fillWithBlocks(world, start, 2, 1, 14, 2, 1, 15, Blocks.GRASS_BLOCK.getDefaultState().with(SnowyDirtBlock.SNOWY, false));
        structure.fillWithBlocks(world, start, 2, 2, 9, 2, 2, 13, Blocks.GRASS_BLOCK.getDefaultState().with(SnowyDirtBlock.SNOWY, false));
        structure.fillWithBlocks(world, start, 3, 0, 5, 6, 0, 8, Blocks.DIRT.getDefaultState());
        structure.fillWithBlocks(world, start, 3, 0, 11, 3, 0, 12, Blocks.STONE.getDefaultState());
        structure.fillWithBlocks(world, start, 3, 0, 16, 4, 0, 17, Blocks.DIRT.getDefaultState());
        structure.fillWithBlocks(world, start, 3, 0, 18, 3, 0, 18, Blocks.GRASS_BLOCK.getDefaultState().with(SnowyDirtBlock.SNOWY, false));
        structure.fillWithBlocks(world, start, 3, 1, 5, 3, 1, 6, Blocks.GRASS_BLOCK.getDefaultState().with(SnowyDirtBlock.SNOWY, false));
        structure.fillWithBlocks(world, start, 3, 1, 7, 6, 1, 11, Blocks.DIRT.getDefaultState());
        structure.fillWithBlocks(world, start, 3, 1, 14, 4, 1, 15, Blocks.DIRT.getDefaultState());
        structure.fillWithBlocks(world, start, 3, 1, 16, 3, 1, 17, Blocks.GRASS_BLOCK.getDefaultState().with(SnowyDirtBlock.SNOWY, false));
        structure.fillWithBlocks(world, start, 3, 2, 8, 9, 2, 14, Blocks.DIRT.getDefaultState());
        structure.fillWithBlocks(world, start, 3, 3, 8, 3, 3, 9, Blocks.GRASS_BLOCK.getDefaultState().with(SnowyDirtBlock.SNOWY, false));
        structure.fillWithBlocks(world, start, 3, 3, 10, 5, 3, 12, Blocks.DIRT.getDefaultState());
        structure.fillWithBlocks(world, start, 3, 3, 13, 3, 3, 14, Blocks.GRASS_BLOCK.getDefaultState().with(SnowyDirtBlock.SNOWY, false));
        structure.fillWithBlocks(world, start, 3, 4, 10, 3, 4, 12, Blocks.GRASS_BLOCK.getDefaultState().with(SnowyDirtBlock.SNOWY, false));
        structure.fillWithBlocks(world, start, 4, 0, 4, 8, 0, 8, Blocks.DIRT.getDefaultState());
        structure.fillWithBlocks(world, start, 4, 0, 10, 5, 0, 12, Blocks.DIRT.getDefaultState());
        structure.fillWithBlocks(world, start, 4, 0, 13, 4, 0, 15, Blocks.STONE.getDefaultState());
        structure.fillWithBlocks(world, start, 4, 0, 18, 4, 0, 18, Blocks.DIRT.getDefaultState());
        structure.fillWithBlocks(world, start, 4, 1, 5, 8, 1, 9, Blocks.DIRT.getDefaultState());
        structure.fillWithBlocks(world, start, 4, 1, 12, 4, 1, 13, Blocks.STONE.getDefaultState());
        structure.fillWithBlocks(world, start, 4, 1, 16, 5, 1, 17, Blocks.DIRT.getDefaultState());
        structure.fillWithBlocks(world, start, 4, 1, 18, 4, 1, 18, Blocks.GRASS_BLOCK.getDefaultState().with(SnowyDirtBlock.SNOWY, false));
        structure.fillWithBlocks(world, start, 4, 2, 6, 14, 2, 16, Blocks.DIRT.getDefaultState());
        structure.fillWithBlocks(world, start, 4, 2, 17, 4, 2, 17, Blocks.GRASS_BLOCK.getDefaultState().with(SnowyDirtBlock.SNOWY, false));
        structure.fillWithBlocks(world, start, 4, 3, 7, 12, 3, 15, Blocks.DIRT.getDefaultState());
        structure.fillWithBlocks(world, start, 4, 3, 16, 4, 3, 16, Blocks.GRASS_BLOCK.getDefaultState().with(SnowyDirtBlock.SNOWY, false));
        structure.fillWithBlocks(world, start, 4, 4, 7, 4, 4, 8, Blocks.GRASS_BLOCK.getDefaultState().with(SnowyDirtBlock.SNOWY, false));
        structure.fillWithBlocks(world, start, 4, 4, 9, 8, 4, 13, Blocks.DIRT.getDefaultState());
        structure.fillWithBlocks(world, start, 4, 4, 14, 4, 4, 15, Blocks.GRASS_BLOCK.getDefaultState().with(SnowyDirtBlock.SNOWY, false));
        structure.fillWithBlocks(world, start, 4, 5, 9, 7, 5, 13, Blocks.GRASS_BLOCK.getDefaultState().with(SnowyDirtBlock.SNOWY, false));
        structure.fillWithBlocks(world, start, 4, 6, 10, 4, 6, 13, Blocks.GRASS.getDefaultState());
        structure.fillWithBlocks(world, start, 5, 0, 3, 8, 0, 8, Blocks.DIRT.getDefaultState());
        structure.fillWithBlocks(world, start, 5, 0, 9, 5, 4, 14, Blocks.DIRT.getDefaultState());
        structure.fillWithBlocks(world, start, 5, 0, 15, 5, 0, 16, Blocks.STONE.getDefaultState());
        structure.fillWithBlocks(world, start, 5, 0, 17, 5, 0, 19, Blocks.DIRT.getDefaultState());
        structure.fillWithBlocks(world, start, 5, 1, 3, 6, 1, 3, Blocks.GRASS_BLOCK.getDefaultState().with(SnowyDirtBlock.SNOWY, false));
        structure.fillWithBlocks(world, start, 5, 1, 4, 10, 1, 9, Blocks.DIRT.getDefaultState());
        structure.fillWithBlocks(world, start, 5, 1, 15, 5, 1, 15, Blocks.STONE.getDefaultState());
        structure.fillWithBlocks(world, start, 5, 1, 18, 17, 1, 18, Blocks.DIRT.getDefaultState());
        structure.fillWithBlocks(world, start, 5, 1, 19, 6, 1, 19, Blocks.GRASS_BLOCK.getDefaultState().with(SnowyDirtBlock.SNOWY, false));
        structure.fillWithBlocks(world, start, 5, 2, 5, 17, 2, 17, Blocks.DIRT.getDefaultState());
        structure.fillWithBlocks(world, start, 5, 3, 6, 15, 3, 16, Blocks.DIRT.getDefaultState());
        structure.fillWithBlocks(world, start, 5, 3, 17, 5, 3, 17, Blocks.GRASS_BLOCK.getDefaultState().with(SnowyDirtBlock.SNOWY, false));
        structure.fillWithBlocks(world, start, 5, 4, 7, 13, 4, 15, Blocks.DIRT.getDefaultState());
        structure.fillWithBlocks(world, start, 5, 4, 16, 5, 4, 16, Blocks.GRASS_BLOCK.getDefaultState().with(SnowyDirtBlock.SNOWY, false));
        structure.fillWithBlocks(world, start, 5, 5, 4, 5, 5, 4, Blocks.CAVE_AIR.getDefaultState());
        structure.fillWithBlocks(world, start, 5, 5, 7, 7, 5, 15, Blocks.GRASS_BLOCK.getDefaultState().with(SnowyDirtBlock.SNOWY, false));
        structure.fillWithBlocks(world, start, 5, 6, 7, 5, 6, 10, Blocks.GRASS.getDefaultState());
        structure.fillWithBlocks(world, start, 5, 6, 13, 6, 6, 14, Blocks.GRASS.getDefaultState());
        structure.fillWithBlocks(world, start, 6, 0, 9, 6, 4, 9, Blocks.DIRT.getDefaultState());
        structure.fillWithBlocks(world, start, 6, 0, 10, 7, 0, 12, Blocks.STONE.getDefaultState());
        structure.fillWithBlocks(world, start, 6, 0, 13, 6, 2, 15, Blocks.DIRT.getDefaultState());
        structure.fillWithBlocks(world, start, 6, 0, 16, 9, 0, 16, Blocks.DIRT.getDefaultState());
        structure.fillWithBlocks(world, start, 6, 0, 17, 7, 0, 17, Blocks.STONE.getDefaultState());
        structure.fillWithBlocks(world, start, 6, 0, 18, 7, 0, 19, Blocks.DIRT.getDefaultState());
        structure.fillWithBlocks(world, start, 6, 1, 12, 6, 4, 15, Blocks.DIRT.getDefaultState());
        structure.fillWithBlocks(world, start, 6, 1, 17, 7, 1, 18, Blocks.DIRT.getDefaultState());
        structure.fillWithBlocks(world, start, 6, 2, 4, 16, 2, 18, Blocks.DIRT.getDefaultState());
        structure.fillWithBlocks(world, start, 6, 3, 5, 16, 3, 17, Blocks.DIRT.getDefaultState());
        structure.fillWithBlocks(world, start, 6, 4, 6, 16, 4, 16, Blocks.DIRT.getDefaultState());
        structure.fillWithBlocks(world, start, 6, 4, 17, 6, 4, 17, Blocks.GRASS_BLOCK.getDefaultState().with(SnowyDirtBlock.SNOWY, false));
        structure.fillWithBlocks(world, start, 6, 5, 6, 7, 5, 16, Blocks.GRASS_BLOCK.getDefaultState().with(SnowyDirtBlock.SNOWY, false));
        structure.fillWithBlocks(world, start, 6, 6, 6, 6, 6, 6, Blocks.GRASS.getDefaultState());
        structure.fillWithBlocks(world, start, 6, 6, 10, 6, 6, 10, Blocks.GRASS.getDefaultState());
        structure.fillWithBlocks(world, start, 6, 6, 12, 6, 6, 16, Blocks.GRASS.getDefaultState());
        structure.fillWithBlocks(world, start, 7, 0, 2, 11, 0, 6, Blocks.DIRT.getDefaultState());
        structure.fillWithBlocks(world, start, 7, 0, 9, 7, 0, 14, Blocks.STONE.getDefaultState());
        structure.fillWithBlocks(world, start, 7, 0, 15, 7, 0, 16, Blocks.DIRT.getDefaultState());
        structure.fillWithBlocks(world, start, 7, 0, 20, 15, 0, 20, Blocks.DIRT.getDefaultState());
        structure.fillWithBlocks(world, start, 7, 1, 2, 8, 1, 2, Blocks.GRASS_BLOCK.getDefaultState().with(SnowyDirtBlock.SNOWY, false));
        structure.fillWithBlocks(world, start, 7, 1, 3, 13, 1, 9, Blocks.DIRT.getDefaultState());
        structure.fillWithBlocks(world, start, 7, 1, 10, 7, 1, 13, Blocks.STONE.getDefaultState());
        structure.fillWithBlocks(world, start, 7, 1, 14, 8, 1, 19, Blocks.DIRT.getDefaultState());
        structure.fillWithBlocks(world, start, 7, 1, 20, 8, 1, 20, Blocks.GRASS_BLOCK.getDefaultState().with(SnowyDirtBlock.SNOWY, false));
        structure.fillWithBlocks(world, start, 7, 3, 4, 15, 3, 18, Blocks.DIRT.getDefaultState());
        structure.fillWithBlocks(world, start, 7, 4, 4, 8, 4, 4, Blocks.GRASS_BLOCK.getDefaultState().with(SnowyDirtBlock.SNOWY, false));
        structure.fillWithBlocks(world, start, 7, 4, 5, 15, 4, 17, Blocks.DIRT.getDefaultState());
        structure.fillWithBlocks(world, start, 7, 4, 18, 8, 4, 18, Blocks.GRASS_BLOCK.getDefaultState().with(SnowyDirtBlock.SNOWY, false));
        structure.fillWithBlocks(world, start, 7, 5, 5, 8, 5, 6, Blocks.GRASS_BLOCK.getDefaultState().with(SnowyDirtBlock.SNOWY, false));
        structure.fillWithBlocks(world, start, 7, 5, 17, 15, 5, 17, Blocks.GRASS_BLOCK.getDefaultState().with(SnowyDirtBlock.SNOWY, false));
        structure.fillWithBlocks(world, start, 7, 6, 5, 8, 6, 6, Blocks.GRASS.getDefaultState());
        structure.fillWithBlocks(world, start, 7, 6, 13, 7, 6, 14, Blocks.GRASS.getDefaultState());
        structure.fillWithBlocks(world, start, 7, 18, 8, 7, 19, 8, Blocks.STONE.getDefaultState());
        structure.fillWithBlocks(world, start, 7, 18, 9, 7, 18, 9, Blocks.COBBLESTONE.getDefaultState());
        structure.fillWithBlocks(world, start, 7, 19, 9, 7, 20, 9, Blocks.SMOOTH_STONE.getDefaultState());
        structure.fillWithBlocks(world, start, 7, 22, 11, 7, 22, 12, Blocks.OAK_SLAB.getDefaultState().with(SlabBlock.TYPE, SlabType.TOP).with(SlabBlock.WATERLOGGED, false));
        structure.fillWithBlocks(world, start, 7, 24, 8, 7, 24, 9, Blocks.SPRUCE_PLANKS.getDefaultState());
        structure.fillWithBlocks(world, start, 7, 25, 11, 8, 25, 11, Blocks.OAK_PLANKS.getDefaultState());
        structure.fillWithBlocks(world, start, 8, 0, 1, 9, 0, 1, Blocks.GRASS_BLOCK.getDefaultState().with(SnowyDirtBlock.SNOWY, false));
        structure.fillWithBlocks(world, start, 8, 0, 9, 13, 0, 14, Blocks.DIRT.getDefaultState());
        structure.fillWithBlocks(world, start, 8, 0, 15, 14, 0, 15, Blocks.STONE.getDefaultState());
        structure.fillWithBlocks(world, start, 8, 0, 17, 8, 2, 19, Blocks.DIRT.getDefaultState());
        structure.fillWithBlocks(world, start, 8, 0, 21, 9, 0, 21, Blocks.GRASS_BLOCK.getDefaultState().with(SnowyDirtBlock.SNOWY, false));
        structure.fillWithBlocks(world, start, 8, 1, 10, 12, 1, 14, Blocks.DIRT.getDefaultState());
        structure.fillWithBlocks(world, start, 8, 2, 3, 14, 2, 19, Blocks.DIRT.getDefaultState());
        structure.fillWithBlocks(world, start, 8, 3, 3, 9, 3, 3, Blocks.GRASS_BLOCK.getDefaultState().with(SnowyDirtBlock.SNOWY, false));
        structure.fillWithBlocks(world, start, 8, 3, 19, 9, 3, 19, Blocks.GRASS_BLOCK.getDefaultState().with(SnowyDirtBlock.SNOWY, false));
        structure.fillWithBlocks(world, start, 8, 5, 7, 8, 5, 10, Blocks.DIRT.getDefaultState());
        structure.fillWithBlocks(world, start, 8, 5, 11, 8, 5, 17, Blocks.GRASS_BLOCK.getDefaultState().with(SnowyDirtBlock.SNOWY, false));
        structure.fillWithBlocks(world, start, 8, 6, 7, 9, 6, 7, Blocks.COBBLESTONE.getDefaultState());
        structure.fillWithBlocks(world, start, 8, 6, 9, 8, 6, 10, Blocks.COBBLESTONE.getDefaultState());
        structure.fillWithBlocks(world, start, 8, 6, 15, 8, 6, 16, Blocks.GRASS.getDefaultState());
        structure.fillWithBlocks(world, start, 8, 7, 7, 8, 7, 9, Blocks.COBBLESTONE.getDefaultState());
        structure.fillWithBlocks(world, start, 8, 7, 10, 8, 8, 10, Blocks.STONE.getDefaultState());
        structure.fillWithBlocks(world, start, 8, 9, 9, 8, 9, 10, Blocks.COBBLESTONE.getDefaultState());
        structure.fillWithBlocks(world, start, 8, 13, 8, 8, 13, 9, Blocks.COBBLESTONE.getDefaultState());
        structure.fillWithBlocks(world, start, 8, 14, 8, 8, 15, 8, Blocks.COBBLESTONE.getDefaultState());
        structure.fillWithBlocks(world, start, 8, 15, 9, 8, 15, 9, Blocks.COBBLESTONE.getDefaultState());
        structure.fillWithBlocks(world, start, 8, 17, 10, 8, 17, 11, Blocks.COBBLESTONE.getDefaultState());
        structure.fillWithBlocks(world, start, 8, 18, 10, 8, 18, 11, Blocks.COBBLESTONE.getDefaultState());
        structure.fillWithBlocks(world, start, 8, 19, 10, 8, 20, 10, Blocks.COBBLESTONE.getDefaultState());
        structure.fillWithBlocks(world, start, 8, 20, 7, 8, 20, 8, Blocks.COBBLESTONE.getDefaultState());
        structure.fillWithBlocks(world, start, 8, 21, 9, 8, 22, 9, Blocks.COBBLESTONE.getDefaultState());
        structure.fillWithBlocks(world, start, 8, 22, 11, 8, 24, 11, Blocks.COBBLESTONE.getDefaultState());
        structure.fillWithBlocks(world, start, 8, 23, 10, 8, 24, 11, Blocks.COBBLESTONE.getDefaultState());
        structure.fillWithBlocks(world, start, 8, 24, 9, 8, 24, 11, Blocks.COBBLESTONE.getDefaultState());
        structure.fillWithBlocks(world, start, 8, 24, 14, 8, 24, 14, Blocks.OAK_PLANKS.getDefaultState());
        structure.fillWithBlocks(world, start, 8, 25, 8, 8, 25, 10, Blocks.SPRUCE_PLANKS.getDefaultState());
        structure.fillWithBlocks(world, start, 8, 25, 12, 8, 25, 12, Blocks.SPRUCE_PLANKS.getDefaultState());
        structure.fillWithBlocks(world, start, 8, 26, 11, 8, 26, 12, Blocks.OAK_PLANKS.getDefaultState());
        structure.fillWithBlocks(world, start, 8, 27, 10, 9, 27, 10, Blocks.OAK_PLANKS.getDefaultState());
        structure.fillWithBlocks(world, start, 9, 0, 7, 13, 0, 7, Blocks.STONE.getDefaultState());
        structure.fillWithBlocks(world, start, 9, 0, 8, 14, 0, 14, Blocks.DIRT.getDefaultState());
        structure.fillWithBlocks(world, start, 9, 0, 17, 9, 0, 17, Blocks.DIRT.getDefaultState());
        structure.fillWithBlocks(world, start, 9, 0, 19, 10, 0, 20, Blocks.DIRT.getDefaultState());
        structure.fillWithBlocks(world, start, 9, 1, 2, 13, 1, 14, Blocks.DIRT.getDefaultState());
        structure.fillWithBlocks(world, start, 9, 1, 15, 13, 1, 15, Blocks.STONE.getDefaultState());
        structure.fillWithBlocks(world, start, 9, 1, 16, 13, 1, 20, Blocks.DIRT.getDefaultState());
        structure.fillWithBlocks(world, start, 9, 2, 2, 13, 2, 2, Blocks.GRASS_BLOCK.getDefaultState().with(SnowyDirtBlock.SNOWY, false));
        structure.fillWithBlocks(world, start, 9, 2, 20, 13, 2, 20, Blocks.GRASS_BLOCK.getDefaultState().with(SnowyDirtBlock.SNOWY, false));
        structure.fillWithBlocks(world, start, 9, 4, 4, 13, 4, 18, Blocks.DIRT.getDefaultState());
        structure.fillWithBlocks(world, start, 9, 5, 4, 10, 5, 5, Blocks.GRASS_BLOCK.getDefaultState().with(SnowyDirtBlock.SNOWY, false));
        structure.fillWithBlocks(world, start, 9, 5, 8, 10, 5, 8, Blocks.SPRUCE_PLANKS.getDefaultState());
        structure.fillWithBlocks(world, start, 9, 5, 9, 9, 5, 9, Blocks.OAK_PLANKS.getDefaultState());
        structure.fillWithBlocks(world, start, 9, 5, 11, 9, 5, 12, Blocks.DIRT.getDefaultState());
        structure.fillWithBlocks(world, start, 9, 5, 13, 10, 5, 14, Blocks.GRASS_BLOCK.getDefaultState().with(SnowyDirtBlock.SNOWY, false));
        structure.fillWithBlocks(world, start, 9, 5, 15, 10, 5, 16, Blocks.WATER.getDefaultState());
        structure.fillWithBlocks(world, start, 9, 5, 18, 13, 5, 18, Blocks.GRASS_BLOCK.getDefaultState().with(SnowyDirtBlock.SNOWY, false));
        structure.fillWithBlocks(world, start, 9, 6, 8, 9, 6, 9, Blocks.BARREL.getDefaultState().with(BarrelBlock.PROPERTY_FACING, Direction.EAST).with(BarrelBlock.PROPERTY_OPEN, false));
        structure.fillWithBlocks(world, start, 9, 6, 11, 9, 6, 11, Blocks.COBBLESTONE.getDefaultState());
        structure.fillWithBlocks(world, start, 9, 7, 7, 9, 8, 7, Blocks.SMOOTH_STONE.getDefaultState());
        structure.fillWithBlocks(world, start, 9, 7, 11, 9, 8, 11, Blocks.ANDESITE.getDefaultState());
        structure.fillWithBlocks(world, start, 9, 7, 12, 10, 7, 12, Blocks.COBBLESTONE.getDefaultState());
        structure.fillWithBlocks(world, start, 9, 9, 7, 9, 9, 8, Blocks.COBBLESTONE.getDefaultState());
        structure.fillWithBlocks(world, start, 9, 9, 11, 10, 10, 11, Blocks.COBBLESTONE.getDefaultState());
        structure.fillWithBlocks(world, start, 9, 10, 8, 9, 11, 8, Blocks.STONE.getDefaultState());
        structure.fillWithBlocks(world, start, 9, 11, 9, 9, 11, 10, Blocks.COBBLESTONE.getDefaultState());
        structure.fillWithBlocks(world, start, 9, 12, 8, 9, 12, 9, Blocks.COBBLESTONE.getDefaultState());
        structure.fillWithBlocks(world, start, 9, 12, 10, 9, 12, 10, Blocks.ANDESITE.getDefaultState());
        structure.fillWithBlocks(world, start, 9, 13, 7, 11, 13, 7, Blocks.COBBLESTONE.getDefaultState());
        structure.fillWithBlocks(world, start, 9, 13, 8, 9, 13, 9, Blocks.OAK_SLAB.getDefaultState().with(SlabBlock.TYPE, SlabType.BOTTOM).with(SlabBlock.WATERLOGGED, false));
        structure.fillWithBlocks(world, start, 9, 13, 10, 9, 15, 10, Blocks.COBBLESTONE.getDefaultState());
        structure.fillWithBlocks(world, start, 9, 14, 7, 9, 15, 7, Blocks.STONE.getDefaultState());
        structure.fillWithBlocks(world, start, 9, 15, 9, 9, 15, 11, Blocks.COBBLESTONE.getDefaultState());
        structure.fillWithBlocks(world, start, 9, 16, 11, 9, 17, 11, Blocks.COBBLESTONE.getDefaultState());
        structure.fillWithBlocks(world, start, 9, 17, 6, 9, 19, 6, Blocks.COBBLESTONE.getDefaultState());
        structure.fillWithBlocks(world, start, 9, 17, 7, 9, 17, 7, Blocks.SPRUCE_SLAB.getDefaultState().with(SlabBlock.TYPE, SlabType.TOP).with(SlabBlock.WATERLOGGED, false));
        structure.fillWithBlocks(world, start, 9, 20, 11, 9, 21, 11, Blocks.COBBLESTONE.getDefaultState());
        structure.fillWithBlocks(world, start, 9, 21, 7, 11, 21, 7, Blocks.COBBLESTONE.getDefaultState());
        structure.fillWithBlocks(world, start, 9, 21, 9, 9, 21, 10, Blocks.SPRUCE_SLAB.getDefaultState().with(SlabBlock.TYPE, SlabType.TOP).with(SlabBlock.WATERLOGGED, false));
        structure.fillWithBlocks(world, start, 9, 21, 12, 9, 21, 12, Blocks.COBBLESTONE.getDefaultState());
        structure.fillWithBlocks(world, start, 9, 22, 13, 9, 24, 13, Blocks.COBBLESTONE.getDefaultState());
        structure.fillWithBlocks(world, start, 9, 24, 8, 12, 24, 8, Blocks.COBBLESTONE.getDefaultState());
        structure.fillWithBlocks(world, start, 9, 24, 12, 9, 24, 13, Blocks.COBBLESTONE.getDefaultState());
        structure.fillWithBlocks(world, start, 9, 25, 7, 11, 25, 7, Blocks.OAK_PLANKS.getDefaultState());
        structure.fillWithBlocks(world, start, 9, 25, 9, 11, 25, 9, Blocks.SPRUCE_SLAB.getDefaultState().with(SlabBlock.TYPE, SlabType.BOTTOM).with(SlabBlock.WATERLOGGED, false));
        structure.fillWithBlocks(world, start, 9, 25, 11, 9, 25, 12, Blocks.OAK_SLAB.getDefaultState().with(SlabBlock.TYPE, SlabType.BOTTOM).with(SlabBlock.WATERLOGGED, false));
        structure.fillWithBlocks(world, start, 9, 25, 13, 9, 26, 13, Blocks.SPRUCE_PLANKS.getDefaultState());
        structure.fillWithBlocks(world, start, 9, 25, 14, 9, 25, 14, Blocks.OAK_PLANKS.getDefaultState());
        structure.fillWithBlocks(world, start, 9, 27, 9, 9, 28, 10, Blocks.OAK_PLANKS.getDefaultState());
        structure.fillWithBlocks(world, start, 9, 27, 11, 9, 27, 12, Blocks.SPRUCE_PLANKS.getDefaultState());
        structure.fillWithBlocks(world, start, 9, 28, 11, 9, 28, 12, Blocks.OAK_PLANKS.getDefaultState());
        structure.fillWithBlocks(world, start, 9, 30, 10, 9, 31, 10, Blocks.SPRUCE_PLANKS.getDefaultState());
        structure.fillWithBlocks(world, start, 9, 32, 10, 10, 32, 10, Blocks.OAK_PLANKS.getDefaultState());
        structure.fillWithBlocks(world, start, 10, 0, 1, 12, 0, 6, Blocks.DIRT.getDefaultState());
        structure.fillWithBlocks(world, start, 10, 0, 16, 12, 0, 16, Blocks.STONE.getDefaultState());
        structure.fillWithBlocks(world, start, 10, 0, 17, 12, 0, 21, Blocks.DIRT.getDefaultState());
        structure.fillWithBlocks(world, start, 10, 1, 1, 12, 1, 1, Blocks.GRASS_BLOCK.getDefaultState().with(SnowyDirtBlock.SNOWY, false));
        structure.fillWithBlocks(world, start, 10, 1, 21, 12, 1, 21, Blocks.GRASS_BLOCK.getDefaultState().with(SnowyDirtBlock.SNOWY, false));
        structure.fillWithBlocks(world, start, 10, 3, 3, 12, 3, 19, Blocks.DIRT.getDefaultState());
        structure.fillWithBlocks(world, start, 10, 4, 3, 12, 4, 3, Blocks.GRASS_BLOCK.getDefaultState().with(SnowyDirtBlock.SNOWY, false));
        structure.fillWithBlocks(world, start, 10, 4, 19, 12, 4, 19, Blocks.GRASS_BLOCK.getDefaultState().with(SnowyDirtBlock.SNOWY, false));
        structure.fillWithBlocks(world, start, 10, 5, 6, 12, 5, 6, Blocks.DIRT.getDefaultState());
        structure.fillWithBlocks(world, start, 10, 5, 7, 10, 5, 8, Blocks.SPRUCE_PLANKS.getDefaultState());
        structure.fillWithBlocks(world, start, 10, 5, 9, 10, 5, 11, Blocks.OAK_PLANKS.getDefaultState());
        structure.fillWithBlocks(world, start, 10, 5, 12, 12, 5, 12, Blocks.DIRT.getDefaultState());
        structure.fillWithBlocks(world, start, 10, 6, 6, 12, 6, 6, Blocks.COBBLESTONE.getDefaultState());
        structure.fillWithBlocks(world, start, 10, 6, 12, 10, 7, 12, Blocks.COBBLESTONE.getDefaultState());
        structure.fillWithBlocks(world, start, 10, 7, 10, 10, 7, 10, Blocks.SPRUCE_SLAB.getDefaultState().with(SlabBlock.TYPE, SlabType.TOP).with(SlabBlock.WATERLOGGED, false));
        structure.fillWithBlocks(world, start, 10, 8, 8, 10, 8, 8, Blocks.OAK_SLAB.getDefaultState().with(SlabBlock.TYPE, SlabType.TOP).with(SlabBlock.WATERLOGGED, false));
        structure.fillWithBlocks(world, start, 10, 8, 12, 10, 9, 12, Blocks.SMOOTH_STONE.getDefaultState());
        structure.fillWithBlocks(world, start, 10, 9, 7, 10, 10, 7, Blocks.COBBLESTONE.getDefaultState());
        structure.fillWithBlocks(world, start, 10, 11, 11, 10, 11, 11, Blocks.COBBLESTONE.getDefaultState());
        structure.fillWithBlocks(world, start, 10, 12, 6, 10, 13, 6, Blocks.CHAIN.getDefaultState().with(ChainBlock.WATERLOGGED, false));
        structure.fillWithBlocks(world, start, 10, 13, 11, 10, 14, 11, Blocks.COBBLESTONE.getDefaultState());
        structure.fillWithBlocks(world, start, 10, 14, 6, 10, 16, 6, Blocks.COBBLESTONE.getDefaultState());
        structure.fillWithBlocks(world, start, 10, 15, 10, 10, 15, 10, Blocks.OAK_SLAB.getDefaultState().with(SlabBlock.TYPE, SlabType.TOP).with(SlabBlock.WATERLOGGED, false));
        structure.fillWithBlocks(world, start, 10, 15, 12, 10, 17, 12, Blocks.COBBLESTONE.getDefaultState());
        structure.fillWithBlocks(world, start, 10, 17, 13, 10, 20, 13, Blocks.CHAIN.getDefaultState().with(ChainBlock.WATERLOGGED, false));
        structure.fillWithBlocks(world, start, 10, 18, 7, 10, 18, 7, Blocks.OAK_SLAB.getDefaultState().with(SlabBlock.TYPE, SlabType.BOTTOM).with(SlabBlock.WATERLOGGED, false));
        structure.fillWithBlocks(world, start, 10, 19, 6, 10, 20, 6, Blocks.COBBLESTONE.getDefaultState());
        structure.fillWithBlocks(world, start, 10, 19, 12, 11, 19, 12, Blocks.COBBLESTONE.getDefaultState());
        structure.fillWithBlocks(world, start, 10, 21, 8, 10, 21, 9, Blocks.SPRUCE_SLAB.getDefaultState().with(SlabBlock.TYPE, SlabType.TOP).with(SlabBlock.WATERLOGGED, false));
        structure.fillWithBlocks(world, start, 10, 21, 10, 10, 21, 11, Blocks.OAK_SLAB.getDefaultState().with(SlabBlock.TYPE, SlabType.TOP).with(SlabBlock.WATERLOGGED, false));
        structure.fillWithBlocks(world, start, 10, 21, 13, 11, 21, 13, Blocks.COBBLESTONE.getDefaultState());
        structure.fillWithBlocks(world, start, 10, 22, 7, 10, 23, 7, Blocks.COBBLESTONE.getDefaultState());
        structure.fillWithBlocks(world, start, 10, 22, 13, 11, 22, 13, Blocks.OAK_SLAB.getDefaultState().with(SlabBlock.TYPE, SlabType.BOTTOM).with(SlabBlock.WATERLOGGED, false));
        structure.fillWithBlocks(world, start, 10, 22, 14, 11, 22, 14, Blocks.STONE.getDefaultState());
        structure.fillWithBlocks(world, start, 10, 23, 14, 10, 24, 14, Blocks.COBBLESTONE.getDefaultState());
        structure.fillWithBlocks(world, start, 10, 25, 10, 10, 25, 10, Blocks.OAK_SLAB.getDefaultState().with(SlabBlock.TYPE, SlabType.BOTTOM).with(SlabBlock.WATERLOGGED, false));
        structure.fillWithBlocks(world, start, 10, 25, 11, 10, 25, 12, Blocks.SPRUCE_SLAB.getDefaultState().with(SlabBlock.TYPE, SlabType.BOTTOM).with(SlabBlock.WATERLOGGED, false));
        structure.fillWithBlocks(world, start, 10, 25, 13, 10, 25, 14, Blocks.OAK_SLAB.getDefaultState().with(SlabBlock.TYPE, SlabType.BOTTOM).with(SlabBlock.WATERLOGGED, false));
        structure.fillWithBlocks(world, start, 10, 25, 15, 10, 26, 15, Blocks.OAK_PLANKS.getDefaultState());
        structure.fillWithBlocks(world, start, 10, 26, 7, 11, 26, 7, Blocks.OAK_PLANKS.getDefaultState());
        structure.fillWithBlocks(world, start, 10, 28, 7, 10, 28, 9, Blocks.OAK_PLANKS.getDefaultState());
        structure.fillWithBlocks(world, start, 10, 30, 9, 10, 30, 9, Blocks.OAK_PLANKS.getDefaultState());
        structure.fillWithBlocks(world, start, 10, 31, 10, 10, 32, 10, Blocks.OAK_PLANKS.getDefaultState());
        structure.fillWithBlocks(world, start, 11, 5, 4, 12, 5, 5, Blocks.GRASS_BLOCK.getDefaultState().with(SnowyDirtBlock.SNOWY, false));
        structure.fillWithBlocks(world, start, 11, 5, 8, 12, 5, 9, Blocks.OAK_PLANKS.getDefaultState());
        structure.fillWithBlocks(world, start, 11, 5, 10, 11, 5, 10, Blocks.SPRUCE_PLANKS.getDefaultState());
        structure.fillWithBlocks(world, start, 11, 5, 13, 11, 5, 13, Blocks.GRASS_BLOCK.getDefaultState().with(SnowyDirtBlock.SNOWY, false));
        structure.fillWithBlocks(world, start, 11, 5, 14, 11, 5, 16, Blocks.WATER.getDefaultState());
        structure.fillWithBlocks(world, start, 11, 6, 11, 12, 6, 11, Blocks.BARREL.getDefaultState().with(BarrelBlock.PROPERTY_FACING, Direction.WEST).with(BarrelBlock.PROPERTY_OPEN, false));
        structure.fillWithBlocks(world, start, 11, 6, 12, 11, 7, 12, Blocks.STONE.getDefaultState());
        structure.fillWithBlocks(world, start, 11, 8, 6, 11, 9, 6, Blocks.SMOOTH_STONE.getDefaultState());
        structure.fillWithBlocks(world, start, 11, 9, 12, 13, 9, 12, Blocks.COBBLESTONE.getDefaultState());
        structure.fillWithBlocks(world, start, 11, 10, 12, 11, 11, 12, Blocks.COBBLESTONE.getDefaultState());
        structure.fillWithBlocks(world, start, 11, 11, 10, 11, 11, 10, Blocks.OAK_SLAB.getDefaultState().with(SlabBlock.TYPE, SlabType.TOP).with(SlabBlock.WATERLOGGED, false));
        structure.fillWithBlocks(world, start, 11, 12, 7, 11, 13, 7, Blocks.COBBLESTONE.getDefaultState());
        structure.fillWithBlocks(world, start, 11, 12, 12, 12, 12, 12, Blocks.SMOOTH_STONE.getDefaultState());
        structure.fillWithBlocks(world, start, 11, 13, 6, 11, 13, 7, Blocks.COBBLESTONE.getDefaultState());
        structure.fillWithBlocks(world, start, 11, 14, 7, 12, 14, 7, Blocks.OAK_SLAB.getDefaultState().with(SlabBlock.TYPE, SlabType.BOTTOM).with(SlabBlock.WATERLOGGED, false));
        structure.fillWithBlocks(world, start, 11, 15, 6, 12, 15, 6, Blocks.COBBLESTONE.getDefaultState());
        structure.fillWithBlocks(world, start, 11, 16, 12, 11, 17, 12, Blocks.COBBLESTONE.getDefaultState());
        structure.fillWithBlocks(world, start, 11, 18, 7, 11, 18, 9, Blocks.OAK_SLAB.getDefaultState().with(SlabBlock.TYPE, SlabType.BOTTOM).with(SlabBlock.WATERLOGGED, false));
        structure.fillWithBlocks(world, start, 11, 19, 7, 12, 19, 7, Blocks.COBBLESTONE.getDefaultState());
        structure.fillWithBlocks(world, start, 11, 20, 7, 12, 20, 7, Blocks.ANDESITE.getDefaultState());
        structure.fillWithBlocks(world, start, 11, 21, 9, 11, 21, 10, Blocks.OAK_SLAB.getDefaultState().with(SlabBlock.TYPE, SlabType.TOP).with(SlabBlock.WATERLOGGED, false));
        structure.fillWithBlocks(world, start, 11, 21, 11, 12, 21, 11, Blocks.SPRUCE_SLAB.getDefaultState().with(SlabBlock.TYPE, SlabType.TOP).with(SlabBlock.WATERLOGGED, false));
        structure.fillWithBlocks(world, start, 11, 21, 12, 12, 21, 12, Blocks.OAK_SLAB.getDefaultState().with(SlabBlock.TYPE, SlabType.TOP).with(SlabBlock.WATERLOGGED, false));
        structure.fillWithBlocks(world, start, 11, 22, 8, 12, 22, 8, Blocks.COBBLESTONE.getDefaultState());
        structure.fillWithBlocks(world, start, 11, 23, 8, 11, 24, 8, Blocks.COBBLESTONE.getDefaultState());
        structure.fillWithBlocks(world, start, 11, 24, 6, 11, 25, 6, Blocks.OAK_PLANKS.getDefaultState());
        structure.fillWithBlocks(world, start, 11, 24, 14, 12, 24, 14, Blocks.COBBLESTONE.getDefaultState());
        structure.fillWithBlocks(world, start, 11, 25, 8, 11, 25, 8, Blocks.OAK_SLAB.getDefaultState().with(SlabBlock.TYPE, SlabType.BOTTOM).with(SlabBlock.WATERLOGGED, false));
        structure.fillWithBlocks(world, start, 11, 25, 11, 11, 25, 12, Blocks.OAK_SLAB.getDefaultState().with(SlabBlock.TYPE, SlabType.BOTTOM).with(SlabBlock.WATERLOGGED, false));
        structure.fillWithBlocks(world, start, 11, 25, 13, 11, 25, 14, Blocks.SPRUCE_SLAB.getDefaultState().with(SlabBlock.TYPE, SlabType.BOTTOM).with(SlabBlock.WATERLOGGED, false));
        structure.fillWithBlocks(world, start, 11, 27, 7, 11, 27, 7, Blocks.OAK_PLANKS.getDefaultState());
        structure.fillWithBlocks(world, start, 11, 28, 8, 11, 29, 8, Blocks.SPRUCE_PLANKS.getDefaultState());
        structure.fillWithBlocks(world, start, 11, 28, 11, 11, 28, 12, Blocks.OAK_PLANKS.getDefaultState());
        structure.fillWithBlocks(world, start, 11, 29, 9, 12, 29, 9, Blocks.OAK_PLANKS.getDefaultState());
        structure.fillWithBlocks(world, start, 11, 30, 9, 11, 30, 10, Blocks.OAK_PLANKS.getDefaultState());
        structure.fillWithBlocks(world, start, 12, 5, 7, 12, 5, 9, Blocks.OAK_PLANKS.getDefaultState());
        structure.fillWithBlocks(world, start, 12, 5, 10, 12, 5, 11, Blocks.SPRUCE_PLANKS.getDefaultState());
        structure.fillWithBlocks(world, start, 12, 5, 13, 13, 5, 14, Blocks.GRASS_BLOCK.getDefaultState().with(SnowyDirtBlock.SNOWY, false));
        structure.fillWithBlocks(world, start, 12, 5, 15, 12, 5, 16, Blocks.WATER.getDefaultState());
        structure.fillWithBlocks(world, start, 12, 6, 12, 12, 7, 12, Blocks.COBBLESTONE.getDefaultState());
        structure.fillWithBlocks(world, start, 12, 6, 13, 12, 6, 13, Blocks.GRASS.getDefaultState());
        structure.fillWithBlocks(world, start, 12, 6, 16, 13, 6, 16, Blocks.SPRUCE_SLAB.getDefaultState().with(SlabBlock.TYPE, SlabType.BOTTOM).with(SlabBlock.WATERLOGGED, false));
        structure.fillWithBlocks(world, start, 12, 7, 6, 12, 8, 6, Blocks.COBBLESTONE.getDefaultState());
        structure.fillWithBlocks(world, start, 12, 9, 7, 12, 9, 8, Blocks.OAK_SLAB.getDefaultState().with(SlabBlock.TYPE, SlabType.TOP).with(SlabBlock.WATERLOGGED, false));
        structure.fillWithBlocks(world, start, 12, 10, 6, 14, 10, 6, Blocks.COBBLESTONE.getDefaultState());
        structure.fillWithBlocks(world, start, 12, 10, 12, 13, 10, 12, Blocks.STONE.getDefaultState());
        structure.fillWithBlocks(world, start, 12, 13, 6, 12, 13, 6, Blocks.COBBLESTONE.getDefaultState());
        structure.fillWithBlocks(world, start, 12, 14, 9, 13, 14, 9, Blocks.OAK_SLAB.getDefaultState().with(SlabBlock.TYPE, SlabType.TOP).with(SlabBlock.WATERLOGGED, false));
        structure.fillWithBlocks(world, start, 12, 17, 7, 12, 19, 7, Blocks.COBBLESTONE.getDefaultState());
        structure.fillWithBlocks(world, start, 12, 19, 9, 12, 21, 9, Blocks.LADDER.getDefaultState().with(LadderBlock.FACING, Direction.WEST).with(LadderBlock.WATERLOGGED, false));
        structure.fillWithBlocks(world, start, 12, 21, 8, 12, 22, 8, Blocks.COBBLESTONE.getDefaultState());
        structure.fillWithBlocks(world, start, 12, 22, 11, 12, 24, 11, Blocks.LADDER.getDefaultState().with(LadderBlock.FACING, Direction.WEST).with(LadderBlock.WATERLOGGED, false));
        structure.fillWithBlocks(world, start, 12, 22, 14, 12, 24, 14, Blocks.COBBLESTONE.getDefaultState());
        structure.fillWithBlocks(world, start, 12, 24, 13, 12, 24, 14, Blocks.COBBLESTONE.getDefaultState());
        structure.fillWithBlocks(world, start, 12, 25, 7, 13, 25, 7, Blocks.SPRUCE_PLANKS.getDefaultState());
        structure.fillWithBlocks(world, start, 12, 25, 9, 12, 25, 10, Blocks.OAK_SLAB.getDefaultState().with(SlabBlock.TYPE, SlabType.BOTTOM).with(SlabBlock.WATERLOGGED, false));
        structure.fillWithBlocks(world, start, 12, 27, 8, 12, 27, 9, Blocks.OAK_PLANKS.getDefaultState());
        structure.fillWithBlocks(world, start, 12, 28, 9, 12, 28, 11, Blocks.SPRUCE_PLANKS.getDefaultState());
        structure.fillWithBlocks(world, start, 13, 0, 1, 14, 0, 1, Blocks.GRASS_BLOCK.getDefaultState().with(SnowyDirtBlock.SNOWY, false));
        structure.fillWithBlocks(world, start, 13, 0, 2, 14, 0, 3, Blocks.DIRT.getDefaultState());
        structure.fillWithBlocks(world, start, 13, 0, 5, 14, 0, 6, Blocks.DIRT.getDefaultState());
        structure.fillWithBlocks(world, start, 13, 0, 16, 14, 0, 17, Blocks.DIRT.getDefaultState());
        structure.fillWithBlocks(world, start, 13, 0, 19, 14, 0, 20, Blocks.DIRT.getDefaultState());
        structure.fillWithBlocks(world, start, 13, 0, 21, 14, 0, 21, Blocks.GRASS_BLOCK.getDefaultState().with(SnowyDirtBlock.SNOWY, false));
        structure.fillWithBlocks(world, start, 13, 3, 3, 14, 3, 3, Blocks.GRASS_BLOCK.getDefaultState().with(SnowyDirtBlock.SNOWY, false));
        structure.fillWithBlocks(world, start, 13, 3, 19, 14, 3, 19, Blocks.GRASS_BLOCK.getDefaultState().with(SnowyDirtBlock.SNOWY, false));
        structure.fillWithBlocks(world, start, 13, 5, 4, 13, 5, 6, Blocks.GRASS_BLOCK.getDefaultState().with(SnowyDirtBlock.SNOWY, false));
        structure.fillWithBlocks(world, start, 13, 5, 7, 13, 5, 7, Blocks.DIRT.getDefaultState());
        structure.fillWithBlocks(world, start, 13, 5, 8, 13, 5, 9, Blocks.SPRUCE_PLANKS.getDefaultState());
        structure.fillWithBlocks(world, start, 13, 5, 12, 16, 5, 15, Blocks.GRASS_BLOCK.getDefaultState().with(SnowyDirtBlock.SNOWY, false));
        structure.fillWithBlocks(world, start, 13, 6, 7, 13, 8, 7, Blocks.COBBLESTONE.getDefaultState());
        structure.fillWithBlocks(world, start, 13, 6, 11, 13, 7, 11, Blocks.COBBLESTONE.getDefaultState());
        structure.fillWithBlocks(world, start, 13, 6, 14, 13, 6, 14, Blocks.GRASS.getDefaultState());
        structure.fillWithBlocks(world, start, 13, 8, 11, 14, 8, 11, Blocks.STONE.getDefaultState());
        structure.fillWithBlocks(world, start, 13, 9, 6, 13, 9, 6, Blocks.COBBLESTONE.getDefaultState());
        structure.fillWithBlocks(world, start, 13, 9, 11, 13, 9, 12, Blocks.COBBLESTONE.getDefaultState());
        structure.fillWithBlocks(world, start, 13, 10, 11, 14, 10, 11, Blocks.COBBLESTONE.getDefaultState());
        structure.fillWithBlocks(world, start, 13, 12, 6, 13, 13, 6, Blocks.COBBLESTONE.getDefaultState());
        structure.fillWithBlocks(world, start, 13, 12, 11, 14, 12, 11, Blocks.STONE.getDefaultState());
        structure.fillWithBlocks(world, start, 13, 13, 7, 13, 13, 7, Blocks.COBBLESTONE.getDefaultState());
        structure.fillWithBlocks(world, start, 13, 13, 11, 14, 13, 11, Blocks.COBBLESTONE.getDefaultState());
        structure.fillWithBlocks(world, start, 13, 14, 7, 13, 14, 7, Blocks.COBBLESTONE.getDefaultState());
        structure.fillWithBlocks(world, start, 13, 16, 7, 13, 16, 8, Blocks.COBBLESTONE.getDefaultState());
        structure.fillWithBlocks(world, start, 13, 16, 10, 13, 17, 10, Blocks.SMOOTH_STONE.getDefaultState());
        structure.fillWithBlocks(world, start, 13, 17, 8, 13, 17, 9, Blocks.COBBLESTONE.getDefaultState());
        structure.fillWithBlocks(world, start, 13, 18, 9, 13, 19, 9, Blocks.STONE.getDefaultState());
        structure.fillWithBlocks(world, start, 13, 18, 10, 13, 20, 10, Blocks.COBBLESTONE.getDefaultState());
        structure.fillWithBlocks(world, start, 13, 19, 8, 13, 19, 9, Blocks.STONE.getDefaultState());
        structure.fillWithBlocks(world, start, 13, 20, 8, 13, 21, 8, Blocks.SMOOTH_STONE.getDefaultState());
        structure.fillWithBlocks(world, start, 13, 20, 9, 13, 20, 10, Blocks.COBBLESTONE.getDefaultState());
        structure.fillWithBlocks(world, start, 13, 20, 11, 13, 21, 11, Blocks.SMOOTH_STONE.getDefaultState());
        structure.fillWithBlocks(world, start, 13, 21, 9, 13, 22, 9, Blocks.COBBLESTONE.getDefaultState());
        structure.fillWithBlocks(world, start, 13, 21, 12, 13, 22, 12, Blocks.COBBLESTONE.getDefaultState());
        structure.fillWithBlocks(world, start, 13, 22, 10, 13, 22, 11, Blocks.STONE.getDefaultState());
        structure.fillWithBlocks(world, start, 13, 22, 13, 13, 23, 13, Blocks.COBBLESTONE.getDefaultState());
        structure.fillWithBlocks(world, start, 13, 23, 11, 13, 24, 11, Blocks.COBBLESTONE.getDefaultState());
        structure.fillWithBlocks(world, start, 13, 24, 9, 13, 24, 12, Blocks.COBBLESTONE.getDefaultState());
        structure.fillWithBlocks(world, start, 13, 24, 14, 13, 25, 14, Blocks.OAK_PLANKS.getDefaultState());
        structure.fillWithBlocks(world, start, 13, 25, 8, 13, 26, 8, Blocks.OAK_PLANKS.getDefaultState());
        structure.fillWithBlocks(world, start, 13, 25, 9, 13, 25, 10, Blocks.BARREL.getDefaultState().with(BarrelBlock.PROPERTY_FACING, Direction.WEST).with(BarrelBlock.PROPERTY_OPEN, false));
        structure.fillWithBlocks(world, start, 13, 25, 11, 13, 27, 11, Blocks.OAK_PLANKS.getDefaultState());
        structure.fillWithBlocks(world, start, 13, 25, 12, 13, 25, 13, Blocks.SPRUCE_PLANKS.getDefaultState());
        structure.fillWithBlocks(world, start, 13, 26, 10, 13, 26, 12, Blocks.OAK_PLANKS.getDefaultState());
        structure.fillWithBlocks(world, start, 14, 0, 4, 14, 3, 14, Blocks.DIRT.getDefaultState());
        structure.fillWithBlocks(world, start, 14, 0, 18, 15, 0, 20, Blocks.DIRT.getDefaultState());
        structure.fillWithBlocks(world, start, 14, 1, 2, 15, 1, 2, Blocks.GRASS_BLOCK.getDefaultState().with(SnowyDirtBlock.SNOWY, false));
        structure.fillWithBlocks(world, start, 14, 1, 3, 15, 1, 11, Blocks.DIRT.getDefaultState());
        structure.fillWithBlocks(world, start, 14, 1, 15, 17, 1, 18, Blocks.DIRT.getDefaultState());
        structure.fillWithBlocks(world, start, 14, 1, 19, 15, 1, 19, Blocks.DIRT.getDefaultState());
        structure.fillWithBlocks(world, start, 14, 1, 20, 15, 1, 20, Blocks.GRASS_BLOCK.getDefaultState().with(SnowyDirtBlock.SNOWY, false));
        structure.fillWithBlocks(world, start, 14, 4, 4, 15, 4, 4, Blocks.GRASS_BLOCK.getDefaultState().with(SnowyDirtBlock.SNOWY, false));
        structure.fillWithBlocks(world, start, 14, 4, 18, 15, 4, 18, Blocks.GRASS_BLOCK.getDefaultState().with(SnowyDirtBlock.SNOWY, false));
        structure.fillWithBlocks(world, start, 14, 5, 5, 15, 5, 7, Blocks.GRASS_BLOCK.getDefaultState().with(SnowyDirtBlock.SNOWY, false));
        structure.fillWithBlocks(world, start, 14, 5, 11, 14, 5, 17, Blocks.GRASS_BLOCK.getDefaultState().with(SnowyDirtBlock.SNOWY, false));
        structure.fillWithBlocks(world, start, 14, 6, 8, 14, 8, 8, Blocks.COBBLESTONE.getDefaultState());
        structure.fillWithBlocks(world, start, 14, 6, 10, 14, 7, 10, Blocks.STONE.getDefaultState());
        structure.fillWithBlocks(world, start, 14, 6, 13, 14, 6, 15, Blocks.GRASS.getDefaultState());
        structure.fillWithBlocks(world, start, 14, 8, 9, 14, 8, 10, Blocks.COBBLESTONE.getDefaultState());
        structure.fillWithBlocks(world, start, 14, 9, 6, 14, 9, 7, Blocks.COBBLESTONE.getDefaultState());
        structure.fillWithBlocks(world, start, 14, 9, 11, 14, 10, 11, Blocks.COBBLESTONE.getDefaultState());
        structure.fillWithBlocks(world, start, 14, 10, 10, 14, 10, 11, Blocks.COBBLESTONE.getDefaultState());
        structure.fillWithBlocks(world, start, 14, 11, 10, 14, 12, 10, Blocks.COBBLESTONE.getDefaultState());
        structure.fillWithBlocks(world, start, 14, 12, 7, 14, 13, 7, Blocks.COBBLESTONE.getDefaultState());
        structure.fillWithBlocks(world, start, 14, 13, 8, 14, 14, 8, Blocks.COBBLESTONE.getDefaultState());
        structure.fillWithBlocks(world, start, 14, 14, 9, 14, 15, 9, Blocks.SMOOTH_STONE.getDefaultState());
        structure.fillWithBlocks(world, start, 14, 14, 10, 14, 15, 10, Blocks.COBBLESTONE.getDefaultState());
        structure.fillWithBlocks(world, start, 14, 24, 11, 14, 25, 11, Blocks.SPRUCE_PLANKS.getDefaultState());
        structure.fillWithBlocks(world, start, 14, 24, 12, 14, 24, 13, Blocks.OAK_PLANKS.getDefaultState());
        structure.fillWithBlocks(world, start, 14, 25, 9, 14, 25, 11, Blocks.SPRUCE_PLANKS.getDefaultState());
        structure.fillWithBlocks(world, start, 15, 0, 2, 15, 0, 4, Blocks.DIRT.getDefaultState());
        structure.fillWithBlocks(world, start, 15, 0, 6, 17, 0, 8, Blocks.DIRT.getDefaultState());
        structure.fillWithBlocks(world, start, 15, 0, 9, 15, 0, 14, Blocks.STONE.getDefaultState());
        structure.fillWithBlocks(world, start, 15, 0, 15, 16, 0, 16, Blocks.DIRT.getDefaultState());
        structure.fillWithBlocks(world, start, 15, 1, 12, 15, 1, 13, Blocks.STONE.getDefaultState());
        structure.fillWithBlocks(world, start, 15, 1, 14, 18, 1, 17, Blocks.DIRT.getDefaultState());
        structure.fillWithBlocks(world, start, 15, 5, 8, 17, 5, 10, Blocks.GRASS_BLOCK.getDefaultState().with(SnowyDirtBlock.SNOWY, false));
        structure.fillWithBlocks(world, start, 15, 5, 16, 15, 5, 17, Blocks.GRASS_BLOCK.getDefaultState().with(SnowyDirtBlock.SNOWY, false));
        structure.fillWithBlocks(world, start, 15, 6, 15, 15, 6, 16, Blocks.GRASS.getDefaultState());
        structure.fillWithBlocks(world, start, 15, 9, 8, 15, 9, 9, Blocks.COBBLESTONE.getDefaultState());
        structure.fillWithBlocks(world, start, 15, 9, 10, 15, 10, 10, Blocks.ANDESITE.getDefaultState());
        structure.fillWithBlocks(world, start, 15, 10, 7, 15, 10, 8, Blocks.STONE.getDefaultState());
        structure.fillWithBlocks(world, start, 15, 10, 9, 15, 11, 9, Blocks.SMOOTH_STONE.getDefaultState());
        structure.fillWithBlocks(world, start, 15, 12, 9, 15, 12, 10, Blocks.COBBLESTONE.getDefaultState());
        structure.fillWithBlocks(world, start, 15, 13, 9, 15, 14, 9, Blocks.STONE.getDefaultState());
        structure.fillWithBlocks(world, start, 15, 24, 9, 15, 24, 10, Blocks.OAK_PLANKS.getDefaultState());
        structure.fillWithBlocks(world, start, 16, 0, 3, 17, 0, 14, Blocks.DIRT.getDefaultState());
        structure.fillWithBlocks(world, start, 16, 0, 17, 17, 0, 19, Blocks.DIRT.getDefaultState());
        structure.fillWithBlocks(world, start, 16, 1, 3, 17, 1, 3, Blocks.GRASS_BLOCK.getDefaultState().with(SnowyDirtBlock.SNOWY, false));
        structure.fillWithBlocks(world, start, 16, 1, 4, 17, 1, 18, Blocks.DIRT.getDefaultState());
        structure.fillWithBlocks(world, start, 16, 1, 19, 17, 1, 19, Blocks.GRASS_BLOCK.getDefaultState().with(SnowyDirtBlock.SNOWY, false));
        structure.fillWithBlocks(world, start, 16, 3, 4, 16, 3, 4, Blocks.GRASS_BLOCK.getDefaultState().with(SnowyDirtBlock.SNOWY, false));
        structure.fillWithBlocks(world, start, 16, 4, 5, 16, 4, 5, Blocks.GRASS_BLOCK.getDefaultState().with(SnowyDirtBlock.SNOWY, false));
        structure.fillWithBlocks(world, start, 16, 5, 6, 16, 5, 16, Blocks.GRASS_BLOCK.getDefaultState().with(SnowyDirtBlock.SNOWY, false));
        structure.fillWithBlocks(world, start, 16, 6, 12, 17, 6, 12, Blocks.GRASS.getDefaultState());
        structure.fillWithBlocks(world, start, 16, 6, 14, 16, 6, 14, Blocks.GRASS.getDefaultState());
        structure.fillWithBlocks(world, start, 16, 22, 9, 16, 23, 9, Blocks.CHAIN.getDefaultState().with(ChainBlock.WATERLOGGED, false));
        structure.fillWithBlocks(world, start, 17, 0, 16, 18, 0, 18, Blocks.DIRT.getDefaultState());
        structure.fillWithBlocks(world, start, 17, 2, 4, 17, 2, 4, Blocks.GRASS_BLOCK.getDefaultState().with(SnowyDirtBlock.SNOWY, false));
        structure.fillWithBlocks(world, start, 17, 3, 5, 17, 3, 5, Blocks.GRASS_BLOCK.getDefaultState().with(SnowyDirtBlock.SNOWY, false));
