package mod.arcalitegames.odyssey.world.structure.structures.towers.tower_fountain;

import mod.arcalitegames.odyssey.world.structure.StructureBase;
import net.minecraft.block.Blocks;
import net.minecraft.block.FourWayBlock;
import net.minecraft.block.SlabBlock;
import net.minecraft.block.SnowyDirtBlock;
import net.minecraft.block.StairsBlock;
import net.minecraft.block.WallTorchBlock;
import net.minecraft.state.properties.Half;
import net.minecraft.state.properties.SlabType;
import net.minecraft.state.properties.StairsShape;
import net.minecraft.util.Direction;
import net.minecraft.util.math.BlockPos;
import net.minecraft.world.World;

public class FountainComponents
{

	public static BlockPos start;
    public static World world;
    public static StructureBase structure;

    public static void init(World worldIn, BlockPos blockPos, StructureBase structureIn)
    {
        world = worldIn; start = blockPos; structure = structureIn;
    }
    
    public static void generatePart1()
    {
        structure.setBlockState(world, Blocks.GRASS_BLOCK.getDefaultState().with(SnowyDirtBlock.SNOWY, false), 4, 0, 12, start);
        structure.setBlockState(world, Blocks.GRASS_BLOCK.getDefaultState().with(SnowyDirtBlock.SNOWY, false), 5, 1, 12, start);
        structure.setBlockState(world, Blocks.STONE.getDefaultState(), 5, 1, 23, start);
        structure.setBlockState(world, Blocks.GRASS_BLOCK.getDefaultState().with(SnowyDirtBlock.SNOWY, false), 5, 1, 34, start);
        structure.setBlockState(world, Blocks.GRASS_BLOCK.getDefaultState().with(SnowyDirtBlock.SNOWY, false), 5, 2, 13, start);
        structure.setBlockState(world, Blocks.GRASS_BLOCK.getDefaultState().with(SnowyDirtBlock.SNOWY, false), 6, 0, 9, start);
        structure.setBlockState(world, Blocks.GRASS_BLOCK.getDefaultState().with(SnowyDirtBlock.SNOWY, false), 6, 1, 10, start);
        structure.setBlockState(world, Blocks.GRASS_BLOCK.getDefaultState().with(SnowyDirtBlock.SNOWY, false), 6, 3, 13, start);
        structure.setBlockState(world, Blocks.GRASS_BLOCK.getDefaultState().with(SnowyDirtBlock.SNOWY, false), 6, 3, 33, start);
        structure.setBlockState(world, Blocks.GRASS_BLOCK.getDefaultState().with(SnowyDirtBlock.SNOWY, false), 7, 0, 8, start);
        structure.setBlockState(world, Blocks.GRASS_BLOCK.getDefaultState().with(SnowyDirtBlock.SNOWY, false), 7, 1, 9, start);
        structure.setBlockState(world, Blocks.GRASS_BLOCK.getDefaultState().with(SnowyDirtBlock.SNOWY, false), 7, 2, 10, start);
        structure.setBlockState(world, Blocks.GRASS_BLOCK.getDefaultState().with(SnowyDirtBlock.SNOWY, false), 7, 3, 11, start);
        structure.setBlockState(world, Blocks.GRASS_BLOCK.getDefaultState().with(SnowyDirtBlock.SNOWY, false), 8, 0, 7, start);
        structure.setBlockState(world, Blocks.GRASS_BLOCK.getDefaultState().with(SnowyDirtBlock.SNOWY, false), 8, 1, 8, start);
        structure.setBlockState(world, Blocks.GRASS_BLOCK.getDefaultState().with(SnowyDirtBlock.SNOWY, false), 8, 2, 9, start);
        structure.setBlockState(world, Blocks.GRASS_BLOCK.getDefaultState().with(SnowyDirtBlock.SNOWY, false), 8, 3, 10, start);
        structure.setBlockState(world, Blocks.GRASS_BLOCK.getDefaultState().with(SnowyDirtBlock.SNOWY, false), 9, 0, 6, start);
        structure.setBlockState(world, Blocks.GRASS_BLOCK.getDefaultState().with(SnowyDirtBlock.SNOWY, false), 9, 1, 7, start);
        structure.setBlockState(world, Blocks.GRASS_BLOCK.getDefaultState().with(SnowyDirtBlock.SNOWY, false), 9, 2, 8, start);
        structure.setBlockState(world, Blocks.GRASS_BLOCK.getDefaultState().with(SnowyDirtBlock.SNOWY, false), 9, 3, 9, start);
        structure.setBlockState(world, Blocks.GRASS_BLOCK.getDefaultState().with(SnowyDirtBlock.SNOWY, false), 9, 4, 10, start);
        structure.setBlockState(world, Blocks.GRASS_BLOCK.getDefaultState().with(SnowyDirtBlock.SNOWY, false), 9, 5, 13, start);
        structure.setBlockState(world, Blocks.GRASS_BLOCK.getDefaultState().with(SnowyDirtBlock.SNOWY, false), 10, 1, 6, start);
        structure.setBlockState(world, Blocks.GRASS_BLOCK.getDefaultState().with(SnowyDirtBlock.SNOWY, false), 10, 1, 40, start);
        structure.setBlockState(world, Blocks.GRASS_BLOCK.getDefaultState().with(SnowyDirtBlock.SNOWY, false), 10, 2, 7, start);
        structure.setBlockState(world, Blocks.GRASS_BLOCK.getDefaultState().with(SnowyDirtBlock.SNOWY, false), 10, 3, 8, start);
        structure.setBlockState(world, Blocks.GRASS_BLOCK.getDefaultState().with(SnowyDirtBlock.SNOWY, false), 10, 4, 9, start);
        structure.setBlockState(world, Blocks.STONE.getDefaultState(), 11, 2, 18, start);
        structure.setBlockState(world, Blocks.GRASS_BLOCK.getDefaultState().with(SnowyDirtBlock.SNOWY, false), 11, 3, 7, start);
        structure.setBlockState(world, Blocks.GRASS_BLOCK.getDefaultState().with(SnowyDirtBlock.SNOWY, false), 11, 3, 39, start);
        structure.setBlockState(world, Blocks.GRASS.getDefaultState(), 11, 7, 20, start);
        structure.setBlockState(world, Blocks.DANDELION.getDefaultState(), 11, 7, 22, start);
        structure.setBlockState(world, Blocks.GRASS.getDefaultState(), 11, 7, 30, start);
        structure.setBlockState(world, Blocks.GRASS_BLOCK.getDefaultState().with(SnowyDirtBlock.SNOWY, false), 12, 0, 4, start);
        structure.setBlockState(world, Blocks.GRASS_BLOCK.getDefaultState().with(SnowyDirtBlock.SNOWY, false), 12, 0, 42, start);
        structure.setBlockState(world, Blocks.GRASS_BLOCK.getDefaultState().with(SnowyDirtBlock.SNOWY, false), 12, 1, 5, start);
        structure.setBlockState(world, Blocks.AIR.getDefaultState(), 12, 7, 23, start);
        structure.setBlockState(world, Blocks.GRASS_BLOCK.getDefaultState().with(SnowyDirtBlock.SNOWY, false), 13, 2, 5, start);
        structure.setBlockState(world, Blocks.GRASS_BLOCK.getDefaultState().with(SnowyDirtBlock.SNOWY, false), 13, 2, 41, start);
        structure.setBlockState(world, Blocks.GRASS_BLOCK.getDefaultState().with(SnowyDirtBlock.SNOWY, false), 13, 3, 6, start);
        structure.setBlockState(world, Blocks.GRASS_BLOCK.getDefaultState().with(SnowyDirtBlock.SNOWY, false), 13, 4, 7, start);
        structure.setBlockState(world, Blocks.WATER.getDefaultState(), 13, 7, 13, start);
        structure.setBlockState(world, Blocks.WATER.getDefaultState(), 13, 7, 14, start);
        structure.setBlockState(world, Blocks.WATER.getDefaultState(), 13, 7, 15, start);
        structure.setBlockState(world, Blocks.WATER.getDefaultState(), 13, 7, 16, start);
        structure.setBlockState(world, Blocks.WATER.getDefaultState(), 13, 7, 17, start);
        structure.setBlockState(world, Blocks.WATER.getDefaultState(), 13, 7, 18, start);
        structure.setBlockState(world, Blocks.WATER.getDefaultState(), 13, 7, 19, start);
        structure.setBlockState(world, Blocks.WATER.getDefaultState(), 13, 7, 20, start);
        structure.setBlockState(world, Blocks.WATER.getDefaultState(), 13, 7, 26, start);
        structure.setBlockState(world, Blocks.WATER.getDefaultState(), 13, 7, 27, start);
        structure.setBlockState(world, Blocks.WATER.getDefaultState(), 13, 7, 28, start);
        structure.setBlockState(world, Blocks.WATER.getDefaultState(), 13, 7, 29, start);
        structure.setBlockState(world, Blocks.WATER.getDefaultState(), 13, 7, 30, start);
        structure.setBlockState(world, Blocks.WATER.getDefaultState(), 13, 7, 31, start);
        structure.setBlockState(world, Blocks.WATER.getDefaultState(), 13, 7, 34, start);
        structure.setBlockState(world, Blocks.WATER.getDefaultState(), 13, 8, 17, start);
        structure.setBlockState(world, Blocks.WATER.getDefaultState(), 13, 8, 29, start);
        structure.setBlockState(world, Blocks.WATER.getDefaultState(), 14, 7, 13, start);
        structure.setBlockState(world, Blocks.COBBLESTONE_SLAB.getDefaultState().with(SlabBlock.TYPE, SlabType.BOTTOM).with(SlabBlock.WATERLOGGED, false), 14, 7, 14, start);
        structure.setBlockState(world, Blocks.COBBLESTONE.getDefaultState(), 14, 7, 15, start);
        structure.setBlockState(world, Blocks.COBBLESTONE_SLAB.getDefaultState().with(SlabBlock.TYPE, SlabType.DOUBLE).with(SlabBlock.WATERLOGGED, false), 14, 7, 32, start);
        structure.setBlockState(world, Blocks.WATER.getDefaultState(), 14, 7, 33, start);
        structure.setBlockState(world, Blocks.WATER.getDefaultState(), 14, 7, 34, start);
        structure.setBlockState(world, Blocks.COBBLESTONE_STAIRS.getDefaultState().with(StairsBlock.FACING, Direction.EAST).with(StairsBlock.WATERLOGGED, false).with(StairsBlock.SHAPE, StairsShape.STRAIGHT).with(StairsBlock.HALF, Half.BOTTOM), 14, 8, 16, start);
        structure.setBlockState(world, Blocks.WATER.getDefaultState(), 14, 8, 17, start);
        structure.setBlockState(world, Blocks.WATER.getDefaultState(), 14, 8, 29, start);
        structure.setBlockState(world, Blocks.COBBLESTONE_STAIRS.getDefaultState().with(StairsBlock.FACING, Direction.EAST).with(StairsBlock.WATERLOGGED, false).with(StairsBlock.SHAPE, StairsShape.STRAIGHT).with(StairsBlock.HALF, Half.BOTTOM), 14, 8, 30, start);
        structure.setBlockState(world, Blocks.WATER.getDefaultState(), 14, 9, 17, start);
        structure.setBlockState(world, Blocks.WATER.getDefaultState(), 14, 9, 29, start);
        structure.setBlockState(world, Blocks.DIRT.getDefaultState(), 15, 6, 25, start);
        structure.setBlockState(world, Blocks.WATER.getDefaultState(), 15, 7, 13, start);
        structure.setBlockState(world, Blocks.COBBLESTONE.getDefaultState(), 15, 7, 14, start);
        structure.setBlockState(world, Blocks.WATER.getDefaultState(), 15, 7, 33, start);
        structure.setBlockState(world, Blocks.GRASS.getDefaultState(), 15, 7, 35, start);
        structure.setBlockState(world, Blocks.COBBLESTONE_SLAB.getDefaultState().with(SlabBlock.TYPE, SlabType.BOTTOM).with(SlabBlock.WATERLOGGED, false), 15, 8, 15, start);
        structure.setBlockState(world, Blocks.COBBLESTONE_SLAB.getDefaultState().with(SlabBlock.TYPE, SlabType.DOUBLE).with(SlabBlock.WATERLOGGED, false), 15, 8, 31, start);
        structure.setBlockState(world, Blocks.COBBLESTONE_SLAB.getDefaultState().with(SlabBlock.TYPE, SlabType.BOTTOM).with(SlabBlock.WATERLOGGED, false), 15, 8, 32, start);
        structure.setBlockState(world, Blocks.WATER.getDefaultState(), 15, 9, 17, start);
        structure.setBlockState(world, Blocks.WATER.getDefaultState(), 15, 9, 29, start);
        structure.setBlockState(world, Blocks.DIRT.getDefaultState(), 16, 6, 18, start);
        structure.setBlockState(world, Blocks.WATER.getDefaultState(), 16, 7, 13, start);
        structure.setBlockState(world, Blocks.STONE.getDefaultState(), 16, 7, 18, start);
        structure.setBlockState(world, Blocks.WATER.getDefaultState(), 16, 7, 33, start);
        structure.setBlockState(world, Blocks.COBBLESTONE_STAIRS.getDefaultState().with(StairsBlock.FACING, Direction.SOUTH).with(StairsBlock.WATERLOGGED, false).with(StairsBlock.SHAPE, StairsShape.STRAIGHT).with(StairsBlock.HALF, Half.BOTTOM), 16, 8, 14, start);
        structure.setBlockState(world, Blocks.COBBLESTONE_STAIRS.getDefaultState().with(StairsBlock.FACING, Direction.NORTH).with(StairsBlock.WATERLOGGED, false).with(StairsBlock.SHAPE, StairsShape.STRAIGHT).with(StairsBlock.HALF, Half.BOTTOM), 16, 8, 32, start);
        structure.setBlockState(world, Blocks.COBBLESTONE_SLAB.getDefaultState().with(SlabBlock.TYPE, SlabType.BOTTOM).with(SlabBlock.WATERLOGGED, false), 16, 9, 16, start);
        structure.setBlockState(world, Blocks.WATER.getDefaultState(), 16, 9, 17, start);
        structure.setBlockState(world, Blocks.WATER.getDefaultState(), 16, 10, 17, start);
        structure.setBlockState(world, Blocks.AIR.getDefaultState(), 16, 11, 19, start);
        structure.setBlockState(world, Blocks.AIR.getDefaultState(), 16, 11, 27, start);
        structure.setBlockState(world, Blocks.DIRT.getDefaultState(), 17, 6, 30, start);
        structure.setBlockState(world, Blocks.WATER.getDefaultState(), 17, 7, 13, start);
        structure.setBlockState(world, Blocks.WATER.getDefaultState(), 17, 7, 33, start);
        structure.setBlockState(world, Blocks.WATER.getDefaultState(), 17, 8, 13, start);
        structure.setBlockState(world, Blocks.WATER.getDefaultState(), 17, 8, 14, start);
        structure.setBlockState(world, Blocks.COBBLESTONE.getDefaultState(), 17, 8, 16, start);
        structure.setBlockState(world, Blocks.WATER.getDefaultState(), 17, 8, 32, start);
        structure.setBlockState(world, Blocks.WATER.getDefaultState(), 17, 8, 33, start);
        structure.setBlockState(world, Blocks.WATER.getDefaultState(), 17, 9, 14, start);
        structure.setBlockState(world, Blocks.WATER.getDefaultState(), 17, 9, 15, start);
        structure.setBlockState(world, Blocks.WATER.getDefaultState(), 17, 9, 16, start);
        structure.setBlockState(world, Blocks.WATER.getDefaultState(), 17, 9, 30, start);
        structure.setBlockState(world, Blocks.WATER.getDefaultState(), 17, 9, 31, start);
        structure.setBlockState(world, Blocks.WATER.getDefaultState(), 17, 9, 32, start);
        structure.setBlockState(world, Blocks.WATER.getDefaultState(), 17, 10, 16, start);
        structure.setBlockState(world, Blocks.WATER.getDefaultState(), 17, 10, 17, start);
        structure.setBlockState(world, Blocks.WATER.getDefaultState(), 17, 10, 18, start);
        structure.setBlockState(world, Blocks.WATER.getDefaultState(), 17, 10, 19, start);
        structure.setBlockState(world, Blocks.WATER.getDefaultState(), 17, 10, 20, start);
        structure.setBlockState(world, Blocks.WATER.getDefaultState(), 17, 10, 27, start);
        structure.setBlockState(world, Blocks.WATER.getDefaultState(), 17, 10, 29, start);
        structure.setBlockState(world, Blocks.WATER.getDefaultState(), 17, 10, 30, start);
        structure.setBlockState(world, Blocks.CHISELED_STONE_BRICKS.getDefaultState(), 17, 16, 23, start);
        structure.setBlockState(world, Blocks.WATER.getDefaultState(), 18, 7, 13, start);
        structure.setBlockState(world, Blocks.WATER.getDefaultState(), 18, 7, 33, start);
        structure.setBlockState(world, Blocks.WATER.getDefaultState(), 18, 10, 17, start);
        structure.setBlockState(world, Blocks.WATER.getDefaultState(), 18, 10, 19, start);
        structure.setBlockState(world, Blocks.WATER.getDefaultState(), 18, 10, 20, start);
        structure.setBlockState(world, Blocks.WATER.getDefaultState(), 18, 10, 29, start);
        structure.setBlockState(world, Blocks.TORCH.getDefaultState(), 18, 12, 18, start);
        structure.setBlockState(world, Blocks.TORCH.getDefaultState(), 18, 12, 28, start);
        structure.setBlockState(world, Blocks.MOSSY_COBBLESTONE.getDefaultState(), 18, 15, 22, start);
        structure.setBlockState(world, Blocks.MOSSY_COBBLESTONE.getDefaultState(), 18, 18, 21, start);
        structure.setBlockState(world, Blocks.MOSSY_COBBLESTONE.getDefaultState(), 18, 18, 25, start);
        structure.setBlockState(world, Blocks.WATER.getDefaultState(), 19, 7, 13, start);
        structure.setBlockState(world, Blocks.WATER.getDefaultState(), 19, 7, 33, start);
        structure.setBlockState(world, Blocks.WATER.getDefaultState(), 19, 10, 17, start);
        structure.setBlockState(world, Blocks.WATER.getDefaultState(), 19, 10, 18, start);
        structure.setBlockState(world, Blocks.WATER.getDefaultState(), 19, 10, 19, start);
        structure.setBlockState(world, Blocks.WATER.getDefaultState(), 19, 10, 20, start);
        structure.setBlockState(world, Blocks.WATER.getDefaultState(), 19, 10, 29, start);
        structure.setBlockState(world, Blocks.AIR.getDefaultState(), 19, 11, 16, start);
        structure.setBlockState(world, Blocks.AIR.getDefaultState(), 19, 11, 30, start);
        structure.setBlockState(world, Blocks.MOSSY_COBBLESTONE.getDefaultState(), 19, 15, 20, start);
        structure.setBlockState(world, Blocks.WALL_TORCH.getDefaultState().with(WallTorchBlock.HORIZONTAL_FACING, Direction.EAST), 19, 16, 23, start);
        structure.setBlockState(world, Blocks.TORCH.getDefaultState(), 19, 17, 19, start);
        structure.setBlockState(world, Blocks.MOSSY_COBBLESTONE.getDefaultState(), 19, 17, 20, start);
        structure.setBlockState(world, Blocks.TORCH.getDefaultState(), 19, 17, 27, start);
        structure.setBlockState(world, Blocks.OAK_FENCE.getDefaultState().with(FourWayBlock.WATERLOGGED, false).with(FourWayBlock.NORTH, false).with(FourWayBlock.SOUTH, false).with(FourWayBlock.EAST, false).with(FourWayBlock.WEST, false), 19, 18, 20, start);
        structure.setBlockState(world, Blocks.COBBLESTONE_SLAB.getDefaultState().with(SlabBlock.TYPE, SlabType.BOTTOM).with(SlabBlock.WATERLOGGED, false), 19, 20, 19, start);
        structure.setBlockState(world, Blocks.COBBLESTONE_SLAB.getDefaultState().with(SlabBlock.TYPE, SlabType.BOTTOM).with(SlabBlock.WATERLOGGED, false), 19, 20, 27, start);
        structure.setBlockState(world, Blocks.GRASS.getDefaultState(), 20, 7, 11, start);
        structure.setBlockState(world, Blocks.WATER.getDefaultState(), 20, 7, 13, start);
        structure.setBlockState(world, Blocks.WATER.getDefaultState(), 20, 7, 33, start);
        structure.setBlockState(world, Blocks.WATER.getDefaultState(), 20, 10, 17, start);
        structure.setBlockState(world, Blocks.WATER.getDefaultState(), 20, 10, 18, start);
        structure.setBlockState(world, Blocks.WATER.getDefaultState(), 20, 10, 19, start);
        structure.setBlockState(world, Blocks.WATER.getDefaultState(), 20, 10, 20, start);
        structure.setBlockState(world, Blocks.WATER.getDefaultState(), 20, 10, 26, start);
        structure.setBlockState(world, Blocks.WATER.getDefaultState(), 20, 10, 27, start);
        structure.setBlockState(world, Blocks.WATER.getDefaultState(), 20, 10, 28, start);
        structure.setBlockState(world, Blocks.WATER.getDefaultState(), 20, 10, 29, start);
        structure.setBlockState(world, Blocks.MOSSY_COBBLESTONE.getDefaultState(), 20, 15, 19, start);
        structure.setBlockState(world, Blocks.MOSSY_COBBLESTONE.getDefaultState(), 20, 17, 19, start);
        structure.setBlockState(world, Blocks.OAK_FENCE.getDefaultState().with(FourWayBlock.WATERLOGGED, false).with(FourWayBlock.NORTH, false).with(FourWayBlock.SOUTH, false).with(FourWayBlock.EAST, false).with(FourWayBlock.WEST, false), 20, 18, 19, start);
        structure.setBlockState(world, Blocks.OAK_FENCE.getDefaultState().with(FourWayBlock.WATERLOGGED, false).with(FourWayBlock.NORTH, false).with(FourWayBlock.SOUTH, false).with(FourWayBlock.EAST, false).with(FourWayBlock.WEST, false), 20, 18, 27, start);
        structure.setBlockState(world, Blocks.COBBLESTONE_SLAB.getDefaultState().with(SlabBlock.TYPE, SlabType.DOUBLE).with(SlabBlock.WATERLOGGED, false), 20, 21, 21, start);
        structure.setBlockState(world, Blocks.COBBLESTONE_SLAB.getDefaultState().with(SlabBlock.TYPE, SlabType.BOTTOM).with(SlabBlock.WATERLOGGED, false), 20, 21, 22, start);
        structure.setBlockState(world, Blocks.COBBLESTONE_SLAB.getDefaultState().with(SlabBlock.TYPE, SlabType.BOTTOM).with(SlabBlock.WATERLOGGED, false), 20, 21, 24, start);
        structure.setBlockState(world, Blocks.COBBLESTONE.getDefaultState(), 20, 23, 26, start);
        structure.setBlockState(world, Blocks.STONE.getDefaultState(), 21, 2, 39, start);
        structure.setBlockState(world, Blocks.MOSSY_COBBLESTONE.getDefaultState(), 21, 8, 32, start);
        structure.setBlockState(world, Blocks.MOSSY_COBBLESTONE.getDefaultState(), 21, 11, 29, start);
        structure.setBlockState(world, Blocks.MOSSY_COBBLESTONE.getDefaultState(), 21, 18, 18, start);
        structure.setBlockState(world, Blocks.OAK_FENCE.getDefaultState().with(FourWayBlock.WATERLOGGED, false).with(FourWayBlock.NORTH, false).with(FourWayBlock.SOUTH, false).with(FourWayBlock.EAST, true).with(FourWayBlock.WEST, false), 21, 18, 23, start);
        structure.setBlockState(world, Blocks.MOSSY_COBBLESTONE.getDefaultState(), 21, 18, 28, start);
        structure.setBlockState(world, Blocks.COBBLESTONE_SLAB.getDefaultState().with(SlabBlock.TYPE, SlabType.DOUBLE).with(SlabBlock.WATERLOGGED, false), 21, 21, 20, start);
        structure.setBlockState(world, Blocks.COBBLESTONE_SLAB.getDefaultState().with(SlabBlock.TYPE, SlabType.DOUBLE).with(SlabBlock.WATERLOGGED, false), 21, 21, 26, start);
        structure.setBlockState(world, Blocks.COBBLESTONE_SLAB.getDefaultState().with(SlabBlock.TYPE, SlabType.BOTTOM).with(SlabBlock.WATERLOGGED, false), 21, 24, 25, start);
        structure.setBlockState(world, Blocks.STONE.getDefaultState(), 22, 9, 30, start);
        structure.setBlockState(world, Blocks.STONE.getDefaultState(), 22, 10, 29, start);
        structure.setBlockState(world, Blocks.STONE.getDefaultState(), 22, 11, 28, start);
        structure.setBlockState(world, Blocks.MOSSY_COBBLESTONE.getDefaultState(), 22, 12, 22, start);
        structure.setBlockState(world, Blocks.MOSSY_COBBLESTONE.getDefaultState(), 22, 15, 18, start);
        structure.setBlockState(world, Blocks.MOSSY_COBBLESTONE.getDefaultState(), 22, 15, 28, start);
        structure.setBlockState(world, Blocks.OAK_FENCE.getDefaultState().with(FourWayBlock.WATERLOGGED, false).with(FourWayBlock.NORTH, false).with(FourWayBlock.SOUTH, false).with(FourWayBlock.EAST, true).with(FourWayBlock.WEST, false), 22, 17, 23, start);
        structure.setBlockState(world, Blocks.OAK_FENCE.getDefaultState().with(FourWayBlock.WATERLOGGED, false).with(FourWayBlock.NORTH, false).with(FourWayBlock.SOUTH, false).with(FourWayBlock.EAST, true).with(FourWayBlock.WEST, true), 22, 18, 23, start);
        structure.setBlockState(world, Blocks.COBBLESTONE_SLAB.getDefaultState().with(SlabBlock.TYPE, SlabType.BOTTOM).with(SlabBlock.WATERLOGGED, false), 22, 21, 20, start);
        structure.setBlockState(world, Blocks.COBBLESTONE_SLAB.getDefaultState().with(SlabBlock.TYPE, SlabType.BOTTOM).with(SlabBlock.WATERLOGGED, false), 22, 21, 26, start);
        structure.setBlockState(world, Blocks.STONE.getDefaultState(), 23, 1, 14, start);
        structure.setBlockState(world, Blocks.AIR.getDefaultState(), 23, 7, 12, start);
        structure.setBlockState(world, Blocks.AIR.getDefaultState(), 23, 7, 34, start);
        structure.setBlockState(world, Blocks.AIR.getDefaultState(), 23, 13, 24, start);
        structure.setBlockState(world, Blocks.CHISELED_STONE_BRICKS.getDefaultState(), 23, 16, 17, start);
        structure.setBlockState(world, Blocks.WALL_TORCH.getDefaultState().with(WallTorchBlock.HORIZONTAL_FACING, Direction.SOUTH), 23, 16, 19, start);
        structure.setBlockState(world, Blocks.WALL_TORCH.getDefaultState().with(WallTorchBlock.HORIZONTAL_FACING, Direction.NORTH), 23, 16, 27, start);
        structure.setBlockState(world, Blocks.CHISELED_STONE_BRICKS.getDefaultState(), 23, 16, 29, start);
        structure.setBlockState(world, Blocks.OAK_FENCE.getDefaultState().with(FourWayBlock.WATERLOGGED, false).with(FourWayBlock.NORTH, false).with(FourWayBlock.SOUTH, true).with(FourWayBlock.EAST, false).with(FourWayBlock.WEST, false), 23, 17, 22, start);
        structure.setBlockState(world, Blocks.OAK_FENCE.getDefaultState().with(FourWayBlock.WATERLOGGED, false).with(FourWayBlock.NORTH, true).with(FourWayBlock.SOUTH, false).with(FourWayBlock.EAST, false).with(FourWayBlock.WEST, false), 23, 17, 24, start);
        structure.setBlockState(world, Blocks.OAK_FENCE.getDefaultState().with(FourWayBlock.WATERLOGGED, false).with(FourWayBlock.NORTH, false).with(FourWayBlock.SOUTH, true).with(FourWayBlock.EAST, false).with(FourWayBlock.WEST, false), 23, 18, 21, start);
        structure.setBlockState(world, Blocks.OAK_FENCE.getDefaultState().with(FourWayBlock.WATERLOGGED, false).with(FourWayBlock.NORTH, true).with(FourWayBlock.SOUTH, true).with(FourWayBlock.EAST, false).with(FourWayBlock.WEST, false), 23, 18, 22, start);
        structure.setBlockState(world, Blocks.OAK_FENCE.getDefaultState().with(FourWayBlock.WATERLOGGED, false).with(FourWayBlock.NORTH, true).with(FourWayBlock.SOUTH, true).with(FourWayBlock.EAST, false).with(FourWayBlock.WEST, false), 23, 18, 24, start);
        structure.setBlockState(world, Blocks.OAK_FENCE.getDefaultState().with(FourWayBlock.WATERLOGGED, false).with(FourWayBlock.NORTH, true).with(FourWayBlock.SOUTH, false).with(FourWayBlock.EAST, false).with(FourWayBlock.WEST, false), 23, 18, 25, start);
        structure.setBlockState(world, Blocks.GLOWSTONE.getDefaultState(), 23, 23, 24, start);
        structure.setBlockState(world, Blocks.COBBLESTONE_SLAB.getDefaultState().with(SlabBlock.TYPE, SlabType.DOUBLE).with(SlabBlock.WATERLOGGED, false), 23, 24, 23, start);
        structure.setBlockState(world, Blocks.CHISELED_STONE_BRICKS.getDefaultState(), 23, 28, 23, start);
        structure.setBlockState(world, Blocks.OAK_FENCE.getDefaultState().with(FourWayBlock.WATERLOGGED, false).with(FourWayBlock.NORTH, false).with(FourWayBlock.SOUTH, false).with(FourWayBlock.EAST, false).with(FourWayBlock.WEST, true), 24, 17, 23, start);
        structure.setBlockState(world, Blocks.OAK_FENCE.getDefaultState().with(FourWayBlock.WATERLOGGED, false).with(FourWayBlock.NORTH, false).with(FourWayBlock.SOUTH, false).with(FourWayBlock.EAST, true).with(FourWayBlock.WEST, true), 24, 18, 23, start);
        structure.setBlockState(world, Blocks.COBBLESTONE_SLAB.getDefaultState().with(SlabBlock.TYPE, SlabType.BOTTOM).with(SlabBlock.WATERLOGGED, false), 24, 21, 20, start);
        structure.setBlockState(world, Blocks.COBBLESTONE_SLAB.getDefaultState().with(SlabBlock.TYPE, SlabType.BOTTOM).with(SlabBlock.WATERLOGGED, false), 24, 21, 26, start);
        structure.setBlockState(world, Blocks.GLOWSTONE.getDefaultState(), 24, 23, 23, start);
        structure.setBlockState(world, Blocks.STONE.getDefaultState(), 25, 1, 13, start);
        structure.setBlockState(world, Blocks.DIRT.getDefaultState(), 25, 2, 43, start);
        structure.setBlockState(world, Blocks.MOSSY_COBBLESTONE.getDefaultState(), 25, 10, 30, start);
        structure.setBlockState(world, Blocks.MOSSY_COBBLESTONE.getDefaultState(), 25, 18, 18, start);
        structure.setBlockState(world, Blocks.OAK_FENCE.getDefaultState().with(FourWayBlock.WATERLOGGED, false).with(FourWayBlock.NORTH, false).with(FourWayBlock.SOUTH, false).with(FourWayBlock.EAST, false).with(FourWayBlock.WEST, true), 25, 18, 23, start);
        structure.setBlockState(world, Blocks.MOSSY_COBBLESTONE.getDefaultState(), 25, 18, 28, start);
        structure.setBlockState(world, Blocks.COBBLESTONE_SLAB.getDefaultState().with(SlabBlock.TYPE, SlabType.DOUBLE).with(SlabBlock.WATERLOGGED, false), 25, 21, 26, start);
        structure.setBlockState(world, Blocks.COBBLESTONE_SLAB.getDefaultState().with(SlabBlock.TYPE, SlabType.BOTTOM).with(SlabBlock.WATERLOGGED, false), 25, 24, 21, start);
        structure.setBlockState(world, Blocks.COBBLESTONE_SLAB.getDefaultState().with(SlabBlock.TYPE, SlabType.BOTTOM).with(SlabBlock.WATERLOGGED, false), 25, 24, 25, start);
        structure.setBlockState(world, Blocks.WATER.getDefaultState(), 26, 7, 13, start);
        structure.setBlockState(world, Blocks.WATER.getDefaultState(), 26, 7, 33, start);
        structure.setBlockState(world, Blocks.WATER.getDefaultState(), 26, 10, 20, start);
        structure.setBlockState(world, Blocks.WATER.getDefaultState(), 26, 10, 26, start);
        structure.setBlockState(world, Blocks.WATER.getDefaultState(), 26, 10, 27, start);
        structure.setBlockState(world, Blocks.WATER.getDefaultState(), 26, 10, 28, start);
        structure.setBlockState(world, Blocks.WATER.getDefaultState(), 26, 10, 29, start);
        structure.setBlockState(world, Blocks.MOSSY_COBBLESTONE.getDefaultState(), 26, 15, 27, start);
        structure.setBlockState(world, Blocks.MOSSY_COBBLESTONE.getDefaultState(), 26, 17, 27, start);
        structure.setBlockState(world, Blocks.OAK_FENCE.getDefaultState().with(FourWayBlock.WATERLOGGED, false).with(FourWayBlock.NORTH, false).with(FourWayBlock.SOUTH, false).with(FourWayBlock.EAST, false).with(FourWayBlock.WEST, false), 26, 18, 27, start);
        structure.setBlockState(world, Blocks.COBBLESTONE_SLAB.getDefaultState().with(SlabBlock.TYPE, SlabType.DOUBLE).with(SlabBlock.WATERLOGGED, false), 26, 21, 21, start);
        structure.setBlockState(world, Blocks.COBBLESTONE_SLAB.getDefaultState().with(SlabBlock.TYPE, SlabType.BOTTOM).with(SlabBlock.WATERLOGGED, false), 26, 21, 22, start);
        structure.setBlockState(world, Blocks.COBBLESTONE_SLAB.getDefaultState().with(SlabBlock.TYPE, SlabType.BOTTOM).with(SlabBlock.WATERLOGGED, false), 26, 21, 24, start);
        structure.setBlockState(world, Blocks.COBBLESTONE_SLAB.getDefaultState().with(SlabBlock.TYPE, SlabType.DOUBLE).with(SlabBlock.WATERLOGGED, false), 26, 21, 25, start);
        structure.setBlockState(world, Blocks.COBBLESTONE.getDefaultState(), 26, 23, 20, start);
        structure.setBlockState(world, Blocks.COBBLESTONE.getDefaultState(), 26, 23, 26, start);
        structure.setBlockState(world, Blocks.WATER.getDefaultState(), 27, 7, 13, start);
        structure.setBlockState(world, Blocks.WATER.getDefaultState(), 27, 7, 33, start);
        structure.setBlockState(world, Blocks.WATER.getDefaultState(), 27, 10, 17, start);
        structure.setBlockState(world, Blocks.WATER.getDefaultState(), 27, 10, 20, start);
        structure.setBlockState(world, Blocks.WATER.getDefaultState(), 27, 10, 26, start);
        structure.setBlockState(world, Blocks.WATER.getDefaultState(), 27, 10, 27, start);
        structure.setBlockState(world, Blocks.WATER.getDefaultState(), 27, 10, 28, start);
        structure.setBlockState(world, Blocks.WATER.getDefaultState(), 27, 10, 29, start);
        structure.setBlockState(world, Blocks.AIR.getDefaultState(), 27, 11, 16, start);
        structure.setBlockState(world, Blocks.AIR.getDefaultState(), 27, 11, 30, start);
        structure.setBlockState(world, Blocks.MOSSY_COBBLESTONE.getDefaultState(), 27, 15, 26, start);
        structure.setBlockState(world, Blocks.WALL_TORCH.getDefaultState().with(WallTorchBlock.HORIZONTAL_FACING, Direction.WEST), 27, 16, 23, start);
        structure.setBlockState(world, Blocks.TORCH.getDefaultState(), 27, 17, 19, start);
        structure.setBlockState(world, Blocks.MOSSY_COBBLESTONE.getDefaultState(), 27, 17, 26, start);
        structure.setBlockState(world, Blocks.TORCH.getDefaultState(), 27, 17, 27, start);
        structure.setBlockState(world, Blocks.OAK_FENCE.getDefaultState().with(FourWayBlock.WATERLOGGED, false).with(FourWayBlock.NORTH, false).with(FourWayBlock.SOUTH, false).with(FourWayBlock.EAST, false).with(FourWayBlock.WEST, false), 27, 18, 20, start);
        structure.setBlockState(world, Blocks.OAK_FENCE.getDefaultState().with(FourWayBlock.WATERLOGGED, false).with(FourWayBlock.NORTH, false).with(FourWayBlock.SOUTH, false).with(FourWayBlock.EAST, false).with(FourWayBlock.WEST, false), 27, 18, 26, start);
        structure.setBlockState(world, Blocks.COBBLESTONE_SLAB.getDefaultState().with(SlabBlock.TYPE, SlabType.BOTTOM).with(SlabBlock.WATERLOGGED, false), 27, 20, 19, start);
        structure.setBlockState(world, Blocks.COBBLESTONE_SLAB.getDefaultState().with(SlabBlock.TYPE, SlabType.BOTTOM).with(SlabBlock.WATERLOGGED, false), 27, 20, 27, start);
        structure.setBlockState(world, Blocks.WATER.getDefaultState(), 28, 7, 13, start);
        structure.setBlockState(world, Blocks.WATER.getDefaultState(), 28, 7, 33, start);
        structure.setBlockState(world, Blocks.WATER.getDefaultState(), 28, 10, 20, start);
        structure.setBlockState(world, Blocks.WATER.getDefaultState(), 28, 10, 26, start);
        structure.setBlockState(world, Blocks.WATER.getDefaultState(), 28, 10, 27, start);
        structure.setBlockState(world, Blocks.COBBLESTONE.getDefaultState(), 28, 10, 28, start);
        structure.setBlockState(world, Blocks.WATER.getDefaultState(), 28, 10, 29, start);
        structure.setBlockState(world, Blocks.COBBLESTONE_SLAB.getDefaultState().with(SlabBlock.TYPE, SlabType.DOUBLE).with(SlabBlock.WATERLOGGED, false), 28, 11, 28, start);
        structure.setBlockState(world, Blocks.TORCH.getDefaultState(), 28, 12, 18, start);
        structure.setBlockState(world, Blocks.TORCH.getDefaultState(), 28, 12, 28, start);
        structure.setBlockState(world, Blocks.MOSSY_COBBLESTONE.getDefaultState(), 28, 15, 22, start);
        structure.setBlockState(world, Blocks.COBBLESTONE.getDefaultState(), 28, 16, 26, start);
        structure.setBlockState(world, Blocks.MOSSY_COBBLESTONE.getDefaultState(), 28, 18, 21, start);
        structure.setBlockState(world, Blocks.MOSSY_COBBLESTONE.getDefaultState(), 28, 18, 25, start);
        structure.setBlockState(world, Blocks.WATER.getDefaultState(), 29, 7, 13, start);
        structure.setBlockState(world, Blocks.WATER.getDefaultState(), 29, 7, 33, start);
        structure.setBlockState(world, Blocks.WATER.getDefaultState(), 29, 8, 13, start);
        structure.setBlockState(world, Blocks.WATER.getDefaultState(), 29, 8, 14, start);
        structure.setBlockState(world, Blocks.WATER.getDefaultState(), 29, 8, 32, start);
        structure.setBlockState(world, Blocks.WATER.getDefaultState(), 29, 8, 33, start);
        structure.setBlockState(world, Blocks.WATER.getDefaultState(), 29, 9, 14, start);
        structure.setBlockState(world, Blocks.WATER.getDefaultState(), 29, 9, 15, start);
        structure.setBlockState(world, Blocks.WATER.getDefaultState(), 29, 9, 29, start);
        structure.setBlockState(world, Blocks.WATER.getDefaultState(), 29, 9, 30, start);
        structure.setBlockState(world, Blocks.WATER.getDefaultState(), 29, 9, 31, start);
        structure.setBlockState(world, Blocks.WATER.getDefaultState(), 29, 9, 32, start);
        structure.setBlockState(world, Blocks.WATER.getDefaultState(), 29, 10, 17, start);
        structure.setBlockState(world, Blocks.WATER.getDefaultState(), 29, 10, 18, start);
        structure.setBlockState(world, Blocks.WATER.getDefaultState(), 29, 10, 19, start);
        structure.setBlockState(world, Blocks.WATER.getDefaultState(), 29, 10, 20, start);
        structure.setBlockState(world, Blocks.WATER.getDefaultState(), 29, 10, 26, start);
        structure.setBlockState(world, Blocks.WATER.getDefaultState(), 29, 10, 27, start);
        structure.setBlockState(world, Blocks.WATER.getDefaultState(), 29, 10, 28, start);
        structure.setBlockState(world, Blocks.WATER.getDefaultState(), 29, 10, 29, start);
        structure.setBlockState(world, Blocks.MOSSY_COBBLESTONE.getDefaultState(), 29, 11, 21, start);
        structure.setBlockState(world, Blocks.CHISELED_STONE_BRICKS.getDefaultState(), 29, 16, 23, start);
        structure.setBlockState(world, Blocks.GRASS_BLOCK.getDefaultState().with(SnowyDirtBlock.SNOWY, false), 30, 6, 31, start);
        structure.setBlockState(world, Blocks.WATER.getDefaultState(), 30, 7, 13, start);
        structure.setBlockState(world, Blocks.WATER.getDefaultState(), 30, 7, 33, start);
        structure.setBlockState(world, Blocks.COBBLESTONE_STAIRS.getDefaultState().with(StairsBlock.FACING, Direction.SOUTH).with(StairsBlock.WATERLOGGED, false).with(StairsBlock.SHAPE, StairsShape.STRAIGHT).with(StairsBlock.HALF, Half.BOTTOM), 30, 8, 14, start);
        structure.setBlockState(world, Blocks.COBBLESTONE.getDefaultState(), 30, 8, 30, start);
        structure.setBlockState(world, Blocks.COBBLESTONE_STAIRS.getDefaultState().with(StairsBlock.FACING, Direction.NORTH).with(StairsBlock.WATERLOGGED, false).with(StairsBlock.SHAPE, StairsShape.STRAIGHT).with(StairsBlock.HALF, Half.BOTTOM), 30, 8, 32, start);
        structure.setBlockState(world, Blocks.COBBLESTONE_SLAB.getDefaultState().with(SlabBlock.TYPE, SlabType.BOTTOM).with(SlabBlock.WATERLOGGED, false), 30, 9, 16, start);
        structure.setBlockState(world, Blocks.WATER.getDefaultState(), 30, 9, 17, start);
        structure.setBlockState(world, Blocks.WATER.getDefaultState(), 30, 9, 29, start);
        structure.setBlockState(world, Blocks.WATER.getDefaultState(), 30, 10, 17, start);
        structure.setBlockState(world, Blocks.MOSSY_COBBLESTONE.getDefaultState(), 30, 10, 25, start);
        structure.setBlockState(world, Blocks.AIR.getDefaultState(), 30, 11, 19, start);
        structure.setBlockState(world, Blocks.AIR.getDefaultState(), 30, 11, 27, start);
        structure.setBlockState(world, Blocks.STONE.getDefaultState(), 31, 0, 38, start);
        structure.setBlockState(world, Blocks.STONE.getDefaultState(), 31, 1, 36, start);
        structure.setBlockState(world, Blocks.WATER.getDefaultState(), 31, 7, 13, start);
        structure.setBlockState(world, Blocks.WATER.getDefaultState(), 31, 7, 33, start);
        structure.setBlockState(world, Blocks.COBBLESTONE_SLAB.getDefaultState().with(SlabBlock.TYPE, SlabType.BOTTOM).with(SlabBlock.WATERLOGGED, false), 31, 8, 15, start);
        structure.setBlockState(world, Blocks.COBBLESTONE.getDefaultState(), 31, 8, 16, start);
        structure.setBlockState(world, Blocks.COBBLESTONE_SLAB.getDefaultState().with(SlabBlock.TYPE, SlabType.BOTTOM).with(SlabBlock.WATERLOGGED, false), 31, 8, 32, start);
        structure.setBlockState(world, Blocks.WATER.getDefaultState(), 31, 9, 17, start);
        structure.setBlockState(world, Blocks.WATER.getDefaultState(), 31, 9, 29, start);
        structure.setBlockState(world, Blocks.COBBLESTONE_SLAB.getDefaultState().with(SlabBlock.TYPE, SlabType.BOTTOM).with(SlabBlock.WATERLOGGED, false), 31, 9, 30, start);
        structure.setBlockState(world, Blocks.GRASS_BLOCK.getDefaultState().with(SnowyDirtBlock.SNOWY, false), 32, 6, 37, start);
        structure.setBlockState(world, Blocks.COBBLESTONE_SLAB.getDefaultState().with(SlabBlock.TYPE, SlabType.BOTTOM).with(SlabBlock.WATERLOGGED, false), 32, 7, 14, start);
        structure.setBlockState(world, Blocks.COBBLESTONE.getDefaultState(), 32, 7, 15, start);
        structure.setBlockState(world, Blocks.COBBLESTONE.getDefaultState(), 32, 7, 32, start);
        structure.setBlockState(world, Blocks.WATER.getDefaultState(), 32, 7, 33, start);
        structure.setBlockState(world, Blocks.COBBLESTONE_STAIRS.getDefaultState().with(StairsBlock.FACING, Direction.WEST).with(StairsBlock.WATERLOGGED, false).with(StairsBlock.SHAPE, StairsShape.STRAIGHT).with(StairsBlock.HALF, Half.BOTTOM), 32, 8, 16, start);
        structure.setBlockState(world, Blocks.WATER.getDefaultState(), 32, 8, 17, start);
        structure.setBlockState(world, Blocks.WATER.getDefaultState(), 32, 8, 29, start);
        structure.setBlockState(world, Blocks.COBBLESTONE_STAIRS.getDefaultState().with(StairsBlock.FACING, Direction.WEST).with(StairsBlock.WATERLOGGED, false).with(StairsBlock.SHAPE, StairsShape.STRAIGHT).with(StairsBlock.HALF, Half.BOTTOM), 32, 8, 30, start);
        structure.setBlockState(world, Blocks.COBBLESTONE_SLAB.getDefaultState().with(SlabBlock.TYPE, SlabType.BOTTOM).with(SlabBlock.WATERLOGGED, false), 32, 8, 31, start);
        structure.setBlockState(world, Blocks.WATER.getDefaultState(), 32, 9, 17, start);
        structure.setBlockState(world, Blocks.WATER.getDefaultState(), 32, 9, 29, start);
        structure.setBlockState(world, Blocks.STONE.getDefaultState(), 33, 0, 36, start);
        structure.setBlockState(world, Blocks.STONE.getDefaultState(), 33, 1, 8, start);
        structure.setBlockState(world, Blocks.GRASS_BLOCK.getDefaultState().with(SnowyDirtBlock.SNOWY, false), 33, 2, 41, start);
        structure.setBlockState(world, Blocks.GRASS_BLOCK.getDefaultState().with(SnowyDirtBlock.SNOWY, false), 33, 3, 6, start);
        structure.setBlockState(world, Blocks.GRASS_BLOCK.getDefaultState().with(SnowyDirtBlock.SNOWY, false), 33, 3, 40, start);
        structure.setBlockState(world, Blocks.WATER.getDefaultState(), 33, 7, 13, start);
        structure.setBlockState(world, Blocks.WATER.getDefaultState(), 33, 7, 14, start);
        structure.setBlockState(world, Blocks.WATER.getDefaultState(), 33, 7, 15, start);
        structure.setBlockState(world, Blocks.WATER.getDefaultState(), 33, 7, 16, start);
        structure.setBlockState(world, Blocks.WATER.getDefaultState(), 33, 7, 17, start);
        structure.setBlockState(world, Blocks.WATER.getDefaultState(), 33, 7, 18, start);
        structure.setBlockState(world, Blocks.WATER.getDefaultState(), 33, 7, 19, start);
        structure.setBlockState(world, Blocks.WATER.getDefaultState(), 33, 7, 20, start);
        structure.setBlockState(world, Blocks.WATER.getDefaultState(), 33, 7, 26, start);
        structure.setBlockState(world, Blocks.WATER.getDefaultState(), 33, 7, 27, start);
        structure.setBlockState(world, Blocks.WATER.getDefaultState(), 33, 7, 28, start);
        structure.setBlockState(world, Blocks.WATER.getDefaultState(), 33, 7, 29, start);
        structure.setBlockState(world, Blocks.WATER.getDefaultState(), 33, 7, 30, start);
        structure.setBlockState(world, Blocks.WATER.getDefaultState(), 33, 7, 31, start);
        structure.setBlockState(world, Blocks.WATER.getDefaultState(), 33, 7, 32, start);
        structure.setBlockState(world, Blocks.WATER.getDefaultState(), 33, 7, 33, start);
        structure.setBlockState(world, Blocks.GRASS.getDefaultState(), 33, 7, 35, start);
        structure.setBlockState(world, Blocks.WATER.getDefaultState(), 33, 8, 17, start);
        structure.setBlockState(world, Blocks.WATER.getDefaultState(), 33, 8, 29, start);
        structure.setBlockState(world, Blocks.GRASS_BLOCK.getDefaultState().with(SnowyDirtBlock.SNOWY, false), 34, 0, 42, start);
        structure.setBlockState(world, Blocks.GRASS_BLOCK.getDefaultState().with(SnowyDirtBlock.SNOWY, false), 34, 1, 5, start);
        structure.setBlockState(world, Blocks.GRASS_BLOCK.getDefaultState().with(SnowyDirtBlock.SNOWY, false), 34, 1, 41, start);
        structure.setBlockState(world, Blocks.AIR.getDefaultState(), 34, 7, 23, start);
        structure.setBlockState(world, Blocks.STONE.getDefaultState(), 35, 1, 9, start);
        structure.setBlockState(world, Blocks.GRASS_BLOCK.getDefaultState().with(SnowyDirtBlock.SNOWY, false), 35, 3, 39, start);
        structure.setBlockState(world, Blocks.GRASS_BLOCK.getDefaultState().with(SnowyDirtBlock.SNOWY, false), 35, 4, 38, start);
        structure.setBlockState(world, Blocks.DANDELION.getDefaultState(), 35, 7, 16, start);
        structure.setBlockState(world, Blocks.GRASS.getDefaultState(), 35, 7, 18, start);
        structure.setBlockState(world, Blocks.GRASS.getDefaultState(), 35, 7, 20, start);
        structure.setBlockState(world, Blocks.GRASS.getDefaultState(), 35, 7, 28, start);
        structure.setBlockState(world, Blocks.DIRT.getDefaultState(), 36, 1, 39, start);
        structure.setBlockState(world, Blocks.GRASS_BLOCK.getDefaultState().with(SnowyDirtBlock.SNOWY, false), 36, 1, 40, start);
        structure.setBlockState(world, Blocks.GRASS_BLOCK.getDefaultState().with(SnowyDirtBlock.SNOWY, false), 36, 2, 39, start);
        structure.setBlockState(world, Blocks.GRASS_BLOCK.getDefaultState().with(SnowyDirtBlock.SNOWY, false), 36, 3, 38, start);
        structure.setBlockState(world, Blocks.GRASS_BLOCK.getDefaultState().with(SnowyDirtBlock.SNOWY, false), 36, 4, 37, start);
        structure.setBlockState(world, Blocks.GRASS_BLOCK.getDefaultState().with(SnowyDirtBlock.SNOWY, false), 36, 5, 36, start);
        structure.setBlockState(world, Blocks.GRASS_BLOCK.getDefaultState().with(SnowyDirtBlock.SNOWY, false), 37, 0, 40, start);
        structure.setBlockState(world, Blocks.GRASS_BLOCK.getDefaultState().with(SnowyDirtBlock.SNOWY, false), 37, 1, 39, start);
        structure.setBlockState(world, Blocks.GRASS_BLOCK.getDefaultState().with(SnowyDirtBlock.SNOWY, false), 37, 2, 38, start);
        structure.setBlockState(world, Blocks.GRASS_BLOCK.getDefaultState().with(SnowyDirtBlock.SNOWY, false), 37, 3, 37, start);
        structure.setBlockState(world, Blocks.GRASS_BLOCK.getDefaultState().with(SnowyDirtBlock.SNOWY, false), 37, 4, 36, start);
        structure.setBlockState(world, Blocks.GRASS_BLOCK.getDefaultState().with(SnowyDirtBlock.SNOWY, false), 38, 0, 39, start);
        structure.setBlockState(world, Blocks.GRASS_BLOCK.getDefaultState().with(SnowyDirtBlock.SNOWY, false), 38, 1, 38, start);
        structure.setBlockState(world, Blocks.GRASS_BLOCK.getDefaultState().with(SnowyDirtBlock.SNOWY, false), 38, 2, 37, start);
        structure.setBlockState(world, Blocks.GRASS_BLOCK.getDefaultState().with(SnowyDirtBlock.SNOWY, false), 38, 3, 36, start);
        structure.setBlockState(world, Blocks.GRASS_BLOCK.getDefaultState().with(SnowyDirtBlock.SNOWY, false), 38, 5, 33, start);
        structure.setBlockState(world, Blocks.DIRT.getDefaultState(), 39, 0, 37, start);
        structure.setBlockState(world, Blocks.GRASS_BLOCK.getDefaultState().with(SnowyDirtBlock.SNOWY, false), 39, 0, 38, start);
        structure.setBlockState(world, Blocks.GRASS_BLOCK.getDefaultState().with(SnowyDirtBlock.SNOWY, false), 39, 1, 37, start);
        structure.setBlockState(world, Blocks.GRASS_BLOCK.getDefaultState().with(SnowyDirtBlock.SNOWY, false), 39, 2, 36, start);
        structure.setBlockState(world, Blocks.GRASS_BLOCK.getDefaultState().with(SnowyDirtBlock.SNOWY, false), 39, 3, 11, start);
        structure.setBlockState(world, Blocks.GRASS_BLOCK.getDefaultState().with(SnowyDirtBlock.SNOWY, false), 39, 3, 35, start);
        structure.setBlockState(world, Blocks.GRASS_BLOCK.getDefaultState().with(SnowyDirtBlock.SNOWY, false), 40, 0, 37, start);
        structure.setBlockState(world, Blocks.GRASS_BLOCK.getDefaultState().with(SnowyDirtBlock.SNOWY, false), 40, 1, 10, start);
        structure.setBlockState(world, Blocks.GRASS_BLOCK.getDefaultState().with(SnowyDirtBlock.SNOWY, false), 40, 1, 36, start);
        structure.setBlockState(world, Blocks.GRASS_BLOCK.getDefaultState().with(SnowyDirtBlock.SNOWY, false), 40, 3, 33, start);
        structure.setBlockState(world, Blocks.DIRT.getDefaultState(), 41, 0, 34, start);
        structure.setBlockState(world, Blocks.GRASS_BLOCK.getDefaultState().with(SnowyDirtBlock.SNOWY, false), 41, 1, 34, start);
        structure.setBlockState(world, Blocks.GRASS_BLOCK.getDefaultState().with(SnowyDirtBlock.SNOWY, false), 41, 2, 13, start);
        structure.setBlockState(world, Blocks.GRASS_BLOCK.getDefaultState().with(SnowyDirtBlock.SNOWY, false), 41, 2, 33, start);
        structure.setBlockState(world, Blocks.GRASS_BLOCK.getDefaultState().with(SnowyDirtBlock.SNOWY, false), 42, 0, 12, start);
        structure.setBlockState(world, Blocks.GRASS_BLOCK.getDefaultState().with(SnowyDirtBlock.SNOWY, false), 42, 0, 34, start);
        structure.fillWithBlocks(world, start, 1, 0, 20, 1, 0, 26, Blocks.GRASS_BLOCK.getDefaultState().with(SnowyDirtBlock.SNOWY, false));
        structure.fillWithBlocks(world, start, 2, 0, 16, 2, 0, 18, Blocks.GRASS_BLOCK.getDefaultState().with(SnowyDirtBlock.SNOWY, false));
        structure.fillWithBlocks(world, start, 2, 0, 19, 3, 0, 27, Blocks.DIRT.getDefaultState());
        structure.fillWithBlocks(world, start, 2, 0, 28, 2, 0, 30, Blocks.GRASS_BLOCK.getDefaultState().with(SnowyDirtBlock.SNOWY, false));
        structure.fillWithBlocks(world, start, 2, 1, 19, 2, 1, 27, Blocks.GRASS_BLOCK.getDefaultState().with(SnowyDirtBlock.SNOWY, false));
        structure.fillWithBlocks(world, start, 3, 0, 14, 3, 0, 15, Blocks.GRASS_BLOCK.getDefaultState().with(SnowyDirtBlock.SNOWY, false));
        structure.fillWithBlocks(world, start, 3, 0, 16, 4, 0, 18, Blocks.DIRT.getDefaultState());
        structure.fillWithBlocks(world, start, 3, 0, 28, 4, 0, 30, Blocks.DIRT.getDefaultState());
        structure.fillWithBlocks(world, start, 3, 0, 31, 3, 0, 32, Blocks.GRASS_BLOCK.getDefaultState().with(SnowyDirtBlock.SNOWY, false));
        structure.fillWithBlocks(world, start, 3, 1, 16, 3, 1, 17, Blocks.GRASS_BLOCK.getDefaultState().with(SnowyDirtBlock.SNOWY, false));
        structure.fillWithBlocks(world, start, 3, 1, 18, 4, 1, 28, Blocks.DIRT.getDefaultState());
        structure.fillWithBlocks(world, start, 3, 1, 29, 3, 1, 30, Blocks.GRASS_BLOCK.getDefaultState().with(SnowyDirtBlock.SNOWY, false));
        structure.fillWithBlocks(world, start, 3, 2, 18, 3, 2, 20, Blocks.GRASS_BLOCK.getDefaultState().with(SnowyDirtBlock.SNOWY, false));
        structure.fillWithBlocks(world, start, 3, 2, 21, 6, 2, 25, Blocks.DIRT.getDefaultState());
        structure.fillWithBlocks(world, start, 3, 2, 26, 3, 2, 28, Blocks.GRASS_BLOCK.getDefaultState().with(SnowyDirtBlock.SNOWY, false));
        structure.fillWithBlocks(world, start, 3, 3, 21, 3, 3, 25, Blocks.GRASS_BLOCK.getDefaultState().with(SnowyDirtBlock.SNOWY, false));
        structure.fillWithBlocks(world, start, 4, 0, 13, 5, 0, 15, Blocks.DIRT.getDefaultState());
        structure.fillWithBlocks(world, start, 4, 0, 19, 9, 0, 24, Blocks.STONE.getDefaultState());
        structure.fillWithBlocks(world, start, 4, 0, 25, 4, 1, 26, Blocks.DIRT.getDefaultState());
        structure.fillWithBlocks(world, start, 4, 0, 27, 4, 0, 27, Blocks.STONE.getDefaultState());
        structure.fillWithBlocks(world, start, 4, 0, 31, 5, 0, 33, Blocks.DIRT.getDefaultState());
        structure.fillWithBlocks(world, start, 4, 0, 34, 4, 0, 34, Blocks.GRASS_BLOCK.getDefaultState().with(SnowyDirtBlock.SNOWY, false));
        structure.fillWithBlocks(world, start, 4, 1, 13, 4, 1, 14, Blocks.GRASS_BLOCK.getDefaultState().with(SnowyDirtBlock.SNOWY, false));
        structure.fillWithBlocks(world, start, 4, 1, 15, 5, 1, 18, Blocks.DIRT.getDefaultState());
        structure.fillWithBlocks(world, start, 4, 1, 29, 5, 1, 31, Blocks.DIRT.getDefaultState());
        structure.fillWithBlocks(world, start, 4, 1, 32, 4, 1, 33, Blocks.GRASS_BLOCK.getDefaultState().with(SnowyDirtBlock.SNOWY, false));
        structure.fillWithBlocks(world, start, 4, 2, 15, 4, 2, 16, Blocks.GRASS_BLOCK.getDefaultState().with(SnowyDirtBlock.SNOWY, false));
        structure.fillWithBlocks(world, start, 4, 2, 17, 6, 2, 29, Blocks.DIRT.getDefaultState());
        structure.fillWithBlocks(world, start, 4, 2, 30, 4, 2, 31, Blocks.GRASS_BLOCK.getDefaultState().with(SnowyDirtBlock.SNOWY, false));
        structure.fillWithBlocks(world, start, 4, 3, 17, 4, 3, 18, Blocks.GRASS_BLOCK.getDefaultState().with(SnowyDirtBlock.SNOWY, false));
        structure.fillWithBlocks(world, start, 4, 3, 19, 12, 3, 27, Blocks.DIRT.getDefaultState());
        structure.fillWithBlocks(world, start, 4, 3, 28, 4, 3, 29, Blocks.GRASS_BLOCK.getDefaultState().with(SnowyDirtBlock.SNOWY, false));
        structure.fillWithBlocks(world, start, 4, 4, 19, 4, 4, 27, Blocks.GRASS_BLOCK.getDefaultState().with(SnowyDirtBlock.SNOWY, false));
        structure.fillWithBlocks(world, start, 5, 0, 10, 5, 0, 11, Blocks.GRASS_BLOCK.getDefaultState().with(SnowyDirtBlock.SNOWY, false));
        structure.fillWithBlocks(world, start, 5, 0, 12, 6, 0, 13, Blocks.DIRT.getDefaultState());
        structure.fillWithBlocks(world, start, 5, 0, 16, 19, 0, 30, Blocks.STONE.getDefaultState());
        structure.fillWithBlocks(world, start, 5, 0, 34, 5, 0, 34, Blocks.DIRT.getDefaultState());
        structure.fillWithBlocks(world, start, 5, 0, 35, 5, 0, 36, Blocks.GRASS_BLOCK.getDefaultState().with(SnowyDirtBlock.SNOWY, false));
        structure.fillWithBlocks(world, start, 5, 1, 13, 6, 1, 15, Blocks.DIRT.getDefaultState());
        structure.fillWithBlocks(world, start, 5, 1, 19, 8, 1, 22, Blocks.STONE.getDefaultState());
        structure.fillWithBlocks(world, start, 5, 1, 24, 6, 1, 28, Blocks.DIRT.getDefaultState());
        structure.fillWithBlocks(world, start, 5, 1, 32, 6, 1, 33, Blocks.DIRT.getDefaultState());
        structure.fillWithBlocks(world, start, 5, 2, 14, 7, 2, 17, Blocks.DIRT.getDefaultState());
        structure.fillWithBlocks(world, start, 5, 2, 30, 7, 2, 32, Blocks.DIRT.getDefaultState());
        structure.fillWithBlocks(world, start, 5, 2, 33, 5, 2, 33, Blocks.GRASS_BLOCK.getDefaultState().with(SnowyDirtBlock.SNOWY, false));
        structure.fillWithBlocks(world, start, 5, 3, 14, 5, 3, 15, Blocks.GRASS_BLOCK.getDefaultState().with(SnowyDirtBlock.SNOWY, false));
        structure.fillWithBlocks(world, start, 5, 3, 16, 19, 3, 30, Blocks.DIRT.getDefaultState());
        structure.fillWithBlocks(world, start, 5, 3, 31, 5, 3, 32, Blocks.GRASS_BLOCK.getDefaultState().with(SnowyDirtBlock.SNOWY, false));
        structure.fillWithBlocks(world, start, 5, 4, 16, 5, 4, 18, Blocks.GRASS_BLOCK.getDefaultState().with(SnowyDirtBlock.SNOWY, false));
        structure.fillWithBlocks(world, start, 5, 4, 19, 13, 4, 27, Blocks.DIRT.getDefaultState());
        structure.fillWithBlocks(world, start, 5, 4, 28, 5, 4, 30, Blocks.GRASS_BLOCK.getDefaultState().with(SnowyDirtBlock.SNOWY, false));
        structure.fillWithBlocks(world, start, 5, 5, 19, 6, 5, 27, Blocks.GRASS_BLOCK.getDefaultState().with(SnowyDirtBlock.SNOWY, false));
        structure.fillWithBlocks(world, start, 6, 0, 10, 7, 0, 11, Blocks.DIRT.getDefaultState());
        structure.fillWithBlocks(world, start, 6, 0, 14, 24, 0, 32, Blocks.STONE.getDefaultState());
        structure.fillWithBlocks(world, start, 6, 0, 33, 6, 1, 35, Blocks.DIRT.getDefaultState());
        structure.fillWithBlocks(world, start, 6, 0, 36, 6, 0, 36, Blocks.DIRT.getDefaultState());
        structure.fillWithBlocks(world, start, 6, 0, 37, 6, 0, 37, Blocks.GRASS_BLOCK.getDefaultState().with(SnowyDirtBlock.SNOWY, false));
        structure.fillWithBlocks(world, start, 6, 1, 11, 7, 1, 13, Blocks.DIRT.getDefaultState());
        structure.fillWithBlocks(world, start, 6, 1, 16, 12, 1, 22, Blocks.STONE.getDefaultState());
        structure.fillWithBlocks(world, start, 6, 1, 23, 6, 4, 28, Blocks.DIRT.getDefaultState());
        structure.fillWithBlocks(world, start, 6, 1, 29, 6, 1, 30, Blocks.STONE.getDefaultState());
        structure.fillWithBlocks(world, start, 6, 1, 31, 6, 2, 33, Blocks.DIRT.getDefaultState());
        structure.fillWithBlocks(world, start, 6, 1, 36, 6, 1, 36, Blocks.GRASS_BLOCK.getDefaultState().with(SnowyDirtBlock.SNOWY, false));
        structure.fillWithBlocks(world, start, 6, 2, 11, 6, 2, 12, Blocks.GRASS_BLOCK.getDefaultState().with(SnowyDirtBlock.SNOWY, false));
        structure.fillWithBlocks(world, start, 6, 2, 13, 8, 2, 15, Blocks.DIRT.getDefaultState());
        structure.fillWithBlocks(world, start, 6, 2, 34, 6, 2, 35, Blocks.GRASS_BLOCK.getDefaultState().with(SnowyDirtBlock.SNOWY, false));
        structure.fillWithBlocks(world, start, 6, 3, 14, 24, 3, 32, Blocks.DIRT.getDefaultState());
        structure.fillWithBlocks(world, start, 6, 4, 14, 6, 4, 15, Blocks.GRASS_BLOCK.getDefaultState().with(SnowyDirtBlock.SNOWY, false));
        structure.fillWithBlocks(world, start, 6, 4, 16, 20, 4, 30, Blocks.DIRT.getDefaultState());
        structure.fillWithBlocks(world, start, 6, 4, 31, 6, 4, 32, Blocks.GRASS_BLOCK.getDefaultState().with(SnowyDirtBlock.SNOWY, false));
        structure.fillWithBlocks(world, start, 6, 5, 16, 7, 5, 17, Blocks.GRASS_BLOCK.getDefaultState().with(SnowyDirtBlock.SNOWY, false));
        structure.fillWithBlocks(world, start, 6, 5, 18, 6, 5, 30, Blocks.GRASS_BLOCK.getDefaultState().with(SnowyDirtBlock.SNOWY, false));
        structure.fillWithBlocks(world, start, 7, 0, 9, 8, 0, 10, Blocks.DIRT.getDefaultState());
        structure.fillWithBlocks(world, start, 7, 0, 12, 29, 0, 34, Blocks.STONE.getDefaultState());
        structure.fillWithBlocks(world, start, 7, 0, 35, 7, 0, 37, Blocks.DIRT.getDefaultState());
        structure.fillWithBlocks(world, start, 7, 0, 38, 7, 0, 38, Blocks.GRASS_BLOCK.getDefaultState().with(SnowyDirtBlock.SNOWY, false));
        structure.fillWithBlocks(world, start, 7, 1, 10, 8, 1, 12, Blocks.DIRT.getDefaultState());
        structure.fillWithBlocks(world, start, 7, 1, 14, 16, 1, 28, Blocks.STONE.getDefaultState());
        structure.fillWithBlocks(world, start, 7, 1, 29, 7, 4, 29, Blocks.DIRT.getDefaultState());
        structure.fillWithBlocks(world, start, 7, 1, 30, 9, 1, 32, Blocks.STONE.getDefaultState());
        structure.fillWithBlocks(world, start, 7, 1, 33, 7, 1, 36, Blocks.DIRT.getDefaultState());
        structure.fillWithBlocks(world, start, 7, 1, 37, 7, 1, 37, Blocks.GRASS_BLOCK.getDefaultState().with(SnowyDirtBlock.SNOWY, false));
        structure.fillWithBlocks(world, start, 7, 2, 11, 9, 2, 13, Blocks.DIRT.getDefaultState());
        structure.fillWithBlocks(world, start, 7, 2, 18, 9, 2, 20, Blocks.STONE.getDefaultState());
        structure.fillWithBlocks(world, start, 7, 2, 21, 8, 2, 21, Blocks.STONE.getDefaultState());
        structure.fillWithBlocks(world, start, 7, 2, 22, 17, 2, 32, Blocks.DIRT.getDefaultState());
        structure.fillWithBlocks(world, start, 7, 2, 33, 9, 2, 35, Blocks.DIRT.getDefaultState());
        structure.fillWithBlocks(world, start, 7, 2, 36, 7, 2, 36, Blocks.GRASS_BLOCK.getDefaultState().with(SnowyDirtBlock.SNOWY, false));
        structure.fillWithBlocks(world, start, 7, 3, 12, 29, 3, 34, Blocks.DIRT.getDefaultState());
        structure.fillWithBlocks(world, start, 7, 3, 35, 7, 3, 35, Blocks.GRASS_BLOCK.getDefaultState().with(SnowyDirtBlock.SNOWY, false));
        structure.fillWithBlocks(world, start, 7, 4, 12, 7, 4, 13, Blocks.GRASS_BLOCK.getDefaultState().with(SnowyDirtBlock.SNOWY, false));
        structure.fillWithBlocks(world, start, 7, 4, 14, 25, 4, 32, Blocks.DIRT.getDefaultState());
        structure.fillWithBlocks(world, start, 7, 4, 33, 7, 4, 34, Blocks.GRASS_BLOCK.getDefaultState().with(SnowyDirtBlock.SNOWY, false));
        structure.fillWithBlocks(world, start, 7, 5, 14, 8, 5, 15, Blocks.GRASS_BLOCK.getDefaultState().with(SnowyDirtBlock.SNOWY, false));
        structure.fillWithBlocks(world, start, 7, 5, 18, 17, 5, 28, Blocks.DIRT.getDefaultState());
        structure.fillWithBlocks(world, start, 7, 5, 29, 7, 5, 32, Blocks.GRASS_BLOCK.getDefaultState().with(SnowyDirtBlock.SNOWY, false));
        structure.fillWithBlocks(world, start, 7, 6, 18, 11, 6, 28, Blocks.GRASS_BLOCK.getDefaultState().with(SnowyDirtBlock.SNOWY, false));
        structure.fillWithBlocks(world, start, 8, 0, 8, 9, 0, 10, Blocks.DIRT.getDefaultState());
        structure.fillWithBlocks(world, start, 8, 0, 11, 32, 0, 35, Blocks.STONE.getDefaultState());
        structure.fillWithBlocks(world, start, 8, 0, 36, 8, 0, 38, Blocks.DIRT.getDefaultState());
        structure.fillWithBlocks(world, start, 8, 0, 39, 8, 0, 39, Blocks.GRASS_BLOCK.getDefaultState().with(SnowyDirtBlock.SNOWY, false));
        structure.fillWithBlocks(world, start, 8, 1, 9, 9, 1, 10, Blocks.DIRT.getDefaultState());
        structure.fillWithBlocks(world, start, 8, 1, 13, 17, 1, 22, Blocks.STONE.getDefaultState());
        structure.fillWithBlocks(world, start, 8, 1, 29, 12, 1, 33, Blocks.STONE.getDefaultState());
        structure.fillWithBlocks(world, start, 8, 1, 34, 8, 2, 36, Blocks.DIRT.getDefaultState());
        structure.fillWithBlocks(world, start, 8, 1, 37, 8, 1, 37, Blocks.DIRT.getDefaultState());
        structure.fillWithBlocks(world, start, 8, 1, 38, 8, 1, 38, Blocks.GRASS_BLOCK.getDefaultState().with(SnowyDirtBlock.SNOWY, false));
        structure.fillWithBlocks(world, start, 8, 2, 10, 10, 2, 12, Blocks.DIRT.getDefaultState());
        structure.fillWithBlocks(world, start, 8, 2, 16, 10, 2, 20, Blocks.STONE.getDefaultState());
        structure.fillWithBlocks(world, start, 8, 2, 37, 8, 2, 37, Blocks.GRASS_BLOCK.getDefaultState().with(SnowyDirtBlock.SNOWY, false));
        structure.fillWithBlocks(world, start, 8, 3, 11, 32, 3, 35, Blocks.DIRT.getDefaultState());
        structure.fillWithBlocks(world, start, 8, 3, 36, 8, 3, 36, Blocks.GRASS_BLOCK.getDefaultState().with(SnowyDirtBlock.SNOWY, false));
        structure.fillWithBlocks(world, start, 8, 4, 11, 8, 4, 12, Blocks.GRASS_BLOCK.getDefaultState().with(SnowyDirtBlock.SNOWY, false));
        structure.fillWithBlocks(world, start, 8, 4, 13, 28, 4, 33, Blocks.DIRT.getDefaultState());
        structure.fillWithBlocks(world, start, 8, 4, 34, 8, 4, 35, Blocks.GRASS_BLOCK.getDefaultState().with(SnowyDirtBlock.SNOWY, false));
        structure.fillWithBlocks(world, start, 8, 5, 13, 8, 5, 15, Blocks.GRASS_BLOCK.getDefaultState().with(SnowyDirtBlock.SNOWY, false));
        structure.fillWithBlocks(world, start, 8, 5, 16, 22, 5, 30, Blocks.DIRT.getDefaultState());
        structure.fillWithBlocks(world, start, 8, 5, 31, 8, 5, 33, Blocks.GRASS_BLOCK.getDefaultState().with(SnowyDirtBlock.SNOWY, false));
        structure.fillWithBlocks(world, start, 8, 6, 16, 11, 6, 30, Blocks.GRASS_BLOCK.getDefaultState().with(SnowyDirtBlock.SNOWY, false));
        structure.fillWithBlocks(world, start, 9, 0, 7, 10, 0, 9, Blocks.DIRT.getDefaultState());
        structure.fillWithBlocks(world, start, 9, 0, 36, 9, 0, 36, Blocks.STONE.getDefaultState());
        structure.fillWithBlocks(world, start, 9, 0, 37, 9, 0, 39, Blocks.DIRT.getDefaultState());
        structure.fillWithBlocks(world, start, 9, 0, 40, 9, 0, 40, Blocks.GRASS_BLOCK.getDefaultState().with(SnowyDirtBlock.SNOWY, false));
        structure.fillWithBlocks(world, start, 9, 1, 8, 11, 1, 10, Blocks.DIRT.getDefaultState());
        structure.fillWithBlocks(world, start, 9, 1, 11, 18, 1, 20, Blocks.STONE.getDefaultState());
        structure.fillWithBlocks(world, start, 9, 1, 34, 10, 1, 35, Blocks.STONE.getDefaultState());
        structure.fillWithBlocks(world, start, 9, 1, 36, 9, 1, 38, Blocks.DIRT.getDefaultState());
        structure.fillWithBlocks(world, start, 9, 1, 39, 9, 1, 39, Blocks.GRASS_BLOCK.getDefaultState().with(SnowyDirtBlock.SNOWY, false));
        structure.fillWithBlocks(world, start, 9, 2, 9, 11, 2, 11, Blocks.DIRT.getDefaultState());
        structure.fillWithBlocks(world, start, 9, 2, 14, 12, 2, 17, Blocks.STONE.getDefaultState());
        structure.fillWithBlocks(world, start, 9, 2, 21, 20, 2, 32, Blocks.DIRT.getDefaultState());
        structure.fillWithBlocks(world, start, 9, 2, 36, 10, 2, 37, Blocks.DIRT.getDefaultState());
        structure.fillWithBlocks(world, start, 9, 2, 38, 9, 2, 38, Blocks.GRASS_BLOCK.getDefaultState().with(SnowyDirtBlock.SNOWY, false));
        structure.fillWithBlocks(world, start, 9, 3, 10, 35, 3, 36, Blocks.DIRT.getDefaultState());
        structure.fillWithBlocks(world, start, 9, 3, 37, 9, 3, 37, Blocks.GRASS_BLOCK.getDefaultState().with(SnowyDirtBlock.SNOWY, false));
        structure.fillWithBlocks(world, start, 9, 4, 11, 33, 4, 35, Blocks.DIRT.getDefaultState());
        structure.fillWithBlocks(world, start, 9, 4, 36, 9, 4, 36, Blocks.GRASS_BLOCK.getDefaultState().with(SnowyDirtBlock.SNOWY, false));
        structure.fillWithBlocks(world, start, 9, 5, 11, 10, 5, 12, Blocks.GRASS_BLOCK.getDefaultState().with(SnowyDirtBlock.SNOWY, false));
        structure.fillWithBlocks(world, start, 9, 5, 14, 27, 5, 32, Blocks.DIRT.getDefaultState());
        structure.fillWithBlocks(world, start, 9, 5, 33, 9, 5, 35, Blocks.GRASS_BLOCK.getDefaultState().with(SnowyDirtBlock.SNOWY, false));
        structure.fillWithBlocks(world, start, 9, 6, 14, 11, 6, 31, Blocks.GRASS_BLOCK.getDefaultState().with(SnowyDirtBlock.SNOWY, false));
        structure.fillWithBlocks(world, start, 9, 6, 32, 9, 6, 32, Blocks.GRASS_BLOCK.getDefaultState().with(SnowyDirtBlock.SNOWY, false));
        structure.fillWithBlocks(world, start, 10, 0, 5, 11, 0, 5, Blocks.GRASS_BLOCK.getDefaultState().with(SnowyDirtBlock.SNOWY, false));
        structure.fillWithBlocks(world, start, 10, 0, 6, 12, 0, 8, Blocks.DIRT.getDefaultState());
        structure.fillWithBlocks(world, start, 10, 0, 10, 35, 0, 35, Blocks.STONE.getDefaultState());
        structure.fillWithBlocks(world, start, 10, 0, 36, 11, 0, 37, Blocks.STONE.getDefaultState());
        structure.fillWithBlocks(world, start, 10, 0, 38, 10, 0, 40, Blocks.DIRT.getDefaultState());
        structure.fillWithBlocks(world, start, 10, 0, 41, 11, 0, 41, Blocks.GRASS_BLOCK.getDefaultState().with(SnowyDirtBlock.SNOWY, false));
        structure.fillWithBlocks(world, start, 10, 1, 7, 12, 1, 10, Blocks.DIRT.getDefaultState());
        structure.fillWithBlocks(world, start, 10, 1, 36, 10, 1, 36, Blocks.STONE.getDefaultState());
        structure.fillWithBlocks(world, start, 10, 1, 37, 10, 1, 39, Blocks.DIRT.getDefaultState());
        structure.fillWithBlocks(world, start, 10, 2, 8, 12, 2, 10, Blocks.DIRT.getDefaultState());
        structure.fillWithBlocks(world, start, 10, 2, 13, 12, 2, 17, Blocks.STONE.getDefaultState());
        structure.fillWithBlocks(world, start, 10, 2, 33, 10, 4, 36, Blocks.DIRT.getDefaultState());
        structure.fillWithBlocks(world, start, 10, 2, 38, 10, 2, 38, Blocks.DIRT.getDefaultState());
        structure.fillWithBlocks(world, start, 10, 2, 39, 10, 2, 39, Blocks.GRASS_BLOCK.getDefaultState().with(SnowyDirtBlock.SNOWY, false));
        structure.fillWithBlocks(world, start, 10, 3, 9, 36, 3, 37, Blocks.DIRT.getDefaultState());
        structure.fillWithBlocks(world, start, 10, 3, 38, 10, 3, 38, Blocks.GRASS_BLOCK.getDefaultState().with(SnowyDirtBlock.SNOWY, false));
        structure.fillWithBlocks(world, start, 10, 4, 10, 36, 4, 36, Blocks.DIRT.getDefaultState());
        structure.fillWithBlocks(world, start, 10, 4, 37, 10, 4, 37, Blocks.GRASS_BLOCK.getDefaultState().with(SnowyDirtBlock.SNOWY, false));
        structure.fillWithBlocks(world, start, 10, 5, 10, 10, 5, 12, Blocks.GRASS_BLOCK.getDefaultState().with(SnowyDirtBlock.SNOWY, false));
        structure.fillWithBlocks(world, start, 10, 5, 13, 30, 5, 33, Blocks.DIRT.getDefaultState());
        structure.fillWithBlocks(world, start, 10, 5, 34, 10, 5, 36, Blocks.GRASS_BLOCK.getDefaultState().with(SnowyDirtBlock.SNOWY, false));
        structure.fillWithBlocks(world, start, 10, 6, 13, 11, 6, 31, Blocks.GRASS_BLOCK.getDefaultState().with(SnowyDirtBlock.SNOWY, false));
        structure.fillWithBlocks(world, start, 10, 6, 32, 10, 6, 33, Blocks.GRASS_BLOCK.getDefaultState().with(SnowyDirtBlock.SNOWY, false));
        structure.fillWithBlocks(world, start, 11, 0, 9, 36, 0, 34, Blocks.STONE.getDefaultState());
        structure.fillWithBlocks(world, start, 11, 0, 38, 11, 0, 38, Blocks.STONE.getDefaultState());
        structure.fillWithBlocks(world, start, 11, 0, 39, 11, 0, 40, Blocks.DIRT.getDefaultState());
        structure.fillWithBlocks(world, start, 11, 1, 6, 13, 1, 9, Blocks.DIRT.getDefaultState());
        structure.fillWithBlocks(world, start, 11, 1, 34, 14, 1, 37, Blocks.STONE.getDefaultState());
        structure.fillWithBlocks(world, start, 11, 1, 38, 12, 1, 40, Blocks.DIRT.getDefaultState());
        structure.fillWithBlocks(world, start, 11, 2, 6, 12, 2, 6, Blocks.GRASS_BLOCK.getDefaultState().with(SnowyDirtBlock.SNOWY, false));
        structure.fillWithBlocks(world, start, 11, 2, 7, 14, 2, 10, Blocks.DIRT.getDefaultState());
        structure.fillWithBlocks(world, start, 11, 2, 12, 13, 2, 14, Blocks.STONE.getDefaultState());
        structure.fillWithBlocks(world, start, 11, 2, 19, 24, 2, 32, Blocks.DIRT.getDefaultState());
        structure.fillWithBlocks(world, start, 11, 2, 33, 12, 2, 34, Blocks.STONE.getDefaultState());
        structure.fillWithBlocks(world, start, 11, 2, 35, 11, 2, 39, Blocks.DIRT.getDefaultState());
        structure.fillWithBlocks(world, start, 11, 2, 40, 12, 2, 40, Blocks.GRASS_BLOCK.getDefaultState().with(SnowyDirtBlock.SNOWY, false));
        structure.fillWithBlocks(world, start, 11, 3, 8, 35, 3, 38, Blocks.DIRT.getDefaultState());
        structure.fillWithBlocks(world, start, 11, 4, 8, 12, 4, 8, Blocks.GRASS_BLOCK.getDefaultState().with(SnowyDirtBlock.SNOWY, false));
        structure.fillWithBlocks(world, start, 11, 4, 9, 35, 4, 37, Blocks.DIRT.getDefaultState());
        structure.fillWithBlocks(world, start, 11, 4, 38, 11, 4, 38, Blocks.GRASS_BLOCK.getDefaultState().with(SnowyDirtBlock.SNOWY, false));
        structure.fillWithBlocks(world, start, 11, 5, 9, 12, 5, 10, Blocks.GRASS_BLOCK.getDefaultState().with(SnowyDirtBlock.SNOWY, false));
        structure.fillWithBlocks(world, start, 11, 5, 11, 35, 5, 35, Blocks.DIRT.getDefaultState());
        structure.fillWithBlocks(world, start, 11, 5, 36, 12, 5, 37, Blocks.GRASS_BLOCK.getDefaultState().with(SnowyDirtBlock.SNOWY, false));
        structure.fillWithBlocks(world, start, 11, 6, 11, 11, 6, 31, Blocks.GRASS_BLOCK.getDefaultState().with(SnowyDirtBlock.SNOWY, false));
        structure.fillWithBlocks(world, start, 11, 6, 32, 11, 6, 33, Blocks.DIRT.getDefaultState());
        structure.fillWithBlocks(world, start, 11, 6, 34, 11, 6, 35, Blocks.GRASS_BLOCK.getDefaultState().with(SnowyDirtBlock.SNOWY, false));
        structure.fillWithBlocks(world, start, 11, 7, 14, 11, 7, 16, Blocks.GRASS.getDefaultState());
        structure.fillWithBlocks(world, start, 11, 7, 32, 11, 7, 33, Blocks.SMOOTH_STONE_SLAB.getDefaultState().with(SlabBlock.TYPE, SlabType.BOTTOM).with(SlabBlock.WATERLOGGED, false));
        structure.fillWithBlocks(world, start, 11, 7, 34, 11, 7, 35, Blocks.GRASS.getDefaultState());
        structure.fillWithBlocks(world, start, 12, 0, 5, 13, 0, 7, Blocks.DIRT.getDefaultState());
        structure.fillWithBlocks(world, start, 12, 0, 36, 15, 0, 39, Blocks.STONE.getDefaultState());
        structure.fillWithBlocks(world, start, 12, 0, 40, 13, 0, 41, Blocks.DIRT.getDefaultState());
        structure.fillWithBlocks(world, start, 12, 1, 41, 12, 1, 41, Blocks.GRASS_BLOCK.getDefaultState().with(SnowyDirtBlock.SNOWY, false));
        structure.fillWithBlocks(world, start, 12, 2, 11, 12, 2, 17, Blocks.STONE.getDefaultState());
        structure.fillWithBlocks(world, start, 12, 2, 18, 26, 2, 32, Blocks.DIRT.getDefaultState());
        structure.fillWithBlocks(world, start, 12, 2, 35, 12, 2, 35, Blocks.STONE.getDefaultState());
        structure.fillWithBlocks(world, start, 12, 2, 36, 12, 2, 39, Blocks.DIRT.getDefaultState());
        structure.fillWithBlocks(world, start, 12, 3, 7, 34, 3, 39, Blocks.DIRT.getDefaultState());
        structure.fillWithBlocks(world, start, 12, 4, 7, 12, 4, 8, Blocks.GRASS_BLOCK.getDefaultState().with(SnowyDirtBlock.SNOWY, false));
        structure.fillWithBlocks(world, start, 12, 4, 38, 12, 4, 39, Blocks.GRASS_BLOCK.getDefaultState().with(SnowyDirtBlock.SNOWY, false));
        structure.fillWithBlocks(world, start, 12, 6, 11, 35, 6, 11, Blocks.GRASS_BLOCK.getDefaultState().with(SnowyDirtBlock.SNOWY, false));
        structure.fillWithBlocks(world, start, 12, 6, 12, 12, 6, 21, Blocks.DIRT.getDefaultState());
        structure.fillWithBlocks(world, start, 12, 6, 22, 12, 6, 24, Blocks.GRASS_BLOCK.getDefaultState().with(SnowyDirtBlock.SNOWY, false));
        structure.fillWithBlocks(world, start, 12, 6, 25, 12, 6, 31, Blocks.DIRT.getDefaultState());
        structure.fillWithBlocks(world, start, 12, 6, 32, 13, 6, 33, Blocks.GRASS_BLOCK.getDefaultState().with(SnowyDirtBlock.SNOWY, false));
        structure.fillWithBlocks(world, start, 12, 6, 34, 12, 6, 34, Blocks.DIRT.getDefaultState());
        structure.fillWithBlocks(world, start, 12, 6, 35, 12, 6, 35, Blocks.GRASS_BLOCK.getDefaultState().with(SnowyDirtBlock.SNOWY, false));
        structure.fillWithBlocks(world, start, 12, 7, 12, 12, 7, 20, Blocks.SMOOTH_STONE_SLAB.getDefaultState().with(SlabBlock.TYPE, SlabType.BOTTOM).with(SlabBlock.WATERLOGGED, false));
        structure.fillWithBlocks(world, start, 12, 7, 21, 14, 7, 21, Blocks.MOSSY_COBBLESTONE.getDefaultState());
        structure.fillWithBlocks(world, start, 12, 7, 25, 15, 7, 25, Blocks.MOSSY_COBBLESTONE.getDefaultState());
        structure.fillWithBlocks(world, start, 12, 7, 26, 12, 7, 31, Blocks.SMOOTH_STONE_SLAB.getDefaultState().with(SlabBlock.TYPE, SlabType.BOTTOM).with(SlabBlock.WATERLOGGED, false));
        structure.fillWithBlocks(world, start, 12, 7, 32, 12, 7, 32, Blocks.WATER.getDefaultState());
        structure.fillWithBlocks(world, start, 12, 7, 33, 12, 7, 33, Blocks.WATER.getDefaultState());
        structure.fillWithBlocks(world, start, 12, 7, 34, 12, 7, 34, Blocks.SMOOTH_STONE_SLAB.getDefaultState().with(SlabBlock.TYPE, SlabType.BOTTOM).with(SlabBlock.WATERLOGGED, false));
        structure.fillWithBlocks(world, start, 13, 0, 4, 15, 0, 6, Blocks.DIRT.getDefaultState());
        structure.fillWithBlocks(world, start, 13, 0, 8, 35, 0, 35, Blocks.STONE.getDefaultState());
        structure.fillWithBlocks(world, start, 13, 0, 42, 33, 0, 42, Blocks.DIRT.getDefaultState());
        structure.fillWithBlocks(world, start, 13, 1, 4, 14, 1, 4, Blocks.GRASS_BLOCK.getDefaultState().with(SnowyDirtBlock.SNOWY, false));
        structure.fillWithBlocks(world, start, 13, 1, 5, 15, 1, 8, Blocks.DIRT.getDefaultState());
        structure.fillWithBlocks(world, start, 13, 1, 10, 20, 1, 17, Blocks.STONE.getDefaultState());
        structure.fillWithBlocks(world, start, 13, 1, 29, 20, 1, 38, Blocks.STONE.getDefaultState());
        structure.fillWithBlocks(world, start, 13, 1, 39, 13, 1, 41, Blocks.DIRT.getDefaultState());
        structure.fillWithBlocks(world, start, 13, 1, 42, 14, 1, 42, Blocks.GRASS_BLOCK.getDefaultState().with(SnowyDirtBlock.SNOWY, false));
        structure.fillWithBlocks(world, start, 13, 2, 6, 18, 2, 11, Blocks.DIRT.getDefaultState());
        structure.fillWithBlocks(world, start, 13, 2, 15, 30, 2, 32, Blocks.DIRT.getDefaultState());
        structure.fillWithBlocks(world, start, 13, 2, 33, 14, 2, 36, Blocks.STONE.getDefaultState());
        structure.fillWithBlocks(world, start, 13, 2, 37, 13, 2, 40, Blocks.DIRT.getDefaultState());
        structure.fillWithBlocks(world, start, 13, 3, 40, 13, 3, 40, Blocks.GRASS_BLOCK.getDefaultState().with(SnowyDirtBlock.SNOWY, false));
        structure.fillWithBlocks(world, start, 13, 4, 8, 33, 4, 38, Blocks.DIRT.getDefaultState());
        structure.fillWithBlocks(world, start, 13, 4, 39, 13, 4, 39, Blocks.GRASS_BLOCK.getDefaultState().with(SnowyDirtBlock.SNOWY, false));
        structure.fillWithBlocks(world, start, 13, 5, 8, 13, 5, 9, Blocks.GRASS_BLOCK.getDefaultState().with(SnowyDirtBlock.SNOWY, false));
        structure.fillWithBlocks(world, start, 13, 5, 10, 33, 5, 36, Blocks.DIRT.getDefaultState());
        structure.fillWithBlocks(world, start, 13, 5, 37, 13, 5, 38, Blocks.GRASS_BLOCK.getDefaultState().with(SnowyDirtBlock.SNOWY, false));
        structure.fillWithBlocks(world, start, 13, 6, 10, 14, 6, 11, Blocks.GRASS_BLOCK.getDefaultState().with(SnowyDirtBlock.SNOWY, false));
        structure.fillWithBlocks(world, start, 13, 6, 12, 21, 6, 12, Blocks.DIRT.getDefaultState());
        structure.fillWithBlocks(world, start, 13, 6, 13, 13, 6, 16, Blocks.GRASS_BLOCK.getDefaultState().with(SnowyDirtBlock.SNOWY, false));
        structure.fillWithBlocks(world, start, 13, 6, 17, 13, 6, 17, Blocks.DIRT.getDefaultState());
        structure.fillWithBlocks(world, start, 13, 6, 18, 13, 6, 20, Blocks.GRASS_BLOCK.getDefaultState().with(SnowyDirtBlock.SNOWY, false));
        structure.fillWithBlocks(world, start, 13, 6, 21, 13, 6, 25, Blocks.DIRT.getDefaultState());
        structure.fillWithBlocks(world, start, 13, 6, 26, 13, 6, 28, Blocks.GRASS_BLOCK.getDefaultState().with(SnowyDirtBlock.SNOWY, false));
        structure.fillWithBlocks(world, start, 13, 6, 29, 13, 6, 29, Blocks.DIRT.getDefaultState());
        structure.fillWithBlocks(world, start, 13, 6, 30, 13, 6, 34, Blocks.GRASS_BLOCK.getDefaultState().with(SnowyDirtBlock.SNOWY, false));
        structure.fillWithBlocks(world, start, 13, 6, 35, 14, 6, 35, Blocks.DIRT.getDefaultState());
        structure.fillWithBlocks(world, start, 13, 6, 36, 13, 6, 36, Blocks.GRASS_BLOCK.getDefaultState().with(SnowyDirtBlock.SNOWY, false));
        structure.fillWithBlocks(world, start, 13, 7, 12, 20, 7, 12, Blocks.SMOOTH_STONE_SLAB.getDefaultState().with(SlabBlock.TYPE, SlabType.BOTTOM).with(SlabBlock.WATERLOGGED, false));
        structure.fillWithBlocks(world, start, 13, 7, 22, 13, 7, 24, Blocks.COBBLESTONE_STAIRS.getDefaultState().with(StairsBlock.FACING, Direction.EAST).with(StairsBlock.WATERLOGGED, false).with(StairsBlock.SHAPE, StairsShape.STRAIGHT).with(StairsBlock.HALF, Half.BOTTOM));
        structure.fillWithBlocks(world, start, 13, 7, 32, 13, 7, 32, Blocks.WATER.getDefaultState());
        structure.fillWithBlocks(world, start, 13, 7, 33, 13, 7, 33, Blocks.WATER.getDefaultState());
        structure.fillWithBlocks(world, start, 13, 7, 35, 14, 7, 35, Blocks.SMOOTH_STONE_SLAB.getDefaultState().with(SlabBlock.TYPE, SlabType.BOTTOM).with(SlabBlock.WATERLOGGED, false));
        structure.fillWithBlocks(world, start, 14, 0, 3, 15, 0, 3, Blocks.GRASS_BLOCK.getDefaultState().with(SnowyDirtBlock.SNOWY, false));
        structure.fillWithBlocks(world, start, 14, 0, 7, 34, 0, 35, Blocks.STONE.getDefaultState());
        structure.fillWithBlocks(world, start, 14, 0, 40, 30, 0, 40, Blocks.STONE.getDefaultState());
        structure.fillWithBlocks(world, start, 14, 0, 41, 15, 0, 42, Blocks.DIRT.getDefaultState());
        structure.fillWithBlocks(world, start, 14, 0, 43, 15, 0, 43, Blocks.GRASS_BLOCK.getDefaultState().with(SnowyDirtBlock.SNOWY, false));
        structure.fillWithBlocks(world, start, 14, 1, 9, 21, 1, 16, Blocks.STONE.getDefaultState());
        structure.fillWithBlocks(world, start, 14, 1, 39, 28, 1, 39, Blocks.STONE.getDefaultState());
        structure.fillWithBlocks(world, start, 14, 1, 40, 15, 1, 41, Blocks.DIRT.getDefaultState());
        structure.fillWithBlocks(world, start, 14, 2, 5, 32, 2, 32, Blocks.DIRT.getDefaultState());
        structure.fillWithBlocks(world, start, 14, 2, 37, 21, 2, 37, Blocks.STONE.getDefaultState());
        structure.fillWithBlocks(world, start, 14, 2, 38, 15, 2, 41, Blocks.DIRT.getDefaultState());
        structure.fillWithBlocks(world, start, 14, 3, 5, 15, 3, 5, Blocks.GRASS_BLOCK.getDefaultState().with(SnowyDirtBlock.SNOWY, false));
        structure.fillWithBlocks(world, start, 14, 3, 6, 32, 3, 40, Blocks.DIRT.getDefaultState());
        structure.fillWithBlocks(world, start, 14, 3, 41, 15, 3, 41, Blocks.GRASS_BLOCK.getDefaultState().with(SnowyDirtBlock.SNOWY, false));
        structure.fillWithBlocks(world, start, 14, 4, 6, 15, 4, 6, Blocks.GRASS_BLOCK.getDefaultState().with(SnowyDirtBlock.SNOWY, false));
        structure.fillWithBlocks(world, start, 14, 4, 7, 32, 4, 39, Blocks.DIRT.getDefaultState());
        structure.fillWithBlocks(world, start, 14, 4, 40, 15, 4, 40, Blocks.GRASS_BLOCK.getDefaultState().with(SnowyDirtBlock.SNOWY, false));
        structure.fillWithBlocks(world, start, 14, 5, 7, 15, 5, 8, Blocks.GRASS_BLOCK.getDefaultState().with(SnowyDirtBlock.SNOWY, false));
        structure.fillWithBlocks(world, start, 14, 5, 9, 32, 5, 37, Blocks.DIRT.getDefaultState());
        structure.fillWithBlocks(world, start, 14, 5, 38, 15, 5, 39, Blocks.GRASS_BLOCK.getDefaultState().with(SnowyDirtBlock.SNOWY, false));
        structure.fillWithBlocks(world, start, 14, 6, 9, 16, 6, 11, Blocks.GRASS_BLOCK.getDefaultState().with(SnowyDirtBlock.SNOWY, false));
        structure.fillWithBlocks(world, start, 14, 6, 13, 16, 6, 13, Blocks.GRASS_BLOCK.getDefaultState().with(SnowyDirtBlock.SNOWY, false));
        structure.fillWithBlocks(world, start, 14, 6, 14, 14, 6, 21, Blocks.DIRT.getDefaultState());
        structure.fillWithBlocks(world, start, 14, 6, 22, 16, 6, 24, Blocks.GRASS_BLOCK.getDefaultState().with(SnowyDirtBlock.SNOWY, false));
        structure.fillWithBlocks(world, start, 14, 6, 25, 14, 6, 32, Blocks.DIRT.getDefaultState());
        structure.fillWithBlocks(world, start, 14, 6, 33, 14, 6, 34, Blocks.GRASS_BLOCK.getDefaultState().with(SnowyDirtBlock.SNOWY, false));
        structure.fillWithBlocks(world, start, 14, 6, 36, 15, 6, 37, Blocks.GRASS_BLOCK.getDefaultState().with(SnowyDirtBlock.SNOWY, false));
        structure.fillWithBlocks(world, start, 14, 7, 16, 14, 7, 20, Blocks.STONE.getDefaultState());
        structure.fillWithBlocks(world, start, 14, 7, 26, 14, 7, 31, Blocks.STONE.getDefaultState());
        structure.fillWithBlocks(world, start, 14, 8, 18, 14, 8, 20, Blocks.COBBLESTONE_STAIRS.getDefaultState().with(StairsBlock.FACING, Direction.EAST).with(StairsBlock.WATERLOGGED, false).with(StairsBlock.SHAPE, StairsShape.STRAIGHT).with(StairsBlock.HALF, Half.BOTTOM));
        structure.fillWithBlocks(world, start, 14, 8, 21, 15, 8, 21, Blocks.MOSSY_COBBLESTONE.getDefaultState());
        structure.fillWithBlocks(world, start, 14, 8, 22, 14, 8, 24, Blocks.COBBLESTONE_STAIRS.getDefaultState().with(StairsBlock.FACING, Direction.EAST).with(StairsBlock.WATERLOGGED, false).with(StairsBlock.SHAPE, StairsShape.STRAIGHT).with(StairsBlock.HALF, Half.BOTTOM));
        structure.fillWithBlocks(world, start, 14, 8, 25, 16, 8, 25, Blocks.MOSSY_COBBLESTONE.getDefaultState());
        structure.fillWithBlocks(world, start, 14, 8, 26, 14, 8, 28, Blocks.COBBLESTONE_STAIRS.getDefaultState().with(StairsBlock.FACING, Direction.EAST).with(StairsBlock.WATERLOGGED, false).with(StairsBlock.SHAPE, StairsShape.STRAIGHT).with(StairsBlock.HALF, Half.BOTTOM));
        structure.fillWithBlocks(world, start, 14, 8, 31, 14, 8, 31, Blocks.COBBLESTONE_SLAB.getDefaultState().with(SlabBlock.TYPE, SlabType.BOTTOM).with(SlabBlock.WATERLOGGED, false));
        structure.fillWithBlocks(world, start, 15, 1, 4, 17, 1, 7, Blocks.DIRT.getDefaultState());
        structure.fillWithBlocks(world, start, 15, 1, 42, 31, 1, 42, Blocks.DIRT.getDefaultState());
        structure.fillWithBlocks(world, start, 15, 2, 4, 16, 2, 4, Blocks.GRASS_BLOCK.getDefaultState().with(SnowyDirtBlock.SNOWY, false));
        structure.fillWithBlocks(world, start, 15, 2, 33, 36, 5, 33, Blocks.DIRT.getDefaultState());
        structure.fillWithBlocks(world, start, 15, 2, 34, 17, 2, 37, Blocks.STONE.getDefaultState());
        structure.fillWithBlocks(world, start, 15, 2, 42, 16, 2, 42, Blocks.GRASS_BLOCK.getDefaultState().with(SnowyDirtBlock.SNOWY, false));
        structure.fillWithBlocks(world, start, 15, 6, 14, 21, 6, 14, Blocks.DIRT.getDefaultState());
        structure.fillWithBlocks(world, start, 15, 6, 15, 17, 6, 17, Blocks.GRASS_BLOCK.getDefaultState().with(SnowyDirtBlock.SNOWY, false));
        structure.fillWithBlocks(world, start, 15, 6, 18, 15, 6, 24, Blocks.GRASS_BLOCK.getDefaultState().with(SnowyDirtBlock.SNOWY, false));
        structure.fillWithBlocks(world, start, 15, 6, 26, 17, 6, 28, Blocks.GRASS_BLOCK.getDefaultState().with(SnowyDirtBlock.SNOWY, false));
        structure.fillWithBlocks(world, start, 15, 6, 29, 15, 6, 31, Blocks.GRASS_BLOCK.getDefaultState().with(SnowyDirtBlock.SNOWY, false));
        structure.fillWithBlocks(world, start, 15, 6, 32, 32, 6, 32, Blocks.DIRT.getDefaultState());
        structure.fillWithBlocks(world, start, 15, 6, 33, 16, 6, 33, Blocks.GRASS_BLOCK.getDefaultState().with(SnowyDirtBlock.SNOWY, false));
        structure.fillWithBlocks(world, start, 15, 6, 34, 21, 6, 34, Blocks.DIRT.getDefaultState());
        structure.fillWithBlocks(world, start, 15, 6, 35, 17, 6, 37, Blocks.GRASS_BLOCK.getDefaultState().with(SnowyDirtBlock.SNOWY, false));
        structure.fillWithBlocks(world, start, 15, 7, 32, 20, 7, 32, Blocks.STONE.getDefaultState());
        structure.fillWithBlocks(world, start, 15, 7, 34, 20, 7, 34, Blocks.SMOOTH_STONE_SLAB.getDefaultState().with(SlabBlock.TYPE, SlabType.BOTTOM).with(SlabBlock.WATERLOGGED, false));
        structure.fillWithBlocks(world, start, 15, 8, 16, 15, 8, 16, Blocks.COBBLESTONE.getDefaultState());
        structure.fillWithBlocks(world, start, 15, 8, 17, 15, 8, 20, Blocks.STONE.getDefaultState());
        structure.fillWithBlocks(world, start, 15, 8, 26, 15, 8, 30, Blocks.STONE.getDefaultState());
        structure.fillWithBlocks(world, start, 15, 9, 18, 15, 9, 20, Blocks.COBBLESTONE_STAIRS.getDefaultState().with(StairsBlock.FACING, Direction.EAST).with(StairsBlock.WATERLOGGED, false).with(StairsBlock.SHAPE, StairsShape.STRAIGHT).with(StairsBlock.HALF, Half.BOTTOM));
        structure.fillWithBlocks(world, start, 15, 9, 21, 16, 9, 21, Blocks.MOSSY_COBBLESTONE.getDefaultState());
        structure.fillWithBlocks(world, start, 15, 9, 22, 15, 9, 24, Blocks.COBBLESTONE_STAIRS.getDefaultState().with(StairsBlock.FACING, Direction.EAST).with(StairsBlock.WATERLOGGED, false).with(StairsBlock.SHAPE, StairsShape.STRAIGHT).with(StairsBlock.HALF, Half.BOTTOM));
        structure.fillWithBlocks(world, start, 15, 9, 25, 17, 9, 25, Blocks.MOSSY_COBBLESTONE.getDefaultState());
        structure.fillWithBlocks(world, start, 15, 9, 26, 15, 9, 28, Blocks.COBBLESTONE_STAIRS.getDefaultState().with(StairsBlock.FACING, Direction.EAST).with(StairsBlock.WATERLOGGED, false).with(StairsBlock.SHAPE, StairsShape.STRAIGHT).with(StairsBlock.HALF, Half.BOTTOM));
        structure.fillWithBlocks(world, start, 15, 9, 30, 15, 9, 30, Blocks.COBBLESTONE_SLAB.getDefaultState().with(SlabBlock.TYPE, SlabType.BOTTOM).with(SlabBlock.WATERLOGGED, false));
        structure.fillWithBlocks(world, start, 16, 0, 2, 18, 0, 2, Blocks.GRASS_BLOCK.getDefaultState().with(SnowyDirtBlock.SNOWY, false));
        structure.fillWithBlocks(world, start, 16, 0, 3, 18, 0, 5, Blocks.DIRT.getDefaultState());
        structure.fillWithBlocks(world, start, 16, 0, 6, 30, 0, 40, Blocks.STONE.getDefaultState());
        structure.fillWithBlocks(world, start, 16, 0, 41, 27, 0, 41, Blocks.STONE.getDefaultState());
        structure.fillWithBlocks(world, start, 16, 0, 43, 30, 0, 43, Blocks.DIRT.getDefaultState());
        structure.fillWithBlocks(world, start, 16, 0, 44, 18, 0, 44, Blocks.GRASS_BLOCK.getDefaultState().with(SnowyDirtBlock.SNOWY, false));
        structure.fillWithBlocks(world, start, 16, 1, 3, 17, 1, 3, Blocks.GRASS_BLOCK.getDefaultState().with(SnowyDirtBlock.SNOWY, false));
        structure.fillWithBlocks(world, start, 16, 1, 8, 22, 1, 15, Blocks.STONE.getDefaultState());
        structure.fillWithBlocks(world, start, 16, 1, 40, 22, 1, 40, Blocks.STONE.getDefaultState());
        structure.fillWithBlocks(world, start, 16, 1, 41, 17, 1, 42, Blocks.DIRT.getDefaultState());
        structure.fillWithBlocks(world, start, 16, 1, 43, 17, 1, 43, Blocks.GRASS_BLOCK.getDefaultState().with(SnowyDirtBlock.SNOWY, false));
        structure.fillWithBlocks(world, start, 16, 2, 38, 21, 2, 38, Blocks.STONE.getDefaultState());
        structure.fillWithBlocks(world, start, 16, 2, 39, 17, 2, 41, Blocks.DIRT.getDefaultState());
        structure.fillWithBlocks(world, start, 16, 3, 5, 30, 3, 41, Blocks.DIRT.getDefaultState());
        structure.fillWithBlocks(world, start, 16, 4, 5, 18, 4, 5, Blocks.GRASS_BLOCK.getDefaultState().with(SnowyDirtBlock.SNOWY, false));
        structure.fillWithBlocks(world, start, 16, 4, 6, 30, 4, 40, Blocks.DIRT.getDefaultState());
        structure.fillWithBlocks(world, start, 16, 4, 41, 18, 4, 41, Blocks.GRASS_BLOCK.getDefaultState().with(SnowyDirtBlock.SNOWY, false));
        structure.fillWithBlocks(world, start, 16, 5, 6, 17, 5, 7, Blocks.GRASS_BLOCK.getDefaultState().with(SnowyDirtBlock.SNOWY, false));
        structure.fillWithBlocks(world, start, 16, 5, 8, 30, 5, 38, Blocks.DIRT.getDefaultState());
        structure.fillWithBlocks(world, start, 16, 5, 39, 17, 5, 40, Blocks.GRASS_BLOCK.getDefaultState().with(SnowyDirtBlock.SNOWY, false));
        structure.fillWithBlocks(world, start, 16, 6, 8, 19, 6, 11, Blocks.GRASS_BLOCK.getDefaultState().with(SnowyDirtBlock.SNOWY, false));
        structure.fillWithBlocks(world, start, 16, 6, 19, 24, 6, 28, Blocks.GRASS_BLOCK.getDefaultState().with(SnowyDirtBlock.SNOWY, false));
        structure.fillWithBlocks(world, start, 16, 6, 29, 16, 6, 29, Blocks.DIRT.getDefaultState());
        structure.fillWithBlocks(world, start, 16, 6, 30, 16, 6, 31, Blocks.GRASS_BLOCK.getDefaultState().with(SnowyDirtBlock.SNOWY, false));
        structure.fillWithBlocks(world, start, 16, 6, 38, 30, 6, 38, Blocks.GRASS_BLOCK.getDefaultState().with(SnowyDirtBlock.SNOWY, false));
        structure.fillWithBlocks(world, start, 16, 7, 14, 20, 7, 14, Blocks.STONE.getDefaultState());
        structure.fillWithBlocks(world, start, 16, 7, 29, 16, 8, 29, Blocks.STONE.getDefaultState());
        structure.fillWithBlocks(world, start, 16, 8, 15, 16, 8, 17, Blocks.COBBLESTONE.getDefaultState());
        structure.fillWithBlocks(world, start, 16, 8, 31, 20, 8, 31, Blocks.STONE.getDefaultState());
        structure.fillWithBlocks(world, start, 16, 9, 18, 18, 9, 20, Blocks.STONE.getDefaultState());
        structure.fillWithBlocks(world, start, 16, 9, 26, 18, 9, 28, Blocks.STONE.getDefaultState());
        structure.fillWithBlocks(world, start, 16, 9, 29, 16, 9, 29, Blocks.WATER.getDefaultState());
        structure.fillWithBlocks(world, start, 16, 9, 30, 16, 9, 31, Blocks.COBBLESTONE_SLAB.getDefaultState().with(SlabBlock.TYPE, SlabType.BOTTOM).with(SlabBlock.WATERLOGGED, false));
        structure.fillWithBlocks(world, start, 16, 10, 18, 16, 10, 20, Blocks.SMOOTH_STONE_SLAB.getDefaultState().with(SlabBlock.TYPE, SlabType.BOTTOM).with(SlabBlock.WATERLOGGED, false));
        structure.fillWithBlocks(world, start, 16, 10, 21, 20, 10, 21, Blocks.MOSSY_COBBLESTONE.getDefaultState());
        structure.fillWithBlocks(world, start, 16, 10, 22, 16, 10, 24, Blocks.COBBLESTONE_STAIRS.getDefaultState().with(StairsBlock.FACING, Direction.EAST).with(StairsBlock.WATERLOGGED, false).with(StairsBlock.SHAPE, StairsShape.STRAIGHT).with(StairsBlock.HALF, Half.BOTTOM));
        structure.fillWithBlocks(world, start, 16, 10, 25, 20, 10, 25, Blocks.MOSSY_COBBLESTONE.getDefaultState());
        structure.fillWithBlocks(world, start, 16, 10, 26, 16, 10, 28, Blocks.SMOOTH_STONE_SLAB.getDefaultState().with(SlabBlock.TYPE, SlabType.BOTTOM).with(SlabBlock.WATERLOGGED, false));
        structure.fillWithBlocks(world, start, 16, 10, 29, 16, 10, 29, Blocks.WATER.getDefaultState());
        structure.fillWithBlocks(world, start, 17, 1, 23, 20, 1, 26, Blocks.DIRT.getDefaultState());
        structure.fillWithBlocks(world, start, 17, 1, 27, 17, 1, 40, Blocks.STONE.getDefaultState());
        structure.fillWithBlocks(world, start, 17, 2, 4, 29, 2, 33, Blocks.DIRT.getDefaultState());
        structure.fillWithBlocks(world, start, 17, 2, 42, 29, 2, 42, Blocks.DIRT.getDefaultState());
        structure.fillWithBlocks(world, start, 17, 3, 4, 18, 3, 4, Blocks.GRASS_BLOCK.getDefaultState().with(SnowyDirtBlock.SNOWY, false));
        structure.fillWithBlocks(world, start, 17, 3, 42, 18, 3, 42, Blocks.GRASS_BLOCK.getDefaultState().with(SnowyDirtBlock.SNOWY, false));
        structure.fillWithBlocks(world, start, 17, 6, 13, 17, 6, 14, Blocks.DIRT.getDefaultState());
        structure.fillWithBlocks(world, start, 17, 6, 18, 24, 6, 29, Blocks.GRASS_BLOCK.getDefaultState().with(SnowyDirtBlock.SNOWY, false));
        structure.fillWithBlocks(world, start, 17, 6, 31, 24, 6, 31, Blocks.GRASS_BLOCK.getDefaultState().with(SnowyDirtBlock.SNOWY, false));
        structure.fillWithBlocks(world, start, 17, 6, 33, 17, 6, 34, Blocks.DIRT.getDefaultState());
        structure.fillWithBlocks(world, start, 17, 7, 30, 17, 8, 30, Blocks.STONE.getDefaultState());
        structure.fillWithBlocks(world, start, 17, 8, 15, 20, 8, 15, Blocks.STONE.getDefaultState());
        structure.fillWithBlocks(world, start, 17, 9, 17, 20, 9, 20, Blocks.STONE.getDefaultState());
        structure.fillWithBlocks(world, start, 17, 9, 29, 17, 9, 29, Blocks.STONE.getDefaultState());
        structure.fillWithBlocks(world, start, 17, 10, 26, 17, 10, 26, Blocks.WATER.getDefaultState());
        structure.fillWithBlocks(world, start, 17, 10, 28, 17, 10, 28, Blocks.WATER.getDefaultState());
        structure.fillWithBlocks(world, start, 17, 11, 21, 20, 11, 21, Blocks.MOSSY_COBBLESTONE.getDefaultState());
        structure.fillWithBlocks(world, start, 17, 11, 22, 17, 11, 24, Blocks.COBBLESTONE_STAIRS.getDefaultState().with(StairsBlock.FACING, Direction.EAST).with(StairsBlock.WATERLOGGED, false).with(StairsBlock.SHAPE, StairsShape.STRAIGHT).with(StairsBlock.HALF, Half.BOTTOM));
        structure.fillWithBlocks(world, start, 17, 11, 25, 20, 11, 25, Blocks.MOSSY_COBBLESTONE.getDefaultState());
        structure.fillWithBlocks(world, start, 17, 16, 21, 18, 16, 22, Blocks.COBBLESTONE.getDefaultState());
        structure.fillWithBlocks(world, start, 17, 16, 24, 18, 16, 25, Blocks.COBBLESTONE.getDefaultState());
        structure.fillWithBlocks(world, start, 17, 17, 21, 17, 18, 21, Blocks.OAK_FENCE.getDefaultState().with(FourWayBlock.WATERLOGGED, false).with(FourWayBlock.NORTH, false).with(FourWayBlock.SOUTH, false).with(FourWayBlock.EAST, true).with(FourWayBlock.WEST, false));
        structure.fillWithBlocks(world, start, 17, 17, 25, 17, 18, 25, Blocks.OAK_FENCE.getDefaultState().with(FourWayBlock.WATERLOGGED, false).with(FourWayBlock.NORTH, false).with(FourWayBlock.SOUTH, false).with(FourWayBlock.EAST, true).with(FourWayBlock.WEST, false));
        structure.fillWithBlocks(world, start, 17, 19, 21, 18, 19, 25, Blocks.COBBLESTONE.getDefaultState());
        structure.fillWithBlocks(world, start, 18, 1, 3, 21, 1, 6, Blocks.DIRT.getDefaultState());
        structure.fillWithBlocks(world, start, 18, 1, 7, 24, 1, 13, Blocks.STONE.getDefaultState());
        structure.fillWithBlocks(world, start, 18, 1, 21, 24, 1, 27, Blocks.DIRT.getDefaultState());
        structure.fillWithBlocks(world, start, 18, 1, 28, 18, 1, 40, Blocks.STONE.getDefaultState());
        structure.fillWithBlocks(world, start, 18, 1, 41, 18, 1, 43, Blocks.DIRT.getDefaultState());
        structure.fillWithBlocks(world, start, 18, 2, 3, 20, 2, 3, Blocks.GRASS_BLOCK.getDefaultState().with(SnowyDirtBlock.SNOWY, false));
        structure.fillWithBlocks(world, start, 18, 2, 34, 35, 5, 34, Blocks.DIRT.getDefaultState());
        structure.fillWithBlocks(world, start, 18, 2, 35, 19, 2, 39, Blocks.STONE.getDefaultState());
        structure.fillWithBlocks(world, start, 18, 2, 40, 20, 2, 42, Blocks.DIRT.getDefaultState());
        structure.fillWithBlocks(world, start, 18, 2, 43, 20, 2, 43, Blocks.GRASS_BLOCK.getDefaultState().with(SnowyDirtBlock.SNOWY, false));
        structure.fillWithBlocks(world, start, 18, 5, 6, 30, 5, 6, Blocks.GRASS_BLOCK.getDefaultState().with(SnowyDirtBlock.SNOWY, false));
        structure.fillWithBlocks(world, start, 18, 5, 7, 28, 5, 39, Blocks.DIRT.getDefaultState());
        structure.fillWithBlocks(world, start, 18, 5, 40, 18, 5, 40, Blocks.GRASS_BLOCK.getDefaultState().with(SnowyDirtBlock.SNOWY, false));
        structure.fillWithBlocks(world, start, 18, 6, 7, 22, 6, 11, Blocks.GRASS_BLOCK.getDefaultState().with(SnowyDirtBlock.SNOWY, false));
        structure.fillWithBlocks(world, start, 18, 6, 13, 20, 6, 13, Blocks.GRASS_BLOCK.getDefaultState().with(SnowyDirtBlock.SNOWY, false));
        structure.fillWithBlocks(world, start, 18, 6, 15, 28, 6, 25, Blocks.GRASS_BLOCK.getDefaultState().with(SnowyDirtBlock.SNOWY, false));
        structure.fillWithBlocks(world, start, 18, 6, 30, 19, 6, 31, Blocks.GRASS_BLOCK.getDefaultState().with(SnowyDirtBlock.SNOWY, false));
        structure.fillWithBlocks(world, start, 18, 6, 33, 20, 6, 33, Blocks.GRASS_BLOCK.getDefaultState().with(SnowyDirtBlock.SNOWY, false));
        structure.fillWithBlocks(world, start, 18, 6, 35, 21, 6, 39, Blocks.GRASS_BLOCK.getDefaultState().with(SnowyDirtBlock.SNOWY, false));
        structure.fillWithBlocks(world, start, 18, 7, 35, 19, 7, 35, Blocks.GRASS.getDefaultState());
        structure.fillWithBlocks(world, start, 18, 8, 14, 20, 8, 14, Blocks.COBBLESTONE_STAIRS.getDefaultState().with(StairsBlock.FACING, Direction.SOUTH).with(StairsBlock.WATERLOGGED, false).with(StairsBlock.SHAPE, StairsShape.STRAIGHT).with(StairsBlock.HALF, Half.BOTTOM));
        structure.fillWithBlocks(world, start, 18, 8, 32, 20, 8, 32, Blocks.COBBLESTONE_STAIRS.getDefaultState().with(StairsBlock.FACING, Direction.NORTH).with(StairsBlock.WATERLOGGED, false).with(StairsBlock.SHAPE, StairsShape.STRAIGHT).with(StairsBlock.HALF, Half.BOTTOM));
        structure.fillWithBlocks(world, start, 18, 9, 15, 20, 9, 15, Blocks.COBBLESTONE_STAIRS.getDefaultState().with(StairsBlock.FACING, Direction.SOUTH).with(StairsBlock.WATERLOGGED, false).with(StairsBlock.SHAPE, StairsShape.STRAIGHT).with(StairsBlock.HALF, Half.BOTTOM));
        structure.fillWithBlocks(world, start, 18, 9, 16, 20, 9, 20, Blocks.STONE.getDefaultState());
        structure.fillWithBlocks(world, start, 18, 9, 29, 19, 9, 30, Blocks.STONE.getDefaultState());
        structure.fillWithBlocks(world, start, 18, 9, 31, 20, 9, 31, Blocks.COBBLESTONE_STAIRS.getDefaultState().with(StairsBlock.FACING, Direction.NORTH).with(StairsBlock.WATERLOGGED, false).with(StairsBlock.SHAPE, StairsShape.STRAIGHT).with(StairsBlock.HALF, Half.BOTTOM));
        structure.fillWithBlocks(world, start, 18, 10, 16, 20, 10, 16, Blocks.SMOOTH_STONE_SLAB.getDefaultState().with(SlabBlock.TYPE, SlabType.BOTTOM).with(SlabBlock.WATERLOGGED, false));
        structure.fillWithBlocks(world, start, 18, 10, 18, 18, 11, 18, Blocks.COBBLESTONE.getDefaultState());
        structure.fillWithBlocks(world, start, 18, 10, 26, 18, 10, 26, Blocks.WATER.getDefaultState());
        structure.fillWithBlocks(world, start, 18, 10, 27, 18, 10, 27, Blocks.WATER.getDefaultState());
        structure.fillWithBlocks(world, start, 18, 10, 28, 18, 11, 28, Blocks.COBBLESTONE.getDefaultState());
        structure.fillWithBlocks(world, start, 18, 10, 30, 20, 10, 30, Blocks.SMOOTH_STONE_SLAB.getDefaultState().with(SlabBlock.TYPE, SlabType.BOTTOM).with(SlabBlock.WATERLOGGED, false));
        structure.fillWithBlocks(world, start, 18, 12, 19, 18, 12, 20, Blocks.COBBLESTONE_SLAB.getDefaultState().with(SlabBlock.TYPE, SlabType.BOTTOM).with(SlabBlock.WATERLOGGED, false));
        structure.fillWithBlocks(world, start, 18, 12, 21, 21, 12, 21, Blocks.MOSSY_COBBLESTONE.getDefaultState());
        structure.fillWithBlocks(world, start, 18, 12, 22, 18, 12, 24, Blocks.COBBLESTONE_STAIRS.getDefaultState().with(StairsBlock.FACING, Direction.EAST).with(StairsBlock.WATERLOGGED, false).with(StairsBlock.SHAPE, StairsShape.STRAIGHT).with(StairsBlock.HALF, Half.BOTTOM));
        structure.fillWithBlocks(world, start, 18, 12, 25, 21, 12, 25, Blocks.MOSSY_COBBLESTONE.getDefaultState());
        structure.fillWithBlocks(world, start, 18, 12, 26, 18, 12, 27, Blocks.COBBLESTONE_SLAB.getDefaultState().with(SlabBlock.TYPE, SlabType.BOTTOM).with(SlabBlock.WATERLOGGED, false));
        structure.fillWithBlocks(world, start, 18, 13, 21, 18, 15, 21, Blocks.MOSSY_COBBLESTONE.getDefaultState());
        structure.fillWithBlocks(world, start, 18, 13, 25, 18, 15, 25, Blocks.MOSSY_COBBLESTONE.getDefaultState());
        structure.fillWithBlocks(world, start, 18, 15, 24, 18, 15, 25, Blocks.MOSSY_COBBLESTONE.getDefaultState());
        structure.fillWithBlocks(world, start, 18, 16, 20, 18, 16, 22, Blocks.COBBLESTONE.getDefaultState());
        structure.fillWithBlocks(world, start, 18, 16, 23, 18, 17, 23, Blocks.MOSSY_COBBLESTONE.getDefaultState());
        structure.fillWithBlocks(world, start, 18, 16, 26, 18, 16, 26, Blocks.COBBLESTONE.getDefaultState());
        structure.fillWithBlocks(world, start, 18, 17, 21, 18, 17, 25, Blocks.MOSSY_COBBLESTONE.getDefaultState());
        structure.fillWithBlocks(world, start, 18, 19, 20, 18, 19, 26, Blocks.COBBLESTONE.getDefaultState());
        structure.fillWithBlocks(world, start, 18, 20, 22, 18, 20, 24, Blocks.COBBLESTONE_SLAB.getDefaultState().with(SlabBlock.TYPE, SlabType.BOTTOM).with(SlabBlock.WATERLOGGED, false));
        structure.fillWithBlocks(world, start, 19, 0, 2, 21, 0, 4, Blocks.DIRT.getDefaultState());
        structure.fillWithBlocks(world, start, 19, 0, 5, 27, 0, 41, Blocks.STONE.getDefaultState());
        structure.fillWithBlocks(world, start, 19, 0, 44, 27, 0, 44, Blocks.DIRT.getDefaultState());
