package mod.arcalitegames.odyssey.world.structure.structures.towers.ruin_tower;

import mod.arcalitegames.odyssey.world.structure.StructureBase;
import net.minecraft.block.Blocks;
import net.minecraft.block.BrewingStandBlock;
import net.minecraft.block.CauldronBlock;
import net.minecraft.block.ChestBlock;
import net.minecraft.block.DoorBlock;
import net.minecraft.block.FourWayBlock;
import net.minecraft.block.SkullBlock;
import net.minecraft.block.SlabBlock;
import net.minecraft.block.SnowyDirtBlock;
import net.minecraft.block.StairsBlock;
import net.minecraft.block.VineBlock;
import net.minecraft.block.WallTorchBlock;
import net.minecraft.state.properties.ChestType;
import net.minecraft.state.properties.DoorHingeSide;
import net.minecraft.state.properties.DoubleBlockHalf;
import net.minecraft.state.properties.Half;
import net.minecraft.state.properties.SlabType;
import net.minecraft.state.properties.StairsShape;
import net.minecraft.util.Direction;
import net.minecraft.util.math.BlockPos;
import net.minecraft.world.World;

public class RuinTowerComponents
{

	public static BlockPos start;
    public static World world;
    public static StructureBase structure;

    public static void init(World worldIn, BlockPos blockPos, StructureBase structureIn)
    {
        world = worldIn; start = blockPos; structure = structureIn;
    }
    
    public static void generatePart1()
    {
        structure.setBlockState(world, Blocks.GRASS_BLOCK.getDefaultState().with(SnowyDirtBlock.SNOWY, false), 2, 0, 6, start);
        structure.setBlockState(world, Blocks.GRASS_BLOCK.getDefaultState().with(SnowyDirtBlock.SNOWY, false), 2, 0, 16, start);
        structure.setBlockState(world, Blocks.GRASS_BLOCK.getDefaultState().with(SnowyDirtBlock.SNOWY, false), 3, 0, 4, start);
        structure.setBlockState(world, Blocks.GRASS_BLOCK.getDefaultState().with(SnowyDirtBlock.SNOWY, false), 3, 2, 7, start);
        structure.setBlockState(world, Blocks.GRASS_BLOCK.getDefaultState().with(SnowyDirtBlock.SNOWY, false), 3, 2, 15, start);
        structure.setBlockState(world, Blocks.GRASS_BLOCK.getDefaultState().with(SnowyDirtBlock.SNOWY, false), 4, 0, 3, start);
        structure.setBlockState(world, Blocks.STONE.getDefaultState(), 4, 0, 9, start);
        structure.setBlockState(world, Blocks.GRASS_BLOCK.getDefaultState().with(SnowyDirtBlock.SNOWY, false), 4, 0, 19, start);
        structure.setBlockState(world, Blocks.GRASS_BLOCK.getDefaultState().with(SnowyDirtBlock.SNOWY, false), 4, 1, 4, start);
        structure.setBlockState(world, Blocks.GRASS_BLOCK.getDefaultState().with(SnowyDirtBlock.SNOWY, false), 4, 2, 5, start);
        structure.setBlockState(world, Blocks.GRASS_BLOCK.getDefaultState().with(SnowyDirtBlock.SNOWY, false), 4, 3, 6, start);
        structure.setBlockState(world, Blocks.GRASS_BLOCK.getDefaultState().with(SnowyDirtBlock.SNOWY, false), 5, 2, 4, start);
        structure.setBlockState(world, Blocks.GRASS_BLOCK.getDefaultState().with(SnowyDirtBlock.SNOWY, false), 5, 2, 18, start);
        structure.setBlockState(world, Blocks.GRASS_BLOCK.getDefaultState().with(SnowyDirtBlock.SNOWY, false), 5, 3, 5, start);
        structure.setBlockState(world, Blocks.GRASS_BLOCK.getDefaultState().with(SnowyDirtBlock.SNOWY, false), 5, 4, 6, start);
        structure.setBlockState(world, Blocks.GRASS_BLOCK.getDefaultState().with(SnowyDirtBlock.SNOWY, false), 6, 0, 2, start);
        structure.setBlockState(world, Blocks.GRASS_BLOCK.getDefaultState().with(SnowyDirtBlock.SNOWY, false), 6, 0, 20, start);
        structure.setBlockState(world, Blocks.STONE.getDefaultState(), 6, 1, 16, start);
        structure.setBlockState(world, Blocks.GRASS_BLOCK.getDefaultState().with(SnowyDirtBlock.SNOWY, false), 6, 3, 4, start);
        structure.setBlockState(world, Blocks.GRASS_BLOCK.getDefaultState().with(SnowyDirtBlock.SNOWY, false), 6, 3, 18, start);
        structure.setBlockState(world, Blocks.GRASS_BLOCK.getDefaultState().with(SnowyDirtBlock.SNOWY, false), 6, 4, 5, start);
        structure.setBlockState(world, Blocks.STONE_BRICK_STAIRS.getDefaultState().with(StairsBlock.FACING, Direction.EAST).with(StairsBlock.WATERLOGGED, false).with(StairsBlock.SHAPE, StairsShape.STRAIGHT).with(StairsBlock.HALF, Half.BOTTOM), 6, 7, 10, start);
        structure.setBlockState(world, Blocks.STONE_BRICK_STAIRS.getDefaultState().with(StairsBlock.FACING, Direction.EAST).with(StairsBlock.WATERLOGGED, false).with(StairsBlock.SHAPE, StairsShape.STRAIGHT).with(StairsBlock.HALF, Half.BOTTOM), 6, 7, 12, start);
        structure.setBlockState(world, Blocks.VINE.getDefaultState().with(VineBlock.UP, false).with(VineBlock.NORTH, false).with(VineBlock.SOUTH, false).with(VineBlock.EAST, true).with(VineBlock.WEST, false), 6, 7, 13, start);
        structure.setBlockState(world, Blocks.CRACKED_STONE_BRICKS.getDefaultState(), 6, 9, 11, start);
        structure.setBlockState(world, Blocks.STONE_BRICK_STAIRS.getDefaultState().with(StairsBlock.FACING, Direction.EAST).with(StairsBlock.WATERLOGGED, false).with(StairsBlock.SHAPE, StairsShape.STRAIGHT).with(StairsBlock.HALF, Half.BOTTOM), 6, 10, 11, start);
        structure.setBlockState(world, Blocks.GRASS_BLOCK.getDefaultState().with(SnowyDirtBlock.SNOWY, false), 7, 2, 3, start);
        structure.setBlockState(world, Blocks.GRASS_BLOCK.getDefaultState().with(SnowyDirtBlock.SNOWY, false), 7, 2, 19, start);
        structure.setBlockState(world, Blocks.CRACKED_STONE_BRICKS.getDefaultState(), 7, 7, 13, start);
        structure.setBlockState(world, Blocks.VINE.getDefaultState().with(VineBlock.UP, false).with(VineBlock.NORTH, true).with(VineBlock.SOUTH, false).with(VineBlock.EAST, true).with(VineBlock.WEST, false), 7, 7, 14, start);
        structure.setBlockState(world, Blocks.CRACKED_STONE_BRICKS.getDefaultState(), 7, 8, 9, start);
        structure.setBlockState(world, Blocks.VINE.getDefaultState().with(VineBlock.UP, false).with(VineBlock.NORTH, false).with(VineBlock.SOUTH, false).with(VineBlock.EAST, true).with(VineBlock.WEST, false), 7, 8, 14, start);
        structure.setBlockState(world, Blocks.SKELETON_SKULL.getDefaultState().with(SkullBlock.ROTATION, 0), 7, 10, 9, start);
        structure.setBlockState(world, Blocks.CRACKED_STONE_BRICKS.getDefaultState(), 7, 10, 12, start);
        structure.setBlockState(world, Blocks.CRACKED_STONE_BRICKS.getDefaultState(), 7, 11, 10, start);
        structure.setBlockState(world, Blocks.STONE_BRICK_STAIRS.getDefaultState().with(StairsBlock.FACING, Direction.EAST).with(StairsBlock.WATERLOGGED, false).with(StairsBlock.SHAPE, StairsShape.STRAIGHT).with(StairsBlock.HALF, Half.BOTTOM), 7, 12, 10, start);
        structure.setBlockState(world, Blocks.STONE_BRICK_STAIRS.getDefaultState().with(StairsBlock.FACING, Direction.EAST).with(StairsBlock.WATERLOGGED, false).with(StairsBlock.SHAPE, StairsShape.STRAIGHT).with(StairsBlock.HALF, Half.BOTTOM), 7, 12, 12, start);
        structure.setBlockState(world, Blocks.VINE.getDefaultState().with(VineBlock.UP, true).with(VineBlock.NORTH, false).with(VineBlock.SOUTH, false).with(VineBlock.EAST, true).with(VineBlock.WEST, false), 7, 26, 10, start);
        structure.setBlockState(world, Blocks.VINE.getDefaultState().with(VineBlock.UP, true).with(VineBlock.NORTH, false).with(VineBlock.SOUTH, false).with(VineBlock.EAST, true).with(VineBlock.WEST, false), 7, 26, 13, start);
        structure.setBlockState(world, Blocks.STONE_BRICK_STAIRS.getDefaultState().with(StairsBlock.FACING, Direction.EAST).with(StairsBlock.WATERLOGGED, false).with(StairsBlock.SHAPE, StairsShape.STRAIGHT).with(StairsBlock.HALF, Half.BOTTOM), 8, 7, 7, start);
        structure.setBlockState(world, Blocks.STONE_BRICK_STAIRS.getDefaultState().with(StairsBlock.FACING, Direction.NORTH).with(StairsBlock.WATERLOGGED, false).with(StairsBlock.SHAPE, StairsShape.STRAIGHT).with(StairsBlock.HALF, Half.BOTTOM), 8, 7, 15, start);
        structure.setBlockState(world, Blocks.VINE.getDefaultState().with(VineBlock.UP, false).with(VineBlock.NORTH, true).with(VineBlock.SOUTH, false).with(VineBlock.EAST, true).with(VineBlock.WEST, false), 8, 8, 15, start);
        structure.setBlockState(world, Blocks.SKELETON_SKULL.getDefaultState().with(SkullBlock.ROTATION, 10), 8, 9, 14, start);
        structure.setBlockState(world, Blocks.CRACKED_STONE_BRICKS.getDefaultState(), 8, 10, 9, start);
        structure.setBlockState(world, Blocks.VINE.getDefaultState().with(VineBlock.UP, false).with(VineBlock.NORTH, true).with(VineBlock.SOUTH, false).with(VineBlock.EAST, true).with(VineBlock.WEST, false), 8, 10, 14, start);
        structure.setBlockState(world, Blocks.CRACKED_STONE_BRICKS.getDefaultState(), 8, 11, 13, start);
        structure.setBlockState(world, Blocks.STONE_BRICK_STAIRS.getDefaultState().with(StairsBlock.FACING, Direction.EAST).with(StairsBlock.WATERLOGGED, false).with(StairsBlock.SHAPE, StairsShape.STRAIGHT).with(StairsBlock.HALF, Half.BOTTOM), 8, 15, 11, start);
        structure.setBlockState(world, Blocks.STONE_BRICK_STAIRS.getDefaultState().with(StairsBlock.FACING, Direction.EAST).with(StairsBlock.WATERLOGGED, false).with(StairsBlock.SHAPE, StairsShape.STRAIGHT).with(StairsBlock.HALF, Half.TOP), 8, 20, 11, start);
        structure.setBlockState(world, Blocks.VINE.getDefaultState().with(VineBlock.UP, true).with(VineBlock.NORTH, false).with(VineBlock.SOUTH, false).with(VineBlock.EAST, true).with(VineBlock.WEST, false), 8, 21, 10, start);
        structure.setBlockState(world, Blocks.CRACKED_STONE_BRICKS.getDefaultState(), 8, 21, 11, start);
        structure.setBlockState(world, Blocks.CRACKED_STONE_BRICKS.getDefaultState(), 8, 23, 12, start);
        structure.setBlockState(world, Blocks.CRACKED_STONE_BRICKS.getDefaultState(), 8, 25, 9, start);
        structure.setBlockState(world, Blocks.CRACKED_STONE_BRICKS.getDefaultState(), 8, 26, 12, start);
        structure.setBlockState(world, Blocks.STONE.getDefaultState(), 9, 0, 18, start);
        structure.setBlockState(world, Blocks.CRACKED_STONE_BRICKS.getDefaultState(), 9, 9, 8, start);
        structure.setBlockState(world, Blocks.CRACKED_STONE_BRICKS.getDefaultState(), 9, 9, 15, start);
        structure.setBlockState(world, Blocks.STONE_BRICK_STAIRS.getDefaultState().with(StairsBlock.FACING, Direction.NORTH).with(StairsBlock.WATERLOGGED, false).with(StairsBlock.SHAPE, StairsShape.STRAIGHT).with(StairsBlock.HALF, Half.BOTTOM), 9, 10, 15, start);
        structure.setBlockState(world, Blocks.CRACKED_STONE_BRICKS.getDefaultState(), 9, 13, 9, start);
        structure.setBlockState(world, Blocks.CRACKED_STONE_BRICKS.getDefaultState(), 9, 13, 13, start);
        structure.setBlockState(world, Blocks.CRACKED_STONE_BRICKS.getDefaultState(), 9, 14, 12, start);
        structure.setBlockState(world, Blocks.SKELETON_SKULL.getDefaultState().with(SkullBlock.ROTATION, 14), 9, 15, 9, start);
        structure.setBlockState(world, Blocks.SKELETON_SKULL.getDefaultState().with(SkullBlock.ROTATION, 10), 9, 15, 13, start);
        structure.setBlockState(world, Blocks.CRACKED_STONE_BRICKS.getDefaultState(), 9, 16, 11, start);
        structure.setBlockState(world, Blocks.STONE_BRICK_STAIRS.getDefaultState().with(StairsBlock.FACING, Direction.SOUTH).with(StairsBlock.WATERLOGGED, false).with(StairsBlock.SHAPE, StairsShape.STRAIGHT).with(StairsBlock.HALF, Half.BOTTOM), 9, 17, 10, start);
        structure.setBlockState(world, Blocks.CRACKED_STONE_BRICKS.getDefaultState(), 9, 17, 12, start);
        structure.setBlockState(world, Blocks.STONE_BRICK_STAIRS.getDefaultState().with(StairsBlock.FACING, Direction.EAST).with(StairsBlock.WATERLOGGED, false).with(StairsBlock.SHAPE, StairsShape.STRAIGHT).with(StairsBlock.HALF, Half.BOTTOM), 9, 17, 13, start);
        structure.setBlockState(world, Blocks.VINE.getDefaultState().with(VineBlock.UP, false).with(VineBlock.NORTH, false).with(VineBlock.SOUTH, true).with(VineBlock.EAST, false).with(VineBlock.WEST, false), 9, 18, 8, start);
        structure.setBlockState(world, Blocks.SKELETON_SKULL.getDefaultState().with(SkullBlock.ROTATION, 15), 9, 19, 9, start);
        structure.setBlockState(world, Blocks.VINE.getDefaultState().with(VineBlock.UP, true).with(VineBlock.NORTH, true).with(VineBlock.SOUTH, false).with(VineBlock.EAST, false).with(VineBlock.WEST, false), 9, 19, 13, start);
        structure.setBlockState(world, Blocks.CRACKED_STONE_BRICKS.getDefaultState(), 9, 20, 12, start);
        structure.setBlockState(world, Blocks.SKELETON_SKULL.getDefaultState().with(SkullBlock.ROTATION, 10), 9, 21, 13, start);
        structure.setBlockState(world, Blocks.CRACKED_STONE_BRICKS.getDefaultState(), 9, 22, 13, start);
        structure.setBlockState(world, Blocks.MOSSY_STONE_BRICKS.getDefaultState(), 9, 23, 9, start);
        structure.setBlockState(world, Blocks.CHEST.getDefaultState().with(ChestBlock.FACING, Direction.NORTH).with(ChestBlock.WATERLOGGED, false).with(ChestBlock.TYPE, ChestType.SINGLE), 9, 24, 13, start);
        structure.setBlockState(world, Blocks.CRACKED_STONE_BRICKS.getDefaultState(), 9, 24, 14, start);
        structure.setBlockState(world, Blocks.MOSSY_STONE_BRICKS.getDefaultState(), 9, 26, 14, start);
        structure.setBlockState(world, Blocks.WALL_TORCH.getDefaultState().with(WallTorchBlock.HORIZONTAL_FACING, Direction.EAST), 9, 27, 11, start);
        structure.setBlockState(world, Blocks.COBWEB.getDefaultState(), 9, 27, 13, start);
        structure.setBlockState(world, Blocks.VINE.getDefaultState().with(VineBlock.UP, false).with(VineBlock.NORTH, false).with(VineBlock.SOUTH, false).with(VineBlock.EAST, true).with(VineBlock.WEST, false), 9, 28, 14, start);
        structure.setBlockState(world, Blocks.VINE.getDefaultState().with(VineBlock.UP, false).with(VineBlock.NORTH, false).with(VineBlock.SOUTH, false).with(VineBlock.EAST, true).with(VineBlock.WEST, false), 9, 31, 10, start);
        structure.setBlockState(world, Blocks.VINE.getDefaultState().with(VineBlock.UP, false).with(VineBlock.NORTH, false).with(VineBlock.SOUTH, false).with(VineBlock.EAST, true).with(VineBlock.WEST, false), 9, 31, 12, start);
        structure.setBlockState(world, Blocks.STONE_BRICK_STAIRS.getDefaultState().with(StairsBlock.FACING, Direction.EAST).with(StairsBlock.WATERLOGGED, false).with(StairsBlock.SHAPE, StairsShape.STRAIGHT).with(StairsBlock.HALF, Half.BOTTOM), 10, 7, 16, start);
        structure.setBlockState(world, Blocks.CRACKED_STONE_BRICKS.getDefaultState(), 10, 8, 7, start);
        structure.setBlockState(world, Blocks.VINE.getDefaultState().with(VineBlock.UP, false).with(VineBlock.NORTH, false).with(VineBlock.SOUTH, true).with(VineBlock.EAST, false).with(VineBlock.WEST, false), 10, 9, 6, start);
        structure.setBlockState(world, Blocks.COBWEB.getDefaultState(), 10, 9, 11, start);
        structure.setBlockState(world, Blocks.STONE_BRICK_STAIRS.getDefaultState().with(StairsBlock.FACING, Direction.SOUTH).with(StairsBlock.WATERLOGGED, false).with(StairsBlock.SHAPE, StairsShape.STRAIGHT).with(StairsBlock.HALF, Half.BOTTOM), 10, 10, 10, start);
        structure.setBlockState(world, Blocks.SKELETON_SKULL.getDefaultState().with(SkullBlock.ROTATION, 10), 10, 10, 16, start);
        structure.setBlockState(world, Blocks.STONE_BRICK_STAIRS.getDefaultState().with(StairsBlock.FACING, Direction.SOUTH).with(StairsBlock.WATERLOGGED, false).with(StairsBlock.SHAPE, StairsShape.STRAIGHT).with(StairsBlock.HALF, Half.BOTTOM), 10, 11, 11, start);
        structure.setBlockState(world, Blocks.SKELETON_SKULL.getDefaultState().with(SkullBlock.ROTATION, 15), 10, 12, 7, start);
        structure.setBlockState(world, Blocks.CRACKED_STONE_BRICKS.getDefaultState(), 10, 12, 8, start);
        structure.setBlockState(world, Blocks.AIR.getDefaultState(), 10, 12, 12, start);
        structure.setBlockState(world, Blocks.CRACKED_STONE_BRICKS.getDefaultState(), 10, 12, 14, start);
        structure.setBlockState(world, Blocks.STONE_BRICK_SLAB.getDefaultState().with(SlabBlock.TYPE, SlabType.TOP).with(SlabBlock.WATERLOGGED, false), 10, 13, 9, start);
        structure.setBlockState(world, Blocks.STONE_BRICK_SLAB.getDefaultState().with(SlabBlock.TYPE, SlabType.BOTTOM).with(SlabBlock.WATERLOGGED, false), 10, 14, 10, start);
        structure.setBlockState(world, Blocks.STONE_BRICK_STAIRS.getDefaultState().with(StairsBlock.FACING, Direction.SOUTH).with(StairsBlock.WATERLOGGED, false).with(StairsBlock.SHAPE, StairsShape.STRAIGHT).with(StairsBlock.HALF, Half.BOTTOM), 10, 14, 11, start);
        structure.setBlockState(world, Blocks.STONE_BRICK_STAIRS.getDefaultState().with(StairsBlock.FACING, Direction.SOUTH).with(StairsBlock.WATERLOGGED, false).with(StairsBlock.SHAPE, StairsShape.STRAIGHT).with(StairsBlock.HALF, Half.BOTTOM), 10, 15, 12, start);
        structure.setBlockState(world, Blocks.VINE.getDefaultState().with(VineBlock.UP, false).with(VineBlock.NORTH, false).with(VineBlock.SOUTH, true).with(VineBlock.EAST, false).with(VineBlock.WEST, false), 10, 17, 8, start);
        structure.setBlockState(world, Blocks.STONE_BRICK_STAIRS.getDefaultState().with(StairsBlock.FACING, Direction.SOUTH).with(StairsBlock.WATERLOGGED, false).with(StairsBlock.SHAPE, StairsShape.STRAIGHT).with(StairsBlock.HALF, Half.BOTTOM), 10, 18, 11, start);
        structure.setBlockState(world, Blocks.VINE.getDefaultState().with(VineBlock.UP, true).with(VineBlock.NORTH, false).with(VineBlock.SOUTH, true).with(VineBlock.EAST, true).with(VineBlock.WEST, false), 10, 21, 8, start);
        structure.setBlockState(world, Blocks.COBWEB.getDefaultState(), 10, 22, 10, start);
        structure.setBlockState(world, Blocks.COBWEB.getDefaultState(), 10, 22, 12, start);
        structure.setBlockState(world, Blocks.CRACKED_STONE_BRICKS.getDefaultState(), 10, 24, 8, start);
        structure.setBlockState(world, Blocks.CAULDRON.getDefaultState().with(CauldronBlock.LEVEL, 3), 10, 24, 11, start);
        structure.setBlockState(world, Blocks.CRACKED_STONE_BRICKS.getDefaultState(), 10, 26, 14, start);
        structure.setBlockState(world, Blocks.COBWEB.getDefaultState(), 10, 28, 10, start);
        structure.setBlockState(world, Blocks.COBWEB.getDefaultState(), 10, 28, 12, start);
        structure.setBlockState(world, Blocks.VINE.getDefaultState().with(VineBlock.UP, false).with(VineBlock.NORTH, false).with(VineBlock.SOUTH, true).with(VineBlock.EAST, false).with(VineBlock.WEST, false), 10, 31, 9, start);
        structure.setBlockState(world, Blocks.CRACKED_STONE_BRICKS.getDefaultState(), 11, 7, 6, start);
        structure.setBlockState(world, Blocks.MOSSY_STONE_BRICKS.getDefaultState(), 11, 7, 16, start);
        structure.setBlockState(world, Blocks.AIR.getDefaultState(), 11, 8, 11, start);
        structure.setBlockState(world, Blocks.CRACKED_STONE_BRICKS.getDefaultState(), 11, 8, 16, start);
        structure.setBlockState(world, Blocks.STONE_BRICK_STAIRS.getDefaultState().with(StairsBlock.FACING, Direction.SOUTH).with(StairsBlock.WATERLOGGED, false).with(StairsBlock.SHAPE, StairsShape.STRAIGHT).with(StairsBlock.HALF, Half.BOTTOM), 11, 9, 6, start);
        structure.setBlockState(world, Blocks.STONE_BRICK_STAIRS.getDefaultState().with(StairsBlock.FACING, Direction.WEST).with(StairsBlock.WATERLOGGED, false).with(StairsBlock.SHAPE, StairsShape.STRAIGHT).with(StairsBlock.HALF, Half.BOTTOM), 11, 9, 9, start);
        structure.setBlockState(world, Blocks.WALL_TORCH.getDefaultState().with(WallTorchBlock.HORIZONTAL_FACING, Direction.NORTH), 11, 9, 13, start);
        structure.setBlockState(world, Blocks.CRACKED_STONE_BRICKS.getDefaultState(), 11, 10, 7, start);
        structure.setBlockState(world, Blocks.STONE_BRICK_STAIRS.getDefaultState().with(StairsBlock.FACING, Direction.NORTH).with(StairsBlock.WATERLOGGED, false).with(StairsBlock.SHAPE, StairsShape.STRAIGHT).with(StairsBlock.HALF, Half.BOTTOM), 11, 10, 16, start);
        structure.setBlockState(world, Blocks.STONE_BRICK_STAIRS.getDefaultState().with(StairsBlock.FACING, Direction.EAST).with(StairsBlock.WATERLOGGED, false).with(StairsBlock.SHAPE, StairsShape.STRAIGHT).with(StairsBlock.HALF, Half.BOTTOM), 11, 12, 12, start);
        structure.setBlockState(world, Blocks.STONE_BRICK_STAIRS.getDefaultState().with(StairsBlock.FACING, Direction.WEST).with(StairsBlock.WATERLOGGED, false).with(StairsBlock.SHAPE, StairsShape.STRAIGHT).with(StairsBlock.HALF, Half.BOTTOM), 11, 13, 10, start);
        structure.setBlockState(world, Blocks.CRACKED_STONE_BRICKS.getDefaultState(), 11, 15, 8, start);
        structure.setBlockState(world, Blocks.STONE_BRICK_STAIRS.getDefaultState().with(StairsBlock.FACING, Direction.SOUTH).with(StairsBlock.WATERLOGGED, false).with(StairsBlock.SHAPE, StairsShape.STRAIGHT).with(StairsBlock.HALF, Half.BOTTOM), 11, 16, 8, start);
        structure.setBlockState(world, Blocks.STONE_BRICK_SLAB.getDefaultState().with(SlabBlock.TYPE, SlabType.TOP).with(SlabBlock.WATERLOGGED, false), 11, 16, 10, start);
        structure.setBlockState(world, Blocks.STONE_BRICK_STAIRS.getDefaultState().with(StairsBlock.FACING, Direction.NORTH).with(StairsBlock.WATERLOGGED, false).with(StairsBlock.SHAPE, StairsShape.STRAIGHT).with(StairsBlock.HALF, Half.BOTTOM), 11, 16, 14, start);
        structure.setBlockState(world, Blocks.STONE_BRICK_STAIRS.getDefaultState().with(StairsBlock.FACING, Direction.WEST).with(StairsBlock.WATERLOGGED, false).with(StairsBlock.SHAPE, StairsShape.STRAIGHT).with(StairsBlock.HALF, Half.BOTTOM), 11, 17, 10, start);
        structure.setBlockState(world, Blocks.STONE_BRICK_SLAB.getDefaultState().with(SlabBlock.TYPE, SlabType.TOP).with(SlabBlock.WATERLOGGED, false), 11, 18, 12, start);
        structure.setBlockState(world, Blocks.STONE_BRICK_STAIRS.getDefaultState().with(StairsBlock.FACING, Direction.EAST).with(StairsBlock.WATERLOGGED, false).with(StairsBlock.SHAPE, StairsShape.STRAIGHT).with(StairsBlock.HALF, Half.BOTTOM), 11, 19, 12, start);
        structure.setBlockState(world, Blocks.STONE_BRICK_STAIRS.getDefaultState().with(StairsBlock.FACING, Direction.SOUTH).with(StairsBlock.WATERLOGGED, false).with(StairsBlock.SHAPE, StairsShape.STRAIGHT).with(StairsBlock.HALF, Half.TOP), 11, 20, 8, start);
        structure.setBlockState(world, Blocks.STONE_BRICK_STAIRS.getDefaultState().with(StairsBlock.FACING, Direction.NORTH).with(StairsBlock.WATERLOGGED, false).with(StairsBlock.SHAPE, StairsShape.STRAIGHT).with(StairsBlock.HALF, Half.TOP), 11, 20, 14, start);
        structure.setBlockState(world, Blocks.CRACKED_STONE_BRICKS.getDefaultState(), 11, 22, 8, start);
        structure.setBlockState(world, Blocks.STONE_BRICK_STAIRS.getDefaultState().with(StairsBlock.FACING, Direction.WEST).with(StairsBlock.WATERLOGGED, false).with(StairsBlock.SHAPE, StairsShape.STRAIGHT).with(StairsBlock.HALF, Half.BOTTOM), 11, 23, 9, start);
        structure.setBlockState(world, Blocks.CRACKED_STONE_BRICKS.getDefaultState(), 11, 23, 14, start);
        structure.setBlockState(world, Blocks.ENCHANTING_TABLE.getDefaultState(), 11, 24, 13, start);
        structure.setBlockState(world, Blocks.WALL_TORCH.getDefaultState().with(WallTorchBlock.HORIZONTAL_FACING, Direction.SOUTH), 11, 27, 9, start);
        structure.setBlockState(world, Blocks.WALL_TORCH.getDefaultState().with(WallTorchBlock.HORIZONTAL_FACING, Direction.NORTH), 11, 27, 13, start);
        structure.setBlockState(world, Blocks.VINE.getDefaultState().with(VineBlock.UP, false).with(VineBlock.NORTH, true).with(VineBlock.SOUTH, false).with(VineBlock.EAST, false).with(VineBlock.WEST, false), 11, 32, 13, start);
        structure.setBlockState(world, Blocks.STONE_BRICK_STAIRS.getDefaultState().with(StairsBlock.FACING, Direction.SOUTH).with(StairsBlock.WATERLOGGED, false).with(StairsBlock.SHAPE, StairsShape.STRAIGHT).with(StairsBlock.HALF, Half.BOTTOM), 12, 7, 6, start);
        structure.setBlockState(world, Blocks.STONE_BRICK_STAIRS.getDefaultState().with(StairsBlock.FACING, Direction.NORTH).with(StairsBlock.WATERLOGGED, false).with(StairsBlock.SHAPE, StairsShape.STRAIGHT).with(StairsBlock.HALF, Half.BOTTOM), 12, 7, 16, start);
        structure.setBlockState(world, Blocks.STONE_BRICK_STAIRS.getDefaultState().with(StairsBlock.FACING, Direction.WEST).with(StairsBlock.WATERLOGGED, false).with(StairsBlock.SHAPE, StairsShape.STRAIGHT).with(StairsBlock.HALF, Half.BOTTOM), 12, 8, 9, start);
        structure.setBlockState(world, Blocks.SPRUCE_DOOR.getDefaultState().with(DoorBlock.FACING, Direction.NORTH).with(DoorBlock.HALF, DoubleBlockHalf.LOWER).with(DoorBlock.HINGE, DoorHingeSide.LEFT).with(DoorBlock.OPEN, false).with(DoorBlock.POWERED, false), 12, 8, 15, start);
        structure.setBlockState(world, Blocks.AIR.getDefaultState(), 12, 8, 16, start);
        structure.setBlockState(world, Blocks.SPRUCE_DOOR.getDefaultState().with(DoorBlock.FACING, Direction.NORTH).with(DoorBlock.HALF, DoubleBlockHalf.UPPER).with(DoorBlock.HINGE, DoorHingeSide.LEFT).with(DoorBlock.OPEN, false).with(DoorBlock.POWERED, false), 12, 9, 15, start);
        structure.setBlockState(world, Blocks.CRACKED_STONE_BRICKS.getDefaultState(), 12, 11, 7, start);
        structure.setBlockState(world, Blocks.CRACKED_STONE_BRICKS.getDefaultState(), 12, 13, 8, start);
        structure.setBlockState(world, Blocks.STONE_BRICK_SLAB.getDefaultState().with(SlabBlock.TYPE, SlabType.TOP).with(SlabBlock.WATERLOGGED, false), 12, 15, 11, start);
        structure.setBlockState(world, Blocks.CRACKED_STONE_BRICKS.getDefaultState(), 12, 15, 13, start);
        structure.setBlockState(world, Blocks.STONE_BRICK_STAIRS.getDefaultState().with(StairsBlock.FACING, Direction.NORTH).with(StairsBlock.WATERLOGGED, false).with(StairsBlock.SHAPE, StairsShape.STRAIGHT).with(StairsBlock.HALF, Half.BOTTOM), 12, 16, 11, start);
        structure.setBlockState(world, Blocks.CRACKED_STONE_BRICKS.getDefaultState(), 12, 17, 9, start);
        structure.setBlockState(world, Blocks.AIR.getDefaultState(), 12, 17, 10, start);
        structure.setBlockState(world, Blocks.CRACKED_STONE_BRICKS.getDefaultState(), 12, 18, 13, start);
        structure.setBlockState(world, Blocks.STONE_BRICK_STAIRS.getDefaultState().with(StairsBlock.FACING, Direction.WEST).with(StairsBlock.WATERLOGGED, false).with(StairsBlock.SHAPE, StairsShape.STRAIGHT).with(StairsBlock.HALF, Half.BOTTOM), 12, 19, 9, start);
        structure.setBlockState(world, Blocks.WALL_TORCH.getDefaultState().with(WallTorchBlock.HORIZONTAL_FACING, Direction.WEST), 12, 19, 10, start);
        structure.setBlockState(world, Blocks.STONE_BRICK_SLAB.getDefaultState().with(SlabBlock.TYPE, SlabType.TOP).with(SlabBlock.WATERLOGGED, false), 12, 19, 11, start);
        structure.setBlockState(world, Blocks.STONE_BRICK_STAIRS.getDefaultState().with(StairsBlock.FACING, Direction.WEST).with(StairsBlock.WATERLOGGED, false).with(StairsBlock.SHAPE, StairsShape.STRAIGHT).with(StairsBlock.HALF, Half.BOTTOM), 12, 19, 13, start);
        structure.setBlockState(world, Blocks.STONE_BRICK_STAIRS.getDefaultState().with(StairsBlock.FACING, Direction.NORTH).with(StairsBlock.WATERLOGGED, false).with(StairsBlock.SHAPE, StairsShape.STRAIGHT).with(StairsBlock.HALF, Half.BOTTOM), 12, 20, 11, start);
        structure.setBlockState(world, Blocks.VINE.getDefaultState().with(VineBlock.UP, true).with(VineBlock.NORTH, false).with(VineBlock.SOUTH, true).with(VineBlock.EAST, false).with(VineBlock.WEST, false), 12, 21, 8, start);
        structure.setBlockState(world, Blocks.AIR.getDefaultState(), 12, 21, 11, start);
        structure.setBlockState(world, Blocks.VINE.getDefaultState().with(VineBlock.UP, true).with(VineBlock.NORTH, false).with(VineBlock.SOUTH, false).with(VineBlock.EAST, false).with(VineBlock.WEST, true), 12, 21, 14, start);
        structure.setBlockState(world, Blocks.STONE_BRICK_STAIRS.getDefaultState().with(StairsBlock.FACING, Direction.WEST).with(StairsBlock.WATERLOGGED, false).with(StairsBlock.SHAPE, StairsShape.STRAIGHT).with(StairsBlock.HALF, Half.BOTTOM), 12, 22, 9, start);
        structure.setBlockState(world, Blocks.MOSSY_STONE_BRICKS.getDefaultState(), 12, 22, 10, start);
        structure.setBlockState(world, Blocks.CRACKED_STONE_BRICKS.getDefaultState(), 12, 23, 8, start);
        structure.setBlockState(world, Blocks.CRACKED_STONE_BRICKS.getDefaultState(), 12, 25, 14, start);
        structure.setBlockState(world, Blocks.VINE.getDefaultState().with(VineBlock.UP, true).with(VineBlock.NORTH, false).with(VineBlock.SOUTH, true).with(VineBlock.EAST, false).with(VineBlock.WEST, false), 12, 26, 7, start);
        structure.setBlockState(world, Blocks.VINE.getDefaultState().with(VineBlock.UP, true).with(VineBlock.NORTH, true).with(VineBlock.SOUTH, false).with(VineBlock.EAST, false).with(VineBlock.WEST, false), 12, 26, 15, start);
        structure.setBlockState(world, Blocks.VINE.getDefaultState().with(VineBlock.UP, false).with(VineBlock.NORTH, false).with(VineBlock.SOUTH, true).with(VineBlock.EAST, false).with(VineBlock.WEST, false), 12, 28, 7, start);
        structure.setBlockState(world, Blocks.COBWEB.getDefaultState(), 12, 28, 10, start);
        structure.setBlockState(world, Blocks.COBWEB.getDefaultState(), 12, 28, 12, start);
        structure.setBlockState(world, Blocks.VINE.getDefaultState().with(VineBlock.UP, false).with(VineBlock.NORTH, false).with(VineBlock.SOUTH, true).with(VineBlock.EAST, false).with(VineBlock.WEST, false), 12, 31, 9, start);
        structure.setBlockState(world, Blocks.VINE.getDefaultState().with(VineBlock.UP, false).with(VineBlock.NORTH, false).with(VineBlock.SOUTH, false).with(VineBlock.EAST, false).with(VineBlock.WEST, true), 12, 31, 13, start);
        structure.setBlockState(world, Blocks.GRAY_TERRACOTTA.getDefaultState(), 12, 33, 11, start);
        structure.setBlockState(world, Blocks.STONE.getDefaultState(), 13, 0, 4, start);
        structure.setBlockState(world, Blocks.STONE.getDefaultState(), 13, 0, 18, start);
        structure.setBlockState(world, Blocks.GRASS_BLOCK.getDefaultState().with(SnowyDirtBlock.SNOWY, false), 13, 6, 6, start);
        structure.setBlockState(world, Blocks.SKELETON_SKULL.getDefaultState().with(SkullBlock.ROTATION, 7), 13, 7, 16, start);
        structure.setBlockState(world, Blocks.CRACKED_STONE_BRICKS.getDefaultState(), 13, 10, 14, start);
        structure.setBlockState(world, Blocks.STONE_BRICK_STAIRS.getDefaultState().with(StairsBlock.FACING, Direction.NORTH).with(StairsBlock.WATERLOGGED, false).with(StairsBlock.SHAPE, StairsShape.STRAIGHT).with(StairsBlock.HALF, Half.BOTTOM), 13, 10, 15, start);
        structure.setBlockState(world, Blocks.COBWEB.getDefaultState(), 13, 11, 11, start);
        structure.setBlockState(world, Blocks.MOSSY_STONE_BRICKS.getDefaultState(), 13, 11, 14, start);
        structure.setBlockState(world, Blocks.SKELETON_SKULL.getDefaultState().with(SkullBlock.ROTATION, 7), 13, 12, 14, start);
        structure.setBlockState(world, Blocks.CRACKED_STONE_BRICKS.getDefaultState(), 13, 14, 9, start);
        structure.setBlockState(world, Blocks.SKELETON_SKULL.getDefaultState().with(SkullBlock.ROTATION, 2), 13, 17, 9, start);
        structure.setBlockState(world, Blocks.STONE_BRICK_STAIRS.getDefaultState().with(StairsBlock.FACING, Direction.WEST).with(StairsBlock.WATERLOGGED, false).with(StairsBlock.SHAPE, StairsShape.STRAIGHT).with(StairsBlock.HALF, Half.BOTTOM), 13, 17, 10, start);
        structure.setBlockState(world, Blocks.MOSSY_STONE_BRICKS.getDefaultState(), 13, 17, 11, start);
        structure.setBlockState(world, Blocks.STONE_BRICK_SLAB.getDefaultState().with(SlabBlock.TYPE, SlabType.BOTTOM).with(SlabBlock.WATERLOGGED, false), 13, 17, 12, start);
        structure.setBlockState(world, Blocks.CRACKED_STONE_BRICKS.getDefaultState(), 13, 17, 13, start);
        structure.setBlockState(world, Blocks.CRACKED_STONE_BRICKS.getDefaultState(), 13, 18, 11, start);
        structure.setBlockState(world, Blocks.STONE_BRICK_STAIRS.getDefaultState().with(StairsBlock.FACING, Direction.NORTH).with(StairsBlock.WATERLOGGED, false).with(StairsBlock.SHAPE, StairsShape.STRAIGHT).with(StairsBlock.HALF, Half.TOP), 13, 18, 12, start);
        structure.setBlockState(world, Blocks.MOSSY_STONE_BRICKS.getDefaultState(), 13, 18, 13, start);
        structure.setBlockState(world, Blocks.CRACKED_STONE_BRICKS.getDefaultState(), 13, 20, 9, start);
        structure.setBlockState(world, Blocks.STONE_BRICK_STAIRS.getDefaultState().with(StairsBlock.FACING, Direction.NORTH).with(StairsBlock.WATERLOGGED, false).with(StairsBlock.SHAPE, StairsShape.STRAIGHT).with(StairsBlock.HALF, Half.BOTTOM), 13, 21, 10, start);
        structure.setBlockState(world, Blocks.AIR.getDefaultState(), 13, 21, 11, start);
        structure.setBlockState(world, Blocks.CRACKED_STONE_BRICKS.getDefaultState(), 13, 22, 10, start);
        structure.setBlockState(world, Blocks.CRACKED_STONE_BRICKS.getDefaultState(), 13, 22, 13, start);
        structure.setBlockState(world, Blocks.DARK_OAK_PLANKS.getDefaultState(), 13, 23, 12, start);
        structure.setBlockState(world, Blocks.MOSSY_STONE_BRICKS.getDefaultState(), 13, 23, 13, start);
        structure.setBlockState(world, Blocks.CRACKED_STONE_BRICKS.getDefaultState(), 13, 24, 14, start);
        structure.setBlockState(world, Blocks.CRACKED_STONE_BRICKS.getDefaultState(), 13, 25, 8, start);
        structure.setBlockState(world, Blocks.BREWING_STAND.getDefaultState().with(BrewingStandBlock.HAS_BOTTLE[0], false).with(BrewingStandBlock.HAS_BOTTLE[1], false).with(BrewingStandBlock.HAS_BOTTLE[2], false), 13, 25, 11, start);
        structure.setBlockState(world, Blocks.RED_MUSHROOM.getDefaultState(), 13, 25, 12, start);
        structure.setBlockState(world, Blocks.SKELETON_SKULL.getDefaultState().with(SkullBlock.ROTATION, 14), 13, 25, 13, start);
        structure.setBlockState(world, Blocks.MOSSY_STONE_BRICKS.getDefaultState(), 13, 26, 8, start);
        structure.setBlockState(world, Blocks.COBWEB.getDefaultState(), 13, 27, 10, start);
        structure.setBlockState(world, Blocks.WALL_TORCH.getDefaultState().with(WallTorchBlock.HORIZONTAL_FACING, Direction.WEST), 13, 27, 11, start);
        structure.setBlockState(world, Blocks.GRAY_TERRACOTTA.getDefaultState(), 13, 31, 11, start);
        structure.setBlockState(world, Blocks.VINE.getDefaultState().with(VineBlock.UP, false).with(VineBlock.NORTH, true).with(VineBlock.SOUTH, false).with(VineBlock.EAST, false).with(VineBlock.WEST, false), 13, 31, 12, start);
        structure.setBlockState(world, Blocks.STONE_BRICK_STAIRS.getDefaultState().with(StairsBlock.FACING, Direction.WEST).with(StairsBlock.WATERLOGGED, false).with(StairsBlock.SHAPE, StairsShape.STRAIGHT).with(StairsBlock.HALF, Half.BOTTOM), 14, 7, 7, start);
        structure.setBlockState(world, Blocks.STONE_BRICK_STAIRS.getDefaultState().with(StairsBlock.FACING, Direction.WEST).with(StairsBlock.WATERLOGGED, false).with(StairsBlock.SHAPE, StairsShape.STRAIGHT).with(StairsBlock.HALF, Half.BOTTOM), 14, 7, 15, start);
        structure.setBlockState(world, Blocks.AIR.getDefaultState(), 14, 7, 16, start);
        structure.setBlockState(world, Blocks.SKELETON_SKULL.getDefaultState().with(SkullBlock.ROTATION, 3), 14, 10, 8, start);
        structure.setBlockState(world, Blocks.STONE_BRICK_STAIRS.getDefaultState().with(StairsBlock.FACING, Direction.WEST).with(StairsBlock.WATERLOGGED, false).with(StairsBlock.SHAPE, StairsShape.STRAIGHT).with(StairsBlock.HALF, Half.BOTTOM), 14, 11, 9, start);
        structure.setBlockState(world, Blocks.STONE_BRICK_STAIRS.getDefaultState().with(StairsBlock.FACING, Direction.WEST).with(StairsBlock.WATERLOGGED, false).with(StairsBlock.SHAPE, StairsShape.STRAIGHT).with(StairsBlock.HALF, Half.BOTTOM), 14, 11, 13, start);
        structure.setBlockState(world, Blocks.MOSSY_STONE_BRICKS.getDefaultState(), 14, 14, 11, start);
        structure.setBlockState(world, Blocks.VINE.getDefaultState().with(VineBlock.UP, false).with(VineBlock.NORTH, true).with(VineBlock.SOUTH, false).with(VineBlock.EAST, false).with(VineBlock.WEST, true), 14, 14, 12, start);
        structure.setBlockState(world, Blocks.STONE_BRICK_STAIRS.getDefaultState().with(StairsBlock.FACING, Direction.WEST).with(StairsBlock.WATERLOGGED, false).with(StairsBlock.SHAPE, StairsShape.STRAIGHT).with(StairsBlock.HALF, Half.BOTTOM), 14, 15, 11, start);
        structure.setBlockState(world, Blocks.VINE.getDefaultState().with(VineBlock.UP, true).with(VineBlock.NORTH, false).with(VineBlock.SOUTH, false).with(VineBlock.EAST, false).with(VineBlock.WEST, true), 14, 20, 10, start);
        structure.setBlockState(world, Blocks.STONE_BRICK_STAIRS.getDefaultState().with(StairsBlock.FACING, Direction.WEST).with(StairsBlock.WATERLOGGED, false).with(StairsBlock.SHAPE, StairsShape.STRAIGHT).with(StairsBlock.HALF, Half.TOP), 14, 20, 11, start);
        structure.setBlockState(world, Blocks.CRACKED_STONE_BRICKS.getDefaultState(), 14, 21, 11, start);
        structure.setBlockState(world, Blocks.VINE.getDefaultState().with(VineBlock.UP, true).with(VineBlock.NORTH, false).with(VineBlock.SOUTH, false).with(VineBlock.EAST, false).with(VineBlock.WEST, true), 14, 21, 12, start);
        structure.setBlockState(world, Blocks.CRACKED_STONE_BRICKS.getDefaultState(), 14, 23, 9, start);
        structure.setBlockState(world, Blocks.CRACKED_STONE_BRICKS.getDefaultState(), 14, 23, 12, start);
        structure.setBlockState(world, Blocks.VINE.getDefaultState().with(VineBlock.UP, true).with(VineBlock.NORTH, false).with(VineBlock.SOUTH, false).with(VineBlock.EAST, false).with(VineBlock.WEST, true), 14, 23, 13, start);
        structure.setBlockState(world, Blocks.CRACKED_STONE_BRICKS.getDefaultState(), 14, 24, 10, start);
        structure.setBlockState(world, Blocks.CRACKED_STONE_BRICKS.getDefaultState(), 14, 25, 11, start);
        structure.setBlockState(world, Blocks.VINE.getDefaultState().with(VineBlock.UP, true).with(VineBlock.NORTH, false).with(VineBlock.SOUTH, false).with(VineBlock.EAST, false).with(VineBlock.WEST, true), 14, 26, 8, start);
        structure.setBlockState(world, Blocks.CRACKED_STONE_BRICKS.getDefaultState(), 14, 26, 9, start);
        structure.setBlockState(world, Blocks.CRACKED_STONE_BRICKS.getDefaultState(), 14, 26, 13, start);
        structure.setBlockState(world, Blocks.VINE.getDefaultState().with(VineBlock.UP, true).with(VineBlock.NORTH, true).with(VineBlock.SOUTH, false).with(VineBlock.EAST, false).with(VineBlock.WEST, true), 14, 26, 14, start);
        structure.setBlockState(world, Blocks.VINE.getDefaultState().with(VineBlock.UP, false).with(VineBlock.NORTH, false).with(VineBlock.SOUTH, true).with(VineBlock.EAST, false).with(VineBlock.WEST, false), 14, 28, 9, start);
        structure.setBlockState(world, Blocks.GRAY_TERRACOTTA.getDefaultState(), 14, 29, 11, start);
        structure.setBlockState(world, Blocks.VINE.getDefaultState().with(VineBlock.UP, false).with(VineBlock.NORTH, true).with(VineBlock.SOUTH, false).with(VineBlock.EAST, false).with(VineBlock.WEST, true), 14, 29, 12, start);
        structure.setBlockState(world, Blocks.STONE.getDefaultState(), 15, 0, 5, start);
        structure.setBlockState(world, Blocks.STONE.getDefaultState(), 15, 0, 17, start);
        structure.setBlockState(world, Blocks.GRASS_BLOCK.getDefaultState().with(SnowyDirtBlock.SNOWY, false), 15, 2, 3, start);
        structure.setBlockState(world, Blocks.GRASS_BLOCK.getDefaultState().with(SnowyDirtBlock.SNOWY, false), 15, 2, 19, start);
        structure.setBlockState(world, Blocks.GRASS_BLOCK.getDefaultState().with(SnowyDirtBlock.SNOWY, false), 15, 6, 15, start);
        structure.setBlockState(world, Blocks.GRASS.getDefaultState(), 15, 7, 7, start);
        structure.setBlockState(world, Blocks.STONE_BRICK_STAIRS.getDefaultState().with(StairsBlock.FACING, Direction.WEST).with(StairsBlock.WATERLOGGED, false).with(StairsBlock.SHAPE, StairsShape.STRAIGHT).with(StairsBlock.HALF, Half.BOTTOM), 15, 8, 9, start);
        structure.setBlockState(world, Blocks.STONE_BRICK_STAIRS.getDefaultState().with(StairsBlock.FACING, Direction.WEST).with(StairsBlock.WATERLOGGED, false).with(StairsBlock.SHAPE, StairsShape.STRAIGHT).with(StairsBlock.HALF, Half.BOTTOM), 15, 8, 14, start);
        structure.setBlockState(world, Blocks.VINE.getDefaultState().with(VineBlock.UP, false).with(VineBlock.NORTH, false).with(VineBlock.SOUTH, true).with(VineBlock.EAST, false).with(VineBlock.WEST, false), 15, 9, 9, start);
        structure.setBlockState(world, Blocks.CRACKED_STONE_BRICKS.getDefaultState(), 15, 9, 10, start);
        structure.setBlockState(world, Blocks.MOSSY_STONE_BRICKS.getDefaultState(), 15, 9, 13, start);
        structure.setBlockState(world, Blocks.STONE_BRICK_STAIRS.getDefaultState().with(StairsBlock.FACING, Direction.SOUTH).with(StairsBlock.WATERLOGGED, false).with(StairsBlock.SHAPE, StairsShape.STRAIGHT).with(StairsBlock.HALF, Half.BOTTOM), 15, 10, 9, start);
        structure.setBlockState(world, Blocks.SKELETON_SKULL.getDefaultState().with(SkullBlock.ROTATION, 4), 15, 10, 13, start);
        structure.setBlockState(world, Blocks.CRACKED_STONE_BRICKS.getDefaultState(), 15, 11, 12, start);
        structure.setBlockState(world, Blocks.SKELETON_SKULL.getDefaultState().with(SkullBlock.ROTATION, 2), 15, 12, 10, start);
        structure.setBlockState(world, Blocks.MOSSY_STONE_BRICKS.getDefaultState(), 15, 12, 11, start);
        structure.setBlockState(world, Blocks.CRACKED_STONE_BRICKS.getDefaultState(), 15, 13, 11, start);
        structure.setBlockState(world, Blocks.VINE.getDefaultState().with(VineBlock.UP, true).with(VineBlock.NORTH, false).with(VineBlock.SOUTH, false).with(VineBlock.EAST, false).with(VineBlock.WEST, true), 15, 26, 10, start);
        structure.setBlockState(world, Blocks.VINE.getDefaultState().with(VineBlock.UP, true).with(VineBlock.NORTH, false).with(VineBlock.SOUTH, false).with(VineBlock.EAST, false).with(VineBlock.WEST, true), 15, 26, 12, start);
        structure.setBlockState(world, Blocks.GRASS_BLOCK.getDefaultState().with(SnowyDirtBlock.SNOWY, false), 16, 0, 2, start);
        structure.setBlockState(world, Blocks.GRASS_BLOCK.getDefaultState().with(SnowyDirtBlock.SNOWY, false), 16, 0, 20, start);
        structure.setBlockState(world, Blocks.GRASS_BLOCK.getDefaultState().with(SnowyDirtBlock.SNOWY, false), 16, 3, 18, start);
        structure.setBlockState(world, Blocks.GRASS_BLOCK.getDefaultState().with(SnowyDirtBlock.SNOWY, false), 16, 4, 17, start);
        structure.setBlockState(world, Blocks.STONE_BRICK_STAIRS.getDefaultState().with(StairsBlock.FACING, Direction.SOUTH).with(StairsBlock.WATERLOGGED, false).with(StairsBlock.SHAPE, StairsShape.STRAIGHT).with(StairsBlock.HALF, Half.BOTTOM), 16, 7, 10, start);
        structure.setBlockState(world, Blocks.STONE_BRICK_STAIRS.getDefaultState().with(StairsBlock.FACING, Direction.WEST).with(StairsBlock.WATERLOGGED, false).with(StairsBlock.SHAPE, StairsShape.STRAIGHT).with(StairsBlock.HALF, Half.BOTTOM), 16, 7, 12, start);
        structure.setBlockState(world, Blocks.VINE.getDefaultState().with(VineBlock.UP, false).with(VineBlock.NORTH, false).with(VineBlock.SOUTH, false).with(VineBlock.EAST, false).with(VineBlock.WEST, true), 16, 10, 10, start);
        structure.setBlockState(world, Blocks.STONE_BRICK_STAIRS.getDefaultState().with(StairsBlock.FACING, Direction.WEST).with(StairsBlock.WATERLOGGED, false).with(StairsBlock.SHAPE, StairsShape.STRAIGHT).with(StairsBlock.HALF, Half.BOTTOM), 16, 10, 11, start);
        structure.setBlockState(world, Blocks.STONE.getDefaultState(), 17, 0, 15, start);
        structure.setBlockState(world, Blocks.GRASS_BLOCK.getDefaultState().with(SnowyDirtBlock.SNOWY, false), 17, 2, 18, start);
        structure.setBlockState(world, Blocks.GRASS_BLOCK.getDefaultState().with(SnowyDirtBlock.SNOWY, false), 17, 3, 17, start);
        structure.setBlockState(world, Blocks.GRASS_BLOCK.getDefaultState().with(SnowyDirtBlock.SNOWY, false), 17, 4, 16, start);
        structure.setBlockState(world, Blocks.VINE.getDefaultState().with(VineBlock.UP, false).with(VineBlock.NORTH, false).with(VineBlock.SOUTH, false).with(VineBlock.EAST, false).with(VineBlock.WEST, true), 17, 9, 11, start);
        structure.setBlockState(world, Blocks.GRASS_BLOCK.getDefaultState().with(SnowyDirtBlock.SNOWY, false), 18, 0, 19, start);
        structure.setBlockState(world, Blocks.GRASS_BLOCK.getDefaultState().with(SnowyDirtBlock.SNOWY, false), 18, 1, 18, start);
        structure.setBlockState(world, Blocks.GRASS_BLOCK.getDefaultState().with(SnowyDirtBlock.SNOWY, false), 18, 2, 5, start);
        structure.setBlockState(world, Blocks.GRASS_BLOCK.getDefaultState().with(SnowyDirtBlock.SNOWY, false), 18, 2, 17, start);
        structure.setBlockState(world, Blocks.GRASS_BLOCK.getDefaultState().with(SnowyDirtBlock.SNOWY, false), 18, 3, 6, start);
        structure.setBlockState(world, Blocks.GRASS_BLOCK.getDefaultState().with(SnowyDirtBlock.SNOWY, false), 18, 3, 16, start);
        structure.setBlockState(world, Blocks.GRASS_BLOCK.getDefaultState().with(SnowyDirtBlock.SNOWY, false), 19, 0, 4, start);
        structure.setBlockState(world, Blocks.GRASS_BLOCK.getDefaultState().with(SnowyDirtBlock.SNOWY, false), 19, 0, 18, start);
        structure.setBlockState(world, Blocks.GRASS_BLOCK.getDefaultState().with(SnowyDirtBlock.SNOWY, false), 19, 2, 7, start);
        structure.setBlockState(world, Blocks.GRASS_BLOCK.getDefaultState().with(SnowyDirtBlock.SNOWY, false), 19, 2, 15, start);
        structure.setBlockState(world, Blocks.GRASS_BLOCK.getDefaultState().with(SnowyDirtBlock.SNOWY, false), 20, 0, 6, start);
        structure.setBlockState(world, Blocks.GRASS_BLOCK.getDefaultState().with(SnowyDirtBlock.SNOWY, false), 20, 0, 16, start);
        structure.fillWithBlocks(world, start, 1, 0, 8, 1, 0, 9, Blocks.GRASS_BLOCK.getDefaultState().with(SnowyDirtBlock.SNOWY, false));
        structure.fillWithBlocks(world, start, 1, 0, 10, 2, 0, 12, Blocks.DIRT.getDefaultState());
        structure.fillWithBlocks(world, start, 1, 0, 13, 1, 0, 14, Blocks.GRASS_BLOCK.getDefaultState().with(SnowyDirtBlock.SNOWY, false));
        structure.fillWithBlocks(world, start, 1, 1, 10, 1, 1, 12, Blocks.GRASS_BLOCK.getDefaultState().with(SnowyDirtBlock.SNOWY, false));
        structure.fillWithBlocks(world, start, 2, 0, 7, 3, 0, 10, Blocks.DIRT.getDefaultState());
        structure.fillWithBlocks(world, start, 2, 0, 13, 3, 0, 15, Blocks.DIRT.getDefaultState());
        structure.fillWithBlocks(world, start, 2, 1, 7, 2, 1, 8, Blocks.GRASS_BLOCK.getDefaultState().with(SnowyDirtBlock.SNOWY, false));
        structure.fillWithBlocks(world, start, 2, 1, 9, 4, 1, 11, Blocks.DIRT.getDefaultState());
        structure.fillWithBlocks(world, start, 2, 1, 12, 3, 1, 13, Blocks.DIRT.getDefaultState());
        structure.fillWithBlocks(world, start, 2, 1, 14, 2, 1, 15, Blocks.GRASS_BLOCK.getDefaultState().with(SnowyDirtBlock.SNOWY, false));
        structure.fillWithBlocks(world, start, 2, 2, 9, 2, 2, 13, Blocks.GRASS_BLOCK.getDefaultState().with(SnowyDirtBlock.SNOWY, false));
        structure.fillWithBlocks(world, start, 3, 0, 5, 6, 0, 8, Blocks.DIRT.getDefaultState());
        structure.fillWithBlocks(world, start, 3, 0, 11, 3, 0, 12, Blocks.STONE.getDefaultState());
        structure.fillWithBlocks(world, start, 3, 0, 16, 4, 0, 17, Blocks.DIRT.getDefaultState());
        structure.fillWithBlocks(world, start, 3, 0, 18, 3, 0, 18, Blocks.GRASS_BLOCK.getDefaultState().with(SnowyDirtBlock.SNOWY, false));
        structure.fillWithBlocks(world, start, 3, 1, 5, 3, 1, 6, Blocks.GRASS_BLOCK.getDefaultState().with(SnowyDirtBlock.SNOWY, false));
        structure.fillWithBlocks(world, start, 3, 1, 7, 6, 1, 11, Blocks.DIRT.getDefaultState());
        structure.fillWithBlocks(world, start, 3, 1, 14, 4, 1, 15, Blocks.DIRT.getDefaultState());
        structure.fillWithBlocks(world, start, 3, 1, 16, 3, 1, 17, Blocks.GRASS_BLOCK.getDefaultState().with(SnowyDirtBlock.SNOWY, false));
        structure.fillWithBlocks(world, start, 3, 2, 8, 9, 2, 14, Blocks.DIRT.getDefaultState());
        structure.fillWithBlocks(world, start, 3, 3, 8, 3, 3, 9, Blocks.GRASS_BLOCK.getDefaultState().with(SnowyDirtBlock.SNOWY, false));
        structure.fillWithBlocks(world, start, 3, 3, 10, 5, 3, 12, Blocks.DIRT.getDefaultState());
        structure.fillWithBlocks(world, start, 3, 3, 13, 3, 3, 14, Blocks.GRASS_BLOCK.getDefaultState().with(SnowyDirtBlock.SNOWY, false));
        structure.fillWithBlocks(world, start, 3, 4, 10, 3, 4, 12, Blocks.GRASS_BLOCK.getDefaultState().with(SnowyDirtBlock.SNOWY, false));
        structure.fillWithBlocks(world, start, 4, 0, 4, 8, 0, 8, Blocks.DIRT.getDefaultState());
        structure.fillWithBlocks(world, start, 4, 0, 10, 5, 0, 12, Blocks.DIRT.getDefaultState());
        structure.fillWithBlocks(world, start, 4, 0, 13, 4, 0, 15, Blocks.STONE.getDefaultState());
        structure.fillWithBlocks(world, start, 4, 0, 18, 4, 0, 18, Blocks.DIRT.getDefaultState());
        structure.fillWithBlocks(world, start, 4, 1, 5, 8, 1, 9, Blocks.DIRT.getDefaultState());
        structure.fillWithBlocks(world, start, 4, 1, 12, 4, 1, 13, Blocks.STONE.getDefaultState());
        structure.fillWithBlocks(world, start, 4, 1, 16, 5, 1, 17, Blocks.DIRT.getDefaultState());
        structure.fillWithBlocks(world, start, 4, 1, 18, 4, 1, 18, Blocks.GRASS_BLOCK.getDefaultState().with(SnowyDirtBlock.SNOWY, false));
        structure.fillWithBlocks(world, start, 4, 2, 6, 14, 2, 16, Blocks.DIRT.getDefaultState());
        structure.fillWithBlocks(world, start, 4, 2, 17, 4, 2, 17, Blocks.GRASS_BLOCK.getDefaultState().with(SnowyDirtBlock.SNOWY, false));
        structure.fillWithBlocks(world, start, 4, 3, 7, 12, 3, 15, Blocks.DIRT.getDefaultState());
        structure.fillWithBlocks(world, start, 4, 3, 16, 4, 3, 16, Blocks.GRASS_BLOCK.getDefaultState().with(SnowyDirtBlock.SNOWY, false));
        structure.fillWithBlocks(world, start, 4, 4, 7, 4, 4, 8, Blocks.GRASS_BLOCK.getDefaultState().with(SnowyDirtBlock.SNOWY, false));
        structure.fillWithBlocks(world, start, 4, 4, 9, 8, 4, 13, Blocks.DIRT.getDefaultState());
        structure.fillWithBlocks(world, start, 4, 4, 14, 4, 4, 15, Blocks.GRASS_BLOCK.getDefaultState().with(SnowyDirtBlock.SNOWY, false));
        structure.fillWithBlocks(world, start, 4, 5, 9, 4, 5, 13, Blocks.GRASS_BLOCK.getDefaultState().with(SnowyDirtBlock.SNOWY, false));
        structure.fillWithBlocks(world, start, 5, 0, 3, 8, 0, 8, Blocks.DIRT.getDefaultState());
        structure.fillWithBlocks(world, start, 5, 0, 9, 5, 4, 14, Blocks.DIRT.getDefaultState());
        structure.fillWithBlocks(world, start, 5, 0, 15, 5, 0, 16, Blocks.STONE.getDefaultState());
        structure.fillWithBlocks(world, start, 5, 0, 17, 5, 0, 19, Blocks.DIRT.getDefaultState());
        structure.fillWithBlocks(world, start, 5, 1, 3, 6, 1, 3, Blocks.GRASS_BLOCK.getDefaultState().with(SnowyDirtBlock.SNOWY, false));
        structure.fillWithBlocks(world, start, 5, 1, 4, 10, 1, 9, Blocks.DIRT.getDefaultState());
        structure.fillWithBlocks(world, start, 5, 1, 15, 5, 1, 15, Blocks.STONE.getDefaultState());
        structure.fillWithBlocks(world, start, 5, 1, 18, 17, 1, 18, Blocks.DIRT.getDefaultState());
        structure.fillWithBlocks(world, start, 5, 1, 19, 6, 1, 19, Blocks.GRASS_BLOCK.getDefaultState().with(SnowyDirtBlock.SNOWY, false));
        structure.fillWithBlocks(world, start, 5, 2, 5, 17, 2, 17, Blocks.DIRT.getDefaultState());
        structure.fillWithBlocks(world, start, 5, 3, 6, 15, 3, 16, Blocks.DIRT.getDefaultState());
        structure.fillWithBlocks(world, start, 5, 3, 17, 5, 3, 17, Blocks.GRASS_BLOCK.getDefaultState().with(SnowyDirtBlock.SNOWY, false));
        structure.fillWithBlocks(world, start, 5, 4, 7, 13, 4, 15, Blocks.DIRT.getDefaultState());
        structure.fillWithBlocks(world, start, 5, 4, 16, 5, 4, 16, Blocks.GRASS_BLOCK.getDefaultState().with(SnowyDirtBlock.SNOWY, false));
        structure.fillWithBlocks(world, start, 5, 5, 7, 5, 5, 9, Blocks.GRASS_BLOCK.getDefaultState().with(SnowyDirtBlock.SNOWY, false));
        structure.fillWithBlocks(world, start, 5, 5, 10, 7, 5, 12, Blocks.DIRT.getDefaultState());
        structure.fillWithBlocks(world, start, 5, 5, 13, 5, 5, 15, Blocks.GRASS_BLOCK.getDefaultState().with(SnowyDirtBlock.SNOWY, false));
        structure.fillWithBlocks(world, start, 5, 6, 10, 5, 6, 12, Blocks.GRASS_BLOCK.getDefaultState().with(SnowyDirtBlock.SNOWY, false));
        structure.fillWithBlocks(world, start, 6, 0, 9, 6, 5, 9, Blocks.DIRT.getDefaultState());
        structure.fillWithBlocks(world, start, 6, 0, 10, 7, 0, 12, Blocks.STONE.getDefaultState());
        structure.fillWithBlocks(world, start, 6, 0, 13, 6, 2, 15, Blocks.DIRT.getDefaultState());
        structure.fillWithBlocks(world, start, 6, 0, 16, 9, 0, 16, Blocks.DIRT.getDefaultState());
        structure.fillWithBlocks(world, start, 6, 0, 17, 7, 0, 17, Blocks.STONE.getDefaultState());
        structure.fillWithBlocks(world, start, 6, 0, 18, 7, 0, 19, Blocks.DIRT.getDefaultState());
        structure.fillWithBlocks(world, start, 6, 1, 12, 6, 4, 15, Blocks.DIRT.getDefaultState());
        structure.fillWithBlocks(world, start, 6, 1, 17, 7, 1, 18, Blocks.DIRT.getDefaultState());
        structure.fillWithBlocks(world, start, 6, 2, 4, 16, 2, 18, Blocks.DIRT.getDefaultState());
        structure.fillWithBlocks(world, start, 6, 3, 5, 16, 3, 17, Blocks.DIRT.getDefaultState());
        structure.fillWithBlocks(world, start, 6, 4, 6, 16, 4, 16, Blocks.DIRT.getDefaultState());
        structure.fillWithBlocks(world, start, 6, 4, 17, 6, 4, 17, Blocks.GRASS_BLOCK.getDefaultState().with(SnowyDirtBlock.SNOWY, false));
        structure.fillWithBlocks(world, start, 6, 5, 6, 6, 5, 7, Blocks.GRASS_BLOCK.getDefaultState().with(SnowyDirtBlock.SNOWY, false));
        structure.fillWithBlocks(world, start, 6, 5, 8, 12, 5, 14, Blocks.DIRT.getDefaultState());
        structure.fillWithBlocks(world, start, 6, 5, 15, 6, 5, 16, Blocks.GRASS_BLOCK.getDefaultState().with(SnowyDirtBlock.SNOWY, false));
        structure.fillWithBlocks(world, start, 6, 6, 8, 6, 6, 9, Blocks.GRASS_BLOCK.getDefaultState().with(SnowyDirtBlock.SNOWY, false));
        structure.fillWithBlocks(world, start, 6, 6, 10, 8, 6, 12, Blocks.DIRT.getDefaultState());
        structure.fillWithBlocks(world, start, 6, 6, 13, 6, 6, 14, Blocks.GRASS_BLOCK.getDefaultState().with(SnowyDirtBlock.SNOWY, false));
        structure.fillWithBlocks(world, start, 6, 7, 11, 6, 7, 11, Blocks.MOSSY_STONE_BRICKS.getDefaultState());
        structure.fillWithBlocks(world, start, 6, 8, 11, 6, 8, 11, Blocks.MOSSY_STONE_BRICKS.getDefaultState());
        structure.fillWithBlocks(world, start, 6, 25, 12, 6, 27, 12, Blocks.VINE.getDefaultState().with(VineBlock.UP, false).with(VineBlock.NORTH, false).with(VineBlock.SOUTH, false).with(VineBlock.EAST, true).with(VineBlock.WEST, false));
        structure.fillWithBlocks(world, start, 7, 0, 2, 11, 0, 6, Blocks.DIRT.getDefaultState());
        structure.fillWithBlocks(world, start, 7, 0, 9, 7, 0, 14, Blocks.STONE.getDefaultState());
        structure.fillWithBlocks(world, start, 7, 0, 15, 7, 0, 16, Blocks.DIRT.getDefaultState());
        structure.fillWithBlocks(world, start, 7, 0, 20, 15, 0, 20, Blocks.DIRT.getDefaultState());
        structure.fillWithBlocks(world, start, 7, 1, 2, 8, 1, 2, Blocks.GRASS_BLOCK.getDefaultState().with(SnowyDirtBlock.SNOWY, false));
        structure.fillWithBlocks(world, start, 7, 1, 3, 13, 1, 9, Blocks.DIRT.getDefaultState());
        structure.fillWithBlocks(world, start, 7, 1, 10, 7, 1, 13, Blocks.STONE.getDefaultState());
        structure.fillWithBlocks(world, start, 7, 1, 14, 8, 1, 19, Blocks.DIRT.getDefaultState());
        structure.fillWithBlocks(world, start, 7, 1, 20, 8, 1, 20, Blocks.GRASS_BLOCK.getDefaultState().with(SnowyDirtBlock.SNOWY, false));
        structure.fillWithBlocks(world, start, 7, 3, 4, 15, 3, 18, Blocks.DIRT.getDefaultState());
        structure.fillWithBlocks(world, start, 7, 4, 4, 8, 4, 4, Blocks.GRASS_BLOCK.getDefaultState().with(SnowyDirtBlock.SNOWY, false));
        structure.fillWithBlocks(world, start, 7, 4, 5, 15, 4, 17, Blocks.DIRT.getDefaultState());
        structure.fillWithBlocks(world, start, 7, 4, 18, 8, 4, 18, Blocks.GRASS_BLOCK.getDefaultState().with(SnowyDirtBlock.SNOWY, false));
        structure.fillWithBlocks(world, start, 7, 5, 5, 7, 5, 6, Blocks.GRASS_BLOCK.getDefaultState().with(SnowyDirtBlock.SNOWY, false));
        structure.fillWithBlocks(world, start, 7, 5, 7, 15, 5, 15, Blocks.DIRT.getDefaultState());
        structure.fillWithBlocks(world, start, 7, 5, 16, 7, 5, 17, Blocks.GRASS_BLOCK.getDefaultState().with(SnowyDirtBlock.SNOWY, false));
        structure.fillWithBlocks(world, start, 7, 6, 7, 7, 6, 8, Blocks.GRASS_BLOCK.getDefaultState().with(SnowyDirtBlock.SNOWY, false));
        structure.fillWithBlocks(world, start, 7, 6, 9, 11, 6, 13, Blocks.DIRT.getDefaultState());
        structure.fillWithBlocks(world, start, 7, 6, 14, 7, 6, 15, Blocks.GRASS_BLOCK.getDefaultState().with(SnowyDirtBlock.SNOWY, false));
        structure.fillWithBlocks(world, start, 7, 7, 9, 10, 7, 12, Blocks.MOSSY_STONE_BRICKS.getDefaultState());
        structure.fillWithBlocks(world, start, 7, 8, 10, 9, 8, 13, Blocks.MOSSY_STONE_BRICKS.getDefaultState());
        structure.fillWithBlocks(world, start, 7, 9, 9, 9, 9, 13, Blocks.MOSSY_STONE_BRICKS.getDefaultState());
        structure.fillWithBlocks(world, start, 7, 10, 10, 8, 10, 11, Blocks.MOSSY_STONE_BRICKS.getDefaultState());
        structure.fillWithBlocks(world, start, 7, 10, 13, 7, 11, 13, Blocks.VINE.getDefaultState().with(VineBlock.UP, false).with(VineBlock.NORTH, true).with(VineBlock.SOUTH, false).with(VineBlock.EAST, true).with(VineBlock.WEST, false));
        structure.fillWithBlocks(world, start, 7, 11, 11, 8, 11, 12, Blocks.MOSSY_STONE_BRICKS.getDefaultState());
        structure.fillWithBlocks(world, start, 7, 12, 11, 7, 12, 11, Blocks.MOSSY_STONE_BRICKS.getDefaultState());
        structure.fillWithBlocks(world, start, 7, 13, 11, 7, 13, 11, Blocks.MOSSY_STONE_BRICKS.getDefaultState());
        structure.fillWithBlocks(world, start, 7, 18, 10, 8, 19, 10, Blocks.VINE.getDefaultState().with(VineBlock.UP, false).with(VineBlock.NORTH, false).with(VineBlock.SOUTH, false).with(VineBlock.EAST, true).with(VineBlock.WEST, false));
        structure.fillWithBlocks(world, start, 7, 18, 13, 7, 25, 13, Blocks.VINE.getDefaultState().with(VineBlock.UP, false).with(VineBlock.NORTH, false).with(VineBlock.SOUTH, false).with(VineBlock.EAST, true).with(VineBlock.WEST, false));
        structure.fillWithBlocks(world, start, 7, 20, 10, 8, 20, 10, Blocks.VINE.getDefaultState().with(VineBlock.UP, false).with(VineBlock.NORTH, false).with(VineBlock.SOUTH, false).with(VineBlock.EAST, true).with(VineBlock.WEST, false));
        structure.fillWithBlocks(world, start, 7, 21, 8, 7, 27, 8, Blocks.VINE.getDefaultState().with(VineBlock.UP, false).with(VineBlock.NORTH, false).with(VineBlock.SOUTH, true).with(VineBlock.EAST, false).with(VineBlock.WEST, false));
        structure.fillWithBlocks(world, start, 7, 21, 10, 7, 25, 10, Blocks.VINE.getDefaultState().with(VineBlock.UP, false).with(VineBlock.NORTH, false).with(VineBlock.SOUTH, false).with(VineBlock.EAST, true).with(VineBlock.WEST, false));
        structure.fillWithBlocks(world, start, 7, 25, 14, 7, 27, 14, Blocks.VINE.getDefaultState().with(VineBlock.UP, false).with(VineBlock.NORTH, false).with(VineBlock.SOUTH, false).with(VineBlock.EAST, true).with(VineBlock.WEST, false));
        structure.fillWithBlocks(world, start, 7, 27, 9, 8, 27, 13, Blocks.GRAY_TERRACOTTA.getDefaultState());
        structure.fillWithBlocks(world, start, 8, 0, 1, 9, 0, 1, Blocks.GRASS_BLOCK.getDefaultState().with(SnowyDirtBlock.SNOWY, false));
        structure.fillWithBlocks(world, start, 8, 0, 9, 13, 0, 14, Blocks.DIRT.getDefaultState());
        structure.fillWithBlocks(world, start, 8, 0, 15, 14, 0, 15, Blocks.STONE.getDefaultState());
        structure.fillWithBlocks(world, start, 8, 0, 17, 8, 2, 19, Blocks.DIRT.getDefaultState());
        structure.fillWithBlocks(world, start, 8, 0, 21, 9, 0, 21, Blocks.GRASS_BLOCK.getDefaultState().with(SnowyDirtBlock.SNOWY, false));
        structure.fillWithBlocks(world, start, 8, 1, 10, 12, 1, 14, Blocks.DIRT.getDefaultState());
        structure.fillWithBlocks(world, start, 8, 2, 3, 14, 2, 19, Blocks.DIRT.getDefaultState());
        structure.fillWithBlocks(world, start, 8, 3, 3, 9, 3, 3, Blocks.GRASS_BLOCK.getDefaultState().with(SnowyDirtBlock.SNOWY, false));
        structure.fillWithBlocks(world, start, 8, 3, 19, 9, 3, 19, Blocks.GRASS_BLOCK.getDefaultState().with(SnowyDirtBlock.SNOWY, false));
        structure.fillWithBlocks(world, start, 8, 5, 5, 9, 5, 5, Blocks.GRASS_BLOCK.getDefaultState().with(SnowyDirtBlock.SNOWY, false));
        structure.fillWithBlocks(world, start, 8, 5, 6, 14, 5, 16, Blocks.DIRT.getDefaultState());
        structure.fillWithBlocks(world, start, 8, 5, 17, 8, 5, 17, Blocks.GRASS_BLOCK.getDefaultState().with(SnowyDirtBlock.SNOWY, false));
        structure.fillWithBlocks(world, start, 8, 6, 6, 9, 6, 6, Blocks.GRASS_BLOCK.getDefaultState().with(SnowyDirtBlock.SNOWY, false));
        structure.fillWithBlocks(world, start, 8, 6, 7, 14, 6, 15, Blocks.DIRT.getDefaultState());
        structure.fillWithBlocks(world, start, 8, 6, 16, 9, 6, 16, Blocks.GRASS_BLOCK.getDefaultState().with(SnowyDirtBlock.SNOWY, false));
        structure.fillWithBlocks(world, start, 8, 7, 8, 14, 7, 14, Blocks.MOSSY_STONE_BRICKS.getDefaultState());
        structure.fillWithBlocks(world, start, 8, 8, 8, 9, 8, 14, Blocks.MOSSY_STONE_BRICKS.getDefaultState());
        structure.fillWithBlocks(world, start, 8, 10, 12, 9, 10, 13, Blocks.MOSSY_STONE_BRICKS.getDefaultState());
        structure.fillWithBlocks(world, start, 8, 11, 9, 9, 11, 12, Blocks.MOSSY_STONE_BRICKS.getDefaultState());
        structure.fillWithBlocks(world, start, 8, 12, 10, 9, 12, 12, Blocks.MOSSY_STONE_BRICKS.getDefaultState());
        structure.fillWithBlocks(world, start, 8, 13, 10, 9, 13, 12, Blocks.MOSSY_STONE_BRICKS.getDefaultState());
        structure.fillWithBlocks(world, start, 8, 14, 11, 9, 14, 11, Blocks.MOSSY_STONE_BRICKS.getDefaultState());
        structure.fillWithBlocks(world, start, 8, 16, 10, 8, 20, 10, Blocks.VINE.getDefaultState().with(VineBlock.UP, false).with(VineBlock.NORTH, false).with(VineBlock.SOUTH, false).with(VineBlock.EAST, true).with(VineBlock.WEST, false));
        structure.fillWithBlocks(world, start, 8, 19, 11, 9, 19, 11, Blocks.DARK_OAK_PLANKS.getDefaultState());
        structure.fillWithBlocks(world, start, 8, 20, 9, 8, 20, 10, Blocks.VINE.getDefaultState().with(VineBlock.UP, false).with(VineBlock.NORTH, false).with(VineBlock.SOUTH, false).with(VineBlock.EAST, true).with(VineBlock.WEST, false));
        structure.fillWithBlocks(world, start, 8, 22, 10, 9, 22, 12, Blocks.MOSSY_STONE_BRICKS.getDefaultState());
        structure.fillWithBlocks(world, start, 8, 23, 10, 8, 24, 11, Blocks.MOSSY_STONE_BRICKS.getDefaultState());
        structure.fillWithBlocks(world, start, 8, 24, 9, 8, 24, 13, Blocks.MOSSY_STONE_BRICKS.getDefaultState());
        structure.fillWithBlocks(world, start, 8, 25, 7, 8, 27, 7, Blocks.VINE.getDefaultState().with(VineBlock.UP, false).with(VineBlock.NORTH, false).with(VineBlock.SOUTH, false).with(VineBlock.EAST, true).with(VineBlock.WEST, false));
        structure.fillWithBlocks(world, start, 8, 25, 10, 8, 26, 10, Blocks.MOSSY_STONE_BRICKS.getDefaultState());
        structure.fillWithBlocks(world, start, 8, 25, 11, 8, 26, 11, Blocks.BLACK_STAINED_GLASS_PANE.getDefaultState().with(FourWayBlock.WATERLOGGED, false).with(FourWayBlock.NORTH, true).with(FourWayBlock.SOUTH, true).with(FourWayBlock.EAST, false).with(FourWayBlock.WEST, false));
        structure.fillWithBlocks(world, start, 8, 25, 12, 8, 25, 13, Blocks.MOSSY_STONE_BRICKS.getDefaultState());
        structure.fillWithBlocks(world, start, 8, 26, 9, 8, 26, 10, Blocks.MOSSY_STONE_BRICKS.getDefaultState());
        structure.fillWithBlocks(world, start, 8, 26, 13, 8, 26, 13, Blocks.MOSSY_STONE_BRICKS.getDefaultState());
        structure.fillWithBlocks(world, start, 8, 27, 8, 8, 27, 14, Blocks.GRAY_TERRACOTTA.getDefaultState());
        structure.fillWithBlocks(world, start, 8, 28, 10, 8, 28, 12, Blocks.GRAY_TERRACOTTA.getDefaultState());
        structure.fillWithBlocks(world, start, 8, 29, 11, 8, 29, 11, Blocks.GRAY_TERRACOTTA.getDefaultState());
        structure.fillWithBlocks(world, start, 8, 29, 12, 8, 29, 12, Blocks.VINE.getDefaultState().with(VineBlock.UP, false).with(VineBlock.NORTH, true).with(VineBlock.SOUTH, false).with(VineBlock.EAST, false).with(VineBlock.WEST, false));
        structure.fillWithBlocks(world, start, 9, 0, 7, 13, 0, 7, Blocks.STONE.getDefaultState());
        structure.fillWithBlocks(world, start, 9, 0, 8, 14, 0, 14, Blocks.DIRT.getDefaultState());
        structure.fillWithBlocks(world, start, 9, 0, 17, 9, 0, 17, Blocks.DIRT.getDefaultState());
        structure.fillWithBlocks(world, start, 9, 0, 19, 10, 0, 20, Blocks.DIRT.getDefaultState());
        structure.fillWithBlocks(world, start, 9, 1, 2, 13, 1, 14, Blocks.DIRT.getDefaultState());
        structure.fillWithBlocks(world, start, 9, 1, 15, 13, 1, 15, Blocks.STONE.getDefaultState());
        structure.fillWithBlocks(world, start, 9, 1, 16, 13, 1, 20, Blocks.DIRT.getDefaultState());
        structure.fillWithBlocks(world, start, 9, 2, 2, 13, 2, 2, Blocks.GRASS_BLOCK.getDefaultState().with(SnowyDirtBlock.SNOWY, false));
        structure.fillWithBlocks(world, start, 9, 2, 20, 13, 2, 20, Blocks.GRASS_BLOCK.getDefaultState().with(SnowyDirtBlock.SNOWY, false));
        structure.fillWithBlocks(world, start, 9, 4, 4, 13, 4, 18, Blocks.DIRT.getDefaultState());
        structure.fillWithBlocks(world, start, 9, 5, 4, 9, 5, 5, Blocks.GRASS_BLOCK.getDefaultState().with(SnowyDirtBlock.SNOWY, false));
        structure.fillWithBlocks(world, start, 9, 5, 17, 9, 5, 18, Blocks.GRASS_BLOCK.getDefaultState().with(SnowyDirtBlock.SNOWY, false));
        structure.fillWithBlocks(world, start, 9, 7, 7, 13, 7, 15, Blocks.MOSSY_STONE_BRICKS.getDefaultState());
        structure.fillWithBlocks(world, start, 9, 7, 16, 9, 8, 16, Blocks.VINE.getDefaultState().with(VineBlock.UP, false).with(VineBlock.NORTH, true).with(VineBlock.SOUTH, false).with(VineBlock.EAST, false).with(VineBlock.WEST, false));
        structure.fillWithBlocks(world, start, 9, 8, 7, 9, 8, 15, Blocks.MOSSY_STONE_BRICKS.getDefaultState());
        structure.fillWithBlocks(world, start, 9, 9, 7, 9, 11, 7, Blocks.VINE.getDefaultState().with(VineBlock.UP, false).with(VineBlock.NORTH, false).with(VineBlock.SOUTH, false).with(VineBlock.EAST, true).with(VineBlock.WEST, false));
        structure.fillWithBlocks(world, start, 9, 9, 14, 9, 9, 14, Blocks.MOSSY_STONE_BRICKS.getDefaultState());
        structure.fillWithBlocks(world, start, 9, 10, 8, 9, 11, 14, Blocks.MOSSY_STONE_BRICKS.getDefaultState());
        structure.fillWithBlocks(world, start, 9, 12, 8, 9, 13, 8, Blocks.VINE.getDefaultState().with(VineBlock.UP, false).with(VineBlock.NORTH, false).with(VineBlock.SOUTH, true).with(VineBlock.EAST, true).with(VineBlock.WEST, false));
        structure.fillWithBlocks(world, start, 9, 12, 9, 9, 12, 13, Blocks.MOSSY_STONE_BRICKS.getDefaultState());
        structure.fillWithBlocks(world, start, 9, 12, 14, 9, 20, 14, Blocks.VINE.getDefaultState().with(VineBlock.UP, false).with(VineBlock.NORTH, true).with(VineBlock.SOUTH, false).with(VineBlock.EAST, false).with(VineBlock.WEST, false));
        structure.fillWithBlocks(world, start, 9, 14, 8, 10, 15, 8, Blocks.VINE.getDefaultState().with(VineBlock.UP, false).with(VineBlock.NORTH, false).with(VineBlock.SOUTH, true).with(VineBlock.EAST, false).with(VineBlock.WEST, false));
        structure.fillWithBlocks(world, start, 9, 14, 9, 9, 14, 11, Blocks.MOSSY_STONE_BRICKS.getDefaultState());
        structure.fillWithBlocks(world, start, 9, 14, 13, 13, 14, 13, Blocks.MOSSY_STONE_BRICKS.getDefaultState());
        structure.fillWithBlocks(world, start, 9, 15, 10, 9, 15, 12, Blocks.MOSSY_STONE_BRICKS.getDefaultState());
        structure.fillWithBlocks(world, start, 9, 16, 8, 10, 16, 8, Blocks.VINE.getDefaultState().with(VineBlock.UP, false).with(VineBlock.NORTH, false).with(VineBlock.SOUTH, true).with(VineBlock.EAST, false).with(VineBlock.WEST, false));
        structure.fillWithBlocks(world, start, 9, 16, 9, 9, 16, 10, Blocks.MOSSY_STONE_BRICKS.getDefaultState());
        structure.fillWithBlocks(world, start, 9, 16, 12, 9, 16, 13, Blocks.MOSSY_STONE_BRICKS.getDefaultState());
        structure.fillWithBlocks(world, start, 9, 17, 11, 9, 18, 11, Blocks.MOSSY_STONE_BRICKS.getDefaultState());
        structure.fillWithBlocks(world, start, 9, 18, 9, 9, 18, 12, Blocks.MOSSY_STONE_BRICKS.getDefaultState());
        structure.fillWithBlocks(world, start, 9, 18, 13, 9, 18, 14, Blocks.VINE.getDefaultState().with(VineBlock.UP, false).with(VineBlock.NORTH, true).with(VineBlock.SOUTH, false).with(VineBlock.EAST, false).with(VineBlock.WEST, false));
        structure.fillWithBlocks(world, start, 9, 19, 10, 9, 22, 10, Blocks.MOSSY_STONE_BRICKS.getDefaultState());
        structure.fillWithBlocks(world, start, 9, 19, 12, 9, 19, 12, Blocks.MOSSY_STONE_BRICKS.getDefaultState());
        structure.fillWithBlocks(world, start, 9, 20, 9, 9, 20, 11, Blocks.MOSSY_STONE_BRICKS.getDefaultState());
        structure.fillWithBlocks(world, start, 9, 20, 13, 13, 20, 13, Blocks.MOSSY_STONE_BRICKS.getDefaultState());
        structure.fillWithBlocks(world, start, 9, 21, 11, 9, 22, 12, Blocks.MOSSY_STONE_BRICKS.getDefaultState());
        structure.fillWithBlocks(world, start, 9, 22, 9, 9, 22, 12, Blocks.MOSSY_STONE_BRICKS.getDefaultState());
        structure.fillWithBlocks(world, start, 9, 23, 10, 11, 23, 12, Blocks.DARK_OAK_PLANKS.getDefaultState());
        structure.fillWithBlocks(world, start, 9, 23, 13, 9, 23, 13, Blocks.MOSSY_STONE_BRICKS.getDefaultState());
        structure.fillWithBlocks(world, start, 9, 24, 8, 9, 26, 8, Blocks.MOSSY_STONE_BRICKS.getDefaultState());
        structure.fillWithBlocks(world, start, 9, 25, 14, 10, 25, 14, Blocks.MOSSY_STONE_BRICKS.getDefaultState());
        structure.fillWithBlocks(world, start, 9, 27, 7, 10, 27, 8, Blocks.GRAY_TERRACOTTA.getDefaultState());
        structure.fillWithBlocks(world, start, 9, 27, 9, 9, 27, 10, Blocks.COBWEB.getDefaultState());
        structure.fillWithBlocks(world, start, 9, 27, 14, 10, 27, 15, Blocks.GRAY_TERRACOTTA.getDefaultState());
        structure.fillWithBlocks(world, start, 9, 28, 9, 9, 28, 10, Blocks.GRAY_TERRACOTTA.getDefaultState());
        structure.fillWithBlocks(world, start, 9, 28, 12, 9, 28, 13, Blocks.GRAY_TERRACOTTA.getDefaultState());
        structure.fillWithBlocks(world, start, 9, 29, 10, 11, 29, 12, Blocks.GRAY_TERRACOTTA.getDefaultState());
        structure.fillWithBlocks(world, start, 9, 29, 13, 9, 30, 13, Blocks.VINE.getDefaultState().with(VineBlock.UP, false).with(VineBlock.NORTH, true).with(VineBlock.SOUTH, false).with(VineBlock.EAST, false).with(VineBlock.WEST, false));
        structure.fillWithBlocks(world, start, 9, 30, 10, 11, 30, 12, Blocks.GRAY_TERRACOTTA.getDefaultState());
        structure.fillWithBlocks(world, start, 9, 31, 11, 9, 31, 11, Blocks.GRAY_TERRACOTTA.getDefaultState());
        structure.fillWithBlocks(world, start, 10, 0, 1, 12, 0, 6, Blocks.DIRT.getDefaultState());
        structure.fillWithBlocks(world, start, 10, 0, 16, 12, 0, 16, Blocks.STONE.getDefaultState());
        structure.fillWithBlocks(world, start, 10, 0, 17, 12, 0, 21, Blocks.DIRT.getDefaultState());
        structure.fillWithBlocks(world, start, 10, 1, 1, 12, 1, 1, Blocks.GRASS_BLOCK.getDefaultState().with(SnowyDirtBlock.SNOWY, false));
        structure.fillWithBlocks(world, start, 10, 1, 21, 12, 1, 21, Blocks.GRASS_BLOCK.getDefaultState().with(SnowyDirtBlock.SNOWY, false));
        structure.fillWithBlocks(world, start, 10, 3, 3, 12, 3, 19, Blocks.DIRT.getDefaultState());
        structure.fillWithBlocks(world, start, 10, 4, 3, 12, 4, 3, Blocks.GRASS_BLOCK.getDefaultState().with(SnowyDirtBlock.SNOWY, false));
        structure.fillWithBlocks(world, start, 10, 4, 19, 12, 4, 19, Blocks.GRASS_BLOCK.getDefaultState().with(SnowyDirtBlock.SNOWY, false));
        structure.fillWithBlocks(world, start, 10, 5, 4, 13, 5, 4, Blocks.GRASS_BLOCK.getDefaultState().with(SnowyDirtBlock.SNOWY, false));
        structure.fillWithBlocks(world, start, 10, 5, 5, 12, 5, 17, Blocks.DIRT.getDefaultState());
        structure.fillWithBlocks(world, start, 10, 5, 18, 13, 5, 18, Blocks.GRASS_BLOCK.getDefaultState().with(SnowyDirtBlock.SNOWY, false));
        structure.fillWithBlocks(world, start, 10, 6, 5, 12, 6, 5, Blocks.GRASS_BLOCK.getDefaultState().with(SnowyDirtBlock.SNOWY, false));
        structure.fillWithBlocks(world, start, 10, 6, 6, 12, 6, 16, Blocks.DIRT.getDefaultState());
        structure.fillWithBlocks(world, start, 10, 6, 17, 12, 6, 17, Blocks.GRASS_BLOCK.getDefaultState().with(SnowyDirtBlock.SNOWY, false));
        structure.fillWithBlocks(world, start, 10, 7, 6, 10, 7, 15, Blocks.MOSSY_STONE_BRICKS.getDefaultState());
        structure.fillWithBlocks(world, start, 10, 8, 8, 11, 8, 9, Blocks.MOSSY_STONE_BRICKS.getDefaultState());
        structure.fillWithBlocks(world, start, 10, 8, 14, 11, 8, 15, Blocks.MOSSY_STONE_BRICKS.getDefaultState());
        structure.fillWithBlocks(world, start, 10, 9, 7, 11, 9, 8, Blocks.MOSSY_STONE_BRICKS.getDefaultState());
        structure.fillWithBlocks(world, start, 10, 9, 9, 10, 9, 10, Blocks.MOSSY_STONE_BRICKS.getDefaultState());
        structure.fillWithBlocks(world, start, 10, 9, 14, 11, 9, 16, Blocks.MOSSY_STONE_BRICKS.getDefaultState());
        structure.fillWithBlocks(world, start, 10, 10, 7, 10, 10, 8, Blocks.MOSSY_STONE_BRICKS.getDefaultState());
        structure.fillWithBlocks(world, start, 10, 10, 11, 10, 10, 15, Blocks.MOSSY_STONE_BRICKS.getDefaultState());
        structure.fillWithBlocks(world, start, 10, 11, 7, 11, 11, 8, Blocks.MOSSY_STONE_BRICKS.getDefaultState());
        structure.fillWithBlocks(world, start, 10, 11, 12, 12, 11, 15, Blocks.MOSSY_STONE_BRICKS.getDefaultState());
        structure.fillWithBlocks(world, start, 10, 12, 13, 10, 12, 13, Blocks.MOSSY_STONE_BRICKS.getDefaultState());
        structure.fillWithBlocks(world, start, 10, 13, 8, 10, 13, 8, Blocks.MOSSY_STONE_BRICKS.getDefaultState());
        structure.fillWithBlocks(world, start, 10, 13, 13, 11, 13, 14, Blocks.MOSSY_STONE_BRICKS.getDefaultState());
        structure.fillWithBlocks(world, start, 10, 14, 9, 12, 16, 9, Blocks.MOSSY_STONE_BRICKS.getDefaultState());
        structure.fillWithBlocks(world, start, 10, 14, 14, 10, 20, 14, Blocks.VINE.getDefaultState().with(VineBlock.UP, false).with(VineBlock.NORTH, true).with(VineBlock.SOUTH, false).with(VineBlock.EAST, false).with(VineBlock.WEST, false));
        structure.fillWithBlocks(world, start, 10, 15, 13, 10, 15, 13, Blocks.MOSSY_STONE_BRICKS.getDefaultState());
        structure.fillWithBlocks(world, start, 10, 16, 13, 12, 17, 13, Blocks.MOSSY_STONE_BRICKS.getDefaultState());
        structure.fillWithBlocks(world, start, 10, 17, 9, 10, 17, 10, Blocks.MOSSY_STONE_BRICKS.getDefaultState());
        structure.fillWithBlocks(world, start, 10, 18, 8, 10, 20, 8, Blocks.VINE.getDefaultState().with(VineBlock.UP, false).with(VineBlock.NORTH, false).with(VineBlock.SOUTH, true).with(VineBlock.EAST, true).with(VineBlock.WEST, false));
        structure.fillWithBlocks(world, start, 10, 18, 9, 12, 18, 9, Blocks.MOSSY_STONE_BRICKS.getDefaultState());
        structure.fillWithBlocks(world, start, 10, 18, 12, 10, 18, 13, Blocks.MOSSY_STONE_BRICKS.getDefaultState());
        structure.fillWithBlocks(world, start, 10, 19, 9, 10, 22, 9, Blocks.MOSSY_STONE_BRICKS.getDefaultState());
        structure.fillWithBlocks(world, start, 10, 19, 13, 10, 22, 13, Blocks.MOSSY_STONE_BRICKS.getDefaultState());
        structure.fillWithBlocks(world, start, 10, 20, 16, 10, 27, 16, Blocks.VINE.getDefaultState().with(VineBlock.UP, false).with(VineBlock.NORTH, true).with(VineBlock.SOUTH, false).with(VineBlock.EAST, false).with(VineBlock.WEST, false));
        structure.fillWithBlocks(world, start, 10, 22, 6, 10, 27, 6, Blocks.VINE.getDefaultState().with(VineBlock.UP, false).with(VineBlock.NORTH, false).with(VineBlock.SOUTH, true).with(VineBlock.EAST, false).with(VineBlock.WEST, false));
        structure.fillWithBlocks(world, start, 10, 22, 8, 10, 22, 9, Blocks.MOSSY_STONE_BRICKS.getDefaultState());
        structure.fillWithBlocks(world, start, 10, 22, 14, 12, 22, 14, Blocks.MOSSY_STONE_BRICKS.getDefaultState());
        structure.fillWithBlocks(world, start, 10, 23, 8, 11, 23, 8, Blocks.MOSSY_STONE_BRICKS.getDefaultState());
        structure.fillWithBlocks(world, start, 10, 23, 9, 10, 23, 13, Blocks.DARK_OAK_PLANKS.getDefaultState());
        structure.fillWithBlocks(world, start, 10, 23, 14, 10, 25, 14, Blocks.MOSSY_STONE_BRICKS.getDefaultState());
        structure.fillWithBlocks(world, start, 10, 25, 8, 10, 26, 8, Blocks.MOSSY_STONE_BRICKS.getDefaultState());
        structure.fillWithBlocks(world, start, 10, 28, 8, 10, 28, 9, Blocks.GRAY_TERRACOTTA.getDefaultState());
        structure.fillWithBlocks(world, start, 10, 28, 13, 10, 28, 14, Blocks.GRAY_TERRACOTTA.getDefaultState());
        structure.fillWithBlocks(world, start, 10, 29, 9, 12, 29, 13, Blocks.GRAY_TERRACOTTA.getDefaultState());
        structure.fillWithBlocks(world, start, 10, 30, 9, 12, 30, 13, Blocks.GRAY_TERRACOTTA.getDefaultState());
        structure.fillWithBlocks(world, start, 10, 31, 10, 12, 31, 12, Blocks.GRAY_TERRACOTTA.getDefaultState());
        structure.fillWithBlocks(world, start, 10, 32, 10, 12, 32, 12, Blocks.GRAY_TERRACOTTA.getDefaultState());
        structure.fillWithBlocks(world, start, 10, 33, 11, 10, 33, 11, Blocks.GRAY_TERRACOTTA.getDefaultState());
        structure.fillWithBlocks(world, start, 11, 8, 6, 11, 8, 9, Blocks.MOSSY_STONE_BRICKS.getDefaultState());
        structure.fillWithBlocks(world, start, 11, 10, 6, 11, 13, 6, Blocks.VINE.getDefaultState().with(VineBlock.UP, false).with(VineBlock.NORTH, false).with(VineBlock.SOUTH, true).with(VineBlock.EAST, false).with(VineBlock.WEST, false));
        structure.fillWithBlocks(world, start, 11, 10, 8, 13, 11, 8, Blocks.MOSSY_STONE_BRICKS.getDefaultState());
        structure.fillWithBlocks(world, start, 11, 10, 14, 12, 10, 15, Blocks.MOSSY_STONE_BRICKS.getDefaultState());
        structure.fillWithBlocks(world, start, 11, 11, 16, 11, 13, 16, Blocks.VINE.getDefaultState().with(VineBlock.UP, false).with(VineBlock.NORTH, true).with(VineBlock.SOUTH, false).with(VineBlock.EAST, false).with(VineBlock.WEST, false));
        structure.fillWithBlocks(world, start, 11, 12, 7, 11, 12, 8, Blocks.MOSSY_STONE_BRICKS.getDefaultState());
        structure.fillWithBlocks(world, start, 11, 12, 9, 11, 12, 10, Blocks.STONE_BRICK_SLAB.getDefaultState().with(SlabBlock.TYPE, SlabType.TOP).with(SlabBlock.WATERLOGGED, false));
        structure.fillWithBlocks(world, start, 11, 12, 13, 12, 12, 14, Blocks.MOSSY_STONE_BRICKS.getDefaultState());
        structure.fillWithBlocks(world, start, 11, 12, 15, 11, 13, 15, Blocks.MOSSY_STONE_BRICKS.getDefaultState());
        structure.fillWithBlocks(world, start, 11, 13, 7, 11, 13, 9, Blocks.MOSSY_STONE_BRICKS.getDefaultState());
        structure.fillWithBlocks(world, start, 11, 14, 8, 11, 14, 9, Blocks.MOSSY_STONE_BRICKS.getDefaultState());
        structure.fillWithBlocks(world, start, 11, 14, 14, 11, 15, 14, Blocks.MOSSY_STONE_BRICKS.getDefaultState());
        structure.fillWithBlocks(world, start, 11, 15, 12, 11, 15, 14, Blocks.MOSSY_STONE_BRICKS.getDefaultState());
        structure.fillWithBlocks(world, start, 11, 17, 9, 11, 18, 9, Blocks.MOSSY_STONE_BRICKS.getDefaultState());
        structure.fillWithBlocks(world, start, 11, 19, 8, 11, 19, 9, Blocks.DARK_OAK_PLANKS.getDefaultState());
        structure.fillWithBlocks(world, start, 11, 19, 13, 11, 19, 14, Blocks.DARK_OAK_PLANKS.getDefaultState());
        structure.fillWithBlocks(world, start, 11, 20, 9, 11, 20, 9, Blocks.MOSSY_STONE_BRICKS.getDefaultState());
        structure.fillWithBlocks(world, start, 11, 21, 8, 11, 21, 9, Blocks.MOSSY_STONE_BRICKS.getDefaultState());
        structure.fillWithBlocks(world, start, 11, 21, 13, 11, 22, 14, Blocks.MOSSY_STONE_BRICKS.getDefaultState());
        structure.fillWithBlocks(world, start, 11, 22, 9, 11, 22, 10, Blocks.MOSSY_STONE_BRICKS.getDefaultState());
        structure.fillWithBlocks(world, start, 11, 23, 13, 12, 23, 13, Blocks.DARK_OAK_PLANKS.getDefaultState());
        structure.fillWithBlocks(world, start, 11, 24, 8, 13, 24, 8, Blocks.MOSSY_STONE_BRICKS.getDefaultState());
        structure.fillWithBlocks(world, start, 11, 24, 14, 12, 24, 14, Blocks.MOSSY_STONE_BRICKS.getDefaultState());
        structure.fillWithBlocks(world, start, 11, 25, 8, 11, 26, 8, Blocks.BLACK_STAINED_GLASS_PANE.getDefaultState().with(FourWayBlock.WATERLOGGED, false).with(FourWayBlock.NORTH, false).with(FourWayBlock.SOUTH, false).with(FourWayBlock.EAST, true).with(FourWayBlock.WEST, true));
        structure.fillWithBlocks(world, start, 11, 25, 14, 11, 26, 14, Blocks.BLACK_STAINED_GLASS_PANE.getDefaultState().with(FourWayBlock.WATERLOGGED, false).with(FourWayBlock.NORTH, false).with(FourWayBlock.SOUTH, false).with(FourWayBlock.EAST, true).with(FourWayBlock.WEST, true));
        structure.fillWithBlocks(world, start, 11, 27, 7, 12, 27, 8, Blocks.GRAY_TERRACOTTA.getDefaultState());
        structure.fillWithBlocks(world, start, 11, 27, 14, 12, 27, 15, Blocks.GRAY_TERRACOTTA.getDefaultState());
        structure.fillWithBlocks(world, start, 11, 28, 8, 11, 28, 8, Blocks.GRAY_TERRACOTTA.getDefaultState());
        structure.fillWithBlocks(world, start, 11, 28, 14, 12, 28, 14, Blocks.GRAY_TERRACOTTA.getDefaultState());
        structure.fillWithBlocks(world, start, 11, 28, 15, 11, 29, 15, Blocks.VINE.getDefaultState().with(VineBlock.UP, false).with(VineBlock.NORTH, true).with(VineBlock.SOUTH, false).with(VineBlock.EAST, false).with(VineBlock.WEST, false));
        structure.fillWithBlocks(world, start, 11, 29, 8, 11, 29, 14, Blocks.GRAY_TERRACOTTA.getDefaultState());
        structure.fillWithBlocks(world, start, 11, 31, 9, 11, 31, 13, Blocks.GRAY_TERRACOTTA.getDefaultState());
        structure.fillWithBlocks(world, start, 11, 33, 10, 11, 33, 12, Blocks.GRAY_TERRACOTTA.getDefaultState());
        structure.fillWithBlocks(world, start, 11, 34, 11, 11, 35, 11, Blocks.GRAY_TERRACOTTA.getDefaultState());
        structure.fillWithBlocks(world, start, 12, 8, 7, 13, 8, 8, Blocks.MOSSY_STONE_BRICKS.getDefaultState());
        structure.fillWithBlocks(world, start, 12, 9, 7, 13, 9, 8, Blocks.MOSSY_STONE_BRICKS.getDefaultState());
        structure.fillWithBlocks(world, start, 12, 10, 7, 12, 10, 8, Blocks.MOSSY_STONE_BRICKS.getDefaultState());
        structure.fillWithBlocks(world, start, 12, 12, 8, 12, 12, 14, Blocks.MOSSY_STONE_BRICKS.getDefaultState());
        structure.fillWithBlocks(world, start, 12, 13, 9, 12, 13, 9, Blocks.MOSSY_STONE_BRICKS.getDefaultState());
        structure.fillWithBlocks(world, start, 12, 13, 13, 12, 13, 14, Blocks.MOSSY_STONE_BRICKS.getDefaultState());
        structure.fillWithBlocks(world, start, 12, 14, 8, 12, 20, 8, Blocks.VINE.getDefaultState().with(VineBlock.UP, false).with(VineBlock.NORTH, false).with(VineBlock.SOUTH, true).with(VineBlock.EAST, false).with(VineBlock.WEST, false));
        structure.fillWithBlocks(world, start, 12, 14, 14, 12, 15, 14, Blocks.VINE.getDefaultState().with(VineBlock.UP, false).with(VineBlock.NORTH, false).with(VineBlock.SOUTH, false).with(VineBlock.EAST, false).with(VineBlock.WEST, true));
        structure.fillWithBlocks(world, start, 12, 15, 12, 13, 15, 12, Blocks.MOSSY_STONE_BRICKS.getDefaultState());
        structure.fillWithBlocks(world, start, 12, 15, 15, 12, 25, 15, Blocks.VINE.getDefaultState().with(VineBlock.UP, false).with(VineBlock.NORTH, true).with(VineBlock.SOUTH, false).with(VineBlock.EAST, false).with(VineBlock.WEST, false));
        structure.fillWithBlocks(world, start, 12, 16, 10, 12, 16, 10, Blocks.MOSSY_STONE_BRICKS.getDefaultState());
        structure.fillWithBlocks(world, start, 12, 19, 12, 13, 19, 12, Blocks.MOSSY_STONE_BRICKS.getDefaultState());
        structure.fillWithBlocks(world, start, 12, 19, 14, 12, 20, 14, Blocks.VINE.getDefaultState().with(VineBlock.UP, false).with(VineBlock.NORTH, false).with(VineBlock.SOUTH, false).with(VineBlock.EAST, false).with(VineBlock.WEST, true));
        structure.fillWithBlocks(world, start, 12, 20, 9, 12, 20, 10, Blocks.MOSSY_STONE_BRICKS.getDefaultState());
        structure.fillWithBlocks(world, start, 12, 21, 7, 12, 25, 7, Blocks.VINE.getDefaultState().with(VineBlock.UP, false).with(VineBlock.NORTH, false).with(VineBlock.SOUTH, true).with(VineBlock.EAST, false).with(VineBlock.WEST, false));
        structure.fillWithBlocks(world, start, 12, 21, 9, 12, 21, 10, Blocks.MOSSY_STONE_BRICKS.getDefaultState());
        structure.fillWithBlocks(world, start, 12, 21, 13, 12, 22, 13, Blocks.MOSSY_STONE_BRICKS.getDefaultState());
        structure.fillWithBlocks(world, start, 12, 22, 8, 13, 22, 8, Blocks.MOSSY_STONE_BRICKS.getDefaultState());
        structure.fillWithBlocks(world, start, 12, 23, 10, 12, 23, 13, Blocks.DARK_OAK_PLANKS.getDefaultState());
        structure.fillWithBlocks(world, start, 12, 23, 14, 12, 24, 14, Blocks.MOSSY_STONE_BRICKS.getDefaultState());
        structure.fillWithBlocks(world, start, 12, 25, 8, 12, 26, 8, Blocks.MOSSY_STONE_BRICKS.getDefaultState());
        structure.fillWithBlocks(world, start, 12, 26, 14, 13, 26, 14, Blocks.MOSSY_STONE_BRICKS.getDefaultState());
        structure.fillWithBlocks(world, start, 12, 28, 8, 12, 28, 9, Blocks.GRAY_TERRACOTTA.getDefaultState());
        structure.fillWithBlocks(world, start, 12, 28, 13, 12, 28, 14, Blocks.GRAY_TERRACOTTA.getDefaultState());
        structure.fillWithBlocks(world, start, 13, 0, 1, 14, 0, 1, Blocks.GRASS_BLOCK.getDefaultState().with(SnowyDirtBlock.SNOWY, false));
        structure.fillWithBlocks(world, start, 13, 0, 2, 14, 0, 3, Blocks.DIRT.getDefaultState());
        structure.fillWithBlocks(world, start, 13, 0, 5, 14, 0, 6, Blocks.DIRT.getDefaultState());
        structure.fillWithBlocks(world, start, 13, 0, 16, 14, 0, 17, Blocks.DIRT.getDefaultState());
        structure.fillWithBlocks(world, start, 13, 0, 19, 14, 0, 20, Blocks.DIRT.getDefaultState());
        structure.fillWithBlocks(world, start, 13, 0, 21, 14, 0, 21, Blocks.GRASS_BLOCK.getDefaultState().with(SnowyDirtBlock.SNOWY, false));
        structure.fillWithBlocks(world, start, 13, 3, 3, 14, 3, 3, Blocks.GRASS_BLOCK.getDefaultState().with(SnowyDirtBlock.SNOWY, false));
        structure.fillWithBlocks(world, start, 13, 3, 19, 14, 3, 19, Blocks.GRASS_BLOCK.getDefaultState().with(SnowyDirtBlock.SNOWY, false));
        structure.fillWithBlocks(world, start, 13, 5, 5, 15, 5, 5, Blocks.GRASS_BLOCK.getDefaultState().with(SnowyDirtBlock.SNOWY, false));
        structure.fillWithBlocks(world, start, 13, 5, 17, 13, 5, 18, Blocks.GRASS_BLOCK.getDefaultState().with(SnowyDirtBlock.SNOWY, false));
        structure.fillWithBlocks(world, start, 13, 6, 16, 14, 6, 16, Blocks.GRASS_BLOCK.getDefaultState().with(SnowyDirtBlock.SNOWY, false));
        structure.fillWithBlocks(world, start, 13, 8, 14, 13, 9, 15, Blocks.MOSSY_STONE_BRICKS.getDefaultState());
        structure.fillWithBlocks(world, start, 13, 8, 16, 13, 9, 16, Blocks.VINE.getDefaultState().with(VineBlock.UP, false).with(VineBlock.NORTH, true).with(VineBlock.SOUTH, false).with(VineBlock.EAST, false).with(VineBlock.WEST, false));
        structure.fillWithBlocks(world, start, 13, 10, 13, 14, 10, 13, Blocks.MOSSY_STONE_BRICKS.getDefaultState());
        structure.fillWithBlocks(world, start, 13, 11, 12, 13, 12, 13, Blocks.MOSSY_STONE_BRICKS.getDefaultState());
        structure.fillWithBlocks(world, start, 13, 12, 9, 13, 12, 13, Blocks.MOSSY_STONE_BRICKS.getDefaultState());
        structure.fillWithBlocks(world, start, 13, 13, 9, 13, 13, 13, Blocks.MOSSY_STONE_BRICKS.getDefaultState());
        structure.fillWithBlocks(world, start, 13, 13, 14, 13, 20, 14, Blocks.VINE.getDefaultState().with(VineBlock.UP, false).with(VineBlock.NORTH, true).with(VineBlock.SOUTH, false).with(VineBlock.EAST, false).with(VineBlock.WEST, false));
        structure.fillWithBlocks(world, start, 13, 14, 10, 13, 14, 13, Blocks.MOSSY_STONE_BRICKS.getDefaultState());
        structure.fillWithBlocks(world, start, 13, 15, 10, 13, 16, 12, Blocks.MOSSY_STONE_BRICKS.getDefaultState());
        structure.fillWithBlocks(world, start, 13, 16, 9, 13, 16, 13, Blocks.MOSSY_STONE_BRICKS.getDefaultState());
        structure.fillWithBlocks(world, start, 13, 18, 10, 13, 20, 10, Blocks.MOSSY_STONE_BRICKS.getDefaultState());
        structure.fillWithBlocks(world, start, 13, 19, 11, 14, 19, 11, Blocks.DARK_OAK_PLANKS.getDefaultState());
        structure.fillWithBlocks(world, start, 13, 20, 11, 13, 20, 13, Blocks.MOSSY_STONE_BRICKS.getDefaultState());
        structure.fillWithBlocks(world, start, 13, 21, 9, 13, 21, 9, Blocks.MOSSY_STONE_BRICKS.getDefaultState());
        structure.fillWithBlocks(world, start, 13, 21, 12, 13, 22, 12, Blocks.MOSSY_STONE_BRICKS.getDefaultState());
        structure.fillWithBlocks(world, start, 13, 23, 8, 13, 24, 8, Blocks.MOSSY_STONE_BRICKS.getDefaultState());
        structure.fillWithBlocks(world, start, 13, 24, 10, 13, 24, 13, Blocks.BOOKSHELF.getDefaultState());
        structure.fillWithBlocks(world, start, 13, 25, 14, 13, 26, 14, Blocks.MOSSY_STONE_BRICKS.getDefaultState());
        structure.fillWithBlocks(world, start, 13, 26, 9, 13, 27, 9, Blocks.COBWEB.getDefaultState());
        structure.fillWithBlocks(world, start, 13, 26, 13, 13, 27, 13, Blocks.COBWEB.getDefaultState());
        structure.fillWithBlocks(world, start, 13, 27, 7, 13, 27, 8, Blocks.GRAY_TERRACOTTA.getDefaultState());
        structure.fillWithBlocks(world, start, 13, 27, 14, 13, 27, 15, Blocks.GRAY_TERRACOTTA.getDefaultState());
        structure.fillWithBlocks(world, start, 13, 28, 9, 13, 28, 10, Blocks.GRAY_TERRACOTTA.getDefaultState());
        structure.fillWithBlocks(world, start, 13, 28, 12, 13, 28, 13, Blocks.GRAY_TERRACOTTA.getDefaultState());
        structure.fillWithBlocks(world, start, 13, 29, 9, 13, 30, 9, Blocks.VINE.getDefaultState().with(VineBlock.UP, false).with(VineBlock.NORTH, false).with(VineBlock.SOUTH, false).with(VineBlock.EAST, false).with(VineBlock.WEST, true));
        structure.fillWithBlocks(world, start, 13, 29, 10, 13, 29, 12, Blocks.GRAY_TERRACOTTA.getDefaultState());
        structure.fillWithBlocks(world, start, 13, 29, 13, 13, 30, 13, Blocks.VINE.getDefaultState().with(VineBlock.UP, false).with(VineBlock.NORTH, false).with(VineBlock.SOUTH, false).with(VineBlock.EAST, false).with(VineBlock.WEST, true));
        structure.fillWithBlocks(world, start, 13, 30, 10, 13, 30, 12, Blocks.GRAY_TERRACOTTA.getDefaultState());
        structure.fillWithBlocks(world, start, 14, 0, 4, 14, 3, 14, Blocks.DIRT.getDefaultState());
        structure.fillWithBlocks(world, start, 14, 0, 18, 15, 0, 20, Blocks.DIRT.getDefaultState());
        structure.fillWithBlocks(world, start, 14, 1, 2, 15, 1, 2, Blocks.GRASS_BLOCK.getDefaultState().with(SnowyDirtBlock.SNOWY, false));
        structure.fillWithBlocks(world, start, 14, 1, 3, 15, 1, 11, Blocks.DIRT.getDefaultState());
        structure.fillWithBlocks(world, start, 14, 1, 15, 17, 1, 18, Blocks.DIRT.getDefaultState());
        structure.fillWithBlocks(world, start, 14, 1, 19, 15, 1, 19, Blocks.DIRT.getDefaultState());
        structure.fillWithBlocks(world, start, 14, 1, 20, 15, 1, 20, Blocks.GRASS_BLOCK.getDefaultState().with(SnowyDirtBlock.SNOWY, false));
        structure.fillWithBlocks(world, start, 14, 4, 4, 15, 4, 4, Blocks.GRASS_BLOCK.getDefaultState().with(SnowyDirtBlock.SNOWY, false));
        structure.fillWithBlocks(world, start, 14, 4, 18, 15, 4, 18, Blocks.GRASS_BLOCK.getDefaultState().with(SnowyDirtBlock.SNOWY, false));
        structure.fillWithBlocks(world, start, 14, 5, 17, 15, 5, 17, Blocks.GRASS_BLOCK.getDefaultState().with(SnowyDirtBlock.SNOWY, false));
        structure.fillWithBlocks(world, start, 14, 6, 6, 14, 6, 15, Blocks.DIRT.getDefaultState());
        structure.fillWithBlocks(world, start, 14, 7, 6, 14, 7, 6, Blocks.GRASS.getDefaultState());
        structure.fillWithBlocks(world, start, 14, 8, 8, 14, 9, 14, Blocks.MOSSY_STONE_BRICKS.getDefaultState());
        structure.fillWithBlocks(world, start, 14, 8, 15, 14, 9, 15, Blocks.VINE.getDefaultState().with(VineBlock.UP, false).with(VineBlock.NORTH, false).with(VineBlock.SOUTH, false).with(VineBlock.EAST, false).with(VineBlock.WEST, true));
        structure.fillWithBlocks(world, start, 14, 10, 9, 14, 10, 13, Blocks.MOSSY_STONE_BRICKS.getDefaultState());
        structure.fillWithBlocks(world, start, 14, 11, 10, 15, 11, 11, Blocks.MOSSY_STONE_BRICKS.getDefaultState());
        structure.fillWithBlocks(world, start, 14, 11, 12, 14, 13, 12, Blocks.MOSSY_STONE_BRICKS.getDefaultState());
        structure.fillWithBlocks(world, start, 14, 12, 9, 14, 13, 9, Blocks.VINE.getDefaultState().with(VineBlock.UP, false).with(VineBlock.NORTH, false).with(VineBlock.SOUTH, false).with(VineBlock.EAST, false).with(VineBlock.WEST, true));
        structure.fillWithBlocks(world, start, 14, 12, 10, 14, 12, 12, Blocks.MOSSY_STONE_BRICKS.getDefaultState());
        structure.fillWithBlocks(world, start, 14, 12, 13, 14, 13, 13, Blocks.VINE.getDefaultState().with(VineBlock.UP, false).with(VineBlock.NORTH, true).with(VineBlock.SOUTH, false).with(VineBlock.EAST, false).with(VineBlock.WEST, true));
        structure.fillWithBlocks(world, start, 14, 13, 10, 14, 13, 12, Blocks.MOSSY_STONE_BRICKS.getDefaultState());
        structure.fillWithBlocks(world, start, 14, 14, 10, 14, 19, 10, Blocks.VINE.getDefaultState().with(VineBlock.UP, false).with(VineBlock.NORTH, false).with(VineBlock.SOUTH, false).with(VineBlock.EAST, false).with(VineBlock.WEST, true));
        structure.fillWithBlocks(world, start, 14, 14, 13, 14, 22, 13, Blocks.VINE.getDefaultState().with(VineBlock.UP, false).with(VineBlock.NORTH, false).with(VineBlock.SOUTH, false).with(VineBlock.EAST, false).with(VineBlock.WEST, true));
        structure.fillWithBlocks(world, start, 14, 15, 12, 14, 16, 13, Blocks.VINE.getDefaultState().with(VineBlock.UP, false).with(VineBlock.NORTH, false).with(VineBlock.SOUTH, false).with(VineBlock.EAST, false).with(VineBlock.WEST, true));
        structure.fillWithBlocks(world, start, 14, 19, 8, 14, 25, 8, Blocks.VINE.getDefaultState().with(VineBlock.UP, false).with(VineBlock.NORTH, false).with(VineBlock.SOUTH, true).with(VineBlock.EAST, false).with(VineBlock.WEST, true));
        structure.fillWithBlocks(world, start, 14, 19, 12, 14, 20, 13, Blocks.VINE.getDefaultState().with(VineBlock.UP, false).with(VineBlock.NORTH, false).with(VineBlock.SOUTH, false).with(VineBlock.EAST, false).with(VineBlock.WEST, true));
        structure.fillWithBlocks(world, start, 14, 21, 10, 14, 23, 10, Blocks.MOSSY_STONE_BRICKS.getDefaultState());
        structure.fillWithBlocks(world, start, 14, 22, 9, 14, 22, 12, Blocks.MOSSY_STONE_BRICKS.getDefaultState());
        structure.fillWithBlocks(world, start, 14, 23, 11, 14, 24, 11, Blocks.MOSSY_STONE_BRICKS.getDefaultState());
        structure.fillWithBlocks(world, start, 14, 23, 14, 14, 25, 14, Blocks.VINE.getDefaultState().with(VineBlock.UP, false).with(VineBlock.NORTH, true).with(VineBlock.SOUTH, false).with(VineBlock.EAST, false).with(VineBlock.WEST, true));
        structure.fillWithBlocks(world, start, 14, 24, 9, 14, 25, 9, Blocks.MOSSY_STONE_BRICKS.getDefaultState());
        structure.fillWithBlocks(world, start, 14, 24, 12, 14, 25, 13, Blocks.MOSSY_STONE_BRICKS.getDefaultState());
        structure.fillWithBlocks(world, start, 14, 25, 10, 14, 26, 10, Blocks.MOSSY_STONE_BRICKS.getDefaultState());
        structure.fillWithBlocks(world, start, 14, 26, 11, 14, 26, 12, Blocks.MOSSY_STONE_BRICKS.getDefaultState());
        structure.fillWithBlocks(world, start, 14, 27, 8, 14, 27, 14, Blocks.GRAY_TERRACOTTA.getDefaultState());
        structure.fillWithBlocks(world, start, 14, 28, 10, 14, 28, 12, Blocks.GRAY_TERRACOTTA.getDefaultState());
        structure.fillWithBlocks(world, start, 14, 30, 11, 14, 31, 11, Blocks.VINE.getDefaultState().with(VineBlock.UP, false).with(VineBlock.NORTH, false).with(VineBlock.SOUTH, false).with(VineBlock.EAST, false).with(VineBlock.WEST, true));
        structure.fillWithBlocks(world, start, 15, 0, 2, 15, 0, 4, Blocks.DIRT.getDefaultState());
        structure.fillWithBlocks(world, start, 15, 0, 6, 17, 0, 8, Blocks.DIRT.getDefaultState());
        structure.fillWithBlocks(world, start, 15, 0, 9, 15, 0, 14, Blocks.STONE.getDefaultState());
        structure.fillWithBlocks(world, start, 15, 0, 15, 16, 0, 16, Blocks.DIRT.getDefaultState());
        structure.fillWithBlocks(world, start, 15, 1, 12, 15, 1, 13, Blocks.STONE.getDefaultState());
        structure.fillWithBlocks(world, start, 15, 1, 14, 18, 1, 17, Blocks.DIRT.getDefaultState());
        structure.fillWithBlocks(world, start, 15, 5, 6, 15, 5, 6, Blocks.GRASS_BLOCK.getDefaultState().with(SnowyDirtBlock.SNOWY, false));
        structure.fillWithBlocks(world, start, 15, 5, 16, 15, 5, 17, Blocks.GRASS_BLOCK.getDefaultState().with(SnowyDirtBlock.SNOWY, false));
        structure.fillWithBlocks(world, start, 15, 6, 7, 15, 6, 8, Blocks.GRASS_BLOCK.getDefaultState().with(SnowyDirtBlock.SNOWY, false));
        structure.fillWithBlocks(world, start, 15, 6, 9, 15, 6, 14, Blocks.DIRT.getDefaultState());
        structure.fillWithBlocks(world, start, 15, 7, 9, 15, 7, 12, Blocks.MOSSY_STONE_BRICKS.getDefaultState());
        structure.fillWithBlocks(world, start, 15, 7, 13, 15, 7, 14, Blocks.CRACKED_STONE_BRICKS.getDefaultState());
        structure.fillWithBlocks(world, start, 15, 8, 10, 15, 8, 13, Blocks.MOSSY_STONE_BRICKS.getDefaultState());
        structure.fillWithBlocks(world, start, 15, 9, 11, 15, 10, 12, Blocks.MOSSY_STONE_BRICKS.getDefaultState());
        structure.fillWithBlocks(world, start, 15, 10, 10, 15, 11, 11, Blocks.MOSSY_STONE_BRICKS.getDefaultState());
        structure.fillWithBlocks(world, start, 15, 21, 10, 15, 25, 10, Blocks.VINE.getDefaultState().with(VineBlock.UP, false).with(VineBlock.NORTH, false).with(VineBlock.SOUTH, false).with(VineBlock.EAST, false).with(VineBlock.WEST, true));
        structure.fillWithBlocks(world, start, 15, 27, 9, 15, 27, 13, Blocks.GRAY_TERRACOTTA.getDefaultState());
        structure.fillWithBlocks(world, start, 15, 28, 11, 15, 29, 11, Blocks.VINE.getDefaultState().with(VineBlock.UP, false).with(VineBlock.NORTH, false).with(VineBlock.SOUTH, false).with(VineBlock.EAST, false).with(VineBlock.WEST, true));
        structure.fillWithBlocks(world, start, 16, 0, 3, 17, 0, 14, Blocks.DIRT.getDefaultState());
        structure.fillWithBlocks(world, start, 16, 0, 17, 17, 0, 19, Blocks.DIRT.getDefaultState());
        structure.fillWithBlocks(world, start, 16, 1, 3, 17, 1, 3, Blocks.GRASS_BLOCK.getDefaultState().with(SnowyDirtBlock.SNOWY, false));
        structure.fillWithBlocks(world, start, 16, 1, 4, 17, 1, 18, Blocks.DIRT.getDefaultState());
        structure.fillWithBlocks(world, start, 16, 1, 19, 17, 1, 19, Blocks.GRASS_BLOCK.getDefaultState().with(SnowyDirtBlock.SNOWY, false));
        structure.fillWithBlocks(world, start, 16, 3, 4, 16, 3, 4, Blocks.GRASS_BLOCK.getDefaultState().with(SnowyDirtBlock.SNOWY, false));
        structure.fillWithBlocks(world, start, 16, 4, 5, 16, 4, 5, Blocks.GRASS_BLOCK.getDefaultState().with(SnowyDirtBlock.SNOWY, false));
