package mod.arcalitegames.odyssey.world.structure.structures.towers.lighthouse;

import mod.arcalitegames.odyssey.world.structure.StructureBase;
import net.minecraft.block.Blocks;
import net.minecraft.block.ChestBlock;
import net.minecraft.block.DoorBlock;
import net.minecraft.block.FourWayBlock;
import net.minecraft.block.LadderBlock;
import net.minecraft.block.SlabBlock;
import net.minecraft.block.SnowyDirtBlock;
import net.minecraft.block.StairsBlock;
import net.minecraft.block.WallBlock;
import net.minecraft.block.WallHeight;
import net.minecraft.block.WallTorchBlock;
import net.minecraft.state.properties.ChestType;
import net.minecraft.state.properties.DoorHingeSide;
import net.minecraft.state.properties.DoubleBlockHalf;
import net.minecraft.state.properties.Half;
import net.minecraft.state.properties.SlabType;
import net.minecraft.state.properties.StairsShape;
import net.minecraft.util.Direction;
import net.minecraft.util.math.BlockPos;
import net.minecraft.world.World;

public class LightHouseComponents
{

	public static BlockPos start;
    public static World world;
    public static StructureBase structure;

    public static void init(World worldIn, BlockPos blockPos, StructureBase structureIn)
    {
        world = worldIn; start = blockPos; structure = structureIn;
    }
    
    public static void generatePart1()
    {
        structure.setBlockState(world, Blocks.GRASS_BLOCK.getDefaultState().with(SnowyDirtBlock.SNOWY, false), 2, 0, 6, start);
        structure.setBlockState(world, Blocks.GRASS_BLOCK.getDefaultState().with(SnowyDirtBlock.SNOWY, false), 2, 0, 16, start);
        structure.setBlockState(world, Blocks.GRASS_BLOCK.getDefaultState().with(SnowyDirtBlock.SNOWY, false), 3, 0, 4, start);
        structure.setBlockState(world, Blocks.GRASS_BLOCK.getDefaultState().with(SnowyDirtBlock.SNOWY, false), 3, 2, 7, start);
        structure.setBlockState(world, Blocks.GRASS_BLOCK.getDefaultState().with(SnowyDirtBlock.SNOWY, false), 3, 2, 15, start);
        structure.setBlockState(world, Blocks.GRASS_BLOCK.getDefaultState().with(SnowyDirtBlock.SNOWY, false), 4, 0, 3, start);
        structure.setBlockState(world, Blocks.STONE.getDefaultState(), 4, 0, 9, start);
        structure.setBlockState(world, Blocks.GRASS_BLOCK.getDefaultState().with(SnowyDirtBlock.SNOWY, false), 4, 0, 19, start);
        structure.setBlockState(world, Blocks.GRASS_BLOCK.getDefaultState().with(SnowyDirtBlock.SNOWY, false), 4, 1, 4, start);
        structure.setBlockState(world, Blocks.GRASS_BLOCK.getDefaultState().with(SnowyDirtBlock.SNOWY, false), 4, 2, 5, start);
        structure.setBlockState(world, Blocks.GRASS_BLOCK.getDefaultState().with(SnowyDirtBlock.SNOWY, false), 4, 3, 6, start);
        structure.setBlockState(world, Blocks.GRASS_BLOCK.getDefaultState().with(SnowyDirtBlock.SNOWY, false), 5, 2, 4, start);
        structure.setBlockState(world, Blocks.GRASS_BLOCK.getDefaultState().with(SnowyDirtBlock.SNOWY, false), 5, 2, 18, start);
        structure.setBlockState(world, Blocks.GRASS_BLOCK.getDefaultState().with(SnowyDirtBlock.SNOWY, false), 5, 3, 5, start);
        structure.setBlockState(world, Blocks.GRASS_BLOCK.getDefaultState().with(SnowyDirtBlock.SNOWY, false), 5, 4, 6, start);
        structure.setBlockState(world, Blocks.GRASS_BLOCK.getDefaultState().with(SnowyDirtBlock.SNOWY, false), 6, 0, 2, start);
        structure.setBlockState(world, Blocks.GRASS_BLOCK.getDefaultState().with(SnowyDirtBlock.SNOWY, false), 6, 0, 20, start);
        structure.setBlockState(world, Blocks.STONE.getDefaultState(), 6, 1, 16, start);
        structure.setBlockState(world, Blocks.GRASS_BLOCK.getDefaultState().with(SnowyDirtBlock.SNOWY, false), 6, 3, 4, start);
        structure.setBlockState(world, Blocks.GRASS_BLOCK.getDefaultState().with(SnowyDirtBlock.SNOWY, false), 6, 3, 18, start);
        structure.setBlockState(world, Blocks.GRASS_BLOCK.getDefaultState().with(SnowyDirtBlock.SNOWY, false), 6, 4, 5, start);
        structure.setBlockState(world, Blocks.GRASS_BLOCK.getDefaultState().with(SnowyDirtBlock.SNOWY, false), 7, 2, 3, start);
        structure.setBlockState(world, Blocks.GRASS_BLOCK.getDefaultState().with(SnowyDirtBlock.SNOWY, false), 7, 2, 19, start);
        structure.setBlockState(world, Blocks.AIR.getDefaultState(), 7, 7, 11, start);
        structure.setBlockState(world, Blocks.WALL_TORCH.getDefaultState().with(WallTorchBlock.HORIZONTAL_FACING, Direction.WEST), 7, 9, 11, start);
        structure.setBlockState(world, Blocks.DARK_OAK_STAIRS.getDefaultState().with(StairsBlock.FACING, Direction.EAST).with(StairsBlock.WATERLOGGED, false).with(StairsBlock.SHAPE, StairsShape.STRAIGHT).with(StairsBlock.HALF, Half.TOP), 7, 23, 11, start);
        structure.setBlockState(world, Blocks.GRASS_BLOCK.getDefaultState().with(SnowyDirtBlock.SNOWY, false), 8, 1, 14, start);
        structure.setBlockState(world, Blocks.STONE_BRICKS.getDefaultState(), 8, 7, 10, start);
        structure.setBlockState(world, Blocks.CRACKED_STONE_BRICKS.getDefaultState(), 8, 7, 12, start);
        structure.setBlockState(world, Blocks.STONE_BRICK_STAIRS.getDefaultState().with(StairsBlock.FACING, Direction.EAST).with(StairsBlock.WATERLOGGED, false).with(StairsBlock.SHAPE, StairsShape.STRAIGHT).with(StairsBlock.HALF, Half.TOP), 8, 10, 10, start);
        structure.setBlockState(world, Blocks.STONE_BRICK_SLAB.getDefaultState().with(SlabBlock.TYPE, SlabType.BOTTOM).with(SlabBlock.WATERLOGGED, false), 8, 10, 11, start);
        structure.setBlockState(world, Blocks.STONE_BRICK_STAIRS.getDefaultState().with(StairsBlock.FACING, Direction.EAST).with(StairsBlock.WATERLOGGED, false).with(StairsBlock.SHAPE, StairsShape.STRAIGHT).with(StairsBlock.HALF, Half.TOP), 8, 10, 12, start);
        structure.setBlockState(world, Blocks.COBBLESTONE_WALL.getDefaultState().with(WallBlock.WATERLOGGED, false).with(WallBlock.UP, true).with(WallBlock.WALL_HEIGHT_NORTH, WallHeight.LOW).with(WallBlock.WALL_HEIGHT_SOUTH, WallHeight.LOW).with(WallBlock.WALL_HEIGHT_EAST, WallHeight.LOW).with(WallBlock.WALL_HEIGHT_WEST, WallHeight.LOW), 8, 11, 10, start);
        structure.setBlockState(world, Blocks.COBBLESTONE_WALL.getDefaultState().with(WallBlock.WATERLOGGED, false).with(WallBlock.UP, true).with(WallBlock.WALL_HEIGHT_NORTH, WallHeight.LOW).with(WallBlock.WALL_HEIGHT_SOUTH, WallHeight.LOW).with(WallBlock.WALL_HEIGHT_EAST, WallHeight.LOW).with(WallBlock.WALL_HEIGHT_WEST, WallHeight.LOW), 8, 11, 12, start);
        structure.setBlockState(world, Blocks.SMOOTH_STONE_SLAB.getDefaultState().with(SlabBlock.TYPE, SlabType.BOTTOM).with(SlabBlock.WATERLOGGED, false), 8, 14, 10, start);
        structure.setBlockState(world, Blocks.SMOOTH_STONE_SLAB.getDefaultState().with(SlabBlock.TYPE, SlabType.TOP).with(SlabBlock.WATERLOGGED, false), 8, 14, 11, start);
        structure.setBlockState(world, Blocks.SMOOTH_STONE_SLAB.getDefaultState().with(SlabBlock.TYPE, SlabType.BOTTOM).with(SlabBlock.WATERLOGGED, false), 8, 14, 12, start);
        structure.setBlockState(world, Blocks.STONE_BRICK_STAIRS.getDefaultState().with(StairsBlock.FACING, Direction.EAST).with(StairsBlock.WATERLOGGED, false).with(StairsBlock.SHAPE, StairsShape.STRAIGHT).with(StairsBlock.HALF, Half.TOP), 8, 19, 10, start);
        structure.setBlockState(world, Blocks.STONE_BRICK_SLAB.getDefaultState().with(SlabBlock.TYPE, SlabType.TOP).with(SlabBlock.WATERLOGGED, false), 8, 19, 11, start);
        structure.setBlockState(world, Blocks.STONE_BRICK_STAIRS.getDefaultState().with(StairsBlock.FACING, Direction.EAST).with(StairsBlock.WATERLOGGED, false).with(StairsBlock.SHAPE, StairsShape.STRAIGHT).with(StairsBlock.HALF, Half.TOP), 8, 19, 12, start);
        structure.setBlockState(world, Blocks.CRACKED_STONE_BRICKS.getDefaultState(), 8, 20, 10, start);
        structure.setBlockState(world, Blocks.STONE_BRICKS.getDefaultState(), 8, 20, 11, start);
        structure.setBlockState(world, Blocks.CRACKED_STONE_BRICKS.getDefaultState(), 8, 20, 12, start);
        structure.setBlockState(world, Blocks.STONE_BRICK_SLAB.getDefaultState().with(SlabBlock.TYPE, SlabType.BOTTOM).with(SlabBlock.WATERLOGGED, false), 8, 21, 10, start);
        structure.setBlockState(world, Blocks.STONE_BRICK_SLAB.getDefaultState().with(SlabBlock.TYPE, SlabType.BOTTOM).with(SlabBlock.WATERLOGGED, false), 8, 21, 12, start);
        structure.setBlockState(world, Blocks.DARK_OAK_SLAB.getDefaultState().with(SlabBlock.TYPE, SlabType.BOTTOM).with(SlabBlock.WATERLOGGED, false), 8, 24, 8, start);
        structure.setBlockState(world, Blocks.DARK_OAK_STAIRS.getDefaultState().with(StairsBlock.FACING, Direction.EAST).with(StairsBlock.WATERLOGGED, false).with(StairsBlock.SHAPE, StairsShape.STRAIGHT).with(StairsBlock.HALF, Half.TOP), 8, 24, 11, start);
        structure.setBlockState(world, Blocks.STONE.getDefaultState(), 9, 0, 18, start);
        structure.setBlockState(world, Blocks.STONE_BRICK_SLAB.getDefaultState().with(SlabBlock.TYPE, SlabType.BOTTOM).with(SlabBlock.WATERLOGGED, false), 9, 10, 9, start);
        structure.setBlockState(world, Blocks.STONE_BRICK_SLAB.getDefaultState().with(SlabBlock.TYPE, SlabType.BOTTOM).with(SlabBlock.WATERLOGGED, false), 9, 10, 13, start);
        structure.setBlockState(world, Blocks.IRON_BARS.getDefaultState().with(FourWayBlock.WATERLOGGED, false).with(FourWayBlock.NORTH, false).with(FourWayBlock.SOUTH, false).with(FourWayBlock.EAST, false).with(FourWayBlock.WEST, false), 9, 16, 11, start);
        structure.setBlockState(world, Blocks.IRON_BARS.getDefaultState().with(FourWayBlock.WATERLOGGED, false).with(FourWayBlock.NORTH, true).with(FourWayBlock.SOUTH, false).with(FourWayBlock.EAST, false).with(FourWayBlock.WEST, false), 9, 17, 11, start);
        structure.setBlockState(world, Blocks.STONE_BRICK_SLAB.getDefaultState().with(SlabBlock.TYPE, SlabType.TOP).with(SlabBlock.WATERLOGGED, false), 9, 19, 9, start);
        structure.setBlockState(world, Blocks.STONE_BRICK_SLAB.getDefaultState().with(SlabBlock.TYPE, SlabType.TOP).with(SlabBlock.WATERLOGGED, false), 9, 19, 13, start);
        structure.setBlockState(world, Blocks.CRACKED_STONE_BRICKS.getDefaultState(), 9, 20, 9, start);
        structure.setBlockState(world, Blocks.CHEST.getDefaultState().with(ChestBlock.FACING, Direction.EAST).with(ChestBlock.WATERLOGGED, false).with(ChestBlock.TYPE, ChestType.SINGLE), 9, 20, 11, start);
        structure.setBlockState(world, Blocks.STONE_BRICKS.getDefaultState(), 9, 20, 13, start);
        structure.setBlockState(world, Blocks.WALL_TORCH.getDefaultState().with(WallTorchBlock.HORIZONTAL_FACING, Direction.EAST), 9, 21, 11, start);
        structure.setBlockState(world, Blocks.STONE_BRICKS.getDefaultState(), 10, 7, 8, start);
        structure.setBlockState(world, Blocks.OAK_STAIRS.getDefaultState().with(StairsBlock.FACING, Direction.NORTH).with(StairsBlock.WATERLOGGED, false).with(StairsBlock.SHAPE, StairsShape.STRAIGHT).with(StairsBlock.HALF, Half.BOTTOM), 10, 7, 11, start);
        structure.setBlockState(world, Blocks.STONE_BRICKS.getDefaultState(), 10, 7, 14, start);
        structure.setBlockState(world, Blocks.COBBLESTONE_WALL.getDefaultState().with(WallBlock.WATERLOGGED, false).with(WallBlock.UP, true).with(WallBlock.WALL_HEIGHT_NORTH, WallHeight.LOW).with(WallBlock.WALL_HEIGHT_SOUTH, WallHeight.LOW).with(WallBlock.WALL_HEIGHT_EAST, WallHeight.LOW).with(WallBlock.WALL_HEIGHT_WEST, WallHeight.LOW), 10, 7, 15, start);
        structure.setBlockState(world, Blocks.WALL_TORCH.getDefaultState().with(WallTorchBlock.HORIZONTAL_FACING, Direction.EAST), 10, 8, 12, start);
        structure.setBlockState(world, Blocks.SPRUCE_FENCE.getDefaultState().with(FourWayBlock.WATERLOGGED, false).with(FourWayBlock.NORTH, true).with(FourWayBlock.SOUTH, false).with(FourWayBlock.EAST, false).with(FourWayBlock.WEST, false), 10, 8, 15, start);
        structure.setBlockState(world, Blocks.SMOOTH_STONE_SLAB.getDefaultState().with(SlabBlock.TYPE, SlabType.BOTTOM).with(SlabBlock.WATERLOGGED, false), 10, 9, 15, start);
        structure.setBlockState(world, Blocks.STONE_BRICK_STAIRS.getDefaultState().with(StairsBlock.FACING, Direction.SOUTH).with(StairsBlock.WATERLOGGED, false).with(StairsBlock.SHAPE, StairsShape.STRAIGHT).with(StairsBlock.HALF, Half.TOP), 10, 10, 8, start);
        structure.setBlockState(world, Blocks.OAK_SLAB.getDefaultState().with(SlabBlock.TYPE, SlabType.TOP).with(SlabBlock.WATERLOGGED, false), 10, 10, 12, start);
        structure.setBlockState(world, Blocks.STONE_BRICK_STAIRS.getDefaultState().with(StairsBlock.FACING, Direction.NORTH).with(StairsBlock.WATERLOGGED, false).with(StairsBlock.SHAPE, StairsShape.STRAIGHT).with(StairsBlock.HALF, Half.TOP), 10, 10, 14, start);
        structure.setBlockState(world, Blocks.COBBLESTONE_WALL.getDefaultState().with(WallBlock.WATERLOGGED, false).with(WallBlock.UP, true).with(WallBlock.WALL_HEIGHT_NORTH, WallHeight.LOW).with(WallBlock.WALL_HEIGHT_SOUTH, WallHeight.LOW).with(WallBlock.WALL_HEIGHT_EAST, WallHeight.LOW).with(WallBlock.WALL_HEIGHT_WEST, WallHeight.LOW), 10, 11, 8, start);
        structure.setBlockState(world, Blocks.WALL_TORCH.getDefaultState().with(WallTorchBlock.HORIZONTAL_FACING, Direction.EAST), 10, 11, 11, start);
        structure.setBlockState(world, Blocks.COBBLESTONE_WALL.getDefaultState().with(WallBlock.WATERLOGGED, false).with(WallBlock.UP, true).with(WallBlock.WALL_HEIGHT_NORTH, WallHeight.LOW).with(WallBlock.WALL_HEIGHT_SOUTH, WallHeight.LOW).with(WallBlock.WALL_HEIGHT_EAST, WallHeight.LOW).with(WallBlock.WALL_HEIGHT_WEST, WallHeight.LOW), 10, 11, 14, start);
        structure.setBlockState(world, Blocks.OAK_FENCE.getDefaultState().with(FourWayBlock.WATERLOGGED, false).with(FourWayBlock.NORTH, false).with(FourWayBlock.SOUTH, true).with(FourWayBlock.EAST, false).with(FourWayBlock.WEST, false), 10, 12, 8, start);
        structure.setBlockState(world, Blocks.OAK_FENCE.getDefaultState().with(FourWayBlock.WATERLOGGED, false).with(FourWayBlock.NORTH, false).with(FourWayBlock.SOUTH, false).with(FourWayBlock.EAST, false).with(FourWayBlock.WEST, false), 10, 12, 14, start);
        structure.setBlockState(world, Blocks.OAK_FENCE.getDefaultState().with(FourWayBlock.WATERLOGGED, false).with(FourWayBlock.NORTH, false).with(FourWayBlock.SOUTH, false).with(FourWayBlock.EAST, false).with(FourWayBlock.WEST, false), 10, 13, 8, start);
        structure.setBlockState(world, Blocks.OAK_FENCE.getDefaultState().with(FourWayBlock.WATERLOGGED, false).with(FourWayBlock.NORTH, true).with(FourWayBlock.SOUTH, false).with(FourWayBlock.EAST, false).with(FourWayBlock.WEST, false), 10, 13, 14, start);
        structure.setBlockState(world, Blocks.SMOOTH_STONE_SLAB.getDefaultState().with(SlabBlock.TYPE, SlabType.BOTTOM).with(SlabBlock.WATERLOGGED, false), 10, 14, 8, start);
        structure.setBlockState(world, Blocks.SMOOTH_STONE_SLAB.getDefaultState().with(SlabBlock.TYPE, SlabType.BOTTOM).with(SlabBlock.WATERLOGGED, false), 10, 14, 14, start);
        structure.setBlockState(world, Blocks.WALL_TORCH.getDefaultState().with(WallTorchBlock.HORIZONTAL_FACING, Direction.EAST), 10, 15, 11, start);
        structure.setBlockState(world, Blocks.STONE_BRICK_STAIRS.getDefaultState().with(StairsBlock.FACING, Direction.SOUTH).with(StairsBlock.WATERLOGGED, false).with(StairsBlock.SHAPE, StairsShape.STRAIGHT).with(StairsBlock.HALF, Half.TOP), 10, 19, 8, start);
        structure.setBlockState(world, Blocks.STONE_BRICK_STAIRS.getDefaultState().with(StairsBlock.FACING, Direction.NORTH).with(StairsBlock.WATERLOGGED, false).with(StairsBlock.SHAPE, StairsShape.STRAIGHT).with(StairsBlock.HALF, Half.TOP), 10, 19, 14, start);
        structure.setBlockState(world, Blocks.CRACKED_STONE_BRICKS.getDefaultState(), 10, 20, 8, start);
        structure.setBlockState(world, Blocks.COBBLESTONE_STAIRS.getDefaultState().with(StairsBlock.FACING, Direction.EAST).with(StairsBlock.WATERLOGGED, false).with(StairsBlock.SHAPE, StairsShape.STRAIGHT).with(StairsBlock.HALF, Half.BOTTOM), 10, 20, 11, start);
        structure.setBlockState(world, Blocks.CRACKED_STONE_BRICKS.getDefaultState(), 10, 20, 14, start);
        structure.setBlockState(world, Blocks.STONE_BRICK_SLAB.getDefaultState().with(SlabBlock.TYPE, SlabType.BOTTOM).with(SlabBlock.WATERLOGGED, false), 10, 21, 8, start);
        structure.setBlockState(world, Blocks.STONE_BRICK_STAIRS.getDefaultState().with(StairsBlock.FACING, Direction.WEST).with(StairsBlock.WATERLOGGED, false).with(StairsBlock.SHAPE, StairsShape.STRAIGHT).with(StairsBlock.HALF, Half.BOTTOM), 10, 21, 11, start);
        structure.setBlockState(world, Blocks.STONE_BRICK_SLAB.getDefaultState().with(SlabBlock.TYPE, SlabType.BOTTOM).with(SlabBlock.WATERLOGGED, false), 10, 21, 14, start);
        structure.setBlockState(world, Blocks.DARK_OAK_STAIRS.getDefaultState().with(StairsBlock.FACING, Direction.EAST).with(StairsBlock.WATERLOGGED, false).with(StairsBlock.SHAPE, StairsShape.STRAIGHT).with(StairsBlock.HALF, Half.BOTTOM), 10, 26, 11, start);
        structure.setBlockState(world, Blocks.AIR.getDefaultState(), 11, 7, 7, start);
        structure.setBlockState(world, Blocks.SPRUCE_DOOR.getDefaultState().with(DoorBlock.FACING, Direction.EAST).with(DoorBlock.HALF, DoubleBlockHalf.LOWER).with(DoorBlock.HINGE, DoorHingeSide.LEFT).with(DoorBlock.OPEN, true).with(DoorBlock.POWERED, false), 11, 7, 14, start);
        structure.setBlockState(world, Blocks.AIR.getDefaultState(), 11, 7, 15, start);
        structure.setBlockState(world, Blocks.OAK_STAIRS.getDefaultState().with(StairsBlock.FACING, Direction.EAST).with(StairsBlock.WATERLOGGED, false).with(StairsBlock.SHAPE, StairsShape.STRAIGHT).with(StairsBlock.HALF, Half.BOTTOM), 11, 8, 10, start);
        structure.setBlockState(world, Blocks.SPRUCE_DOOR.getDefaultState().with(DoorBlock.FACING, Direction.EAST).with(DoorBlock.HALF, DoubleBlockHalf.UPPER).with(DoorBlock.HINGE, DoorHingeSide.LEFT).with(DoorBlock.OPEN, true).with(DoorBlock.POWERED, false), 11, 8, 14, start);
        structure.setBlockState(world, Blocks.SMOOTH_STONE_SLAB.getDefaultState().with(SlabBlock.TYPE, SlabType.TOP).with(SlabBlock.WATERLOGGED, false), 11, 9, 15, start);
        structure.setBlockState(world, Blocks.STONE_BRICK_SLAB.getDefaultState().with(SlabBlock.TYPE, SlabType.BOTTOM).with(SlabBlock.WATERLOGGED, false), 11, 10, 8, start);
        structure.setBlockState(world, Blocks.OAK_STAIRS.getDefaultState().with(StairsBlock.FACING, Direction.WEST).with(StairsBlock.WATERLOGGED, false).with(StairsBlock.SHAPE, StairsShape.STRAIGHT).with(StairsBlock.HALF, Half.BOTTOM), 11, 10, 12, start);
        structure.setBlockState(world, Blocks.STONE_BRICK_SLAB.getDefaultState().with(SlabBlock.TYPE, SlabType.BOTTOM).with(SlabBlock.WATERLOGGED, false), 11, 10, 14, start);
        structure.setBlockState(world, Blocks.WALL_TORCH.getDefaultState().with(WallTorchBlock.HORIZONTAL_FACING, Direction.SOUTH), 11, 11, 10, start);
        structure.setBlockState(world, Blocks.IRON_BARS.getDefaultState().with(FourWayBlock.WATERLOGGED, false).with(FourWayBlock.NORTH, false).with(FourWayBlock.SOUTH, false).with(FourWayBlock.EAST, false).with(FourWayBlock.WEST, true), 11, 12, 9, start);
        structure.setBlockState(world, Blocks.IRON_BARS.getDefaultState().with(FourWayBlock.WATERLOGGED, false).with(FourWayBlock.NORTH, false).with(FourWayBlock.SOUTH, false).with(FourWayBlock.EAST, false).with(FourWayBlock.WEST, false), 11, 12, 13, start);
        structure.setBlockState(world, Blocks.IRON_BARS.getDefaultState().with(FourWayBlock.WATERLOGGED, false).with(FourWayBlock.NORTH, false).with(FourWayBlock.SOUTH, false).with(FourWayBlock.EAST, true).with(FourWayBlock.WEST, true), 11, 13, 9, start);
        structure.setBlockState(world, Blocks.IRON_BARS.getDefaultState().with(FourWayBlock.WATERLOGGED, false).with(FourWayBlock.NORTH, false).with(FourWayBlock.SOUTH, false).with(FourWayBlock.EAST, true).with(FourWayBlock.WEST, true), 11, 13, 13, start);
        structure.setBlockState(world, Blocks.SMOOTH_STONE_SLAB.getDefaultState().with(SlabBlock.TYPE, SlabType.TOP).with(SlabBlock.WATERLOGGED, false), 11, 14, 8, start);
        structure.setBlockState(world, Blocks.SMOOTH_STONE_SLAB.getDefaultState().with(SlabBlock.TYPE, SlabType.TOP).with(SlabBlock.WATERLOGGED, false), 11, 14, 14, start);
        structure.setBlockState(world, Blocks.WALL_TORCH.getDefaultState().with(WallTorchBlock.HORIZONTAL_FACING, Direction.SOUTH), 11, 15, 10, start);
        structure.setBlockState(world, Blocks.AIR.getDefaultState(), 11, 15, 11, start);
        structure.setBlockState(world, Blocks.WALL_TORCH.getDefaultState().with(WallTorchBlock.HORIZONTAL_FACING, Direction.NORTH), 11, 15, 12, start);
        structure.setBlockState(world, Blocks.IRON_BARS.getDefaultState().with(FourWayBlock.WATERLOGGED, false).with(FourWayBlock.NORTH, false).with(FourWayBlock.SOUTH, false).with(FourWayBlock.EAST, false).with(FourWayBlock.WEST, false), 11, 16, 9, start);
        structure.setBlockState(world, Blocks.IRON_BARS.getDefaultState().with(FourWayBlock.WATERLOGGED, false).with(FourWayBlock.NORTH, false).with(FourWayBlock.SOUTH, false).with(FourWayBlock.EAST, false).with(FourWayBlock.WEST, false), 11, 16, 13, start);
        structure.setBlockState(world, Blocks.IRON_BARS.getDefaultState().with(FourWayBlock.WATERLOGGED, false).with(FourWayBlock.NORTH, false).with(FourWayBlock.SOUTH, false).with(FourWayBlock.EAST, true).with(FourWayBlock.WEST, true), 11, 17, 9, start);
        structure.setBlockState(world, Blocks.IRON_BARS.getDefaultState().with(FourWayBlock.WATERLOGGED, false).with(FourWayBlock.NORTH, false).with(FourWayBlock.SOUTH, false).with(FourWayBlock.EAST, true).with(FourWayBlock.WEST, true), 11, 17, 13, start);
        structure.setBlockState(world, Blocks.STONE_BRICK_SLAB.getDefaultState().with(SlabBlock.TYPE, SlabType.TOP).with(SlabBlock.WATERLOGGED, false), 11, 19, 8, start);
        structure.setBlockState(world, Blocks.STONE_BRICK_SLAB.getDefaultState().with(SlabBlock.TYPE, SlabType.TOP).with(SlabBlock.WATERLOGGED, false), 11, 19, 14, start);
        structure.setBlockState(world, Blocks.STONE_BRICKS.getDefaultState(), 11, 20, 8, start);
        structure.setBlockState(world, Blocks.CHEST.getDefaultState().with(ChestBlock.FACING, Direction.SOUTH).with(ChestBlock.WATERLOGGED, false).with(ChestBlock.TYPE, ChestType.SINGLE), 11, 20, 9, start);
        structure.setBlockState(world, Blocks.COBBLESTONE_STAIRS.getDefaultState().with(StairsBlock.FACING, Direction.SOUTH).with(StairsBlock.WATERLOGGED, false).with(StairsBlock.SHAPE, StairsShape.STRAIGHT).with(StairsBlock.HALF, Half.BOTTOM), 11, 20, 10, start);
        structure.setBlockState(world, Blocks.NETHERRACK.getDefaultState(), 11, 20, 11, start);
        structure.setBlockState(world, Blocks.COBBLESTONE_STAIRS.getDefaultState().with(StairsBlock.FACING, Direction.NORTH).with(StairsBlock.WATERLOGGED, false).with(StairsBlock.SHAPE, StairsShape.STRAIGHT).with(StairsBlock.HALF, Half.BOTTOM), 11, 20, 12, start);
        structure.setBlockState(world, Blocks.CHEST.getDefaultState().with(ChestBlock.FACING, Direction.NORTH).with(ChestBlock.WATERLOGGED, false).with(ChestBlock.TYPE, ChestType.SINGLE), 11, 20, 13, start);
        structure.setBlockState(world, Blocks.STONE_BRICKS.getDefaultState(), 11, 20, 14, start);
        structure.setBlockState(world, Blocks.STONE_BRICK_STAIRS.getDefaultState().with(StairsBlock.FACING, Direction.NORTH).with(StairsBlock.WATERLOGGED, false).with(StairsBlock.SHAPE, StairsShape.STRAIGHT).with(StairsBlock.HALF, Half.BOTTOM), 11, 21, 10, start);
        structure.setBlockState(world, Blocks.FIRE.getDefaultState(), 11, 21, 11, start);
        structure.setBlockState(world, Blocks.STONE_BRICK_STAIRS.getDefaultState().with(StairsBlock.FACING, Direction.SOUTH).with(StairsBlock.WATERLOGGED, false).with(StairsBlock.SHAPE, StairsShape.STRAIGHT).with(StairsBlock.HALF, Half.BOTTOM), 11, 21, 12, start);
        structure.setBlockState(world, Blocks.DARK_OAK_STAIRS.getDefaultState().with(StairsBlock.FACING, Direction.SOUTH).with(StairsBlock.WATERLOGGED, false).with(StairsBlock.SHAPE, StairsShape.STRAIGHT).with(StairsBlock.HALF, Half.TOP), 11, 23, 7, start);
        structure.setBlockState(world, Blocks.DARK_OAK_STAIRS.getDefaultState().with(StairsBlock.FACING, Direction.NORTH).with(StairsBlock.WATERLOGGED, false).with(StairsBlock.SHAPE, StairsShape.STRAIGHT).with(StairsBlock.HALF, Half.TOP), 11, 23, 15, start);
        structure.setBlockState(world, Blocks.DARK_OAK_STAIRS.getDefaultState().with(StairsBlock.FACING, Direction.SOUTH).with(StairsBlock.WATERLOGGED, false).with(StairsBlock.SHAPE, StairsShape.STRAIGHT).with(StairsBlock.HALF, Half.TOP), 11, 24, 8, start);
        structure.setBlockState(world, Blocks.DARK_OAK_STAIRS.getDefaultState().with(StairsBlock.FACING, Direction.NORTH).with(StairsBlock.WATERLOGGED, false).with(StairsBlock.SHAPE, StairsShape.STRAIGHT).with(StairsBlock.HALF, Half.TOP), 11, 24, 14, start);
        structure.setBlockState(world, Blocks.DARK_OAK_STAIRS.getDefaultState().with(StairsBlock.FACING, Direction.SOUTH).with(StairsBlock.WATERLOGGED, false).with(StairsBlock.SHAPE, StairsShape.STRAIGHT).with(StairsBlock.HALF, Half.BOTTOM), 11, 26, 10, start);
        structure.setBlockState(world, Blocks.DARK_OAK_STAIRS.getDefaultState().with(StairsBlock.FACING, Direction.NORTH).with(StairsBlock.WATERLOGGED, false).with(StairsBlock.SHAPE, StairsShape.STRAIGHT).with(StairsBlock.HALF, Half.BOTTOM), 11, 26, 12, start);
        structure.setBlockState(world, Blocks.COBBLESTONE_WALL.getDefaultState().with(WallBlock.WATERLOGGED, false).with(WallBlock.UP, true).with(WallBlock.WALL_HEIGHT_NORTH, WallHeight.LOW).with(WallBlock.WALL_HEIGHT_SOUTH, WallHeight.LOW).with(WallBlock.WALL_HEIGHT_EAST, WallHeight.LOW).with(WallBlock.WALL_HEIGHT_WEST, WallHeight.LOW), 11, 28, 11, start);
        structure.setBlockState(world, Blocks.TORCH.getDefaultState(), 11, 32, 11, start);
        structure.setBlockState(world, Blocks.STONE_BRICKS.getDefaultState(), 12, 7, 14, start);
        structure.setBlockState(world, Blocks.COBBLESTONE_WALL.getDefaultState().with(WallBlock.WATERLOGGED, false).with(WallBlock.UP, true).with(WallBlock.WALL_HEIGHT_NORTH, WallHeight.LOW).with(WallBlock.WALL_HEIGHT_SOUTH, WallHeight.LOW).with(WallBlock.WALL_HEIGHT_EAST, WallHeight.LOW).with(WallBlock.WALL_HEIGHT_WEST, WallHeight.LOW), 12, 7, 15, start);
        structure.setBlockState(world, Blocks.OAK_PLANKS.getDefaultState(), 12, 8, 10, start);
        structure.setBlockState(world, Blocks.OAK_SLAB.getDefaultState().with(SlabBlock.TYPE, SlabType.TOP).with(SlabBlock.WATERLOGGED, false), 12, 8, 11, start);
        structure.setBlockState(world, Blocks.WALL_TORCH.getDefaultState().with(WallTorchBlock.HORIZONTAL_FACING, Direction.WEST), 12, 8, 12, start);
        structure.setBlockState(world, Blocks.SPRUCE_FENCE.getDefaultState().with(FourWayBlock.WATERLOGGED, false).with(FourWayBlock.NORTH, true).with(FourWayBlock.SOUTH, false).with(FourWayBlock.EAST, false).with(FourWayBlock.WEST, false), 12, 8, 15, start);
        structure.setBlockState(world, Blocks.OAK_STAIRS.getDefaultState().with(StairsBlock.FACING, Direction.SOUTH).with(StairsBlock.WATERLOGGED, false).with(StairsBlock.SHAPE, StairsShape.STRAIGHT).with(StairsBlock.HALF, Half.BOTTOM), 12, 9, 11, start);
        structure.setBlockState(world, Blocks.OAK_SLAB.getDefaultState().with(SlabBlock.TYPE, SlabType.TOP).with(SlabBlock.WATERLOGGED, false), 12, 9, 12, start);
        structure.setBlockState(world, Blocks.SMOOTH_STONE_SLAB.getDefaultState().with(SlabBlock.TYPE, SlabType.BOTTOM).with(SlabBlock.WATERLOGGED, false), 12, 9, 15, start);
        structure.setBlockState(world, Blocks.STONE_BRICK_STAIRS.getDefaultState().with(StairsBlock.FACING, Direction.SOUTH).with(StairsBlock.WATERLOGGED, false).with(StairsBlock.SHAPE, StairsShape.STRAIGHT).with(StairsBlock.HALF, Half.TOP), 12, 10, 8, start);
        structure.setBlockState(world, Blocks.AIR.getDefaultState(), 12, 10, 12, start);
        structure.setBlockState(world, Blocks.STONE_BRICK_STAIRS.getDefaultState().with(StairsBlock.FACING, Direction.NORTH).with(StairsBlock.WATERLOGGED, false).with(StairsBlock.SHAPE, StairsShape.STRAIGHT).with(StairsBlock.HALF, Half.TOP), 12, 10, 14, start);
        structure.setBlockState(world, Blocks.COBBLESTONE_WALL.getDefaultState().with(WallBlock.WATERLOGGED, false).with(WallBlock.UP, true).with(WallBlock.WALL_HEIGHT_NORTH, WallHeight.LOW).with(WallBlock.WALL_HEIGHT_SOUTH, WallHeight.LOW).with(WallBlock.WALL_HEIGHT_EAST, WallHeight.LOW).with(WallBlock.WALL_HEIGHT_WEST, WallHeight.LOW), 12, 11, 8, start);
        structure.setBlockState(world, Blocks.WALL_TORCH.getDefaultState().with(WallTorchBlock.HORIZONTAL_FACING, Direction.WEST), 12, 11, 11, start);
        structure.setBlockState(world, Blocks.COBBLESTONE_WALL.getDefaultState().with(WallBlock.WATERLOGGED, false).with(WallBlock.UP, true).with(WallBlock.WALL_HEIGHT_NORTH, WallHeight.LOW).with(WallBlock.WALL_HEIGHT_SOUTH, WallHeight.LOW).with(WallBlock.WALL_HEIGHT_EAST, WallHeight.LOW).with(WallBlock.WALL_HEIGHT_WEST, WallHeight.LOW), 12, 11, 14, start);
        structure.setBlockState(world, Blocks.SMOOTH_STONE_SLAB.getDefaultState().with(SlabBlock.TYPE, SlabType.BOTTOM).with(SlabBlock.WATERLOGGED, false), 12, 14, 8, start);
        structure.setBlockState(world, Blocks.SMOOTH_STONE_SLAB.getDefaultState().with(SlabBlock.TYPE, SlabType.BOTTOM).with(SlabBlock.WATERLOGGED, false), 12, 14, 14, start);
        structure.setBlockState(world, Blocks.WALL_TORCH.getDefaultState().with(WallTorchBlock.HORIZONTAL_FACING, Direction.WEST), 12, 15, 11, start);
        structure.setBlockState(world, Blocks.STONE_BRICK_STAIRS.getDefaultState().with(StairsBlock.FACING, Direction.SOUTH).with(StairsBlock.WATERLOGGED, false).with(StairsBlock.SHAPE, StairsShape.STRAIGHT).with(StairsBlock.HALF, Half.TOP), 12, 19, 8, start);
        structure.setBlockState(world, Blocks.STONE_BRICK_STAIRS.getDefaultState().with(StairsBlock.FACING, Direction.NORTH).with(StairsBlock.WATERLOGGED, false).with(StairsBlock.SHAPE, StairsShape.STRAIGHT).with(StairsBlock.HALF, Half.TOP), 12, 19, 14, start);
        structure.setBlockState(world, Blocks.COBBLESTONE_STAIRS.getDefaultState().with(StairsBlock.FACING, Direction.WEST).with(StairsBlock.WATERLOGGED, false).with(StairsBlock.SHAPE, StairsShape.STRAIGHT).with(StairsBlock.HALF, Half.BOTTOM), 12, 20, 11, start);
        structure.setBlockState(world, Blocks.CRACKED_STONE_BRICKS.getDefaultState(), 12, 20, 14, start);
        structure.setBlockState(world, Blocks.STONE_BRICK_SLAB.getDefaultState().with(SlabBlock.TYPE, SlabType.BOTTOM).with(SlabBlock.WATERLOGGED, false), 12, 21, 8, start);
        structure.setBlockState(world, Blocks.STONE_BRICK_STAIRS.getDefaultState().with(StairsBlock.FACING, Direction.EAST).with(StairsBlock.WATERLOGGED, false).with(StairsBlock.SHAPE, StairsShape.STRAIGHT).with(StairsBlock.HALF, Half.BOTTOM), 12, 21, 11, start);
        structure.setBlockState(world, Blocks.STONE_BRICK_SLAB.getDefaultState().with(SlabBlock.TYPE, SlabType.BOTTOM).with(SlabBlock.WATERLOGGED, false), 12, 21, 14, start);
        structure.setBlockState(world, Blocks.DARK_OAK_STAIRS.getDefaultState().with(StairsBlock.FACING, Direction.WEST).with(StairsBlock.WATERLOGGED, false).with(StairsBlock.SHAPE, StairsShape.STRAIGHT).with(StairsBlock.HALF, Half.BOTTOM), 12, 26, 11, start);
        structure.setBlockState(world, Blocks.STONE.getDefaultState(), 13, 0, 4, start);
        structure.setBlockState(world, Blocks.STONE.getDefaultState(), 13, 0, 18, start);
        structure.setBlockState(world, Blocks.STONE_BRICK_SLAB.getDefaultState().with(SlabBlock.TYPE, SlabType.BOTTOM).with(SlabBlock.WATERLOGGED, false), 13, 10, 9, start);
        structure.setBlockState(world, Blocks.STONE_BRICK_SLAB.getDefaultState().with(SlabBlock.TYPE, SlabType.BOTTOM).with(SlabBlock.WATERLOGGED, false), 13, 10, 13, start);
        structure.setBlockState(world, Blocks.IRON_BARS.getDefaultState().with(FourWayBlock.WATERLOGGED, false).with(FourWayBlock.NORTH, true).with(FourWayBlock.SOUTH, true).with(FourWayBlock.EAST, false).with(FourWayBlock.WEST, false), 13, 12, 11, start);
        structure.setBlockState(world, Blocks.IRON_BARS.getDefaultState().with(FourWayBlock.WATERLOGGED, false).with(FourWayBlock.NORTH, true).with(FourWayBlock.SOUTH, false).with(FourWayBlock.EAST, false).with(FourWayBlock.WEST, false), 13, 13, 11, start);
        structure.setBlockState(world, Blocks.IRON_BARS.getDefaultState().with(FourWayBlock.WATERLOGGED, false).with(FourWayBlock.NORTH, false).with(FourWayBlock.SOUTH, true).with(FourWayBlock.EAST, false).with(FourWayBlock.WEST, false), 13, 16, 11, start);
        structure.setBlockState(world, Blocks.IRON_BARS.getDefaultState().with(FourWayBlock.WATERLOGGED, false).with(FourWayBlock.NORTH, false).with(FourWayBlock.SOUTH, false).with(FourWayBlock.EAST, false).with(FourWayBlock.WEST, false), 13, 17, 11, start);
        structure.setBlockState(world, Blocks.STONE_BRICK_SLAB.getDefaultState().with(SlabBlock.TYPE, SlabType.TOP).with(SlabBlock.WATERLOGGED, false), 13, 19, 9, start);
        structure.setBlockState(world, Blocks.STONE_BRICK_SLAB.getDefaultState().with(SlabBlock.TYPE, SlabType.TOP).with(SlabBlock.WATERLOGGED, false), 13, 19, 13, start);
        structure.setBlockState(world, Blocks.CRACKED_STONE_BRICKS.getDefaultState(), 13, 20, 9, start);
        structure.setBlockState(world, Blocks.AIR.getDefaultState(), 13, 20, 11, start);
        structure.setBlockState(world, Blocks.STONE_BRICKS.getDefaultState(), 13, 20, 13, start);
        structure.setBlockState(world, Blocks.WALL_TORCH.getDefaultState().with(WallTorchBlock.HORIZONTAL_FACING, Direction.WEST), 13, 21, 11, start);
        structure.setBlockState(world, Blocks.STONE_BRICKS.getDefaultState(), 14, 7, 10, start);
        structure.setBlockState(world, Blocks.STONE_BRICKS.getDefaultState(), 14, 7, 12, start);
        structure.setBlockState(world, Blocks.STONE_BRICK_STAIRS.getDefaultState().with(StairsBlock.FACING, Direction.WEST).with(StairsBlock.WATERLOGGED, false).with(StairsBlock.SHAPE, StairsShape.STRAIGHT).with(StairsBlock.HALF, Half.TOP), 14, 10, 10, start);
        structure.setBlockState(world, Blocks.STONE_BRICK_SLAB.getDefaultState().with(SlabBlock.TYPE, SlabType.BOTTOM).with(SlabBlock.WATERLOGGED, false), 14, 10, 11, start);
        structure.setBlockState(world, Blocks.STONE_BRICK_STAIRS.getDefaultState().with(StairsBlock.FACING, Direction.WEST).with(StairsBlock.WATERLOGGED, false).with(StairsBlock.SHAPE, StairsShape.STRAIGHT).with(StairsBlock.HALF, Half.TOP), 14, 10, 12, start);
        structure.setBlockState(world, Blocks.COBBLESTONE_WALL.getDefaultState().with(WallBlock.WATERLOGGED, false).with(WallBlock.UP, true).with(WallBlock.WALL_HEIGHT_NORTH, WallHeight.LOW).with(WallBlock.WALL_HEIGHT_SOUTH, WallHeight.LOW).with(WallBlock.WALL_HEIGHT_EAST, WallHeight.LOW).with(WallBlock.WALL_HEIGHT_WEST, WallHeight.LOW), 14, 11, 10, start);
        structure.setBlockState(world, Blocks.COBBLESTONE_WALL.getDefaultState().with(WallBlock.WATERLOGGED, false).with(WallBlock.UP, true).with(WallBlock.WALL_HEIGHT_NORTH, WallHeight.LOW).with(WallBlock.WALL_HEIGHT_SOUTH, WallHeight.LOW).with(WallBlock.WALL_HEIGHT_EAST, WallHeight.LOW).with(WallBlock.WALL_HEIGHT_WEST, WallHeight.LOW), 14, 11, 12, start);
        structure.setBlockState(world, Blocks.OAK_FENCE.getDefaultState().with(FourWayBlock.WATERLOGGED, false).with(FourWayBlock.NORTH, false).with(FourWayBlock.SOUTH, false).with(FourWayBlock.EAST, false).with(FourWayBlock.WEST, false), 14, 12, 10, start);
        structure.setBlockState(world, Blocks.OAK_FENCE.getDefaultState().with(FourWayBlock.WATERLOGGED, false).with(FourWayBlock.NORTH, false).with(FourWayBlock.SOUTH, false).with(FourWayBlock.EAST, false).with(FourWayBlock.WEST, true), 14, 13, 10, start);
        structure.setBlockState(world, Blocks.SMOOTH_STONE_SLAB.getDefaultState().with(SlabBlock.TYPE, SlabType.BOTTOM).with(SlabBlock.WATERLOGGED, false), 14, 14, 10, start);
        structure.setBlockState(world, Blocks.SMOOTH_STONE_SLAB.getDefaultState().with(SlabBlock.TYPE, SlabType.TOP).with(SlabBlock.WATERLOGGED, false), 14, 14, 11, start);
        structure.setBlockState(world, Blocks.SMOOTH_STONE_SLAB.getDefaultState().with(SlabBlock.TYPE, SlabType.BOTTOM).with(SlabBlock.WATERLOGGED, false), 14, 14, 12, start);
        structure.setBlockState(world, Blocks.STONE_BRICK_STAIRS.getDefaultState().with(StairsBlock.FACING, Direction.WEST).with(StairsBlock.WATERLOGGED, false).with(StairsBlock.SHAPE, StairsShape.STRAIGHT).with(StairsBlock.HALF, Half.TOP), 14, 19, 10, start);
        structure.setBlockState(world, Blocks.STONE_BRICK_SLAB.getDefaultState().with(SlabBlock.TYPE, SlabType.TOP).with(SlabBlock.WATERLOGGED, false), 14, 19, 11, start);
        structure.setBlockState(world, Blocks.STONE_BRICK_STAIRS.getDefaultState().with(StairsBlock.FACING, Direction.WEST).with(StairsBlock.WATERLOGGED, false).with(StairsBlock.SHAPE, StairsShape.STRAIGHT).with(StairsBlock.HALF, Half.TOP), 14, 19, 12, start);
        structure.setBlockState(world, Blocks.STONE_BRICKS.getDefaultState(), 14, 20, 10, start);
        structure.setBlockState(world, Blocks.CRACKED_STONE_BRICKS.getDefaultState(), 14, 20, 11, start);
        structure.setBlockState(world, Blocks.STONE_BRICKS.getDefaultState(), 14, 20, 12, start);
        structure.setBlockState(world, Blocks.STONE_BRICK_SLAB.getDefaultState().with(SlabBlock.TYPE, SlabType.BOTTOM).with(SlabBlock.WATERLOGGED, false), 14, 21, 10, start);
        structure.setBlockState(world, Blocks.STONE_BRICK_SLAB.getDefaultState().with(SlabBlock.TYPE, SlabType.BOTTOM).with(SlabBlock.WATERLOGGED, false), 14, 21, 12, start);
        structure.setBlockState(world, Blocks.DARK_OAK_SLAB.getDefaultState().with(SlabBlock.TYPE, SlabType.TOP).with(SlabBlock.WATERLOGGED, false), 14, 23, 13, start);
        structure.setBlockState(world, Blocks.DARK_OAK_STAIRS.getDefaultState().with(StairsBlock.FACING, Direction.WEST).with(StairsBlock.WATERLOGGED, false).with(StairsBlock.SHAPE, StairsShape.STRAIGHT).with(StairsBlock.HALF, Half.TOP), 14, 24, 11, start);
        structure.setBlockState(world, Blocks.DARK_OAK_SLAB.getDefaultState().with(SlabBlock.TYPE, SlabType.BOTTOM).with(SlabBlock.WATERLOGGED, false), 14, 24, 14, start);
        structure.setBlockState(world, Blocks.STONE.getDefaultState(), 15, 0, 5, start);
        structure.setBlockState(world, Blocks.STONE.getDefaultState(), 15, 0, 17, start);
        structure.setBlockState(world, Blocks.GRASS_BLOCK.getDefaultState().with(SnowyDirtBlock.SNOWY, false), 15, 2, 3, start);
        structure.setBlockState(world, Blocks.GRASS_BLOCK.getDefaultState().with(SnowyDirtBlock.SNOWY, false), 15, 2, 19, start);
        structure.setBlockState(world, Blocks.AIR.getDefaultState(), 15, 7, 11, start);
        structure.setBlockState(world, Blocks.WALL_TORCH.getDefaultState().with(WallTorchBlock.HORIZONTAL_FACING, Direction.EAST), 15, 9, 11, start);
        structure.setBlockState(world, Blocks.DARK_OAK_STAIRS.getDefaultState().with(StairsBlock.FACING, Direction.WEST).with(StairsBlock.WATERLOGGED, false).with(StairsBlock.SHAPE, StairsShape.STRAIGHT).with(StairsBlock.HALF, Half.TOP), 15, 23, 11, start);
        structure.setBlockState(world, Blocks.GRASS_BLOCK.getDefaultState().with(SnowyDirtBlock.SNOWY, false), 16, 0, 2, start);
        structure.setBlockState(world, Blocks.GRASS_BLOCK.getDefaultState().with(SnowyDirtBlock.SNOWY, false), 16, 0, 20, start);
        structure.setBlockState(world, Blocks.GRASS_BLOCK.getDefaultState().with(SnowyDirtBlock.SNOWY, false), 16, 3, 18, start);
        structure.setBlockState(world, Blocks.GRASS_BLOCK.getDefaultState().with(SnowyDirtBlock.SNOWY, false), 16, 4, 17, start);
        structure.setBlockState(world, Blocks.STONE.getDefaultState(), 17, 0, 15, start);
        structure.setBlockState(world, Blocks.GRASS_BLOCK.getDefaultState().with(SnowyDirtBlock.SNOWY, false), 17, 2, 18, start);
        structure.setBlockState(world, Blocks.GRASS_BLOCK.getDefaultState().with(SnowyDirtBlock.SNOWY, false), 17, 3, 17, start);
        structure.setBlockState(world, Blocks.GRASS_BLOCK.getDefaultState().with(SnowyDirtBlock.SNOWY, false), 17, 4, 16, start);
        structure.setBlockState(world, Blocks.GRASS_BLOCK.getDefaultState().with(SnowyDirtBlock.SNOWY, false), 18, 0, 19, start);
        structure.setBlockState(world, Blocks.GRASS_BLOCK.getDefaultState().with(SnowyDirtBlock.SNOWY, false), 18, 1, 18, start);
        structure.setBlockState(world, Blocks.GRASS_BLOCK.getDefaultState().with(SnowyDirtBlock.SNOWY, false), 18, 2, 5, start);
        structure.setBlockState(world, Blocks.GRASS_BLOCK.getDefaultState().with(SnowyDirtBlock.SNOWY, false), 18, 2, 17, start);
        structure.setBlockState(world, Blocks.GRASS_BLOCK.getDefaultState().with(SnowyDirtBlock.SNOWY, false), 18, 3, 6, start);
        structure.setBlockState(world, Blocks.GRASS_BLOCK.getDefaultState().with(SnowyDirtBlock.SNOWY, false), 18, 3, 16, start);
        structure.setBlockState(world, Blocks.GRASS_BLOCK.getDefaultState().with(SnowyDirtBlock.SNOWY, false), 19, 0, 4, start);
        structure.setBlockState(world, Blocks.GRASS_BLOCK.getDefaultState().with(SnowyDirtBlock.SNOWY, false), 19, 0, 18, start);
        structure.setBlockState(world, Blocks.GRASS_BLOCK.getDefaultState().with(SnowyDirtBlock.SNOWY, false), 19, 2, 7, start);
        structure.setBlockState(world, Blocks.GRASS_BLOCK.getDefaultState().with(SnowyDirtBlock.SNOWY, false), 19, 2, 15, start);
        structure.setBlockState(world, Blocks.GRASS_BLOCK.getDefaultState().with(SnowyDirtBlock.SNOWY, false), 20, 0, 6, start);
        structure.setBlockState(world, Blocks.GRASS_BLOCK.getDefaultState().with(SnowyDirtBlock.SNOWY, false), 20, 0, 16, start);
        structure.fillWithBlocks(world, start, 1, 0, 8, 1, 0, 9, Blocks.GRASS_BLOCK.getDefaultState().with(SnowyDirtBlock.SNOWY, false));
        structure.fillWithBlocks(world, start, 1, 0, 10, 2, 0, 12, Blocks.DIRT.getDefaultState());
        structure.fillWithBlocks(world, start, 1, 0, 13, 1, 0, 14, Blocks.GRASS_BLOCK.getDefaultState().with(SnowyDirtBlock.SNOWY, false));
        structure.fillWithBlocks(world, start, 1, 1, 10, 1, 1, 12, Blocks.GRASS_BLOCK.getDefaultState().with(SnowyDirtBlock.SNOWY, false));
        structure.fillWithBlocks(world, start, 2, 0, 7, 3, 0, 10, Blocks.DIRT.getDefaultState());
        structure.fillWithBlocks(world, start, 2, 0, 13, 3, 0, 15, Blocks.DIRT.getDefaultState());
        structure.fillWithBlocks(world, start, 2, 1, 7, 2, 1, 8, Blocks.GRASS_BLOCK.getDefaultState().with(SnowyDirtBlock.SNOWY, false));
        structure.fillWithBlocks(world, start, 2, 1, 9, 4, 1, 11, Blocks.DIRT.getDefaultState());
        structure.fillWithBlocks(world, start, 2, 1, 12, 3, 1, 13, Blocks.DIRT.getDefaultState());
        structure.fillWithBlocks(world, start, 2, 1, 14, 2, 1, 15, Blocks.GRASS_BLOCK.getDefaultState().with(SnowyDirtBlock.SNOWY, false));
        structure.fillWithBlocks(world, start, 2, 2, 9, 2, 2, 13, Blocks.GRASS_BLOCK.getDefaultState().with(SnowyDirtBlock.SNOWY, false));
        structure.fillWithBlocks(world, start, 3, 0, 5, 6, 0, 8, Blocks.DIRT.getDefaultState());
        structure.fillWithBlocks(world, start, 3, 0, 11, 3, 0, 12, Blocks.STONE.getDefaultState());
        structure.fillWithBlocks(world, start, 3, 0, 16, 4, 0, 17, Blocks.DIRT.getDefaultState());
        structure.fillWithBlocks(world, start, 3, 0, 18, 3, 0, 18, Blocks.GRASS_BLOCK.getDefaultState().with(SnowyDirtBlock.SNOWY, false));
        structure.fillWithBlocks(world, start, 3, 1, 5, 3, 1, 6, Blocks.GRASS_BLOCK.getDefaultState().with(SnowyDirtBlock.SNOWY, false));
        structure.fillWithBlocks(world, start, 3, 1, 7, 6, 1, 11, Blocks.DIRT.getDefaultState());
        structure.fillWithBlocks(world, start, 3, 1, 14, 4, 1, 15, Blocks.DIRT.getDefaultState());
        structure.fillWithBlocks(world, start, 3, 1, 16, 3, 1, 17, Blocks.GRASS_BLOCK.getDefaultState().with(SnowyDirtBlock.SNOWY, false));
        structure.fillWithBlocks(world, start, 3, 2, 8, 9, 2, 14, Blocks.DIRT.getDefaultState());
        structure.fillWithBlocks(world, start, 3, 3, 8, 3, 3, 9, Blocks.GRASS_BLOCK.getDefaultState().with(SnowyDirtBlock.SNOWY, false));
        structure.fillWithBlocks(world, start, 3, 3, 10, 5, 3, 12, Blocks.DIRT.getDefaultState());
        structure.fillWithBlocks(world, start, 3, 3, 13, 3, 3, 14, Blocks.GRASS_BLOCK.getDefaultState().with(SnowyDirtBlock.SNOWY, false));
        structure.fillWithBlocks(world, start, 3, 4, 10, 3, 4, 12, Blocks.GRASS_BLOCK.getDefaultState().with(SnowyDirtBlock.SNOWY, false));
        structure.fillWithBlocks(world, start, 4, 0, 4, 8, 0, 8, Blocks.DIRT.getDefaultState());
        structure.fillWithBlocks(world, start, 4, 0, 10, 5, 0, 12, Blocks.DIRT.getDefaultState());
        structure.fillWithBlocks(world, start, 4, 0, 13, 4, 0, 15, Blocks.STONE.getDefaultState());
        structure.fillWithBlocks(world, start, 4, 0, 18, 4, 0, 18, Blocks.DIRT.getDefaultState());
        structure.fillWithBlocks(world, start, 4, 1, 5, 8, 1, 9, Blocks.DIRT.getDefaultState());
        structure.fillWithBlocks(world, start, 4, 1, 12, 4, 1, 13, Blocks.STONE.getDefaultState());
        structure.fillWithBlocks(world, start, 4, 1, 16, 5, 1, 17, Blocks.DIRT.getDefaultState());
        structure.fillWithBlocks(world, start, 4, 1, 18, 4, 1, 18, Blocks.GRASS_BLOCK.getDefaultState().with(SnowyDirtBlock.SNOWY, false));
        structure.fillWithBlocks(world, start, 4, 2, 6, 14, 2, 16, Blocks.DIRT.getDefaultState());
        structure.fillWithBlocks(world, start, 4, 2, 17, 4, 2, 17, Blocks.GRASS_BLOCK.getDefaultState().with(SnowyDirtBlock.SNOWY, false));
        structure.fillWithBlocks(world, start, 4, 3, 7, 12, 3, 15, Blocks.DIRT.getDefaultState());
        structure.fillWithBlocks(world, start, 4, 3, 16, 4, 3, 16, Blocks.GRASS_BLOCK.getDefaultState().with(SnowyDirtBlock.SNOWY, false));
        structure.fillWithBlocks(world, start, 4, 4, 7, 4, 4, 8, Blocks.GRASS_BLOCK.getDefaultState().with(SnowyDirtBlock.SNOWY, false));
        structure.fillWithBlocks(world, start, 4, 4, 9, 8, 4, 13, Blocks.DIRT.getDefaultState());
        structure.fillWithBlocks(world, start, 4, 4, 14, 4, 4, 15, Blocks.GRASS_BLOCK.getDefaultState().with(SnowyDirtBlock.SNOWY, false));
        structure.fillWithBlocks(world, start, 4, 5, 9, 4, 5, 13, Blocks.GRASS_BLOCK.getDefaultState().with(SnowyDirtBlock.SNOWY, false));
        structure.fillWithBlocks(world, start, 5, 0, 3, 8, 0, 8, Blocks.DIRT.getDefaultState());
        structure.fillWithBlocks(world, start, 5, 0, 9, 5, 4, 14, Blocks.DIRT.getDefaultState());
        structure.fillWithBlocks(world, start, 5, 0, 15, 5, 0, 16, Blocks.STONE.getDefaultState());
        structure.fillWithBlocks(world, start, 5, 0, 17, 5, 0, 19, Blocks.DIRT.getDefaultState());
        structure.fillWithBlocks(world, start, 5, 1, 3, 6, 1, 3, Blocks.GRASS_BLOCK.getDefaultState().with(SnowyDirtBlock.SNOWY, false));
        structure.fillWithBlocks(world, start, 5, 1, 4, 10, 1, 9, Blocks.DIRT.getDefaultState());
        structure.fillWithBlocks(world, start, 5, 1, 15, 5, 1, 15, Blocks.STONE.getDefaultState());
        structure.fillWithBlocks(world, start, 5, 1, 18, 17, 1, 18, Blocks.DIRT.getDefaultState());
        structure.fillWithBlocks(world, start, 5, 1, 19, 6, 1, 19, Blocks.GRASS_BLOCK.getDefaultState().with(SnowyDirtBlock.SNOWY, false));
        structure.fillWithBlocks(world, start, 5, 2, 5, 17, 2, 17, Blocks.DIRT.getDefaultState());
        structure.fillWithBlocks(world, start, 5, 3, 6, 15, 3, 16, Blocks.DIRT.getDefaultState());
        structure.fillWithBlocks(world, start, 5, 3, 17, 5, 3, 17, Blocks.GRASS_BLOCK.getDefaultState().with(SnowyDirtBlock.SNOWY, false));
        structure.fillWithBlocks(world, start, 5, 4, 7, 13, 4, 15, Blocks.DIRT.getDefaultState());
        structure.fillWithBlocks(world, start, 5, 4, 16, 5, 4, 16, Blocks.GRASS_BLOCK.getDefaultState().with(SnowyDirtBlock.SNOWY, false));
        structure.fillWithBlocks(world, start, 5, 5, 7, 5, 5, 9, Blocks.GRASS_BLOCK.getDefaultState().with(SnowyDirtBlock.SNOWY, false));
        structure.fillWithBlocks(world, start, 5, 5, 10, 7, 5, 12, Blocks.DIRT.getDefaultState());
        structure.fillWithBlocks(world, start, 5, 5, 13, 5, 5, 15, Blocks.GRASS_BLOCK.getDefaultState().with(SnowyDirtBlock.SNOWY, false));
        structure.fillWithBlocks(world, start, 5, 6, 10, 7, 6, 12, Blocks.GRASS_BLOCK.getDefaultState().with(SnowyDirtBlock.SNOWY, false));
        structure.fillWithBlocks(world, start, 6, 0, 9, 6, 5, 9, Blocks.DIRT.getDefaultState());
        structure.fillWithBlocks(world, start, 6, 0, 10, 7, 0, 12, Blocks.STONE.getDefaultState());
        structure.fillWithBlocks(world, start, 6, 0, 13, 6, 2, 15, Blocks.DIRT.getDefaultState());
        structure.fillWithBlocks(world, start, 6, 0, 16, 9, 0, 16, Blocks.DIRT.getDefaultState());
        structure.fillWithBlocks(world, start, 6, 0, 17, 7, 0, 17, Blocks.STONE.getDefaultState());
        structure.fillWithBlocks(world, start, 6, 0, 18, 7, 0, 19, Blocks.DIRT.getDefaultState());
        structure.fillWithBlocks(world, start, 6, 1, 12, 6, 4, 15, Blocks.DIRT.getDefaultState());
        structure.fillWithBlocks(world, start, 6, 1, 17, 7, 1, 18, Blocks.DIRT.getDefaultState());
        structure.fillWithBlocks(world, start, 6, 2, 4, 16, 2, 18, Blocks.DIRT.getDefaultState());
        structure.fillWithBlocks(world, start, 6, 3, 5, 16, 3, 17, Blocks.DIRT.getDefaultState());
        structure.fillWithBlocks(world, start, 6, 4, 6, 16, 4, 16, Blocks.DIRT.getDefaultState());
        structure.fillWithBlocks(world, start, 6, 4, 17, 6, 4, 17, Blocks.GRASS_BLOCK.getDefaultState().with(SnowyDirtBlock.SNOWY, false));
        structure.fillWithBlocks(world, start, 6, 5, 6, 6, 5, 7, Blocks.GRASS_BLOCK.getDefaultState().with(SnowyDirtBlock.SNOWY, false));
        structure.fillWithBlocks(world, start, 6, 5, 8, 12, 5, 14, Blocks.DIRT.getDefaultState());
        structure.fillWithBlocks(world, start, 6, 5, 15, 6, 5, 16, Blocks.GRASS_BLOCK.getDefaultState().with(SnowyDirtBlock.SNOWY, false));
        structure.fillWithBlocks(world, start, 6, 6, 8, 7, 6, 14, Blocks.GRASS_BLOCK.getDefaultState().with(SnowyDirtBlock.SNOWY, false));
        structure.fillWithBlocks(world, start, 7, 0, 2, 11, 0, 6, Blocks.DIRT.getDefaultState());
        structure.fillWithBlocks(world, start, 7, 0, 9, 7, 0, 14, Blocks.STONE.getDefaultState());
        structure.fillWithBlocks(world, start, 7, 0, 15, 7, 0, 16, Blocks.DIRT.getDefaultState());
        structure.fillWithBlocks(world, start, 7, 0, 20, 15, 0, 20, Blocks.DIRT.getDefaultState());
        structure.fillWithBlocks(world, start, 7, 1, 2, 8, 1, 2, Blocks.GRASS_BLOCK.getDefaultState().with(SnowyDirtBlock.SNOWY, false));
        structure.fillWithBlocks(world, start, 7, 1, 3, 13, 1, 9, Blocks.DIRT.getDefaultState());
        structure.fillWithBlocks(world, start, 7, 1, 10, 7, 1, 13, Blocks.STONE.getDefaultState());
        structure.fillWithBlocks(world, start, 7, 1, 14, 7, 1, 19, Blocks.DIRT.getDefaultState());
        structure.fillWithBlocks(world, start, 7, 1, 20, 8, 1, 20, Blocks.GRASS_BLOCK.getDefaultState().with(SnowyDirtBlock.SNOWY, false));
        structure.fillWithBlocks(world, start, 7, 3, 4, 15, 3, 18, Blocks.DIRT.getDefaultState());
        structure.fillWithBlocks(world, start, 7, 4, 4, 8, 4, 4, Blocks.GRASS_BLOCK.getDefaultState().with(SnowyDirtBlock.SNOWY, false));
        structure.fillWithBlocks(world, start, 7, 4, 5, 15, 4, 17, Blocks.DIRT.getDefaultState());
        structure.fillWithBlocks(world, start, 7, 4, 18, 8, 4, 18, Blocks.GRASS_BLOCK.getDefaultState().with(SnowyDirtBlock.SNOWY, false));
        structure.fillWithBlocks(world, start, 7, 5, 5, 7, 5, 6, Blocks.GRASS_BLOCK.getDefaultState().with(SnowyDirtBlock.SNOWY, false));
        structure.fillWithBlocks(world, start, 7, 5, 7, 15, 5, 15, Blocks.DIRT.getDefaultState());
        structure.fillWithBlocks(world, start, 7, 5, 16, 7, 5, 17, Blocks.GRASS_BLOCK.getDefaultState().with(SnowyDirtBlock.SNOWY, false));
        structure.fillWithBlocks(world, start, 7, 6, 7, 8, 6, 9, Blocks.GRASS_BLOCK.getDefaultState().with(SnowyDirtBlock.SNOWY, false));
        structure.fillWithBlocks(world, start, 7, 6, 15, 7, 6, 15, Blocks.GRASS_BLOCK.getDefaultState().with(SnowyDirtBlock.SNOWY, false));
        structure.fillWithBlocks(world, start, 7, 24, 9, 7, 24, 13, Blocks.DARK_OAK_SLAB.getDefaultState().with(SlabBlock.TYPE, SlabType.BOTTOM).with(SlabBlock.WATERLOGGED, false));
        structure.fillWithBlocks(world, start, 8, 0, 1, 9, 0, 1, Blocks.GRASS_BLOCK.getDefaultState().with(SnowyDirtBlock.SNOWY, false));
        structure.fillWithBlocks(world, start, 8, 0, 9, 13, 0, 14, Blocks.DIRT.getDefaultState());
        structure.fillWithBlocks(world, start, 8, 0, 15, 14, 0, 15, Blocks.STONE.getDefaultState());
        structure.fillWithBlocks(world, start, 8, 0, 17, 8, 2, 19, Blocks.DIRT.getDefaultState());
        structure.fillWithBlocks(world, start, 8, 0, 21, 9, 0, 21, Blocks.GRASS_BLOCK.getDefaultState().with(SnowyDirtBlock.SNOWY, false));
        structure.fillWithBlocks(world, start, 8, 1, 10, 11, 1, 13, Blocks.DIRT.getDefaultState());
        structure.fillWithBlocks(world, start, 8, 1, 15, 8, 1, 19, Blocks.DIRT.getDefaultState());
        structure.fillWithBlocks(world, start, 8, 2, 3, 14, 2, 19, Blocks.DIRT.getDefaultState());
        structure.fillWithBlocks(world, start, 8, 3, 3, 9, 3, 3, Blocks.GRASS_BLOCK.getDefaultState().with(SnowyDirtBlock.SNOWY, false));
        structure.fillWithBlocks(world, start, 8, 3, 19, 9, 3, 19, Blocks.GRASS_BLOCK.getDefaultState().with(SnowyDirtBlock.SNOWY, false));
        structure.fillWithBlocks(world, start, 8, 5, 5, 9, 5, 5, Blocks.GRASS_BLOCK.getDefaultState().with(SnowyDirtBlock.SNOWY, false));
        structure.fillWithBlocks(world, start, 8, 5, 6, 14, 5, 16, Blocks.DIRT.getDefaultState());
        structure.fillWithBlocks(world, start, 8, 5, 17, 8, 5, 17, Blocks.GRASS_BLOCK.getDefaultState().with(SnowyDirtBlock.SNOWY, false));
        structure.fillWithBlocks(world, start, 8, 6, 6, 9, 6, 8, Blocks.GRASS_BLOCK.getDefaultState().with(SnowyDirtBlock.SNOWY, false));
        structure.fillWithBlocks(world, start, 8, 6, 10, 9, 6, 12, Blocks.DIRT.getDefaultState());
        structure.fillWithBlocks(world, start, 8, 6, 13, 8, 6, 16, Blocks.GRASS_BLOCK.getDefaultState().with(SnowyDirtBlock.SNOWY, false));
        structure.fillWithBlocks(world, start, 8, 7, 11, 9, 8, 11, Blocks.POLISHED_ANDESITE.getDefaultState());
        structure.fillWithBlocks(world, start, 8, 8, 10, 9, 9, 10, Blocks.COBBLESTONE.getDefaultState());
        structure.fillWithBlocks(world, start, 8, 8, 12, 9, 9, 12, Blocks.COBBLESTONE.getDefaultState());
        structure.fillWithBlocks(world, start, 8, 9, 11, 9, 9, 11, Blocks.POLISHED_ANDESITE.getDefaultState());
        structure.fillWithBlocks(world, start, 8, 12, 10, 8, 13, 10, Blocks.OAK_FENCE.getDefaultState().with(FourWayBlock.WATERLOGGED, false).with(FourWayBlock.NORTH, false).with(FourWayBlock.SOUTH, false).with(FourWayBlock.EAST, true).with(FourWayBlock.WEST, false));
        structure.fillWithBlocks(world, start, 8, 12, 12, 8, 13, 12, Blocks.OAK_FENCE.getDefaultState().with(FourWayBlock.WATERLOGGED, false).with(FourWayBlock.NORTH, false).with(FourWayBlock.SOUTH, false).with(FourWayBlock.EAST, true).with(FourWayBlock.WEST, false));
        structure.fillWithBlocks(world, start, 8, 21, 11, 8, 23, 11, Blocks.COBBLESTONE.getDefaultState());
        structure.fillWithBlocks(world, start, 8, 23, 9, 8, 23, 10, Blocks.DARK_OAK_SLAB.getDefaultState().with(SlabBlock.TYPE, SlabType.TOP).with(SlabBlock.WATERLOGGED, false));
        structure.fillWithBlocks(world, start, 8, 23, 12, 8, 23, 13, Blocks.DARK_OAK_SLAB.getDefaultState().with(SlabBlock.TYPE, SlabType.TOP).with(SlabBlock.WATERLOGGED, false));
        structure.fillWithBlocks(world, start, 8, 24, 9, 9, 24, 10, Blocks.COBBLESTONE.getDefaultState());
        structure.fillWithBlocks(world, start, 8, 24, 12, 9, 24, 13, Blocks.COBBLESTONE.getDefaultState());
        structure.fillWithBlocks(world, start, 8, 24, 14, 8, 24, 14, Blocks.DARK_OAK_SLAB.getDefaultState().with(SlabBlock.TYPE, SlabType.BOTTOM).with(SlabBlock.WATERLOGGED, false));
        structure.fillWithBlocks(world, start, 9, 0, 7, 13, 0, 7, Blocks.STONE.getDefaultState());
        structure.fillWithBlocks(world, start, 9, 0, 8, 14, 0, 14, Blocks.DIRT.getDefaultState());
        structure.fillWithBlocks(world, start, 9, 0, 17, 9, 0, 17, Blocks.DIRT.getDefaultState());
        structure.fillWithBlocks(world, start, 9, 0, 19, 10, 0, 20, Blocks.DIRT.getDefaultState());
        structure.fillWithBlocks(world, start, 9, 1, 2, 13, 1, 14, Blocks.DIRT.getDefaultState());
        structure.fillWithBlocks(world, start, 9, 1, 15, 13, 1, 15, Blocks.STONE.getDefaultState());
        structure.fillWithBlocks(world, start, 9, 1, 16, 13, 1, 20, Blocks.DIRT.getDefaultState());
        structure.fillWithBlocks(world, start, 9, 2, 2, 13, 2, 2, Blocks.GRASS_BLOCK.getDefaultState().with(SnowyDirtBlock.SNOWY, false));
        structure.fillWithBlocks(world, start, 9, 2, 20, 13, 2, 20, Blocks.GRASS_BLOCK.getDefaultState().with(SnowyDirtBlock.SNOWY, false));
        structure.fillWithBlocks(world, start, 9, 4, 4, 13, 4, 18, Blocks.DIRT.getDefaultState());
        structure.fillWithBlocks(world, start, 9, 5, 4, 9, 5, 5, Blocks.GRASS_BLOCK.getDefaultState().with(SnowyDirtBlock.SNOWY, false));
        structure.fillWithBlocks(world, start, 9, 5, 17, 9, 5, 18, Blocks.GRASS_BLOCK.getDefaultState().with(SnowyDirtBlock.SNOWY, false));
        structure.fillWithBlocks(world, start, 9, 6, 9, 10, 6, 11, Blocks.DIRT.getDefaultState());
        structure.fillWithBlocks(world, start, 9, 6, 13, 9, 6, 13, Blocks.DIRT.getDefaultState());
        structure.fillWithBlocks(world, start, 9, 6, 14, 9, 6, 16, Blocks.GRASS_BLOCK.getDefaultState().with(SnowyDirtBlock.SNOWY, false));
        structure.fillWithBlocks(world, start, 9, 7, 9, 9, 9, 9, Blocks.STONE_BRICKS.getDefaultState());
        structure.fillWithBlocks(world, start, 9, 7, 10, 9, 19, 10, Blocks.COBBLESTONE.getDefaultState());
        structure.fillWithBlocks(world, start, 9, 7, 12, 9, 19, 12, Blocks.COBBLESTONE.getDefaultState());
        structure.fillWithBlocks(world, start, 9, 7, 13, 9, 9, 13, Blocks.STONE_BRICKS.getDefaultState());
        structure.fillWithBlocks(world, start, 9, 10, 11, 9, 11, 11, Blocks.POLISHED_ANDESITE.getDefaultState());
        structure.fillWithBlocks(world, start, 9, 12, 11, 9, 13, 11, Blocks.IRON_BARS.getDefaultState().with(FourWayBlock.WATERLOGGED, false).with(FourWayBlock.NORTH, false).with(FourWayBlock.SOUTH, true).with(FourWayBlock.EAST, false).with(FourWayBlock.WEST, false));
        structure.fillWithBlocks(world, start, 9, 14, 11, 9, 15, 11, Blocks.POLISHED_ANDESITE.getDefaultState());
        structure.fillWithBlocks(world, start, 9, 18, 11, 9, 19, 11, Blocks.POLISHED_ANDESITE.getDefaultState());
        structure.fillWithBlocks(world, start, 9, 23, 8, 10, 23, 8, Blocks.DARK_OAK_SLAB.getDefaultState().with(SlabBlock.TYPE, SlabType.TOP).with(SlabBlock.WATERLOGGED, false));
        structure.fillWithBlocks(world, start, 9, 23, 14, 10, 23, 14, Blocks.DARK_OAK_SLAB.getDefaultState().with(SlabBlock.TYPE, SlabType.TOP).with(SlabBlock.WATERLOGGED, false));
        structure.fillWithBlocks(world, start, 9, 24, 7, 13, 24, 7, Blocks.DARK_OAK_SLAB.getDefaultState().with(SlabBlock.TYPE, SlabType.BOTTOM).with(SlabBlock.WATERLOGGED, false));
        structure.fillWithBlocks(world, start, 9, 24, 8, 10, 24, 14, Blocks.COBBLESTONE.getDefaultState());
        structure.fillWithBlocks(world, start, 9, 24, 15, 13, 24, 15, Blocks.DARK_OAK_SLAB.getDefaultState().with(SlabBlock.TYPE, SlabType.BOTTOM).with(SlabBlock.WATERLOGGED, false));
        structure.fillWithBlocks(world, start, 9, 25, 10, 9, 25, 12, Blocks.DARK_OAK_STAIRS.getDefaultState().with(StairsBlock.FACING, Direction.EAST).with(StairsBlock.WATERLOGGED, false).with(StairsBlock.SHAPE, StairsShape.STRAIGHT).with(StairsBlock.HALF, Half.BOTTOM));
        structure.fillWithBlocks(world, start, 10, 0, 1, 12, 0, 6, Blocks.DIRT.getDefaultState());
        structure.fillWithBlocks(world, start, 10, 0, 16, 12, 0, 16, Blocks.STONE.getDefaultState());
        structure.fillWithBlocks(world, start, 10, 0, 17, 12, 0, 21, Blocks.DIRT.getDefaultState());
        structure.fillWithBlocks(world, start, 10, 1, 1, 12, 1, 1, Blocks.GRASS_BLOCK.getDefaultState().with(SnowyDirtBlock.SNOWY, false));
        structure.fillWithBlocks(world, start, 10, 1, 21, 12, 1, 21, Blocks.GRASS_BLOCK.getDefaultState().with(SnowyDirtBlock.SNOWY, false));
        structure.fillWithBlocks(world, start, 10, 3, 3, 12, 3, 19, Blocks.DIRT.getDefaultState());
        structure.fillWithBlocks(world, start, 10, 4, 3, 12, 4, 3, Blocks.GRASS_BLOCK.getDefaultState().with(SnowyDirtBlock.SNOWY, false));
        structure.fillWithBlocks(world, start, 10, 4, 19, 12, 4, 19, Blocks.GRASS_BLOCK.getDefaultState().with(SnowyDirtBlock.SNOWY, false));
        structure.fillWithBlocks(world, start, 10, 5, 4, 13, 5, 4, Blocks.GRASS_BLOCK.getDefaultState().with(SnowyDirtBlock.SNOWY, false));
        structure.fillWithBlocks(world, start, 10, 5, 5, 12, 5, 17, Blocks.DIRT.getDefaultState());
        structure.fillWithBlocks(world, start, 10, 5, 18, 13, 5, 18, Blocks.GRASS_BLOCK.getDefaultState().with(SnowyDirtBlock.SNOWY, false));
        structure.fillWithBlocks(world, start, 10, 6, 5, 12, 6, 7, Blocks.GRASS_BLOCK.getDefaultState().with(SnowyDirtBlock.SNOWY, false));
        structure.fillWithBlocks(world, start, 10, 6, 8, 12, 6, 10, Blocks.DIRT.getDefaultState());
        structure.fillWithBlocks(world, start, 10, 6, 12, 10, 6, 12, Blocks.GRASS_BLOCK.getDefaultState().with(SnowyDirtBlock.SNOWY, false));
        structure.fillWithBlocks(world, start, 10, 6, 13, 10, 6, 14, Blocks.DIRT.getDefaultState());
        structure.fillWithBlocks(world, start, 10, 6, 15, 12, 6, 17, Blocks.GRASS_BLOCK.getDefaultState().with(SnowyDirtBlock.SNOWY, false));
        structure.fillWithBlocks(world, start, 10, 7, 9, 10, 19, 9, Blocks.COBBLESTONE.getDefaultState());
        structure.fillWithBlocks(world, start, 10, 7, 10, 12, 7, 10, Blocks.OAK_PLANKS.getDefaultState());
        structure.fillWithBlocks(world, start, 10, 7, 13, 10, 19, 13, Blocks.COBBLESTONE.getDefaultState());
        structure.fillWithBlocks(world, start, 10, 8, 8, 10, 9, 9, Blocks.COBBLESTONE.getDefaultState());
        structure.fillWithBlocks(world, start, 10, 8, 14, 10, 9, 14, Blocks.COBBLESTONE.getDefaultState());
        structure.fillWithBlocks(world, start, 10, 11, 12, 10, 19, 12, Blocks.LADDER.getDefaultState().with(LadderBlock.FACING, Direction.EAST).with(LadderBlock.WATERLOGGED, false));
        structure.fillWithBlocks(world, start, 10, 14, 10, 11, 14, 11, Blocks.OAK_SLAB.getDefaultState().with(SlabBlock.TYPE, SlabType.DOUBLE).with(SlabBlock.WATERLOGGED, false));
        structure.fillWithBlocks(world, start, 10, 19, 10, 11, 19, 11, Blocks.STONE_BRICKS.getDefaultState());
        structure.fillWithBlocks(world, start, 10, 23, 7, 10, 23, 8, Blocks.DARK_OAK_SLAB.getDefaultState().with(SlabBlock.TYPE, SlabType.TOP).with(SlabBlock.WATERLOGGED, false));
        structure.fillWithBlocks(world, start, 10, 25, 9, 12, 25, 9, Blocks.DARK_OAK_STAIRS.getDefaultState().with(StairsBlock.FACING, Direction.SOUTH).with(StairsBlock.WATERLOGGED, false).with(StairsBlock.SHAPE, StairsShape.STRAIGHT).with(StairsBlock.HALF, Half.BOTTOM));
        structure.fillWithBlocks(world, start, 10, 25, 10, 12, 25, 12, Blocks.COBBLESTONE.getDefaultState());
        structure.fillWithBlocks(world, start, 10, 25, 13, 12, 25, 13, Blocks.DARK_OAK_STAIRS.getDefaultState().with(StairsBlock.FACING, Direction.NORTH).with(StairsBlock.WATERLOGGED, false).with(StairsBlock.SHAPE, StairsShape.STRAIGHT).with(StairsBlock.HALF, Half.BOTTOM));
        structure.fillWithBlocks(world, start, 11, 6, 11, 12, 6, 12, Blocks.GRASS_BLOCK.getDefaultState().with(SnowyDirtBlock.SNOWY, false));
        structure.fillWithBlocks(world, start, 11, 6, 13, 11, 6, 17, Blocks.GRASS_BLOCK.getDefaultState().with(SnowyDirtBlock.SNOWY, false));
        structure.fillWithBlocks(world, start, 11, 7, 8, 11, 8, 9, Blocks.POLISHED_ANDESITE.getDefaultState());
        structure.fillWithBlocks(world, start, 11, 9, 8, 11, 9, 9, Blocks.POLISHED_ANDESITE.getDefaultState());
        structure.fillWithBlocks(world, start, 11, 9, 13, 11, 9, 14, Blocks.POLISHED_ANDESITE.getDefaultState());
        structure.fillWithBlocks(world, start, 11, 10, 9, 11, 11, 9, Blocks.POLISHED_ANDESITE.getDefaultState());
        structure.fillWithBlocks(world, start, 11, 10, 13, 11, 11, 13, Blocks.POLISHED_ANDESITE.getDefaultState());
        structure.fillWithBlocks(world, start, 11, 14, 9, 11, 15, 9, Blocks.POLISHED_ANDESITE.getDefaultState());
        structure.fillWithBlocks(world, start, 11, 14, 12, 12, 14, 12, Blocks.OAK_SLAB.getDefaultState().with(SlabBlock.TYPE, SlabType.DOUBLE).with(SlabBlock.WATERLOGGED, false));
        structure.fillWithBlocks(world, start, 11, 14, 13, 11, 15, 13, Blocks.POLISHED_ANDESITE.getDefaultState());
        structure.fillWithBlocks(world, start, 11, 18, 9, 11, 19, 9, Blocks.POLISHED_ANDESITE.getDefaultState());
        structure.fillWithBlocks(world, start, 11, 18, 13, 11, 19, 13, Blocks.POLISHED_ANDESITE.getDefaultState());
        structure.fillWithBlocks(world, start, 11, 19, 12, 12, 19, 12, Blocks.STONE_BRICKS.getDefaultState());
        structure.fillWithBlocks(world, start, 11, 21, 8, 11, 23, 8, Blocks.COBBLESTONE.getDefaultState());
        structure.fillWithBlocks(world, start, 11, 21, 14, 11, 23, 14, Blocks.COBBLESTONE.getDefaultState());
        structure.fillWithBlocks(world, start, 11, 24, 9, 13, 24, 13, Blocks.COBBLESTONE.getDefaultState());
        structure.fillWithBlocks(world, start, 11, 26, 11, 11, 27, 11, Blocks.COBBLESTONE.getDefaultState());
        structure.fillWithBlocks(world, start, 11, 29, 11, 11, 31, 11, Blocks.SPRUCE_FENCE.getDefaultState().with(FourWayBlock.WATERLOGGED, false).with(FourWayBlock.NORTH, false).with(FourWayBlock.SOUTH, false).with(FourWayBlock.EAST, false).with(FourWayBlock.WEST, false));
        structure.fillWithBlocks(world, start, 12, 6, 13, 12, 6, 14, Blocks.DIRT.getDefaultState());
        structure.fillWithBlocks(world, start, 12, 7, 8, 12, 7, 8, Blocks.STONE_BRICKS.getDefaultState());
        structure.fillWithBlocks(world, start, 12, 7, 9, 12, 19, 9, Blocks.COBBLESTONE.getDefaultState());
        structure.fillWithBlocks(world, start, 12, 7, 13, 12, 19, 13, Blocks.COBBLESTONE.getDefaultState());
        structure.fillWithBlocks(world, start, 12, 8, 8, 12, 9, 9, Blocks.COBBLESTONE.getDefaultState());
        structure.fillWithBlocks(world, start, 12, 8, 14, 12, 9, 14, Blocks.COBBLESTONE.getDefaultState());
        structure.fillWithBlocks(world, start, 12, 12, 8, 12, 13, 8, Blocks.OAK_FENCE.getDefaultState().with(FourWayBlock.WATERLOGGED, false).with(FourWayBlock.NORTH, false).with(FourWayBlock.SOUTH, true).with(FourWayBlock.EAST, false).with(FourWayBlock.WEST, false));
        structure.fillWithBlocks(world, start, 12, 12, 14, 12, 13, 14, Blocks.OAK_FENCE.getDefaultState().with(FourWayBlock.WATERLOGGED, false).with(FourWayBlock.NORTH, true).with(FourWayBlock.SOUTH, false).with(FourWayBlock.EAST, false).with(FourWayBlock.WEST, false));
        structure.fillWithBlocks(world, start, 12, 14, 10, 12, 14, 12, Blocks.OAK_SLAB.getDefaultState().with(SlabBlock.TYPE, SlabType.DOUBLE).with(SlabBlock.WATERLOGGED, false));
        structure.fillWithBlocks(world, start, 12, 19, 10, 12, 19, 12, Blocks.STONE_BRICKS.getDefaultState());
        structure.fillWithBlocks(world, start, 12, 20, 8, 12, 20, 8, Blocks.CRACKED_STONE_BRICKS.getDefaultState());
        structure.fillWithBlocks(world, start, 12, 23, 7, 12, 23, 8, Blocks.DARK_OAK_SLAB.getDefaultState().with(SlabBlock.TYPE, SlabType.TOP).with(SlabBlock.WATERLOGGED, false));
        structure.fillWithBlocks(world, start, 12, 23, 14, 13, 23, 14, Blocks.DARK_OAK_SLAB.getDefaultState().with(SlabBlock.TYPE, SlabType.TOP).with(SlabBlock.WATERLOGGED, false));
        structure.fillWithBlocks(world, start, 12, 24, 8, 13, 24, 14, Blocks.COBBLESTONE.getDefaultState());
        structure.fillWithBlocks(world, start, 13, 0, 1, 14, 0, 1, Blocks.GRASS_BLOCK.getDefaultState().with(SnowyDirtBlock.SNOWY, false));
        structure.fillWithBlocks(world, start, 13, 0, 2, 14, 0, 3, Blocks.DIRT.getDefaultState());
        structure.fillWithBlocks(world, start, 13, 0, 5, 14, 0, 6, Blocks.DIRT.getDefaultState());
        structure.fillWithBlocks(world, start, 13, 0, 16, 14, 0, 17, Blocks.DIRT.getDefaultState());
        structure.fillWithBlocks(world, start, 13, 0, 19, 14, 0, 20, Blocks.DIRT.getDefaultState());
        structure.fillWithBlocks(world, start, 13, 0, 21, 14, 0, 21, Blocks.GRASS_BLOCK.getDefaultState().with(SnowyDirtBlock.SNOWY, false));
        structure.fillWithBlocks(world, start, 13, 3, 3, 14, 3, 3, Blocks.GRASS_BLOCK.getDefaultState().with(SnowyDirtBlock.SNOWY, false));
        structure.fillWithBlocks(world, start, 13, 3, 19, 14, 3, 19, Blocks.GRASS_BLOCK.getDefaultState().with(SnowyDirtBlock.SNOWY, false));
        structure.fillWithBlocks(world, start, 13, 5, 5, 15, 5, 5, Blocks.GRASS_BLOCK.getDefaultState().with(SnowyDirtBlock.SNOWY, false));
        structure.fillWithBlocks(world, start, 13, 5, 17, 13, 5, 18, Blocks.GRASS_BLOCK.getDefaultState().with(SnowyDirtBlock.SNOWY, false));
        structure.fillWithBlocks(world, start, 13, 6, 6, 14, 6, 8, Blocks.GRASS_BLOCK.getDefaultState().with(SnowyDirtBlock.SNOWY, false));
        structure.fillWithBlocks(world, start, 13, 6, 9, 13, 6, 13, Blocks.DIRT.getDefaultState());
        structure.fillWithBlocks(world, start, 13, 6, 14, 14, 6, 16, Blocks.GRASS_BLOCK.getDefaultState().with(SnowyDirtBlock.SNOWY, false));
        structure.fillWithBlocks(world, start, 13, 7, 9, 13, 9, 9, Blocks.STONE_BRICKS.getDefaultState());
        structure.fillWithBlocks(world, start, 13, 7, 10, 13, 19, 10, Blocks.COBBLESTONE.getDefaultState());
        structure.fillWithBlocks(world, start, 13, 7, 11, 14, 8, 11, Blocks.POLISHED_ANDESITE.getDefaultState());
        structure.fillWithBlocks(world, start, 13, 7, 12, 13, 19, 12, Blocks.COBBLESTONE.getDefaultState());
        structure.fillWithBlocks(world, start, 13, 7, 13, 13, 9, 13, Blocks.STONE_BRICKS.getDefaultState());
        structure.fillWithBlocks(world, start, 13, 9, 11, 14, 9, 11, Blocks.POLISHED_ANDESITE.getDefaultState());
        structure.fillWithBlocks(world, start, 13, 10, 11, 13, 11, 11, Blocks.POLISHED_ANDESITE.getDefaultState());
        structure.fillWithBlocks(world, start, 13, 14, 11, 13, 15, 11, Blocks.POLISHED_ANDESITE.getDefaultState());
        structure.fillWithBlocks(world, start, 13, 18, 11, 13, 19, 11, Blocks.POLISHED_ANDESITE.getDefaultState());
        structure.fillWithBlocks(world, start, 13, 23, 8, 13, 23, 8, Blocks.DARK_OAK_SLAB.getDefaultState().with(SlabBlock.TYPE, SlabType.TOP).with(SlabBlock.WATERLOGGED, false));
        structure.fillWithBlocks(world, start, 13, 25, 10, 13, 25, 12, Blocks.DARK_OAK_STAIRS.getDefaultState().with(StairsBlock.FACING, Direction.WEST).with(StairsBlock.WATERLOGGED, false).with(StairsBlock.SHAPE, StairsShape.STRAIGHT).with(StairsBlock.HALF, Half.BOTTOM));
        structure.fillWithBlocks(world, start, 14, 0, 4, 14, 3, 14, Blocks.DIRT.getDefaultState());
        structure.fillWithBlocks(world, start, 14, 0, 18, 15, 0, 20, Blocks.DIRT.getDefaultState());
        structure.fillWithBlocks(world, start, 14, 1, 2, 15, 1, 2, Blocks.GRASS_BLOCK.getDefaultState().with(SnowyDirtBlock.SNOWY, false));
        structure.fillWithBlocks(world, start, 14, 1, 3, 15, 1, 11, Blocks.DIRT.getDefaultState());
        structure.fillWithBlocks(world, start, 14, 1, 15, 17, 1, 18, Blocks.DIRT.getDefaultState());
        structure.fillWithBlocks(world, start, 14, 1, 19, 15, 1, 19, Blocks.DIRT.getDefaultState());
        structure.fillWithBlocks(world, start, 14, 1, 20, 15, 1, 20, Blocks.GRASS_BLOCK.getDefaultState().with(SnowyDirtBlock.SNOWY, false));
        structure.fillWithBlocks(world, start, 14, 4, 4, 15, 4, 4, Blocks.GRASS_BLOCK.getDefaultState().with(SnowyDirtBlock.SNOWY, false));
        structure.fillWithBlocks(world, start, 14, 4, 18, 15, 4, 18, Blocks.GRASS_BLOCK.getDefaultState().with(SnowyDirtBlock.SNOWY, false));
        structure.fillWithBlocks(world, start, 14, 5, 17, 15, 5, 17, Blocks.GRASS_BLOCK.getDefaultState().with(SnowyDirtBlock.SNOWY, false));
        structure.fillWithBlocks(world, start, 14, 6, 9, 14, 6, 9, Blocks.GRASS_BLOCK.getDefaultState().with(SnowyDirtBlock.SNOWY, false));
        structure.fillWithBlocks(world, start, 14, 6, 10, 14, 6, 12, Blocks.DIRT.getDefaultState());
        structure.fillWithBlocks(world, start, 14, 6, 13, 15, 6, 15, Blocks.GRASS_BLOCK.getDefaultState().with(SnowyDirtBlock.SNOWY, false));
        structure.fillWithBlocks(world, start, 14, 8, 10, 14, 9, 10, Blocks.COBBLESTONE.getDefaultState());
        structure.fillWithBlocks(world, start, 14, 8, 12, 14, 9, 12, Blocks.COBBLESTONE.getDefaultState());
        structure.fillWithBlocks(world, start, 14, 12, 12, 14, 13, 12, Blocks.OAK_FENCE.getDefaultState().with(FourWayBlock.WATERLOGGED, false).with(FourWayBlock.NORTH, false).with(FourWayBlock.SOUTH, false).with(FourWayBlock.EAST, false).with(FourWayBlock.WEST, false));
        structure.fillWithBlocks(world, start, 14, 21, 11, 14, 23, 11, Blocks.COBBLESTONE.getDefaultState());
        structure.fillWithBlocks(world, start, 14, 23, 9, 14, 23, 10, Blocks.DARK_OAK_SLAB.getDefaultState().with(SlabBlock.TYPE, SlabType.TOP).with(SlabBlock.WATERLOGGED, false));
        structure.fillWithBlocks(world, start, 14, 24, 8, 14, 24, 8, Blocks.DARK_OAK_SLAB.getDefaultState().with(SlabBlock.TYPE, SlabType.BOTTOM).with(SlabBlock.WATERLOGGED, false));
        structure.fillWithBlocks(world, start, 14, 24, 9, 14, 24, 10, Blocks.COBBLESTONE.getDefaultState());
        structure.fillWithBlocks(world, start, 14, 24, 12, 14, 24, 13, Blocks.COBBLESTONE.getDefaultState());
        structure.fillWithBlocks(world, start, 15, 0, 2, 15, 0, 4, Blocks.DIRT.getDefaultState());
        structure.fillWithBlocks(world, start, 15, 0, 6, 17, 0, 8, Blocks.DIRT.getDefaultState());
        structure.fillWithBlocks(world, start, 15, 0, 9, 15, 0, 14, Blocks.STONE.getDefaultState());
        structure.fillWithBlocks(world, start, 15, 0, 15, 16, 0, 16, Blocks.DIRT.getDefaultState());
        structure.fillWithBlocks(world, start, 15, 1, 12, 15, 1, 13, Blocks.STONE.getDefaultState());
        structure.fillWithBlocks(world, start, 15, 1, 14, 18, 1, 17, Blocks.DIRT.getDefaultState());
        structure.fillWithBlocks(world, start, 15, 5, 6, 15, 5, 6, Blocks.GRASS_BLOCK.getDefaultState().with(SnowyDirtBlock.SNOWY, false));
        structure.fillWithBlocks(world, start, 15, 5, 16, 15, 5, 17, Blocks.GRASS_BLOCK.getDefaultState().with(SnowyDirtBlock.SNOWY, false));
        structure.fillWithBlocks(world, start, 15, 6, 7, 15, 6, 15, Blocks.GRASS_BLOCK.getDefaultState().with(SnowyDirtBlock.SNOWY, false));
        structure.fillWithBlocks(world, start, 15, 24, 9, 15, 24, 13, Blocks.DARK_OAK_SLAB.getDefaultState().with(SlabBlock.TYPE, SlabType.BOTTOM).with(SlabBlock.WATERLOGGED, false));
        structure.fillWithBlocks(world, start, 16, 0, 3, 17, 0, 14, Blocks.DIRT.getDefaultState());
        structure.fillWithBlocks(world, start, 16, 0, 17, 17, 0, 19, Blocks.DIRT.getDefaultState());
        structure.fillWithBlocks(world, start, 16, 1, 3, 17, 1, 3, Blocks.GRASS_BLOCK.getDefaultState().with(SnowyDirtBlock.SNOWY, false));
        structure.fillWithBlocks(world, start, 16, 1, 4, 17, 1, 18, Blocks.DIRT.getDefaultState());
        structure.fillWithBlocks(world, start, 16, 1, 19, 17, 1, 19, Blocks.GRASS_BLOCK.getDefaultState().with(SnowyDirtBlock.SNOWY, false));
        structure.fillWithBlocks(world, start, 16, 3, 4, 16, 3, 4, Blocks.GRASS_BLOCK.getDefaultState().with(SnowyDirtBlock.SNOWY, false));
        structure.fillWithBlocks(world, start, 16, 4, 5, 16, 4, 5, Blocks.GRASS_BLOCK.getDefaultState().with(SnowyDirtBlock.SNOWY, false));
        structure.fillWithBlocks(world, start, 16, 5, 6, 16, 5, 7, Blocks.GRASS_BLOCK.getDefaultState().with(SnowyDirtBlock.SNOWY, false));
        structure.fillWithBlocks(world, start, 16, 5, 8, 16, 5, 14, Blocks.DIRT.getDefaultState());
        structure.fillWithBlocks(world, start, 16, 5, 15, 16, 5, 16, Blocks.GRASS_BLOCK.getDefaultState().with(SnowyDirtBlock.SNOWY, false));
        structure.fillWithBlocks(world, start, 16, 6, 8, 16, 6, 14, Blocks.GRASS_BLOCK.getDefaultState().with(SnowyDirtBlock.SNOWY, false));
        structure.fillWithBlocks(world, start, 17, 0, 16, 18, 0, 18, Blocks.DIRT.getDefaultState());
        structure.fillWithBlocks(world, start, 17, 2, 4, 17, 2, 4, Blocks.GRASS_BLOCK.getDefaultState().with(SnowyDirtBlock.SNOWY, false));
        structure.fillWithBlocks(world, start, 17, 3, 5, 17, 3, 5, Blocks.GRASS_BLOCK.getDefaultState().with(SnowyDirtBlock.SNOWY, false));
        structure.fillWithBlocks(world, start, 17, 3, 6, 17, 3, 16, Blocks.DIRT.getDefaultState());
        structure.fillWithBlocks(world, start, 17, 4, 6, 17, 4, 6, Blocks.GRASS_BLOCK.getDefaultState().with(SnowyDirtBlock.SNOWY, false));
        structure.fillWithBlocks(world, start, 17, 4, 7, 17, 4, 15, Blocks.DIRT.getDefaultState());
        structure.fillWithBlocks(world, start, 17, 5, 7, 17, 5, 9, Blocks.GRASS_BLOCK.getDefaultState().with(SnowyDirtBlock.SNOWY, false));
        structure.fillWithBlocks(world, start, 17, 5, 10, 17, 5, 12, Blocks.DIRT.getDefaultState());
        structure.fillWithBlocks(world, start, 17, 5, 13, 17, 5, 15, Blocks.GRASS_BLOCK.getDefaultState().with(SnowyDirtBlock.SNOWY, false));
        structure.fillWithBlocks(world, start, 17, 6, 10, 17, 6, 12, Blocks.GRASS_BLOCK.getDefaultState().with(SnowyDirtBlock.SNOWY, false));
        structure.fillWithBlocks(world, start, 18, 0, 3, 18, 0, 3, Blocks.GRASS_BLOCK.getDefaultState().with(SnowyDirtBlock.SNOWY, false));
        structure.fillWithBlocks(world, start, 18, 0, 4, 18, 0, 18, Blocks.DIRT.getDefaultState());
        structure.fillWithBlocks(world, start, 18, 1, 4, 18, 1, 4, Blocks.GRASS_BLOCK.getDefaultState().with(SnowyDirtBlock.SNOWY, false));
        structure.fillWithBlocks(world, start, 18, 1, 5, 18, 1, 17, Blocks.DIRT.getDefaultState());
        structure.fillWithBlocks(world, start, 18, 2, 6, 18, 2, 16, Blocks.DIRT.getDefaultState());
        structure.fillWithBlocks(world, start, 18, 3, 7, 18, 3, 15, Blocks.DIRT.getDefaultState());
        structure.fillWithBlocks(world, start, 18, 4, 7, 18, 4, 8, Blocks.GRASS_BLOCK.getDefaultState().with(SnowyDirtBlock.SNOWY, false));
        structure.fillWithBlocks(world, start, 18, 4, 9, 18, 4, 13, Blocks.DIRT.getDefaultState());
        structure.fillWithBlocks(world, start, 18, 4, 14, 18, 4, 15, Blocks.GRASS_BLOCK.getDefaultState().with(SnowyDirtBlock.SNOWY, false));
        structure.fillWithBlocks(world, start, 18, 5, 9, 18, 5, 13, Blocks.GRASS_BLOCK.getDefaultState().with(SnowyDirtBlock.SNOWY, false));
        structure.fillWithBlocks(world, start, 19, 0, 5, 19, 0, 17, Blocks.DIRT.getDefaultState());
        structure.fillWithBlocks(world, start, 19, 1, 5, 19, 1, 6, Blocks.GRASS_BLOCK.getDefaultState().with(SnowyDirtBlock.SNOWY, false));
        structure.fillWithBlocks(world, start, 19, 1, 7, 19, 1, 15, Blocks.DIRT.getDefaultState());
        structure.fillWithBlocks(world, start, 19, 1, 16, 19, 1, 17, Blocks.GRASS_BLOCK.getDefaultState().with(SnowyDirtBlock.SNOWY, false));
        structure.fillWithBlocks(world, start, 19, 2, 8, 19, 2, 14, Blocks.DIRT.getDefaultState());
        structure.fillWithBlocks(world, start, 19, 3, 8, 19, 3, 9, Blocks.GRASS_BLOCK.getDefaultState().with(SnowyDirtBlock.SNOWY, false));
        structure.fillWithBlocks(world, start, 19, 3, 10, 19, 3, 12, Blocks.DIRT.getDefaultState());
        structure.fillWithBlocks(world, start, 19, 3, 13, 19, 3, 14, Blocks.GRASS_BLOCK.getDefaultState().with(SnowyDirtBlock.SNOWY, false));
        structure.fillWithBlocks(world, start, 19, 4, 10, 19, 4, 12, Blocks.GRASS_BLOCK.getDefaultState().with(SnowyDirtBlock.SNOWY, false));
        structure.fillWithBlocks(world, start, 20, 0, 7, 20, 0, 15, Blocks.DIRT.getDefaultState());
        structure.fillWithBlocks(world, start, 20, 1, 7, 20, 1, 8, Blocks.GRASS_BLOCK.getDefaultState().with(SnowyDirtBlock.SNOWY, false));
        structure.fillWithBlocks(world, start, 20, 1, 9, 20, 1, 13, Blocks.DIRT.getDefaultState());
        structure.fillWithBlocks(world, start, 20, 1, 14, 20, 1, 15, Blocks.GRASS_BLOCK.getDefaultState().with(SnowyDirtBlock.SNOWY, false));
        structure.fillWithBlocks(world, start, 20, 2, 9, 20, 2, 13, Blocks.GRASS_BLOCK.getDefaultState().with(SnowyDirtBlock.SNOWY, false));
        structure.fillWithBlocks(world, start, 21, 0, 8, 21, 0, 9, Blocks.GRASS_BLOCK.getDefaultState().with(SnowyDirtBlock.SNOWY, false));
        structure.fillWithBlocks(world, start, 21, 0, 10, 21, 0, 12, Blocks.DIRT.getDefaultState());
        structure.fillWithBlocks(world, start, 21, 0, 13, 21, 0, 14, Blocks.GRASS_BLOCK.getDefaultState().with(SnowyDirtBlock.SNOWY, false));
        structure.fillWithBlocks(world, start, 21, 1, 10, 21, 1, 12, Blocks.GRASS_BLOCK.getDefaultState().with(SnowyDirtBlock.SNOWY, false));

    }
    
}
