package mod.arcalitegames.odyssey.world.structure.structures.dungeons.ziggurat;

import mod.arcalitegames.odyssey.world.structure.StructureBase;
import net.minecraft.block.BarrelBlock;
import net.minecraft.block.Blocks;
import net.minecraft.block.FourWayBlock;
import net.minecraft.block.SlabBlock;
import net.minecraft.block.StairsBlock;
import net.minecraft.state.properties.Half;
import net.minecraft.state.properties.SlabType;
import net.minecraft.state.properties.StairsShape;
import net.minecraft.util.Direction;
import net.minecraft.util.math.BlockPos;
import net.minecraft.world.World;

public class ZigguratComponent2
{
	public static BlockPos start;
    public static World world;
    public static StructureBase structure;

    public static void init(World worldIn, BlockPos blockPos, StructureBase structureIn)
    {
        world = worldIn; start = blockPos; structure = structureIn;
    }
    
    public static void generatePart21()
    {
        structure.fillWithBlocks(world, start, 76, -39, 34, 76, -34, 34, Blocks.SANDSTONE.getDefaultState());
        structure.fillWithBlocks(world, start, 76, -39, 35, 76, -38, 36, Blocks.STONE_BRICKS.getDefaultState());
        structure.fillWithBlocks(world, start, 76, -39, 40, 76, -38, 41, Blocks.STONE_BRICKS.getDefaultState());
        structure.fillWithBlocks(world, start, 76, -39, 42, 76, -34, 42, Blocks.SANDSTONE.getDefaultState());
        structure.fillWithBlocks(world, start, 76, -39, 43, 77, -39, 45, Blocks.STONE_BRICKS.getDefaultState());
        structure.fillWithBlocks(world, start, 76, -39, 49, 76, -39, 50, Blocks.AIR.getDefaultState());
        structure.fillWithBlocks(world, start, 76, -39, 51, 77, -39, 52, Blocks.STONE_BRICKS.getDefaultState());
        structure.fillWithBlocks(world, start, 76, -39, 64, 76, -38, 65, Blocks.STONE_BRICKS.getDefaultState());
        structure.fillWithBlocks(world, start, 76, -39, 67, 77, -39, 70, Blocks.STONE_BRICKS.getDefaultState());
        structure.fillWithBlocks(world, start, 76, -39, 73, 77, -39, 74, Blocks.STONE_BRICKS.getDefaultState());
        structure.fillWithBlocks(world, start, 76, -39, 76, 77, -39, 79, Blocks.STONE_BRICKS.getDefaultState());
        structure.fillWithBlocks(world, start, 76, -38, 0, 78, -38, 3, Blocks.STONE_BRICKS.getDefaultState());
        structure.fillWithBlocks(world, start, 76, -38, 4, 76, -37, 5, Blocks.STONE_BRICKS.getDefaultState());
        structure.fillWithBlocks(world, start, 76, -38, 43, 77, -38, 45, Blocks.STONE_BRICKS.getDefaultState());
        structure.fillWithBlocks(world, start, 76, -38, 49, 77, -38, 51, Blocks.STONE_BRICKS.getDefaultState());
        structure.fillWithBlocks(world, start, 76, -38, 52, 76, -38, 59, Blocks.STONE_BRICKS.getDefaultState());
        structure.fillWithBlocks(world, start, 76, -38, 61, 76, -35, 64, Blocks.STONE_BRICKS.getDefaultState());
        structure.fillWithBlocks(world, start, 76, -38, 66, 77, -37, 66, Blocks.STONE_BRICKS.getDefaultState());
        structure.fillWithBlocks(world, start, 76, -38, 67, 77, -38, 67, Blocks.AIR.getDefaultState());
        structure.fillWithBlocks(world, start, 76, -38, 68, 76, -38, 72, Blocks.STONE_BRICKS.getDefaultState());
        structure.fillWithBlocks(world, start, 76, -38, 76, 77, -38, 78, Blocks.STONE_BRICKS.getDefaultState());
        structure.fillWithBlocks(world, start, 76, -38, 79, 76, -38, 79, Blocks.AIR.getDefaultState());
        structure.fillWithBlocks(world, start, 76, -38, 80, 76, -36, 82, Blocks.STONE_BRICKS.getDefaultState());
        structure.fillWithBlocks(world, start, 76, -38, 84, 76, -35, 87, Blocks.STONE_BRICKS.getDefaultState());
        structure.fillWithBlocks(world, start, 76, -38, 88, 78, -38, 90, Blocks.STONE_BRICKS.getDefaultState());
        structure.fillWithBlocks(world, start, 76, -37, 0, 76, -37, 0, Blocks.STONE_BRICKS.getDefaultState());
        structure.fillWithBlocks(world, start, 76, -37, 1, 76, -37, 1, Blocks.AIR.getDefaultState());
        structure.fillWithBlocks(world, start, 76, -37, 2, 76, -37, 5, Blocks.STONE_BRICKS.getDefaultState());
        structure.fillWithBlocks(world, start, 76, -37, 6, 76, -37, 7, Blocks.AIR.getDefaultState());
        structure.fillWithBlocks(world, start, 76, -37, 8, 76, -37, 13, Blocks.STONE_BRICKS.getDefaultState());
        structure.fillWithBlocks(world, start, 76, -37, 35, 76, -36, 36, Blocks.STONE_BRICKS.getDefaultState());
        structure.fillWithBlocks(world, start, 76, -37, 40, 76, -36, 41, Blocks.STONE_BRICKS.getDefaultState());
        structure.fillWithBlocks(world, start, 76, -37, 43, 77, -36, 43, Blocks.STONE_BRICKS.getDefaultState());
        structure.fillWithBlocks(world, start, 76, -37, 44, 77, -37, 44, Blocks.AIR.getDefaultState());
        structure.fillWithBlocks(world, start, 76, -37, 49, 77, -37, 53, Blocks.STONE_BRICKS.getDefaultState());
        structure.fillWithBlocks(world, start, 76, -37, 55, 77, -37, 57, Blocks.STONE_BRICKS.getDefaultState());
        structure.fillWithBlocks(world, start, 76, -37, 58, 76, -34, 64, Blocks.STONE_BRICKS.getDefaultState());
        structure.fillWithBlocks(world, start, 76, -37, 67, 76, -37, 67, Blocks.STONE_BRICKS.getDefaultState());
        structure.fillWithBlocks(world, start, 76, -37, 69, 77, -37, 72, Blocks.STONE_BRICKS.getDefaultState());
        structure.fillWithBlocks(world, start, 76, -37, 83, 76, -33, 87, Blocks.STONE_BRICKS.getDefaultState());
        structure.fillWithBlocks(world, start, 76, -36, 0, 78, -36, 2, Blocks.STONE_BRICKS.getDefaultState());
        structure.fillWithBlocks(world, start, 76, -36, 3, 77, -36, 4, Blocks.STONE_BRICKS.getDefaultState());
        structure.fillWithBlocks(world, start, 76, -36, 6, 77, -36, 7, Blocks.STONE_BRICKS.getDefaultState());
        structure.fillWithBlocks(world, start, 76, -36, 50, 77, -36, 51, Blocks.STONE_BRICKS.getDefaultState());
        structure.fillWithBlocks(world, start, 76, -36, 65, 77, -36, 67, Blocks.STONE_BRICKS.getDefaultState());
        structure.fillWithBlocks(world, start, 76, -36, 68, 76, -36, 74, Blocks.STONE_BRICKS.getDefaultState());
        structure.fillWithBlocks(world, start, 76, -36, 76, 78, -34, 76, Blocks.STONE_BRICKS.getDefaultState());
        structure.fillWithBlocks(world, start, 76, -36, 77, 77, -36, 77, Blocks.AIR.getDefaultState());
        structure.fillWithBlocks(world, start, 76, -36, 78, 77, -36, 79, Blocks.STONE_BRICKS.getDefaultState());
        structure.fillWithBlocks(world, start, 76, -35, 0, 77, -35, 3, Blocks.STONE_BRICKS.getDefaultState());
        structure.fillWithBlocks(world, start, 76, -35, 4, 78, -35, 4, Blocks.AIR.getDefaultState());
        structure.fillWithBlocks(world, start, 76, -35, 5, 77, -35, 7, Blocks.STONE_BRICKS.getDefaultState());
        structure.fillWithBlocks(world, start, 76, -35, 8, 76, -34, 9, Blocks.STONE_BRICKS.getDefaultState());
        structure.fillWithBlocks(world, start, 76, -35, 12, 76, -35, 13, Blocks.STONE_BRICKS.getDefaultState());
        structure.fillWithBlocks(world, start, 76, -35, 19, 77, -35, 20, Blocks.STONE_BRICKS.getDefaultState());
        structure.fillWithBlocks(world, start, 76, -35, 31, 76, -35, 31, Blocks.STONE_BRICKS.getDefaultState());
        structure.fillWithBlocks(world, start, 76, -35, 32, 76, -34, 32, Blocks.AIR.getDefaultState());
        structure.fillWithBlocks(world, start, 76, -35, 33, 77, -34, 33, Blocks.STONE_BRICKS.getDefaultState());
        structure.fillWithBlocks(world, start, 76, -35, 35, 76, -34, 42, Blocks.SANDSTONE.getDefaultState());
        structure.fillWithBlocks(world, start, 76, -35, 43, 79, -32, 43, Blocks.STONE_BRICKS.getDefaultState());
        structure.fillWithBlocks(world, start, 76, -35, 44, 78, -35, 44, Blocks.AIR.getDefaultState());
        structure.fillWithBlocks(world, start, 76, -35, 45, 77, -34, 45, Blocks.STONE_BRICKS.getDefaultState());
        structure.fillWithBlocks(world, start, 76, -35, 49, 76, -35, 49, Blocks.STONE_BRICKS.getDefaultState());
        structure.fillWithBlocks(world, start, 76, -35, 50, 76, -35, 51, Blocks.AIR.getDefaultState());
        structure.fillWithBlocks(world, start, 76, -35, 52, 76, -35, 53, Blocks.STONE_BRICKS.getDefaultState());
        structure.fillWithBlocks(world, start, 76, -35, 55, 76, -35, 55, Blocks.STONE_BRICKS.getDefaultState());
        structure.fillWithBlocks(world, start, 76, -35, 67, 78, -35, 69, Blocks.STONE_BRICKS.getDefaultState());
        structure.fillWithBlocks(world, start, 76, -35, 71, 77, -35, 72, Blocks.STONE_BRICKS.getDefaultState());
        structure.fillWithBlocks(world, start, 76, -35, 77, 78, -35, 79, Blocks.STONE_BRICKS.getDefaultState());
        structure.fillWithBlocks(world, start, 76, -35, 80, 76, -34, 87, Blocks.STONE_BRICKS.getDefaultState());
        structure.fillWithBlocks(world, start, 76, -35, 89, 77, -35, 90, Blocks.STONE_BRICKS.getDefaultState());
        structure.fillWithBlocks(world, start, 76, -34, 1, 76, -33, 11, Blocks.STONE_BRICKS.getDefaultState());
        structure.fillWithBlocks(world, start, 76, -34, 31, 89, -32, 31, Blocks.STONE_BRICKS.getDefaultState());
        structure.fillWithBlocks(world, start, 76, -34, 44, 77, -34, 45, Blocks.STONE_BRICKS.getDefaultState());
        structure.fillWithBlocks(world, start, 76, -34, 49, 76, -34, 53, Blocks.STONE_BRICKS.getDefaultState());
        structure.fillWithBlocks(world, start, 76, -34, 55, 77, -34, 69, Blocks.STONE_BRICKS.getDefaultState());
        structure.fillWithBlocks(world, start, 76, -34, 77, 78, -34, 90, Blocks.STONE_BRICKS.getDefaultState());
        structure.fillWithBlocks(world, start, 76, -33, 0, 78, -33, 4, Blocks.STONE_BRICKS.getDefaultState());
        structure.fillWithBlocks(world, start, 76, -33, 12, 76, -33, 13, Blocks.AIR.getDefaultState());
        structure.fillWithBlocks(world, start, 76, -33, 14, 77, -33, 17, Blocks.STONE_BRICKS.getDefaultState());
        structure.fillWithBlocks(world, start, 76, -33, 32, 77, -33, 33, Blocks.STONE_BRICKS.getDefaultState());
        structure.fillWithBlocks(world, start, 76, -33, 35, 76, -33, 45, Blocks.STONE_BRICKS.getDefaultState());
        structure.fillWithBlocks(world, start, 76, -33, 51, 79, -33, 54, Blocks.STONE_BRICKS.getDefaultState());
        structure.fillWithBlocks(world, start, 76, -33, 56, 78, -33, 58, Blocks.STONE_BRICKS.getDefaultState());
        structure.fillWithBlocks(world, start, 76, -33, 82, 76, -33, 82, Blocks.AIR.getDefaultState());
        structure.fillWithBlocks(world, start, 76, -32, 0, 80, -31, 0, Blocks.STONE_BRICKS.getDefaultState());
        structure.fillWithBlocks(world, start, 76, -32, 1, 76, -32, 2, Blocks.AIR.getDefaultState());
        structure.fillWithBlocks(world, start, 76, -32, 10, 76, -32, 11, Blocks.STONE_BRICKS.getDefaultState());
        structure.fillWithBlocks(world, start, 76, -32, 13, 77, -32, 15, Blocks.STONE_BRICKS.getDefaultState());
        structure.fillWithBlocks(world, start, 76, -32, 20, 90, -31, 20, Blocks.STONE_BRICKS.getDefaultState());
        structure.fillWithBlocks(world, start, 76, -32, 38, 77, -32, 38, Blocks.AIR.getDefaultState());
        structure.fillWithBlocks(world, start, 76, -32, 40, 76, -32, 45, Blocks.STONE_BRICKS.getDefaultState());
        structure.fillWithBlocks(world, start, 76, -32, 53, 79, -32, 56, Blocks.STONE_BRICKS.getDefaultState());
        structure.fillWithBlocks(world, start, 76, -32, 68, 77, -32, 69, Blocks.STONE_BRICKS.getDefaultState());
        structure.fillWithBlocks(world, start, 76, -32, 76, 76, -32, 76, Blocks.STONE_BRICKS.getDefaultState());
        structure.fillWithBlocks(world, start, 76, -32, 78, 76, -32, 78, Blocks.STONE_BRICKS.getDefaultState());
        structure.fillWithBlocks(world, start, 76, -32, 79, 76, -32, 80, Blocks.AIR.getDefaultState());
        structure.fillWithBlocks(world, start, 76, -32, 81, 77, -32, 82, Blocks.STONE_BRICKS.getDefaultState());
        structure.fillWithBlocks(world, start, 76, -32, 83, 76, -32, 83, Blocks.AIR.getDefaultState());
        structure.fillWithBlocks(world, start, 76, -31, 10, 76, -31, 11, Blocks.AIR.getDefaultState());
        structure.fillWithBlocks(world, start, 76, -31, 12, 76, -31, 14, Blocks.STONE_BRICKS.getDefaultState());
        structure.fillWithBlocks(world, start, 76, -31, 31, 76, -31, 31, Blocks.STONE_BRICKS.getDefaultState());
        structure.fillWithBlocks(world, start, 76, -31, 33, 77, -31, 34, Blocks.STONE_BRICKS.getDefaultState());
        structure.fillWithBlocks(world, start, 76, -31, 35, 76, -31, 38, Blocks.STONE_BRICKS.getDefaultState());
        structure.fillWithBlocks(world, start, 76, -31, 39, 76, -31, 39, Blocks.SANDSTONE.getDefaultState());
        structure.fillWithBlocks(world, start, 76, -31, 43, 76, -31, 43, Blocks.STONE_BRICKS.getDefaultState());
        structure.fillWithBlocks(world, start, 76, -31, 45, 87, -31, 45, Blocks.STONE_BRICKS.getDefaultState());
        structure.fillWithBlocks(world, start, 76, -31, 48, 80, -31, 52, Blocks.STONE_BRICKS.getDefaultState());
        structure.fillWithBlocks(world, start, 76, -31, 61, 76, -30, 61, Blocks.AIR.getDefaultState());
        structure.fillWithBlocks(world, start, 76, -31, 62, 76, -31, 72, Blocks.STONE_BRICKS.getDefaultState());
        structure.fillWithBlocks(world, start, 76, -31, 76, 79, -31, 79, Blocks.STONE_BRICKS.getDefaultState());
        structure.fillWithBlocks(world, start, 76, -30, -5, 76, -30, -4, Blocks.STONE_BRICKS.getDefaultState());
        structure.fillWithBlocks(world, start, 76, -30, -3, 78, -30, 41, Blocks.SANDSTONE.getDefaultState());
        structure.fillWithBlocks(world, start, 76, -30, 42, 76, -30, 46, Blocks.SANDSTONE.getDefaultState());
        structure.fillWithBlocks(world, start, 76, -30, 48, 77, -30, 48, Blocks.AIR.getDefaultState());
        structure.fillWithBlocks(world, start, 76, -30, 49, 77, -30, 50, Blocks.SANDSTONE.getDefaultState());
        structure.fillWithBlocks(world, start, 76, -30, 63, 76, -30, 64, Blocks.SANDSTONE.getDefaultState());
        structure.fillWithBlocks(world, start, 76, -29, -4, 78, -29, -4, Blocks.SANDSTONE.getDefaultState());
        structure.fillWithBlocks(world, start, 76, -29, -2, 76, -29, 33, Blocks.AIR.getDefaultState());
        structure.fillWithBlocks(world, start, 76, -29, 34, 76, -27, 34, Blocks.IRON_BARS.getDefaultState().with(FourWayBlock.WATERLOGGED, false).with(FourWayBlock.NORTH, true).with(FourWayBlock.SOUTH, true).with(FourWayBlock.EAST, true).with(FourWayBlock.WEST, true));
        structure.fillWithBlocks(world, start, 76, -29, 48, 77, -29, 49, Blocks.SANDSTONE.getDefaultState());
        structure.fillWithBlocks(world, start, 76, -29, 50, 76, -29, 51, Blocks.SANDSTONE.getDefaultState());
        structure.fillWithBlocks(world, start, 76, -29, 59, 76, -27, 61, Blocks.SANDSTONE.getDefaultState());
        structure.fillWithBlocks(world, start, 76, -29, 64, 77, -29, 65, Blocks.SANDSTONE.getDefaultState());
        structure.fillWithBlocks(world, start, 76, -28, -6, 76, -28, -5, Blocks.STONE_BRICKS.getDefaultState());
        structure.fillWithBlocks(world, start, 76, -28, -4, 76, -25, -4, Blocks.SANDSTONE.getDefaultState());
        structure.fillWithBlocks(world, start, 76, -28, -2, 78, -28, 33, Blocks.AIR.getDefaultState());
        structure.fillWithBlocks(world, start, 76, -28, 40, 77, -28, 41, Blocks.AIR.getDefaultState());
        structure.fillWithBlocks(world, start, 76, -28, 44, 77, -28, 45, Blocks.SANDSTONE.getDefaultState());
        structure.fillWithBlocks(world, start, 76, -28, 48, 76, -27, 49, Blocks.SANDSTONE.getDefaultState());
        structure.fillWithBlocks(world, start, 76, -28, 51, 76, -23, 51, Blocks.SANDSTONE.getDefaultState());
        structure.fillWithBlocks(world, start, 76, -28, 63, 77, -28, 65, Blocks.SANDSTONE.getDefaultState());
        structure.fillWithBlocks(world, start, 76, -27, -6, 76, -26, -5, Blocks.STONE_BRICKS.getDefaultState());
        structure.fillWithBlocks(world, start, 76, -27, -2, 78, -27, 33, Blocks.AIR.getDefaultState());
        structure.fillWithBlocks(world, start, 76, -27, 39, 78, -27, 41, Blocks.AIR.getDefaultState());
        structure.fillWithBlocks(world, start, 76, -27, 42, 78, -27, 44, Blocks.SANDSTONE.getDefaultState());
        structure.fillWithBlocks(world, start, 76, -27, 47, 77, -27, 48, Blocks.SANDSTONE.getDefaultState());
        structure.fillWithBlocks(world, start, 76, -27, 62, 77, -27, 65, Blocks.SANDSTONE.getDefaultState());
        structure.fillWithBlocks(world, start, 76, -26, -3, 78, -26, -3, Blocks.SANDSTONE.getDefaultState());
        structure.fillWithBlocks(world, start, 76, -26, -2, 78, -26, 10, Blocks.AIR.getDefaultState());
        structure.fillWithBlocks(world, start, 76, -26, 11, 79, -26, 14, Blocks.SANDSTONE.getDefaultState());
        structure.fillWithBlocks(world, start, 76, -26, 15, 78, -26, 18, Blocks.SANDSTONE.getDefaultState());
        structure.fillWithBlocks(world, start, 76, -26, 19, 78, -26, 23, Blocks.AIR.getDefaultState());
        structure.fillWithBlocks(world, start, 76, -26, 24, 79, -26, 34, Blocks.SANDSTONE.getDefaultState());
        structure.fillWithBlocks(world, start, 76, -26, 42, 76, -24, 44, Blocks.SANDSTONE.getDefaultState());
        structure.fillWithBlocks(world, start, 76, -26, 45, 76, -26, 51, Blocks.SANDSTONE.getDefaultState());
        structure.fillWithBlocks(world, start, 76, -26, 59, 76, -25, 63, Blocks.SANDSTONE.getDefaultState());
        structure.fillWithBlocks(world, start, 76, -26, 64, 76, -25, 64, Blocks.AIR.getDefaultState());
        structure.fillWithBlocks(world, start, 76, -25, -6, 77, -24, -6, Blocks.STONE_BRICKS.getDefaultState());
        structure.fillWithBlocks(world, start, 76, -25, -5, 76, -25, -4, Blocks.SANDSTONE.getDefaultState());
        structure.fillWithBlocks(world, start, 76, -25, -3, 77, -25, -3, Blocks.STONE_BRICKS.getDefaultState());
        structure.fillWithBlocks(world, start, 76, -25, -2, 79, -25, -2, Blocks.SANDSTONE.getDefaultState());
        structure.fillWithBlocks(world, start, 76, -25, -1, 78, -25, 9, Blocks.AIR.getDefaultState());
        structure.fillWithBlocks(world, start, 76, -25, 10, 79, -25, 13, Blocks.SANDSTONE.getDefaultState());
        structure.fillWithBlocks(world, start, 76, -25, 17, 76, -24, 17, Blocks.DIRT.getDefaultState());
        structure.fillWithBlocks(world, start, 76, -25, 18, 76, -25, 25, Blocks.SANDSTONE.getDefaultState());
        structure.fillWithBlocks(world, start, 76, -25, 45, 76, -25, 46, Blocks.DIRT.getDefaultState());
        structure.fillWithBlocks(world, start, 76, -25, 47, 76, -25, 49, Blocks.SANDSTONE.getDefaultState());
        structure.fillWithBlocks(world, start, 76, -25, 50, 77, -25, 50, Blocks.AIR.getDefaultState());
        structure.fillWithBlocks(world, start, 76, -24, -4, 76, -24, -2, Blocks.STONE_BRICKS.getDefaultState());
        structure.fillWithBlocks(world, start, 76, -24, 8, 76, -24, 11, Blocks.SANDSTONE.getDefaultState());
        structure.fillWithBlocks(world, start, 76, -24, 12, 76, -23, 12, Blocks.AIR.getDefaultState());
        structure.fillWithBlocks(world, start, 76, -24, 13, 77, -24, 14, Blocks.SANDSTONE.getDefaultState());
        structure.fillWithBlocks(world, start, 76, -24, 22, 76, -23, 23, Blocks.SANDSTONE.getDefaultState());
        structure.fillWithBlocks(world, start, 76, -24, 25, 80, -22, 25, Blocks.SANDSTONE.getDefaultState());
        structure.fillWithBlocks(world, start, 76, -24, 32, 78, -24, 34, Blocks.SANDSTONE.getDefaultState());
        structure.fillWithBlocks(world, start, 76, -24, 40, 77, -24, 41, Blocks.AIR.getDefaultState());
        structure.fillWithBlocks(world, start, 76, -24, 45, 76, -24, 59, Blocks.SANDSTONE.getDefaultState());
        structure.fillWithBlocks(world, start, 76, -24, 61, 76, -22, 63, Blocks.SANDSTONE.getDefaultState());
        structure.fillWithBlocks(world, start, 76, -23, -6, 76, -23, -5, Blocks.DIRT.getDefaultState());
        structure.fillWithBlocks(world, start, 76, -23, -3, 78, -23, -3, Blocks.SANDSTONE.getDefaultState());
        structure.fillWithBlocks(world, start, 76, -23, -1, 78, -22, -1, Blocks.STONE_BRICKS.getDefaultState());
        structure.fillWithBlocks(world, start, 76, -23, 0, 78, -23, 4, Blocks.SANDSTONE.getDefaultState());
        structure.fillWithBlocks(world, start, 76, -23, 5, 76, -23, 6, Blocks.AIR.getDefaultState());
        structure.fillWithBlocks(world, start, 76, -23, 8, 76, -22, 8, Blocks.STONE_BRICKS.getDefaultState());
        structure.fillWithBlocks(world, start, 76, -23, 9, 77, -23, 11, Blocks.SANDSTONE.getDefaultState());
        structure.fillWithBlocks(world, start, 76, -23, 13, 76, -23, 14, Blocks.SANDSTONE.getDefaultState());
        structure.fillWithBlocks(world, start, 76, -23, 17, 76, -22, 18, Blocks.SANDSTONE.getDefaultState());
        structure.fillWithBlocks(world, start, 76, -23, 24, 76, -23, 25, Blocks.SANDSTONE.getDefaultState());
        structure.fillWithBlocks(world, start, 76, -23, 39, 78, -23, 41, Blocks.AIR.getDefaultState());
        structure.fillWithBlocks(world, start, 76, -23, 46, 77, -23, 47, Blocks.SANDSTONE.getDefaultState());
        structure.fillWithBlocks(world, start, 76, -23, 48, 76, -21, 50, Blocks.SANDSTONE.getDefaultState());
        structure.fillWithBlocks(world, start, 76, -23, 52, 76, -23, 52, Blocks.SANDSTONE.getDefaultState());
        structure.fillWithBlocks(world, start, 76, -23, 54, 77, -22, 54, Blocks.SANDSTONE.getDefaultState());
        structure.fillWithBlocks(world, start, 76, -23, 55, 77, -23, 55, Blocks.AIR.getDefaultState());
        structure.fillWithBlocks(world, start, 76, -23, 56, 76, -22, 56, Blocks.DIRT.getDefaultState());
        structure.fillWithBlocks(world, start, 76, -23, 57, 77, -23, 58, Blocks.SANDSTONE.getDefaultState());
        structure.fillWithBlocks(world, start, 76, -23, 59, 77, -23, 59, Blocks.DIRT.getDefaultState());
        structure.fillWithBlocks(world, start, 76, -23, 60, 76, -23, 65, Blocks.SANDSTONE.getDefaultState());
        structure.fillWithBlocks(world, start, 76, -22, -4, 76, -22, 0, Blocks.STONE_BRICKS.getDefaultState());
        structure.fillWithBlocks(world, start, 76, -22, 2, 76, -21, 4, Blocks.STONE_BRICKS.getDefaultState());
        structure.fillWithBlocks(world, start, 76, -22, 9, 76, -21, 10, Blocks.SANDSTONE.getDefaultState());
        structure.fillWithBlocks(world, start, 76, -22, 12, 77, -22, 14, Blocks.SANDSTONE.getDefaultState());
        structure.fillWithBlocks(world, start, 76, -22, 19, 76, -21, 19, Blocks.AIR.getDefaultState());
        structure.fillWithBlocks(world, start, 76, -22, 21, 77, -22, 25, Blocks.SANDSTONE.getDefaultState());
        structure.fillWithBlocks(world, start, 76, -22, 32, 77, -22, 33, Blocks.SANDSTONE.getDefaultState());
        structure.fillWithBlocks(world, start, 76, -22, 44, 76, -22, 45, Blocks.AIR.getDefaultState());
        structure.fillWithBlocks(world, start, 76, -22, 47, 76, -22, 50, Blocks.SANDSTONE.getDefaultState());
        structure.fillWithBlocks(world, start, 76, -22, 51, 76, -21, 51, Blocks.DIRT.getDefaultState());
        structure.fillWithBlocks(world, start, 76, -22, 52, 78, -22, 54, Blocks.SANDSTONE.getDefaultState());
        structure.fillWithBlocks(world, start, 76, -22, 55, 76, -20, 55, Blocks.SANDSTONE.getDefaultState());
        structure.fillWithBlocks(world, start, 76, -22, 57, 76, -22, 63, Blocks.SANDSTONE.getDefaultState());
        structure.fillWithBlocks(world, start, 76, -22, 64, 76, -22, 65, Blocks.AIR.getDefaultState());
        structure.fillWithBlocks(world, start, 76, -21, -3, 77, -21, -2, Blocks.STONE_BRICKS.getDefaultState());
        structure.fillWithBlocks(world, start, 76, -21, -1, 76, -21, -1, Blocks.STONE_BRICKS.getDefaultState());
        structure.fillWithBlocks(world, start, 76, -21, 1, 77, -21, 4, Blocks.STONE_BRICKS.getDefaultState());
        structure.fillWithBlocks(world, start, 76, -21, 5, 76, -21, 5, Blocks.SANDSTONE.getDefaultState());
        structure.fillWithBlocks(world, start, 76, -21, 7, 76, -21, 7, Blocks.DIRT.getDefaultState());
        structure.fillWithBlocks(world, start, 76, -21, 8, 76, -21, 14, Blocks.SANDSTONE.getDefaultState());
        structure.fillWithBlocks(world, start, 76, -21, 17, 76, -21, 18, Blocks.SANDSTONE.getDefaultState());
        structure.fillWithBlocks(world, start, 76, -21, 20, 77, -21, 21, Blocks.SANDSTONE.getDefaultState());
        structure.fillWithBlocks(world, start, 76, -21, 22, 76, -21, 24, Blocks.SANDSTONE.getDefaultState());
        structure.fillWithBlocks(world, start, 76, -21, 42, 76, -20, 50, Blocks.SANDSTONE.getDefaultState());
        structure.fillWithBlocks(world, start, 76, -21, 53, 78, -21, 57, Blocks.SANDSTONE.getDefaultState());
        structure.fillWithBlocks(world, start, 76, -21, 59, 78, -21, 62, Blocks.SANDSTONE.getDefaultState());
        structure.fillWithBlocks(world, start, 76, -21, 63, 76, -20, 65, Blocks.SANDSTONE.getDefaultState());
        structure.fillWithBlocks(world, start, 76, -20, 15, 76, -20, 15, Blocks.SANDSTONE.getDefaultState());
        structure.fillWithBlocks(world, start, 76, -20, 17, 80, -20, 17, Blocks.OAK_PLANKS.getDefaultState());
        structure.fillWithBlocks(world, start, 76, -20, 18, 78, -20, 36, Blocks.SANDSTONE.getDefaultState());
        structure.fillWithBlocks(world, start, 76, -20, 37, 78, -18, 37, Blocks.AIR.getDefaultState());
        structure.fillWithBlocks(world, start, 76, -20, 40, 78, -20, 80, Blocks.SANDSTONE.getDefaultState());
        structure.fillWithBlocks(world, start, 76, -20, 81, 77, -20, 81, Blocks.AIR.getDefaultState());
        structure.fillWithBlocks(world, start, 76, -19, 15, 78, -19, 17, Blocks.SANDSTONE.getDefaultState());
        structure.fillWithBlocks(world, start, 76, -19, 18, 78, -19, 20, Blocks.AIR.getDefaultState());
        structure.fillWithBlocks(world, start, 76, -19, 24, 78, -19, 72, Blocks.AIR.getDefaultState());
        structure.fillWithBlocks(world, start, 76, -19, 81, 80, -15, 81, Blocks.SANDSTONE.getDefaultState());
        structure.fillWithBlocks(world, start, 76, -18, 17, 78, -16, 17, Blocks.SANDSTONE.getDefaultState());
        structure.fillWithBlocks(world, start, 76, -18, 18, 78, -18, 74, Blocks.AIR.getDefaultState());
        structure.fillWithBlocks(world, start, 76, -17, 15, 78, -17, 17, Blocks.SANDSTONE.getDefaultState());
        structure.fillWithBlocks(world, start, 76, -17, 18, 78, -17, 78, Blocks.AIR.getDefaultState());
        structure.fillWithBlocks(world, start, 76, -17, 79, 78, -17, 81, Blocks.SANDSTONE.getDefaultState());
        structure.fillWithBlocks(world, start, 76, -16, 18, 78, -16, 24, Blocks.AIR.getDefaultState());
        structure.fillWithBlocks(world, start, 76, -16, 25, 78, -16, 34, Blocks.SANDSTONE.getDefaultState());
        structure.fillWithBlocks(world, start, 76, -16, 35, 78, -16, 41, Blocks.AIR.getDefaultState());
        structure.fillWithBlocks(world, start, 76, -16, 42, 76, -15, 44, Blocks.SANDSTONE.getDefaultState());
        structure.fillWithBlocks(world, start, 76, -16, 45, 79, -16, 68, Blocks.SANDSTONE.getDefaultState());
        structure.fillWithBlocks(world, start, 76, -16, 69, 78, -16, 71, Blocks.SANDSTONE.getDefaultState());
        structure.fillWithBlocks(world, start, 76, -15, 17, 80, -15, 17, Blocks.OAK_PLANKS.getDefaultState());
        structure.fillWithBlocks(world, start, 76, -15, 18, 78, -15, 20, Blocks.SANDSTONE.getDefaultState());
        structure.fillWithBlocks(world, start, 76, -15, 25, 80, -15, 25, Blocks.OAK_PLANKS.getDefaultState());
        structure.fillWithBlocks(world, start, 76, -15, 32, 77, -15, 33, Blocks.SANDSTONE.getDefaultState());
        structure.fillWithBlocks(world, start, 76, -15, 35, 83, -15, 35, Blocks.SANDSTONE.getDefaultState());
        structure.fillWithBlocks(world, start, 76, -15, 41, 77, -15, 43, Blocks.SANDSTONE.getDefaultState());
        structure.fillWithBlocks(world, start, 76, -15, 74, 78, -15, 76, Blocks.AIR.getDefaultState());
        structure.fillWithBlocks(world, start, 76, -15, 77, 78, -15, 79, Blocks.SANDSTONE.getDefaultState());
        structure.fillWithBlocks(world, start, 76, -14, 15, 81, -14, 20, Blocks.SANDSTONE.getDefaultState());
        structure.fillWithBlocks(world, start, 76, -14, 26, 77, -14, 27, Blocks.SANDSTONE.getDefaultState());
        structure.fillWithBlocks(world, start, 76, -14, 32, 77, -14, 33, Blocks.SANDSTONE.getDefaultState());
        structure.fillWithBlocks(world, start, 76, -14, 34, 76, -10, 43, Blocks.SANDSTONE.getDefaultState());
        structure.fillWithBlocks(world, start, 76, -14, 74, 76, -11, 81, Blocks.SANDSTONE.getDefaultState());
        structure.fillWithBlocks(world, start, 76, -13, 15, 80, -13, 27, Blocks.SANDSTONE.getDefaultState());
        structure.fillWithBlocks(world, start, 76, -13, 44, 78, -11, 44, Blocks.SANDSTONE.getDefaultState());
        structure.fillWithBlocks(world, start, 76, -12, 73, 76, -12, 81, Blocks.SANDSTONE.getDefaultState());
        structure.fillWithBlocks(world, start, 76, -11, 15, 81, -11, 20, Blocks.SANDSTONE.getDefaultState());
        structure.fillWithBlocks(world, start, 76, -11, 25, 77, -11, 27, Blocks.SANDSTONE.getDefaultState());
        structure.fillWithBlocks(world, start, 76, -11, 69, 78, -11, 74, Blocks.SANDSTONE.getDefaultState());
        structure.fillWithBlocks(world, start, 76, -10, 32, 76, -8, 34, Blocks.SANDSTONE.getDefaultState());
        structure.fillWithBlocks(world, start, 76, -8, 44, 76, -1, 44, Blocks.SANDSTONE.getDefaultState());
        structure.fillWithBlocks(world, start, 76, -7, 32, 76, -6, 33, Blocks.SANDSTONE.getDefaultState());
        structure.fillWithBlocks(world, start, 76, -7, 35, 76, -7, 36, Blocks.SANDSTONE.getDefaultState());
        structure.fillWithBlocks(world, start, 76, -5, 36, 76, 1, 36, Blocks.SANDSTONE.getDefaultState());
        structure.fillWithBlocks(world, start, 76, -5, 40, 76, -3, 44, Blocks.SANDSTONE.getDefaultState());
        structure.fillWithBlocks(world, start, 76, -3, 33, 76, 0, 36, Blocks.SANDSTONE.getDefaultState());
        structure.fillWithBlocks(world, start, 76, -2, 37, 76, -2, 38, Blocks.AIR.getDefaultState());
        structure.fillWithBlocks(world, start, 76, -2, 39, 76, -1, 39, Blocks.SANDSTONE.getDefaultState());
        structure.fillWithBlocks(world, start, 76, -2, 41, 76, -1, 42, Blocks.SANDSTONE.getDefaultState());
        structure.fillWithBlocks(world, start, 76, -1, 38, 76, -1, 42, Blocks.SANDSTONE.getDefaultState());
        structure.fillWithBlocks(world, start, 76, 0, 10, 81, 0, 32, Blocks.STONE.getDefaultState());
        structure.fillWithBlocks(world, start, 76, 1, 35, 80, 1, 39, Blocks.SANDSTONE.getDefaultState());
        structure.fillWithBlocks(world, start, 76, 2, 31, 81, 2, 36, Blocks.STONE.getDefaultState());
        structure.fillWithBlocks(world, start, 76, 2, 37, 81, 2, 42, Blocks.SANDSTONE.getDefaultState());
        structure.fillWithBlocks(world, start, 76, 2, 111, 87, 2, 125, Blocks.SANDSTONE.getDefaultState());
        structure.fillWithBlocks(world, start, 76, 2, 128, 80, 2, 132, Blocks.STONE.getDefaultState());
        structure.fillWithBlocks(world, start, 77, -53, 19, 77, -52, 19, Blocks.SANDSTONE.getDefaultState());
        structure.fillWithBlocks(world, start, 77, -52, 31, 77, -51, 31, Blocks.SHROOMLIGHT.getDefaultState());
        structure.fillWithBlocks(world, start, 77, -52, 33, 79, -52, 35, Blocks.AIR.getDefaultState());
        structure.fillWithBlocks(world, start, 77, -52, 41, 79, -52, 43, Blocks.AIR.getDefaultState());
        structure.fillWithBlocks(world, start, 77, -52, 44, 77, -41, 44, Blocks.SANDSTONE.getDefaultState());
        structure.fillWithBlocks(world, start, 77, -52, 45, 77, -51, 45, Blocks.SHROOMLIGHT.getDefaultState());
        structure.fillWithBlocks(world, start, 77, -52, 46, 80, -52, 49, Blocks.SANDSTONE.getDefaultState());
        structure.fillWithBlocks(world, start, 77, -51, 33, 79, -51, 35, Blocks.AIR.getDefaultState());
        structure.fillWithBlocks(world, start, 77, -51, 41, 79, -51, 43, Blocks.AIR.getDefaultState());
        structure.fillWithBlocks(world, start, 77, -51, 46, 80, -51, 49, Blocks.SANDSTONE.getDefaultState());
        structure.fillWithBlocks(world, start, 77, -50, 29, 77, -50, 30, Blocks.SANDSTONE_STAIRS.getDefaultState().with(StairsBlock.FACING, Direction.WEST).with(StairsBlock.WATERLOGGED, false).with(StairsBlock.SHAPE, StairsShape.STRAIGHT).with(StairsBlock.HALF, Half.BOTTOM));
        structure.fillWithBlocks(world, start, 77, -50, 46, 77, -50, 47, Blocks.SANDSTONE_STAIRS.getDefaultState().with(StairsBlock.FACING, Direction.WEST).with(StairsBlock.WATERLOGGED, false).with(StairsBlock.SHAPE, StairsShape.STRAIGHT).with(StairsBlock.HALF, Half.BOTTOM));
        structure.fillWithBlocks(world, start, 77, -50, 48, 78, -50, 49, Blocks.SANDSTONE.getDefaultState());
        structure.fillWithBlocks(world, start, 77, -49, 19, 78, -49, 23, Blocks.AIR.getDefaultState());
        structure.fillWithBlocks(world, start, 77, -49, 24, 78, -49, 27, Blocks.SANDSTONE.getDefaultState());
        structure.fillWithBlocks(world, start, 77, -49, 28, 77, -41, 28, Blocks.SANDSTONE.getDefaultState());
        structure.fillWithBlocks(world, start, 77, -49, 29, 79, -49, 31, Blocks.AIR.getDefaultState());
        structure.fillWithBlocks(world, start, 77, -49, 32, 77, -41, 32, Blocks.SANDSTONE.getDefaultState());
        structure.fillWithBlocks(world, start, 77, -49, 33, 79, -49, 35, Blocks.AIR.getDefaultState());
        structure.fillWithBlocks(world, start, 77, -49, 36, 77, -41, 36, Blocks.SANDSTONE.getDefaultState());
        structure.fillWithBlocks(world, start, 77, -49, 37, 79, -49, 39, Blocks.AIR.getDefaultState());
        structure.fillWithBlocks(world, start, 77, -49, 40, 77, -41, 40, Blocks.SANDSTONE.getDefaultState());
        structure.fillWithBlocks(world, start, 77, -49, 41, 79, -49, 43, Blocks.AIR.getDefaultState());
        structure.fillWithBlocks(world, start, 77, -49, 45, 79, -49, 47, Blocks.AIR.getDefaultState());
        structure.fillWithBlocks(world, start, 77, -49, 48, 77, -49, 51, Blocks.SANDSTONE.getDefaultState());
        structure.fillWithBlocks(world, start, 77, -49, 52, 77, -47, 52, Blocks.AIR.getDefaultState());
        structure.fillWithBlocks(world, start, 77, -49, 53, 77, -49, 53, Blocks.SANDSTONE.getDefaultState());
        structure.fillWithBlocks(world, start, 77, -49, 54, 77, -47, 56, Blocks.AIR.getDefaultState());
        structure.fillWithBlocks(world, start, 77, -49, 57, 77, -49, 57, Blocks.SANDSTONE.getDefaultState());
        structure.fillWithBlocks(world, start, 77, -49, 58, 77, -47, 58, Blocks.AIR.getDefaultState());
        structure.fillWithBlocks(world, start, 77, -49, 59, 77, -49, 59, Blocks.SANDSTONE.getDefaultState());
        structure.fillWithBlocks(world, start, 77, -49, 60, 77, -47, 62, Blocks.AIR.getDefaultState());
        structure.fillWithBlocks(world, start, 77, -49, 63, 78, -49, 64, Blocks.SANDSTONE.getDefaultState());
        structure.fillWithBlocks(world, start, 77, -49, 65, 77, -41, 65, Blocks.SANDSTONE.getDefaultState());
        structure.fillWithBlocks(world, start, 77, -49, 79, 77, -49, 82, Blocks.SANDSTONE.getDefaultState());
        structure.fillWithBlocks(world, start, 77, -48, 19, 78, -48, 23, Blocks.AIR.getDefaultState());
        structure.fillWithBlocks(world, start, 77, -48, 24, 80, -48, 27, Blocks.SANDSTONE.getDefaultState());
        structure.fillWithBlocks(world, start, 77, -48, 29, 79, -48, 31, Blocks.AIR.getDefaultState());
        structure.fillWithBlocks(world, start, 77, -48, 33, 79, -48, 35, Blocks.AIR.getDefaultState());
        structure.fillWithBlocks(world, start, 77, -48, 37, 79, -48, 39, Blocks.AIR.getDefaultState());
        structure.fillWithBlocks(world, start, 77, -48, 41, 79, -48, 43, Blocks.AIR.getDefaultState());
        structure.fillWithBlocks(world, start, 77, -48, 45, 79, -48, 47, Blocks.AIR.getDefaultState());
        structure.fillWithBlocks(world, start, 77, -48, 48, 77, -48, 51, Blocks.SANDSTONE.getDefaultState());
        structure.fillWithBlocks(world, start, 77, -48, 53, 77, -48, 53, Blocks.SANDSTONE.getDefaultState());
        structure.fillWithBlocks(world, start, 77, -48, 57, 77, -48, 57, Blocks.SANDSTONE.getDefaultState());
        structure.fillWithBlocks(world, start, 77, -48, 59, 77, -48, 59, Blocks.SANDSTONE.getDefaultState());
        structure.fillWithBlocks(world, start, 77, -48, 63, 78, -48, 64, Blocks.SANDSTONE.getDefaultState());
        structure.fillWithBlocks(world, start, 77, -48, 79, 77, -48, 82, Blocks.SANDSTONE.getDefaultState());
        structure.fillWithBlocks(world, start, 77, -47, 15, 80, -47, 18, Blocks.SANDSTONE.getDefaultState());
        structure.fillWithBlocks(world, start, 77, -47, 19, 78, -47, 23, Blocks.AIR.getDefaultState());
        structure.fillWithBlocks(world, start, 77, -47, 24, 80, -47, 27, Blocks.SANDSTONE.getDefaultState());
        structure.fillWithBlocks(world, start, 77, -47, 29, 79, -47, 31, Blocks.AIR.getDefaultState());
        structure.fillWithBlocks(world, start, 77, -47, 33, 79, -47, 35, Blocks.AIR.getDefaultState());
        structure.fillWithBlocks(world, start, 77, -47, 37, 79, -47, 39, Blocks.AIR.getDefaultState());
        structure.fillWithBlocks(world, start, 77, -47, 41, 79, -47, 43, Blocks.AIR.getDefaultState());
        structure.fillWithBlocks(world, start, 77, -47, 45, 79, -47, 47, Blocks.AIR.getDefaultState());
        structure.fillWithBlocks(world, start, 77, -47, 48, 77, -47, 51, Blocks.SANDSTONE.getDefaultState());
        structure.fillWithBlocks(world, start, 77, -47, 53, 77, -47, 53, Blocks.SANDSTONE.getDefaultState());
        structure.fillWithBlocks(world, start, 77, -47, 57, 77, -47, 57, Blocks.SANDSTONE.getDefaultState());
        structure.fillWithBlocks(world, start, 77, -47, 59, 77, -47, 59, Blocks.SANDSTONE.getDefaultState());
        structure.fillWithBlocks(world, start, 77, -47, 63, 78, -47, 64, Blocks.SANDSTONE.getDefaultState());
        structure.fillWithBlocks(world, start, 77, -47, 79, 77, -47, 82, Blocks.SANDSTONE.getDefaultState());
        structure.fillWithBlocks(world, start, 77, -46, 15, 80, -46, 18, Blocks.SANDSTONE.getDefaultState());
        structure.fillWithBlocks(world, start, 77, -46, 19, 78, -46, 23, Blocks.AIR.getDefaultState());
        structure.fillWithBlocks(world, start, 77, -46, 24, 81, -46, 28, Blocks.SANDSTONE.getDefaultState());
        structure.fillWithBlocks(world, start, 77, -46, 29, 77, -41, 36, Blocks.SANDSTONE.getDefaultState());
        structure.fillWithBlocks(world, start, 77, -46, 37, 79, -46, 39, Blocks.AIR.getDefaultState());
        structure.fillWithBlocks(world, start, 77, -46, 41, 77, -41, 48, Blocks.SANDSTONE.getDefaultState());
        structure.fillWithBlocks(world, start, 77, -46, 79, 77, -46, 82, Blocks.SANDSTONE.getDefaultState());
        structure.fillWithBlocks(world, start, 77, -44, 37, 77, -41, 48, Blocks.SANDSTONE.getDefaultState());
        structure.fillWithBlocks(world, start, 77, -43, 62, 81, -43, 66, Blocks.SANDSTONE.getDefaultState());
        structure.fillWithBlocks(world, start, 77, -42, 81, 77, -40, 81, Blocks.STONE_BRICKS.getDefaultState());
        structure.fillWithBlocks(world, start, 77, -42, 82, 78, -41, 82, Blocks.AIR.getDefaultState());
        structure.fillWithBlocks(world, start, 77, -42, 83, 77, -41, 84, Blocks.STONE_BRICKS.getDefaultState());
        structure.fillWithBlocks(world, start, 77, -42, 86, 78, -42, 87, Blocks.STONE_BRICKS.getDefaultState());
        structure.fillWithBlocks(world, start, 77, -41, 79, 77, -40, 81, Blocks.STONE_BRICKS.getDefaultState());
        structure.fillWithBlocks(world, start, 77, -41, 85, 77, -40, 85, Blocks.STONE_BRICKS.getDefaultState());
        structure.fillWithBlocks(world, start, 77, -41, 87, 84, -39, 87, Blocks.STONE_BRICKS.getDefaultState());
        structure.fillWithBlocks(world, start, 77, -40, 0, 77, -40, 20, Blocks.STONE_BRICKS.getDefaultState());
        structure.fillWithBlocks(world, start, 77, -40, 22, 77, -40, 22, Blocks.STONE_BRICKS.getDefaultState());
        structure.fillWithBlocks(world, start, 77, -40, 35, 83, -40, 41, Blocks.STONE_BRICKS.getDefaultState());
        structure.fillWithBlocks(world, start, 77, -40, 43, 81, -40, 48, Blocks.STONE_BRICKS.getDefaultState());
        structure.fillWithBlocks(world, start, 77, -40, 51, 82, -40, 63, Blocks.STONE_BRICKS.getDefaultState());
        structure.fillWithBlocks(world, start, 77, -40, 64, 77, -40, 64, Blocks.STONE_BRICKS.getDefaultState());
        structure.fillWithBlocks(world, start, 77, -40, 65, 77, -39, 65, Blocks.AIR.getDefaultState());
        structure.fillWithBlocks(world, start, 77, -40, 66, 82, -40, 72, Blocks.STONE_BRICKS.getDefaultState());
        structure.fillWithBlocks(world, start, 77, -40, 83, 82, -40, 88, Blocks.STONE_BRICKS.getDefaultState());
        structure.fillWithBlocks(world, start, 77, -40, 90, 78, -39, 90, Blocks.STONE_BRICKS.getDefaultState());
        structure.fillWithBlocks(world, start, 77, -39, 0, 77, -39, 0, Blocks.STONE_BRICKS.getDefaultState());
        structure.fillWithBlocks(world, start, 77, -39, 2, 77, -38, 4, Blocks.STONE_BRICKS.getDefaultState());
        structure.fillWithBlocks(world, start, 77, -39, 7, 77, -31, 7, Blocks.STONE_BRICKS.getDefaultState());
        structure.fillWithBlocks(world, start, 77, -39, 8, 79, -39, 12, Blocks.AIR.getDefaultState());
        structure.fillWithBlocks(world, start, 77, -39, 13, 77, -32, 13, Blocks.STONE_BRICKS.getDefaultState());
        structure.fillWithBlocks(world, start, 77, -39, 19, 78, -39, 20, Blocks.STONE_BRICKS.getDefaultState());
        structure.fillWithBlocks(world, start, 77, -39, 22, 77, -37, 22, Blocks.STONE_BRICKS.getDefaultState());
        structure.fillWithBlocks(world, start, 77, -39, 24, 77, -39, 25, Blocks.STONE_BRICKS.getDefaultState());
        structure.fillWithBlocks(world, start, 77, -39, 28, 77, -39, 34, Blocks.STONE_BRICKS.getDefaultState());
        structure.fillWithBlocks(world, start, 77, -39, 35, 83, -39, 41, Blocks.AIR.getDefaultState());
        structure.fillWithBlocks(world, start, 77, -39, 42, 78, -39, 44, Blocks.STONE_BRICKS.getDefaultState());
        structure.fillWithBlocks(world, start, 77, -39, 46, 77, -39, 54, Blocks.STONE_BRICKS.getDefaultState());
        structure.fillWithBlocks(world, start, 77, -39, 56, 77, -38, 57, Blocks.STONE_BRICKS.getDefaultState());
        structure.fillWithBlocks(world, start, 77, -39, 58, 81, -39, 62, Blocks.AIR.getDefaultState());
        structure.fillWithBlocks(world, start, 77, -39, 63, 77, -39, 64, Blocks.STONE_BRICKS.getDefaultState());
        structure.fillWithBlocks(world, start, 77, -39, 66, 77, -39, 74, Blocks.STONE_BRICKS.getDefaultState());
        structure.fillWithBlocks(world, start, 77, -39, 80, 79, -39, 86, Blocks.AIR.getDefaultState());
        structure.fillWithBlocks(world, start, 77, -39, 88, 78, -39, 90, Blocks.STONE_BRICKS.getDefaultState());
        structure.fillWithBlocks(world, start, 77, -38, 6, 77, -37, 7, Blocks.STONE_BRICKS.getDefaultState());
        structure.fillWithBlocks(world, start, 77, -38, 8, 79, -38, 12, Blocks.AIR.getDefaultState());
        structure.fillWithBlocks(world, start, 77, -38, 19, 78, -38, 20, Blocks.STONE_BRICKS.getDefaultState());
        structure.fillWithBlocks(world, start, 77, -38, 24, 77, -37, 24, Blocks.STONE_BRICKS.getDefaultState());
        structure.fillWithBlocks(world, start, 77, -38, 26, 77, -37, 26, Blocks.STONE_BRICKS.getDefaultState());
        structure.fillWithBlocks(world, start, 77, -38, 28, 77, -38, 30, Blocks.STONE_BRICKS.getDefaultState());
        structure.fillWithBlocks(world, start, 77, -38, 32, 77, -35, 32, Blocks.STONE_BRICKS.getDefaultState());
        structure.fillWithBlocks(world, start, 77, -38, 34, 78, -37, 34, Blocks.STONE_BRICKS.getDefaultState());
        structure.fillWithBlocks(world, start, 77, -38, 35, 83, -38, 41, Blocks.AIR.getDefaultState());
        structure.fillWithBlocks(world, start, 77, -38, 42, 78, -38, 44, Blocks.STONE_BRICKS.getDefaultState());
        structure.fillWithBlocks(world, start, 77, -38, 47, 77, -38, 51, Blocks.STONE_BRICKS.getDefaultState());
        structure.fillWithBlocks(world, start, 77, -38, 53, 77, -38, 57, Blocks.STONE_BRICKS.getDefaultState());
        structure.fillWithBlocks(world, start, 77, -38, 58, 81, -38, 62, Blocks.AIR.getDefaultState());
        structure.fillWithBlocks(world, start, 77, -38, 64, 78, -38, 65, Blocks.STONE_BRICKS.getDefaultState());
        structure.fillWithBlocks(world, start, 77, -38, 70, 77, -38, 72, Blocks.STONE_BRICKS.getDefaultState());
        structure.fillWithBlocks(world, start, 77, -38, 79, 78, -37, 79, Blocks.STONE_BRICKS.getDefaultState());
        structure.fillWithBlocks(world, start, 77, -38, 80, 79, -38, 86, Blocks.AIR.getDefaultState());
        structure.fillWithBlocks(world, start, 77, -38, 87, 79, -38, 90, Blocks.STONE_BRICKS.getDefaultState());
        structure.fillWithBlocks(world, start, 77, -37, 0, 78, -37, 1, Blocks.STONE_BRICKS.getDefaultState());
        structure.fillWithBlocks(world, start, 77, -37, 3, 77, -36, 7, Blocks.STONE_BRICKS.getDefaultState());
        structure.fillWithBlocks(world, start, 77, -37, 8, 81, -37, 12, Blocks.AIR.getDefaultState());
        structure.fillWithBlocks(world, start, 77, -37, 19, 78, -37, 21, Blocks.STONE_BRICKS.getDefaultState());
        structure.fillWithBlocks(world, start, 77, -37, 25, 77, -37, 26, Blocks.STONE_BRICKS.getDefaultState());
        structure.fillWithBlocks(world, start, 77, -37, 28, 77, -37, 34, Blocks.STONE_BRICKS.getDefaultState());
        structure.fillWithBlocks(world, start, 77, -37, 35, 83, -37, 41, Blocks.AIR.getDefaultState());
        structure.fillWithBlocks(world, start, 77, -37, 42, 78, -37, 43, Blocks.STONE_BRICKS.getDefaultState());
        structure.fillWithBlocks(world, start, 77, -37, 46, 77, -37, 47, Blocks.STONE_BRICKS.getDefaultState());
        structure.fillWithBlocks(world, start, 77, -37, 48, 77, -37, 48, Blocks.AIR.getDefaultState());
        structure.fillWithBlocks(world, start, 77, -37, 54, 78, -37, 56, Blocks.STONE_BRICKS.getDefaultState());
        structure.fillWithBlocks(world, start, 77, -37, 58, 81, -37, 62, Blocks.AIR.getDefaultState());
        structure.fillWithBlocks(world, start, 77, -37, 63, 77, -37, 74, Blocks.STONE_BRICKS.getDefaultState());
        structure.fillWithBlocks(world, start, 77, -37, 76, 77, -31, 76, Blocks.STONE_BRICKS.getDefaultState());
        structure.fillWithBlocks(world, start, 77, -37, 77, 77, -36, 77, Blocks.AIR.getDefaultState());
        structure.fillWithBlocks(world, start, 77, -37, 78, 78, -37, 79, Blocks.STONE_BRICKS.getDefaultState());
        structure.fillWithBlocks(world, start, 77, -37, 80, 83, -37, 86, Blocks.AIR.getDefaultState());
        structure.fillWithBlocks(world, start, 77, -37, 87, 77, -37, 87, Blocks.STONE_BRICKS.getDefaultState());
        structure.fillWithBlocks(world, start, 77, -37, 89, 78, -37, 90, Blocks.STONE_BRICKS.getDefaultState());
        structure.fillWithBlocks(world, start, 77, -36, 8, 81, -36, 12, Blocks.AIR.getDefaultState());
        structure.fillWithBlocks(world, start, 77, -36, 19, 77, -35, 20, Blocks.STONE_BRICKS.getDefaultState());
        structure.fillWithBlocks(world, start, 77, -36, 34, 83, -36, 34, Blocks.STONE_BRICKS.getDefaultState());
        structure.fillWithBlocks(world, start, 77, -36, 35, 83, -36, 41, Blocks.AIR.getDefaultState());
        structure.fillWithBlocks(world, start, 77, -36, 42, 77, -36, 45, Blocks.STONE_BRICKS.getDefaultState());
        structure.fillWithBlocks(world, start, 77, -36, 48, 77, -36, 51, Blocks.STONE_BRICKS.getDefaultState());
        structure.fillWithBlocks(world, start, 77, -36, 52, 77, -35, 52, Blocks.AIR.getDefaultState());
        structure.fillWithBlocks(world, start, 77, -36, 53, 77, -34, 57, Blocks.STONE_BRICKS.getDefaultState());
        structure.fillWithBlocks(world, start, 77, -36, 58, 81, -36, 62, Blocks.AIR.getDefaultState());
        structure.fillWithBlocks(world, start, 77, -36, 63, 77, -36, 67, Blocks.STONE_BRICKS.getDefaultState());
        structure.fillWithBlocks(world, start, 77, -36, 69, 78, -36, 71, Blocks.STONE_BRICKS.getDefaultState());
        structure.fillWithBlocks(world, start, 77, -36, 72, 78, -36, 72, Blocks.AIR.getDefaultState());
        structure.fillWithBlocks(world, start, 77, -36, 73, 78, -36, 74, Blocks.STONE_BRICKS.getDefaultState());
        structure.fillWithBlocks(world, start, 77, -36, 80, 83, -36, 86, Blocks.AIR.getDefaultState());
        structure.fillWithBlocks(world, start, 77, -36, 87, 80, -36, 90, Blocks.STONE_BRICKS.getDefaultState());
        structure.fillWithBlocks(world, start, 77, -35, 8, 81, -35, 12, Blocks.AIR.getDefaultState());
        structure.fillWithBlocks(world, start, 77, -35, 31, 79, -35, 33, Blocks.STONE_BRICKS.getDefaultState());
        structure.fillWithBlocks(world, start, 77, -35, 34, 84, -34, 34, Blocks.SANDSTONE.getDefaultState());
        structure.fillWithBlocks(world, start, 77, -35, 35, 79, -35, 41, Blocks.STONE_BRICKS.getDefaultState());
        structure.fillWithBlocks(world, start, 77, -35, 42, 84, -34, 42, Blocks.SANDSTONE.getDefaultState());
        structure.fillWithBlocks(world, start, 77, -35, 48, 78, -35, 49, Blocks.STONE_BRICKS.getDefaultState());
        structure.fillWithBlocks(world, start, 77, -35, 50, 77, -31, 50, Blocks.STONE_BRICKS.getDefaultState());
        structure.fillWithBlocks(world, start, 77, -35, 58, 81, -35, 62, Blocks.AIR.getDefaultState());
        structure.fillWithBlocks(world, start, 77, -35, 63, 81, -35, 67, Blocks.STONE_BRICKS.getDefaultState());
        structure.fillWithBlocks(world, start, 77, -35, 70, 79, -35, 72, Blocks.STONE_BRICKS.getDefaultState());
        structure.fillWithBlocks(world, start, 77, -35, 80, 83, -35, 86, Blocks.AIR.getDefaultState());
        structure.fillWithBlocks(world, start, 77, -35, 87, 78, -35, 90, Blocks.STONE_BRICKS.getDefaultState());
        structure.fillWithBlocks(world, start, 77, -34, 0, 77, -34, 0, Blocks.STONE_BRICKS.getDefaultState());
        structure.fillWithBlocks(world, start, 77, -34, 1, 77, -34, 2, Blocks.AIR.getDefaultState());
        structure.fillWithBlocks(world, start, 77, -34, 3, 79, -34, 11, Blocks.STONE_BRICKS.getDefaultState());
        structure.fillWithBlocks(world, start, 77, -34, 16, 77, -34, 16, Blocks.STONE_BRICKS.getDefaultState());
        structure.fillWithBlocks(world, start, 77, -34, 18, 79, -34, 20, Blocks.STONE_BRICKS.getDefaultState());
        structure.fillWithBlocks(world, start, 77, -34, 32, 77, -34, 32, Blocks.AIR.getDefaultState());
        structure.fillWithBlocks(world, start, 77, -34, 35, 77, -34, 36, Blocks.STONE_BRICKS.getDefaultState());
        structure.fillWithBlocks(world, start, 77, -34, 37, 77, -34, 37, Blocks.AIR.getDefaultState());
        structure.fillWithBlocks(world, start, 77, -34, 38, 77, -33, 38, Blocks.STONE_BRICKS.getDefaultState());
        structure.fillWithBlocks(world, start, 77, -34, 39, 77, -34, 39, Blocks.AIR.getDefaultState());
        structure.fillWithBlocks(world, start, 77, -34, 40, 77, -33, 41, Blocks.STONE_BRICKS.getDefaultState());
        structure.fillWithBlocks(world, start, 77, -34, 48, 92, -34, 48, Blocks.STONE_BRICKS.getDefaultState());
        structure.fillWithBlocks(world, start, 77, -34, 51, 77, -34, 69, Blocks.STONE_BRICKS.getDefaultState());
        structure.fillWithBlocks(world, start, 77, -34, 70, 77, -32, 70, Blocks.AIR.getDefaultState());
        structure.fillWithBlocks(world, start, 77, -34, 71, 78, -34, 72, Blocks.STONE_BRICKS.getDefaultState());
        structure.fillWithBlocks(world, start, 77, -33, 6, 79, -33, 8, Blocks.STONE_BRICKS.getDefaultState());
        structure.fillWithBlocks(world, start, 77, -33, 9, 77, -33, 17, Blocks.STONE_BRICKS.getDefaultState());
        structure.fillWithBlocks(world, start, 77, -33, 19, 78, -33, 20, Blocks.STONE_BRICKS.getDefaultState());
        structure.fillWithBlocks(world, start, 77, -33, 34, 79, -31, 34, Blocks.STONE_BRICKS.getDefaultState());
        structure.fillWithBlocks(world, start, 77, -33, 35, 77, -33, 35, Blocks.SANDSTONE.getDefaultState());
        structure.fillWithBlocks(world, start, 77, -33, 36, 77, -33, 36, Blocks.STONE_BRICKS.getDefaultState());
        structure.fillWithBlocks(world, start, 77, -33, 39, 77, -33, 45, Blocks.STONE_BRICKS.getDefaultState());
        structure.fillWithBlocks(world, start, 77, -33, 48, 77, -33, 54, Blocks.STONE_BRICKS.getDefaultState());
        structure.fillWithBlocks(world, start, 77, -33, 59, 78, -33, 62, Blocks.STONE_BRICKS.getDefaultState());
        structure.fillWithBlocks(world, start, 77, -33, 63, 77, -33, 63, Blocks.AIR.getDefaultState());
        structure.fillWithBlocks(world, start, 77, -33, 64, 77, -33, 68, Blocks.STONE_BRICKS.getDefaultState());
        structure.fillWithBlocks(world, start, 77, -33, 69, 77, -33, 70, Blocks.AIR.getDefaultState());
        structure.fillWithBlocks(world, start, 77, -33, 71, 78, -33, 72, Blocks.STONE_BRICKS.getDefaultState());
        structure.fillWithBlocks(world, start, 77, -33, 82, 77, -33, 82, Blocks.STONE_BRICKS.getDefaultState());
        structure.fillWithBlocks(world, start, 77, -33, 84, 77, -33, 90, Blocks.STONE_BRICKS.getDefaultState());
        structure.fillWithBlocks(world, start, 77, -32, 1, 77, -31, 1, Blocks.AIR.getDefaultState());
        structure.fillWithBlocks(world, start, 77, -32, 2, 79, -32, 7, Blocks.STONE_BRICKS.getDefaultState());
        structure.fillWithBlocks(world, start, 77, -32, 10, 77, -32, 10, Blocks.STONE_BRICKS.getDefaultState());
        structure.fillWithBlocks(world, start, 77, -32, 12, 78, -32, 14, Blocks.STONE_BRICKS.getDefaultState());
        structure.fillWithBlocks(world, start, 77, -32, 16, 78, -32, 17, Blocks.STONE_BRICKS.getDefaultState());
        structure.fillWithBlocks(world, start, 77, -32, 18, 77, -32, 20, Blocks.STONE_BRICKS.getDefaultState());
        structure.fillWithBlocks(world, start, 77, -32, 32, 77, -31, 34, Blocks.STONE_BRICKS.getDefaultState());
        structure.fillWithBlocks(world, start, 77, -32, 35, 78, -32, 35, Blocks.STONE_BRICKS.getDefaultState());
        structure.fillWithBlocks(world, start, 77, -32, 36, 77, -32, 38, Blocks.AIR.getDefaultState());
        structure.fillWithBlocks(world, start, 77, -32, 39, 77, -31, 40, Blocks.SANDSTONE.getDefaultState());
        structure.fillWithBlocks(world, start, 77, -32, 41, 79, -32, 45, Blocks.STONE_BRICKS.getDefaultState());
        structure.fillWithBlocks(world, start, 77, -32, 48, 78, -32, 51, Blocks.STONE_BRICKS.getDefaultState());
        structure.fillWithBlocks(world, start, 77, -32, 58, 77, -32, 58, Blocks.STONE_BRICKS.getDefaultState());
        structure.fillWithBlocks(world, start, 77, -32, 60, 81, -32, 67, Blocks.STONE_BRICKS.getDefaultState());
        structure.fillWithBlocks(world, start, 77, -32, 71, 78, -32, 72, Blocks.STONE_BRICKS.getDefaultState());
        structure.fillWithBlocks(world, start, 77, -32, 77, 79, -32, 79, Blocks.STONE_BRICKS.getDefaultState());
        structure.fillWithBlocks(world, start, 77, -32, 83, 77, -32, 83, Blocks.STONE_BRICKS.getDefaultState());
        structure.fillWithBlocks(world, start, 77, -32, 85, 79, -32, 88, Blocks.STONE_BRICKS.getDefaultState());
        structure.fillWithBlocks(world, start, 77, -32, 89, 78, -32, 90, Blocks.STONE_BRICKS.getDefaultState());
        structure.fillWithBlocks(world, start, 77, -31, 9, 78, -31, 12, Blocks.STONE_BRICKS.getDefaultState());
        structure.fillWithBlocks(world, start, 77, -31, 14, 79, -31, 16, Blocks.STONE_BRICKS.getDefaultState());
        structure.fillWithBlocks(world, start, 77, -31, 35, 77, -30, 35, Blocks.SANDSTONE.getDefaultState());
        structure.fillWithBlocks(world, start, 77, -31, 38, 77, -31, 38, Blocks.STONE_BRICKS.getDefaultState());
        structure.fillWithBlocks(world, start, 77, -31, 41, 78, -31, 41, Blocks.AIR.getDefaultState());
        structure.fillWithBlocks(world, start, 77, -31, 42, 80, -31, 45, Blocks.STONE_BRICKS.getDefaultState());
        structure.fillWithBlocks(world, start, 77, -31, 54, 78, -31, 55, Blocks.STONE_BRICKS.getDefaultState());
        structure.fillWithBlocks(world, start, 77, -31, 56, 77, -31, 62, Blocks.STONE_BRICKS.getDefaultState());
        structure.fillWithBlocks(world, start, 77, -31, 64, 77, -31, 72, Blocks.STONE_BRICKS.getDefaultState());
        structure.fillWithBlocks(world, start, 77, -30, -6, 77, -29, -5, Blocks.STONE_BRICKS.getDefaultState());
        structure.fillWithBlocks(world, start, 77, -30, 42, 78, -30, 42, Blocks.DIRT.getDefaultState());
        structure.fillWithBlocks(world, start, 77, -30, 43, 77, -30, 43, Blocks.SANDSTONE.getDefaultState());
        structure.fillWithBlocks(world, start, 77, -30, 45, 79, -30, 47, Blocks.SANDSTONE.getDefaultState());
        structure.fillWithBlocks(world, start, 77, -30, 52, 82, -30, 57, Blocks.SANDSTONE.getDefaultState());
        structure.fillWithBlocks(world, start, 77, -30, 59, 78, -30, 61, Blocks.SANDSTONE.getDefaultState());
        structure.fillWithBlocks(world, start, 77, -30, 62, 78, -30, 63, Blocks.DIRT.getDefaultState());
        structure.fillWithBlocks(world, start, 77, -30, 64, 77, -30, 65, Blocks.SANDSTONE.getDefaultState());
        structure.fillWithBlocks(world, start, 77, -29, 10, 78, -29, 20, Blocks.AIR.getDefaultState());
        structure.fillWithBlocks(world, start, 77, -29, 22, 78, -29, 33, Blocks.AIR.getDefaultState());
        structure.fillWithBlocks(world, start, 77, -29, 34, 77, -29, 37, Blocks.AIR.getDefaultState());
        structure.fillWithBlocks(world, start, 77, -29, 38, 77, -20, 38, Blocks.SHROOMLIGHT.getDefaultState());
        structure.fillWithBlocks(world, start, 77, -29, 40, 78, -29, 41, Blocks.AIR.getDefaultState());
        structure.fillWithBlocks(world, start, 77, -29, 46, 78, -29, 49, Blocks.SANDSTONE.getDefaultState());
        structure.fillWithBlocks(world, start, 77, -29, 51, 80, -29, 51, Blocks.SANDSTONE.getDefaultState());
        structure.fillWithBlocks(world, start, 77, -29, 59, 77, -29, 59, Blocks.SANDSTONE.getDefaultState());
        structure.fillWithBlocks(world, start, 77, -29, 60, 77, -25, 60, Blocks.AIR.getDefaultState());
        structure.fillWithBlocks(world, start, 77, -29, 61, 77, -29, 65, Blocks.SANDSTONE.getDefaultState());
        structure.fillWithBlocks(world, start, 77, -28, -5, 79, -28, -5, Blocks.STONE_BRICKS.getDefaultState());
        structure.fillWithBlocks(world, start, 77, -28, 34, 77, -28, 37, Blocks.AIR.getDefaultState());
        structure.fillWithBlocks(world, start, 77, -28, 43, 77, -28, 45, Blocks.SANDSTONE.getDefaultState());
        structure.fillWithBlocks(world, start, 77, -28, 46, 78, -28, 46, Blocks.DIRT.getDefaultState());
        structure.fillWithBlocks(world, start, 77, -28, 47, 78, -27, 47, Blocks.SANDSTONE.getDefaultState());
        structure.fillWithBlocks(world, start, 77, -28, 48, 77, -28, 50, Blocks.AIR.getDefaultState());
        structure.fillWithBlocks(world, start, 77, -28, 61, 77, -25, 61, Blocks.AIR.getDefaultState());
        structure.fillWithBlocks(world, start, 77, -28, 62, 79, -28, 64, Blocks.SANDSTONE.getDefaultState());
        structure.fillWithBlocks(world, start, 77, -27, -6, 77, -23, -6, Blocks.STONE_BRICKS.getDefaultState());
        structure.fillWithBlocks(world, start, 77, -27, -4, 78, -27, -4, Blocks.SANDSTONE.getDefaultState());
        structure.fillWithBlocks(world, start, 77, -27, 34, 78, -27, 34, Blocks.IRON_BARS.getDefaultState().with(FourWayBlock.WATERLOGGED, false).with(FourWayBlock.NORTH, true).with(FourWayBlock.SOUTH, true).with(FourWayBlock.EAST, true).with(FourWayBlock.WEST, true));
        structure.fillWithBlocks(world, start, 77, -27, 35, 78, -27, 36, Blocks.AIR.getDefaultState());
        structure.fillWithBlocks(world, start, 77, -27, 45, 77, -27, 48, Blocks.SANDSTONE.getDefaultState());
        structure.fillWithBlocks(world, start, 77, -27, 49, 77, -27, 50, Blocks.AIR.getDefaultState());
        structure.fillWithBlocks(world, start, 77, -27, 59, 77, -27, 59, Blocks.SANDSTONE.getDefaultState());
        structure.fillWithBlocks(world, start, 77, -26, -4, 84, -26, -4, Blocks.STONE_BRICKS.getDefaultState());
        structure.fillWithBlocks(world, start, 77, -26, 35, 78, -26, 36, Blocks.AIR.getDefaultState());
        structure.fillWithBlocks(world, start, 77, -26, 39, 79, -26, 41, Blocks.AIR.getDefaultState());
        structure.fillWithBlocks(world, start, 77, -26, 42, 77, -26, 42, Blocks.SANDSTONE.getDefaultState());
        structure.fillWithBlocks(world, start, 77, -26, 43, 77, -26, 44, Blocks.AIR.getDefaultState());
        structure.fillWithBlocks(world, start, 77, -26, 45, 77, -26, 46, Blocks.DIRT.getDefaultState());
        structure.fillWithBlocks(world, start, 77, -26, 47, 77, -26, 47, Blocks.SANDSTONE.getDefaultState());
        structure.fillWithBlocks(world, start, 77, -26, 48, 77, -26, 50, Blocks.AIR.getDefaultState());
        structure.fillWithBlocks(world, start, 77, -26, 62, 78, -26, 65, Blocks.SANDSTONE.getDefaultState());
        structure.fillWithBlocks(world, start, 77, -25, -4, 77, -25, -3, Blocks.STONE_BRICKS.getDefaultState());
        structure.fillWithBlocks(world, start, 77, -25, 14, 77, -21, 14, Blocks.SANDSTONE.getDefaultState());
        structure.fillWithBlocks(world, start, 77, -25, 25, 77, -20, 25, Blocks.SANDSTONE.getDefaultState());
        structure.fillWithBlocks(world, start, 77, -25, 32, 78, -25, 34, Blocks.SANDSTONE.getDefaultState());
        structure.fillWithBlocks(world, start, 77, -25, 40, 78, -25, 41, Blocks.AIR.getDefaultState());
        structure.fillWithBlocks(world, start, 77, -25, 45, 78, -25, 46, Blocks.SANDSTONE.getDefaultState());
        structure.fillWithBlocks(world, start, 77, -25, 48, 77, -24, 48, Blocks.SANDSTONE.getDefaultState());
        structure.fillWithBlocks(world, start, 77, -25, 49, 77, -25, 50, Blocks.AIR.getDefaultState());
        structure.fillWithBlocks(world, start, 77, -25, 59, 77, -25, 59, Blocks.SANDSTONE.getDefaultState());
        structure.fillWithBlocks(world, start, 77, -25, 62, 77, -25, 62, Blocks.SANDSTONE.getDefaultState());
        structure.fillWithBlocks(world, start, 77, -25, 64, 78, -25, 64, Blocks.DIRT.getDefaultState());
        structure.fillWithBlocks(world, start, 77, -25, 65, 79, -25, 65, Blocks.SANDSTONE.getDefaultState());
        structure.fillWithBlocks(world, start, 77, -24, -4, 77, -24, -4, Blocks.STONE_BRICKS.getDefaultState());
        structure.fillWithBlocks(world, start, 77, -24, -3, 77, -23, -3, Blocks.SANDSTONE.getDefaultState());
        structure.fillWithBlocks(world, start, 77, -24, -2, 78, -24, -2, Blocks.STONE_BRICKS.getDefaultState());
        structure.fillWithBlocks(world, start, 77, -24, -1, 77, -24, -1, Blocks.SANDSTONE.getDefaultState());
        structure.fillWithBlocks(world, start, 77, -24, 1, 79, -24, 3, Blocks.SANDSTONE.getDefaultState());
        structure.fillWithBlocks(world, start, 77, -24, 5, 79, -24, 7, Blocks.SANDSTONE.getDefaultState());
        structure.fillWithBlocks(world, start, 77, -24, 9, 78, -24, 14, Blocks.SANDSTONE.getDefaultState());
        structure.fillWithBlocks(world, start, 77, -24, 21, 78, -24, 22, Blocks.SANDSTONE.getDefaultState());
        structure.fillWithBlocks(world, start, 77, -24, 24, 78, -24, 25, Blocks.SANDSTONE.getDefaultState());
        structure.fillWithBlocks(world, start, 77, -24, 42, 77, -23, 43, Blocks.SANDSTONE.getDefaultState());
        structure.fillWithBlocks(world, start, 77, -24, 45, 77, -24, 45, Blocks.SANDSTONE.getDefaultState());
        structure.fillWithBlocks(world, start, 77, -24, 47, 78, -24, 48, Blocks.SANDSTONE.getDefaultState());
        structure.fillWithBlocks(world, start, 77, -24, 49, 77, -23, 49, Blocks.AIR.getDefaultState());
        structure.fillWithBlocks(world, start, 77, -24, 50, 77, -24, 61, Blocks.SANDSTONE.getDefaultState());
        structure.fillWithBlocks(world, start, 77, -24, 63, 77, -23, 64, Blocks.SANDSTONE.getDefaultState());
        structure.fillWithBlocks(world, start, 77, -23, -5, 78, -23, -5, Blocks.STONE_BRICKS.getDefaultState());
        structure.fillWithBlocks(world, start, 77, -23, -2, 77, -23, -1, Blocks.STONE_BRICKS.getDefaultState());
        structure.fillWithBlocks(world, start, 77, -23, 7, 77, -23, 7, Blocks.STONE_BRICKS.getDefaultState());
        structure.fillWithBlocks(world, start, 77, -23, 12, 77, -23, 12, Blocks.SANDSTONE.getDefaultState());
        structure.fillWithBlocks(world, start, 77, -23, 17, 77, -23, 17, Blocks.SANDSTONE.getDefaultState());
        structure.fillWithBlocks(world, start, 77, -23, 19, 78, -23, 19, Blocks.AIR.getDefaultState());
        structure.fillWithBlocks(world, start, 77, -23, 20, 77, -23, 20, Blocks.SANDSTONE.getDefaultState());
        structure.fillWithBlocks(world, start, 77, -23, 22, 77, -23, 22, Blocks.SANDSTONE.getDefaultState());
        structure.fillWithBlocks(world, start, 77, -23, 23, 77, -23, 24, Blocks.DIRT.getDefaultState());
        structure.fillWithBlocks(world, start, 77, -23, 35, 78, -23, 36, Blocks.AIR.getDefaultState());
        structure.fillWithBlocks(world, start, 77, -23, 45, 78, -23, 47, Blocks.SANDSTONE.getDefaultState());
        structure.fillWithBlocks(world, start, 77, -23, 48, 77, -23, 49, Blocks.AIR.getDefaultState());
        structure.fillWithBlocks(world, start, 77, -23, 51, 79, -23, 53, Blocks.SANDSTONE.getDefaultState());
        structure.fillWithBlocks(world, start, 77, -23, 56, 77, -23, 58, Blocks.SANDSTONE.getDefaultState());
        structure.fillWithBlocks(world, start, 77, -23, 61, 79, -23, 63, Blocks.SANDSTONE.getDefaultState());
        structure.fillWithBlocks(world, start, 77, -22, -6, 77, -22, -4, Blocks.SANDSTONE.getDefaultState());
        structure.fillWithBlocks(world, start, 77, -22, -3, 77, -22, -1, Blocks.STONE_BRICKS.getDefaultState());
        structure.fillWithBlocks(world, start, 77, -22, 1, 77, -22, 1, Blocks.STONE_BRICKS.getDefaultState());
        structure.fillWithBlocks(world, start, 77, -22, 2, 77, -22, 3, Blocks.DIRT.getDefaultState());
        structure.fillWithBlocks(world, start, 77, -22, 4, 77, -21, 4, Blocks.STONE_BRICKS.getDefaultState());
        structure.fillWithBlocks(world, start, 77, -22, 5, 78, -22, 5, Blocks.SANDSTONE.getDefaultState());
        structure.fillWithBlocks(world, start, 77, -22, 8, 78, -22, 8, Blocks.STONE_BRICKS.getDefaultState());
        structure.fillWithBlocks(world, start, 77, -22, 11, 78, -22, 12, Blocks.SANDSTONE.getDefaultState());
        structure.fillWithBlocks(world, start, 77, -22, 17, 79, -22, 19, Blocks.SANDSTONE.getDefaultState());
        structure.fillWithBlocks(world, start, 77, -22, 35, 78, -22, 36, Blocks.AIR.getDefaultState());
        structure.fillWithBlocks(world, start, 77, -22, 39, 79, -22, 41, Blocks.AIR.getDefaultState());
        structure.fillWithBlocks(world, start, 77, -22, 43, 77, -22, 46, Blocks.SANDSTONE.getDefaultState());
        structure.fillWithBlocks(world, start, 77, -22, 48, 77, -21, 49, Blocks.SANDSTONE.getDefaultState());
        structure.fillWithBlocks(world, start, 77, -22, 51, 79, -22, 54, Blocks.SANDSTONE.getDefaultState());
        structure.fillWithBlocks(world, start, 77, -22, 56, 77, -20, 56, Blocks.SANDSTONE.getDefaultState());
        structure.fillWithBlocks(world, start, 77, -22, 58, 78, -22, 60, Blocks.SANDSTONE.getDefaultState());
        structure.fillWithBlocks(world, start, 77, -22, 62, 77, -22, 62, Blocks.SANDSTONE.getDefaultState());
        structure.fillWithBlocks(world, start, 77, -22, 64, 78, -22, 65, Blocks.SANDSTONE.getDefaultState());
        structure.fillWithBlocks(world, start, 77, -21, -5, 78, -21, -4, Blocks.STONE_BRICKS.getDefaultState());
        structure.fillWithBlocks(world, start, 77, -21, 0, 77, -21, 5, Blocks.STONE_BRICKS.getDefaultState());
        structure.fillWithBlocks(world, start, 77, -21, 7, 77, -21, 7, Blocks.STONE_BRICKS.getDefaultState());
        structure.fillWithBlocks(world, start, 77, -21, 18, 78, -21, 21, Blocks.SANDSTONE.getDefaultState());
        structure.fillWithBlocks(world, start, 77, -21, 23, 78, -21, 25, Blocks.SANDSTONE.getDefaultState());
        structure.fillWithBlocks(world, start, 77, -21, 33, 78, -21, 34, Blocks.SANDSTONE.getDefaultState());
        structure.fillWithBlocks(world, start, 77, -21, 40, 78, -21, 41, Blocks.AIR.getDefaultState());
        structure.fillWithBlocks(world, start, 77, -21, 42, 78, -20, 42, Blocks.SANDSTONE.getDefaultState());
        structure.fillWithBlocks(world, start, 77, -21, 43, 77, -21, 44, Blocks.DIRT.getDefaultState());
        structure.fillWithBlocks(world, start, 77, -21, 45, 77, -21, 62, Blocks.SANDSTONE.getDefaultState());
        structure.fillWithBlocks(world, start, 77, -20, 15, 78, -20, 16, Blocks.SANDSTONE.getDefaultState());
        structure.fillWithBlocks(world, start, 77, -19, 23, 78, -19, 72, Blocks.AIR.getDefaultState());
        structure.fillWithBlocks(world, start, 77, -19, 74, 77, -19, 74, Blocks.AIR.getDefaultState());
        structure.fillWithBlocks(world, start, 77, -19, 76, 79, -19, 78, Blocks.AIR.getDefaultState());
        structure.fillWithBlocks(world, start, 77, -19, 79, 79, -19, 81, Blocks.SANDSTONE.getDefaultState());
        structure.fillWithBlocks(world, start, 77, -18, 15, 78, -18, 17, Blocks.SANDSTONE.getDefaultState());
        structure.fillWithBlocks(world, start, 77, -18, 76, 79, -18, 78, Blocks.AIR.getDefaultState());
        structure.fillWithBlocks(world, start, 77, -16, 15, 78, -16, 17, Blocks.SANDSTONE.getDefaultState());
        structure.fillWithBlocks(world, start, 77, -16, 42, 77, -16, 42, Blocks.SANDSTONE.getDefaultState());
        structure.fillWithBlocks(world, start, 77, -16, 44, 79, -16, 68, Blocks.SANDSTONE.getDefaultState());
        structure.fillWithBlocks(world, start, 77, -15, 16, 79, -13, 16, Blocks.SANDSTONE.getDefaultState());
        structure.fillWithBlocks(world, start, 77, -15, 22, 78, -15, 24, Blocks.SANDSTONE.getDefaultState());
        structure.fillWithBlocks(world, start, 77, -15, 26, 78, -15, 27, Blocks.SANDSTONE.getDefaultState());
        structure.fillWithBlocks(world, start, 77, -15, 34, 78, -15, 35, Blocks.SANDSTONE.getDefaultState());
        structure.fillWithBlocks(world, start, 77, -15, 80, 78, -15, 81, Blocks.SANDSTONE.getDefaultState());
        structure.fillWithBlocks(world, start, 77, -14, 34, 77, -14, 35, Blocks.AIR.getDefaultState());
        structure.fillWithBlocks(world, start, 77, -14, 36, 78, -14, 37, Blocks.SANDSTONE.getDefaultState());
        structure.fillWithBlocks(world, start, 77, -14, 39, 79, -14, 41, Blocks.SANDSTONE.getDefaultState());
        structure.fillWithBlocks(world, start, 77, -14, 42, 77, -12, 44, Blocks.SANDSTONE.getDefaultState());
        structure.fillWithBlocks(world, start, 77, -14, 74, 77, -14, 74, Blocks.SANDSTONE.getDefaultState());
        structure.fillWithBlocks(world, start, 77, -14, 76, 82, -14, 81, Blocks.SANDSTONE.getDefaultState());
        structure.fillWithBlocks(world, start, 77, -13, 32, 80, -13, 35, Blocks.SANDSTONE.getDefaultState());
        structure.fillWithBlocks(world, start, 77, -13, 36, 78, -13, 40, Blocks.SANDSTONE.getDefaultState());
        structure.fillWithBlocks(world, start, 77, -13, 75, 78, -13, 81, Blocks.SANDSTONE.getDefaultState());
        structure.fillWithBlocks(world, start, 77, -12, 15, 79, -12, 17, Blocks.SANDSTONE.getDefaultState());
        structure.fillWithBlocks(world, start, 77, -12, 20, 81, -12, 24, Blocks.SANDSTONE.getDefaultState());
        structure.fillWithBlocks(world, start, 77, -12, 26, 78, -12, 27, Blocks.SANDSTONE.getDefaultState());
        structure.fillWithBlocks(world, start, 77, -12, 74, 79, -12, 78, Blocks.SANDSTONE.getDefaultState());
        structure.fillWithBlocks(world, start, 77, -11, 75, 77, -11, 81, Blocks.SANDSTONE.getDefaultState());
        structure.fillWithBlocks(world, start, 77, -10, 36, 81, -10, 40, Blocks.SANDSTONE.getDefaultState());
        structure.fillWithBlocks(world, start, 77, -9, 36, 77, -5, 36, Blocks.STONE.getDefaultState());
        structure.fillWithBlocks(world, start, 77, -9, 37, 79, -9, 39, Blocks.AIR.getDefaultState());
        structure.fillWithBlocks(world, start, 77, -9, 40, 77, -7, 40, Blocks.STONE.getDefaultState());
        structure.fillWithBlocks(world, start, 77, -8, 37, 79, -8, 39, Blocks.AIR.getDefaultState());
        structure.fillWithBlocks(world, start, 77, -7, 37, 79, -7, 39, Blocks.AIR.getDefaultState());
        structure.fillWithBlocks(world, start, 77, -6, 35, 77, -5, 36, Blocks.STONE.getDefaultState());
        structure.fillWithBlocks(world, start, 77, 0, 33, 83, 2, 33, Blocks.STONE.getDefaultState());
        structure.fillWithBlocks(world, start, 77, 0, 34, 81, 0, 38, Blocks.SANDSTONE.getDefaultState());
        structure.fillWithBlocks(world, start, 77, 0, 150, 107, 0, 150, Blocks.SANDSTONE.getDefaultState());
        structure.fillWithBlocks(world, start, 77, 1, 4, 82, 1, 17, Blocks.SANDSTONE.getDefaultState());
        structure.fillWithBlocks(world, start, 77, 1, 117, 81, 1, 125, Blocks.SANDSTONE.getDefaultState());
        structure.fillWithBlocks(world, start, 77, 1, 126, 85, 1, 134, Blocks.STONE.getDefaultState());
        structure.fillWithBlocks(world, start, 77, 2, 28, 80, 2, 36, Blocks.STONE.getDefaultState());
        structure.fillWithBlocks(world, start, 77, 2, 44, 114, 6, 44, Blocks.SANDSTONE.getDefaultState());
        structure.fillWithBlocks(world, start, 77, 2, 108, 87, 2, 125, Blocks.SANDSTONE.getDefaultState());
        structure.fillWithBlocks(world, start, 77, 2, 133, 92, 2, 133, Blocks.STONE.getDefaultState());
        structure.fillWithBlocks(world, start, 77, 6, 133, 146, 6, 133, Blocks.SANDSTONE.getDefaultState());
        structure.fillWithBlocks(world, start, 78, -54, 32, 81, -53, 32, Blocks.SANDSTONE.getDefaultState());
        structure.fillWithBlocks(world, start, 78, -52, 31, 86, -52, 31, Blocks.SANDSTONE.getDefaultState());
        structure.fillWithBlocks(world, start, 78, -52, 32, 79, -52, 32, Blocks.SANDSTONE_STAIRS.getDefaultState().with(StairsBlock.FACING, Direction.NORTH).with(StairsBlock.WATERLOGGED, false).with(StairsBlock.SHAPE, StairsShape.STRAIGHT).with(StairsBlock.HALF, Half.BOTTOM));
        structure.fillWithBlocks(world, start, 78, -52, 36, 80, -51, 36, Blocks.AIR.getDefaultState());
        structure.fillWithBlocks(world, start, 78, -52, 37, 78, -51, 39, Blocks.SHROOMLIGHT.getDefaultState());
        structure.fillWithBlocks(world, start, 78, -52, 40, 80, -52, 43, Blocks.AIR.getDefaultState());
        structure.fillWithBlocks(world, start, 78, -52, 44, 79, -52, 44, Blocks.SANDSTONE_STAIRS.getDefaultState().with(StairsBlock.FACING, Direction.SOUTH).with(StairsBlock.WATERLOGGED, false).with(StairsBlock.SHAPE, StairsShape.STRAIGHT).with(StairsBlock.HALF, Half.BOTTOM));
        structure.fillWithBlocks(world, start, 78, -52, 45, 82, -52, 49, Blocks.SANDSTONE.getDefaultState());
        structure.fillWithBlocks(world, start, 78, -51, 20, 78, -50, 21, Blocks.SANDSTONE.getDefaultState());
        structure.fillWithBlocks(world, start, 78, -51, 23, 78, -50, 23, Blocks.SANDSTONE.getDefaultState());
        structure.fillWithBlocks(world, start, 78, -51, 31, 79, -51, 31, Blocks.SANDSTONE_STAIRS.getDefaultState().with(StairsBlock.FACING, Direction.NORTH).with(StairsBlock.WATERLOGGED, false).with(StairsBlock.SHAPE, StairsShape.STRAIGHT).with(StairsBlock.HALF, Half.BOTTOM));
        structure.fillWithBlocks(world, start, 78, -51, 32, 79, -51, 36, Blocks.AIR.getDefaultState());
        structure.fillWithBlocks(world, start, 78, -51, 40, 80, -51, 43, Blocks.AIR.getDefaultState());
        structure.fillWithBlocks(world, start, 78, -51, 44, 79, -50, 44, Blocks.AIR.getDefaultState());
        structure.fillWithBlocks(world, start, 78, -51, 45, 79, -51, 45, Blocks.SANDSTONE_STAIRS.getDefaultState().with(StairsBlock.FACING, Direction.SOUTH).with(StairsBlock.WATERLOGGED, false).with(StairsBlock.SHAPE, StairsShape.STRAIGHT).with(StairsBlock.HALF, Half.BOTTOM));
        structure.fillWithBlocks(world, start, 78, -50, 29, 80, -50, 31, Blocks.AIR.getDefaultState());
        structure.fillWithBlocks(world, start, 78, -50, 32, 79, -50, 35, Blocks.AIR.getDefaultState());
        structure.fillWithBlocks(world, start, 78, -50, 36, 82, -50, 40, Blocks.SANDSTONE.getDefaultState());
        structure.fillWithBlocks(world, start, 78, -50, 41, 80, -50, 43, Blocks.AIR.getDefaultState());
        structure.fillWithBlocks(world, start, 78, -50, 45, 80, -50, 47, Blocks.AIR.getDefaultState());
        structure.fillWithBlocks(world, start, 78, -50, 77, 83, -50, 82, Blocks.SANDSTONE.getDefaultState());
        structure.fillWithBlocks(world, start, 78, -49, 28, 79, -49, 48, Blocks.AIR.getDefaultState());
        structure.fillWithBlocks(world, start, 78, -49, 49, 86, -46, 49, Blocks.SANDSTONE.getDefaultState());
        structure.fillWithBlocks(world, start, 78, -49, 52, 78, -47, 54, Blocks.SANDSTONE.getDefaultState());
        structure.fillWithBlocks(world, start, 78, -49, 55, 78, -49, 64, Blocks.SANDSTONE.getDefaultState());
        structure.fillWithBlocks(world, start, 78, -49, 65, 79, -49, 79, Blocks.AIR.getDefaultState());
        structure.fillWithBlocks(world, start, 78, -49, 80, 80, -49, 82, Blocks.SANDSTONE.getDefaultState());
        structure.fillWithBlocks(world, start, 78, -48, 28, 79, -48, 48, Blocks.AIR.getDefaultState());
        structure.fillWithBlocks(world, start, 78, -48, 56, 78, -47, 60, Blocks.SANDSTONE.getDefaultState());
        structure.fillWithBlocks(world, start, 78, -48, 62, 80, -48, 64, Blocks.SANDSTONE.getDefaultState());
        structure.fillWithBlocks(world, start, 78, -48, 65, 79, -48, 79, Blocks.AIR.getDefaultState());
        structure.fillWithBlocks(world, start, 78, -47, 28, 79, -47, 48, Blocks.AIR.getDefaultState());
        structure.fillWithBlocks(world, start, 78, -47, 55, 78, -47, 64, Blocks.SANDSTONE.getDefaultState());
        structure.fillWithBlocks(world, start, 78, -47, 65, 79, -47, 79, Blocks.AIR.getDefaultState());
        structure.fillWithBlocks(world, start, 78, -47, 80, 80, -47, 82, Blocks.SANDSTONE.getDefaultState());
        structure.fillWithBlocks(world, start, 78, -46, 29, 80, -46, 31, Blocks.AIR.getDefaultState());
        structure.fillWithBlocks(world, start, 78, -46, 32, 85, -41, 32, Blocks.SANDSTONE.getDefaultState());
        structure.fillWithBlocks(world, start, 78, -46, 33, 80, -46, 35, Blocks.AIR.getDefaultState());
        structure.fillWithBlocks(world, start, 78, -46, 36, 85, -42, 36, Blocks.SANDSTONE.getDefaultState());
        structure.fillWithBlocks(world, start, 78, -46, 40, 85, -42, 40, Blocks.SANDSTONE.getDefaultState());
        structure.fillWithBlocks(world, start, 78, -46, 41, 80, -46, 43, Blocks.AIR.getDefaultState());
        structure.fillWithBlocks(world, start, 78, -46, 44, 85, -41, 44, Blocks.SANDSTONE.getDefaultState());
        structure.fillWithBlocks(world, start, 78, -46, 45, 80, -46, 47, Blocks.AIR.getDefaultState());
        structure.fillWithBlocks(world, start, 78, -46, 48, 79, -46, 49, Blocks.SANDSTONE.getDefaultState());
        structure.fillWithBlocks(world, start, 78, -46, 62, 80, -46, 64, Blocks.SANDSTONE.getDefaultState());
        structure.fillWithBlocks(world, start, 78, -46, 65, 79, -46, 79, Blocks.AIR.getDefaultState());
        structure.fillWithBlocks(world, start, 78, -46, 80, 80, -46, 82, Blocks.SANDSTONE.getDefaultState());
        structure.fillWithBlocks(world, start, 78, -45, 37, 80, -45, 39, Blocks.AIR.getDefaultState());
        structure.fillWithBlocks(world, start, 78, -45, 41, 80, -45, 43, Blocks.AIR.getDefaultState());
        structure.fillWithBlocks(world, start, 78, -45, 45, 78, -42, 48, Blocks.SANDSTONE.getDefaultState());
        structure.fillWithBlocks(world, start, 78, -44, 33, 78, -44, 35, Blocks.AIR.getDefaultState());
        structure.fillWithBlocks(world, start, 78, -44, 37, 78, -44, 39, Blocks.AIR.getDefaultState());
        structure.fillWithBlocks(world, start, 78, -44, 41, 78, -44, 43, Blocks.AIR.getDefaultState());
        structure.fillWithBlocks(world, start, 78, -42, 81, 78, -41, 82, Blocks.AIR.getDefaultState());
        structure.fillWithBlocks(world, start, 78, -42, 85, 78, -42, 87, Blocks.STONE_BRICKS.getDefaultState());
        structure.fillWithBlocks(world, start, 78, -41, 9, 81, -40, 9, Blocks.STONE_BRICKS.getDefaultState());
        structure.fillWithBlocks(world, start, 78, -41, 79, 78, -41, 79, Blocks.STONE_BRICKS.getDefaultState());
        structure.fillWithBlocks(world, start, 78, -41, 80, 78, -41, 82, Blocks.AIR.getDefaultState());
        structure.fillWithBlocks(world, start, 78, -41, 83, 78, -41, 84, Blocks.STONE_BRICKS.getDefaultState());
        structure.fillWithBlocks(world, start, 78, -40, 21, 82, -40, 33, Blocks.STONE_BRICKS.getDefaultState());
        structure.fillWithBlocks(world, start, 78, -40, 49, 82, -40, 63, Blocks.STONE_BRICKS.getDefaultState());
        structure.fillWithBlocks(world, start, 78, -40, 64, 81, -40, 90, Blocks.STONE_BRICKS.getDefaultState());
        structure.fillWithBlocks(world, start, 78, -39, 0, 80, -39, 2, Blocks.STONE_BRICKS.getDefaultState());
        structure.fillWithBlocks(world, start, 78, -39, 4, 79, -39, 6, Blocks.STONE_BRICKS.getDefaultState());
        structure.fillWithBlocks(world, start, 78, -39, 7, 80, -39, 9, Blocks.AIR.getDefaultState());
        structure.fillWithBlocks(world, start, 78, -39, 13, 82, -39, 18, Blocks.AIR.getDefaultState());
        structure.fillWithBlocks(world, start, 78, -39, 21, 78, -36, 21, Blocks.STONE_BRICKS.getDefaultState());
        structure.fillWithBlocks(world, start, 78, -39, 22, 78, -39, 22, Blocks.AIR.getDefaultState());
        structure.fillWithBlocks(world, start, 78, -39, 23, 78, -36, 23, Blocks.STONE_BRICKS.getDefaultState());
        structure.fillWithBlocks(world, start, 78, -39, 24, 80, -39, 26, Blocks.AIR.getDefaultState());
        structure.fillWithBlocks(world, start, 78, -39, 28, 78, -39, 28, Blocks.AIR.getDefaultState());
        structure.fillWithBlocks(world, start, 78, -39, 29, 78, -36, 29, Blocks.STONE_BRICKS.getDefaultState());
        structure.fillWithBlocks(world, start, 78, -39, 30, 80, -39, 32, Blocks.AIR.getDefaultState());
        structure.fillWithBlocks(world, start, 78, -39, 33, 78, -38, 34, Blocks.STONE_BRICKS.getDefaultState());
        structure.fillWithBlocks(world, start, 78, -39, 45, 80, -39, 47, Blocks.AIR.getDefaultState());
        structure.fillWithBlocks(world, start, 78, -39, 48, 78, -37, 48, Blocks.STONE_BRICKS.getDefaultState());
        structure.fillWithBlocks(world, start, 78, -39, 49, 78, -39, 49, Blocks.AIR.getDefaultState());
        structure.fillWithBlocks(world, start, 78, -39, 50, 78, -36, 50, Blocks.STONE_BRICKS.getDefaultState());
        structure.fillWithBlocks(world, start, 78, -39, 51, 80, -39, 53, Blocks.AIR.getDefaultState());
        structure.fillWithBlocks(world, start, 78, -39, 54, 78, -37, 56, Blocks.STONE_BRICKS.getDefaultState());
        structure.fillWithBlocks(world, start, 78, -39, 57, 82, -39, 63, Blocks.AIR.getDefaultState());
        structure.fillWithBlocks(world, start, 78, -39, 64, 78, -38, 65, Blocks.STONE_BRICKS.getDefaultState());
        structure.fillWithBlocks(world, start, 78, -39, 66, 78, -39, 66, Blocks.AIR.getDefaultState());
        structure.fillWithBlocks(world, start, 78, -39, 67, 78, -31, 67, Blocks.STONE_BRICKS.getDefaultState());
        structure.fillWithBlocks(world, start, 78, -39, 68, 80, -39, 70, Blocks.AIR.getDefaultState());
        structure.fillWithBlocks(world, start, 78, -39, 71, 78, -31, 71, Blocks.STONE_BRICKS.getDefaultState());
        structure.fillWithBlocks(world, start, 78, -39, 72, 80, -39, 74, Blocks.AIR.getDefaultState());
        structure.fillWithBlocks(world, start, 78, -39, 75, 78, -36, 75, Blocks.STONE_BRICKS.getDefaultState());
        structure.fillWithBlocks(world, start, 78, -39, 76, 78, -39, 76, Blocks.AIR.getDefaultState());
        structure.fillWithBlocks(world, start, 78, -39, 77, 78, -37, 79, Blocks.STONE_BRICKS.getDefaultState());
        structure.fillWithBlocks(world, start, 78, -38, 4, 78, -38, 6, Blocks.SHROOMLIGHT.getDefaultState());
        structure.fillWithBlocks(world, start, 78, -38, 7, 80, -38, 9, Blocks.AIR.getDefaultState());
        structure.fillWithBlocks(world, start, 78, -38, 13, 82, -38, 18, Blocks.AIR.getDefaultState());
        structure.fillWithBlocks(world, start, 78, -38, 22, 78, -38, 22, Blocks.AIR.getDefaultState());
        structure.fillWithBlocks(world, start, 78, -38, 24, 80, -38, 26, Blocks.AIR.getDefaultState());
        structure.fillWithBlocks(world, start, 78, -38, 28, 78, -38, 28, Blocks.AIR.getDefaultState());
        structure.fillWithBlocks(world, start, 78, -38, 30, 80, -38, 32, Blocks.AIR.getDefaultState());
        structure.fillWithBlocks(world, start, 78, -38, 45, 80, -38, 47, Blocks.AIR.getDefaultState());
        structure.fillWithBlocks(world, start, 78, -38, 49, 78, -38, 49, Blocks.AIR.getDefaultState());
        structure.fillWithBlocks(world, start, 78, -38, 51, 80, -38, 53, Blocks.AIR.getDefaultState());
        structure.fillWithBlocks(world, start, 78, -38, 57, 82, -38, 63, Blocks.AIR.getDefaultState());
        structure.fillWithBlocks(world, start, 78, -38, 66, 78, -38, 66, Blocks.AIR.getDefaultState());
        structure.fillWithBlocks(world, start, 78, -38, 68, 80, -38, 70, Blocks.AIR.getDefaultState());
        structure.fillWithBlocks(world, start, 78, -38, 72, 80, -38, 74, Blocks.AIR.getDefaultState());
        structure.fillWithBlocks(world, start, 78, -38, 76, 78, -38, 76, Blocks.AIR.getDefaultState());
        structure.fillWithBlocks(world, start, 78, -37, 2, 79, -37, 3, Blocks.STONE_BRICKS.getDefaultState());
        structure.fillWithBlocks(world, start, 78, -37, 4, 78, -37, 5, Blocks.AIR.getDefaultState());
        structure.fillWithBlocks(world, start, 78, -37, 6, 90, -37, 6, Blocks.STONE_BRICKS.getDefaultState());
        structure.fillWithBlocks(world, start, 78, -37, 7, 82, -37, 18, Blocks.AIR.getDefaultState());
        structure.fillWithBlocks(world, start, 78, -37, 22, 78, -37, 22, Blocks.AIR.getDefaultState());
        structure.fillWithBlocks(world, start, 78, -37, 24, 80, -37, 26, Blocks.AIR.getDefaultState());
        structure.fillWithBlocks(world, start, 78, -37, 27, 78, -36, 27, Blocks.STONE_BRICKS.getDefaultState());
        structure.fillWithBlocks(world, start, 78, -37, 28, 78, -37, 28, Blocks.AIR.getDefaultState());
        structure.fillWithBlocks(world, start, 78, -37, 30, 80, -37, 32, Blocks.AIR.getDefaultState());
        structure.fillWithBlocks(world, start, 78, -37, 33, 78, -36, 34, Blocks.STONE_BRICKS.getDefaultState());
        structure.fillWithBlocks(world, start, 78, -37, 44, 78, -36, 44, Blocks.STONE_BRICKS.getDefaultState());
        structure.fillWithBlocks(world, start, 78, -37, 45, 80, -37, 47, Blocks.AIR.getDefaultState());
        structure.fillWithBlocks(world, start, 78, -37, 49, 78, -37, 49, Blocks.AIR.getDefaultState());
        structure.fillWithBlocks(world, start, 78, -37, 51, 80, -37, 53, Blocks.AIR.getDefaultState());
        structure.fillWithBlocks(world, start, 78, -37, 57, 82, -37, 63, Blocks.AIR.getDefaultState());
        structure.fillWithBlocks(world, start, 78, -37, 64, 78, -37, 65, Blocks.STONE_BRICKS.getDefaultState());
        structure.fillWithBlocks(world, start, 78, -37, 66, 78, -37, 66, Blocks.AIR.getDefaultState());
        structure.fillWithBlocks(world, start, 78, -37, 68, 80, -37, 70, Blocks.AIR.getDefaultState());
        structure.fillWithBlocks(world, start, 78, -37, 72, 80, -37, 74, Blocks.AIR.getDefaultState());
        structure.fillWithBlocks(world, start, 78, -37, 76, 78, -37, 76, Blocks.AIR.getDefaultState());
        structure.fillWithBlocks(world, start, 78, -37, 87, 81, -37, 90, Blocks.STONE_BRICKS.getDefaultState());
        structure.fillWithBlocks(world, start, 78, -36, 4, 78, -36, 6, Blocks.SHROOMLIGHT.getDefaultState());
        structure.fillWithBlocks(world, start, 78, -36, 7, 82, -36, 18, Blocks.AIR.getDefaultState());
        structure.fillWithBlocks(world, start, 78, -36, 19, 78, -36, 19, Blocks.STONE_BRICKS.getDefaultState());
        structure.fillWithBlocks(world, start, 78, -36, 22, 82, -36, 34, Blocks.STONE_BRICKS.getDefaultState());
        structure.fillWithBlocks(world, start, 78, -36, 42, 78, -36, 42, Blocks.STONE_BRICKS.getDefaultState());
        structure.fillWithBlocks(world, start, 78, -36, 45, 78, -36, 45, Blocks.STONE_BRICKS.getDefaultState());
        structure.fillWithBlocks(world, start, 78, -36, 47, 78, -36, 47, Blocks.STONE_BRICKS.getDefaultState());
        structure.fillWithBlocks(world, start, 78, -36, 49, 82, -36, 53, Blocks.STONE_BRICKS.getDefaultState());
        structure.fillWithBlocks(world, start, 78, -36, 55, 79, -36, 56, Blocks.STONE_BRICKS.getDefaultState());
        structure.fillWithBlocks(world, start, 78, -36, 57, 82, -36, 63, Blocks.AIR.getDefaultState());
        structure.fillWithBlocks(world, start, 78, -36, 64, 78, -36, 64, Blocks.STONE_BRICKS.getDefaultState());
        structure.fillWithBlocks(world, start, 78, -36, 66, 80, -36, 70, Blocks.STONE_BRICKS.getDefaultState());
        structure.fillWithBlocks(world, start, 78, -36, 77, 80, -36, 79, Blocks.STONE_BRICKS.getDefaultState());
        structure.fillWithBlocks(world, start, 78, -35, 0, 78, -35, 0, Blocks.STONE_BRICKS.getDefaultState());
        structure.fillWithBlocks(world, start, 78, -35, 2, 79, -35, 3, Blocks.STONE_BRICKS.getDefaultState());
        structure.fillWithBlocks(world, start, 78, -35, 6, 84, -33, 6, Blocks.STONE_BRICKS.getDefaultState());
        structure.fillWithBlocks(world, start, 78, -35, 7, 82, -35, 18, Blocks.AIR.getDefaultState());
        structure.fillWithBlocks(world, start, 78, -35, 19, 78, -35, 20, Blocks.STONE_BRICKS.getDefaultState());
        structure.fillWithBlocks(world, start, 78, -35, 45, 87, -35, 45, Blocks.STONE_BRICKS.getDefaultState());
        structure.fillWithBlocks(world, start, 78, -35, 51, 81, -35, 54, Blocks.STONE_BRICKS.getDefaultState());
        structure.fillWithBlocks(world, start, 78, -35, 55, 78, -35, 57, Blocks.STONE_BRICKS.getDefaultState());
        structure.fillWithBlocks(world, start, 78, -34, 0, 79, -34, 11, Blocks.STONE_BRICKS.getDefaultState());
        structure.fillWithBlocks(world, start, 78, -34, 13, 80, -34, 15, Blocks.STONE_BRICKS.getDefaultState());
        structure.fillWithBlocks(world, start, 78, -34, 16, 79, -34, 20, Blocks.STONE_BRICKS.getDefaultState());
        structure.fillWithBlocks(world, start, 78, -34, 32, 78, -31, 32, Blocks.STONE_BRICKS.getDefaultState());
        structure.fillWithBlocks(world, start, 78, -34, 35, 79, -34, 37, Blocks.AIR.getDefaultState());
        structure.fillWithBlocks(world, start, 78, -34, 38, 78, -34, 40, Blocks.AIR.getDefaultState());
        structure.fillWithBlocks(world, start, 78, -34, 41, 78, -34, 42, Blocks.SANDSTONE.getDefaultState());
        structure.fillWithBlocks(world, start, 78, -34, 44, 82, -34, 44, Blocks.AIR.getDefaultState());
        structure.fillWithBlocks(world, start, 78, -34, 50, 78, -34, 50, Blocks.STONE_BRICKS.getDefaultState());
        structure.fillWithBlocks(world, start, 78, -34, 52, 78, -32, 54, Blocks.STONE_BRICKS.getDefaultState());
        structure.fillWithBlocks(world, start, 78, -34, 56, 80, -34, 58, Blocks.STONE_BRICKS.getDefaultState());
        structure.fillWithBlocks(world, start, 78, -34, 59, 80, -34, 61, Blocks.AIR.getDefaultState());
        structure.fillWithBlocks(world, start, 78, -34, 62, 79, -34, 63, Blocks.STONE_BRICKS.getDefaultState());
        structure.fillWithBlocks(world, start, 78, -34, 64, 78, -34, 65, Blocks.AIR.getDefaultState());
        structure.fillWithBlocks(world, start, 78, -34, 66, 79, -34, 72, Blocks.STONE_BRICKS.getDefaultState());
        structure.fillWithBlocks(world, start, 78, -33, 5, 81, -33, 8, Blocks.STONE_BRICKS.getDefaultState());
        structure.fillWithBlocks(world, start, 78, -33, 10, 80, -33, 12, Blocks.STONE_BRICKS.getDefaultState());
        structure.fillWithBlocks(world, start, 78, -33, 13, 78, -31, 13, Blocks.STONE_BRICKS.getDefaultState());
        structure.fillWithBlocks(world, start, 78, -33, 15, 80, -33, 17, Blocks.STONE_BRICKS.getDefaultState());
        structure.fillWithBlocks(world, start, 78, -33, 18, 78, -33, 20, Blocks.STONE_BRICKS.getDefaultState());
        structure.fillWithBlocks(world, start, 78, -33, 33, 79, -33, 34, Blocks.STONE_BRICKS.getDefaultState());
        structure.fillWithBlocks(world, start, 78, -33, 36, 79, -33, 36, Blocks.SANDSTONE.getDefaultState());
        structure.fillWithBlocks(world, start, 78, -33, 37, 79, -32, 37, Blocks.STONE_BRICKS.getDefaultState());
        structure.fillWithBlocks(world, start, 78, -33, 38, 78, -33, 38, Blocks.AIR.getDefaultState());
        structure.fillWithBlocks(world, start, 78, -33, 40, 78, -31, 40, Blocks.STONE_BRICKS.getDefaultState());
        structure.fillWithBlocks(world, start, 78, -33, 41, 79, -33, 41, Blocks.AIR.getDefaultState());
        structure.fillWithBlocks(world, start, 78, -33, 42, 81, -33, 45, Blocks.STONE_BRICKS.getDefaultState());
        structure.fillWithBlocks(world, start, 78, -33, 49, 80, -33, 51, Blocks.STONE_BRICKS.getDefaultState());
        structure.fillWithBlocks(world, start, 78, -33, 55, 81, -33, 59, Blocks.STONE_BRICKS.getDefaultState());
        structure.fillWithBlocks(world, start, 78, -33, 63, 78, -33, 63, Blocks.STONE_BRICKS.getDefaultState());
        structure.fillWithBlocks(world, start, 78, -33, 65, 81, -33, 68, Blocks.STONE_BRICKS.getDefaultState());
        structure.fillWithBlocks(world, start, 78, -33, 69, 79, -33, 69, Blocks.AIR.getDefaultState());
        structure.fillWithBlocks(world, start, 78, -33, 70, 80, -33, 72, Blocks.STONE_BRICKS.getDefaultState());
        structure.fillWithBlocks(world, start, 78, -33, 76, 79, -33, 78, Blocks.STONE_BRICKS.getDefaultState());
        structure.fillWithBlocks(world, start, 78, -33, 80, 81, -33, 84, Blocks.STONE_BRICKS.getDefaultState());
        structure.fillWithBlocks(world, start, 78, -33, 86, 80, -33, 88, Blocks.STONE_BRICKS.getDefaultState());
        structure.fillWithBlocks(world, start, 78, -32, 1, 79, -32, 7, Blocks.STONE_BRICKS.getDefaultState());
        structure.fillWithBlocks(world, start, 78, -32, 10, 79, -32, 11, Blocks.STONE_BRICKS.getDefaultState());
        structure.fillWithBlocks(world, start, 78, -32, 19, 79, -32, 20, Blocks.STONE_BRICKS.getDefaultState());
        structure.fillWithBlocks(world, start, 78, -32, 36, 80, -32, 36, Blocks.AIR.getDefaultState());
        structure.fillWithBlocks(world, start, 78, -32, 38, 78, -32, 38, Blocks.STONE_BRICKS.getDefaultState());
        structure.fillWithBlocks(world, start, 78, -32, 57, 81, -32, 67, Blocks.STONE_BRICKS.getDefaultState());
        structure.fillWithBlocks(world, start, 78, -32, 68, 79, -32, 69, Blocks.STONE_BRICKS.getDefaultState());
        structure.fillWithBlocks(world, start, 78, -32, 70, 78, -32, 72, Blocks.STONE_BRICKS.getDefaultState());
        structure.fillWithBlocks(world, start, 78, -32, 76, 80, -32, 78, Blocks.STONE_BRICKS.getDefaultState());
        structure.fillWithBlocks(world, start, 78, -32, 80, 79, -32, 88, Blocks.STONE_BRICKS.getDefaultState());
        structure.fillWithBlocks(world, start, 78, -31, 1, 79, -31, 5, Blocks.STONE_BRICKS.getDefaultState());
        structure.fillWithBlocks(world, start, 78, -31, 6, 78, -30, 6, Blocks.SANDSTONE.getDefaultState());
        structure.fillWithBlocks(world, start, 78, -31, 7, 79, -31, 10, Blocks.STONE_BRICKS.getDefaultState());
        structure.fillWithBlocks(world, start, 78, -31, 17, 78, -31, 18, Blocks.STONE_BRICKS.getDefaultState());
        structure.fillWithBlocks(world, start, 78, -31, 31, 80, -31, 33, Blocks.STONE_BRICKS.getDefaultState());
        structure.fillWithBlocks(world, start, 78, -31, 35, 78, -31, 36, Blocks.AIR.getDefaultState());
        structure.fillWithBlocks(world, start, 78, -31, 37, 78, -30, 38, Blocks.SANDSTONE.getDefaultState());
        structure.fillWithBlocks(world, start, 78, -31, 39, 78, -31, 40, Blocks.STONE_BRICKS.getDefaultState());
        structure.fillWithBlocks(world, start, 78, -31, 53, 80, -31, 55, Blocks.STONE_BRICKS.getDefaultState());
        structure.fillWithBlocks(world, start, 78, -31, 57, 78, -30, 57, Blocks.SANDSTONE.getDefaultState());
        structure.fillWithBlocks(world, start, 78, -31, 58, 81, -31, 63, Blocks.STONE_BRICKS.getDefaultState());
        structure.fillWithBlocks(world, start, 78, -31, 64, 78, -31, 64, Blocks.STONE_BRICKS.getDefaultState());
        structure.fillWithBlocks(world, start, 78, -31, 66, 82, -31, 72, Blocks.STONE_BRICKS.getDefaultState());
        structure.fillWithBlocks(world, start, 78, -31, 81, 86, -31, 90, Blocks.STONE_BRICKS.getDefaultState());
        structure.fillWithBlocks(world, start, 78, -30, -6, 78, -28, -6, Blocks.STONE_BRICKS.getDefaultState());
        structure.fillWithBlocks(world, start, 78, -30, -5, 79, -30, -5, Blocks.SANDSTONE.getDefaultState());
        structure.fillWithBlocks(world, start, 78, -30, -4, 78, -30, -4, Blocks.STONE_BRICKS.getDefaultState());
        structure.fillWithBlocks(world, start, 78, -30, 43, 78, -30, 49, Blocks.SANDSTONE.getDefaultState());
        structure.fillWithBlocks(world, start, 78, -30, 50, 80, -30, 50, Blocks.DIRT.getDefaultState());
        structure.fillWithBlocks(world, start, 78, -30, 64, 79, -30, 64, Blocks.DIRT.getDefaultState());
        structure.fillWithBlocks(world, start, 78, -30, 65, 80, -29, 65, Blocks.SANDSTONE.getDefaultState());
        structure.fillWithBlocks(world, start, 78, -29, -5, 78, -29, -5, Blocks.STONE_BRICKS.getDefaultState());
        structure.fillWithBlocks(world, start, 78, -29, -2, 78, -29, 33, Blocks.AIR.getDefaultState());
        structure.fillWithBlocks(world, start, 78, -29, 34, 78, -27, 34, Blocks.IRON_BARS.getDefaultState().with(FourWayBlock.WATERLOGGED, false).with(FourWayBlock.NORTH, true).with(FourWayBlock.SOUTH, true).with(FourWayBlock.EAST, true).with(FourWayBlock.WEST, true));
        structure.fillWithBlocks(world, start, 78, -29, 35, 79, -29, 37, Blocks.AIR.getDefaultState());
        structure.fillWithBlocks(world, start, 78, -29, 50, 79, -29, 51, Blocks.SANDSTONE.getDefaultState());
        structure.fillWithBlocks(world, start, 78, -29, 59, 78, -28, 60, Blocks.SANDSTONE.getDefaultState());
        structure.fillWithBlocks(world, start, 78, -29, 61, 78, -29, 62, Blocks.AIR.getDefaultState());
        structure.fillWithBlocks(world, start, 78, -29, 63, 78, -20, 63, Blocks.SANDSTONE.getDefaultState());
        structure.fillWithBlocks(world, start, 78, -28, -4, 78, -28, -4, Blocks.SANDSTONE.getDefaultState());
        structure.fillWithBlocks(world, start, 78, -28, 35, 79, -28, 41, Blocks.AIR.getDefaultState());
        structure.fillWithBlocks(world, start, 78, -28, 42, 78, -28, 42, Blocks.SANDSTONE.getDefaultState());
        structure.fillWithBlocks(world, start, 78, -28, 44, 78, -28, 44, Blocks.SANDSTONE.getDefaultState());
        structure.fillWithBlocks(world, start, 78, -28, 45, 78, -28, 46, Blocks.DIRT.getDefaultState());
        structure.fillWithBlocks(world, start, 78, -28, 48, 78, -28, 48, Blocks.AIR.getDefaultState());
        structure.fillWithBlocks(world, start, 78, -28, 49, 78, -25, 49, Blocks.SANDSTONE.getDefaultState());
        structure.fillWithBlocks(world, start, 78, -28, 51, 78, -25, 51, Blocks.SANDSTONE.getDefaultState());
        structure.fillWithBlocks(world, start, 78, -28, 65, 79, -28, 65, Blocks.DIRT.getDefaultState());
        structure.fillWithBlocks(world, start, 78, -27, -5, 78, -27, -5, Blocks.STONE_BRICKS.getDefaultState());
        structure.fillWithBlocks(world, start, 78, -27, 37, 80, -27, 40, Blocks.AIR.getDefaultState());
