package mod.arcalitegames.odyssey.world.structure.structures.dungeons.ziggurat;

import mod.arcalitegames.odyssey.world.structure.StructureBase;
import net.minecraft.block.Blocks;
import net.minecraft.block.FourWayBlock;
import net.minecraft.block.SlabBlock;
import net.minecraft.block.StairsBlock;
import net.minecraft.state.properties.Half;
import net.minecraft.state.properties.SlabType;
import net.minecraft.state.properties.StairsShape;
import net.minecraft.util.Direction;
import net.minecraft.util.math.BlockPos;
import net.minecraft.world.World;

public class ZigguratComponent4
{
	public static BlockPos start;
    public static World world;
    public static StructureBase structure;

    public static void init(World worldIn, BlockPos blockPos, StructureBase structureIn)
    {
        world = worldIn; start = blockPos; structure = structureIn;
    }
    
    public static void generatePart41()
    {
        structure.fillWithBlocks(world, start, 151, -32, 43, 151, -32, 44, Blocks.AIR.getDefaultState());
        structure.fillWithBlocks(world, start, 151, -10, 62, 158, -10, 74, Blocks.SANDSTONE.getDefaultState());
        structure.fillWithBlocks(world, start, 151, -9, 66, 151, -7, 66, Blocks.STONE.getDefaultState());
        structure.fillWithBlocks(world, start, 151, -9, 70, 151, -7, 70, Blocks.STONE.getDefaultState());
        structure.fillWithBlocks(world, start, 151, -6, 71, 151, -6, 71, Blocks.SANDSTONE.getDefaultState());
        structure.fillWithBlocks(world, start, 151, -5, 62, 151, -5, 62, Blocks.SANDSTONE.getDefaultState());
        structure.fillWithBlocks(world, start, 151, -5, 64, 152, -5, 65, Blocks.SANDSTONE.getDefaultState());
        structure.fillWithBlocks(world, start, 151, -5, 73, 152, -5, 74, Blocks.SANDSTONE.getDefaultState());
        structure.fillWithBlocks(world, start, 151, -4, 62, 151, -4, 65, Blocks.SANDSTONE.getDefaultState());
        structure.fillWithBlocks(world, start, 151, -4, 67, 152, -4, 72, Blocks.SANDSTONE.getDefaultState());
        structure.fillWithBlocks(world, start, 151, -3, 63, 152, -3, 64, Blocks.SANDSTONE.getDefaultState());
        structure.fillWithBlocks(world, start, 151, -3, 65, 151, -3, 68, Blocks.SANDSTONE.getDefaultState());
        structure.fillWithBlocks(world, start, 151, -3, 70, 153, -3, 72, Blocks.SANDSTONE.getDefaultState());
        structure.fillWithBlocks(world, start, 151, -3, 73, 151, -3, 74, Blocks.SANDSTONE.getDefaultState());
        structure.fillWithBlocks(world, start, 151, -2, 67, 152, -2, 72, Blocks.SANDSTONE.getDefaultState());
        structure.fillWithBlocks(world, start, 151, -2, 73, 151, -2, 74, Blocks.SANDSTONE.getDefaultState());
        structure.fillWithBlocks(world, start, 151, -1, 67, 152, -1, 68, Blocks.SANDSTONE.getDefaultState());
        structure.fillWithBlocks(world, start, 151, -1, 70, 152, -1, 71, Blocks.SANDSTONE.getDefaultState());
        structure.fillWithBlocks(world, start, 151, -1, 73, 152, -1, 74, Blocks.SANDSTONE.getDefaultState());
        structure.fillWithBlocks(world, start, 151, 0, 36, 158, 6, 36, Blocks.SANDSTONE.getDefaultState());
        structure.fillWithBlocks(world, start, 151, 0, 135, 152, 0, 136, Blocks.STONE.getDefaultState());
        structure.fillWithBlocks(world, start, 151, 0, 137, 151, 5, 137, Blocks.SANDSTONE.getDefaultState());
        structure.fillWithBlocks(world, start, 151, 0, 138, 152, 0, 139, Blocks.STONE.getDefaultState());
        structure.fillWithBlocks(world, start, 151, 0, 140, 159, 0, 148, Blocks.SANDSTONE.getDefaultState());
        structure.fillWithBlocks(world, start, 151, 1, 33, 152, 1, 36, Blocks.SANDSTONE.getDefaultState());
        structure.fillWithBlocks(world, start, 151, 1, 111, 152, 1, 112, Blocks.STONE.getDefaultState());
        structure.fillWithBlocks(world, start, 151, 1, 113, 158, 1, 120, Blocks.SANDSTONE.getDefaultState());
        structure.fillWithBlocks(world, start, 151, 1, 122, 160, 1, 131, Blocks.STONE.getDefaultState());
        structure.fillWithBlocks(world, start, 151, 2, 17, 151, 5, 17, Blocks.SANDSTONE.getDefaultState());
        structure.fillWithBlocks(world, start, 151, 2, 18, 152, 2, 20, Blocks.STONE.getDefaultState());
        structure.fillWithBlocks(world, start, 151, 2, 21, 151, 2, 22, Blocks.STONE.getDefaultState());
        structure.fillWithBlocks(world, start, 151, 2, 38, 157, 2, 44, Blocks.SANDSTONE.getDefaultState());
        structure.fillWithBlocks(world, start, 151, 6, 18, 170, 6, 125, Blocks.SANDSTONE.getDefaultState());
        structure.fillWithBlocks(world, start, 151, 8, 64, 152, 8, 65, Blocks.SANDSTONE.getDefaultState());
        structure.fillWithBlocks(world, start, 151, 8, 71, 152, 8, 72, Blocks.SANDSTONE.getDefaultState());
        structure.fillWithBlocks(world, start, 151, 9, 64, 152, 9, 65, Blocks.SANDSTONE.getDefaultState());
        structure.fillWithBlocks(world, start, 151, 9, 71, 152, 9, 72, Blocks.SANDSTONE.getDefaultState());
        structure.fillWithBlocks(world, start, 151, 10, 64, 152, 10, 65, Blocks.SANDSTONE.getDefaultState());
        structure.fillWithBlocks(world, start, 151, 10, 66, 151, 10, 72, Blocks.SANDSTONE.getDefaultState());
        structure.fillWithBlocks(world, start, 151, 11, 64, 151, 11, 65, Blocks.SANDSTONE.getDefaultState());
        structure.fillWithBlocks(world, start, 151, 11, 71, 151, 11, 72, Blocks.SANDSTONE.getDefaultState());
        structure.fillWithBlocks(world, start, 152, -50, 57, 153, -50, 58, Blocks.SANDSTONE.getDefaultState());
        structure.fillWithBlocks(world, start, 152, -50, 59, 152, -50, 59, Blocks.AIR.getDefaultState());
        structure.fillWithBlocks(world, start, 152, -50, 61, 160, -46, 61, Blocks.AIR.getDefaultState());
        structure.fillWithBlocks(world, start, 152, -50, 69, 154, -50, 71, Blocks.AIR.getDefaultState());
        structure.fillWithBlocks(world, start, 152, -50, 72, 153, -50, 73, Blocks.SANDSTONE.getDefaultState());
        structure.fillWithBlocks(world, start, 152, -49, 16, 154, -49, 20, Blocks.AIR.getDefaultState());
        structure.fillWithBlocks(world, start, 152, -49, 35, 156, -49, 41, Blocks.AIR.getDefaultState());
        structure.fillWithBlocks(world, start, 152, -49, 58, 156, -49, 58, Blocks.IRON_BARS.getDefaultState().with(FourWayBlock.WATERLOGGED, false).with(FourWayBlock.NORTH, true).with(FourWayBlock.SOUTH, true).with(FourWayBlock.EAST, true).with(FourWayBlock.WEST, true));
        structure.fillWithBlocks(world, start, 152, -49, 59, 154, -49, 61, Blocks.AIR.getDefaultState());
        structure.fillWithBlocks(world, start, 152, -49, 62, 156, -49, 62, Blocks.IRON_BARS.getDefaultState().with(FourWayBlock.WATERLOGGED, false).with(FourWayBlock.NORTH, true).with(FourWayBlock.SOUTH, true).with(FourWayBlock.EAST, true).with(FourWayBlock.WEST, true));
        structure.fillWithBlocks(world, start, 152, -49, 63, 156, -49, 67, Blocks.AIR.getDefaultState());
        structure.fillWithBlocks(world, start, 152, -49, 68, 156, -49, 68, Blocks.IRON_BARS.getDefaultState().with(FourWayBlock.WATERLOGGED, false).with(FourWayBlock.NORTH, true).with(FourWayBlock.SOUTH, true).with(FourWayBlock.EAST, true).with(FourWayBlock.WEST, true));
        structure.fillWithBlocks(world, start, 152, -49, 72, 156, -49, 72, Blocks.IRON_BARS.getDefaultState().with(FourWayBlock.WATERLOGGED, false).with(FourWayBlock.NORTH, true).with(FourWayBlock.SOUTH, true).with(FourWayBlock.EAST, true).with(FourWayBlock.WEST, true));
        structure.fillWithBlocks(world, start, 152, -48, 15, 152, -47, 15, Blocks.SANDSTONE.getDefaultState());
        structure.fillWithBlocks(world, start, 152, -48, 16, 154, -48, 20, Blocks.AIR.getDefaultState());
        structure.fillWithBlocks(world, start, 152, -48, 35, 156, -48, 41, Blocks.AIR.getDefaultState());
        structure.fillWithBlocks(world, start, 152, -48, 42, 152, -44, 50, Blocks.SANDSTONE.getDefaultState());
        structure.fillWithBlocks(world, start, 152, -48, 58, 156, -48, 72, Blocks.AIR.getDefaultState());
        structure.fillWithBlocks(world, start, 152, -47, 16, 154, -47, 20, Blocks.AIR.getDefaultState());
        structure.fillWithBlocks(world, start, 152, -47, 35, 156, -47, 41, Blocks.AIR.getDefaultState());
        structure.fillWithBlocks(world, start, 152, -47, 58, 156, -47, 72, Blocks.AIR.getDefaultState());
        structure.fillWithBlocks(world, start, 152, -46, 16, 156, -46, 20, Blocks.SANDSTONE.getDefaultState());
        structure.fillWithBlocks(world, start, 152, -46, 35, 156, -46, 41, Blocks.AIR.getDefaultState());
        structure.fillWithBlocks(world, start, 152, -46, 58, 156, -46, 72, Blocks.AIR.getDefaultState());
        structure.fillWithBlocks(world, start, 152, -45, 36, 156, -45, 40, Blocks.AIR.getDefaultState());
        structure.fillWithBlocks(world, start, 152, -45, 41, 154, -45, 43, Blocks.SANDSTONE.getDefaultState());
        structure.fillWithBlocks(world, start, 152, -45, 59, 154, -45, 61, Blocks.AIR.getDefaultState());
        structure.fillWithBlocks(world, start, 152, -45, 63, 156, -45, 67, Blocks.AIR.getDefaultState());
        structure.fillWithBlocks(world, start, 152, -45, 69, 154, -45, 71, Blocks.AIR.getDefaultState());
        structure.fillWithBlocks(world, start, 152, -45, 72, 153, -45, 73, Blocks.SANDSTONE.getDefaultState());
        structure.fillWithBlocks(world, start, 152, -43, 35, 154, -43, 37, Blocks.SANDSTONE.getDefaultState());
        structure.fillWithBlocks(world, start, 152, -42, 35, 152, -42, 37, Blocks.AIR.getDefaultState());
        structure.fillWithBlocks(world, start, 152, -42, 38, 153, -41, 38, Blocks.STONE_BRICKS.getDefaultState());
        structure.fillWithBlocks(world, start, 152, -42, 39, 153, -42, 39, Blocks.AIR.getDefaultState());
        structure.fillWithBlocks(world, start, 152, -42, 40, 152, -42, 42, Blocks.STONE_BRICKS.getDefaultState());
        structure.fillWithBlocks(world, start, 152, -41, 35, 152, -41, 35, Blocks.AIR.getDefaultState());
        structure.fillWithBlocks(world, start, 152, -41, 36, 152, -40, 36, Blocks.STONE_BRICKS.getDefaultState());
        structure.fillWithBlocks(world, start, 152, -41, 39, 152, -41, 40, Blocks.AIR.getDefaultState());
        structure.fillWithBlocks(world, start, 152, -41, 41, 153, -41, 42, Blocks.STONE_BRICKS.getDefaultState());
        structure.fillWithBlocks(world, start, 152, -40, 43, 154, -40, 45, Blocks.STONE_BRICKS.getDefaultState());
        structure.fillWithBlocks(world, start, 152, -39, 31, 152, -39, 31, Blocks.STONE_BRICKS.getDefaultState());
        structure.fillWithBlocks(world, start, 152, -39, 33, 153, -39, 34, Blocks.STONE_BRICKS.getDefaultState());
        structure.fillWithBlocks(world, start, 152, -38, 42, 152, -38, 45, Blocks.STONE_BRICKS.getDefaultState());
        structure.fillWithBlocks(world, start, 152, -37, 33, 153, -37, 34, Blocks.STONE_BRICKS.getDefaultState());
        structure.fillWithBlocks(world, start, 152, -36, 32, 154, -36, 34, Blocks.STONE_BRICKS.getDefaultState());
        structure.fillWithBlocks(world, start, 152, -35, 44, 152, -35, 45, Blocks.STONE_BRICKS.getDefaultState());
        structure.fillWithBlocks(world, start, 152, -34, 32, 152, -31, 35, Blocks.STONE_BRICKS.getDefaultState());
        structure.fillWithBlocks(world, start, 152, -33, 36, 155, -33, 39, Blocks.STONE_BRICKS.getDefaultState());
        structure.fillWithBlocks(world, start, 152, -33, 43, 153, -33, 45, Blocks.STONE_BRICKS.getDefaultState());
        structure.fillWithBlocks(world, start, 152, -32, 43, 153, -32, 45, Blocks.STONE_BRICKS.getDefaultState());
        structure.fillWithBlocks(world, start, 152, -9, 65, 152, -8, 66, Blocks.SANDSTONE.getDefaultState());
        structure.fillWithBlocks(world, start, 152, -9, 67, 154, -9, 69, Blocks.AIR.getDefaultState());
        structure.fillWithBlocks(world, start, 152, -9, 70, 152, -9, 74, Blocks.SANDSTONE.getDefaultState());
        structure.fillWithBlocks(world, start, 152, -8, 62, 153, -8, 63, Blocks.SANDSTONE.getDefaultState());
        structure.fillWithBlocks(world, start, 152, -8, 67, 154, -8, 69, Blocks.AIR.getDefaultState());
        structure.fillWithBlocks(world, start, 152, -8, 70, 152, -8, 74, Blocks.SANDSTONE.getDefaultState());
        structure.fillWithBlocks(world, start, 152, -7, 66, 152, -6, 66, Blocks.SANDSTONE.getDefaultState());
        structure.fillWithBlocks(world, start, 152, -7, 67, 154, -7, 69, Blocks.AIR.getDefaultState());
        structure.fillWithBlocks(world, start, 152, -7, 70, 152, -7, 74, Blocks.SANDSTONE.getDefaultState());
        structure.fillWithBlocks(world, start, 152, -6, 67, 152, -4, 74, Blocks.SANDSTONE.getDefaultState());
        structure.fillWithBlocks(world, start, 152, -5, 62, 155, -5, 65, Blocks.SANDSTONE.getDefaultState());
        structure.fillWithBlocks(world, start, 152, -4, 63, 153, -4, 65, Blocks.SANDSTONE.getDefaultState());
        structure.fillWithBlocks(world, start, 152, -4, 66, 152, -4, 74, Blocks.SANDSTONE.getDefaultState());
        structure.fillWithBlocks(world, start, 152, -3, 62, 154, -3, 64, Blocks.SANDSTONE.getDefaultState());
        structure.fillWithBlocks(world, start, 152, -3, 66, 152, -3, 66, Blocks.SANDSTONE.getDefaultState());
        structure.fillWithBlocks(world, start, 152, -3, 67, 152, -3, 67, Blocks.AIR.getDefaultState());
        structure.fillWithBlocks(world, start, 152, -3, 68, 152, -3, 72, Blocks.SANDSTONE.getDefaultState());
        structure.fillWithBlocks(world, start, 152, -3, 73, 152, -3, 73, Blocks.AIR.getDefaultState());
        structure.fillWithBlocks(world, start, 152, -2, 66, 154, -2, 68, Blocks.SANDSTONE.getDefaultState());
        structure.fillWithBlocks(world, start, 152, -2, 74, 159, -1, 74, Blocks.SANDSTONE.getDefaultState());
        structure.fillWithBlocks(world, start, 152, -1, 69, 155, -1, 72, Blocks.SANDSTONE.getDefaultState());
        structure.fillWithBlocks(world, start, 152, 0, 137, 154, 0, 139, Blocks.STONE.getDefaultState());
        structure.fillWithBlocks(world, start, 152, 1, 37, 154, 1, 39, Blocks.SANDSTONE.getDefaultState());
        structure.fillWithBlocks(world, start, 152, 1, 110, 153, 1, 112, Blocks.STONE.getDefaultState());
        structure.fillWithBlocks(world, start, 152, 2, 17, 152, 2, 20, Blocks.STONE.getDefaultState());
        structure.fillWithBlocks(world, start, 152, 2, 21, 168, 2, 37, Blocks.SANDSTONE.getDefaultState());
        structure.fillWithBlocks(world, start, 152, 2, 129, 160, 2, 129, Blocks.STONE.getDefaultState());
        structure.fillWithBlocks(world, start, 152, 2, 130, 153, 2, 145, Blocks.SANDSTONE.getDefaultState());
        structure.fillWithBlocks(world, start, 152, 3, 141, 154, 3, 143, Blocks.SANDSTONE.getDefaultState());
        structure.fillWithBlocks(world, start, 152, 6, 17, 152, 6, 131, Blocks.SANDSTONE.getDefaultState());
        structure.fillWithBlocks(world, start, 152, 10, 66, 152, 10, 70, Blocks.SANDSTONE_STAIRS.getDefaultState().with(StairsBlock.FACING, Direction.WEST).with(StairsBlock.WATERLOGGED, false).with(StairsBlock.SHAPE, StairsShape.STRAIGHT).with(StairsBlock.HALF, Half.BOTTOM));
        structure.fillWithBlocks(world, start, 152, 10, 71, 153, 10, 72, Blocks.SANDSTONE.getDefaultState());
        structure.fillWithBlocks(world, start, 152, 11, 64, 152, 11, 65, Blocks.SANDSTONE_STAIRS.getDefaultState().with(StairsBlock.FACING, Direction.WEST).with(StairsBlock.WATERLOGGED, false).with(StairsBlock.SHAPE, StairsShape.STRAIGHT).with(StairsBlock.HALF, Half.BOTTOM));
        structure.fillWithBlocks(world, start, 152, 11, 71, 152, 11, 72, Blocks.SANDSTONE_STAIRS.getDefaultState().with(StairsBlock.FACING, Direction.WEST).with(StairsBlock.WATERLOGGED, false).with(StairsBlock.SHAPE, StairsShape.STRAIGHT).with(StairsBlock.HALF, Half.BOTTOM));
        structure.fillWithBlocks(world, start, 153, -50, 59, 155, -50, 61, Blocks.AIR.getDefaultState());
        structure.fillWithBlocks(world, start, 153, -49, 26, 157, -49, 30, Blocks.SANDSTONE.getDefaultState());
        structure.fillWithBlocks(world, start, 153, -49, 31, 153, -47, 33, Blocks.AIR.getDefaultState());
        structure.fillWithBlocks(world, start, 153, -49, 34, 153, -47, 34, Blocks.IRON_BARS.getDefaultState().with(FourWayBlock.WATERLOGGED, false).with(FourWayBlock.NORTH, true).with(FourWayBlock.SOUTH, true).with(FourWayBlock.EAST, true).with(FourWayBlock.WEST, true));
        structure.fillWithBlocks(world, start, 153, -49, 42, 153, -47, 42, Blocks.IRON_BARS.getDefaultState().with(FourWayBlock.WATERLOGGED, false).with(FourWayBlock.NORTH, true).with(FourWayBlock.SOUTH, true).with(FourWayBlock.EAST, true).with(FourWayBlock.WEST, true));
        structure.fillWithBlocks(world, start, 153, -49, 43, 153, -47, 45, Blocks.AIR.getDefaultState());
        structure.fillWithBlocks(world, start, 153, -49, 46, 157, -49, 50, Blocks.SANDSTONE.getDefaultState());
        structure.fillWithBlocks(world, start, 153, -48, 26, 157, -48, 30, Blocks.SANDSTONE.getDefaultState());
        structure.fillWithBlocks(world, start, 153, -48, 46, 157, -48, 50, Blocks.SANDSTONE.getDefaultState());
        structure.fillWithBlocks(world, start, 153, -47, 26, 157, -47, 30, Blocks.SANDSTONE.getDefaultState());
        structure.fillWithBlocks(world, start, 153, -47, 46, 157, -47, 50, Blocks.SANDSTONE.getDefaultState());
        structure.fillWithBlocks(world, start, 153, -46, 26, 157, -46, 30, Blocks.SANDSTONE.getDefaultState());
        structure.fillWithBlocks(world, start, 153, -46, 31, 155, -46, 33, Blocks.AIR.getDefaultState());
        structure.fillWithBlocks(world, start, 153, -46, 34, 172, -44, 34, Blocks.SANDSTONE.getDefaultState());
        structure.fillWithBlocks(world, start, 153, -46, 42, 172, -44, 42, Blocks.SANDSTONE.getDefaultState());
        structure.fillWithBlocks(world, start, 153, -46, 43, 155, -46, 45, Blocks.AIR.getDefaultState());
        structure.fillWithBlocks(world, start, 153, -46, 46, 157, -46, 50, Blocks.SANDSTONE.getDefaultState());
        structure.fillWithBlocks(world, start, 153, -45, 44, 153, -45, 50, Blocks.SANDSTONE.getDefaultState());
        structure.fillWithBlocks(world, start, 153, -44, 37, 155, -44, 39, Blocks.AIR.getDefaultState());
        structure.fillWithBlocks(world, start, 153, -44, 40, 163, -44, 50, Blocks.SANDSTONE.getDefaultState());
        structure.fillWithBlocks(world, start, 153, -43, 42, 157, -43, 42, Blocks.STONE_BRICKS.getDefaultState());
        structure.fillWithBlocks(world, start, 153, -42, 35, 154, -42, 35, Blocks.STONE_BRICKS.getDefaultState());
        structure.fillWithBlocks(world, start, 153, -42, 36, 154, -41, 36, Blocks.AIR.getDefaultState());
        structure.fillWithBlocks(world, start, 153, -42, 37, 153, -41, 38, Blocks.STONE_BRICKS.getDefaultState());
        structure.fillWithBlocks(world, start, 153, -42, 40, 155, -42, 40, Blocks.STONE_BRICKS.getDefaultState());
        structure.fillWithBlocks(world, start, 153, -42, 41, 153, -42, 42, Blocks.AIR.getDefaultState());
        structure.fillWithBlocks(world, start, 153, -41, 35, 153, -40, 35, Blocks.STONE_BRICKS.getDefaultState());
        structure.fillWithBlocks(world, start, 153, -41, 39, 153, -41, 39, Blocks.STONE_BRICKS.getDefaultState());
        structure.fillWithBlocks(world, start, 153, -41, 40, 153, -41, 40, Blocks.AIR.getDefaultState());
        structure.fillWithBlocks(world, start, 153, -40, 31, 155, -40, 45, Blocks.STONE_BRICKS.getDefaultState());
        structure.fillWithBlocks(world, start, 153, -39, 31, 156, -39, 34, Blocks.STONE_BRICKS.getDefaultState());
        structure.fillWithBlocks(world, start, 153, -39, 35, 155, -39, 37, Blocks.AIR.getDefaultState());
        structure.fillWithBlocks(world, start, 153, -39, 39, 155, -39, 41, Blocks.AIR.getDefaultState());
        structure.fillWithBlocks(world, start, 153, -39, 42, 154, -39, 43, Blocks.STONE_BRICKS.getDefaultState());
        structure.fillWithBlocks(world, start, 153, -39, 45, 160, -32, 45, Blocks.STONE_BRICKS.getDefaultState());
        structure.fillWithBlocks(world, start, 153, -38, 31, 154, -38, 32, Blocks.STONE_BRICKS.getDefaultState());
        structure.fillWithBlocks(world, start, 153, -38, 33, 153, -38, 34, Blocks.SHROOMLIGHT.getDefaultState());
        structure.fillWithBlocks(world, start, 153, -38, 35, 155, -38, 37, Blocks.AIR.getDefaultState());
        structure.fillWithBlocks(world, start, 153, -38, 39, 155, -38, 41, Blocks.AIR.getDefaultState());
        structure.fillWithBlocks(world, start, 153, -38, 43, 155, -38, 45, Blocks.STONE_BRICKS.getDefaultState());
        structure.fillWithBlocks(world, start, 153, -37, 31, 156, -37, 34, Blocks.STONE_BRICKS.getDefaultState());
        structure.fillWithBlocks(world, start, 153, -35, 42, 154, -35, 43, Blocks.STONE_BRICKS.getDefaultState());
        structure.fillWithBlocks(world, start, 153, -34, 32, 153, -34, 32, Blocks.STONE_BRICKS.getDefaultState());
        structure.fillWithBlocks(world, start, 153, -34, 35, 155, -34, 37, Blocks.STONE_BRICKS.getDefaultState());
        structure.fillWithBlocks(world, start, 153, -34, 39, 155, -34, 41, Blocks.STONE_BRICKS.getDefaultState());
        structure.fillWithBlocks(world, start, 153, -34, 42, 153, -34, 43, Blocks.STONE_BRICKS.getDefaultState());
        structure.fillWithBlocks(world, start, 153, -33, 41, 153, -33, 41, Blocks.STONE_BRICKS.getDefaultState());
        structure.fillWithBlocks(world, start, 153, -33, 42, 153, -33, 42, Blocks.AIR.getDefaultState());
        structure.fillWithBlocks(world, start, 153, -32, 32, 154, -32, 34, Blocks.STONE_BRICKS.getDefaultState());
        structure.fillWithBlocks(world, start, 153, -32, 36, 153, -31, 45, Blocks.STONE_BRICKS.getDefaultState());
        structure.fillWithBlocks(world, start, 153, -9, 62, 155, -9, 64, Blocks.SANDSTONE.getDefaultState());
        structure.fillWithBlocks(world, start, 153, -9, 65, 153, -1, 65, Blocks.SANDSTONE.getDefaultState());
        structure.fillWithBlocks(world, start, 153, -9, 66, 155, -9, 70, Blocks.AIR.getDefaultState());
        structure.fillWithBlocks(world, start, 153, -9, 71, 153, -9, 72, Blocks.SANDSTONE.getDefaultState());
        structure.fillWithBlocks(world, start, 153, -9, 74, 154, -8, 74, Blocks.SANDSTONE.getDefaultState());
        structure.fillWithBlocks(world, start, 153, -8, 64, 153, -7, 65, Blocks.SANDSTONE.getDefaultState());
        structure.fillWithBlocks(world, start, 153, -8, 66, 155, -8, 70, Blocks.AIR.getDefaultState());
        structure.fillWithBlocks(world, start, 153, -7, 66, 157, -7, 70, Blocks.AIR.getDefaultState());
        structure.fillWithBlocks(world, start, 153, -6, 66, 157, -6, 70, Blocks.AIR.getDefaultState());
        structure.fillWithBlocks(world, start, 153, -6, 71, 153, -1, 71, Blocks.SANDSTONE.getDefaultState());
        structure.fillWithBlocks(world, start, 153, -6, 73, 154, -6, 74, Blocks.SANDSTONE.getDefaultState());
        structure.fillWithBlocks(world, start, 153, -5, 66, 153, -5, 74, Blocks.SANDSTONE.getDefaultState());
        structure.fillWithBlocks(world, start, 153, -4, 62, 153, -1, 65, Blocks.SANDSTONE.getDefaultState());
        structure.fillWithBlocks(world, start, 153, -4, 67, 153, -4, 67, Blocks.SANDSTONE.getDefaultState());
        structure.fillWithBlocks(world, start, 153, -4, 68, 153, -3, 68, Blocks.AIR.getDefaultState());
        structure.fillWithBlocks(world, start, 153, -4, 69, 158, -4, 74, Blocks.SANDSTONE.getDefaultState());
        structure.fillWithBlocks(world, start, 153, -3, 66, 154, -3, 67, Blocks.SANDSTONE.getDefaultState());
        structure.fillWithBlocks(world, start, 153, -3, 69, 156, -3, 72, Blocks.SANDSTONE.getDefaultState());
        structure.fillWithBlocks(world, start, 153, -3, 73, 153, -3, 74, Blocks.AIR.getDefaultState());
        structure.fillWithBlocks(world, start, 153, -2, 70, 155, -2, 72, Blocks.SANDSTONE.getDefaultState());
        structure.fillWithBlocks(world, start, 153, -2, 73, 154, -2, 74, Blocks.SANDSTONE.getDefaultState());
        structure.fillWithBlocks(world, start, 153, -1, 67, 153, -1, 67, Blocks.SANDSTONE.getDefaultState());
        structure.fillWithBlocks(world, start, 153, 0, 2, 153, 0, 9, Blocks.SANDSTONE.getDefaultState());
        structure.fillWithBlocks(world, start, 153, 0, 37, 159, 6, 37, Blocks.SANDSTONE.getDefaultState());
        structure.fillWithBlocks(world, start, 153, 0, 112, 153, 0, 115, Blocks.STONE.getDefaultState());
        structure.fillWithBlocks(world, start, 153, 0, 116, 158, 0, 122, Blocks.SANDSTONE.getDefaultState());
        structure.fillWithBlocks(world, start, 153, 0, 135, 157, 0, 139, Blocks.STONE.getDefaultState());
        structure.fillWithBlocks(world, start, 153, 1, 4, 158, 1, 9, Blocks.SANDSTONE.getDefaultState());
        structure.fillWithBlocks(world, start, 153, 1, 10, 153, 1, 14, Blocks.STONE.getDefaultState());
        structure.fillWithBlocks(world, start, 153, 1, 15, 155, 1, 17, Blocks.SANDSTONE.getDefaultState());
        structure.fillWithBlocks(world, start, 153, 1, 18, 167, 1, 33, Blocks.STONE.getDefaultState());
        structure.fillWithBlocks(world, start, 153, 1, 34, 155, 1, 40, Blocks.SANDSTONE.getDefaultState());
        structure.fillWithBlocks(world, start, 153, 2, 17, 173, 2, 37, Blocks.SANDSTONE.getDefaultState());
        structure.fillWithBlocks(world, start, 153, 8, 64, 154, 8, 65, Blocks.SANDSTONE.getDefaultState());
        structure.fillWithBlocks(world, start, 153, 8, 71, 154, 8, 72, Blocks.SANDSTONE.getDefaultState());
        structure.fillWithBlocks(world, start, 153, 9, 64, 154, 9, 65, Blocks.SANDSTONE.getDefaultState());
        structure.fillWithBlocks(world, start, 153, 9, 71, 154, 9, 72, Blocks.SANDSTONE.getDefaultState());
        structure.fillWithBlocks(world, start, 153, 10, 64, 154, 10, 65, Blocks.SANDSTONE.getDefaultState());
        structure.fillWithBlocks(world, start, 153, 10, 66, 153, 10, 70, Blocks.SANDSTONE_SLAB.getDefaultState().with(SlabBlock.TYPE, SlabType.BOTTOM).with(SlabBlock.WATERLOGGED, false));
        structure.fillWithBlocks(world, start, 153, 11, 64, 153, 11, 65, Blocks.SANDSTONE_SLAB.getDefaultState().with(SlabBlock.TYPE, SlabType.BOTTOM).with(SlabBlock.WATERLOGGED, false));
        structure.fillWithBlocks(world, start, 153, 11, 71, 153, 11, 72, Blocks.SANDSTONE_SLAB.getDefaultState().with(SlabBlock.TYPE, SlabType.BOTTOM).with(SlabBlock.WATERLOGGED, false));
        structure.fillWithBlocks(world, start, 154, -51, 59, 156, -51, 61, Blocks.SANDSTONE.getDefaultState());
        structure.fillWithBlocks(world, start, 154, -51, 69, 156, -51, 71, Blocks.SANDSTONE.getDefaultState());
        structure.fillWithBlocks(world, start, 154, -50, 57, 155, -50, 58, Blocks.SANDSTONE.getDefaultState());
        structure.fillWithBlocks(world, start, 154, -50, 72, 155, -50, 73, Blocks.SANDSTONE.getDefaultState());
        structure.fillWithBlocks(world, start, 154, -49, 31, 154, -49, 31, Blocks.AIR.getDefaultState());
        structure.fillWithBlocks(world, start, 154, -49, 33, 154, -48, 43, Blocks.AIR.getDefaultState());
        structure.fillWithBlocks(world, start, 154, -49, 45, 155, -48, 45, Blocks.AIR.getDefaultState());
        structure.fillWithBlocks(world, start, 154, -49, 69, 156, -49, 71, Blocks.AIR.getDefaultState());
        structure.fillWithBlocks(world, start, 154, -48, 15, 154, -48, 15, Blocks.SANDSTONE.getDefaultState());
        structure.fillWithBlocks(world, start, 154, -48, 21, 158, -47, 21, Blocks.SANDSTONE.getDefaultState());
        structure.fillWithBlocks(world, start, 154, -48, 31, 155, -48, 33, Blocks.AIR.getDefaultState());
        structure.fillWithBlocks(world, start, 154, -48, 44, 155, -48, 45, Blocks.AIR.getDefaultState());
        structure.fillWithBlocks(world, start, 154, -47, 31, 155, -47, 33, Blocks.AIR.getDefaultState());
        structure.fillWithBlocks(world, start, 154, -47, 34, 155, -47, 34, Blocks.IRON_BARS.getDefaultState().with(FourWayBlock.WATERLOGGED, false).with(FourWayBlock.NORTH, true).with(FourWayBlock.SOUTH, true).with(FourWayBlock.EAST, true).with(FourWayBlock.WEST, true));
        structure.fillWithBlocks(world, start, 154, -47, 42, 155, -47, 42, Blocks.IRON_BARS.getDefaultState().with(FourWayBlock.WATERLOGGED, false).with(FourWayBlock.NORTH, true).with(FourWayBlock.SOUTH, true).with(FourWayBlock.EAST, true).with(FourWayBlock.WEST, true));
        structure.fillWithBlocks(world, start, 154, -47, 43, 155, -47, 45, Blocks.AIR.getDefaultState());
        structure.fillWithBlocks(world, start, 154, -45, 26, 159, -45, 31, Blocks.SANDSTONE.getDefaultState());
        structure.fillWithBlocks(world, start, 154, -45, 33, 156, -45, 35, Blocks.SANDSTONE.getDefaultState());
        structure.fillWithBlocks(world, start, 154, -45, 45, 159, -45, 50, Blocks.SANDSTONE.getDefaultState());
        structure.fillWithBlocks(world, start, 154, -45, 72, 155, -45, 73, Blocks.SANDSTONE.getDefaultState());
        structure.fillWithBlocks(world, start, 154, -44, 59, 154, -44, 59, Blocks.SANDSTONE.getDefaultState());
        structure.fillWithBlocks(world, start, 154, -44, 61, 157, -44, 64, Blocks.SANDSTONE.getDefaultState());
        structure.fillWithBlocks(world, start, 154, -44, 66, 157, -44, 69, Blocks.SANDSTONE.getDefaultState());
        structure.fillWithBlocks(world, start, 154, -44, 71, 156, -44, 73, Blocks.SANDSTONE.getDefaultState());
        structure.fillWithBlocks(world, start, 154, -43, 39, 156, -43, 41, Blocks.SANDSTONE.getDefaultState());
        structure.fillWithBlocks(world, start, 154, -42, 37, 154, -40, 37, Blocks.STONE_BRICKS.getDefaultState());
        structure.fillWithBlocks(world, start, 154, -42, 38, 155, -42, 38, Blocks.AIR.getDefaultState());
        structure.fillWithBlocks(world, start, 154, -42, 39, 155, -42, 40, Blocks.STONE_BRICKS.getDefaultState());
        structure.fillWithBlocks(world, start, 154, -42, 41, 155, -41, 41, Blocks.AIR.getDefaultState());
        structure.fillWithBlocks(world, start, 154, -42, 42, 157, -42, 42, Blocks.STONE_BRICKS.getDefaultState());
        structure.fillWithBlocks(world, start, 154, -41, 35, 154, -41, 36, Blocks.AIR.getDefaultState());
        structure.fillWithBlocks(world, start, 154, -41, 38, 155, -41, 39, Blocks.STONE_BRICKS.getDefaultState());
        structure.fillWithBlocks(world, start, 154, -41, 40, 154, -40, 40, Blocks.STONE_BRICKS.getDefaultState());
        structure.fillWithBlocks(world, start, 154, -41, 42, 154, -35, 42, Blocks.STONE_BRICKS.getDefaultState());
        structure.fillWithBlocks(world, start, 154, -39, 38, 156, -39, 41, Blocks.AIR.getDefaultState());
        structure.fillWithBlocks(world, start, 154, -39, 44, 155, -39, 45, Blocks.STONE_BRICKS.getDefaultState());
        structure.fillWithBlocks(world, start, 154, -38, 33, 155, -38, 34, Blocks.STONE_BRICKS.getDefaultState());
        structure.fillWithBlocks(world, start, 154, -38, 38, 156, -38, 41, Blocks.AIR.getDefaultState());
        structure.fillWithBlocks(world, start, 154, -37, 43, 156, -37, 45, Blocks.STONE_BRICKS.getDefaultState());
        structure.fillWithBlocks(world, start, 154, -36, 44, 155, -36, 45, Blocks.STONE_BRICKS.getDefaultState());
        structure.fillWithBlocks(world, start, 154, -35, 32, 156, -35, 34, Blocks.STONE_BRICKS.getDefaultState());
        structure.fillWithBlocks(world, start, 154, -35, 44, 154, -35, 45, Blocks.STONE_BRICKS.getDefaultState());
        structure.fillWithBlocks(world, start, 154, -34, 32, 155, -34, 41, Blocks.STONE_BRICKS.getDefaultState());
        structure.fillWithBlocks(world, start, 154, -34, 43, 156, -34, 45, Blocks.STONE_BRICKS.getDefaultState());
        structure.fillWithBlocks(world, start, 154, -33, 35, 158, -33, 42, Blocks.STONE_BRICKS.getDefaultState());
        structure.fillWithBlocks(world, start, 154, -33, 44, 155, -33, 45, Blocks.STONE_BRICKS.getDefaultState());
        structure.fillWithBlocks(world, start, 154, -32, 35, 155, -32, 36, Blocks.STONE_BRICKS.getDefaultState());
        structure.fillWithBlocks(world, start, 154, -32, 38, 154, -32, 38, Blocks.STONE_BRICKS.getDefaultState());
        structure.fillWithBlocks(world, start, 154, -32, 40, 155, -32, 41, Blocks.STONE_BRICKS.getDefaultState());
        structure.fillWithBlocks(world, start, 154, -32, 42, 155, -32, 42, Blocks.AIR.getDefaultState());
        structure.fillWithBlocks(world, start, 154, -32, 43, 154, -32, 43, Blocks.STONE_BRICKS.getDefaultState());
        structure.fillWithBlocks(world, start, 154, -31, 32, 160, -31, 39, Blocks.STONE_BRICKS.getDefaultState());
        structure.fillWithBlocks(world, start, 154, -9, 65, 156, -9, 67, Blocks.AIR.getDefaultState());
        structure.fillWithBlocks(world, start, 154, -9, 71, 158, -6, 71, Blocks.AIR.getDefaultState());
        structure.fillWithBlocks(world, start, 154, -9, 72, 156, -9, 74, Blocks.SANDSTONE.getDefaultState());
        structure.fillWithBlocks(world, start, 154, -8, 62, 156, -8, 64, Blocks.SANDSTONE.getDefaultState());
        structure.fillWithBlocks(world, start, 154, -8, 65, 156, -8, 67, Blocks.AIR.getDefaultState());
        structure.fillWithBlocks(world, start, 154, -8, 72, 155, -8, 73, Blocks.SANDSTONE.getDefaultState());
        structure.fillWithBlocks(world, start, 154, -7, 62, 156, -7, 64, Blocks.SANDSTONE.getDefaultState());
        structure.fillWithBlocks(world, start, 154, -7, 65, 158, -7, 71, Blocks.AIR.getDefaultState());
        structure.fillWithBlocks(world, start, 154, -7, 72, 156, -7, 74, Blocks.SANDSTONE.getDefaultState());
        structure.fillWithBlocks(world, start, 154, -6, 62, 156, -6, 64, Blocks.SANDSTONE.getDefaultState());
        structure.fillWithBlocks(world, start, 154, -6, 65, 158, -6, 71, Blocks.AIR.getDefaultState());
        structure.fillWithBlocks(world, start, 154, -6, 72, 156, -6, 74, Blocks.SANDSTONE.getDefaultState());
        structure.fillWithBlocks(world, start, 154, -5, 66, 154, -1, 66, Blocks.SANDSTONE.getDefaultState());
        structure.fillWithBlocks(world, start, 154, -5, 67, 156, -5, 69, Blocks.AIR.getDefaultState());
        structure.fillWithBlocks(world, start, 154, -5, 70, 154, -5, 74, Blocks.SANDSTONE.getDefaultState());
        structure.fillWithBlocks(world, start, 154, -4, 62, 154, -4, 62, Blocks.SANDSTONE.getDefaultState());
        structure.fillWithBlocks(world, start, 154, -4, 64, 155, -4, 74, Blocks.SANDSTONE.getDefaultState());
        structure.fillWithBlocks(world, start, 154, -3, 65, 157, -3, 72, Blocks.SANDSTONE.getDefaultState());
        structure.fillWithBlocks(world, start, 154, -3, 73, 154, -3, 74, Blocks.SANDSTONE.getDefaultState());
        structure.fillWithBlocks(world, start, 154, -2, 62, 156, -2, 64, Blocks.SANDSTONE.getDefaultState());
        structure.fillWithBlocks(world, start, 154, -2, 65, 154, -2, 74, Blocks.SANDSTONE.getDefaultState());
        structure.fillWithBlocks(world, start, 154, -1, 67, 155, -1, 74, Blocks.SANDSTONE.getDefaultState());
        structure.fillWithBlocks(world, start, 154, 0, 3, 160, 0, 9, Blocks.SANDSTONE.getDefaultState());
        structure.fillWithBlocks(world, start, 154, 0, 32, 169, 1, 32, Blocks.STONE.getDefaultState());
        structure.fillWithBlocks(world, start, 154, 0, 33, 155, 0, 37, Blocks.SANDSTONE.getDefaultState());
        structure.fillWithBlocks(world, start, 154, 0, 112, 154, 0, 112, Blocks.SANDSTONE.getDefaultState());
        structure.fillWithBlocks(world, start, 154, 0, 113, 154, 0, 115, Blocks.STONE.getDefaultState());
        structure.fillWithBlocks(world, start, 154, 1, 10, 161, 1, 17, Blocks.SANDSTONE.getDefaultState());
        structure.fillWithBlocks(world, start, 154, 1, 41, 162, 6, 41, Blocks.SANDSTONE.getDefaultState());
        structure.fillWithBlocks(world, start, 154, 1, 42, 155, 1, 43, Blocks.STONE.getDefaultState());
        structure.fillWithBlocks(world, start, 154, 1, 44, 156, 3, 44, Blocks.SANDSTONE.getDefaultState());
        structure.fillWithBlocks(world, start, 154, 1, 45, 155, 1, 110, Blocks.STONE.getDefaultState());
        structure.fillWithBlocks(world, start, 154, 1, 112, 161, 1, 119, Blocks.SANDSTONE.getDefaultState());
        structure.fillWithBlocks(world, start, 154, 1, 147, 160, 1, 147, Blocks.SANDSTONE.getDefaultState());
        structure.fillWithBlocks(world, start, 154, 2, 121, 179, 6, 121, Blocks.SANDSTONE.getDefaultState());
        structure.fillWithBlocks(world, start, 154, 2, 122, 155, 2, 130, Blocks.STONE.getDefaultState());
        structure.fillWithBlocks(world, start, 154, 2, 131, 154, 2, 145, Blocks.SANDSTONE.getDefaultState());
        structure.fillWithBlocks(world, start, 154, 9, 66, 154, 9, 72, Blocks.SANDSTONE.getDefaultState());
        structure.fillWithBlocks(world, start, 154, 10, 71, 154, 10, 72, Blocks.SANDSTONE.getDefaultState());
        structure.fillWithBlocks(world, start, 155, -51, 63, 155, -50, 67, Blocks.SANDSTONE.getDefaultState());
        structure.fillWithBlocks(world, start, 155, -50, 62, 157, -50, 68, Blocks.SANDSTONE.getDefaultState());
        structure.fillWithBlocks(world, start, 155, -50, 69, 156, -50, 71, Blocks.AIR.getDefaultState());
        structure.fillWithBlocks(world, start, 155, -49, 16, 155, -46, 16, Blocks.SANDSTONE.getDefaultState());
        structure.fillWithBlocks(world, start, 155, -49, 17, 155, -47, 19, Blocks.AIR.getDefaultState());
        structure.fillWithBlocks(world, start, 155, -49, 20, 155, -49, 21, Blocks.SANDSTONE.getDefaultState());
        structure.fillWithBlocks(world, start, 155, -49, 31, 155, -47, 33, Blocks.AIR.getDefaultState());
        structure.fillWithBlocks(world, start, 155, -49, 34, 155, -47, 34, Blocks.IRON_BARS.getDefaultState().with(FourWayBlock.WATERLOGGED, false).with(FourWayBlock.NORTH, true).with(FourWayBlock.SOUTH, true).with(FourWayBlock.EAST, true).with(FourWayBlock.WEST, true));
        structure.fillWithBlocks(world, start, 155, -49, 42, 155, -47, 42, Blocks.IRON_BARS.getDefaultState().with(FourWayBlock.WATERLOGGED, false).with(FourWayBlock.NORTH, true).with(FourWayBlock.SOUTH, true).with(FourWayBlock.EAST, true).with(FourWayBlock.WEST, true));
        structure.fillWithBlocks(world, start, 155, -49, 43, 155, -47, 45, Blocks.AIR.getDefaultState());
        structure.fillWithBlocks(world, start, 155, -49, 59, 157, -49, 61, Blocks.AIR.getDefaultState());
        structure.fillWithBlocks(world, start, 155, -48, 15, 155, -47, 16, Blocks.SANDSTONE.getDefaultState());
        structure.fillWithBlocks(world, start, 155, -48, 20, 155, -48, 21, Blocks.SANDSTONE.getDefaultState());
        structure.fillWithBlocks(world, start, 155, -47, 20, 155, -47, 21, Blocks.SANDSTONE.getDefaultState());
        structure.fillWithBlocks(world, start, 155, -45, 32, 158, -45, 35, Blocks.SANDSTONE.getDefaultState());
        structure.fillWithBlocks(world, start, 155, -45, 41, 164, -45, 50, Blocks.SANDSTONE.getDefaultState());
        structure.fillWithBlocks(world, start, 155, -45, 59, 156, -45, 61, Blocks.AIR.getDefaultState());
        structure.fillWithBlocks(world, start, 155, -45, 69, 156, -45, 71, Blocks.AIR.getDefaultState());
        structure.fillWithBlocks(world, start, 155, -44, 59, 158, -44, 73, Blocks.SANDSTONE.getDefaultState());
        structure.fillWithBlocks(world, start, 155, -43, 35, 159, -43, 41, Blocks.SANDSTONE.getDefaultState());
        structure.fillWithBlocks(world, start, 155, -42, 35, 156, -42, 36, Blocks.AIR.getDefaultState());
        structure.fillWithBlocks(world, start, 155, -42, 37, 155, -42, 38, Blocks.AIR.getDefaultState());
        structure.fillWithBlocks(world, start, 155, -41, 36, 156, -41, 38, Blocks.STONE_BRICKS.getDefaultState());
        structure.fillWithBlocks(world, start, 155, -41, 40, 155, -41, 42, Blocks.AIR.getDefaultState());
        structure.fillWithBlocks(world, start, 155, -39, 42, 158, -39, 45, Blocks.STONE_BRICKS.getDefaultState());
        structure.fillWithBlocks(world, start, 155, -38, 31, 155, -37, 34, Blocks.STONE_BRICKS.getDefaultState());
        structure.fillWithBlocks(world, start, 155, -38, 42, 155, -36, 45, Blocks.STONE_BRICKS.getDefaultState());
        structure.fillWithBlocks(world, start, 155, -36, 33, 156, -36, 34, Blocks.STONE_BRICKS.getDefaultState());
        structure.fillWithBlocks(world, start, 155, -35, 42, 156, -35, 43, Blocks.STONE_BRICKS.getDefaultState());
        structure.fillWithBlocks(world, start, 155, -34, 42, 156, -34, 45, Blocks.STONE_BRICKS.getDefaultState());
        structure.fillWithBlocks(world, start, 155, -33, 32, 156, -33, 45, Blocks.STONE_BRICKS.getDefaultState());
        structure.fillWithBlocks(world, start, 155, -32, 32, 155, -31, 32, Blocks.STONE_BRICKS.getDefaultState());
        structure.fillWithBlocks(world, start, 155, -32, 33, 156, -32, 33, Blocks.AIR.getDefaultState());
        structure.fillWithBlocks(world, start, 155, -32, 34, 157, -32, 38, Blocks.STONE_BRICKS.getDefaultState());
        structure.fillWithBlocks(world, start, 155, -32, 39, 155, -31, 41, Blocks.STONE_BRICKS.getDefaultState());
        structure.fillWithBlocks(world, start, 155, -32, 43, 155, -31, 45, Blocks.STONE_BRICKS.getDefaultState());
        structure.fillWithBlocks(world, start, 155, -5, 66, 157, -5, 70, Blocks.AIR.getDefaultState());
        structure.fillWithBlocks(world, start, 155, -5, 71, 158, -5, 74, Blocks.SANDSTONE.getDefaultState());
        structure.fillWithBlocks(world, start, 155, -4, 62, 156, -4, 63, Blocks.SANDSTONE.getDefaultState());
        structure.fillWithBlocks(world, start, 155, -3, 62, 156, -3, 63, Blocks.SANDSTONE.getDefaultState());
        structure.fillWithBlocks(world, start, 155, -3, 64, 155, -3, 72, Blocks.SANDSTONE.getDefaultState());
        structure.fillWithBlocks(world, start, 155, -3, 73, 155, -2, 73, Blocks.AIR.getDefaultState());
        structure.fillWithBlocks(world, start, 155, -3, 74, 159, -1, 74, Blocks.SANDSTONE.getDefaultState());
        structure.fillWithBlocks(world, start, 155, -2, 66, 159, -2, 71, Blocks.SANDSTONE.getDefaultState());
        structure.fillWithBlocks(world, start, 155, -1, 62, 158, -1, 65, Blocks.SANDSTONE.getDefaultState());
        structure.fillWithBlocks(world, start, 155, -1, 66, 156, -1, 68, Blocks.SANDSTONE.getDefaultState());
        structure.fillWithBlocks(world, start, 155, 0, 38, 155, 0, 38, Blocks.SANDSTONE.getDefaultState());
        structure.fillWithBlocks(world, start, 155, 0, 39, 155, 0, 111, Blocks.STONE.getDefaultState());
        structure.fillWithBlocks(world, start, 155, 0, 112, 157, 0, 114, Blocks.SANDSTONE.getDefaultState());
        structure.fillWithBlocks(world, start, 155, 1, 111, 162, 1, 118, Blocks.SANDSTONE.getDefaultState());
        structure.fillWithBlocks(world, start, 155, 2, 131, 156, 2, 131, Blocks.STONE.getDefaultState());
        structure.fillWithBlocks(world, start, 155, 2, 132, 167, 2, 144, Blocks.SANDSTONE.getDefaultState());
        structure.fillWithBlocks(world, start, 155, 3, 141, 157, 3, 143, Blocks.SANDSTONE.getDefaultState());
        structure.fillWithBlocks(world, start, 155, 7, 64, 160, 7, 72, Blocks.SANDSTONE.getDefaultState());
        structure.fillWithBlocks(world, start, 155, 8, 64, 156, 8, 65, Blocks.SANDSTONE.getDefaultState());
        structure.fillWithBlocks(world, start, 155, 8, 71, 156, 8, 72, Blocks.SANDSTONE.getDefaultState());
        structure.fillWithBlocks(world, start, 155, 9, 64, 156, 9, 65, Blocks.SANDSTONE.getDefaultState());
        structure.fillWithBlocks(world, start, 155, 9, 66, 155, 9, 70, Blocks.SANDSTONE_STAIRS.getDefaultState().with(StairsBlock.FACING, Direction.WEST).with(StairsBlock.WATERLOGGED, false).with(StairsBlock.SHAPE, StairsShape.STRAIGHT).with(StairsBlock.HALF, Half.BOTTOM));
        structure.fillWithBlocks(world, start, 155, 9, 71, 156, 9, 72, Blocks.SANDSTONE.getDefaultState());
        structure.fillWithBlocks(world, start, 155, 10, 64, 155, 10, 65, Blocks.SANDSTONE_STAIRS.getDefaultState().with(StairsBlock.FACING, Direction.WEST).with(StairsBlock.WATERLOGGED, false).with(StairsBlock.SHAPE, StairsShape.STRAIGHT).with(StairsBlock.HALF, Half.BOTTOM));
        structure.fillWithBlocks(world, start, 155, 10, 71, 155, 10, 72, Blocks.SANDSTONE_STAIRS.getDefaultState().with(StairsBlock.FACING, Direction.WEST).with(StairsBlock.WATERLOGGED, false).with(StairsBlock.SHAPE, StairsShape.STRAIGHT).with(StairsBlock.HALF, Half.BOTTOM));
        structure.fillWithBlocks(world, start, 156, -50, 16, 160, -50, 20, Blocks.SANDSTONE.getDefaultState());
        structure.fillWithBlocks(world, start, 156, -50, 57, 157, -50, 58, Blocks.SANDSTONE.getDefaultState());
        structure.fillWithBlocks(world, start, 156, -50, 59, 156, -48, 61, Blocks.AIR.getDefaultState());
        structure.fillWithBlocks(world, start, 156, -50, 72, 157, -50, 73, Blocks.SANDSTONE.getDefaultState());
        structure.fillWithBlocks(world, start, 156, -49, 16, 156, -49, 17, Blocks.AIR.getDefaultState());
        structure.fillWithBlocks(world, start, 156, -49, 20, 156, -47, 20, Blocks.AIR.getDefaultState());
        structure.fillWithBlocks(world, start, 156, -49, 31, 159, -49, 34, Blocks.SANDSTONE.getDefaultState());
        structure.fillWithBlocks(world, start, 156, -49, 42, 164, -49, 50, Blocks.SANDSTONE.getDefaultState());
        structure.fillWithBlocks(world, start, 156, -48, 15, 156, -48, 15, Blocks.SANDSTONE.getDefaultState());
        structure.fillWithBlocks(world, start, 156, -48, 16, 156, -48, 20, Blocks.AIR.getDefaultState());
        structure.fillWithBlocks(world, start, 156, -48, 31, 159, -48, 34, Blocks.SANDSTONE.getDefaultState());
        structure.fillWithBlocks(world, start, 156, -48, 42, 159, -48, 50, Blocks.SANDSTONE.getDefaultState());
        structure.fillWithBlocks(world, start, 156, -47, 16, 156, -47, 20, Blocks.AIR.getDefaultState());
        structure.fillWithBlocks(world, start, 156, -47, 31, 159, -47, 34, Blocks.SANDSTONE.getDefaultState());
        structure.fillWithBlocks(world, start, 156, -47, 42, 164, -47, 50, Blocks.SANDSTONE.getDefaultState());
        structure.fillWithBlocks(world, start, 156, -46, 31, 159, -46, 34, Blocks.SANDSTONE.getDefaultState());
        structure.fillWithBlocks(world, start, 156, -46, 43, 163, -46, 50, Blocks.SANDSTONE.getDefaultState());
        structure.fillWithBlocks(world, start, 156, -45, 72, 157, -45, 73, Blocks.SANDSTONE.getDefaultState());
        structure.fillWithBlocks(world, start, 156, -44, 37, 158, -44, 39, Blocks.AIR.getDefaultState());
        structure.fillWithBlocks(world, start, 156, -43, 26, 163, -43, 33, Blocks.SANDSTONE.getDefaultState());
        structure.fillWithBlocks(world, start, 156, -42, 26, 163, -42, 33, Blocks.SANDSTONE.getDefaultState());
        structure.fillWithBlocks(world, start, 156, -42, 37, 157, -42, 38, Blocks.STONE_BRICKS.getDefaultState());
        structure.fillWithBlocks(world, start, 156, -42, 39, 156, -42, 40, Blocks.AIR.getDefaultState());
        structure.fillWithBlocks(world, start, 156, -42, 41, 157, -42, 42, Blocks.STONE_BRICKS.getDefaultState());
        structure.fillWithBlocks(world, start, 156, -41, 26, 163, -41, 33, Blocks.SANDSTONE.getDefaultState());
        structure.fillWithBlocks(world, start, 156, -41, 35, 157, -41, 36, Blocks.STONE_BRICKS.getDefaultState());
        structure.fillWithBlocks(world, start, 156, -41, 40, 157, -41, 42, Blocks.STONE_BRICKS.getDefaultState());
        structure.fillWithBlocks(world, start, 156, -40, 31, 156, -39, 32, Blocks.STONE_BRICKS.getDefaultState());
        structure.fillWithBlocks(world, start, 156, -40, 43, 160, -39, 43, Blocks.STONE_BRICKS.getDefaultState());
        structure.fillWithBlocks(world, start, 156, -40, 44, 157, -40, 44, Blocks.AIR.getDefaultState());
        structure.fillWithBlocks(world, start, 156, -40, 45, 160, -36, 45, Blocks.STONE_BRICKS.getDefaultState());
        structure.fillWithBlocks(world, start, 156, -39, 35, 156, -35, 41, Blocks.AIR.getDefaultState());
        structure.fillWithBlocks(world, start, 156, -38, 31, 156, -38, 31, Blocks.STONE_BRICKS.getDefaultState());
        structure.fillWithBlocks(world, start, 156, -38, 33, 157, -38, 34, Blocks.STONE_BRICKS.getDefaultState());
        structure.fillWithBlocks(world, start, 156, -38, 42, 156, -38, 42, Blocks.STONE_BRICKS.getDefaultState());
        structure.fillWithBlocks(world, start, 156, -38, 44, 156, -38, 45, Blocks.STONE_BRICKS.getDefaultState());
        structure.fillWithBlocks(world, start, 156, -37, 42, 157, -37, 45, Blocks.STONE_BRICKS.getDefaultState());
        structure.fillWithBlocks(world, start, 156, -36, 32, 158, -36, 34, Blocks.STONE_BRICKS.getDefaultState());
        structure.fillWithBlocks(world, start, 156, -36, 42, 157, -36, 45, Blocks.STONE_BRICKS.getDefaultState());
        structure.fillWithBlocks(world, start, 156, -35, 44, 157, -35, 45, Blocks.STONE_BRICKS.getDefaultState());
        structure.fillWithBlocks(world, start, 156, -34, 32, 158, -34, 32, Blocks.AIR.getDefaultState());
        structure.fillWithBlocks(world, start, 156, -34, 33, 159, -34, 36, Blocks.STONE_BRICKS.getDefaultState());
        structure.fillWithBlocks(world, start, 156, -34, 37, 156, -33, 45, Blocks.STONE_BRICKS.getDefaultState());
        structure.fillWithBlocks(world, start, 156, -32, 32, 156, -32, 33, Blocks.AIR.getDefaultState());
        structure.fillWithBlocks(world, start, 156, -32, 39, 156, -32, 40, Blocks.AIR.getDefaultState());
        structure.fillWithBlocks(world, start, 156, -32, 41, 158, -32, 43, Blocks.STONE_BRICKS.getDefaultState());
        structure.fillWithBlocks(world, start, 156, -32, 44, 158, -32, 44, Blocks.AIR.getDefaultState());
        structure.fillWithBlocks(world, start, 156, -9, 62, 158, -9, 64, Blocks.SANDSTONE.getDefaultState());
        structure.fillWithBlocks(world, start, 156, -9, 69, 158, -9, 71, Blocks.AIR.getDefaultState());
        structure.fillWithBlocks(world, start, 156, -8, 69, 158, -8, 71, Blocks.AIR.getDefaultState());
        structure.fillWithBlocks(world, start, 156, -8, 72, 158, -8, 74, Blocks.SANDSTONE.getDefaultState());
        structure.fillWithBlocks(world, start, 156, -5, 62, 159, -5, 65, Blocks.SANDSTONE.getDefaultState());
        structure.fillWithBlocks(world, start, 156, -4, 64, 156, -3, 64, Blocks.AIR.getDefaultState());
        structure.fillWithBlocks(world, start, 156, -4, 65, 156, -4, 67, Blocks.SANDSTONE.getDefaultState());
        structure.fillWithBlocks(world, start, 156, -3, 73, 157, -3, 74, Blocks.SANDSTONE.getDefaultState());
        structure.fillWithBlocks(world, start, 156, -2, 65, 159, -2, 71, Blocks.SANDSTONE.getDefaultState());
        structure.fillWithBlocks(world, start, 156, -2, 72, 156, -1, 74, Blocks.SANDSTONE.getDefaultState());
        structure.fillWithBlocks(world, start, 156, -1, 70, 157, -1, 74, Blocks.SANDSTONE.getDefaultState());
        structure.fillWithBlocks(world, start, 156, 0, 33, 170, 1, 33, Blocks.STONE.getDefaultState());
        structure.fillWithBlocks(world, start, 156, 0, 34, 157, 0, 39, Blocks.SANDSTONE.getDefaultState());
        structure.fillWithBlocks(world, start, 156, 0, 40, 157, 0, 109, Blocks.STONE.getDefaultState());
        structure.fillWithBlocks(world, start, 156, 0, 111, 158, 0, 122, Blocks.SANDSTONE.getDefaultState());
        structure.fillWithBlocks(world, start, 156, 0, 123, 170, 0, 137, Blocks.STONE.getDefaultState());
        structure.fillWithBlocks(world, start, 156, 1, 34, 156, 1, 34, Blocks.STONE.getDefaultState());
        structure.fillWithBlocks(world, start, 156, 1, 35, 156, 1, 42, Blocks.SANDSTONE.getDefaultState());
        structure.fillWithBlocks(world, start, 156, 1, 43, 156, 1, 43, Blocks.STONE.getDefaultState());
        structure.fillWithBlocks(world, start, 156, 1, 45, 158, 1, 50, Blocks.SANDSTONE.getDefaultState());
        structure.fillWithBlocks(world, start, 156, 1, 51, 156, 2, 52, Blocks.SANDSTONE.getDefaultState());
        structure.fillWithBlocks(world, start, 156, 1, 53, 160, 1, 59, Blocks.STONE.getDefaultState());
        structure.fillWithBlocks(world, start, 156, 1, 60, 157, 1, 61, Blocks.STONE.getDefaultState());
        structure.fillWithBlocks(world, start, 156, 1, 63, 168, 1, 75, Blocks.SANDSTONE.getDefaultState());
        structure.fillWithBlocks(world, start, 156, 1, 76, 156, 1, 109, Blocks.STONE.getDefaultState());
        structure.fillWithBlocks(world, start, 156, 1, 110, 163, 1, 118, Blocks.SANDSTONE.getDefaultState());
        structure.fillWithBlocks(world, start, 156, 1, 121, 165, 1, 132, Blocks.STONE.getDefaultState());
        structure.fillWithBlocks(world, start, 156, 1, 133, 156, 1, 147, Blocks.SANDSTONE.getDefaultState());
        structure.fillWithBlocks(world, start, 156, 2, 45, 164, 2, 87, Blocks.SANDSTONE.getDefaultState());
        structure.fillWithBlocks(world, start, 156, 2, 88, 157, 2, 94, Blocks.STONE.getDefaultState());
        structure.fillWithBlocks(world, start, 156, 2, 96, 163, 2, 122, Blocks.SANDSTONE.getDefaultState());
        structure.fillWithBlocks(world, start, 156, 2, 123, 158, 2, 130, Blocks.STONE.getDefaultState());
        structure.fillWithBlocks(world, start, 156, 3, 45, 202, 3, 107, Blocks.SANDSTONE.getDefaultState());
        structure.fillWithBlocks(world, start, 156, 9, 66, 156, 9, 70, Blocks.SANDSTONE_SLAB.getDefaultState().with(SlabBlock.TYPE, SlabType.BOTTOM).with(SlabBlock.WATERLOGGED, false));
        structure.fillWithBlocks(world, start, 156, 10, 64, 156, 10, 65, Blocks.SANDSTONE_SLAB.getDefaultState().with(SlabBlock.TYPE, SlabType.BOTTOM).with(SlabBlock.WATERLOGGED, false));
        structure.fillWithBlocks(world, start, 156, 10, 71, 156, 10, 72, Blocks.SANDSTONE_SLAB.getDefaultState().with(SlabBlock.TYPE, SlabType.BOTTOM).with(SlabBlock.WATERLOGGED, false));
        structure.fillWithBlocks(world, start, 157, -51, 59, 159, -51, 61, Blocks.SANDSTONE.getDefaultState());
        structure.fillWithBlocks(world, start, 157, -51, 69, 159, -51, 71, Blocks.SANDSTONE.getDefaultState());
        structure.fillWithBlocks(world, start, 157, -50, 59, 157, -50, 59, Blocks.AIR.getDefaultState());
        structure.fillWithBlocks(world, start, 157, -50, 69, 157, -50, 69, Blocks.AIR.getDefaultState());
        structure.fillWithBlocks(world, start, 157, -49, 16, 157, -46, 16, Blocks.SANDSTONE.getDefaultState());
        structure.fillWithBlocks(world, start, 157, -49, 17, 159, -49, 19, Blocks.AIR.getDefaultState());
        structure.fillWithBlocks(world, start, 157, -49, 20, 157, -49, 21, Blocks.SANDSTONE.getDefaultState());
        structure.fillWithBlocks(world, start, 157, -49, 35, 157, -43, 35, Blocks.SANDSTONE.getDefaultState());
        structure.fillWithBlocks(world, start, 157, -49, 36, 159, -49, 40, Blocks.AIR.getDefaultState());
        structure.fillWithBlocks(world, start, 157, -49, 41, 157, -49, 50, Blocks.SANDSTONE.getDefaultState());
        structure.fillWithBlocks(world, start, 157, -49, 58, 157, -41, 58, Blocks.SANDSTONE.getDefaultState());
        structure.fillWithBlocks(world, start, 157, -49, 62, 157, -41, 62, Blocks.SANDSTONE.getDefaultState());
        structure.fillWithBlocks(world, start, 157, -49, 63, 157, -49, 67, Blocks.IRON_BARS.getDefaultState().with(FourWayBlock.WATERLOGGED, false).with(FourWayBlock.NORTH, true).with(FourWayBlock.SOUTH, true).with(FourWayBlock.EAST, true).with(FourWayBlock.WEST, true));
        structure.fillWithBlocks(world, start, 157, -49, 68, 157, -41, 68, Blocks.SANDSTONE.getDefaultState());
        structure.fillWithBlocks(world, start, 157, -49, 69, 159, -49, 71, Blocks.AIR.getDefaultState());
        structure.fillWithBlocks(world, start, 157, -49, 72, 157, -49, 73, Blocks.SANDSTONE.getDefaultState());
        structure.fillWithBlocks(world, start, 157, -48, 15, 157, -47, 16, Blocks.SANDSTONE.getDefaultState());
        structure.fillWithBlocks(world, start, 157, -48, 17, 159, -48, 19, Blocks.AIR.getDefaultState());
        structure.fillWithBlocks(world, start, 157, -48, 20, 157, -48, 21, Blocks.SANDSTONE.getDefaultState());
        structure.fillWithBlocks(world, start, 157, -48, 36, 159, -48, 40, Blocks.AIR.getDefaultState());
        structure.fillWithBlocks(world, start, 157, -48, 41, 157, -48, 50, Blocks.SANDSTONE.getDefaultState());
        structure.fillWithBlocks(world, start, 157, -48, 59, 159, -48, 61, Blocks.AIR.getDefaultState());
        structure.fillWithBlocks(world, start, 157, -48, 63, 161, -48, 67, Blocks.AIR.getDefaultState());
        structure.fillWithBlocks(world, start, 157, -48, 69, 159, -48, 71, Blocks.AIR.getDefaultState());
        structure.fillWithBlocks(world, start, 157, -48, 72, 157, -48, 73, Blocks.SANDSTONE.getDefaultState());
        structure.fillWithBlocks(world, start, 157, -47, 17, 159, -47, 19, Blocks.AIR.getDefaultState());
        structure.fillWithBlocks(world, start, 157, -47, 20, 157, -47, 21, Blocks.SANDSTONE.getDefaultState());
        structure.fillWithBlocks(world, start, 157, -47, 36, 161, -47, 40, Blocks.AIR.getDefaultState());
        structure.fillWithBlocks(world, start, 157, -47, 41, 157, -47, 50, Blocks.SANDSTONE.getDefaultState());
        structure.fillWithBlocks(world, start, 157, -47, 59, 159, -47, 61, Blocks.AIR.getDefaultState());
        structure.fillWithBlocks(world, start, 157, -47, 63, 161, -47, 67, Blocks.AIR.getDefaultState());
        structure.fillWithBlocks(world, start, 157, -47, 69, 159, -47, 71, Blocks.AIR.getDefaultState());
        structure.fillWithBlocks(world, start, 157, -47, 72, 157, -47, 73, Blocks.SANDSTONE.getDefaultState());
        structure.fillWithBlocks(world, start, 157, -46, 17, 160, -46, 20, Blocks.SANDSTONE.getDefaultState());
        structure.fillWithBlocks(world, start, 157, -46, 36, 161, -46, 40, Blocks.AIR.getDefaultState());
        structure.fillWithBlocks(world, start, 157, -46, 41, 157, -46, 50, Blocks.SANDSTONE.getDefaultState());
        structure.fillWithBlocks(world, start, 157, -46, 59, 159, -46, 61, Blocks.AIR.getDefaultState());
        structure.fillWithBlocks(world, start, 157, -46, 63, 161, -46, 67, Blocks.AIR.getDefaultState());
        structure.fillWithBlocks(world, start, 157, -46, 69, 159, -46, 71, Blocks.AIR.getDefaultState());
        structure.fillWithBlocks(world, start, 157, -46, 72, 157, -46, 73, Blocks.SANDSTONE.getDefaultState());
        structure.fillWithBlocks(world, start, 157, -45, 36, 161, -45, 40, Blocks.AIR.getDefaultState());
        structure.fillWithBlocks(world, start, 157, -45, 59, 157, -41, 73, Blocks.SANDSTONE.getDefaultState());
        structure.fillWithBlocks(world, start, 157, -43, 43, 164, -43, 50, Blocks.SANDSTONE.getDefaultState());
        structure.fillWithBlocks(world, start, 157, -42, 35, 157, -41, 36, Blocks.STONE_BRICKS.getDefaultState());
        structure.fillWithBlocks(world, start, 157, -42, 39, 157, -39, 42, Blocks.STONE_BRICKS.getDefaultState());
        structure.fillWithBlocks(world, start, 157, -42, 43, 164, -42, 50, Blocks.SANDSTONE.getDefaultState());
        structure.fillWithBlocks(world, start, 157, -41, 38, 157, -39, 42, Blocks.STONE_BRICKS.getDefaultState());
        structure.fillWithBlocks(world, start, 157, -41, 43, 164, -41, 50, Blocks.SANDSTONE.getDefaultState());
        structure.fillWithBlocks(world, start, 157, -40, 31, 157, -40, 31, Blocks.STONE_BRICKS.getDefaultState());
        structure.fillWithBlocks(world, start, 157, -40, 33, 160, -40, 38, Blocks.STONE_BRICKS.getDefaultState());
        structure.fillWithBlocks(world, start, 157, -39, 31, 160, -39, 45, Blocks.STONE_BRICKS.getDefaultState());
        structure.fillWithBlocks(world, start, 157, -38, 31, 159, -38, 37, Blocks.STONE_BRICKS.getDefaultState());
        structure.fillWithBlocks(world, start, 157, -38, 39, 160, -38, 43, Blocks.STONE_BRICKS.getDefaultState());
        structure.fillWithBlocks(world, start, 157, -37, 31, 158, -37, 36, Blocks.STONE_BRICKS.getDefaultState());
        structure.fillWithBlocks(world, start, 157, -37, 37, 157, -37, 45, Blocks.STONE_BRICKS.getDefaultState());
        structure.fillWithBlocks(world, start, 157, -36, 35, 158, -36, 38, Blocks.STONE_BRICKS.getDefaultState());
        structure.fillWithBlocks(world, start, 157, -36, 39, 157, -35, 45, Blocks.STONE_BRICKS.getDefaultState());
        structure.fillWithBlocks(world, start, 157, -35, 32, 158, -35, 42, Blocks.STONE_BRICKS.getDefaultState());
        structure.fillWithBlocks(world, start, 157, -34, 37, 157, -31, 37, Blocks.STONE_BRICKS.getDefaultState());
        structure.fillWithBlocks(world, start, 157, -34, 39, 158, -34, 40, Blocks.STONE_BRICKS.getDefaultState());
        structure.fillWithBlocks(world, start, 157, -34, 42, 158, -34, 43, Blocks.STONE_BRICKS.getDefaultState());
        structure.fillWithBlocks(world, start, 157, -33, 32, 157, -31, 32, Blocks.STONE_BRICKS.getDefaultState());
        structure.fillWithBlocks(world, start, 157, -33, 33, 157, -33, 33, Blocks.AIR.getDefaultState());
        structure.fillWithBlocks(world, start, 157, -33, 43, 159, -33, 45, Blocks.STONE_BRICKS.getDefaultState());
        structure.fillWithBlocks(world, start, 157, -32, 33, 158, -32, 34, Blocks.STONE_BRICKS.getDefaultState());
        structure.fillWithBlocks(world, start, 157, -32, 39, 157, -31, 43, Blocks.STONE_BRICKS.getDefaultState());
        structure.fillWithBlocks(world, start, 157, -31, 44, 157, -31, 44, Blocks.STONE_BRICKS.getDefaultState());
        structure.fillWithBlocks(world, start, 157, -11, 66, 157, -10, 70, Blocks.SANDSTONE.getDefaultState());
        structure.fillWithBlocks(world, start, 157, -9, 65, 158, -9, 71, Blocks.AIR.getDefaultState());
        structure.fillWithBlocks(world, start, 157, -9, 72, 157, -7, 74, Blocks.SANDSTONE.getDefaultState());
        structure.fillWithBlocks(world, start, 157, -8, 62, 159, -8, 64, Blocks.SANDSTONE.getDefaultState());
        structure.fillWithBlocks(world, start, 157, -8, 65, 158, -8, 71, Blocks.AIR.getDefaultState());
        structure.fillWithBlocks(world, start, 157, -7, 62, 159, -7, 64, Blocks.SANDSTONE.getDefaultState());
        structure.fillWithBlocks(world, start, 157, -6, 62, 159, -6, 64, Blocks.SANDSTONE.getDefaultState());
        structure.fillWithBlocks(world, start, 157, -6, 72, 157, -6, 72, Blocks.SANDSTONE.getDefaultState());
        structure.fillWithBlocks(world, start, 157, -6, 74, 162, -2, 74, Blocks.SANDSTONE.getDefaultState());
        structure.fillWithBlocks(world, start, 157, -4, 63, 158, -4, 64, Blocks.SANDSTONE.getDefaultState());
        structure.fillWithBlocks(world, start, 157, -4, 65, 158, -4, 65, Blocks.AIR.getDefaultState());
        structure.fillWithBlocks(world, start, 157, -4, 66, 161, -4, 71, Blocks.SANDSTONE.getDefaultState());
        structure.fillWithBlocks(world, start, 157, -3, 62, 160, -3, 65, Blocks.SANDSTONE.getDefaultState());
        structure.fillWithBlocks(world, start, 157, -2, 62, 159, -2, 71, Blocks.SANDSTONE.getDefaultState());
        structure.fillWithBlocks(world, start, 157, -2, 72, 157, -1, 72, Blocks.SANDSTONE.getDefaultState());
        structure.fillWithBlocks(world, start, 157, -1, 66, 157, -1, 66, Blocks.SANDSTONE.getDefaultState());
        structure.fillWithBlocks(world, start, 157, -1, 68, 157, -1, 74, Blocks.SANDSTONE.getDefaultState());
        structure.fillWithBlocks(world, start, 157, 0, 110, 158, 0, 122, Blocks.SANDSTONE.getDefaultState());
        structure.fillWithBlocks(world, start, 157, 1, 34, 158, 1, 35, Blocks.STONE.getDefaultState());
        structure.fillWithBlocks(world, start, 157, 1, 38, 160, 1, 43, Blocks.SANDSTONE.getDefaultState());
        structure.fillWithBlocks(world, start, 157, 1, 51, 157, 6, 51, Blocks.SANDSTONE.getDefaultState());
        structure.fillWithBlocks(world, start, 157, 1, 52, 160, 1, 59, Blocks.STONE.getDefaultState());
        structure.fillWithBlocks(world, start, 157, 1, 62, 169, 1, 75, Blocks.SANDSTONE.getDefaultState());
        structure.fillWithBlocks(world, start, 157, 1, 76, 161, 5, 76, Blocks.SANDSTONE.getDefaultState());
        structure.fillWithBlocks(world, start, 157, 1, 77, 162, 1, 105, Blocks.STONE.getDefaultState());
        structure.fillWithBlocks(world, start, 157, 1, 106, 159, 1, 108, Blocks.STONE.getDefaultState());
        structure.fillWithBlocks(world, start, 157, 1, 109, 158, 1, 109, Blocks.STONE.getDefaultState());
        structure.fillWithBlocks(world, start, 157, 1, 133, 157, 1, 133, Blocks.STONE.getDefaultState());
        structure.fillWithBlocks(world, start, 157, 1, 134, 157, 5, 139, Blocks.SANDSTONE.getDefaultState());
        structure.fillWithBlocks(world, start, 157, 1, 141, 162, 1, 146, Blocks.SANDSTONE.getDefaultState());
        structure.fillWithBlocks(world, start, 157, 2, 6, 161, 2, 87, Blocks.SANDSTONE.getDefaultState());
        structure.fillWithBlocks(world, start, 157, 2, 95, 163, 2, 122, Blocks.SANDSTONE.getDefaultState());
        structure.fillWithBlocks(world, start, 157, 2, 131, 170, 2, 144, Blocks.SANDSTONE.getDefaultState());
        structure.fillWithBlocks(world, start, 157, 8, 64, 158, 8, 65, Blocks.SANDSTONE.getDefaultState());
        structure.fillWithBlocks(world, start, 157, 8, 66, 157, 8, 72, Blocks.SANDSTONE.getDefaultState());
        structure.fillWithBlocks(world, start, 157, 9, 64, 157, 9, 65, Blocks.SANDSTONE.getDefaultState());
        structure.fillWithBlocks(world, start, 157, 9, 71, 157, 9, 72, Blocks.SANDSTONE.getDefaultState());
        structure.fillWithBlocks(world, start, 158, -51, 62, 160, -51, 71, Blocks.SANDSTONE.getDefaultState());
        structure.fillWithBlocks(world, start, 158, -50, 57, 159, -50, 58, Blocks.SANDSTONE.getDefaultState());
        structure.fillWithBlocks(world, start, 158, -50, 59, 160, -50, 64, Blocks.AIR.getDefaultState());
        structure.fillWithBlocks(world, start, 158, -50, 65, 158, -50, 71, Blocks.AIR.getDefaultState());
        structure.fillWithBlocks(world, start, 158, -50, 72, 159, -50, 73, Blocks.SANDSTONE.getDefaultState());
        structure.fillWithBlocks(world, start, 158, -49, 16, 160, -49, 20, Blocks.AIR.getDefaultState());
        structure.fillWithBlocks(world, start, 158, -49, 26, 166, -49, 34, Blocks.SANDSTONE.getDefaultState());
        structure.fillWithBlocks(world, start, 158, -49, 35, 160, -49, 37, Blocks.AIR.getDefaultState());
        structure.fillWithBlocks(world, start, 158, -49, 41, 162, -46, 41, Blocks.AIR.getDefaultState());
        structure.fillWithBlocks(world, start, 158, -49, 58, 160, -49, 58, Blocks.IRON_BARS.getDefaultState().with(FourWayBlock.WATERLOGGED, false).with(FourWayBlock.NORTH, true).with(FourWayBlock.SOUTH, true).with(FourWayBlock.EAST, true).with(FourWayBlock.WEST, true));
        structure.fillWithBlocks(world, start, 158, -49, 59, 160, -49, 71, Blocks.AIR.getDefaultState());
        structure.fillWithBlocks(world, start, 158, -49, 72, 160, -49, 72, Blocks.IRON_BARS.getDefaultState().with(FourWayBlock.WATERLOGGED, false).with(FourWayBlock.NORTH, true).with(FourWayBlock.SOUTH, true).with(FourWayBlock.EAST, true).with(FourWayBlock.WEST, true));
        structure.fillWithBlocks(world, start, 158, -48, 15, 158, -47, 15, Blocks.SANDSTONE.getDefaultState());
        structure.fillWithBlocks(world, start, 158, -48, 16, 160, -48, 20, Blocks.AIR.getDefaultState());
        structure.fillWithBlocks(world, start, 158, -48, 26, 165, -48, 33, Blocks.SANDSTONE.getDefaultState());
        structure.fillWithBlocks(world, start, 158, -48, 35, 160, -48, 37, Blocks.AIR.getDefaultState());
        structure.fillWithBlocks(world, start, 158, -48, 58, 160, -48, 72, Blocks.AIR.getDefaultState());
        structure.fillWithBlocks(world, start, 158, -47, 16, 160, -47, 20, Blocks.AIR.getDefaultState());
        structure.fillWithBlocks(world, start, 158, -47, 26, 166, -47, 34, Blocks.SANDSTONE.getDefaultState());
        structure.fillWithBlocks(world, start, 158, -47, 35, 162, -47, 41, Blocks.AIR.getDefaultState());
        structure.fillWithBlocks(world, start, 158, -47, 58, 160, -47, 72, Blocks.AIR.getDefaultState());
        structure.fillWithBlocks(world, start, 158, -46, 16, 162, -46, 20, Blocks.SANDSTONE.getDefaultState());
        structure.fillWithBlocks(world, start, 158, -46, 26, 166, -46, 34, Blocks.SANDSTONE.getDefaultState());
        structure.fillWithBlocks(world, start, 158, -46, 35, 162, -46, 41, Blocks.AIR.getDefaultState());
        structure.fillWithBlocks(world, start, 158, -46, 58, 160, -46, 72, Blocks.AIR.getDefaultState());
        structure.fillWithBlocks(world, start, 158, -45, 59, 160, -45, 61, Blocks.AIR.getDefaultState());
        structure.fillWithBlocks(world, start, 158, -45, 63, 160, -45, 67, Blocks.AIR.getDefaultState());
        structure.fillWithBlocks(world, start, 158, -45, 69, 160, -45, 71, Blocks.AIR.getDefaultState());
        structure.fillWithBlocks(world, start, 158, -45, 72, 159, -45, 73, Blocks.SANDSTONE.getDefaultState());
        structure.fillWithBlocks(world, start, 158, -43, 34, 161, -43, 37, Blocks.SANDSTONE.getDefaultState());
        structure.fillWithBlocks(world, start, 158, -43, 42, 166, -43, 50, Blocks.SANDSTONE.getDefaultState());
        structure.fillWithBlocks(world, start, 158, -42, 34, 172, -42, 50, Blocks.SANDSTONE.getDefaultState());
        structure.fillWithBlocks(world, start, 158, -41, 34, 172, -41, 50, Blocks.SANDSTONE.getDefaultState());
        structure.fillWithBlocks(world, start, 158, -40, 31, 158, -35, 36, Blocks.STONE_BRICKS.getDefaultState());
        structure.fillWithBlocks(world, start, 158, -40, 44, 158, -40, 45, Blocks.STONE_BRICKS.getDefaultState());
        structure.fillWithBlocks(world, start, 158, -38, 38, 160, -38, 45, Blocks.STONE_BRICKS.getDefaultState());
        structure.fillWithBlocks(world, start, 158, -37, 38, 160, -37, 41, Blocks.STONE_BRICKS.getDefaultState());
        structure.fillWithBlocks(world, start, 158, -37, 42, 158, -37, 43, Blocks.AIR.getDefaultState());
        structure.fillWithBlocks(world, start, 158, -37, 44, 159, -37, 45, Blocks.STONE_BRICKS.getDefaultState());
        structure.fillWithBlocks(world, start, 158, -36, 39, 158, -36, 40, Blocks.AIR.getDefaultState());
        structure.fillWithBlocks(world, start, 158, -36, 41, 158, -36, 41, Blocks.STONE_BRICKS.getDefaultState());
        structure.fillWithBlocks(world, start, 158, -36, 43, 160, -36, 45, Blocks.STONE_BRICKS.getDefaultState());
        structure.fillWithBlocks(world, start, 158, -35, 44, 159, -35, 45, Blocks.STONE_BRICKS.getDefaultState());
        structure.fillWithBlocks(world, start, 158, -34, 37, 158, -34, 37, Blocks.AIR.getDefaultState());
        structure.fillWithBlocks(world, start, 158, -34, 38, 158, -34, 45, Blocks.STONE_BRICKS.getDefaultState());
        structure.fillWithBlocks(world, start, 158, -33, 33, 158, -33, 33, Blocks.STONE_BRICKS.getDefaultState());
        structure.fillWithBlocks(world, start, 158, -32, 32, 160, -32, 34, Blocks.STONE_BRICKS.getDefaultState());
        structure.fillWithBlocks(world, start, 158, -32, 36, 158, -31, 39, Blocks.STONE_BRICKS.getDefaultState());
        structure.fillWithBlocks(world, start, 158, -31, 41, 158, -31, 41, Blocks.STONE_BRICKS.getDefaultState());
        structure.fillWithBlocks(world, start, 158, -31, 43, 160, -31, 45, Blocks.STONE_BRICKS.getDefaultState());
        structure.fillWithBlocks(world, start, 158, -9, 72, 158, -9, 72, Blocks.SANDSTONE.getDefaultState());
        structure.fillWithBlocks(world, start, 158, -9, 73, 158, -9, 73, Blocks.AIR.getDefaultState());
        structure.fillWithBlocks(world, start, 158, -9, 74, 158, -1, 74, Blocks.SANDSTONE.getDefaultState());
        structure.fillWithBlocks(world, start, 158, -7, 72, 158, -3, 72, Blocks.SANDSTONE.getDefaultState());
        structure.fillWithBlocks(world, start, 158, -6, 73, 159, -6, 74, Blocks.SANDSTONE.getDefaultState());
        structure.fillWithBlocks(world, start, 158, -5, 66, 158, -5, 66, Blocks.SANDSTONE.getDefaultState());
        structure.fillWithBlocks(world, start, 158, -5, 67, 158, -5, 69, Blocks.AIR.getDefaultState());
        structure.fillWithBlocks(world, start, 158, -5, 70, 162, -5, 74, Blocks.SANDSTONE.getDefaultState());
        structure.fillWithBlocks(world, start, 158, -4, 62, 160, -4, 64, Blocks.SANDSTONE.getDefaultState());
        structure.fillWithBlocks(world, start, 158, -3, 67, 162, -3, 71, Blocks.SANDSTONE.getDefaultState());
        structure.fillWithBlocks(world, start, 158, -3, 73, 159, -3, 74, Blocks.SANDSTONE.getDefaultState());
        structure.fillWithBlocks(world, start, 158, -2, 73, 159, -2, 74, Blocks.SANDSTONE.getDefaultState());
        structure.fillWithBlocks(world, start, 158, -1, 67, 159, -1, 68, Blocks.SANDSTONE.getDefaultState());
        structure.fillWithBlocks(world, start, 158, -1, 69, 158, -1, 70, Blocks.AIR.getDefaultState());
        structure.fillWithBlocks(world, start, 158, -1, 71, 158, -1, 74, Blocks.SANDSTONE.getDefaultState());
        structure.fillWithBlocks(world, start, 158, 0, 10, 164, 4, 10, Blocks.SANDSTONE.getDefaultState());
        structure.fillWithBlocks(world, start, 158, 0, 11, 160, 0, 34, Blocks.STONE.getDefaultState());
        structure.fillWithBlocks(world, start, 158, 0, 35, 159, 0, 40, Blocks.SANDSTONE.getDefaultState());
        structure.fillWithBlocks(world, start, 158, 0, 41, 158, 0, 109, Blocks.STONE.getDefaultState());
        structure.fillWithBlocks(world, start, 158, 0, 138, 159, 0, 139, Blocks.STONE.getDefaultState());
        structure.fillWithBlocks(world, start, 158, 1, 44, 161, 1, 47, Blocks.SANDSTONE.getDefaultState());
        structure.fillWithBlocks(world, start, 158, 1, 51, 160, 1, 59, Blocks.STONE.getDefaultState());
        structure.fillWithBlocks(world, start, 158, 1, 61, 169, 1, 75, Blocks.SANDSTONE.getDefaultState());
        structure.fillWithBlocks(world, start, 158, 1, 133, 160, 1, 135, Blocks.STONE.getDefaultState());
        structure.fillWithBlocks(world, start, 158, 1, 136, 158, 4, 141, Blocks.SANDSTONE.getDefaultState());
        structure.fillWithBlocks(world, start, 158, 2, 88, 158, 2, 88, Blocks.SANDSTONE.getDefaultState());
        structure.fillWithBlocks(world, start, 158, 2, 89, 158, 2, 94, Blocks.STONE.getDefaultState());
        structure.fillWithBlocks(world, start, 158, 3, 142, 159, 3, 143, Blocks.SANDSTONE.getDefaultState());
        structure.fillWithBlocks(world, start, 158, 5, 11, 161, 5, 139, Blocks.SANDSTONE.getDefaultState());
        structure.fillWithBlocks(world, start, 158, 8, 66, 158, 8, 70, Blocks.SANDSTONE_STAIRS.getDefaultState().with(StairsBlock.FACING, Direction.WEST).with(StairsBlock.WATERLOGGED, false).with(StairsBlock.SHAPE, StairsShape.STRAIGHT).with(StairsBlock.HALF, Half.BOTTOM));
        structure.fillWithBlocks(world, start, 158, 8, 71, 159, 8, 72, Blocks.SANDSTONE.getDefaultState());
        structure.fillWithBlocks(world, start, 158, 9, 64, 158, 9, 65, Blocks.SANDSTONE_STAIRS.getDefaultState().with(StairsBlock.FACING, Direction.WEST).with(StairsBlock.WATERLOGGED, false).with(StairsBlock.SHAPE, StairsShape.STRAIGHT).with(StairsBlock.HALF, Half.BOTTOM));
        structure.fillWithBlocks(world, start, 158, 9, 71, 158, 9, 72, Blocks.SANDSTONE_STAIRS.getDefaultState().with(StairsBlock.FACING, Direction.WEST).with(StairsBlock.WATERLOGGED, false).with(StairsBlock.SHAPE, StairsShape.STRAIGHT).with(StairsBlock.HALF, Half.BOTTOM));
        structure.fillWithBlocks(world, start, 159, -50, 66, 160, -50, 71, Blocks.AIR.getDefaultState());
        structure.fillWithBlocks(world, start, 159, -45, 32, 162, -45, 35, Blocks.SANDSTONE.getDefaultState());
        structure.fillWithBlocks(world, start, 159, -44, 26, 169, -44, 36, Blocks.SANDSTONE.getDefaultState());
        structure.fillWithBlocks(world, start, 159, -44, 37, 161, -44, 39, Blocks.AIR.getDefaultState());
        structure.fillWithBlocks(world, start, 159, -44, 59, 159, -44, 59, Blocks.SANDSTONE.getDefaultState());
        structure.fillWithBlocks(world, start, 159, -44, 61, 162, -44, 64, Blocks.SANDSTONE.getDefaultState());
        structure.fillWithBlocks(world, start, 159, -44, 66, 162, -44, 69, Blocks.SANDSTONE.getDefaultState());
        structure.fillWithBlocks(world, start, 159, -44, 71, 161, -44, 73, Blocks.SANDSTONE.getDefaultState());
        structure.fillWithBlocks(world, start, 159, -40, 31, 159, -40, 31, Blocks.STONE_BRICKS.getDefaultState());
        structure.fillWithBlocks(world, start, 159, -40, 40, 160, -40, 41, Blocks.STONE_BRICKS.getDefaultState());
        structure.fillWithBlocks(world, start, 159, -37, 31, 159, -37, 31, Blocks.STONE_BRICKS.getDefaultState());
        structure.fillWithBlocks(world, start, 159, -37, 33, 159, -37, 45, Blocks.STONE_BRICKS.getDefaultState());
        structure.fillWithBlocks(world, start, 159, -36, 32, 160, -36, 32, Blocks.STONE_BRICKS.getDefaultState());
        structure.fillWithBlocks(world, start, 159, -36, 33, 159, -36, 34, Blocks.AIR.getDefaultState());
        structure.fillWithBlocks(world, start, 159, -36, 35, 159, -36, 35, Blocks.STONE_BRICKS.getDefaultState());
        structure.fillWithBlocks(world, start, 159, -36, 36, 159, -36, 37, Blocks.AIR.getDefaultState());
        structure.fillWithBlocks(world, start, 159, -36, 38, 160, -36, 45, Blocks.STONE_BRICKS.getDefaultState());
        structure.fillWithBlocks(world, start, 159, -35, 32, 159, -35, 33, Blocks.AIR.getDefaultState());
        structure.fillWithBlocks(world, start, 159, -35, 35, 160, -35, 41, Blocks.STONE_BRICKS.getDefaultState());
        structure.fillWithBlocks(world, start, 159, -35, 42, 159, -34, 42, Blocks.AIR.getDefaultState());
        structure.fillWithBlocks(world, start, 159, -35, 43, 160, -35, 45, Blocks.STONE_BRICKS.getDefaultState());
        structure.fillWithBlocks(world, start, 159, -34, 32, 160, -34, 37, Blocks.STONE_BRICKS.getDefaultState());
        structure.fillWithBlocks(world, start, 159, -34, 39, 160, -34, 41, Blocks.STONE_BRICKS.getDefaultState());
        structure.fillWithBlocks(world, start, 159, -34, 43, 160, -34, 45, Blocks.STONE_BRICKS.getDefaultState());
        structure.fillWithBlocks(world, start, 159, -33, 32, 160, -33, 39, Blocks.STONE_BRICKS.getDefaultState());
        structure.fillWithBlocks(world, start, 159, -33, 41, 160, -33, 45, Blocks.STONE_BRICKS.getDefaultState());
        structure.fillWithBlocks(world, start, 159, -32, 35, 160, -32, 36, Blocks.STONE_BRICKS.getDefaultState());
        structure.fillWithBlocks(world, start, 159, -32, 39, 160, -32, 45, Blocks.STONE_BRICKS.getDefaultState());
        structure.fillWithBlocks(world, start, 159, -31, 40, 160, -31, 45, Blocks.STONE_BRICKS.getDefaultState());
        structure.fillWithBlocks(world, start, 159, -10, 62, 160, -10, 64, Blocks.SANDSTONE.getDefaultState());
        structure.fillWithBlocks(world, start, 159, -10, 65, 160, -10, 65, Blocks.AIR.getDefaultState());
        structure.fillWithBlocks(world, start, 159, -10, 66, 161, -10, 72, Blocks.SANDSTONE.getDefaultState());
        structure.fillWithBlocks(world, start, 159, -10, 73, 160, -10, 74, Blocks.SANDSTONE.getDefaultState());
        structure.fillWithBlocks(world, start, 159, -9, 62, 162, -9, 65, Blocks.SANDSTONE.getDefaultState());
        structure.fillWithBlocks(world, start, 159, -9, 66, 159, -6, 70, Blocks.AIR.getDefaultState());
        structure.fillWithBlocks(world, start, 159, -9, 71, 161, -9, 73, Blocks.SANDSTONE.getDefaultState());
        structure.fillWithBlocks(world, start, 159, -8, 65, 159, -8, 65, Blocks.SANDSTONE.getDefaultState());
        structure.fillWithBlocks(world, start, 159, -8, 71, 159, -8, 74, Blocks.SANDSTONE.getDefaultState());
        structure.fillWithBlocks(world, start, 159, -7, 65, 159, -7, 65, Blocks.SANDSTONE.getDefaultState());
        structure.fillWithBlocks(world, start, 159, -7, 71, 159, -2, 71, Blocks.SANDSTONE.getDefaultState());
        structure.fillWithBlocks(world, start, 159, -7, 73, 160, -7, 74, Blocks.SANDSTONE.getDefaultState());
        structure.fillWithBlocks(world, start, 159, -6, 65, 159, -6, 65, Blocks.SANDSTONE.getDefaultState());
        structure.fillWithBlocks(world, start, 159, -6, 72, 161, -6, 74, Blocks.SANDSTONE.getDefaultState());
        structure.fillWithBlocks(world, start, 159, -5, 66, 161, -5, 68, Blocks.SANDSTONE.getDefaultState());
        structure.fillWithBlocks(world, start, 159, -5, 69, 159, -5, 74, Blocks.SANDSTONE.getDefaultState());
        structure.fillWithBlocks(world, start, 159, -4, 65, 161, -4, 71, Blocks.SANDSTONE.getDefaultState());
        structure.fillWithBlocks(world, start, 159, -4, 72, 160, -4, 74, Blocks.SANDSTONE.getDefaultState());
        structure.fillWithBlocks(world, start, 159, -3, 66, 162, -3, 71, Blocks.SANDSTONE.getDefaultState());
        structure.fillWithBlocks(world, start, 159, -3, 72, 159, -3, 74, Blocks.SANDSTONE.getDefaultState());
        structure.fillWithBlocks(world, start, 159, -2, 72, 161, -2, 74, Blocks.SANDSTONE.getDefaultState());
        structure.fillWithBlocks(world, start, 159, -1, 62, 161, -1, 64, Blocks.SANDSTONE.getDefaultState());
        structure.fillWithBlocks(world, start, 159, -1, 65, 159, -1, 70, Blocks.SANDSTONE.getDefaultState());
        structure.fillWithBlocks(world, start, 159, -1, 72, 159, -1, 72, Blocks.SANDSTONE.getDefaultState());
        structure.fillWithBlocks(world, start, 159, -1, 73, 159, -1, 73, Blocks.AIR.getDefaultState());
        structure.fillWithBlocks(world, start, 159, 0, 41, 159, 0, 41, Blocks.SANDSTONE.getDefaultState());
        structure.fillWithBlocks(world, start, 159, 0, 42, 159, 0, 113, Blocks.STONE.getDefaultState());
        structure.fillWithBlocks(world, start, 159, 0, 114, 164, 0, 119, Blocks.SANDSTONE.getDefaultState());
        structure.fillWithBlocks(world, start, 159, 0, 120, 160, 0, 121, Blocks.SANDSTONE.getDefaultState());
        structure.fillWithBlocks(world, start, 159, 0, 122, 170, 0, 137, Blocks.STONE.getDefaultState());
        structure.fillWithBlocks(world, start, 159, 1, 5, 163, 1, 17, Blocks.SANDSTONE.getDefaultState());
        structure.fillWithBlocks(world, start, 159, 1, 34, 161, 1, 36, Blocks.STONE.getDefaultState());
        structure.fillWithBlocks(world, start, 159, 1, 48, 159, 1, 59, Blocks.STONE.getDefaultState());
        structure.fillWithBlocks(world, start, 159, 1, 60, 169, 1, 75, Blocks.SANDSTONE.getDefaultState());
        structure.fillWithBlocks(world, start, 159, 1, 109, 166, 1, 116, Blocks.SANDSTONE.getDefaultState());
        structure.fillWithBlocks(world, start, 159, 1, 120, 159, 6, 120, Blocks.SANDSTONE.getDefaultState());
        structure.fillWithBlocks(world, start, 159, 1, 136, 160, 1, 137, Blocks.STONE.getDefaultState());
        structure.fillWithBlocks(world, start, 159, 1, 138, 159, 1, 147, Blocks.SANDSTONE.getDefaultState());
        structure.fillWithBlocks(world, start, 159, 2, 88, 161, 2, 90, Blocks.SANDSTONE.getDefaultState());
        structure.fillWithBlocks(world, start, 159, 2, 91, 159, 2, 93, Blocks.STONE.getDefaultState());
        structure.fillWithBlocks(world, start, 159, 2, 94, 163, 2, 123, Blocks.SANDSTONE.getDefaultState());
        structure.fillWithBlocks(world, start, 159, 2, 124, 160, 2, 130, Blocks.STONE.getDefaultState());
        structure.fillWithBlocks(world, start, 159, 3, 141, 161, 3, 143, Blocks.SANDSTONE.getDefaultState());
        structure.fillWithBlocks(world, start, 159, 4, 9, 161, 4, 141, Blocks.SANDSTONE.getDefaultState());
        structure.fillWithBlocks(world, start, 159, 8, 64, 160, 8, 65, Blocks.SANDSTONE.getDefaultState());
        structure.fillWithBlocks(world, start, 159, 8, 66, 159, 8, 70, Blocks.SANDSTONE_SLAB.getDefaultState().with(SlabBlock.TYPE, SlabType.BOTTOM).with(SlabBlock.WATERLOGGED, false));
        structure.fillWithBlocks(world, start, 159, 9, 64, 159, 9, 65, Blocks.SANDSTONE_SLAB.getDefaultState().with(SlabBlock.TYPE, SlabType.BOTTOM).with(SlabBlock.WATERLOGGED, false));
        structure.fillWithBlocks(world, start, 159, 9, 71, 159, 9, 72, Blocks.SANDSTONE_SLAB.getDefaultState().with(SlabBlock.TYPE, SlabType.BOTTOM).with(SlabBlock.WATERLOGGED, false));
        structure.fillWithBlocks(world, start, 160, -51, 59, 160, -51, 71, Blocks.SANDSTONE.getDefaultState());
        structure.fillWithBlocks(world, start, 160, -50, 57, 161, -50, 58, Blocks.SANDSTONE.getDefaultState());
        structure.fillWithBlocks(world, start, 160, -50, 65, 160, -46, 71, Blocks.AIR.getDefaultState());
        structure.fillWithBlocks(world, start, 160, -50, 72, 161, -50, 73, Blocks.SANDSTONE.getDefaultState());
        structure.fillWithBlocks(world, start, 160, -49, 39, 162, -49, 41, Blocks.AIR.getDefaultState());
        structure.fillWithBlocks(world, start, 160, -48, 15, 160, -48, 15, Blocks.SANDSTONE.getDefaultState());
        structure.fillWithBlocks(world, start, 160, -48, 21, 160, -48, 21, Blocks.SANDSTONE.getDefaultState());
        structure.fillWithBlocks(world, start, 160, -48, 39, 162, -48, 41, Blocks.AIR.getDefaultState());
        structure.fillWithBlocks(world, start, 160, -48, 43, 167, -48, 50, Blocks.SANDSTONE.getDefaultState());
        structure.fillWithBlocks(world, start, 160, -45, 26, 169, -45, 35, Blocks.SANDSTONE.getDefaultState());
        structure.fillWithBlocks(world, start, 160, -45, 72, 161, -45, 73, Blocks.SANDSTONE.getDefaultState());
        structure.fillWithBlocks(world, start, 160, -44, 59, 162, -44, 73, Blocks.SANDSTONE.getDefaultState());
        structure.fillWithBlocks(world, start, 160, -43, 39, 171, -43, 50, Blocks.SANDSTONE.getDefaultState());
        structure.fillWithBlocks(world, start, 160, -40, 31, 160, -39, 45, Blocks.STONE_BRICKS.getDefaultState());
        structure.fillWithBlocks(world, start, 160, -38, 32, 160, -37, 33, Blocks.STONE_BRICKS.getDefaultState());
        structure.fillWithBlocks(world, start, 160, -38, 34, 160, -38, 45, Blocks.STONE_BRICKS.getDefaultState());
        structure.fillWithBlocks(world, start, 160, -37, 31, 160, -36, 32, Blocks.STONE_BRICKS.getDefaultState());
        structure.fillWithBlocks(world, start, 160, -37, 35, 160, -31, 45, Blocks.STONE_BRICKS.getDefaultState());
        structure.fillWithBlocks(world, start, 160, -36, 34, 160, -31, 45, Blocks.STONE_BRICKS.getDefaultState());
        structure.fillWithBlocks(world, start, 160, -35, 32, 160, -31, 45, Blocks.STONE_BRICKS.getDefaultState());
        structure.fillWithBlocks(world, start, 160, -9, 66, 162, -9, 68, Blocks.SANDSTONE.getDefaultState());
        structure.fillWithBlocks(world, start, 160, -9, 69, 160, -9, 74, Blocks.SANDSTONE.getDefaultState());
        structure.fillWithBlocks(world, start, 160, -8, 62, 162, -8, 67, Blocks.SANDSTONE.getDefaultState());
        structure.fillWithBlocks(world, start, 160, -8, 68, 160, -8, 71, Blocks.SANDSTONE.getDefaultState());
        structure.fillWithBlocks(world, start, 160, -8, 73, 161, -8, 74, Blocks.SANDSTONE.getDefaultState());
        structure.fillWithBlocks(world, start, 160, -7, 62, 160, -7, 70, Blocks.SANDSTONE.getDefaultState());
        structure.fillWithBlocks(world, start, 160, -7, 71, 160, -7, 71, Blocks.AIR.getDefaultState());
        structure.fillWithBlocks(world, start, 160, -7, 72, 160, -7, 74, Blocks.SANDSTONE.getDefaultState());
        structure.fillWithBlocks(world, start, 160, -6, 62, 161, -6, 74, Blocks.SANDSTONE.getDefaultState());
        structure.fillWithBlocks(world, start, 160, -5, 62, 162, -5, 66, Blocks.SANDSTONE.getDefaultState());
        structure.fillWithBlocks(world, start, 160, -3, 73, 161, -3, 74, Blocks.SANDSTONE.getDefaultState());
        structure.fillWithBlocks(world, start, 160, -2, 63, 162, -2, 68, Blocks.SANDSTONE.getDefaultState());
        structure.fillWithBlocks(world, start, 160, -2, 70, 161, -2, 74, Blocks.SANDSTONE.getDefaultState());
        structure.fillWithBlocks(world, start, 160, -1, 66, 160, -1, 67, Blocks.SANDSTONE.getDefaultState());
        structure.fillWithBlocks(world, start, 160, -1, 69, 162, -1, 73, Blocks.SANDSTONE.getDefaultState());
        structure.fillWithBlocks(world, start, 160, 0, 35, 160, 0, 35, Blocks.STONE.getDefaultState());
        structure.fillWithBlocks(world, start, 160, 0, 36, 160, 0, 43, Blocks.SANDSTONE.getDefaultState());
        structure.fillWithBlocks(world, start, 160, 0, 44, 160, 0, 112, Blocks.STONE.getDefaultState());
        structure.fillWithBlocks(world, start, 160, 0, 113, 165, 0, 119, Blocks.SANDSTONE.getDefaultState());
        structure.fillWithBlocks(world, start, 160, 0, 138, 161, 0, 139, Blocks.STONE.getDefaultState());
        structure.fillWithBlocks(world, start, 160, 0, 140, 168, 0, 148, Blocks.SANDSTONE.getDefaultState());
        structure.fillWithBlocks(world, start, 160, 1, 37, 160, 1, 37, Blocks.STONE.getDefaultState());
        structure.fillWithBlocks(world, start, 160, 1, 48, 161, 1, 49, Blocks.SANDSTONE.getDefaultState());
        structure.fillWithBlocks(world, start, 160, 1, 50, 160, 1, 59, Blocks.STONE.getDefaultState());
        structure.fillWithBlocks(world, start, 160, 1, 106, 160, 1, 107, Blocks.STONE.getDefaultState());
        structure.fillWithBlocks(world, start, 160, 1, 108, 167, 1, 115, Blocks.SANDSTONE.getDefaultState());
        structure.fillWithBlocks(world, start, 160, 1, 120, 166, 1, 127, Blocks.STONE.getDefaultState());
        structure.fillWithBlocks(world, start, 160, 1, 138, 165, 1, 138, Blocks.STONE.getDefaultState());
        structure.fillWithBlocks(world, start, 160, 1, 139, 167, 1, 146, Blocks.SANDSTONE.getDefaultState());
        structure.fillWithBlocks(world, start, 160, 2, 91, 165, 2, 96, Blocks.SANDSTONE.getDefaultState());
        structure.fillWithBlocks(world, start, 160, 3, 8, 163, 3, 143, Blocks.SANDSTONE.getDefaultState());
        structure.fillWithBlocks(world, start, 160, 8, 71, 160, 8, 72, Blocks.SANDSTONE.getDefaultState());
        structure.fillWithBlocks(world, start, 161, -51, 36, 161, -50, 40, Blocks.SANDSTONE.getDefaultState());
        structure.fillWithBlocks(world, start, 161, -50, 14, 169, -50, 22, Blocks.SANDSTONE.getDefaultState());
        structure.fillWithBlocks(world, start, 161, -50, 59, 162, -50, 73, Blocks.SANDSTONE.getDefaultState());
        structure.fillWithBlocks(world, start, 161, -49, 14, 161, -47, 16, Blocks.SANDSTONE.getDefaultState());
        structure.fillWithBlocks(world, start, 161, -49, 17, 161, -49, 17, Blocks.AIR.getDefaultState());
        structure.fillWithBlocks(world, start, 161, -49, 20, 161, -47, 22, Blocks.SANDSTONE.getDefaultState());
        structure.fillWithBlocks(world, start, 161, -49, 35, 162, -49, 41, Blocks.AIR.getDefaultState());
        structure.fillWithBlocks(world, start, 161, -49, 58, 161, -49, 58, Blocks.SANDSTONE.getDefaultState());
        structure.fillWithBlocks(world, start, 161, -49, 59, 161, -49, 61, Blocks.IRON_BARS.getDefaultState().with(FourWayBlock.WATERLOGGED, false).with(FourWayBlock.NORTH, true).with(FourWayBlock.SOUTH, true).with(FourWayBlock.EAST, true).with(FourWayBlock.WEST, true));
        structure.fillWithBlocks(world, start, 161, -49, 62, 161, -49, 62, Blocks.SANDSTONE.getDefaultState());
        structure.fillWithBlocks(world, start, 161, -49, 63, 161, -49, 64, Blocks.IRON_BARS.getDefaultState().with(FourWayBlock.WATERLOGGED, false).with(FourWayBlock.NORTH, true).with(FourWayBlock.SOUTH, true).with(FourWayBlock.EAST, true).with(FourWayBlock.WEST, true));
        structure.fillWithBlocks(world, start, 161, -49, 66, 161, -49, 67, Blocks.IRON_BARS.getDefaultState().with(FourWayBlock.WATERLOGGED, false).with(FourWayBlock.NORTH, true).with(FourWayBlock.SOUTH, true).with(FourWayBlock.EAST, true).with(FourWayBlock.WEST, true));
        structure.fillWithBlocks(world, start, 161, -49, 68, 161, -49, 68, Blocks.SANDSTONE.getDefaultState());
        structure.fillWithBlocks(world, start, 161, -49, 69, 161, -49, 71, Blocks.IRON_BARS.getDefaultState().with(FourWayBlock.WATERLOGGED, false).with(FourWayBlock.NORTH, true).with(FourWayBlock.SOUTH, true).with(FourWayBlock.EAST, true).with(FourWayBlock.WEST, true));
        structure.fillWithBlocks(world, start, 161, -49, 72, 162, -49, 73, Blocks.SANDSTONE.getDefaultState());
        structure.fillWithBlocks(world, start, 161, -48, 17, 163, -48, 19, Blocks.AIR.getDefaultState());
        structure.fillWithBlocks(world, start, 161, -48, 34, 172, -41, 34, Blocks.SANDSTONE.getDefaultState());
        structure.fillWithBlocks(world, start, 161, -48, 35, 162, -48, 41, Blocks.AIR.getDefaultState());
        structure.fillWithBlocks(world, start, 161, -48, 42, 169, -48, 50, Blocks.SANDSTONE.getDefaultState());
        structure.fillWithBlocks(world, start, 161, -48, 58, 161, -48, 58, Blocks.SANDSTONE.getDefaultState());
        structure.fillWithBlocks(world, start, 161, -48, 59, 161, -46, 61, Blocks.AIR.getDefaultState());
        structure.fillWithBlocks(world, start, 161, -48, 62, 161, -48, 62, Blocks.SANDSTONE.getDefaultState());
        structure.fillWithBlocks(world, start, 161, -48, 68, 161, -48, 68, Blocks.SANDSTONE.getDefaultState());
        structure.fillWithBlocks(world, start, 161, -48, 69, 161, -46, 71, Blocks.AIR.getDefaultState());
        structure.fillWithBlocks(world, start, 161, -48, 72, 162, -48, 73, Blocks.SANDSTONE.getDefaultState());
        structure.fillWithBlocks(world, start, 161, -47, 17, 163, -47, 19, Blocks.AIR.getDefaultState());
        structure.fillWithBlocks(world, start, 161, -47, 58, 161, -47, 58, Blocks.SANDSTONE.getDefaultState());
        structure.fillWithBlocks(world, start, 161, -47, 62, 161, -47, 62, Blocks.SANDSTONE.getDefaultState());
        structure.fillWithBlocks(world, start, 161, -47, 68, 161, -47, 68, Blocks.SANDSTONE.getDefaultState());
        structure.fillWithBlocks(world, start, 161, -47, 72, 162, -47, 73, Blocks.SANDSTONE.getDefaultState());
        structure.fillWithBlocks(world, start, 161, -46, 14, 162, -46, 22, Blocks.SANDSTONE.getDefaultState());
        structure.fillWithBlocks(world, start, 161, -46, 58, 161, -46, 58, Blocks.SANDSTONE.getDefaultState());
        structure.fillWithBlocks(world, start, 161, -46, 62, 161, -46, 62, Blocks.SANDSTONE.getDefaultState());
        structure.fillWithBlocks(world, start, 161, -46, 68, 161, -46, 68, Blocks.SANDSTONE.getDefaultState());
        structure.fillWithBlocks(world, start, 161, -46, 72, 162, -46, 73, Blocks.SANDSTONE.getDefaultState());
        structure.fillWithBlocks(world, start, 161, -45, 14, 163, -45, 22, Blocks.SANDSTONE.getDefaultState());
        structure.fillWithBlocks(world, start, 161, -45, 59, 162, -45, 73, Blocks.SANDSTONE.getDefaultState());
        structure.fillWithBlocks(world, start, 161, -44, 14, 164, -44, 22, Blocks.SANDSTONE.getDefaultState());
        structure.fillWithBlocks(world, start, 161, -43, 14, 169, -43, 22, Blocks.SANDSTONE.getDefaultState());
        structure.fillWithBlocks(world, start, 161, -43, 38, 172, -43, 50, Blocks.SANDSTONE.getDefaultState());
        structure.fillWithBlocks(world, start, 161, -42, 14, 169, -42, 22, Blocks.SANDSTONE.getDefaultState());
        structure.fillWithBlocks(world, start, 161, -41, 14, 169, -41, 22, Blocks.SANDSTONE.getDefaultState());
        structure.fillWithBlocks(world, start, 161, -10, 62, 162, -10, 63, Blocks.SANDSTONE.getDefaultState());
        structure.fillWithBlocks(world, start, 161, -10, 65, 162, -10, 68, Blocks.SANDSTONE.getDefaultState());
        structure.fillWithBlocks(world, start, 161, -10, 73, 161, -10, 74, Blocks.AIR.getDefaultState());
        structure.fillWithBlocks(world, start, 161, -9, 70, 162, -9, 74, Blocks.SANDSTONE.getDefaultState());
        structure.fillWithBlocks(world, start, 161, -8, 69, 162, -8, 72, Blocks.SANDSTONE.getDefaultState());
        structure.fillWithBlocks(world, start, 161, -7, 63, 162, -7, 69, Blocks.SANDSTONE.getDefaultState());
        structure.fillWithBlocks(world, start, 161, -7, 71, 161, -7, 71, Blocks.SANDSTONE.getDefaultState());
        structure.fillWithBlocks(world, start, 161, -7, 72, 161, -7, 72, Blocks.AIR.getDefaultState());
        structure.fillWithBlocks(world, start, 161, -7, 73, 161, -6, 74, Blocks.SANDSTONE.getDefaultState());
        structure.fillWithBlocks(world, start, 161, -5, 69, 162, -5, 74, Blocks.SANDSTONE.getDefaultState());
        structure.fillWithBlocks(world, start, 161, -4, 62, 161, -4, 63, Blocks.AIR.getDefaultState());
        structure.fillWithBlocks(world, start, 161, -4, 64, 162, -4, 66, Blocks.SANDSTONE.getDefaultState());
        structure.fillWithBlocks(world, start, 161, -4, 73, 162, -4, 74, Blocks.SANDSTONE.getDefaultState());
        structure.fillWithBlocks(world, start, 161, -3, 62, 162, -3, 63, Blocks.SANDSTONE.getDefaultState());
        structure.fillWithBlocks(world, start, 161, -3, 65, 162, -3, 74, Blocks.SANDSTONE.getDefaultState());
        structure.fillWithBlocks(world, start, 161, -2, 62, 162, -2, 69, Blocks.SANDSTONE.getDefaultState());
        structure.fillWithBlocks(world, start, 161, -1, 65, 162, -1, 66, Blocks.SANDSTONE.getDefaultState());
        structure.fillWithBlocks(world, start, 161, -1, 68, 162, -1, 74, Blocks.SANDSTONE.getDefaultState());
        structure.fillWithBlocks(world, start, 161, 0, 3, 162, 0, 10, Blocks.SANDSTONE.getDefaultState());
        structure.fillWithBlocks(world, start, 161, 0, 11, 161, 0, 13, Blocks.STONE.getDefaultState());
        structure.fillWithBlocks(world, start, 161, 0, 14, 162, 0, 15, Blocks.SANDSTONE.getDefaultState());
        structure.fillWithBlocks(world, start, 161, 0, 16, 161, 0, 36, Blocks.STONE.getDefaultState());
        structure.fillWithBlocks(world, start, 161, 0, 37, 161, 0, 44, Blocks.SANDSTONE.getDefaultState());
        structure.fillWithBlocks(world, start, 161, 0, 45, 161, 0, 112, Blocks.STONE.getDefaultState());
        structure.fillWithBlocks(world, start, 161, 0, 120, 161, 0, 121, Blocks.SANDSTONE.getDefaultState());
        structure.fillWithBlocks(world, start, 161, 1, 37, 162, 1, 38, Blocks.STONE.getDefaultState());
        structure.fillWithBlocks(world, start, 161, 1, 39, 161, 1, 53, Blocks.SANDSTONE.getDefaultState());
        structure.fillWithBlocks(world, start, 161, 1, 54, 161, 1, 58, Blocks.STONE.getDefaultState());
        structure.fillWithBlocks(world, start, 161, 1, 59, 169, 1, 75, Blocks.SANDSTONE.getDefaultState());
        structure.fillWithBlocks(world, start, 161, 1, 107, 168, 1, 114, Blocks.SANDSTONE.getDefaultState());
        structure.fillWithBlocks(world, start, 161, 1, 133, 165, 1, 138, Blocks.STONE.getDefaultState());
        structure.fillWithBlocks(world, start, 161, 2, 124, 161, 2, 124, Blocks.SANDSTONE.getDefaultState());
        structure.fillWithBlocks(world, start, 161, 2, 125, 161, 2, 128, Blocks.STONE.getDefaultState());
        structure.fillWithBlocks(world, start, 161, 2, 129, 174, 2, 142, Blocks.SANDSTONE.getDefaultState());
        structure.fillWithBlocks(world, start, 161, 7, 64, 162, 7, 65, Blocks.SANDSTONE.getDefaultState());
        structure.fillWithBlocks(world, start, 161, 7, 66, 161, 7, 70, Blocks.SANDSTONE_STAIRS.getDefaultState().with(StairsBlock.FACING, Direction.WEST).with(StairsBlock.WATERLOGGED, false).with(StairsBlock.SHAPE, StairsShape.STRAIGHT).with(StairsBlock.HALF, Half.BOTTOM));
        structure.fillWithBlocks(world, start, 161, 7, 71, 162, 7, 72, Blocks.SANDSTONE.getDefaultState());
        structure.fillWithBlocks(world, start, 161, 8, 64, 161, 8, 65, Blocks.SANDSTONE_STAIRS.getDefaultState().with(StairsBlock.FACING, Direction.WEST).with(StairsBlock.WATERLOGGED, false).with(StairsBlock.SHAPE, StairsShape.STRAIGHT).with(StairsBlock.HALF, Half.BOTTOM));
        structure.fillWithBlocks(world, start, 161, 8, 71, 161, 8, 72, Blocks.SANDSTONE_STAIRS.getDefaultState().with(StairsBlock.FACING, Direction.WEST).with(StairsBlock.WATERLOGGED, false).with(StairsBlock.SHAPE, StairsShape.STRAIGHT).with(StairsBlock.HALF, Half.BOTTOM));
        structure.fillWithBlocks(world, start, 162, -50, 57, 162, -41, 73, Blocks.SANDSTONE.getDefaultState());
        structure.fillWithBlocks(world, start, 162, -49, 14, 169, -42, 14, Blocks.SANDSTONE.getDefaultState());
        structure.fillWithBlocks(world, start, 162, -49, 15, 164, -49, 21, Blocks.AIR.getDefaultState());
        structure.fillWithBlocks(world, start, 162, -49, 22, 169, -42, 22, Blocks.SANDSTONE.getDefaultState());
        structure.fillWithBlocks(world, start, 162, -48, 15, 164, -48, 21, Blocks.AIR.getDefaultState());
