package mod.arcalitegames.odyssey.world.structure.structures.dungeons.ziggurat;

import mod.arcalitegames.odyssey.world.structure.StructureBase;
import net.minecraft.block.Blocks;
import net.minecraft.block.FourWayBlock;
import net.minecraft.block.RedstoneWireBlock;
import net.minecraft.block.StairsBlock;
import net.minecraft.state.properties.Half;
import net.minecraft.state.properties.RedstoneSide;
import net.minecraft.state.properties.StairsShape;
import net.minecraft.util.Direction;
import net.minecraft.util.math.BlockPos;
import net.minecraft.world.World;

public class ZigguratComponent1
{
	public static BlockPos start;
    public static World world;
    public static StructureBase structure;

    public static void init(World worldIn, BlockPos blockPos, StructureBase structureIn)
    {
        world = worldIn; start = blockPos; structure = structureIn;
    }
    
    public static void generatePart11()
    {
        structure.fillWithBlocks(world, start, 35, -30, 31, 36, -30, 32, Blocks.SANDSTONE.getDefaultState());
        structure.fillWithBlocks(world, start, 35, -30, 34, 50, -30, 34, Blocks.SANDSTONE.getDefaultState());
        structure.fillWithBlocks(world, start, 35, -30, 35, 35, -30, 35, Blocks.DIRT.getDefaultState());
        structure.fillWithBlocks(world, start, 35, -30, 36, 35, -29, 38, Blocks.SANDSTONE.getDefaultState());
        structure.fillWithBlocks(world, start, 35, -30, 39, 36, -30, 39, Blocks.AIR.getDefaultState());
        structure.fillWithBlocks(world, start, 35, -30, 40, 35, -30, 40, Blocks.DIRT.getDefaultState());
        structure.fillWithBlocks(world, start, 35, -30, 41, 35, -28, 41, Blocks.SANDSTONE.getDefaultState());
        structure.fillWithBlocks(world, start, 35, -30, 42, 35, -30, 45, Blocks.DIRT.getDefaultState());
        structure.fillWithBlocks(world, start, 35, -30, 46, 35, -28, 50, Blocks.SANDSTONE.getDefaultState());
        structure.fillWithBlocks(world, start, 35, -30, 51, 35, -30, 51, Blocks.AIR.getDefaultState());
        structure.fillWithBlocks(world, start, 35, -30, 52, 35, -30, 53, Blocks.SANDSTONE.getDefaultState());
        structure.fillWithBlocks(world, start, 35, -30, 54, 35, -30, 54, Blocks.AIR.getDefaultState());
        structure.fillWithBlocks(world, start, 35, -30, 55, 35, -30, 56, Blocks.DIRT.getDefaultState());
        structure.fillWithBlocks(world, start, 35, -30, 59, 35, -30, 59, Blocks.AIR.getDefaultState());
        structure.fillWithBlocks(world, start, 35, -30, 60, 35, -21, 60, Blocks.SANDSTONE.getDefaultState());
        structure.fillWithBlocks(world, start, 35, -29, -4, 35, -29, -1, Blocks.STONE_BRICKS.getDefaultState());
        structure.fillWithBlocks(world, start, 35, -29, 0, 36, -29, 0, Blocks.SANDSTONE.getDefaultState());
        structure.fillWithBlocks(world, start, 35, -29, 1, 35, -27, 1, Blocks.STONE_BRICKS.getDefaultState());
        structure.fillWithBlocks(world, start, 35, -29, 2, 35, -29, 3, Blocks.SANDSTONE.getDefaultState());
        structure.fillWithBlocks(world, start, 35, -29, 8, 35, -29, 16, Blocks.SANDSTONE.getDefaultState());
        structure.fillWithBlocks(world, start, 35, -29, 18, 35, -29, 23, Blocks.SANDSTONE.getDefaultState());
        structure.fillWithBlocks(world, start, 35, -29, 25, 35, -27, 28, Blocks.SANDSTONE.getDefaultState());
        structure.fillWithBlocks(world, start, 35, -29, 30, 35, -29, 38, Blocks.SANDSTONE.getDefaultState());
        structure.fillWithBlocks(world, start, 35, -29, 40, 36, -29, 41, Blocks.SANDSTONE.getDefaultState());
        structure.fillWithBlocks(world, start, 35, -29, 51, 35, -21, 51, Blocks.SANDSTONE.getDefaultState());
        structure.fillWithBlocks(world, start, 35, -29, 53, 36, -29, 54, Blocks.SANDSTONE.getDefaultState());
        structure.fillWithBlocks(world, start, 35, -29, 56, 35, -29, 65, Blocks.SANDSTONE.getDefaultState());
        structure.fillWithBlocks(world, start, 35, -28, -6, 35, -28, -5, Blocks.STONE_BRICKS.getDefaultState());
        structure.fillWithBlocks(world, start, 35, -28, -3, 36, -28, -2, Blocks.STONE_BRICKS.getDefaultState());
        structure.fillWithBlocks(world, start, 35, -28, -1, 35, -28, 0, Blocks.DIRT.getDefaultState());
        structure.fillWithBlocks(world, start, 35, -28, 4, 35, -28, 7, Blocks.STONE_BRICKS.getDefaultState());
        structure.fillWithBlocks(world, start, 35, -28, 8, 35, -25, 8, Blocks.SANDSTONE.getDefaultState());
        structure.fillWithBlocks(world, start, 35, -28, 9, 35, -28, 9, Blocks.AIR.getDefaultState());
        structure.fillWithBlocks(world, start, 35, -28, 11, 35, -28, 11, Blocks.AIR.getDefaultState());
        structure.fillWithBlocks(world, start, 35, -28, 12, 35, -28, 17, Blocks.SANDSTONE.getDefaultState());
        structure.fillWithBlocks(world, start, 35, -28, 18, 35, -27, 18, Blocks.DIRT.getDefaultState());
        structure.fillWithBlocks(world, start, 35, -28, 19, 36, -28, 25, Blocks.SANDSTONE.getDefaultState());
        structure.fillWithBlocks(world, start, 35, -28, 29, 35, -28, 29, Blocks.AIR.getDefaultState());
        structure.fillWithBlocks(world, start, 35, -28, 30, 35, -21, 30, Blocks.SANDSTONE.getDefaultState());
        structure.fillWithBlocks(world, start, 35, -28, 31, 35, -28, 31, Blocks.AIR.getDefaultState());
        structure.fillWithBlocks(world, start, 35, -28, 33, 35, -28, 33, Blocks.AIR.getDefaultState());
        structure.fillWithBlocks(world, start, 35, -28, 34, 35, -24, 34, Blocks.SANDSTONE.getDefaultState());
        structure.fillWithBlocks(world, start, 35, -28, 36, 36, -28, 37, Blocks.SANDSTONE.getDefaultState());
        structure.fillWithBlocks(world, start, 35, -28, 38, 35, -28, 39, Blocks.AIR.getDefaultState());
        structure.fillWithBlocks(world, start, 35, -28, 43, 36, -28, 50, Blocks.SANDSTONE.getDefaultState());
        structure.fillWithBlocks(world, start, 35, -28, 52, 36, -28, 55, Blocks.SANDSTONE.getDefaultState());
        structure.fillWithBlocks(world, start, 35, -28, 61, 36, -28, 63, Blocks.SANDSTONE.getDefaultState());
        structure.fillWithBlocks(world, start, 35, -28, 65, 36, -27, 65, Blocks.SANDSTONE.getDefaultState());
        structure.fillWithBlocks(world, start, 35, -27, -6, 35, -27, -1, Blocks.STONE_BRICKS.getDefaultState());
        structure.fillWithBlocks(world, start, 35, -27, 0, 35, -27, 0, Blocks.DIRT.getDefaultState());
        structure.fillWithBlocks(world, start, 35, -27, 2, 35, -27, 2, Blocks.STONE_BRICKS.getDefaultState());
        structure.fillWithBlocks(world, start, 35, -27, 3, 35, -27, 4, Blocks.AIR.getDefaultState());
        structure.fillWithBlocks(world, start, 35, -27, 6, 35, -26, 7, Blocks.STONE_BRICKS.getDefaultState());
        structure.fillWithBlocks(world, start, 35, -27, 9, 37, -27, 11, Blocks.AIR.getDefaultState());
        structure.fillWithBlocks(world, start, 35, -27, 12, 35, -27, 16, Blocks.SANDSTONE.getDefaultState());
        structure.fillWithBlocks(world, start, 35, -27, 19, 35, -27, 28, Blocks.SANDSTONE.getDefaultState());
        structure.fillWithBlocks(world, start, 35, -27, 31, 37, -27, 33, Blocks.AIR.getDefaultState());
        structure.fillWithBlocks(world, start, 35, -27, 35, 36, -27, 40, Blocks.SANDSTONE.getDefaultState());
        structure.fillWithBlocks(world, start, 35, -27, 41, 36, -27, 41, Blocks.DIRT.getDefaultState());
        structure.fillWithBlocks(world, start, 35, -27, 46, 36, -27, 47, Blocks.SANDSTONE.getDefaultState());
        structure.fillWithBlocks(world, start, 35, -27, 49, 35, -27, 49, Blocks.SANDSTONE.getDefaultState());
        structure.fillWithBlocks(world, start, 35, -27, 50, 35, -27, 50, Blocks.AIR.getDefaultState());
        structure.fillWithBlocks(world, start, 35, -27, 52, 35, -26, 55, Blocks.SANDSTONE.getDefaultState());
        structure.fillWithBlocks(world, start, 35, -27, 56, 35, -27, 57, Blocks.DIRT.getDefaultState());
        structure.fillWithBlocks(world, start, 35, -27, 58, 37, -27, 62, Blocks.SANDSTONE.getDefaultState());
        structure.fillWithBlocks(world, start, 35, -27, 64, 36, -27, 65, Blocks.SANDSTONE.getDefaultState());
        structure.fillWithBlocks(world, start, 35, -26, -5, 35, -26, -2, Blocks.STONE_BRICKS.getDefaultState());
        structure.fillWithBlocks(world, start, 35, -26, -1, 35, -25, -1, Blocks.AIR.getDefaultState());
        structure.fillWithBlocks(world, start, 35, -26, 0, 36, -25, 0, Blocks.STONE_BRICKS.getDefaultState());
        structure.fillWithBlocks(world, start, 35, -26, 1, 35, -26, 1, Blocks.SANDSTONE.getDefaultState());
        structure.fillWithBlocks(world, start, 35, -26, 3, 35, -26, 7, Blocks.STONE_BRICKS.getDefaultState());
        structure.fillWithBlocks(world, start, 35, -26, 9, 37, -26, 11, Blocks.AIR.getDefaultState());
        structure.fillWithBlocks(world, start, 35, -26, 12, 35, -21, 12, Blocks.SANDSTONE.getDefaultState());
        structure.fillWithBlocks(world, start, 35, -26, 14, 35, -25, 18, Blocks.SANDSTONE.getDefaultState());
        structure.fillWithBlocks(world, start, 35, -26, 26, 35, -26, 30, Blocks.SANDSTONE.getDefaultState());
        structure.fillWithBlocks(world, start, 35, -26, 31, 37, -26, 33, Blocks.AIR.getDefaultState());
        structure.fillWithBlocks(world, start, 35, -26, 36, 36, -26, 37, Blocks.SANDSTONE.getDefaultState());
        structure.fillWithBlocks(world, start, 35, -26, 39, 35, -26, 39, Blocks.SANDSTONE.getDefaultState());
        structure.fillWithBlocks(world, start, 35, -26, 41, 35, -26, 46, Blocks.SANDSTONE.getDefaultState());
        structure.fillWithBlocks(world, start, 35, -26, 47, 36, -26, 47, Blocks.AIR.getDefaultState());
        structure.fillWithBlocks(world, start, 35, -26, 48, 35, -26, 49, Blocks.SANDSTONE.getDefaultState());
        structure.fillWithBlocks(world, start, 35, -26, 56, 36, -26, 57, Blocks.SANDSTONE.getDefaultState());
        structure.fillWithBlocks(world, start, 35, -26, 58, 35, -21, 58, Blocks.SANDSTONE.getDefaultState());
        structure.fillWithBlocks(world, start, 35, -26, 61, 35, -26, 65, Blocks.SANDSTONE.getDefaultState());
        structure.fillWithBlocks(world, start, 35, -25, -4, 35, -24, -4, Blocks.STONE_BRICKS.getDefaultState());
        structure.fillWithBlocks(world, start, 35, -25, 3, 35, -23, 3, Blocks.STONE_BRICKS.getDefaultState());
        structure.fillWithBlocks(world, start, 35, -25, 5, 36, -25, 5, Blocks.STONE_BRICKS.getDefaultState());
        structure.fillWithBlocks(world, start, 35, -25, 6, 35, -25, 6, Blocks.SANDSTONE.getDefaultState());
        structure.fillWithBlocks(world, start, 35, -25, 9, 35, -24, 12, Blocks.SANDSTONE.getDefaultState());
        structure.fillWithBlocks(world, start, 35, -25, 20, 35, -23, 22, Blocks.SANDSTONE.getDefaultState());
        structure.fillWithBlocks(world, start, 35, -25, 35, 38, -25, 38, Blocks.SANDSTONE.getDefaultState());
        structure.fillWithBlocks(world, start, 35, -25, 40, 36, -25, 41, Blocks.SANDSTONE.getDefaultState());
        structure.fillWithBlocks(world, start, 35, -25, 43, 36, -25, 44, Blocks.SANDSTONE.getDefaultState());
        structure.fillWithBlocks(world, start, 35, -25, 46, 36, -25, 47, Blocks.SANDSTONE.getDefaultState());
        structure.fillWithBlocks(world, start, 35, -25, 49, 37, -25, 51, Blocks.SANDSTONE.getDefaultState());
        structure.fillWithBlocks(world, start, 35, -25, 53, 36, -25, 53, Blocks.DIRT.getDefaultState());
        structure.fillWithBlocks(world, start, 35, -25, 54, 36, -25, 65, Blocks.SANDSTONE.getDefaultState());
        structure.fillWithBlocks(world, start, 35, -24, -5, 37, -24, -1, Blocks.STONE_BRICKS.getDefaultState());
        structure.fillWithBlocks(world, start, 35, -24, 0, 35, -24, 1, Blocks.AIR.getDefaultState());
        structure.fillWithBlocks(world, start, 35, -24, 4, 35, -24, 5, Blocks.AIR.getDefaultState());
        structure.fillWithBlocks(world, start, 35, -24, 6, 36, -23, 6, Blocks.STONE_BRICKS.getDefaultState());
        structure.fillWithBlocks(world, start, 35, -24, 13, 35, -24, 14, Blocks.AIR.getDefaultState());
        structure.fillWithBlocks(world, start, 35, -24, 16, 35, -24, 17, Blocks.SANDSTONE.getDefaultState());
        structure.fillWithBlocks(world, start, 35, -24, 19, 37, -24, 24, Blocks.SANDSTONE.getDefaultState());
        structure.fillWithBlocks(world, start, 35, -24, 28, 41, -24, 42, Blocks.SANDSTONE.getDefaultState());
        structure.fillWithBlocks(world, start, 35, -24, 45, 35, -24, 60, Blocks.SANDSTONE.getDefaultState());
        structure.fillWithBlocks(world, start, 35, -23, -5, 35, -22, -5, Blocks.STONE_BRICKS.getDefaultState());
        structure.fillWithBlocks(world, start, 35, -23, -4, 35, -23, -3, Blocks.SANDSTONE.getDefaultState());
        structure.fillWithBlocks(world, start, 35, -23, -2, 35, -23, 1, Blocks.STONE_BRICKS.getDefaultState());
        structure.fillWithBlocks(world, start, 35, -23, 4, 35, -22, 6, Blocks.STONE_BRICKS.getDefaultState());
        structure.fillWithBlocks(world, start, 35, -23, 8, 35, -23, 9, Blocks.AIR.getDefaultState());
        structure.fillWithBlocks(world, start, 35, -23, 10, 37, -23, 10, Blocks.DIRT.getDefaultState());
        structure.fillWithBlocks(world, start, 35, -23, 11, 37, -23, 15, Blocks.SANDSTONE.getDefaultState());
        structure.fillWithBlocks(world, start, 35, -23, 17, 36, -23, 17, Blocks.DIRT.getDefaultState());
        structure.fillWithBlocks(world, start, 35, -23, 18, 37, -23, 20, Blocks.SANDSTONE.getDefaultState());
        structure.fillWithBlocks(world, start, 35, -23, 23, 35, -23, 23, Blocks.SANDSTONE.getDefaultState());
        structure.fillWithBlocks(world, start, 35, -23, 25, 35, -23, 33, Blocks.SANDSTONE.getDefaultState());
        structure.fillWithBlocks(world, start, 35, -23, 34, 35, -22, 34, Blocks.AIR.getDefaultState());
        structure.fillWithBlocks(world, start, 35, -23, 35, 35, -23, 35, Blocks.SANDSTONE.getDefaultState());
        structure.fillWithBlocks(world, start, 35, -23, 36, 35, -23, 36, Blocks.AIR.getDefaultState());
        structure.fillWithBlocks(world, start, 35, -23, 37, 35, -21, 39, Blocks.SANDSTONE.getDefaultState());
        structure.fillWithBlocks(world, start, 35, -23, 44, 36, -23, 48, Blocks.SANDSTONE.getDefaultState());
        structure.fillWithBlocks(world, start, 35, -23, 50, 37, -23, 52, Blocks.SANDSTONE.getDefaultState());
        structure.fillWithBlocks(world, start, 35, -23, 55, 35, -22, 56, Blocks.SANDSTONE.getDefaultState());
        structure.fillWithBlocks(world, start, 35, -23, 59, 38, -23, 63, Blocks.SANDSTONE.getDefaultState());
        structure.fillWithBlocks(world, start, 35, -22, -3, 35, -21, -2, Blocks.STONE_BRICKS.getDefaultState());
        structure.fillWithBlocks(world, start, 35, -22, 0, 35, -22, 0, Blocks.STONE_BRICKS.getDefaultState());
        structure.fillWithBlocks(world, start, 35, -22, 2, 35, -22, 2, Blocks.STONE_BRICKS.getDefaultState());
        structure.fillWithBlocks(world, start, 35, -22, 9, 39, -22, 13, Blocks.SANDSTONE.getDefaultState());
        structure.fillWithBlocks(world, start, 35, -22, 17, 35, -22, 17, Blocks.SANDSTONE.getDefaultState());
        structure.fillWithBlocks(world, start, 35, -22, 19, 35, -21, 19, Blocks.AIR.getDefaultState());
        structure.fillWithBlocks(world, start, 35, -22, 20, 36, -22, 22, Blocks.SANDSTONE.getDefaultState());
        structure.fillWithBlocks(world, start, 35, -22, 24, 35, -21, 26, Blocks.SANDSTONE.getDefaultState());
        structure.fillWithBlocks(world, start, 35, -22, 31, 35, -22, 32, Blocks.SANDSTONE.getDefaultState());
        structure.fillWithBlocks(world, start, 35, -22, 33, 35, -22, 34, Blocks.AIR.getDefaultState());
        structure.fillWithBlocks(world, start, 35, -22, 35, 36, -22, 36, Blocks.SANDSTONE.getDefaultState());
        structure.fillWithBlocks(world, start, 35, -22, 41, 35, -22, 42, Blocks.SANDSTONE.getDefaultState());
        structure.fillWithBlocks(world, start, 35, -22, 43, 35, -22, 43, Blocks.DIRT.getDefaultState());
        structure.fillWithBlocks(world, start, 35, -22, 44, 35, -22, 45, Blocks.SANDSTONE.getDefaultState());
        structure.fillWithBlocks(world, start, 35, -22, 61, 36, -21, 61, Blocks.SANDSTONE.getDefaultState());
        structure.fillWithBlocks(world, start, 35, -22, 62, 36, -22, 62, Blocks.AIR.getDefaultState());
        structure.fillWithBlocks(world, start, 35, -22, 63, 35, -22, 65, Blocks.SANDSTONE.getDefaultState());
        structure.fillWithBlocks(world, start, 35, -21, -6, 35, -21, -6, Blocks.STONE_BRICKS.getDefaultState());
        structure.fillWithBlocks(world, start, 35, -21, -4, 35, -21, -2, Blocks.STONE_BRICKS.getDefaultState());
        structure.fillWithBlocks(world, start, 35, -21, 0, 36, -21, 2, Blocks.STONE_BRICKS.getDefaultState());
        structure.fillWithBlocks(world, start, 35, -21, 3, 36, -21, 3, Blocks.AIR.getDefaultState());
        structure.fillWithBlocks(world, start, 35, -21, 4, 35, -21, 6, Blocks.SANDSTONE.getDefaultState());
        structure.fillWithBlocks(world, start, 35, -21, 7, 36, -21, 8, Blocks.STONE_BRICKS.getDefaultState());
        structure.fillWithBlocks(world, start, 35, -21, 15, 36, -21, 16, Blocks.SANDSTONE.getDefaultState());
        structure.fillWithBlocks(world, start, 35, -21, 18, 35, -21, 18, Blocks.SANDSTONE.getDefaultState());
        structure.fillWithBlocks(world, start, 35, -21, 20, 36, -21, 21, Blocks.SANDSTONE.getDefaultState());
        structure.fillWithBlocks(world, start, 35, -21, 22, 36, -21, 22, Blocks.AIR.getDefaultState());
        structure.fillWithBlocks(world, start, 35, -21, 27, 37, -21, 27, Blocks.DIRT.getDefaultState());
        structure.fillWithBlocks(world, start, 35, -21, 29, 37, -21, 31, Blocks.SANDSTONE.getDefaultState());
        structure.fillWithBlocks(world, start, 35, -21, 32, 35, -21, 41, Blocks.SANDSTONE.getDefaultState());
        structure.fillWithBlocks(world, start, 35, -21, 43, 36, -21, 44, Blocks.SANDSTONE.getDefaultState());
        structure.fillWithBlocks(world, start, 35, -21, 46, 36, -21, 47, Blocks.SANDSTONE.getDefaultState());
        structure.fillWithBlocks(world, start, 35, -21, 63, 36, -21, 64, Blocks.SANDSTONE.getDefaultState());
        structure.fillWithBlocks(world, start, 35, -20, 39, 39, -20, 43, Blocks.SANDSTONE.getDefaultState());
        structure.fillWithBlocks(world, start, 35, -19, 34, 35, -18, 35, Blocks.SANDSTONE.getDefaultState());
        structure.fillWithBlocks(world, start, 35, -19, 36, 37, -19, 40, Blocks.AIR.getDefaultState());
        structure.fillWithBlocks(world, start, 35, -19, 41, 35, -19, 44, Blocks.SANDSTONE.getDefaultState());
        structure.fillWithBlocks(world, start, 35, -18, 32, 37, -18, 34, Blocks.SANDSTONE.getDefaultState());
        structure.fillWithBlocks(world, start, 35, -18, 36, 37, -18, 40, Blocks.AIR.getDefaultState());
        structure.fillWithBlocks(world, start, 35, -18, 41, 35, -18, 44, Blocks.SANDSTONE.getDefaultState());
        structure.fillWithBlocks(world, start, 35, -17, 36, 39, -17, 40, Blocks.AIR.getDefaultState());
        structure.fillWithBlocks(world, start, 35, -16, 36, 39, -16, 40, Blocks.AIR.getDefaultState());
        structure.fillWithBlocks(world, start, 35, -16, 41, 35, -16, 44, Blocks.SANDSTONE.getDefaultState());
        structure.fillWithBlocks(world, start, 35, -15, 32, 35, -15, 32, Blocks.SANDSTONE.getDefaultState());
        structure.fillWithBlocks(world, start, 35, -15, 33, 35, -14, 33, Blocks.AIR.getDefaultState());
        structure.fillWithBlocks(world, start, 35, -14, 32, 35, -14, 32, Blocks.SANDSTONE.getDefaultState());
        structure.fillWithBlocks(world, start, 35, -14, 34, 38, -14, 37, Blocks.SANDSTONE.getDefaultState());
        structure.fillWithBlocks(world, start, 35, -13, 32, 38, -13, 37, Blocks.SANDSTONE.getDefaultState());
        structure.fillWithBlocks(world, start, 35, -12, 32, 39, -12, 39, Blocks.SANDSTONE.getDefaultState());
        structure.fillWithBlocks(world, start, 35, -12, 40, 35, -12, 42, Blocks.SANDSTONE.getDefaultState());
        structure.fillWithBlocks(world, start, 35, -12, 43, 35, -12, 43, Blocks.AIR.getDefaultState());
        structure.fillWithBlocks(world, start, 35, -11, 32, 40, -11, 37, Blocks.SANDSTONE.getDefaultState());
        structure.fillWithBlocks(world, start, 35, -11, 39, 40, -11, 44, Blocks.SANDSTONE.getDefaultState());
        structure.fillWithBlocks(world, start, 35, 0, 21, 43, 0, 29, Blocks.STONE.getDefaultState());
        structure.fillWithBlocks(world, start, 35, 0, 124, 35, 0, 127, Blocks.SANDSTONE.getDefaultState());
        structure.fillWithBlocks(world, start, 35, 0, 128, 44, 0, 137, Blocks.STONE.getDefaultState());
        structure.fillWithBlocks(world, start, 35, 0, 138, 35, 0, 147, Blocks.SANDSTONE.getDefaultState());
        structure.fillWithBlocks(world, start, 35, 1, 15, 45, 1, 25, Blocks.SANDSTONE.getDefaultState());
        structure.fillWithBlocks(world, start, 35, 1, 29, 35, 1, 69, Blocks.STONE.getDefaultState());
        structure.fillWithBlocks(world, start, 35, 1, 77, 37, 1, 79, Blocks.SANDSTONE.getDefaultState());
        structure.fillWithBlocks(world, start, 35, 1, 119, 41, 1, 126, Blocks.SANDSTONE.getDefaultState());
        structure.fillWithBlocks(world, start, 35, 1, 133, 71, 5, 133, Blocks.SANDSTONE.getDefaultState());
        structure.fillWithBlocks(world, start, 35, 1, 134, 40, 1, 134, Blocks.STONE.getDefaultState());
        structure.fillWithBlocks(world, start, 35, 1, 135, 36, 1, 144, Blocks.SANDSTONE.getDefaultState());
        structure.fillWithBlocks(world, start, 35, 2, 60, 37, 2, 62, Blocks.STONE.getDefaultState());
        structure.fillWithBlocks(world, start, 35, 2, 142, 176, 2, 142, Blocks.SANDSTONE.getDefaultState());
        structure.fillWithBlocks(world, start, 35, 3, 18, 70, 3, 140, Blocks.SANDSTONE.getDefaultState());
        structure.fillWithBlocks(world, start, 35, 4, 137, 35, 4, 137, Blocks.SANDSTONE.getDefaultState());
        structure.fillWithBlocks(world, start, 35, 5, 21, 100, 5, 134, Blocks.SANDSTONE.getDefaultState());
        structure.fillWithBlocks(world, start, 35, 6, 29, 100, 6, 123, Blocks.SANDSTONE.getDefaultState());
        structure.fillWithBlocks(world, start, 36, -50, 30, 37, -50, 31, Blocks.SANDSTONE.getDefaultState());
        structure.fillWithBlocks(world, start, 36, -50, 45, 37, -50, 46, Blocks.SANDSTONE.getDefaultState());
        structure.fillWithBlocks(world, start, 36, -45, 45, 37, -45, 46, Blocks.SANDSTONE.getDefaultState());
        structure.fillWithBlocks(world, start, 36, -41, 35, 36, -41, 35, Blocks.SANDSTONE.getDefaultState());
        structure.fillWithBlocks(world, start, 36, -41, 37, 36, -40, 38, Blocks.STONE_BRICKS.getDefaultState());
        structure.fillWithBlocks(world, start, 36, -41, 40, 36, -40, 40, Blocks.STONE_BRICKS.getDefaultState());
        structure.fillWithBlocks(world, start, 36, -41, 41, 42, -41, 41, Blocks.SANDSTONE.getDefaultState());
        structure.fillWithBlocks(world, start, 36, -34, 41, 37, -34, 42, Blocks.STONE_BRICKS.getDefaultState());
        structure.fillWithBlocks(world, start, 36, -34, 45, 37, -34, 46, Blocks.STONE_BRICKS.getDefaultState());
        structure.fillWithBlocks(world, start, 36, -33, 33, 36, -33, 33, Blocks.STONE_BRICKS.getDefaultState());
        structure.fillWithBlocks(world, start, 36, -33, 36, 38, -33, 38, Blocks.STONE_BRICKS.getDefaultState());
        structure.fillWithBlocks(world, start, 36, -33, 40, 37, -33, 43, Blocks.STONE_BRICKS.getDefaultState());
        structure.fillWithBlocks(world, start, 36, -33, 44, 36, -31, 44, Blocks.STONE_BRICKS.getDefaultState());
        structure.fillWithBlocks(world, start, 36, -32, 31, 37, -32, 46, Blocks.STONE_BRICKS.getDefaultState());
        structure.fillWithBlocks(world, start, 36, -31, 36, 38, -31, 38, Blocks.STONE_BRICKS.getDefaultState());
        structure.fillWithBlocks(world, start, 36, -31, 42, 40, -31, 46, Blocks.STONE_BRICKS.getDefaultState());
        structure.fillWithBlocks(world, start, 36, -30, -6, 36, -30, -6, Blocks.AIR.getDefaultState());
        structure.fillWithBlocks(world, start, 36, -30, -3, 39, -30, -3, Blocks.SANDSTONE.getDefaultState());
        structure.fillWithBlocks(world, start, 36, -30, -2, 36, -30, -2, Blocks.DIRT.getDefaultState());
        structure.fillWithBlocks(world, start, 36, -30, 0, 36, -29, 0, Blocks.SANDSTONE.getDefaultState());
        structure.fillWithBlocks(world, start, 36, -30, 1, 36, -29, 1, Blocks.AIR.getDefaultState());
        structure.fillWithBlocks(world, start, 36, -30, 5, 36, -30, 5, Blocks.DIRT.getDefaultState());
        structure.fillWithBlocks(world, start, 36, -30, 6, 36, -30, 6, Blocks.SANDSTONE.getDefaultState());
        structure.fillWithBlocks(world, start, 36, -30, 8, 45, -30, 17, Blocks.SANDSTONE.getDefaultState());
        structure.fillWithBlocks(world, start, 36, -30, 19, 36, -30, 34, Blocks.SANDSTONE.getDefaultState());
        structure.fillWithBlocks(world, start, 36, -30, 35, 36, -30, 37, Blocks.DIRT.getDefaultState());
        structure.fillWithBlocks(world, start, 36, -30, 38, 36, -30, 39, Blocks.AIR.getDefaultState());
        structure.fillWithBlocks(world, start, 36, -30, 40, 36, -30, 41, Blocks.DIRT.getDefaultState());
        structure.fillWithBlocks(world, start, 36, -30, 42, 36, -30, 42, Blocks.SANDSTONE.getDefaultState());
        structure.fillWithBlocks(world, start, 36, -30, 44, 36, -30, 45, Blocks.DIRT.getDefaultState());
        structure.fillWithBlocks(world, start, 36, -30, 46, 36, -29, 46, Blocks.AIR.getDefaultState());
        structure.fillWithBlocks(world, start, 36, -30, 47, 36, -30, 47, Blocks.DIRT.getDefaultState());
        structure.fillWithBlocks(world, start, 36, -30, 48, 36, -28, 50, Blocks.SANDSTONE.getDefaultState());
        structure.fillWithBlocks(world, start, 36, -30, 51, 36, -28, 51, Blocks.DIRT.getDefaultState());
        structure.fillWithBlocks(world, start, 36, -30, 52, 36, -30, 53, Blocks.AIR.getDefaultState());
        structure.fillWithBlocks(world, start, 36, -30, 54, 36, -28, 54, Blocks.SANDSTONE.getDefaultState());
        structure.fillWithBlocks(world, start, 36, -30, 55, 36, -30, 55, Blocks.AIR.getDefaultState());
        structure.fillWithBlocks(world, start, 36, -30, 57, 36, -29, 57, Blocks.SANDSTONE.getDefaultState());
        structure.fillWithBlocks(world, start, 36, -30, 59, 36, -21, 59, Blocks.SANDSTONE.getDefaultState());
        structure.fillWithBlocks(world, start, 36, -30, 60, 36, -30, 60, Blocks.AIR.getDefaultState());
        structure.fillWithBlocks(world, start, 36, -30, 61, 36, -29, 62, Blocks.SANDSTONE.getDefaultState());
        structure.fillWithBlocks(world, start, 36, -30, 64, 37, -30, 65, Blocks.SANDSTONE.getDefaultState());
        structure.fillWithBlocks(world, start, 36, -29, -6, 36, -29, -6, Blocks.STONE_BRICKS.getDefaultState());
        structure.fillWithBlocks(world, start, 36, -29, -5, 36, -29, -5, Blocks.DIRT.getDefaultState());
        structure.fillWithBlocks(world, start, 36, -29, -4, 36, -26, -4, Blocks.STONE_BRICKS.getDefaultState());
        structure.fillWithBlocks(world, start, 36, -29, -2, 36, -29, -1, Blocks.STONE_BRICKS.getDefaultState());
        structure.fillWithBlocks(world, start, 36, -29, 2, 37, -29, 3, Blocks.STONE_BRICKS.getDefaultState());
        structure.fillWithBlocks(world, start, 36, -29, 4, 36, -29, 4, Blocks.STONE_BRICKS.getDefaultState());
        structure.fillWithBlocks(world, start, 36, -29, 6, 38, -29, 6, Blocks.STONE_BRICKS.getDefaultState());
        structure.fillWithBlocks(world, start, 36, -29, 7, 40, -25, 7, Blocks.SANDSTONE.getDefaultState());
        structure.fillWithBlocks(world, start, 36, -29, 8, 40, -29, 12, Blocks.AIR.getDefaultState());
        structure.fillWithBlocks(world, start, 36, -29, 13, 39, -26, 13, Blocks.SANDSTONE.getDefaultState());
        structure.fillWithBlocks(world, start, 36, -29, 14, 36, -27, 16, Blocks.AIR.getDefaultState());
        structure.fillWithBlocks(world, start, 36, -29, 17, 37, -29, 18, Blocks.SANDSTONE.getDefaultState());
        structure.fillWithBlocks(world, start, 36, -29, 19, 37, -29, 19, Blocks.AIR.getDefaultState());
        structure.fillWithBlocks(world, start, 36, -29, 20, 37, -29, 21, Blocks.SANDSTONE.getDefaultState());
        structure.fillWithBlocks(world, start, 36, -29, 22, 36, -29, 25, Blocks.SANDSTONE.getDefaultState());
        structure.fillWithBlocks(world, start, 36, -29, 26, 38, -29, 28, Blocks.AIR.getDefaultState());
        structure.fillWithBlocks(world, start, 36, -29, 29, 39, -26, 29, Blocks.SANDSTONE.getDefaultState());
        structure.fillWithBlocks(world, start, 36, -29, 30, 37, -29, 31, Blocks.AIR.getDefaultState());
        structure.fillWithBlocks(world, start, 36, -29, 33, 37, -29, 34, Blocks.AIR.getDefaultState());
        structure.fillWithBlocks(world, start, 36, -29, 35, 37, -29, 36, Blocks.SANDSTONE.getDefaultState());
        structure.fillWithBlocks(world, start, 36, -29, 37, 36, -29, 37, Blocks.DIRT.getDefaultState());
        structure.fillWithBlocks(world, start, 36, -29, 38, 36, -29, 41, Blocks.SANDSTONE.getDefaultState());
        structure.fillWithBlocks(world, start, 36, -29, 43, 36, -27, 45, Blocks.SANDSTONE.getDefaultState());
        structure.fillWithBlocks(world, start, 36, -29, 47, 37, -29, 50, Blocks.SANDSTONE.getDefaultState());
        structure.fillWithBlocks(world, start, 36, -29, 55, 36, -29, 55, Blocks.SANDSTONE.getDefaultState());
        structure.fillWithBlocks(world, start, 36, -29, 56, 36, -28, 56, Blocks.DIRT.getDefaultState());
        structure.fillWithBlocks(world, start, 36, -29, 58, 36, -27, 63, Blocks.SANDSTONE.getDefaultState());
        structure.fillWithBlocks(world, start, 36, -29, 65, 38, -29, 65, Blocks.SANDSTONE.getDefaultState());
        structure.fillWithBlocks(world, start, 36, -28, -5, 36, -27, -2, Blocks.STONE_BRICKS.getDefaultState());
        structure.fillWithBlocks(world, start, 36, -28, -1, 36, -28, -1, Blocks.SANDSTONE.getDefaultState());
        structure.fillWithBlocks(world, start, 36, -28, 0, 36, -28, 1, Blocks.DIRT.getDefaultState());
        structure.fillWithBlocks(world, start, 36, -28, 2, 36, -28, 3, Blocks.AIR.getDefaultState());
        structure.fillWithBlocks(world, start, 36, -28, 4, 36, -26, 4, Blocks.SANDSTONE.getDefaultState());
        structure.fillWithBlocks(world, start, 36, -28, 5, 36, -28, 6, Blocks.STONE_BRICKS.getDefaultState());
        structure.fillWithBlocks(world, start, 36, -28, 8, 40, -28, 12, Blocks.AIR.getDefaultState());
        structure.fillWithBlocks(world, start, 36, -28, 17, 36, -27, 18, Blocks.SANDSTONE.getDefaultState());
        structure.fillWithBlocks(world, start, 36, -28, 26, 38, -28, 28, Blocks.AIR.getDefaultState());
        structure.fillWithBlocks(world, start, 36, -28, 30, 40, -28, 34, Blocks.AIR.getDefaultState());
        structure.fillWithBlocks(world, start, 36, -28, 35, 36, -25, 38, Blocks.SANDSTONE.getDefaultState());
        structure.fillWithBlocks(world, start, 36, -28, 40, 36, -22, 40, Blocks.SANDSTONE.getDefaultState());
        structure.fillWithBlocks(world, start, 36, -28, 42, 36, -27, 50, Blocks.SANDSTONE.getDefaultState());
        structure.fillWithBlocks(world, start, 36, -28, 64, 36, -27, 65, Blocks.SANDSTONE.getDefaultState());
        structure.fillWithBlocks(world, start, 36, -27, -1, 36, -26, 0, Blocks.STONE_BRICKS.getDefaultState());
        structure.fillWithBlocks(world, start, 36, -27, 2, 36, -27, 3, Blocks.STONE_BRICKS.getDefaultState());
        structure.fillWithBlocks(world, start, 36, -27, 5, 36, -27, 5, Blocks.AIR.getDefaultState());
        structure.fillWithBlocks(world, start, 36, -27, 8, 40, -27, 12, Blocks.AIR.getDefaultState());
        structure.fillWithBlocks(world, start, 36, -27, 19, 37, -27, 19, Blocks.DIRT.getDefaultState());
        structure.fillWithBlocks(world, start, 36, -27, 20, 38, -27, 22, Blocks.SANDSTONE.getDefaultState());
        structure.fillWithBlocks(world, start, 36, -27, 23, 36, -26, 23, Blocks.DIRT.getDefaultState());
        structure.fillWithBlocks(world, start, 36, -27, 24, 37, -27, 25, Blocks.SANDSTONE.getDefaultState());
        structure.fillWithBlocks(world, start, 36, -27, 26, 38, -27, 28, Blocks.AIR.getDefaultState());
        structure.fillWithBlocks(world, start, 36, -27, 30, 40, -27, 34, Blocks.AIR.getDefaultState());
        structure.fillWithBlocks(world, start, 36, -27, 52, 37, -26, 52, Blocks.SANDSTONE.getDefaultState());
        structure.fillWithBlocks(world, start, 36, -27, 53, 36, -27, 54, Blocks.DIRT.getDefaultState());
        structure.fillWithBlocks(world, start, 36, -27, 55, 36, -27, 65, Blocks.SANDSTONE.getDefaultState());
        structure.fillWithBlocks(world, start, 36, -26, -6, 36, -26, -6, Blocks.STONE_BRICKS.getDefaultState());
        structure.fillWithBlocks(world, start, 36, -26, 1, 36, -26, 1, Blocks.AIR.getDefaultState());
        structure.fillWithBlocks(world, start, 36, -26, 2, 36, -26, 2, Blocks.SANDSTONE.getDefaultState());
        structure.fillWithBlocks(world, start, 36, -26, 8, 40, -26, 12, Blocks.AIR.getDefaultState());
        structure.fillWithBlocks(world, start, 36, -26, 14, 38, -26, 16, Blocks.AIR.getDefaultState());
        structure.fillWithBlocks(world, start, 36, -26, 17, 37, -26, 19, Blocks.SANDSTONE.getDefaultState());
        structure.fillWithBlocks(world, start, 36, -26, 20, 36, -26, 22, Blocks.SANDSTONE.getDefaultState());
        structure.fillWithBlocks(world, start, 36, -26, 24, 37, -26, 25, Blocks.SANDSTONE.getDefaultState());
        structure.fillWithBlocks(world, start, 36, -26, 26, 38, -26, 28, Blocks.AIR.getDefaultState());
        structure.fillWithBlocks(world, start, 36, -26, 30, 40, -26, 34, Blocks.AIR.getDefaultState());
        structure.fillWithBlocks(world, start, 36, -26, 39, 36, -24, 41, Blocks.SANDSTONE.getDefaultState());
        structure.fillWithBlocks(world, start, 36, -26, 43, 37, -26, 46, Blocks.SANDSTONE.getDefaultState());
        structure.fillWithBlocks(world, start, 36, -26, 48, 36, -26, 48, Blocks.SANDSTONE.getDefaultState());
        structure.fillWithBlocks(world, start, 36, -26, 50, 37, -26, 52, Blocks.SANDSTONE.getDefaultState());
        structure.fillWithBlocks(world, start, 36, -26, 54, 36, -26, 54, Blocks.AIR.getDefaultState());
        structure.fillWithBlocks(world, start, 36, -26, 55, 36, -24, 57, Blocks.SANDSTONE.getDefaultState());
        structure.fillWithBlocks(world, start, 36, -26, 60, 36, -26, 60, Blocks.SANDSTONE.getDefaultState());
        structure.fillWithBlocks(world, start, 36, -26, 62, 36, -26, 62, Blocks.SANDSTONE.getDefaultState());
        structure.fillWithBlocks(world, start, 36, -26, 63, 36, -26, 63, Blocks.AIR.getDefaultState());
        structure.fillWithBlocks(world, start, 36, -26, 64, 36, -24, 64, Blocks.SANDSTONE.getDefaultState());
        structure.fillWithBlocks(world, start, 36, -25, -5, 36, -24, -5, Blocks.STONE_BRICKS.getDefaultState());
        structure.fillWithBlocks(world, start, 36, -25, -3, 36, -24, -2, Blocks.STONE_BRICKS.getDefaultState());
        structure.fillWithBlocks(world, start, 36, -25, 3, 37, -24, 3, Blocks.SANDSTONE.getDefaultState());
        structure.fillWithBlocks(world, start, 36, -25, 4, 36, -25, 5, Blocks.STONE_BRICKS.getDefaultState());
        structure.fillWithBlocks(world, start, 36, -25, 6, 36, -25, 7, Blocks.SANDSTONE.getDefaultState());
        structure.fillWithBlocks(world, start, 36, -25, 8, 39, -25, 11, Blocks.AIR.getDefaultState());
        structure.fillWithBlocks(world, start, 36, -25, 12, 38, -25, 14, Blocks.SANDSTONE.getDefaultState());
        structure.fillWithBlocks(world, start, 36, -25, 16, 40, -24, 16, Blocks.SANDSTONE.getDefaultState());
        structure.fillWithBlocks(world, start, 36, -25, 17, 37, -25, 17, Blocks.AIR.getDefaultState());
        structure.fillWithBlocks(world, start, 36, -25, 18, 37, -25, 19, Blocks.SANDSTONE.getDefaultState());
        structure.fillWithBlocks(world, start, 36, -25, 20, 36, -21, 20, Blocks.SANDSTONE.getDefaultState());
        structure.fillWithBlocks(world, start, 36, -25, 21, 36, -25, 22, Blocks.DIRT.getDefaultState());
        structure.fillWithBlocks(world, start, 36, -25, 23, 37, -25, 24, Blocks.SANDSTONE.getDefaultState());
        structure.fillWithBlocks(world, start, 36, -25, 26, 36, -25, 29, Blocks.SANDSTONE.getDefaultState());
        structure.fillWithBlocks(world, start, 36, -25, 30, 40, -25, 34, Blocks.AIR.getDefaultState());
        structure.fillWithBlocks(world, start, 36, -25, 42, 37, -25, 52, Blocks.SANDSTONE.getDefaultState());
        structure.fillWithBlocks(world, start, 36, -24, 0, 36, -24, 0, Blocks.STONE_BRICKS.getDefaultState());
        structure.fillWithBlocks(world, start, 36, -24, 1, 36, -24, 3, Blocks.SANDSTONE.getDefaultState());
        structure.fillWithBlocks(world, start, 36, -24, 5, 36, -24, 6, Blocks.STONE_BRICKS.getDefaultState());
        structure.fillWithBlocks(world, start, 36, -24, 8, 41, -24, 16, Blocks.SANDSTONE.getDefaultState());
        structure.fillWithBlocks(world, start, 36, -24, 17, 36, -22, 17, Blocks.DIRT.getDefaultState());
        structure.fillWithBlocks(world, start, 36, -24, 18, 37, -24, 24, Blocks.SANDSTONE.getDefaultState());
        structure.fillWithBlocks(world, start, 36, -24, 25, 36, -24, 26, Blocks.DIRT.getDefaultState());
        structure.fillWithBlocks(world, start, 36, -24, 27, 41, -24, 42, Blocks.SANDSTONE.getDefaultState());
        structure.fillWithBlocks(world, start, 36, -24, 43, 37, -24, 44, Blocks.SANDSTONE.getDefaultState());
        structure.fillWithBlocks(world, start, 36, -24, 45, 36, -24, 45, Blocks.DIRT.getDefaultState());
        structure.fillWithBlocks(world, start, 36, -24, 46, 36, -24, 49, Blocks.SANDSTONE.getDefaultState());
        structure.fillWithBlocks(world, start, 36, -24, 51, 37, -24, 53, Blocks.SANDSTONE.getDefaultState());
        structure.fillWithBlocks(world, start, 36, -24, 60, 37, -24, 61, Blocks.SANDSTONE.getDefaultState());
        structure.fillWithBlocks(world, start, 36, -23, -6, 37, -22, -6, Blocks.STONE_BRICKS.getDefaultState());
        structure.fillWithBlocks(world, start, 36, -23, -4, 37, -23, -3, Blocks.STONE_BRICKS.getDefaultState());
        structure.fillWithBlocks(world, start, 36, -23, -1, 36, -23, 2, Blocks.STONE_BRICKS.getDefaultState());
        structure.fillWithBlocks(world, start, 36, -23, 4, 36, -21, 4, Blocks.STONE_BRICKS.getDefaultState());
        structure.fillWithBlocks(world, start, 36, -23, 5, 36, -23, 5, Blocks.SANDSTONE.getDefaultState());
        structure.fillWithBlocks(world, start, 36, -23, 8, 37, -22, 8, Blocks.STONE_BRICKS.getDefaultState());
        structure.fillWithBlocks(world, start, 36, -23, 9, 37, -22, 9, Blocks.SANDSTONE.getDefaultState());
        structure.fillWithBlocks(world, start, 36, -23, 22, 37, -23, 24, Blocks.SANDSTONE.getDefaultState());
        structure.fillWithBlocks(world, start, 36, -23, 25, 36, -22, 25, Blocks.DIRT.getDefaultState());
        structure.fillWithBlocks(world, start, 36, -23, 26, 36, -22, 29, Blocks.SANDSTONE.getDefaultState());
        structure.fillWithBlocks(world, start, 36, -23, 30, 36, -23, 31, Blocks.DIRT.getDefaultState());
        structure.fillWithBlocks(world, start, 36, -23, 32, 36, -23, 32, Blocks.SANDSTONE.getDefaultState());
        structure.fillWithBlocks(world, start, 36, -23, 34, 38, -23, 36, Blocks.SANDSTONE.getDefaultState());
        structure.fillWithBlocks(world, start, 36, -23, 37, 36, -22, 37, Blocks.AIR.getDefaultState());
        structure.fillWithBlocks(world, start, 36, -23, 38, 37, -23, 38, Blocks.DIRT.getDefaultState());
        structure.fillWithBlocks(world, start, 36, -23, 39, 37, -23, 41, Blocks.SANDSTONE.getDefaultState());
        structure.fillWithBlocks(world, start, 36, -23, 43, 36, -23, 52, Blocks.SANDSTONE.getDefaultState());
        structure.fillWithBlocks(world, start, 36, -23, 55, 36, -23, 55, Blocks.SANDSTONE.getDefaultState());
        structure.fillWithBlocks(world, start, 36, -23, 57, 37, -23, 63, Blocks.SANDSTONE.getDefaultState());
        structure.fillWithBlocks(world, start, 36, -22, -5, 37, -22, -3, Blocks.STONE_BRICKS.getDefaultState());
        structure.fillWithBlocks(world, start, 36, -22, -1, 37, -22, 2, Blocks.STONE_BRICKS.getDefaultState());
        structure.fillWithBlocks(world, start, 36, -22, 3, 36, -22, 4, Blocks.STONE_BRICKS.getDefaultState());
        structure.fillWithBlocks(world, start, 36, -22, 5, 36, -22, 5, Blocks.AIR.getDefaultState());
        structure.fillWithBlocks(world, start, 36, -22, 6, 36, -22, 8, Blocks.STONE_BRICKS.getDefaultState());
        structure.fillWithBlocks(world, start, 36, -22, 14, 36, -21, 14, Blocks.SANDSTONE.getDefaultState());
        structure.fillWithBlocks(world, start, 36, -22, 18, 38, -22, 20, Blocks.SANDSTONE.getDefaultState());
        structure.fillWithBlocks(world, start, 36, -22, 23, 37, -22, 24, Blocks.SANDSTONE.getDefaultState());
        structure.fillWithBlocks(world, start, 36, -22, 32, 37, -22, 34, Blocks.SANDSTONE.getDefaultState());
        structure.fillWithBlocks(world, start, 36, -22, 38, 37, -22, 39, Blocks.SANDSTONE.getDefaultState());
        structure.fillWithBlocks(world, start, 36, -22, 41, 36, -22, 41, Blocks.DIRT.getDefaultState());
        structure.fillWithBlocks(world, start, 36, -22, 42, 36, -22, 43, Blocks.SANDSTONE.getDefaultState());
        structure.fillWithBlocks(world, start, 36, -22, 46, 36, -22, 57, Blocks.SANDSTONE.getDefaultState());
        structure.fillWithBlocks(world, start, 36, -22, 58, 37, -22, 58, Blocks.DIRT.getDefaultState());
        structure.fillWithBlocks(world, start, 36, -22, 60, 36, -21, 61, Blocks.SANDSTONE.getDefaultState());
        structure.fillWithBlocks(world, start, 36, -22, 64, 37, -22, 65, Blocks.SANDSTONE.getDefaultState());
        structure.fillWithBlocks(world, start, 36, -21, -6, 37, -21, -4, Blocks.STONE_BRICKS.getDefaultState());
        structure.fillWithBlocks(world, start, 36, -21, -3, 36, -21, -3, Blocks.SANDSTONE.getDefaultState());
        structure.fillWithBlocks(world, start, 36, -21, -2, 36, -21, 2, Blocks.STONE_BRICKS.getDefaultState());
        structure.fillWithBlocks(world, start, 36, -21, 6, 36, -21, 6, Blocks.AIR.getDefaultState());
        structure.fillWithBlocks(world, start, 36, -21, 10, 39, -21, 16, Blocks.SANDSTONE.getDefaultState());
        structure.fillWithBlocks(world, start, 36, -21, 17, 36, -21, 21, Blocks.SANDSTONE.getDefaultState());
        structure.fillWithBlocks(world, start, 36, -21, 23, 36, -21, 23, Blocks.SANDSTONE.getDefaultState());
        structure.fillWithBlocks(world, start, 36, -21, 24, 36, -21, 25, Blocks.AIR.getDefaultState());
        structure.fillWithBlocks(world, start, 36, -21, 26, 36, -21, 27, Blocks.DIRT.getDefaultState());
        structure.fillWithBlocks(world, start, 36, -21, 28, 37, -21, 31, Blocks.SANDSTONE.getDefaultState());
        structure.fillWithBlocks(world, start, 36, -21, 33, 36, -21, 37, Blocks.SANDSTONE.getDefaultState());
        structure.fillWithBlocks(world, start, 36, -21, 40, 36, -21, 41, Blocks.AIR.getDefaultState());
        structure.fillWithBlocks(world, start, 36, -21, 42, 36, -21, 47, Blocks.SANDSTONE.getDefaultState());
        structure.fillWithBlocks(world, start, 36, -21, 48, 37, -21, 48, Blocks.AIR.getDefaultState());
        structure.fillWithBlocks(world, start, 36, -21, 49, 37, -21, 50, Blocks.SANDSTONE.getDefaultState());
        structure.fillWithBlocks(world, start, 36, -21, 52, 37, -21, 53, Blocks.SANDSTONE.getDefaultState());
        structure.fillWithBlocks(world, start, 36, -21, 54, 37, -21, 55, Blocks.AIR.getDefaultState());
        structure.fillWithBlocks(world, start, 36, -21, 56, 36, -21, 56, Blocks.DIRT.getDefaultState());
        structure.fillWithBlocks(world, start, 36, -21, 57, 36, -21, 64, Blocks.SANDSTONE.getDefaultState());
        structure.fillWithBlocks(world, start, 36, -19, 32, 38, -19, 34, Blocks.SANDSTONE.getDefaultState());
        structure.fillWithBlocks(world, start, 36, -19, 35, 38, -19, 37, Blocks.AIR.getDefaultState());
        structure.fillWithBlocks(world, start, 36, -19, 41, 40, -16, 41, Blocks.AIR.getDefaultState());
        structure.fillWithBlocks(world, start, 36, -19, 42, 38, -19, 44, Blocks.SANDSTONE.getDefaultState());
        structure.fillWithBlocks(world, start, 36, -18, 35, 38, -18, 37, Blocks.AIR.getDefaultState());
        structure.fillWithBlocks(world, start, 36, -18, 42, 38, -18, 44, Blocks.SANDSTONE.getDefaultState());
        structure.fillWithBlocks(world, start, 36, -17, 32, 38, -17, 34, Blocks.SANDSTONE.getDefaultState());
        structure.fillWithBlocks(world, start, 36, -17, 35, 40, -17, 41, Blocks.AIR.getDefaultState());
        structure.fillWithBlocks(world, start, 36, -17, 42, 38, -17, 44, Blocks.SANDSTONE.getDefaultState());
        structure.fillWithBlocks(world, start, 36, -16, 35, 40, -16, 41, Blocks.AIR.getDefaultState());
        structure.fillWithBlocks(world, start, 36, -16, 42, 38, -16, 44, Blocks.SANDSTONE.getDefaultState());
        structure.fillWithBlocks(world, start, 36, -15, 32, 38, -15, 35, Blocks.SANDSTONE.getDefaultState());
        structure.fillWithBlocks(world, start, 36, -15, 37, 38, -15, 39, Blocks.AIR.getDefaultState());
        structure.fillWithBlocks(world, start, 36, -15, 40, 36, -15, 44, Blocks.SANDSTONE.getDefaultState());
        structure.fillWithBlocks(world, start, 36, -14, 32, 38, -14, 37, Blocks.SANDSTONE.getDefaultState());
        structure.fillWithBlocks(world, start, 36, -14, 38, 37, -14, 40, Blocks.SANDSTONE.getDefaultState());
        structure.fillWithBlocks(world, start, 36, -14, 41, 36, -14, 42, Blocks.AIR.getDefaultState());
        structure.fillWithBlocks(world, start, 36, -14, 43, 37, -14, 44, Blocks.SANDSTONE.getDefaultState());
        structure.fillWithBlocks(world, start, 36, -13, 39, 37, -13, 40, Blocks.SANDSTONE.getDefaultState());
        structure.fillWithBlocks(world, start, 36, -13, 41, 36, -13, 44, Blocks.SANDSTONE.getDefaultState());
        structure.fillWithBlocks(world, start, 36, -12, 41, 38, -12, 43, Blocks.SANDSTONE.getDefaultState());
        structure.fillWithBlocks(world, start, 36, -11, 38, 41, -11, 43, Blocks.SANDSTONE.getDefaultState());
        structure.fillWithBlocks(world, start, 36, 0, 13, 41, 0, 18, Blocks.SANDSTONE.getDefaultState());
        structure.fillWithBlocks(world, start, 36, 0, 124, 36, 0, 124, Blocks.STONE.getDefaultState());
        structure.fillWithBlocks(world, start, 36, 0, 125, 36, 0, 127, Blocks.SANDSTONE.getDefaultState());
        structure.fillWithBlocks(world, start, 36, 0, 138, 39, 0, 138, Blocks.STONE.getDefaultState());
        structure.fillWithBlocks(world, start, 36, 0, 139, 44, 0, 147, Blocks.SANDSTONE.getDefaultState());
        structure.fillWithBlocks(world, start, 36, 1, 26, 37, 1, 27, Blocks.SANDSTONE.getDefaultState());
        structure.fillWithBlocks(world, start, 36, 1, 28, 36, 1, 29, Blocks.STONE.getDefaultState());
        structure.fillWithBlocks(world, start, 36, 1, 30, 38, 1, 32, Blocks.SANDSTONE.getDefaultState());
        structure.fillWithBlocks(world, start, 36, 1, 69, 36, 1, 69, Blocks.STONE.getDefaultState());
        structure.fillWithBlocks(world, start, 36, 1, 118, 42, 1, 125, Blocks.SANDSTONE.getDefaultState());
        structure.fillWithBlocks(world, start, 36, 2, 16, 67, 2, 50, Blocks.SANDSTONE.getDefaultState());
        structure.fillWithBlocks(world, start, 36, 2, 63, 47, 2, 63, Blocks.STONE.getDefaultState());
        structure.fillWithBlocks(world, start, 36, 2, 64, 37, 2, 86, Blocks.SANDSTONE.getDefaultState());
        structure.fillWithBlocks(world, start, 36, 2, 87, 38, 2, 89, Blocks.STONE.getDefaultState());
        structure.fillWithBlocks(world, start, 36, 2, 106, 39, 2, 109, Blocks.STONE.getDefaultState());
        structure.fillWithBlocks(world, start, 36, 2, 110, 36, 2, 142, Blocks.SANDSTONE.getDefaultState());
        structure.fillWithBlocks(world, start, 36, 4, 19, 100, 4, 138, Blocks.SANDSTONE.getDefaultState());
        structure.fillWithBlocks(world, start, 36, 6, 28, 100, 6, 124, Blocks.SANDSTONE.getDefaultState());
        structure.fillWithBlocks(world, start, 37, -51, 32, 39, -51, 34, Blocks.SANDSTONE.getDefaultState());
        structure.fillWithBlocks(world, start, 37, -51, 42, 39, -51, 44, Blocks.SANDSTONE.getDefaultState());
        structure.fillWithBlocks(world, start, 37, -50, 32, 39, -50, 34, Blocks.AIR.getDefaultState());
        structure.fillWithBlocks(world, start, 37, -50, 42, 39, -50, 44, Blocks.AIR.getDefaultState());
        structure.fillWithBlocks(world, start, 37, -49, 31, 37, -41, 31, Blocks.SANDSTONE.getDefaultState());
        structure.fillWithBlocks(world, start, 37, -49, 32, 39, -49, 34, Blocks.AIR.getDefaultState());
        structure.fillWithBlocks(world, start, 37, -49, 35, 37, -41, 35, Blocks.SANDSTONE.getDefaultState());
        structure.fillWithBlocks(world, start, 37, -49, 36, 38, -49, 37, Blocks.AIR.getDefaultState());
        structure.fillWithBlocks(world, start, 37, -49, 39, 38, -49, 40, Blocks.AIR.getDefaultState());
        structure.fillWithBlocks(world, start, 37, -49, 41, 37, -41, 41, Blocks.SANDSTONE.getDefaultState());
        structure.fillWithBlocks(world, start, 37, -49, 42, 39, -49, 44, Blocks.AIR.getDefaultState());
        structure.fillWithBlocks(world, start, 37, -49, 45, 37, -49, 46, Blocks.SANDSTONE.getDefaultState());
        structure.fillWithBlocks(world, start, 37, -48, 32, 39, -48, 34, Blocks.AIR.getDefaultState());
        structure.fillWithBlocks(world, start, 37, -48, 36, 41, -48, 40, Blocks.AIR.getDefaultState());
        structure.fillWithBlocks(world, start, 37, -48, 42, 39, -48, 44, Blocks.AIR.getDefaultState());
        structure.fillWithBlocks(world, start, 37, -48, 45, 37, -48, 46, Blocks.SANDSTONE.getDefaultState());
        structure.fillWithBlocks(world, start, 37, -47, 32, 39, -47, 34, Blocks.AIR.getDefaultState());
        structure.fillWithBlocks(world, start, 37, -47, 36, 41, -47, 40, Blocks.AIR.getDefaultState());
        structure.fillWithBlocks(world, start, 37, -47, 42, 39, -47, 44, Blocks.AIR.getDefaultState());
        structure.fillWithBlocks(world, start, 37, -47, 45, 37, -47, 46, Blocks.SANDSTONE.getDefaultState());
        structure.fillWithBlocks(world, start, 37, -46, 32, 39, -46, 34, Blocks.AIR.getDefaultState());
        structure.fillWithBlocks(world, start, 37, -46, 36, 41, -46, 40, Blocks.AIR.getDefaultState());
        structure.fillWithBlocks(world, start, 37, -46, 42, 39, -46, 44, Blocks.AIR.getDefaultState());
        structure.fillWithBlocks(world, start, 37, -46, 45, 37, -46, 46, Blocks.SANDSTONE.getDefaultState());
        structure.fillWithBlocks(world, start, 37, -45, 32, 37, -42, 46, Blocks.SANDSTONE.getDefaultState());
        structure.fillWithBlocks(world, start, 37, -41, 32, 39, -41, 34, Blocks.STONE_BRICKS.getDefaultState());
        structure.fillWithBlocks(world, start, 37, -41, 36, 42, -41, 41, Blocks.SANDSTONE.getDefaultState());
        structure.fillWithBlocks(world, start, 37, -41, 42, 39, -41, 44, Blocks.STONE_BRICKS.getDefaultState());
        structure.fillWithBlocks(world, start, 37, -41, 45, 38, -41, 46, Blocks.SANDSTONE.getDefaultState());
        structure.fillWithBlocks(world, start, 37, -40, 30, 38, -40, 31, Blocks.STONE_BRICKS.getDefaultState());
        structure.fillWithBlocks(world, start, 37, -40, 45, 38, -40, 46, Blocks.STONE_BRICKS.getDefaultState());
        structure.fillWithBlocks(world, start, 37, -39, 32, 39, -39, 34, Blocks.AIR.getDefaultState());
        structure.fillWithBlocks(world, start, 37, -39, 42, 39, -39, 44, Blocks.AIR.getDefaultState());
        structure.fillWithBlocks(world, start, 37, -35, 45, 38, -35, 46, Blocks.STONE_BRICKS.getDefaultState());
        structure.fillWithBlocks(world, start, 37, -34, 32, 37, -34, 32, Blocks.STONE_BRICKS.getDefaultState());
        structure.fillWithBlocks(world, start, 37, -34, 34, 40, -34, 37, Blocks.STONE_BRICKS.getDefaultState());
        structure.fillWithBlocks(world, start, 37, -34, 39, 40, -34, 42, Blocks.STONE_BRICKS.getDefaultState());
        structure.fillWithBlocks(world, start, 37, -34, 44, 39, -34, 46, Blocks.STONE_BRICKS.getDefaultState());
        structure.fillWithBlocks(world, start, 37, -33, 32, 37, -33, 43, Blocks.STONE_BRICKS.getDefaultState());
        structure.fillWithBlocks(world, start, 37, -33, 45, 38, -33, 46, Blocks.STONE_BRICKS.getDefaultState());
        structure.fillWithBlocks(world, start, 37, -31, 34, 37, -31, 39, Blocks.STONE_BRICKS.getDefaultState());
        structure.fillWithBlocks(world, start, 37, -31, 41, 41, -31, 45, Blocks.STONE_BRICKS.getDefaultState());
        structure.fillWithBlocks(world, start, 37, -30, -6, 38, -30, -6, Blocks.STONE_BRICKS.getDefaultState());
        structure.fillWithBlocks(world, start, 37, -30, -4, 38, -30, -4, Blocks.DIRT.getDefaultState());
        structure.fillWithBlocks(world, start, 37, -30, -2, 37, -30, -2, Blocks.AIR.getDefaultState());
        structure.fillWithBlocks(world, start, 37, -30, -1, 37, -30, 2, Blocks.DIRT.getDefaultState());
        structure.fillWithBlocks(world, start, 37, -30, 3, 38, -30, 5, Blocks.SANDSTONE.getDefaultState());
        structure.fillWithBlocks(world, start, 37, -30, 7, 45, -30, 17, Blocks.SANDSTONE.getDefaultState());
        structure.fillWithBlocks(world, start, 37, -30, 18, 37, -30, 19, Blocks.SANDSTONE.getDefaultState());
        structure.fillWithBlocks(world, start, 37, -30, 20, 38, -30, 20, Blocks.DIRT.getDefaultState());
        structure.fillWithBlocks(world, start, 37, -30, 25, 40, -30, 28, Blocks.SANDSTONE.getDefaultState());
        structure.fillWithBlocks(world, start, 37, -30, 30, 41, -30, 34, Blocks.SANDSTONE.getDefaultState());
        structure.fillWithBlocks(world, start, 37, -30, 35, 37, -30, 35, Blocks.AIR.getDefaultState());
        structure.fillWithBlocks(world, start, 37, -30, 36, 37, -29, 36, Blocks.SANDSTONE.getDefaultState());
        structure.fillWithBlocks(world, start, 37, -30, 37, 37, -30, 37, Blocks.DIRT.getDefaultState());
        structure.fillWithBlocks(world, start, 37, -30, 39, 38, -30, 39, Blocks.DIRT.getDefaultState());
        structure.fillWithBlocks(world, start, 37, -30, 40, 37, -29, 41, Blocks.SANDSTONE.getDefaultState());
        structure.fillWithBlocks(world, start, 37, -30, 43, 37, -30, 45, Blocks.SANDSTONE.getDefaultState());
        structure.fillWithBlocks(world, start, 37, -30, 46, 37, -30, 46, Blocks.DIRT.getDefaultState());
        structure.fillWithBlocks(world, start, 37, -30, 47, 37, -21, 47, Blocks.SANDSTONE.getDefaultState());
        structure.fillWithBlocks(world, start, 37, -30, 48, 37, -30, 48, Blocks.DIRT.getDefaultState());
        structure.fillWithBlocks(world, start, 37, -30, 51, 37, -21, 51, Blocks.SANDSTONE.getDefaultState());
        structure.fillWithBlocks(world, start, 37, -30, 54, 37, -30, 55, Blocks.DIRT.getDefaultState());
        structure.fillWithBlocks(world, start, 37, -30, 56, 37, -30, 57, Blocks.AIR.getDefaultState());
        structure.fillWithBlocks(world, start, 37, -30, 58, 37, -26, 58, Blocks.SANDSTONE.getDefaultState());
        structure.fillWithBlocks(world, start, 37, -30, 59, 37, -29, 59, Blocks.AIR.getDefaultState());
        structure.fillWithBlocks(world, start, 37, -30, 60, 37, -21, 60, Blocks.SANDSTONE.getDefaultState());
        structure.fillWithBlocks(world, start, 37, -30, 61, 37, -29, 61, Blocks.AIR.getDefaultState());
        structure.fillWithBlocks(world, start, 37, -30, 62, 39, -30, 62, Blocks.DIRT.getDefaultState());
        structure.fillWithBlocks(world, start, 37, -30, 63, 38, -30, 64, Blocks.SANDSTONE.getDefaultState());
        structure.fillWithBlocks(world, start, 37, -29, -5, 40, -28, -5, Blocks.STONE_BRICKS.getDefaultState());
        structure.fillWithBlocks(world, start, 37, -29, -4, 37, -29, -4, Blocks.DIRT.getDefaultState());
        structure.fillWithBlocks(world, start, 37, -29, -3, 37, -29, -2, Blocks.STONE_BRICKS.getDefaultState());
        structure.fillWithBlocks(world, start, 37, -29, -1, 37, -29, -1, Blocks.SANDSTONE.getDefaultState());
        structure.fillWithBlocks(world, start, 37, -29, 0, 37, -29, 3, Blocks.STONE_BRICKS.getDefaultState());
        structure.fillWithBlocks(world, start, 37, -29, 5, 38, -29, 6, Blocks.STONE_BRICKS.getDefaultState());
        structure.fillWithBlocks(world, start, 37, -29, 14, 37, -29, 14, Blocks.AIR.getDefaultState());
        structure.fillWithBlocks(world, start, 37, -29, 16, 38, -28, 16, Blocks.AIR.getDefaultState());
        structure.fillWithBlocks(world, start, 37, -29, 22, 37, -28, 22, Blocks.AIR.getDefaultState());
        structure.fillWithBlocks(world, start, 37, -29, 23, 37, -29, 25, Blocks.SANDSTONE.getDefaultState());
        structure.fillWithBlocks(world, start, 37, -29, 32, 39, -29, 34, Blocks.AIR.getDefaultState());
        structure.fillWithBlocks(world, start, 37, -29, 37, 37, -29, 37, Blocks.SANDSTONE.getDefaultState());
        structure.fillWithBlocks(world, start, 37, -29, 38, 37, -29, 39, Blocks.DIRT.getDefaultState());
        structure.fillWithBlocks(world, start, 37, -29, 42, 38, -29, 43, Blocks.SANDSTONE.getDefaultState());
        structure.fillWithBlocks(world, start, 37, -29, 44, 37, -28, 44, Blocks.DIRT.getDefaultState());
        structure.fillWithBlocks(world, start, 37, -29, 45, 38, -29, 48, Blocks.SANDSTONE.getDefaultState());
        structure.fillWithBlocks(world, start, 37, -29, 52, 39, -29, 57, Blocks.SANDSTONE.getDefaultState());
        structure.fillWithBlocks(world, start, 37, -29, 63, 37, -28, 64, Blocks.SANDSTONE.getDefaultState());
        structure.fillWithBlocks(world, start, 37, -28, -6, 37, -28, -5, Blocks.STONE_BRICKS.getDefaultState());
        structure.fillWithBlocks(world, start, 37, -28, -3, 39, -27, -3, Blocks.STONE_BRICKS.getDefaultState());
        structure.fillWithBlocks(world, start, 37, -28, -2, 38, -28, -2, Blocks.SANDSTONE.getDefaultState());
        structure.fillWithBlocks(world, start, 37, -28, -1, 37, -28, -1, Blocks.STONE_BRICKS.getDefaultState());
        structure.fillWithBlocks(world, start, 37, -28, 1, 38, -28, 1, Blocks.STONE_BRICKS.getDefaultState());
        structure.fillWithBlocks(world, start, 37, -28, 2, 38, -27, 2, Blocks.AIR.getDefaultState());
        structure.fillWithBlocks(world, start, 37, -28, 4, 38, -27, 4, Blocks.AIR.getDefaultState());
        structure.fillWithBlocks(world, start, 37, -28, 6, 38, -27, 6, Blocks.AIR.getDefaultState());
        structure.fillWithBlocks(world, start, 37, -28, 14, 38, -28, 16, Blocks.AIR.getDefaultState());
        structure.fillWithBlocks(world, start, 37, -28, 17, 37, -28, 17, Blocks.SANDSTONE.getDefaultState());
        structure.fillWithBlocks(world, start, 37, -28, 19, 38, -28, 20, Blocks.SANDSTONE.getDefaultState());
        structure.fillWithBlocks(world, start, 37, -28, 21, 37, -28, 22, Blocks.AIR.getDefaultState());
        structure.fillWithBlocks(world, start, 37, -28, 23, 37, -28, 25, Blocks.SANDSTONE.getDefaultState());
        structure.fillWithBlocks(world, start, 37, -28, 35, 40, -25, 35, Blocks.SANDSTONE.getDefaultState());
        structure.fillWithBlocks(world, start, 37, -28, 36, 39, -28, 36, Blocks.SHROOMLIGHT.getDefaultState());
        structure.fillWithBlocks(world, start, 37, -28, 37, 39, -27, 37, Blocks.SANDSTONE.getDefaultState());
        structure.fillWithBlocks(world, start, 37, -28, 38, 39, -28, 38, Blocks.SHROOMLIGHT.getDefaultState());
        structure.fillWithBlocks(world, start, 37, -28, 39, 39, -26, 39, Blocks.SANDSTONE.getDefaultState());
        structure.fillWithBlocks(world, start, 37, -28, 40, 39, -28, 40, Blocks.SHROOMLIGHT.getDefaultState());
        structure.fillWithBlocks(world, start, 37, -28, 42, 37, -28, 42, Blocks.SANDSTONE.getDefaultState());
        structure.fillWithBlocks(world, start, 37, -28, 43, 37, -28, 44, Blocks.DIRT.getDefaultState());
        structure.fillWithBlocks(world, start, 37, -28, 45, 38, -28, 48, Blocks.SANDSTONE.getDefaultState());
        structure.fillWithBlocks(world, start, 37, -28, 50, 37, -28, 51, Blocks.SANDSTONE.getDefaultState());
        structure.fillWithBlocks(world, start, 37, -28, 53, 38, -27, 53, Blocks.AIR.getDefaultState());
        structure.fillWithBlocks(world, start, 37, -28, 54, 37, -28, 54, Blocks.SANDSTONE.getDefaultState());
        structure.fillWithBlocks(world, start, 37, -28, 55, 37, -25, 55, Blocks.AIR.getDefaultState());
        structure.fillWithBlocks(world, start, 37, -28, 56, 37, -27, 56, Blocks.SANDSTONE.getDefaultState());
        structure.fillWithBlocks(world, start, 37, -28, 57, 38, -27, 57, Blocks.AIR.getDefaultState());
        structure.fillWithBlocks(world, start, 37, -28, 61, 38, -27, 61, Blocks.SANDSTONE.getDefaultState());
        structure.fillWithBlocks(world, start, 37, -28, 65, 37, -27, 65, Blocks.AIR.getDefaultState());
        structure.fillWithBlocks(world, start, 37, -27, -6, 38, -27, -5, Blocks.STONE_BRICKS.getDefaultState());
        structure.fillWithBlocks(world, start, 37, -27, -4, 38, -27, -4, Blocks.SANDSTONE.getDefaultState());
        structure.fillWithBlocks(world, start, 37, -27, -2, 37, -27, -2, Blocks.STONE_BRICKS.getDefaultState());
        structure.fillWithBlocks(world, start, 37, -27, -1, 37, -27, 0, Blocks.DIRT.getDefaultState());
        structure.fillWithBlocks(world, start, 37, -27, 14, 38, -27, 16, Blocks.AIR.getDefaultState());
        structure.fillWithBlocks(world, start, 37, -27, 17, 38, -27, 18, Blocks.SANDSTONE.getDefaultState());
        structure.fillWithBlocks(world, start, 37, -27, 23, 39, -27, 25, Blocks.SANDSTONE.getDefaultState());
        structure.fillWithBlocks(world, start, 37, -27, 36, 38, -27, 36, Blocks.AIR.getDefaultState());
        structure.fillWithBlocks(world, start, 37, -27, 38, 38, -27, 38, Blocks.AIR.getDefaultState());
        structure.fillWithBlocks(world, start, 37, -27, 40, 38, -27, 40, Blocks.AIR.getDefaultState());
        structure.fillWithBlocks(world, start, 37, -27, 41, 37, -27, 41, Blocks.SANDSTONE.getDefaultState());
        structure.fillWithBlocks(world, start, 37, -27, 43, 38, -27, 46, Blocks.SANDSTONE.getDefaultState());
        structure.fillWithBlocks(world, start, 37, -27, 48, 37, -27, 48, Blocks.DIRT.getDefaultState());
        structure.fillWithBlocks(world, start, 37, -27, 49, 37, -23, 49, Blocks.SANDSTONE.getDefaultState());
        structure.fillWithBlocks(world, start, 37, -27, 54, 39, -27, 54, Blocks.SANDSTONE.getDefaultState());
        structure.fillWithBlocks(world, start, 37, -27, 63, 37, -27, 63, Blocks.SANDSTONE.getDefaultState());
        structure.fillWithBlocks(world, start, 37, -26, -6, 37, -26, 1, Blocks.STONE_BRICKS.getDefaultState());
        structure.fillWithBlocks(world, start, 37, -26, 2, 38, -25, 2, Blocks.AIR.getDefaultState());
        structure.fillWithBlocks(world, start, 37, -26, 3, 37, -24, 3, Blocks.SANDSTONE.getDefaultState());
        structure.fillWithBlocks(world, start, 37, -26, 4, 38, -25, 4, Blocks.AIR.getDefaultState());
        structure.fillWithBlocks(world, start, 37, -26, 5, 38, -26, 5, Blocks.STONE_BRICKS.getDefaultState());
        structure.fillWithBlocks(world, start, 37, -26, 6, 38, -25, 6, Blocks.AIR.getDefaultState());
        structure.fillWithBlocks(world, start, 37, -26, 20, 37, -25, 20, Blocks.DIRT.getDefaultState());
        structure.fillWithBlocks(world, start, 37, -26, 21, 37, -23, 25, Blocks.SANDSTONE.getDefaultState());
        structure.fillWithBlocks(world, start, 37, -26, 36, 39, -26, 36, Blocks.SHROOMLIGHT.getDefaultState());
        structure.fillWithBlocks(world, start, 37, -26, 37, 37, -24, 37, Blocks.SANDSTONE.getDefaultState());
        structure.fillWithBlocks(world, start, 37, -26, 38, 39, -26, 38, Blocks.SHROOMLIGHT.getDefaultState());
        structure.fillWithBlocks(world, start, 37, -26, 40, 39, -26, 40, Blocks.SHROOMLIGHT.getDefaultState());
        structure.fillWithBlocks(world, start, 37, -26, 41, 39, -26, 43, Blocks.SANDSTONE.getDefaultState());
        structure.fillWithBlocks(world, start, 37, -26, 48, 38, -26, 51, Blocks.SANDSTONE.getDefaultState());
        structure.fillWithBlocks(world, start, 37, -26, 53, 37, -26, 57, Blocks.AIR.getDefaultState());
        structure.fillWithBlocks(world, start, 37, -26, 59, 37, -26, 63, Blocks.SANDSTONE.getDefaultState());
        structure.fillWithBlocks(world, start, 37, -26, 65, 42, -26, 65, Blocks.SANDSTONE.getDefaultState());
        structure.fillWithBlocks(world, start, 37, -25, -4, 37, -24, -3, Blocks.STONE_BRICKS.getDefaultState());
        structure.fillWithBlocks(world, start, 37, -25, -2, 38, -25, -2, Blocks.DIRT.getDefaultState());
        structure.fillWithBlocks(world, start, 37, -25, -1, 37, -24, -1, Blocks.STONE_BRICKS.getDefaultState());
        structure.fillWithBlocks(world, start, 37, -25, 1, 37, -24, 1, Blocks.STONE_BRICKS.getDefaultState());
        structure.fillWithBlocks(world, start, 37, -25, 5, 37, -24, 5, Blocks.SANDSTONE.getDefaultState());
        structure.fillWithBlocks(world, start, 37, -25, 26, 37, -25, 26, Blocks.SANDSTONE.getDefaultState());
        structure.fillWithBlocks(world, start, 37, -25, 29, 40, -23, 29, Blocks.SANDSTONE.getDefaultState());
        structure.fillWithBlocks(world, start, 37, -25, 39, 39, -24, 39, Blocks.SANDSTONE.getDefaultState());
        structure.fillWithBlocks(world, start, 37, -25, 40, 38, -25, 40, Blocks.AIR.getDefaultState());
        structure.fillWithBlocks(world, start, 37, -25, 41, 37, -24, 44, Blocks.SANDSTONE.getDefaultState());
        structure.fillWithBlocks(world, start, 37, -25, 53, 38, -25, 53, Blocks.AIR.getDefaultState());
        structure.fillWithBlocks(world, start, 37, -25, 54, 37, -25, 54, Blocks.SANDSTONE.getDefaultState());
        structure.fillWithBlocks(world, start, 37, -25, 57, 38, -25, 59, Blocks.AIR.getDefaultState());
        structure.fillWithBlocks(world, start, 37, -25, 61, 37, -25, 61, Blocks.SANDSTONE.getDefaultState());
        structure.fillWithBlocks(world, start, 37, -25, 62, 37, -25, 63, Blocks.AIR.getDefaultState());
        structure.fillWithBlocks(world, start, 37, -25, 64, 37, -25, 64, Blocks.SANDSTONE.getDefaultState());
        structure.fillWithBlocks(world, start, 37, -24, 0, 37, -24, 2, Blocks.STONE_BRICKS.getDefaultState());
        structure.fillWithBlocks(world, start, 37, -24, 6, 38, -24, 7, Blocks.STONE_BRICKS.getDefaultState());
        structure.fillWithBlocks(world, start, 37, -24, 17, 37, -22, 21, Blocks.SANDSTONE.getDefaultState());
        structure.fillWithBlocks(world, start, 37, -24, 26, 39, -24, 43, Blocks.SANDSTONE.getDefaultState());
        structure.fillWithBlocks(world, start, 37, -24, 45, 37, -24, 46, Blocks.DIRT.getDefaultState());
        structure.fillWithBlocks(world, start, 37, -24, 48, 38, -24, 49, Blocks.SANDSTONE.getDefaultState());
        structure.fillWithBlocks(world, start, 37, -24, 50, 37, -24, 61, Blocks.SANDSTONE.getDefaultState());
        structure.fillWithBlocks(world, start, 37, -24, 62, 37, -24, 62, Blocks.AIR.getDefaultState());
        structure.fillWithBlocks(world, start, 37, -24, 63, 37, -24, 65, Blocks.SANDSTONE.getDefaultState());
        structure.fillWithBlocks(world, start, 37, -23, -2, 37, -23, -2, Blocks.STONE_BRICKS.getDefaultState());
        structure.fillWithBlocks(world, start, 37, -23, 0, 37, -22, 0, Blocks.STONE_BRICKS.getDefaultState());
        structure.fillWithBlocks(world, start, 37, -23, 1, 37, -23, 2, Blocks.SANDSTONE.getDefaultState());
        structure.fillWithBlocks(world, start, 37, -23, 3, 37, -23, 3, Blocks.STONE_BRICKS.getDefaultState());
        structure.fillWithBlocks(world, start, 37, -23, 5, 37, -21, 5, Blocks.STONE_BRICKS.getDefaultState());
        structure.fillWithBlocks(world, start, 37, -23, 6, 38, -23, 6, Blocks.SANDSTONE.getDefaultState());
        structure.fillWithBlocks(world, start, 37, -23, 7, 37, -23, 8, Blocks.STONE_BRICKS.getDefaultState());
        structure.fillWithBlocks(world, start, 37, -23, 16, 38, -23, 16, Blocks.DIRT.getDefaultState());
        structure.fillWithBlocks(world, start, 37, -23, 26, 37, -21, 26, Blocks.SANDSTONE.getDefaultState());
        structure.fillWithBlocks(world, start, 37, -23, 28, 38, -23, 29, Blocks.SANDSTONE.getDefaultState());
        structure.fillWithBlocks(world, start, 37, -23, 31, 39, -23, 36, Blocks.SANDSTONE.getDefaultState());
        structure.fillWithBlocks(world, start, 37, -23, 37, 37, -23, 38, Blocks.DIRT.getDefaultState());
        structure.fillWithBlocks(world, start, 37, -23, 42, 37, -23, 42, Blocks.SANDSTONE.getDefaultState());
        structure.fillWithBlocks(world, start, 37, -23, 44, 37, -23, 44, Blocks.SANDSTONE.getDefaultState());
        structure.fillWithBlocks(world, start, 37, -23, 45, 37, -23, 46, Blocks.DIRT.getDefaultState());
        structure.fillWithBlocks(world, start, 37, -23, 48, 38, -23, 49, Blocks.SANDSTONE.getDefaultState());
        structure.fillWithBlocks(world, start, 37, -23, 53, 40, -23, 57, Blocks.SANDSTONE.getDefaultState());
        structure.fillWithBlocks(world, start, 37, -23, 64, 38, -23, 65, Blocks.SANDSTONE.getDefaultState());
        structure.fillWithBlocks(world, start, 37, -22, -2, 37, -22, 2, Blocks.STONE_BRICKS.getDefaultState());
        structure.fillWithBlocks(world, start, 37, -22, 3, 37, -22, 4, Blocks.SANDSTONE.getDefaultState());
        structure.fillWithBlocks(world, start, 37, -22, 6, 37, -21, 6, Blocks.AIR.getDefaultState());
        structure.fillWithBlocks(world, start, 37, -22, 15, 40, -22, 18, Blocks.SANDSTONE.getDefaultState());
        structure.fillWithBlocks(world, start, 37, -22, 27, 37, -22, 27, Blocks.SANDSTONE.getDefaultState());
        structure.fillWithBlocks(world, start, 37, -22, 29, 38, -22, 30, Blocks.SANDSTONE.getDefaultState());
        structure.fillWithBlocks(world, start, 37, -22, 31, 37, -22, 34, Blocks.SANDSTONE.getDefaultState());
        structure.fillWithBlocks(world, start, 37, -22, 35, 38, -22, 35, Blocks.DIRT.getDefaultState());
        structure.fillWithBlocks(world, start, 37, -22, 36, 38, -22, 38, Blocks.SANDSTONE.getDefaultState());
        structure.fillWithBlocks(world, start, 37, -22, 41, 37, -22, 41, Blocks.SANDSTONE.getDefaultState());
        structure.fillWithBlocks(world, start, 37, -22, 42, 37, -21, 42, Blocks.DIRT.getDefaultState());
        structure.fillWithBlocks(world, start, 37, -22, 43, 39, -22, 45, Blocks.SANDSTONE.getDefaultState());
        structure.fillWithBlocks(world, start, 37, -22, 46, 37, -22, 46, Blocks.AIR.getDefaultState());
        structure.fillWithBlocks(world, start, 37, -22, 48, 37, -22, 48, Blocks.SANDSTONE.getDefaultState());
        structure.fillWithBlocks(world, start, 37, -22, 50, 38, -22, 51, Blocks.SANDSTONE.getDefaultState());
        structure.fillWithBlocks(world, start, 37, -22, 52, 37, -21, 52, Blocks.SANDSTONE.getDefaultState());
        structure.fillWithBlocks(world, start, 37, -22, 55, 38, -22, 56, Blocks.SANDSTONE.getDefaultState());
        structure.fillWithBlocks(world, start, 37, -22, 57, 37, -22, 57, Blocks.SANDSTONE.getDefaultState());
        structure.fillWithBlocks(world, start, 37, -22, 59, 37, -21, 60, Blocks.SANDSTONE.getDefaultState());
        structure.fillWithBlocks(world, start, 37, -22, 62, 37, -22, 62, Blocks.SANDSTONE.getDefaultState());
        structure.fillWithBlocks(world, start, 37, -21, -3, 37, -21, -2, Blocks.SANDSTONE.getDefaultState());
        structure.fillWithBlocks(world, start, 37, -21, 2, 38, -21, 2, Blocks.SANDSTONE.getDefaultState());
        structure.fillWithBlocks(world, start, 37, -21, 3, 37, -21, 3, Blocks.STONE_BRICKS.getDefaultState());
        structure.fillWithBlocks(world, start, 37, -21, 7, 38, -21, 7, Blocks.AIR.getDefaultState());
        structure.fillWithBlocks(world, start, 37, -21, 8, 37, -21, 17, Blocks.SANDSTONE.getDefaultState());
        structure.fillWithBlocks(world, start, 37, -21, 19, 40, -21, 22, Blocks.SANDSTONE.getDefaultState());
        structure.fillWithBlocks(world, start, 37, -21, 23, 37, -21, 26, Blocks.SANDSTONE.getDefaultState());
        structure.fillWithBlocks(world, start, 37, -21, 32, 37, -21, 32, Blocks.SANDSTONE.getDefaultState());
        structure.fillWithBlocks(world, start, 37, -21, 34, 37, -20, 40, Blocks.SANDSTONE.getDefaultState());
        structure.fillWithBlocks(world, start, 37, -21, 43, 37, -21, 43, Blocks.SANDSTONE.getDefaultState());
        structure.fillWithBlocks(world, start, 37, -21, 45, 39, -21, 47, Blocks.SANDSTONE.getDefaultState());
        structure.fillWithBlocks(world, start, 37, -21, 56, 37, -21, 57, Blocks.DIRT.getDefaultState());
        structure.fillWithBlocks(world, start, 37, -21, 61, 38, -21, 62, Blocks.SANDSTONE.getDefaultState());
        structure.fillWithBlocks(world, start, 37, -21, 63, 37, -21, 65, Blocks.SANDSTONE.getDefaultState());
        structure.fillWithBlocks(world, start, 37, -16, 32, 39, -16, 34, Blocks.SANDSTONE.getDefaultState());
        structure.fillWithBlocks(world, start, 37, -15, 36, 39, -15, 40, Blocks.AIR.getDefaultState());
        structure.fillWithBlocks(world, start, 37, -15, 41, 38, -15, 44, Blocks.SANDSTONE.getDefaultState());
        structure.fillWithBlocks(world, start, 37, -14, 41, 37, -14, 44, Blocks.SANDSTONE.getDefaultState());
        structure.fillWithBlocks(world, start, 37, -13, 38, 38, -13, 40, Blocks.SANDSTONE.getDefaultState());
        structure.fillWithBlocks(world, start, 37, -13, 42, 39, -13, 44, Blocks.SANDSTONE.getDefaultState());
        structure.fillWithBlocks(world, start, 37, -12, 40, 41, -12, 44, Blocks.SANDSTONE.getDefaultState());
        structure.fillWithBlocks(world, start, 37, 0, 20, 37, 4, 20, Blocks.SANDSTONE.getDefaultState());
        structure.fillWithBlocks(world, start, 37, 0, 124, 38, 0, 125, Blocks.STONE.getDefaultState());
        structure.fillWithBlocks(world, start, 37, 0, 126, 38, 0, 127, Blocks.SANDSTONE.getDefaultState());
        structure.fillWithBlocks(world, start, 37, 1, 28, 45, 1, 28, Blocks.STONE.getDefaultState());
        structure.fillWithBlocks(world, start, 37, 1, 29, 39, 1, 32, Blocks.SANDSTONE.getDefaultState());
        structure.fillWithBlocks(world, start, 37, 1, 69, 38, 1, 70, Blocks.STONE.getDefaultState());
        structure.fillWithBlocks(world, start, 37, 1, 71, 37, 1, 79, Blocks.SANDSTONE.getDefaultState());
        structure.fillWithBlocks(world, start, 37, 1, 135, 41, 1, 135, Blocks.STONE.getDefaultState());
        structure.fillWithBlocks(world, start, 37, 1, 136, 38, 1, 145, Blocks.SANDSTONE.getDefaultState());
        structure.fillWithBlocks(world, start, 37, 2, 90, 42, 2, 90, Blocks.STONE.getDefaultState());
        structure.fillWithBlocks(world, start, 37, 2, 91, 40, 2, 102, Blocks.SANDSTONE.getDefaultState());
        structure.fillWithBlocks(world, start, 37, 2, 103, 37, 3, 104, Blocks.SANDSTONE.getDefaultState());
        structure.fillWithBlocks(world, start, 37, 2, 105, 42, 2, 110, Blocks.STONE.getDefaultState());
        structure.fillWithBlocks(world, start, 37, 2, 111, 51, 2, 143, Blocks.SANDSTONE.getDefaultState());
        structure.fillWithBlocks(world, start, 37, 3, 17, 70, 3, 141, Blocks.SANDSTONE.getDefaultState());
        structure.fillWithBlocks(world, start, 37, 5, 135, 176, 5, 135, Blocks.SANDSTONE.getDefaultState());
        structure.fillWithBlocks(world, start, 37, 6, 125, 170, 6, 125, Blocks.SANDSTONE.getDefaultState());
        structure.fillWithBlocks(world, start, 38, -50, 30, 39, -50, 31, Blocks.SANDSTONE.getDefaultState());
        structure.fillWithBlocks(world, start, 38, -50, 35, 42, -50, 41, Blocks.SANDSTONE.getDefaultState());
        structure.fillWithBlocks(world, start, 38, -50, 45, 39, -50, 46, Blocks.SANDSTONE.getDefaultState());
        structure.fillWithBlocks(world, start, 38, -49, 31, 40, -49, 31, Blocks.IRON_BARS.getDefaultState().with(FourWayBlock.WATERLOGGED, false).with(FourWayBlock.NORTH, true).with(FourWayBlock.SOUTH, true).with(FourWayBlock.EAST, true).with(FourWayBlock.WEST, true));
        structure.fillWithBlocks(world, start, 38, -49, 35, 40, -49, 35, Blocks.IRON_BARS.getDefaultState().with(FourWayBlock.WATERLOGGED, false).with(FourWayBlock.NORTH, true).with(FourWayBlock.SOUTH, true).with(FourWayBlock.EAST, true).with(FourWayBlock.WEST, true));
        structure.fillWithBlocks(world, start, 38, -49, 38, 40, -49, 40, Blocks.AIR.getDefaultState());
        structure.fillWithBlocks(world, start, 38, -49, 41, 40, -49, 41, Blocks.IRON_BARS.getDefaultState().with(FourWayBlock.WATERLOGGED, false).with(FourWayBlock.NORTH, true).with(FourWayBlock.SOUTH, true).with(FourWayBlock.EAST, true).with(FourWayBlock.WEST, true));
        structure.fillWithBlocks(world, start, 38, -49, 45, 40, -49, 45, Blocks.IRON_BARS.getDefaultState().with(FourWayBlock.WATERLOGGED, false).with(FourWayBlock.NORTH, true).with(FourWayBlock.SOUTH, true).with(FourWayBlock.EAST, true).with(FourWayBlock.WEST, true));
        structure.fillWithBlocks(world, start, 38, -48, 31, 40, -48, 45, Blocks.AIR.getDefaultState());
        structure.fillWithBlocks(world, start, 38, -47, 31, 40, -47, 45, Blocks.AIR.getDefaultState());
        structure.fillWithBlocks(world, start, 38, -46, 31, 40, -46, 45, Blocks.AIR.getDefaultState());
        structure.fillWithBlocks(world, start, 38, -45, 32, 40, -45, 34, Blocks.AIR.getDefaultState());
        structure.fillWithBlocks(world, start, 38, -45, 36, 40, -45, 40, Blocks.AIR.getDefaultState());
        structure.fillWithBlocks(world, start, 38, -45, 42, 40, -45, 44, Blocks.AIR.getDefaultState());
        structure.fillWithBlocks(world, start, 38, -45, 45, 39, -45, 46, Blocks.SANDSTONE.getDefaultState());
        structure.fillWithBlocks(world, start, 38, -41, 35, 42, -41, 41, Blocks.SANDSTONE.getDefaultState());
        structure.fillWithBlocks(world, start, 38, -40, 32, 39, -40, 34, Blocks.AIR.getDefaultState());
        structure.fillWithBlocks(world, start, 38, -40, 42, 39, -40, 44, Blocks.AIR.getDefaultState());
        structure.fillWithBlocks(world, start, 38, -35, 31, 48, -35, 31, Blocks.STONE_BRICKS.getDefaultState());
        structure.fillWithBlocks(world, start, 38, -35, 32, 39, -35, 34, Blocks.AIR.getDefaultState());
        structure.fillWithBlocks(world, start, 38, -35, 42, 39, -35, 44, Blocks.AIR.getDefaultState());
        structure.fillWithBlocks(world, start, 38, -34, 32, 39, -34, 46, Blocks.STONE_BRICKS.getDefaultState());
        structure.fillWithBlocks(world, start, 38, -33, 31, 38, -33, 31, Blocks.STONE_BRICKS.getDefaultState());
        structure.fillWithBlocks(world, start, 38, -33, 33, 39, -33, 39, Blocks.STONE_BRICKS.getDefaultState());
        structure.fillWithBlocks(world, start, 38, -33, 41, 40, -33, 43, Blocks.STONE_BRICKS.getDefaultState());
        structure.fillWithBlocks(world, start, 38, -33, 44, 39, -33, 46, Blocks.STONE_BRICKS.getDefaultState());
        structure.fillWithBlocks(world, start, 38, -32, 32, 38, -32, 32, Blocks.STONE_BRICKS.getDefaultState());
        structure.fillWithBlocks(world, start, 38, -32, 34, 38, -32, 37, Blocks.STONE_BRICKS.getDefaultState());
        structure.fillWithBlocks(world, start, 38, -32, 39, 39, -32, 42, Blocks.STONE_BRICKS.getDefaultState());
        structure.fillWithBlocks(world, start, 38, -32, 44, 38, -31, 46, Blocks.STONE_BRICKS.getDefaultState());
        structure.fillWithBlocks(world, start, 38, -31, 35, 41, -31, 38, Blocks.STONE_BRICKS.getDefaultState());
        structure.fillWithBlocks(world, start, 38, -31, 40, 41, -31, 45, Blocks.STONE_BRICKS.getDefaultState());
        structure.fillWithBlocks(world, start, 38, -30, -1, 38, -29, -1, Blocks.AIR.getDefaultState());
        structure.fillWithBlocks(world, start, 38, -30, 0, 38, -30, 0, Blocks.SANDSTONE.getDefaultState());
        structure.fillWithBlocks(world, start, 38, -30, 6, 45, -30, 17, Blocks.SANDSTONE.getDefaultState());
        structure.fillWithBlocks(world, start, 38, -30, 19, 38, -30, 19, Blocks.SANDSTONE.getDefaultState());
        structure.fillWithBlocks(world, start, 38, -30, 21, 38, -30, 22, Blocks.SANDSTONE.getDefaultState());
        structure.fillWithBlocks(world, start, 38, -30, 24, 39, -30, 28, Blocks.SANDSTONE.getDefaultState());
        structure.fillWithBlocks(world, start, 38, -30, 35, 38, -30, 35, Blocks.SANDSTONE.getDefaultState());
        structure.fillWithBlocks(world, start, 38, -30, 36, 38, -30, 36, Blocks.AIR.getDefaultState());
        structure.fillWithBlocks(world, start, 38, -30, 37, 38, -27, 37, Blocks.SANDSTONE.getDefaultState());
        structure.fillWithBlocks(world, start, 38, -30, 38, 38, -30, 39, Blocks.DIRT.getDefaultState());
        structure.fillWithBlocks(world, start, 38, -30, 40, 38, -30, 41, Blocks.AIR.getDefaultState());
        structure.fillWithBlocks(world, start, 38, -30, 42, 38, -30, 42, Blocks.DIRT.getDefaultState());
        structure.fillWithBlocks(world, start, 38, -30, 43, 38, -26, 43, Blocks.SANDSTONE.getDefaultState());
        structure.fillWithBlocks(world, start, 38, -30, 44, 38, -30, 45, Blocks.DIRT.getDefaultState());
        structure.fillWithBlocks(world, start, 38, -30, 46, 38, -30, 46, Blocks.SANDSTONE.getDefaultState());
        structure.fillWithBlocks(world, start, 38, -30, 47, 38, -30, 49, Blocks.DIRT.getDefaultState());
        structure.fillWithBlocks(world, start, 38, -30, 52, 39, -30, 53, Blocks.SANDSTONE.getDefaultState());
        structure.fillWithBlocks(world, start, 38, -30, 56, 38, -30, 58, Blocks.DIRT.getDefaultState());
        structure.fillWithBlocks(world, start, 38, -30, 59, 38, -27, 59, Blocks.SANDSTONE.getDefaultState());
        structure.fillWithBlocks(world, start, 38, -30, 60, 38, -30, 62, Blocks.DIRT.getDefaultState());
        structure.fillWithBlocks(world, start, 38, -29, -6, 38, -29, -5, Blocks.STONE_BRICKS.getDefaultState());
        structure.fillWithBlocks(world, start, 38, -29, -2, 38, -29, -2, Blocks.STONE_BRICKS.getDefaultState());
        structure.fillWithBlocks(world, start, 38, -29, 3, 38, -29, 3, Blocks.SANDSTONE.getDefaultState());
        structure.fillWithBlocks(world, start, 38, -29, 4, 38, -29, 6, Blocks.STONE_BRICKS.getDefaultState());
        structure.fillWithBlocks(world, start, 38, -29, 14, 38, -29, 16, Blocks.AIR.getDefaultState());
        structure.fillWithBlocks(world, start, 38, -29, 17, 38, -29, 17, Blocks.SANDSTONE.getDefaultState());
        structure.fillWithBlocks(world, start, 38, -29, 19, 39, -29, 20, Blocks.SANDSTONE.getDefaultState());
        structure.fillWithBlocks(world, start, 38, -29, 22, 38, -29, 22, Blocks.SANDSTONE.getDefaultState());
        structure.fillWithBlocks(world, start, 38, -29, 24, 38, -29, 25, Blocks.SANDSTONE.getDefaultState());
        structure.fillWithBlocks(world, start, 38, -29, 30, 42, -29, 34, Blocks.AIR.getDefaultState());
        structure.fillWithBlocks(world, start, 38, -29, 35, 39, -29, 40, Blocks.SANDSTONE.getDefaultState());
        structure.fillWithBlocks(world, start, 38, -29, 44, 38, -28, 44, Blocks.AIR.getDefaultState());
        structure.fillWithBlocks(world, start, 38, -29, 49, 38, -27, 49, Blocks.DIRT.getDefaultState());
        structure.fillWithBlocks(world, start, 38, -29, 50, 38, -29, 63, Blocks.SANDSTONE.getDefaultState());
        structure.fillWithBlocks(world, start, 38, -28, -4, 38, -28, -3, Blocks.STONE_BRICKS.getDefaultState());
        structure.fillWithBlocks(world, start, 38, -28, 0, 38, -27, 1, Blocks.STONE_BRICKS.getDefaultState());
        structure.fillWithBlocks(world, start, 38, -28, 5, 39, -28, 5, Blocks.SANDSTONE.getDefaultState());
        structure.fillWithBlocks(world, start, 38, -28, 17, 39, -28, 20, Blocks.SANDSTONE.getDefaultState());
        structure.fillWithBlocks(world, start, 38, -28, 21, 38, -28, 22, Blocks.SANDSTONE.getDefaultState());
        structure.fillWithBlocks(world, start, 38, -28, 24, 39, -28, 25, Blocks.SANDSTONE.getDefaultState());
        structure.fillWithBlocks(world, start, 38, -28, 41, 39, -28, 42, Blocks.SANDSTONE.getDefaultState());
        structure.fillWithBlocks(world, start, 38, -28, 51, 38, -27, 52, Blocks.SANDSTONE.getDefaultState());
        structure.fillWithBlocks(world, start, 38, -28, 54, 38, -28, 55, Blocks.SANDSTONE.getDefaultState());
        structure.fillWithBlocks(world, start, 38, -28, 58, 38, -27, 59, Blocks.SANDSTONE.getDefaultState());
        structure.fillWithBlocks(world, start, 38, -28, 60, 39, -28, 60, Blocks.AIR.getDefaultState());
        structure.fillWithBlocks(world, start, 38, -28, 64, 38, -27, 65, Blocks.SANDSTONE.getDefaultState());
        structure.fillWithBlocks(world, start, 38, -27, -2, 38, -27, 1, Blocks.STONE_BRICKS.getDefaultState());
        structure.fillWithBlocks(world, start, 38, -27, 3, 38, -27, 3, Blocks.SANDSTONE.getDefaultState());
        structure.fillWithBlocks(world, start, 38, -27, 19, 39, -27, 25, Blocks.SANDSTONE.getDefaultState());
        structure.fillWithBlocks(world, start, 38, -27, 41, 39, -27, 44, Blocks.SANDSTONE.getDefaultState());
        structure.fillWithBlocks(world, start, 38, -27, 47, 38, -26, 47, Blocks.DIRT.getDefaultState());
        structure.fillWithBlocks(world, start, 38, -27, 50, 38, -26, 51, Blocks.SANDSTONE.getDefaultState());
        structure.fillWithBlocks(world, start, 38, -27, 55, 38, -26, 55, Blocks.AIR.getDefaultState());
        structure.fillWithBlocks(world, start, 38, -27, 56, 38, -27, 56, Blocks.SANDSTONE.getDefaultState());
        structure.fillWithBlocks(world, start, 38, -27, 60, 38, -27, 60, Blocks.AIR.getDefaultState());
        structure.fillWithBlocks(world, start, 38, -27, 62, 39, -27, 63, Blocks.SANDSTONE.getDefaultState());
        structure.fillWithBlocks(world, start, 38, -26, -6, 38, -25, -6, Blocks.STONE_BRICKS.getDefaultState());
        structure.fillWithBlocks(world, start, 38, -26, -4, 38, -26, -2, Blocks.STONE_BRICKS.getDefaultState());
        structure.fillWithBlocks(world, start, 38, -26, -1, 38, -25, -1, Blocks.SANDSTONE.getDefaultState());
        structure.fillWithBlocks(world, start, 38, -26, 0, 39, -26, 0, Blocks.STONE_BRICKS.getDefaultState());
        structure.fillWithBlocks(world, start, 38, -26, 1, 38, -26, 2, Blocks.AIR.getDefaultState());
        structure.fillWithBlocks(world, start, 38, -26, 17, 38, -26, 17, Blocks.SANDSTONE.getDefaultState());
        structure.fillWithBlocks(world, start, 38, -26, 19, 39, -26, 21, Blocks.SANDSTONE.getDefaultState());
        structure.fillWithBlocks(world, start, 38, -26, 23, 39, -26, 25, Blocks.SANDSTONE.getDefaultState());
        structure.fillWithBlocks(world, start, 38, -26, 44, 38, -21, 44, Blocks.SANDSTONE.getDefaultState());
        structure.fillWithBlocks(world, start, 38, -26, 45, 39, -26, 45, Blocks.AIR.getDefaultState());
        structure.fillWithBlocks(world, start, 38, -26, 46, 38, -26, 46, Blocks.SANDSTONE.getDefaultState());
        structure.fillWithBlocks(world, start, 38, -26, 52, 38, -25, 53, Blocks.AIR.getDefaultState());
        structure.fillWithBlocks(world, start, 38, -26, 54, 39, -25, 54, Blocks.SANDSTONE.getDefaultState());
        structure.fillWithBlocks(world, start, 38, -26, 56, 39, -25, 56, Blocks.SANDSTONE.getDefaultState());
        structure.fillWithBlocks(world, start, 38, -26, 57, 38, -25, 57, Blocks.AIR.getDefaultState());
        structure.fillWithBlocks(world, start, 38, -26, 58, 38, -26, 58, Blocks.SANDSTONE.getDefaultState());
        structure.fillWithBlocks(world, start, 38, -26, 59, 38, -25, 59, Blocks.AIR.getDefaultState());
        structure.fillWithBlocks(world, start, 38, -26, 60, 39, -26, 61, Blocks.SANDSTONE.getDefaultState());
        structure.fillWithBlocks(world, start, 38, -26, 62, 38, -25, 65, Blocks.SANDSTONE.getDefaultState());
        structure.fillWithBlocks(world, start, 38, -25, -5, 39, -25, -4, Blocks.STONE_BRICKS.getDefaultState());
        structure.fillWithBlocks(world, start, 38, -25, -3, 38, -24, -3, Blocks.AIR.getDefaultState());
        structure.fillWithBlocks(world, start, 38, -25, 0, 38, -25, 1, Blocks.SANDSTONE.getDefaultState());
        structure.fillWithBlocks(world, start, 38, -25, 3, 38, -24, 3, Blocks.STONE_BRICKS.getDefaultState());
        structure.fillWithBlocks(world, start, 38, -25, 15, 40, -25, 18, Blocks.SANDSTONE.getDefaultState());
        structure.fillWithBlocks(world, start, 38, -25, 19, 39, -25, 23, Blocks.SANDSTONE.getDefaultState());
        structure.fillWithBlocks(world, start, 38, -25, 24, 38, -25, 25, Blocks.DIRT.getDefaultState());
        structure.fillWithBlocks(world, start, 38, -25, 26, 38, -25, 29, Blocks.SANDSTONE.getDefaultState());
        structure.fillWithBlocks(world, start, 38, -25, 41, 38, -25, 41, Blocks.SANDSTONE.getDefaultState());
        structure.fillWithBlocks(world, start, 38, -25, 42, 38, -25, 43, Blocks.DIRT.getDefaultState());
        structure.fillWithBlocks(world, start, 38, -25, 46, 40, -25, 48, Blocks.SANDSTONE.getDefaultState());
        structure.fillWithBlocks(world, start, 38, -25, 50, 39, -25, 51, Blocks.SANDSTONE.getDefaultState());
        structure.fillWithBlocks(world, start, 38, -25, 55, 39, -25, 56, Blocks.SANDSTONE.getDefaultState());
        structure.fillWithBlocks(world, start, 38, -25, 60, 40, -25, 63, Blocks.SANDSTONE.getDefaultState());
        structure.fillWithBlocks(world, start, 38, -24, -6, 38, -24, -6, Blocks.DIRT.getDefaultState());
        structure.fillWithBlocks(world, start, 38, -24, -5, 38, -24, -4, Blocks.STONE_BRICKS.getDefaultState());
        structure.fillWithBlocks(world, start, 38, -24, -2, 39, -24, -1, Blocks.STONE_BRICKS.getDefaultState());
        structure.fillWithBlocks(world, start, 38, -24, 0, 39, -24, 0, Blocks.DIRT.getDefaultState());
        structure.fillWithBlocks(world, start, 38, -24, 1, 38, -24, 1, Blocks.STONE_BRICKS.getDefaultState());
        structure.fillWithBlocks(world, start, 38, -24, 2, 38, -23, 2, Blocks.AIR.getDefaultState());
        structure.fillWithBlocks(world, start, 38, -24, 4, 38, -24, 5, Blocks.SANDSTONE.getDefaultState());
        structure.fillWithBlocks(world, start, 38, -24, 17, 41, -24, 17, Blocks.SANDSTONE.getDefaultState());
        structure.fillWithBlocks(world, start, 38, -24, 20, 38, -24, 20, Blocks.SANDSTONE.getDefaultState());
        structure.fillWithBlocks(world, start, 38, -24, 22, 38, -21, 22, Blocks.SANDSTONE.getDefaultState());
        structure.fillWithBlocks(world, start, 38, -24, 23, 38, -24, 24, Blocks.AIR.getDefaultState());
        structure.fillWithBlocks(world, start, 38, -24, 25, 38, -24, 45, Blocks.SANDSTONE.getDefaultState());
        structure.fillWithBlocks(world, start, 38, -24, 47, 39, -24, 48, Blocks.SANDSTONE.getDefaultState());
        structure.fillWithBlocks(world, start, 38, -24, 51, 39, -24, 52, Blocks.SANDSTONE.getDefaultState());
        structure.fillWithBlocks(world, start, 38, -24, 54, 44, -24, 62, Blocks.SANDSTONE.getDefaultState());
        structure.fillWithBlocks(world, start, 38, -24, 64, 39, -24, 65, Blocks.SANDSTONE.getDefaultState());
        structure.fillWithBlocks(world, start, 38, -23, -6, 38, -23, -5, Blocks.STONE_BRICKS.getDefaultState());
        structure.fillWithBlocks(world, start, 38, -23, -3, 38, -23, -1, Blocks.STONE_BRICKS.getDefaultState());
        structure.fillWithBlocks(world, start, 38, -23, 1, 38, -23, 2, Blocks.AIR.getDefaultState());
        structure.fillWithBlocks(world, start, 38, -23, 4, 39, -22, 4, Blocks.STONE_BRICKS.getDefaultState());
        structure.fillWithBlocks(world, start, 38, -23, 5, 38, -23, 6, Blocks.SANDSTONE.getDefaultState());
        structure.fillWithBlocks(world, start, 38, -23, 7, 38, -23, 7, Blocks.STONE_BRICKS.getDefaultState());
        structure.fillWithBlocks(world, start, 38, -23, 10, 39, -22, 10, Blocks.SANDSTONE.getDefaultState());
        structure.fillWithBlocks(world, start, 38, -23, 11, 39, -23, 11, Blocks.DIRT.getDefaultState());
        structure.fillWithBlocks(world, start, 38, -23, 12, 40, -23, 14, Blocks.SANDSTONE.getDefaultState());
        structure.fillWithBlocks(world, start, 38, -23, 15, 39, -22, 15, Blocks.SANDSTONE.getDefaultState());
        structure.fillWithBlocks(world, start, 38, -23, 17, 38, -23, 23, Blocks.SANDSTONE.getDefaultState());
        structure.fillWithBlocks(world, start, 38, -23, 24, 38, -23, 24, Blocks.DIRT.getDefaultState());
        structure.fillWithBlocks(world, start, 38, -23, 26, 38, -23, 26, Blocks.DIRT.getDefaultState());
        structure.fillWithBlocks(world, start, 38, -23, 27, 38, -23, 29, Blocks.SANDSTONE.getDefaultState());
        structure.fillWithBlocks(world, start, 38, -23, 38, 38, -23, 38, Blocks.SANDSTONE.getDefaultState());
        structure.fillWithBlocks(world, start, 38, -23, 39, 38, -22, 39, Blocks.DIRT.getDefaultState());
        structure.fillWithBlocks(world, start, 38, -23, 40, 38, -23, 40, Blocks.SANDSTONE.getDefaultState());
        structure.fillWithBlocks(world, start, 38, -23, 42, 40, -23, 44, Blocks.SANDSTONE.getDefaultState());
        structure.fillWithBlocks(world, start, 38, -23, 45, 38, -23, 49, Blocks.SANDSTONE.getDefaultState());
        structure.fillWithBlocks(world, start, 38, -23, 50, 38, -23, 51, Blocks.AIR.getDefaultState());
        structure.fillWithBlocks(world, start, 38, -23, 52, 38, -23, 57, Blocks.SANDSTONE.getDefaultState());
        structure.fillWithBlocks(world, start, 38, -22, -6, 39, -22, -5, Blocks.SANDSTONE.getDefaultState());
        structure.fillWithBlocks(world, start, 38, -22, -4, 38, -22, -4, Blocks.STONE_BRICKS.getDefaultState());
        structure.fillWithBlocks(world, start, 38, -22, -3, 38, -22, -3, Blocks.SANDSTONE.getDefaultState());
        structure.fillWithBlocks(world, start, 38, -22, -2, 38, -22, -1, Blocks.AIR.getDefaultState());
        structure.fillWithBlocks(world, start, 38, -22, 0, 38, -22, 1, Blocks.STONE_BRICKS.getDefaultState());
        structure.fillWithBlocks(world, start, 38, -22, 2, 38, -21, 2, Blocks.SANDSTONE.getDefaultState());
        structure.fillWithBlocks(world, start, 38, -22, 3, 38, -22, 4, Blocks.STONE_BRICKS.getDefaultState());
        structure.fillWithBlocks(world, start, 38, -22, 5, 38, -22, 5, Blocks.SANDSTONE.getDefaultState());
        structure.fillWithBlocks(world, start, 38, -22, 6, 38, -22, 8, Blocks.STONE_BRICKS.getDefaultState());
        structure.fillWithBlocks(world, start, 38, -22, 14, 39, -22, 18, Blocks.SANDSTONE.getDefaultState());
        structure.fillWithBlocks(world, start, 38, -22, 23, 39, -22, 26, Blocks.SANDSTONE.getDefaultState());
        structure.fillWithBlocks(world, start, 38, -22, 27, 38, -22, 30, Blocks.SANDSTONE.getDefaultState());
        structure.fillWithBlocks(world, start, 38, -22, 31, 38, -22, 31, Blocks.AIR.getDefaultState());
        structure.fillWithBlocks(world, start, 38, -22, 32, 38, -11, 32, Blocks.SANDSTONE.getDefaultState());
        structure.fillWithBlocks(world, start, 38, -22, 34, 38, -22, 34, Blocks.SANDSTONE.getDefaultState());
        structure.fillWithBlocks(world, start, 38, -22, 40, 39, -22, 45, Blocks.SANDSTONE.getDefaultState());
        structure.fillWithBlocks(world, start, 38, -22, 46, 38, -22, 47, Blocks.AIR.getDefaultState());
        structure.fillWithBlocks(world, start, 38, -22, 48, 39, -22, 51, Blocks.SANDSTONE.getDefaultState());
        structure.fillWithBlocks(world, start, 38, -22, 53, 38, -22, 56, Blocks.SANDSTONE.getDefaultState());
        structure.fillWithBlocks(world, start, 38, -22, 57, 39, -22, 57, Blocks.DIRT.getDefaultState());
        structure.fillWithBlocks(world, start, 38, -22, 58, 38, -22, 59, Blocks.SANDSTONE.getDefaultState());
        structure.fillWithBlocks(world, start, 38, -22, 60, 39, -22, 60, Blocks.DIRT.getDefaultState());
        structure.fillWithBlocks(world, start, 38, -22, 61, 39, -22, 62, Blocks.SANDSTONE.getDefaultState());
        structure.fillWithBlocks(world, start, 38, -22, 63, 38, -22, 65, Blocks.SANDSTONE.getDefaultState());
        structure.fillWithBlocks(world, start, 38, -21, -6, 38, -21, -5, Blocks.STONE_BRICKS.getDefaultState());
        structure.fillWithBlocks(world, start, 38, -21, -4, 39, -21, -4, Blocks.SANDSTONE.getDefaultState());
        structure.fillWithBlocks(world, start, 38, -21, -1, 38, -21, 1, Blocks.STONE_BRICKS.getDefaultState());
        structure.fillWithBlocks(world, start, 38, -21, 4, 38, -21, 4, Blocks.STONE_BRICKS.getDefaultState());
        structure.fillWithBlocks(world, start, 38, -21, 5, 38, -21, 6, Blocks.SANDSTONE.getDefaultState());
        structure.fillWithBlocks(world, start, 38, -21, 8, 39, -21, 8, Blocks.STONE_BRICKS.getDefaultState());
        structure.fillWithBlocks(world, start, 38, -21, 9, 39, -21, 16, Blocks.SANDSTONE.getDefaultState());
        structure.fillWithBlocks(world, start, 38, -21, 17, 38, -21, 22, Blocks.SANDSTONE.getDefaultState());
        structure.fillWithBlocks(world, start, 38, -21, 24, 38, -21, 29, Blocks.SANDSTONE.getDefaultState());
        structure.fillWithBlocks(world, start, 38, -21, 31, 38, -21, 34, Blocks.SANDSTONE.getDefaultState());
        structure.fillWithBlocks(world, start, 38, -21, 36, 39, -21, 37, Blocks.SANDSTONE.getDefaultState());
        structure.fillWithBlocks(world, start, 38, -21, 38, 38, -21, 49, Blocks.SANDSTONE.getDefaultState());
        structure.fillWithBlocks(world, start, 38, -21, 51, 38, -21, 62, Blocks.SANDSTONE.getDefaultState());
        structure.fillWithBlocks(world, start, 38, -21, 63, 39, -21, 63, Blocks.AIR.getDefaultState());
        structure.fillWithBlocks(world, start, 38, -21, 64, 46, -21, 64, Blocks.SANDSTONE.getDefaultState());
        structure.fillWithBlocks(world, start, 38, -21, 65, 39, -21, 65, Blocks.AIR.getDefaultState());
        structure.fillWithBlocks(world, start, 38, -19, 39, 40, -19, 41, Blocks.AIR.getDefaultState());
        structure.fillWithBlocks(world, start, 38, -18, 33, 39, -18, 34, Blocks.SANDSTONE.getDefaultState());
        structure.fillWithBlocks(world, start, 38, -18, 39, 40, -18, 41, Blocks.AIR.getDefaultState());
        structure.fillWithBlocks(world, start, 38, -14, 39, 40, -14, 41, Blocks.SANDSTONE.getDefaultState());
        structure.fillWithBlocks(world, start, 38, -14, 43, 39, -14, 44, Blocks.SANDSTONE.getDefaultState());
        structure.fillWithBlocks(world, start, 38, -13, 41, 41, -13, 44, Blocks.SANDSTONE.getDefaultState());
        structure.fillWithBlocks(world, start, 38, 0, 20, 47, 0, 29, Blocks.STONE.getDefaultState());
        structure.fillWithBlocks(world, start, 38, 0, 148, 169, 0, 148, Blocks.SANDSTONE.getDefaultState());
        structure.fillWithBlocks(world, start, 38, 1, 14, 48, 1, 24, Blocks.SANDSTONE.getDefaultState());
        structure.fillWithBlocks(world, start, 38, 1, 26, 39, 1, 27, Blocks.SANDSTONE.getDefaultState());
        structure.fillWithBlocks(world, start, 38, 1, 71, 38, 1, 71, Blocks.STONE.getDefaultState());
        structure.fillWithBlocks(world, start, 38, 1, 72, 38, 1, 79, Blocks.SANDSTONE.getDefaultState());
        structure.fillWithBlocks(world, start, 38, 2, 60, 42, 2, 64, Blocks.STONE.getDefaultState());
        structure.fillWithBlocks(world, start, 38, 2, 65, 38, 2, 86, Blocks.SANDSTONE.getDefaultState());
        structure.fillWithBlocks(world, start, 38, 2, 103, 38, 6, 103, Blocks.SANDSTONE.getDefaultState());
        structure.fillWithBlocks(world, start, 38, 2, 104, 43, 2, 109, Blocks.STONE.getDefaultState());
        structure.fillWithBlocks(world, start, 38, 4, 18, 100, 4, 139, Blocks.SANDSTONE.getDefaultState());
        structure.fillWithBlocks(world, start, 38, 5, 20, 100, 5, 135, Blocks.SANDSTONE.getDefaultState());
        structure.fillWithBlocks(world, start, 39, -49, 36, 41, -49, 40, Blocks.AIR.getDefaultState());
        structure.fillWithBlocks(world, start, 39, -44, 32, 39, -44, 32, Blocks.SANDSTONE.getDefaultState());
        structure.fillWithBlocks(world, start, 39, -44, 34, 42, -44, 37, Blocks.SANDSTONE.getDefaultState());
        structure.fillWithBlocks(world, start, 39, -44, 39, 42, -44, 42, Blocks.SANDSTONE.getDefaultState());
        structure.fillWithBlocks(world, start, 39, -44, 44, 41, -44, 46, Blocks.SANDSTONE.getDefaultState());
