package mod.arcalitegames.odyssey.world.structure.structures.camps.bandit_hideout;

import mod.arcalitegames.odyssey.world.structure.StructureBase;
import net.minecraft.block.AbstractButtonBlock;
import net.minecraft.block.BarrelBlock;
import net.minecraft.block.Blocks;
import net.minecraft.block.CampfireBlock;
import net.minecraft.block.ChestBlock;
import net.minecraft.block.FourWayBlock;
import net.minecraft.block.HorizontalBlock;
import net.minecraft.block.HorizontalFaceBlock;
import net.minecraft.block.LanternBlock;
import net.minecraft.block.LeavesBlock;
import net.minecraft.block.SlabBlock;
import net.minecraft.block.SnowyDirtBlock;
import net.minecraft.block.StairsBlock;
import net.minecraft.block.SweetBerryBushBlock;
import net.minecraft.block.TrapDoorBlock;
import net.minecraft.block.WallBannerBlock;
import net.minecraft.state.properties.AttachFace;
import net.minecraft.state.properties.ChestType;
import net.minecraft.state.properties.Half;
import net.minecraft.state.properties.SlabType;
import net.minecraft.state.properties.StairsShape;
import net.minecraft.util.Direction;
import net.minecraft.util.math.BlockPos;
import net.minecraft.world.World;

public class BanditHideoutComponents
{
	public static BlockPos start;
    public static World world;
    public static StructureBase structure;

    public static void init(World worldIn, BlockPos blockPos, StructureBase structureIn)
    {
        world = worldIn; start = blockPos; structure = structureIn;
    }
    
	public static void generatePart1()
	{
        structure.setBlockState(world, Blocks.GRASS_BLOCK.getDefaultState().with(SnowyDirtBlock.SNOWY, false), 3, 2, 29, start);
        structure.setBlockState(world, Blocks.GRASS_BLOCK.getDefaultState().with(SnowyDirtBlock.SNOWY, false), 4, 0, 5, start);
        structure.setBlockState(world, Blocks.GRASS_BLOCK.getDefaultState().with(SnowyDirtBlock.SNOWY, false), 4, 0, 33, start);
        structure.setBlockState(world, Blocks.GRASS_BLOCK.getDefaultState().with(SnowyDirtBlock.SNOWY, false), 4, 1, 32, start);
        structure.setBlockState(world, Blocks.GRASS_BLOCK.getDefaultState().with(SnowyDirtBlock.SNOWY, false), 4, 2, 8, start);
        structure.setBlockState(world, Blocks.GRASS_BLOCK.getDefaultState().with(SnowyDirtBlock.SNOWY, false), 4, 2, 31, start);
        structure.setBlockState(world, Blocks.GRASS_BLOCK.getDefaultState().with(SnowyDirtBlock.SNOWY, false), 4, 3, 30, start);
        structure.setBlockState(world, Blocks.GRASS.getDefaultState(), 4, 5, 18, start);
        structure.setBlockState(world, Blocks.GRASS.getDefaultState(), 5, 5, 11, start);
        structure.setBlockState(world, Blocks.GRASS_BLOCK.getDefaultState().with(SnowyDirtBlock.SNOWY, false), 6, 1, 35, start);
        structure.setBlockState(world, Blocks.GRASS_BLOCK.getDefaultState().with(SnowyDirtBlock.SNOWY, false), 6, 2, 6, start);
        structure.setBlockState(world, Blocks.GRASS_BLOCK.getDefaultState().with(SnowyDirtBlock.SNOWY, false), 6, 3, 7, start);
        structure.setBlockState(world, Blocks.GRASS.getDefaultState(), 6, 5, 9, start);
        structure.setBlockState(world, Blocks.GRASS.getDefaultState(), 6, 6, 26, start);
        structure.setBlockState(world, Blocks.GRASS_BLOCK.getDefaultState().with(SnowyDirtBlock.SNOWY, false), 7, 0, 3, start);
        structure.setBlockState(world, Blocks.GRASS_BLOCK.getDefaultState().with(SnowyDirtBlock.SNOWY, false), 7, 1, 4, start);
        structure.setBlockState(world, Blocks.GRASS_BLOCK.getDefaultState().with(SnowyDirtBlock.SNOWY, false), 7, 2, 5, start);
        structure.setBlockState(world, Blocks.GRASS_BLOCK.getDefaultState().with(SnowyDirtBlock.SNOWY, false), 7, 3, 6, start);
        structure.setBlockState(world, Blocks.GRASS.getDefaultState(), 7, 5, 32, start);
        structure.setBlockState(world, Blocks.GRASS.getDefaultState(), 7, 6, 13, start);
        structure.setBlockState(world, Blocks.GRASS_BLOCK.getDefaultState().with(SnowyDirtBlock.SNOWY, false), 8, 0, 37, start);
        structure.setBlockState(world, Blocks.GRASS_BLOCK.getDefaultState().with(SnowyDirtBlock.SNOWY, false), 8, 2, 36, start);
        structure.setBlockState(world, Blocks.GRASS.getDefaultState(), 8, 6, 17, start);
        structure.setBlockState(world, Blocks.GRASS.getDefaultState(), 8, 6, 23, start);
        structure.setBlockState(world, Blocks.GRASS.getDefaultState(), 8, 6, 28, start);
        structure.setBlockState(world, Blocks.GRASS.getDefaultState(), 8, 6, 30, start);
        structure.setBlockState(world, Blocks.GRASS_BLOCK.getDefaultState().with(SnowyDirtBlock.SNOWY, false), 9, 1, 37, start);
        structure.setBlockState(world, Blocks.GRASS.getDefaultState(), 9, 5, 6, start);
        structure.setBlockState(world, Blocks.GRASS.getDefaultState(), 9, 6, 9, start);
        structure.setBlockState(world, Blocks.GRASS.getDefaultState(), 9, 6, 13, start);
        structure.setBlockState(world, Blocks.GRASS.getDefaultState(), 9, 6, 21, start);
        structure.setBlockState(world, Blocks.GRASS_BLOCK.getDefaultState().with(SnowyDirtBlock.SNOWY, false), 10, 0, 38, start);
        structure.setBlockState(world, Blocks.GRASS_BLOCK.getDefaultState().with(SnowyDirtBlock.SNOWY, false), 10, 2, 37, start);
        structure.setBlockState(world, Blocks.POPPY.getDefaultState(), 10, 5, 34, start);
        structure.setBlockState(world, Blocks.DANDELION.getDefaultState(), 10, 6, 16, start);
        structure.setBlockState(world, Blocks.GRASS.getDefaultState(), 10, 6, 20, start);
        structure.setBlockState(world, Blocks.GRASS.getDefaultState(), 11, 6, 18, start);
        structure.setBlockState(world, Blocks.GRASS.getDefaultState(), 12, 5, 5, start);
        structure.setBlockState(world, Blocks.GRASS.getDefaultState(), 12, 6, 10, start);
        structure.setBlockState(world, Blocks.COBBLESTONE.getDefaultState(), 12, 7, 23, start);
        structure.setBlockState(world, Blocks.GRASS.getDefaultState(), 13, 5, 37, start);
        structure.setBlockState(world, Blocks.GRASS.getDefaultState(), 13, 6, 18, start);
        structure.setBlockState(world, Blocks.GRASS.getDefaultState(), 13, 6, 34, start);
        structure.setBlockState(world, Blocks.COBBLESTONE_SLAB.getDefaultState().with(SlabBlock.TYPE, SlabType.DOUBLE).with(SlabBlock.WATERLOGGED, false), 13, 7, 25, start);
        structure.setBlockState(world, Blocks.SPRUCE_TRAPDOOR.getDefaultState().with(HorizontalBlock.HORIZONTAL_FACING, Direction.WEST).with(TrapDoorBlock.HALF, Half.TOP).with(TrapDoorBlock.WATERLOGGED, false).with(TrapDoorBlock.POWERED, false).with(TrapDoorBlock.OPEN, true), 13, 8, 26, start);
        structure.setBlockState(world, Blocks.SPRUCE_TRAPDOOR.getDefaultState().with(HorizontalBlock.HORIZONTAL_FACING, Direction.WEST).with(TrapDoorBlock.HALF, Half.TOP).with(TrapDoorBlock.WATERLOGGED, false).with(TrapDoorBlock.POWERED, false).with(TrapDoorBlock.OPEN, true), 13, 9, 19, start);
        structure.setBlockState(world, Blocks.SPRUCE_TRAPDOOR.getDefaultState().with(HorizontalBlock.HORIZONTAL_FACING, Direction.EAST).with(TrapDoorBlock.HALF, Half.BOTTOM).with(TrapDoorBlock.WATERLOGGED, false).with(TrapDoorBlock.POWERED, false).with(TrapDoorBlock.OPEN, false), 13, 10, 21, start);
        structure.setBlockState(world, Blocks.SPRUCE_FENCE.getDefaultState().with(FourWayBlock.WATERLOGGED, false).with(FourWayBlock.NORTH, false).with(FourWayBlock.SOUTH, false).with(FourWayBlock.EAST, false).with(FourWayBlock.WEST, false), 13, 10, 23, start);
        structure.setBlockState(world, Blocks.GRASS.getDefaultState(), 14, 6, 12, start);
        structure.setBlockState(world, Blocks.DIRT.getDefaultState(), 14, 6, 19, start);
        structure.setBlockState(world, Blocks.COBBLESTONE_SLAB.getDefaultState().with(SlabBlock.TYPE, SlabType.DOUBLE).with(SlabBlock.WATERLOGGED, false), 14, 6, 28, start);
        structure.setBlockState(world, Blocks.COBBLESTONE.getDefaultState(), 14, 6, 29, start);
        structure.setBlockState(world, Blocks.AIR.getDefaultState(), 14, 6, 32, start);
        structure.setBlockState(world, Blocks.GRASS.getDefaultState(), 14, 6, 33, start);
        structure.setBlockState(world, Blocks.COBBLESTONE_SLAB.getDefaultState().with(SlabBlock.TYPE, SlabType.BOTTOM).with(SlabBlock.WATERLOGGED, false), 14, 7, 21, start);
        structure.setBlockState(world, Blocks.COBBLESTONE_SLAB.getDefaultState().with(SlabBlock.TYPE, SlabType.BOTTOM).with(SlabBlock.WATERLOGGED, false), 14, 7, 23, start);
        structure.setBlockState(world, Blocks.SPRUCE_TRAPDOOR.getDefaultState().with(HorizontalBlock.HORIZONTAL_FACING, Direction.NORTH).with(TrapDoorBlock.HALF, Half.TOP).with(TrapDoorBlock.WATERLOGGED, false).with(TrapDoorBlock.POWERED, false).with(TrapDoorBlock.OPEN, true), 14, 8, 24, start);
        structure.setBlockState(world, Blocks.SPRUCE_TRAPDOOR.getDefaultState().with(HorizontalBlock.HORIZONTAL_FACING, Direction.NORTH).with(TrapDoorBlock.HALF, Half.TOP).with(TrapDoorBlock.WATERLOGGED, false).with(TrapDoorBlock.POWERED, false).with(TrapDoorBlock.OPEN, true), 14, 9, 18, start);
        structure.setBlockState(world, Blocks.STRIPPED_SPRUCE_LOG.getDefaultState(), 14, 9, 19, start);
        structure.setBlockState(world, Blocks.SPRUCE_SLAB.getDefaultState().with(SlabBlock.TYPE, SlabType.BOTTOM).with(SlabBlock.WATERLOGGED, false), 14, 9, 20, start);
        structure.setBlockState(world, Blocks.SPRUCE_SLAB.getDefaultState().with(SlabBlock.TYPE, SlabType.BOTTOM).with(SlabBlock.WATERLOGGED, false), 14, 9, 25, start);
        structure.setBlockState(world, Blocks.STRIPPED_SPRUCE_LOG.getDefaultState(), 14, 9, 26, start);
        structure.setBlockState(world, Blocks.SPRUCE_TRAPDOOR.getDefaultState().with(HorizontalBlock.HORIZONTAL_FACING, Direction.EAST).with(TrapDoorBlock.HALF, Half.BOTTOM).with(TrapDoorBlock.WATERLOGGED, false).with(TrapDoorBlock.POWERED, false).with(TrapDoorBlock.OPEN, false), 14, 9, 27, start);
        structure.setBlockState(world, Blocks.SPRUCE_FENCE.getDefaultState().with(FourWayBlock.WATERLOGGED, false).with(FourWayBlock.NORTH, false).with(FourWayBlock.SOUTH, false).with(FourWayBlock.EAST, false).with(FourWayBlock.WEST, false), 14, 10, 19, start);
        structure.setBlockState(world, Blocks.SPRUCE_FENCE.getDefaultState().with(FourWayBlock.WATERLOGGED, false).with(FourWayBlock.NORTH, false).with(FourWayBlock.SOUTH, false).with(FourWayBlock.EAST, false).with(FourWayBlock.WEST, false), 14, 10, 26, start);
        structure.setBlockState(world, Blocks.DIRT.getDefaultState(), 15, 5, 19, start);
        structure.setBlockState(world, Blocks.GRASS.getDefaultState(), 15, 5, 37, start);
        structure.setBlockState(world, Blocks.GRASS.getDefaultState(), 15, 6, 8, start);
        structure.setBlockState(world, Blocks.COBBLESTONE_SLAB.getDefaultState().with(SlabBlock.TYPE, SlabType.DOUBLE).with(SlabBlock.WATERLOGGED, false), 15, 6, 20, start);
        structure.setBlockState(world, Blocks.COBBLESTONE_SLAB.getDefaultState().with(SlabBlock.TYPE, SlabType.BOTTOM).with(SlabBlock.WATERLOGGED, false), 15, 6, 24, start);
        structure.setBlockState(world, Blocks.COBBLESTONE_SLAB.getDefaultState().with(SlabBlock.TYPE, SlabType.BOTTOM).with(SlabBlock.WATERLOGGED, false), 15, 6, 26, start);
        structure.setBlockState(world, Blocks.COBBLESTONE_SLAB.getDefaultState().with(SlabBlock.TYPE, SlabType.DOUBLE).with(SlabBlock.WATERLOGGED, false), 15, 6, 27, start);
        structure.setBlockState(world, Blocks.COBBLESTONE_SLAB.getDefaultState().with(SlabBlock.TYPE, SlabType.BOTTOM).with(SlabBlock.WATERLOGGED, false), 15, 7, 19, start);
        structure.setBlockState(world, Blocks.CAMPFIRE.getDefaultState().with(CampfireBlock.FACING, Direction.WEST).with(CampfireBlock.LIT, false).with(CampfireBlock.SIGNAL_FIRE, false).with(CampfireBlock.WATERLOGGED, false), 15, 7, 27, start);
        structure.setBlockState(world, Blocks.SPRUCE_TRAPDOOR.getDefaultState().with(HorizontalBlock.HORIZONTAL_FACING, Direction.EAST).with(TrapDoorBlock.HALF, Half.TOP).with(TrapDoorBlock.WATERLOGGED, false).with(TrapDoorBlock.POWERED, false).with(TrapDoorBlock.OPEN, true), 15, 8, 25, start);
        structure.setBlockState(world, Blocks.SPRUCE_TRAPDOOR.getDefaultState().with(HorizontalBlock.HORIZONTAL_FACING, Direction.WEST).with(TrapDoorBlock.HALF, Half.TOP).with(TrapDoorBlock.WATERLOGGED, false).with(TrapDoorBlock.POWERED, false).with(TrapDoorBlock.OPEN, true), 15, 8, 29, start);
        structure.setBlockState(world, Blocks.SPRUCE_TRAPDOOR.getDefaultState().with(HorizontalBlock.HORIZONTAL_FACING, Direction.WEST).with(TrapDoorBlock.HALF, Half.TOP).with(TrapDoorBlock.WATERLOGGED, false).with(TrapDoorBlock.POWERED, false).with(TrapDoorBlock.OPEN, true), 15, 9, 17, start);
        structure.setBlockState(world, Blocks.SPRUCE_TRAPDOOR.getDefaultState().with(HorizontalBlock.HORIZONTAL_FACING, Direction.SOUTH).with(TrapDoorBlock.HALF, Half.TOP).with(TrapDoorBlock.WATERLOGGED, false).with(TrapDoorBlock.POWERED, false).with(TrapDoorBlock.OPEN, true), 15, 9, 19, start);
        structure.setBlockState(world, Blocks.SPRUCE_FENCE.getDefaultState().with(FourWayBlock.WATERLOGGED, false).with(FourWayBlock.NORTH, false).with(FourWayBlock.SOUTH, false).with(FourWayBlock.EAST, false).with(FourWayBlock.WEST, false), 15, 9, 28, start);
        structure.setBlockState(world, Blocks.SPRUCE_SLAB.getDefaultState().with(SlabBlock.TYPE, SlabType.BOTTOM).with(SlabBlock.WATERLOGGED, false), 15, 10, 18, start);
        structure.setBlockState(world, Blocks.PODZOL.getDefaultState().with(SnowyDirtBlock.SNOWY, false), 16, 5, 22, start);
        structure.setBlockState(world, Blocks.GRASS_BLOCK.getDefaultState().with(SnowyDirtBlock.SNOWY, false), 16, 5, 24, start);
        structure.setBlockState(world, Blocks.DIRT.getDefaultState(), 16, 5, 26, start);
        structure.setBlockState(world, Blocks.GRASS.getDefaultState(), 16, 5, 36, start);
        structure.setBlockState(world, Blocks.GRASS.getDefaultState(), 16, 6, 13, start);
        structure.setBlockState(world, Blocks.SPRUCE_STAIRS.getDefaultState().with(StairsBlock.FACING, Direction.SOUTH).with(StairsBlock.WATERLOGGED, false).with(StairsBlock.SHAPE, StairsShape.STRAIGHT).with(StairsBlock.HALF, Half.BOTTOM), 16, 6, 18, start);
        structure.setBlockState(world, Blocks.SPRUCE_STAIRS.getDefaultState().with(StairsBlock.FACING, Direction.NORTH).with(StairsBlock.WATERLOGGED, false).with(StairsBlock.SHAPE, StairsShape.STRAIGHT).with(StairsBlock.HALF, Half.TOP), 16, 6, 19, start);
        structure.setBlockState(world, Blocks.SPRUCE_STAIRS.getDefaultState().with(StairsBlock.FACING, Direction.SOUTH).with(StairsBlock.WATERLOGGED, false).with(StairsBlock.SHAPE, StairsShape.STRAIGHT).with(StairsBlock.HALF, Half.TOP), 16, 6, 25, start);
        structure.setBlockState(world, Blocks.SPRUCE_STAIRS.getDefaultState().with(StairsBlock.FACING, Direction.NORTH).with(StairsBlock.WATERLOGGED, false).with(StairsBlock.SHAPE, StairsShape.STRAIGHT).with(StairsBlock.HALF, Half.BOTTOM), 16, 6, 26, start);
        structure.setBlockState(world, Blocks.ROSE_BUSH.getDefaultState(), 16, 6, 27, start);
        structure.setBlockState(world, Blocks.COBBLESTONE_SLAB.getDefaultState().with(SlabBlock.TYPE, SlabType.BOTTOM).with(SlabBlock.WATERLOGGED, false), 16, 6, 28, start);
        structure.setBlockState(world, Blocks.COBBLESTONE_SLAB.getDefaultState().with(SlabBlock.TYPE, SlabType.DOUBLE).with(SlabBlock.WATERLOGGED, false), 16, 6, 30, start);
        structure.setBlockState(world, Blocks.COBBLESTONE_SLAB.getDefaultState().with(SlabBlock.TYPE, SlabType.BOTTOM).with(SlabBlock.WATERLOGGED, false), 16, 7, 18, start);
        structure.setBlockState(world, Blocks.SPRUCE_STAIRS.getDefaultState().with(StairsBlock.FACING, Direction.SOUTH).with(StairsBlock.WATERLOGGED, false).with(StairsBlock.SHAPE, StairsShape.STRAIGHT).with(StairsBlock.HALF, Half.BOTTOM), 16, 7, 19, start);
        structure.setBlockState(world, Blocks.SPRUCE_STAIRS.getDefaultState().with(StairsBlock.FACING, Direction.NORTH).with(StairsBlock.WATERLOGGED, false).with(StairsBlock.SHAPE, StairsShape.STRAIGHT).with(StairsBlock.HALF, Half.TOP), 16, 7, 20, start);
        structure.setBlockState(world, Blocks.SPRUCE_STAIRS.getDefaultState().with(StairsBlock.FACING, Direction.SOUTH).with(StairsBlock.WATERLOGGED, false).with(StairsBlock.SHAPE, StairsShape.STRAIGHT).with(StairsBlock.HALF, Half.TOP), 16, 7, 24, start);
        structure.setBlockState(world, Blocks.SPRUCE_STAIRS.getDefaultState().with(StairsBlock.FACING, Direction.NORTH).with(StairsBlock.WATERLOGGED, false).with(StairsBlock.SHAPE, StairsShape.STRAIGHT).with(StairsBlock.HALF, Half.BOTTOM), 16, 7, 25, start);
        structure.setBlockState(world, Blocks.ROSE_BUSH.getDefaultState(), 16, 7, 27, start);
        structure.setBlockState(world, Blocks.SPRUCE_STAIRS.getDefaultState().with(StairsBlock.FACING, Direction.SOUTH).with(StairsBlock.WATERLOGGED, false).with(StairsBlock.SHAPE, StairsShape.STRAIGHT).with(StairsBlock.HALF, Half.BOTTOM), 16, 8, 20, start);
        structure.setBlockState(world, Blocks.SPRUCE_STAIRS.getDefaultState().with(StairsBlock.FACING, Direction.NORTH).with(StairsBlock.WATERLOGGED, false).with(StairsBlock.SHAPE, StairsShape.STRAIGHT).with(StairsBlock.HALF, Half.TOP), 16, 8, 21, start);
        structure.setBlockState(world, Blocks.SPRUCE_STAIRS.getDefaultState().with(StairsBlock.FACING, Direction.SOUTH).with(StairsBlock.WATERLOGGED, false).with(StairsBlock.SHAPE, StairsShape.STRAIGHT).with(StairsBlock.HALF, Half.TOP), 16, 8, 23, start);
        structure.setBlockState(world, Blocks.SPRUCE_STAIRS.getDefaultState().with(StairsBlock.FACING, Direction.NORTH).with(StairsBlock.WATERLOGGED, false).with(StairsBlock.SHAPE, StairsShape.STRAIGHT).with(StairsBlock.HALF, Half.BOTTOM), 16, 8, 24, start);
        structure.setBlockState(world, Blocks.SPRUCE_TRAPDOOR.getDefaultState().with(HorizontalBlock.HORIZONTAL_FACING, Direction.NORTH).with(TrapDoorBlock.HALF, Half.TOP).with(TrapDoorBlock.WATERLOGGED, false).with(TrapDoorBlock.POWERED, false).with(TrapDoorBlock.OPEN, true), 16, 8, 28, start);
        structure.setBlockState(world, Blocks.SPRUCE_TRAPDOOR.getDefaultState().with(HorizontalBlock.HORIZONTAL_FACING, Direction.SOUTH).with(TrapDoorBlock.HALF, Half.TOP).with(TrapDoorBlock.WATERLOGGED, false).with(TrapDoorBlock.POWERED, false).with(TrapDoorBlock.OPEN, true), 16, 8, 30, start);
        structure.setBlockState(world, Blocks.SPRUCE_TRAPDOOR.getDefaultState().with(HorizontalBlock.HORIZONTAL_FACING, Direction.NORTH).with(TrapDoorBlock.HALF, Half.TOP).with(TrapDoorBlock.WATERLOGGED, false).with(TrapDoorBlock.POWERED, false).with(TrapDoorBlock.OPEN, true), 16, 9, 16, start);
        structure.setBlockState(world, Blocks.SPRUCE_TRAPDOOR.getDefaultState().with(HorizontalBlock.HORIZONTAL_FACING, Direction.EAST).with(TrapDoorBlock.HALF, Half.TOP).with(TrapDoorBlock.WATERLOGGED, false).with(TrapDoorBlock.POWERED, false).with(TrapDoorBlock.OPEN, true), 16, 9, 18, start);
        structure.setBlockState(world, Blocks.SPRUCE_STAIRS.getDefaultState().with(StairsBlock.FACING, Direction.SOUTH).with(StairsBlock.WATERLOGGED, false).with(StairsBlock.SHAPE, StairsShape.STRAIGHT).with(StairsBlock.HALF, Half.BOTTOM), 16, 9, 21, start);
        structure.setBlockState(world, Blocks.OAK_LOG.getDefaultState(), 16, 9, 22, start);
        structure.setBlockState(world, Blocks.SPRUCE_STAIRS.getDefaultState().with(StairsBlock.FACING, Direction.NORTH).with(StairsBlock.WATERLOGGED, false).with(StairsBlock.SHAPE, StairsShape.STRAIGHT).with(StairsBlock.HALF, Half.BOTTOM), 16, 9, 23, start);
        structure.setBlockState(world, Blocks.STRIPPED_SPRUCE_LOG.getDefaultState(), 16, 10, 17, start);
        structure.setBlockState(world, Blocks.SPRUCE_SLAB.getDefaultState().with(SlabBlock.TYPE, SlabType.BOTTOM).with(SlabBlock.WATERLOGGED, false), 16, 10, 22, start);
        structure.setBlockState(world, Blocks.SPRUCE_SLAB.getDefaultState().with(SlabBlock.TYPE, SlabType.BOTTOM).with(SlabBlock.WATERLOGGED, false), 16, 10, 29, start);
        structure.setBlockState(world, Blocks.SPRUCE_FENCE.getDefaultState().with(FourWayBlock.WATERLOGGED, false).with(FourWayBlock.NORTH, false).with(FourWayBlock.SOUTH, false).with(FourWayBlock.EAST, false).with(FourWayBlock.WEST, false), 16, 11, 17, start);
        structure.setBlockState(world, Blocks.PODZOL.getDefaultState().with(SnowyDirtBlock.SNOWY, false), 17, 5, 20, start);
        structure.setBlockState(world, Blocks.PODZOL.getDefaultState().with(SnowyDirtBlock.SNOWY, false), 17, 5, 24, start);
        structure.setBlockState(world, Blocks.AIR.getDefaultState(), 17, 6, 13, start);
        structure.setBlockState(world, Blocks.COBBLESTONE.getDefaultState(), 17, 6, 16, start);
        structure.setBlockState(world, Blocks.COBBLESTONE_SLAB.getDefaultState().with(SlabBlock.TYPE, SlabType.DOUBLE).with(SlabBlock.WATERLOGGED, false), 17, 6, 18, start);
        structure.setBlockState(world, Blocks.COBBLESTONE_SLAB.getDefaultState().with(SlabBlock.TYPE, SlabType.DOUBLE).with(SlabBlock.WATERLOGGED, false), 17, 6, 29, start);
        structure.setBlockState(world, Blocks.COBBLESTONE_SLAB.getDefaultState().with(SlabBlock.TYPE, SlabType.BOTTOM).with(SlabBlock.WATERLOGGED, false), 17, 6, 31, start);
        structure.setBlockState(world, Blocks.COBBLESTONE_SLAB.getDefaultState().with(SlabBlock.TYPE, SlabType.DOUBLE).with(SlabBlock.WATERLOGGED, false), 17, 7, 16, start);
        structure.setBlockState(world, Blocks.CAMPFIRE.getDefaultState().with(CampfireBlock.FACING, Direction.WEST).with(CampfireBlock.LIT, false).with(CampfireBlock.SIGNAL_FIRE, false).with(CampfireBlock.WATERLOGGED, false), 17, 7, 18, start);
        structure.setBlockState(world, Blocks.GRAY_CARPET.getDefaultState(), 17, 7, 25, start);
        structure.setBlockState(world, Blocks.CAMPFIRE.getDefaultState().with(CampfireBlock.FACING, Direction.WEST).with(CampfireBlock.LIT, false).with(CampfireBlock.SIGNAL_FIRE, false).with(CampfireBlock.WATERLOGGED, false), 17, 7, 29, start);
        structure.setBlockState(world, Blocks.RED_CARPET.getDefaultState(), 17, 8, 24, start);
        structure.setBlockState(world, Blocks.SPRUCE_TRAPDOOR.getDefaultState().with(HorizontalBlock.HORIZONTAL_FACING, Direction.EAST).with(TrapDoorBlock.HALF, Half.TOP).with(TrapDoorBlock.WATERLOGGED, false).with(TrapDoorBlock.POWERED, false).with(TrapDoorBlock.OPEN, true), 17, 8, 29, start);
        structure.setBlockState(world, Blocks.SPRUCE_TRAPDOOR.getDefaultState().with(HorizontalBlock.HORIZONTAL_FACING, Direction.WEST).with(TrapDoorBlock.HALF, Half.BOTTOM).with(TrapDoorBlock.WATERLOGGED, false).with(TrapDoorBlock.POWERED, false).with(TrapDoorBlock.OPEN, false), 17, 10, 22, start);
        structure.setBlockState(world, Blocks.SPRUCE_FENCE.getDefaultState().with(FourWayBlock.WATERLOGGED, false).with(FourWayBlock.NORTH, false).with(FourWayBlock.SOUTH, false).with(FourWayBlock.EAST, false).with(FourWayBlock.WEST, false), 17, 10, 30, start);
        structure.setBlockState(world, Blocks.DIRT.getDefaultState(), 18, 4, 35, start);
        structure.setBlockState(world, Blocks.GRASS_BLOCK.getDefaultState().with(SnowyDirtBlock.SNOWY, false), 18, 5, 15, start);
        structure.setBlockState(world, Blocks.DIRT.getDefaultState(), 18, 5, 30, start);
        structure.setBlockState(world, Blocks.GRASS.getDefaultState(), 18, 6, 12, start);
        structure.setBlockState(world, Blocks.COBBLESTONE_SLAB.getDefaultState().with(SlabBlock.TYPE, SlabType.BOTTOM).with(SlabBlock.WATERLOGGED, false), 18, 6, 18, start);
        structure.setBlockState(world, Blocks.STONE_BUTTON.getDefaultState().with(HorizontalBlock.HORIZONTAL_FACING, Direction.WEST).with(HorizontalFaceBlock.FACE, AttachFace.FLOOR).with(AbstractButtonBlock.POWERED, false), 18, 6, 27, start);
        structure.setBlockState(world, Blocks.SPRUCE_LEAVES.getDefaultState().with(LeavesBlock.PERSISTENT, true).with(LeavesBlock.DISTANCE, 1), 18, 6, 29, start);
        structure.setBlockState(world, Blocks.GRASS.getDefaultState(), 18, 6, 32, start);
        structure.setBlockState(world, Blocks.RED_CARPET.getDefaultState(), 18, 7, 25, start);
        structure.setBlockState(world, Blocks.SPRUCE_SLAB.getDefaultState().with(SlabBlock.TYPE, SlabType.BOTTOM).with(SlabBlock.WATERLOGGED, false), 18, 7, 30, start);
        structure.setBlockState(world, Blocks.SPRUCE_TRAPDOOR.getDefaultState().with(HorizontalBlock.HORIZONTAL_FACING, Direction.WEST).with(TrapDoorBlock.HALF, Half.TOP).with(TrapDoorBlock.WATERLOGGED, false).with(TrapDoorBlock.POWERED, false).with(TrapDoorBlock.OPEN, true), 18, 8, 16, start);
        structure.setBlockState(world, Blocks.SPRUCE_TRAPDOOR.getDefaultState().with(HorizontalBlock.HORIZONTAL_FACING, Direction.EAST).with(TrapDoorBlock.HALF, Half.BOTTOM).with(TrapDoorBlock.WATERLOGGED, false).with(TrapDoorBlock.POWERED, false).with(TrapDoorBlock.OPEN, false), 18, 9, 17, start);
        structure.setBlockState(world, Blocks.GRAY_CARPET.getDefaultState(), 18, 9, 21, start);
        structure.setBlockState(world, Blocks.SPRUCE_SLAB.getDefaultState().with(SlabBlock.TYPE, SlabType.BOTTOM).with(SlabBlock.WATERLOGGED, false), 18, 10, 22, start);
        structure.setBlockState(world, Blocks.GRASS_BLOCK.getDefaultState().with(SnowyDirtBlock.SNOWY, false), 19, 5, 18, start);
        structure.setBlockState(world, Blocks.GRASS.getDefaultState(), 19, 5, 37, start);
        structure.setBlockState(world, Blocks.GRASS.getDefaultState(), 19, 6, 10, start);
        structure.setBlockState(world, Blocks.COBBLESTONE_SLAB.getDefaultState().with(SlabBlock.TYPE, SlabType.DOUBLE).with(SlabBlock.WATERLOGGED, false), 19, 6, 17, start);
        structure.setBlockState(world, Blocks.AIR.getDefaultState(), 19, 6, 22, start);
        structure.setBlockState(world, Blocks.FERN.getDefaultState(), 19, 6, 26, start);
        structure.setBlockState(world, Blocks.SPRUCE_LEAVES.getDefaultState().with(LeavesBlock.PERSISTENT, true).with(LeavesBlock.DISTANCE, 3), 19, 6, 28, start);
        structure.setBlockState(world, Blocks.SPRUCE_LEAVES.getDefaultState().with(LeavesBlock.PERSISTENT, true).with(LeavesBlock.DISTANCE, 2), 19, 6, 29, start);
        structure.setBlockState(world, Blocks.SPRUCE_FENCE.getDefaultState().with(FourWayBlock.WATERLOGGED, false).with(FourWayBlock.NORTH, false).with(FourWayBlock.SOUTH, false).with(FourWayBlock.EAST, false).with(FourWayBlock.WEST, true), 19, 6, 30, start);
        structure.setBlockState(world, Blocks.CAMPFIRE.getDefaultState().with(CampfireBlock.FACING, Direction.WEST).with(CampfireBlock.LIT, false).with(CampfireBlock.SIGNAL_FIRE, false).with(CampfireBlock.WATERLOGGED, false), 19, 7, 17, start);
        structure.setBlockState(world, Blocks.SPRUCE_TRAPDOOR.getDefaultState().with(HorizontalBlock.HORIZONTAL_FACING, Direction.NORTH).with(TrapDoorBlock.HALF, Half.TOP).with(TrapDoorBlock.WATERLOGGED, false).with(TrapDoorBlock.POWERED, false).with(TrapDoorBlock.OPEN, true), 19, 8, 15, start);
        structure.setBlockState(world, Blocks.SPRUCE_TRAPDOOR.getDefaultState().with(HorizontalBlock.HORIZONTAL_FACING, Direction.SOUTH).with(TrapDoorBlock.HALF, Half.TOP).with(TrapDoorBlock.WATERLOGGED, false).with(TrapDoorBlock.POWERED, false).with(TrapDoorBlock.OPEN, true), 19, 8, 17, start);
        structure.setBlockState(world, Blocks.RED_CARPET.getDefaultState(), 19, 9, 21, start);
        structure.setBlockState(world, Blocks.SPRUCE_FENCE.getDefaultState().with(FourWayBlock.WATERLOGGED, false).with(FourWayBlock.NORTH, false).with(FourWayBlock.SOUTH, false).with(FourWayBlock.EAST, false).with(FourWayBlock.WEST, false), 19, 10, 16, start);
        structure.setBlockState(world, Blocks.SPRUCE_TRAPDOOR.getDefaultState().with(HorizontalBlock.HORIZONTAL_FACING, Direction.WEST).with(TrapDoorBlock.HALF, Half.BOTTOM).with(TrapDoorBlock.WATERLOGGED, false).with(TrapDoorBlock.POWERED, false).with(TrapDoorBlock.OPEN, false), 19, 10, 22, start);
        structure.setBlockState(world, Blocks.DIRT.getDefaultState(), 20, 5, 17, start);
        structure.setBlockState(world, Blocks.STONE_BUTTON.getDefaultState().with(HorizontalBlock.HORIZONTAL_FACING, Direction.WEST).with(HorizontalFaceBlock.FACE, AttachFace.FLOOR).with(AbstractButtonBlock.POWERED, false), 20, 6, 23, start);
        structure.setBlockState(world, Blocks.STONE_BUTTON.getDefaultState().with(HorizontalBlock.HORIZONTAL_FACING, Direction.WEST).with(HorizontalFaceBlock.FACE, AttachFace.FLOOR).with(AbstractButtonBlock.POWERED, false), 20, 6, 26, start);
        structure.setBlockState(world, Blocks.SWEET_BERRY_BUSH.getDefaultState().with(SweetBerryBushBlock.AGE, 3), 20, 6, 27, start);
        structure.setBlockState(world, Blocks.SPRUCE_FENCE.getDefaultState().with(FourWayBlock.WATERLOGGED, false).with(FourWayBlock.NORTH, false).with(FourWayBlock.SOUTH, false).with(FourWayBlock.EAST, false).with(FourWayBlock.WEST, false), 20, 6, 29, start);
        structure.setBlockState(world, Blocks.GRAY_CARPET.getDefaultState(), 20, 7, 25, start);
        structure.setBlockState(world, Blocks.SPRUCE_SLAB.getDefaultState().with(SlabBlock.TYPE, SlabType.BOTTOM).with(SlabBlock.WATERLOGGED, false), 20, 9, 16, start);
        structure.setBlockState(world, Blocks.SPRUCE_SLAB.getDefaultState().with(SlabBlock.TYPE, SlabType.BOTTOM).with(SlabBlock.WATERLOGGED, false), 20, 10, 22, start);
        structure.setBlockState(world, Blocks.DIRT.getDefaultState(), 21, 5, 16, start);
        structure.setBlockState(world, Blocks.COBBLESTONE_SLAB.getDefaultState().with(SlabBlock.TYPE, SlabType.DOUBLE).with(SlabBlock.WATERLOGGED, false), 21, 6, 15, start);
        structure.setBlockState(world, Blocks.COBBLESTONE_SLAB.getDefaultState().with(SlabBlock.TYPE, SlabType.DOUBLE).with(SlabBlock.WATERLOGGED, false), 21, 6, 17, start);
        structure.setBlockState(world, Blocks.COBBLESTONE_SLAB.getDefaultState().with(SlabBlock.TYPE, SlabType.BOTTOM).with(SlabBlock.WATERLOGGED, false), 21, 6, 18, start);
        structure.setBlockState(world, Blocks.FERN.getDefaultState(), 21, 6, 20, start);
        structure.setBlockState(world, Blocks.SPRUCE_FENCE.getDefaultState().with(FourWayBlock.WATERLOGGED, false).with(FourWayBlock.NORTH, false).with(FourWayBlock.SOUTH, false).with(FourWayBlock.EAST, true).with(FourWayBlock.WEST, false), 21, 6, 28, start);
        structure.setBlockState(world, Blocks.AIR.getDefaultState(), 21, 6, 31, start);
        structure.setBlockState(world, Blocks.GRASS.getDefaultState(), 21, 6, 34, start);
        structure.setBlockState(world, Blocks.RED_CARPET.getDefaultState(), 21, 7, 19, start);
        structure.setBlockState(world, Blocks.STRIPPED_SPRUCE_LOG.getDefaultState(), 21, 8, 16, start);
        structure.setBlockState(world, Blocks.SPRUCE_FENCE.getDefaultState().with(FourWayBlock.WATERLOGGED, false).with(FourWayBlock.NORTH, false).with(FourWayBlock.SOUTH, false).with(FourWayBlock.EAST, false).with(FourWayBlock.WEST, false), 21, 9, 16, start);
        structure.setBlockState(world, Blocks.RED_CARPET.getDefaultState(), 21, 9, 21, start);
        structure.setBlockState(world, Blocks.SPRUCE_TRAPDOOR.getDefaultState().with(HorizontalBlock.HORIZONTAL_FACING, Direction.WEST).with(TrapDoorBlock.HALF, Half.BOTTOM).with(TrapDoorBlock.WATERLOGGED, false).with(TrapDoorBlock.POWERED, false).with(TrapDoorBlock.OPEN, false), 21, 10, 22, start);
        structure.setBlockState(world, Blocks.DIRT.getDefaultState(), 22, 5, 18, start);
        structure.setBlockState(world, Blocks.PODZOL.getDefaultState().with(SnowyDirtBlock.SNOWY, false), 22, 5, 21, start);
        structure.setBlockState(world, Blocks.DIRT.getDefaultState(), 22, 5, 26, start);
        structure.setBlockState(world, Blocks.GRASS.getDefaultState(), 22, 6, 9, start);
        structure.setBlockState(world, Blocks.GRASS.getDefaultState(), 22, 6, 11, start);
        structure.setBlockState(world, Blocks.COBBLESTONE_SLAB.getDefaultState().with(SlabBlock.TYPE, SlabType.BOTTOM).with(SlabBlock.WATERLOGGED, false), 22, 6, 15, start);
        structure.setBlockState(world, Blocks.SPRUCE_STAIRS.getDefaultState().with(StairsBlock.FACING, Direction.SOUTH).with(StairsBlock.WATERLOGGED, false).with(StairsBlock.SHAPE, StairsShape.STRAIGHT).with(StairsBlock.HALF, Half.BOTTOM), 22, 6, 18, start);
        structure.setBlockState(world, Blocks.SPRUCE_STAIRS.getDefaultState().with(StairsBlock.FACING, Direction.NORTH).with(StairsBlock.WATERLOGGED, false).with(StairsBlock.SHAPE, StairsShape.STRAIGHT).with(StairsBlock.HALF, Half.TOP), 22, 6, 19, start);
        structure.setBlockState(world, Blocks.ROSE_BUSH.getDefaultState(), 22, 6, 21, start);
        structure.setBlockState(world, Blocks.SPRUCE_STAIRS.getDefaultState().with(StairsBlock.FACING, Direction.SOUTH).with(StairsBlock.WATERLOGGED, false).with(StairsBlock.SHAPE, StairsShape.STRAIGHT).with(StairsBlock.HALF, Half.TOP), 22, 6, 25, start);
        structure.setBlockState(world, Blocks.SPRUCE_STAIRS.getDefaultState().with(StairsBlock.FACING, Direction.NORTH).with(StairsBlock.WATERLOGGED, false).with(StairsBlock.SHAPE, StairsShape.STRAIGHT).with(StairsBlock.HALF, Half.BOTTOM), 22, 6, 26, start);
        structure.setBlockState(world, Blocks.ROSE_BUSH.getDefaultState(), 22, 6, 27, start);
        structure.setBlockState(world, Blocks.SPRUCE_FENCE.getDefaultState().with(FourWayBlock.WATERLOGGED, false).with(FourWayBlock.NORTH, false).with(FourWayBlock.SOUTH, false).with(FourWayBlock.EAST, true).with(FourWayBlock.WEST, true), 22, 6, 28, start);
        structure.setBlockState(world, Blocks.GRASS.getDefaultState(), 22, 6, 29, start);
        structure.setBlockState(world, Blocks.SPRUCE_STAIRS.getDefaultState().with(StairsBlock.FACING, Direction.SOUTH).with(StairsBlock.WATERLOGGED, false).with(StairsBlock.SHAPE, StairsShape.STRAIGHT).with(StairsBlock.HALF, Half.BOTTOM), 22, 7, 19, start);
        structure.setBlockState(world, Blocks.SPRUCE_STAIRS.getDefaultState().with(StairsBlock.FACING, Direction.NORTH).with(StairsBlock.WATERLOGGED, false).with(StairsBlock.SHAPE, StairsShape.STRAIGHT).with(StairsBlock.HALF, Half.TOP), 22, 7, 20, start);
        structure.setBlockState(world, Blocks.ROSE_BUSH.getDefaultState(), 22, 7, 21, start);
        structure.setBlockState(world, Blocks.SPRUCE_STAIRS.getDefaultState().with(StairsBlock.FACING, Direction.SOUTH).with(StairsBlock.WATERLOGGED, false).with(StairsBlock.SHAPE, StairsShape.STRAIGHT).with(StairsBlock.HALF, Half.TOP), 22, 7, 24, start);
        structure.setBlockState(world, Blocks.SPRUCE_STAIRS.getDefaultState().with(StairsBlock.FACING, Direction.NORTH).with(StairsBlock.WATERLOGGED, false).with(StairsBlock.SHAPE, StairsShape.STRAIGHT).with(StairsBlock.HALF, Half.BOTTOM), 22, 7, 25, start);
        structure.setBlockState(world, Blocks.ROSE_BUSH.getDefaultState(), 22, 7, 27, start);
        structure.setBlockState(world, Blocks.SPRUCE_STAIRS.getDefaultState().with(StairsBlock.FACING, Direction.SOUTH).with(StairsBlock.WATERLOGGED, false).with(StairsBlock.SHAPE, StairsShape.STRAIGHT).with(StairsBlock.HALF, Half.BOTTOM), 22, 8, 20, start);
        structure.setBlockState(world, Blocks.SPRUCE_STAIRS.getDefaultState().with(StairsBlock.FACING, Direction.NORTH).with(StairsBlock.WATERLOGGED, false).with(StairsBlock.SHAPE, StairsShape.STRAIGHT).with(StairsBlock.HALF, Half.TOP), 22, 8, 21, start);
        structure.setBlockState(world, Blocks.SPRUCE_STAIRS.getDefaultState().with(StairsBlock.FACING, Direction.SOUTH).with(StairsBlock.WATERLOGGED, false).with(StairsBlock.SHAPE, StairsShape.STRAIGHT).with(StairsBlock.HALF, Half.TOP), 22, 8, 23, start);
        structure.setBlockState(world, Blocks.SPRUCE_STAIRS.getDefaultState().with(StairsBlock.FACING, Direction.NORTH).with(StairsBlock.WATERLOGGED, false).with(StairsBlock.SHAPE, StairsShape.STRAIGHT).with(StairsBlock.HALF, Half.BOTTOM), 22, 8, 24, start);
        structure.setBlockState(world, Blocks.SPRUCE_STAIRS.getDefaultState().with(StairsBlock.FACING, Direction.SOUTH).with(StairsBlock.WATERLOGGED, false).with(StairsBlock.SHAPE, StairsShape.STRAIGHT).with(StairsBlock.HALF, Half.BOTTOM), 22, 9, 21, start);
        structure.setBlockState(world, Blocks.OAK_LOG.getDefaultState(), 22, 9, 22, start);
        structure.setBlockState(world, Blocks.SPRUCE_STAIRS.getDefaultState().with(StairsBlock.FACING, Direction.NORTH).with(StairsBlock.WATERLOGGED, false).with(StairsBlock.SHAPE, StairsShape.STRAIGHT).with(StairsBlock.HALF, Half.BOTTOM), 22, 9, 23, start);
        structure.setBlockState(world, Blocks.SPRUCE_SLAB.getDefaultState().with(SlabBlock.TYPE, SlabType.BOTTOM).with(SlabBlock.WATERLOGGED, false), 22, 10, 22, start);
        structure.setBlockState(world, Blocks.GRASS.getDefaultState(), 23, 5, 5, start);
        structure.setBlockState(world, Blocks.PODZOL.getDefaultState().with(SnowyDirtBlock.SNOWY, false), 23, 5, 14, start);
        structure.setBlockState(world, Blocks.GRASS_BLOCK.getDefaultState().with(SnowyDirtBlock.SNOWY, false), 23, 5, 25, start);
        structure.setBlockState(world, Blocks.DIRT.getDefaultState(), 23, 5, 28, start);
        structure.setBlockState(world, Blocks.GRASS.getDefaultState(), 23, 5, 37, start);
        structure.setBlockState(world, Blocks.BARREL.getDefaultState().with(BarrelBlock.PROPERTY_FACING, Direction.UP).with(BarrelBlock.PROPERTY_OPEN, false), 23, 6, 19, start);
        structure.setBlockState(world, Blocks.CHEST.getDefaultState().with(ChestBlock.FACING, Direction.EAST).with(ChestBlock.WATERLOGGED, false).with(ChestBlock.TYPE, ChestType.SINGLE), 23, 6, 20, start);
        structure.setBlockState(world, Blocks.STONE_BUTTON.getDefaultState().with(HorizontalBlock.HORIZONTAL_FACING, Direction.WEST).with(HorizontalFaceBlock.FACE, AttachFace.FLOOR).with(AbstractButtonBlock.POWERED, false), 23, 6, 23, start);
        structure.setBlockState(world, Blocks.FERN.getDefaultState(), 23, 6, 26, start);
        structure.setBlockState(world, Blocks.SPRUCE_FENCE.getDefaultState().with(FourWayBlock.WATERLOGGED, false).with(FourWayBlock.NORTH, false).with(FourWayBlock.SOUTH, true).with(FourWayBlock.EAST, true).with(FourWayBlock.WEST, false), 23, 6, 27, start);
        structure.setBlockState(world, Blocks.STRIPPED_SPRUCE_LOG.getDefaultState(), 23, 6, 28, start);
        structure.setBlockState(world, Blocks.SPRUCE_TRAPDOOR.getDefaultState().with(HorizontalBlock.HORIZONTAL_FACING, Direction.WEST).with(TrapDoorBlock.HALF, Half.TOP).with(TrapDoorBlock.WATERLOGGED, false).with(TrapDoorBlock.POWERED, false).with(TrapDoorBlock.OPEN, true), 23, 7, 18, start);
        structure.setBlockState(world, Blocks.LANTERN.getDefaultState().with(LanternBlock.WATERLOGGED, false).with(LanternBlock.HANGING, false), 23, 7, 19, start);
        structure.setBlockState(world, Blocks.SPRUCE_SLAB.getDefaultState().with(SlabBlock.TYPE, SlabType.BOTTOM).with(SlabBlock.WATERLOGGED, false), 23, 7, 28, start);
        structure.setBlockState(world, Blocks.SPRUCE_TRAPDOOR.getDefaultState().with(HorizontalBlock.HORIZONTAL_FACING, Direction.WEST).with(TrapDoorBlock.HALF, Half.TOP).with(TrapDoorBlock.WATERLOGGED, false).with(TrapDoorBlock.POWERED, false).with(TrapDoorBlock.OPEN, true), 23, 8, 15, start);
        structure.setBlockState(world, Blocks.SPRUCE_SLAB.getDefaultState().with(SlabBlock.TYPE, SlabType.BOTTOM).with(SlabBlock.WATERLOGGED, false), 23, 9, 16, start);
        structure.setBlockState(world, Blocks.GRASS.getDefaultState(), 24, 5, 4, start);
        structure.setBlockState(world, Blocks.PODZOL.getDefaultState().with(SnowyDirtBlock.SNOWY, false), 24, 5, 20, start);
        structure.setBlockState(world, Blocks.COBBLESTONE.getDefaultState(), 24, 5, 21, start);
        structure.setBlockState(world, Blocks.PODZOL.getDefaultState().with(SnowyDirtBlock.SNOWY, false), 24, 5, 25, start);
        structure.setBlockState(world, Blocks.COBBLESTONE_SLAB.getDefaultState().with(SlabBlock.TYPE, SlabType.BOTTOM).with(SlabBlock.WATERLOGGED, false), 24, 6, 14, start);
        structure.setBlockState(world, Blocks.COBBLESTONE_SLAB.getDefaultState().with(SlabBlock.TYPE, SlabType.DOUBLE).with(SlabBlock.WATERLOGGED, false), 24, 6, 16, start);
        structure.setBlockState(world, Blocks.BARREL.getDefaultState().with(BarrelBlock.PROPERTY_FACING, Direction.SOUTH).with(BarrelBlock.PROPERTY_OPEN, false), 24, 6, 18, start);
        structure.setBlockState(world, Blocks.WARPED_NYLIUM.getDefaultState(), 24, 6, 19, start);
        structure.setBlockState(world, Blocks.SPRUCE_TRAPDOOR.getDefaultState().with(HorizontalBlock.HORIZONTAL_FACING, Direction.SOUTH).with(TrapDoorBlock.HALF, Half.TOP).with(TrapDoorBlock.WATERLOGGED, false).with(TrapDoorBlock.POWERED, false).with(TrapDoorBlock.OPEN, true), 24, 6, 20, start);
        structure.setBlockState(world, Blocks.AIR.getDefaultState(), 24, 6, 23, start);
        structure.setBlockState(world, Blocks.SPRUCE_LEAVES.getDefaultState().with(LeavesBlock.PERSISTENT, true).with(LeavesBlock.DISTANCE, 7), 24, 6, 25, start);
        structure.setBlockState(world, Blocks.SPRUCE_FENCE.getDefaultState().with(FourWayBlock.WATERLOGGED, false).with(FourWayBlock.NORTH, false).with(FourWayBlock.SOUTH, true).with(FourWayBlock.EAST, true).with(FourWayBlock.WEST, false), 24, 6, 26, start);
        structure.setBlockState(world, Blocks.SPRUCE_FENCE.getDefaultState().with(FourWayBlock.WATERLOGGED, false).with(FourWayBlock.NORTH, true).with(FourWayBlock.SOUTH, false).with(FourWayBlock.EAST, false).with(FourWayBlock.WEST, true), 24, 6, 27, start);
        structure.setBlockState(world, Blocks.GRASS.getDefaultState(), 24, 6, 32, start);
        structure.setBlockState(world, Blocks.CAMPFIRE.getDefaultState().with(CampfireBlock.FACING, Direction.NORTH).with(CampfireBlock.LIT, false).with(CampfireBlock.SIGNAL_FIRE, false).with(CampfireBlock.WATERLOGGED, false), 24, 7, 16, start);
        structure.setBlockState(world, Blocks.OAK_LEAVES.getDefaultState().with(LeavesBlock.PERSISTENT, true).with(LeavesBlock.DISTANCE, 7), 24, 7, 18, start);
        structure.setBlockState(world, Blocks.SPRUCE_TRAPDOOR.getDefaultState().with(HorizontalBlock.HORIZONTAL_FACING, Direction.SOUTH).with(TrapDoorBlock.HALF, Half.TOP).with(TrapDoorBlock.WATERLOGGED, false).with(TrapDoorBlock.POWERED, false).with(TrapDoorBlock.OPEN, true), 24, 7, 19, start);
        structure.setBlockState(world, Blocks.SPRUCE_TRAPDOOR.getDefaultState().with(HorizontalBlock.HORIZONTAL_FACING, Direction.NORTH).with(TrapDoorBlock.HALF, Half.TOP).with(TrapDoorBlock.WATERLOGGED, false).with(TrapDoorBlock.POWERED, false).with(TrapDoorBlock.OPEN, true), 24, 8, 14, start);
        structure.setBlockState(world, Blocks.SPRUCE_TRAPDOOR.getDefaultState().with(HorizontalBlock.HORIZONTAL_FACING, Direction.SOUTH).with(TrapDoorBlock.HALF, Half.TOP).with(TrapDoorBlock.WATERLOGGED, false).with(TrapDoorBlock.POWERED, false).with(TrapDoorBlock.OPEN, true), 24, 8, 16, start);
        structure.setBlockState(world, Blocks.SPRUCE_TRAPDOOR.getDefaultState().with(HorizontalBlock.HORIZONTAL_FACING, Direction.SOUTH).with(TrapDoorBlock.HALF, Half.BOTTOM).with(TrapDoorBlock.WATERLOGGED, false).with(TrapDoorBlock.POWERED, false).with(TrapDoorBlock.OPEN, false), 24, 9, 17, start);
        structure.setBlockState(world, Blocks.SPRUCE_TRAPDOOR.getDefaultState().with(HorizontalBlock.HORIZONTAL_FACING, Direction.SOUTH).with(TrapDoorBlock.HALF, Half.BOTTOM).with(TrapDoorBlock.WATERLOGGED, false).with(TrapDoorBlock.POWERED, false).with(TrapDoorBlock.OPEN, false), 24, 10, 15, start);
        structure.setBlockState(world, Blocks.SPRUCE_FENCE.getDefaultState().with(FourWayBlock.WATERLOGGED, false).with(FourWayBlock.NORTH, false).with(FourWayBlock.SOUTH, false).with(FourWayBlock.EAST, true).with(FourWayBlock.WEST, false), 24, 11, 17, start);
        structure.setBlockState(world, Blocks.RED_WALL_BANNER.getDefaultState().with(WallBannerBlock.HORIZONTAL_FACING, Direction.SOUTH), 24, 11, 18, start);
        structure.setBlockState(world, Blocks.SPRUCE_TRAPDOOR.getDefaultState().with(HorizontalBlock.HORIZONTAL_FACING, Direction.SOUTH).with(TrapDoorBlock.HALF, Half.BOTTOM).with(TrapDoorBlock.WATERLOGGED, false).with(TrapDoorBlock.POWERED, false).with(TrapDoorBlock.OPEN, false), 24, 12, 17, start);
        structure.setBlockState(world, Blocks.DIRT.getDefaultState(), 25, 5, 13, start);
        structure.setBlockState(world, Blocks.PODZOL.getDefaultState().with(SnowyDirtBlock.SNOWY, false), 25, 5, 18, start);
        structure.setBlockState(world, Blocks.COBBLESTONE.getDefaultState(), 25, 5, 25, start);
        structure.setBlockState(world, Blocks.SPRUCE_TRAPDOOR.getDefaultState().with(HorizontalBlock.HORIZONTAL_FACING, Direction.SOUTH).with(TrapDoorBlock.HALF, Half.TOP).with(TrapDoorBlock.WATERLOGGED, true).with(TrapDoorBlock.POWERED, false).with(TrapDoorBlock.OPEN, false), 25, 5, 27, start);
        structure.setBlockState(world, Blocks.COBBLESTONE_SLAB.getDefaultState().with(SlabBlock.TYPE, SlabType.DOUBLE).with(SlabBlock.WATERLOGGED, false), 25, 6, 13, start);
        structure.setBlockState(world, Blocks.COBBLESTONE_SLAB.getDefaultState().with(SlabBlock.TYPE, SlabType.DOUBLE).with(SlabBlock.WATERLOGGED, false), 25, 6, 15, start);
        structure.setBlockState(world, Blocks.COBBLESTONE_SLAB.getDefaultState().with(SlabBlock.TYPE, SlabType.BOTTOM).with(SlabBlock.WATERLOGGED, false), 25, 6, 16, start);
        structure.setBlockState(world, Blocks.AIR.getDefaultState(), 25, 6, 17, start);
        structure.setBlockState(world, Blocks.SPRUCE_TRAPDOOR.getDefaultState().with(HorizontalBlock.HORIZONTAL_FACING, Direction.WEST).with(TrapDoorBlock.HALF, Half.TOP).with(TrapDoorBlock.WATERLOGGED, false).with(TrapDoorBlock.POWERED, false).with(TrapDoorBlock.OPEN, true), 25, 6, 18, start);
        structure.setBlockState(world, Blocks.SPRUCE_TRAPDOOR.getDefaultState().with(HorizontalBlock.HORIZONTAL_FACING, Direction.EAST).with(TrapDoorBlock.HALF, Half.TOP).with(TrapDoorBlock.WATERLOGGED, false).with(TrapDoorBlock.POWERED, false).with(TrapDoorBlock.OPEN, true), 25, 6, 19, start);
        structure.setBlockState(world, Blocks.FERN.getDefaultState(), 25, 6, 20, start);
        structure.setBlockState(world, Blocks.STONE_BUTTON.getDefaultState().with(HorizontalBlock.HORIZONTAL_FACING, Direction.WEST).with(HorizontalFaceBlock.FACE, AttachFace.FLOOR).with(AbstractButtonBlock.POWERED, false), 25, 6, 21, start);
        structure.setBlockState(world, Blocks.CAMPFIRE.getDefaultState().with(CampfireBlock.FACING, Direction.NORTH).with(CampfireBlock.LIT, false).with(CampfireBlock.SIGNAL_FIRE, false).with(CampfireBlock.WATERLOGGED, false), 25, 6, 25, start);
        structure.setBlockState(world, Blocks.SPRUCE_FENCE.getDefaultState().with(FourWayBlock.WATERLOGGED, false).with(FourWayBlock.NORTH, false).with(FourWayBlock.SOUTH, false).with(FourWayBlock.EAST, false).with(FourWayBlock.WEST, true), 25, 6, 26, start);
        structure.setBlockState(world, Blocks.CAMPFIRE.getDefaultState().with(CampfireBlock.FACING, Direction.NORTH).with(CampfireBlock.LIT, false).with(CampfireBlock.SIGNAL_FIRE, false).with(CampfireBlock.WATERLOGGED, false), 25, 6, 27, start);
        structure.setBlockState(world, Blocks.SPRUCE_TRAPDOOR.getDefaultState().with(HorizontalBlock.HORIZONTAL_FACING, Direction.SOUTH).with(TrapDoorBlock.HALF, Half.TOP).with(TrapDoorBlock.WATERLOGGED, false).with(TrapDoorBlock.POWERED, false).with(TrapDoorBlock.OPEN, false), 25, 7, 17, start);
        structure.setBlockState(world, Blocks.SPRUCE_TRAPDOOR.getDefaultState().with(HorizontalBlock.HORIZONTAL_FACING, Direction.EAST).with(TrapDoorBlock.HALF, Half.TOP).with(TrapDoorBlock.WATERLOGGED, false).with(TrapDoorBlock.POWERED, false).with(TrapDoorBlock.OPEN, true), 25, 7, 18, start);
        structure.setBlockState(world, Blocks.SPRUCE_TRAPDOOR.getDefaultState().with(HorizontalBlock.HORIZONTAL_FACING, Direction.EAST).with(TrapDoorBlock.HALF, Half.TOP).with(TrapDoorBlock.WATERLOGGED, false).with(TrapDoorBlock.POWERED, false).with(TrapDoorBlock.OPEN, true), 25, 8, 15, start);
        structure.setBlockState(world, Blocks.SPRUCE_FENCE.getDefaultState().with(FourWayBlock.WATERLOGGED, false).with(FourWayBlock.NORTH, false).with(FourWayBlock.SOUTH, false).with(FourWayBlock.EAST, false).with(FourWayBlock.WEST, false), 25, 10, 14, start);
        structure.setBlockState(world, Blocks.SPRUCE_FENCE.getDefaultState().with(FourWayBlock.WATERLOGGED, false).with(FourWayBlock.NORTH, false).with(FourWayBlock.SOUTH, false).with(FourWayBlock.EAST, true).with(FourWayBlock.WEST, true), 25, 11, 17, start);
        structure.setBlockState(world, Blocks.COBBLESTONE.getDefaultState(), 26, 5, 24, start);
        structure.setBlockState(world, Blocks.SPRUCE_SLAB.getDefaultState().with(SlabBlock.TYPE, SlabType.TOP).with(SlabBlock.WATERLOGGED, true), 26, 5, 27, start);
        structure.setBlockState(world, Blocks.GRASS.getDefaultState(), 26, 5, 35, start);
        structure.setBlockState(world, Blocks.COBBLESTONE_SLAB.getDefaultState().with(SlabBlock.TYPE, SlabType.BOTTOM).with(SlabBlock.WATERLOGGED, false), 26, 6, 13, start);
        structure.setBlockState(world, Blocks.COBBLESTONE_SLAB.getDefaultState().with(SlabBlock.TYPE, SlabType.BOTTOM).with(SlabBlock.WATERLOGGED, false), 26, 6, 15, start);
        structure.setBlockState(world, Blocks.BARREL.getDefaultState().with(BarrelBlock.PROPERTY_FACING, Direction.UP).with(BarrelBlock.PROPERTY_OPEN, false), 26, 6, 17, start);
        structure.setBlockState(world, Blocks.CRIMSON_NYLIUM.getDefaultState(), 26, 6, 18, start);
        structure.setBlockState(world, Blocks.SPRUCE_TRAPDOOR.getDefaultState().with(HorizontalBlock.HORIZONTAL_FACING, Direction.SOUTH).with(TrapDoorBlock.HALF, Half.TOP).with(TrapDoorBlock.WATERLOGGED, false).with(TrapDoorBlock.POWERED, false).with(TrapDoorBlock.OPEN, true), 26, 6, 19, start);
        structure.setBlockState(world, Blocks.ANDESITE_SLAB.getDefaultState().with(SlabBlock.TYPE, SlabType.BOTTOM).with(SlabBlock.WATERLOGGED, false), 26, 6, 23, start);
        structure.setBlockState(world, Blocks.STONE_BUTTON.getDefaultState().with(HorizontalBlock.HORIZONTAL_FACING, Direction.NORTH).with(HorizontalFaceBlock.FACE, AttachFace.FLOOR).with(AbstractButtonBlock.POWERED, false), 26, 6, 26, start);
        structure.setBlockState(world, Blocks.SPRUCE_FENCE.getDefaultState().with(FourWayBlock.WATERLOGGED, false).with(FourWayBlock.NORTH, false).with(FourWayBlock.SOUTH, false).with(FourWayBlock.EAST, false).with(FourWayBlock.WEST, false), 26, 6, 30, start);
        structure.setBlockState(world, Blocks.GRASS.getDefaultState(), 26, 6, 33, start);
        structure.setBlockState(world, Blocks.LANTERN.getDefaultState().with(LanternBlock.WATERLOGGED, false).with(LanternBlock.HANGING, false), 26, 7, 30, start);
        structure.setBlockState(world, Blocks.SPRUCE_TRAPDOOR.getDefaultState().with(HorizontalBlock.HORIZONTAL_FACING, Direction.NORTH).with(TrapDoorBlock.HALF, Half.TOP).with(TrapDoorBlock.WATERLOGGED, false).with(TrapDoorBlock.POWERED, false).with(TrapDoorBlock.OPEN, true), 26, 8, 13, start);
        structure.setBlockState(world, Blocks.LANTERN.getDefaultState().with(LanternBlock.WATERLOGGED, false).with(LanternBlock.HANGING, false), 26, 9, 17, start);
        structure.setBlockState(world, Blocks.SPRUCE_FENCE.getDefaultState().with(FourWayBlock.WATERLOGGED, false).with(FourWayBlock.NORTH, false).with(FourWayBlock.SOUTH, false).with(FourWayBlock.EAST, false).with(FourWayBlock.WEST, true), 26, 11, 17, start);
        structure.setBlockState(world, Blocks.RED_WALL_BANNER.getDefaultState().with(WallBannerBlock.HORIZONTAL_FACING, Direction.SOUTH), 26, 11, 18, start);
        structure.setBlockState(world, Blocks.SPRUCE_TRAPDOOR.getDefaultState().with(HorizontalBlock.HORIZONTAL_FACING, Direction.SOUTH).with(TrapDoorBlock.HALF, Half.BOTTOM).with(TrapDoorBlock.WATERLOGGED, false).with(TrapDoorBlock.POWERED, false).with(TrapDoorBlock.OPEN, false), 26, 12, 17, start);
        structure.setBlockState(world, Blocks.PODZOL.getDefaultState().with(SnowyDirtBlock.SNOWY, false), 27, 5, 14, start);
        structure.setBlockState(world, Blocks.COARSE_DIRT.getDefaultState(), 27, 5, 17, start);
        structure.setBlockState(world, Blocks.DIRT.getDefaultState(), 27, 5, 20, start);
        structure.setBlockState(world, Blocks.GRASS_BLOCK.getDefaultState().with(SnowyDirtBlock.SNOWY, false), 27, 5, 21, start);
        structure.setBlockState(world, Blocks.SPRUCE_SLAB.getDefaultState().with(SlabBlock.TYPE, SlabType.TOP).with(SlabBlock.WATERLOGGED, false), 27, 5, 26, start);
        structure.setBlockState(world, Blocks.SPRUCE_TRAPDOOR.getDefaultState().with(HorizontalBlock.HORIZONTAL_FACING, Direction.SOUTH).with(TrapDoorBlock.HALF, Half.TOP).with(TrapDoorBlock.WATERLOGGED, true).with(TrapDoorBlock.POWERED, false).with(TrapDoorBlock.OPEN, false), 27, 5, 27, start);
        structure.setBlockState(world, Blocks.GRASS.getDefaultState(), 27, 5, 37, start);
        structure.setBlockState(world, Blocks.GRASS.getDefaultState(), 27, 6, 8, start);
        structure.setBlockState(world, Blocks.COBBLESTONE_SLAB.getDefaultState().with(SlabBlock.TYPE, SlabType.DOUBLE).with(SlabBlock.WATERLOGGED, false), 27, 6, 13, start);
        structure.setBlockState(world, Blocks.COBBLESTONE_SLAB.getDefaultState().with(SlabBlock.TYPE, SlabType.DOUBLE).with(SlabBlock.WATERLOGGED, false), 27, 6, 15, start);
        structure.setBlockState(world, Blocks.SPRUCE_STAIRS.getDefaultState().with(StairsBlock.FACING, Direction.EAST).with(StairsBlock.WATERLOGGED, false).with(StairsBlock.SHAPE, StairsShape.STRAIGHT).with(StairsBlock.HALF, Half.BOTTOM), 27, 6, 16, start);
        structure.setBlockState(world, Blocks.SPRUCE_LEAVES.getDefaultState().with(LeavesBlock.PERSISTENT, true).with(LeavesBlock.DISTANCE, 7), 27, 6, 17, start);
        structure.setBlockState(world, Blocks.SPRUCE_STAIRS.getDefaultState().with(StairsBlock.FACING, Direction.EAST).with(StairsBlock.WATERLOGGED, false).with(StairsBlock.SHAPE, StairsShape.STRAIGHT).with(StairsBlock.HALF, Half.BOTTOM), 27, 6, 20, start);
        structure.setBlockState(world, Blocks.SWEET_BERRY_BUSH.getDefaultState().with(SweetBerryBushBlock.AGE, 3), 27, 6, 21, start);
        structure.setBlockState(world, Blocks.CAMPFIRE.getDefaultState().with(CampfireBlock.FACING, Direction.NORTH).with(CampfireBlock.LIT, true).with(CampfireBlock.SIGNAL_FIRE, false).with(CampfireBlock.WATERLOGGED, false), 27, 6, 23, start);
        structure.setBlockState(world, Blocks.COBBLESTONE_SLAB.getDefaultState().with(SlabBlock.TYPE, SlabType.BOTTOM).with(SlabBlock.WATERLOGGED, false), 27, 6, 24, start);
        structure.setBlockState(world, Blocks.FERN.getDefaultState(), 27, 6, 25, start);
        structure.setBlockState(world, Blocks.CAMPFIRE.getDefaultState().with(CampfireBlock.FACING, Direction.NORTH).with(CampfireBlock.LIT, false).with(CampfireBlock.SIGNAL_FIRE, false).with(CampfireBlock.WATERLOGGED, false), 27, 7, 15, start);
        structure.setBlockState(world, Blocks.BARREL.getDefaultState().with(BarrelBlock.PROPERTY_FACING, Direction.WEST).with(BarrelBlock.PROPERTY_OPEN, false), 27, 7, 18, start);
        structure.setBlockState(world, Blocks.CHEST.getDefaultState().with(ChestBlock.FACING, Direction.SOUTH).with(ChestBlock.WATERLOGGED, false).with(ChestBlock.TYPE, ChestType.SINGLE), 27, 7, 19, start);
        structure.setBlockState(world, Blocks.SPRUCE_TRAPDOOR.getDefaultState().with(HorizontalBlock.HORIZONTAL_FACING, Direction.SOUTH).with(TrapDoorBlock.HALF, Half.TOP).with(TrapDoorBlock.WATERLOGGED, false).with(TrapDoorBlock.POWERED, false).with(TrapDoorBlock.OPEN, true), 27, 8, 15, start);
        structure.setBlockState(world, Blocks.LANTERN.getDefaultState().with(LanternBlock.WATERLOGGED, false).with(LanternBlock.HANGING, false), 27, 8, 18, start);
        structure.setBlockState(world, Blocks.STRIPPED_SPRUCE_LOG.getDefaultState(), 27, 9, 14, start);
        structure.setBlockState(world, Blocks.SPRUCE_SLAB.getDefaultState().with(SlabBlock.TYPE, SlabType.BOTTOM).with(SlabBlock.WATERLOGGED, false), 27, 10, 14, start);
        structure.setBlockState(world, Blocks.GRASS.getDefaultState(), 28, 5, 4, start);
        structure.setBlockState(world, Blocks.GRASS_BLOCK.getDefaultState().with(SnowyDirtBlock.SNOWY, false), 28, 5, 11, start);
        structure.setBlockState(world, Blocks.PODZOL.getDefaultState().with(SnowyDirtBlock.SNOWY, false), 28, 5, 16, start);
        structure.setBlockState(world, Blocks.ANDESITE.getDefaultState(), 28, 5, 22, start);
        structure.setBlockState(world, Blocks.ANDESITE.getDefaultState(), 28, 5, 24, start);
        structure.setBlockState(world, Blocks.SPRUCE_SLAB.getDefaultState().with(SlabBlock.TYPE, SlabType.TOP).with(SlabBlock.WATERLOGGED, true), 28, 5, 27, start);
        structure.setBlockState(world, Blocks.SPRUCE_STAIRS.getDefaultState().with(StairsBlock.FACING, Direction.WEST).with(StairsBlock.WATERLOGGED, false).with(StairsBlock.SHAPE, StairsShape.STRAIGHT).with(StairsBlock.HALF, Half.TOP), 28, 6, 16, start);
        structure.setBlockState(world, Blocks.SPRUCE_STAIRS.getDefaultState().with(StairsBlock.FACING, Direction.WEST).with(StairsBlock.WATERLOGGED, false).with(StairsBlock.SHAPE, StairsShape.STRAIGHT).with(StairsBlock.HALF, Half.TOP), 28, 6, 20, start);
        structure.setBlockState(world, Blocks.SPRUCE_LEAVES.getDefaultState().with(LeavesBlock.PERSISTENT, true).with(LeavesBlock.DISTANCE, 7), 28, 6, 21, start);
        structure.setBlockState(world, Blocks.COBBLESTONE_SLAB.getDefaultState().with(SlabBlock.TYPE, SlabType.BOTTOM).with(SlabBlock.WATERLOGGED, false), 28, 6, 23, start);
        structure.setBlockState(world, Blocks.CAMPFIRE.getDefaultState().with(CampfireBlock.FACING, Direction.NORTH).with(CampfireBlock.LIT, false).with(CampfireBlock.SIGNAL_FIRE, false).with(CampfireBlock.WATERLOGGED, false), 28, 6, 28, start);
        structure.setBlockState(world, Blocks.COBBLESTONE_SLAB.getDefaultState().with(SlabBlock.TYPE, SlabType.DOUBLE).with(SlabBlock.WATERLOGGED, false), 28, 7, 12, start);
        structure.setBlockState(world, Blocks.SPRUCE_STAIRS.getDefaultState().with(StairsBlock.FACING, Direction.EAST).with(StairsBlock.WATERLOGGED, false).with(StairsBlock.SHAPE, StairsShape.STRAIGHT).with(StairsBlock.HALF, Half.BOTTOM), 28, 7, 16, start);
        structure.setBlockState(world, Blocks.RED_CARPET.getDefaultState(), 28, 7, 17, start);
        structure.setBlockState(world, Blocks.GRAY_CARPET.getDefaultState(), 28, 7, 18, start);
        structure.setBlockState(world, Blocks.RED_CARPET.getDefaultState(), 28, 7, 19, start);
        structure.setBlockState(world, Blocks.SPRUCE_STAIRS.getDefaultState().with(StairsBlock.FACING, Direction.EAST).with(StairsBlock.WATERLOGGED, false).with(StairsBlock.SHAPE, StairsShape.STRAIGHT).with(StairsBlock.HALF, Half.BOTTOM), 28, 7, 20, start);
        structure.setBlockState(world, Blocks.SPRUCE_TRAPDOOR.getDefaultState().with(HorizontalBlock.HORIZONTAL_FACING, Direction.EAST).with(TrapDoorBlock.HALF, Half.TOP).with(TrapDoorBlock.WATERLOGGED, false).with(TrapDoorBlock.POWERED, false).with(TrapDoorBlock.OPEN, true), 28, 8, 14, start);
        structure.setBlockState(world, Blocks.GRASS_BLOCK.getDefaultState().with(SnowyDirtBlock.SNOWY, false), 29, 5, 15, start);
        structure.setBlockState(world, Blocks.COBBLESTONE.getDefaultState(), 29, 5, 21, start);
        structure.setBlockState(world, Blocks.SPRUCE_TRAPDOOR.getDefaultState().with(HorizontalBlock.HORIZONTAL_FACING, Direction.SOUTH).with(TrapDoorBlock.HALF, Half.TOP).with(TrapDoorBlock.WATERLOGGED, true).with(TrapDoorBlock.POWERED, false).with(TrapDoorBlock.OPEN, false), 29, 5, 27, start);
        structure.setBlockState(world, Blocks.COBBLESTONE_SLAB.getDefaultState().with(SlabBlock.TYPE, SlabType.BOTTOM).with(SlabBlock.WATERLOGGED, false), 29, 6, 14, start);
        structure.setBlockState(world, Blocks.SPRUCE_LEAVES.getDefaultState().with(LeavesBlock.PERSISTENT, true).with(LeavesBlock.DISTANCE, 7), 29, 6, 20, start);
        structure.setBlockState(world, Blocks.SPRUCE_FENCE.getDefaultState().with(FourWayBlock.WATERLOGGED, false).with(FourWayBlock.NORTH, false).with(FourWayBlock.SOUTH, false).with(FourWayBlock.EAST, true).with(FourWayBlock.WEST, false), 29, 6, 26, start);
        structure.setBlockState(world, Blocks.SPRUCE_STAIRS.getDefaultState().with(StairsBlock.FACING, Direction.WEST).with(StairsBlock.WATERLOGGED, false).with(StairsBlock.SHAPE, StairsShape.STRAIGHT).with(StairsBlock.HALF, Half.TOP), 29, 7, 16, start);
        structure.setBlockState(world, Blocks.SPRUCE_STAIRS.getDefaultState().with(StairsBlock.FACING, Direction.WEST).with(StairsBlock.WATERLOGGED, false).with(StairsBlock.SHAPE, StairsShape.STRAIGHT).with(StairsBlock.HALF, Half.TOP), 29, 7, 20, start);
        structure.setBlockState(world, Blocks.SPRUCE_STAIRS.getDefaultState().with(StairsBlock.FACING, Direction.EAST).with(StairsBlock.WATERLOGGED, false).with(StairsBlock.SHAPE, StairsShape.STRAIGHT).with(StairsBlock.HALF, Half.BOTTOM), 29, 8, 16, start);
        structure.setBlockState(world, Blocks.GRAY_CARPET.getDefaultState(), 29, 8, 17, start);
        structure.setBlockState(world, Blocks.RED_CARPET.getDefaultState(), 29, 8, 18, start);
        structure.setBlockState(world, Blocks.GRAY_CARPET.getDefaultState(), 29, 8, 19, start);
        structure.setBlockState(world, Blocks.SPRUCE_STAIRS.getDefaultState().with(StairsBlock.FACING, Direction.EAST).with(StairsBlock.WATERLOGGED, false).with(StairsBlock.SHAPE, StairsShape.STRAIGHT).with(StairsBlock.HALF, Half.BOTTOM), 29, 8, 20, start);
        structure.setBlockState(world, Blocks.SPRUCE_FENCE.getDefaultState().with(FourWayBlock.WATERLOGGED, false).with(FourWayBlock.NORTH, false).with(FourWayBlock.SOUTH, false).with(FourWayBlock.EAST, true).with(FourWayBlock.WEST, false), 29, 10, 12, start);
        structure.setBlockState(world, Blocks.PODZOL.getDefaultState().with(SnowyDirtBlock.SNOWY, false), 30, 5, 14, start);
        structure.setBlockState(world, Blocks.FERN.getDefaultState(), 30, 6, 24, start);
        structure.setBlockState(world, Blocks.SPRUCE_FENCE.getDefaultState().with(FourWayBlock.WATERLOGGED, false).with(FourWayBlock.NORTH, false).with(FourWayBlock.SOUTH, true).with(FourWayBlock.EAST, false).with(FourWayBlock.WEST, true), 30, 6, 26, start);
        structure.setBlockState(world, Blocks.SPRUCE_FENCE.getDefaultState().with(FourWayBlock.WATERLOGGED, false).with(FourWayBlock.NORTH, true).with(FourWayBlock.SOUTH, false).with(FourWayBlock.EAST, false).with(FourWayBlock.WEST, false), 30, 6, 27, start);
        structure.setBlockState(world, Blocks.AIR.getDefaultState(), 30, 6, 30, start);
        structure.setBlockState(world, Blocks.DANDELION.getDefaultState(), 30, 6, 34, start);
        structure.setBlockState(world, Blocks.SPRUCE_STAIRS.getDefaultState().with(StairsBlock.FACING, Direction.WEST).with(StairsBlock.WATERLOGGED, false).with(StairsBlock.SHAPE, StairsShape.STRAIGHT).with(StairsBlock.HALF, Half.TOP), 30, 8, 16, start);
        structure.setBlockState(world, Blocks.SPRUCE_STAIRS.getDefaultState().with(StairsBlock.FACING, Direction.WEST).with(StairsBlock.WATERLOGGED, false).with(StairsBlock.SHAPE, StairsShape.STRAIGHT).with(StairsBlock.HALF, Half.TOP), 30, 8, 20, start);
        structure.setBlockState(world, Blocks.SPRUCE_TRAPDOOR.getDefaultState().with(HorizontalBlock.HORIZONTAL_FACING, Direction.NORTH).with(TrapDoorBlock.HALF, Half.TOP).with(TrapDoorBlock.WATERLOGGED, false).with(TrapDoorBlock.POWERED, false).with(TrapDoorBlock.OPEN, true), 30, 9, 11, start);
        structure.setBlockState(world, Blocks.SPRUCE_STAIRS.getDefaultState().with(StairsBlock.FACING, Direction.EAST).with(StairsBlock.WATERLOGGED, false).with(StairsBlock.SHAPE, StairsShape.STRAIGHT).with(StairsBlock.HALF, Half.BOTTOM), 30, 9, 16, start);
        structure.setBlockState(world, Blocks.GRAY_CARPET.getDefaultState(), 30, 9, 19, start);
        structure.setBlockState(world, Blocks.SPRUCE_STAIRS.getDefaultState().with(StairsBlock.FACING, Direction.EAST).with(StairsBlock.WATERLOGGED, false).with(StairsBlock.SHAPE, StairsShape.STRAIGHT).with(StairsBlock.HALF, Half.BOTTOM), 30, 9, 20, start);
        structure.setBlockState(world, Blocks.STRIPPED_SPRUCE_LOG.getDefaultState(), 30, 10, 12, start);
        structure.setBlockState(world, Blocks.SPRUCE_FENCE.getDefaultState().with(FourWayBlock.WATERLOGGED, false).with(FourWayBlock.NORTH, false).with(FourWayBlock.SOUTH, false).with(FourWayBlock.EAST, false).with(FourWayBlock.WEST, false), 30, 11, 12, start);
        structure.setBlockState(world, Blocks.PODZOL.getDefaultState().with(SnowyDirtBlock.SNOWY, false), 31, 5, 24, start);
        structure.setBlockState(world, Blocks.COARSE_DIRT.getDefaultState(), 31, 5, 25, start);
        structure.setBlockState(world, Blocks.DIRT.getDefaultState(), 31, 5, 28, start);
        structure.setBlockState(world, Blocks.PODZOL.getDefaultState().with(SnowyDirtBlock.SNOWY, false), 31, 6, 14, start);
        structure.setBlockState(world, Blocks.AIR.getDefaultState(), 31, 6, 18, start);
        structure.setBlockState(world, Blocks.AIR.getDefaultState(), 31, 6, 23, start);
        structure.setBlockState(world, Blocks.SPRUCE_LEAVES.getDefaultState().with(LeavesBlock.PERSISTENT, true).with(LeavesBlock.DISTANCE, 2), 31, 6, 26, start);
        structure.setBlockState(world, Blocks.SPRUCE_LEAVES.getDefaultState().with(LeavesBlock.PERSISTENT, true).with(LeavesBlock.DISTANCE, 1), 31, 6, 27, start);
        structure.setBlockState(world, Blocks.STRIPPED_SPRUCE_LOG.getDefaultState(), 31, 6, 28, start);
        structure.setBlockState(world, Blocks.COBBLESTONE_SLAB.getDefaultState().with(SlabBlock.TYPE, SlabType.DOUBLE).with(SlabBlock.WATERLOGGED, false), 31, 7, 13, start);
        structure.setBlockState(world, Blocks.SPRUCE_SLAB.getDefaultState().with(SlabBlock.TYPE, SlabType.BOTTOM).with(SlabBlock.WATERLOGGED, false), 31, 7, 28, start);
        structure.setBlockState(world, Blocks.CAMPFIRE.getDefaultState().with(CampfireBlock.FACING, Direction.NORTH).with(CampfireBlock.LIT, false).with(CampfireBlock.SIGNAL_FIRE, false).with(CampfireBlock.WATERLOGGED, false), 31, 8, 13, start);
        structure.setBlockState(world, Blocks.OAK_LOG.getDefaultState(), 31, 9, 16, start);
        structure.setBlockState(world, Blocks.OAK_LOG.getDefaultState(), 31, 9, 20, start);
        structure.setBlockState(world, Blocks.SPRUCE_SLAB.getDefaultState().with(SlabBlock.TYPE, SlabType.BOTTOM).with(SlabBlock.WATERLOGGED, false), 31, 10, 16, start);
        structure.setBlockState(world, Blocks.SPRUCE_TRAPDOOR.getDefaultState().with(HorizontalBlock.HORIZONTAL_FACING, Direction.SOUTH).with(TrapDoorBlock.HALF, Half.BOTTOM).with(TrapDoorBlock.WATERLOGGED, false).with(TrapDoorBlock.POWERED, false).with(TrapDoorBlock.OPEN, false), 31, 10, 17, start);
        structure.setBlockState(world, Blocks.SPRUCE_SLAB.getDefaultState().with(SlabBlock.TYPE, SlabType.BOTTOM).with(SlabBlock.WATERLOGGED, false), 31, 10, 18, start);
        structure.setBlockState(world, Blocks.SPRUCE_TRAPDOOR.getDefaultState().with(HorizontalBlock.HORIZONTAL_FACING, Direction.SOUTH).with(TrapDoorBlock.HALF, Half.BOTTOM).with(TrapDoorBlock.WATERLOGGED, false).with(TrapDoorBlock.POWERED, false).with(TrapDoorBlock.OPEN, false), 31, 10, 19, start);
        structure.setBlockState(world, Blocks.SPRUCE_SLAB.getDefaultState().with(SlabBlock.TYPE, SlabType.BOTTOM).with(SlabBlock.WATERLOGGED, false), 31, 10, 20, start);
        structure.setBlockState(world, Blocks.PODZOL.getDefaultState().with(SnowyDirtBlock.SNOWY, false), 32, 5, 20, start);
        structure.setBlockState(world, Blocks.SWEET_BERRY_BUSH.getDefaultState().with(SweetBerryBushBlock.AGE, 3), 32, 6, 27, start);
        structure.setBlockState(world, Blocks.SPRUCE_FENCE.getDefaultState().with(FourWayBlock.WATERLOGGED, false).with(FourWayBlock.NORTH, false).with(FourWayBlock.SOUTH, false).with(FourWayBlock.EAST, true).with(FourWayBlock.WEST, false), 32, 6, 29, start);
        structure.setBlockState(world, Blocks.GRASS.getDefaultState(), 32, 6, 30, start);
        structure.setBlockState(world, Blocks.COBBLESTONE_SLAB.getDefaultState().with(SlabBlock.TYPE, SlabType.BOTTOM).with(SlabBlock.WATERLOGGED, false), 32, 8, 11, start);
        structure.setBlockState(world, Blocks.SPRUCE_STAIRS.getDefaultState().with(StairsBlock.FACING, Direction.EAST).with(StairsBlock.WATERLOGGED, false).with(StairsBlock.SHAPE, StairsShape.STRAIGHT).with(StairsBlock.HALF, Half.TOP), 32, 8, 16, start);
        structure.setBlockState(world, Blocks.SPRUCE_STAIRS.getDefaultState().with(StairsBlock.FACING, Direction.EAST).with(StairsBlock.WATERLOGGED, false).with(StairsBlock.SHAPE, StairsShape.STRAIGHT).with(StairsBlock.HALF, Half.TOP), 32, 8, 20, start);
        structure.setBlockState(world, Blocks.SPRUCE_TRAPDOOR.getDefaultState().with(HorizontalBlock.HORIZONTAL_FACING, Direction.WEST).with(TrapDoorBlock.HALF, Half.TOP).with(TrapDoorBlock.WATERLOGGED, false).with(TrapDoorBlock.POWERED, false).with(TrapDoorBlock.OPEN, true), 32, 9, 13, start);
        structure.setBlockState(world, Blocks.SPRUCE_STAIRS.getDefaultState().with(StairsBlock.FACING, Direction.WEST).with(StairsBlock.WATERLOGGED, false).with(StairsBlock.SHAPE, StairsShape.STRAIGHT).with(StairsBlock.HALF, Half.BOTTOM), 32, 9, 16, start);
        structure.setBlockState(world, Blocks.RED_CARPET.getDefaultState(), 32, 9, 17, start);
        structure.setBlockState(world, Blocks.SPRUCE_STAIRS.getDefaultState().with(StairsBlock.FACING, Direction.WEST).with(StairsBlock.WATERLOGGED, false).with(StairsBlock.SHAPE, StairsShape.STRAIGHT).with(StairsBlock.HALF, Half.BOTTOM), 32, 9, 20, start);
        structure.setBlockState(world, Blocks.STONE_BUTTON.getDefaultState().with(HorizontalBlock.HORIZONTAL_FACING, Direction.NORTH).with(HorizontalFaceBlock.FACE, AttachFace.FLOOR).with(AbstractButtonBlock.POWERED, false), 33, 6, 21, start);
        structure.setBlockState(world, Blocks.STONE_BUTTON.getDefaultState().with(HorizontalBlock.HORIZONTAL_FACING, Direction.NORTH).with(HorizontalFaceBlock.FACE, AttachFace.FLOOR).with(AbstractButtonBlock.POWERED, false), 33, 6, 26, start);
        structure.setBlockState(world, Blocks.SPRUCE_FENCE.getDefaultState().with(FourWayBlock.WATERLOGGED, false).with(FourWayBlock.NORTH, false).with(FourWayBlock.SOUTH, true).with(FourWayBlock.EAST, false).with(FourWayBlock.WEST, true), 33, 6, 29, start);
        structure.setBlockState(world, Blocks.SPRUCE_FENCE.getDefaultState().with(FourWayBlock.WATERLOGGED, false).with(FourWayBlock.NORTH, true).with(FourWayBlock.SOUTH, false).with(FourWayBlock.EAST, true).with(FourWayBlock.WEST, false), 33, 6, 30, start);
        structure.setBlockState(world, Blocks.COBBLESTONE_SLAB.getDefaultState().with(SlabBlock.TYPE, SlabType.DOUBLE).with(SlabBlock.WATERLOGGED, false), 33, 7, 14, start);
        structure.setBlockState(world, Blocks.SPRUCE_STAIRS.getDefaultState().with(StairsBlock.FACING, Direction.EAST).with(StairsBlock.WATERLOGGED, false).with(StairsBlock.SHAPE, StairsShape.STRAIGHT).with(StairsBlock.HALF, Half.TOP), 33, 7, 16, start);
        structure.setBlockState(world, Blocks.SPRUCE_STAIRS.getDefaultState().with(StairsBlock.FACING, Direction.EAST).with(StairsBlock.WATERLOGGED, false).with(StairsBlock.SHAPE, StairsShape.STRAIGHT).with(StairsBlock.HALF, Half.TOP), 33, 7, 20, start);
        structure.setBlockState(world, Blocks.CAMPFIRE.getDefaultState().with(CampfireBlock.FACING, Direction.NORTH).with(CampfireBlock.LIT, false).with(CampfireBlock.SIGNAL_FIRE, false).with(CampfireBlock.WATERLOGGED, false), 33, 8, 14, start);
        structure.setBlockState(world, Blocks.SPRUCE_STAIRS.getDefaultState().with(StairsBlock.FACING, Direction.WEST).with(StairsBlock.WATERLOGGED, false).with(StairsBlock.SHAPE, StairsShape.STRAIGHT).with(StairsBlock.HALF, Half.BOTTOM), 33, 8, 16, start);
        structure.setBlockState(world, Blocks.RED_CARPET.getDefaultState(), 33, 8, 19, start);
        structure.setBlockState(world, Blocks.SPRUCE_STAIRS.getDefaultState().with(StairsBlock.FACING, Direction.WEST).with(StairsBlock.WATERLOGGED, false).with(StairsBlock.SHAPE, StairsShape.STRAIGHT).with(StairsBlock.HALF, Half.BOTTOM), 33, 8, 20, start);
        structure.setBlockState(world, Blocks.SPRUCE_TRAPDOOR.getDefaultState().with(HorizontalBlock.HORIZONTAL_FACING, Direction.SOUTH).with(TrapDoorBlock.HALF, Half.TOP).with(TrapDoorBlock.WATERLOGGED, false).with(TrapDoorBlock.POWERED, false).with(TrapDoorBlock.OPEN, true), 33, 9, 14, start);
        structure.setBlockState(world, Blocks.SPRUCE_FENCE.getDefaultState().with(FourWayBlock.WATERLOGGED, false).with(FourWayBlock.NORTH, false).with(FourWayBlock.SOUTH, false).with(FourWayBlock.EAST, false).with(FourWayBlock.WEST, false), 33, 10, 13, start);
        structure.setBlockState(world, Blocks.DIRT.getDefaultState(), 34, 5, 31, start);
        structure.setBlockState(world, Blocks.GRASS.getDefaultState(), 34, 6, 8, start);
        structure.setBlockState(world, Blocks.COBBLESTONE.getDefaultState(), 34, 6, 15, start);
        structure.setBlockState(world, Blocks.SPRUCE_STAIRS.getDefaultState().with(StairsBlock.FACING, Direction.EAST).with(StairsBlock.WATERLOGGED, false).with(StairsBlock.SHAPE, StairsShape.STRAIGHT).with(StairsBlock.HALF, Half.TOP), 34, 6, 16, start);
        structure.setBlockState(world, Blocks.SPRUCE_STAIRS.getDefaultState().with(StairsBlock.FACING, Direction.EAST).with(StairsBlock.WATERLOGGED, false).with(StairsBlock.SHAPE, StairsShape.STRAIGHT).with(StairsBlock.HALF, Half.TOP), 34, 6, 20, start);
        structure.setBlockState(world, Blocks.ROSE_BUSH.getDefaultState(), 34, 6, 21, start);
        structure.setBlockState(world, Blocks.FERN.getDefaultState(), 34, 6, 23, start);
        structure.setBlockState(world, Blocks.CHEST.getDefaultState().with(ChestBlock.FACING, Direction.WEST).with(ChestBlock.WATERLOGGED, false).with(ChestBlock.TYPE, ChestType.RIGHT), 34, 6, 25, start);
        structure.setBlockState(world, Blocks.CHEST.getDefaultState().with(ChestBlock.FACING, Direction.WEST).with(ChestBlock.WATERLOGGED, false).with(ChestBlock.TYPE, ChestType.LEFT), 34, 6, 26, start);
        structure.setBlockState(world, Blocks.ROSE_BUSH.getDefaultState(), 34, 6, 27, start);
        structure.setBlockState(world, Blocks.COBBLESTONE_SLAB.getDefaultState().with(SlabBlock.TYPE, SlabType.BOTTOM).with(SlabBlock.WATERLOGGED, false), 34, 6, 29, start);
        structure.setBlockState(world, Blocks.STRIPPED_SPRUCE_LOG.getDefaultState(), 34, 6, 30, start);
        structure.setBlockState(world, Blocks.COBBLESTONE_SLAB.getDefaultState().with(SlabBlock.TYPE, SlabType.BOTTOM).with(SlabBlock.WATERLOGGED, false), 34, 6, 31, start);
        structure.setBlockState(world, Blocks.GRASS.getDefaultState(), 34, 6, 32, start);
        structure.setBlockState(world, Blocks.SPRUCE_STAIRS.getDefaultState().with(StairsBlock.FACING, Direction.WEST).with(StairsBlock.WATERLOGGED, false).with(StairsBlock.SHAPE, StairsShape.STRAIGHT).with(StairsBlock.HALF, Half.BOTTOM), 34, 7, 16, start);
        structure.setBlockState(world, Blocks.RED_CARPET.getDefaultState(), 34, 7, 17, start);
        structure.setBlockState(world, Blocks.GRAY_CARPET.getDefaultState(), 34, 7, 18, start);
        structure.setBlockState(world, Blocks.SPRUCE_STAIRS.getDefaultState().with(StairsBlock.FACING, Direction.WEST).with(StairsBlock.WATERLOGGED, false).with(StairsBlock.SHAPE, StairsShape.STRAIGHT).with(StairsBlock.HALF, Half.BOTTOM), 34, 7, 20, start);
        structure.setBlockState(world, Blocks.ROSE_BUSH.getDefaultState(), 34, 7, 21, start);
        structure.setBlockState(world, Blocks.ROSE_BUSH.getDefaultState(), 34, 7, 27, start);
        structure.setBlockState(world, Blocks.SPRUCE_LEAVES.getDefaultState().with(LeavesBlock.PERSISTENT, true).with(LeavesBlock.DISTANCE, 7), 34, 7, 28, start);
        structure.setBlockState(world, Blocks.SPRUCE_SLAB.getDefaultState().with(SlabBlock.TYPE, SlabType.BOTTOM).with(SlabBlock.WATERLOGGED, false), 34, 7, 30, start);
        structure.setBlockState(world, Blocks.SPRUCE_TRAPDOOR.getDefaultState().with(HorizontalBlock.HORIZONTAL_FACING, Direction.WEST).with(TrapDoorBlock.HALF, Half.TOP).with(TrapDoorBlock.WATERLOGGED, false).with(TrapDoorBlock.POWERED, false).with(TrapDoorBlock.OPEN, true), 34, 9, 15, start);
        structure.setBlockState(world, Blocks.SPRUCE_SLAB.getDefaultState().with(SlabBlock.TYPE, SlabType.BOTTOM).with(SlabBlock.WATERLOGGED, false), 34, 10, 14, start);
        structure.setBlockState(world, Blocks.DIRT.getDefaultState(), 35, 5, 20, start);
        structure.setBlockState(world, Blocks.PODZOL.getDefaultState().with(SnowyDirtBlock.SNOWY, false), 35, 5, 24, start);
        structure.setBlockState(world, Blocks.COARSE_DIRT.getDefaultState(), 35, 5, 25, start);
        structure.setBlockState(world, Blocks.AIR.getDefaultState(), 35, 6, 11, start);
        structure.setBlockState(world, Blocks.DIRT.getDefaultState(), 35, 6, 15, start);
        structure.setBlockState(world, Blocks.SPRUCE_STAIRS.getDefaultState().with(StairsBlock.FACING, Direction.WEST).with(StairsBlock.WATERLOGGED, false).with(StairsBlock.SHAPE, StairsShape.STRAIGHT).with(StairsBlock.HALF, Half.BOTTOM), 35, 6, 16, start);
        structure.setBlockState(world, Blocks.SPRUCE_STAIRS.getDefaultState().with(StairsBlock.FACING, Direction.WEST).with(StairsBlock.WATERLOGGED, false).with(StairsBlock.SHAPE, StairsShape.STRAIGHT).with(StairsBlock.HALF, Half.BOTTOM), 35, 6, 20, start);
        structure.setBlockState(world, Blocks.AIR.getDefaultState(), 35, 6, 24, start);
        structure.setBlockState(world, Blocks.COBBLESTONE_SLAB.getDefaultState().with(SlabBlock.TYPE, SlabType.DOUBLE).with(SlabBlock.WATERLOGGED, false), 35, 6, 30, start);
        structure.setBlockState(world, Blocks.COBBLESTONE_SLAB.getDefaultState().with(SlabBlock.TYPE, SlabType.BOTTOM).with(SlabBlock.WATERLOGGED, false), 35, 7, 16, start);
        structure.setBlockState(world, Blocks.BARREL.getDefaultState().with(BarrelBlock.PROPERTY_FACING, Direction.WEST).with(BarrelBlock.PROPERTY_OPEN, false), 35, 7, 25, start);
        structure.setBlockState(world, Blocks.LANTERN.getDefaultState().with(LanternBlock.WATERLOGGED, false).with(LanternBlock.HANGING, false), 35, 7, 26, start);
        structure.setBlockState(world, Blocks.COBBLESTONE_SLAB.getDefaultState().with(SlabBlock.TYPE, SlabType.DOUBLE).with(SlabBlock.WATERLOGGED, false), 35, 8, 14, start);
        structure.setBlockState(world, Blocks.SPRUCE_TRAPDOOR.getDefaultState().with(HorizontalBlock.HORIZONTAL_FACING, Direction.NORTH).with(TrapDoorBlock.HALF, Half.TOP).with(TrapDoorBlock.WATERLOGGED, false).with(TrapDoorBlock.POWERED, false).with(TrapDoorBlock.OPEN, true), 35, 9, 14, start);
        structure.setBlockState(world, Blocks.SPRUCE_TRAPDOOR.getDefaultState().with(HorizontalBlock.HORIZONTAL_FACING, Direction.SOUTH).with(TrapDoorBlock.HALF, Half.TOP).with(TrapDoorBlock.WATERLOGGED, false).with(TrapDoorBlock.POWERED, false).with(TrapDoorBlock.OPEN, true), 35, 9, 16, start);
        structure.setBlockState(world, Blocks.SPRUCE_TRAPDOOR.getDefaultState().with(HorizontalBlock.HORIZONTAL_FACING, Direction.WEST).with(TrapDoorBlock.HALF, Half.TOP).with(TrapDoorBlock.WATERLOGGED, false).with(TrapDoorBlock.POWERED, false).with(TrapDoorBlock.OPEN, true), 35, 9, 17, start);
        structure.setBlockState(world, Blocks.SPRUCE_FENCE.getDefaultState().with(FourWayBlock.WATERLOGGED, false).with(FourWayBlock.NORTH, false).with(FourWayBlock.SOUTH, false).with(FourWayBlock.EAST, false).with(FourWayBlock.WEST, false), 35, 9, 29, start);
        structure.setBlockState(world, Blocks.SPRUCE_TRAPDOOR.getDefaultState().with(HorizontalBlock.HORIZONTAL_FACING, Direction.WEST).with(TrapDoorBlock.HALF, Half.BOTTOM).with(TrapDoorBlock.WATERLOGGED, false).with(TrapDoorBlock.POWERED, false).with(TrapDoorBlock.OPEN, false), 35, 11, 15, start);
        structure.setBlockState(world, Blocks.PODZOL.getDefaultState().with(SnowyDirtBlock.SNOWY, false), 36, 5, 23, start);
        structure.setBlockState(world, Blocks.COARSE_DIRT.getDefaultState(), 36, 5, 24, start);
        structure.setBlockState(world, Blocks.DIRT.getDefaultState(), 36, 5, 30, start);
        structure.setBlockState(world, Blocks.GRASS.getDefaultState(), 36, 6, 10, start);
        structure.setBlockState(world, Blocks.COBBLESTONE_SLAB.getDefaultState().with(SlabBlock.TYPE, SlabType.BOTTOM).with(SlabBlock.WATERLOGGED, false), 36, 6, 23, start);
        structure.setBlockState(world, Blocks.BARREL.getDefaultState().with(BarrelBlock.PROPERTY_FACING, Direction.WEST).with(BarrelBlock.PROPERTY_OPEN, false), 36, 6, 24, start);
        structure.setBlockState(world, Blocks.COBBLESTONE_SLAB.getDefaultState().with(SlabBlock.TYPE, SlabType.DOUBLE).with(SlabBlock.WATERLOGGED, false), 36, 6, 27, start);
        structure.setBlockState(world, Blocks.COBBLESTONE_SLAB.getDefaultState().with(SlabBlock.TYPE, SlabType.BOTTOM).with(SlabBlock.WATERLOGGED, false), 36, 6, 30, start);
        structure.setBlockState(world, Blocks.GRASS.getDefaultState(), 36, 6, 32, start);
        structure.setBlockState(world, Blocks.CAMPFIRE.getDefaultState().with(CampfireBlock.FACING, Direction.NORTH).with(CampfireBlock.LIT, false).with(CampfireBlock.SIGNAL_FIRE, false).with(CampfireBlock.WATERLOGGED, false), 36, 7, 18, start);
        structure.setBlockState(world, Blocks.CAMPFIRE.getDefaultState().with(CampfireBlock.FACING, Direction.EAST).with(CampfireBlock.LIT, false).with(CampfireBlock.SIGNAL_FIRE, false).with(CampfireBlock.WATERLOGGED, false), 36, 7, 27, start);
        structure.setBlockState(world, Blocks.SPRUCE_TRAPDOOR.getDefaultState().with(HorizontalBlock.HORIZONTAL_FACING, Direction.SOUTH).with(TrapDoorBlock.HALF, Half.TOP).with(TrapDoorBlock.WATERLOGGED, false).with(TrapDoorBlock.POWERED, false).with(TrapDoorBlock.OPEN, true), 36, 7, 29, start);
        structure.setBlockState(world, Blocks.COBBLESTONE_SLAB.getDefaultState().with(SlabBlock.TYPE, SlabType.BOTTOM).with(SlabBlock.WATERLOGGED, false), 36, 8, 15, start);
        structure.setBlockState(world, Blocks.SPRUCE_TRAPDOOR.getDefaultState().with(HorizontalBlock.HORIZONTAL_FACING, Direction.WEST).with(TrapDoorBlock.HALF, Half.TOP).with(TrapDoorBlock.WATERLOGGED, false).with(TrapDoorBlock.POWERED, false).with(TrapDoorBlock.OPEN, true), 36, 8, 27, start);
        structure.setBlockState(world, Blocks.SPRUCE_TRAPDOOR.getDefaultState().with(HorizontalBlock.HORIZONTAL_FACING, Direction.EAST).with(TrapDoorBlock.HALF, Half.TOP).with(TrapDoorBlock.WATERLOGGED, false).with(TrapDoorBlock.POWERED, false).with(TrapDoorBlock.OPEN, true), 36, 9, 15, start);
        structure.setBlockState(world, Blocks.SPRUCE_TRAPDOOR.getDefaultState().with(HorizontalBlock.HORIZONTAL_FACING, Direction.SOUTH).with(TrapDoorBlock.HALF, Half.TOP).with(TrapDoorBlock.WATERLOGGED, false).with(TrapDoorBlock.POWERED, false).with(TrapDoorBlock.OPEN, true), 36, 9, 18, start);
        structure.setBlockState(world, Blocks.SPRUCE_SLAB.getDefaultState().with(SlabBlock.TYPE, SlabType.BOTTOM).with(SlabBlock.WATERLOGGED, false), 36, 9, 28, start);
        structure.setBlockState(world, Blocks.SPRUCE_SLAB.getDefaultState().with(SlabBlock.TYPE, SlabType.BOTTOM).with(SlabBlock.WATERLOGGED, false), 36, 10, 16, start);
        structure.setBlockState(world, Blocks.SPRUCE_FENCE.getDefaultState().with(FourWayBlock.WATERLOGGED, false).with(FourWayBlock.NORTH, false).with(FourWayBlock.SOUTH, false).with(FourWayBlock.EAST, false).with(FourWayBlock.WEST, false), 36, 11, 17, start);
        structure.setBlockState(world, Blocks.COBBLESTONE.getDefaultState(), 37, 6, 28, start);
        structure.setBlockState(world, Blocks.COBBLESTONE.getDefaultState(), 37, 7, 16, start);
        structure.setBlockState(world, Blocks.COBBLESTONE_SLAB.getDefaultState().with(SlabBlock.TYPE, SlabType.BOTTOM).with(SlabBlock.WATERLOGGED, false), 37, 7, 22, start);
        structure.setBlockState(world, Blocks.CAMPFIRE.getDefaultState().with(CampfireBlock.FACING, Direction.EAST).with(CampfireBlock.LIT, false).with(CampfireBlock.SIGNAL_FIRE, false).with(CampfireBlock.WATERLOGGED, false), 37, 7, 23, start);
        structure.setBlockState(world, Blocks.COBBLESTONE_SLAB.getDefaultState().with(SlabBlock.TYPE, SlabType.BOTTOM).with(SlabBlock.WATERLOGGED, false), 37, 7, 25, start);
        structure.setBlockState(world, Blocks.COBBLESTONE_SLAB.getDefaultState().with(SlabBlock.TYPE, SlabType.DOUBLE).with(SlabBlock.WATERLOGGED, false), 37, 7, 28, start);
        structure.setBlockState(world, Blocks.COBBLESTONE_SLAB.getDefaultState().with(SlabBlock.TYPE, SlabType.BOTTOM).with(SlabBlock.WATERLOGGED, false), 37, 7, 29, start);
        structure.setBlockState(world, Blocks.COBBLESTONE_SLAB.getDefaultState().with(SlabBlock.TYPE, SlabType.DOUBLE).with(SlabBlock.WATERLOGGED, false), 37, 8, 16, start);
        structure.setBlockState(world, Blocks.SPRUCE_TRAPDOOR.getDefaultState().with(HorizontalBlock.HORIZONTAL_FACING, Direction.NORTH).with(TrapDoorBlock.HALF, Half.TOP).with(TrapDoorBlock.WATERLOGGED, false).with(TrapDoorBlock.POWERED, false).with(TrapDoorBlock.OPEN, true), 37, 8, 26, start);
        structure.setBlockState(world, Blocks.SPRUCE_TRAPDOOR.getDefaultState().with(HorizontalBlock.HORIZONTAL_FACING, Direction.EAST).with(TrapDoorBlock.HALF, Half.TOP).with(TrapDoorBlock.WATERLOGGED, false).with(TrapDoorBlock.POWERED, false).with(TrapDoorBlock.OPEN, true), 37, 9, 17, start);
        structure.setBlockState(world, Blocks.SPRUCE_SLAB.getDefaultState().with(SlabBlock.TYPE, SlabType.BOTTOM).with(SlabBlock.WATERLOGGED, false), 37, 9, 19, start);
        structure.setBlockState(world, Blocks.SPRUCE_TRAPDOOR.getDefaultState().with(HorizontalBlock.HORIZONTAL_FACING, Direction.WEST).with(TrapDoorBlock.HALF, Half.TOP).with(TrapDoorBlock.WATERLOGGED, false).with(TrapDoorBlock.POWERED, false).with(TrapDoorBlock.OPEN, true), 37, 9, 22, start);
        structure.setBlockState(world, Blocks.SPRUCE_TRAPDOOR.getDefaultState().with(HorizontalBlock.HORIZONTAL_FACING, Direction.WEST).with(TrapDoorBlock.HALF, Half.BOTTOM).with(TrapDoorBlock.WATERLOGGED, false).with(TrapDoorBlock.POWERED, false).with(TrapDoorBlock.OPEN, false), 37, 10, 27, start);
        structure.setBlockState(world, Blocks.GRASS.getDefaultState(), 38, 6, 32, start);
        structure.setBlockState(world, Blocks.COBBLESTONE_SLAB.getDefaultState().with(SlabBlock.TYPE, SlabType.DOUBLE).with(SlabBlock.WATERLOGGED, false), 38, 7, 18, start);
        structure.setBlockState(world, Blocks.COBBLESTONE_SLAB.getDefaultState().with(SlabBlock.TYPE, SlabType.DOUBLE).with(SlabBlock.WATERLOGGED, false), 38, 7, 27, start);
        structure.setBlockState(world, Blocks.SPRUCE_TRAPDOOR.getDefaultState().with(HorizontalBlock.HORIZONTAL_FACING, Direction.NORTH).with(TrapDoorBlock.HALF, Half.TOP).with(TrapDoorBlock.WATERLOGGED, false).with(TrapDoorBlock.POWERED, false).with(TrapDoorBlock.OPEN, true), 38, 8, 19, start);
        structure.setBlockState(world, Blocks.SPRUCE_SLAB.getDefaultState().with(SlabBlock.TYPE, SlabType.BOTTOM).with(SlabBlock.WATERLOGGED, false), 38, 9, 21, start);
        structure.setBlockState(world, Blocks.STRIPPED_SPRUCE_LOG.getDefaultState(), 38, 9, 25, start);
        structure.setBlockState(world, Blocks.SPRUCE_FENCE.getDefaultState().with(FourWayBlock.WATERLOGGED, false).with(FourWayBlock.NORTH, false).with(FourWayBlock.SOUTH, false).with(FourWayBlock.EAST, false).with(FourWayBlock.WEST, false), 38, 10, 20, start);
        structure.setBlockState(world, Blocks.SPRUCE_SLAB.getDefaultState().with(SlabBlock.TYPE, SlabType.BOTTOM).with(SlabBlock.WATERLOGGED, false), 38, 10, 23, start);
        structure.setBlockState(world, Blocks.SPRUCE_FENCE.getDefaultState().with(FourWayBlock.WATERLOGGED, false).with(FourWayBlock.NORTH, false).with(FourWayBlock.SOUTH, false).with(FourWayBlock.EAST, false).with(FourWayBlock.WEST, false), 38, 10, 25, start);
        structure.setBlockState(world, Blocks.GRASS.getDefaultState(), 39, 5, 35, start);
        structure.setBlockState(world, Blocks.GRASS.getDefaultState(), 39, 5, 37, start);
        structure.setBlockState(world, Blocks.GRASS.getDefaultState(), 39, 6, 11, start);
        structure.setBlockState(world, Blocks.GRASS.getDefaultState(), 39, 6, 17, start);
        structure.setBlockState(world, Blocks.GRASS.getDefaultState(), 39, 6, 19, start);
        structure.setBlockState(world, Blocks.GRASS.getDefaultState(), 39, 6, 30, start);
        structure.setBlockState(world, Blocks.AIR.getDefaultState(), 39, 6, 32, start);
        structure.setBlockState(world, Blocks.COBBLESTONE_SLAB.getDefaultState().with(SlabBlock.TYPE, SlabType.DOUBLE).with(SlabBlock.WATERLOGGED, false), 39, 7, 24, start);
        structure.setBlockState(world, Blocks.SPRUCE_TRAPDOOR.getDefaultState().with(HorizontalBlock.HORIZONTAL_FACING, Direction.EAST).with(TrapDoorBlock.HALF, Half.TOP).with(TrapDoorBlock.WATERLOGGED, false).with(TrapDoorBlock.POWERED, false).with(TrapDoorBlock.OPEN, true), 39, 8, 20, start);
        structure.setBlockState(world, Blocks.GRASS.getDefaultState(), 40, 5, 7, start);
        structure.setBlockState(world, Blocks.DIRT.getDefaultState(), 40, 5, 21, start);
        structure.setBlockState(world, Blocks.DIRT.getDefaultState(), 40, 5, 23, start);
        structure.setBlockState(world, Blocks.DIRT.getDefaultState(), 40, 5, 25, start);
        structure.setBlockState(world, Blocks.GRASS.getDefaultState(), 40, 6, 9, start);
        structure.setBlockState(world, Blocks.COBBLESTONE.getDefaultState(), 40, 6, 21, start);
        structure.setBlockState(world, Blocks.COBBLESTONE.getDefaultState(), 40, 6, 23, start);
        structure.setBlockState(world, Blocks.COBBLESTONE.getDefaultState(), 40, 6, 25, start);
        structure.setBlockState(world, Blocks.GRASS.getDefaultState(), 40, 6, 33, start);
        structure.setBlockState(world, Blocks.COBBLESTONE_SLAB.getDefaultState().with(SlabBlock.TYPE, SlabType.BOTTOM).with(SlabBlock.WATERLOGGED, false), 40, 7, 21, start);
        structure.setBlockState(world, Blocks.COBBLESTONE_SLAB.getDefaultState().with(SlabBlock.TYPE, SlabType.BOTTOM).with(SlabBlock.WATERLOGGED, false), 40, 7, 25, start);
        structure.setBlockState(world, Blocks.GRASS.getDefaultState(), 41, 6, 17, start);
        structure.setBlockState(world, Blocks.GRASS.getDefaultState(), 41, 6, 19, start);
        structure.setBlockState(world, Blocks.GRASS.getDefaultState(), 42, 5, 35, start);
        structure.setBlockState(world, Blocks.GRASS_BLOCK.getDefaultState().with(SnowyDirtBlock.SNOWY, false), 43, 1, 38, start);
        structure.setBlockState(world, Blocks.GRASS.getDefaultState(), 43, 5, 5, start);
        structure.setBlockState(world, Blocks.GRASS.getDefaultState(), 43, 6, 9, start);
        structure.setBlockState(world, Blocks.GRASS.getDefaultState(), 43, 6, 14, start);
        structure.setBlockState(world, Blocks.GRASS.getDefaultState(), 43, 6, 28, start);
        structure.setBlockState(world, Blocks.STONE.getDefaultState(), 44, 0, 31, start);
        structure.setBlockState(world, Blocks.GRASS_BLOCK.getDefaultState().with(SnowyDirtBlock.SNOWY, false), 44, 1, 3, start);
        structure.setBlockState(world, Blocks.GRASS_BLOCK.getDefaultState().with(SnowyDirtBlock.SNOWY, false), 44, 2, 37, start);
        structure.setBlockState(world, Blocks.GRASS_BLOCK.getDefaultState().with(SnowyDirtBlock.SNOWY, false), 44, 3, 36, start);
        structure.setBlockState(world, Blocks.GRASS.getDefaultState(), 44, 5, 33, start);
        structure.setBlockState(world, Blocks.GRASS.getDefaultState(), 44, 6, 26, start);
        structure.setBlockState(world, Blocks.GRASS_BLOCK.getDefaultState().with(SnowyDirtBlock.SNOWY, false), 45, 1, 37, start);
        structure.setBlockState(world, Blocks.GRASS_BLOCK.getDefaultState().with(SnowyDirtBlock.SNOWY, false), 45, 2, 36, start);
        structure.setBlockState(world, Blocks.DIRT.getDefaultState(), 45, 3, 34, start);
        structure.setBlockState(world, Blocks.GRASS_BLOCK.getDefaultState().with(SnowyDirtBlock.SNOWY, false), 45, 3, 35, start);
        structure.setBlockState(world, Blocks.GRASS.getDefaultState(), 45, 6, 17, start);
        structure.setBlockState(world, Blocks.GRASS.getDefaultState(), 45, 6, 19, start);
        structure.setBlockState(world, Blocks.GRASS.getDefaultState(), 45, 6, 23, start);
        structure.setBlockState(world, Blocks.GRASS_BLOCK.getDefaultState().with(SnowyDirtBlock.SNOWY, false), 46, 0, 37, start);
        structure.setBlockState(world, Blocks.GRASS_BLOCK.getDefaultState().with(SnowyDirtBlock.SNOWY, false), 46, 1, 36, start);
        structure.setBlockState(world, Blocks.GRASS_BLOCK.getDefaultState().with(SnowyDirtBlock.SNOWY, false), 46, 2, 35, start);
        structure.setBlockState(world, Blocks.GRASS_BLOCK.getDefaultState().with(SnowyDirtBlock.SNOWY, false), 46, 3, 34, start);
        structure.setBlockState(world, Blocks.GRASS.getDefaultState(), 46, 5, 13, start);
        structure.setBlockState(world, Blocks.GRASS.getDefaultState(), 46, 5, 22, start);
        structure.setBlockState(world, Blocks.GRASS.getDefaultState(), 46, 5, 29, start);
        structure.setBlockState(world, Blocks.GRASS.getDefaultState(), 46, 5, 32, start);
        structure.setBlockState(world, Blocks.GRASS_BLOCK.getDefaultState().with(SnowyDirtBlock.SNOWY, false), 47, 0, 36, start);
        structure.setBlockState(world, Blocks.GRASS_BLOCK.getDefaultState().with(SnowyDirtBlock.SNOWY, false), 47, 1, 35, start);
        structure.setBlockState(world, Blocks.GRASS_BLOCK.getDefaultState().with(SnowyDirtBlock.SNOWY, false), 47, 2, 34, start);
        structure.setBlockState(world, Blocks.GRASS.getDefaultState(), 47, 5, 16, start);
        structure.setBlockState(world, Blocks.GRASS_BLOCK.getDefaultState().with(SnowyDirtBlock.SNOWY, false), 48, 1, 33, start);
        structure.setBlockState(world, Blocks.GRASS_BLOCK.getDefaultState().with(SnowyDirtBlock.SNOWY, false), 48, 2, 32, start);
        structure.setBlockState(world, Blocks.GRASS.getDefaultState(), 48, 5, 14, start);
        structure.setBlockState(world, Blocks.GRASS_BLOCK.getDefaultState().with(SnowyDirtBlock.SNOWY, false), 49, 0, 33, start);
        structure.setBlockState(world, Blocks.GRASS_BLOCK.getDefaultState().with(SnowyDirtBlock.SNOWY, false), 49, 1, 7, start);
        structure.setBlockState(world, Blocks.GRASS_BLOCK.getDefaultState().with(SnowyDirtBlock.SNOWY, false), 50, 1, 21, start);
        structure.fillWithBlocks(world, start, 1, 0, 11, 1, 0, 25, Blocks.GRASS_BLOCK.getDefaultState().with(SnowyDirtBlock.SNOWY, false));
        structure.fillWithBlocks(world, start, 2, 0, 8, 2, 0, 9, Blocks.GRASS_BLOCK.getDefaultState().with(SnowyDirtBlock.SNOWY, false));
        structure.fillWithBlocks(world, start, 2, 0, 10, 3, 0, 28, Blocks.DIRT.getDefaultState());
        structure.fillWithBlocks(world, start, 2, 0, 29, 2, 0, 30, Blocks.GRASS_BLOCK.getDefaultState().with(SnowyDirtBlock.SNOWY, false));
        structure.fillWithBlocks(world, start, 2, 1, 10, 2, 1, 14, Blocks.GRASS_BLOCK.getDefaultState().with(SnowyDirtBlock.SNOWY, false));
        structure.fillWithBlocks(world, start, 2, 1, 15, 4, 1, 17, Blocks.DIRT.getDefaultState());
        structure.fillWithBlocks(world, start, 2, 1, 18, 2, 1, 22, Blocks.GRASS_BLOCK.getDefaultState().with(SnowyDirtBlock.SNOWY, false));
        structure.fillWithBlocks(world, start, 2, 1, 23, 3, 1, 24, Blocks.DIRT.getDefaultState());
        structure.fillWithBlocks(world, start, 2, 1, 25, 2, 1, 28, Blocks.GRASS_BLOCK.getDefaultState().with(SnowyDirtBlock.SNOWY, false));
        structure.fillWithBlocks(world, start, 2, 2, 15, 2, 2, 17, Blocks.GRASS_BLOCK.getDefaultState().with(SnowyDirtBlock.SNOWY, false));
        structure.fillWithBlocks(world, start, 2, 2, 23, 2, 2, 24, Blocks.GRASS_BLOCK.getDefaultState().with(SnowyDirtBlock.SNOWY, false));
        structure.fillWithBlocks(world, start, 3, 0, 6, 3, 0, 7, Blocks.GRASS_BLOCK.getDefaultState().with(SnowyDirtBlock.SNOWY, false));
        structure.fillWithBlocks(world, start, 3, 0, 8, 4, 0, 11, Blocks.DIRT.getDefaultState());
        structure.fillWithBlocks(world, start, 3, 0, 29, 5, 0, 31, Blocks.DIRT.getDefaultState());
        structure.fillWithBlocks(world, start, 3, 0, 32, 3, 0, 32, Blocks.GRASS_BLOCK.getDefaultState().with(SnowyDirtBlock.SNOWY, false));
        structure.fillWithBlocks(world, start, 3, 1, 8, 3, 1, 9, Blocks.GRASS_BLOCK.getDefaultState().with(SnowyDirtBlock.SNOWY, false));
        structure.fillWithBlocks(world, start, 3, 1, 10, 6, 1, 29, Blocks.DIRT.getDefaultState());
        structure.fillWithBlocks(world, start, 3, 1, 30, 3, 1, 31, Blocks.GRASS_BLOCK.getDefaultState().with(SnowyDirtBlock.SNOWY, false));
        structure.fillWithBlocks(world, start, 3, 2, 10, 3, 2, 11, Blocks.GRASS_BLOCK.getDefaultState().with(SnowyDirtBlock.SNOWY, false));
        structure.fillWithBlocks(world, start, 3, 2, 12, 10, 2, 28, Blocks.DIRT.getDefaultState());
        structure.fillWithBlocks(world, start, 3, 3, 12, 3, 3, 28, Blocks.GRASS_BLOCK.getDefaultState().with(SnowyDirtBlock.SNOWY, false));
        structure.fillWithBlocks(world, start, 4, 0, 6, 5, 0, 9, Blocks.DIRT.getDefaultState());
        structure.fillWithBlocks(world, start, 4, 0, 12, 6, 0, 14, Blocks.STONE.getDefaultState());
        structure.fillWithBlocks(world, start, 4, 0, 15, 4, 0, 32, Blocks.DIRT.getDefaultState());
        structure.fillWithBlocks(world, start, 4, 1, 6, 4, 1, 7, Blocks.GRASS_BLOCK.getDefaultState().with(SnowyDirtBlock.SNOWY, false));
        structure.fillWithBlocks(world, start, 4, 1, 8, 7, 1, 11, Blocks.DIRT.getDefaultState());
        structure.fillWithBlocks(world, start, 4, 1, 30, 5, 1, 31, Blocks.DIRT.getDefaultState());
        structure.fillWithBlocks(world, start, 4, 2, 9, 10, 2, 30, Blocks.DIRT.getDefaultState());
        structure.fillWithBlocks(world, start, 4, 3, 9, 4, 3, 11, Blocks.GRASS_BLOCK.getDefaultState().with(SnowyDirtBlock.SNOWY, false));
        structure.fillWithBlocks(world, start, 4, 3, 12, 10, 3, 29, Blocks.DIRT.getDefaultState());
        structure.fillWithBlocks(world, start, 4, 4, 12, 6, 4, 19, Blocks.GRASS_BLOCK.getDefaultState().with(SnowyDirtBlock.SNOWY, false));
        structure.fillWithBlocks(world, start, 4, 4, 20, 5, 4, 29, Blocks.GRASS_BLOCK.getDefaultState().with(SnowyDirtBlock.SNOWY, false));
        structure.fillWithBlocks(world, start, 5, 0, 4, 6, 0, 4, Blocks.GRASS_BLOCK.getDefaultState().with(SnowyDirtBlock.SNOWY, false));
        structure.fillWithBlocks(world, start, 5, 0, 5, 6, 0, 7, Blocks.DIRT.getDefaultState());
        structure.fillWithBlocks(world, start, 5, 0, 10, 10, 0, 15, Blocks.STONE.getDefaultState());
        structure.fillWithBlocks(world, start, 5, 0, 16, 5, 0, 34, Blocks.DIRT.getDefaultState());
        structure.fillWithBlocks(world, start, 5, 1, 5, 6, 1, 5, Blocks.GRASS_BLOCK.getDefaultState().with(SnowyDirtBlock.SNOWY, false));
        structure.fillWithBlocks(world, start, 5, 1, 6, 8, 1, 9, Blocks.DIRT.getDefaultState());
        structure.fillWithBlocks(world, start, 5, 1, 32, 6, 1, 33, Blocks.DIRT.getDefaultState());
        structure.fillWithBlocks(world, start, 5, 1, 34, 5, 1, 34, Blocks.GRASS_BLOCK.getDefaultState().with(SnowyDirtBlock.SNOWY, false));
        structure.fillWithBlocks(world, start, 5, 2, 6, 5, 2, 7, Blocks.GRASS_BLOCK.getDefaultState().with(SnowyDirtBlock.SNOWY, false));
        structure.fillWithBlocks(world, start, 5, 2, 8, 10, 2, 32, Blocks.DIRT.getDefaultState());
        structure.fillWithBlocks(world, start, 5, 2, 33, 5, 2, 33, Blocks.GRASS_BLOCK.getDefaultState().with(SnowyDirtBlock.SNOWY, false));
        structure.fillWithBlocks(world, start, 5, 3, 8, 5, 3, 9, Blocks.GRASS_BLOCK.getDefaultState().with(SnowyDirtBlock.SNOWY, false));
        structure.fillWithBlocks(world, start, 5, 3, 10, 10, 3, 31, Blocks.DIRT.getDefaultState());
        structure.fillWithBlocks(world, start, 5, 3, 32, 5, 3, 32, Blocks.GRASS_BLOCK.getDefaultState().with(SnowyDirtBlock.SNOWY, false));
        structure.fillWithBlocks(world, start, 5, 4, 10, 6, 4, 19, Blocks.GRASS_BLOCK.getDefaultState().with(SnowyDirtBlock.SNOWY, false));
