package mod.arcalitegames.odyssey.world.structure.structures.camps.outpost_camp;

import mod.arcalitegames.buildersaddition.Index;
import mod.arcalitegames.buildersaddition.blocks.Table;
import mod.arcalitegames.odyssey.world.structure.StructureBase;
import net.minecraft.block.AbstractFurnaceBlock;
import net.minecraft.block.BedBlock;
import net.minecraft.block.Blocks;
import net.minecraft.block.ChestBlock;
import net.minecraft.block.FourWayBlock;
import net.minecraft.block.HorizontalBlock;
import net.minecraft.block.SnowyDirtBlock;
import net.minecraft.block.StairsBlock;
import net.minecraft.block.WallBlock;
import net.minecraft.block.WallHeight;
import net.minecraft.block.WallTorchBlock;
import net.minecraft.state.properties.BedPart;
import net.minecraft.state.properties.ChestType;
import net.minecraft.state.properties.Half;
import net.minecraft.state.properties.StairsShape;
import net.minecraft.util.Direction;
import net.minecraft.util.math.BlockPos;
import net.minecraft.world.World;

public class OutpostComponents
{
	public static BlockPos start;
    public static World world;
    public static StructureBase structure;

    public static void init(World worldIn, BlockPos blockPos, StructureBase structureIn)
    {
        world = worldIn; start = blockPos; structure = structureIn;
    }
    
    public static void generatePart1()
    {
        structure.setBlockState(world, Blocks.GRASS_BLOCK.getDefaultState().with(SnowyDirtBlock.SNOWY, false), 2, 0, 11, start);
        structure.setBlockState(world, Blocks.GRASS_BLOCK.getDefaultState().with(SnowyDirtBlock.SNOWY, false), 3, 0, 9, start);
        structure.setBlockState(world, Blocks.GRASS_BLOCK.getDefaultState().with(SnowyDirtBlock.SNOWY, false), 3, 2, 12, start);
        structure.setBlockState(world, Blocks.GRASS_BLOCK.getDefaultState().with(SnowyDirtBlock.SNOWY, false), 4, 0, 8, start);
        structure.setBlockState(world, Blocks.GRASS_BLOCK.getDefaultState().with(SnowyDirtBlock.SNOWY, false), 4, 1, 9, start);
        structure.setBlockState(world, Blocks.GRASS_BLOCK.getDefaultState().with(SnowyDirtBlock.SNOWY, false), 4, 2, 10, start);
        structure.setBlockState(world, Blocks.GRASS_BLOCK.getDefaultState().with(SnowyDirtBlock.SNOWY, false), 4, 3, 11, start);
        structure.setBlockState(world, Blocks.GRASS_BLOCK.getDefaultState().with(SnowyDirtBlock.SNOWY, false), 5, 0, 7, start);
        structure.setBlockState(world, Blocks.GRASS_BLOCK.getDefaultState().with(SnowyDirtBlock.SNOWY, false), 5, 1, 42, start);
        structure.setBlockState(world, Blocks.GRASS_BLOCK.getDefaultState().with(SnowyDirtBlock.SNOWY, false), 5, 2, 8, start);
        structure.setBlockState(world, Blocks.GRASS_BLOCK.getDefaultState().with(SnowyDirtBlock.SNOWY, false), 5, 4, 11, start);
        structure.setBlockState(world, Blocks.GRASS_BLOCK.getDefaultState().with(SnowyDirtBlock.SNOWY, false), 6, 0, 6, start);
        structure.setBlockState(world, Blocks.GRASS_BLOCK.getDefaultState().with(SnowyDirtBlock.SNOWY, false), 6, 2, 7, start);
        structure.setBlockState(world, Blocks.GRASS_BLOCK.getDefaultState().with(SnowyDirtBlock.SNOWY, false), 6, 3, 8, start);
        structure.setBlockState(world, Blocks.GRASS_BLOCK.getDefaultState().with(SnowyDirtBlock.SNOWY, false), 6, 3, 41, start);
        structure.setBlockState(world, Blocks.GRASS_BLOCK.getDefaultState().with(SnowyDirtBlock.SNOWY, false), 7, 0, 5, start);
        structure.setBlockState(world, Blocks.GRASS_BLOCK.getDefaultState().with(SnowyDirtBlock.SNOWY, false), 7, 1, 6, start);
        structure.setBlockState(world, Blocks.GRASS_BLOCK.getDefaultState().with(SnowyDirtBlock.SNOWY, false), 7, 1, 45, start);
        structure.setBlockState(world, Blocks.GRASS_BLOCK.getDefaultState().with(SnowyDirtBlock.SNOWY, false), 7, 3, 7, start);
        structure.setBlockState(world, Blocks.GRASS_BLOCK.getDefaultState().with(SnowyDirtBlock.SNOWY, false), 7, 4, 8, start);
        structure.setBlockState(world, Blocks.GRASS_BLOCK.getDefaultState().with(SnowyDirtBlock.SNOWY, false), 7, 5, 11, start);
        structure.setBlockState(world, Blocks.GRASS_BLOCK.getDefaultState().with(SnowyDirtBlock.SNOWY, false), 8, 1, 5, start);
        structure.setBlockState(world, Blocks.GRASS_BLOCK.getDefaultState().with(SnowyDirtBlock.SNOWY, false), 8, 2, 6, start);
        structure.setBlockState(world, Blocks.GRASS_BLOCK.getDefaultState().with(SnowyDirtBlock.SNOWY, false), 8, 3, 44, start);
        structure.setBlockState(world, Blocks.GRASS_BLOCK.getDefaultState().with(SnowyDirtBlock.SNOWY, false), 9, 0, 4, start);
        structure.setBlockState(world, Blocks.GRASS_BLOCK.getDefaultState().with(SnowyDirtBlock.SNOWY, false), 9, 1, 46, start);
        structure.setBlockState(world, Blocks.GRASS_BLOCK.getDefaultState().with(SnowyDirtBlock.SNOWY, false), 9, 3, 6, start);
        structure.setBlockState(world, Blocks.GRASS_BLOCK.getDefaultState().with(SnowyDirtBlock.SNOWY, false), 10, 3, 45, start);
        structure.setBlockState(world, Blocks.GRASS.getDefaultState(), 13, 7, 12, start);
        structure.setBlockState(world, Blocks.OAK_LOG.getDefaultState(), 13, 10, 13, start);
        structure.setBlockState(world, Blocks.OAK_LOG.getDefaultState(), 13, 10, 15, start);
        structure.setBlockState(world, Blocks.OAK_LOG.getDefaultState(), 13, 10, 17, start);
        structure.setBlockState(world, Blocks.OAK_LOG.getDefaultState(), 13, 10, 19, start);
        structure.setBlockState(world, Blocks.OAK_LOG.getDefaultState(), 13, 10, 21, start);
        structure.setBlockState(world, Blocks.OAK_LOG.getDefaultState(), 13, 10, 23, start);
        structure.setBlockState(world, Blocks.OAK_LOG.getDefaultState(), 13, 10, 25, start);
        structure.setBlockState(world, Blocks.OAK_LOG.getDefaultState(), 13, 10, 27, start);
        structure.setBlockState(world, Blocks.OAK_LOG.getDefaultState(), 13, 10, 29, start);
        structure.setBlockState(world, Blocks.OAK_LOG.getDefaultState(), 13, 10, 31, start);
        structure.setBlockState(world, Blocks.OAK_LOG.getDefaultState(), 13, 10, 33, start);
        structure.setBlockState(world, Blocks.OAK_LOG.getDefaultState(), 13, 10, 35, start);
        structure.setBlockState(world, Blocks.OAK_LOG.getDefaultState(), 13, 10, 37, start);
        structure.setBlockState(world, Blocks.COBBLESTONE_WALL.getDefaultState().with(WallBlock.WATERLOGGED, false).with(WallBlock.UP, true).with(WallBlock.WALL_HEIGHT_NORTH, WallHeight.LOW).with(WallBlock.WALL_HEIGHT_SOUTH, WallHeight.LOW).with(WallBlock.WALL_HEIGHT_EAST, WallHeight.LOW).with(WallBlock.WALL_HEIGHT_WEST, WallHeight.LOW), 13, 11, 13, start);
        structure.setBlockState(world, Blocks.COBBLESTONE_WALL.getDefaultState().with(WallBlock.WATERLOGGED, false).with(WallBlock.UP, true).with(WallBlock.WALL_HEIGHT_NORTH, WallHeight.LOW).with(WallBlock.WALL_HEIGHT_SOUTH, WallHeight.LOW).with(WallBlock.WALL_HEIGHT_EAST, WallHeight.LOW).with(WallBlock.WALL_HEIGHT_WEST, WallHeight.LOW), 13, 11, 15, start);
        structure.setBlockState(world, Blocks.COBBLESTONE_WALL.getDefaultState().with(WallBlock.WATERLOGGED, false).with(WallBlock.UP, true).with(WallBlock.WALL_HEIGHT_NORTH, WallHeight.LOW).with(WallBlock.WALL_HEIGHT_SOUTH, WallHeight.LOW).with(WallBlock.WALL_HEIGHT_EAST, WallHeight.LOW).with(WallBlock.WALL_HEIGHT_WEST, WallHeight.LOW), 13, 11, 17, start);
        structure.setBlockState(world, Blocks.COBBLESTONE_WALL.getDefaultState().with(WallBlock.WATERLOGGED, false).with(WallBlock.UP, true).with(WallBlock.WALL_HEIGHT_NORTH, WallHeight.LOW).with(WallBlock.WALL_HEIGHT_SOUTH, WallHeight.LOW).with(WallBlock.WALL_HEIGHT_EAST, WallHeight.LOW).with(WallBlock.WALL_HEIGHT_WEST, WallHeight.LOW), 13, 11, 19, start);
        structure.setBlockState(world, Blocks.COBBLESTONE_WALL.getDefaultState().with(WallBlock.WATERLOGGED, false).with(WallBlock.UP, true).with(WallBlock.WALL_HEIGHT_NORTH, WallHeight.LOW).with(WallBlock.WALL_HEIGHT_SOUTH, WallHeight.LOW).with(WallBlock.WALL_HEIGHT_EAST, WallHeight.LOW).with(WallBlock.WALL_HEIGHT_WEST, WallHeight.LOW), 13, 11, 21, start);
        structure.setBlockState(world, Blocks.COBBLESTONE_WALL.getDefaultState().with(WallBlock.WATERLOGGED, false).with(WallBlock.UP, true).with(WallBlock.WALL_HEIGHT_NORTH, WallHeight.LOW).with(WallBlock.WALL_HEIGHT_SOUTH, WallHeight.LOW).with(WallBlock.WALL_HEIGHT_EAST, WallHeight.LOW).with(WallBlock.WALL_HEIGHT_WEST, WallHeight.LOW), 13, 11, 23, start);
        structure.setBlockState(world, Blocks.COBBLESTONE_WALL.getDefaultState().with(WallBlock.WATERLOGGED, false).with(WallBlock.UP, false).with(WallBlock.WALL_HEIGHT_NORTH, WallHeight.LOW).with(WallBlock.WALL_HEIGHT_SOUTH, WallHeight.LOW).with(WallBlock.WALL_HEIGHT_EAST, WallHeight.LOW).with(WallBlock.WALL_HEIGHT_WEST, WallHeight.LOW), 13, 11, 25, start);
        structure.setBlockState(world, Blocks.COBBLESTONE_WALL.getDefaultState().with(WallBlock.WATERLOGGED, false).with(WallBlock.UP, true).with(WallBlock.WALL_HEIGHT_NORTH, WallHeight.LOW).with(WallBlock.WALL_HEIGHT_SOUTH, WallHeight.LOW).with(WallBlock.WALL_HEIGHT_EAST, WallHeight.LOW).with(WallBlock.WALL_HEIGHT_WEST, WallHeight.LOW), 13, 11, 27, start);
        structure.setBlockState(world, Blocks.COBBLESTONE_WALL.getDefaultState().with(WallBlock.WATERLOGGED, false).with(WallBlock.UP, true).with(WallBlock.WALL_HEIGHT_NORTH, WallHeight.LOW).with(WallBlock.WALL_HEIGHT_SOUTH, WallHeight.LOW).with(WallBlock.WALL_HEIGHT_EAST, WallHeight.LOW).with(WallBlock.WALL_HEIGHT_WEST, WallHeight.LOW), 13, 11, 29, start);
        structure.setBlockState(world, Blocks.COBBLESTONE_WALL.getDefaultState().with(WallBlock.WATERLOGGED, false).with(WallBlock.UP, true).with(WallBlock.WALL_HEIGHT_NORTH, WallHeight.LOW).with(WallBlock.WALL_HEIGHT_SOUTH, WallHeight.LOW).with(WallBlock.WALL_HEIGHT_EAST, WallHeight.LOW).with(WallBlock.WALL_HEIGHT_WEST, WallHeight.LOW), 13, 11, 31, start);
        structure.setBlockState(world, Blocks.COBBLESTONE_WALL.getDefaultState().with(WallBlock.WATERLOGGED, false).with(WallBlock.UP, true).with(WallBlock.WALL_HEIGHT_NORTH, WallHeight.LOW).with(WallBlock.WALL_HEIGHT_SOUTH, WallHeight.LOW).with(WallBlock.WALL_HEIGHT_EAST, WallHeight.LOW).with(WallBlock.WALL_HEIGHT_WEST, WallHeight.LOW), 13, 11, 33, start);
        structure.setBlockState(world, Blocks.COBBLESTONE_WALL.getDefaultState().with(WallBlock.WATERLOGGED, false).with(WallBlock.UP, true).with(WallBlock.WALL_HEIGHT_NORTH, WallHeight.LOW).with(WallBlock.WALL_HEIGHT_SOUTH, WallHeight.LOW).with(WallBlock.WALL_HEIGHT_EAST, WallHeight.LOW).with(WallBlock.WALL_HEIGHT_WEST, WallHeight.LOW), 13, 11, 35, start);
        structure.setBlockState(world, Blocks.COBBLESTONE_WALL.getDefaultState().with(WallBlock.WATERLOGGED, false).with(WallBlock.UP, true).with(WallBlock.WALL_HEIGHT_NORTH, WallHeight.LOW).with(WallBlock.WALL_HEIGHT_SOUTH, WallHeight.LOW).with(WallBlock.WALL_HEIGHT_EAST, WallHeight.LOW).with(WallBlock.WALL_HEIGHT_WEST, WallHeight.LOW), 13, 11, 37, start);
        structure.setBlockState(world, Blocks.OAK_FENCE.getDefaultState().with(FourWayBlock.WATERLOGGED, false).with(FourWayBlock.NORTH, false).with(FourWayBlock.SOUTH, false).with(FourWayBlock.EAST, false).with(FourWayBlock.WEST, false), 13, 12, 13, start);
        structure.setBlockState(world, Blocks.OAK_FENCE.getDefaultState().with(FourWayBlock.WATERLOGGED, false).with(FourWayBlock.NORTH, false).with(FourWayBlock.SOUTH, false).with(FourWayBlock.EAST, false).with(FourWayBlock.WEST, false), 13, 12, 15, start);
        structure.setBlockState(world, Blocks.OAK_FENCE.getDefaultState().with(FourWayBlock.WATERLOGGED, false).with(FourWayBlock.NORTH, false).with(FourWayBlock.SOUTH, false).with(FourWayBlock.EAST, false).with(FourWayBlock.WEST, false), 13, 12, 17, start);
        structure.setBlockState(world, Blocks.OAK_FENCE.getDefaultState().with(FourWayBlock.WATERLOGGED, false).with(FourWayBlock.NORTH, false).with(FourWayBlock.SOUTH, false).with(FourWayBlock.EAST, false).with(FourWayBlock.WEST, false), 13, 12, 19, start);
        structure.setBlockState(world, Blocks.OAK_FENCE.getDefaultState().with(FourWayBlock.WATERLOGGED, false).with(FourWayBlock.NORTH, false).with(FourWayBlock.SOUTH, false).with(FourWayBlock.EAST, false).with(FourWayBlock.WEST, false), 13, 12, 21, start);
        structure.setBlockState(world, Blocks.OAK_FENCE.getDefaultState().with(FourWayBlock.WATERLOGGED, false).with(FourWayBlock.NORTH, false).with(FourWayBlock.SOUTH, false).with(FourWayBlock.EAST, false).with(FourWayBlock.WEST, false), 13, 12, 23, start);
        structure.setBlockState(world, Blocks.OAK_FENCE.getDefaultState().with(FourWayBlock.WATERLOGGED, false).with(FourWayBlock.NORTH, false).with(FourWayBlock.SOUTH, false).with(FourWayBlock.EAST, false).with(FourWayBlock.WEST, false), 13, 12, 25, start);
        structure.setBlockState(world, Blocks.OAK_FENCE.getDefaultState().with(FourWayBlock.WATERLOGGED, false).with(FourWayBlock.NORTH, false).with(FourWayBlock.SOUTH, false).with(FourWayBlock.EAST, false).with(FourWayBlock.WEST, false), 13, 12, 27, start);
        structure.setBlockState(world, Blocks.OAK_FENCE.getDefaultState().with(FourWayBlock.WATERLOGGED, false).with(FourWayBlock.NORTH, false).with(FourWayBlock.SOUTH, false).with(FourWayBlock.EAST, false).with(FourWayBlock.WEST, false), 13, 12, 29, start);
        structure.setBlockState(world, Blocks.OAK_FENCE.getDefaultState().with(FourWayBlock.WATERLOGGED, false).with(FourWayBlock.NORTH, false).with(FourWayBlock.SOUTH, false).with(FourWayBlock.EAST, false).with(FourWayBlock.WEST, false), 13, 12, 31, start);
        structure.setBlockState(world, Blocks.OAK_FENCE.getDefaultState().with(FourWayBlock.WATERLOGGED, false).with(FourWayBlock.NORTH, false).with(FourWayBlock.SOUTH, false).with(FourWayBlock.EAST, false).with(FourWayBlock.WEST, false), 13, 12, 33, start);
        structure.setBlockState(world, Blocks.OAK_FENCE.getDefaultState().with(FourWayBlock.WATERLOGGED, false).with(FourWayBlock.NORTH, false).with(FourWayBlock.SOUTH, false).with(FourWayBlock.EAST, false).with(FourWayBlock.WEST, false), 13, 12, 35, start);
        structure.setBlockState(world, Blocks.OAK_FENCE.getDefaultState().with(FourWayBlock.WATERLOGGED, false).with(FourWayBlock.NORTH, false).with(FourWayBlock.SOUTH, false).with(FourWayBlock.EAST, false).with(FourWayBlock.WEST, false), 13, 12, 37, start);
        structure.setBlockState(world, Blocks.TALL_GRASS.getDefaultState(), 14, 7, 14, start);
        structure.setBlockState(world, Blocks.POPPY.getDefaultState(), 14, 7, 20, start);
        structure.setBlockState(world, Blocks.DANDELION.getDefaultState(), 14, 7, 21, start);
        structure.setBlockState(world, Blocks.GRASS.getDefaultState(), 14, 7, 32, start);
        structure.setBlockState(world, Blocks.DIRT.getDefaultState(), 15, 6, 24, start);
        structure.setBlockState(world, Blocks.DIRT.getDefaultState(), 15, 6, 26, start);
        structure.setBlockState(world, Blocks.TALL_GRASS.getDefaultState(), 15, 7, 17, start);
        structure.setBlockState(world, Blocks.OAK_FENCE.getDefaultState().with(FourWayBlock.WATERLOGGED, false).with(FourWayBlock.NORTH, true).with(FourWayBlock.SOUTH, true).with(FourWayBlock.EAST, false).with(FourWayBlock.WEST, false), 15, 7, 25, start);
        structure.setBlockState(world, Blocks.ORANGE_TULIP.getDefaultState(), 15, 7, 32, start);
        structure.setBlockState(world, Blocks.GRASS.getDefaultState(), 15, 7, 34, start);
        structure.setBlockState(world, Blocks.OAK_LOG.getDefaultState(), 15, 10, 13, start);
        structure.setBlockState(world, Blocks.OAK_LOG.getDefaultState(), 15, 10, 37, start);
        structure.setBlockState(world, Blocks.COBBLESTONE_WALL.getDefaultState().with(WallBlock.WATERLOGGED, false).with(WallBlock.UP, true).with(WallBlock.WALL_HEIGHT_NORTH, WallHeight.LOW).with(WallBlock.WALL_HEIGHT_SOUTH, WallHeight.LOW).with(WallBlock.WALL_HEIGHT_EAST, WallHeight.LOW).with(WallBlock.WALL_HEIGHT_WEST, WallHeight.LOW), 15, 11, 13, start);
        structure.setBlockState(world, Blocks.COBBLESTONE_WALL.getDefaultState().with(WallBlock.WATERLOGGED, false).with(WallBlock.UP, true).with(WallBlock.WALL_HEIGHT_NORTH, WallHeight.LOW).with(WallBlock.WALL_HEIGHT_SOUTH, WallHeight.LOW).with(WallBlock.WALL_HEIGHT_EAST, WallHeight.LOW).with(WallBlock.WALL_HEIGHT_WEST, WallHeight.LOW), 15, 11, 37, start);
        structure.setBlockState(world, Blocks.OAK_FENCE.getDefaultState().with(FourWayBlock.WATERLOGGED, false).with(FourWayBlock.NORTH, false).with(FourWayBlock.SOUTH, false).with(FourWayBlock.EAST, false).with(FourWayBlock.WEST, false), 15, 12, 13, start);
        structure.setBlockState(world, Blocks.OAK_FENCE.getDefaultState().with(FourWayBlock.WATERLOGGED, false).with(FourWayBlock.NORTH, false).with(FourWayBlock.SOUTH, false).with(FourWayBlock.EAST, false).with(FourWayBlock.WEST, false), 15, 12, 37, start);
        structure.setBlockState(world, Blocks.STONE.getDefaultState(), 16, 1, 15, start);
        structure.setBlockState(world, Blocks.DIRT.getDefaultState(), 16, 6, 21, start);
        structure.setBlockState(world, Blocks.POPPY.getDefaultState(), 16, 7, 14, start);
        structure.setBlockState(world, Blocks.OAK_FENCE.getDefaultState().with(FourWayBlock.WATERLOGGED, false).with(FourWayBlock.NORTH, true).with(FourWayBlock.SOUTH, true).with(FourWayBlock.EAST, false).with(FourWayBlock.WEST, false), 16, 7, 22, start);
        structure.setBlockState(world, Blocks.CRAFTING_TABLE.getDefaultState(), 16, 7, 24, start);
        structure.setBlockState(world, Blocks.CRAFTING_TABLE.getDefaultState(), 16, 7, 26, start);
        structure.setBlockState(world, Blocks.OAK_FENCE.getDefaultState().with(FourWayBlock.WATERLOGGED, false).with(FourWayBlock.NORTH, false).with(FourWayBlock.SOUTH, false).with(FourWayBlock.EAST, false).with(FourWayBlock.WEST, false), 16, 7, 28, start);
        structure.setBlockState(world, Blocks.OAK_FENCE.getDefaultState().with(FourWayBlock.WATERLOGGED, false).with(FourWayBlock.NORTH, true).with(FourWayBlock.SOUTH, false).with(FourWayBlock.EAST, false).with(FourWayBlock.WEST, false), 16, 8, 22, start);
        structure.setBlockState(world, Blocks.OAK_FENCE.getDefaultState().with(FourWayBlock.WATERLOGGED, false).with(FourWayBlock.NORTH, true).with(FourWayBlock.SOUTH, true).with(FourWayBlock.EAST, false).with(FourWayBlock.WEST, false), 16, 8, 28, start);
        structure.setBlockState(world, Blocks.GRASS.getDefaultState(), 17, 7, 14, start);
        structure.setBlockState(world, Blocks.OAK_LOG.getDefaultState(), 17, 10, 13, start);
        structure.setBlockState(world, Blocks.OAK_LOG.getDefaultState(), 17, 10, 37, start);
        structure.setBlockState(world, Blocks.COBBLESTONE_WALL.getDefaultState().with(WallBlock.WATERLOGGED, false).with(WallBlock.UP, true).with(WallBlock.WALL_HEIGHT_NORTH, WallHeight.LOW).with(WallBlock.WALL_HEIGHT_SOUTH, WallHeight.LOW).with(WallBlock.WALL_HEIGHT_EAST, WallHeight.LOW).with(WallBlock.WALL_HEIGHT_WEST, WallHeight.LOW), 17, 11, 13, start);
        structure.setBlockState(world, Blocks.COBBLESTONE_WALL.getDefaultState().with(WallBlock.WATERLOGGED, false).with(WallBlock.UP, true).with(WallBlock.WALL_HEIGHT_NORTH, WallHeight.LOW).with(WallBlock.WALL_HEIGHT_SOUTH, WallHeight.LOW).with(WallBlock.WALL_HEIGHT_EAST, WallHeight.LOW).with(WallBlock.WALL_HEIGHT_WEST, WallHeight.LOW), 17, 11, 37, start);
        structure.setBlockState(world, Blocks.OAK_FENCE.getDefaultState().with(FourWayBlock.WATERLOGGED, false).with(FourWayBlock.NORTH, false).with(FourWayBlock.SOUTH, false).with(FourWayBlock.EAST, false).with(FourWayBlock.WEST, false), 17, 12, 13, start);
        structure.setBlockState(world, Blocks.OAK_FENCE.getDefaultState().with(FourWayBlock.WATERLOGGED, false).with(FourWayBlock.NORTH, false).with(FourWayBlock.SOUTH, false).with(FourWayBlock.EAST, false).with(FourWayBlock.WEST, false), 17, 12, 37, start);
        structure.setBlockState(world, Blocks.GRASS_BLOCK.getDefaultState().with(SnowyDirtBlock.SNOWY, false), 18, 6, 17, start);
        structure.setBlockState(world, Blocks.DIRT.getDefaultState(), 18, 6, 18, start);
        structure.setBlockState(world, Blocks.OXEYE_DAISY.getDefaultState(), 18, 7, 14, start);
        structure.setBlockState(world, Blocks.POPPY.getDefaultState(), 18, 7, 15, start);
        structure.setBlockState(world, Blocks.GRASS.getDefaultState(), 18, 7, 17, start);
        structure.setBlockState(world, Blocks.AIR.getDefaultState(), 18, 7, 25, start);
        structure.setBlockState(world, Blocks.AZURE_BLUET.getDefaultState(), 19, 7, 35, start);
        structure.setBlockState(world, Blocks.OAK_LOG.getDefaultState(), 19, 10, 13, start);
        structure.setBlockState(world, Blocks.OAK_LOG.getDefaultState(), 19, 10, 37, start);
        structure.setBlockState(world, Blocks.COBBLESTONE_WALL.getDefaultState().with(WallBlock.WATERLOGGED, false).with(WallBlock.UP, true).with(WallBlock.WALL_HEIGHT_NORTH, WallHeight.LOW).with(WallBlock.WALL_HEIGHT_SOUTH, WallHeight.LOW).with(WallBlock.WALL_HEIGHT_EAST, WallHeight.LOW).with(WallBlock.WALL_HEIGHT_WEST, WallHeight.LOW), 19, 11, 13, start);
        structure.setBlockState(world, Blocks.COBBLESTONE_WALL.getDefaultState().with(WallBlock.WATERLOGGED, false).with(WallBlock.UP, true).with(WallBlock.WALL_HEIGHT_NORTH, WallHeight.LOW).with(WallBlock.WALL_HEIGHT_SOUTH, WallHeight.LOW).with(WallBlock.WALL_HEIGHT_EAST, WallHeight.LOW).with(WallBlock.WALL_HEIGHT_WEST, WallHeight.LOW), 19, 11, 37, start);
        structure.setBlockState(world, Blocks.OAK_FENCE.getDefaultState().with(FourWayBlock.WATERLOGGED, false).with(FourWayBlock.NORTH, false).with(FourWayBlock.SOUTH, false).with(FourWayBlock.EAST, false).with(FourWayBlock.WEST, false), 19, 12, 13, start);
        structure.setBlockState(world, Blocks.OAK_FENCE.getDefaultState().with(FourWayBlock.WATERLOGGED, false).with(FourWayBlock.NORTH, false).with(FourWayBlock.SOUTH, false).with(FourWayBlock.EAST, false).with(FourWayBlock.WEST, false), 19, 12, 37, start);
        structure.setBlockState(world, Blocks.DIRT.getDefaultState(), 21, 6, 16, start);
        structure.setBlockState(world, Blocks.DIRT.getDefaultState(), 21, 6, 34, start);
        structure.setBlockState(world, Blocks.RED_TULIP.getDefaultState(), 21, 7, 12, start);
        structure.setBlockState(world, Blocks.CRAFTING_TABLE.getDefaultState(), 21, 7, 17, start);
        structure.setBlockState(world, Blocks.OAK_FENCE.getDefaultState().with(FourWayBlock.WATERLOGGED, false).with(FourWayBlock.NORTH, false).with(FourWayBlock.SOUTH, false).with(FourWayBlock.EAST, true).with(FourWayBlock.WEST, false), 21, 7, 25, start);
        structure.setBlockState(world, Index.TABLE_OAK.getDefaultState().with(Table.NE, false).with(Table.NW, true).with(Table.SE, false).with(Table.SW, false), 21, 7, 28, start);
        structure.setBlockState(world, Index.TABLE_OAK.getDefaultState().with(Table.NE, false).with(Table.NW, false).with(Table.SE, false).with(Table.SW, true), 21, 7, 29, start);
        structure.setBlockState(world, Blocks.CRAFTING_TABLE.getDefaultState(), 21, 7, 33, start);
        structure.setBlockState(world, Blocks.OAK_LOG.getDefaultState(), 21, 10, 13, start);
        structure.setBlockState(world, Blocks.OAK_LOG.getDefaultState(), 21, 10, 37, start);
        structure.setBlockState(world, Blocks.COBBLESTONE_WALL.getDefaultState().with(WallBlock.WATERLOGGED, false).with(WallBlock.UP, true).with(WallBlock.WALL_HEIGHT_NORTH, WallHeight.LOW).with(WallBlock.WALL_HEIGHT_SOUTH, WallHeight.LOW).with(WallBlock.WALL_HEIGHT_EAST, WallHeight.LOW).with(WallBlock.WALL_HEIGHT_WEST, WallHeight.LOW), 21, 11, 13, start);
        structure.setBlockState(world, Blocks.OAK_FENCE.getDefaultState().with(FourWayBlock.WATERLOGGED, false).with(FourWayBlock.NORTH, false).with(FourWayBlock.SOUTH, false).with(FourWayBlock.EAST, true).with(FourWayBlock.WEST, false), 21, 11, 25, start);
        structure.setBlockState(world, Blocks.COBBLESTONE_WALL.getDefaultState().with(WallBlock.WATERLOGGED, false).with(WallBlock.UP, true).with(WallBlock.WALL_HEIGHT_NORTH, WallHeight.LOW).with(WallBlock.WALL_HEIGHT_SOUTH, WallHeight.LOW).with(WallBlock.WALL_HEIGHT_EAST, WallHeight.LOW).with(WallBlock.WALL_HEIGHT_WEST, WallHeight.LOW), 21, 11, 37, start);
        structure.setBlockState(world, Blocks.OAK_FENCE.getDefaultState().with(FourWayBlock.WATERLOGGED, false).with(FourWayBlock.NORTH, false).with(FourWayBlock.SOUTH, false).with(FourWayBlock.EAST, false).with(FourWayBlock.WEST, false), 21, 12, 13, start);
        structure.setBlockState(world, Blocks.OAK_FENCE.getDefaultState().with(FourWayBlock.WATERLOGGED, false).with(FourWayBlock.NORTH, false).with(FourWayBlock.SOUTH, false).with(FourWayBlock.EAST, false).with(FourWayBlock.WEST, false), 21, 12, 37, start);
        structure.setBlockState(world, Blocks.DIRT.getDefaultState(), 22, 6, 25, start);
        structure.setBlockState(world, Blocks.GRAVEL.getDefaultState(), 22, 6, 34, start);
        structure.setBlockState(world, Blocks.OXEYE_DAISY.getDefaultState(), 22, 7, 12, start);
        structure.setBlockState(world, Blocks.AIR.getDefaultState(), 22, 7, 19, start);
        structure.setBlockState(world, Blocks.OAK_FENCE.getDefaultState().with(FourWayBlock.WATERLOGGED, false).with(FourWayBlock.NORTH, false).with(FourWayBlock.SOUTH, true).with(FourWayBlock.EAST, false).with(FourWayBlock.WEST, false), 22, 7, 24, start);
        structure.setBlockState(world, Blocks.OAK_FENCE.getDefaultState().with(FourWayBlock.WATERLOGGED, false).with(FourWayBlock.NORTH, true).with(FourWayBlock.SOUTH, false).with(FourWayBlock.EAST, false).with(FourWayBlock.WEST, false), 22, 7, 26, start);
        structure.setBlockState(world, Blocks.AIR.getDefaultState(), 22, 7, 31, start);
        structure.setBlockState(world, Blocks.OAK_FENCE.getDefaultState().with(FourWayBlock.WATERLOGGED, false).with(FourWayBlock.NORTH, false).with(FourWayBlock.SOUTH, false).with(FourWayBlock.EAST, true).with(FourWayBlock.WEST, true), 22, 7, 34, start);
        structure.setBlockState(world, Blocks.TORCH.getDefaultState(), 22, 8, 26, start);
        structure.setBlockState(world, Blocks.OAK_FENCE.getDefaultState().with(FourWayBlock.WATERLOGGED, false).with(FourWayBlock.NORTH, false).with(FourWayBlock.SOUTH, false).with(FourWayBlock.EAST, true).with(FourWayBlock.WEST, false), 22, 8, 34, start);
        structure.setBlockState(world, Blocks.OAK_FENCE.getDefaultState().with(FourWayBlock.WATERLOGGED, false).with(FourWayBlock.NORTH, false).with(FourWayBlock.SOUTH, false).with(FourWayBlock.EAST, false).with(FourWayBlock.WEST, false), 22, 11, 24, start);
        structure.setBlockState(world, Blocks.OAK_FENCE.getDefaultState().with(FourWayBlock.WATERLOGGED, false).with(FourWayBlock.NORTH, true).with(FourWayBlock.SOUTH, false).with(FourWayBlock.EAST, false).with(FourWayBlock.WEST, false), 22, 11, 26, start);
        structure.setBlockState(world, Blocks.WHITE_WOOL.getDefaultState(), 22, 11, 33, start);
        structure.setBlockState(world, Blocks.OAK_FENCE.getDefaultState().with(FourWayBlock.WATERLOGGED, false).with(FourWayBlock.NORTH, true).with(FourWayBlock.SOUTH, true).with(FourWayBlock.EAST, true).with(FourWayBlock.WEST, false), 22, 12, 21, start);
        structure.setBlockState(world, Blocks.OAK_FENCE.getDefaultState().with(FourWayBlock.WATERLOGGED, false).with(FourWayBlock.NORTH, true).with(FourWayBlock.SOUTH, true).with(FourWayBlock.EAST, true).with(FourWayBlock.WEST, true), 22, 12, 29, start);
        structure.setBlockState(world, Blocks.OAK_FENCE.getDefaultState().with(FourWayBlock.WATERLOGGED, false).with(FourWayBlock.NORTH, true).with(FourWayBlock.SOUTH, true).with(FourWayBlock.EAST, false).with(FourWayBlock.WEST, true), 22, 13, 23, start);
        structure.setBlockState(world, Blocks.OAK_FENCE.getDefaultState().with(FourWayBlock.WATERLOGGED, false).with(FourWayBlock.NORTH, true).with(FourWayBlock.SOUTH, true).with(FourWayBlock.EAST, true).with(FourWayBlock.WEST, true), 22, 13, 24, start);
        structure.setBlockState(world, Blocks.OAK_FENCE.getDefaultState().with(FourWayBlock.WATERLOGGED, false).with(FourWayBlock.NORTH, true).with(FourWayBlock.SOUTH, true).with(FourWayBlock.EAST, true).with(FourWayBlock.WEST, true), 22, 13, 26, start);
        structure.setBlockState(world, Blocks.OAK_FENCE.getDefaultState().with(FourWayBlock.WATERLOGGED, false).with(FourWayBlock.NORTH, true).with(FourWayBlock.SOUTH, false).with(FourWayBlock.EAST, false).with(FourWayBlock.WEST, false), 22, 13, 27, start);
        structure.setBlockState(world, Blocks.DIRT.getDefaultState(), 23, 6, 16, start);
        structure.setBlockState(world, Blocks.DIRT.getDefaultState(), 23, 6, 34, start);
        structure.setBlockState(world, Blocks.CRAFTING_TABLE.getDefaultState(), 23, 7, 17, start);
        structure.setBlockState(world, Blocks.OAK_FENCE.getDefaultState().with(FourWayBlock.WATERLOGGED, false).with(FourWayBlock.NORTH, false).with(FourWayBlock.SOUTH, false).with(FourWayBlock.EAST, false).with(FourWayBlock.WEST, true), 23, 7, 25, start);
        structure.setBlockState(world, Index.TABLE_OAK.getDefaultState().with(Table.NE, true).with(Table.NW, false).with(Table.SE, false).with(Table.SW, false), 23, 7, 28, start);
        structure.setBlockState(world, Index.TABLE_OAK.getDefaultState().with(Table.NE, false).with(Table.NW, false).with(Table.SE, true).with(Table.SW, false), 23, 7, 29, start);
        structure.setBlockState(world, Blocks.CRAFTING_TABLE.getDefaultState(), 23, 7, 33, start);
        structure.setBlockState(world, Blocks.TORCH.getDefaultState(), 23, 8, 25, start);
        structure.setBlockState(world, Blocks.OAK_LOG.getDefaultState(), 23, 10, 13, start);
        structure.setBlockState(world, Blocks.OAK_LOG.getDefaultState(), 23, 10, 37, start);
        structure.setBlockState(world, Blocks.COBBLESTONE_WALL.getDefaultState().with(WallBlock.WATERLOGGED, false).with(WallBlock.UP, true).with(WallBlock.WALL_HEIGHT_NORTH, WallHeight.LOW).with(WallBlock.WALL_HEIGHT_SOUTH, WallHeight.LOW).with(WallBlock.WALL_HEIGHT_EAST, WallHeight.LOW).with(WallBlock.WALL_HEIGHT_WEST, WallHeight.LOW), 23, 11, 13, start);
        structure.setBlockState(world, Blocks.OAK_FENCE.getDefaultState().with(FourWayBlock.WATERLOGGED, false).with(FourWayBlock.NORTH, false).with(FourWayBlock.SOUTH, false).with(FourWayBlock.EAST, false).with(FourWayBlock.WEST, true), 23, 11, 25, start);
        structure.setBlockState(world, Blocks.COBBLESTONE_WALL.getDefaultState().with(WallBlock.WATERLOGGED, false).with(WallBlock.UP, true).with(WallBlock.WALL_HEIGHT_NORTH, WallHeight.LOW).with(WallBlock.WALL_HEIGHT_SOUTH, WallHeight.LOW).with(WallBlock.WALL_HEIGHT_EAST, WallHeight.LOW).with(WallBlock.WALL_HEIGHT_WEST, WallHeight.LOW), 23, 11, 37, start);
        structure.setBlockState(world, Blocks.OAK_FENCE.getDefaultState().with(FourWayBlock.WATERLOGGED, false).with(FourWayBlock.NORTH, false).with(FourWayBlock.SOUTH, false).with(FourWayBlock.EAST, false).with(FourWayBlock.WEST, false), 23, 12, 13, start);
        structure.setBlockState(world, Blocks.OAK_FENCE.getDefaultState().with(FourWayBlock.WATERLOGGED, false).with(FourWayBlock.NORTH, false).with(FourWayBlock.SOUTH, false).with(FourWayBlock.EAST, false).with(FourWayBlock.WEST, false), 23, 12, 37, start);
        structure.setBlockState(world, Blocks.OAK_FENCE.getDefaultState().with(FourWayBlock.WATERLOGGED, false).with(FourWayBlock.NORTH, false).with(FourWayBlock.SOUTH, true).with(FourWayBlock.EAST, false).with(FourWayBlock.WEST, false), 23, 13, 25, start);
        structure.setBlockState(world, Blocks.WHITE_WOOL.getDefaultState(), 23, 14, 25, start);
        structure.setBlockState(world, Blocks.GRASS.getDefaultState(), 24, 7, 14, start);
        structure.setBlockState(world, Blocks.PINK_TULIP.getDefaultState(), 25, 7, 12, start);
        structure.setBlockState(world, Blocks.POPPY.getDefaultState(), 25, 7, 14, start);
        structure.setBlockState(world, Blocks.OAK_LOG.getDefaultState(), 25, 10, 13, start);
        structure.setBlockState(world, Blocks.OAK_LOG.getDefaultState(), 25, 10, 37, start);
        structure.setBlockState(world, Blocks.COBBLESTONE_WALL.getDefaultState().with(WallBlock.WATERLOGGED, false).with(WallBlock.UP, true).with(WallBlock.WALL_HEIGHT_NORTH, WallHeight.LOW).with(WallBlock.WALL_HEIGHT_SOUTH, WallHeight.LOW).with(WallBlock.WALL_HEIGHT_EAST, WallHeight.LOW).with(WallBlock.WALL_HEIGHT_WEST, WallHeight.LOW), 25, 11, 13, start);
        structure.setBlockState(world, Blocks.COBBLESTONE_WALL.getDefaultState().with(WallBlock.WATERLOGGED, false).with(WallBlock.UP, true).with(WallBlock.WALL_HEIGHT_NORTH, WallHeight.LOW).with(WallBlock.WALL_HEIGHT_SOUTH, WallHeight.LOW).with(WallBlock.WALL_HEIGHT_EAST, WallHeight.LOW).with(WallBlock.WALL_HEIGHT_WEST, WallHeight.LOW), 25, 11, 37, start);
        structure.setBlockState(world, Blocks.OAK_FENCE.getDefaultState().with(FourWayBlock.WATERLOGGED, false).with(FourWayBlock.NORTH, false).with(FourWayBlock.SOUTH, false).with(FourWayBlock.EAST, false).with(FourWayBlock.WEST, false), 25, 12, 13, start);
        structure.setBlockState(world, Blocks.OAK_FENCE.getDefaultState().with(FourWayBlock.WATERLOGGED, false).with(FourWayBlock.NORTH, false).with(FourWayBlock.SOUTH, false).with(FourWayBlock.EAST, false).with(FourWayBlock.WEST, false), 25, 12, 37, start);
        structure.setBlockState(world, Blocks.WHITE_WOOL.getDefaultState(), 25, 13, 25, start);
        structure.setBlockState(world, Blocks.DIRT.getDefaultState(), 26, 6, 32, start);
        structure.setBlockState(world, Blocks.AIR.getDefaultState(), 26, 7, 19, start);
        structure.setBlockState(world, Blocks.CHEST.getDefaultState().with(ChestBlock.FACING, Direction.WEST).with(ChestBlock.WATERLOGGED, false).with(ChestBlock.TYPE, ChestType.SINGLE), 26, 7, 30, start);
        structure.setBlockState(world, Blocks.AIR.getDefaultState(), 26, 7, 31, start);
        structure.setBlockState(world, Blocks.GRASS.getDefaultState(), 26, 7, 33, start);
        structure.setBlockState(world, Blocks.WHITE_WOOL.getDefaultState(), 26, 12, 25, start);
        structure.setBlockState(world, Blocks.GRASS.getDefaultState(), 27, 7, 12, start);
        structure.setBlockState(world, Blocks.GRASS.getDefaultState(), 27, 7, 16, start);
        structure.setBlockState(world, Blocks.CHEST.getDefaultState().with(ChestBlock.FACING, Direction.WEST).with(ChestBlock.WATERLOGGED, false).with(ChestBlock.TYPE, ChestType.SINGLE), 27, 7, 21, start);
        structure.setBlockState(world, Blocks.CHEST.getDefaultState().with(ChestBlock.FACING, Direction.WEST).with(ChestBlock.WATERLOGGED, false).with(ChestBlock.TYPE, ChestType.SINGLE), 27, 7, 29, start);
        structure.setBlockState(world, Blocks.GRASS.getDefaultState(), 27, 7, 32, start);
        structure.setBlockState(world, Blocks.AZURE_BLUET.getDefaultState(), 27, 7, 33, start);
        structure.setBlockState(world, Blocks.OAK_LOG.getDefaultState(), 27, 10, 13, start);
        structure.setBlockState(world, Blocks.OAK_LOG.getDefaultState(), 27, 10, 37, start);
        structure.setBlockState(world, Blocks.COBBLESTONE_WALL.getDefaultState().with(WallBlock.WATERLOGGED, false).with(WallBlock.UP, true).with(WallBlock.WALL_HEIGHT_NORTH, WallHeight.LOW).with(WallBlock.WALL_HEIGHT_SOUTH, WallHeight.LOW).with(WallBlock.WALL_HEIGHT_EAST, WallHeight.LOW).with(WallBlock.WALL_HEIGHT_WEST, WallHeight.LOW), 27, 11, 13, start);
        structure.setBlockState(world, Blocks.WHITE_WOOL.getDefaultState(), 27, 11, 25, start);
        structure.setBlockState(world, Blocks.COBBLESTONE_WALL.getDefaultState().with(WallBlock.WATERLOGGED, false).with(WallBlock.UP, true).with(WallBlock.WALL_HEIGHT_NORTH, WallHeight.LOW).with(WallBlock.WALL_HEIGHT_SOUTH, WallHeight.LOW).with(WallBlock.WALL_HEIGHT_EAST, WallHeight.LOW).with(WallBlock.WALL_HEIGHT_WEST, WallHeight.LOW), 27, 11, 37, start);
        structure.setBlockState(world, Blocks.OAK_FENCE.getDefaultState().with(FourWayBlock.WATERLOGGED, false).with(FourWayBlock.NORTH, false).with(FourWayBlock.SOUTH, false).with(FourWayBlock.EAST, false).with(FourWayBlock.WEST, false), 27, 12, 13, start);
        structure.setBlockState(world, Blocks.OAK_FENCE.getDefaultState().with(FourWayBlock.WATERLOGGED, false).with(FourWayBlock.NORTH, false).with(FourWayBlock.SOUTH, false).with(FourWayBlock.EAST, false).with(FourWayBlock.WEST, false), 27, 12, 37, start);
        structure.setBlockState(world, Blocks.DIRT.getDefaultState(), 28, 6, 21, start);
        structure.setBlockState(world, Blocks.GRAVEL.getDefaultState(), 28, 6, 22, start);
        structure.setBlockState(world, Blocks.DIRT.getDefaultState(), 28, 6, 23, start);
        structure.setBlockState(world, Blocks.DIRT.getDefaultState(), 28, 6, 27, start);
        structure.setBlockState(world, Blocks.GRAVEL.getDefaultState(), 28, 6, 28, start);
        structure.setBlockState(world, Blocks.DIRT.getDefaultState(), 28, 6, 29, start);
        structure.setBlockState(world, Blocks.DANDELION.getDefaultState(), 28, 7, 12, start);
        structure.setBlockState(world, Blocks.GRASS.getDefaultState(), 28, 7, 20, start);
        structure.setBlockState(world, Blocks.OAK_FENCE.getDefaultState().with(FourWayBlock.WATERLOGGED, false).with(FourWayBlock.NORTH, false).with(FourWayBlock.SOUTH, true).with(FourWayBlock.EAST, false).with(FourWayBlock.WEST, false), 28, 7, 22, start);
        structure.setBlockState(world, Blocks.DANDELION.getDefaultState(), 28, 7, 32, start);
        structure.setBlockState(world, Blocks.GRASS.getDefaultState(), 28, 7, 35, start);
        structure.setBlockState(world, Blocks.POPPY.getDefaultState(), 28, 7, 36, start);
        structure.setBlockState(world, Blocks.OAK_FENCE.getDefaultState().with(FourWayBlock.WATERLOGGED, false).with(FourWayBlock.NORTH, true).with(FourWayBlock.SOUTH, true).with(FourWayBlock.EAST, false).with(FourWayBlock.WEST, false), 28, 8, 22, start);
        structure.setBlockState(world, Blocks.OAK_FENCE.getDefaultState().with(FourWayBlock.WATERLOGGED, false).with(FourWayBlock.NORTH, true).with(FourWayBlock.SOUTH, false).with(FourWayBlock.EAST, false).with(FourWayBlock.WEST, false), 28, 9, 25, start);
        structure.setBlockState(world, Blocks.WHITE_WOOL.getDefaultState(), 28, 10, 25, start);
        structure.setBlockState(world, Blocks.GRASS.getDefaultState(), 29, 7, 12, start);
        structure.setBlockState(world, Blocks.TALL_GRASS.getDefaultState(), 29, 7, 21, start);
        structure.setBlockState(world, Blocks.POPPY.getDefaultState(), 29, 7, 30, start);
        structure.setBlockState(world, Blocks.DANDELION.getDefaultState(), 29, 7, 31, start);
        structure.setBlockState(world, Blocks.WALL_TORCH.getDefaultState().with(WallTorchBlock.HORIZONTAL_FACING, Direction.EAST), 29, 8, 23, start);
        structure.setBlockState(world, Blocks.WALL_TORCH.getDefaultState().with(WallTorchBlock.HORIZONTAL_FACING, Direction.EAST), 29, 8, 27, start);
        structure.setBlockState(world, Blocks.OAK_LOG.getDefaultState(), 29, 10, 13, start);
        structure.setBlockState(world, Blocks.OAK_LOG.getDefaultState(), 29, 10, 37, start);
        structure.setBlockState(world, Blocks.COBBLESTONE_WALL.getDefaultState().with(WallBlock.WATERLOGGED, false).with(WallBlock.UP, true).with(WallBlock.WALL_HEIGHT_NORTH, WallHeight.LOW).with(WallBlock.WALL_HEIGHT_SOUTH, WallHeight.LOW).with(WallBlock.WALL_HEIGHT_EAST, WallHeight.LOW).with(WallBlock.WALL_HEIGHT_WEST, WallHeight.LOW), 29, 11, 13, start);
        structure.setBlockState(world, Blocks.COBBLESTONE_WALL.getDefaultState().with(WallBlock.WATERLOGGED, false).with(WallBlock.UP, true).with(WallBlock.WALL_HEIGHT_NORTH, WallHeight.LOW).with(WallBlock.WALL_HEIGHT_SOUTH, WallHeight.LOW).with(WallBlock.WALL_HEIGHT_EAST, WallHeight.LOW).with(WallBlock.WALL_HEIGHT_WEST, WallHeight.LOW), 29, 11, 37, start);
        structure.setBlockState(world, Blocks.OAK_FENCE.getDefaultState().with(FourWayBlock.WATERLOGGED, false).with(FourWayBlock.NORTH, false).with(FourWayBlock.SOUTH, false).with(FourWayBlock.EAST, false).with(FourWayBlock.WEST, false), 29, 12, 13, start);
        structure.setBlockState(world, Blocks.OAK_FENCE.getDefaultState().with(FourWayBlock.WATERLOGGED, false).with(FourWayBlock.NORTH, false).with(FourWayBlock.SOUTH, false).with(FourWayBlock.EAST, false).with(FourWayBlock.WEST, false), 29, 12, 37, start);
        structure.setBlockState(world, Blocks.PINK_TULIP.getDefaultState(), 30, 7, 14, start);
        structure.setBlockState(world, Blocks.GRASS.getDefaultState(), 30, 7, 22, start);
        structure.setBlockState(world, Blocks.AIR.getDefaultState(), 30, 7, 23, start);
        structure.setBlockState(world, Blocks.AIR.getDefaultState(), 30, 7, 27, start);
        structure.setBlockState(world, Blocks.GRASS.getDefaultState(), 30, 7, 28, start);
        structure.setBlockState(world, Blocks.DIRT.getDefaultState(), 31, 6, 16, start);
        structure.setBlockState(world, Blocks.DIRT.getDefaultState(), 31, 6, 34, start);
        structure.setBlockState(world, Blocks.GRASS.getDefaultState(), 31, 7, 15, start);
        structure.setBlockState(world, Blocks.CRAFTING_TABLE.getDefaultState(), 31, 7, 17, start);
        structure.setBlockState(world, Blocks.RED_BED.getDefaultState().with(HorizontalBlock.HORIZONTAL_FACING, Direction.NORTH).with(BedBlock.PART, BedPart.HEAD), 31, 7, 18, start);
        structure.setBlockState(world, Blocks.RED_BED.getDefaultState().with(HorizontalBlock.HORIZONTAL_FACING, Direction.NORTH).with(BedBlock.PART, BedPart.FOOT), 31, 7, 19, start);
        structure.setBlockState(world, Blocks.RED_BED.getDefaultState().with(HorizontalBlock.HORIZONTAL_FACING, Direction.SOUTH).with(BedBlock.PART, BedPart.FOOT), 31, 7, 31, start);
        structure.setBlockState(world, Blocks.RED_BED.getDefaultState().with(HorizontalBlock.HORIZONTAL_FACING, Direction.SOUTH).with(BedBlock.PART, BedPart.HEAD), 31, 7, 32, start);
        structure.setBlockState(world, Blocks.CRAFTING_TABLE.getDefaultState(), 31, 7, 33, start);
        structure.setBlockState(world, Blocks.TALL_GRASS.getDefaultState(), 31, 7, 35, start);
        structure.setBlockState(world, Blocks.GRASS.getDefaultState(), 31, 7, 36, start);
        structure.setBlockState(world, Blocks.WALL_TORCH.getDefaultState().with(WallTorchBlock.HORIZONTAL_FACING, Direction.SOUTH), 31, 8, 17, start);
        structure.setBlockState(world, Blocks.WALL_TORCH.getDefaultState().with(WallTorchBlock.HORIZONTAL_FACING, Direction.NORTH), 31, 8, 33, start);
        structure.setBlockState(world, Blocks.OAK_LOG.getDefaultState(), 31, 10, 13, start);
        structure.setBlockState(world, Blocks.OAK_LOG.getDefaultState(), 31, 10, 37, start);
        structure.setBlockState(world, Blocks.COBBLESTONE_WALL.getDefaultState().with(WallBlock.WATERLOGGED, false).with(WallBlock.UP, true).with(WallBlock.WALL_HEIGHT_NORTH, WallHeight.LOW).with(WallBlock.WALL_HEIGHT_SOUTH, WallHeight.LOW).with(WallBlock.WALL_HEIGHT_EAST, WallHeight.LOW).with(WallBlock.WALL_HEIGHT_WEST, WallHeight.LOW), 31, 11, 13, start);
        structure.setBlockState(world, Blocks.COBBLESTONE_WALL.getDefaultState().with(WallBlock.WATERLOGGED, false).with(WallBlock.UP, true).with(WallBlock.WALL_HEIGHT_NORTH, WallHeight.LOW).with(WallBlock.WALL_HEIGHT_SOUTH, WallHeight.LOW).with(WallBlock.WALL_HEIGHT_EAST, WallHeight.LOW).with(WallBlock.WALL_HEIGHT_WEST, WallHeight.LOW), 31, 11, 37, start);
        structure.setBlockState(world, Blocks.OAK_FENCE.getDefaultState().with(FourWayBlock.WATERLOGGED, false).with(FourWayBlock.NORTH, false).with(FourWayBlock.SOUTH, false).with(FourWayBlock.EAST, false).with(FourWayBlock.WEST, false), 31, 12, 13, start);
        structure.setBlockState(world, Blocks.OAK_FENCE.getDefaultState().with(FourWayBlock.WATERLOGGED, false).with(FourWayBlock.NORTH, false).with(FourWayBlock.SOUTH, false).with(FourWayBlock.EAST, false).with(FourWayBlock.WEST, false), 31, 12, 37, start);
        structure.setBlockState(world, Blocks.TALL_GRASS.getDefaultState(), 32, 7, 15, start);
        structure.setBlockState(world, Blocks.GRASS.getDefaultState(), 32, 7, 35, start);
        structure.setBlockState(world, Blocks.AZURE_BLUET.getDefaultState(), 32, 7, 36, start);
        structure.setBlockState(world, Blocks.OAK_FENCE.getDefaultState().with(FourWayBlock.WATERLOGGED, false).with(FourWayBlock.NORTH, false).with(FourWayBlock.SOUTH, false).with(FourWayBlock.EAST, false).with(FourWayBlock.WEST, true), 32, 9, 21, start);
        structure.setBlockState(world, Blocks.OAK_FENCE.getDefaultState().with(FourWayBlock.WATERLOGGED, false).with(FourWayBlock.NORTH, false).with(FourWayBlock.SOUTH, false).with(FourWayBlock.EAST, true).with(FourWayBlock.WEST, true), 32, 9, 29, start);
        structure.setBlockState(world, Blocks.GRASS.getDefaultState(), 33, 7, 15, start);
        structure.setBlockState(world, Blocks.CRAFTING_TABLE.getDefaultState(), 33, 7, 17, start);
        structure.setBlockState(world, Blocks.RED_BED.getDefaultState().with(HorizontalBlock.HORIZONTAL_FACING, Direction.NORTH).with(BedBlock.PART, BedPart.HEAD), 33, 7, 18, start);
        structure.setBlockState(world, Blocks.RED_BED.getDefaultState().with(HorizontalBlock.HORIZONTAL_FACING, Direction.NORTH).with(BedBlock.PART, BedPart.FOOT), 33, 7, 19, start);
        structure.setBlockState(world, Blocks.RED_BED.getDefaultState().with(HorizontalBlock.HORIZONTAL_FACING, Direction.SOUTH).with(BedBlock.PART, BedPart.FOOT), 33, 7, 31, start);
        structure.setBlockState(world, Blocks.RED_BED.getDefaultState().with(HorizontalBlock.HORIZONTAL_FACING, Direction.SOUTH).with(BedBlock.PART, BedPart.HEAD), 33, 7, 32, start);
        structure.setBlockState(world, Blocks.CRAFTING_TABLE.getDefaultState(), 33, 7, 33, start);
        structure.setBlockState(world, Blocks.OAK_LOG.getDefaultState(), 33, 10, 13, start);
        structure.setBlockState(world, Blocks.OAK_LOG.getDefaultState(), 33, 10, 37, start);
        structure.setBlockState(world, Blocks.COBBLESTONE_WALL.getDefaultState().with(WallBlock.WATERLOGGED, false).with(WallBlock.UP, true).with(WallBlock.WALL_HEIGHT_NORTH, WallHeight.LOW).with(WallBlock.WALL_HEIGHT_SOUTH, WallHeight.LOW).with(WallBlock.WALL_HEIGHT_EAST, WallHeight.LOW).with(WallBlock.WALL_HEIGHT_WEST, WallHeight.LOW), 33, 11, 13, start);
        structure.setBlockState(world, Blocks.COBBLESTONE_WALL.getDefaultState().with(WallBlock.WATERLOGGED, false).with(WallBlock.UP, true).with(WallBlock.WALL_HEIGHT_NORTH, WallHeight.LOW).with(WallBlock.WALL_HEIGHT_SOUTH, WallHeight.LOW).with(WallBlock.WALL_HEIGHT_EAST, WallHeight.LOW).with(WallBlock.WALL_HEIGHT_WEST, WallHeight.LOW), 33, 11, 37, start);
        structure.setBlockState(world, Blocks.OAK_FENCE.getDefaultState().with(FourWayBlock.WATERLOGGED, false).with(FourWayBlock.NORTH, false).with(FourWayBlock.SOUTH, false).with(FourWayBlock.EAST, false).with(FourWayBlock.WEST, false), 33, 12, 13, start);
        structure.setBlockState(world, Blocks.OAK_FENCE.getDefaultState().with(FourWayBlock.WATERLOGGED, false).with(FourWayBlock.NORTH, false).with(FourWayBlock.SOUTH, false).with(FourWayBlock.EAST, false).with(FourWayBlock.WEST, false), 33, 12, 37, start);
        structure.setBlockState(world, Blocks.GRASS.getDefaultState(), 34, 7, 14, start);
        structure.setBlockState(world, Blocks.TALL_GRASS.getDefaultState(), 34, 7, 36, start);
        structure.setBlockState(world, Blocks.POPPY.getDefaultState(), 35, 7, 12, start);
        structure.setBlockState(world, Blocks.POPPY.getDefaultState(), 35, 7, 14, start);
        structure.setBlockState(world, Blocks.GRASS.getDefaultState(), 35, 7, 17, start);
        structure.setBlockState(world, Blocks.POPPY.getDefaultState(), 35, 7, 29, start);
        structure.setBlockState(world, Blocks.GRASS.getDefaultState(), 35, 7, 30, start);
        structure.setBlockState(world, Blocks.DANDELION.getDefaultState(), 35, 7, 31, start);
        structure.setBlockState(world, Blocks.OAK_LOG.getDefaultState(), 35, 10, 13, start);
        structure.setBlockState(world, Blocks.OAK_LOG.getDefaultState(), 35, 10, 37, start);
        structure.setBlockState(world, Blocks.COBBLESTONE_WALL.getDefaultState().with(WallBlock.WATERLOGGED, false).with(WallBlock.UP, true).with(WallBlock.WALL_HEIGHT_NORTH, WallHeight.LOW).with(WallBlock.WALL_HEIGHT_SOUTH, WallHeight.LOW).with(WallBlock.WALL_HEIGHT_EAST, WallHeight.LOW).with(WallBlock.WALL_HEIGHT_WEST, WallHeight.LOW), 35, 11, 13, start);
        structure.setBlockState(world, Blocks.COBBLESTONE_WALL.getDefaultState().with(WallBlock.WATERLOGGED, false).with(WallBlock.UP, true).with(WallBlock.WALL_HEIGHT_NORTH, WallHeight.LOW).with(WallBlock.WALL_HEIGHT_SOUTH, WallHeight.LOW).with(WallBlock.WALL_HEIGHT_EAST, WallHeight.LOW).with(WallBlock.WALL_HEIGHT_WEST, WallHeight.LOW), 35, 11, 37, start);
        structure.setBlockState(world, Blocks.OAK_FENCE.getDefaultState().with(FourWayBlock.WATERLOGGED, false).with(FourWayBlock.NORTH, false).with(FourWayBlock.SOUTH, false).with(FourWayBlock.EAST, false).with(FourWayBlock.WEST, false), 35, 12, 13, start);
        structure.setBlockState(world, Blocks.OAK_FENCE.getDefaultState().with(FourWayBlock.WATERLOGGED, false).with(FourWayBlock.NORTH, false).with(FourWayBlock.SOUTH, false).with(FourWayBlock.EAST, false).with(FourWayBlock.WEST, false), 35, 12, 37, start);
        structure.setBlockState(world, Blocks.DIRT.getDefaultState(), 37, 6, 16, start);
        structure.setBlockState(world, Blocks.DIRT.getDefaultState(), 37, 6, 34, start);
        structure.setBlockState(world, Blocks.TALL_GRASS.getDefaultState(), 37, 7, 14, start);
        structure.setBlockState(world, Blocks.DANDELION.getDefaultState(), 37, 7, 15, start);
        structure.setBlockState(world, Blocks.CRAFTING_TABLE.getDefaultState(), 37, 7, 17, start);
        structure.setBlockState(world, Blocks.RED_BED.getDefaultState().with(HorizontalBlock.HORIZONTAL_FACING, Direction.NORTH).with(BedBlock.PART, BedPart.HEAD), 37, 7, 18, start);
        structure.setBlockState(world, Blocks.RED_BED.getDefaultState().with(HorizontalBlock.HORIZONTAL_FACING, Direction.NORTH).with(BedBlock.PART, BedPart.FOOT), 37, 7, 19, start);
        structure.setBlockState(world, Blocks.RED_BED.getDefaultState().with(HorizontalBlock.HORIZONTAL_FACING, Direction.SOUTH).with(BedBlock.PART, BedPart.FOOT), 37, 7, 31, start);
        structure.setBlockState(world, Blocks.RED_BED.getDefaultState().with(HorizontalBlock.HORIZONTAL_FACING, Direction.SOUTH).with(BedBlock.PART, BedPart.HEAD), 37, 7, 32, start);
        structure.setBlockState(world, Blocks.CRAFTING_TABLE.getDefaultState(), 37, 7, 33, start);
        structure.setBlockState(world, Blocks.WALL_TORCH.getDefaultState().with(WallTorchBlock.HORIZONTAL_FACING, Direction.SOUTH), 37, 8, 17, start);
        structure.setBlockState(world, Blocks.COBBLESTONE_STAIRS.getDefaultState().with(StairsBlock.FACING, Direction.EAST).with(StairsBlock.WATERLOGGED, false).with(StairsBlock.SHAPE, StairsShape.OUTER_RIGHT).with(StairsBlock.HALF, Half.BOTTOM), 37, 8, 24, start);
        structure.setBlockState(world, Blocks.COBBLESTONE_STAIRS.getDefaultState().with(StairsBlock.FACING, Direction.EAST).with(StairsBlock.WATERLOGGED, false).with(StairsBlock.SHAPE, StairsShape.STRAIGHT).with(StairsBlock.HALF, Half.BOTTOM), 37, 8, 25, start);
        structure.setBlockState(world, Blocks.COBBLESTONE_STAIRS.getDefaultState().with(StairsBlock.FACING, Direction.EAST).with(StairsBlock.WATERLOGGED, false).with(StairsBlock.SHAPE, StairsShape.OUTER_LEFT).with(StairsBlock.HALF, Half.BOTTOM), 37, 8, 26, start);
        structure.setBlockState(world, Blocks.WALL_TORCH.getDefaultState().with(WallTorchBlock.HORIZONTAL_FACING, Direction.NORTH), 37, 8, 33, start);
        structure.setBlockState(world, Blocks.OAK_LOG.getDefaultState(), 37, 10, 13, start);
        structure.setBlockState(world, Blocks.OAK_LOG.getDefaultState(), 37, 10, 37, start);
        structure.setBlockState(world, Blocks.COBBLESTONE_WALL.getDefaultState().with(WallBlock.WATERLOGGED, false).with(WallBlock.UP, true).with(WallBlock.WALL_HEIGHT_NORTH, WallHeight.LOW).with(WallBlock.WALL_HEIGHT_SOUTH, WallHeight.LOW).with(WallBlock.WALL_HEIGHT_EAST, WallHeight.LOW).with(WallBlock.WALL_HEIGHT_WEST, WallHeight.LOW), 37, 11, 13, start);
        structure.setBlockState(world, Blocks.COBBLESTONE_WALL.getDefaultState().with(WallBlock.WATERLOGGED, false).with(WallBlock.UP, true).with(WallBlock.WALL_HEIGHT_NORTH, WallHeight.LOW).with(WallBlock.WALL_HEIGHT_SOUTH, WallHeight.LOW).with(WallBlock.WALL_HEIGHT_EAST, WallHeight.LOW).with(WallBlock.WALL_HEIGHT_WEST, WallHeight.LOW), 37, 11, 37, start);
        structure.setBlockState(world, Blocks.OAK_FENCE.getDefaultState().with(FourWayBlock.WATERLOGGED, false).with(FourWayBlock.NORTH, false).with(FourWayBlock.SOUTH, false).with(FourWayBlock.EAST, false).with(FourWayBlock.WEST, false), 37, 12, 13, start);
        structure.setBlockState(world, Blocks.OAK_FENCE.getDefaultState().with(FourWayBlock.WATERLOGGED, false).with(FourWayBlock.NORTH, false).with(FourWayBlock.SOUTH, false).with(FourWayBlock.EAST, false).with(FourWayBlock.WEST, false), 37, 12, 37, start);
        structure.setBlockState(world, Blocks.GRAVEL.getDefaultState(), 38, 6, 34, start);
        structure.setBlockState(world, Blocks.OAK_FENCE.getDefaultState().with(FourWayBlock.WATERLOGGED, false).with(FourWayBlock.NORTH, false).with(FourWayBlock.SOUTH, false).with(FourWayBlock.EAST, false).with(FourWayBlock.WEST, false), 38, 7, 16, start);
        structure.setBlockState(world, Blocks.AIR.getDefaultState(), 38, 7, 23, start);
        structure.setBlockState(world, Blocks.AIR.getDefaultState(), 38, 7, 27, start);
        structure.setBlockState(world, Blocks.TALL_GRASS.getDefaultState(), 38, 7, 35, start);
        structure.setBlockState(world, Blocks.OXEYE_DAISY.getDefaultState(), 38, 7, 36, start);
        structure.setBlockState(world, Blocks.OAK_FENCE.getDefaultState().with(FourWayBlock.WATERLOGGED, false).with(FourWayBlock.NORTH, false).with(FourWayBlock.SOUTH, false).with(FourWayBlock.EAST, true).with(FourWayBlock.WEST, true), 38, 8, 16, start);
        structure.setBlockState(world, Blocks.COBBLESTONE_STAIRS.getDefaultState().with(StairsBlock.FACING, Direction.SOUTH).with(StairsBlock.WATERLOGGED, false).with(StairsBlock.SHAPE, StairsShape.STRAIGHT).with(StairsBlock.HALF, Half.BOTTOM), 38, 8, 24, start);
        structure.setBlockState(world, Blocks.COBBLESTONE_STAIRS.getDefaultState().with(StairsBlock.FACING, Direction.NORTH).with(StairsBlock.WATERLOGGED, false).with(StairsBlock.SHAPE, StairsShape.STRAIGHT).with(StairsBlock.HALF, Half.BOTTOM), 38, 8, 26, start);
        structure.setBlockState(world, Blocks.OAK_FENCE.getDefaultState().with(FourWayBlock.WATERLOGGED, false).with(FourWayBlock.NORTH, false).with(FourWayBlock.SOUTH, false).with(FourWayBlock.EAST, true).with(FourWayBlock.WEST, true), 38, 9, 21, start);
        structure.setBlockState(world, Blocks.FIRE.getDefaultState(), 38, 9, 25, start);
        structure.setBlockState(world, Blocks.CRAFTING_TABLE.getDefaultState(), 39, 7, 17, start);
        structure.setBlockState(world, Blocks.RED_BED.getDefaultState().with(HorizontalBlock.HORIZONTAL_FACING, Direction.NORTH).with(BedBlock.PART, BedPart.HEAD), 39, 7, 18, start);
        structure.setBlockState(world, Blocks.RED_BED.getDefaultState().with(HorizontalBlock.HORIZONTAL_FACING, Direction.NORTH).with(BedBlock.PART, BedPart.FOOT), 39, 7, 19, start);
        structure.setBlockState(world, Blocks.RED_BED.getDefaultState().with(HorizontalBlock.HORIZONTAL_FACING, Direction.SOUTH).with(BedBlock.PART, BedPart.FOOT), 39, 7, 31, start);
        structure.setBlockState(world, Blocks.RED_BED.getDefaultState().with(HorizontalBlock.HORIZONTAL_FACING, Direction.SOUTH).with(BedBlock.PART, BedPart.HEAD), 39, 7, 32, start);
        structure.setBlockState(world, Blocks.CRAFTING_TABLE.getDefaultState(), 39, 7, 33, start);
        structure.setBlockState(world, Blocks.GRASS.getDefaultState(), 39, 7, 36, start);
        structure.setBlockState(world, Blocks.COBBLESTONE_STAIRS.getDefaultState().with(StairsBlock.FACING, Direction.SOUTH).with(StairsBlock.WATERLOGGED, false).with(StairsBlock.SHAPE, StairsShape.OUTER_RIGHT).with(StairsBlock.HALF, Half.BOTTOM), 39, 8, 24, start);
        structure.setBlockState(world, Blocks.COBBLESTONE_STAIRS.getDefaultState().with(StairsBlock.FACING, Direction.WEST).with(StairsBlock.WATERLOGGED, false).with(StairsBlock.SHAPE, StairsShape.STRAIGHT).with(StairsBlock.HALF, Half.BOTTOM), 39, 8, 25, start);
        structure.setBlockState(world, Blocks.COBBLESTONE_STAIRS.getDefaultState().with(StairsBlock.FACING, Direction.WEST).with(StairsBlock.WATERLOGGED, false).with(StairsBlock.SHAPE, StairsShape.OUTER_RIGHT).with(StairsBlock.HALF, Half.BOTTOM), 39, 8, 26, start);
        structure.setBlockState(world, Blocks.OAK_LOG.getDefaultState(), 39, 10, 13, start);
        structure.setBlockState(world, Blocks.OAK_LOG.getDefaultState(), 39, 10, 37, start);
        structure.setBlockState(world, Blocks.COBBLESTONE_WALL.getDefaultState().with(WallBlock.WATERLOGGED, false).with(WallBlock.UP, false).with(WallBlock.WALL_HEIGHT_NORTH, WallHeight.LOW).with(WallBlock.WALL_HEIGHT_SOUTH, WallHeight.LOW).with(WallBlock.WALL_HEIGHT_EAST, WallHeight.LOW).with(WallBlock.WALL_HEIGHT_WEST, WallHeight.LOW), 39, 11, 13, start);
        structure.setBlockState(world, Blocks.COBBLESTONE_WALL.getDefaultState().with(WallBlock.WATERLOGGED, false).with(WallBlock.UP, true).with(WallBlock.WALL_HEIGHT_NORTH, WallHeight.LOW).with(WallBlock.WALL_HEIGHT_SOUTH, WallHeight.LOW).with(WallBlock.WALL_HEIGHT_EAST, WallHeight.LOW).with(WallBlock.WALL_HEIGHT_WEST, WallHeight.LOW), 39, 11, 37, start);
        structure.setBlockState(world, Blocks.OAK_FENCE.getDefaultState().with(FourWayBlock.WATERLOGGED, false).with(FourWayBlock.NORTH, false).with(FourWayBlock.SOUTH, false).with(FourWayBlock.EAST, false).with(FourWayBlock.WEST, false), 39, 12, 13, start);
        structure.setBlockState(world, Blocks.OAK_FENCE.getDefaultState().with(FourWayBlock.WATERLOGGED, false).with(FourWayBlock.NORTH, false).with(FourWayBlock.SOUTH, false).with(FourWayBlock.EAST, false).with(FourWayBlock.WEST, false), 39, 12, 37, start);
        structure.setBlockState(world, Blocks.GRASS.getDefaultState(), 40, 7, 15, start);
        structure.setBlockState(world, Blocks.GRASS.getDefaultState(), 40, 7, 35, start);
        structure.setBlockState(world, Blocks.OXEYE_DAISY.getDefaultState(), 41, 7, 15, start);
        structure.setBlockState(world, Blocks.POPPY.getDefaultState(), 41, 7, 16, start);
        structure.setBlockState(world, Blocks.OXEYE_DAISY.getDefaultState(), 41, 7, 21, start);
        structure.setBlockState(world, Blocks.GRASS.getDefaultState(), 41, 7, 32, start);
        structure.setBlockState(world, Blocks.DANDELION.getDefaultState(), 41, 7, 34, start);
        structure.setBlockState(world, Blocks.OAK_LOG.getDefaultState(), 41, 10, 13, start);
        structure.setBlockState(world, Blocks.OAK_LOG.getDefaultState(), 41, 10, 37, start);
        structure.setBlockState(world, Blocks.COBBLESTONE_WALL.getDefaultState().with(WallBlock.WATERLOGGED, false).with(WallBlock.UP, true).with(WallBlock.WALL_HEIGHT_NORTH, WallHeight.LOW).with(WallBlock.WALL_HEIGHT_SOUTH, WallHeight.LOW).with(WallBlock.WALL_HEIGHT_EAST, WallHeight.LOW).with(WallBlock.WALL_HEIGHT_WEST, WallHeight.LOW), 41, 11, 13, start);
        structure.setBlockState(world, Blocks.COBBLESTONE_WALL.getDefaultState().with(WallBlock.WATERLOGGED, false).with(WallBlock.UP, true).with(WallBlock.WALL_HEIGHT_NORTH, WallHeight.LOW).with(WallBlock.WALL_HEIGHT_SOUTH, WallHeight.LOW).with(WallBlock.WALL_HEIGHT_EAST, WallHeight.LOW).with(WallBlock.WALL_HEIGHT_WEST, WallHeight.LOW), 41, 11, 37, start);
        structure.setBlockState(world, Blocks.OAK_FENCE.getDefaultState().with(FourWayBlock.WATERLOGGED, false).with(FourWayBlock.NORTH, false).with(FourWayBlock.SOUTH, false).with(FourWayBlock.EAST, false).with(FourWayBlock.WEST, false), 41, 12, 13, start);
        structure.setBlockState(world, Blocks.OAK_FENCE.getDefaultState().with(FourWayBlock.WATERLOGGED, false).with(FourWayBlock.NORTH, false).with(FourWayBlock.SOUTH, false).with(FourWayBlock.EAST, false).with(FourWayBlock.WEST, false), 41, 12, 37, start);
        structure.setBlockState(world, Blocks.OAK_LOG.getDefaultState(), 42, 11, 37, start);
        structure.setBlockState(world, Blocks.DIRT.getDefaultState(), 43, 6, 16, start);
        structure.setBlockState(world, Blocks.DIRT.getDefaultState(), 43, 6, 34, start);
        structure.setBlockState(world, Blocks.POPPY.getDefaultState(), 43, 7, 14, start);
        structure.setBlockState(world, Blocks.GRASS.getDefaultState(), 43, 7, 15, start);
        structure.setBlockState(world, Blocks.CRAFTING_TABLE.getDefaultState(), 43, 7, 17, start);
        structure.setBlockState(world, Blocks.RED_BED.getDefaultState().with(HorizontalBlock.HORIZONTAL_FACING, Direction.NORTH).with(BedBlock.PART, BedPart.HEAD), 43, 7, 18, start);
        structure.setBlockState(world, Blocks.RED_BED.getDefaultState().with(HorizontalBlock.HORIZONTAL_FACING, Direction.NORTH).with(BedBlock.PART, BedPart.FOOT), 43, 7, 19, start);
        structure.setBlockState(world, Blocks.RED_BED.getDefaultState().with(HorizontalBlock.HORIZONTAL_FACING, Direction.SOUTH).with(BedBlock.PART, BedPart.FOOT), 43, 7, 31, start);
        structure.setBlockState(world, Blocks.RED_BED.getDefaultState().with(HorizontalBlock.HORIZONTAL_FACING, Direction.SOUTH).with(BedBlock.PART, BedPart.HEAD), 43, 7, 32, start);
        structure.setBlockState(world, Blocks.CRAFTING_TABLE.getDefaultState(), 43, 7, 33, start);
        structure.setBlockState(world, Blocks.WALL_TORCH.getDefaultState().with(WallTorchBlock.HORIZONTAL_FACING, Direction.SOUTH), 43, 8, 17, start);
        structure.setBlockState(world, Blocks.WALL_TORCH.getDefaultState().with(WallTorchBlock.HORIZONTAL_FACING, Direction.NORTH), 43, 8, 33, start);
        structure.setBlockState(world, Blocks.OAK_LOG.getDefaultState(), 43, 10, 13, start);
        structure.setBlockState(world, Blocks.OAK_LOG.getDefaultState(), 43, 10, 37, start);
        structure.setBlockState(world, Blocks.COBBLESTONE_WALL.getDefaultState().with(WallBlock.WATERLOGGED, false).with(WallBlock.UP, false).with(WallBlock.WALL_HEIGHT_NORTH, WallHeight.LOW).with(WallBlock.WALL_HEIGHT_SOUTH, WallHeight.LOW).with(WallBlock.WALL_HEIGHT_EAST, WallHeight.LOW).with(WallBlock.WALL_HEIGHT_WEST, WallHeight.LOW), 43, 11, 13, start);
        structure.setBlockState(world, Blocks.COBBLESTONE_WALL.getDefaultState().with(WallBlock.WATERLOGGED, false).with(WallBlock.UP, true).with(WallBlock.WALL_HEIGHT_NORTH, WallHeight.LOW).with(WallBlock.WALL_HEIGHT_SOUTH, WallHeight.LOW).with(WallBlock.WALL_HEIGHT_EAST, WallHeight.LOW).with(WallBlock.WALL_HEIGHT_WEST, WallHeight.LOW), 43, 11, 37, start);
        structure.setBlockState(world, Blocks.OAK_FENCE.getDefaultState().with(FourWayBlock.WATERLOGGED, false).with(FourWayBlock.NORTH, false).with(FourWayBlock.SOUTH, false).with(FourWayBlock.EAST, false).with(FourWayBlock.WEST, false), 43, 12, 13, start);
        structure.setBlockState(world, Blocks.OAK_FENCE.getDefaultState().with(FourWayBlock.WATERLOGGED, false).with(FourWayBlock.NORTH, false).with(FourWayBlock.SOUTH, false).with(FourWayBlock.EAST, false).with(FourWayBlock.WEST, false), 43, 12, 37, start);
        structure.setBlockState(world, Blocks.GRASS.getDefaultState(), 44, 7, 12, start);
        structure.setBlockState(world, Blocks.OAK_FENCE.getDefaultState().with(FourWayBlock.WATERLOGGED, false).with(FourWayBlock.NORTH, false).with(FourWayBlock.SOUTH, false).with(FourWayBlock.EAST, true).with(FourWayBlock.WEST, false), 44, 7, 16, start);
        structure.setBlockState(world, Blocks.AIR.getDefaultState(), 44, 7, 23, start);
        structure.setBlockState(world, Blocks.AIR.getDefaultState(), 44, 7, 27, start);
        structure.setBlockState(world, Blocks.OAK_FENCE.getDefaultState().with(FourWayBlock.WATERLOGGED, false).with(FourWayBlock.NORTH, false).with(FourWayBlock.SOUTH, false).with(FourWayBlock.EAST, true).with(FourWayBlock.WEST, false), 44, 7, 34, start);
        structure.setBlockState(world, Blocks.DANDELION.getDefaultState(), 44, 7, 35, start);
        structure.setBlockState(world, Blocks.GRASS.getDefaultState(), 44, 7, 36, start);
        structure.setBlockState(world, Blocks.OAK_FENCE.getDefaultState().with(FourWayBlock.WATERLOGGED, false).with(FourWayBlock.NORTH, false).with(FourWayBlock.SOUTH, false).with(FourWayBlock.EAST, true).with(FourWayBlock.WEST, true), 44, 8, 16, start);
        structure.setBlockState(world, Blocks.OAK_FENCE.getDefaultState().with(FourWayBlock.WATERLOGGED, false).with(FourWayBlock.NORTH, false).with(FourWayBlock.SOUTH, false).with(FourWayBlock.EAST, false).with(FourWayBlock.WEST, false), 44, 8, 34, start);
        structure.setBlockState(world, Blocks.OAK_FENCE.getDefaultState().with(FourWayBlock.WATERLOGGED, false).with(FourWayBlock.NORTH, false).with(FourWayBlock.SOUTH, false).with(FourWayBlock.EAST, true).with(FourWayBlock.WEST, false), 44, 9, 21, start);
        structure.setBlockState(world, Blocks.OAK_FENCE.getDefaultState().with(FourWayBlock.WATERLOGGED, false).with(FourWayBlock.NORTH, false).with(FourWayBlock.SOUTH, false).with(FourWayBlock.EAST, true).with(FourWayBlock.WEST, true), 44, 9, 29, start);
        structure.setBlockState(world, Blocks.OXEYE_DAISY.getDefaultState(), 45, 7, 12, start);
        structure.setBlockState(world, Blocks.POPPY.getDefaultState(), 45, 7, 15, start);
        structure.setBlockState(world, Blocks.CRAFTING_TABLE.getDefaultState(), 45, 7, 17, start);
        structure.setBlockState(world, Blocks.RED_BED.getDefaultState().with(HorizontalBlock.HORIZONTAL_FACING, Direction.NORTH).with(BedBlock.PART, BedPart.HEAD), 45, 7, 18, start);
        structure.setBlockState(world, Blocks.RED_BED.getDefaultState().with(HorizontalBlock.HORIZONTAL_FACING, Direction.NORTH).with(BedBlock.PART, BedPart.FOOT), 45, 7, 19, start);
        structure.setBlockState(world, Blocks.RED_BED.getDefaultState().with(HorizontalBlock.HORIZONTAL_FACING, Direction.SOUTH).with(BedBlock.PART, BedPart.FOOT), 45, 7, 31, start);
        structure.setBlockState(world, Blocks.RED_BED.getDefaultState().with(HorizontalBlock.HORIZONTAL_FACING, Direction.SOUTH).with(BedBlock.PART, BedPart.HEAD), 45, 7, 32, start);
        structure.setBlockState(world, Blocks.CRAFTING_TABLE.getDefaultState(), 45, 7, 33, start);
        structure.setBlockState(world, Blocks.GRASS.getDefaultState(), 45, 7, 35, start);
        structure.setBlockState(world, Blocks.OAK_LOG.getDefaultState(), 45, 10, 13, start);
        structure.setBlockState(world, Blocks.OAK_LOG.getDefaultState(), 45, 10, 37, start);
        structure.setBlockState(world, Blocks.COBBLESTONE_WALL.getDefaultState().with(WallBlock.WATERLOGGED, false).with(WallBlock.UP, true).with(WallBlock.WALL_HEIGHT_NORTH, WallHeight.LOW).with(WallBlock.WALL_HEIGHT_SOUTH, WallHeight.LOW).with(WallBlock.WALL_HEIGHT_EAST, WallHeight.LOW).with(WallBlock.WALL_HEIGHT_WEST, WallHeight.LOW), 45, 11, 13, start);
        structure.setBlockState(world, Blocks.COBBLESTONE_WALL.getDefaultState().with(WallBlock.WATERLOGGED, false).with(WallBlock.UP, true).with(WallBlock.WALL_HEIGHT_NORTH, WallHeight.LOW).with(WallBlock.WALL_HEIGHT_SOUTH, WallHeight.LOW).with(WallBlock.WALL_HEIGHT_EAST, WallHeight.LOW).with(WallBlock.WALL_HEIGHT_WEST, WallHeight.LOW), 45, 11, 37, start);
        structure.setBlockState(world, Blocks.OAK_FENCE.getDefaultState().with(FourWayBlock.WATERLOGGED, false).with(FourWayBlock.NORTH, false).with(FourWayBlock.SOUTH, false).with(FourWayBlock.EAST, false).with(FourWayBlock.WEST, false), 45, 12, 13, start);
        structure.setBlockState(world, Blocks.OAK_FENCE.getDefaultState().with(FourWayBlock.WATERLOGGED, false).with(FourWayBlock.NORTH, false).with(FourWayBlock.SOUTH, false).with(FourWayBlock.EAST, false).with(FourWayBlock.WEST, false), 45, 12, 37, start);
        structure.setBlockState(world, Blocks.DANDELION.getDefaultState(), 46, 7, 12, start);
        structure.setBlockState(world, Blocks.GRASS.getDefaultState(), 46, 7, 15, start);
        structure.setBlockState(world, Blocks.POPPY.getDefaultState(), 46, 7, 35, start);
        structure.setBlockState(world, Blocks.AZURE_BLUET.getDefaultState(), 47, 7, 14, start);
        structure.setBlockState(world, Blocks.OAK_LOG.getDefaultState(), 47, 10, 13, start);
        structure.setBlockState(world, Blocks.OAK_LOG.getDefaultState(), 47, 10, 37, start);
        structure.setBlockState(world, Blocks.COBBLESTONE_WALL.getDefaultState().with(WallBlock.WATERLOGGED, false).with(WallBlock.UP, true).with(WallBlock.WALL_HEIGHT_NORTH, WallHeight.LOW).with(WallBlock.WALL_HEIGHT_SOUTH, WallHeight.LOW).with(WallBlock.WALL_HEIGHT_EAST, WallHeight.LOW).with(WallBlock.WALL_HEIGHT_WEST, WallHeight.LOW), 47, 11, 13, start);
        structure.setBlockState(world, Blocks.COBBLESTONE_WALL.getDefaultState().with(WallBlock.WATERLOGGED, false).with(WallBlock.UP, true).with(WallBlock.WALL_HEIGHT_NORTH, WallHeight.LOW).with(WallBlock.WALL_HEIGHT_SOUTH, WallHeight.LOW).with(WallBlock.WALL_HEIGHT_EAST, WallHeight.LOW).with(WallBlock.WALL_HEIGHT_WEST, WallHeight.LOW), 47, 11, 37, start);
        structure.setBlockState(world, Blocks.OAK_FENCE.getDefaultState().with(FourWayBlock.WATERLOGGED, false).with(FourWayBlock.NORTH, false).with(FourWayBlock.SOUTH, false).with(FourWayBlock.EAST, false).with(FourWayBlock.WEST, false), 47, 12, 13, start);
        structure.setBlockState(world, Blocks.OAK_FENCE.getDefaultState().with(FourWayBlock.WATERLOGGED, false).with(FourWayBlock.NORTH, false).with(FourWayBlock.SOUTH, false).with(FourWayBlock.EAST, false).with(FourWayBlock.WEST, false), 47, 12, 37, start);
        structure.setBlockState(world, Blocks.GRASS.getDefaultState(), 48, 7, 12, start);
        structure.setBlockState(world, Blocks.GRASS.getDefaultState(), 48, 7, 14, start);
        structure.setBlockState(world, Blocks.TALL_GRASS.getDefaultState(), 48, 7, 15, start);
        structure.setBlockState(world, Blocks.GRASS.getDefaultState(), 48, 7, 16, start);
        structure.setBlockState(world, Blocks.TALL_GRASS.getDefaultState(), 48, 7, 17, start);
        structure.setBlockState(world, Blocks.OXEYE_DAISY.getDefaultState(), 48, 7, 21, start);
        structure.setBlockState(world, Blocks.TALL_GRASS.getDefaultState(), 48, 7, 22, start);
        structure.setBlockState(world, Blocks.GRASS.getDefaultState(), 48, 7, 23, start);
        structure.setBlockState(world, Blocks.GRASS.getDefaultState(), 48, 7, 30, start);
        structure.setBlockState(world, Blocks.DANDELION.getDefaultState(), 48, 7, 33, start);
        structure.setBlockState(world, Blocks.TALL_GRASS.getDefaultState(), 48, 7, 34, start);
        structure.setBlockState(world, Blocks.POPPY.getDefaultState(), 48, 7, 35, start);
        structure.setBlockState(world, Blocks.GRASS_BLOCK.getDefaultState().with(SnowyDirtBlock.SNOWY, false), 49, 2, 5, start);
        structure.setBlockState(world, Blocks.AZURE_BLUET.getDefaultState(), 49, 7, 12, start);
        structure.setBlockState(world, Blocks.OAK_LOG.getDefaultState(), 49, 10, 13, start);
        structure.setBlockState(world, Blocks.OAK_LOG.getDefaultState(), 49, 10, 15, start);
        structure.setBlockState(world, Blocks.OAK_LOG.getDefaultState(), 49, 10, 17, start);
        structure.setBlockState(world, Blocks.OAK_LOG.getDefaultState(), 49, 10, 19, start);
        structure.setBlockState(world, Blocks.OAK_LOG.getDefaultState(), 49, 10, 21, start);
        structure.setBlockState(world, Blocks.OAK_LOG.getDefaultState(), 49, 10, 23, start);
        structure.setBlockState(world, Blocks.OAK_LOG.getDefaultState(), 49, 10, 27, start);
        structure.setBlockState(world, Blocks.OAK_LOG.getDefaultState(), 49, 10, 29, start);
        structure.setBlockState(world, Blocks.OAK_LOG.getDefaultState(), 49, 10, 31, start);
        structure.setBlockState(world, Blocks.OAK_LOG.getDefaultState(), 49, 10, 33, start);
        structure.setBlockState(world, Blocks.OAK_LOG.getDefaultState(), 49, 10, 35, start);
        structure.setBlockState(world, Blocks.OAK_LOG.getDefaultState(), 49, 10, 37, start);
        structure.setBlockState(world, Blocks.COBBLESTONE_WALL.getDefaultState().with(WallBlock.WATERLOGGED, false).with(WallBlock.UP, true).with(WallBlock.WALL_HEIGHT_NORTH, WallHeight.LOW).with(WallBlock.WALL_HEIGHT_SOUTH, WallHeight.LOW).with(WallBlock.WALL_HEIGHT_EAST, WallHeight.LOW).with(WallBlock.WALL_HEIGHT_WEST, WallHeight.LOW), 49, 11, 13, start);
        structure.setBlockState(world, Blocks.COBBLESTONE_WALL.getDefaultState().with(WallBlock.WATERLOGGED, false).with(WallBlock.UP, true).with(WallBlock.WALL_HEIGHT_NORTH, WallHeight.LOW).with(WallBlock.WALL_HEIGHT_SOUTH, WallHeight.LOW).with(WallBlock.WALL_HEIGHT_EAST, WallHeight.LOW).with(WallBlock.WALL_HEIGHT_WEST, WallHeight.LOW), 49, 11, 15, start);
        structure.setBlockState(world, Blocks.COBBLESTONE_WALL.getDefaultState().with(WallBlock.WATERLOGGED, false).with(WallBlock.UP, true).with(WallBlock.WALL_HEIGHT_NORTH, WallHeight.LOW).with(WallBlock.WALL_HEIGHT_SOUTH, WallHeight.LOW).with(WallBlock.WALL_HEIGHT_EAST, WallHeight.LOW).with(WallBlock.WALL_HEIGHT_WEST, WallHeight.LOW), 49, 11, 17, start);
        structure.setBlockState(world, Blocks.COBBLESTONE_WALL.getDefaultState().with(WallBlock.WATERLOGGED, false).with(WallBlock.UP, true).with(WallBlock.WALL_HEIGHT_NORTH, WallHeight.LOW).with(WallBlock.WALL_HEIGHT_SOUTH, WallHeight.LOW).with(WallBlock.WALL_HEIGHT_EAST, WallHeight.LOW).with(WallBlock.WALL_HEIGHT_WEST, WallHeight.LOW), 49, 11, 19, start);
        structure.setBlockState(world, Blocks.COBBLESTONE_WALL.getDefaultState().with(WallBlock.WATERLOGGED, false).with(WallBlock.UP, true).with(WallBlock.WALL_HEIGHT_NORTH, WallHeight.LOW).with(WallBlock.WALL_HEIGHT_SOUTH, WallHeight.LOW).with(WallBlock.WALL_HEIGHT_EAST, WallHeight.LOW).with(WallBlock.WALL_HEIGHT_WEST, WallHeight.LOW), 49, 11, 21, start);
        structure.setBlockState(world, Blocks.COBBLESTONE_WALL.getDefaultState().with(WallBlock.WATERLOGGED, false).with(WallBlock.UP, true).with(WallBlock.WALL_HEIGHT_NORTH, WallHeight.LOW).with(WallBlock.WALL_HEIGHT_SOUTH, WallHeight.LOW).with(WallBlock.WALL_HEIGHT_EAST, WallHeight.LOW).with(WallBlock.WALL_HEIGHT_WEST, WallHeight.LOW), 49, 11, 23, start);
        structure.setBlockState(world, Blocks.COBBLESTONE_WALL.getDefaultState().with(WallBlock.WATERLOGGED, false).with(WallBlock.UP, true).with(WallBlock.WALL_HEIGHT_NORTH, WallHeight.LOW).with(WallBlock.WALL_HEIGHT_SOUTH, WallHeight.LOW).with(WallBlock.WALL_HEIGHT_EAST, WallHeight.LOW).with(WallBlock.WALL_HEIGHT_WEST, WallHeight.LOW), 49, 11, 27, start);
        structure.setBlockState(world, Blocks.COBBLESTONE_WALL.getDefaultState().with(WallBlock.WATERLOGGED, false).with(WallBlock.UP, true).with(WallBlock.WALL_HEIGHT_NORTH, WallHeight.LOW).with(WallBlock.WALL_HEIGHT_SOUTH, WallHeight.LOW).with(WallBlock.WALL_HEIGHT_EAST, WallHeight.LOW).with(WallBlock.WALL_HEIGHT_WEST, WallHeight.LOW), 49, 11, 29, start);
        structure.setBlockState(world, Blocks.COBBLESTONE_WALL.getDefaultState().with(WallBlock.WATERLOGGED, false).with(WallBlock.UP, true).with(WallBlock.WALL_HEIGHT_NORTH, WallHeight.LOW).with(WallBlock.WALL_HEIGHT_SOUTH, WallHeight.LOW).with(WallBlock.WALL_HEIGHT_EAST, WallHeight.LOW).with(WallBlock.WALL_HEIGHT_WEST, WallHeight.LOW), 49, 11, 31, start);
        structure.setBlockState(world, Blocks.COBBLESTONE_WALL.getDefaultState().with(WallBlock.WATERLOGGED, false).with(WallBlock.UP, true).with(WallBlock.WALL_HEIGHT_NORTH, WallHeight.LOW).with(WallBlock.WALL_HEIGHT_SOUTH, WallHeight.LOW).with(WallBlock.WALL_HEIGHT_EAST, WallHeight.LOW).with(WallBlock.WALL_HEIGHT_WEST, WallHeight.LOW), 49, 11, 33, start);
        structure.setBlockState(world, Blocks.COBBLESTONE_WALL.getDefaultState().with(WallBlock.WATERLOGGED, false).with(WallBlock.UP, true).with(WallBlock.WALL_HEIGHT_NORTH, WallHeight.LOW).with(WallBlock.WALL_HEIGHT_SOUTH, WallHeight.LOW).with(WallBlock.WALL_HEIGHT_EAST, WallHeight.LOW).with(WallBlock.WALL_HEIGHT_WEST, WallHeight.LOW), 49, 11, 35, start);
        structure.setBlockState(world, Blocks.COBBLESTONE_WALL.getDefaultState().with(WallBlock.WATERLOGGED, false).with(WallBlock.UP, true).with(WallBlock.WALL_HEIGHT_NORTH, WallHeight.LOW).with(WallBlock.WALL_HEIGHT_SOUTH, WallHeight.LOW).with(WallBlock.WALL_HEIGHT_EAST, WallHeight.LOW).with(WallBlock.WALL_HEIGHT_WEST, WallHeight.LOW), 49, 11, 37, start);
        structure.setBlockState(world, Blocks.OAK_FENCE.getDefaultState().with(FourWayBlock.WATERLOGGED, false).with(FourWayBlock.NORTH, false).with(FourWayBlock.SOUTH, false).with(FourWayBlock.EAST, false).with(FourWayBlock.WEST, false), 49, 12, 13, start);
        structure.setBlockState(world, Blocks.OAK_FENCE.getDefaultState().with(FourWayBlock.WATERLOGGED, false).with(FourWayBlock.NORTH, false).with(FourWayBlock.SOUTH, false).with(FourWayBlock.EAST, false).with(FourWayBlock.WEST, false), 49, 12, 15, start);
        structure.setBlockState(world, Blocks.OAK_FENCE.getDefaultState().with(FourWayBlock.WATERLOGGED, false).with(FourWayBlock.NORTH, false).with(FourWayBlock.SOUTH, false).with(FourWayBlock.EAST, false).with(FourWayBlock.WEST, false), 49, 12, 17, start);
        structure.setBlockState(world, Blocks.OAK_FENCE.getDefaultState().with(FourWayBlock.WATERLOGGED, false).with(FourWayBlock.NORTH, false).with(FourWayBlock.SOUTH, false).with(FourWayBlock.EAST, false).with(FourWayBlock.WEST, false), 49, 12, 19, start);
        structure.setBlockState(world, Blocks.OAK_FENCE.getDefaultState().with(FourWayBlock.WATERLOGGED, false).with(FourWayBlock.NORTH, false).with(FourWayBlock.SOUTH, false).with(FourWayBlock.EAST, false).with(FourWayBlock.WEST, false), 49, 12, 21, start);
        structure.setBlockState(world, Blocks.OAK_FENCE.getDefaultState().with(FourWayBlock.WATERLOGGED, false).with(FourWayBlock.NORTH, false).with(FourWayBlock.SOUTH, false).with(FourWayBlock.EAST, false).with(FourWayBlock.WEST, false), 49, 12, 23, start);
        structure.setBlockState(world, Blocks.OAK_FENCE.getDefaultState().with(FourWayBlock.WATERLOGGED, false).with(FourWayBlock.NORTH, false).with(FourWayBlock.SOUTH, false).with(FourWayBlock.EAST, false).with(FourWayBlock.WEST, false), 49, 12, 27, start);
        structure.setBlockState(world, Blocks.OAK_FENCE.getDefaultState().with(FourWayBlock.WATERLOGGED, false).with(FourWayBlock.NORTH, false).with(FourWayBlock.SOUTH, false).with(FourWayBlock.EAST, false).with(FourWayBlock.WEST, false), 49, 12, 29, start);
        structure.setBlockState(world, Blocks.OAK_FENCE.getDefaultState().with(FourWayBlock.WATERLOGGED, false).with(FourWayBlock.NORTH, false).with(FourWayBlock.SOUTH, false).with(FourWayBlock.EAST, false).with(FourWayBlock.WEST, false), 49, 12, 31, start);
        structure.setBlockState(world, Blocks.OAK_FENCE.getDefaultState().with(FourWayBlock.WATERLOGGED, false).with(FourWayBlock.NORTH, false).with(FourWayBlock.SOUTH, false).with(FourWayBlock.EAST, false).with(FourWayBlock.WEST, false), 49, 12, 33, start);
        structure.setBlockState(world, Blocks.OAK_FENCE.getDefaultState().with(FourWayBlock.WATERLOGGED, false).with(FourWayBlock.NORTH, false).with(FourWayBlock.SOUTH, false).with(FourWayBlock.EAST, false).with(FourWayBlock.WEST, false), 49, 12, 35, start);
        structure.setBlockState(world, Blocks.OAK_FENCE.getDefaultState().with(FourWayBlock.WATERLOGGED, false).with(FourWayBlock.NORTH, false).with(FourWayBlock.SOUTH, false).with(FourWayBlock.EAST, false).with(FourWayBlock.WEST, false), 49, 12, 37, start);
        structure.setBlockState(world, Blocks.GRASS_BLOCK.getDefaultState().with(SnowyDirtBlock.SNOWY, false), 50, 1, 5, start);
        structure.setBlockState(world, Blocks.DIRT.getDefaultState(), 50, 3, 43, start);
        structure.setBlockState(world, Blocks.GRASS_BLOCK.getDefaultState().with(SnowyDirtBlock.SNOWY, false), 50, 4, 7, start);
        structure.setBlockState(world, Blocks.DIRT.getDefaultState(), 50, 4, 42, start);
        structure.setBlockState(world, Blocks.GRASS.getDefaultState(), 50, 7, 13, start);
        structure.setBlockState(world, Blocks.DANDELION.getDefaultState(), 50, 7, 21, start);
        structure.setBlockState(world, Blocks.AIR.getDefaultState(), 50, 7, 23, start);
        structure.setBlockState(world, Blocks.AIR.getDefaultState(), 50, 7, 27, start);
        structure.setBlockState(world, Blocks.TALL_GRASS.getDefaultState(), 50, 7, 28, start);
        structure.setBlockState(world, Blocks.GRASS.getDefaultState(), 50, 7, 29, start);
        structure.setBlockState(world, Blocks.ORANGE_TULIP.getDefaultState(), 50, 7, 34, start);
        structure.setBlockState(world, Blocks.GRASS.getDefaultState(), 50, 7, 35, start);
        structure.setBlockState(world, Blocks.GRASS.getDefaultState(), 50, 7, 37, start);
        structure.setBlockState(world, Blocks.GRASS_BLOCK.getDefaultState().with(SnowyDirtBlock.SNOWY, false), 51, 3, 7, start);
        structure.setBlockState(world, Blocks.GRASS_BLOCK.getDefaultState().with(SnowyDirtBlock.SNOWY, false), 51, 3, 43, start);
        structure.setBlockState(world, Blocks.STONE.getDefaultState(), 53, 0, 39, start);
        structure.setBlockState(world, Blocks.STONE.getDefaultState(), 53, 1, 20, start);
        structure.setBlockState(world, Blocks.DIRT.getDefaultState(), 53, 2, 42, start);
        structure.setBlockState(world, Blocks.GRASS_BLOCK.getDefaultState().with(SnowyDirtBlock.SNOWY, false), 53, 3, 42, start);
        structure.setBlockState(world, Blocks.GRASS_BLOCK.getDefaultState().with(SnowyDirtBlock.SNOWY, false), 53, 5, 39, start);
        structure.setBlockState(world, Blocks.GRASS_BLOCK.getDefaultState().with(SnowyDirtBlock.SNOWY, false), 54, 0, 44, start);
        structure.setBlockState(world, Blocks.GRASS_BLOCK.getDefaultState().with(SnowyDirtBlock.SNOWY, false), 54, 1, 43, start);
        structure.setBlockState(world, Blocks.GRASS_BLOCK.getDefaultState().with(SnowyDirtBlock.SNOWY, false), 54, 2, 42, start);
        structure.setBlockState(world, Blocks.GRASS_BLOCK.getDefaultState().with(SnowyDirtBlock.SNOWY, false), 54, 3, 41, start);
        structure.setBlockState(world, Blocks.GRASS_BLOCK.getDefaultState().with(SnowyDirtBlock.SNOWY, false), 54, 4, 11, start);
        structure.setBlockState(world, Blocks.GRASS_BLOCK.getDefaultState().with(SnowyDirtBlock.SNOWY, false), 55, 0, 8, start);
        structure.setBlockState(world, Blocks.GRASS_BLOCK.getDefaultState().with(SnowyDirtBlock.SNOWY, false), 55, 0, 43, start);
        structure.setBlockState(world, Blocks.GRASS_BLOCK.getDefaultState().with(SnowyDirtBlock.SNOWY, false), 55, 1, 9, start);
        structure.setBlockState(world, Blocks.GRASS_BLOCK.getDefaultState().with(SnowyDirtBlock.SNOWY, false), 55, 1, 42, start);
        structure.setBlockState(world, Blocks.GRASS_BLOCK.getDefaultState().with(SnowyDirtBlock.SNOWY, false), 55, 2, 10, start);
        structure.setBlockState(world, Blocks.GRASS_BLOCK.getDefaultState().with(SnowyDirtBlock.SNOWY, false), 55, 2, 24, start);
        structure.setBlockState(world, Blocks.GRASS_BLOCK.getDefaultState().with(SnowyDirtBlock.SNOWY, false), 55, 2, 41, start);
        structure.setBlockState(world, Blocks.GRASS_BLOCK.getDefaultState().with(SnowyDirtBlock.SNOWY, false), 56, 0, 10, start);
        structure.setBlockState(world, Blocks.GRASS_BLOCK.getDefaultState().with(SnowyDirtBlock.SNOWY, false), 56, 0, 42, start);
        structure.setBlockState(world, Blocks.GRASS_BLOCK.getDefaultState().with(SnowyDirtBlock.SNOWY, false), 56, 1, 11, start);
        structure.setBlockState(world, Blocks.GRASS_BLOCK.getDefaultState().with(SnowyDirtBlock.SNOWY, false), 56, 1, 41, start);
        structure.setBlockState(world, Blocks.GRASS_BLOCK.getDefaultState().with(SnowyDirtBlock.SNOWY, false), 57, 0, 41, start);
        structure.fillWithBlocks(world, start, 1, 0, 13, 1, 0, 19, Blocks.GRASS_BLOCK.getDefaultState().with(SnowyDirtBlock.SNOWY, false));
        structure.fillWithBlocks(world, start, 2, 0, 12, 3, 0, 20, Blocks.DIRT.getDefaultState());
        structure.fillWithBlocks(world, start, 2, 0, 21, 2, 0, 30, Blocks.GRASS_BLOCK.getDefaultState().with(SnowyDirtBlock.SNOWY, false));
        structure.fillWithBlocks(world, start, 2, 1, 12, 2, 1, 15, Blocks.GRASS_BLOCK.getDefaultState().with(SnowyDirtBlock.SNOWY, false));
        structure.fillWithBlocks(world, start, 2, 1, 16, 3, 1, 17, Blocks.DIRT.getDefaultState());
        structure.fillWithBlocks(world, start, 2, 1, 18, 2, 1, 20, Blocks.GRASS_BLOCK.getDefaultState().with(SnowyDirtBlock.SNOWY, false));
        structure.fillWithBlocks(world, start, 2, 2, 16, 2, 2, 17, Blocks.GRASS_BLOCK.getDefaultState().with(SnowyDirtBlock.SNOWY, false));
        structure.fillWithBlocks(world, start, 3, 0, 10, 4, 0, 11, Blocks.DIRT.getDefaultState());
        structure.fillWithBlocks(world, start, 3, 0, 21, 4, 0, 36, Blocks.DIRT.getDefaultState());
        structure.fillWithBlocks(world, start, 3, 0, 37, 3, 0, 40, Blocks.GRASS_BLOCK.getDefaultState().with(SnowyDirtBlock.SNOWY, false));
        structure.fillWithBlocks(world, start, 3, 1, 10, 3, 1, 11, Blocks.GRASS_BLOCK.getDefaultState().with(SnowyDirtBlock.SNOWY, false));
        structure.fillWithBlocks(world, start, 3, 1, 12, 4, 1, 22, Blocks.DIRT.getDefaultState());
        structure.fillWithBlocks(world, start, 3, 1, 23, 3, 1, 36, Blocks.GRASS_BLOCK.getDefaultState().with(SnowyDirtBlock.SNOWY, false));
        structure.fillWithBlocks(world, start, 3, 2, 13, 5, 2, 19, Blocks.DIRT.getDefaultState());
        structure.fillWithBlocks(world, start, 3, 2, 20, 3, 2, 22, Blocks.GRASS_BLOCK.getDefaultState().with(SnowyDirtBlock.SNOWY, false));
        structure.fillWithBlocks(world, start, 3, 3, 13, 3, 3, 19, Blocks.GRASS_BLOCK.getDefaultState().with(SnowyDirtBlock.SNOWY, false));
        structure.fillWithBlocks(world, start, 4, 0, 9, 5, 0, 10, Blocks.DIRT.getDefaultState());
        structure.fillWithBlocks(world, start, 4, 0, 12, 9, 0, 17, Blocks.STONE.getDefaultState());
        structure.fillWithBlocks(world, start, 4, 0, 18, 4, 3, 21, Blocks.DIRT.getDefaultState());
        structure.fillWithBlocks(world, start, 4, 0, 37, 5, 0, 40, Blocks.DIRT.getDefaultState());
        structure.fillWithBlocks(world, start, 4, 0, 41, 4, 0, 42, Blocks.GRASS_BLOCK.getDefaultState().with(SnowyDirtBlock.SNOWY, false));
        structure.fillWithBlocks(world, start, 4, 1, 10, 5, 1, 11, Blocks.DIRT.getDefaultState());
        structure.fillWithBlocks(world, start, 4, 1, 23, 6, 1, 30, Blocks.DIRT.getDefaultState());
        structure.fillWithBlocks(world, start, 4, 1, 31, 5, 1, 38, Blocks.DIRT.getDefaultState());
        structure.fillWithBlocks(world, start, 4, 1, 39, 4, 1, 40, Blocks.GRASS_BLOCK.getDefaultState().with(SnowyDirtBlock.SNOWY, false));
        structure.fillWithBlocks(world, start, 4, 2, 11, 6, 2, 13, Blocks.DIRT.getDefaultState());
        structure.fillWithBlocks(world, start, 4, 2, 22, 6, 2, 24, Blocks.DIRT.getDefaultState());
        structure.fillWithBlocks(world, start, 4, 2, 25, 4, 2, 28, Blocks.GRASS_BLOCK.getDefaultState().with(SnowyDirtBlock.SNOWY, false));
        structure.fillWithBlocks(world, start, 4, 2, 29, 6, 2, 34, Blocks.DIRT.getDefaultState());
        structure.fillWithBlocks(world, start, 4, 2, 35, 4, 2, 38, Blocks.GRASS_BLOCK.getDefaultState().with(SnowyDirtBlock.SNOWY, false));
        structure.fillWithBlocks(world, start, 4, 3, 12, 13, 3, 21, Blocks.DIRT.getDefaultState());
        structure.fillWithBlocks(world, start, 4, 3, 22, 4, 3, 24, Blocks.GRASS_BLOCK.getDefaultState().with(SnowyDirtBlock.SNOWY, false));
        structure.fillWithBlocks(world, start, 4, 3, 29, 4, 3, 30, Blocks.GRASS_BLOCK.getDefaultState().with(SnowyDirtBlock.SNOWY, false));
        structure.fillWithBlocks(world, start, 4, 3, 31, 4, 3, 31, Blocks.DIRT.getDefaultState());
        structure.fillWithBlocks(world, start, 4, 3, 32, 4, 3, 34, Blocks.GRASS_BLOCK.getDefaultState().with(SnowyDirtBlock.SNOWY, false));
        structure.fillWithBlocks(world, start, 4, 4, 12, 4, 4, 21, Blocks.GRASS_BLOCK.getDefaultState().with(SnowyDirtBlock.SNOWY, false));
        structure.fillWithBlocks(world, start, 5, 0, 8, 5, 1, 10, Blocks.DIRT.getDefaultState());
        structure.fillWithBlocks(world, start, 5, 0, 11, 16, 0, 22, Blocks.STONE.getDefaultState());
        structure.fillWithBlocks(world, start, 5, 0, 23, 5, 3, 32, Blocks.DIRT.getDefaultState());
        structure.fillWithBlocks(world, start, 5, 0, 33, 8, 0, 36, Blocks.STONE.getDefaultState());
        structure.fillWithBlocks(world, start, 5, 0, 41, 6, 0, 42, Blocks.DIRT.getDefaultState());
        structure.fillWithBlocks(world, start, 5, 0, 43, 5, 0, 44, Blocks.GRASS_BLOCK.getDefaultState().with(SnowyDirtBlock.SNOWY, false));
        structure.fillWithBlocks(world, start, 5, 1, 12, 10, 1, 17, Blocks.STONE.getDefaultState());
        structure.fillWithBlocks(world, start, 5, 1, 18, 5, 4, 22, Blocks.DIRT.getDefaultState());
        structure.fillWithBlocks(world, start, 5, 1, 39, 7, 1, 41, Blocks.DIRT.getDefaultState());
        structure.fillWithBlocks(world, start, 5, 2, 9, 7, 2, 11, Blocks.DIRT.getDefaultState());
        structure.fillWithBlocks(world, start, 5, 2, 35, 6, 2, 39, Blocks.DIRT.getDefaultState());
        structure.fillWithBlocks(world, start, 5, 2, 40, 5, 2, 41, Blocks.GRASS_BLOCK.getDefaultState().with(SnowyDirtBlock.SNOWY, false));
        structure.fillWithBlocks(world, start, 5, 3, 9, 5, 3, 10, Blocks.GRASS_BLOCK.getDefaultState().with(SnowyDirtBlock.SNOWY, false));
        structure.fillWithBlocks(world, start, 5, 3, 11, 31, 3, 37, Blocks.DIRT.getDefaultState());
        structure.fillWithBlocks(world, start, 5, 3, 38, 5, 3, 39, Blocks.GRASS_BLOCK.getDefaultState().with(SnowyDirtBlock.SNOWY, false));
        structure.fillWithBlocks(world, start, 5, 4, 12, 15, 4, 22, Blocks.DIRT.getDefaultState());
        structure.fillWithBlocks(world, start, 5, 4, 23, 5, 4, 37, Blocks.GRASS_BLOCK.getDefaultState().with(SnowyDirtBlock.SNOWY, false));
        structure.fillWithBlocks(world, start, 5, 5, 12, 6, 5, 13, Blocks.GRASS_BLOCK.getDefaultState().with(SnowyDirtBlock.SNOWY, false));
        structure.fillWithBlocks(world, start, 5, 5, 14, 5, 5, 22, Blocks.GRASS_BLOCK.getDefaultState().with(SnowyDirtBlock.SNOWY, false));
        structure.fillWithBlocks(world, start, 6, 0, 7, 6, 1, 8, Blocks.DIRT.getDefaultState());
        structure.fillWithBlocks(world, start, 6, 0, 9, 35, 0, 38, Blocks.STONE.getDefaultState());
        structure.fillWithBlocks(world, start, 6, 0, 39, 6, 2, 41, Blocks.DIRT.getDefaultState());
        structure.fillWithBlocks(world, start, 6, 0, 43, 7, 0, 44, Blocks.DIRT.getDefaultState());
        structure.fillWithBlocks(world, start, 6, 0, 45, 6, 0, 45, Blocks.GRASS_BLOCK.getDefaultState().with(SnowyDirtBlock.SNOWY, false));
        structure.fillWithBlocks(world, start, 6, 1, 9, 6, 2, 10, Blocks.DIRT.getDefaultState());
        structure.fillWithBlocks(world, start, 6, 1, 11, 13, 1, 20, Blocks.STONE.getDefaultState());
        structure.fillWithBlocks(world, start, 6, 1, 21, 6, 4, 30, Blocks.DIRT.getDefaultState());
        structure.fillWithBlocks(world, start, 6, 1, 31, 12, 1, 37, Blocks.STONE.getDefaultState());
        structure.fillWithBlocks(world, start, 6, 1, 38, 7, 1, 43, Blocks.DIRT.getDefaultState());
        structure.fillWithBlocks(world, start, 6, 1, 44, 6, 1, 44, Blocks.GRASS_BLOCK.getDefaultState().with(SnowyDirtBlock.SNOWY, false));
        structure.fillWithBlocks(world, start, 6, 2, 8, 8, 2, 10, Blocks.DIRT.getDefaultState());
        structure.fillWithBlocks(world, start, 6, 2, 14, 8, 2, 17, Blocks.STONE.getDefaultState());
        structure.fillWithBlocks(world, start, 6, 2, 18, 7, 2, 18, Blocks.STONE.getDefaultState());
        structure.fillWithBlocks(world, start, 6, 2, 19, 14, 2, 27, Blocks.DIRT.getDefaultState());
        structure.fillWithBlocks(world, start, 6, 2, 42, 6, 2, 43, Blocks.GRASS_BLOCK.getDefaultState().with(SnowyDirtBlock.SNOWY, false));
        structure.fillWithBlocks(world, start, 6, 3, 9, 37, 3, 40, Blocks.DIRT.getDefaultState());
        structure.fillWithBlocks(world, start, 6, 4, 9, 6, 4, 10, Blocks.GRASS_BLOCK.getDefaultState().with(SnowyDirtBlock.SNOWY, false));
        structure.fillWithBlocks(world, start, 6, 4, 11, 33, 4, 38, Blocks.DIRT.getDefaultState());
        structure.fillWithBlocks(world, start, 6, 4, 39, 6, 4, 40, Blocks.GRASS_BLOCK.getDefaultState().with(SnowyDirtBlock.SNOWY, false));
        structure.fillWithBlocks(world, start, 6, 5, 11, 6, 5, 13, Blocks.GRASS_BLOCK.getDefaultState().with(SnowyDirtBlock.SNOWY, false));
        structure.fillWithBlocks(world, start, 6, 5, 14, 12, 5, 20, Blocks.DIRT.getDefaultState());
        structure.fillWithBlocks(world, start, 6, 5, 21, 6, 5, 38, Blocks.GRASS_BLOCK.getDefaultState().with(SnowyDirtBlock.SNOWY, false));
        structure.fillWithBlocks(world, start, 6, 6, 14, 12, 6, 20, Blocks.GRASS_BLOCK.getDefaultState().with(SnowyDirtBlock.SNOWY, false));
        structure.fillWithBlocks(world, start, 7, 0, 6, 8, 0, 7, Blocks.DIRT.getDefaultState());
        structure.fillWithBlocks(world, start, 7, 0, 8, 39, 0, 40, Blocks.STONE.getDefaultState());
        structure.fillWithBlocks(world, start, 7, 0, 41, 7, 0, 45, Blocks.DIRT.getDefaultState());
        structure.fillWithBlocks(world, start, 7, 0, 46, 8, 0, 46, Blocks.GRASS_BLOCK.getDefaultState().with(SnowyDirtBlock.SNOWY, false));
        structure.fillWithBlocks(world, start, 7, 1, 7, 7, 2, 8, Blocks.DIRT.getDefaultState());
        structure.fillWithBlocks(world, start, 7, 1, 9, 14, 1, 17, Blocks.STONE.getDefaultState());
        structure.fillWithBlocks(world, start, 7, 1, 21, 10, 1, 24, Blocks.STONE.getDefaultState());
        structure.fillWithBlocks(world, start, 7, 1, 25, 7, 4, 28, Blocks.DIRT.getDefaultState());
        structure.fillWithBlocks(world, start, 7, 1, 29, 15, 1, 37, Blocks.STONE.getDefaultState());
        structure.fillWithBlocks(world, start, 7, 1, 44, 7, 1, 44, Blocks.DIRT.getDefaultState());
        structure.fillWithBlocks(world, start, 7, 2, 12, 9, 2, 16, Blocks.STONE.getDefaultState());
        structure.fillWithBlocks(world, start, 7, 2, 29, 7, 4, 29, Blocks.DIRT.getDefaultState());
        structure.fillWithBlocks(world, start, 7, 2, 30, 12, 2, 35, Blocks.STONE.getDefaultState());
        structure.fillWithBlocks(world, start, 7, 2, 36, 7, 4, 40, Blocks.DIRT.getDefaultState());
        structure.fillWithBlocks(world, start, 7, 2, 41, 9, 2, 43, Blocks.DIRT.getDefaultState());
        structure.fillWithBlocks(world, start, 7, 2, 44, 7, 2, 44, Blocks.GRASS_BLOCK.getDefaultState().with(SnowyDirtBlock.SNOWY, false));
        structure.fillWithBlocks(world, start, 7, 3, 8, 41, 3, 42, Blocks.DIRT.getDefaultState());
        structure.fillWithBlocks(world, start, 7, 3, 43, 7, 3, 43, Blocks.GRASS_BLOCK.getDefaultState().with(SnowyDirtBlock.SNOWY, false));
        structure.fillWithBlocks(world, start, 7, 4, 9, 38, 4, 40, Blocks.DIRT.getDefaultState());
        structure.fillWithBlocks(world, start, 7, 4, 41, 7, 4, 42, Blocks.GRASS_BLOCK.getDefaultState().with(SnowyDirtBlock.SNOWY, false));
        structure.fillWithBlocks(world, start, 7, 5, 9, 8, 5, 10, Blocks.GRASS_BLOCK.getDefaultState().with(SnowyDirtBlock.SNOWY, false));
        structure.fillWithBlocks(world, start, 7, 5, 12, 19, 5, 24, Blocks.DIRT.getDefaultState());
        structure.fillWithBlocks(world, start, 7, 5, 25, 7, 5, 29, Blocks.GRASS_BLOCK.getDefaultState().with(SnowyDirtBlock.SNOWY, false));
        structure.fillWithBlocks(world, start, 7, 5, 30, 12, 5, 35, Blocks.DIRT.getDefaultState());
        structure.fillWithBlocks(world, start, 7, 5, 36, 7, 5, 40, Blocks.GRASS_BLOCK.getDefaultState().with(SnowyDirtBlock.SNOWY, false));
        structure.fillWithBlocks(world, start, 7, 6, 12, 12, 6, 24, Blocks.GRASS_BLOCK.getDefaultState().with(SnowyDirtBlock.SNOWY, false));
        structure.fillWithBlocks(world, start, 7, 6, 30, 12, 6, 35, Blocks.GRASS_BLOCK.getDefaultState().with(SnowyDirtBlock.SNOWY, false));
        structure.fillWithBlocks(world, start, 8, 0, 5, 9, 0, 7, Blocks.DIRT.getDefaultState());
        structure.fillWithBlocks(world, start, 8, 0, 41, 51, 0, 41, Blocks.STONE.getDefaultState());
        structure.fillWithBlocks(world, start, 8, 0, 42, 10, 0, 45, Blocks.DIRT.getDefaultState());
        structure.fillWithBlocks(world, start, 8, 1, 6, 9, 1, 7, Blocks.DIRT.getDefaultState());
        structure.fillWithBlocks(world, start, 8, 1, 8, 8, 1, 38, Blocks.STONE.getDefaultState());
        structure.fillWithBlocks(world, start, 8, 1, 39, 8, 4, 42, Blocks.DIRT.getDefaultState());
        structure.fillWithBlocks(world, start, 8, 1, 43, 10, 1, 45, Blocks.DIRT.getDefaultState());
        structure.fillWithBlocks(world, start, 8, 2, 7, 9, 2, 9, Blocks.DIRT.getDefaultState());
        structure.fillWithBlocks(world, start, 8, 2, 11, 10, 2, 13, Blocks.STONE.getDefaultState());
        structure.fillWithBlocks(world, start, 8, 2, 18, 17, 2, 27, Blocks.DIRT.getDefaultState());
        structure.fillWithBlocks(world, start, 8, 2, 28, 13, 2, 36, Blocks.STONE.getDefaultState());
        structure.fillWithBlocks(world, start, 8, 2, 37, 10, 2, 37, Blocks.STONE.getDefaultState());
        structure.fillWithBlocks(world, start, 8, 2, 38, 14, 2, 44, Blocks.DIRT.getDefaultState());
        structure.fillWithBlocks(world, start, 8, 2, 45, 9, 2, 45, Blocks.GRASS_BLOCK.getDefaultState().with(SnowyDirtBlock.SNOWY, false));
        structure.fillWithBlocks(world, start, 8, 3, 7, 44, 3, 43, Blocks.DIRT.getDefaultState());
        structure.fillWithBlocks(world, start, 8, 4, 7, 9, 4, 7, Blocks.GRASS_BLOCK.getDefaultState().with(SnowyDirtBlock.SNOWY, false));
        structure.fillWithBlocks(world, start, 8, 4, 8, 42, 4, 42, Blocks.DIRT.getDefaultState());
        structure.fillWithBlocks(world, start, 8, 4, 43, 8, 4, 43, Blocks.GRASS_BLOCK.getDefaultState().with(SnowyDirtBlock.SNOWY, false));
        structure.fillWithBlocks(world, start, 8, 5, 8, 9, 5, 9, Blocks.GRASS_BLOCK.getDefaultState().with(SnowyDirtBlock.SNOWY, false));
        structure.fillWithBlocks(world, start, 8, 5, 11, 35, 5, 38, Blocks.DIRT.getDefaultState());
        structure.fillWithBlocks(world, start, 8, 5, 39, 8, 5, 42, Blocks.GRASS_BLOCK.getDefaultState().with(SnowyDirtBlock.SNOWY, false));
        structure.fillWithBlocks(world, start, 8, 6, 11, 12, 6, 38, Blocks.GRASS_BLOCK.getDefaultState().with(SnowyDirtBlock.SNOWY, false));
        structure.fillWithBlocks(world, start, 9, 0, 46, 47, 0, 46, Blocks.DIRT.getDefaultState());
        structure.fillWithBlocks(world, start, 9, 0, 47, 10, 0, 47, Blocks.GRASS_BLOCK.getDefaultState().with(SnowyDirtBlock.SNOWY, false));
        structure.fillWithBlocks(world, start, 9, 1, 5, 11, 1, 7, Blocks.DIRT.getDefaultState());
        structure.fillWithBlocks(world, start, 9, 1, 8, 10, 2, 8, Blocks.DIRT.getDefaultState());
        structure.fillWithBlocks(world, start, 9, 1, 25, 22, 1, 38, Blocks.STONE.getDefaultState());
        structure.fillWithBlocks(world, start, 9, 1, 39, 10, 1, 40, Blocks.STONE.getDefaultState());
        structure.fillWithBlocks(world, start, 9, 1, 41, 9, 1, 45, Blocks.DIRT.getDefaultState());
        structure.fillWithBlocks(world, start, 9, 2, 5, 10, 2, 5, Blocks.GRASS_BLOCK.getDefaultState().with(SnowyDirtBlock.SNOWY, false));
        structure.fillWithBlocks(world, start, 9, 2, 6, 11, 2, 8, Blocks.DIRT.getDefaultState());
        structure.fillWithBlocks(world, start, 9, 2, 10, 10, 2, 13, Blocks.STONE.getDefaultState());
        structure.fillWithBlocks(world, start, 9, 2, 17, 19, 2, 27, Blocks.DIRT.getDefaultState());
        structure.fillWithBlocks(world, start, 9, 3, 44, 47, 3, 44, Blocks.DIRT.getDefaultState());
        structure.fillWithBlocks(world, start, 9, 4, 43, 48, 4, 43, Blocks.DIRT.getDefaultState());
        structure.fillWithBlocks(world, start, 9, 4, 44, 10, 4, 44, Blocks.GRASS_BLOCK.getDefaultState().with(SnowyDirtBlock.SNOWY, false));
