package mod.arcalitegames.odyssey.world.structure.structures.camps.illager_camp;

import mod.arcalitegames.odyssey.world.structure.StructureBase;
import net.minecraft.block.Blocks;
import net.minecraft.block.ChainBlock;
import net.minecraft.block.FenceGateBlock;
import net.minecraft.block.FourWayBlock;
import net.minecraft.block.HorizontalBlock;
import net.minecraft.block.LadderBlock;
import net.minecraft.block.LeavesBlock;
import net.minecraft.block.SlabBlock;
import net.minecraft.block.SnowyDirtBlock;
import net.minecraft.block.StairsBlock;
import net.minecraft.block.SweetBerryBushBlock;
import net.minecraft.block.TrapDoorBlock;
import net.minecraft.block.WallBlock;
import net.minecraft.block.WallHeight;
import net.minecraft.state.properties.Half;
import net.minecraft.state.properties.SlabType;
import net.minecraft.state.properties.StairsShape;
import net.minecraft.util.Direction;
import net.minecraft.util.math.BlockPos;
import net.minecraft.world.World;

public class IllagerComponent1
{

	public static BlockPos start;
    public static World world;
    public static StructureBase structure;

    public static void init(World worldIn, BlockPos blockPos, StructureBase structureIn)
    {
        world = worldIn; start = blockPos; structure = structureIn;
    }
    
    public static void generatePart11()
    {
        structure.fillWithBlocks(world, start, 66, 9, 46, 67, 9, 46, Blocks.SPRUCE_TRAPDOOR.getDefaultState().with(HorizontalBlock.HORIZONTAL_FACING, Direction.SOUTH).with(TrapDoorBlock.HALF, Half.BOTTOM).with(TrapDoorBlock.WATERLOGGED, false).with(TrapDoorBlock.POWERED, false).with(TrapDoorBlock.OPEN, true));
        structure.fillWithBlocks(world, start, 66, 9, 48, 67, 9, 48, Blocks.GRASS.getDefaultState());
        structure.fillWithBlocks(world, start, 66, 9, 79, 66, 9, 79, Blocks.GRASS.getDefaultState());
        structure.fillWithBlocks(world, start, 66, 9, 95, 66, 9, 95, Blocks.GRASS.getDefaultState());
        structure.fillWithBlocks(world, start, 66, 9, 99, 93, 9, 99, Blocks.GRASS.getDefaultState());
        structure.fillWithBlocks(world, start, 66, 10, 20, 67, 11, 20, Blocks.DARK_OAK_LOG.getDefaultState());
        structure.fillWithBlocks(world, start, 66, 10, 31, 67, 10, 31, Blocks.OAK_TRAPDOOR.getDefaultState().with(HorizontalBlock.HORIZONTAL_FACING, Direction.NORTH).with(TrapDoorBlock.HALF, Half.TOP).with(TrapDoorBlock.WATERLOGGED, false).with(TrapDoorBlock.POWERED, false).with(TrapDoorBlock.OPEN, true));
        structure.fillWithBlocks(world, start, 66, 10, 39, 67, 11, 39, Blocks.OAK_TRAPDOOR.getDefaultState().with(HorizontalBlock.HORIZONTAL_FACING, Direction.SOUTH).with(TrapDoorBlock.HALF, Half.BOTTOM).with(TrapDoorBlock.WATERLOGGED, false).with(TrapDoorBlock.POWERED, false).with(TrapDoorBlock.OPEN, true));
        structure.fillWithBlocks(world, start, 66, 10, 100, 67, 11, 100, Blocks.DARK_OAK_LOG.getDefaultState());
        structure.fillWithBlocks(world, start, 66, 11, 31, 67, 11, 31, Blocks.OAK_TRAPDOOR.getDefaultState().with(HorizontalBlock.HORIZONTAL_FACING, Direction.NORTH).with(TrapDoorBlock.HALF, Half.BOTTOM).with(TrapDoorBlock.WATERLOGGED, false).with(TrapDoorBlock.POWERED, false).with(TrapDoorBlock.OPEN, true));
        structure.fillWithBlocks(world, start, 66, 12, 20, 67, 13, 20, Blocks.DARK_OAK_LOG.getDefaultState());
        structure.fillWithBlocks(world, start, 66, 12, 32, 67, 12, 32, Blocks.OAK_FENCE_GATE.getDefaultState().with(FenceGateBlock.IN_WALL, false).with(FenceGateBlock.OPEN, false).with(FenceGateBlock.POWERED, false));
        structure.fillWithBlocks(world, start, 66, 12, 38, 67, 12, 38, Blocks.OAK_FENCE_GATE.getDefaultState().with(FenceGateBlock.IN_WALL, false).with(FenceGateBlock.OPEN, false).with(FenceGateBlock.POWERED, false));
        structure.fillWithBlocks(world, start, 66, 12, 39, 68, 12, 39, Blocks.SPRUCE_TRAPDOOR.getDefaultState().with(HorizontalBlock.HORIZONTAL_FACING, Direction.SOUTH).with(TrapDoorBlock.HALF, Half.TOP).with(TrapDoorBlock.WATERLOGGED, false).with(TrapDoorBlock.POWERED, false).with(TrapDoorBlock.OPEN, true));
        structure.fillWithBlocks(world, start, 66, 12, 81, 66, 12, 81, Blocks.BIRCH_SLAB.getDefaultState().with(SlabBlock.TYPE, SlabType.BOTTOM).with(SlabBlock.WATERLOGGED, false));
        structure.fillWithBlocks(world, start, 66, 12, 83, 66, 12, 83, Blocks.BIRCH_SLAB.getDefaultState().with(SlabBlock.TYPE, SlabType.BOTTOM).with(SlabBlock.WATERLOGGED, false));
        structure.fillWithBlocks(world, start, 66, 12, 100, 67, 13, 100, Blocks.DARK_OAK_LOG.getDefaultState());
        structure.fillWithBlocks(world, start, 66, 13, 99, 94, 13, 99, Blocks.DARK_OAK_TRAPDOOR.getDefaultState().with(HorizontalBlock.HORIZONTAL_FACING, Direction.NORTH).with(TrapDoorBlock.HALF, Half.TOP).with(TrapDoorBlock.WATERLOGGED, false).with(TrapDoorBlock.POWERED, false).with(TrapDoorBlock.OPEN, false));
        structure.fillWithBlocks(world, start, 66, 14, 19, 70, 14, 19, Blocks.SPRUCE_WOOD.getDefaultState());
        structure.fillWithBlocks(world, start, 66, 14, 98, 94, 14, 98, Blocks.DARK_OAK_TRAPDOOR.getDefaultState().with(HorizontalBlock.HORIZONTAL_FACING, Direction.NORTH).with(TrapDoorBlock.HALF, Half.BOTTOM).with(TrapDoorBlock.WATERLOGGED, false).with(TrapDoorBlock.POWERED, false).with(TrapDoorBlock.OPEN, true));
        structure.fillWithBlocks(world, start, 66, 14, 99, 67, 14, 100, Blocks.JUNGLE_SLAB.getDefaultState().with(SlabBlock.TYPE, SlabType.BOTTOM).with(SlabBlock.WATERLOGGED, false));
        structure.fillWithBlocks(world, start, 66, 14, 101, 70, 14, 101, Blocks.SPRUCE_LOG.getDefaultState());
        structure.fillWithBlocks(world, start, 66, 15, 19, 70, 15, 19, Blocks.BIRCH_FENCE.getDefaultState().with(FourWayBlock.WATERLOGGED, false).with(FourWayBlock.NORTH, false).with(FourWayBlock.SOUTH, false).with(FourWayBlock.EAST, true).with(FourWayBlock.WEST, true));
        structure.fillWithBlocks(world, start, 66, 15, 101, 70, 15, 101, Blocks.BIRCH_FENCE.getDefaultState().with(FourWayBlock.WATERLOGGED, false).with(FourWayBlock.NORTH, false).with(FourWayBlock.SOUTH, false).with(FourWayBlock.EAST, true).with(FourWayBlock.WEST, true));
        structure.fillWithBlocks(world, start, 67, 0, 109, 69, 0, 111, Blocks.DIRT.getDefaultState());
        structure.fillWithBlocks(world, start, 67, 1, 106, 84, 1, 106, Blocks.STONE.getDefaultState());
        structure.fillWithBlocks(world, start, 67, 1, 107, 70, 1, 110, Blocks.DIRT.getDefaultState());
        structure.fillWithBlocks(world, start, 67, 6, 16, 68, 6, 18, Blocks.GRASS_BLOCK.getDefaultState().with(SnowyDirtBlock.SNOWY, false));
        structure.fillWithBlocks(world, start, 67, 6, 74, 67, 6, 76, Blocks.STONE.getDefaultState());
        structure.fillWithBlocks(world, start, 67, 6, 77, 68, 6, 100, Blocks.DIRT.getDefaultState());
        structure.fillWithBlocks(world, start, 67, 6, 101, 99, 6, 101, Blocks.MOSSY_COBBLESTONE.getDefaultState());
        structure.fillWithBlocks(world, start, 67, 6, 106, 68, 6, 107, Blocks.GRASS_BLOCK.getDefaultState().with(SnowyDirtBlock.SNOWY, false));
        structure.fillWithBlocks(world, start, 67, 7, 21, 80, 7, 34, Blocks.DIRT.getDefaultState());
        structure.fillWithBlocks(world, start, 67, 8, 23, 68, 8, 24, Blocks.GRASS_BLOCK.getDefaultState().with(SnowyDirtBlock.SNOWY, false));
        structure.fillWithBlocks(world, start, 67, 8, 46, 69, 8, 48, Blocks.GRASS_BLOCK.getDefaultState().with(SnowyDirtBlock.SNOWY, false));
        structure.fillWithBlocks(world, start, 67, 8, 50, 67, 8, 70, Blocks.STONE_BRICKS.getDefaultState());
        structure.fillWithBlocks(world, start, 67, 8, 74, 67, 8, 78, Blocks.GRASS_PATH.getDefaultState());
        structure.fillWithBlocks(world, start, 67, 8, 85, 69, 8, 85, Blocks.MOSSY_COBBLESTONE.getDefaultState());
        structure.fillWithBlocks(world, start, 67, 8, 86, 67, 8, 86, Blocks.GRASS_BLOCK.getDefaultState().with(SnowyDirtBlock.SNOWY, false));
        structure.fillWithBlocks(world, start, 67, 8, 87, 67, 8, 87, Blocks.GRASS_PATH.getDefaultState());
        structure.fillWithBlocks(world, start, 67, 8, 88, 67, 8, 88, Blocks.GRASS_BLOCK.getDefaultState().with(SnowyDirtBlock.SNOWY, false));
        structure.fillWithBlocks(world, start, 67, 8, 90, 68, 8, 97, Blocks.GRASS_BLOCK.getDefaultState().with(SnowyDirtBlock.SNOWY, false));
        structure.fillWithBlocks(world, start, 67, 9, 25, 67, 10, 25, Blocks.OAK_FENCE.getDefaultState().with(FourWayBlock.WATERLOGGED, false).with(FourWayBlock.NORTH, true).with(FourWayBlock.SOUTH, false).with(FourWayBlock.EAST, true).with(FourWayBlock.WEST, false));
        structure.fillWithBlocks(world, start, 67, 9, 28, 67, 10, 28, Blocks.OAK_FENCE.getDefaultState().with(FourWayBlock.WATERLOGGED, false).with(FourWayBlock.NORTH, false).with(FourWayBlock.SOUTH, true).with(FourWayBlock.EAST, true).with(FourWayBlock.WEST, false));
        structure.fillWithBlocks(world, start, 67, 9, 42, 67, 10, 42, Blocks.OAK_FENCE.getDefaultState().with(FourWayBlock.WATERLOGGED, false).with(FourWayBlock.NORTH, true).with(FourWayBlock.SOUTH, false).with(FourWayBlock.EAST, true).with(FourWayBlock.WEST, false));
        structure.fillWithBlocks(world, start, 67, 9, 45, 67, 10, 45, Blocks.OAK_FENCE.getDefaultState().with(FourWayBlock.WATERLOGGED, false).with(FourWayBlock.NORTH, false).with(FourWayBlock.SOUTH, true).with(FourWayBlock.EAST, true).with(FourWayBlock.WEST, false));
        structure.fillWithBlocks(world, start, 67, 9, 80, 72, 9, 80, Blocks.GRASS.getDefaultState());
        structure.fillWithBlocks(world, start, 67, 9, 91, 67, 9, 91, Blocks.GRASS.getDefaultState());
        structure.fillWithBlocks(world, start, 67, 9, 94, 67, 9, 94, Blocks.GRASS.getDefaultState());
        structure.fillWithBlocks(world, start, 67, 9, 96, 67, 9, 97, Blocks.GRASS.getDefaultState());
        structure.fillWithBlocks(world, start, 67, 10, 24, 67, 11, 24, Blocks.SPRUCE_TRAPDOOR.getDefaultState().with(HorizontalBlock.HORIZONTAL_FACING, Direction.NORTH).with(TrapDoorBlock.HALF, Half.BOTTOM).with(TrapDoorBlock.WATERLOGGED, false).with(TrapDoorBlock.POWERED, false).with(TrapDoorBlock.OPEN, true));
        structure.fillWithBlocks(world, start, 67, 10, 29, 67, 11, 29, Blocks.SPRUCE_TRAPDOOR.getDefaultState().with(HorizontalBlock.HORIZONTAL_FACING, Direction.SOUTH).with(TrapDoorBlock.HALF, Half.BOTTOM).with(TrapDoorBlock.WATERLOGGED, false).with(TrapDoorBlock.POWERED, false).with(TrapDoorBlock.OPEN, true));
        structure.fillWithBlocks(world, start, 67, 11, 26, 67, 11, 27, Blocks.OAK_FENCE_GATE.getDefaultState().with(FenceGateBlock.IN_WALL, false).with(FenceGateBlock.OPEN, false).with(FenceGateBlock.POWERED, false));
        structure.fillWithBlocks(world, start, 67, 11, 43, 67, 11, 44, Blocks.OAK_FENCE_GATE.getDefaultState().with(FenceGateBlock.IN_WALL, false).with(FenceGateBlock.OPEN, false).with(FenceGateBlock.POWERED, false));
        structure.fillWithBlocks(world, start, 67, 12, 82, 67, 12, 82, Blocks.BIRCH_SLAB.getDefaultState().with(SlabBlock.TYPE, SlabType.BOTTOM).with(SlabBlock.WATERLOGGED, false));
        structure.fillWithBlocks(world, start, 67, 12, 84, 67, 12, 84, Blocks.BIRCH_SLAB.getDefaultState().with(SlabBlock.TYPE, SlabType.BOTTOM).with(SlabBlock.WATERLOGGED, false));
        structure.fillWithBlocks(world, start, 67, 14, 20, 68, 14, 21, Blocks.JUNGLE_SLAB.getDefaultState().with(SlabBlock.TYPE, SlabType.BOTTOM).with(SlabBlock.WATERLOGGED, false));
        structure.fillWithBlocks(world, start, 68, 4, 5, 70, 4, 7, Blocks.DIRT.getDefaultState());
        structure.fillWithBlocks(world, start, 68, 5, 103, 72, 5, 107, Blocks.DIRT.getDefaultState());
        structure.fillWithBlocks(world, start, 68, 6, 15, 68, 6, 18, Blocks.GRASS_BLOCK.getDefaultState().with(SnowyDirtBlock.SNOWY, false));
        structure.fillWithBlocks(world, start, 68, 6, 75, 68, 6, 76, Blocks.COAL_ORE.getDefaultState());
        structure.fillWithBlocks(world, start, 68, 6, 105, 70, 6, 107, Blocks.GRASS_BLOCK.getDefaultState().with(SnowyDirtBlock.SNOWY, false));
        structure.fillWithBlocks(world, start, 68, 7, 8, 68, 7, 8, Blocks.GRASS.getDefaultState());
        structure.fillWithBlocks(world, start, 68, 7, 36, 91, 7, 99, Blocks.DIRT.getDefaultState());
        structure.fillWithBlocks(world, start, 68, 8, 20, 70, 8, 20, Blocks.DARK_OAK_LOG.getDefaultState());
        structure.fillWithBlocks(world, start, 68, 8, 25, 72, 8, 31, Blocks.GRASS_BLOCK.getDefaultState().with(SnowyDirtBlock.SNOWY, false));
        structure.fillWithBlocks(world, start, 68, 8, 32, 68, 8, 34, Blocks.PODZOL.getDefaultState().with(SnowyDirtBlock.SNOWY, false));
        structure.fillWithBlocks(world, start, 68, 8, 36, 68, 8, 38, Blocks.PODZOL.getDefaultState().with(SnowyDirtBlock.SNOWY, false));
        structure.fillWithBlocks(world, start, 68, 8, 42, 70, 8, 48, Blocks.GRASS_BLOCK.getDefaultState().with(SnowyDirtBlock.SNOWY, false));
        structure.fillWithBlocks(world, start, 68, 8, 49, 68, 8, 50, Blocks.GRASS_BLOCK.getDefaultState().with(SnowyDirtBlock.SNOWY, false));
        structure.fillWithBlocks(world, start, 68, 8, 51, 68, 8, 54, Blocks.STONE_BRICKS.getDefaultState());
        structure.fillWithBlocks(world, start, 68, 8, 56, 69, 8, 60, Blocks.STONE_BRICKS.getDefaultState());
        structure.fillWithBlocks(world, start, 68, 8, 62, 69, 8, 65, Blocks.STONE_BRICKS.getDefaultState());
        structure.fillWithBlocks(world, start, 68, 8, 67, 69, 8, 68, Blocks.STONE_BRICKS.getDefaultState());
        structure.fillWithBlocks(world, start, 68, 8, 70, 68, 8, 73, Blocks.GRASS_BLOCK.getDefaultState().with(SnowyDirtBlock.SNOWY, false));
        structure.fillWithBlocks(world, start, 68, 8, 74, 68, 8, 74, Blocks.ACACIA_SLAB.getDefaultState().with(SlabBlock.TYPE, SlabType.DOUBLE).with(SlabBlock.WATERLOGGED, false));
        structure.fillWithBlocks(world, start, 68, 8, 75, 68, 8, 77, Blocks.GRASS_PATH.getDefaultState());
        structure.fillWithBlocks(world, start, 68, 8, 79, 69, 8, 80, Blocks.GRASS_BLOCK.getDefaultState().with(SnowyDirtBlock.SNOWY, false));
        structure.fillWithBlocks(world, start, 68, 8, 82, 68, 8, 85, Blocks.MOSSY_COBBLESTONE.getDefaultState());
        structure.fillWithBlocks(world, start, 68, 8, 86, 68, 8, 87, Blocks.GRASS_BLOCK.getDefaultState().with(SnowyDirtBlock.SNOWY, false));
        structure.fillWithBlocks(world, start, 68, 8, 88, 68, 8, 88, Blocks.GRASS_PATH.getDefaultState());
        structure.fillWithBlocks(world, start, 68, 8, 89, 68, 8, 97, Blocks.GRASS_BLOCK.getDefaultState().with(SnowyDirtBlock.SNOWY, false));
        structure.fillWithBlocks(world, start, 68, 8, 100, 70, 8, 100, Blocks.DARK_OAK_LOG.getDefaultState());
        structure.fillWithBlocks(world, start, 68, 9, 24, 68, 9, 24, Blocks.GRASS.getDefaultState());
        structure.fillWithBlocks(world, start, 68, 9, 25, 68, 9, 28, Blocks.SPRUCE_TRAPDOOR.getDefaultState().with(HorizontalBlock.HORIZONTAL_FACING, Direction.EAST).with(TrapDoorBlock.HALF, Half.BOTTOM).with(TrapDoorBlock.WATERLOGGED, false).with(TrapDoorBlock.POWERED, false).with(TrapDoorBlock.OPEN, true));
        structure.fillWithBlocks(world, start, 68, 9, 29, 69, 9, 30, Blocks.GRASS.getDefaultState());
        structure.fillWithBlocks(world, start, 68, 9, 32, 68, 11, 32, Blocks.OAK_FENCE.getDefaultState().with(FourWayBlock.WATERLOGGED, false).with(FourWayBlock.NORTH, true).with(FourWayBlock.SOUTH, false).with(FourWayBlock.EAST, true).with(FourWayBlock.WEST, false));
        structure.fillWithBlocks(world, start, 68, 9, 35, 68, 11, 35, Blocks.OAK_FENCE.getDefaultState().with(FourWayBlock.WATERLOGGED, false).with(FourWayBlock.NORTH, false).with(FourWayBlock.SOUTH, false).with(FourWayBlock.EAST, true).with(FourWayBlock.WEST, false));
        structure.fillWithBlocks(world, start, 68, 9, 38, 68, 11, 38, Blocks.OAK_FENCE.getDefaultState().with(FourWayBlock.WATERLOGGED, false).with(FourWayBlock.NORTH, false).with(FourWayBlock.SOUTH, true).with(FourWayBlock.EAST, true).with(FourWayBlock.WEST, false));
        structure.fillWithBlocks(world, start, 68, 9, 41, 68, 9, 41, Blocks.GRASS.getDefaultState());
        structure.fillWithBlocks(world, start, 68, 9, 42, 68, 9, 45, Blocks.SPRUCE_TRAPDOOR.getDefaultState().with(HorizontalBlock.HORIZONTAL_FACING, Direction.EAST).with(TrapDoorBlock.HALF, Half.BOTTOM).with(TrapDoorBlock.WATERLOGGED, false).with(TrapDoorBlock.POWERED, false).with(TrapDoorBlock.OPEN, true));
        structure.fillWithBlocks(world, start, 68, 9, 46, 69, 9, 47, Blocks.GRASS.getDefaultState());
        structure.fillWithBlocks(world, start, 68, 9, 50, 68, 9, 50, Blocks.GRASS.getDefaultState());
        structure.fillWithBlocks(world, start, 68, 9, 72, 68, 9, 73, Blocks.GRASS.getDefaultState());
        structure.fillWithBlocks(world, start, 68, 9, 74, 68, 9, 74, Blocks.ACACIA_SLAB.getDefaultState().with(SlabBlock.TYPE, SlabType.BOTTOM).with(SlabBlock.WATERLOGGED, false));
        structure.fillWithBlocks(world, start, 68, 9, 81, 68, 11, 81, Blocks.BIRCH_FENCE.getDefaultState().with(FourWayBlock.WATERLOGGED, false).with(FourWayBlock.NORTH, false).with(FourWayBlock.SOUTH, false).with(FourWayBlock.EAST, false).with(FourWayBlock.WEST, false));
        structure.fillWithBlocks(world, start, 68, 9, 82, 68, 10, 84, Blocks.CHAIN.getDefaultState().with(ChainBlock.WATERLOGGED, false));
        structure.fillWithBlocks(world, start, 68, 9, 85, 68, 11, 85, Blocks.BIRCH_FENCE.getDefaultState().with(FourWayBlock.WATERLOGGED, false).with(FourWayBlock.NORTH, false).with(FourWayBlock.SOUTH, false).with(FourWayBlock.EAST, false).with(FourWayBlock.WEST, false));
        structure.fillWithBlocks(world, start, 68, 9, 89, 68, 9, 92, Blocks.GRASS.getDefaultState());
        structure.fillWithBlocks(world, start, 68, 9, 94, 68, 9, 95, Blocks.GRASS.getDefaultState());
        structure.fillWithBlocks(world, start, 68, 9, 97, 70, 9, 97, Blocks.GRASS.getDefaultState());
        structure.fillWithBlocks(world, start, 68, 10, 20, 68, 11, 20, Blocks.IRON_BARS.getDefaultState().with(FourWayBlock.WATERLOGGED, false).with(FourWayBlock.NORTH, false).with(FourWayBlock.SOUTH, false).with(FourWayBlock.EAST, true).with(FourWayBlock.WEST, true));
        structure.fillWithBlocks(world, start, 68, 10, 25, 68, 11, 25, Blocks.SPRUCE_TRAPDOOR.getDefaultState().with(HorizontalBlock.HORIZONTAL_FACING, Direction.EAST).with(TrapDoorBlock.HALF, Half.BOTTOM).with(TrapDoorBlock.WATERLOGGED, false).with(TrapDoorBlock.POWERED, false).with(TrapDoorBlock.OPEN, true));
        structure.fillWithBlocks(world, start, 68, 10, 26, 68, 10, 27, Blocks.OAK_TRAPDOOR.getDefaultState().with(HorizontalBlock.HORIZONTAL_FACING, Direction.EAST).with(TrapDoorBlock.HALF, Half.BOTTOM).with(TrapDoorBlock.WATERLOGGED, false).with(TrapDoorBlock.POWERED, false).with(TrapDoorBlock.OPEN, true));
        structure.fillWithBlocks(world, start, 68, 10, 28, 68, 11, 28, Blocks.SPRUCE_TRAPDOOR.getDefaultState().with(HorizontalBlock.HORIZONTAL_FACING, Direction.EAST).with(TrapDoorBlock.HALF, Half.BOTTOM).with(TrapDoorBlock.WATERLOGGED, false).with(TrapDoorBlock.POWERED, false).with(TrapDoorBlock.OPEN, true));
        structure.fillWithBlocks(world, start, 68, 10, 39, 68, 12, 39, Blocks.SPRUCE_TRAPDOOR.getDefaultState().with(HorizontalBlock.HORIZONTAL_FACING, Direction.SOUTH).with(TrapDoorBlock.HALF, Half.TOP).with(TrapDoorBlock.WATERLOGGED, false).with(TrapDoorBlock.POWERED, false).with(TrapDoorBlock.OPEN, true));
        structure.fillWithBlocks(world, start, 68, 10, 43, 68, 10, 44, Blocks.OAK_TRAPDOOR.getDefaultState().with(HorizontalBlock.HORIZONTAL_FACING, Direction.EAST).with(TrapDoorBlock.HALF, Half.BOTTOM).with(TrapDoorBlock.WATERLOGGED, false).with(TrapDoorBlock.POWERED, false).with(TrapDoorBlock.OPEN, true));
        structure.fillWithBlocks(world, start, 68, 10, 45, 68, 11, 45, Blocks.SPRUCE_TRAPDOOR.getDefaultState().with(HorizontalBlock.HORIZONTAL_FACING, Direction.EAST).with(TrapDoorBlock.HALF, Half.BOTTOM).with(TrapDoorBlock.WATERLOGGED, false).with(TrapDoorBlock.POWERED, false).with(TrapDoorBlock.OPEN, true));
        structure.fillWithBlocks(world, start, 68, 10, 100, 68, 11, 100, Blocks.IRON_BARS.getDefaultState().with(FourWayBlock.WATERLOGGED, false).with(FourWayBlock.NORTH, false).with(FourWayBlock.SOUTH, false).with(FourWayBlock.EAST, true).with(FourWayBlock.WEST, true));
        structure.fillWithBlocks(world, start, 68, 11, 26, 68, 11, 28, Blocks.SPRUCE_TRAPDOOR.getDefaultState().with(HorizontalBlock.HORIZONTAL_FACING, Direction.EAST).with(TrapDoorBlock.HALF, Half.BOTTOM).with(TrapDoorBlock.WATERLOGGED, false).with(TrapDoorBlock.POWERED, false).with(TrapDoorBlock.OPEN, true));
        structure.fillWithBlocks(world, start, 68, 11, 43, 68, 11, 45, Blocks.SPRUCE_TRAPDOOR.getDefaultState().with(HorizontalBlock.HORIZONTAL_FACING, Direction.EAST).with(TrapDoorBlock.HALF, Half.BOTTOM).with(TrapDoorBlock.WATERLOGGED, false).with(TrapDoorBlock.POWERED, false).with(TrapDoorBlock.OPEN, true));
        structure.fillWithBlocks(world, start, 68, 12, 33, 68, 12, 34, Blocks.OAK_FENCE_GATE.getDefaultState().with(FenceGateBlock.IN_WALL, false).with(FenceGateBlock.OPEN, false).with(FenceGateBlock.POWERED, false));
        structure.fillWithBlocks(world, start, 68, 12, 36, 68, 12, 37, Blocks.OAK_FENCE_GATE.getDefaultState().with(FenceGateBlock.IN_WALL, false).with(FenceGateBlock.OPEN, false).with(FenceGateBlock.POWERED, false));
        structure.fillWithBlocks(world, start, 68, 12, 81, 68, 12, 85, Blocks.BIRCH_SLAB.getDefaultState().with(SlabBlock.TYPE, SlabType.BOTTOM).with(SlabBlock.WATERLOGGED, false));
        structure.fillWithBlocks(world, start, 68, 13, 20, 70, 13, 20, Blocks.DARK_OAK_LOG.getDefaultState());
        structure.fillWithBlocks(world, start, 68, 13, 100, 70, 13, 100, Blocks.DARK_OAK_LOG.getDefaultState());
        structure.fillWithBlocks(world, start, 68, 14, 99, 69, 14, 100, Blocks.JUNGLE_SLAB.getDefaultState().with(SlabBlock.TYPE, SlabType.BOTTOM).with(SlabBlock.WATERLOGGED, false));
        structure.fillWithBlocks(world, start, 69, 0, 1, 71, 0, 3, Blocks.DIRT.getDefaultState());
        structure.fillWithBlocks(world, start, 69, 2, 2, 74, 2, 7, Blocks.DIRT.getDefaultState());
        structure.fillWithBlocks(world, start, 69, 3, 5, 71, 3, 7, Blocks.DIRT.getDefaultState());
        structure.fillWithBlocks(world, start, 69, 5, 5, 71, 5, 7, Blocks.DIRT.getDefaultState());
        structure.fillWithBlocks(world, start, 69, 6, 15, 69, 6, 15, Blocks.GRASS_BLOCK.getDefaultState().with(SnowyDirtBlock.SNOWY, false));
        structure.fillWithBlocks(world, start, 69, 6, 17, 70, 6, 18, Blocks.GRASS_BLOCK.getDefaultState().with(SnowyDirtBlock.SNOWY, false));
        structure.fillWithBlocks(world, start, 69, 6, 74, 69, 6, 74, Blocks.DIRT.getDefaultState());
        structure.fillWithBlocks(world, start, 69, 6, 75, 69, 6, 75, Blocks.COAL_ORE.getDefaultState());
        structure.fillWithBlocks(world, start, 69, 6, 76, 69, 7, 77, Blocks.DIRT.getDefaultState());
        structure.fillWithBlocks(world, start, 69, 6, 98, 71, 6, 100, Blocks.DIRT.getDefaultState());
        structure.fillWithBlocks(world, start, 69, 6, 102, 70, 6, 103, Blocks.GRASS_BLOCK.getDefaultState().with(SnowyDirtBlock.SNOWY, false));
        structure.fillWithBlocks(world, start, 69, 7, 8, 69, 7, 9, Blocks.GRASS.getDefaultState());
        structure.fillWithBlocks(world, start, 69, 7, 35, 91, 7, 99, Blocks.DIRT.getDefaultState());
        structure.fillWithBlocks(world, start, 69, 8, 23, 72, 8, 32, Blocks.GRASS_BLOCK.getDefaultState().with(SnowyDirtBlock.SNOWY, false));
        structure.fillWithBlocks(world, start, 69, 8, 33, 70, 8, 48, Blocks.GRASS_BLOCK.getDefaultState().with(SnowyDirtBlock.SNOWY, false));
        structure.fillWithBlocks(world, start, 69, 8, 50, 70, 8, 51, Blocks.GRASS_BLOCK.getDefaultState().with(SnowyDirtBlock.SNOWY, false));
        structure.fillWithBlocks(world, start, 69, 8, 53, 69, 8, 68, Blocks.STONE_BRICKS.getDefaultState());
        structure.fillWithBlocks(world, start, 69, 8, 69, 70, 8, 70, Blocks.GRASS_BLOCK.getDefaultState().with(SnowyDirtBlock.SNOWY, false));
        structure.fillWithBlocks(world, start, 69, 8, 72, 71, 8, 74, Blocks.GRASS_BLOCK.getDefaultState().with(SnowyDirtBlock.SNOWY, false));
        structure.fillWithBlocks(world, start, 69, 8, 78, 71, 8, 80, Blocks.GRASS_BLOCK.getDefaultState().with(SnowyDirtBlock.SNOWY, false));
        structure.fillWithBlocks(world, start, 69, 8, 82, 71, 8, 84, Blocks.COBBLESTONE.getDefaultState());
        structure.fillWithBlocks(world, start, 69, 8, 86, 69, 8, 86, Blocks.GRASS_BLOCK.getDefaultState().with(SnowyDirtBlock.SNOWY, false));
        structure.fillWithBlocks(world, start, 69, 8, 87, 69, 8, 87, Blocks.GRASS_PATH.getDefaultState());
        structure.fillWithBlocks(world, start, 69, 8, 88, 69, 8, 88, Blocks.GRASS_BLOCK.getDefaultState().with(SnowyDirtBlock.SNOWY, false));
        structure.fillWithBlocks(world, start, 69, 8, 89, 69, 8, 89, Blocks.GRASS_PATH.getDefaultState());
        structure.fillWithBlocks(world, start, 69, 8, 91, 71, 8, 94, Blocks.HAY_BLOCK.getDefaultState());
        structure.fillWithBlocks(world, start, 69, 8, 95, 71, 8, 97, Blocks.GRASS_BLOCK.getDefaultState().with(SnowyDirtBlock.SNOWY, false));
        structure.fillWithBlocks(world, start, 69, 9, 20, 70, 10, 20, Blocks.DARK_OAK_LOG.getDefaultState());
        structure.fillWithBlocks(world, start, 69, 9, 24, 69, 9, 26, Blocks.GRASS.getDefaultState());
        structure.fillWithBlocks(world, start, 69, 9, 28, 69, 9, 30, Blocks.GRASS.getDefaultState());
        structure.fillWithBlocks(world, start, 69, 9, 32, 69, 9, 38, Blocks.SPRUCE_TRAPDOOR.getDefaultState().with(HorizontalBlock.HORIZONTAL_FACING, Direction.EAST).with(TrapDoorBlock.HALF, Half.BOTTOM).with(TrapDoorBlock.WATERLOGGED, false).with(TrapDoorBlock.POWERED, false).with(TrapDoorBlock.OPEN, true));
        structure.fillWithBlocks(world, start, 69, 9, 39, 70, 9, 48, Blocks.GRASS.getDefaultState());
        structure.fillWithBlocks(world, start, 69, 9, 50, 70, 9, 51, Blocks.GRASS.getDefaultState());
        structure.fillWithBlocks(world, start, 69, 9, 69, 69, 9, 69, Blocks.GRASS.getDefaultState());
        structure.fillWithBlocks(world, start, 69, 9, 72, 74, 9, 72, Blocks.GRASS.getDefaultState());
        structure.fillWithBlocks(world, start, 69, 9, 79, 70, 9, 80, Blocks.GRASS.getDefaultState());
        structure.fillWithBlocks(world, start, 69, 9, 95, 70, 9, 95, Blocks.GRASS.getDefaultState());
        structure.fillWithBlocks(world, start, 69, 9, 100, 70, 10, 100, Blocks.DARK_OAK_LOG.getDefaultState());
        structure.fillWithBlocks(world, start, 69, 10, 32, 69, 10, 33, Blocks.SPRUCE_TRAPDOOR.getDefaultState().with(HorizontalBlock.HORIZONTAL_FACING, Direction.EAST).with(TrapDoorBlock.HALF, Half.TOP).with(TrapDoorBlock.WATERLOGGED, false).with(TrapDoorBlock.POWERED, false).with(TrapDoorBlock.OPEN, true));
        structure.fillWithBlocks(world, start, 69, 10, 34, 69, 11, 34, Blocks.OAK_TRAPDOOR.getDefaultState().with(HorizontalBlock.HORIZONTAL_FACING, Direction.EAST).with(TrapDoorBlock.HALF, Half.BOTTOM).with(TrapDoorBlock.WATERLOGGED, false).with(TrapDoorBlock.POWERED, false).with(TrapDoorBlock.OPEN, true));
        structure.fillWithBlocks(world, start, 69, 10, 35, 69, 12, 35, Blocks.SPRUCE_TRAPDOOR.getDefaultState().with(HorizontalBlock.HORIZONTAL_FACING, Direction.EAST).with(TrapDoorBlock.HALF, Half.TOP).with(TrapDoorBlock.WATERLOGGED, false).with(TrapDoorBlock.POWERED, false).with(TrapDoorBlock.OPEN, true));
        structure.fillWithBlocks(world, start, 69, 10, 37, 69, 11, 37, Blocks.SPRUCE_TRAPDOOR.getDefaultState().with(HorizontalBlock.HORIZONTAL_FACING, Direction.EAST).with(TrapDoorBlock.HALF, Half.TOP).with(TrapDoorBlock.WATERLOGGED, false).with(TrapDoorBlock.POWERED, false).with(TrapDoorBlock.OPEN, true));
        structure.fillWithBlocks(world, start, 69, 10, 38, 69, 12, 38, Blocks.SPRUCE_TRAPDOOR.getDefaultState().with(HorizontalBlock.HORIZONTAL_FACING, Direction.EAST).with(TrapDoorBlock.HALF, Half.BOTTOM).with(TrapDoorBlock.WATERLOGGED, false).with(TrapDoorBlock.POWERED, false).with(TrapDoorBlock.OPEN, true));
        structure.fillWithBlocks(world, start, 69, 11, 20, 70, 12, 20, Blocks.DARK_OAK_LOG.getDefaultState());
        structure.fillWithBlocks(world, start, 69, 11, 32, 69, 12, 32, Blocks.SPRUCE_TRAPDOOR.getDefaultState().with(HorizontalBlock.HORIZONTAL_FACING, Direction.EAST).with(TrapDoorBlock.HALF, Half.BOTTOM).with(TrapDoorBlock.WATERLOGGED, false).with(TrapDoorBlock.POWERED, false).with(TrapDoorBlock.OPEN, true));
        structure.fillWithBlocks(world, start, 69, 11, 100, 70, 12, 100, Blocks.DARK_OAK_LOG.getDefaultState());
        structure.fillWithBlocks(world, start, 69, 12, 33, 69, 12, 34, Blocks.SPRUCE_TRAPDOOR.getDefaultState().with(HorizontalBlock.HORIZONTAL_FACING, Direction.EAST).with(TrapDoorBlock.HALF, Half.BOTTOM).with(TrapDoorBlock.WATERLOGGED, false).with(TrapDoorBlock.POWERED, false).with(TrapDoorBlock.OPEN, true));
        structure.fillWithBlocks(world, start, 69, 12, 36, 69, 12, 38, Blocks.SPRUCE_TRAPDOOR.getDefaultState().with(HorizontalBlock.HORIZONTAL_FACING, Direction.EAST).with(TrapDoorBlock.HALF, Half.BOTTOM).with(TrapDoorBlock.WATERLOGGED, false).with(TrapDoorBlock.POWERED, false).with(TrapDoorBlock.OPEN, true));
        structure.fillWithBlocks(world, start, 69, 12, 82, 69, 12, 82, Blocks.BIRCH_SLAB.getDefaultState().with(SlabBlock.TYPE, SlabType.BOTTOM).with(SlabBlock.WATERLOGGED, false));
        structure.fillWithBlocks(world, start, 69, 12, 84, 69, 12, 84, Blocks.BIRCH_SLAB.getDefaultState().with(SlabBlock.TYPE, SlabType.BOTTOM).with(SlabBlock.WATERLOGGED, false));
        structure.fillWithBlocks(world, start, 69, 14, 20, 70, 14, 21, Blocks.JUNGLE_SLAB.getDefaultState().with(SlabBlock.TYPE, SlabType.BOTTOM).with(SlabBlock.WATERLOGGED, false));
        structure.fillWithBlocks(world, start, 70, 0, 109, 72, 0, 111, Blocks.DIRT.getDefaultState());
        structure.fillWithBlocks(world, start, 70, 4, 103, 75, 4, 108, Blocks.DIRT.getDefaultState());
        structure.fillWithBlocks(world, start, 70, 6, 5, 79, 6, 14, Blocks.GRASS_BLOCK.getDefaultState().with(SnowyDirtBlock.SNOWY, false));
        structure.fillWithBlocks(world, start, 70, 6, 15, 70, 6, 18, Blocks.GRASS_BLOCK.getDefaultState().with(SnowyDirtBlock.SNOWY, false));
        structure.fillWithBlocks(world, start, 70, 6, 74, 71, 6, 75, Blocks.DIRT.getDefaultState());
        structure.fillWithBlocks(world, start, 70, 6, 78, 92, 6, 100, Blocks.DIRT.getDefaultState());
        structure.fillWithBlocks(world, start, 70, 6, 104, 70, 6, 107, Blocks.GRASS_BLOCK.getDefaultState().with(SnowyDirtBlock.SNOWY, false));
        structure.fillWithBlocks(world, start, 70, 7, 11, 70, 7, 13, Blocks.GRASS.getDefaultState());
        structure.fillWithBlocks(world, start, 70, 7, 103, 70, 7, 104, Blocks.GRASS.getDefaultState());
        structure.fillWithBlocks(world, start, 70, 8, 49, 70, 8, 56, Blocks.GRASS_BLOCK.getDefaultState().with(SnowyDirtBlock.SNOWY, false));
        structure.fillWithBlocks(world, start, 70, 8, 57, 70, 8, 63, Blocks.STONE_BRICKS.getDefaultState());
        structure.fillWithBlocks(world, start, 70, 8, 64, 72, 8, 70, Blocks.GRASS_BLOCK.getDefaultState().with(SnowyDirtBlock.SNOWY, false));
        structure.fillWithBlocks(world, start, 70, 8, 71, 70, 8, 80, Blocks.GRASS_BLOCK.getDefaultState().with(SnowyDirtBlock.SNOWY, false));
        structure.fillWithBlocks(world, start, 70, 8, 86, 70, 8, 86, Blocks.GRASS_PATH.getDefaultState());
        structure.fillWithBlocks(world, start, 70, 8, 87, 70, 8, 87, Blocks.GRASS_BLOCK.getDefaultState().with(SnowyDirtBlock.SNOWY, false));
        structure.fillWithBlocks(world, start, 70, 8, 88, 70, 8, 88, Blocks.GRASS_PATH.getDefaultState());
        structure.fillWithBlocks(world, start, 70, 8, 89, 70, 8, 89, Blocks.GRASS_BLOCK.getDefaultState().with(SnowyDirtBlock.SNOWY, false));
        structure.fillWithBlocks(world, start, 70, 9, 24, 70, 9, 24, Blocks.GRASS.getDefaultState());
        structure.fillWithBlocks(world, start, 70, 9, 25, 70, 9, 28, Blocks.DARK_OAK_LEAVES.getDefaultState().with(LeavesBlock.PERSISTENT, true).with(LeavesBlock.DISTANCE, 7));
        structure.fillWithBlocks(world, start, 70, 9, 29, 72, 9, 31, Blocks.GRASS.getDefaultState());
        structure.fillWithBlocks(world, start, 70, 9, 33, 70, 9, 37, Blocks.GRASS.getDefaultState());
        structure.fillWithBlocks(world, start, 70, 9, 52, 70, 9, 52, Blocks.GRASS.getDefaultState());
        structure.fillWithBlocks(world, start, 70, 9, 53, 70, 9, 54, Blocks.SWEET_BERRY_BUSH.getDefaultState().with(SweetBerryBushBlock.AGE, 3));
        structure.fillWithBlocks(world, start, 70, 9, 56, 71, 9, 56, Blocks.GRASS.getDefaultState());
        structure.fillWithBlocks(world, start, 70, 9, 64, 71, 9, 64, Blocks.GRASS.getDefaultState());
        structure.fillWithBlocks(world, start, 70, 9, 66, 70, 9, 67, Blocks.SWEET_BERRY_BUSH.getDefaultState().with(SweetBerryBushBlock.AGE, 3));
        structure.fillWithBlocks(world, start, 70, 9, 68, 71, 9, 70, Blocks.GRASS.getDefaultState());
        structure.fillWithBlocks(world, start, 70, 9, 74, 72, 9, 74, Blocks.GRASS.getDefaultState());
        structure.fillWithBlocks(world, start, 70, 9, 76, 71, 9, 80, Blocks.GRASS.getDefaultState());
        structure.fillWithBlocks(world, start, 70, 12, 81, 70, 12, 81, Blocks.BIRCH_SLAB.getDefaultState().with(SlabBlock.TYPE, SlabType.BOTTOM).with(SlabBlock.WATERLOGGED, false));
        structure.fillWithBlocks(world, start, 70, 12, 83, 70, 12, 83, Blocks.BIRCH_SLAB.getDefaultState().with(SlabBlock.TYPE, SlabType.BOTTOM).with(SlabBlock.WATERLOGGED, false));
        structure.fillWithBlocks(world, start, 70, 14, 99, 71, 14, 100, Blocks.JUNGLE_SLAB.getDefaultState().with(SlabBlock.TYPE, SlabType.BOTTOM).with(SlabBlock.WATERLOGGED, false));
        structure.fillWithBlocks(world, start, 71, 1, 107, 74, 1, 110, Blocks.DIRT.getDefaultState());
        structure.fillWithBlocks(world, start, 71, 4, 5, 73, 4, 7, Blocks.DIRT.getDefaultState());
        structure.fillWithBlocks(world, start, 71, 6, 16, 72, 6, 18, Blocks.GRASS_BLOCK.getDefaultState().with(SnowyDirtBlock.SNOWY, false));
        structure.fillWithBlocks(world, start, 71, 6, 20, 71, 7, 20, Blocks.MOSSY_COBBLESTONE.getDefaultState());
        structure.fillWithBlocks(world, start, 71, 6, 21, 81, 6, 31, Blocks.DIRT.getDefaultState());
        structure.fillWithBlocks(world, start, 71, 6, 76, 94, 6, 100, Blocks.DIRT.getDefaultState());
        structure.fillWithBlocks(world, start, 71, 6, 102, 72, 6, 104, Blocks.GRASS_BLOCK.getDefaultState().with(SnowyDirtBlock.SNOWY, false));
        structure.fillWithBlocks(world, start, 71, 6, 106, 72, 6, 107, Blocks.GRASS_BLOCK.getDefaultState().with(SnowyDirtBlock.SNOWY, false));
        structure.fillWithBlocks(world, start, 71, 7, 11, 71, 7, 11, Blocks.GRASS.getDefaultState());
        structure.fillWithBlocks(world, start, 71, 7, 19, 71, 15, 19, Blocks.SPRUCE_LOG.getDefaultState());
        structure.fillWithBlocks(world, start, 71, 7, 101, 71, 15, 101, Blocks.SPRUCE_LOG.getDefaultState());
        structure.fillWithBlocks(world, start, 71, 7, 103, 72, 7, 103, Blocks.GRASS.getDefaultState());
        structure.fillWithBlocks(world, start, 71, 8, 20, 71, 13, 20, Blocks.SPRUCE_LOG.getDefaultState());
        structure.fillWithBlocks(world, start, 71, 8, 34, 71, 8, 34, Blocks.GRASS_BLOCK.getDefaultState().with(SnowyDirtBlock.SNOWY, false));
        structure.fillWithBlocks(world, start, 71, 8, 36, 71, 8, 36, Blocks.GRASS_BLOCK.getDefaultState().with(SnowyDirtBlock.SNOWY, false));
        structure.fillWithBlocks(world, start, 71, 8, 38, 71, 8, 38, Blocks.GRASS_BLOCK.getDefaultState().with(SnowyDirtBlock.SNOWY, false));
        structure.fillWithBlocks(world, start, 71, 8, 40, 71, 8, 40, Blocks.GRASS_BLOCK.getDefaultState().with(SnowyDirtBlock.SNOWY, false));
        structure.fillWithBlocks(world, start, 71, 8, 42, 71, 8, 42, Blocks.GRASS_BLOCK.getDefaultState().with(SnowyDirtBlock.SNOWY, false));
        structure.fillWithBlocks(world, start, 71, 8, 44, 71, 8, 44, Blocks.GRASS_BLOCK.getDefaultState().with(SnowyDirtBlock.SNOWY, false));
        structure.fillWithBlocks(world, start, 71, 8, 46, 71, 8, 46, Blocks.GRASS_BLOCK.getDefaultState().with(SnowyDirtBlock.SNOWY, false));
        structure.fillWithBlocks(world, start, 71, 8, 50, 73, 8, 52, Blocks.GRASS_BLOCK.getDefaultState().with(SnowyDirtBlock.SNOWY, false));
        structure.fillWithBlocks(world, start, 71, 8, 53, 72, 8, 57, Blocks.GRASS_BLOCK.getDefaultState().with(SnowyDirtBlock.SNOWY, false));
        structure.fillWithBlocks(world, start, 71, 8, 58, 71, 8, 62, Blocks.STONE_BRICKS.getDefaultState());
        structure.fillWithBlocks(world, start, 71, 8, 63, 72, 8, 70, Blocks.GRASS_BLOCK.getDefaultState().with(SnowyDirtBlock.SNOWY, false));
        structure.fillWithBlocks(world, start, 71, 8, 75, 72, 8, 80, Blocks.GRASS_BLOCK.getDefaultState().with(SnowyDirtBlock.SNOWY, false));
        structure.fillWithBlocks(world, start, 71, 8, 85, 73, 8, 85, Blocks.MOSSY_COBBLESTONE.getDefaultState());
        structure.fillWithBlocks(world, start, 71, 8, 86, 71, 8, 86, Blocks.GRASS_BLOCK.getDefaultState().with(SnowyDirtBlock.SNOWY, false));
        structure.fillWithBlocks(world, start, 71, 8, 87, 71, 8, 87, Blocks.GRASS_PATH.getDefaultState());
        structure.fillWithBlocks(world, start, 71, 8, 88, 71, 8, 88, Blocks.GRASS_BLOCK.getDefaultState().with(SnowyDirtBlock.SNOWY, false));
        structure.fillWithBlocks(world, start, 71, 8, 90, 71, 8, 90, Blocks.GRASS_BLOCK.getDefaultState().with(SnowyDirtBlock.SNOWY, false));
        structure.fillWithBlocks(world, start, 71, 8, 100, 71, 9, 101, Blocks.SPRUCE_LOG.getDefaultState());
        structure.fillWithBlocks(world, start, 71, 9, 24, 71, 9, 27, Blocks.GRASS.getDefaultState());
        structure.fillWithBlocks(world, start, 71, 9, 50, 72, 9, 52, Blocks.GRASS.getDefaultState());
        structure.fillWithBlocks(world, start, 71, 9, 53, 71, 9, 54, Blocks.GRASS.getDefaultState());
        structure.fillWithBlocks(world, start, 71, 9, 63, 71, 9, 64, Blocks.GRASS.getDefaultState());
        structure.fillWithBlocks(world, start, 71, 9, 67, 71, 9, 70, Blocks.GRASS.getDefaultState());
        structure.fillWithBlocks(world, start, 71, 9, 86, 71, 9, 86, Blocks.GRASS.getDefaultState());
        structure.fillWithBlocks(world, start, 71, 10, 100, 71, 11, 101, Blocks.SPRUCE_LOG.getDefaultState());
        structure.fillWithBlocks(world, start, 71, 12, 82, 71, 12, 82, Blocks.BIRCH_SLAB.getDefaultState().with(SlabBlock.TYPE, SlabType.BOTTOM).with(SlabBlock.WATERLOGGED, false));
        structure.fillWithBlocks(world, start, 71, 12, 84, 71, 12, 84, Blocks.BIRCH_SLAB.getDefaultState().with(SlabBlock.TYPE, SlabType.BOTTOM).with(SlabBlock.WATERLOGGED, false));
        structure.fillWithBlocks(world, start, 71, 12, 100, 71, 13, 101, Blocks.SPRUCE_LOG.getDefaultState());
        structure.fillWithBlocks(world, start, 71, 14, 20, 72, 14, 21, Blocks.JUNGLE_SLAB.getDefaultState().with(SlabBlock.TYPE, SlabType.BOTTOM).with(SlabBlock.WATERLOGGED, false));
        structure.fillWithBlocks(world, start, 72, 0, 1, 74, 0, 1, Blocks.GRASS_BLOCK.getDefaultState().with(SnowyDirtBlock.SNOWY, false));
        structure.fillWithBlocks(world, start, 72, 0, 108, 75, 0, 111, Blocks.DIRT.getDefaultState());
        structure.fillWithBlocks(world, start, 72, 2, 105, 76, 2, 109, Blocks.DIRT.getDefaultState());
        structure.fillWithBlocks(world, start, 72, 2, 110, 75, 2, 110, Blocks.DIRT.getDefaultState());
        structure.fillWithBlocks(world, start, 72, 3, 5, 74, 3, 7, Blocks.DIRT.getDefaultState());
        structure.fillWithBlocks(world, start, 72, 3, 103, 78, 3, 109, Blocks.DIRT.getDefaultState());
        structure.fillWithBlocks(world, start, 72, 5, 5, 74, 5, 7, Blocks.DIRT.getDefaultState());
        structure.fillWithBlocks(world, start, 72, 6, 15, 72, 6, 18, Blocks.GRASS_BLOCK.getDefaultState().with(SnowyDirtBlock.SNOWY, false));
        structure.fillWithBlocks(world, start, 72, 6, 20, 82, 6, 30, Blocks.DIRT.getDefaultState());
        structure.fillWithBlocks(world, start, 72, 6, 74, 95, 6, 97, Blocks.DIRT.getDefaultState());
        structure.fillWithBlocks(world, start, 72, 6, 105, 74, 6, 107, Blocks.GRASS_BLOCK.getDefaultState().with(SnowyDirtBlock.SNOWY, false));
        structure.fillWithBlocks(world, start, 72, 7, 12, 72, 7, 12, Blocks.GRASS.getDefaultState());
        structure.fillWithBlocks(world, start, 72, 7, 19, 76, 7, 19, Blocks.MOSSY_COBBLESTONE_STAIRS.getDefaultState().with(StairsBlock.FACING, Direction.SOUTH).with(StairsBlock.WATERLOGGED, false).with(StairsBlock.SHAPE, StairsShape.STRAIGHT).with(StairsBlock.HALF, Half.BOTTOM));
        structure.fillWithBlocks(world, start, 72, 7, 101, 76, 7, 101, Blocks.MOSSY_COBBLESTONE_STAIRS.getDefaultState().with(StairsBlock.FACING, Direction.NORTH).with(StairsBlock.WATERLOGGED, false).with(StairsBlock.SHAPE, StairsShape.STRAIGHT).with(StairsBlock.HALF, Half.BOTTOM));
        structure.fillWithBlocks(world, start, 72, 8, 20, 76, 12, 20, Blocks.OAK_LOG.getDefaultState());
        structure.fillWithBlocks(world, start, 72, 8, 33, 74, 8, 35, Blocks.GRASS_BLOCK.getDefaultState().with(SnowyDirtBlock.SNOWY, false));
        structure.fillWithBlocks(world, start, 72, 8, 36, 73, 8, 48, Blocks.GRASS_BLOCK.getDefaultState().with(SnowyDirtBlock.SNOWY, false));
        structure.fillWithBlocks(world, start, 72, 8, 49, 72, 8, 58, Blocks.GRASS_BLOCK.getDefaultState().with(SnowyDirtBlock.SNOWY, false));
        structure.fillWithBlocks(world, start, 72, 8, 60, 72, 8, 61, Blocks.STONE_BRICKS.getDefaultState());
        structure.fillWithBlocks(world, start, 72, 8, 62, 73, 8, 63, Blocks.GRASS_BLOCK.getDefaultState().with(SnowyDirtBlock.SNOWY, false));
        structure.fillWithBlocks(world, start, 72, 8, 71, 72, 8, 80, Blocks.GRASS_BLOCK.getDefaultState().with(SnowyDirtBlock.SNOWY, false));
        structure.fillWithBlocks(world, start, 72, 8, 82, 72, 8, 85, Blocks.MOSSY_COBBLESTONE.getDefaultState());
        structure.fillWithBlocks(world, start, 72, 8, 86, 72, 8, 87, Blocks.GRASS_BLOCK.getDefaultState().with(SnowyDirtBlock.SNOWY, false));
        structure.fillWithBlocks(world, start, 72, 8, 88, 72, 8, 88, Blocks.GRASS_PATH.getDefaultState());
        structure.fillWithBlocks(world, start, 72, 8, 89, 72, 8, 97, Blocks.GRASS_BLOCK.getDefaultState().with(SnowyDirtBlock.SNOWY, false));
        structure.fillWithBlocks(world, start, 72, 8, 100, 76, 12, 100, Blocks.OAK_LOG.getDefaultState());
        structure.fillWithBlocks(world, start, 72, 9, 23, 72, 9, 24, Blocks.GRASS.getDefaultState());
        structure.fillWithBlocks(world, start, 72, 9, 25, 72, 9, 26, Blocks.SPRUCE_TRAPDOOR.getDefaultState().with(HorizontalBlock.HORIZONTAL_FACING, Direction.WEST).with(TrapDoorBlock.HALF, Half.BOTTOM).with(TrapDoorBlock.WATERLOGGED, false).with(TrapDoorBlock.POWERED, false).with(TrapDoorBlock.OPEN, true));
        structure.fillWithBlocks(world, start, 72, 9, 27, 72, 9, 28, Blocks.SPRUCE_TRAPDOOR.getDefaultState().with(HorizontalBlock.HORIZONTAL_FACING, Direction.WEST).with(TrapDoorBlock.HALF, Half.TOP).with(TrapDoorBlock.WATERLOGGED, false).with(TrapDoorBlock.POWERED, false).with(TrapDoorBlock.OPEN, true));
        structure.fillWithBlocks(world, start, 72, 9, 33, 72, 9, 33, Blocks.POPPY.getDefaultState());
        structure.fillWithBlocks(world, start, 72, 9, 34, 72, 9, 44, Blocks.GRASS.getDefaultState());
        structure.fillWithBlocks(world, start, 72, 9, 46, 73, 9, 48, Blocks.GRASS.getDefaultState());
        structure.fillWithBlocks(world, start, 72, 9, 53, 72, 9, 56, Blocks.SPRUCE_TRAPDOOR.getDefaultState().with(HorizontalBlock.HORIZONTAL_FACING, Direction.WEST).with(TrapDoorBlock.HALF, Half.BOTTOM).with(TrapDoorBlock.WATERLOGGED, false).with(TrapDoorBlock.POWERED, false).with(TrapDoorBlock.OPEN, true));
        structure.fillWithBlocks(world, start, 72, 9, 57, 72, 9, 58, Blocks.GRASS.getDefaultState());
        structure.fillWithBlocks(world, start, 72, 9, 64, 72, 9, 65, Blocks.SPRUCE_TRAPDOOR.getDefaultState().with(HorizontalBlock.HORIZONTAL_FACING, Direction.WEST).with(TrapDoorBlock.HALF, Half.BOTTOM).with(TrapDoorBlock.WATERLOGGED, false).with(TrapDoorBlock.POWERED, false).with(TrapDoorBlock.OPEN, true));
        structure.fillWithBlocks(world, start, 72, 9, 67, 72, 11, 67, Blocks.SPRUCE_TRAPDOOR.getDefaultState().with(HorizontalBlock.HORIZONTAL_FACING, Direction.WEST).with(TrapDoorBlock.HALF, Half.BOTTOM).with(TrapDoorBlock.WATERLOGGED, false).with(TrapDoorBlock.POWERED, false).with(TrapDoorBlock.OPEN, true));
        structure.fillWithBlocks(world, start, 72, 9, 68, 72, 9, 69, Blocks.GRASS.getDefaultState());
        structure.fillWithBlocks(world, start, 72, 9, 73, 72, 9, 74, Blocks.GRASS.getDefaultState());
        structure.fillWithBlocks(world, start, 72, 9, 75, 72, 11, 75, Blocks.SPRUCE_TRAPDOOR.getDefaultState().with(HorizontalBlock.HORIZONTAL_FACING, Direction.WEST).with(TrapDoorBlock.HALF, Half.BOTTOM).with(TrapDoorBlock.WATERLOGGED, false).with(TrapDoorBlock.POWERED, false).with(TrapDoorBlock.OPEN, true));
        structure.fillWithBlocks(world, start, 72, 9, 79, 72, 9, 79, Blocks.POPPY.getDefaultState());
        structure.fillWithBlocks(world, start, 72, 9, 81, 72, 11, 81, Blocks.BIRCH_FENCE.getDefaultState().with(FourWayBlock.WATERLOGGED, false).with(FourWayBlock.NORTH, false).with(FourWayBlock.SOUTH, false).with(FourWayBlock.EAST, false).with(FourWayBlock.WEST, false));
        structure.fillWithBlocks(world, start, 72, 9, 82, 72, 10, 84, Blocks.CHAIN.getDefaultState().with(ChainBlock.WATERLOGGED, false));
        structure.fillWithBlocks(world, start, 72, 9, 85, 72, 11, 85, Blocks.BIRCH_FENCE.getDefaultState().with(FourWayBlock.WATERLOGGED, false).with(FourWayBlock.NORTH, false).with(FourWayBlock.SOUTH, false).with(FourWayBlock.EAST, false).with(FourWayBlock.WEST, false));
        structure.fillWithBlocks(world, start, 72, 9, 89, 72, 9, 90, Blocks.GRASS.getDefaultState());
        structure.fillWithBlocks(world, start, 72, 9, 92, 73, 9, 92, Blocks.GRASS.getDefaultState());
        structure.fillWithBlocks(world, start, 72, 9, 94, 72, 9, 94, Blocks.GRASS.getDefaultState());
        structure.fillWithBlocks(world, start, 72, 10, 26, 72, 10, 27, Blocks.OAK_TRAPDOOR.getDefaultState().with(HorizontalBlock.HORIZONTAL_FACING, Direction.WEST).with(TrapDoorBlock.HALF, Half.BOTTOM).with(TrapDoorBlock.WATERLOGGED, false).with(TrapDoorBlock.POWERED, false).with(TrapDoorBlock.OPEN, true));
        structure.fillWithBlocks(world, start, 72, 10, 53, 72, 11, 53, Blocks.SPRUCE_TRAPDOOR.getDefaultState().with(HorizontalBlock.HORIZONTAL_FACING, Direction.WEST).with(TrapDoorBlock.HALF, Half.BOTTOM).with(TrapDoorBlock.WATERLOGGED, false).with(TrapDoorBlock.POWERED, false).with(TrapDoorBlock.OPEN, true));
        structure.fillWithBlocks(world, start, 72, 10, 54, 72, 10, 55, Blocks.OAK_TRAPDOOR.getDefaultState().with(HorizontalBlock.HORIZONTAL_FACING, Direction.WEST).with(TrapDoorBlock.HALF, Half.BOTTOM).with(TrapDoorBlock.WATERLOGGED, false).with(TrapDoorBlock.POWERED, false).with(TrapDoorBlock.OPEN, true));
        structure.fillWithBlocks(world, start, 72, 10, 56, 72, 11, 56, Blocks.SPRUCE_TRAPDOOR.getDefaultState().with(HorizontalBlock.HORIZONTAL_FACING, Direction.WEST).with(TrapDoorBlock.HALF, Half.BOTTOM).with(TrapDoorBlock.WATERLOGGED, false).with(TrapDoorBlock.POWERED, false).with(TrapDoorBlock.OPEN, true));
        structure.fillWithBlocks(world, start, 72, 10, 65, 72, 10, 66, Blocks.OAK_TRAPDOOR.getDefaultState().with(HorizontalBlock.HORIZONTAL_FACING, Direction.WEST).with(TrapDoorBlock.HALF, Half.BOTTOM).with(TrapDoorBlock.WATERLOGGED, false).with(TrapDoorBlock.POWERED, false).with(TrapDoorBlock.OPEN, true));
        structure.fillWithBlocks(world, start, 72, 10, 76, 72, 10, 77, Blocks.OAK_TRAPDOOR.getDefaultState().with(HorizontalBlock.HORIZONTAL_FACING, Direction.WEST).with(TrapDoorBlock.HALF, Half.TOP).with(TrapDoorBlock.WATERLOGGED, false).with(TrapDoorBlock.POWERED, false).with(TrapDoorBlock.OPEN, true));
        structure.fillWithBlocks(world, start, 72, 10, 78, 72, 11, 78, Blocks.SPRUCE_TRAPDOOR.getDefaultState().with(HorizontalBlock.HORIZONTAL_FACING, Direction.WEST).with(TrapDoorBlock.HALF, Half.BOTTOM).with(TrapDoorBlock.WATERLOGGED, false).with(TrapDoorBlock.POWERED, false).with(TrapDoorBlock.OPEN, true));
        structure.fillWithBlocks(world, start, 72, 11, 25, 72, 11, 28, Blocks.SPRUCE_TRAPDOOR.getDefaultState().with(HorizontalBlock.HORIZONTAL_FACING, Direction.WEST).with(TrapDoorBlock.HALF, Half.BOTTOM).with(TrapDoorBlock.WATERLOGGED, false).with(TrapDoorBlock.POWERED, false).with(TrapDoorBlock.OPEN, true));
        structure.fillWithBlocks(world, start, 72, 11, 54, 72, 11, 56, Blocks.SPRUCE_TRAPDOOR.getDefaultState().with(HorizontalBlock.HORIZONTAL_FACING, Direction.WEST).with(TrapDoorBlock.HALF, Half.BOTTOM).with(TrapDoorBlock.WATERLOGGED, false).with(TrapDoorBlock.POWERED, false).with(TrapDoorBlock.OPEN, true));
        structure.fillWithBlocks(world, start, 72, 11, 65, 72, 11, 67, Blocks.SPRUCE_TRAPDOOR.getDefaultState().with(HorizontalBlock.HORIZONTAL_FACING, Direction.WEST).with(TrapDoorBlock.HALF, Half.BOTTOM).with(TrapDoorBlock.WATERLOGGED, false).with(TrapDoorBlock.POWERED, false).with(TrapDoorBlock.OPEN, true));
        structure.fillWithBlocks(world, start, 72, 11, 76, 72, 11, 78, Blocks.SPRUCE_TRAPDOOR.getDefaultState().with(HorizontalBlock.HORIZONTAL_FACING, Direction.WEST).with(TrapDoorBlock.HALF, Half.BOTTOM).with(TrapDoorBlock.WATERLOGGED, false).with(TrapDoorBlock.POWERED, false).with(TrapDoorBlock.OPEN, true));
        structure.fillWithBlocks(world, start, 72, 12, 81, 72, 12, 85, Blocks.BIRCH_SLAB.getDefaultState().with(SlabBlock.TYPE, SlabType.BOTTOM).with(SlabBlock.WATERLOGGED, false));
        structure.fillWithBlocks(world, start, 72, 13, 20, 76, 13, 20, Blocks.OAK_LOG.getDefaultState());
        structure.fillWithBlocks(world, start, 72, 13, 100, 76, 13, 100, Blocks.OAK_LOG.getDefaultState());
        structure.fillWithBlocks(world, start, 72, 14, 19, 76, 14, 19, Blocks.SPRUCE_WOOD.getDefaultState());
        structure.fillWithBlocks(world, start, 72, 14, 99, 73, 14, 100, Blocks.JUNGLE_SLAB.getDefaultState().with(SlabBlock.TYPE, SlabType.BOTTOM).with(SlabBlock.WATERLOGGED, false));
        structure.fillWithBlocks(world, start, 72, 14, 101, 76, 14, 101, Blocks.SPRUCE_LOG.getDefaultState());
        structure.fillWithBlocks(world, start, 72, 15, 19, 76, 15, 19, Blocks.BIRCH_FENCE.getDefaultState().with(FourWayBlock.WATERLOGGED, false).with(FourWayBlock.NORTH, false).with(FourWayBlock.SOUTH, false).with(FourWayBlock.EAST, true).with(FourWayBlock.WEST, true));
        structure.fillWithBlocks(world, start, 72, 15, 101, 76, 15, 101, Blocks.BIRCH_FENCE.getDefaultState().with(FourWayBlock.WATERLOGGED, false).with(FourWayBlock.NORTH, false).with(FourWayBlock.SOUTH, false).with(FourWayBlock.EAST, true).with(FourWayBlock.WEST, true));
        structure.fillWithBlocks(world, start, 73, 5, 103, 77, 5, 107, Blocks.DIRT.getDefaultState());
        structure.fillWithBlocks(world, start, 73, 6, 15, 73, 6, 15, Blocks.GRASS_BLOCK.getDefaultState().with(SnowyDirtBlock.SNOWY, false));
        structure.fillWithBlocks(world, start, 73, 6, 17, 74, 6, 18, Blocks.GRASS_BLOCK.getDefaultState().with(SnowyDirtBlock.SNOWY, false));
        structure.fillWithBlocks(world, start, 73, 6, 102, 74, 6, 103, Blocks.GRASS_BLOCK.getDefaultState().with(SnowyDirtBlock.SNOWY, false));
        structure.fillWithBlocks(world, start, 73, 7, 6, 73, 7, 7, Blocks.GRASS.getDefaultState());
        structure.fillWithBlocks(world, start, 73, 8, 23, 74, 8, 24, Blocks.GRASS_BLOCK.getDefaultState().with(SnowyDirtBlock.SNOWY, false));
        structure.fillWithBlocks(world, start, 73, 8, 25, 76, 8, 28, Blocks.PODZOL.getDefaultState().with(SnowyDirtBlock.SNOWY, false));
        structure.fillWithBlocks(world, start, 73, 8, 29, 74, 8, 31, Blocks.GRASS_BLOCK.getDefaultState().with(SnowyDirtBlock.SNOWY, false));
        structure.fillWithBlocks(world, start, 73, 8, 53, 76, 8, 56, Blocks.PODZOL.getDefaultState().with(SnowyDirtBlock.SNOWY, false));
        structure.fillWithBlocks(world, start, 73, 8, 57, 74, 8, 58, Blocks.GRASS_BLOCK.getDefaultState().with(SnowyDirtBlock.SNOWY, false));
        structure.fillWithBlocks(world, start, 73, 8, 59, 74, 8, 60, Blocks.STONE_BRICKS.getDefaultState());
        structure.fillWithBlocks(world, start, 73, 8, 64, 76, 8, 67, Blocks.PODZOL.getDefaultState().with(SnowyDirtBlock.SNOWY, false));
        structure.fillWithBlocks(world, start, 73, 8, 68, 74, 8, 70, Blocks.GRASS_BLOCK.getDefaultState().with(SnowyDirtBlock.SNOWY, false));
        structure.fillWithBlocks(world, start, 73, 8, 72, 74, 8, 74, Blocks.GRASS_BLOCK.getDefaultState().with(SnowyDirtBlock.SNOWY, false));
        structure.fillWithBlocks(world, start, 73, 8, 75, 76, 8, 78, Blocks.PODZOL.getDefaultState().with(SnowyDirtBlock.SNOWY, false));
        structure.fillWithBlocks(world, start, 73, 8, 79, 74, 8, 80, Blocks.GRASS_BLOCK.getDefaultState().with(SnowyDirtBlock.SNOWY, false));
        structure.fillWithBlocks(world, start, 73, 8, 82, 75, 8, 84, Blocks.COBBLESTONE.getDefaultState());
        structure.fillWithBlocks(world, start, 73, 8, 86, 73, 8, 86, Blocks.GRASS_BLOCK.getDefaultState().with(SnowyDirtBlock.SNOWY, false));
        structure.fillWithBlocks(world, start, 73, 8, 87, 73, 8, 87, Blocks.GRASS_PATH.getDefaultState());
        structure.fillWithBlocks(world, start, 73, 8, 88, 73, 8, 88, Blocks.GRASS_BLOCK.getDefaultState().with(SnowyDirtBlock.SNOWY, false));
        structure.fillWithBlocks(world, start, 73, 8, 89, 73, 8, 89, Blocks.GRASS_PATH.getDefaultState());
        structure.fillWithBlocks(world, start, 73, 8, 90, 73, 8, 97, Blocks.GRASS_BLOCK.getDefaultState().with(SnowyDirtBlock.SNOWY, false));
        structure.fillWithBlocks(world, start, 73, 9, 24, 77, 9, 24, Blocks.SPRUCE_TRAPDOOR.getDefaultState().with(HorizontalBlock.HORIZONTAL_FACING, Direction.NORTH).with(TrapDoorBlock.HALF, Half.TOP).with(TrapDoorBlock.WATERLOGGED, false).with(TrapDoorBlock.POWERED, false).with(TrapDoorBlock.OPEN, true));
        structure.fillWithBlocks(world, start, 73, 9, 25, 73, 10, 25, Blocks.OAK_FENCE.getDefaultState().with(FourWayBlock.WATERLOGGED, false).with(FourWayBlock.NORTH, true).with(FourWayBlock.SOUTH, false).with(FourWayBlock.EAST, false).with(FourWayBlock.WEST, true));
        structure.fillWithBlocks(world, start, 73, 9, 28, 73, 10, 28, Blocks.OAK_FENCE.getDefaultState().with(FourWayBlock.WATERLOGGED, false).with(FourWayBlock.NORTH, false).with(FourWayBlock.SOUTH, true).with(FourWayBlock.EAST, false).with(FourWayBlock.WEST, true));
        structure.fillWithBlocks(world, start, 73, 9, 29, 73, 10, 29, Blocks.SPRUCE_TRAPDOOR.getDefaultState().with(HorizontalBlock.HORIZONTAL_FACING, Direction.SOUTH).with(TrapDoorBlock.HALF, Half.TOP).with(TrapDoorBlock.WATERLOGGED, false).with(TrapDoorBlock.POWERED, false).with(TrapDoorBlock.OPEN, true));
        structure.fillWithBlocks(world, start, 73, 9, 33, 73, 9, 33, Blocks.GRASS.getDefaultState());
        structure.fillWithBlocks(world, start, 73, 9, 35, 73, 9, 48, Blocks.GRASS.getDefaultState());
        structure.fillWithBlocks(world, start, 73, 9, 50, 73, 9, 50, Blocks.GRASS.getDefaultState());
        structure.fillWithBlocks(world, start, 73, 9, 52, 74, 10, 52, Blocks.SPRUCE_TRAPDOOR.getDefaultState().with(HorizontalBlock.HORIZONTAL_FACING, Direction.NORTH).with(TrapDoorBlock.HALF, Half.BOTTOM).with(TrapDoorBlock.WATERLOGGED, false).with(TrapDoorBlock.POWERED, false).with(TrapDoorBlock.OPEN, true));
        structure.fillWithBlocks(world, start, 73, 9, 53, 73, 10, 53, Blocks.OAK_FENCE.getDefaultState().with(FourWayBlock.WATERLOGGED, false).with(FourWayBlock.NORTH, true).with(FourWayBlock.SOUTH, false).with(FourWayBlock.EAST, false).with(FourWayBlock.WEST, true));
        structure.fillWithBlocks(world, start, 73, 9, 56, 73, 10, 56, Blocks.OAK_FENCE.getDefaultState().with(FourWayBlock.WATERLOGGED, false).with(FourWayBlock.NORTH, false).with(FourWayBlock.SOUTH, true).with(FourWayBlock.EAST, false).with(FourWayBlock.WEST, true));
        structure.fillWithBlocks(world, start, 73, 9, 57, 77, 9, 57, Blocks.SPRUCE_TRAPDOOR.getDefaultState().with(HorizontalBlock.HORIZONTAL_FACING, Direction.SOUTH).with(TrapDoorBlock.HALF, Half.BOTTOM).with(TrapDoorBlock.WATERLOGGED, false).with(TrapDoorBlock.POWERED, false).with(TrapDoorBlock.OPEN, true));
        structure.fillWithBlocks(world, start, 73, 9, 58, 81, 9, 58, Blocks.GRASS.getDefaultState());
        structure.fillWithBlocks(world, start, 73, 9, 62, 74, 9, 62, Blocks.GRASS.getDefaultState());
        structure.fillWithBlocks(world, start, 73, 9, 63, 76, 9, 63, Blocks.SPRUCE_TRAPDOOR.getDefaultState().with(HorizontalBlock.HORIZONTAL_FACING, Direction.NORTH).with(TrapDoorBlock.HALF, Half.TOP).with(TrapDoorBlock.WATERLOGGED, false).with(TrapDoorBlock.POWERED, false).with(TrapDoorBlock.OPEN, true));
        structure.fillWithBlocks(world, start, 73, 9, 67, 73, 10, 67, Blocks.OAK_FENCE.getDefaultState().with(FourWayBlock.WATERLOGGED, false).with(FourWayBlock.NORTH, false).with(FourWayBlock.SOUTH, true).with(FourWayBlock.EAST, false).with(FourWayBlock.WEST, true));
        structure.fillWithBlocks(world, start, 73, 9, 68, 74, 9, 68, Blocks.SPRUCE_TRAPDOOR.getDefaultState().with(HorizontalBlock.HORIZONTAL_FACING, Direction.SOUTH).with(TrapDoorBlock.HALF, Half.BOTTOM).with(TrapDoorBlock.WATERLOGGED, false).with(TrapDoorBlock.POWERED, false).with(TrapDoorBlock.OPEN, true));
        structure.fillWithBlocks(world, start, 73, 9, 69, 74, 9, 70, Blocks.GRASS.getDefaultState());
        structure.fillWithBlocks(world, start, 73, 9, 74, 74, 9, 74, Blocks.SPRUCE_TRAPDOOR.getDefaultState().with(HorizontalBlock.HORIZONTAL_FACING, Direction.NORTH).with(TrapDoorBlock.HALF, Half.TOP).with(TrapDoorBlock.WATERLOGGED, false).with(TrapDoorBlock.POWERED, false).with(TrapDoorBlock.OPEN, true));
        structure.fillWithBlocks(world, start, 73, 9, 75, 73, 10, 75, Blocks.OAK_FENCE.getDefaultState().with(FourWayBlock.WATERLOGGED, false).with(FourWayBlock.NORTH, true).with(FourWayBlock.SOUTH, false).with(FourWayBlock.EAST, false).with(FourWayBlock.WEST, true));
        structure.fillWithBlocks(world, start, 73, 9, 78, 73, 10, 78, Blocks.OAK_FENCE.getDefaultState().with(FourWayBlock.WATERLOGGED, false).with(FourWayBlock.NORTH, false).with(FourWayBlock.SOUTH, true).with(FourWayBlock.EAST, false).with(FourWayBlock.WEST, true));
        structure.fillWithBlocks(world, start, 73, 9, 79, 77, 9, 79, Blocks.SPRUCE_TRAPDOOR.getDefaultState().with(HorizontalBlock.HORIZONTAL_FACING, Direction.SOUTH).with(TrapDoorBlock.HALF, Half.BOTTOM).with(TrapDoorBlock.WATERLOGGED, false).with(TrapDoorBlock.POWERED, false).with(TrapDoorBlock.OPEN, true));
        structure.fillWithBlocks(world, start, 73, 9, 86, 73, 9, 86, Blocks.GRASS.getDefaultState());
        structure.fillWithBlocks(world, start, 73, 9, 90, 73, 9, 92, Blocks.GRASS.getDefaultState());
        structure.fillWithBlocks(world, start, 73, 9, 94, 73, 9, 96, Blocks.GRASS.getDefaultState());
        structure.fillWithBlocks(world, start, 73, 10, 24, 73, 11, 24, Blocks.SPRUCE_TRAPDOOR.getDefaultState().with(HorizontalBlock.HORIZONTAL_FACING, Direction.NORTH).with(TrapDoorBlock.HALF, Half.BOTTOM).with(TrapDoorBlock.WATERLOGGED, false).with(TrapDoorBlock.POWERED, false).with(TrapDoorBlock.OPEN, true));
        structure.fillWithBlocks(world, start, 73, 10, 63, 73, 11, 63, Blocks.SPRUCE_TRAPDOOR.getDefaultState().with(HorizontalBlock.HORIZONTAL_FACING, Direction.NORTH).with(TrapDoorBlock.HALF, Half.BOTTOM).with(TrapDoorBlock.WATERLOGGED, false).with(TrapDoorBlock.POWERED, false).with(TrapDoorBlock.OPEN, true));
        structure.fillWithBlocks(world, start, 73, 10, 68, 73, 11, 68, Blocks.SPRUCE_TRAPDOOR.getDefaultState().with(HorizontalBlock.HORIZONTAL_FACING, Direction.SOUTH).with(TrapDoorBlock.HALF, Half.TOP).with(TrapDoorBlock.WATERLOGGED, false).with(TrapDoorBlock.POWERED, false).with(TrapDoorBlock.OPEN, true));
        structure.fillWithBlocks(world, start, 73, 10, 74, 74, 11, 74, Blocks.SPRUCE_TRAPDOOR.getDefaultState().with(HorizontalBlock.HORIZONTAL_FACING, Direction.NORTH).with(TrapDoorBlock.HALF, Half.BOTTOM).with(TrapDoorBlock.WATERLOGGED, false).with(TrapDoorBlock.POWERED, false).with(TrapDoorBlock.OPEN, true));
        structure.fillWithBlocks(world, start, 73, 10, 79, 73, 11, 79, Blocks.SPRUCE_TRAPDOOR.getDefaultState().with(HorizontalBlock.HORIZONTAL_FACING, Direction.SOUTH).with(TrapDoorBlock.HALF, Half.BOTTOM).with(TrapDoorBlock.WATERLOGGED, false).with(TrapDoorBlock.POWERED, false).with(TrapDoorBlock.OPEN, true));
        structure.fillWithBlocks(world, start, 73, 11, 26, 73, 11, 27, Blocks.OAK_FENCE_GATE.getDefaultState().with(FenceGateBlock.IN_WALL, false).with(FenceGateBlock.OPEN, false).with(FenceGateBlock.POWERED, false));
        structure.fillWithBlocks(world, start, 73, 11, 29, 74, 11, 29, Blocks.SPRUCE_TRAPDOOR.getDefaultState().with(HorizontalBlock.HORIZONTAL_FACING, Direction.SOUTH).with(TrapDoorBlock.HALF, Half.BOTTOM).with(TrapDoorBlock.WATERLOGGED, false).with(TrapDoorBlock.POWERED, false).with(TrapDoorBlock.OPEN, true));
        structure.fillWithBlocks(world, start, 73, 11, 52, 74, 11, 52, Blocks.SPRUCE_TRAPDOOR.getDefaultState().with(HorizontalBlock.HORIZONTAL_FACING, Direction.NORTH).with(TrapDoorBlock.HALF, Half.BOTTOM).with(TrapDoorBlock.WATERLOGGED, false).with(TrapDoorBlock.POWERED, false).with(TrapDoorBlock.OPEN, true));
        structure.fillWithBlocks(world, start, 73, 11, 54, 73, 11, 55, Blocks.OAK_FENCE_GATE.getDefaultState().with(FenceGateBlock.IN_WALL, false).with(FenceGateBlock.OPEN, false).with(FenceGateBlock.POWERED, false));
        structure.fillWithBlocks(world, start, 73, 11, 65, 73, 11, 66, Blocks.OAK_FENCE_GATE.getDefaultState().with(FenceGateBlock.IN_WALL, false).with(FenceGateBlock.OPEN, false).with(FenceGateBlock.POWERED, false));
        structure.fillWithBlocks(world, start, 73, 11, 76, 73, 11, 77, Blocks.OAK_FENCE_GATE.getDefaultState().with(FenceGateBlock.IN_WALL, false).with(FenceGateBlock.OPEN, false).with(FenceGateBlock.POWERED, false));
        structure.fillWithBlocks(world, start, 73, 12, 25, 76, 12, 28, Blocks.SPRUCE_TRAPDOOR.getDefaultState().with(HorizontalBlock.HORIZONTAL_FACING, Direction.NORTH).with(TrapDoorBlock.HALF, Half.BOTTOM).with(TrapDoorBlock.WATERLOGGED, false).with(TrapDoorBlock.POWERED, false).with(TrapDoorBlock.OPEN, false));
        structure.fillWithBlocks(world, start, 73, 12, 53, 76, 12, 56, Blocks.SPRUCE_TRAPDOOR.getDefaultState().with(HorizontalBlock.HORIZONTAL_FACING, Direction.SOUTH).with(TrapDoorBlock.HALF, Half.BOTTOM).with(TrapDoorBlock.WATERLOGGED, false).with(TrapDoorBlock.POWERED, false).with(TrapDoorBlock.OPEN, false));
        structure.fillWithBlocks(world, start, 73, 12, 64, 76, 12, 67, Blocks.SPRUCE_TRAPDOOR.getDefaultState().with(HorizontalBlock.HORIZONTAL_FACING, Direction.NORTH).with(TrapDoorBlock.HALF, Half.BOTTOM).with(TrapDoorBlock.WATERLOGGED, false).with(TrapDoorBlock.POWERED, false).with(TrapDoorBlock.OPEN, false));
        structure.fillWithBlocks(world, start, 73, 12, 75, 76, 12, 78, Blocks.SPRUCE_TRAPDOOR.getDefaultState().with(HorizontalBlock.HORIZONTAL_FACING, Direction.SOUTH).with(TrapDoorBlock.HALF, Half.BOTTOM).with(TrapDoorBlock.WATERLOGGED, false).with(TrapDoorBlock.POWERED, false).with(TrapDoorBlock.OPEN, false));
        structure.fillWithBlocks(world, start, 73, 12, 82, 73, 12, 82, Blocks.BIRCH_SLAB.getDefaultState().with(SlabBlock.TYPE, SlabType.BOTTOM).with(SlabBlock.WATERLOGGED, false));
        structure.fillWithBlocks(world, start, 73, 12, 84, 73, 12, 84, Blocks.BIRCH_SLAB.getDefaultState().with(SlabBlock.TYPE, SlabType.BOTTOM).with(SlabBlock.WATERLOGGED, false));
        structure.fillWithBlocks(world, start, 73, 14, 20, 74, 14, 21, Blocks.JUNGLE_SLAB.getDefaultState().with(SlabBlock.TYPE, SlabType.BOTTOM).with(SlabBlock.WATERLOGGED, false));
        structure.fillWithBlocks(world, start, 74, 4, 5, 76, 4, 7, Blocks.DIRT.getDefaultState());
        structure.fillWithBlocks(world, start, 74, 6, 15, 74, 6, 18, Blocks.GRASS_BLOCK.getDefaultState().with(SnowyDirtBlock.SNOWY, false));
        structure.fillWithBlocks(world, start, 74, 6, 104, 74, 6, 107, Blocks.GRASS_BLOCK.getDefaultState().with(SnowyDirtBlock.SNOWY, false));
        structure.fillWithBlocks(world, start, 74, 8, 32, 74, 8, 35, Blocks.GRASS_BLOCK.getDefaultState().with(SnowyDirtBlock.SNOWY, false));
        structure.fillWithBlocks(world, start, 74, 8, 37, 75, 8, 39, Blocks.GRASS_PATH.getDefaultState());
        structure.fillWithBlocks(world, start, 74, 8, 40, 74, 8, 41, Blocks.ACACIA_SLAB.getDefaultState().with(SlabBlock.TYPE, SlabType.DOUBLE).with(SlabBlock.WATERLOGGED, false));
        structure.fillWithBlocks(world, start, 74, 8, 42, 75, 8, 44, Blocks.GRASS_PATH.getDefaultState());
        structure.fillWithBlocks(world, start, 74, 8, 45, 74, 8, 45, Blocks.ACACIA_SLAB.getDefaultState().with(SlabBlock.TYPE, SlabType.DOUBLE).with(SlabBlock.WATERLOGGED, false));
        structure.fillWithBlocks(world, start, 74, 8, 46, 74, 8, 52, Blocks.GRASS_BLOCK.getDefaultState().with(SnowyDirtBlock.SNOWY, false));
        structure.fillWithBlocks(world, start, 74, 8, 61, 78, 8, 61, Blocks.STONE_BRICKS.getDefaultState());
        structure.fillWithBlocks(world, start, 74, 8, 62, 75, 8, 63, Blocks.GRASS_BLOCK.getDefaultState().with(SnowyDirtBlock.SNOWY, false));
        structure.fillWithBlocks(world, start, 74, 8, 71, 74, 8, 74, Blocks.GRASS_BLOCK.getDefaultState().with(SnowyDirtBlock.SNOWY, false));
        structure.fillWithBlocks(world, start, 74, 8, 86, 74, 8, 86, Blocks.GRASS_PATH.getDefaultState());
        structure.fillWithBlocks(world, start, 74, 8, 87, 74, 8, 87, Blocks.GRASS_BLOCK.getDefaultState().with(SnowyDirtBlock.SNOWY, false));
        structure.fillWithBlocks(world, start, 74, 8, 88, 74, 8, 88, Blocks.GRASS_PATH.getDefaultState());
        structure.fillWithBlocks(world, start, 74, 8, 89, 74, 8, 89, Blocks.GRASS_BLOCK.getDefaultState().with(SnowyDirtBlock.SNOWY, false));
        structure.fillWithBlocks(world, start, 74, 8, 91, 76, 8, 94, Blocks.HAY_BLOCK.getDefaultState());
        structure.fillWithBlocks(world, start, 74, 8, 95, 76, 8, 97, Blocks.GRASS_BLOCK.getDefaultState().with(SnowyDirtBlock.SNOWY, false));
        structure.fillWithBlocks(world, start, 74, 9, 23, 86, 9, 23, Blocks.GRASS.getDefaultState());
        structure.fillWithBlocks(world, start, 74, 9, 29, 74, 11, 29, Blocks.SPRUCE_TRAPDOOR.getDefaultState().with(HorizontalBlock.HORIZONTAL_FACING, Direction.SOUTH).with(TrapDoorBlock.HALF, Half.BOTTOM).with(TrapDoorBlock.WATERLOGGED, false).with(TrapDoorBlock.POWERED, false).with(TrapDoorBlock.OPEN, true));
        structure.fillWithBlocks(world, start, 74, 9, 33, 75, 9, 34, Blocks.GRASS.getDefaultState());
        structure.fillWithBlocks(world, start, 74, 9, 40, 74, 9, 41, Blocks.ACACIA_SLAB.getDefaultState().with(SlabBlock.TYPE, SlabType.BOTTOM).with(SlabBlock.WATERLOGGED, false));
        structure.fillWithBlocks(world, start, 74, 9, 45, 74, 9, 45, Blocks.ACACIA_SLAB.getDefaultState().with(SlabBlock.TYPE, SlabType.BOTTOM).with(SlabBlock.WATERLOGGED, false));
        structure.fillWithBlocks(world, start, 74, 9, 48, 76, 9, 48, Blocks.GRASS.getDefaultState());
        structure.fillWithBlocks(world, start, 74, 9, 50, 74, 9, 51, Blocks.GRASS.getDefaultState());
        structure.fillWithBlocks(world, start, 74, 9, 80, 77, 9, 80, Blocks.GRASS.getDefaultState());
        structure.fillWithBlocks(world, start, 74, 9, 95, 74, 9, 97, Blocks.GRASS.getDefaultState());
        structure.fillWithBlocks(world, start, 74, 10, 68, 74, 11, 68, Blocks.SPRUCE_TRAPDOOR.getDefaultState().with(HorizontalBlock.HORIZONTAL_FACING, Direction.SOUTH).with(TrapDoorBlock.HALF, Half.BOTTOM).with(TrapDoorBlock.WATERLOGGED, false).with(TrapDoorBlock.POWERED, false).with(TrapDoorBlock.OPEN, true));
        structure.fillWithBlocks(world, start, 74, 11, 24, 77, 11, 24, Blocks.SPRUCE_TRAPDOOR.getDefaultState().with(HorizontalBlock.HORIZONTAL_FACING, Direction.NORTH).with(TrapDoorBlock.HALF, Half.BOTTOM).with(TrapDoorBlock.WATERLOGGED, false).with(TrapDoorBlock.POWERED, false).with(TrapDoorBlock.OPEN, true));
        structure.fillWithBlocks(world, start, 74, 11, 25, 76, 11, 25, Blocks.OAK_FENCE_GATE.getDefaultState().with(FenceGateBlock.IN_WALL, false).with(FenceGateBlock.OPEN, false).with(FenceGateBlock.POWERED, false));
        structure.fillWithBlocks(world, start, 74, 11, 56, 76, 11, 56, Blocks.OAK_FENCE_GATE.getDefaultState().with(FenceGateBlock.IN_WALL, false).with(FenceGateBlock.OPEN, false).with(FenceGateBlock.POWERED, false));
        structure.fillWithBlocks(world, start, 74, 11, 57, 77, 11, 57, Blocks.SPRUCE_TRAPDOOR.getDefaultState().with(HorizontalBlock.HORIZONTAL_FACING, Direction.SOUTH).with(TrapDoorBlock.HALF, Half.BOTTOM).with(TrapDoorBlock.WATERLOGGED, false).with(TrapDoorBlock.POWERED, false).with(TrapDoorBlock.OPEN, true));
        structure.fillWithBlocks(world, start, 74, 11, 63, 77, 11, 63, Blocks.SPRUCE_TRAPDOOR.getDefaultState().with(HorizontalBlock.HORIZONTAL_FACING, Direction.NORTH).with(TrapDoorBlock.HALF, Half.BOTTOM).with(TrapDoorBlock.WATERLOGGED, false).with(TrapDoorBlock.POWERED, false).with(TrapDoorBlock.OPEN, true));
        structure.fillWithBlocks(world, start, 74, 11, 64, 76, 11, 64, Blocks.OAK_FENCE_GATE.getDefaultState().with(FenceGateBlock.IN_WALL, false).with(FenceGateBlock.OPEN, false).with(FenceGateBlock.POWERED, false));
        structure.fillWithBlocks(world, start, 74, 11, 78, 76, 11, 78, Blocks.OAK_FENCE_GATE.getDefaultState().with(FenceGateBlock.IN_WALL, false).with(FenceGateBlock.OPEN, false).with(FenceGateBlock.POWERED, false));
        structure.fillWithBlocks(world, start, 74, 11, 79, 77, 11, 79, Blocks.SPRUCE_TRAPDOOR.getDefaultState().with(HorizontalBlock.HORIZONTAL_FACING, Direction.SOUTH).with(TrapDoorBlock.HALF, Half.BOTTOM).with(TrapDoorBlock.WATERLOGGED, false).with(TrapDoorBlock.POWERED, false).with(TrapDoorBlock.OPEN, true));
        structure.fillWithBlocks(world, start, 74, 12, 81, 74, 12, 81, Blocks.BIRCH_SLAB.getDefaultState().with(SlabBlock.TYPE, SlabType.BOTTOM).with(SlabBlock.WATERLOGGED, false));
        structure.fillWithBlocks(world, start, 74, 12, 83, 74, 12, 83, Blocks.BIRCH_SLAB.getDefaultState().with(SlabBlock.TYPE, SlabType.BOTTOM).with(SlabBlock.WATERLOGGED, false));
        structure.fillWithBlocks(world, start, 74, 14, 99, 75, 14, 100, Blocks.JUNGLE_SLAB.getDefaultState().with(SlabBlock.TYPE, SlabType.BOTTOM).with(SlabBlock.WATERLOGGED, false));
        structure.fillWithBlocks(world, start, 75, 0, 1, 76, 0, 2, Blocks.DIRT.getDefaultState());
        structure.fillWithBlocks(world, start, 75, 0, 3, 90, 0, 107, Blocks.STONE.getDefaultState());
        structure.fillWithBlocks(world, start, 75, 1, 1, 86, 1, 1, Blocks.GRASS_BLOCK.getDefaultState().with(SnowyDirtBlock.SNOWY, false));
        structure.fillWithBlocks(world, start, 75, 1, 3, 76, 1, 4, Blocks.DIRT.getDefaultState());
        structure.fillWithBlocks(world, start, 75, 1, 107, 78, 1, 110, Blocks.DIRT.getDefaultState());
        structure.fillWithBlocks(world, start, 75, 2, 2, 80, 2, 7, Blocks.DIRT.getDefaultState());
        structure.fillWithBlocks(world, start, 75, 3, 3, 79, 3, 7, Blocks.DIRT.getDefaultState());
        structure.fillWithBlocks(world, start, 75, 4, 3, 79, 4, 7, Blocks.DIRT.getDefaultState());
        structure.fillWithBlocks(world, start, 75, 5, 3, 76, 5, 4, Blocks.GRASS_BLOCK.getDefaultState().with(SnowyDirtBlock.SNOWY, false));
        structure.fillWithBlocks(world, start, 75, 5, 5, 77, 5, 7, Blocks.DIRT.getDefaultState());
        structure.fillWithBlocks(world, start, 75, 6, 16, 76, 6, 18, Blocks.GRASS_BLOCK.getDefaultState().with(SnowyDirtBlock.SNOWY, false));
        structure.fillWithBlocks(world, start, 75, 6, 65, 97, 6, 92, Blocks.DIRT.getDefaultState());
        structure.fillWithBlocks(world, start, 75, 6, 102, 76, 6, 104, Blocks.GRASS_BLOCK.getDefaultState().with(SnowyDirtBlock.SNOWY, false));
        structure.fillWithBlocks(world, start, 75, 6, 106, 76, 6, 107, Blocks.GRASS_BLOCK.getDefaultState().with(SnowyDirtBlock.SNOWY, false));
        structure.fillWithBlocks(world, start, 75, 7, 12, 76, 7, 12, Blocks.GRASS.getDefaultState());
        structure.fillWithBlocks(world, start, 75, 8, 23, 76, 8, 24, Blocks.GRASS_BLOCK.getDefaultState().with(SnowyDirtBlock.SNOWY, false));
        structure.fillWithBlocks(world, start, 75, 8, 29, 75, 8, 29, Blocks.GRASS_BLOCK.getDefaultState().with(SnowyDirtBlock.SNOWY, false));
        structure.fillWithBlocks(world, start, 75, 8, 31, 75, 8, 31, Blocks.GRASS_BLOCK.getDefaultState().with(SnowyDirtBlock.SNOWY, false));
        structure.fillWithBlocks(world, start, 75, 8, 33, 76, 8, 34, Blocks.GRASS_BLOCK.getDefaultState().with(SnowyDirtBlock.SNOWY, false));
        structure.fillWithBlocks(world, start, 75, 8, 36, 76, 8, 37, Blocks.GRASS_PATH.getDefaultState());
        structure.fillWithBlocks(world, start, 75, 8, 40, 77, 8, 42, Blocks.GRASS_PATH.getDefaultState());
        structure.fillWithBlocks(world, start, 75, 8, 45, 75, 8, 45, Blocks.GRASS_PATH.getDefaultState());
        structure.fillWithBlocks(world, start, 75, 8, 47, 76, 8, 48, Blocks.GRASS_BLOCK.getDefaultState().with(SnowyDirtBlock.SNOWY, false));
        structure.fillWithBlocks(world, start, 75, 8, 50, 75, 8, 50, Blocks.GRASS_BLOCK.getDefaultState().with(SnowyDirtBlock.SNOWY, false));
        structure.fillWithBlocks(world, start, 75, 8, 52, 88, 8, 52, Blocks.GRASS_BLOCK.getDefaultState().with(SnowyDirtBlock.SNOWY, false));
        structure.fillWithBlocks(world, start, 75, 8, 57, 76, 8, 58, Blocks.GRASS_BLOCK.getDefaultState().with(SnowyDirtBlock.SNOWY, false));
        structure.fillWithBlocks(world, start, 75, 8, 59, 75, 8, 61, Blocks.STONE_BRICKS.getDefaultState());
        structure.fillWithBlocks(world, start, 75, 8, 68, 75, 8, 68, Blocks.GRASS_BLOCK.getDefaultState().with(SnowyDirtBlock.SNOWY, false));
        structure.fillWithBlocks(world, start, 75, 8, 70, 75, 8, 70, Blocks.GRASS_BLOCK.getDefaultState().with(SnowyDirtBlock.SNOWY, false));
        structure.fillWithBlocks(world, start, 75, 8, 72, 75, 8, 72, Blocks.GRASS_BLOCK.getDefaultState().with(SnowyDirtBlock.SNOWY, false));
        structure.fillWithBlocks(world, start, 75, 8, 74, 88, 8, 74, Blocks.GRASS_BLOCK.getDefaultState().with(SnowyDirtBlock.SNOWY, false));
        structure.fillWithBlocks(world, start, 75, 8, 79, 76, 8, 80, Blocks.GRASS_BLOCK.getDefaultState().with(SnowyDirtBlock.SNOWY, false));
        structure.fillWithBlocks(world, start, 75, 8, 85, 76, 8, 85, Blocks.MOSSY_COBBLESTONE.getDefaultState());
        structure.fillWithBlocks(world, start, 75, 8, 86, 75, 8, 86, Blocks.GRASS_BLOCK.getDefaultState().with(SnowyDirtBlock.SNOWY, false));
        structure.fillWithBlocks(world, start, 75, 8, 87, 75, 8, 87, Blocks.GRASS_PATH.getDefaultState());
        structure.fillWithBlocks(world, start, 75, 8, 88, 75, 8, 88, Blocks.GRASS_BLOCK.getDefaultState().with(SnowyDirtBlock.SNOWY, false));
        structure.fillWithBlocks(world, start, 75, 8, 89, 75, 8, 89, Blocks.GRASS_PATH.getDefaultState());
        structure.fillWithBlocks(world, start, 75, 10, 24, 75, 11, 24, Blocks.SPRUCE_TRAPDOOR.getDefaultState().with(HorizontalBlock.HORIZONTAL_FACING, Direction.NORTH).with(TrapDoorBlock.HALF, Half.BOTTOM).with(TrapDoorBlock.WATERLOGGED, false).with(TrapDoorBlock.POWERED, false).with(TrapDoorBlock.OPEN, true));
        structure.fillWithBlocks(world, start, 75, 10, 57, 75, 11, 57, Blocks.SPRUCE_TRAPDOOR.getDefaultState().with(HorizontalBlock.HORIZONTAL_FACING, Direction.SOUTH).with(TrapDoorBlock.HALF, Half.BOTTOM).with(TrapDoorBlock.WATERLOGGED, false).with(TrapDoorBlock.POWERED, false).with(TrapDoorBlock.OPEN, true));
        structure.fillWithBlocks(world, start, 75, 10, 63, 75, 11, 63, Blocks.SPRUCE_TRAPDOOR.getDefaultState().with(HorizontalBlock.HORIZONTAL_FACING, Direction.NORTH).with(TrapDoorBlock.HALF, Half.BOTTOM).with(TrapDoorBlock.WATERLOGGED, false).with(TrapDoorBlock.POWERED, false).with(TrapDoorBlock.OPEN, true));
        structure.fillWithBlocks(world, start, 75, 10, 79, 75, 11, 79, Blocks.SPRUCE_TRAPDOOR.getDefaultState().with(HorizontalBlock.HORIZONTAL_FACING, Direction.SOUTH).with(TrapDoorBlock.HALF, Half.BOTTOM).with(TrapDoorBlock.WATERLOGGED, false).with(TrapDoorBlock.POWERED, false).with(TrapDoorBlock.OPEN, true));
        structure.fillWithBlocks(world, start, 75, 12, 82, 75, 12, 82, Blocks.BIRCH_SLAB.getDefaultState().with(SlabBlock.TYPE, SlabType.BOTTOM).with(SlabBlock.WATERLOGGED, false));
        structure.fillWithBlocks(world, start, 75, 12, 84, 75, 12, 84, Blocks.BIRCH_SLAB.getDefaultState().with(SlabBlock.TYPE, SlabType.BOTTOM).with(SlabBlock.WATERLOGGED, false));
        structure.fillWithBlocks(world, start, 75, 14, 20, 76, 14, 21, Blocks.JUNGLE_SLAB.getDefaultState().with(SlabBlock.TYPE, SlabType.BOTTOM).with(SlabBlock.WATERLOGGED, false));
        structure.fillWithBlocks(world, start, 76, 0, 108, 78, 0, 111, Blocks.DIRT.getDefaultState());
        structure.fillWithBlocks(world, start, 76, 2, 110, 89, 2, 110, Blocks.GRASS_BLOCK.getDefaultState().with(SnowyDirtBlock.SNOWY, false));
        structure.fillWithBlocks(world, start, 76, 4, 103, 80, 4, 108, Blocks.DIRT.getDefaultState());
        structure.fillWithBlocks(world, start, 76, 6, 15, 76, 6, 18, Blocks.GRASS_BLOCK.getDefaultState().with(SnowyDirtBlock.SNOWY, false));
        structure.fillWithBlocks(world, start, 76, 6, 105, 78, 6, 107, Blocks.GRASS_BLOCK.getDefaultState().with(SnowyDirtBlock.SNOWY, false));
        structure.fillWithBlocks(world, start, 76, 8, 29, 78, 8, 31, Blocks.GRASS_BLOCK.getDefaultState().with(SnowyDirtBlock.SNOWY, false));
        structure.fillWithBlocks(world, start, 76, 8, 32, 76, 8, 34, Blocks.GRASS_BLOCK.getDefaultState().with(SnowyDirtBlock.SNOWY, false));
        structure.fillWithBlocks(world, start, 76, 8, 35, 76, 8, 37, Blocks.GRASS_PATH.getDefaultState());
        structure.fillWithBlocks(world, start, 76, 8, 39, 77, 8, 42, Blocks.GRASS_PATH.getDefaultState());
        structure.fillWithBlocks(world, start, 76, 8, 44, 77, 8, 45, Blocks.GRASS_PATH.getDefaultState());
        structure.fillWithBlocks(world, start, 76, 8, 49, 76, 8, 52, Blocks.GRASS_BLOCK.getDefaultState().with(SnowyDirtBlock.SNOWY, false));
        structure.fillWithBlocks(world, start, 76, 8, 59, 76, 8, 59, Blocks.STONE_BRICKS.getDefaultState());
        structure.fillWithBlocks(world, start, 76, 8, 62, 77, 8, 63, Blocks.GRASS_BLOCK.getDefaultState().with(SnowyDirtBlock.SNOWY, false));
        structure.fillWithBlocks(world, start, 76, 8, 68, 78, 8, 70, Blocks.GRASS_BLOCK.getDefaultState().with(SnowyDirtBlock.SNOWY, false));
        structure.fillWithBlocks(world, start, 76, 8, 71, 76, 8, 74, Blocks.GRASS_BLOCK.getDefaultState().with(SnowyDirtBlock.SNOWY, false));
        structure.fillWithBlocks(world, start, 76, 8, 82, 76, 8, 85, Blocks.MOSSY_COBBLESTONE.getDefaultState());
        structure.fillWithBlocks(world, start, 76, 8, 86, 76, 8, 87, Blocks.GRASS_BLOCK.getDefaultState().with(SnowyDirtBlock.SNOWY, false));
        structure.fillWithBlocks(world, start, 76, 8, 88, 76, 8, 88, Blocks.GRASS_PATH.getDefaultState());
        structure.fillWithBlocks(world, start, 76, 8, 89, 76, 8, 89, Blocks.GRASS_BLOCK.getDefaultState().with(SnowyDirtBlock.SNOWY, false));
        structure.fillWithBlocks(world, start, 76, 9, 30, 76, 9, 30, Blocks.GRASS.getDefaultState());
        structure.fillWithBlocks(world, start, 76, 9, 33, 77, 9, 34, Blocks.GRASS.getDefaultState());
        structure.fillWithBlocks(world, start, 76, 9, 50, 77, 9, 51, Blocks.GRASS.getDefaultState());
        structure.fillWithBlocks(world, start, 76, 9, 62, 77, 9, 62, Blocks.GRASS.getDefaultState());
        structure.fillWithBlocks(world, start, 76, 9, 69, 77, 9, 70, Blocks.GRASS.getDefaultState());
        structure.fillWithBlocks(world, start, 76, 9, 72, 76, 9, 73, Blocks.GRASS.getDefaultState());
        structure.fillWithBlocks(world, start, 76, 9, 74, 77, 10, 74, Blocks.SPRUCE_TRAPDOOR.getDefaultState().with(HorizontalBlock.HORIZONTAL_FACING, Direction.NORTH).with(TrapDoorBlock.HALF, Half.BOTTOM).with(TrapDoorBlock.WATERLOGGED, false).with(TrapDoorBlock.POWERED, false).with(TrapDoorBlock.OPEN, true));
        structure.fillWithBlocks(world, start, 76, 9, 81, 76, 11, 81, Blocks.BIRCH_FENCE.getDefaultState().with(FourWayBlock.WATERLOGGED, false).with(FourWayBlock.NORTH, false).with(FourWayBlock.SOUTH, false).with(FourWayBlock.EAST, false).with(FourWayBlock.WEST, false));
        structure.fillWithBlocks(world, start, 76, 9, 82, 76, 11, 84, Blocks.CHAIN.getDefaultState().with(ChainBlock.WATERLOGGED, false));
        structure.fillWithBlocks(world, start, 76, 9, 85, 76, 11, 85, Blocks.BIRCH_FENCE.getDefaultState().with(FourWayBlock.WATERLOGGED, false).with(FourWayBlock.NORTH, false).with(FourWayBlock.SOUTH, false).with(FourWayBlock.EAST, false).with(FourWayBlock.WEST, false));
        structure.fillWithBlocks(world, start, 76, 9, 86, 76, 9, 87, Blocks.GRASS.getDefaultState());
        structure.fillWithBlocks(world, start, 76, 9, 89, 76, 9, 89, Blocks.GRASS.getDefaultState());
        structure.fillWithBlocks(world, start, 76, 9, 96, 76, 9, 96, Blocks.GRASS.getDefaultState());
        structure.fillWithBlocks(world, start, 76, 10, 29, 77, 11, 29, Blocks.SPRUCE_TRAPDOOR.getDefaultState().with(HorizontalBlock.HORIZONTAL_FACING, Direction.SOUTH).with(TrapDoorBlock.HALF, Half.BOTTOM).with(TrapDoorBlock.WATERLOGGED, false).with(TrapDoorBlock.POWERED, false).with(TrapDoorBlock.OPEN, true));
        structure.fillWithBlocks(world, start, 76, 10, 52, 77, 11, 52, Blocks.SPRUCE_TRAPDOOR.getDefaultState().with(HorizontalBlock.HORIZONTAL_FACING, Direction.NORTH).with(TrapDoorBlock.HALF, Half.BOTTOM).with(TrapDoorBlock.WATERLOGGED, false).with(TrapDoorBlock.POWERED, false).with(TrapDoorBlock.OPEN, true));
        structure.fillWithBlocks(world, start, 76, 10, 68, 77, 11, 68, Blocks.SPRUCE_TRAPDOOR.getDefaultState().with(HorizontalBlock.HORIZONTAL_FACING, Direction.SOUTH).with(TrapDoorBlock.HALF, Half.BOTTOM).with(TrapDoorBlock.WATERLOGGED, false).with(TrapDoorBlock.POWERED, false).with(TrapDoorBlock.OPEN, true));
        structure.fillWithBlocks(world, start, 76, 11, 74, 77, 11, 74, Blocks.SPRUCE_TRAPDOOR.getDefaultState().with(HorizontalBlock.HORIZONTAL_FACING, Direction.NORTH).with(TrapDoorBlock.HALF, Half.BOTTOM).with(TrapDoorBlock.WATERLOGGED, false).with(TrapDoorBlock.POWERED, false).with(TrapDoorBlock.OPEN, true));
        structure.fillWithBlocks(world, start, 76, 12, 81, 76, 12, 85, Blocks.BIRCH_SLAB.getDefaultState().with(SlabBlock.TYPE, SlabType.BOTTOM).with(SlabBlock.WATERLOGGED, false));
        structure.fillWithBlocks(world, start, 76, 14, 99, 77, 14, 100, Blocks.JUNGLE_SLAB.getDefaultState().with(SlabBlock.TYPE, SlabType.BOTTOM).with(SlabBlock.WATERLOGGED, false));
        structure.fillWithBlocks(world, start, 77, 0, 1, 78, 0, 2, Blocks.DIRT.getDefaultState());
        structure.fillWithBlocks(world, start, 77, 1, 3, 78, 1, 4, Blocks.DIRT.getDefaultState());
        structure.fillWithBlocks(world, start, 77, 2, 105, 81, 2, 109, Blocks.DIRT.getDefaultState());
        structure.fillWithBlocks(world, start, 77, 5, 3, 78, 5, 4, Blocks.GRASS_BLOCK.getDefaultState().with(SnowyDirtBlock.SNOWY, false));
        structure.fillWithBlocks(world, start, 77, 6, 15, 77, 6, 15, Blocks.GRASS_BLOCK.getDefaultState().with(SnowyDirtBlock.SNOWY, false));
        structure.fillWithBlocks(world, start, 77, 6, 17, 78, 6, 18, Blocks.GRASS_BLOCK.getDefaultState().with(SnowyDirtBlock.SNOWY, false));
        structure.fillWithBlocks(world, start, 77, 6, 53, 95, 6, 97, Blocks.DIRT.getDefaultState());
        structure.fillWithBlocks(world, start, 77, 6, 102, 78, 6, 103, Blocks.GRASS_BLOCK.getDefaultState().with(SnowyDirtBlock.SNOWY, false));
        structure.fillWithBlocks(world, start, 77, 7, 7, 77, 7, 7, Blocks.GRASS.getDefaultState());
        structure.fillWithBlocks(world, start, 77, 7, 19, 77, 15, 19, Blocks.SPRUCE_LOG.getDefaultState());
        structure.fillWithBlocks(world, start, 77, 7, 101, 77, 15, 101, Blocks.SPRUCE_LOG.getDefaultState());
        structure.fillWithBlocks(world, start, 77, 8, 20, 77, 13, 20, Blocks.SPRUCE_LOG.getDefaultState());
        structure.fillWithBlocks(world, start, 77, 8, 23, 78, 8, 24, Blocks.GRASS_BLOCK.getDefaultState().with(SnowyDirtBlock.SNOWY, false));
        structure.fillWithBlocks(world, start, 77, 8, 25, 77, 8, 28, Blocks.PODZOL.getDefaultState().with(SnowyDirtBlock.SNOWY, false));
        structure.fillWithBlocks(world, start, 77, 8, 33, 78, 8, 34, Blocks.GRASS_BLOCK.getDefaultState().with(SnowyDirtBlock.SNOWY, false));
        structure.fillWithBlocks(world, start, 77, 8, 35, 77, 8, 35, Blocks.ACACIA_SLAB.getDefaultState().with(SlabBlock.TYPE, SlabType.DOUBLE).with(SlabBlock.WATERLOGGED, false));
        structure.fillWithBlocks(world, start, 77, 8, 36, 77, 8, 45, Blocks.GRASS_PATH.getDefaultState());
        structure.fillWithBlocks(world, start, 77, 8, 47, 78, 8, 48, Blocks.GRASS_BLOCK.getDefaultState().with(SnowyDirtBlock.SNOWY, false));
        structure.fillWithBlocks(world, start, 77, 8, 50, 79, 8, 52, Blocks.GRASS_BLOCK.getDefaultState().with(SnowyDirtBlock.SNOWY, false));
        structure.fillWithBlocks(world, start, 77, 8, 53, 77, 8, 56, Blocks.PODZOL.getDefaultState().with(SnowyDirtBlock.SNOWY, false));
        structure.fillWithBlocks(world, start, 77, 8, 57, 78, 8, 58, Blocks.GRASS_BLOCK.getDefaultState().with(SnowyDirtBlock.SNOWY, false));
        structure.fillWithBlocks(world, start, 77, 8, 59, 78, 8, 61, Blocks.STONE_BRICKS.getDefaultState());
        structure.fillWithBlocks(world, start, 77, 8, 64, 77, 8, 67, Blocks.PODZOL.getDefaultState().with(SnowyDirtBlock.SNOWY, false));
        structure.fillWithBlocks(world, start, 77, 8, 72, 79, 8, 74, Blocks.GRASS_BLOCK.getDefaultState().with(SnowyDirtBlock.SNOWY, false));
        structure.fillWithBlocks(world, start, 77, 8, 75, 77, 8, 78, Blocks.PODZOL.getDefaultState().with(SnowyDirtBlock.SNOWY, false));
        structure.fillWithBlocks(world, start, 77, 8, 79, 79, 8, 82, Blocks.GRASS_BLOCK.getDefaultState().with(SnowyDirtBlock.SNOWY, false));
        structure.fillWithBlocks(world, start, 77, 8, 83, 77, 8, 86, Blocks.GRASS_BLOCK.getDefaultState().with(SnowyDirtBlock.SNOWY, false));
        structure.fillWithBlocks(world, start, 77, 8, 87, 77, 8, 87, Blocks.GRASS_PATH.getDefaultState());
        structure.fillWithBlocks(world, start, 77, 8, 88, 77, 8, 88, Blocks.GRASS_BLOCK.getDefaultState().with(SnowyDirtBlock.SNOWY, false));
        structure.fillWithBlocks(world, start, 77, 8, 89, 77, 8, 89, Blocks.GRASS_PATH.getDefaultState());
        structure.fillWithBlocks(world, start, 77, 8, 90, 77, 8, 97, Blocks.GRASS_BLOCK.getDefaultState().with(SnowyDirtBlock.SNOWY, false));
        structure.fillWithBlocks(world, start, 77, 8, 100, 77, 9, 101, Blocks.SPRUCE_LOG.getDefaultState());
        structure.fillWithBlocks(world, start, 77, 9, 25, 77, 10, 25, Blocks.OAK_FENCE.getDefaultState().with(FourWayBlock.WATERLOGGED, false).with(FourWayBlock.NORTH, true).with(FourWayBlock.SOUTH, false).with(FourWayBlock.EAST, true).with(FourWayBlock.WEST, false));
        structure.fillWithBlocks(world, start, 77, 9, 28, 77, 10, 28, Blocks.OAK_FENCE.getDefaultState().with(FourWayBlock.WATERLOGGED, false).with(FourWayBlock.NORTH, false).with(FourWayBlock.SOUTH, true).with(FourWayBlock.EAST, true).with(FourWayBlock.WEST, false));
        structure.fillWithBlocks(world, start, 77, 9, 29, 77, 11, 29, Blocks.SPRUCE_TRAPDOOR.getDefaultState().with(HorizontalBlock.HORIZONTAL_FACING, Direction.SOUTH).with(TrapDoorBlock.HALF, Half.BOTTOM).with(TrapDoorBlock.WATERLOGGED, false).with(TrapDoorBlock.POWERED, false).with(TrapDoorBlock.OPEN, true));
        structure.fillWithBlocks(world, start, 77, 9, 30, 77, 9, 31, Blocks.GRASS.getDefaultState());
        structure.fillWithBlocks(world, start, 77, 9, 35, 77, 9, 35, Blocks.ACACIA_SLAB.getDefaultState().with(SlabBlock.TYPE, SlabType.BOTTOM).with(SlabBlock.WATERLOGGED, false));
        structure.fillWithBlocks(world, start, 77, 9, 47, 77, 9, 47, Blocks.GRASS.getDefaultState());
        structure.fillWithBlocks(world, start, 77, 9, 52, 77, 11, 52, Blocks.SPRUCE_TRAPDOOR.getDefaultState().with(HorizontalBlock.HORIZONTAL_FACING, Direction.NORTH).with(TrapDoorBlock.HALF, Half.BOTTOM).with(TrapDoorBlock.WATERLOGGED, false).with(TrapDoorBlock.POWERED, false).with(TrapDoorBlock.OPEN, true));
        structure.fillWithBlocks(world, start, 77, 9, 53, 77, 10, 53, Blocks.OAK_FENCE.getDefaultState().with(FourWayBlock.WATERLOGGED, false).with(FourWayBlock.NORTH, true).with(FourWayBlock.SOUTH, false).with(FourWayBlock.EAST, true).with(FourWayBlock.WEST, false));
        structure.fillWithBlocks(world, start, 77, 9, 56, 77, 10, 56, Blocks.OAK_FENCE.getDefaultState().with(FourWayBlock.WATERLOGGED, false).with(FourWayBlock.NORTH, false).with(FourWayBlock.SOUTH, true).with(FourWayBlock.EAST, true).with(FourWayBlock.WEST, false));
        structure.fillWithBlocks(world, start, 77, 9, 63, 77, 11, 63, Blocks.SPRUCE_TRAPDOOR.getDefaultState().with(HorizontalBlock.HORIZONTAL_FACING, Direction.NORTH).with(TrapDoorBlock.HALF, Half.BOTTOM).with(TrapDoorBlock.WATERLOGGED, false).with(TrapDoorBlock.POWERED, false).with(TrapDoorBlock.OPEN, true));
        structure.fillWithBlocks(world, start, 77, 9, 64, 77, 10, 64, Blocks.OAK_FENCE.getDefaultState().with(FourWayBlock.WATERLOGGED, false).with(FourWayBlock.NORTH, true).with(FourWayBlock.SOUTH, false).with(FourWayBlock.EAST, true).with(FourWayBlock.WEST, false));
        structure.fillWithBlocks(world, start, 77, 9, 67, 77, 10, 67, Blocks.OAK_FENCE.getDefaultState().with(FourWayBlock.WATERLOGGED, false).with(FourWayBlock.NORTH, false).with(FourWayBlock.SOUTH, true).with(FourWayBlock.EAST, true).with(FourWayBlock.WEST, false));
        structure.fillWithBlocks(world, start, 77, 9, 68, 77, 11, 68, Blocks.SPRUCE_TRAPDOOR.getDefaultState().with(HorizontalBlock.HORIZONTAL_FACING, Direction.SOUTH).with(TrapDoorBlock.HALF, Half.BOTTOM).with(TrapDoorBlock.WATERLOGGED, false).with(TrapDoorBlock.POWERED, false).with(TrapDoorBlock.OPEN, true));
        structure.fillWithBlocks(world, start, 77, 9, 73, 77, 9, 73, Blocks.GRASS.getDefaultState());
        structure.fillWithBlocks(world, start, 77, 9, 75, 77, 10, 75, Blocks.OAK_FENCE.getDefaultState().with(FourWayBlock.WATERLOGGED, false).with(FourWayBlock.NORTH, true).with(FourWayBlock.SOUTH, false).with(FourWayBlock.EAST, true).with(FourWayBlock.WEST, false));
        structure.fillWithBlocks(world, start, 77, 9, 78, 77, 10, 78, Blocks.OAK_FENCE.getDefaultState().with(FourWayBlock.WATERLOGGED, false).with(FourWayBlock.NORTH, false).with(FourWayBlock.SOUTH, true).with(FourWayBlock.EAST, true).with(FourWayBlock.WEST, false));
        structure.fillWithBlocks(world, start, 77, 9, 81, 80, 9, 81, Blocks.GRASS.getDefaultState());
        structure.fillWithBlocks(world, start, 77, 9, 83, 77, 9, 84, Blocks.GRASS.getDefaultState());
        structure.fillWithBlocks(world, start, 77, 9, 90, 77, 9, 91, Blocks.GRASS.getDefaultState());
        structure.fillWithBlocks(world, start, 77, 9, 93, 77, 9, 94, Blocks.GRASS.getDefaultState());
        structure.fillWithBlocks(world, start, 77, 9, 97, 79, 9, 97, Blocks.GRASS.getDefaultState());
        structure.fillWithBlocks(world, start, 77, 10, 24, 77, 11, 24, Blocks.SPRUCE_TRAPDOOR.getDefaultState().with(HorizontalBlock.HORIZONTAL_FACING, Direction.NORTH).with(TrapDoorBlock.HALF, Half.BOTTOM).with(TrapDoorBlock.WATERLOGGED, false).with(TrapDoorBlock.POWERED, false).with(TrapDoorBlock.OPEN, true));
        structure.fillWithBlocks(world, start, 77, 10, 79, 77, 11, 79, Blocks.SPRUCE_TRAPDOOR.getDefaultState().with(HorizontalBlock.HORIZONTAL_FACING, Direction.SOUTH).with(TrapDoorBlock.HALF, Half.BOTTOM).with(TrapDoorBlock.WATERLOGGED, false).with(TrapDoorBlock.POWERED, false).with(TrapDoorBlock.OPEN, true));
        structure.fillWithBlocks(world, start, 77, 10, 100, 77, 11, 101, Blocks.SPRUCE_LOG.getDefaultState());
        structure.fillWithBlocks(world, start, 77, 11, 26, 77, 11, 27, Blocks.OAK_FENCE_GATE.getDefaultState().with(FenceGateBlock.IN_WALL, false).with(FenceGateBlock.OPEN, false).with(FenceGateBlock.POWERED, false));
        structure.fillWithBlocks(world, start, 77, 11, 54, 77, 11, 55, Blocks.OAK_FENCE_GATE.getDefaultState().with(FenceGateBlock.IN_WALL, false).with(FenceGateBlock.OPEN, false).with(FenceGateBlock.POWERED, false));
        structure.fillWithBlocks(world, start, 77, 11, 65, 77, 11, 66, Blocks.OAK_FENCE_GATE.getDefaultState().with(FenceGateBlock.IN_WALL, false).with(FenceGateBlock.OPEN, false).with(FenceGateBlock.POWERED, false));
        structure.fillWithBlocks(world, start, 77, 11, 76, 77, 11, 77, Blocks.OAK_FENCE_GATE.getDefaultState().with(FenceGateBlock.IN_WALL, false).with(FenceGateBlock.OPEN, false).with(FenceGateBlock.POWERED, false));
        structure.fillWithBlocks(world, start, 77, 12, 25, 77, 12, 28, Blocks.SPRUCE_TRAPDOOR.getDefaultState().with(HorizontalBlock.HORIZONTAL_FACING, Direction.NORTH).with(TrapDoorBlock.HALF, Half.BOTTOM).with(TrapDoorBlock.WATERLOGGED, false).with(TrapDoorBlock.POWERED, false).with(TrapDoorBlock.OPEN, false));
        structure.fillWithBlocks(world, start, 77, 12, 53, 77, 12, 56, Blocks.SPRUCE_TRAPDOOR.getDefaultState().with(HorizontalBlock.HORIZONTAL_FACING, Direction.SOUTH).with(TrapDoorBlock.HALF, Half.BOTTOM).with(TrapDoorBlock.WATERLOGGED, false).with(TrapDoorBlock.POWERED, false).with(TrapDoorBlock.OPEN, false));
        structure.fillWithBlocks(world, start, 77, 12, 64, 77, 12, 67, Blocks.SPRUCE_TRAPDOOR.getDefaultState().with(HorizontalBlock.HORIZONTAL_FACING, Direction.NORTH).with(TrapDoorBlock.HALF, Half.BOTTOM).with(TrapDoorBlock.WATERLOGGED, false).with(TrapDoorBlock.POWERED, false).with(TrapDoorBlock.OPEN, false));
        structure.fillWithBlocks(world, start, 77, 12, 75, 77, 12, 78, Blocks.SPRUCE_TRAPDOOR.getDefaultState().with(HorizontalBlock.HORIZONTAL_FACING, Direction.SOUTH).with(TrapDoorBlock.HALF, Half.BOTTOM).with(TrapDoorBlock.WATERLOGGED, false).with(TrapDoorBlock.POWERED, false).with(TrapDoorBlock.OPEN, false));
        structure.fillWithBlocks(world, start, 77, 12, 100, 77, 13, 101, Blocks.SPRUCE_LOG.getDefaultState());
        structure.fillWithBlocks(world, start, 77, 14, 20, 78, 14, 21, Blocks.JUNGLE_SLAB.getDefaultState().with(SlabBlock.TYPE, SlabType.BOTTOM).with(SlabBlock.WATERLOGGED, false));
        structure.fillWithBlocks(world, start, 78, 5, 5, 80, 5, 7, Blocks.DIRT.getDefaultState());
        structure.fillWithBlocks(world, start, 78, 5, 103, 82, 5, 107, Blocks.DIRT.getDefaultState());
        structure.fillWithBlocks(world, start, 78, 6, 15, 78, 6, 18, Blocks.GRASS_BLOCK.getDefaultState().with(SnowyDirtBlock.SNOWY, false));
        structure.fillWithBlocks(world, start, 78, 6, 104, 78, 6, 107, Blocks.GRASS_BLOCK.getDefaultState().with(SnowyDirtBlock.SNOWY, false));
        structure.fillWithBlocks(world, start, 78, 7, 14, 79, 7, 14, Blocks.GRASS.getDefaultState());
        structure.fillWithBlocks(world, start, 78, 7, 19, 82, 7, 19, Blocks.MOSSY_COBBLESTONE_STAIRS.getDefaultState().with(StairsBlock.FACING, Direction.SOUTH).with(StairsBlock.WATERLOGGED, false).with(StairsBlock.SHAPE, StairsShape.STRAIGHT).with(StairsBlock.HALF, Half.BOTTOM));
        structure.fillWithBlocks(world, start, 78, 7, 101, 82, 7, 101, Blocks.MOSSY_COBBLESTONE_STAIRS.getDefaultState().with(StairsBlock.FACING, Direction.NORTH).with(StairsBlock.WATERLOGGED, false).with(StairsBlock.SHAPE, StairsShape.STRAIGHT).with(StairsBlock.HALF, Half.BOTTOM));
        structure.fillWithBlocks(world, start, 78, 8, 20, 79, 9, 20, Blocks.DARK_OAK_LOG.getDefaultState());
        structure.fillWithBlocks(world, start, 78, 8, 25, 80, 8, 31, Blocks.GRASS_BLOCK.getDefaultState().with(SnowyDirtBlock.SNOWY, false));
        structure.fillWithBlocks(world, start, 78, 8, 32, 78, 8, 35, Blocks.GRASS_BLOCK.getDefaultState().with(SnowyDirtBlock.SNOWY, false));
        structure.fillWithBlocks(world, start, 78, 8, 37, 78, 8, 39, Blocks.GRASS_PATH.getDefaultState());
        structure.fillWithBlocks(world, start, 78, 8, 40, 78, 8, 41, Blocks.ACACIA_SLAB.getDefaultState().with(SlabBlock.TYPE, SlabType.DOUBLE).with(SlabBlock.WATERLOGGED, false));
        structure.fillWithBlocks(world, start, 78, 8, 42, 78, 8, 44, Blocks.GRASS_PATH.getDefaultState());
        structure.fillWithBlocks(world, start, 78, 8, 46, 80, 8, 48, Blocks.GRASS_BLOCK.getDefaultState().with(SnowyDirtBlock.SNOWY, false));
        structure.fillWithBlocks(world, start, 78, 8, 49, 78, 8, 58, Blocks.GRASS_BLOCK.getDefaultState().with(SnowyDirtBlock.SNOWY, false));
        structure.fillWithBlocks(world, start, 78, 8, 62, 80, 8, 70, Blocks.GRASS_BLOCK.getDefaultState().with(SnowyDirtBlock.SNOWY, false));
        structure.fillWithBlocks(world, start, 78, 8, 71, 78, 8, 83, Blocks.GRASS_BLOCK.getDefaultState().with(SnowyDirtBlock.SNOWY, false));
        structure.fillWithBlocks(world, start, 78, 8, 84, 78, 8, 84, Blocks.GRASS_PATH.getDefaultState());
        structure.fillWithBlocks(world, start, 78, 8, 85, 78, 8, 85, Blocks.GRASS_BLOCK.getDefaultState().with(SnowyDirtBlock.SNOWY, false));
        structure.fillWithBlocks(world, start, 78, 8, 86, 78, 8, 86, Blocks.GRASS_PATH.getDefaultState());
        structure.fillWithBlocks(world, start, 78, 8, 87, 78, 8, 87, Blocks.GRASS_BLOCK.getDefaultState().with(SnowyDirtBlock.SNOWY, false));
        structure.fillWithBlocks(world, start, 78, 8, 88, 78, 8, 88, Blocks.GRASS_PATH.getDefaultState());
        structure.fillWithBlocks(world, start, 78, 8, 89, 78, 8, 89, Blocks.GRASS_BLOCK.getDefaultState().with(SnowyDirtBlock.SNOWY, false));
        structure.fillWithBlocks(world, start, 78, 8, 90, 78, 8, 90, Blocks.GRASS_PATH.getDefaultState());
        structure.fillWithBlocks(world, start, 78, 8, 91, 78, 8, 91, Blocks.GRASS_BLOCK.getDefaultState().with(SnowyDirtBlock.SNOWY, false));
        structure.fillWithBlocks(world, start, 78, 8, 92, 78, 8, 92, Blocks.GRASS_PATH.getDefaultState());
        structure.fillWithBlocks(world, start, 78, 8, 93, 78, 8, 97, Blocks.GRASS_BLOCK.getDefaultState().with(SnowyDirtBlock.SNOWY, false));
        structure.fillWithBlocks(world, start, 78, 8, 100, 79, 9, 100, Blocks.DARK_OAK_LOG.getDefaultState());
        structure.fillWithBlocks(world, start, 78, 9, 24, 78, 9, 24, Blocks.GRASS.getDefaultState());
        structure.fillWithBlocks(world, start, 78, 9, 25, 78, 11, 25, Blocks.SPRUCE_TRAPDOOR.getDefaultState().with(HorizontalBlock.HORIZONTAL_FACING, Direction.EAST).with(TrapDoorBlock.HALF, Half.BOTTOM).with(TrapDoorBlock.WATERLOGGED, false).with(TrapDoorBlock.POWERED, false).with(TrapDoorBlock.OPEN, true));
        structure.fillWithBlocks(world, start, 78, 9, 26, 78, 9, 27, Blocks.SPRUCE_TRAPDOOR.getDefaultState().with(HorizontalBlock.HORIZONTAL_FACING, Direction.EAST).with(TrapDoorBlock.HALF, Half.TOP).with(TrapDoorBlock.WATERLOGGED, false).with(TrapDoorBlock.POWERED, false).with(TrapDoorBlock.OPEN, true));
        structure.fillWithBlocks(world, start, 78, 9, 28, 78, 11, 28, Blocks.SPRUCE_TRAPDOOR.getDefaultState().with(HorizontalBlock.HORIZONTAL_FACING, Direction.EAST).with(TrapDoorBlock.HALF, Half.BOTTOM).with(TrapDoorBlock.WATERLOGGED, false).with(TrapDoorBlock.POWERED, false).with(TrapDoorBlock.OPEN, true));
        structure.fillWithBlocks(world, start, 78, 9, 29, 79, 9, 30, Blocks.GRASS.getDefaultState());
        structure.fillWithBlocks(world, start, 78, 9, 33, 78, 9, 33, Blocks.GRASS.getDefaultState());
        structure.fillWithBlocks(world, start, 78, 9, 40, 78, 9, 41, Blocks.ACACIA_SLAB.getDefaultState().with(SlabBlock.TYPE, SlabType.BOTTOM).with(SlabBlock.WATERLOGGED, false));
