package mod.arcalitegames.odyssey.world.structure.structures.towers.guard_tower;

import mod.arcalitegames.buildersaddition.Index;
import mod.arcalitegames.buildersaddition.blocks.Bench;
import mod.arcalitegames.buildersaddition.state.BenchState;
import mod.arcalitegames.odyssey.blocks.ChairBlock;
import mod.arcalitegames.odyssey.blocks.ModBlocks;
import mod.arcalitegames.odyssey.world.structure.StructureBase;
import net.minecraft.block.AbstractButtonBlock;
import net.minecraft.block.Blocks;
import net.minecraft.block.CakeBlock;
import net.minecraft.block.CauldronBlock;
import net.minecraft.block.DoorBlock;
import net.minecraft.block.FenceGateBlock;
import net.minecraft.block.FourWayBlock;
import net.minecraft.block.HorizontalBlock;
import net.minecraft.block.HorizontalFaceBlock;
import net.minecraft.block.LadderBlock;
import net.minecraft.block.LeavesBlock;
import net.minecraft.block.LecternBlock;
import net.minecraft.block.SlabBlock;
import net.minecraft.block.SnowyDirtBlock;
import net.minecraft.block.StairsBlock;
import net.minecraft.block.TrapDoorBlock;
import net.minecraft.block.WallTorchBlock;
import net.minecraft.state.properties.AttachFace;
import net.minecraft.state.properties.DoorHingeSide;
import net.minecraft.state.properties.DoubleBlockHalf;
import net.minecraft.state.properties.Half;
import net.minecraft.state.properties.SlabType;
import net.minecraft.state.properties.StairsShape;
import net.minecraft.util.Direction;
import net.minecraft.util.math.BlockPos;
import net.minecraft.world.World;

public class GuardTowerComponents
{

	public static BlockPos start;
    public static World world;
    public static StructureBase structure;

    public static void init(World worldIn, BlockPos blockPos, StructureBase structureIn)
    {
        world = worldIn; start = blockPos; structure = structureIn;
    }
    
    public static void generatePart1()
    {
        structure.setBlockState(world, Blocks.GRASS_BLOCK.getDefaultState().with(SnowyDirtBlock.SNOWY, false), 4, 2, 7, start);
        structure.setBlockState(world, Blocks.GRASS_BLOCK.getDefaultState().with(SnowyDirtBlock.SNOWY, false), 4, 3, 8, start);
        structure.setBlockState(world, Blocks.GRASS.getDefaultState(), 4, 5, 10, start);
        structure.setBlockState(world, Blocks.OAK_LEAVES.getDefaultState().with(LeavesBlock.PERSISTENT, false).with(LeavesBlock.DISTANCE, 3), 4, 8, 9, start);
        structure.setBlockState(world, Blocks.DIRT.getDefaultState(), 5, 2, 14, start);
        structure.setBlockState(world, Blocks.GRASS_BLOCK.getDefaultState().with(SnowyDirtBlock.SNOWY, false), 5, 3, 7, start);
        structure.setBlockState(world, Blocks.GRASS_BLOCK.getDefaultState().with(SnowyDirtBlock.SNOWY, false), 5, 4, 8, start);
        structure.setBlockState(world, Blocks.OAK_LEAVES.getDefaultState().with(LeavesBlock.PERSISTENT, false).with(LeavesBlock.DISTANCE, 2), 5, 11, 10, start);
        structure.setBlockState(world, Blocks.GRASS_BLOCK.getDefaultState().with(SnowyDirtBlock.SNOWY, false), 6, 2, 5, start);
        structure.setBlockState(world, Blocks.DIRT.getDefaultState(), 6, 2, 6, start);
        structure.setBlockState(world, Blocks.DIRT.getDefaultState(), 6, 2, 16, start);
        structure.setBlockState(world, Blocks.GRASS_BLOCK.getDefaultState().with(SnowyDirtBlock.SNOWY, false), 6, 3, 6, start);
        structure.setBlockState(world, Blocks.GRASS_BLOCK.getDefaultState().with(SnowyDirtBlock.SNOWY, false), 6, 4, 13, start);
        structure.setBlockState(world, Blocks.GRASS.getDefaultState(), 6, 6, 8, start);
        structure.setBlockState(world, Blocks.DIRT.getDefaultState(), 7, 2, 5, start);
        structure.setBlockState(world, Blocks.GRASS_BLOCK.getDefaultState().with(SnowyDirtBlock.SNOWY, false), 7, 3, 5, start);
        structure.setBlockState(world, Blocks.GRASS.getDefaultState(), 7, 4, 17, start);
        structure.setBlockState(world, Index.BENCH_OAK.getDefaultState().with(Bench.STATE, BenchState.SOUTH), 7, 6, 9, start);
        structure.setBlockState(world, Index.BENCH_OAK.getDefaultState().with(Bench.STATE, BenchState.NORTH), 7, 6, 10, start);
        structure.setBlockState(world, Blocks.GRASS.getDefaultState(), 7, 6, 12, start);
        structure.setBlockState(world, Blocks.OAK_LEAVES.getDefaultState().with(LeavesBlock.PERSISTENT, false).with(LeavesBlock.DISTANCE, 3), 7, 9, 12, start);
        structure.setBlockState(world, Blocks.GRASS_BLOCK.getDefaultState().with(SnowyDirtBlock.SNOWY, false), 8, 2, 3, start);
        structure.setBlockState(world, Blocks.GRASS_BLOCK.getDefaultState().with(SnowyDirtBlock.SNOWY, false), 8, 3, 4, start);
        structure.setBlockState(world, Blocks.GRASS_BLOCK.getDefaultState().with(SnowyDirtBlock.SNOWY, false), 8, 3, 18, start);
        structure.setBlockState(world, Blocks.GRAVEL.getDefaultState(), 8, 4, 14, start);
        structure.setBlockState(world, Blocks.COBBLESTONE_SLAB.getDefaultState().with(SlabBlock.TYPE, SlabType.DOUBLE).with(SlabBlock.WATERLOGGED, false), 8, 4, 15, start);
        structure.setBlockState(world, Blocks.COBBLESTONE_SLAB.getDefaultState().with(SlabBlock.TYPE, SlabType.BOTTOM).with(SlabBlock.WATERLOGGED, false), 8, 4, 16, start);
        structure.setBlockState(world, Blocks.GRASS.getDefaultState(), 8, 5, 6, start);
        structure.setBlockState(world, Blocks.GRASS_BLOCK.getDefaultState().with(SnowyDirtBlock.SNOWY, false), 8, 5, 9, start);
        structure.setBlockState(world, Blocks.SMOOTH_STONE_SLAB.getDefaultState().with(SlabBlock.TYPE, SlabType.DOUBLE).with(SlabBlock.WATERLOGGED, false), 8, 5, 10, start);
        structure.setBlockState(world, Blocks.GRAVEL.getDefaultState(), 8, 5, 11, start);
        structure.setBlockState(world, Blocks.SMOOTH_STONE_SLAB.getDefaultState().with(SlabBlock.TYPE, SlabType.DOUBLE).with(SlabBlock.WATERLOGGED, false), 8, 5, 12, start);
        structure.setBlockState(world, Blocks.COBBLESTONE_SLAB.getDefaultState().with(SlabBlock.TYPE, SlabType.BOTTOM).with(SlabBlock.WATERLOGGED, false), 8, 5, 13, start);
        structure.setBlockState(world, Blocks.OAK_LEAVES.getDefaultState().with(LeavesBlock.PERSISTENT, false).with(LeavesBlock.DISTANCE, 4), 8, 9, 8, start);
        structure.setBlockState(world, Blocks.GRASS_BLOCK.getDefaultState().with(SnowyDirtBlock.SNOWY, false), 9, 3, 3, start);
        structure.setBlockState(world, Blocks.GRASS_BLOCK.getDefaultState().with(SnowyDirtBlock.SNOWY, false), 9, 4, 4, start);
        structure.setBlockState(world, Blocks.GRASS_BLOCK.getDefaultState().with(SnowyDirtBlock.SNOWY, false), 9, 5, 8, start);
        structure.setBlockState(world, Blocks.COBBLESTONE_SLAB.getDefaultState().with(SlabBlock.TYPE, SlabType.DOUBLE).with(SlabBlock.WATERLOGGED, false), 9, 5, 11, start);
        structure.setBlockState(world, Blocks.GRAVEL.getDefaultState(), 9, 5, 13, start);
        structure.setBlockState(world, Blocks.GRASS.getDefaultState(), 9, 5, 16, start);
        structure.setBlockState(world, Blocks.AIR.getDefaultState(), 9, 6, 11, start);
        structure.setBlockState(world, Blocks.STONE_BUTTON.getDefaultState().with(HorizontalBlock.HORIZONTAL_FACING, Direction.WEST).with(HorizontalFaceBlock.FACE, AttachFace.WALL).with(AbstractButtonBlock.POWERED, false), 9, 18, 10, start);
        structure.setBlockState(world, Blocks.STONE_BUTTON.getDefaultState().with(HorizontalBlock.HORIZONTAL_FACING, Direction.WEST).with(HorizontalFaceBlock.FACE, AttachFace.WALL).with(AbstractButtonBlock.POWERED, false), 9, 18, 12, start);
        structure.setBlockState(world, Blocks.OAK_TRAPDOOR.getDefaultState().with(HorizontalBlock.HORIZONTAL_FACING, Direction.WEST).with(TrapDoorBlock.HALF, Half.BOTTOM).with(TrapDoorBlock.WATERLOGGED, false).with(TrapDoorBlock.POWERED, false).with(TrapDoorBlock.OPEN, false), 9, 21, 10, start);
        structure.setBlockState(world, Blocks.OAK_TRAPDOOR.getDefaultState().with(HorizontalBlock.HORIZONTAL_FACING, Direction.WEST).with(TrapDoorBlock.HALF, Half.BOTTOM).with(TrapDoorBlock.WATERLOGGED, false).with(TrapDoorBlock.POWERED, false).with(TrapDoorBlock.OPEN, false), 9, 21, 12, start);
        structure.setBlockState(world, Blocks.GRAVEL.getDefaultState(), 10, 3, 18, start);
        structure.setBlockState(world, Blocks.COBBLESTONE_SLAB.getDefaultState().with(SlabBlock.TYPE, SlabType.DOUBLE).with(SlabBlock.WATERLOGGED, false), 10, 5, 7, start);
        structure.setBlockState(world, Blocks.GRAVEL.getDefaultState(), 10, 5, 8, start);
        structure.setBlockState(world, Blocks.GRAVEL.getDefaultState(), 10, 5, 11, start);
        structure.setBlockState(world, Blocks.OAK_FENCE.getDefaultState().with(FourWayBlock.WATERLOGGED, false).with(FourWayBlock.NORTH, false).with(FourWayBlock.SOUTH, false).with(FourWayBlock.EAST, true).with(FourWayBlock.WEST, false), 10, 17, 10, start);
        structure.setBlockState(world, Blocks.OAK_FENCE.getDefaultState().with(FourWayBlock.WATERLOGGED, false).with(FourWayBlock.NORTH, false).with(FourWayBlock.SOUTH, false).with(FourWayBlock.EAST, true).with(FourWayBlock.WEST, false), 10, 17, 12, start);
        structure.setBlockState(world, Blocks.OAK_STAIRS.getDefaultState().with(StairsBlock.FACING, Direction.EAST).with(StairsBlock.WATERLOGGED, false).with(StairsBlock.SHAPE, StairsShape.STRAIGHT).with(StairsBlock.HALF, Half.TOP), 10, 18, 9, start);
        structure.setBlockState(world, Blocks.OAK_STAIRS.getDefaultState().with(StairsBlock.FACING, Direction.EAST).with(StairsBlock.WATERLOGGED, false).with(StairsBlock.SHAPE, StairsShape.STRAIGHT).with(StairsBlock.HALF, Half.TOP), 10, 18, 13, start);
        structure.setBlockState(world, Blocks.OAK_PLANKS.getDefaultState(), 10, 19, 10, start);
        structure.setBlockState(world, Blocks.OAK_PLANKS.getDefaultState(), 10, 19, 12, start);
        structure.setBlockState(world, Blocks.OAK_PLANKS.getDefaultState(), 10, 21, 10, start);
        structure.setBlockState(world, Blocks.NETHER_BRICK_STAIRS.getDefaultState().with(StairsBlock.FACING, Direction.EAST).with(StairsBlock.WATERLOGGED, false).with(StairsBlock.SHAPE, StairsShape.STRAIGHT).with(StairsBlock.HALF, Half.TOP), 10, 31, 11, start);
        structure.setBlockState(world, Blocks.STONE.getDefaultState(), 11, 3, 18, start);
        structure.setBlockState(world, Blocks.STONE.getDefaultState(), 11, 4, 17, start);
        structure.setBlockState(world, Blocks.GRASS_BLOCK.getDefaultState().with(SnowyDirtBlock.SNOWY, false), 11, 4, 18, start);
        structure.setBlockState(world, Blocks.DANDELION.getDefaultState(), 11, 5, 3, start);
        structure.setBlockState(world, Blocks.SMOOTH_STONE_SLAB.getDefaultState().with(SlabBlock.TYPE, SlabType.DOUBLE).with(SlabBlock.WATERLOGGED, false), 11, 5, 8, start);
        structure.setBlockState(world, Blocks.GRASS_BLOCK.getDefaultState().with(SnowyDirtBlock.SNOWY, false), 11, 5, 10, start);
        structure.setBlockState(world, Blocks.GRASS_BLOCK.getDefaultState().with(SnowyDirtBlock.SNOWY, false), 11, 5, 12, start);
        structure.setBlockState(world, Blocks.DANDELION.getDefaultState(), 11, 6, 4, start);
        structure.setBlockState(world, Blocks.STONE_BRICK_STAIRS.getDefaultState().with(StairsBlock.FACING, Direction.EAST).with(StairsBlock.WATERLOGGED, false).with(StairsBlock.SHAPE, StairsShape.STRAIGHT).with(StairsBlock.HALF, Half.BOTTOM), 11, 6, 9, start);
        structure.setBlockState(world, Blocks.AIR.getDefaultState(), 11, 6, 10, start);
        structure.setBlockState(world, Blocks.CRAFTING_TABLE.getDefaultState(), 11, 6, 11, start);
        structure.setBlockState(world, Blocks.CAULDRON.getDefaultState().with(CauldronBlock.LEVEL, 0), 11, 6, 12, start);
        structure.setBlockState(world, Blocks.STONE_BRICK_STAIRS.getDefaultState().with(StairsBlock.FACING, Direction.EAST).with(StairsBlock.WATERLOGGED, false).with(StairsBlock.SHAPE, StairsShape.STRAIGHT).with(StairsBlock.HALF, Half.BOTTOM), 11, 6, 13, start);
        structure.setBlockState(world, Blocks.GRASS.getDefaultState(), 11, 6, 17, start);
        structure.setBlockState(world, Blocks.WALL_TORCH.getDefaultState().with(WallTorchBlock.HORIZONTAL_FACING, Direction.WEST), 11, 11, 11, start);
        structure.setBlockState(world, Blocks.OAK_FENCE_GATE.getDefaultState().with(FenceGateBlock.IN_WALL, false).with(FenceGateBlock.OPEN, false).with(FenceGateBlock.POWERED, false), 11, 16, 10, start);
        structure.setBlockState(world, Blocks.OAK_FENCE_GATE.getDefaultState().with(FenceGateBlock.IN_WALL, false).with(FenceGateBlock.OPEN, false).with(FenceGateBlock.POWERED, false), 11, 16, 12, start);
        structure.setBlockState(world, Blocks.OAK_FENCE.getDefaultState().with(FourWayBlock.WATERLOGGED, false).with(FourWayBlock.NORTH, false).with(FourWayBlock.SOUTH, false).with(FourWayBlock.EAST, false).with(FourWayBlock.WEST, true), 11, 17, 10, start);
        structure.setBlockState(world, Blocks.OAK_FENCE.getDefaultState().with(FourWayBlock.WATERLOGGED, false).with(FourWayBlock.NORTH, false).with(FourWayBlock.SOUTH, false).with(FourWayBlock.EAST, false).with(FourWayBlock.WEST, true), 11, 17, 12, start);
        structure.setBlockState(world, Blocks.SPRUCE_PLANKS.getDefaultState(), 11, 18, 9, start);
        structure.setBlockState(world, Blocks.OAK_STAIRS.getDefaultState().with(StairsBlock.FACING, Direction.EAST).with(StairsBlock.WATERLOGGED, false).with(StairsBlock.SHAPE, StairsShape.STRAIGHT).with(StairsBlock.HALF, Half.BOTTOM), 11, 19, 9, start);
        structure.setBlockState(world, Blocks.OAK_STAIRS.getDefaultState().with(StairsBlock.FACING, Direction.EAST).with(StairsBlock.WATERLOGGED, false).with(StairsBlock.SHAPE, StairsShape.STRAIGHT).with(StairsBlock.HALF, Half.BOTTOM), 11, 19, 13, start);
        structure.setBlockState(world, Blocks.OAK_STAIRS.getDefaultState().with(StairsBlock.FACING, Direction.EAST).with(StairsBlock.WATERLOGGED, false).with(StairsBlock.SHAPE, StairsShape.STRAIGHT).with(StairsBlock.HALF, Half.TOP), 11, 20, 9, start);
        structure.setBlockState(world, Blocks.OAK_STAIRS.getDefaultState().with(StairsBlock.FACING, Direction.EAST).with(StairsBlock.WATERLOGGED, false).with(StairsBlock.SHAPE, StairsShape.STRAIGHT).with(StairsBlock.HALF, Half.TOP), 11, 20, 13, start);
        structure.setBlockState(world, Blocks.OAK_PLANKS.getDefaultState(), 11, 21, 9, start);
        structure.setBlockState(world, Blocks.SPRUCE_PLANKS.getDefaultState(), 11, 22, 9, start);
        structure.setBlockState(world, Blocks.WALL_TORCH.getDefaultState().with(WallTorchBlock.HORIZONTAL_FACING, Direction.EAST), 11, 22, 11, start);
        structure.setBlockState(world, Blocks.STONE_BRICKS.getDefaultState(), 11, 23, 8, start);
        structure.setBlockState(world, Blocks.OAK_PLANKS.getDefaultState(), 11, 23, 9, start);
        structure.setBlockState(world, Blocks.STONE_BUTTON.getDefaultState().with(HorizontalBlock.HORIZONTAL_FACING, Direction.WEST).with(HorizontalFaceBlock.FACE, AttachFace.WALL).with(AbstractButtonBlock.POWERED, false), 11, 25, 9, start);
        structure.setBlockState(world, Blocks.STONE_BUTTON.getDefaultState().with(HorizontalBlock.HORIZONTAL_FACING, Direction.WEST).with(HorizontalFaceBlock.FACE, AttachFace.WALL).with(AbstractButtonBlock.POWERED, false), 11, 25, 11, start);
        structure.setBlockState(world, Blocks.STONE_BUTTON.getDefaultState().with(HorizontalBlock.HORIZONTAL_FACING, Direction.WEST).with(HorizontalFaceBlock.FACE, AttachFace.WALL).with(AbstractButtonBlock.POWERED, false), 11, 25, 13, start);
        structure.setBlockState(world, Blocks.STONE_BUTTON.getDefaultState().with(HorizontalBlock.HORIZONTAL_FACING, Direction.WEST).with(HorizontalFaceBlock.FACE, AttachFace.WALL).with(AbstractButtonBlock.POWERED, false), 11, 27, 9, start);
        structure.setBlockState(world, Blocks.STONE_BUTTON.getDefaultState().with(HorizontalBlock.HORIZONTAL_FACING, Direction.WEST).with(HorizontalFaceBlock.FACE, AttachFace.WALL).with(AbstractButtonBlock.POWERED, false), 11, 27, 11, start);
        structure.setBlockState(world, Blocks.STONE_BUTTON.getDefaultState().with(HorizontalBlock.HORIZONTAL_FACING, Direction.WEST).with(HorizontalFaceBlock.FACE, AttachFace.WALL).with(AbstractButtonBlock.POWERED, false), 11, 27, 13, start);
        structure.setBlockState(world, Blocks.GRASS_BLOCK.getDefaultState().with(SnowyDirtBlock.SNOWY, false), 12, 3, 18, start);
        structure.setBlockState(world, Blocks.GRASS_BLOCK.getDefaultState().with(SnowyDirtBlock.SNOWY, false), 12, 4, 17, start);
        structure.setBlockState(world, Blocks.GRASS.getDefaultState(), 12, 5, 3, start);
        structure.setBlockState(world, Blocks.GRAVEL.getDefaultState(), 12, 5, 5, start);
        structure.setBlockState(world, Blocks.GRASS_BLOCK.getDefaultState().with(SnowyDirtBlock.SNOWY, false), 12, 5, 6, start);
        structure.setBlockState(world, Blocks.GRASS.getDefaultState(), 12, 5, 17, start);
        structure.setBlockState(world, Blocks.AIR.getDefaultState(), 12, 6, 6, start);
        structure.setBlockState(world, Blocks.COBBLESTONE.getDefaultState(), 12, 6, 12, start);
        structure.setBlockState(world, Blocks.STONE_BRICKS.getDefaultState(), 12, 6, 13, start);
        structure.setBlockState(world, Blocks.STONE_BRICK_STAIRS.getDefaultState().with(StairsBlock.FACING, Direction.NORTH).with(StairsBlock.WATERLOGGED, false).with(StairsBlock.SHAPE, StairsShape.STRAIGHT).with(StairsBlock.HALF, Half.BOTTOM), 12, 6, 14, start);
        structure.setBlockState(world, Blocks.MOSSY_STONE_BRICKS.getDefaultState(), 12, 7, 13, start);
        structure.setBlockState(world, Blocks.SMOOTH_STONE_SLAB.getDefaultState().with(SlabBlock.TYPE, SlabType.DOUBLE).with(SlabBlock.WATERLOGGED, false), 12, 8, 11, start);
        structure.setBlockState(world, Blocks.IRON_BARS.getDefaultState().with(FourWayBlock.WATERLOGGED, false).with(FourWayBlock.NORTH, false).with(FourWayBlock.SOUTH, false).with(FourWayBlock.EAST, false).with(FourWayBlock.WEST, false), 12, 9, 11, start);
        structure.setBlockState(world, Blocks.SMOOTH_STONE_SLAB.getDefaultState().with(SlabBlock.TYPE, SlabType.DOUBLE).with(SlabBlock.WATERLOGGED, false), 12, 11, 11, start);
        structure.setBlockState(world, Blocks.SMOOTH_STONE_SLAB.getDefaultState().with(SlabBlock.TYPE, SlabType.DOUBLE).with(SlabBlock.WATERLOGGED, false), 12, 14, 11, start);
        structure.setBlockState(world, Blocks.IRON_BARS.getDefaultState().with(FourWayBlock.WATERLOGGED, false).with(FourWayBlock.NORTH, false).with(FourWayBlock.SOUTH, true).with(FourWayBlock.EAST, false).with(FourWayBlock.WEST, false), 12, 15, 11, start);
        structure.setBlockState(world, Blocks.SMOOTH_STONE_SLAB.getDefaultState().with(SlabBlock.TYPE, SlabType.DOUBLE).with(SlabBlock.WATERLOGGED, false), 12, 17, 11, start);
        structure.setBlockState(world, Blocks.OAK_STAIRS.getDefaultState().with(StairsBlock.FACING, Direction.SOUTH).with(StairsBlock.WATERLOGGED, false).with(StairsBlock.SHAPE, StairsShape.STRAIGHT).with(StairsBlock.HALF, Half.TOP), 12, 18, 7, start);
        structure.setBlockState(world, Blocks.SPRUCE_PLANKS.getDefaultState(), 12, 18, 8, start);
        structure.setBlockState(world, Blocks.OAK_STAIRS.getDefaultState().with(StairsBlock.FACING, Direction.NORTH).with(StairsBlock.WATERLOGGED, false).with(StairsBlock.SHAPE, StairsShape.STRAIGHT).with(StairsBlock.HALF, Half.TOP), 12, 18, 15, start);
        structure.setBlockState(world, Blocks.OAK_STAIRS.getDefaultState().with(StairsBlock.FACING, Direction.SOUTH).with(StairsBlock.WATERLOGGED, false).with(StairsBlock.SHAPE, StairsShape.STRAIGHT).with(StairsBlock.HALF, Half.BOTTOM), 12, 19, 8, start);
        structure.setBlockState(world, Blocks.OAK_STAIRS.getDefaultState().with(StairsBlock.FACING, Direction.NORTH).with(StairsBlock.WATERLOGGED, false).with(StairsBlock.SHAPE, StairsShape.STRAIGHT).with(StairsBlock.HALF, Half.BOTTOM), 12, 19, 14, start);
        structure.setBlockState(world, Blocks.OAK_STAIRS.getDefaultState().with(StairsBlock.FACING, Direction.SOUTH).with(StairsBlock.WATERLOGGED, false).with(StairsBlock.SHAPE, StairsShape.STRAIGHT).with(StairsBlock.HALF, Half.TOP), 12, 20, 8, start);
        structure.setBlockState(world, Blocks.OAK_STAIRS.getDefaultState().with(StairsBlock.FACING, Direction.NORTH).with(StairsBlock.WATERLOGGED, false).with(StairsBlock.SHAPE, StairsShape.STRAIGHT).with(StairsBlock.HALF, Half.TOP), 12, 20, 14, start);
        structure.setBlockState(world, Blocks.OAK_PLANKS.getDefaultState(), 12, 21, 8, start);
        structure.setBlockState(world, Blocks.SPRUCE_PLANKS.getDefaultState(), 12, 22, 8, start);
        structure.setBlockState(world, Blocks.OAK_PLANKS.getDefaultState(), 12, 23, 8, start);
        structure.setBlockState(world, Blocks.OAK_FENCE.getDefaultState().with(FourWayBlock.WATERLOGGED, false).with(FourWayBlock.NORTH, true).with(FourWayBlock.SOUTH, false).with(FourWayBlock.EAST, false).with(FourWayBlock.WEST, true), 12, 23, 9, start);
        structure.setBlockState(world, Blocks.OAK_FENCE.getDefaultState().with(FourWayBlock.WATERLOGGED, false).with(FourWayBlock.NORTH, false).with(FourWayBlock.SOUTH, false).with(FourWayBlock.EAST, false).with(FourWayBlock.WEST, false), 12, 23, 13, start);
        structure.setBlockState(world, Blocks.OAK_PLANKS.getDefaultState(), 12, 23, 14, start);
        structure.setBlockState(world, Blocks.OAK_STAIRS.getDefaultState().with(StairsBlock.FACING, Direction.WEST).with(StairsBlock.WATERLOGGED, false).with(StairsBlock.SHAPE, StairsShape.STRAIGHT).with(StairsBlock.HALF, Half.TOP), 12, 24, 10, start);
        structure.setBlockState(world, Blocks.OAK_STAIRS.getDefaultState().with(StairsBlock.FACING, Direction.WEST).with(StairsBlock.WATERLOGGED, false).with(StairsBlock.SHAPE, StairsShape.STRAIGHT).with(StairsBlock.HALF, Half.TOP), 12, 24, 12, start);
        structure.setBlockState(world, Blocks.STONE_BUTTON.getDefaultState().with(HorizontalBlock.HORIZONTAL_FACING, Direction.NORTH).with(HorizontalFaceBlock.FACE, AttachFace.WALL).with(AbstractButtonBlock.POWERED, false), 12, 25, 8, start);
        structure.setBlockState(world, Blocks.OAK_STAIRS.getDefaultState().with(StairsBlock.FACING, Direction.WEST).with(StairsBlock.WATERLOGGED, false).with(StairsBlock.SHAPE, StairsShape.STRAIGHT).with(StairsBlock.HALF, Half.BOTTOM), 12, 25, 10, start);
        structure.setBlockState(world, Blocks.OAK_STAIRS.getDefaultState().with(StairsBlock.FACING, Direction.WEST).with(StairsBlock.WATERLOGGED, false).with(StairsBlock.SHAPE, StairsShape.STRAIGHT).with(StairsBlock.HALF, Half.BOTTOM), 12, 25, 12, start);
        structure.setBlockState(world, Blocks.STONE_BUTTON.getDefaultState().with(HorizontalBlock.HORIZONTAL_FACING, Direction.SOUTH).with(HorizontalFaceBlock.FACE, AttachFace.WALL).with(AbstractButtonBlock.POWERED, false), 12, 25, 14, start);
        structure.setBlockState(world, Blocks.GLASS_PANE.getDefaultState().with(FourWayBlock.WATERLOGGED, false).with(FourWayBlock.NORTH, true).with(FourWayBlock.SOUTH, true).with(FourWayBlock.EAST, false).with(FourWayBlock.WEST, false), 12, 26, 10, start);
        structure.setBlockState(world, Blocks.GLASS_PANE.getDefaultState().with(FourWayBlock.WATERLOGGED, false).with(FourWayBlock.NORTH, true).with(FourWayBlock.SOUTH, true).with(FourWayBlock.EAST, false).with(FourWayBlock.WEST, false), 12, 26, 12, start);
        structure.setBlockState(world, Blocks.STONE_BUTTON.getDefaultState().with(HorizontalBlock.HORIZONTAL_FACING, Direction.NORTH).with(HorizontalFaceBlock.FACE, AttachFace.WALL).with(AbstractButtonBlock.POWERED, false), 12, 27, 8, start);
        structure.setBlockState(world, Blocks.OAK_STAIRS.getDefaultState().with(StairsBlock.FACING, Direction.WEST).with(StairsBlock.WATERLOGGED, false).with(StairsBlock.SHAPE, StairsShape.STRAIGHT).with(StairsBlock.HALF, Half.TOP), 12, 27, 10, start);
        structure.setBlockState(world, Blocks.OAK_STAIRS.getDefaultState().with(StairsBlock.FACING, Direction.WEST).with(StairsBlock.WATERLOGGED, false).with(StairsBlock.SHAPE, StairsShape.STRAIGHT).with(StairsBlock.HALF, Half.TOP), 12, 27, 12, start);
        structure.setBlockState(world, Blocks.STONE_BUTTON.getDefaultState().with(HorizontalBlock.HORIZONTAL_FACING, Direction.SOUTH).with(HorizontalFaceBlock.FACE, AttachFace.WALL).with(AbstractButtonBlock.POWERED, false), 12, 27, 14, start);
        structure.setBlockState(world, Blocks.OAK_STAIRS.getDefaultState().with(StairsBlock.FACING, Direction.EAST).with(StairsBlock.WATERLOGGED, false).with(StairsBlock.SHAPE, StairsShape.STRAIGHT).with(StairsBlock.HALF, Half.BOTTOM), 12, 29, 11, start);
        structure.setBlockState(world, Blocks.GLOWSTONE.getDefaultState(), 12, 30, 11, start);
        structure.setBlockState(world, Blocks.GRASS_BLOCK.getDefaultState().with(SnowyDirtBlock.SNOWY, false), 13, 3, 17, start);
        structure.setBlockState(world, Blocks.GRASS_BLOCK.getDefaultState().with(SnowyDirtBlock.SNOWY, false), 13, 4, 4, start);
        structure.setBlockState(world, Blocks.COBBLESTONE_SLAB.getDefaultState().with(SlabBlock.TYPE, SlabType.DOUBLE).with(SlabBlock.WATERLOGGED, false), 13, 5, 6, start);
        structure.setBlockState(world, Blocks.DIRT.getDefaultState(), 13, 5, 9, start);
        structure.setBlockState(world, Blocks.MOSSY_COBBLESTONE.getDefaultState(), 13, 6, 9, start);
        structure.setBlockState(world, Blocks.CAULDRON.getDefaultState().with(CauldronBlock.LEVEL, 0), 13, 6, 10, start);
        structure.setBlockState(world, Blocks.MOSSY_COBBLESTONE.getDefaultState(), 13, 6, 13, start);
        structure.setBlockState(world, Blocks.MAGENTA_WOOL.getDefaultState(), 13, 7, 12, start);
        structure.setBlockState(world, Blocks.SMOOTH_STONE_SLAB.getDefaultState().with(SlabBlock.TYPE, SlabType.BOTTOM).with(SlabBlock.WATERLOGGED, false), 13, 9, 11, start);
        structure.setBlockState(world, Blocks.SMOOTH_STONE_SLAB.getDefaultState().with(SlabBlock.TYPE, SlabType.DOUBLE).with(SlabBlock.WATERLOGGED, false), 13, 9, 12, start);
        structure.setBlockState(world, Blocks.WALL_TORCH.getDefaultState().with(WallTorchBlock.HORIZONTAL_FACING, Direction.EAST), 13, 11, 11, start);
        structure.setBlockState(world, Blocks.OAK_TRAPDOOR.getDefaultState().with(HorizontalBlock.HORIZONTAL_FACING, Direction.SOUTH).with(TrapDoorBlock.HALF, Half.BOTTOM).with(TrapDoorBlock.WATERLOGGED, false).with(TrapDoorBlock.POWERED, true).with(TrapDoorBlock.OPEN, true), 13, 15, 10, start);
        structure.setBlockState(world, Blocks.AIR.getDefaultState(), 13, 15, 12, start);
        structure.setBlockState(world, Blocks.OAK_FENCE_GATE.getDefaultState().with(FenceGateBlock.IN_WALL, false).with(FenceGateBlock.OPEN, false).with(FenceGateBlock.POWERED, false), 13, 16, 8, start);
        structure.setBlockState(world, Blocks.OAK_FENCE_GATE.getDefaultState().with(FenceGateBlock.IN_WALL, false).with(FenceGateBlock.OPEN, false).with(FenceGateBlock.POWERED, false), 13, 16, 14, start);
        structure.setBlockState(world, Blocks.OAK_FENCE.getDefaultState().with(FourWayBlock.WATERLOGGED, false).with(FourWayBlock.NORTH, false).with(FourWayBlock.SOUTH, true).with(FourWayBlock.EAST, false).with(FourWayBlock.WEST, false), 13, 17, 7, start);
        structure.setBlockState(world, Blocks.OAK_FENCE.getDefaultState().with(FourWayBlock.WATERLOGGED, false).with(FourWayBlock.NORTH, true).with(FourWayBlock.SOUTH, false).with(FourWayBlock.EAST, false).with(FourWayBlock.WEST, false), 13, 17, 8, start);
        structure.setBlockState(world, Blocks.OAK_FENCE.getDefaultState().with(FourWayBlock.WATERLOGGED, false).with(FourWayBlock.NORTH, false).with(FourWayBlock.SOUTH, true).with(FourWayBlock.EAST, false).with(FourWayBlock.WEST, false), 13, 17, 14, start);
        structure.setBlockState(world, Blocks.OAK_FENCE.getDefaultState().with(FourWayBlock.WATERLOGGED, false).with(FourWayBlock.NORTH, true).with(FourWayBlock.SOUTH, false).with(FourWayBlock.EAST, false).with(FourWayBlock.WEST, false), 13, 17, 15, start);
        structure.setBlockState(world, Blocks.STONE_BUTTON.getDefaultState().with(HorizontalBlock.HORIZONTAL_FACING, Direction.NORTH).with(HorizontalFaceBlock.FACE, AttachFace.WALL).with(AbstractButtonBlock.POWERED, false), 13, 18, 6, start);
        structure.setBlockState(world, Blocks.STONE_BUTTON.getDefaultState().with(HorizontalBlock.HORIZONTAL_FACING, Direction.SOUTH).with(HorizontalFaceBlock.FACE, AttachFace.WALL).with(AbstractButtonBlock.POWERED, false), 13, 18, 16, start);
        structure.setBlockState(world, Blocks.OAK_PLANKS.getDefaultState(), 13, 19, 7, start);
        structure.setBlockState(world, Blocks.OAK_PLANKS.getDefaultState(), 13, 19, 15, start);
        structure.setBlockState(world, Blocks.OAK_TRAPDOOR.getDefaultState().with(HorizontalBlock.HORIZONTAL_FACING, Direction.NORTH).with(TrapDoorBlock.HALF, Half.BOTTOM).with(TrapDoorBlock.WATERLOGGED, false).with(TrapDoorBlock.POWERED, false).with(TrapDoorBlock.OPEN, false), 13, 21, 6, start);
        structure.setBlockState(world, Blocks.OAK_PLANKS.getDefaultState(), 13, 21, 7, start);
        structure.setBlockState(world, Blocks.OAK_PLANKS.getDefaultState(), 13, 21, 15, start);
        structure.setBlockState(world, Blocks.OAK_TRAPDOOR.getDefaultState().with(HorizontalBlock.HORIZONTAL_FACING, Direction.SOUTH).with(TrapDoorBlock.HALF, Half.BOTTOM).with(TrapDoorBlock.WATERLOGGED, false).with(TrapDoorBlock.POWERED, false).with(TrapDoorBlock.OPEN, false), 13, 21, 16, start);
        structure.setBlockState(world, Blocks.OAK_STAIRS.getDefaultState().with(StairsBlock.FACING, Direction.NORTH).with(StairsBlock.WATERLOGGED, false).with(StairsBlock.SHAPE, StairsShape.STRAIGHT).with(StairsBlock.HALF, Half.BOTTOM), 13, 25, 9, start);
        structure.setBlockState(world, Blocks.OAK_STAIRS.getDefaultState().with(StairsBlock.FACING, Direction.SOUTH).with(StairsBlock.WATERLOGGED, false).with(StairsBlock.SHAPE, StairsShape.STRAIGHT).with(StairsBlock.HALF, Half.BOTTOM), 13, 25, 13, start);
        structure.setBlockState(world, Blocks.GLASS_PANE.getDefaultState().with(FourWayBlock.WATERLOGGED, false).with(FourWayBlock.NORTH, false).with(FourWayBlock.SOUTH, false).with(FourWayBlock.EAST, true).with(FourWayBlock.WEST, true), 13, 26, 9, start);
        structure.setBlockState(world, Blocks.GLASS_PANE.getDefaultState().with(FourWayBlock.WATERLOGGED, false).with(FourWayBlock.NORTH, false).with(FourWayBlock.SOUTH, false).with(FourWayBlock.EAST, true).with(FourWayBlock.WEST, true), 13, 26, 13, start);
        structure.setBlockState(world, Blocks.OAK_STAIRS.getDefaultState().with(StairsBlock.FACING, Direction.NORTH).with(StairsBlock.WATERLOGGED, false).with(StairsBlock.SHAPE, StairsShape.STRAIGHT).with(StairsBlock.HALF, Half.TOP), 13, 27, 9, start);
        structure.setBlockState(world, Blocks.OAK_STAIRS.getDefaultState().with(StairsBlock.FACING, Direction.SOUTH).with(StairsBlock.WATERLOGGED, false).with(StairsBlock.SHAPE, StairsShape.STRAIGHT).with(StairsBlock.HALF, Half.TOP), 13, 27, 13, start);
        structure.setBlockState(world, Blocks.STONE_BRICKS.getDefaultState(), 13, 30, 14, start);
        structure.setBlockState(world, Blocks.GRAVEL.getDefaultState(), 14, 5, 7, start);
        structure.setBlockState(world, Blocks.GRASS.getDefaultState(), 14, 5, 17, start);
        structure.setBlockState(world, Blocks.OAK_DOOR.getDefaultState().with(DoorBlock.FACING, Direction.EAST).with(DoorBlock.HALF, DoubleBlockHalf.LOWER).with(DoorBlock.HINGE, DoorHingeSide.LEFT).with(DoorBlock.OPEN, false).with(DoorBlock.POWERED, false), 14, 6, 9, start);
        structure.setBlockState(world, Blocks.MAGENTA_WOOL.getDefaultState(), 14, 6, 12, start);
        structure.setBlockState(world, Blocks.OAK_DOOR.getDefaultState().with(DoorBlock.FACING, Direction.EAST).with(DoorBlock.HALF, DoubleBlockHalf.UPPER).with(DoorBlock.HINGE, DoorHingeSide.LEFT).with(DoorBlock.OPEN, false).with(DoorBlock.POWERED, false), 14, 7, 9, start);
        structure.setBlockState(world, Blocks.MOSSY_COBBLESTONE.getDefaultState(), 14, 7, 13, start);
        structure.setBlockState(world, Blocks.SMOOTH_STONE_SLAB.getDefaultState().with(SlabBlock.TYPE, SlabType.DOUBLE).with(SlabBlock.WATERLOGGED, false), 14, 8, 9, start);
        structure.setBlockState(world, Blocks.IRON_BARS.getDefaultState().with(FourWayBlock.WATERLOGGED, false).with(FourWayBlock.NORTH, false).with(FourWayBlock.SOUTH, false).with(FourWayBlock.EAST, true).with(FourWayBlock.WEST, true), 14, 9, 9, start);
        structure.setBlockState(world, Blocks.SMOOTH_STONE_SLAB.getDefaultState().with(SlabBlock.TYPE, SlabType.TOP).with(SlabBlock.WATERLOGGED, false), 14, 9, 12, start);
        structure.setBlockState(world, Blocks.IRON_BARS.getDefaultState().with(FourWayBlock.WATERLOGGED, false).with(FourWayBlock.NORTH, false).with(FourWayBlock.SOUTH, false).with(FourWayBlock.EAST, false).with(FourWayBlock.WEST, false), 14, 10, 9, start);
        structure.setBlockState(world, Blocks.SMOOTH_STONE_SLAB.getDefaultState().with(SlabBlock.TYPE, SlabType.BOTTOM).with(SlabBlock.WATERLOGGED, false), 14, 10, 12, start);
        structure.setBlockState(world, Blocks.WALL_TORCH.getDefaultState().with(WallTorchBlock.HORIZONTAL_FACING, Direction.NORTH), 14, 11, 8, start);
        structure.setBlockState(world, Blocks.SMOOTH_STONE_SLAB.getDefaultState().with(SlabBlock.TYPE, SlabType.TOP).with(SlabBlock.WATERLOGGED, false), 14, 11, 10, start);
        structure.setBlockState(world, Blocks.WALL_TORCH.getDefaultState().with(WallTorchBlock.HORIZONTAL_FACING, Direction.SOUTH), 14, 11, 14, start);
        structure.setBlockState(world, Blocks.SMOOTH_STONE_SLAB.getDefaultState().with(SlabBlock.TYPE, SlabType.DOUBLE).with(SlabBlock.WATERLOGGED, false), 14, 14, 9, start);
        structure.setBlockState(world, Blocks.SMOOTH_STONE_SLAB.getDefaultState().with(SlabBlock.TYPE, SlabType.DOUBLE).with(SlabBlock.WATERLOGGED, false), 14, 14, 13, start);
        structure.setBlockState(world, Blocks.IRON_BARS.getDefaultState().with(FourWayBlock.WATERLOGGED, false).with(FourWayBlock.NORTH, false).with(FourWayBlock.SOUTH, false).with(FourWayBlock.EAST, false).with(FourWayBlock.WEST, false), 14, 15, 9, start);
        structure.setBlockState(world, Blocks.AIR.getDefaultState(), 14, 15, 11, start);
        structure.setBlockState(world, Blocks.IRON_BARS.getDefaultState().with(FourWayBlock.WATERLOGGED, false).with(FourWayBlock.NORTH, false).with(FourWayBlock.SOUTH, false).with(FourWayBlock.EAST, false).with(FourWayBlock.WEST, false), 14, 15, 13, start);
        structure.setBlockState(world, Blocks.SMOOTH_STONE_SLAB.getDefaultState().with(SlabBlock.TYPE, SlabType.DOUBLE).with(SlabBlock.WATERLOGGED, false), 14, 17, 9, start);
        structure.setBlockState(world, Blocks.SMOOTH_STONE_SLAB.getDefaultState().with(SlabBlock.TYPE, SlabType.DOUBLE).with(SlabBlock.WATERLOGGED, false), 14, 17, 13, start);
        structure.setBlockState(world, ModBlocks.CHAIR.get().getDefaultState().with(ChairBlock.FACING, Direction.SOUTH), 14, 19, 9, start);
        structure.setBlockState(world, Blocks.AIR.getDefaultState(), 14, 19, 11, start);
        structure.setBlockState(world, Blocks.AIR.getDefaultState(), 14, 19, 14, start);
        structure.setBlockState(world, Blocks.WALL_TORCH.getDefaultState().with(WallTorchBlock.HORIZONTAL_FACING, Direction.SOUTH), 14, 22, 8, start);
        structure.setBlockState(world, Blocks.WALL_TORCH.getDefaultState().with(WallTorchBlock.HORIZONTAL_FACING, Direction.NORTH), 14, 22, 14, start);
        structure.setBlockState(world, Blocks.STONE_BUTTON.getDefaultState().with(HorizontalBlock.HORIZONTAL_FACING, Direction.NORTH).with(HorizontalFaceBlock.FACE, AttachFace.WALL).with(AbstractButtonBlock.POWERED, false), 14, 25, 8, start);
        structure.setBlockState(world, Blocks.AIR.getDefaultState(), 14, 25, 11, start);
        structure.setBlockState(world, Blocks.STONE_BUTTON.getDefaultState().with(HorizontalBlock.HORIZONTAL_FACING, Direction.SOUTH).with(HorizontalFaceBlock.FACE, AttachFace.WALL).with(AbstractButtonBlock.POWERED, false), 14, 25, 14, start);
        structure.setBlockState(world, Blocks.STONE_BUTTON.getDefaultState().with(HorizontalBlock.HORIZONTAL_FACING, Direction.NORTH).with(HorizontalFaceBlock.FACE, AttachFace.WALL).with(AbstractButtonBlock.POWERED, false), 14, 27, 8, start);
        structure.setBlockState(world, Blocks.STONE_BUTTON.getDefaultState().with(HorizontalBlock.HORIZONTAL_FACING, Direction.SOUTH).with(HorizontalFaceBlock.FACE, AttachFace.WALL).with(AbstractButtonBlock.POWERED, false), 14, 27, 14, start);
        structure.setBlockState(world, Blocks.GLOWSTONE.getDefaultState(), 14, 28, 11, start);
        structure.setBlockState(world, Blocks.OAK_STAIRS.getDefaultState().with(StairsBlock.FACING, Direction.SOUTH).with(StairsBlock.WATERLOGGED, false).with(StairsBlock.SHAPE, StairsShape.STRAIGHT).with(StairsBlock.HALF, Half.BOTTOM), 14, 29, 9, start);
        structure.setBlockState(world, Blocks.OAK_FENCE.getDefaultState().with(FourWayBlock.WATERLOGGED, false).with(FourWayBlock.NORTH, false).with(FourWayBlock.SOUTH, false).with(FourWayBlock.EAST, false).with(FourWayBlock.WEST, false), 14, 29, 11, start);
        structure.setBlockState(world, Blocks.OAK_STAIRS.getDefaultState().with(StairsBlock.FACING, Direction.NORTH).with(StairsBlock.WATERLOGGED, false).with(StairsBlock.SHAPE, StairsShape.STRAIGHT).with(StairsBlock.HALF, Half.BOTTOM), 14, 29, 13, start);
        structure.setBlockState(world, Blocks.GLOWSTONE.getDefaultState(), 14, 30, 9, start);
        structure.setBlockState(world, Blocks.GLOWSTONE.getDefaultState(), 14, 30, 13, start);
        structure.setBlockState(world, Blocks.NETHER_BRICK_STAIRS.getDefaultState().with(StairsBlock.FACING, Direction.SOUTH).with(StairsBlock.WATERLOGGED, false).with(StairsBlock.SHAPE, StairsShape.STRAIGHT).with(StairsBlock.HALF, Half.TOP), 14, 31, 7, start);
        structure.setBlockState(world, Blocks.NETHER_BRICK_STAIRS.getDefaultState().with(StairsBlock.FACING, Direction.NORTH).with(StairsBlock.WATERLOGGED, false).with(StairsBlock.SHAPE, StairsShape.STRAIGHT).with(StairsBlock.HALF, Half.TOP), 14, 31, 15, start);
        structure.setBlockState(world, Blocks.STONE_BRICKS.getDefaultState(), 14, 32, 12, start);
        structure.setBlockState(world, Blocks.STONE_BRICKS.getDefaultState(), 14, 33, 11, start);
        structure.setBlockState(world, Blocks.OAK_FENCE.getDefaultState().with(FourWayBlock.WATERLOGGED, false).with(FourWayBlock.NORTH, false).with(FourWayBlock.SOUTH, false).with(FourWayBlock.EAST, false).with(FourWayBlock.WEST, false), 14, 34, 11, start);
        structure.setBlockState(world, Blocks.TORCH.getDefaultState(), 14, 37, 11, start);
        structure.setBlockState(world, Blocks.DIRT.getDefaultState(), 15, 2, 4, start);
        structure.setBlockState(world, Blocks.GRASS.getDefaultState(), 15, 3, 20, start);
        structure.setBlockState(world, Blocks.SMOOTH_STONE_SLAB.getDefaultState().with(SlabBlock.TYPE, SlabType.BOTTOM).with(SlabBlock.WATERLOGGED, false), 15, 6, 8, start);
        structure.setBlockState(world, Blocks.AIR.getDefaultState(), 15, 6, 10, start);
        structure.setBlockState(world, Blocks.COBBLESTONE_SLAB.getDefaultState().with(SlabBlock.TYPE, SlabType.BOTTOM).with(SlabBlock.WATERLOGGED, false), 15, 7, 7, start);
        structure.setBlockState(world, Blocks.CAULDRON.getDefaultState().with(CauldronBlock.LEVEL, 0), 15, 7, 12, start);
        structure.setBlockState(world, Blocks.CAULDRON.getDefaultState().with(CauldronBlock.LEVEL, 0), 15, 9, 10, start);
        structure.setBlockState(world, Blocks.MAGENTA_WOOL.getDefaultState(), 15, 9, 12, start);
        structure.setBlockState(world, Blocks.SMOOTH_STONE_SLAB.getDefaultState().with(SlabBlock.TYPE, SlabType.DOUBLE).with(SlabBlock.WATERLOGGED, false), 15, 10, 12, start);
        structure.setBlockState(world, Blocks.SMOOTH_STONE_SLAB.getDefaultState().with(SlabBlock.TYPE, SlabType.DOUBLE).with(SlabBlock.WATERLOGGED, false), 15, 11, 10, start);
        structure.setBlockState(world, Blocks.SMOOTH_STONE_SLAB.getDefaultState().with(SlabBlock.TYPE, SlabType.BOTTOM).with(SlabBlock.WATERLOGGED, false), 15, 11, 11, start);
        structure.setBlockState(world, Blocks.OAK_FENCE_GATE.getDefaultState().with(FenceGateBlock.IN_WALL, false).with(FenceGateBlock.OPEN, false).with(FenceGateBlock.POWERED, false), 15, 16, 8, start);
        structure.setBlockState(world, Blocks.OAK_FENCE_GATE.getDefaultState().with(FenceGateBlock.IN_WALL, false).with(FenceGateBlock.OPEN, false).with(FenceGateBlock.POWERED, false), 15, 16, 14, start);
        structure.setBlockState(world, Blocks.OAK_FENCE.getDefaultState().with(FourWayBlock.WATERLOGGED, false).with(FourWayBlock.NORTH, false).with(FourWayBlock.SOUTH, true).with(FourWayBlock.EAST, false).with(FourWayBlock.WEST, false), 15, 17, 7, start);
        structure.setBlockState(world, Blocks.OAK_FENCE.getDefaultState().with(FourWayBlock.WATERLOGGED, false).with(FourWayBlock.NORTH, true).with(FourWayBlock.SOUTH, false).with(FourWayBlock.EAST, false).with(FourWayBlock.WEST, false), 15, 17, 8, start);
        structure.setBlockState(world, Blocks.WALL_TORCH.getDefaultState().with(WallTorchBlock.HORIZONTAL_FACING, Direction.WEST), 15, 17, 11, start);
        structure.setBlockState(world, Blocks.OAK_FENCE.getDefaultState().with(FourWayBlock.WATERLOGGED, false).with(FourWayBlock.NORTH, true).with(FourWayBlock.SOUTH, true).with(FourWayBlock.EAST, false).with(FourWayBlock.WEST, false), 15, 17, 14, start);
        structure.setBlockState(world, Blocks.OAK_FENCE.getDefaultState().with(FourWayBlock.WATERLOGGED, false).with(FourWayBlock.NORTH, true).with(FourWayBlock.SOUTH, false).with(FourWayBlock.EAST, false).with(FourWayBlock.WEST, false), 15, 17, 15, start);
        structure.setBlockState(world, Blocks.STONE_BUTTON.getDefaultState().with(HorizontalBlock.HORIZONTAL_FACING, Direction.NORTH).with(HorizontalFaceBlock.FACE, AttachFace.WALL).with(AbstractButtonBlock.POWERED, false), 15, 18, 6, start);
        structure.setBlockState(world, Blocks.STONE_BUTTON.getDefaultState().with(HorizontalBlock.HORIZONTAL_FACING, Direction.SOUTH).with(HorizontalFaceBlock.FACE, AttachFace.WALL).with(AbstractButtonBlock.POWERED, false), 15, 18, 16, start);
        structure.setBlockState(world, Blocks.OAK_PLANKS.getDefaultState(), 15, 19, 7, start);
        structure.setBlockState(world, Blocks.OAK_PLANKS.getDefaultState(), 15, 19, 15, start);
        structure.setBlockState(world, Blocks.OAK_TRAPDOOR.getDefaultState().with(HorizontalBlock.HORIZONTAL_FACING, Direction.NORTH).with(TrapDoorBlock.HALF, Half.BOTTOM).with(TrapDoorBlock.WATERLOGGED, false).with(TrapDoorBlock.POWERED, false).with(TrapDoorBlock.OPEN, false), 15, 21, 6, start);
        structure.setBlockState(world, Blocks.OAK_PLANKS.getDefaultState(), 15, 21, 15, start);
        structure.setBlockState(world, Blocks.OAK_TRAPDOOR.getDefaultState().with(HorizontalBlock.HORIZONTAL_FACING, Direction.SOUTH).with(TrapDoorBlock.HALF, Half.BOTTOM).with(TrapDoorBlock.WATERLOGGED, false).with(TrapDoorBlock.POWERED, false).with(TrapDoorBlock.OPEN, false), 15, 21, 16, start);
        structure.setBlockState(world, Blocks.OAK_STAIRS.getDefaultState().with(StairsBlock.FACING, Direction.NORTH).with(StairsBlock.WATERLOGGED, false).with(StairsBlock.SHAPE, StairsShape.STRAIGHT).with(StairsBlock.HALF, Half.BOTTOM), 15, 25, 9, start);
        structure.setBlockState(world, Blocks.LECTERN.getDefaultState().with(LecternBlock.FACING, Direction.WEST).with(LecternBlock.HAS_BOOK, false).with(LecternBlock.POWERED, false), 15, 25, 11, start);
        structure.setBlockState(world, Blocks.OAK_STAIRS.getDefaultState().with(StairsBlock.FACING, Direction.SOUTH).with(StairsBlock.WATERLOGGED, false).with(StairsBlock.SHAPE, StairsShape.STRAIGHT).with(StairsBlock.HALF, Half.BOTTOM), 15, 25, 13, start);
        structure.setBlockState(world, Blocks.GLASS_PANE.getDefaultState().with(FourWayBlock.WATERLOGGED, false).with(FourWayBlock.NORTH, false).with(FourWayBlock.SOUTH, false).with(FourWayBlock.EAST, true).with(FourWayBlock.WEST, true), 15, 26, 9, start);
        structure.setBlockState(world, Blocks.GLASS_PANE.getDefaultState().with(FourWayBlock.WATERLOGGED, false).with(FourWayBlock.NORTH, false).with(FourWayBlock.SOUTH, false).with(FourWayBlock.EAST, true).with(FourWayBlock.WEST, true), 15, 26, 13, start);
        structure.setBlockState(world, Blocks.OAK_STAIRS.getDefaultState().with(StairsBlock.FACING, Direction.NORTH).with(StairsBlock.WATERLOGGED, false).with(StairsBlock.SHAPE, StairsShape.STRAIGHT).with(StairsBlock.HALF, Half.TOP), 15, 27, 9, start);
        structure.setBlockState(world, Blocks.OAK_STAIRS.getDefaultState().with(StairsBlock.FACING, Direction.SOUTH).with(StairsBlock.WATERLOGGED, false).with(StairsBlock.SHAPE, StairsShape.STRAIGHT).with(StairsBlock.HALF, Half.TOP), 15, 27, 13, start);
        structure.setBlockState(world, Blocks.NETHER_BRICKS.getDefaultState(), 15, 30, 11, start);
        structure.setBlockState(world, Blocks.STONE_BRICKS.getDefaultState(), 15, 32, 11, start);
        structure.setBlockState(world, Blocks.GRASS.getDefaultState(), 16, 6, 5, start);
        structure.setBlockState(world, Blocks.CAULDRON.getDefaultState().with(CauldronBlock.LEVEL, 0), 16, 6, 6, start);
        structure.setBlockState(world, Blocks.SMOOTH_STONE_SLAB.getDefaultState().with(SlabBlock.TYPE, SlabType.DOUBLE).with(SlabBlock.WATERLOGGED, false), 16, 6, 8, start);
        structure.setBlockState(world, Blocks.STONE_BRICKS.getDefaultState(), 16, 6, 13, start);
        structure.setBlockState(world, Blocks.STONE_BRICK_STAIRS.getDefaultState().with(StairsBlock.FACING, Direction.NORTH).with(StairsBlock.WATERLOGGED, false).with(StairsBlock.SHAPE, StairsShape.STRAIGHT).with(StairsBlock.HALF, Half.BOTTOM), 16, 6, 14, start);
        structure.setBlockState(world, Blocks.GRASS.getDefaultState(), 16, 6, 16, start);
        structure.setBlockState(world, Blocks.MOSSY_STONE_BRICKS.getDefaultState(), 16, 7, 13, start);
        structure.setBlockState(world, Blocks.OAK_DOOR.getDefaultState().with(DoorBlock.FACING, Direction.WEST).with(DoorBlock.HALF, DoubleBlockHalf.LOWER).with(DoorBlock.HINGE, DoorHingeSide.RIGHT).with(DoorBlock.OPEN, true).with(DoorBlock.POWERED, false), 16, 9, 11, start);
        structure.setBlockState(world, Blocks.MOSSY_STONE_BRICKS.getDefaultState(), 16, 9, 13, start);
        structure.setBlockState(world, Blocks.OAK_DOOR.getDefaultState().with(DoorBlock.FACING, Direction.WEST).with(DoorBlock.HALF, DoubleBlockHalf.UPPER).with(DoorBlock.HINGE, DoorHingeSide.RIGHT).with(DoorBlock.OPEN, true).with(DoorBlock.POWERED, false), 16, 10, 11, start);
        structure.setBlockState(world, Blocks.STONE_BRICKS.getDefaultState(), 16, 11, 11, start);
        structure.setBlockState(world, Blocks.SMOOTH_STONE_SLAB.getDefaultState().with(SlabBlock.TYPE, SlabType.DOUBLE).with(SlabBlock.WATERLOGGED, false), 16, 14, 11, start);
        structure.setBlockState(world, Blocks.IRON_BARS.getDefaultState().with(FourWayBlock.WATERLOGGED, false).with(FourWayBlock.NORTH, true).with(FourWayBlock.SOUTH, true).with(FourWayBlock.EAST, false).with(FourWayBlock.WEST, false), 16, 15, 11, start);
        structure.setBlockState(world, Blocks.SMOOTH_STONE_SLAB.getDefaultState().with(SlabBlock.TYPE, SlabType.DOUBLE).with(SlabBlock.WATERLOGGED, false), 16, 17, 11, start);
        structure.setBlockState(world, Blocks.OAK_STAIRS.getDefaultState().with(StairsBlock.FACING, Direction.SOUTH).with(StairsBlock.WATERLOGGED, false).with(StairsBlock.SHAPE, StairsShape.STRAIGHT).with(StairsBlock.HALF, Half.TOP), 16, 18, 7, start);
        structure.setBlockState(world, Blocks.SPRUCE_PLANKS.getDefaultState(), 16, 18, 14, start);
        structure.setBlockState(world, Blocks.OAK_STAIRS.getDefaultState().with(StairsBlock.FACING, Direction.NORTH).with(StairsBlock.WATERLOGGED, false).with(StairsBlock.SHAPE, StairsShape.STRAIGHT).with(StairsBlock.HALF, Half.TOP), 16, 18, 15, start);
        structure.setBlockState(world, Blocks.OAK_STAIRS.getDefaultState().with(StairsBlock.FACING, Direction.SOUTH).with(StairsBlock.WATERLOGGED, false).with(StairsBlock.SHAPE, StairsShape.STRAIGHT).with(StairsBlock.HALF, Half.BOTTOM), 16, 19, 8, start);
        structure.setBlockState(world, Blocks.NETHER_BRICK_STAIRS.getDefaultState().with(StairsBlock.FACING, Direction.NORTH).with(StairsBlock.WATERLOGGED, false).with(StairsBlock.SHAPE, StairsShape.STRAIGHT).with(StairsBlock.HALF, Half.TOP), 16, 19, 10, start);
        structure.setBlockState(world, Blocks.NETHER_BRICK_STAIRS.getDefaultState().with(StairsBlock.FACING, Direction.SOUTH).with(StairsBlock.WATERLOGGED, false).with(StairsBlock.SHAPE, StairsShape.STRAIGHT).with(StairsBlock.HALF, Half.TOP), 16, 19, 11, start);
        structure.setBlockState(world, Blocks.OAK_STAIRS.getDefaultState().with(StairsBlock.FACING, Direction.NORTH).with(StairsBlock.WATERLOGGED, false).with(StairsBlock.SHAPE, StairsShape.STRAIGHT).with(StairsBlock.HALF, Half.BOTTOM), 16, 19, 14, start);
        structure.setBlockState(world, Blocks.OAK_STAIRS.getDefaultState().with(StairsBlock.FACING, Direction.SOUTH).with(StairsBlock.WATERLOGGED, false).with(StairsBlock.SHAPE, StairsShape.STRAIGHT).with(StairsBlock.HALF, Half.TOP), 16, 20, 8, start);
        structure.setBlockState(world, Blocks.CAKE.getDefaultState().with(CakeBlock.BITES, 0), 16, 20, 10, start);
        structure.setBlockState(world, Blocks.OAK_STAIRS.getDefaultState().with(StairsBlock.FACING, Direction.NORTH).with(StairsBlock.WATERLOGGED, false).with(StairsBlock.SHAPE, StairsShape.STRAIGHT).with(StairsBlock.HALF, Half.TOP), 16, 20, 14, start);
        structure.setBlockState(world, Blocks.OAK_PLANKS.getDefaultState(), 16, 21, 14, start);
        structure.setBlockState(world, Blocks.OAK_FENCE.getDefaultState().with(FourWayBlock.WATERLOGGED, false).with(FourWayBlock.NORTH, false).with(FourWayBlock.SOUTH, false).with(FourWayBlock.EAST, false).with(FourWayBlock.WEST, false), 16, 23, 9, start);
        structure.setBlockState(world, Blocks.OAK_FENCE.getDefaultState().with(FourWayBlock.WATERLOGGED, false).with(FourWayBlock.NORTH, false).with(FourWayBlock.SOUTH, false).with(FourWayBlock.EAST, false).with(FourWayBlock.WEST, false), 16, 23, 13, start);
        structure.setBlockState(world, Blocks.OAK_PLANKS.getDefaultState(), 16, 23, 14, start);
        structure.setBlockState(world, Blocks.STONE_BUTTON.getDefaultState().with(HorizontalBlock.HORIZONTAL_FACING, Direction.NORTH).with(HorizontalFaceBlock.FACE, AttachFace.WALL).with(AbstractButtonBlock.POWERED, false), 16, 25, 8, start);
        structure.setBlockState(world, Blocks.OAK_STAIRS.getDefaultState().with(StairsBlock.FACING, Direction.EAST).with(StairsBlock.WATERLOGGED, false).with(StairsBlock.SHAPE, StairsShape.STRAIGHT).with(StairsBlock.HALF, Half.BOTTOM), 16, 25, 10, start);
        structure.setBlockState(world, Blocks.OAK_STAIRS.getDefaultState().with(StairsBlock.FACING, Direction.EAST).with(StairsBlock.WATERLOGGED, false).with(StairsBlock.SHAPE, StairsShape.STRAIGHT).with(StairsBlock.HALF, Half.BOTTOM), 16, 25, 12, start);
        structure.setBlockState(world, Blocks.STONE_BUTTON.getDefaultState().with(HorizontalBlock.HORIZONTAL_FACING, Direction.SOUTH).with(HorizontalFaceBlock.FACE, AttachFace.WALL).with(AbstractButtonBlock.POWERED, false), 16, 25, 14, start);
        structure.setBlockState(world, Blocks.GLASS_PANE.getDefaultState().with(FourWayBlock.WATERLOGGED, false).with(FourWayBlock.NORTH, true).with(FourWayBlock.SOUTH, true).with(FourWayBlock.EAST, false).with(FourWayBlock.WEST, false), 16, 26, 10, start);
        structure.setBlockState(world, Blocks.GLASS_PANE.getDefaultState().with(FourWayBlock.WATERLOGGED, false).with(FourWayBlock.NORTH, true).with(FourWayBlock.SOUTH, true).with(FourWayBlock.EAST, false).with(FourWayBlock.WEST, false), 16, 26, 12, start);
        structure.setBlockState(world, Blocks.STONE_BUTTON.getDefaultState().with(HorizontalBlock.HORIZONTAL_FACING, Direction.NORTH).with(HorizontalFaceBlock.FACE, AttachFace.WALL).with(AbstractButtonBlock.POWERED, false), 16, 27, 8, start);
        structure.setBlockState(world, Blocks.OAK_STAIRS.getDefaultState().with(StairsBlock.FACING, Direction.EAST).with(StairsBlock.WATERLOGGED, false).with(StairsBlock.SHAPE, StairsShape.STRAIGHT).with(StairsBlock.HALF, Half.TOP), 16, 27, 10, start);
        structure.setBlockState(world, Blocks.OAK_STAIRS.getDefaultState().with(StairsBlock.FACING, Direction.EAST).with(StairsBlock.WATERLOGGED, false).with(StairsBlock.SHAPE, StairsShape.STRAIGHT).with(StairsBlock.HALF, Half.TOP), 16, 27, 12, start);
        structure.setBlockState(world, Blocks.STONE_BUTTON.getDefaultState().with(HorizontalBlock.HORIZONTAL_FACING, Direction.SOUTH).with(HorizontalFaceBlock.FACE, AttachFace.WALL).with(AbstractButtonBlock.POWERED, false), 16, 27, 14, start);
        structure.setBlockState(world, Blocks.OAK_STAIRS.getDefaultState().with(StairsBlock.FACING, Direction.WEST).with(StairsBlock.WATERLOGGED, false).with(StairsBlock.SHAPE, StairsShape.STRAIGHT).with(StairsBlock.HALF, Half.BOTTOM), 16, 29, 11, start);
        structure.setBlockState(world, Blocks.GLOWSTONE.getDefaultState(), 16, 30, 11, start);
        structure.setBlockState(world, Blocks.WHITE_WOOL.getDefaultState(), 16, 35, 12, start);
        structure.setBlockState(world, Blocks.STONE_BRICKS.getDefaultState(), 16, 36, 12, start);
        structure.setBlockState(world, Blocks.STONE.getDefaultState(), 17, 3, 16, start);
        structure.setBlockState(world, Blocks.GRASS_BLOCK.getDefaultState().with(SnowyDirtBlock.SNOWY, false), 17, 3, 17, start);
        structure.setBlockState(world, Blocks.GRASS_BLOCK.getDefaultState().with(SnowyDirtBlock.SNOWY, false), 17, 4, 16, start);
        structure.setBlockState(world, Blocks.GRASS_BLOCK.getDefaultState().with(SnowyDirtBlock.SNOWY, false), 17, 5, 6, start);
        structure.setBlockState(world, Blocks.DIRT.getDefaultState(), 17, 5, 7, start);
        structure.setBlockState(world, Blocks.GRASS.getDefaultState(), 17, 5, 16, start);
        structure.setBlockState(world, Blocks.MOSSY_COBBLESTONE.getDefaultState(), 17, 6, 7, start);
        structure.setBlockState(world, Blocks.STONE_BRICK_STAIRS.getDefaultState().with(StairsBlock.FACING, Direction.WEST).with(StairsBlock.WATERLOGGED, false).with(StairsBlock.SHAPE, StairsShape.STRAIGHT).with(StairsBlock.HALF, Half.BOTTOM), 17, 6, 13, start);
        structure.setBlockState(world, Blocks.SMOOTH_STONE_SLAB.getDefaultState().with(SlabBlock.TYPE, SlabType.BOTTOM).with(SlabBlock.WATERLOGGED, false), 17, 7, 8, start);
        structure.setBlockState(world, Blocks.SMOOTH_STONE_SLAB.getDefaultState().with(SlabBlock.TYPE, SlabType.DOUBLE).with(SlabBlock.WATERLOGGED, false), 17, 7, 9, start);
        structure.setBlockState(world, Blocks.SMOOTH_STONE_SLAB.getDefaultState().with(SlabBlock.TYPE, SlabType.BOTTOM).with(SlabBlock.WATERLOGGED, false), 17, 8, 10, start);
        structure.setBlockState(world, Blocks.SMOOTH_STONE_SLAB.getDefaultState().with(SlabBlock.TYPE, SlabType.DOUBLE).with(SlabBlock.WATERLOGGED, false), 17, 8, 11, start);
        structure.setBlockState(world, Blocks.AIR.getDefaultState(), 17, 9, 10, start);
        structure.setBlockState(world, Blocks.COBBLESTONE.getDefaultState(), 17, 9, 12, start);
        structure.setBlockState(world, Blocks.WALL_TORCH.getDefaultState().with(WallTorchBlock.HORIZONTAL_FACING, Direction.EAST), 17, 11, 11, start);
        structure.setBlockState(world, Blocks.OAK_FENCE_GATE.getDefaultState().with(FenceGateBlock.IN_WALL, false).with(FenceGateBlock.OPEN, false).with(FenceGateBlock.POWERED, false), 17, 16, 10, start);
        structure.setBlockState(world, Blocks.OAK_FENCE_GATE.getDefaultState().with(FenceGateBlock.IN_WALL, false).with(FenceGateBlock.OPEN, false).with(FenceGateBlock.POWERED, false), 17, 16, 12, start);
        structure.setBlockState(world, Blocks.OAK_FENCE.getDefaultState().with(FourWayBlock.WATERLOGGED, false).with(FourWayBlock.NORTH, false).with(FourWayBlock.SOUTH, false).with(FourWayBlock.EAST, true).with(FourWayBlock.WEST, false), 17, 17, 10, start);
        structure.setBlockState(world, Blocks.OAK_FENCE.getDefaultState().with(FourWayBlock.WATERLOGGED, false).with(FourWayBlock.NORTH, false).with(FourWayBlock.SOUTH, false).with(FourWayBlock.EAST, true).with(FourWayBlock.WEST, false), 17, 17, 12, start);
        structure.setBlockState(world, Blocks.SPRUCE_PLANKS.getDefaultState(), 17, 18, 13, start);
        structure.setBlockState(world, Blocks.OAK_STAIRS.getDefaultState().with(StairsBlock.FACING, Direction.WEST).with(StairsBlock.WATERLOGGED, false).with(StairsBlock.SHAPE, StairsShape.STRAIGHT).with(StairsBlock.HALF, Half.BOTTOM), 17, 19, 9, start);
        structure.setBlockState(world, ModBlocks.CHAIR.get().getDefaultState().with(ChairBlock.FACING, Direction.WEST), 17, 19, 11, start);
        structure.setBlockState(world, Blocks.OAK_STAIRS.getDefaultState().with(StairsBlock.FACING, Direction.WEST).with(StairsBlock.WATERLOGGED, false).with(StairsBlock.SHAPE, StairsShape.STRAIGHT).with(StairsBlock.HALF, Half.BOTTOM), 17, 19, 13, start);
        structure.setBlockState(world, Blocks.OAK_STAIRS.getDefaultState().with(StairsBlock.FACING, Direction.WEST).with(StairsBlock.WATERLOGGED, false).with(StairsBlock.SHAPE, StairsShape.STRAIGHT).with(StairsBlock.HALF, Half.TOP), 17, 20, 9, start);
        structure.setBlockState(world, Blocks.OAK_STAIRS.getDefaultState().with(StairsBlock.FACING, Direction.WEST).with(StairsBlock.WATERLOGGED, false).with(StairsBlock.SHAPE, StairsShape.STRAIGHT).with(StairsBlock.HALF, Half.TOP), 17, 20, 13, start);
        structure.setBlockState(world, Blocks.OAK_PLANKS.getDefaultState(), 17, 21, 13, start);
        structure.setBlockState(world, Blocks.WALL_TORCH.getDefaultState().with(WallTorchBlock.HORIZONTAL_FACING, Direction.WEST), 17, 22, 11, start);
        structure.setBlockState(world, Blocks.OAK_PLANKS.getDefaultState(), 17, 23, 9, start);
        structure.setBlockState(world, Blocks.OAK_PLANKS.getDefaultState(), 17, 23, 13, start);
        structure.setBlockState(world, Blocks.STONE_BRICKS.getDefaultState(), 17, 23, 14, start);
        structure.setBlockState(world, Blocks.STONE_BUTTON.getDefaultState().with(HorizontalBlock.HORIZONTAL_FACING, Direction.EAST).with(HorizontalFaceBlock.FACE, AttachFace.WALL).with(AbstractButtonBlock.POWERED, false), 17, 25, 9, start);
        structure.setBlockState(world, Blocks.STONE_BUTTON.getDefaultState().with(HorizontalBlock.HORIZONTAL_FACING, Direction.EAST).with(HorizontalFaceBlock.FACE, AttachFace.WALL).with(AbstractButtonBlock.POWERED, false), 17, 25, 11, start);
        structure.setBlockState(world, Blocks.STONE_BUTTON.getDefaultState().with(HorizontalBlock.HORIZONTAL_FACING, Direction.EAST).with(HorizontalFaceBlock.FACE, AttachFace.WALL).with(AbstractButtonBlock.POWERED, false), 17, 25, 13, start);
        structure.setBlockState(world, Blocks.STONE_BUTTON.getDefaultState().with(HorizontalBlock.HORIZONTAL_FACING, Direction.EAST).with(HorizontalFaceBlock.FACE, AttachFace.WALL).with(AbstractButtonBlock.POWERED, false), 17, 27, 9, start);
        structure.setBlockState(world, Blocks.STONE_BUTTON.getDefaultState().with(HorizontalBlock.HORIZONTAL_FACING, Direction.EAST).with(HorizontalFaceBlock.FACE, AttachFace.WALL).with(AbstractButtonBlock.POWERED, false), 17, 27, 11, start);
        structure.setBlockState(world, Blocks.STONE_BUTTON.getDefaultState().with(HorizontalBlock.HORIZONTAL_FACING, Direction.EAST).with(HorizontalFaceBlock.FACE, AttachFace.WALL).with(AbstractButtonBlock.POWERED, false), 17, 27, 13, start);
        structure.setBlockState(world, Blocks.GRASS_BLOCK.getDefaultState().with(SnowyDirtBlock.SNOWY, false), 18, 3, 16, start);
        structure.setBlockState(world, Blocks.GRASS_BLOCK.getDefaultState().with(SnowyDirtBlock.SNOWY, false), 18, 4, 6, start);
        structure.setBlockState(world, Blocks.GRASS_BLOCK.getDefaultState().with(SnowyDirtBlock.SNOWY, false), 18, 5, 13, start);
        structure.setBlockState(world, Blocks.GRASS.getDefaultState(), 18, 5, 15, start);
        structure.setBlockState(world, Blocks.GRASS.getDefaultState(), 18, 6, 13, start);
        structure.setBlockState(world, Blocks.MOSSY_COBBLESTONE.getDefaultState(), 18, 7, 10, start);
        structure.setBlockState(world, Blocks.COBBLESTONE_SLAB.getDefaultState().with(SlabBlock.TYPE, SlabType.DOUBLE).with(SlabBlock.WATERLOGGED, false), 18, 8, 7, start);
        structure.setBlockState(world, Blocks.COBBLESTONE_SLAB.getDefaultState().with(SlabBlock.TYPE, SlabType.BOTTOM).with(SlabBlock.WATERLOGGED, false), 18, 8, 8, start);
        structure.setBlockState(world, Blocks.COBBLESTONE_SLAB.getDefaultState().with(SlabBlock.TYPE, SlabType.BOTTOM).with(SlabBlock.WATERLOGGED, false), 18, 9, 10, start);
        structure.setBlockState(world, Blocks.COBBLESTONE.getDefaultState(), 18, 9, 11, start);
        structure.setBlockState(world, Blocks.COBBLESTONE_SLAB.getDefaultState().with(SlabBlock.TYPE, SlabType.DOUBLE).with(SlabBlock.WATERLOGGED, false), 18, 9, 12, start);
        structure.setBlockState(world, Blocks.COBBLESTONE_SLAB.getDefaultState().with(SlabBlock.TYPE, SlabType.BOTTOM).with(SlabBlock.WATERLOGGED, false), 18, 10, 12, start);
        structure.setBlockState(world, Blocks.OAK_FENCE.getDefaultState().with(FourWayBlock.WATERLOGGED, false).with(FourWayBlock.NORTH, false).with(FourWayBlock.SOUTH, false).with(FourWayBlock.EAST, false).with(FourWayBlock.WEST, true), 18, 17, 10, start);
        structure.setBlockState(world, Blocks.OAK_FENCE.getDefaultState().with(FourWayBlock.WATERLOGGED, false).with(FourWayBlock.NORTH, false).with(FourWayBlock.SOUTH, false).with(FourWayBlock.EAST, false).with(FourWayBlock.WEST, true), 18, 17, 12, start);
        structure.setBlockState(world, Blocks.OAK_STAIRS.getDefaultState().with(StairsBlock.FACING, Direction.WEST).with(StairsBlock.WATERLOGGED, false).with(StairsBlock.SHAPE, StairsShape.STRAIGHT).with(StairsBlock.HALF, Half.TOP), 18, 18, 9, start);
        structure.setBlockState(world, Blocks.OAK_STAIRS.getDefaultState().with(StairsBlock.FACING, Direction.WEST).with(StairsBlock.WATERLOGGED, false).with(StairsBlock.SHAPE, StairsShape.STRAIGHT).with(StairsBlock.HALF, Half.TOP), 18, 18, 13, start);
        structure.setBlockState(world, Blocks.OAK_PLANKS.getDefaultState(), 18, 19, 10, start);
        structure.setBlockState(world, Blocks.OAK_PLANKS.getDefaultState(), 18, 19, 12, start);
        structure.setBlockState(world, Blocks.OAK_PLANKS.getDefaultState(), 18, 21, 10, start);
        structure.setBlockState(world, Blocks.OAK_PLANKS.getDefaultState(), 18, 21, 12, start);
        structure.setBlockState(world, Blocks.NETHER_BRICK_STAIRS.getDefaultState().with(StairsBlock.FACING, Direction.WEST).with(StairsBlock.WATERLOGGED, false).with(StairsBlock.SHAPE, StairsShape.STRAIGHT).with(StairsBlock.HALF, Half.TOP), 18, 31, 11, start);
        structure.setBlockState(world, Blocks.GRASS_BLOCK.getDefaultState().with(SnowyDirtBlock.SNOWY, false), 19, 1, 13, start);
        structure.setBlockState(world, Blocks.DIRT.getDefaultState(), 19, 2, 8, start);
        structure.setBlockState(world, Blocks.GRASS_BLOCK.getDefaultState().with(SnowyDirtBlock.SNOWY, false), 19, 3, 8, start);
        structure.setBlockState(world, Blocks.STONE.getDefaultState(), 19, 3, 13, start);
        structure.setBlockState(world, Blocks.GRASS_BLOCK.getDefaultState().with(SnowyDirtBlock.SNOWY, false), 19, 4, 9, start);
        structure.setBlockState(world, Blocks.GRASS_BLOCK.getDefaultState().with(SnowyDirtBlock.SNOWY, false), 19, 4, 13, start);
        structure.setBlockState(world, Blocks.GRASS.getDefaultState(), 19, 5, 13, start);
        structure.setBlockState(world, Blocks.STONE_BUTTON.getDefaultState().with(HorizontalBlock.HORIZONTAL_FACING, Direction.EAST).with(HorizontalFaceBlock.FACE, AttachFace.WALL).with(AbstractButtonBlock.POWERED, false), 19, 18, 10, start);
        structure.setBlockState(world, Blocks.STONE_BUTTON.getDefaultState().with(HorizontalBlock.HORIZONTAL_FACING, Direction.EAST).with(HorizontalFaceBlock.FACE, AttachFace.WALL).with(AbstractButtonBlock.POWERED, false), 19, 18, 12, start);
        structure.setBlockState(world, Blocks.OAK_TRAPDOOR.getDefaultState().with(HorizontalBlock.HORIZONTAL_FACING, Direction.EAST).with(TrapDoorBlock.HALF, Half.BOTTOM).with(TrapDoorBlock.WATERLOGGED, false).with(TrapDoorBlock.POWERED, false).with(TrapDoorBlock.OPEN, false), 19, 21, 10, start);
        structure.setBlockState(world, Blocks.OAK_TRAPDOOR.getDefaultState().with(HorizontalBlock.HORIZONTAL_FACING, Direction.EAST).with(TrapDoorBlock.HALF, Half.BOTTOM).with(TrapDoorBlock.WATERLOGGED, false).with(TrapDoorBlock.POWERED, false).with(TrapDoorBlock.OPEN, false), 19, 21, 12, start);
        structure.setBlockState(world, Blocks.DIRT.getDefaultState(), 20, 2, 11, start);
        structure.setBlockState(world, Blocks.GRASS_BLOCK.getDefaultState().with(SnowyDirtBlock.SNOWY, false), 20, 3, 11, start);
        structure.fillWithBlocks(world, start, 1, 0, 1, 1, 0, 22, Blocks.GRASS_BLOCK.getDefaultState().with(SnowyDirtBlock.SNOWY, false));
        structure.fillWithBlocks(world, start, 2, 0, 1, 22, 0, 1, Blocks.GRASS_BLOCK.getDefaultState().with(SnowyDirtBlock.SNOWY, false));
        structure.fillWithBlocks(world, start, 2, 0, 2, 21, 0, 21, Blocks.DIRT.getDefaultState());
        structure.fillWithBlocks(world, start, 2, 0, 22, 22, 0, 22, Blocks.GRASS_BLOCK.getDefaultState().with(SnowyDirtBlock.SNOWY, false));
        structure.fillWithBlocks(world, start, 2, 1, 2, 2, 1, 21, Blocks.GRASS_BLOCK.getDefaultState().with(SnowyDirtBlock.SNOWY, false));
        structure.fillWithBlocks(world, start, 3, 1, 2, 21, 1, 2, Blocks.GRASS_BLOCK.getDefaultState().with(SnowyDirtBlock.SNOWY, false));
        structure.fillWithBlocks(world, start, 3, 1, 3, 16, 1, 16, Blocks.DIRT.getDefaultState());
        structure.fillWithBlocks(world, start, 3, 1, 17, 6, 1, 20, Blocks.DIRT.getDefaultState());
        structure.fillWithBlocks(world, start, 3, 1, 21, 21, 1, 21, Blocks.GRASS_BLOCK.getDefaultState().with(SnowyDirtBlock.SNOWY, false));
        structure.fillWithBlocks(world, start, 3, 2, 3, 5, 2, 6, Blocks.GRASS_BLOCK.getDefaultState().with(SnowyDirtBlock.SNOWY, false));
        structure.fillWithBlocks(world, start, 3, 2, 7, 3, 2, 20, Blocks.GRASS_BLOCK.getDefaultState().with(SnowyDirtBlock.SNOWY, false));
        structure.fillWithBlocks(world, start, 4, 2, 8, 8, 2, 12, Blocks.STONE.getDefaultState());
        structure.fillWithBlocks(world, start, 4, 2, 13, 4, 2, 20, Blocks.GRASS_BLOCK.getDefaultState().with(SnowyDirtBlock.SNOWY, false));
        structure.fillWithBlocks(world, start, 4, 3, 9, 6, 3, 11, Blocks.STONE.getDefaultState());
        structure.fillWithBlocks(world, start, 4, 3, 12, 4, 3, 12, Blocks.GRASS_BLOCK.getDefaultState().with(SnowyDirtBlock.SNOWY, false));
        structure.fillWithBlocks(world, start, 4, 3, 14, 4, 3, 15, Blocks.GRASS.getDefaultState());
        structure.fillWithBlocks(world, start, 4, 4, 9, 4, 4, 11, Blocks.GRASS_BLOCK.getDefaultState().with(SnowyDirtBlock.SNOWY, false));
        structure.fillWithBlocks(world, start, 4, 8, 10, 4, 9, 10, Blocks.OAK_LEAVES.getDefaultState().with(LeavesBlock.PERSISTENT, false).with(LeavesBlock.DISTANCE, 2));
        structure.fillWithBlocks(world, start, 4, 8, 11, 4, 9, 11, Blocks.OAK_LEAVES.getDefaultState().with(LeavesBlock.PERSISTENT, false).with(LeavesBlock.DISTANCE, 3));
        structure.fillWithBlocks(world, start, 5, 2, 7, 11, 2, 13, Blocks.STONE.getDefaultState());
        structure.fillWithBlocks(world, start, 5, 2, 15, 5, 2, 20, Blocks.GRASS_BLOCK.getDefaultState().with(SnowyDirtBlock.SNOWY, false));
        structure.fillWithBlocks(world, start, 5, 3, 8, 9, 3, 12, Blocks.STONE.getDefaultState());
        structure.fillWithBlocks(world, start, 5, 3, 13, 5, 3, 14, Blocks.GRASS_BLOCK.getDefaultState().with(SnowyDirtBlock.SNOWY, false));
        structure.fillWithBlocks(world, start, 5, 3, 15, 5, 3, 16, Blocks.GRASS.getDefaultState());
        structure.fillWithBlocks(world, start, 5, 4, 9, 7, 4, 11, Blocks.STONE.getDefaultState());
        structure.fillWithBlocks(world, start, 5, 4, 12, 5, 4, 12, Blocks.GRASS_BLOCK.getDefaultState().with(SnowyDirtBlock.SNOWY, false));
        structure.fillWithBlocks(world, start, 5, 4, 14, 5, 4, 14, Blocks.GRASS.getDefaultState());
        structure.fillWithBlocks(world, start, 5, 5, 9, 5, 5, 11, Blocks.GRASS_BLOCK.getDefaultState().with(SnowyDirtBlock.SNOWY, false));
        structure.fillWithBlocks(world, start, 5, 6, 9, 5, 6, 10, Blocks.GRASS.getDefaultState());
        structure.fillWithBlocks(world, start, 5, 8, 8, 5, 9, 8, Blocks.OAK_LEAVES.getDefaultState().with(LeavesBlock.PERSISTENT, false).with(LeavesBlock.DISTANCE, 3));
        structure.fillWithBlocks(world, start, 5, 8, 9, 5, 9, 9, Blocks.OAK_LEAVES.getDefaultState().with(LeavesBlock.PERSISTENT, false).with(LeavesBlock.DISTANCE, 2));
        structure.fillWithBlocks(world, start, 5, 8, 10, 5, 10, 10, Blocks.OAK_LEAVES.getDefaultState().with(LeavesBlock.PERSISTENT, false).with(LeavesBlock.DISTANCE, 1));
        structure.fillWithBlocks(world, start, 5, 8, 11, 5, 10, 11, Blocks.OAK_LEAVES.getDefaultState().with(LeavesBlock.PERSISTENT, false).with(LeavesBlock.DISTANCE, 2));
        structure.fillWithBlocks(world, start, 5, 8, 12, 5, 9, 12, Blocks.OAK_LEAVES.getDefaultState().with(LeavesBlock.PERSISTENT, false).with(LeavesBlock.DISTANCE, 3));
        structure.fillWithBlocks(world, start, 6, 2, 3, 7, 2, 4, Blocks.GRASS_BLOCK.getDefaultState().with(SnowyDirtBlock.SNOWY, false));
        structure.fillWithBlocks(world, start, 6, 2, 14, 7, 2, 15, Blocks.STONE.getDefaultState());
        structure.fillWithBlocks(world, start, 6, 2, 17, 6, 2, 20, Blocks.GRASS_BLOCK.getDefaultState().with(SnowyDirtBlock.SNOWY, false));
        structure.fillWithBlocks(world, start, 6, 3, 7, 12, 3, 13, Blocks.STONE.getDefaultState());
        structure.fillWithBlocks(world, start, 6, 3, 14, 6, 3, 16, Blocks.GRASS_BLOCK.getDefaultState().with(SnowyDirtBlock.SNOWY, false));
        structure.fillWithBlocks(world, start, 6, 4, 7, 8, 4, 7, Blocks.GRASS_BLOCK.getDefaultState().with(SnowyDirtBlock.SNOWY, false));
        structure.fillWithBlocks(world, start, 6, 4, 8, 10, 4, 12, Blocks.STONE.getDefaultState());
        structure.fillWithBlocks(world, start, 6, 4, 14, 6, 4, 15, Blocks.GRASS.getDefaultState());
        structure.fillWithBlocks(world, start, 6, 5, 8, 6, 5, 9, Blocks.GRASS_BLOCK.getDefaultState().with(SnowyDirtBlock.SNOWY, false));
        structure.fillWithBlocks(world, start, 6, 5, 10, 7, 5, 10, Blocks.DIRT.getDefaultState());
        structure.fillWithBlocks(world, start, 6, 5, 11, 7, 5, 12, Blocks.GRASS_BLOCK.getDefaultState().with(SnowyDirtBlock.SNOWY, false));
        structure.fillWithBlocks(world, start, 6, 6, 10, 6, 10, 10, Blocks.OAK_LOG.getDefaultState());
        structure.fillWithBlocks(world, start, 6, 6, 11, 6, 6, 12, Blocks.GRASS.getDefaultState());
        structure.fillWithBlocks(world, start, 6, 8, 8, 6, 9, 8, Blocks.OAK_LEAVES.getDefaultState().with(LeavesBlock.PERSISTENT, false).with(LeavesBlock.DISTANCE, 2));
        structure.fillWithBlocks(world, start, 6, 8, 9, 6, 11, 9, Blocks.OAK_LEAVES.getDefaultState().with(LeavesBlock.PERSISTENT, false).with(LeavesBlock.DISTANCE, 1));
        structure.fillWithBlocks(world, start, 6, 8, 11, 6, 11, 11, Blocks.OAK_LEAVES.getDefaultState().with(LeavesBlock.PERSISTENT, false).with(LeavesBlock.DISTANCE, 1));
        structure.fillWithBlocks(world, start, 6, 8, 12, 6, 9, 12, Blocks.OAK_LEAVES.getDefaultState().with(LeavesBlock.PERSISTENT, false).with(LeavesBlock.DISTANCE, 2));
        structure.fillWithBlocks(world, start, 6, 11, 10, 6, 11, 11, Blocks.OAK_LEAVES.getDefaultState().with(LeavesBlock.PERSISTENT, false).with(LeavesBlock.DISTANCE, 1));
        structure.fillWithBlocks(world, start, 7, 1, 17, 10, 1, 20, Blocks.DIRT.getDefaultState());
        structure.fillWithBlocks(world, start, 7, 2, 6, 16, 2, 16, Blocks.STONE.getDefaultState());
        structure.fillWithBlocks(world, start, 7, 2, 17, 7, 2, 17, Blocks.STONE.getDefaultState());
        structure.fillWithBlocks(world, start, 7, 2, 18, 7, 2, 20, Blocks.GRASS_BLOCK.getDefaultState().with(SnowyDirtBlock.SNOWY, false));
        structure.fillWithBlocks(world, start, 7, 3, 6, 16, 3, 15, Blocks.STONE.getDefaultState());
        structure.fillWithBlocks(world, start, 7, 3, 16, 7, 3, 16, Blocks.GRAVEL.getDefaultState());
        structure.fillWithBlocks(world, start, 7, 3, 17, 7, 3, 17, Blocks.GRASS_BLOCK.getDefaultState().with(SnowyDirtBlock.SNOWY, false));
        structure.fillWithBlocks(world, start, 7, 4, 6, 8, 4, 7, Blocks.GRASS_BLOCK.getDefaultState().with(SnowyDirtBlock.SNOWY, false));
        structure.fillWithBlocks(world, start, 7, 4, 13, 7, 4, 15, Blocks.GRAVEL.getDefaultState());
        structure.fillWithBlocks(world, start, 7, 5, 6, 7, 5, 7, Blocks.GRASS.getDefaultState());
        structure.fillWithBlocks(world, start, 7, 5, 8, 7, 5, 8, Blocks.GRASS_BLOCK.getDefaultState().with(SnowyDirtBlock.SNOWY, false));
        structure.fillWithBlocks(world, start, 7, 5, 9, 7, 5, 10, Blocks.DIRT.getDefaultState());
        structure.fillWithBlocks(world, start, 7, 8, 8, 7, 9, 8, Blocks.OAK_LEAVES.getDefaultState().with(LeavesBlock.PERSISTENT, false).with(LeavesBlock.DISTANCE, 3));
        structure.fillWithBlocks(world, start, 7, 8, 9, 7, 9, 9, Blocks.OAK_LEAVES.getDefaultState().with(LeavesBlock.PERSISTENT, false).with(LeavesBlock.DISTANCE, 2));
        structure.fillWithBlocks(world, start, 7, 8, 10, 7, 11, 10, Blocks.OAK_LEAVES.getDefaultState().with(LeavesBlock.PERSISTENT, false).with(LeavesBlock.DISTANCE, 1));
        structure.fillWithBlocks(world, start, 7, 8, 11, 7, 10, 11, Blocks.OAK_LEAVES.getDefaultState().with(LeavesBlock.PERSISTENT, false).with(LeavesBlock.DISTANCE, 2));
        structure.fillWithBlocks(world, start, 8, 2, 4, 14, 2, 17, Blocks.STONE.getDefaultState());
        structure.fillWithBlocks(world, start, 8, 2, 18, 8, 2, 18, Blocks.STONE.getDefaultState());
        structure.fillWithBlocks(world, start, 8, 2, 19, 8, 2, 20, Blocks.GRASS_BLOCK.getDefaultState().with(SnowyDirtBlock.SNOWY, false));
        structure.fillWithBlocks(world, start, 8, 3, 5, 17, 3, 15, Blocks.STONE.getDefaultState());
        structure.fillWithBlocks(world, start, 8, 3, 16, 8, 3, 17, Blocks.GRAVEL.getDefaultState());
        structure.fillWithBlocks(world, start, 8, 4, 5, 8, 4, 7, Blocks.GRASS_BLOCK.getDefaultState().with(SnowyDirtBlock.SNOWY, false));
        structure.fillWithBlocks(world, start, 8, 4, 13, 8, 4, 13, Blocks.STONE.getDefaultState());
        structure.fillWithBlocks(world, start, 8, 5, 8, 8, 5, 8, Blocks.GRAVEL.getDefaultState());
        structure.fillWithBlocks(world, start, 8, 8, 9, 8, 9, 9, Blocks.OAK_LEAVES.getDefaultState().with(LeavesBlock.PERSISTENT, false).with(LeavesBlock.DISTANCE, 3));
        structure.fillWithBlocks(world, start, 8, 8, 10, 8, 9, 10, Blocks.OAK_LEAVES.getDefaultState().with(LeavesBlock.PERSISTENT, false).with(LeavesBlock.DISTANCE, 2));
        structure.fillWithBlocks(world, start, 8, 8, 11, 8, 9, 11, Blocks.OAK_LEAVES.getDefaultState().with(LeavesBlock.PERSISTENT, false).with(LeavesBlock.DISTANCE, 3));
        structure.fillWithBlocks(world, start, 9, 2, 3, 13, 2, 17, Blocks.STONE.getDefaultState());
        structure.fillWithBlocks(world, start, 9, 2, 18, 10, 2, 20, Blocks.STONE.getDefaultState());
        structure.fillWithBlocks(world, start, 9, 3, 4, 13, 3, 16, Blocks.STONE.getDefaultState());
        structure.fillWithBlocks(world, start, 9, 3, 17, 9, 3, 18, Blocks.GRAVEL.getDefaultState());
        structure.fillWithBlocks(world, start, 9, 3, 19, 10, 3, 19, Blocks.COBBLESTONE_SLAB.getDefaultState().with(SlabBlock.TYPE, SlabType.BOTTOM).with(SlabBlock.WATERLOGGED, false));
        structure.fillWithBlocks(world, start, 9, 4, 5, 13, 4, 14, Blocks.STONE.getDefaultState());
        structure.fillWithBlocks(world, start, 9, 4, 15, 9, 4, 16, Blocks.GRASS_BLOCK.getDefaultState().with(SnowyDirtBlock.SNOWY, false));
        structure.fillWithBlocks(world, start, 9, 5, 5, 10, 5, 6, Blocks.GRASS_BLOCK.getDefaultState().with(SnowyDirtBlock.SNOWY, false));
        structure.fillWithBlocks(world, start, 9, 5, 7, 9, 5, 7, Blocks.GRAVEL.getDefaultState());
        structure.fillWithBlocks(world, start, 9, 5, 9, 9, 5, 10, Blocks.GRAVEL.getDefaultState());
        structure.fillWithBlocks(world, start, 9, 5, 12, 9, 5, 12, Blocks.GRASS_BLOCK.getDefaultState().with(SnowyDirtBlock.SNOWY, false));
        structure.fillWithBlocks(world, start, 9, 5, 14, 9, 5, 14, Blocks.GRASS_BLOCK.getDefaultState().with(SnowyDirtBlock.SNOWY, false));
        structure.fillWithBlocks(world, start, 9, 6, 5, 10, 6, 6, Blocks.GRASS.getDefaultState());
        structure.fillWithBlocks(world, start, 9, 6, 14, 9, 6, 14, Blocks.GRASS.getDefaultState());
        structure.fillWithBlocks(world, start, 9, 22, 9, 9, 22, 13, Blocks.STONE_BRICKS.getDefaultState());
        structure.fillWithBlocks(world, start, 10, 3, 3, 12, 3, 17, Blocks.STONE.getDefaultState());
        structure.fillWithBlocks(world, start, 10, 4, 3, 12, 4, 3, Blocks.GRASS_BLOCK.getDefaultState().with(SnowyDirtBlock.SNOWY, false));
        structure.fillWithBlocks(world, start, 10, 4, 4, 12, 4, 16, Blocks.STONE.getDefaultState());
        structure.fillWithBlocks(world, start, 10, 4, 17, 10, 4, 17, Blocks.GRASS_BLOCK.getDefaultState().with(SnowyDirtBlock.SNOWY, false));
        structure.fillWithBlocks(world, start, 10, 5, 4, 11, 5, 6, Blocks.GRASS_BLOCK.getDefaultState().with(SnowyDirtBlock.SNOWY, false));
        structure.fillWithBlocks(world, start, 10, 5, 9, 10, 5, 10, Blocks.SMOOTH_STONE_SLAB.getDefaultState().with(SlabBlock.TYPE, SlabType.DOUBLE).with(SlabBlock.WATERLOGGED, false));
        structure.fillWithBlocks(world, start, 10, 5, 12, 10, 5, 16, Blocks.GRASS_BLOCK.getDefaultState().with(SnowyDirtBlock.SNOWY, false));
        structure.fillWithBlocks(world, start, 10, 6, 4, 10, 6, 6, Blocks.GRASS.getDefaultState());
        structure.fillWithBlocks(world, start, 10, 6, 15, 11, 6, 16, Blocks.GRASS.getDefaultState());
        structure.fillWithBlocks(world, start, 10, 18, 10, 10, 18, 12, Blocks.SPRUCE_PLANKS.getDefaultState());
        structure.fillWithBlocks(world, start, 10, 19, 9, 10, 22, 9, Blocks.SPRUCE_PLANKS.getDefaultState());
        structure.fillWithBlocks(world, start, 10, 19, 11, 10, 22, 11, Blocks.SPRUCE_PLANKS.getDefaultState());
        structure.fillWithBlocks(world, start, 10, 19, 13, 10, 22, 13, Blocks.SPRUCE_PLANKS.getDefaultState());
        structure.fillWithBlocks(world, start, 10, 21, 12, 10, 21, 12, Blocks.OAK_PLANKS.getDefaultState());
        structure.fillWithBlocks(world, start, 10, 22, 10, 10, 22, 13, Blocks.SPRUCE_PLANKS.getDefaultState());
        structure.fillWithBlocks(world, start, 10, 23, 9, 10, 23, 13, Blocks.STONE_BRICKS.getDefaultState());
        structure.fillWithBlocks(world, start, 11, 1, 17, 14, 1, 20, Blocks.DIRT.getDefaultState());
        structure.fillWithBlocks(world, start, 11, 2, 18, 12, 2, 18, Blocks.STONE.getDefaultState());
        structure.fillWithBlocks(world, start, 11, 2, 19, 12, 2, 20, Blocks.GRASS_BLOCK.getDefaultState().with(SnowyDirtBlock.SNOWY, false));
        structure.fillWithBlocks(world, start, 11, 3, 20, 12, 3, 20, Blocks.GRASS.getDefaultState());
        structure.fillWithBlocks(world, start, 11, 5, 7, 11, 5, 7, Blocks.GRAVEL.getDefaultState());
        structure.fillWithBlocks(world, start, 11, 5, 9, 11, 5, 9, Blocks.DIRT.getDefaultState());
        structure.fillWithBlocks(world, start, 11, 5, 11, 11, 5, 11, Blocks.DIRT.getDefaultState());
        structure.fillWithBlocks(world, start, 11, 5, 13, 11, 5, 13, Blocks.DIRT.getDefaultState());
        structure.fillWithBlocks(world, start, 11, 5, 14, 11, 5, 17, Blocks.GRASS_BLOCK.getDefaultState().with(SnowyDirtBlock.SNOWY, false));
        structure.fillWithBlocks(world, start, 11, 6, 5, 11, 6, 6, Blocks.GRASS.getDefaultState());
        structure.fillWithBlocks(world, start, 11, 18, 10, 12, 18, 12, Blocks.OAK_PLANKS.getDefaultState());
        structure.fillWithBlocks(world, start, 11, 18, 13, 11, 18, 13, Blocks.SPRUCE_PLANKS.getDefaultState());
        structure.fillWithBlocks(world, start, 11, 21, 13, 11, 21, 13, Blocks.OAK_PLANKS.getDefaultState());
        structure.fillWithBlocks(world, start, 11, 22, 13, 11, 22, 13, Blocks.SPRUCE_PLANKS.getDefaultState());
        structure.fillWithBlocks(world, start, 11, 23, 10, 11, 23, 12, Blocks.OAK_STAIRS.getDefaultState().with(StairsBlock.FACING, Direction.WEST).with(StairsBlock.WATERLOGGED, false).with(StairsBlock.SHAPE, StairsShape.STRAIGHT).with(StairsBlock.HALF, Half.TOP));
        structure.fillWithBlocks(world, start, 11, 23, 13, 11, 23, 13, Blocks.OAK_PLANKS.getDefaultState());
        structure.fillWithBlocks(world, start, 11, 23, 14, 11, 23, 14, Blocks.STONE_BRICKS.getDefaultState());
        structure.fillWithBlocks(world, start, 11, 24, 9, 11, 24, 13, Blocks.STONE_BRICKS.getDefaultState());
        structure.fillWithBlocks(world, start, 11, 28, 9, 11, 28, 13, Blocks.STONE_BRICKS.getDefaultState());
        structure.fillWithBlocks(world, start, 11, 30, 10, 12, 30, 10, Blocks.STONE_BRICKS.getDefaultState());
        structure.fillWithBlocks(world, start, 11, 30, 12, 12, 30, 12, Blocks.STONE_BRICKS.getDefaultState());
        structure.fillWithBlocks(world, start, 11, 31, 11, 12, 31, 11, Blocks.NETHER_BRICKS.getDefaultState());
        structure.fillWithBlocks(world, start, 12, 5, 4, 12, 5, 4, Blocks.GRASS_BLOCK.getDefaultState().with(SnowyDirtBlock.SNOWY, false));
        structure.fillWithBlocks(world, start, 12, 5, 7, 13, 5, 7, Blocks.SMOOTH_STONE_SLAB.getDefaultState().with(SlabBlock.TYPE, SlabType.DOUBLE).with(SlabBlock.WATERLOGGED, false));
        structure.fillWithBlocks(world, start, 12, 5, 8, 13, 5, 8, Blocks.GRAVEL.getDefaultState());
        structure.fillWithBlocks(world, start, 12, 5, 9, 12, 5, 14, Blocks.DIRT.getDefaultState());
        structure.fillWithBlocks(world, start, 12, 5, 15, 12, 5, 16, Blocks.GRASS_BLOCK.getDefaultState().with(SnowyDirtBlock.SNOWY, false));
        structure.fillWithBlocks(world, start, 12, 6, 4, 12, 6, 4, Blocks.GRASS.getDefaultState());
        structure.fillWithBlocks(world, start, 12, 6, 9, 12, 7, 9, Blocks.MOSSY_STONE_BRICKS.getDefaultState());
        structure.fillWithBlocks(world, start, 12, 6, 10, 12, 7, 11, Blocks.COBBLESTONE.getDefaultState());
        structure.fillWithBlocks(world, start, 12, 6, 15, 17, 6, 15, Blocks.GRASS.getDefaultState());
        structure.fillWithBlocks(world, start, 12, 7, 12, 12, 8, 12, Blocks.MOSSY_COBBLESTONE.getDefaultState());
        structure.fillWithBlocks(world, start, 12, 8, 9, 12, 17, 9, Blocks.STONE_BRICKS.getDefaultState());
        structure.fillWithBlocks(world, start, 12, 8, 10, 12, 17, 10, Blocks.COBBLESTONE.getDefaultState());
        structure.fillWithBlocks(world, start, 12, 8, 13, 12, 17, 13, Blocks.STONE_BRICKS.getDefaultState());
        structure.fillWithBlocks(world, start, 12, 9, 12, 12, 17, 12, Blocks.COBBLESTONE.getDefaultState());
        structure.fillWithBlocks(world, start, 12, 12, 11, 12, 13, 12, Blocks.COBBLESTONE.getDefaultState());
        structure.fillWithBlocks(world, start, 12, 18, 9, 12, 18, 13, Blocks.OAK_PLANKS.getDefaultState());
        structure.fillWithBlocks(world, start, 12, 18, 14, 12, 18, 14, Blocks.SPRUCE_PLANKS.getDefaultState());
        structure.fillWithBlocks(world, start, 12, 19, 7, 12, 22, 7, Blocks.SPRUCE_PLANKS.getDefaultState());
        structure.fillWithBlocks(world, start, 12, 19, 11, 12, 28, 11, Blocks.SPRUCE_PLANKS.getDefaultState());
        structure.fillWithBlocks(world, start, 12, 19, 13, 12, 20, 13, Blocks.CAULDRON.getDefaultState().with(CauldronBlock.LEVEL, 0));
        structure.fillWithBlocks(world, start, 12, 19, 15, 12, 22, 15, Blocks.SPRUCE_PLANKS.getDefaultState());
        structure.fillWithBlocks(world, start, 12, 21, 14, 12, 21, 14, Blocks.OAK_PLANKS.getDefaultState());
        structure.fillWithBlocks(world, start, 12, 22, 6, 16, 22, 6, Blocks.STONE_BRICKS.getDefaultState());
        structure.fillWithBlocks(world, start, 12, 22, 14, 12, 22, 15, Blocks.SPRUCE_PLANKS.getDefaultState());
        structure.fillWithBlocks(world, start, 12, 22, 16, 16, 22, 16, Blocks.STONE_BRICKS.getDefaultState());
        structure.fillWithBlocks(world, start, 12, 23, 7, 16, 23, 7, Blocks.STONE_BRICKS.getDefaultState());
        structure.fillWithBlocks(world, start, 12, 23, 15, 16, 23, 15, Blocks.STONE_BRICKS.getDefaultState());
        structure.fillWithBlocks(world, start, 12, 24, 8, 16, 24, 8, Blocks.STONE_BRICKS.getDefaultState());
        structure.fillWithBlocks(world, start, 12, 24, 9, 12, 28, 9, Blocks.SPRUCE_PLANKS.getDefaultState());
        structure.fillWithBlocks(world, start, 12, 24, 13, 12, 28, 13, Blocks.SPRUCE_PLANKS.getDefaultState());
        structure.fillWithBlocks(world, start, 12, 24, 14, 16, 24, 14, Blocks.STONE_BRICKS.getDefaultState());
        structure.fillWithBlocks(world, start, 12, 28, 8, 16, 28, 8, Blocks.STONE_BRICKS.getDefaultState());
        structure.fillWithBlocks(world, start, 12, 28, 10, 12, 28, 13, Blocks.SPRUCE_PLANKS.getDefaultState());
        structure.fillWithBlocks(world, start, 12, 28, 14, 16, 28, 14, Blocks.STONE_BRICKS.getDefaultState());
        structure.fillWithBlocks(world, start, 12, 29, 9, 12, 29, 10, Blocks.STONE_BRICKS.getDefaultState());
        structure.fillWithBlocks(world, start, 12, 29, 12, 12, 29, 13, Blocks.STONE_BRICKS.getDefaultState());
        structure.fillWithBlocks(world, start, 13, 2, 18, 15, 2, 20, Blocks.GRASS_BLOCK.getDefaultState().with(SnowyDirtBlock.SNOWY, false));
        structure.fillWithBlocks(world, start, 13, 3, 3, 13, 3, 3, Blocks.GRASS_BLOCK.getDefaultState().with(SnowyDirtBlock.SNOWY, false));
        structure.fillWithBlocks(world, start, 13, 4, 15, 13, 4, 15, Blocks.STONE.getDefaultState());
        structure.fillWithBlocks(world, start, 13, 4, 16, 13, 4, 16, Blocks.GRASS_BLOCK.getDefaultState().with(SnowyDirtBlock.SNOWY, false));
        structure.fillWithBlocks(world, start, 13, 5, 5, 13, 5, 5, Blocks.GRASS_BLOCK.getDefaultState().with(SnowyDirtBlock.SNOWY, false));
        structure.fillWithBlocks(world, start, 13, 5, 10, 15, 5, 12, Blocks.SMOOTH_STONE_SLAB.getDefaultState().with(SlabBlock.TYPE, SlabType.DOUBLE).with(SlabBlock.WATERLOGGED, false));
        structure.fillWithBlocks(world, start, 13, 5, 13, 17, 5, 13, Blocks.DIRT.getDefaultState());
        structure.fillWithBlocks(world, start, 13, 5, 14, 14, 5, 15, Blocks.GRASS_BLOCK.getDefaultState().with(SnowyDirtBlock.SNOWY, false));
        structure.fillWithBlocks(world, start, 13, 5, 16, 13, 5, 16, Blocks.GRASS.getDefaultState());
        structure.fillWithBlocks(world, start, 13, 6, 5, 13, 6, 5, Blocks.GRASS.getDefaultState());
        structure.fillWithBlocks(world, start, 13, 6, 11, 13, 6, 12, Blocks.MAGENTA_WOOL.getDefaultState());
        structure.fillWithBlocks(world, start, 13, 7, 9, 13, 17, 9, Blocks.COBBLESTONE.getDefaultState());
        structure.fillWithBlocks(world, start, 13, 7, 13, 13, 17, 13, Blocks.COBBLESTONE.getDefaultState());
        structure.fillWithBlocks(world, start, 13, 8, 10, 15, 8, 12, Blocks.STONE_BRICKS.getDefaultState());
        structure.fillWithBlocks(world, start, 13, 12, 10, 14, 12, 10, Blocks.SMOOTH_STONE_SLAB.getDefaultState().with(SlabBlock.TYPE, SlabType.BOTTOM).with(SlabBlock.WATERLOGGED, false));
        structure.fillWithBlocks(world, start, 13, 13, 10, 13, 14, 10, Blocks.LADDER.getDefaultState().with(LadderBlock.FACING, Direction.EAST).with(LadderBlock.WATERLOGGED, false));
        structure.fillWithBlocks(world, start, 13, 14, 11, 14, 14, 12, Blocks.PETRIFIED_OAK_SLAB.getDefaultState().with(SlabBlock.TYPE, SlabType.TOP).with(SlabBlock.WATERLOGGED, false));
        structure.fillWithBlocks(world, start, 13, 18, 7, 15, 18, 7, Blocks.SPRUCE_PLANKS.getDefaultState());
        structure.fillWithBlocks(world, start, 13, 18, 8, 14, 18, 9, Blocks.OAK_PLANKS.getDefaultState());
        structure.fillWithBlocks(world, start, 13, 18, 10, 14, 18, 12, Blocks.PETRIFIED_OAK_SLAB.getDefaultState().with(SlabBlock.TYPE, SlabType.TOP).with(SlabBlock.WATERLOGGED, false));
        structure.fillWithBlocks(world, start, 13, 18, 13, 14, 18, 14, Blocks.OAK_PLANKS.getDefaultState());
        structure.fillWithBlocks(world, start, 13, 18, 15, 15, 18, 15, Blocks.SPRUCE_PLANKS.getDefaultState());
        structure.fillWithBlocks(world, start, 13, 20, 11, 13, 24, 11, Blocks.LADDER.getDefaultState().with(LadderBlock.FACING, Direction.EAST).with(LadderBlock.WATERLOGGED, false));
        structure.fillWithBlocks(world, start, 13, 22, 7, 16, 22, 7, Blocks.SPRUCE_PLANKS.getDefaultState());
        structure.fillWithBlocks(world, start, 13, 22, 15, 16, 22, 15, Blocks.SPRUCE_PLANKS.getDefaultState());
        structure.fillWithBlocks(world, start, 13, 23, 8, 15, 23, 8, Blocks.OAK_STAIRS.getDefaultState().with(StairsBlock.FACING, Direction.NORTH).with(StairsBlock.WATERLOGGED, false).with(StairsBlock.SHAPE, StairsShape.STRAIGHT).with(StairsBlock.HALF, Half.TOP));
        structure.fillWithBlocks(world, start, 13, 23, 14, 15, 23, 14, Blocks.OAK_STAIRS.getDefaultState().with(StairsBlock.FACING, Direction.SOUTH).with(StairsBlock.WATERLOGGED, false).with(StairsBlock.SHAPE, StairsShape.STRAIGHT).with(StairsBlock.HALF, Half.TOP));
        structure.fillWithBlocks(world, start, 13, 24, 9, 15, 24, 9, Blocks.OAK_STAIRS.getDefaultState().with(StairsBlock.FACING, Direction.NORTH).with(StairsBlock.WATERLOGGED, false).with(StairsBlock.SHAPE, StairsShape.STRAIGHT).with(StairsBlock.HALF, Half.TOP));
        structure.fillWithBlocks(world, start, 13, 24, 10, 13, 24, 10, Blocks.PETRIFIED_OAK_SLAB.getDefaultState().with(SlabBlock.TYPE, SlabType.TOP).with(SlabBlock.WATERLOGGED, false));
        structure.fillWithBlocks(world, start, 13, 24, 12, 15, 24, 12, Blocks.PETRIFIED_OAK_SLAB.getDefaultState().with(SlabBlock.TYPE, SlabType.TOP).with(SlabBlock.WATERLOGGED, false));
        structure.fillWithBlocks(world, start, 13, 24, 13, 15, 24, 13, Blocks.OAK_STAIRS.getDefaultState().with(StairsBlock.FACING, Direction.SOUTH).with(StairsBlock.WATERLOGGED, false).with(StairsBlock.SHAPE, StairsShape.STRAIGHT).with(StairsBlock.HALF, Half.TOP));
        structure.fillWithBlocks(world, start, 13, 28, 9, 16, 28, 9, Blocks.SPRUCE_PLANKS.getDefaultState());
        structure.fillWithBlocks(world, start, 13, 28, 13, 16, 28, 13, Blocks.SPRUCE_PLANKS.getDefaultState());
        structure.fillWithBlocks(world, start, 13, 29, 9, 13, 30, 9, Blocks.STONE_BRICKS.getDefaultState());
        structure.fillWithBlocks(world, start, 13, 29, 13, 13, 30, 13, Blocks.STONE_BRICKS.getDefaultState());
        structure.fillWithBlocks(world, start, 13, 30, 8, 13, 30, 9, Blocks.STONE_BRICKS.getDefaultState());
        structure.fillWithBlocks(world, start, 13, 30, 11, 13, 30, 11, Blocks.NETHER_BRICKS.getDefaultState());
        structure.fillWithBlocks(world, start, 13, 31, 10, 13, 31, 12, Blocks.STONE_BRICKS.getDefaultState());
        structure.fillWithBlocks(world, start, 13, 32, 11, 13, 32, 11, Blocks.STONE_BRICKS.getDefaultState());
        structure.fillWithBlocks(world, start, 14, 2, 3, 20, 2, 3, Blocks.GRASS_BLOCK.getDefaultState().with(SnowyDirtBlock.SNOWY, false));
        structure.fillWithBlocks(world, start, 14, 3, 4, 15, 3, 4, Blocks.GRASS_BLOCK.getDefaultState().with(SnowyDirtBlock.SNOWY, false));
        structure.fillWithBlocks(world, start, 14, 3, 16, 15, 3, 17, Blocks.STONE.getDefaultState());
        structure.fillWithBlocks(world, start, 14, 4, 5, 16, 4, 9, Blocks.STONE.getDefaultState());
        structure.fillWithBlocks(world, start, 14, 4, 10, 14, 5, 10, Blocks.SMOOTH_STONE_SLAB.getDefaultState().with(SlabBlock.TYPE, SlabType.DOUBLE).with(SlabBlock.WATERLOGGED, false));
        structure.fillWithBlocks(world, start, 14, 4, 11, 14, 4, 16, Blocks.STONE.getDefaultState());
        structure.fillWithBlocks(world, start, 14, 4, 17, 16, 4, 17, Blocks.GRASS_BLOCK.getDefaultState().with(SnowyDirtBlock.SNOWY, false));
        structure.fillWithBlocks(world, start, 14, 5, 5, 15, 5, 6, Blocks.GRASS_BLOCK.getDefaultState().with(SnowyDirtBlock.SNOWY, false));
        structure.fillWithBlocks(world, start, 14, 5, 8, 14, 5, 12, Blocks.SMOOTH_STONE_SLAB.getDefaultState().with(SlabBlock.TYPE, SlabType.DOUBLE).with(SlabBlock.WATERLOGGED, false));
        structure.fillWithBlocks(world, start, 14, 5, 16, 16, 5, 16, Blocks.GRASS_BLOCK.getDefaultState().with(SnowyDirtBlock.SNOWY, false));
        structure.fillWithBlocks(world, start, 14, 6, 5, 15, 6, 6, Blocks.GRASS.getDefaultState());
        structure.fillWithBlocks(world, start, 14, 6, 13, 15, 6, 13, Blocks.COBBLESTONE.getDefaultState());
        structure.fillWithBlocks(world, start, 14, 6, 14, 15, 6, 16, Blocks.GRASS.getDefaultState());
        structure.fillWithBlocks(world, start, 14, 8, 13, 15, 9, 13, Blocks.COBBLESTONE.getDefaultState());
        structure.fillWithBlocks(world, start, 14, 10, 13, 15, 11, 13, Blocks.COBBLESTONE.getDefaultState());
        structure.fillWithBlocks(world, start, 14, 11, 9, 14, 11, 9, Blocks.SMOOTH_STONE_SLAB.getDefaultState().with(SlabBlock.TYPE, SlabType.DOUBLE).with(SlabBlock.WATERLOGGED, false));
        structure.fillWithBlocks(world, start, 14, 12, 9, 15, 13, 9, Blocks.COBBLESTONE.getDefaultState());
        structure.fillWithBlocks(world, start, 14, 12, 13, 15, 13, 13, Blocks.COBBLESTONE.getDefaultState());
        structure.fillWithBlocks(world, start, 14, 14, 10, 15, 14, 12, Blocks.PETRIFIED_OAK_SLAB.getDefaultState().with(SlabBlock.TYPE, SlabType.TOP).with(SlabBlock.WATERLOGGED, false));
        structure.fillWithBlocks(world, start, 14, 19, 7, 14, 22, 7, Blocks.SPRUCE_PLANKS.getDefaultState());
        structure.fillWithBlocks(world, start, 14, 19, 15, 14, 22, 15, Blocks.SPRUCE_PLANKS.getDefaultState());
        structure.fillWithBlocks(world, start, 14, 24, 10, 15, 24, 12, Blocks.PETRIFIED_OAK_SLAB.getDefaultState().with(SlabBlock.TYPE, SlabType.TOP).with(SlabBlock.WATERLOGGED, false));
        structure.fillWithBlocks(world, start, 14, 25, 9, 14, 28, 9, Blocks.SPRUCE_PLANKS.getDefaultState());
        structure.fillWithBlocks(world, start, 14, 25, 13, 14, 28, 13, Blocks.SPRUCE_PLANKS.getDefaultState());
        structure.fillWithBlocks(world, start, 14, 30, 10, 14, 30, 12, Blocks.NETHER_BRICKS.getDefaultState());
        structure.fillWithBlocks(world, start, 14, 31, 8, 14, 31, 9, Blocks.NETHER_BRICKS.getDefaultState());
        structure.fillWithBlocks(world, start, 14, 31, 10, 14, 31, 10, Blocks.STONE_BRICKS.getDefaultState());
        structure.fillWithBlocks(world, start, 14, 31, 12, 15, 31, 12, Blocks.STONE_BRICKS.getDefaultState());
        structure.fillWithBlocks(world, start, 14, 31, 13, 14, 31, 14, Blocks.NETHER_BRICKS.getDefaultState());
        structure.fillWithBlocks(world, start, 14, 32, 10, 14, 32, 10, Blocks.STONE_BRICKS.getDefaultState());
        structure.fillWithBlocks(world, start, 14, 35, 11, 14, 36, 11, Blocks.OAK_FENCE.getDefaultState().with(FourWayBlock.WATERLOGGED, false).with(FourWayBlock.NORTH, false).with(FourWayBlock.SOUTH, false).with(FourWayBlock.EAST, true).with(FourWayBlock.WEST, false));
        structure.fillWithBlocks(world, start, 15, 1, 17, 15, 1, 20, Blocks.DIRT.getDefaultState());
        structure.fillWithBlocks(world, start, 15, 2, 5, 17, 2, 15, Blocks.STONE.getDefaultState());
        structure.fillWithBlocks(world, start, 15, 2, 17, 15, 3, 17, Blocks.STONE.getDefaultState());
        structure.fillWithBlocks(world, start, 15, 4, 10, 15, 4, 10, Blocks.STONE.getDefaultState());
        structure.fillWithBlocks(world, start, 15, 4, 12, 17, 4, 15, Blocks.STONE.getDefaultState());
        structure.fillWithBlocks(world, start, 15, 4, 16, 16, 4, 16, Blocks.STONE.getDefaultState());
        structure.fillWithBlocks(world, start, 15, 5, 7, 16, 5, 9, Blocks.DIRT.getDefaultState());
        structure.fillWithBlocks(world, start, 15, 5, 14, 15, 5, 16, Blocks.GRASS_BLOCK.getDefaultState().with(SnowyDirtBlock.SNOWY, false));
        structure.fillWithBlocks(world, start, 15, 6, 7, 16, 6, 7, Blocks.COBBLESTONE.getDefaultState());
        structure.fillWithBlocks(world, start, 15, 6, 9, 15, 17, 9, Blocks.COBBLESTONE.getDefaultState());
        structure.fillWithBlocks(world, start, 15, 6, 11, 15, 6, 12, Blocks.CAULDRON.getDefaultState().with(CauldronBlock.LEVEL, 0));
        structure.fillWithBlocks(world, start, 15, 7, 13, 15, 17, 13, Blocks.COBBLESTONE.getDefaultState());
        structure.fillWithBlocks(world, start, 15, 16, 12, 15, 18, 12, Blocks.LADDER.getDefaultState().with(LadderBlock.FACING, Direction.NORTH).with(LadderBlock.WATERLOGGED, false));
        structure.fillWithBlocks(world, start, 15, 18, 8, 15, 18, 9, Blocks.OAK_PLANKS.getDefaultState());
        structure.fillWithBlocks(world, start, 15, 18, 10, 15, 18, 11, Blocks.PETRIFIED_OAK_SLAB.getDefaultState().with(SlabBlock.TYPE, SlabType.TOP).with(SlabBlock.WATERLOGGED, false));
        structure.fillWithBlocks(world, start, 15, 18, 13, 15, 18, 14, Blocks.OAK_PLANKS.getDefaultState());
        structure.fillWithBlocks(world, start, 15, 21, 7, 15, 21, 7, Blocks.OAK_PLANKS.getDefaultState());
        structure.fillWithBlocks(world, start, 15, 29, 9, 15, 29, 9, Blocks.STONE_BRICKS.getDefaultState());
        structure.fillWithBlocks(world, start, 15, 29, 13, 16, 29, 13, Blocks.STONE_BRICKS.getDefaultState());
        structure.fillWithBlocks(world, start, 15, 30, 8, 15, 30, 9, Blocks.STONE_BRICKS.getDefaultState());
        structure.fillWithBlocks(world, start, 15, 30, 13, 15, 30, 14, Blocks.STONE_BRICKS.getDefaultState());
        structure.fillWithBlocks(world, start, 15, 31, 10, 15, 31, 12, Blocks.STONE_BRICKS.getDefaultState());
        structure.fillWithBlocks(world, start, 15, 35, 11, 15, 35, 11, Blocks.WHITE_WOOL.getDefaultState());
        structure.fillWithBlocks(world, start, 15, 36, 11, 15, 36, 11, Blocks.STONE_BRICKS.getDefaultState());
        structure.fillWithBlocks(world, start, 16, 1, 17, 17, 1, 17, Blocks.GRASS_BLOCK.getDefaultState().with(SnowyDirtBlock.SNOWY, false));
        structure.fillWithBlocks(world, start, 16, 1, 18, 18, 1, 20, Blocks.DIRT.getDefaultState());
        structure.fillWithBlocks(world, start, 16, 2, 4, 20, 2, 4, Blocks.GRASS_BLOCK.getDefaultState().with(SnowyDirtBlock.SNOWY, false));
        structure.fillWithBlocks(world, start, 16, 2, 18, 18, 2, 20, Blocks.GRASS_BLOCK.getDefaultState().with(SnowyDirtBlock.SNOWY, false));
        structure.fillWithBlocks(world, start, 16, 3, 16, 16, 3, 17, Blocks.STONE.getDefaultState());
        structure.fillWithBlocks(world, start, 16, 4, 10, 18, 4, 13, Blocks.STONE.getDefaultState());
        structure.fillWithBlocks(world, start, 16, 5, 5, 16, 5, 6, Blocks.GRASS_BLOCK.getDefaultState().with(SnowyDirtBlock.SNOWY, false));
        structure.fillWithBlocks(world, start, 16, 5, 10, 16, 5, 14, Blocks.DIRT.getDefaultState());
        structure.fillWithBlocks(world, start, 16, 5, 15, 16, 5, 16, Blocks.GRASS_BLOCK.getDefaultState().with(SnowyDirtBlock.SNOWY, false));
        structure.fillWithBlocks(world, start, 16, 6, 9, 16, 17, 9, Blocks.STONE_BRICKS.getDefaultState());
        structure.fillWithBlocks(world, start, 16, 6, 10, 16, 7, 12, Blocks.COBBLESTONE.getDefaultState());
        structure.fillWithBlocks(world, start, 16, 7, 7, 18, 7, 7, Blocks.COBBLESTONE.getDefaultState());
        structure.fillWithBlocks(world, start, 16, 8, 10, 16, 8, 13, Blocks.STONE_BRICKS.getDefaultState());
        structure.fillWithBlocks(world, start, 16, 9, 10, 16, 10, 10, Blocks.STONE_BRICKS.getDefaultState());
        structure.fillWithBlocks(world, start, 16, 9, 12, 16, 10, 12, Blocks.STONE_BRICKS.getDefaultState());
        structure.fillWithBlocks(world, start, 16, 10, 13, 16, 17, 13, Blocks.STONE_BRICKS.getDefaultState());
        structure.fillWithBlocks(world, start, 16, 11, 10, 16, 17, 10, Blocks.COBBLESTONE.getDefaultState());
