package mod.arcalitegames.odyssey.world.structure.structures.dungeons.desert_pyramid;

import mod.arcalitegames.odyssey.world.structure.StructureBase;
import net.minecraft.block.Blocks;
import net.minecraft.block.FourWayBlock;
import net.minecraft.block.RedstoneWireBlock;
import net.minecraft.block.StairsBlock;
import net.minecraft.state.properties.Half;
import net.minecraft.state.properties.RedstoneSide;
import net.minecraft.state.properties.StairsShape;
import net.minecraft.util.Direction;
import net.minecraft.util.math.BlockPos;
import net.minecraft.world.World;

public class PyramidComponent1
{

	public static BlockPos start;
    public static World world;
    public static StructureBase structure;

    public static void init(World worldIn, BlockPos blockPos, StructureBase structureIn)
    {
        world = worldIn; start = blockPos; structure = structureIn;
    }
    
    public static void generatePart11()
    {
        structure.fillWithBlocks(world, start, -38, -33, -8, -37, -33, -6, Blocks.STONE_BRICKS.getDefaultState());
        structure.fillWithBlocks(world, start, -38, -33, -5, -38, -33, -4, Blocks.AIR.getDefaultState());
        structure.fillWithBlocks(world, start, -38, -33, -2, -32, -32, -2, Blocks.STONE_BRICKS.getDefaultState());
        structure.fillWithBlocks(world, start, -38, -33, -1, -37, -33, -1, Blocks.AIR.getDefaultState());
        structure.fillWithBlocks(world, start, -38, -33, 0, -38, -32, 16, Blocks.STONE_BRICKS.getDefaultState());
        structure.fillWithBlocks(world, start, -38, -32, -25, -37, -32, -24, Blocks.STONE_BRICKS.getDefaultState());
        structure.fillWithBlocks(world, start, -38, -32, -23, -38, -32, -8, Blocks.STONE_BRICKS.getDefaultState());
        structure.fillWithBlocks(world, start, -38, -32, -7, -37, -32, -7, Blocks.AIR.getDefaultState());
        structure.fillWithBlocks(world, start, -38, -32, -3, -38, -32, 16, Blocks.STONE_BRICKS.getDefaultState());
        structure.fillWithBlocks(world, start, -38, -31, -30, -37, -31, -26, Blocks.STONE_BRICKS.getDefaultState());
        structure.fillWithBlocks(world, start, -38, -31, -24, -38, -31, -24, Blocks.STONE_BRICKS.getDefaultState());
        structure.fillWithBlocks(world, start, -38, -31, -20, -36, -31, -18, Blocks.STONE_BRICKS.getDefaultState());
        structure.fillWithBlocks(world, start, -38, -31, -17, -38, -31, -17, Blocks.STONE_BRICKS.getDefaultState());
        structure.fillWithBlocks(world, start, -38, -31, -15, -36, -31, -12, Blocks.STONE_BRICKS.getDefaultState());
        structure.fillWithBlocks(world, start, -38, -31, -10, -38, -31, -10, Blocks.STONE_BRICKS.getDefaultState());
        structure.fillWithBlocks(world, start, -38, -31, -8, -38, -31, -5, Blocks.STONE_BRICKS.getDefaultState());
        structure.fillWithBlocks(world, start, -38, -31, -3, -37, -31, 1, Blocks.STONE_BRICKS.getDefaultState());
        structure.fillWithBlocks(world, start, -38, -31, 2, -38, -31, 2, Blocks.AIR.getDefaultState());
        structure.fillWithBlocks(world, start, -38, -31, 4, -37, -31, 7, Blocks.STONE_BRICKS.getDefaultState());
        structure.fillWithBlocks(world, start, -38, -31, 9, -35, -31, 12, Blocks.STONE_BRICKS.getDefaultState());
        structure.fillWithBlocks(world, start, -38, -31, 14, -37, -31, 16, Blocks.STONE_BRICKS.getDefaultState());
        structure.fillWithBlocks(world, start, -38, -30, -53, -37, -30, -52, Blocks.SANDSTONE.getDefaultState());
        structure.fillWithBlocks(world, start, -38, -30, -51, -38, -30, -50, Blocks.DIRT.getDefaultState());
        structure.fillWithBlocks(world, start, -38, -30, -49, -38, -30, -5, Blocks.SANDSTONE.getDefaultState());
        structure.fillWithBlocks(world, start, -38, -30, -4, -38, -30, -2, Blocks.DIRT.getDefaultState());
        structure.fillWithBlocks(world, start, -38, -30, -1, -37, -29, -1, Blocks.SANDSTONE.getDefaultState());
        structure.fillWithBlocks(world, start, -38, -30, 0, -36, -30, 0, Blocks.AIR.getDefaultState());
        structure.fillWithBlocks(world, start, -38, -30, 1, -38, -29, 4, Blocks.SANDSTONE.getDefaultState());
        structure.fillWithBlocks(world, start, -38, -30, 11, -38, -30, 13, Blocks.SANDSTONE.getDefaultState());
        structure.fillWithBlocks(world, start, -38, -30, 14, -38, -29, 14, Blocks.AIR.getDefaultState());
        structure.fillWithBlocks(world, start, -38, -30, 15, -38, -30, 18, Blocks.SANDSTONE.getDefaultState());
        structure.fillWithBlocks(world, start, -38, -29, -53, -35, -29, -53, Blocks.STONE_BRICKS.getDefaultState());
        structure.fillWithBlocks(world, start, -38, -29, -51, -38, -29, -51, Blocks.STONE_BRICKS.getDefaultState());
        structure.fillWithBlocks(world, start, -38, -29, -50, -38, -29, -50, Blocks.AIR.getDefaultState());
        structure.fillWithBlocks(world, start, -38, -29, -49, -38, -29, -49, Blocks.STONE_BRICKS.getDefaultState());
        structure.fillWithBlocks(world, start, -38, -29, -48, -38, -29, -47, Blocks.SANDSTONE.getDefaultState());
        structure.fillWithBlocks(world, start, -38, -29, -19, -35, -29, -13, Blocks.AIR.getDefaultState());
        structure.fillWithBlocks(world, start, -38, -29, -8, -36, -29, -6, Blocks.AIR.getDefaultState());
        structure.fillWithBlocks(world, start, -38, -29, -2, -37, -29, -1, Blocks.SANDSTONE.getDefaultState());
        structure.fillWithBlocks(world, start, -38, -29, 0, -38, -29, 0, Blocks.AIR.getDefaultState());
        structure.fillWithBlocks(world, start, -38, -29, 9, -36, -29, 11, Blocks.AIR.getDefaultState());
        structure.fillWithBlocks(world, start, -38, -29, 12, -37, -29, 13, Blocks.SANDSTONE.getDefaultState());
        structure.fillWithBlocks(world, start, -38, -29, 15, -38, -23, 15, Blocks.SANDSTONE.getDefaultState());
        structure.fillWithBlocks(world, start, -38, -29, 17, -37, -29, 18, Blocks.SANDSTONE.getDefaultState());
        structure.fillWithBlocks(world, start, -38, -28, -52, -37, -28, -50, Blocks.STONE_BRICKS.getDefaultState());
        structure.fillWithBlocks(world, start, -38, -28, -49, -38, -27, -48, Blocks.AIR.getDefaultState());
        structure.fillWithBlocks(world, start, -38, -28, -8, -36, -28, -6, Blocks.AIR.getDefaultState());
        structure.fillWithBlocks(world, start, -38, -28, -5, -38, -28, -3, Blocks.SHROOMLIGHT.getDefaultState());
        structure.fillWithBlocks(world, start, -38, -28, 0, -37, -28, 1, Blocks.SANDSTONE.getDefaultState());
        structure.fillWithBlocks(world, start, -38, -28, 2, -38, -27, 3, Blocks.AIR.getDefaultState());
        structure.fillWithBlocks(world, start, -38, -28, 9, -36, -28, 11, Blocks.AIR.getDefaultState());
        structure.fillWithBlocks(world, start, -38, -28, 13, -37, -28, 14, Blocks.SANDSTONE.getDefaultState());
        structure.fillWithBlocks(world, start, -38, -27, -53, -38, -27, -53, Blocks.STONE_BRICKS.getDefaultState());
        structure.fillWithBlocks(world, start, -38, -27, -50, -38, -27, -48, Blocks.AIR.getDefaultState());
        structure.fillWithBlocks(world, start, -38, -27, -5, -37, -27, -4, Blocks.SANDSTONE.getDefaultState());
        structure.fillWithBlocks(world, start, -38, -27, -2, -38, -26, -1, Blocks.SANDSTONE.getDefaultState());
        structure.fillWithBlocks(world, start, -38, -27, 12, -38, -27, 12, Blocks.SANDSTONE.getDefaultState());
        structure.fillWithBlocks(world, start, -38, -27, 13, -38, -27, 14, Blocks.AIR.getDefaultState());
        structure.fillWithBlocks(world, start, -38, -27, 16, -37, -27, 18, Blocks.SANDSTONE.getDefaultState());
        structure.fillWithBlocks(world, start, -38, -26, -53, -38, -26, -53, Blocks.DIRT.getDefaultState());
        structure.fillWithBlocks(world, start, -38, -26, -52, -38, -26, -51, Blocks.STONE_BRICKS.getDefaultState());
        structure.fillWithBlocks(world, start, -38, -26, -49, -38, -25, -48, Blocks.AIR.getDefaultState());
        structure.fillWithBlocks(world, start, -38, -26, -5, -38, -26, -3, Blocks.SHROOMLIGHT.getDefaultState());
        structure.fillWithBlocks(world, start, -38, -26, 0, -37, -26, 1, Blocks.SANDSTONE.getDefaultState());
        structure.fillWithBlocks(world, start, -38, -26, 2, -38, -26, 4, Blocks.SHROOMLIGHT.getDefaultState());
        structure.fillWithBlocks(world, start, -38, -26, 12, -38, -26, 14, Blocks.SHROOMLIGHT.getDefaultState());
        structure.fillWithBlocks(world, start, -38, -26, 16, -38, -25, 17, Blocks.SANDSTONE.getDefaultState());
        structure.fillWithBlocks(world, start, -38, -25, -52, -37, -25, -51, Blocks.STONE_BRICKS.getDefaultState());
        structure.fillWithBlocks(world, start, -38, -25, -5, -36, -24, -5, Blocks.SANDSTONE.getDefaultState());
        structure.fillWithBlocks(world, start, -38, -25, -4, -38, -25, -3, Blocks.AIR.getDefaultState());
        structure.fillWithBlocks(world, start, -38, -25, 2, -38, -25, 3, Blocks.AIR.getDefaultState());
        structure.fillWithBlocks(world, start, -38, -25, 12, -38, -25, 12, Blocks.SANDSTONE.getDefaultState());
        structure.fillWithBlocks(world, start, -38, -25, 13, -38, -25, 14, Blocks.AIR.getDefaultState());
        structure.fillWithBlocks(world, start, -38, -24, -53, -38, -24, -53, Blocks.STONE_BRICKS.getDefaultState());
        structure.fillWithBlocks(world, start, -38, -24, -51, -38, -24, -51, Blocks.STONE_BRICKS.getDefaultState());
        structure.fillWithBlocks(world, start, -38, -24, -50, -38, -23, -50, Blocks.SANDSTONE.getDefaultState());
        structure.fillWithBlocks(world, start, -38, -24, -49, -38, -22, -49, Blocks.STONE_BRICKS.getDefaultState());
        structure.fillWithBlocks(world, start, -38, -24, -48, -37, -24, -48, Blocks.DIRT.getDefaultState());
        structure.fillWithBlocks(world, start, -38, -24, -47, -38, -24, -34, Blocks.SANDSTONE.getDefaultState());
        structure.fillWithBlocks(world, start, -38, -24, -3, -38, -24, -3, Blocks.SANDSTONE.getDefaultState());
        structure.fillWithBlocks(world, start, -38, -24, -1, -38, -24, 16, Blocks.SANDSTONE.getDefaultState());
        structure.fillWithBlocks(world, start, -38, -24, 17, -38, -24, 18, Blocks.AIR.getDefaultState());
        structure.fillWithBlocks(world, start, -38, -23, -53, -38, -23, -51, Blocks.STONE_BRICKS.getDefaultState());
        structure.fillWithBlocks(world, start, -38, -23, -47, -38, -23, -47, Blocks.STONE_BRICKS.getDefaultState());
        structure.fillWithBlocks(world, start, -38, -23, -43, -38, -23, -42, Blocks.AIR.getDefaultState());
        structure.fillWithBlocks(world, start, -38, -23, -41, -38, -22, -41, Blocks.SANDSTONE.getDefaultState());
        structure.fillWithBlocks(world, start, -38, -23, -38, -38, -23, -37, Blocks.SANDSTONE.getDefaultState());
        structure.fillWithBlocks(world, start, -38, -23, -36, -38, -23, -36, Blocks.DIRT.getDefaultState());
        structure.fillWithBlocks(world, start, -38, -23, -35, -38, -23, -33, Blocks.SANDSTONE.getDefaultState());
        structure.fillWithBlocks(world, start, -38, -23, -31, -34, -23, -25, Blocks.SANDSTONE.getDefaultState());
        structure.fillWithBlocks(world, start, -38, -23, -19, -38, -21, -17, Blocks.SANDSTONE.getDefaultState());
        structure.fillWithBlocks(world, start, -38, -23, -10, -37, -23, -8, Blocks.SANDSTONE.getDefaultState());
        structure.fillWithBlocks(world, start, -38, -23, -5, -38, -23, -1, Blocks.SANDSTONE.getDefaultState());
        structure.fillWithBlocks(world, start, -38, -23, 3, -37, -23, 4, Blocks.SANDSTONE.getDefaultState());
        structure.fillWithBlocks(world, start, -38, -23, 6, -36, -23, 9, Blocks.SANDSTONE.getDefaultState());
        structure.fillWithBlocks(world, start, -38, -23, 14, -38, -23, 15, Blocks.SANDSTONE.getDefaultState());
        structure.fillWithBlocks(world, start, -38, -23, 18, -33, -22, 18, Blocks.SANDSTONE.getDefaultState());
        structure.fillWithBlocks(world, start, -38, -22, -53, -38, -22, -53, Blocks.STONE_BRICKS.getDefaultState());
        structure.fillWithBlocks(world, start, -38, -22, -50, -37, -22, -50, Blocks.AIR.getDefaultState());
        structure.fillWithBlocks(world, start, -38, -22, -46, -38, -21, -46, Blocks.AIR.getDefaultState());
        structure.fillWithBlocks(world, start, -38, -22, -38, -38, -22, -38, Blocks.SANDSTONE.getDefaultState());
        structure.fillWithBlocks(world, start, -38, -22, -36, -37, -22, -35, Blocks.SANDSTONE.getDefaultState());
        structure.fillWithBlocks(world, start, -38, -22, -34, -38, -21, -34, Blocks.SANDSTONE.getDefaultState());
        structure.fillWithBlocks(world, start, -38, -22, -33, -38, -22, -32, Blocks.DIRT.getDefaultState());
        structure.fillWithBlocks(world, start, -38, -22, -31, -38, -22, -31, Blocks.SANDSTONE.getDefaultState());
        structure.fillWithBlocks(world, start, -38, -22, -29, -36, -22, -25, Blocks.SANDSTONE.getDefaultState());
        structure.fillWithBlocks(world, start, -38, -22, -23, -37, -22, -22, Blocks.SANDSTONE.getDefaultState());
        structure.fillWithBlocks(world, start, -38, -22, -20, -36, -22, -18, Blocks.SANDSTONE.getDefaultState());
        structure.fillWithBlocks(world, start, -38, -22, -14, -38, -21, -13, Blocks.SANDSTONE.getDefaultState());
        structure.fillWithBlocks(world, start, -38, -22, -11, -37, -22, -8, Blocks.SANDSTONE.getDefaultState());
        structure.fillWithBlocks(world, start, -38, -22, -7, -38, -22, -5, Blocks.SANDSTONE.getDefaultState());
        structure.fillWithBlocks(world, start, -38, -22, -3, -38, -21, -2, Blocks.SANDSTONE.getDefaultState());
        structure.fillWithBlocks(world, start, -38, -22, 0, -37, -22, 1, Blocks.SANDSTONE.getDefaultState());
        structure.fillWithBlocks(world, start, -38, -22, 2, -38, -22, 3, Blocks.AIR.getDefaultState());
        structure.fillWithBlocks(world, start, -38, -22, 4, -37, -22, 5, Blocks.SANDSTONE.getDefaultState());
        structure.fillWithBlocks(world, start, -38, -22, 6, -38, -22, 14, Blocks.SANDSTONE.getDefaultState());
        structure.fillWithBlocks(world, start, -38, -22, 15, -37, -22, 15, Blocks.DIRT.getDefaultState());
        structure.fillWithBlocks(world, start, -38, -22, 16, -36, -22, 18, Blocks.SANDSTONE.getDefaultState());
        structure.fillWithBlocks(world, start, -38, -21, -53, -37, -21, -52, Blocks.STONE_BRICKS.getDefaultState());
        structure.fillWithBlocks(world, start, -38, -21, -51, -38, -21, -51, Blocks.DIRT.getDefaultState());
        structure.fillWithBlocks(world, start, -38, -21, -50, -38, -21, -50, Blocks.STONE_BRICKS.getDefaultState());
        structure.fillWithBlocks(world, start, -38, -21, -48, -38, -21, -47, Blocks.DIRT.getDefaultState());
        structure.fillWithBlocks(world, start, -38, -21, -38, -36, -21, -36, Blocks.SANDSTONE.getDefaultState());
        structure.fillWithBlocks(world, start, -38, -21, -35, -37, -21, -32, Blocks.SANDSTONE.getDefaultState());
        structure.fillWithBlocks(world, start, -38, -21, -25, -37, -21, -22, Blocks.SANDSTONE.getDefaultState());
        structure.fillWithBlocks(world, start, -38, -21, -21, -38, -21, -17, Blocks.SANDSTONE.getDefaultState());
        structure.fillWithBlocks(world, start, -38, -21, -11, -37, -20, -11, Blocks.SANDSTONE.getDefaultState());
        structure.fillWithBlocks(world, start, -38, -21, -9, -38, -21, -9, Blocks.SANDSTONE.getDefaultState());
        structure.fillWithBlocks(world, start, -38, -21, -7, -38, -18, -3, Blocks.SANDSTONE.getDefaultState());
        structure.fillWithBlocks(world, start, -38, -21, -1, -35, -21, 2, Blocks.SANDSTONE.getDefaultState());
        structure.fillWithBlocks(world, start, -38, -21, 8, -37, -21, 10, Blocks.SANDSTONE.getDefaultState());
        structure.fillWithBlocks(world, start, -38, -21, 12, -37, -21, 12, Blocks.DIRT.getDefaultState());
        structure.fillWithBlocks(world, start, -38, -21, 15, -37, -21, 17, Blocks.SANDSTONE.getDefaultState());
        structure.fillWithBlocks(world, start, -38, -19, -12, -38, -18, -11, Blocks.SANDSTONE.getDefaultState());
        structure.fillWithBlocks(world, start, -38, -19, -10, -38, -19, -10, Blocks.AIR.getDefaultState());
        structure.fillWithBlocks(world, start, -38, -19, -8, -38, -19, -8, Blocks.AIR.getDefaultState());
        structure.fillWithBlocks(world, start, -38, -18, -15, -38, -18, -14, Blocks.AIR.getDefaultState());
        structure.fillWithBlocks(world, start, -38, -18, -10, -36, -18, -8, Blocks.AIR.getDefaultState());
        structure.fillWithBlocks(world, start, -38, -17, -10, -36, -17, -8, Blocks.AIR.getDefaultState());
        structure.fillWithBlocks(world, start, -38, -17, -5, -37, -17, -5, Blocks.AIR.getDefaultState());
        structure.fillWithBlocks(world, start, -38, -17, -4, -38, -17, -4, Blocks.SANDSTONE.getDefaultState());
        structure.fillWithBlocks(world, start, -38, -16, -15, -37, -16, -7, Blocks.SANDSTONE.getDefaultState());
        structure.fillWithBlocks(world, start, -38, -16, -6, -38, -16, -3, Blocks.SANDSTONE.getDefaultState());
        structure.fillWithBlocks(world, start, -38, -14, -11, -38, -14, -3, Blocks.SANDSTONE.getDefaultState());
        structure.fillWithBlocks(world, start, -38, -13, -15, -37, -13, -14, Blocks.SANDSTONE.getDefaultState());
        structure.fillWithBlocks(world, start, -38, -13, -12, -37, -13, -10, Blocks.SANDSTONE.getDefaultState());
        structure.fillWithBlocks(world, start, -38, -13, -9, -38, -13, -3, Blocks.SANDSTONE.getDefaultState());
        structure.fillWithBlocks(world, start, -38, -12, -15, -37, -12, -11, Blocks.SANDSTONE.getDefaultState());
        structure.fillWithBlocks(world, start, -38, -11, -3, -37, -11, -3, Blocks.SANDSTONE.getDefaultState());
        structure.fillWithBlocks(world, start, -37, -49, -12, -17, -49, -12, Blocks.SANDSTONE.getDefaultState());
        structure.fillWithBlocks(world, start, -37, -49, -11, -35, -49, -7, Blocks.AIR.getDefaultState());
        structure.fillWithBlocks(world, start, -37, -49, -6, -17, -49, -6, Blocks.SANDSTONE.getDefaultState());
        structure.fillWithBlocks(world, start, -37, -48, -12, -37, -47, -12, Blocks.SANDSTONE.getDefaultState());
        structure.fillWithBlocks(world, start, -37, -48, -11, -35, -48, -7, Blocks.AIR.getDefaultState());
        structure.fillWithBlocks(world, start, -37, -48, -6, -37, -47, -6, Blocks.SANDSTONE.getDefaultState());
        structure.fillWithBlocks(world, start, -37, -47, -11, -35, -47, -7, Blocks.AIR.getDefaultState());
        structure.fillWithBlocks(world, start, -37, -40, -31, -31, -40, -25, Blocks.STONE_BRICKS.getDefaultState());
        structure.fillWithBlocks(world, start, -37, -40, -21, -35, -40, -18, Blocks.STONE_BRICKS.getDefaultState());
        structure.fillWithBlocks(world, start, -37, -40, -16, -28, -40, -6, Blocks.STONE_BRICKS.getDefaultState());
        structure.fillWithBlocks(world, start, -37, -40, -5, -35, -40, -1, Blocks.STONE_BRICKS.getDefaultState());
        structure.fillWithBlocks(world, start, -37, -40, 2, -37, -40, 16, Blocks.STONE_BRICKS.getDefaultState());
        structure.fillWithBlocks(world, start, -37, -39, -36, -36, -39, -35, Blocks.STONE_BRICKS.getDefaultState());
        structure.fillWithBlocks(world, start, -37, -39, -34, -37, -39, -28, Blocks.STONE_BRICKS.getDefaultState());
        structure.fillWithBlocks(world, start, -37, -39, -27, -37, -39, -27, Blocks.AIR.getDefaultState());
        structure.fillWithBlocks(world, start, -37, -39, -25, -31, -37, -25, Blocks.AIR.getDefaultState());
        structure.fillWithBlocks(world, start, -37, -39, -20, -36, -39, -16, Blocks.STONE_BRICKS.getDefaultState());
        structure.fillWithBlocks(world, start, -37, -39, -15, -37, -39, -13, Blocks.IRON_BARS.getDefaultState().with(FourWayBlock.WATERLOGGED, false).with(FourWayBlock.NORTH, true).with(FourWayBlock.SOUTH, true).with(FourWayBlock.EAST, true).with(FourWayBlock.WEST, true));
        structure.fillWithBlocks(world, start, -37, -39, -12, -37, -35, -12, Blocks.STONE_BRICKS.getDefaultState());
        structure.fillWithBlocks(world, start, -37, -39, -11, -36, -39, -10, Blocks.AIR.getDefaultState());
        structure.fillWithBlocks(world, start, -37, -39, -8, -36, -39, -7, Blocks.AIR.getDefaultState());
        structure.fillWithBlocks(world, start, -37, -39, -6, -37, -31, -6, Blocks.STONE_BRICKS.getDefaultState());
        structure.fillWithBlocks(world, start, -37, -39, -5, -37, -39, -3, Blocks.IRON_BARS.getDefaultState().with(FourWayBlock.WATERLOGGED, false).with(FourWayBlock.NORTH, true).with(FourWayBlock.SOUTH, true).with(FourWayBlock.EAST, true).with(FourWayBlock.WEST, true));
        structure.fillWithBlocks(world, start, -37, -39, -2, -35, -39, 0, Blocks.STONE_BRICKS.getDefaultState());
        structure.fillWithBlocks(world, start, -37, -39, 2, -37, -39, 4, Blocks.IRON_BARS.getDefaultState().with(FourWayBlock.WATERLOGGED, false).with(FourWayBlock.NORTH, true).with(FourWayBlock.SOUTH, true).with(FourWayBlock.EAST, true).with(FourWayBlock.WEST, true));
        structure.fillWithBlocks(world, start, -37, -39, 5, -37, -31, 5, Blocks.STONE_BRICKS.getDefaultState());
        structure.fillWithBlocks(world, start, -37, -39, 6, -37, -39, 10, Blocks.IRON_BARS.getDefaultState().with(FourWayBlock.WATERLOGGED, false).with(FourWayBlock.NORTH, true).with(FourWayBlock.SOUTH, true).with(FourWayBlock.EAST, true).with(FourWayBlock.WEST, true));
        structure.fillWithBlocks(world, start, -37, -39, 11, -37, -31, 11, Blocks.STONE_BRICKS.getDefaultState());
        structure.fillWithBlocks(world, start, -37, -39, 12, -37, -39, 14, Blocks.IRON_BARS.getDefaultState().with(FourWayBlock.WATERLOGGED, false).with(FourWayBlock.NORTH, true).with(FourWayBlock.SOUTH, true).with(FourWayBlock.EAST, true).with(FourWayBlock.WEST, true));
        structure.fillWithBlocks(world, start, -37, -39, 15, -37, -39, 16, Blocks.STONE_BRICKS.getDefaultState());
        structure.fillWithBlocks(world, start, -37, -38, -36, -35, -38, -34, Blocks.STONE_BRICKS.getDefaultState());
        structure.fillWithBlocks(world, start, -37, -38, -30, -37, -31, -30, Blocks.STONE_BRICKS.getDefaultState());
        structure.fillWithBlocks(world, start, -37, -38, -28, -35, -36, -28, Blocks.STONE_BRICKS.getDefaultState());
        structure.fillWithBlocks(world, start, -37, -38, -27, -35, -38, -25, Blocks.AIR.getDefaultState());
        structure.fillWithBlocks(world, start, -37, -38, -24, -35, -36, -24, Blocks.STONE_BRICKS.getDefaultState());
        structure.fillWithBlocks(world, start, -37, -38, -22, -37, -31, -22, Blocks.STONE_BRICKS.getDefaultState());
        structure.fillWithBlocks(world, start, -37, -38, -20, -36, -38, -16, Blocks.STONE_BRICKS.getDefaultState());
        structure.fillWithBlocks(world, start, -37, -38, -15, -37, -36, -13, Blocks.AIR.getDefaultState());
        structure.fillWithBlocks(world, start, -37, -38, -5, -37, -36, -3, Blocks.AIR.getDefaultState());
        structure.fillWithBlocks(world, start, -37, -38, -2, -35, -38, 0, Blocks.STONE_BRICKS.getDefaultState());
        structure.fillWithBlocks(world, start, -37, -38, 2, -35, -38, 4, Blocks.AIR.getDefaultState());
        structure.fillWithBlocks(world, start, -37, -38, 6, -33, -38, 10, Blocks.AIR.getDefaultState());
        structure.fillWithBlocks(world, start, -37, -38, 12, -35, -38, 14, Blocks.AIR.getDefaultState());
        structure.fillWithBlocks(world, start, -37, -38, 15, -37, -38, 16, Blocks.STONE_BRICKS.getDefaultState());
        structure.fillWithBlocks(world, start, -37, -37, -36, -37, -37, -36, Blocks.STONE_BRICKS.getDefaultState());
        structure.fillWithBlocks(world, start, -37, -37, -35, -37, -37, -35, Blocks.AIR.getDefaultState());
        structure.fillWithBlocks(world, start, -37, -37, -34, -37, -37, -28, Blocks.STONE_BRICKS.getDefaultState());
        structure.fillWithBlocks(world, start, -37, -37, -27, -35, -37, -25, Blocks.AIR.getDefaultState());
        structure.fillWithBlocks(world, start, -37, -37, -20, -37, -36, -19, Blocks.STONE_BRICKS.getDefaultState());
        structure.fillWithBlocks(world, start, -37, -37, -17, -36, -37, -16, Blocks.STONE_BRICKS.getDefaultState());
        structure.fillWithBlocks(world, start, -37, -37, -2, -37, -37, -1, Blocks.STONE_BRICKS.getDefaultState());
        structure.fillWithBlocks(world, start, -37, -37, 0, -37, -37, 0, Blocks.AIR.getDefaultState());
        structure.fillWithBlocks(world, start, -37, -37, 1, -37, -34, 1, Blocks.STONE_BRICKS.getDefaultState());
        structure.fillWithBlocks(world, start, -37, -37, 2, -35, -37, 4, Blocks.AIR.getDefaultState());
        structure.fillWithBlocks(world, start, -37, -37, 6, -33, -37, 10, Blocks.AIR.getDefaultState());
        structure.fillWithBlocks(world, start, -37, -37, 12, -35, -37, 14, Blocks.AIR.getDefaultState());
        structure.fillWithBlocks(world, start, -37, -37, 15, -37, -37, 16, Blocks.STONE_BRICKS.getDefaultState());
        structure.fillWithBlocks(world, start, -37, -36, -27, -35, -36, -24, Blocks.STONE_BRICKS.getDefaultState());
        structure.fillWithBlocks(world, start, -37, -36, -16, -37, -36, -16, Blocks.STONE_BRICKS.getDefaultState());
        structure.fillWithBlocks(world, start, -37, -36, -2, -35, -36, 0, Blocks.STONE_BRICKS.getDefaultState());
        structure.fillWithBlocks(world, start, -37, -36, 2, -35, -36, 4, Blocks.AIR.getDefaultState());
        structure.fillWithBlocks(world, start, -37, -36, 6, -33, -36, 10, Blocks.AIR.getDefaultState());
        structure.fillWithBlocks(world, start, -37, -36, 12, -35, -36, 14, Blocks.AIR.getDefaultState());
        structure.fillWithBlocks(world, start, -37, -36, 15, -37, -36, 16, Blocks.STONE_BRICKS.getDefaultState());
        structure.fillWithBlocks(world, start, -37, -35, -36, -36, -35, -35, Blocks.STONE_BRICKS.getDefaultState());
        structure.fillWithBlocks(world, start, -37, -35, -29, -37, -35, -20, Blocks.STONE_BRICKS.getDefaultState());
        structure.fillWithBlocks(world, start, -37, -35, -18, -33, -35, -14, Blocks.STONE_BRICKS.getDefaultState());
        structure.fillWithBlocks(world, start, -37, -35, -13, -36, -35, -11, Blocks.STONE_BRICKS.getDefaultState());
        structure.fillWithBlocks(world, start, -37, -35, -10, -37, -33, -6, Blocks.STONE_BRICKS.getDefaultState());
        structure.fillWithBlocks(world, start, -37, -35, -5, -36, -35, 1, Blocks.STONE_BRICKS.getDefaultState());
        structure.fillWithBlocks(world, start, -37, -34, -33, -35, -34, -29, Blocks.STONE_BRICKS.getDefaultState());
        structure.fillWithBlocks(world, start, -37, -34, -26, -37, -34, -26, Blocks.STONE_BRICKS.getDefaultState());
        structure.fillWithBlocks(world, start, -37, -34, -19, -37, -34, -13, Blocks.STONE_BRICKS.getDefaultState());
        structure.fillWithBlocks(world, start, -37, -34, -12, -37, -33, -12, Blocks.AIR.getDefaultState());
        structure.fillWithBlocks(world, start, -37, -34, -11, -36, -34, -6, Blocks.STONE_BRICKS.getDefaultState());
        structure.fillWithBlocks(world, start, -37, -34, -4, -36, -34, -3, Blocks.STONE_BRICKS.getDefaultState());
        structure.fillWithBlocks(world, start, -37, -34, -2, -37, -34, 3, Blocks.STONE_BRICKS.getDefaultState());
        structure.fillWithBlocks(world, start, -37, -34, 6, -36, -34, 14, Blocks.STONE_BRICKS.getDefaultState());
        structure.fillWithBlocks(world, start, -37, -34, 15, -37, -34, 16, Blocks.STONE_BRICKS.getDefaultState());
        structure.fillWithBlocks(world, start, -37, -33, -36, -37, -33, -35, Blocks.STONE_BRICKS.getDefaultState());
        structure.fillWithBlocks(world, start, -37, -33, -34, -37, -32, -34, Blocks.AIR.getDefaultState());
        structure.fillWithBlocks(world, start, -37, -33, -33, -34, -33, -30, Blocks.STONE_BRICKS.getDefaultState());
        structure.fillWithBlocks(world, start, -37, -33, -29, -37, -33, -28, Blocks.STONE_BRICKS.getDefaultState());
        structure.fillWithBlocks(world, start, -37, -33, -26, -35, -33, -24, Blocks.STONE_BRICKS.getDefaultState());
        structure.fillWithBlocks(world, start, -37, -33, -20, -37, -31, -20, Blocks.STONE_BRICKS.getDefaultState());
        structure.fillWithBlocks(world, start, -37, -33, -5, -35, -33, -2, Blocks.STONE_BRICKS.getDefaultState());
        structure.fillWithBlocks(world, start, -37, -33, 0, -37, -33, 0, Blocks.STONE_BRICKS.getDefaultState());
        structure.fillWithBlocks(world, start, -37, -33, 2, -34, -33, 9, Blocks.STONE_BRICKS.getDefaultState());
        structure.fillWithBlocks(world, start, -37, -33, 10, -36, -33, 12, Blocks.STONE_BRICKS.getDefaultState());
        structure.fillWithBlocks(world, start, -37, -33, 14, -36, -33, 16, Blocks.STONE_BRICKS.getDefaultState());
        structure.fillWithBlocks(world, start, -37, -32, -36, -36, -32, -35, Blocks.STONE_BRICKS.getDefaultState());
        structure.fillWithBlocks(world, start, -37, -32, -33, -37, -31, -24, Blocks.STONE_BRICKS.getDefaultState());
        structure.fillWithBlocks(world, start, -37, -32, -12, -32, -31, -12, Blocks.STONE_BRICKS.getDefaultState());
        structure.fillWithBlocks(world, start, -37, -32, -11, -36, -32, -11, Blocks.AIR.getDefaultState());
        structure.fillWithBlocks(world, start, -37, -32, -10, -35, -32, -8, Blocks.STONE_BRICKS.getDefaultState());
        structure.fillWithBlocks(world, start, -37, -32, -1, -37, -32, -1, Blocks.STONE_BRICKS.getDefaultState());
        structure.fillWithBlocks(world, start, -37, -32, 1, -36, -32, 3, Blocks.STONE_BRICKS.getDefaultState());
        structure.fillWithBlocks(world, start, -37, -32, 4, -37, -31, 5, Blocks.STONE_BRICKS.getDefaultState());
        structure.fillWithBlocks(world, start, -37, -32, 7, -36, -32, 8, Blocks.STONE_BRICKS.getDefaultState());
        structure.fillWithBlocks(world, start, -37, -32, 9, -37, -32, 16, Blocks.STONE_BRICKS.getDefaultState());
        structure.fillWithBlocks(world, start, -37, -31, -23, -36, -31, -18, Blocks.STONE_BRICKS.getDefaultState());
        structure.fillWithBlocks(world, start, -37, -31, -17, -37, -31, -9, Blocks.STONE_BRICKS.getDefaultState());
        structure.fillWithBlocks(world, start, -37, -31, -7, -37, -31, 2, Blocks.STONE_BRICKS.getDefaultState());
        structure.fillWithBlocks(world, start, -37, -31, 3, -37, -31, 3, Blocks.AIR.getDefaultState());
        structure.fillWithBlocks(world, start, -37, -31, 8, -35, -31, 12, Blocks.STONE_BRICKS.getDefaultState());
        structure.fillWithBlocks(world, start, -37, -31, 13, -37, -31, 16, Blocks.STONE_BRICKS.getDefaultState());
        structure.fillWithBlocks(world, start, -37, -30, -51, -37, -30, -51, Blocks.AIR.getDefaultState());
        structure.fillWithBlocks(world, start, -37, -30, -50, -37, -30, -49, Blocks.SANDSTONE.getDefaultState());
        structure.fillWithBlocks(world, start, -37, -30, -4, -37, -26, -4, Blocks.SANDSTONE.getDefaultState());
        structure.fillWithBlocks(world, start, -37, -30, -3, -37, -30, -2, Blocks.AIR.getDefaultState());
        structure.fillWithBlocks(world, start, -37, -30, 1, -37, -30, 1, Blocks.SANDSTONE.getDefaultState());
        structure.fillWithBlocks(world, start, -37, -30, 3, -37, -30, 3, Blocks.SANDSTONE.getDefaultState());
        structure.fillWithBlocks(world, start, -37, -30, 11, -29, -30, 11, Blocks.SANDSTONE.getDefaultState());
        structure.fillWithBlocks(world, start, -37, -30, 12, -35, -30, 12, Blocks.DIRT.getDefaultState());
        structure.fillWithBlocks(world, start, -37, -30, 13, -36, -30, 13, Blocks.AIR.getDefaultState());
        structure.fillWithBlocks(world, start, -37, -30, 14, -36, -30, 14, Blocks.DIRT.getDefaultState());
        structure.fillWithBlocks(world, start, -37, -30, 15, -36, -30, 15, Blocks.SANDSTONE.getDefaultState());
        structure.fillWithBlocks(world, start, -37, -30, 16, -36, -30, 16, Blocks.DIRT.getDefaultState());
        structure.fillWithBlocks(world, start, -37, -29, -52, -36, -29, -52, Blocks.SANDSTONE.getDefaultState());
        structure.fillWithBlocks(world, start, -37, -29, -51, -36, -29, -50, Blocks.STONE_BRICKS.getDefaultState());
        structure.fillWithBlocks(world, start, -37, -29, -48, -36, -29, -48, Blocks.STONE_BRICKS.getDefaultState());
        structure.fillWithBlocks(world, start, -37, -29, -46, -36, -29, -44, Blocks.AIR.getDefaultState());
        structure.fillWithBlocks(world, start, -37, -29, -42, -36, -29, -6, Blocks.AIR.getDefaultState());
        structure.fillWithBlocks(world, start, -37, -29, -5, -37, -26, -2, Blocks.SANDSTONE.getDefaultState());
        structure.fillWithBlocks(world, start, -37, -29, 0, -37, -25, 0, Blocks.SANDSTONE.getDefaultState());
        structure.fillWithBlocks(world, start, -37, -29, 2, -35, -29, 4, Blocks.SANDSTONE.getDefaultState());
        structure.fillWithBlocks(world, start, -37, -29, 5, -36, -29, 11, Blocks.AIR.getDefaultState());
        structure.fillWithBlocks(world, start, -37, -29, 14, -37, -24, 14, Blocks.SANDSTONE.getDefaultState());
        structure.fillWithBlocks(world, start, -37, -29, 15, -37, -28, 15, Blocks.DIRT.getDefaultState());
        structure.fillWithBlocks(world, start, -37, -29, 16, -36, -29, 17, Blocks.SANDSTONE.getDefaultState());
        structure.fillWithBlocks(world, start, -37, -28, -53, -37, -27, -51, Blocks.STONE_BRICKS.getDefaultState());
        structure.fillWithBlocks(world, start, -37, -28, -49, -37, -27, -48, Blocks.STONE_BRICKS.getDefaultState());
        structure.fillWithBlocks(world, start, -37, -28, -47, -37, -25, -47, Blocks.SANDSTONE.getDefaultState());
        structure.fillWithBlocks(world, start, -37, -28, -9, -35, -28, -7, Blocks.AIR.getDefaultState());
        structure.fillWithBlocks(world, start, -37, -28, -1, -37, -27, -1, Blocks.DIRT.getDefaultState());
        structure.fillWithBlocks(world, start, -37, -28, 2, -37, -26, 4, Blocks.SANDSTONE.getDefaultState());
        structure.fillWithBlocks(world, start, -37, -28, 5, -36, -28, 11, Blocks.AIR.getDefaultState());
        structure.fillWithBlocks(world, start, -37, -28, 12, -37, -26, 14, Blocks.SANDSTONE.getDefaultState());
        structure.fillWithBlocks(world, start, -37, -28, 17, -36, -28, 18, Blocks.SANDSTONE.getDefaultState());
        structure.fillWithBlocks(world, start, -37, -27, -50, -37, -27, -50, Blocks.AIR.getDefaultState());
        structure.fillWithBlocks(world, start, -37, -27, 15, -37, -27, 18, Blocks.SANDSTONE.getDefaultState());
        structure.fillWithBlocks(world, start, -37, -26, -53, -37, -26, -52, Blocks.DIRT.getDefaultState());
        structure.fillWithBlocks(world, start, -37, -26, -49, -37, -25, -49, Blocks.STONE_BRICKS.getDefaultState());
        structure.fillWithBlocks(world, start, -37, -26, -48, -37, -26, -47, Blocks.SANDSTONE.getDefaultState());
        structure.fillWithBlocks(world, start, -37, -26, -1, -37, -26, 4, Blocks.SANDSTONE.getDefaultState());
        structure.fillWithBlocks(world, start, -37, -26, 16, -37, -26, 16, Blocks.SANDSTONE.getDefaultState());
        structure.fillWithBlocks(world, start, -37, -26, 17, -37, -25, 17, Blocks.AIR.getDefaultState());
        structure.fillWithBlocks(world, start, -37, -26, 18, -37, -25, 18, Blocks.SANDSTONE.getDefaultState());
        structure.fillWithBlocks(world, start, -37, -25, -50, -37, -25, -49, Blocks.STONE_BRICKS.getDefaultState());
        structure.fillWithBlocks(world, start, -37, -25, -48, -36, -25, -48, Blocks.AIR.getDefaultState());
        structure.fillWithBlocks(world, start, -37, -25, -4, -37, -25, -4, Blocks.AIR.getDefaultState());
        structure.fillWithBlocks(world, start, -37, -25, 2, -37, -24, 3, Blocks.SANDSTONE.getDefaultState());
        structure.fillWithBlocks(world, start, -37, -25, 4, -35, -25, 4, Blocks.SANDSTONE.getDefaultState());
        structure.fillWithBlocks(world, start, -37, -25, 12, -37, -24, 15, Blocks.SANDSTONE.getDefaultState());
        structure.fillWithBlocks(world, start, -37, -25, 16, -37, -25, 17, Blocks.AIR.getDefaultState());
        structure.fillWithBlocks(world, start, -37, -24, -53, -36, -24, -52, Blocks.STONE_BRICKS.getDefaultState());
        structure.fillWithBlocks(world, start, -37, -24, -51, -37, -24, -50, Blocks.STONE_BRICKS.getDefaultState());
        structure.fillWithBlocks(world, start, -37, -24, -47, -36, -23, -47, Blocks.STONE_BRICKS.getDefaultState());
        structure.fillWithBlocks(world, start, -37, -24, -4, -36, -24, -2, Blocks.SANDSTONE.getDefaultState());
        structure.fillWithBlocks(world, start, -37, -24, -1, -37, -21, -1, Blocks.SANDSTONE.getDefaultState());
        structure.fillWithBlocks(world, start, -37, -24, 16, -37, -24, 16, Blocks.SANDSTONE.getDefaultState());
        structure.fillWithBlocks(world, start, -37, -24, 17, -37, -24, 18, Blocks.DIRT.getDefaultState());
        structure.fillWithBlocks(world, start, -37, -23, -53, -37, -23, -53, Blocks.STONE_BRICKS.getDefaultState());
        structure.fillWithBlocks(world, start, -37, -23, -51, -37, -23, -45, Blocks.STONE_BRICKS.getDefaultState());
        structure.fillWithBlocks(world, start, -37, -23, -42, -37, -23, -39, Blocks.STONE_BRICKS.getDefaultState());
        structure.fillWithBlocks(world, start, -37, -23, -38, -37, -21, -38, Blocks.SANDSTONE.getDefaultState());
        structure.fillWithBlocks(world, start, -37, -23, -36, -37, -23, -36, Blocks.SANDSTONE.getDefaultState());
        structure.fillWithBlocks(world, start, -37, -23, -34, -36, -23, -25, Blocks.SANDSTONE.getDefaultState());
        structure.fillWithBlocks(world, start, -37, -23, -20, -36, -23, -19, Blocks.SANDSTONE.getDefaultState());
        structure.fillWithBlocks(world, start, -37, -23, -17, -36, -23, -15, Blocks.SANDSTONE.getDefaultState());
        structure.fillWithBlocks(world, start, -37, -23, -12, -37, -23, -12, Blocks.DIRT.getDefaultState());
        structure.fillWithBlocks(world, start, -37, -23, -11, -37, -23, -8, Blocks.SANDSTONE.getDefaultState());
        structure.fillWithBlocks(world, start, -37, -23, -7, -37, -23, -6, Blocks.DIRT.getDefaultState());
        structure.fillWithBlocks(world, start, -37, -23, -4, -37, -23, -4, Blocks.SANDSTONE.getDefaultState());
        structure.fillWithBlocks(world, start, -37, -23, -3, -37, -23, -3, Blocks.AIR.getDefaultState());
        structure.fillWithBlocks(world, start, -37, -23, -2, -37, -23, 0, Blocks.SANDSTONE.getDefaultState());
        structure.fillWithBlocks(world, start, -37, -23, 2, -35, -23, 7, Blocks.SANDSTONE.getDefaultState());
        structure.fillWithBlocks(world, start, -37, -23, 11, -33, -23, 11, Blocks.SANDSTONE.getDefaultState());
        structure.fillWithBlocks(world, start, -37, -23, 13, -37, -21, 13, Blocks.SANDSTONE.getDefaultState());
        structure.fillWithBlocks(world, start, -37, -23, 15, -37, -23, 15, Blocks.SANDSTONE.getDefaultState());
        structure.fillWithBlocks(world, start, -37, -22, -53, -37, -21, -52, Blocks.STONE_BRICKS.getDefaultState());
        structure.fillWithBlocks(world, start, -37, -22, -51, -37, -22, -50, Blocks.AIR.getDefaultState());
        structure.fillWithBlocks(world, start, -37, -22, -49, -37, -22, -48, Blocks.STONE_BRICKS.getDefaultState());
        structure.fillWithBlocks(world, start, -37, -22, -46, -37, -22, -46, Blocks.SANDSTONE.getDefaultState());
        structure.fillWithBlocks(world, start, -37, -22, -45, -37, -22, -44, Blocks.STONE_BRICKS.getDefaultState());
        structure.fillWithBlocks(world, start, -37, -22, -43, -37, -22, -42, Blocks.DIRT.getDefaultState());
        structure.fillWithBlocks(world, start, -37, -22, -41, -37, -21, -40, Blocks.STONE_BRICKS.getDefaultState());
        structure.fillWithBlocks(world, start, -37, -22, -37, -35, -22, -35, Blocks.SANDSTONE.getDefaultState());
        structure.fillWithBlocks(world, start, -37, -22, -33, -37, -22, -18, Blocks.SANDSTONE.getDefaultState());
        structure.fillWithBlocks(world, start, -37, -22, -15, -37, -21, -14, Blocks.SANDSTONE.getDefaultState());
        structure.fillWithBlocks(world, start, -37, -22, -12, -35, -22, -10, Blocks.SANDSTONE.getDefaultState());
        structure.fillWithBlocks(world, start, -37, -22, -6, -35, -22, -3, Blocks.SANDSTONE.getDefaultState());
        structure.fillWithBlocks(world, start, -37, -22, -2, -37, -21, -2, Blocks.DIRT.getDefaultState());
        structure.fillWithBlocks(world, start, -37, -22, 2, -35, -22, 5, Blocks.SANDSTONE.getDefaultState());
        structure.fillWithBlocks(world, start, -37, -22, 8, -37, -21, 10, Blocks.SANDSTONE.getDefaultState());
        structure.fillWithBlocks(world, start, -37, -22, 11, -37, -22, 12, Blocks.AIR.getDefaultState());
        structure.fillWithBlocks(world, start, -37, -21, -51, -37, -21, -51, Blocks.STONE_BRICKS.getDefaultState());
        structure.fillWithBlocks(world, start, -37, -21, -49, -36, -21, -45, Blocks.STONE_BRICKS.getDefaultState());
        structure.fillWithBlocks(world, start, -37, -21, -44, -37, -21, -43, Blocks.DIRT.getDefaultState());
        structure.fillWithBlocks(world, start, -37, -21, -42, -34, -21, -42, Blocks.SANDSTONE.getDefaultState());
        structure.fillWithBlocks(world, start, -37, -21, -30, -36, -21, -28, Blocks.SANDSTONE.getDefaultState());
        structure.fillWithBlocks(world, start, -37, -21, -26, -37, -21, -22, Blocks.SANDSTONE.getDefaultState());
        structure.fillWithBlocks(world, start, -37, -21, -20, -36, -21, -19, Blocks.SANDSTONE.getDefaultState());
        structure.fillWithBlocks(world, start, -37, -21, -18, -37, -21, -17, Blocks.AIR.getDefaultState());
        structure.fillWithBlocks(world, start, -37, -21, -16, -35, -21, -14, Blocks.SANDSTONE.getDefaultState());
        structure.fillWithBlocks(world, start, -37, -21, -13, -37, -21, -11, Blocks.SANDSTONE.getDefaultState());
        structure.fillWithBlocks(world, start, -37, -21, -9, -37, -20, -7, Blocks.SANDSTONE.getDefaultState());
        structure.fillWithBlocks(world, start, -37, -21, -5, -37, -21, -3, Blocks.SANDSTONE.getDefaultState());
        structure.fillWithBlocks(world, start, -37, -21, 3, -37, -21, 3, Blocks.SANDSTONE.getDefaultState());
        structure.fillWithBlocks(world, start, -37, -21, 5, -36, -21, 7, Blocks.SANDSTONE.getDefaultState());
        structure.fillWithBlocks(world, start, -37, -20, -6, -37, -20, -3, Blocks.SANDSTONE.getDefaultState());
        structure.fillWithBlocks(world, start, -37, -19, -12, -35, -19, -12, Blocks.STONE_BRICKS.getDefaultState());
        structure.fillWithBlocks(world, start, -37, -19, -11, -35, -19, -7, Blocks.AIR.getDefaultState());
        structure.fillWithBlocks(world, start, -37, -19, -6, -35, -19, -6, Blocks.STONE_BRICKS.getDefaultState());
        structure.fillWithBlocks(world, start, -37, -19, -5, -37, -18, -3, Blocks.SANDSTONE.getDefaultState());
        structure.fillWithBlocks(world, start, -37, -18, -15, -37, -11, -15, Blocks.SANDSTONE.getDefaultState());
        structure.fillWithBlocks(world, start, -37, -18, -14, -37, -17, -14, Blocks.AIR.getDefaultState());
        structure.fillWithBlocks(world, start, -37, -18, -13, -37, -12, -13, Blocks.SANDSTONE.getDefaultState());
        structure.fillWithBlocks(world, start, -37, -18, -12, -37, -17, -12, Blocks.STONE_BRICKS.getDefaultState());
        structure.fillWithBlocks(world, start, -37, -18, -11, -35, -18, -7, Blocks.AIR.getDefaultState());
        structure.fillWithBlocks(world, start, -37, -18, -6, -37, -17, -6, Blocks.STONE_BRICKS.getDefaultState());
        structure.fillWithBlocks(world, start, -37, -17, -11, -35, -17, -7, Blocks.AIR.getDefaultState());
        structure.fillWithBlocks(world, start, -37, -17, -4, -37, -16, -3, Blocks.SANDSTONE.getDefaultState());
        structure.fillWithBlocks(world, start, -37, -16, -5, -37, -14, -3, Blocks.SANDSTONE.getDefaultState());
        structure.fillWithBlocks(world, start, -37, -14, -10, -37, -14, -3, Blocks.SANDSTONE.getDefaultState());
        structure.fillWithBlocks(world, start, -37, -13, -9, -37, -12, -9, Blocks.AIR.getDefaultState());
        structure.fillWithBlocks(world, start, -37, -13, -8, -37, -11, -5, Blocks.SANDSTONE.getDefaultState());
        structure.fillWithBlocks(world, start, -37, -12, -10, -37, -12, -9, Blocks.AIR.getDefaultState());
        structure.fillWithBlocks(world, start, -37, -12, -3, -37, -11, -3, Blocks.SANDSTONE.getDefaultState());
        structure.fillWithBlocks(world, start, -37, -11, -12, -37, -11, -3, Blocks.SANDSTONE.getDefaultState());
        structure.fillWithBlocks(world, start, -36, -47, -12, -17, -47, -12, Blocks.SANDSTONE.getDefaultState());
        structure.fillWithBlocks(world, start, -36, -47, -6, -17, -47, -6, Blocks.SANDSTONE.getDefaultState());
        structure.fillWithBlocks(world, start, -36, -41, 2, -34, -41, 14, Blocks.STONE_BRICKS.getDefaultState());
        structure.fillWithBlocks(world, start, -36, -40, -36, -35, -40, -35, Blocks.STONE_BRICKS.getDefaultState());
        structure.fillWithBlocks(world, start, -36, -40, -34, -36, -39, -34, Blocks.AIR.getDefaultState());
        structure.fillWithBlocks(world, start, -36, -40, -33, -28, -40, -25, Blocks.STONE_BRICKS.getDefaultState());
        structure.fillWithBlocks(world, start, -36, -40, -23, -33, -40, -20, Blocks.STONE_BRICKS.getDefaultState());
        structure.fillWithBlocks(world, start, -36, -40, -17, -28, -40, -6, Blocks.STONE_BRICKS.getDefaultState());
        structure.fillWithBlocks(world, start, -36, -40, 1, -18, -40, 1, Blocks.STONE_BRICKS.getDefaultState());
        structure.fillWithBlocks(world, start, -36, -40, 2, -34, -40, 4, Blocks.AIR.getDefaultState());
        structure.fillWithBlocks(world, start, -36, -40, 5, -35, -40, 14, Blocks.AIR.getDefaultState());
        structure.fillWithBlocks(world, start, -36, -40, 15, -35, -40, 16, Blocks.STONE_BRICKS.getDefaultState());
        structure.fillWithBlocks(world, start, -36, -39, -33, -36, -38, -32, Blocks.STONE_BRICKS.getDefaultState());
        structure.fillWithBlocks(world, start, -36, -39, -31, -34, -39, -29, Blocks.AIR.getDefaultState());
        structure.fillWithBlocks(world, start, -36, -39, -28, -35, -38, -28, Blocks.STONE_BRICKS.getDefaultState());
        structure.fillWithBlocks(world, start, -36, -39, -27, -34, -39, -25, Blocks.AIR.getDefaultState());
        structure.fillWithBlocks(world, start, -36, -39, -24, -35, -38, -24, Blocks.STONE_BRICKS.getDefaultState());
        structure.fillWithBlocks(world, start, -36, -39, -23, -34, -39, -21, Blocks.AIR.getDefaultState());
        structure.fillWithBlocks(world, start, -36, -39, -15, -35, -39, -14, Blocks.STONE_BRICKS.getDefaultState());
        structure.fillWithBlocks(world, start, -36, -39, -13, -36, -31, -13, Blocks.STONE_BRICKS.getDefaultState());
        structure.fillWithBlocks(world, start, -36, -39, -12, -34, -39, -6, Blocks.AIR.getDefaultState());
        structure.fillWithBlocks(world, start, -36, -39, -5, -36, -39, 0, Blocks.STONE_BRICKS.getDefaultState());
        structure.fillWithBlocks(world, start, -36, -39, 1, -34, -39, 1, Blocks.IRON_BARS.getDefaultState().with(FourWayBlock.WATERLOGGED, false).with(FourWayBlock.NORTH, true).with(FourWayBlock.SOUTH, true).with(FourWayBlock.EAST, true).with(FourWayBlock.WEST, true));
        structure.fillWithBlocks(world, start, -36, -39, 2, -34, -39, 14, Blocks.AIR.getDefaultState());
        structure.fillWithBlocks(world, start, -36, -39, 15, -34, -39, 15, Blocks.IRON_BARS.getDefaultState().with(FourWayBlock.WATERLOGGED, false).with(FourWayBlock.NORTH, true).with(FourWayBlock.SOUTH, true).with(FourWayBlock.EAST, true).with(FourWayBlock.WEST, true));
        structure.fillWithBlocks(world, start, -36, -39, 16, -22, -36, 16, Blocks.STONE_BRICKS.getDefaultState());
        structure.fillWithBlocks(world, start, -36, -38, -31, -34, -38, -29, Blocks.AIR.getDefaultState());
        structure.fillWithBlocks(world, start, -36, -38, -23, -34, -38, -21, Blocks.AIR.getDefaultState());
        structure.fillWithBlocks(world, start, -36, -38, -15, -35, -38, -14, Blocks.STONE_BRICKS.getDefaultState());
        structure.fillWithBlocks(world, start, -36, -38, -12, -34, -38, -6, Blocks.AIR.getDefaultState());
        structure.fillWithBlocks(world, start, -36, -38, -5, -36, -38, 0, Blocks.STONE_BRICKS.getDefaultState());
        structure.fillWithBlocks(world, start, -36, -38, 1, -34, -38, 15, Blocks.AIR.getDefaultState());
        structure.fillWithBlocks(world, start, -36, -37, -36, -35, -37, -35, Blocks.STONE_BRICKS.getDefaultState());
        structure.fillWithBlocks(world, start, -36, -37, -33, -36, -36, -32, Blocks.STONE_BRICKS.getDefaultState());
        structure.fillWithBlocks(world, start, -36, -37, -31, -34, -37, -29, Blocks.AIR.getDefaultState());
        structure.fillWithBlocks(world, start, -36, -37, -23, -34, -37, -21, Blocks.AIR.getDefaultState());
        structure.fillWithBlocks(world, start, -36, -37, -20, -36, -34, -20, Blocks.STONE_BRICKS.getDefaultState());
        structure.fillWithBlocks(world, start, -36, -37, -18, -35, -37, -14, Blocks.STONE_BRICKS.getDefaultState());
        structure.fillWithBlocks(world, start, -36, -37, -12, -34, -37, -6, Blocks.AIR.getDefaultState());
        structure.fillWithBlocks(world, start, -36, -37, -5, -36, -37, -3, Blocks.STONE_BRICKS.getDefaultState());
        structure.fillWithBlocks(world, start, -36, -37, -1, -35, -37, 0, Blocks.STONE_BRICKS.getDefaultState());
        structure.fillWithBlocks(world, start, -36, -37, 1, -34, -37, 15, Blocks.AIR.getDefaultState());
        structure.fillWithBlocks(world, start, -36, -36, -36, -36, -36, -36, Blocks.STONE_BRICKS.getDefaultState());
        structure.fillWithBlocks(world, start, -36, -36, -34, -36, -36, -32, Blocks.STONE_BRICKS.getDefaultState());
        structure.fillWithBlocks(world, start, -36, -36, -31, -34, -36, -29, Blocks.AIR.getDefaultState());
        structure.fillWithBlocks(world, start, -36, -36, -23, -34, -36, -21, Blocks.AIR.getDefaultState());
        structure.fillWithBlocks(world, start, -36, -36, -16, -34, -36, -13, Blocks.STONE_BRICKS.getDefaultState());
        structure.fillWithBlocks(world, start, -36, -36, -12, -34, -36, -6, Blocks.AIR.getDefaultState());
        structure.fillWithBlocks(world, start, -36, -36, -5, -34, -36, 0, Blocks.STONE_BRICKS.getDefaultState());
        structure.fillWithBlocks(world, start, -36, -36, 1, -34, -36, 15, Blocks.AIR.getDefaultState());
        structure.fillWithBlocks(world, start, -36, -35, -33, -36, -34, -32, Blocks.STONE_BRICKS.getDefaultState());
        structure.fillWithBlocks(world, start, -36, -35, -31, -34, -35, -29, Blocks.AIR.getDefaultState());
        structure.fillWithBlocks(world, start, -36, -35, -28, -35, -35, -24, Blocks.STONE_BRICKS.getDefaultState());
        structure.fillWithBlocks(world, start, -36, -35, -23, -34, -35, -21, Blocks.AIR.getDefaultState());
        structure.fillWithBlocks(world, start, -36, -35, -19, -33, -35, -14, Blocks.STONE_BRICKS.getDefaultState());
        structure.fillWithBlocks(world, start, -36, -35, -10, -33, -35, -7, Blocks.AIR.getDefaultState());
        structure.fillWithBlocks(world, start, -36, -35, 2, -34, -35, 4, Blocks.AIR.getDefaultState());
        structure.fillWithBlocks(world, start, -36, -35, 5, -34, -35, 5, Blocks.STONE_BRICKS.getDefaultState());
        structure.fillWithBlocks(world, start, -36, -35, 6, -34, -35, 10, Blocks.AIR.getDefaultState());
        structure.fillWithBlocks(world, start, -36, -35, 11, -33, -32, 11, Blocks.STONE_BRICKS.getDefaultState());
        structure.fillWithBlocks(world, start, -36, -35, 12, -34, -35, 14, Blocks.AIR.getDefaultState());
        structure.fillWithBlocks(world, start, -36, -35, 15, -36, -35, 15, Blocks.STONE_BRICKS.getDefaultState());
        structure.fillWithBlocks(world, start, -36, -34, -36, -35, -34, -35, Blocks.STONE_BRICKS.getDefaultState());
        structure.fillWithBlocks(world, start, -36, -34, -34, -36, -34, -29, Blocks.STONE_BRICKS.getDefaultState());
        structure.fillWithBlocks(world, start, -36, -34, -27, -33, -34, -23, Blocks.STONE_BRICKS.getDefaultState());
        structure.fillWithBlocks(world, start, -36, -34, -19, -35, -34, -19, Blocks.AIR.getDefaultState());
        structure.fillWithBlocks(world, start, -36, -34, -18, -35, -34, -11, Blocks.STONE_BRICKS.getDefaultState());
        structure.fillWithBlocks(world, start, -36, -34, -5, -35, -34, -3, Blocks.STONE_BRICKS.getDefaultState());
        structure.fillWithBlocks(world, start, -36, -34, -2, -35, -34, -2, Blocks.AIR.getDefaultState());
        structure.fillWithBlocks(world, start, -36, -34, 4, -36, -33, 14, Blocks.STONE_BRICKS.getDefaultState());
        structure.fillWithBlocks(world, start, -36, -34, 16, -22, -32, 16, Blocks.STONE_BRICKS.getDefaultState());
        structure.fillWithBlocks(world, start, -36, -33, -35, -33, -33, -30, Blocks.STONE_BRICKS.getDefaultState());
        structure.fillWithBlocks(world, start, -36, -33, -28, -34, -33, -24, Blocks.STONE_BRICKS.getDefaultState());
        structure.fillWithBlocks(world, start, -36, -33, -19, -35, -33, -13, Blocks.STONE_BRICKS.getDefaultState());
        structure.fillWithBlocks(world, start, -36, -33, -11, -36, -33, -11, Blocks.STONE_BRICKS.getDefaultState());
        structure.fillWithBlocks(world, start, -36, -33, -9, -36, -33, -9, Blocks.STONE_BRICKS.getDefaultState());
        structure.fillWithBlocks(world, start, -36, -33, -8, -36, -33, -7, Blocks.AIR.getDefaultState());
        structure.fillWithBlocks(world, start, -36, -33, -6, -35, -33, -1, Blocks.STONE_BRICKS.getDefaultState());
        structure.fillWithBlocks(world, start, -36, -33, 0, -36, -33, 16, Blocks.STONE_BRICKS.getDefaultState());
        structure.fillWithBlocks(world, start, -36, -32, -34, -36, -32, -34, Blocks.STONE_BRICKS.getDefaultState());
        structure.fillWithBlocks(world, start, -36, -32, -31, -35, -32, -23, Blocks.STONE_BRICKS.getDefaultState());
        structure.fillWithBlocks(world, start, -36, -32, -7, -35, -32, -6, Blocks.STONE_BRICKS.getDefaultState());
        structure.fillWithBlocks(world, start, -36, -32, -5, -36, -31, -5, Blocks.STONE_BRICKS.getDefaultState());
        structure.fillWithBlocks(world, start, -36, -32, -4, -36, -32, -4, Blocks.AIR.getDefaultState());
        structure.fillWithBlocks(world, start, -36, -32, -3, -36, -32, 3, Blocks.STONE_BRICKS.getDefaultState());
        structure.fillWithBlocks(world, start, -36, -32, 4, -36, -32, 5, Blocks.AIR.getDefaultState());
        structure.fillWithBlocks(world, start, -36, -32, 6, -34, -32, 8, Blocks.STONE_BRICKS.getDefaultState());
        structure.fillWithBlocks(world, start, -36, -32, 10, -35, -32, 12, Blocks.STONE_BRICKS.getDefaultState());
        structure.fillWithBlocks(world, start, -36, -32, 13, -36, -32, 14, Blocks.STONE_BRICKS.getDefaultState());
        structure.fillWithBlocks(world, start, -36, -32, 15, -35, -32, 15, Blocks.AIR.getDefaultState());
        structure.fillWithBlocks(world, start, -36, -31, -31, -36, -31, -31, Blocks.AIR.getDefaultState());
        structure.fillWithBlocks(world, start, -36, -31, -30, -36, -31, -29, Blocks.STONE_BRICKS.getDefaultState());
        structure.fillWithBlocks(world, start, -36, -31, -27, -35, -31, -24, Blocks.STONE_BRICKS.getDefaultState());
        structure.fillWithBlocks(world, start, -36, -31, -11, -34, -31, -9, Blocks.STONE_BRICKS.getDefaultState());
        structure.fillWithBlocks(world, start, -36, -31, -8, -36, -30, -8, Blocks.SANDSTONE.getDefaultState());
        structure.fillWithBlocks(world, start, -36, -31, -6, -35, -31, -5, Blocks.STONE_BRICKS.getDefaultState());
        structure.fillWithBlocks(world, start, -36, -31, -4, -36, -31, -3, Blocks.STONE_BRICKS.getDefaultState());
        structure.fillWithBlocks(world, start, -36, -31, -1, -34, -31, 1, Blocks.STONE_BRICKS.getDefaultState());
        structure.fillWithBlocks(world, start, -36, -31, 2, -36, -31, 3, Blocks.STONE_BRICKS.getDefaultState());
        structure.fillWithBlocks(world, start, -36, -31, 4, -36, -31, 4, Blocks.AIR.getDefaultState());
        structure.fillWithBlocks(world, start, -36, -31, 5, -36, -31, 13, Blocks.STONE_BRICKS.getDefaultState());
        structure.fillWithBlocks(world, start, -36, -31, 15, -36, -31, 16, Blocks.STONE_BRICKS.getDefaultState());
        structure.fillWithBlocks(world, start, -36, -30, -53, -35, -29, -53, Blocks.STONE_BRICKS.getDefaultState());
        structure.fillWithBlocks(world, start, -36, -30, -52, -36, -30, -52, Blocks.AIR.getDefaultState());
        structure.fillWithBlocks(world, start, -36, -30, -50, -35, -30, -50, Blocks.AIR.getDefaultState());
        structure.fillWithBlocks(world, start, -36, -30, -49, -36, -30, -49, Blocks.SANDSTONE.getDefaultState());
        structure.fillWithBlocks(world, start, -36, -30, -47, -36, -30, -5, Blocks.SANDSTONE.getDefaultState());
        structure.fillWithBlocks(world, start, -36, -30, -4, -36, -29, -4, Blocks.AIR.getDefaultState());
        structure.fillWithBlocks(world, start, -36, -30, -3, -35, -30, -2, Blocks.SANDSTONE.getDefaultState());
        structure.fillWithBlocks(world, start, -36, -30, 2, -36, -30, 11, Blocks.SANDSTONE.getDefaultState());
        structure.fillWithBlocks(world, start, -36, -30, 17, -36, -30, 18, Blocks.SANDSTONE.getDefaultState());
        structure.fillWithBlocks(world, start, -36, -29, -49, -36, -29, -48, Blocks.STONE_BRICKS.getDefaultState());
        structure.fillWithBlocks(world, start, -36, -29, -43, -34, -29, -41, Blocks.AIR.getDefaultState());
        structure.fillWithBlocks(world, start, -36, -29, -5, -36, -29, -5, Blocks.SANDSTONE.getDefaultState());
        structure.fillWithBlocks(world, start, -36, -29, -3, -36, -29, -3, Blocks.SANDSTONE.getDefaultState());
        structure.fillWithBlocks(world, start, -36, -29, -1, -36, -29, -1, Blocks.SANDSTONE.getDefaultState());
        structure.fillWithBlocks(world, start, -36, -29, 1, -35, -29, 4, Blocks.SANDSTONE.getDefaultState());
        structure.fillWithBlocks(world, start, -36, -29, 12, -35, -29, 13, Blocks.SANDSTONE.getDefaultState());
        structure.fillWithBlocks(world, start, -36, -29, 14, -36, -29, 15, Blocks.AIR.getDefaultState());
        structure.fillWithBlocks(world, start, -36, -28, -53, -36, -28, -52, Blocks.SANDSTONE.getDefaultState());
        structure.fillWithBlocks(world, start, -36, -28, -51, -36, -27, -51, Blocks.AIR.getDefaultState());
        structure.fillWithBlocks(world, start, -36, -28, -50, -36, -27, -50, Blocks.DIRT.getDefaultState());
        structure.fillWithBlocks(world, start, -36, -28, -49, -36, -27, -48, Blocks.AIR.getDefaultState());
        structure.fillWithBlocks(world, start, -36, -28, -5, -36, -28, -3, Blocks.SHROOMLIGHT.getDefaultState());
        structure.fillWithBlocks(world, start, -36, -28, -2, -34, -28, 0, Blocks.SANDSTONE.getDefaultState());
        structure.fillWithBlocks(world, start, -36, -28, 2, -36, -27, 3, Blocks.AIR.getDefaultState());
        structure.fillWithBlocks(world, start, -36, -28, 12, -36, -28, 14, Blocks.SHROOMLIGHT.getDefaultState());
        structure.fillWithBlocks(world, start, -36, -28, 15, -36, -28, 18, Blocks.SANDSTONE.getDefaultState());
        structure.fillWithBlocks(world, start, -36, -27, -53, -36, -27, -53, Blocks.AIR.getDefaultState());
        structure.fillWithBlocks(world, start, -36, -27, -52, -36, -26, -52, Blocks.SANDSTONE.getDefaultState());
        structure.fillWithBlocks(world, start, -36, -27, -5, -36, -27, -5, Blocks.SANDSTONE.getDefaultState());
        structure.fillWithBlocks(world, start, -36, -27, -4, -36, -27, -3, Blocks.AIR.getDefaultState());
        structure.fillWithBlocks(world, start, -36, -27, -2, -36, -27, -2, Blocks.SANDSTONE.getDefaultState());
        structure.fillWithBlocks(world, start, -36, -27, 0, -35, -27, 1, Blocks.SANDSTONE.getDefaultState());
        structure.fillWithBlocks(world, start, -36, -27, 12, -36, -27, 12, Blocks.SANDSTONE.getDefaultState());
        structure.fillWithBlocks(world, start, -36, -27, 13, -36, -27, 14, Blocks.AIR.getDefaultState());
        structure.fillWithBlocks(world, start, -36, -27, 15, -36, -27, 15, Blocks.SANDSTONE.getDefaultState());
        structure.fillWithBlocks(world, start, -36, -27, 16, -36, -27, 16, Blocks.DIRT.getDefaultState());
        structure.fillWithBlocks(world, start, -36, -27, 17, -36, -27, 18, Blocks.SANDSTONE.getDefaultState());
        structure.fillWithBlocks(world, start, -36, -26, -53, -36, -25, -53, Blocks.DIRT.getDefaultState());
        structure.fillWithBlocks(world, start, -36, -26, -51, -36, -25, -51, Blocks.STONE_BRICKS.getDefaultState());
        structure.fillWithBlocks(world, start, -36, -26, -50, -36, -26, -50, Blocks.SANDSTONE.getDefaultState());
        structure.fillWithBlocks(world, start, -36, -26, -49, -36, -25, -48, Blocks.AIR.getDefaultState());
        structure.fillWithBlocks(world, start, -36, -26, -4, -36, -26, -4, Blocks.SANDSTONE.getDefaultState());
        structure.fillWithBlocks(world, start, -36, -26, -3, -36, -25, -3, Blocks.AIR.getDefaultState());
        structure.fillWithBlocks(world, start, -36, -26, -2, -36, -26, -2, Blocks.SANDSTONE.getDefaultState());
        structure.fillWithBlocks(world, start, -36, -26, -1, -36, -26, -1, Blocks.AIR.getDefaultState());
        structure.fillWithBlocks(world, start, -36, -26, 0, -36, -26, 2, Blocks.SANDSTONE.getDefaultState());
        structure.fillWithBlocks(world, start, -36, -26, 3, -36, -26, 4, Blocks.SHROOMLIGHT.getDefaultState());
        structure.fillWithBlocks(world, start, -36, -26, 12, -36, -26, 14, Blocks.SHROOMLIGHT.getDefaultState());
        structure.fillWithBlocks(world, start, -36, -26, 15, -36, -25, 17, Blocks.SANDSTONE.getDefaultState());
        structure.fillWithBlocks(world, start, -36, -25, -52, -36, -25, -50, Blocks.STONE_BRICKS.getDefaultState());
        structure.fillWithBlocks(world, start, -36, -25, -4, -36, -25, -3, Blocks.AIR.getDefaultState());
        structure.fillWithBlocks(world, start, -36, -25, -2, -35, -25, -1, Blocks.SANDSTONE.getDefaultState());
        structure.fillWithBlocks(world, start, -36, -25, 2, -36, -25, 2, Blocks.SANDSTONE.getDefaultState());
        structure.fillWithBlocks(world, start, -36, -25, 3, -36, -24, 3, Blocks.AIR.getDefaultState());
        structure.fillWithBlocks(world, start, -36, -25, 12, -36, -25, 12, Blocks.SANDSTONE.getDefaultState());
        structure.fillWithBlocks(world, start, -36, -25, 13, -36, -25, 14, Blocks.AIR.getDefaultState());
        structure.fillWithBlocks(world, start, -36, -25, 18, -28, -25, 18, Blocks.SANDSTONE.getDefaultState());
        structure.fillWithBlocks(world, start, -36, -24, -48, -29, -24, -48, Blocks.SANDSTONE.getDefaultState());
        structure.fillWithBlocks(world, start, -36, -24, -33, -34, -24, -31, Blocks.SANDSTONE.getDefaultState());
        structure.fillWithBlocks(world, start, -36, -24, -30, -35, -24, -28, Blocks.SANDSTONE.getDefaultState());
        structure.fillWithBlocks(world, start, -36, -24, -27, -34, -24, -25, Blocks.AIR.getDefaultState());
        structure.fillWithBlocks(world, start, -36, -24, -24, -34, -24, -22, Blocks.SANDSTONE.getDefaultState());
        structure.fillWithBlocks(world, start, -36, -24, -21, -35, -24, -7, Blocks.SANDSTONE.getDefaultState());
        structure.fillWithBlocks(world, start, -36, -24, -1, -36, -23, -1, Blocks.AIR.getDefaultState());
        structure.fillWithBlocks(world, start, -36, -24, 0, -34, -24, 2, Blocks.SANDSTONE.getDefaultState());
        structure.fillWithBlocks(world, start, -36, -24, 4, -30, -24, 12, Blocks.SANDSTONE.getDefaultState());
        structure.fillWithBlocks(world, start, -36, -24, 13, -36, -24, 14, Blocks.DIRT.getDefaultState());
        structure.fillWithBlocks(world, start, -36, -24, 15, -36, -24, 15, Blocks.SANDSTONE.getDefaultState());
        structure.fillWithBlocks(world, start, -36, -24, 17, -36, -23, 18, Blocks.SANDSTONE.getDefaultState());
        structure.fillWithBlocks(world, start, -36, -23, -53, -36, -23, -51, Blocks.STONE_BRICKS.getDefaultState());
        structure.fillWithBlocks(world, start, -36, -23, -49, -36, -23, -48, Blocks.AIR.getDefaultState());
        structure.fillWithBlocks(world, start, -36, -23, -46, -36, -23, -43, Blocks.STONE_BRICKS.getDefaultState());
        structure.fillWithBlocks(world, start, -36, -23, -42, -36, -23, -41, Blocks.AIR.getDefaultState());
        structure.fillWithBlocks(world, start, -36, -23, -40, -36, -23, -40, Blocks.SANDSTONE.getDefaultState());
        structure.fillWithBlocks(world, start, -36, -23, -37, -35, -23, -36, Blocks.SANDSTONE.getDefaultState());
        structure.fillWithBlocks(world, start, -36, -23, -35, -36, -23, -25, Blocks.SANDSTONE.getDefaultState());
        structure.fillWithBlocks(world, start, -36, -23, -23, -35, -23, -22, Blocks.SANDSTONE.getDefaultState());
        structure.fillWithBlocks(world, start, -36, -23, -18, -36, -21, -16, Blocks.SANDSTONE.getDefaultState());
        structure.fillWithBlocks(world, start, -36, -23, -14, -36, -23, -14, Blocks.SANDSTONE.getDefaultState());
        structure.fillWithBlocks(world, start, -36, -23, -13, -36, -23, -12, Blocks.AIR.getDefaultState());
        structure.fillWithBlocks(world, start, -36, -23, -10, -35, -23, -9, Blocks.SANDSTONE.getDefaultState());
        structure.fillWithBlocks(world, start, -36, -23, -7, -36, -22, -3, Blocks.SANDSTONE.getDefaultState());
        structure.fillWithBlocks(world, start, -36, -23, -2, -36, -23, -1, Blocks.AIR.getDefaultState());
        structure.fillWithBlocks(world, start, -36, -23, 0, -36, -21, 0, Blocks.SANDSTONE.getDefaultState());
        structure.fillWithBlocks(world, start, -36, -23, 1, -35, -23, 1, Blocks.AIR.getDefaultState());
        structure.fillWithBlocks(world, start, -36, -23, 10, -36, -23, 11, Blocks.SANDSTONE.getDefaultState());
        structure.fillWithBlocks(world, start, -36, -23, 12, -36, -23, 13, Blocks.AIR.getDefaultState());
        structure.fillWithBlocks(world, start, -36, -23, 14, -36, -23, 18, Blocks.SANDSTONE.getDefaultState());
        structure.fillWithBlocks(world, start, -36, -22, -53, -34, -21, -53, Blocks.STONE_BRICKS.getDefaultState());
        structure.fillWithBlocks(world, start, -36, -22, -52, -36, -21, -52, Blocks.DIRT.getDefaultState());
        structure.fillWithBlocks(world, start, -36, -22, -51, -35, -22, -50, Blocks.STONE_BRICKS.getDefaultState());
        structure.fillWithBlocks(world, start, -36, -22, -48, -36, -22, -48, Blocks.STONE_BRICKS.getDefaultState());
        structure.fillWithBlocks(world, start, -36, -22, -46, -36, -21, -46, Blocks.STONE_BRICKS.getDefaultState());
        structure.fillWithBlocks(world, start, -36, -22, -45, -36, -22, -44, Blocks.SANDSTONE.getDefaultState());
        structure.fillWithBlocks(world, start, -36, -22, -43, -36, -21, -43, Blocks.STONE_BRICKS.getDefaultState());
        structure.fillWithBlocks(world, start, -36, -22, -41, -36, -22, -41, Blocks.STONE_BRICKS.getDefaultState());
        structure.fillWithBlocks(world, start, -36, -22, -40, -36, -22, -34, Blocks.SANDSTONE.getDefaultState());
        structure.fillWithBlocks(world, start, -36, -22, -32, -35, -22, -31, Blocks.SANDSTONE.getDefaultState());
        structure.fillWithBlocks(world, start, -36, -22, -24, -35, -22, -16, Blocks.SANDSTONE.getDefaultState());
        structure.fillWithBlocks(world, start, -36, -22, -15, -36, -22, -14, Blocks.AIR.getDefaultState());
        structure.fillWithBlocks(world, start, -36, -22, -13, -34, -22, -10, Blocks.SANDSTONE.getDefaultState());
        structure.fillWithBlocks(world, start, -36, -22, -2, -34, -22, 0, Blocks.SANDSTONE.getDefaultState());
        structure.fillWithBlocks(world, start, -36, -22, 1, -34, -22, 1, Blocks.DIRT.getDefaultState());
        structure.fillWithBlocks(world, start, -36, -22, 6, -34, -22, 8, Blocks.SANDSTONE.getDefaultState());
        structure.fillWithBlocks(world, start, -36, -22, 9, -36, -21, 9, Blocks.DIRT.getDefaultState());
        structure.fillWithBlocks(world, start, -36, -22, 12, -35, -22, 13, Blocks.SANDSTONE.getDefaultState());
        structure.fillWithBlocks(world, start, -36, -22, 14, -36, -22, 14, Blocks.SANDSTONE.getDefaultState());
        structure.fillWithBlocks(world, start, -36, -21, -51, -36, -21, -43, Blocks.STONE_BRICKS.getDefaultState());
        structure.fillWithBlocks(world, start, -36, -21, -41, -35, -21, -41, Blocks.STONE_BRICKS.getDefaultState());
        structure.fillWithBlocks(world, start, -36, -21, -34, -35, -21, -30, Blocks.SANDSTONE.getDefaultState());
        structure.fillWithBlocks(world, start, -36, -21, -27, -36, -21, -26, Blocks.SANDSTONE.getDefaultState());
        structure.fillWithBlocks(world, start, -36, -21, -24, -36, -21, -24, Blocks.SANDSTONE.getDefaultState());
        structure.fillWithBlocks(world, start, -36, -21, -23, -36, -21, -22, Blocks.DIRT.getDefaultState());
        structure.fillWithBlocks(world, start, -36, -21, -21, -35, -21, -14, Blocks.SANDSTONE.getDefaultState());
        structure.fillWithBlocks(world, start, -36, -21, -12, -25, -21, -12, Blocks.SANDSTONE.getDefaultState());
        structure.fillWithBlocks(world, start, -36, -21, -10, -35, -21, -9, Blocks.SANDSTONE.getDefaultState());
        structure.fillWithBlocks(world, start, -36, -21, -7, -35, -21, -6, Blocks.SANDSTONE.getDefaultState());
        structure.fillWithBlocks(world, start, -36, -21, -4, -35, -21, -3, Blocks.SANDSTONE.getDefaultState());
        structure.fillWithBlocks(world, start, -36, -21, 3, -35, -21, 5, Blocks.SANDSTONE.getDefaultState());
        structure.fillWithBlocks(world, start, -36, -21, 8, -35, -21, 8, Blocks.AIR.getDefaultState());
        structure.fillWithBlocks(world, start, -36, -21, 10, -35, -21, 13, Blocks.SANDSTONE.getDefaultState());
        structure.fillWithBlocks(world, start, -36, -21, 16, -35, -21, 17, Blocks.SANDSTONE.getDefaultState());
        structure.fillWithBlocks(world, start, -36, -20, -11, -33, -20, -7, Blocks.SANDSTONE.getDefaultState());
        structure.fillWithBlocks(world, start, -36, -17, -12, -35, -17, -12, Blocks.STONE_BRICKS.getDefaultState());
        structure.fillWithBlocks(world, start, -36, -17, -6, -35, -17, -6, Blocks.STONE_BRICKS.getDefaultState());
        structure.fillWithBlocks(world, start, -36, -16, -11, -33, -16, -7, Blocks.SANDSTONE.getDefaultState());
        structure.fillWithBlocks(world, start, -35, -48, -12, -35, -48, -12, Blocks.SANDSTONE.getDefaultState());
        structure.fillWithBlocks(world, start, -35, -48, -6, -31, -47, -6, Blocks.SANDSTONE.getDefaultState());
        structure.fillWithBlocks(world, start, -35, -40, -34, -33, -40, -20, Blocks.STONE_BRICKS.getDefaultState());
        structure.fillWithBlocks(world, start, -35, -40, 0, -34, -40, 1, Blocks.STONE_BRICKS.getDefaultState());
        structure.fillWithBlocks(world, start, -35, -39, -36, -33, -39, -33, Blocks.STONE_BRICKS.getDefaultState());
        structure.fillWithBlocks(world, start, -35, -39, -32, -33, -39, -29, Blocks.AIR.getDefaultState());
        structure.fillWithBlocks(world, start, -35, -39, -20, -33, -37, -20, Blocks.AIR.getDefaultState());
        structure.fillWithBlocks(world, start, -35, -39, -19, -34, -39, -17, Blocks.STONE_BRICKS.getDefaultState());
        structure.fillWithBlocks(world, start, -35, -39, -16, -35, -37, -14, Blocks.STONE_BRICKS.getDefaultState());
        structure.fillWithBlocks(world, start, -35, -39, -13, -35, -37, -13, Blocks.IRON_BARS.getDefaultState().with(FourWayBlock.WATERLOGGED, false).with(FourWayBlock.NORTH, true).with(FourWayBlock.SOUTH, true).with(FourWayBlock.EAST, true).with(FourWayBlock.WEST, true));
        structure.fillWithBlocks(world, start, -35, -39, -5, -35, -37, -5, Blocks.IRON_BARS.getDefaultState().with(FourWayBlock.WATERLOGGED, false).with(FourWayBlock.NORTH, true).with(FourWayBlock.SOUTH, true).with(FourWayBlock.EAST, true).with(FourWayBlock.WEST, true));
        structure.fillWithBlocks(world, start, -35, -39, -4, -35, -35, 0, Blocks.STONE_BRICKS.getDefaultState());
        structure.fillWithBlocks(world, start, -35, -38, -32, -33, -38, -29, Blocks.AIR.getDefaultState());
        structure.fillWithBlocks(world, start, -35, -38, -17, -35, -35, -14, Blocks.STONE_BRICKS.getDefaultState());
        structure.fillWithBlocks(world, start, -35, -37, -34, -35, -37, -33, Blocks.STONE_BRICKS.getDefaultState());
        structure.fillWithBlocks(world, start, -35, -37, -32, -33, -37, -29, Blocks.AIR.getDefaultState());
        structure.fillWithBlocks(world, start, -35, -37, -19, -34, -37, -17, Blocks.STONE_BRICKS.getDefaultState());
        structure.fillWithBlocks(world, start, -35, -36, -36, -34, -36, -34, Blocks.STONE_BRICKS.getDefaultState());
        structure.fillWithBlocks(world, start, -35, -36, -32, -33, -36, -29, Blocks.AIR.getDefaultState());
        structure.fillWithBlocks(world, start, -35, -36, -20, -33, -35, -20, Blocks.AIR.getDefaultState());
        structure.fillWithBlocks(world, start, -35, -36, -18, -34, -36, -13, Blocks.STONE_BRICKS.getDefaultState());
        structure.fillWithBlocks(world, start, -35, -35, -36, -35, -34, -35, Blocks.STONE_BRICKS.getDefaultState());
        structure.fillWithBlocks(world, start, -35, -35, -34, -34, -35, -33, Blocks.STONE_BRICKS.getDefaultState());
        structure.fillWithBlocks(world, start, -35, -35, -32, -33, -35, -29, Blocks.AIR.getDefaultState());
        structure.fillWithBlocks(world, start, -35, -35, -13, -35, -35, -12, Blocks.STONE_BRICKS.getDefaultState());
        structure.fillWithBlocks(world, start, -35, -35, -11, -31, -35, -7, Blocks.AIR.getDefaultState());
        structure.fillWithBlocks(world, start, -35, -35, 1, -31, -33, 1, Blocks.STONE_BRICKS.getDefaultState());
        structure.fillWithBlocks(world, start, -35, -35, 15, -34, -35, 16, Blocks.STONE_BRICKS.getDefaultState());
        structure.fillWithBlocks(world, start, -35, -34, -28, -33, -34, -23, Blocks.STONE_BRICKS.getDefaultState());
        structure.fillWithBlocks(world, start, -35, -34, -10, -33, -34, -8, Blocks.AIR.getDefaultState());
        structure.fillWithBlocks(world, start, -35, -34, -7, -34, -34, -5, Blocks.STONE_BRICKS.getDefaultState());
        structure.fillWithBlocks(world, start, -35, -34, 4, -35, -34, 4, Blocks.STONE_BRICKS.getDefaultState());
        structure.fillWithBlocks(world, start, -35, -34, 6, -34, -34, 7, Blocks.STONE_BRICKS.getDefaultState());
        structure.fillWithBlocks(world, start, -35, -34, 9, -33, -34, 12, Blocks.STONE_BRICKS.getDefaultState());
        structure.fillWithBlocks(world, start, -35, -34, 14, -33, -34, 16, Blocks.STONE_BRICKS.getDefaultState());
        structure.fillWithBlocks(world, start, -35, -33, -36, -33, -33, -28, Blocks.STONE_BRICKS.getDefaultState());
        structure.fillWithBlocks(world, start, -35, -33, -23, -35, -33, -22, Blocks.AIR.getDefaultState());
        structure.fillWithBlocks(world, start, -35, -33, -21, -34, -33, -18, Blocks.STONE_BRICKS.getDefaultState());
        structure.fillWithBlocks(world, start, -35, -33, -12, -33, -33, -10, Blocks.STONE_BRICKS.getDefaultState());
        structure.fillWithBlocks(world, start, -35, -33, -9, -35, -33, -1, Blocks.STONE_BRICKS.getDefaultState());
        structure.fillWithBlocks(world, start, -35, -33, 12, -33, -33, 14, Blocks.STONE_BRICKS.getDefaultState());
        structure.fillWithBlocks(world, start, -35, -33, 15, -35, -32, 15, Blocks.AIR.getDefaultState());
        structure.fillWithBlocks(world, start, -35, -32, -36, -33, -32, -32, Blocks.STONE_BRICKS.getDefaultState());
        structure.fillWithBlocks(world, start, -35, -32, -22, -35, -31, -22, Blocks.AIR.getDefaultState());
        structure.fillWithBlocks(world, start, -35, -32, -21, -35, -31, -17, Blocks.STONE_BRICKS.getDefaultState());
        structure.fillWithBlocks(world, start, -35, -32, -15, -35, -32, -6, Blocks.STONE_BRICKS.getDefaultState());
        structure.fillWithBlocks(world, start, -35, -32, -5, -34, -32, -5, Blocks.AIR.getDefaultState());
        structure.fillWithBlocks(world, start, -35, -32, -4, -34, -32, -4, Blocks.STONE_BRICKS.getDefaultState());
        structure.fillWithBlocks(world, start, -35, -32, -3, -34, -32, -3, Blocks.AIR.getDefaultState());
        structure.fillWithBlocks(world, start, -35, -32, -1, -35, -31, 1, Blocks.STONE_BRICKS.getDefaultState());
        structure.fillWithBlocks(world, start, -35, -32, 2, -35, -31, 2, Blocks.AIR.getDefaultState());
        structure.fillWithBlocks(world, start, -35, -32, 3, -31, -32, 9, Blocks.STONE_BRICKS.getDefaultState());
        structure.fillWithBlocks(world, start, -35, -32, 13, -35, -31, 13, Blocks.AIR.getDefaultState());
        structure.fillWithBlocks(world, start, -35, -32, 14, -35, -32, 14, Blocks.STONE_BRICKS.getDefaultState());
        structure.fillWithBlocks(world, start, -35, -31, -31, -35, -31, -31, Blocks.STONE_BRICKS.getDefaultState());
        structure.fillWithBlocks(world, start, -35, -31, -29, -34, -31, -28, Blocks.STONE_BRICKS.getDefaultState());
        structure.fillWithBlocks(world, start, -35, -31, -23, -35, -21, -23, Blocks.SANDSTONE.getDefaultState());
        structure.fillWithBlocks(world, start, -35, -31, -16, -35, -31, -16, Blocks.STONE_BRICKS.getDefaultState());
        structure.fillWithBlocks(world, start, -35, -31, -15, -35, -30, -15, Blocks.SANDSTONE.getDefaultState());
        structure.fillWithBlocks(world, start, -35, -31, -14, -32, -31, -10, Blocks.STONE_BRICKS.getDefaultState());
        structure.fillWithBlocks(world, start, -35, -31, -8, -34, -31, -5, Blocks.STONE_BRICKS.getDefaultState());
        structure.fillWithBlocks(world, start, -35, -31, -3, -32, -31, 1, Blocks.STONE_BRICKS.getDefaultState());
        structure.fillWithBlocks(world, start, -35, -31, 3, -35, -31, 4, Blocks.STONE_BRICKS.getDefaultState());
        structure.fillWithBlocks(world, start, -35, -31, 6, -35, -31, 6, Blocks.STONE_BRICKS.getDefaultState());
        structure.fillWithBlocks(world, start, -35, -31, 14, -35, -31, 15, Blocks.STONE_BRICKS.getDefaultState());
        structure.fillWithBlocks(world, start, -35, -30, -52, -35, -29, -52, Blocks.DIRT.getDefaultState());
        structure.fillWithBlocks(world, start, -35, -30, -51, -35, -30, -50, Blocks.AIR.getDefaultState());
        structure.fillWithBlocks(world, start, -35, -30, -49, -33, -30, -47, Blocks.SANDSTONE.getDefaultState());
        structure.fillWithBlocks(world, start, -35, -30, -45, -31, -30, -41, Blocks.SANDSTONE.getDefaultState());
        structure.fillWithBlocks(world, start, -35, -30, -39, -34, -30, -38, Blocks.SANDSTONE.getDefaultState());
        structure.fillWithBlocks(world, start, -35, -30, -36, -35, -30, -13, Blocks.SANDSTONE.getDefaultState());
        structure.fillWithBlocks(world, start, -35, -30, -12, -35, -30, -12, Blocks.DIRT.getDefaultState());
        structure.fillWithBlocks(world, start, -35, -30, -11, -35, -30, -7, Blocks.SANDSTONE.getDefaultState());
        structure.fillWithBlocks(world, start, -35, -30, -5, -35, -28, -5, Blocks.SANDSTONE.getDefaultState());
        structure.fillWithBlocks(world, start, -35, -30, -4, -34, -30, -4, Blocks.DIRT.getDefaultState());
        structure.fillWithBlocks(world, start, -35, -30, -1, -35, -30, 0, Blocks.SANDSTONE.getDefaultState());
        structure.fillWithBlocks(world, start, -35, -30, 1, -35, -30, 2, Blocks.DIRT.getDefaultState());
        structure.fillWithBlocks(world, start, -35, -30, 3, -35, -30, 3, Blocks.SANDSTONE.getDefaultState());
        structure.fillWithBlocks(world, start, -35, -30, 5, -30, -30, 11, Blocks.SANDSTONE.getDefaultState());
        structure.fillWithBlocks(world, start, -35, -30, 14, -35, -30, 15, Blocks.AIR.getDefaultState());
        structure.fillWithBlocks(world, start, -35, -30, 16, -35, -30, 16, Blocks.SANDSTONE.getDefaultState());
        structure.fillWithBlocks(world, start, -35, -30, 18, -33, -29, 18, Blocks.SANDSTONE.getDefaultState());
        structure.fillWithBlocks(world, start, -35, -29, -50, -35, -25, -46, Blocks.SANDSTONE.getDefaultState());
        structure.fillWithBlocks(world, start, -35, -29, -45, -31, -29, -41, Blocks.AIR.getDefaultState());
        structure.fillWithBlocks(world, start, -35, -29, -39, -34, -29, -38, Blocks.AIR.getDefaultState());
        structure.fillWithBlocks(world, start, -35, -29, -37, -33, -29, -35, Blocks.SANDSTONE.getDefaultState());
        structure.fillWithBlocks(world, start, -35, -29, -34, -35, -26, -30, Blocks.AIR.getDefaultState());
        structure.fillWithBlocks(world, start, -35, -29, -29, -35, -22, -29, Blocks.SANDSTONE.getDefaultState());
        structure.fillWithBlocks(world, start, -35, -29, -28, -33, -29, -24, Blocks.AIR.getDefaultState());
        structure.fillWithBlocks(world, start, -35, -29, -22, -35, -26, -13, Blocks.AIR.getDefaultState());
        structure.fillWithBlocks(world, start, -35, -29, -12, -35, -29, -12, Blocks.SANDSTONE.getDefaultState());
        structure.fillWithBlocks(world, start, -35, -29, -11, -35, -25, -7, Blocks.AIR.getDefaultState());
        structure.fillWithBlocks(world, start, -35, -29, -6, -34, -29, -5, Blocks.SANDSTONE.getDefaultState());
        structure.fillWithBlocks(world, start, -35, -29, -4, -35, -29, 5, Blocks.SANDSTONE.getDefaultState());
        structure.fillWithBlocks(world, start, -35, -29, 6, -34, -29, 7, Blocks.AIR.getDefaultState());
        structure.fillWithBlocks(world, start, -35, -29, 9, -34, -29, 10, Blocks.AIR.getDefaultState());
        structure.fillWithBlocks(world, start, -35, -29, 11, -35, -25, 15, Blocks.SANDSTONE.getDefaultState());
        structure.fillWithBlocks(world, start, -35, -29, 17, -34, -29, 18, Blocks.SANDSTONE.getDefaultState());
        structure.fillWithBlocks(world, start, -35, -28, -53, -35, -28, -52, Blocks.STONE_BRICKS.getDefaultState());
        structure.fillWithBlocks(world, start, -35, -28, -51, -35, -27, -46, Blocks.SANDSTONE.getDefaultState());
        structure.fillWithBlocks(world, start, -35, -28, -45, -30, -28, -38, Blocks.AIR.getDefaultState());
        structure.fillWithBlocks(world, start, -35, -28, -37, -33, -28, -35, Blocks.SANDSTONE.getDefaultState());
        structure.fillWithBlocks(world, start, -35, -28, -28, -31, -28, -24, Blocks.AIR.getDefaultState());
        structure.fillWithBlocks(world, start, -35, -28, -12, -31, -24, -12, Blocks.SANDSTONE.getDefaultState());
        structure.fillWithBlocks(world, start, -35, -28, -6, -35, -28, 5, Blocks.SANDSTONE.getDefaultState());
        structure.fillWithBlocks(world, start, -35, -28, 6, -31, -28, 10, Blocks.AIR.getDefaultState());
        structure.fillWithBlocks(world, start, -35, -28, 17, -29, -28, 17, Blocks.SANDSTONE.getDefaultState());
        structure.fillWithBlocks(world, start, -35, -28, 18, -34, -28, 18, Blocks.AIR.getDefaultState());
        structure.fillWithBlocks(world, start, -35, -27, -53, -35, -25, -53, Blocks.STONE_BRICKS.getDefaultState());
        structure.fillWithBlocks(world, start, -35, -27, -52, -35, -26, -52, Blocks.AIR.getDefaultState());
        structure.fillWithBlocks(world, start, -35, -27, -45, -30, -27, -38, Blocks.AIR.getDefaultState());
        structure.fillWithBlocks(world, start, -35, -27, -37, -35, -25, -35, Blocks.SANDSTONE.getDefaultState());
        structure.fillWithBlocks(world, start, -35, -27, -28, -31, -27, -24, Blocks.AIR.getDefaultState());
        structure.fillWithBlocks(world, start, -35, -27, -6, -35, -27, -6, Blocks.SANDSTONE.getDefaultState());
        structure.fillWithBlocks(world, start, -35, -27, -4, -35, -25, -1, Blocks.SANDSTONE.getDefaultState());
        structure.fillWithBlocks(world, start, -35, -27, 2, -35, -24, 5, Blocks.SANDSTONE.getDefaultState());
        structure.fillWithBlocks(world, start, -35, -27, 6, -31, -27, 10, Blocks.AIR.getDefaultState());
        structure.fillWithBlocks(world, start, -35, -27, 16, -35, -27, 16, Blocks.SANDSTONE.getDefaultState());
        structure.fillWithBlocks(world, start, -35, -27, 18, -34, -26, 18, Blocks.SANDSTONE.getDefaultState());
        structure.fillWithBlocks(world, start, -35, -26, -51, -35, -25, -51, Blocks.AIR.getDefaultState());
        structure.fillWithBlocks(world, start, -35, -26, -45, -30, -26, -38, Blocks.AIR.getDefaultState());
        structure.fillWithBlocks(world, start, -35, -26, -28, -31, -26, -24, Blocks.AIR.getDefaultState());
        structure.fillWithBlocks(world, start, -35, -26, -6, -35, -25, -1, Blocks.SANDSTONE.getDefaultState());
        structure.fillWithBlocks(world, start, -35, -26, 0, -35, -26, 0, Blocks.AIR.getDefaultState());
        structure.fillWithBlocks(world, start, -35, -26, 6, -31, -26, 10, Blocks.AIR.getDefaultState());
        structure.fillWithBlocks(world, start, -35, -26, 17, -35, -26, 18, Blocks.SANDSTONE.getDefaultState());
        structure.fillWithBlocks(world, start, -35, -25, -45, -30, -25, -38, Blocks.AIR.getDefaultState());
        structure.fillWithBlocks(world, start, -35, -25, -34, -35, -25, -29, Blocks.SANDSTONE.getDefaultState());
        structure.fillWithBlocks(world, start, -35, -25, -28, -31, -25, -24, Blocks.AIR.getDefaultState());
        structure.fillWithBlocks(world, start, -35, -25, -22, -34, -25, -21, Blocks.SANDSTONE.getDefaultState());
        structure.fillWithBlocks(world, start, -35, -25, -20, -35, -25, -18, Blocks.SANDSTONE.getDefaultState());
        structure.fillWithBlocks(world, start, -35, -25, -17, -31, -25, -13, Blocks.AIR.getDefaultState());
        structure.fillWithBlocks(world, start, -35, -25, 0, -35, -24, 5, Blocks.SANDSTONE.getDefaultState());
        structure.fillWithBlocks(world, start, -35, -25, 6, -31, -25, 10, Blocks.AIR.getDefaultState());
        structure.fillWithBlocks(world, start, -35, -25, 16, -35, -24, 17, Blocks.SANDSTONE.getDefaultState());
        structure.fillWithBlocks(world, start, -35, -24, -53, -35, -23, -53, Blocks.DIRT.getDefaultState());
        structure.fillWithBlocks(world, start, -35, -24, -52, -35, -22, -52, Blocks.SANDSTONE.getDefaultState());
        structure.fillWithBlocks(world, start, -35, -24, -51, -29, -24, -51, Blocks.STONE_BRICKS.getDefaultState());
        structure.fillWithBlocks(world, start, -35, -24, -49, -34, -24, -48, Blocks.SANDSTONE.getDefaultState());
        structure.fillWithBlocks(world, start, -35, -24, -47, -35, -24, -46, Blocks.STONE_BRICKS.getDefaultState());
        structure.fillWithBlocks(world, start, -35, -24, -45, -31, -24, -41, Blocks.SANDSTONE.getDefaultState());
        structure.fillWithBlocks(world, start, -35, -24, -39, -33, -24, -37, Blocks.SANDSTONE.getDefaultState());
        structure.fillWithBlocks(world, start, -35, -24, -36, -35, -24, -35, Blocks.AIR.getDefaultState());
        structure.fillWithBlocks(world, start, -35, -24, -34, -34, -24, -31, Blocks.SANDSTONE.getDefaultState());
        structure.fillWithBlocks(world, start, -35, -24, -4, -35, -24, -4, Blocks.SANDSTONE.getDefaultState());
        structure.fillWithBlocks(world, start, -35, -24, -2, -33, -24, 16, Blocks.SANDSTONE.getDefaultState());
        structure.fillWithBlocks(world, start, -35, -23, -51, -35, -23, -49, Blocks.STONE_BRICKS.getDefaultState());
        structure.fillWithBlocks(world, start, -35, -23, -47, -35, -23, -46, Blocks.AIR.getDefaultState());
        structure.fillWithBlocks(world, start, -35, -23, -45, -35, -23, -44, Blocks.STONE_BRICKS.getDefaultState());
        structure.fillWithBlocks(world, start, -35, -23, -43, -35, -22, -43, Blocks.DIRT.getDefaultState());
        structure.fillWithBlocks(world, start, -35, -23, -42, -35, -23, -41, Blocks.STONE_BRICKS.getDefaultState());
        structure.fillWithBlocks(world, start, -35, -23, -40, -35, -23, -36, Blocks.SANDSTONE.getDefaultState());
        structure.fillWithBlocks(world, start, -35, -23, -34, -35, -23, -34, Blocks.SANDSTONE.getDefaultState());
        structure.fillWithBlocks(world, start, -35, -23, -32, -34, -23, -22, Blocks.SANDSTONE.getDefaultState());
        structure.fillWithBlocks(world, start, -35, -23, -20, -34, -23, -18, Blocks.SANDSTONE.getDefaultState());
        structure.fillWithBlocks(world, start, -35, -23, -15, -34, -23, -15, Blocks.DIRT.getDefaultState());
        structure.fillWithBlocks(world, start, -35, -23, -14, -34, -23, -13, Blocks.SANDSTONE.getDefaultState());
        structure.fillWithBlocks(world, start, -35, -23, -12, -35, -23, -7, Blocks.SANDSTONE.getDefaultState());
        structure.fillWithBlocks(world, start, -35, -23, -5, -34, -23, -1, Blocks.SANDSTONE.getDefaultState());
        structure.fillWithBlocks(world, start, -35, -23, 0, -34, -23, 0, Blocks.DIRT.getDefaultState());
        structure.fillWithBlocks(world, start, -35, -23, 9, -35, -23, 9, Blocks.SANDSTONE.getDefaultState());
        structure.fillWithBlocks(world, start, -35, -23, 12, -35, -23, 12, Blocks.SANDSTONE.getDefaultState());
        structure.fillWithBlocks(world, start, -35, -23, 13, -35, -23, 15, Blocks.DIRT.getDefaultState());
        structure.fillWithBlocks(world, start, -35, -23, 16, -35, -23, 16, Blocks.SANDSTONE.getDefaultState());
        structure.fillWithBlocks(world, start, -35, -22, -49, -34, -22, -48, Blocks.STONE_BRICKS.getDefaultState());
        structure.fillWithBlocks(world, start, -35, -22, -47, -35, -21, -47, Blocks.STONE_BRICKS.getDefaultState());
        structure.fillWithBlocks(world, start, -35, -22, -44, -35, -22, -44, Blocks.AIR.getDefaultState());
        structure.fillWithBlocks(world, start, -35, -22, -42, -34, -22, -42, Blocks.AIR.getDefaultState());
        structure.fillWithBlocks(world, start, -35, -22, -41, -34, -22, -39, Blocks.STONE_BRICKS.getDefaultState());
        structure.fillWithBlocks(world, start, -35, -22, -38, -34, -22, -35, Blocks.SANDSTONE.getDefaultState());
        structure.fillWithBlocks(world, start, -35, -22, -34, -35, -22, -34, Blocks.AIR.getDefaultState());
        structure.fillWithBlocks(world, start, -35, -22, -33, -35, -22, -29, Blocks.SANDSTONE.getDefaultState());
        structure.fillWithBlocks(world, start, -35, -22, -26, -35, -22, -16, Blocks.SANDSTONE.getDefaultState());
        structure.fillWithBlocks(world, start, -35, -22, -14, -34, -22, -10, Blocks.SANDSTONE.getDefaultState());
        structure.fillWithBlocks(world, start, -35, -22, -9, -35, -22, 0, Blocks.SANDSTONE.getDefaultState());
        structure.fillWithBlocks(world, start, -35, -22, 9, -34, -22, 10, Blocks.SANDSTONE.getDefaultState());
        structure.fillWithBlocks(world, start, -35, -22, 11, -35, -21, 13, Blocks.SANDSTONE.getDefaultState());
        structure.fillWithBlocks(world, start, -35, -22, 15, -35, -21, 18, Blocks.SANDSTONE.getDefaultState());
        structure.fillWithBlocks(world, start, -35, -21, -51, -33, -21, -51, Blocks.STONE_BRICKS.getDefaultState());
        structure.fillWithBlocks(world, start, -35, -21, -49, -32, -21, -49, Blocks.STONE_BRICKS.getDefaultState());
        structure.fillWithBlocks(world, start, -35, -21, -48, -34, -21, -48, Blocks.AIR.getDefaultState());
        structure.fillWithBlocks(world, start, -35, -21, -45, -35, -21, -43, Blocks.STONE_BRICKS.getDefaultState());
        structure.fillWithBlocks(world, start, -35, -21, -40, -35, -21, -39, Blocks.DIRT.getDefaultState());
        structure.fillWithBlocks(world, start, -35, -21, -38, -34, -21, -33, Blocks.SANDSTONE.getDefaultState());
        structure.fillWithBlocks(world, start, -35, -21, -28, -33, -21, -28, Blocks.SANDSTONE.getDefaultState());
        structure.fillWithBlocks(world, start, -35, -21, -27, -34, -21, -27, Blocks.AIR.getDefaultState());
        structure.fillWithBlocks(world, start, -35, -21, -26, -34, -21, -23, Blocks.SANDSTONE.getDefaultState());
        structure.fillWithBlocks(world, start, -35, -21, -22, -35, -21, -22, Blocks.AIR.getDefaultState());
        structure.fillWithBlocks(world, start, -35, -21, -13, -34, -21, -12, Blocks.SANDSTONE.getDefaultState());
        structure.fillWithBlocks(world, start, -35, -21, -11, -34, -21, -11, Blocks.AIR.getDefaultState());
        structure.fillWithBlocks(world, start, -35, -21, -8, -34, -21, -7, Blocks.SANDSTONE.getDefaultState());
        structure.fillWithBlocks(world, start, -35, -21, -5, -34, -21, -4, Blocks.SANDSTONE.getDefaultState());
        structure.fillWithBlocks(world, start, -35, -21, -2, -34, -21, 2, Blocks.SANDSTONE.getDefaultState());
        structure.fillWithBlocks(world, start, -35, -21, 9, -34, -21, 11, Blocks.SANDSTONE.getDefaultState());
        structure.fillWithBlocks(world, start, -35, -21, 14, -33, -21, 16, Blocks.SANDSTONE.getDefaultState());
        structure.fillWithBlocks(world, start, -35, -18, -12, -35, -17, -12, Blocks.STONE_BRICKS.getDefaultState());
        structure.fillWithBlocks(world, start, -35, -18, -6, -35, -17, -6, Blocks.STONE_BRICKS.getDefaultState());
        structure.fillWithBlocks(world, start, -34, -50, -6, -31, -47, -6, Blocks.SANDSTONE.getDefaultState());
        structure.fillWithBlocks(world, start, -34, -49, -11, -34, -46, -11, Blocks.SANDSTONE.getDefaultState());
        structure.fillWithBlocks(world, start, -34, -49, -10, -32, -49, -8, Blocks.AIR.getDefaultState());
        structure.fillWithBlocks(world, start, -34, -49, -7, -34, -49, -6, Blocks.SANDSTONE.getDefaultState());
        structure.fillWithBlocks(world, start, -34, -48, -12, -34, -47, -11, Blocks.SANDSTONE.getDefaultState());
        structure.fillWithBlocks(world, start, -34, -48, -10, -32, -48, -8, Blocks.AIR.getDefaultState());
        structure.fillWithBlocks(world, start, -34, -48, -7, -34, -48, -6, Blocks.SANDSTONE.getDefaultState());
        structure.fillWithBlocks(world, start, -34, -47, -10, -32, -47, -8, Blocks.AIR.getDefaultState());
        structure.fillWithBlocks(world, start, -34, -47, -7, -34, -47, -6, Blocks.SANDSTONE.getDefaultState());
        structure.fillWithBlocks(world, start, -34, -40, -36, -34, -40, -36, Blocks.STONE_BRICKS.getDefaultState());
        structure.fillWithBlocks(world, start, -34, -40, -18, -28, -40, -6, Blocks.STONE_BRICKS.getDefaultState());
        structure.fillWithBlocks(world, start, -34, -40, -4, -29, -40, 1, Blocks.STONE_BRICKS.getDefaultState());
        structure.fillWithBlocks(world, start, -34, -40, 6, -34, -36, 10, Blocks.AIR.getDefaultState());
        structure.fillWithBlocks(world, start, -34, -40, 12, -32, -40, 14, Blocks.AIR.getDefaultState());
        structure.fillWithBlocks(world, start, -34, -40, 15, -33, -40, 16, Blocks.STONE_BRICKS.getDefaultState());
        structure.fillWithBlocks(world, start, -34, -39, -28, -32, -39, -22, Blocks.AIR.getDefaultState());
        structure.fillWithBlocks(world, start, -34, -39, -16, -34, -37, -16, Blocks.IRON_BARS.getDefaultState().with(FourWayBlock.WATERLOGGED, false).with(FourWayBlock.NORTH, true).with(FourWayBlock.SOUTH, true).with(FourWayBlock.EAST, true).with(FourWayBlock.WEST, true));
        structure.fillWithBlocks(world, start, -34, -39, -15, -34, -39, -15, Blocks.AIR.getDefaultState());
        structure.fillWithBlocks(world, start, -34, -39, -14, -34, -37, -14, Blocks.IRON_BARS.getDefaultState().with(FourWayBlock.WATERLOGGED, false).with(FourWayBlock.NORTH, true).with(FourWayBlock.SOUTH, true).with(FourWayBlock.EAST, true).with(FourWayBlock.WEST, true));
        structure.fillWithBlocks(world, start, -34, -39, -13, -34, -36, -13, Blocks.STONE_BRICKS.getDefaultState());
        structure.fillWithBlocks(world, start, -34, -39, -5, -34, -33, -5, Blocks.STONE_BRICKS.getDefaultState());
        structure.fillWithBlocks(world, start, -34, -39, -4, -34, -37, -4, Blocks.IRON_BARS.getDefaultState().with(FourWayBlock.WATERLOGGED, false).with(FourWayBlock.NORTH, true).with(FourWayBlock.SOUTH, true).with(FourWayBlock.EAST, true).with(FourWayBlock.WEST, true));
        structure.fillWithBlocks(world, start, -34, -39, -3, -34, -39, -3, Blocks.AIR.getDefaultState());
        structure.fillWithBlocks(world, start, -34, -39, -2, -34, -37, -2, Blocks.IRON_BARS.getDefaultState().with(FourWayBlock.WATERLOGGED, false).with(FourWayBlock.NORTH, true).with(FourWayBlock.SOUTH, true).with(FourWayBlock.EAST, true).with(FourWayBlock.WEST, true));
        structure.fillWithBlocks(world, start, -34, -39, -1, -34, -39, 0, Blocks.STONE_BRICKS.getDefaultState());
        structure.fillWithBlocks(world, start, -34, -38, -36, -34, -38, -36, Blocks.STONE_BRICKS.getDefaultState());
        structure.fillWithBlocks(world, start, -34, -38, -34, -34, -38, -33, Blocks.STONE_BRICKS.getDefaultState());
        structure.fillWithBlocks(world, start, -34, -38, -28, -28, -38, -22, Blocks.AIR.getDefaultState());
        structure.fillWithBlocks(world, start, -34, -38, -19, -34, -38, -17, Blocks.STONE_BRICKS.getDefaultState());
        structure.fillWithBlocks(world, start, -34, -38, -15, -34, -38, -15, Blocks.AIR.getDefaultState());
        structure.fillWithBlocks(world, start, -34, -38, -3, -34, -38, -3, Blocks.AIR.getDefaultState());
        structure.fillWithBlocks(world, start, -34, -38, -1, -34, -38, 0, Blocks.STONE_BRICKS.getDefaultState());
        structure.fillWithBlocks(world, start, -34, -37, -36, -33, -37, -35, Blocks.STONE_BRICKS.getDefaultState());
        structure.fillWithBlocks(world, start, -34, -37, -33, -32, -37, -33, Blocks.STONE_BRICKS.getDefaultState());
        structure.fillWithBlocks(world, start, -34, -37, -28, -28, -37, -22, Blocks.AIR.getDefaultState());
        structure.fillWithBlocks(world, start, -34, -37, -15, -34, -37, -14, Blocks.IRON_BARS.getDefaultState().with(FourWayBlock.WATERLOGGED, false).with(FourWayBlock.NORTH, true).with(FourWayBlock.SOUTH, true).with(FourWayBlock.EAST, true).with(FourWayBlock.WEST, true));
        structure.fillWithBlocks(world, start, -34, -37, -3, -34, -37, -2, Blocks.IRON_BARS.getDefaultState().with(FourWayBlock.WATERLOGGED, false).with(FourWayBlock.NORTH, true).with(FourWayBlock.SOUTH, true).with(FourWayBlock.EAST, true).with(FourWayBlock.WEST, true));
        structure.fillWithBlocks(world, start, -34, -37, -1, -34, -37, 0, Blocks.STONE_BRICKS.getDefaultState());
        structure.fillWithBlocks(world, start, -34, -36, -33, -34, -31, -33, Blocks.STONE_BRICKS.getDefaultState());
        structure.fillWithBlocks(world, start, -34, -36, -28, -28, -36, -22, Blocks.AIR.getDefaultState());
        structure.fillWithBlocks(world, start, -34, -36, -19, -34, -36, -13, Blocks.STONE_BRICKS.getDefaultState());
        structure.fillWithBlocks(world, start, -34, -35, -36, -34, -35, -36, Blocks.STONE_BRICKS.getDefaultState());
        structure.fillWithBlocks(world, start, -34, -35, -35, -34, -35, -35, Blocks.AIR.getDefaultState());
        structure.fillWithBlocks(world, start, -34, -35, -27, -34, -33, -24, Blocks.STONE_BRICKS.getDefaultState());
        structure.fillWithBlocks(world, start, -34, -35, -12, -33, -34, -12, Blocks.STONE_BRICKS.getDefaultState());
        structure.fillWithBlocks(world, start, -34, -35, -4, -33, -35, 1, Blocks.STONE_BRICKS.getDefaultState());
        structure.fillWithBlocks(world, start, -34, -34, -36, -33, -34, -31, Blocks.STONE_BRICKS.getDefaultState());
        structure.fillWithBlocks(world, start, -34, -34, -29, -33, -34, -23, Blocks.STONE_BRICKS.getDefaultState());
        structure.fillWithBlocks(world, start, -34, -34, -21, -34, -34, -21, Blocks.STONE_BRICKS.getDefaultState());
        structure.fillWithBlocks(world, start, -34, -34, -19, -33, -34, -17, Blocks.STONE_BRICKS.getDefaultState());
        structure.fillWithBlocks(world, start, -34, -34, -15, -32, -34, -11, Blocks.STONE_BRICKS.getDefaultState());
        structure.fillWithBlocks(world, start, -34, -34, -4, -34, -33, -4, Blocks.AIR.getDefaultState());
        structure.fillWithBlocks(world, start, -34, -34, -2, -34, -33, 16, Blocks.STONE_BRICKS.getDefaultState());
        structure.fillWithBlocks(world, start, -34, -33, -23, -32, -33, -21, Blocks.STONE_BRICKS.getDefaultState());
        structure.fillWithBlocks(world, start, -34, -33, -17, -34, -32, -17, Blocks.AIR.getDefaultState());
        structure.fillWithBlocks(world, start, -34, -33, -16, -34, -32, -15, Blocks.STONE_BRICKS.getDefaultState());
        structure.fillWithBlocks(world, start, -34, -33, -14, -34, -33, -10, Blocks.STONE_BRICKS.getDefaultState());
        structure.fillWithBlocks(world, start, -34, -33, -8, -31, -33, -5, Blocks.STONE_BRICKS.getDefaultState());
