package mod.arcalitegames.odyssey.world.structure.structures.dungeons.desert_pyramid;

import mod.arcalitegames.odyssey.world.structure.StructureBase;
import net.minecraft.block.Blocks;
import net.minecraft.block.FourWayBlock;
import net.minecraft.block.SlabBlock;
import net.minecraft.block.StairsBlock;
import net.minecraft.state.properties.Half;
import net.minecraft.state.properties.SlabType;
import net.minecraft.state.properties.StairsShape;
import net.minecraft.util.Direction;
import net.minecraft.util.math.BlockPos;
import net.minecraft.world.World;

public class PyramidComponent2
{

	public static BlockPos start;
    public static World world;
    public static StructureBase structure;

    public static void init(World worldIn, BlockPos blockPos, StructureBase structureIn)
    {
        world = worldIn; start = blockPos; structure = structureIn;
    }
    
    public static void generatePart21()
    {
        structure.fillWithBlocks(world, start, -1, -26, -6, 0, -26, -5, Blocks.SANDSTONE.getDefaultState());
        structure.fillWithBlocks(world, start, -1, -26, -4, -1, -26, -4, Blocks.AIR.getDefaultState());
        structure.fillWithBlocks(world, start, -1, -26, 6, 3, -26, 10, Blocks.AIR.getDefaultState());
        structure.fillWithBlocks(world, start, -1, -26, 16, -1, -26, 16, Blocks.AIR.getDefaultState());
        structure.fillWithBlocks(world, start, -1, -26, 17, -1, -26, 18, Blocks.SANDSTONE.getDefaultState());
        structure.fillWithBlocks(world, start, -1, -25, -53, 0, -25, -52, Blocks.STONE_BRICKS.getDefaultState());
        structure.fillWithBlocks(world, start, -1, -25, -50, 1, -25, -50, Blocks.SANDSTONE.getDefaultState());
        structure.fillWithBlocks(world, start, -1, -25, -49, 1, -25, -46, Blocks.AIR.getDefaultState());
        structure.fillWithBlocks(world, start, -1, -25, -39, 1, -25, -37, Blocks.AIR.getDefaultState());
        structure.fillWithBlocks(world, start, -1, -25, -36, 1, -23, -36, Blocks.SANDSTONE.getDefaultState());
        structure.fillWithBlocks(world, start, -1, -25, -34, -1, -24, -33, Blocks.SANDSTONE.getDefaultState());
        structure.fillWithBlocks(world, start, -1, -25, -27, 0, -25, -25, Blocks.SANDSTONE.getDefaultState());
        structure.fillWithBlocks(world, start, -1, -25, -24, -1, -25, -23, Blocks.DIRT.getDefaultState());
        structure.fillWithBlocks(world, start, -1, -25, -15, 1, -25, -12, Blocks.SANDSTONE.getDefaultState());
        structure.fillWithBlocks(world, start, -1, -25, -6, 1, -25, 0, Blocks.SANDSTONE.getDefaultState());
        structure.fillWithBlocks(world, start, -1, -25, 6, 3, -25, 10, Blocks.AIR.getDefaultState());
        structure.fillWithBlocks(world, start, -1, -24, -50, 6, -24, -50, Blocks.STONE_BRICKS.getDefaultState());
        structure.fillWithBlocks(world, start, -1, -24, -35, 1, -24, -33, Blocks.SANDSTONE.getDefaultState());
        structure.fillWithBlocks(world, start, -1, -24, -25, -1, -23, -22, Blocks.SANDSTONE.getDefaultState());
        structure.fillWithBlocks(world, start, -1, -24, -12, -1, -24, -12, Blocks.SANDSTONE.getDefaultState());
        structure.fillWithBlocks(world, start, -1, -24, -11, -1, -21, -7, Blocks.AIR.getDefaultState());
        structure.fillWithBlocks(world, start, -1, -24, -6, 0, -24, -1, Blocks.SANDSTONE.getDefaultState());
        structure.fillWithBlocks(world, start, -1, -24, 0, 0, -24, 0, Blocks.DIRT.getDefaultState());
        structure.fillWithBlocks(world, start, -1, -24, 1, 0, -24, 2, Blocks.SANDSTONE.getDefaultState());
        structure.fillWithBlocks(world, start, -1, -24, 4, -1, -24, 4, Blocks.SANDSTONE.getDefaultState());
        structure.fillWithBlocks(world, start, -1, -24, 6, 3, -24, 10, Blocks.SANDSTONE.getDefaultState());
        structure.fillWithBlocks(world, start, -1, -24, 11, -1, -23, 11, Blocks.AIR.getDefaultState());
        structure.fillWithBlocks(world, start, -1, -24, 13, 2, -24, 16, Blocks.SANDSTONE.getDefaultState());
        structure.fillWithBlocks(world, start, -1, -24, 17, -1, -24, 17, Blocks.AIR.getDefaultState());
        structure.fillWithBlocks(world, start, -1, -23, -53, 0, -23, -51, Blocks.STONE_BRICKS.getDefaultState());
        structure.fillWithBlocks(world, start, -1, -23, -50, -1, -22, -50, Blocks.SANDSTONE.getDefaultState());
        structure.fillWithBlocks(world, start, -1, -23, -49, 1, -23, -47, Blocks.STONE_BRICKS.getDefaultState());
        structure.fillWithBlocks(world, start, -1, -23, -45, -1, -23, -45, Blocks.AIR.getDefaultState());
        structure.fillWithBlocks(world, start, -1, -23, -44, -1, -23, -43, Blocks.STONE_BRICKS.getDefaultState());
        structure.fillWithBlocks(world, start, -1, -23, -40, 0, -23, -39, Blocks.STONE_BRICKS.getDefaultState());
        structure.fillWithBlocks(world, start, -1, -23, -37, 0, -23, -36, Blocks.SANDSTONE.getDefaultState());
        structure.fillWithBlocks(world, start, -1, -23, -34, 0, -23, -33, Blocks.SANDSTONE.getDefaultState());
        structure.fillWithBlocks(world, start, -1, -23, -30, 0, -23, -29, Blocks.SANDSTONE.getDefaultState());
        structure.fillWithBlocks(world, start, -1, -23, -27, 0, -23, -24, Blocks.SANDSTONE.getDefaultState());
        structure.fillWithBlocks(world, start, -1, -23, -15, -1, -20, -15, Blocks.SANDSTONE.getDefaultState());
        structure.fillWithBlocks(world, start, -1, -23, -12, -1, -23, -12, Blocks.SANDSTONE.getDefaultState());
        structure.fillWithBlocks(world, start, -1, -23, -6, 1, -23, -1, Blocks.SANDSTONE.getDefaultState());
        structure.fillWithBlocks(world, start, -1, -23, 0, -1, -23, 7, Blocks.SANDSTONE.getDefaultState());
        structure.fillWithBlocks(world, start, -1, -23, 9, 0, -23, 10, Blocks.SANDSTONE.getDefaultState());
        structure.fillWithBlocks(world, start, -1, -23, 12, -1, -22, 14, Blocks.SANDSTONE.getDefaultState());
        structure.fillWithBlocks(world, start, -1, -23, 15, 0, -23, 16, Blocks.SANDSTONE.getDefaultState());
        structure.fillWithBlocks(world, start, -1, -23, 18, 0, -22, 18, Blocks.SANDSTONE.getDefaultState());
        structure.fillWithBlocks(world, start, -1, -22, -48, -1, -22, -48, Blocks.STONE_BRICKS.getDefaultState());
        structure.fillWithBlocks(world, start, -1, -22, -46, 1, -22, -46, Blocks.SANDSTONE.getDefaultState());
        structure.fillWithBlocks(world, start, -1, -22, -45, 2, -22, -45, Blocks.STONE_BRICKS.getDefaultState());
        structure.fillWithBlocks(world, start, -1, -22, -44, -1, -21, -44, Blocks.AIR.getDefaultState());
        structure.fillWithBlocks(world, start, -1, -22, -43, 1, -21, -43, Blocks.STONE_BRICKS.getDefaultState());
        structure.fillWithBlocks(world, start, -1, -22, -42, -1, -22, -42, Blocks.SANDSTONE.getDefaultState());
        structure.fillWithBlocks(world, start, -1, -22, -40, -1, -22, -35, Blocks.SANDSTONE.getDefaultState());
        structure.fillWithBlocks(world, start, -1, -22, -34, -1, -22, -33, Blocks.AIR.getDefaultState());
        structure.fillWithBlocks(world, start, -1, -22, -30, 0, -22, -27, Blocks.SANDSTONE.getDefaultState());
        structure.fillWithBlocks(world, start, -1, -22, -26, -1, -20, -26, Blocks.SANDSTONE.getDefaultState());
        structure.fillWithBlocks(world, start, -1, -22, -23, 0, -22, -22, Blocks.SANDSTONE.getDefaultState());
        structure.fillWithBlocks(world, start, -1, -22, -14, 1, -22, -12, Blocks.SANDSTONE.getDefaultState());
        structure.fillWithBlocks(world, start, -1, -22, -6, 0, -22, -5, Blocks.SANDSTONE.getDefaultState());
        structure.fillWithBlocks(world, start, -1, -22, 1, 0, -22, 3, Blocks.SANDSTONE.getDefaultState());
        structure.fillWithBlocks(world, start, -1, -22, 6, -1, -22, 7, Blocks.DIRT.getDefaultState());
        structure.fillWithBlocks(world, start, -1, -22, 17, 0, -22, 18, Blocks.SANDSTONE.getDefaultState());
        structure.fillWithBlocks(world, start, -1, -21, -52, -1, -21, -50, Blocks.STONE_BRICKS.getDefaultState());
        structure.fillWithBlocks(world, start, -1, -21, -49, -1, -21, -48, Blocks.SANDSTONE.getDefaultState());
        structure.fillWithBlocks(world, start, -1, -21, -39, 0, -21, -39, Blocks.STONE_BRICKS.getDefaultState());
        structure.fillWithBlocks(world, start, -1, -21, -34, 0, -21, -33, Blocks.SANDSTONE.getDefaultState());
        structure.fillWithBlocks(world, start, -1, -21, -30, -1, -21, -24, Blocks.SANDSTONE.getDefaultState());
        structure.fillWithBlocks(world, start, -1, -21, -22, 0, -21, -22, Blocks.SANDSTONE.getDefaultState());
        structure.fillWithBlocks(world, start, -1, -21, -12, -1, -21, -12, Blocks.SANDSTONE.getDefaultState());
        structure.fillWithBlocks(world, start, -1, -21, -6, 0, -21, -5, Blocks.SANDSTONE.getDefaultState());
        structure.fillWithBlocks(world, start, -1, -21, 0, 3, -21, 5, Blocks.SANDSTONE.getDefaultState());
        structure.fillWithBlocks(world, start, -1, -21, 7, -1, -21, 8, Blocks.SANDSTONE.getDefaultState());
        structure.fillWithBlocks(world, start, -1, -21, 10, -1, -21, 10, Blocks.SANDSTONE.getDefaultState());
        structure.fillWithBlocks(world, start, -1, -21, 13, -1, -21, 13, Blocks.SANDSTONE.getDefaultState());
        structure.fillWithBlocks(world, start, -1, -21, 15, 0, -21, 16, Blocks.SANDSTONE.getDefaultState());
        structure.fillWithBlocks(world, start, -1, -21, 17, -1, -21, 18, Blocks.SANDSTONE.getDefaultState());
        structure.fillWithBlocks(world, start, -1, -20, -29, -1, -20, -28, Blocks.OAK_PLANKS.getDefaultState());
        structure.fillWithBlocks(world, start, -1, -20, -27, 1, -20, -25, Blocks.SANDSTONE.getDefaultState());
        structure.fillWithBlocks(world, start, -1, -20, -24, -1, -20, -22, Blocks.OAK_PLANKS.getDefaultState());
        structure.fillWithBlocks(world, start, -1, -20, -14, 1, -20, -12, Blocks.SANDSTONE.getDefaultState());
        structure.fillWithBlocks(world, start, -1, -20, -11, -1, -20, -6, Blocks.SANDSTONE.getDefaultState());
        structure.fillWithBlocks(world, start, -1, -20, -4, 0, -20, -3, Blocks.SANDSTONE.getDefaultState());
        structure.fillWithBlocks(world, start, -1, -20, 5, -1, -17, 5, Blocks.SANDSTONE.getDefaultState());
        structure.fillWithBlocks(world, start, -1, -20, 11, -1, -17, 11, Blocks.SANDSTONE.getDefaultState());
        structure.fillWithBlocks(world, start, -1, -20, 22, 1, -20, 33, Blocks.SANDSTONE.getDefaultState());
        structure.fillWithBlocks(world, start, -1, -19, -30, -1, -18, -29, Blocks.OAK_PLANKS.getDefaultState());
        structure.fillWithBlocks(world, start, -1, -19, -28, 1, -17, -28, Blocks.SANDSTONE.getDefaultState());
        structure.fillWithBlocks(world, start, -1, -19, -27, 1, -19, -25, Blocks.AIR.getDefaultState());
        structure.fillWithBlocks(world, start, -1, -19, -24, -1, -19, -24, Blocks.SANDSTONE.getDefaultState());
        structure.fillWithBlocks(world, start, -1, -19, -23, -1, -18, -22, Blocks.OAK_PLANKS.getDefaultState());
        structure.fillWithBlocks(world, start, -1, -19, -21, 0, -19, -20, Blocks.SANDSTONE.getDefaultState());
        structure.fillWithBlocks(world, start, -1, -19, -19, -1, -16, -19, Blocks.SANDSTONE.getDefaultState());
        structure.fillWithBlocks(world, start, -1, -19, -17, -1, -19, -15, Blocks.STONE_BRICKS.getDefaultState());
        structure.fillWithBlocks(world, start, -1, -19, -12, -1, -19, -12, Blocks.SANDSTONE.getDefaultState());
        structure.fillWithBlocks(world, start, -1, -19, -11, -1, -19, -7, Blocks.AIR.getDefaultState());
        structure.fillWithBlocks(world, start, -1, -19, -6, 2, -19, -3, Blocks.SANDSTONE.getDefaultState());
        structure.fillWithBlocks(world, start, -1, -19, -1, -1, -17, -1, Blocks.SANDSTONE.getDefaultState());
        structure.fillWithBlocks(world, start, -1, -19, 1, -1, -19, 3, Blocks.STONE_BRICKS.getDefaultState());
        structure.fillWithBlocks(world, start, -1, -19, 7, -1, -19, 9, Blocks.STONE_BRICKS.getDefaultState());
        structure.fillWithBlocks(world, start, -1, -19, 13, -1, -19, 15, Blocks.STONE_BRICKS.getDefaultState());
        structure.fillWithBlocks(world, start, -1, -19, 17, -1, -16, 17, Blocks.SANDSTONE.getDefaultState());
        structure.fillWithBlocks(world, start, -1, -19, 19, -1, -19, 21, Blocks.STONE_BRICKS.getDefaultState());
        structure.fillWithBlocks(world, start, -1, -19, 25, -1, -19, 25, Blocks.SANDSTONE.getDefaultState());
        structure.fillWithBlocks(world, start, -1, -19, 31, -1, -16, 34, Blocks.SANDSTONE.getDefaultState());
        structure.fillWithBlocks(world, start, -1, -18, -27, 1, -18, -25, Blocks.AIR.getDefaultState());
        structure.fillWithBlocks(world, start, -1, -18, -24, -1, -18, -24, Blocks.SANDSTONE.getDefaultState());
        structure.fillWithBlocks(world, start, -1, -18, -21, 0, -18, -20, Blocks.SANDSTONE.getDefaultState());
        structure.fillWithBlocks(world, start, -1, -18, -17, -1, -17, -17, Blocks.STONE_BRICKS.getDefaultState());
        structure.fillWithBlocks(world, start, -1, -18, -15, -1, -17, -15, Blocks.STONE_BRICKS.getDefaultState());
        structure.fillWithBlocks(world, start, -1, -18, -12, -1, -18, -12, Blocks.SANDSTONE.getDefaultState());
        structure.fillWithBlocks(world, start, -1, -18, -11, -1, -18, -7, Blocks.AIR.getDefaultState());
        structure.fillWithBlocks(world, start, -1, -18, -6, 1, -18, -3, Blocks.SANDSTONE.getDefaultState());
        structure.fillWithBlocks(world, start, -1, -18, 1, -1, -17, 1, Blocks.STONE_BRICKS.getDefaultState());
        structure.fillWithBlocks(world, start, -1, -18, 3, -1, -17, 3, Blocks.STONE_BRICKS.getDefaultState());
        structure.fillWithBlocks(world, start, -1, -18, 7, -1, -17, 7, Blocks.STONE_BRICKS.getDefaultState());
        structure.fillWithBlocks(world, start, -1, -18, 9, -1, -17, 9, Blocks.STONE_BRICKS.getDefaultState());
        structure.fillWithBlocks(world, start, -1, -18, 13, -1, -17, 13, Blocks.STONE_BRICKS.getDefaultState());
        structure.fillWithBlocks(world, start, -1, -18, 15, -1, -17, 15, Blocks.STONE_BRICKS.getDefaultState());
        structure.fillWithBlocks(world, start, -1, -18, 19, -1, -17, 19, Blocks.STONE_BRICKS.getDefaultState());
        structure.fillWithBlocks(world, start, -1, -18, 21, -1, -17, 21, Blocks.STONE_BRICKS.getDefaultState());
        structure.fillWithBlocks(world, start, -1, -18, 25, -1, -18, 25, Blocks.SANDSTONE.getDefaultState());
        structure.fillWithBlocks(world, start, -1, -18, 26, -1, -16, 30, Blocks.AIR.getDefaultState());
        structure.fillWithBlocks(world, start, -1, -17, -30, -1, -16, -29, Blocks.OAK_PLANKS.getDefaultState());
        structure.fillWithBlocks(world, start, -1, -17, -27, 1, -17, -25, Blocks.AIR.getDefaultState());
        structure.fillWithBlocks(world, start, -1, -17, -24, -1, -17, -24, Blocks.SANDSTONE.getDefaultState());
        structure.fillWithBlocks(world, start, -1, -17, -23, -1, -16, -22, Blocks.OAK_PLANKS.getDefaultState());
        structure.fillWithBlocks(world, start, -1, -17, -21, 0, -17, -20, Blocks.SANDSTONE.getDefaultState());
        structure.fillWithBlocks(world, start, -1, -17, -16, -1, -17, -14, Blocks.STONE_BRICKS.getDefaultState());
        structure.fillWithBlocks(world, start, -1, -17, -13, 0, -17, -12, Blocks.SANDSTONE.getDefaultState());
        structure.fillWithBlocks(world, start, -1, -17, -11, -1, -17, -7, Blocks.AIR.getDefaultState());
        structure.fillWithBlocks(world, start, -1, -17, -6, 2, -17, -3, Blocks.SANDSTONE.getDefaultState());
        structure.fillWithBlocks(world, start, -1, -17, 2, -1, -17, 3, Blocks.STONE_BRICKS.getDefaultState());
        structure.fillWithBlocks(world, start, -1, -17, 8, -1, -17, 9, Blocks.STONE_BRICKS.getDefaultState());
        structure.fillWithBlocks(world, start, -1, -17, 14, -1, -17, 15, Blocks.STONE_BRICKS.getDefaultState());
        structure.fillWithBlocks(world, start, -1, -17, 20, -1, -17, 21, Blocks.STONE_BRICKS.getDefaultState());
        structure.fillWithBlocks(world, start, -1, -17, 25, -1, -17, 25, Blocks.SANDSTONE.getDefaultState());
        structure.fillWithBlocks(world, start, -1, -16, -28, -1, -16, -24, Blocks.SANDSTONE.getDefaultState());
        structure.fillWithBlocks(world, start, -1, -16, -15, 1, -16, -12, Blocks.SANDSTONE.getDefaultState());
        structure.fillWithBlocks(world, start, -1, -16, -11, -1, -10, -11, Blocks.SANDSTONE.getDefaultState());
        structure.fillWithBlocks(world, start, -1, -16, -10, -1, -16, -8, Blocks.AIR.getDefaultState());
        structure.fillWithBlocks(world, start, -1, -16, -7, 1, -16, -5, Blocks.SANDSTONE.getDefaultState());
        structure.fillWithBlocks(world, start, -1, -16, 22, 0, -16, 25, Blocks.SANDSTONE.getDefaultState());
        structure.fillWithBlocks(world, start, -1, -15, -32, 1, -13, -32, Blocks.SANDSTONE.getDefaultState());
        structure.fillWithBlocks(world, start, -1, -15, -31, 0, -15, -31, Blocks.AIR.getDefaultState());
        structure.fillWithBlocks(world, start, -1, -15, -29, -1, -15, -22, Blocks.OAK_PLANKS.getDefaultState());
        structure.fillWithBlocks(world, start, -1, -15, -15, -1, -15, -5, Blocks.SANDSTONE.getDefaultState());
        structure.fillWithBlocks(world, start, -1, -15, -3, 2, -12, -3, Blocks.SANDSTONE.getDefaultState());
        structure.fillWithBlocks(world, start, -1, -15, 22, 1, -15, 24, Blocks.SANDSTONE.getDefaultState());
        structure.fillWithBlocks(world, start, -1, -15, 26, 1, -15, 34, Blocks.SANDSTONE.getDefaultState());
        structure.fillWithBlocks(world, start, -1, -14, -25, 2, -14, -20, Blocks.SANDSTONE.getDefaultState());
        structure.fillWithBlocks(world, start, -1, -14, -12, 1, -14, -10, Blocks.SANDSTONE.getDefaultState());
        structure.fillWithBlocks(world, start, -1, -14, -9, -1, -14, -8, Blocks.AIR.getDefaultState());
        structure.fillWithBlocks(world, start, -1, -14, -6, 2, -11, -6, Blocks.SANDSTONE.getDefaultState());
        structure.fillWithBlocks(world, start, -1, -14, -4, 0, -14, -3, Blocks.SANDSTONE.getDefaultState());
        structure.fillWithBlocks(world, start, -1, -14, 22, 2, -14, 25, Blocks.SANDSTONE.getDefaultState());
        structure.fillWithBlocks(world, start, -1, -13, -9, 1, -13, -6, Blocks.SANDSTONE.getDefaultState());
        structure.fillWithBlocks(world, start, -1, -13, 26, 2, -13, 34, Blocks.SANDSTONE.getDefaultState());
        structure.fillWithBlocks(world, start, -1, -12, -32, -1, -12, -32, Blocks.SANDSTONE.getDefaultState());
        structure.fillWithBlocks(world, start, -1, -12, -30, 0, -12, -21, Blocks.SANDSTONE.getDefaultState());
        structure.fillWithBlocks(world, start, -1, -12, 25, -1, -12, 25, Blocks.SANDSTONE.getDefaultState());
        structure.fillWithBlocks(world, start, -1, -12, 27, 0, -12, 28, Blocks.SANDSTONE.getDefaultState());
        structure.fillWithBlocks(world, start, -1, -12, 30, 1, -12, 32, Blocks.SANDSTONE.getDefaultState());
        structure.fillWithBlocks(world, start, -1, -11, -26, -1, -11, -20, Blocks.SANDSTONE.getDefaultState());
        structure.fillWithBlocks(world, start, -1, -11, -8, 2, -11, -4, Blocks.SANDSTONE.getDefaultState());
        structure.fillWithBlocks(world, start, -1, -11, 22, -1, -11, 22, Blocks.SANDSTONE.getDefaultState());
        structure.fillWithBlocks(world, start, -1, -11, 24, 0, -11, 34, Blocks.SANDSTONE.getDefaultState());
        structure.fillWithBlocks(world, start, -1, -10, -12, 1, -9, -12, Blocks.STONE_BRICKS.getDefaultState());
        structure.fillWithBlocks(world, start, -1, -9, -11, 1, -9, -7, Blocks.AIR.getDefaultState());
        structure.fillWithBlocks(world, start, -1, -9, -6, 1, -9, -6, Blocks.STONE_BRICKS.getDefaultState());
        structure.fillWithBlocks(world, start, -1, -8, -12, -1, -7, -12, Blocks.STONE_BRICKS.getDefaultState());
        structure.fillWithBlocks(world, start, -1, -8, -11, 1, -8, -7, Blocks.AIR.getDefaultState());
        structure.fillWithBlocks(world, start, -1, -8, -6, -1, -7, -6, Blocks.STONE_BRICKS.getDefaultState());
        structure.fillWithBlocks(world, start, -1, -7, -11, 1, -7, -7, Blocks.AIR.getDefaultState());
        structure.fillWithBlocks(world, start, -1, -6, -10, 2, -6, -7, Blocks.SANDSTONE.getDefaultState());
        structure.fillWithBlocks(world, start, 0, -52, -15, 1, -52, -14, Blocks.SANDSTONE.getDefaultState());
        structure.fillWithBlocks(world, start, 0, -52, -13, 0, -52, -12, Blocks.SANDSTONE_STAIRS.getDefaultState().with(StairsBlock.FACING, Direction.EAST).with(StairsBlock.WATERLOGGED, false).with(StairsBlock.SHAPE, StairsShape.STRAIGHT).with(StairsBlock.HALF, Half.BOTTOM));
        structure.fillWithBlocks(world, start, 0, -52, -11, 0, -52, -7, Blocks.SANDSTONE.getDefaultState());
        structure.fillWithBlocks(world, start, 0, -52, -6, 0, -52, -5, Blocks.SANDSTONE_STAIRS.getDefaultState().with(StairsBlock.FACING, Direction.EAST).with(StairsBlock.WATERLOGGED, false).with(StairsBlock.SHAPE, StairsShape.STRAIGHT).with(StairsBlock.HALF, Half.BOTTOM));
        structure.fillWithBlocks(world, start, 0, -52, -4, 4, -52, 0, Blocks.SANDSTONE.getDefaultState());
        structure.fillWithBlocks(world, start, 0, -51, -14, 5, -51, -14, Blocks.SANDSTONE.getDefaultState());
        structure.fillWithBlocks(world, start, 0, -51, -13, 0, -50, -12, Blocks.AIR.getDefaultState());
        structure.fillWithBlocks(world, start, 0, -51, -11, 0, -51, -7, Blocks.SANDSTONE.getDefaultState());
        structure.fillWithBlocks(world, start, 0, -51, -6, 0, -50, -5, Blocks.AIR.getDefaultState());
        structure.fillWithBlocks(world, start, 0, -51, -4, 4, -51, 0, Blocks.SANDSTONE.getDefaultState());
        structure.fillWithBlocks(world, start, 0, -50, -18, 3, -50, -15, Blocks.AIR.getDefaultState());
        structure.fillWithBlocks(world, start, 0, -50, -14, 0, -41, -14, Blocks.SANDSTONE.getDefaultState());
        structure.fillWithBlocks(world, start, 0, -50, -4, 0, -41, -4, Blocks.SANDSTONE.getDefaultState());
        structure.fillWithBlocks(world, start, 0, -50, -3, 3, -50, 0, Blocks.AIR.getDefaultState());
        structure.fillWithBlocks(world, start, 0, -50, 1, 1, -50, 2, Blocks.SANDSTONE.getDefaultState());
        structure.fillWithBlocks(world, start, 0, -49, -19, 1, -49, -15, Blocks.AIR.getDefaultState());
        structure.fillWithBlocks(world, start, 0, -49, -13, 1, -49, -12, Blocks.AIR.getDefaultState());
        structure.fillWithBlocks(world, start, 0, -49, -11, 0, -41, -11, Blocks.SANDSTONE.getDefaultState());
        structure.fillWithBlocks(world, start, 0, -49, -10, 2, -49, -8, Blocks.AIR.getDefaultState());
        structure.fillWithBlocks(world, start, 0, -49, -7, 0, -41, -7, Blocks.SANDSTONE.getDefaultState());
        structure.fillWithBlocks(world, start, 0, -49, -6, 1, -49, -5, Blocks.AIR.getDefaultState());
        structure.fillWithBlocks(world, start, 0, -49, -3, 3, -49, 0, Blocks.AIR.getDefaultState());
        structure.fillWithBlocks(world, start, 0, -49, 1, 1, -48, 1, Blocks.AIR.getDefaultState());
        structure.fillWithBlocks(world, start, 0, -49, 18, 0, -49, 19, Blocks.SHROOMLIGHT.getDefaultState());
        structure.fillWithBlocks(world, start, 0, -49, 20, 5, -49, 20, Blocks.SANDSTONE.getDefaultState());
        structure.fillWithBlocks(world, start, 0, -49, 30, 4, -49, 30, Blocks.SANDSTONE.getDefaultState());
        structure.fillWithBlocks(world, start, 0, -49, 31, 1, -49, 31, Blocks.SHROOMLIGHT.getDefaultState());
        structure.fillWithBlocks(world, start, 0, -49, 33, 2, -49, 35, Blocks.SANDSTONE.getDefaultState());
        structure.fillWithBlocks(world, start, 0, -48, -19, 1, -48, -15, Blocks.AIR.getDefaultState());
        structure.fillWithBlocks(world, start, 0, -48, -13, 1, -48, -12, Blocks.AIR.getDefaultState());
        structure.fillWithBlocks(world, start, 0, -48, -10, 2, -48, -8, Blocks.AIR.getDefaultState());
        structure.fillWithBlocks(world, start, 0, -48, -6, 1, -48, -5, Blocks.AIR.getDefaultState());
        structure.fillWithBlocks(world, start, 0, -48, -3, 3, -48, 0, Blocks.AIR.getDefaultState());
        structure.fillWithBlocks(world, start, 0, -48, 15, 2, -48, 17, Blocks.SANDSTONE.getDefaultState());
        structure.fillWithBlocks(world, start, 0, -48, 18, 0, -48, 18, Blocks.IRON_BARS.getDefaultState().with(FourWayBlock.WATERLOGGED, false).with(FourWayBlock.NORTH, true).with(FourWayBlock.SOUTH, true).with(FourWayBlock.EAST, true).with(FourWayBlock.WEST, true));
        structure.fillWithBlocks(world, start, 0, -48, 30, 0, -48, 30, Blocks.IRON_BARS.getDefaultState().with(FourWayBlock.WATERLOGGED, false).with(FourWayBlock.NORTH, true).with(FourWayBlock.SOUTH, true).with(FourWayBlock.EAST, true).with(FourWayBlock.WEST, true));
        structure.fillWithBlocks(world, start, 0, -47, -32, 0, -41, -20, Blocks.SANDSTONE.getDefaultState());
        structure.fillWithBlocks(world, start, 0, -47, -19, 1, -47, -15, Blocks.AIR.getDefaultState());
        structure.fillWithBlocks(world, start, 0, -47, -13, 1, -47, -12, Blocks.AIR.getDefaultState());
        structure.fillWithBlocks(world, start, 0, -47, -10, 2, -47, -8, Blocks.AIR.getDefaultState());
        structure.fillWithBlocks(world, start, 0, -47, -6, 1, -47, -5, Blocks.AIR.getDefaultState());
        structure.fillWithBlocks(world, start, 0, -47, -3, 3, -47, 0, Blocks.AIR.getDefaultState());
        structure.fillWithBlocks(world, start, 0, -47, 1, 1, -47, 1, Blocks.AIR.getDefaultState());
        structure.fillWithBlocks(world, start, 0, -47, 30, 0, -44, 35, Blocks.SANDSTONE.getDefaultState());
        structure.fillWithBlocks(world, start, 0, -46, -18, 0, -41, 1, Blocks.SANDSTONE.getDefaultState());
        structure.fillWithBlocks(world, start, 0, -46, 15, 4, -46, 20, Blocks.SANDSTONE.getDefaultState());
        structure.fillWithBlocks(world, start, 0, -43, 20, 6, -43, 28, Blocks.SANDSTONE.getDefaultState());
        structure.fillWithBlocks(world, start, 0, -43, 34, 3, -43, 40, Blocks.STONE_BRICKS.getDefaultState());
        structure.fillWithBlocks(world, start, 0, -42, 34, 0, -41, 34, Blocks.AIR.getDefaultState());
        structure.fillWithBlocks(world, start, 0, -42, 38, 0, -40, 38, Blocks.STONE_BRICKS.getDefaultState());
        structure.fillWithBlocks(world, start, 0, -41, 35, 1, -41, 35, Blocks.AIR.getDefaultState());
        structure.fillWithBlocks(world, start, 0, -41, 37, 0, -41, 38, Blocks.STONE_BRICKS.getDefaultState());
        structure.fillWithBlocks(world, start, 0, -40, -43, 2, -40, -28, Blocks.STONE_BRICKS.getDefaultState());
        structure.fillWithBlocks(world, start, 0, -40, -27, 1, -40, -14, Blocks.STONE_BRICKS.getDefaultState());
        structure.fillWithBlocks(world, start, 0, -39, -47, 2, -39, -43, Blocks.STONE_BRICKS.getDefaultState());
        structure.fillWithBlocks(world, start, 0, -39, -40, 1, -39, -29, Blocks.AIR.getDefaultState());
        structure.fillWithBlocks(world, start, 0, -39, 35, 2, -39, 39, Blocks.AIR.getDefaultState());
        structure.fillWithBlocks(world, start, 0, -39, 41, 0, -39, 43, Blocks.STONE_BRICKS.getDefaultState());
        structure.fillWithBlocks(world, start, 0, -38, -47, 9, -33, -47, Blocks.STONE_BRICKS.getDefaultState());
        structure.fillWithBlocks(world, start, 0, -38, -46, 1, -37, -46, Blocks.AIR.getDefaultState());
        structure.fillWithBlocks(world, start, 0, -38, -43, 0, -36, -41, Blocks.STONE_BRICKS.getDefaultState());
        structure.fillWithBlocks(world, start, 0, -38, -40, 1, -38, -29, Blocks.AIR.getDefaultState());
        structure.fillWithBlocks(world, start, 0, -38, 36, 2, -38, 39, Blocks.AIR.getDefaultState());
        structure.fillWithBlocks(world, start, 0, -38, 40, 0, -38, 40, Blocks.STONE_BRICKS.getDefaultState());
        structure.fillWithBlocks(world, start, 0, -38, 42, 1, -38, 43, Blocks.STONE_BRICKS.getDefaultState());
        structure.fillWithBlocks(world, start, 0, -37, -45, 0, -37, -45, Blocks.AIR.getDefaultState());
        structure.fillWithBlocks(world, start, 0, -36, 23, 2, -36, 25, Blocks.STONE_BRICKS.getDefaultState());
        structure.fillWithBlocks(world, start, 0, -36, 30, 1, -36, 32, Blocks.STONE_BRICKS.getDefaultState());
        structure.fillWithBlocks(world, start, 0, -36, 40, 1, -36, 41, Blocks.STONE_BRICKS.getDefaultState());
        structure.fillWithBlocks(world, start, 0, -36, 42, 0, -36, 43, Blocks.STONE_BRICKS.getDefaultState());
        structure.fillWithBlocks(world, start, 0, -35, -43, 0, -33, -41, Blocks.STONE_BRICKS.getDefaultState());
        structure.fillWithBlocks(world, start, 0, -35, -16, 1, -35, -14, Blocks.STONE_BRICKS.getDefaultState());
        structure.fillWithBlocks(world, start, 0, -35, -9, 2, -35, -6, Blocks.STONE_BRICKS.getDefaultState());
        structure.fillWithBlocks(world, start, 0, -35, 25, 6, -31, 25, Blocks.STONE_BRICKS.getDefaultState());
        structure.fillWithBlocks(world, start, 0, -35, 29, 0, -34, 30, Blocks.STONE_BRICKS.getDefaultState());
        structure.fillWithBlocks(world, start, 0, -35, 31, 0, -34, 31, Blocks.AIR.getDefaultState());
        structure.fillWithBlocks(world, start, 0, -35, 32, 3, -34, 32, Blocks.STONE_BRICKS.getDefaultState());
        structure.fillWithBlocks(world, start, 0, -35, 42, 1, -35, 43, Blocks.STONE_BRICKS.getDefaultState());
        structure.fillWithBlocks(world, start, 0, -34, -46, 0, -33, -32, Blocks.STONE_BRICKS.getDefaultState());
        structure.fillWithBlocks(world, start, 0, -34, -31, 3, -34, -27, Blocks.STONE_BRICKS.getDefaultState());
        structure.fillWithBlocks(world, start, 0, -34, -9, 0, -34, -8, Blocks.STONE_BRICKS.getDefaultState());
        structure.fillWithBlocks(world, start, 0, -34, -7, 0, -34, -7, Blocks.AIR.getDefaultState());
        structure.fillWithBlocks(world, start, 0, -34, -6, 0, -33, -6, Blocks.STONE_BRICKS.getDefaultState());
        structure.fillWithBlocks(world, start, 0, -34, 12, 2, -34, 14, Blocks.AIR.getDefaultState());
        structure.fillWithBlocks(world, start, 0, -34, 15, 0, -34, 15, Blocks.STONE_BRICKS.getDefaultState());
        structure.fillWithBlocks(world, start, 0, -34, 16, 0, -34, 17, Blocks.AIR.getDefaultState());
        structure.fillWithBlocks(world, start, 0, -34, 18, 1, -34, 21, Blocks.STONE_BRICKS.getDefaultState());
        structure.fillWithBlocks(world, start, 0, -34, 22, 0, -34, 23, Blocks.STONE_BRICKS.getDefaultState());
        structure.fillWithBlocks(world, start, 0, -34, 33, 2, -34, 43, Blocks.STONE_BRICKS.getDefaultState());
        structure.fillWithBlocks(world, start, 0, -33, -31, 0, -32, -31, Blocks.AIR.getDefaultState());
        structure.fillWithBlocks(world, start, 0, -33, -30, 0, -33, -30, Blocks.STONE_BRICKS.getDefaultState());
        structure.fillWithBlocks(world, start, 0, -33, -29, 0, -33, -28, Blocks.AIR.getDefaultState());
        structure.fillWithBlocks(world, start, 0, -33, -12, 0, -33, -10, Blocks.STONE_BRICKS.getDefaultState());
        structure.fillWithBlocks(world, start, 0, -33, -9, 1, -33, -9, Blocks.AIR.getDefaultState());
        structure.fillWithBlocks(world, start, 0, -33, -8, 1, -33, -8, Blocks.STONE_BRICKS.getDefaultState());
        structure.fillWithBlocks(world, start, 0, -33, 5, 1, -33, 10, Blocks.STONE_BRICKS.getDefaultState());
        structure.fillWithBlocks(world, start, 0, -33, 16, 2, -33, 21, Blocks.STONE_BRICKS.getDefaultState());
        structure.fillWithBlocks(world, start, 0, -33, 23, 2, -33, 25, Blocks.STONE_BRICKS.getDefaultState());
        structure.fillWithBlocks(world, start, 0, -33, 30, 0, -33, 43, Blocks.STONE_BRICKS.getDefaultState());
        structure.fillWithBlocks(world, start, 0, -32, -46, 0, -31, -46, Blocks.AIR.getDefaultState());
        structure.fillWithBlocks(world, start, 0, -32, -45, 1, -32, -44, Blocks.STONE_BRICKS.getDefaultState());
        structure.fillWithBlocks(world, start, 0, -32, -42, 0, -32, -42, Blocks.STONE_BRICKS.getDefaultState());
        structure.fillWithBlocks(world, start, 0, -32, -40, 0, -32, -40, Blocks.STONE_BRICKS.getDefaultState());
        structure.fillWithBlocks(world, start, 0, -32, -39, 0, -32, -38, Blocks.AIR.getDefaultState());
        structure.fillWithBlocks(world, start, 0, -32, -37, 2, -32, -35, Blocks.STONE_BRICKS.getDefaultState());
        structure.fillWithBlocks(world, start, 0, -32, -34, 0, -32, -34, Blocks.STONE_BRICKS.getDefaultState());
        structure.fillWithBlocks(world, start, 0, -32, -32, 0, -32, -32, Blocks.STONE_BRICKS.getDefaultState());
        structure.fillWithBlocks(world, start, 0, -32, -30, 0, -32, -30, Blocks.STONE_BRICKS.getDefaultState());
        structure.fillWithBlocks(world, start, 0, -32, -29, 0, -31, -29, Blocks.AIR.getDefaultState());
        structure.fillWithBlocks(world, start, 0, -32, -28, 1, -32, -27, Blocks.STONE_BRICKS.getDefaultState());
        structure.fillWithBlocks(world, start, 0, -32, -13, 0, -32, -13, Blocks.STONE_BRICKS.getDefaultState());
        structure.fillWithBlocks(world, start, 0, -32, -12, 0, -32, -12, Blocks.AIR.getDefaultState());
        structure.fillWithBlocks(world, start, 0, -32, -11, 0, -31, -11, Blocks.STONE_BRICKS.getDefaultState());
        structure.fillWithBlocks(world, start, 0, -32, -9, 0, -32, -8, Blocks.STONE_BRICKS.getDefaultState());
        structure.fillWithBlocks(world, start, 0, -32, -7, 0, -32, -6, Blocks.AIR.getDefaultState());
        structure.fillWithBlocks(world, start, 0, -32, -5, 0, -32, -2, Blocks.STONE_BRICKS.getDefaultState());
        structure.fillWithBlocks(world, start, 0, -32, 7, 6, -31, 7, Blocks.STONE_BRICKS.getDefaultState());
        structure.fillWithBlocks(world, start, 0, -32, 8, 1, -32, 8, Blocks.AIR.getDefaultState());
        structure.fillWithBlocks(world, start, 0, -32, 9, 2, -32, 12, Blocks.STONE_BRICKS.getDefaultState());
        structure.fillWithBlocks(world, start, 0, -32, 21, 0, -31, 22, Blocks.STONE_BRICKS.getDefaultState());
        structure.fillWithBlocks(world, start, 0, -32, 24, 1, -32, 25, Blocks.STONE_BRICKS.getDefaultState());
        structure.fillWithBlocks(world, start, 0, -32, 29, 18, -31, 29, Blocks.STONE_BRICKS.getDefaultState());
        structure.fillWithBlocks(world, start, 0, -32, 30, 1, -32, 30, Blocks.AIR.getDefaultState());
        structure.fillWithBlocks(world, start, 0, -32, 31, 2, -32, 33, Blocks.STONE_BRICKS.getDefaultState());
        structure.fillWithBlocks(world, start, 0, -32, 35, 1, -32, 43, Blocks.STONE_BRICKS.getDefaultState());
        structure.fillWithBlocks(world, start, 0, -31, -47, 0, -31, -47, Blocks.STONE_BRICKS.getDefaultState());
        structure.fillWithBlocks(world, start, 0, -31, -45, 0, -31, -45, Blocks.STONE_BRICKS.getDefaultState());
        structure.fillWithBlocks(world, start, 0, -31, -43, 0, -30, -43, Blocks.SANDSTONE.getDefaultState());
        structure.fillWithBlocks(world, start, 0, -31, -42, 2, -31, -40, Blocks.STONE_BRICKS.getDefaultState());
        structure.fillWithBlocks(world, start, 0, -31, -28, 1, -31, -27, Blocks.STONE_BRICKS.getDefaultState());
        structure.fillWithBlocks(world, start, 0, -31, -16, 2, -31, -13, Blocks.STONE_BRICKS.getDefaultState());
        structure.fillWithBlocks(world, start, 0, -31, -10, 0, -31, -10, Blocks.SANDSTONE.getDefaultState());
        structure.fillWithBlocks(world, start, 0, -31, -7, 9, -31, -7, Blocks.STONE_BRICKS.getDefaultState());
        structure.fillWithBlocks(world, start, 0, -31, -5, 3, -31, -2, Blocks.STONE_BRICKS.getDefaultState());
        structure.fillWithBlocks(world, start, 0, -31, 1, 2, -31, 4, Blocks.STONE_BRICKS.getDefaultState());
        structure.fillWithBlocks(world, start, 0, -31, 5, 1, -31, 8, Blocks.STONE_BRICKS.getDefaultState());
        structure.fillWithBlocks(world, start, 0, -31, 17, 0, -31, 25, Blocks.STONE_BRICKS.getDefaultState());
        structure.fillWithBlocks(world, start, 0, -30, -53, 0, -28, -53, Blocks.STONE_BRICKS.getDefaultState());
        structure.fillWithBlocks(world, start, 0, -30, -51, 1, -30, -50, Blocks.STONE_BRICKS.getDefaultState());
        structure.fillWithBlocks(world, start, 0, -30, -23, 0, -30, -22, Blocks.SANDSTONE.getDefaultState());
        structure.fillWithBlocks(world, start, 0, -30, -12, 0, -30, -10, Blocks.DIRT.getDefaultState());
        structure.fillWithBlocks(world, start, 0, -30, -9, 0, -30, -9, Blocks.SANDSTONE.getDefaultState());
        structure.fillWithBlocks(world, start, 0, -30, -7, 0, -15, -7, Blocks.SANDSTONE.getDefaultState());
        structure.fillWithBlocks(world, start, 0, -30, 1, 4, -30, 16, Blocks.SANDSTONE.getDefaultState());
        structure.fillWithBlocks(world, start, 0, -30, 17, 1, -30, 17, Blocks.DIRT.getDefaultState());
        structure.fillWithBlocks(world, start, 0, -30, 18, 2, -30, 18, Blocks.SANDSTONE.getDefaultState());
        structure.fillWithBlocks(world, start, 0, -29, -52, 1, -29, -51, Blocks.STONE_BRICKS.getDefaultState());
        structure.fillWithBlocks(world, start, 0, -29, -50, 1, -29, -50, Blocks.SANDSTONE.getDefaultState());
        structure.fillWithBlocks(world, start, 0, -29, -33, 1, -28, -33, Blocks.SANDSTONE.getDefaultState());
        structure.fillWithBlocks(world, start, 0, -29, -30, 0, -29, -29, Blocks.SANDSTONE.getDefaultState());
        structure.fillWithBlocks(world, start, 0, -29, -23, 1, -29, -23, Blocks.SANDSTONE.getDefaultState());
        structure.fillWithBlocks(world, start, 0, -29, -15, 0, -29, -4, Blocks.SANDSTONE.getDefaultState());
        structure.fillWithBlocks(world, start, 0, -29, -2, 2, -29, 0, Blocks.SANDSTONE.getDefaultState());
        structure.fillWithBlocks(world, start, 0, -29, 1, 1, -29, 15, Blocks.AIR.getDefaultState());
        structure.fillWithBlocks(world, start, 0, -28, -50, 0, -25, -50, Blocks.SANDSTONE.getDefaultState());
        structure.fillWithBlocks(world, start, 0, -28, -36, 0, -28, -33, Blocks.SANDSTONE.getDefaultState());
        structure.fillWithBlocks(world, start, 0, -28, -30, 0, -22, -30, Blocks.SANDSTONE.getDefaultState());
        structure.fillWithBlocks(world, start, 0, -28, -22, 0, -26, -22, Blocks.SANDSTONE.getDefaultState());
        structure.fillWithBlocks(world, start, 0, -28, -11, 0, -27, -10, Blocks.SANDSTONE.getDefaultState());
        structure.fillWithBlocks(world, start, 0, -28, -8, 1, -28, -1, Blocks.SANDSTONE.getDefaultState());
        structure.fillWithBlocks(world, start, 0, -28, 0, 0, -25, 0, Blocks.SANDSTONE.getDefaultState());
        structure.fillWithBlocks(world, start, 0, -28, 1, 4, -28, 15, Blocks.AIR.getDefaultState());
        structure.fillWithBlocks(world, start, 0, -28, 18, 1, -27, 18, Blocks.SANDSTONE.getDefaultState());
        structure.fillWithBlocks(world, start, 0, -27, -53, 0, -27, -53, Blocks.SANDSTONE.getDefaultState());
        structure.fillWithBlocks(world, start, 0, -27, -52, 0, -25, -52, Blocks.STONE_BRICKS.getDefaultState());
        structure.fillWithBlocks(world, start, 0, -27, -51, 0, -27, -50, Blocks.SANDSTONE.getDefaultState());
        structure.fillWithBlocks(world, start, 0, -27, -29, 1, -27, -29, Blocks.SANDSTONE.getDefaultState());
        structure.fillWithBlocks(world, start, 0, -27, -23, 0, -26, -22, Blocks.SANDSTONE.getDefaultState());
        structure.fillWithBlocks(world, start, 0, -27, -15, 1, -27, -4, Blocks.SANDSTONE.getDefaultState());
        structure.fillWithBlocks(world, start, 0, -27, -3, 0, -26, -3, Blocks.AIR.getDefaultState());
        structure.fillWithBlocks(world, start, 0, -27, -2, 0, -27, -1, Blocks.DIRT.getDefaultState());
        structure.fillWithBlocks(world, start, 0, -27, 1, 4, -27, 15, Blocks.AIR.getDefaultState());
        structure.fillWithBlocks(world, start, 0, -27, 16, 0, -27, 18, Blocks.SANDSTONE.getDefaultState());
        structure.fillWithBlocks(world, start, 0, -26, -36, 0, -26, -33, Blocks.SANDSTONE.getDefaultState());
        structure.fillWithBlocks(world, start, 0, -26, -14, 0, -22, -10, Blocks.SANDSTONE.getDefaultState());
        structure.fillWithBlocks(world, start, 0, -26, -9, 1, -26, -4, Blocks.SANDSTONE.getDefaultState());
        structure.fillWithBlocks(world, start, 0, -26, -2, 1, -26, -1, Blocks.SANDSTONE.getDefaultState());
        structure.fillWithBlocks(world, start, 0, -26, 1, 4, -26, 15, Blocks.AIR.getDefaultState());
        structure.fillWithBlocks(world, start, 0, -26, 16, 0, -21, 16, Blocks.SANDSTONE.getDefaultState());
        structure.fillWithBlocks(world, start, 0, -25, -51, 1, -25, -51, Blocks.STONE_BRICKS.getDefaultState());
        structure.fillWithBlocks(world, start, 0, -25, -45, 3, -25, -45, Blocks.SANDSTONE.getDefaultState());
        structure.fillWithBlocks(world, start, 0, -25, -44, 1, -25, -42, Blocks.AIR.getDefaultState());
        structure.fillWithBlocks(world, start, 0, -25, -41, 3, -25, -41, Blocks.SANDSTONE.getDefaultState());
        structure.fillWithBlocks(world, start, 0, -25, -40, 2, -25, -38, Blocks.AIR.getDefaultState());
        structure.fillWithBlocks(world, start, 0, -25, -35, 0, -25, -35, Blocks.DIRT.getDefaultState());
        structure.fillWithBlocks(world, start, 0, -25, -34, 0, -21, -34, Blocks.SANDSTONE.getDefaultState());
        structure.fillWithBlocks(world, start, 0, -25, -24, 0, -25, -23, Blocks.SANDSTONE.getDefaultState());
        structure.fillWithBlocks(world, start, 0, -25, -9, 1, -25, 0, Blocks.SANDSTONE.getDefaultState());
        structure.fillWithBlocks(world, start, 0, -25, 1, 4, -25, 15, Blocks.AIR.getDefaultState());
        structure.fillWithBlocks(world, start, 0, -25, 17, 1, -25, 18, Blocks.SANDSTONE.getDefaultState());
        structure.fillWithBlocks(world, start, 0, -24, -53, 0, -22, -53, Blocks.STONE_BRICKS.getDefaultState());
        structure.fillWithBlocks(world, start, 0, -24, -49, 1, -24, -48, Blocks.SANDSTONE.getDefaultState());
        structure.fillWithBlocks(world, start, 0, -24, -46, 2, -24, -46, Blocks.SANDSTONE.getDefaultState());
        structure.fillWithBlocks(world, start, 0, -24, -45, 6, -24, -45, Blocks.STONE_BRICKS.getDefaultState());
        structure.fillWithBlocks(world, start, 0, -24, -44, 0, -24, -44, Blocks.SANDSTONE.getDefaultState());
        structure.fillWithBlocks(world, start, 0, -24, -42, 0, -24, -40, Blocks.SANDSTONE.getDefaultState());
        structure.fillWithBlocks(world, start, 0, -24, -38, 1, -24, -33, Blocks.SANDSTONE.getDefaultState());
        structure.fillWithBlocks(world, start, 0, -24, -26, 0, -23, -25, Blocks.SANDSTONE.getDefaultState());
        structure.fillWithBlocks(world, start, 0, -24, -9, 1, -24, -5, Blocks.SANDSTONE.getDefaultState());
        structure.fillWithBlocks(world, start, 0, -24, 3, 4, -24, 17, Blocks.SANDSTONE.getDefaultState());
        structure.fillWithBlocks(world, start, 0, -23, -46, 0, -23, -45, Blocks.SANDSTONE.getDefaultState());
        structure.fillWithBlocks(world, start, 0, -23, -42, 1, -23, -41, Blocks.STONE_BRICKS.getDefaultState());
        structure.fillWithBlocks(world, start, 0, -23, -38, 2, -23, -36, Blocks.SANDSTONE.getDefaultState());
        structure.fillWithBlocks(world, start, 0, -23, -35, 0, -23, -33, Blocks.SANDSTONE.getDefaultState());
        structure.fillWithBlocks(world, start, 0, -23, -28, 0, -22, -27, Blocks.SANDSTONE.getDefaultState());
        structure.fillWithBlocks(world, start, 0, -23, -9, 2, -23, -7, Blocks.SANDSTONE.getDefaultState());
        structure.fillWithBlocks(world, start, 0, -23, 1, 0, -22, 2, Blocks.SANDSTONE.getDefaultState());
        structure.fillWithBlocks(world, start, 0, -23, 3, 1, -23, 3, Blocks.AIR.getDefaultState());
        structure.fillWithBlocks(world, start, 0, -23, 4, 1, -23, 5, Blocks.SANDSTONE.getDefaultState());
        structure.fillWithBlocks(world, start, 0, -23, 6, 0, -23, 7, Blocks.SANDSTONE.getDefaultState());
        structure.fillWithBlocks(world, start, 0, -23, 11, 0, -23, 11, Blocks.SANDSTONE.getDefaultState());
        structure.fillWithBlocks(world, start, 0, -23, 12, 0, -23, 13, Blocks.AIR.getDefaultState());
        structure.fillWithBlocks(world, start, 0, -23, 14, 2, -23, 16, Blocks.SANDSTONE.getDefaultState());
        structure.fillWithBlocks(world, start, 0, -23, 17, 0, -23, 17, Blocks.AIR.getDefaultState());
        structure.fillWithBlocks(world, start, 0, -22, -52, 1, -22, -51, Blocks.STONE_BRICKS.getDefaultState());
        structure.fillWithBlocks(world, start, 0, -22, -49, 1, -22, -48, Blocks.STONE_BRICKS.getDefaultState());
        structure.fillWithBlocks(world, start, 0, -22, -41, 1, -22, -41, Blocks.SANDSTONE.getDefaultState());
        structure.fillWithBlocks(world, start, 0, -22, -40, 0, -21, -40, Blocks.DIRT.getDefaultState());
        structure.fillWithBlocks(world, start, 0, -22, -39, 0, -21, -39, Blocks.STONE_BRICKS.getDefaultState());
        structure.fillWithBlocks(world, start, 0, -22, -38, 0, -22, -36, Blocks.SANDSTONE.getDefaultState());
        structure.fillWithBlocks(world, start, 0, -22, -25, 0, -20, -22, Blocks.SANDSTONE.getDefaultState());
        structure.fillWithBlocks(world, start, 0, -22, -9, 1, -22, -9, Blocks.SHROOMLIGHT.getDefaultState());
        structure.fillWithBlocks(world, start, 0, -22, -8, 0, -22, 3, Blocks.SANDSTONE.getDefaultState());
        structure.fillWithBlocks(world, start, 0, -22, 5, 2, -22, 10, Blocks.SANDSTONE.getDefaultState());
        structure.fillWithBlocks(world, start, 0, -22, 12, 1, -22, 14, Blocks.SANDSTONE.getDefaultState());
        structure.fillWithBlocks(world, start, 0, -21, -51, 0, -21, -50, Blocks.DIRT.getDefaultState());
        structure.fillWithBlocks(world, start, 0, -21, -49, 0, -21, -48, Blocks.STONE_BRICKS.getDefaultState());
        structure.fillWithBlocks(world, start, 0, -21, -45, 2, -21, -43, Blocks.STONE_BRICKS.getDefaultState());
        structure.fillWithBlocks(world, start, 0, -21, -42, 0, -21, -41, Blocks.STONE_BRICKS.getDefaultState());
        structure.fillWithBlocks(world, start, 0, -21, -37, 2, -21, -33, Blocks.SANDSTONE.getDefaultState());
        structure.fillWithBlocks(world, start, 0, -21, -28, 0, -21, -27, Blocks.DIRT.getDefaultState());
        structure.fillWithBlocks(world, start, 0, -21, -26, 0, -20, -22, Blocks.SANDSTONE.getDefaultState());
        structure.fillWithBlocks(world, start, 0, -21, -15, 0, -21, -15, Blocks.SANDSTONE.getDefaultState());
        structure.fillWithBlocks(world, start, 0, -21, -12, 1, -21, -11, Blocks.SANDSTONE.getDefaultState());
        structure.fillWithBlocks(world, start, 0, -21, -10, 0, -21, 5, Blocks.SANDSTONE.getDefaultState());
        structure.fillWithBlocks(world, start, 0, -21, 7, 4, -21, 7, Blocks.SANDSTONE.getDefaultState());
        structure.fillWithBlocks(world, start, 0, -21, 10, 0, -21, 16, Blocks.SANDSTONE.getDefaultState());
        structure.fillWithBlocks(world, start, 0, -21, 18, 2, -21, 18, Blocks.SANDSTONE.getDefaultState());
        structure.fillWithBlocks(world, start, 0, -20, -32, 0, -20, -32, Blocks.AIR.getDefaultState());
        structure.fillWithBlocks(world, start, 0, -20, -31, 0, -20, -21, Blocks.SANDSTONE.getDefaultState());
        structure.fillWithBlocks(world, start, 0, -20, -15, 1, -20, -12, Blocks.SANDSTONE.getDefaultState());
        structure.fillWithBlocks(world, start, 0, -20, -5, 2, -20, -3, Blocks.SANDSTONE.getDefaultState());
        structure.fillWithBlocks(world, start, 0, -19, -32, 1, -19, -28, Blocks.SANDSTONE.getDefaultState());
        structure.fillWithBlocks(world, start, 0, -19, -24, 1, -19, -20, Blocks.SANDSTONE.getDefaultState());
        structure.fillWithBlocks(world, start, 0, -19, -15, 2, -19, -12, Blocks.SANDSTONE.getDefaultState());
        structure.fillWithBlocks(world, start, 0, -19, -11, 1, -18, -11, Blocks.SANDSTONE.getDefaultState());
        structure.fillWithBlocks(world, start, 0, -19, -10, 2, -19, -8, Blocks.AIR.getDefaultState());
        structure.fillWithBlocks(world, start, 0, -19, 25, 0, -19, 31, Blocks.SANDSTONE.getDefaultState());
        structure.fillWithBlocks(world, start, 0, -19, 33, 1, -19, 34, Blocks.SANDSTONE.getDefaultState());
        structure.fillWithBlocks(world, start, 0, -18, -32, 1, -18, -31, Blocks.SANDSTONE.getDefaultState());
        structure.fillWithBlocks(world, start, 0, -18, -30, 0, -18, -28, Blocks.SANDSTONE.getDefaultState());
        structure.fillWithBlocks(world, start, 0, -18, -24, 1, -18, -20, Blocks.SANDSTONE.getDefaultState());
        structure.fillWithBlocks(world, start, 0, -18, -15, 2, -18, -12, Blocks.SANDSTONE.getDefaultState());
        structure.fillWithBlocks(world, start, 0, -18, -10, 2, -18, -8, Blocks.AIR.getDefaultState());
        structure.fillWithBlocks(world, start, 0, -18, 25, 2, -18, 33, Blocks.SANDSTONE.getDefaultState());
        structure.fillWithBlocks(world, start, 0, -17, -32, 2, -17, -29, Blocks.SANDSTONE.getDefaultState());
        structure.fillWithBlocks(world, start, 0, -17, -24, 1, -17, -20, Blocks.SANDSTONE.getDefaultState());
        structure.fillWithBlocks(world, start, 0, -17, -15, 2, -17, -12, Blocks.SANDSTONE.getDefaultState());
        structure.fillWithBlocks(world, start, 0, -17, -11, 1, -17, -11, Blocks.SANDSTONE.getDefaultState());
        structure.fillWithBlocks(world, start, 0, -17, -10, 2, -17, -8, Blocks.AIR.getDefaultState());
        structure.fillWithBlocks(world, start, 0, -17, 25, 2, -17, 27, Blocks.SANDSTONE.getDefaultState());
        structure.fillWithBlocks(world, start, 0, -17, 28, 0, -17, 34, Blocks.SANDSTONE.getDefaultState());
        structure.fillWithBlocks(world, start, 0, -16, -32, 2, -16, -29, Blocks.SANDSTONE.getDefaultState());
        structure.fillWithBlocks(world, start, 0, -16, -27, 3, -16, -24, Blocks.SANDSTONE.getDefaultState());
        structure.fillWithBlocks(world, start, 0, -16, -23, 1, -16, -22, Blocks.SANDSTONE.getDefaultState());
        structure.fillWithBlocks(world, start, 0, -16, -21, 0, -16, -20, Blocks.SANDSTONE.getDefaultState());
        structure.fillWithBlocks(world, start, 0, -16, -11, 0, -15, -11, Blocks.DIRT.getDefaultState());
        structure.fillWithBlocks(world, start, 0, -16, -10, 3, -16, -7, Blocks.SANDSTONE.getDefaultState());
        structure.fillWithBlocks(world, start, 0, -16, -3, 2, -14, -3, Blocks.SANDSTONE.getDefaultState());
        structure.fillWithBlocks(world, start, 0, -16, 26, 2, -16, 34, Blocks.SANDSTONE.getDefaultState());
        structure.fillWithBlocks(world, start, 0, -15, -30, 1, -15, -20, Blocks.SANDSTONE.getDefaultState());
        structure.fillWithBlocks(world, start, 0, -15, -14, 0, -13, -12, Blocks.SANDSTONE.getDefaultState());
        structure.fillWithBlocks(world, start, 0, -15, -10, 0, -15, -10, Blocks.SANDSTONE.getDefaultState());
        structure.fillWithBlocks(world, start, 0, -15, -8, 1, -15, -3, Blocks.SANDSTONE.getDefaultState());
        structure.fillWithBlocks(world, start, 0, -15, 25, 0, -15, 34, Blocks.SANDSTONE.getDefaultState());
        structure.fillWithBlocks(world, start, 0, -14, -26, 2, -14, -20, Blocks.SANDSTONE.getDefaultState());
        structure.fillWithBlocks(world, start, 0, -14, -15, 1, -14, -8, Blocks.SANDSTONE.getDefaultState());
        structure.fillWithBlocks(world, start, 0, -14, -7, 1, -14, -7, Blocks.AIR.getDefaultState());
        structure.fillWithBlocks(world, start, 0, -14, 26, 1, -14, 27, Blocks.SANDSTONE.getDefaultState());
        structure.fillWithBlocks(world, start, 0, -13, -31, 0, -13, -31, Blocks.SANDSTONE.getDefaultState());
        structure.fillWithBlocks(world, start, 0, -13, -29, 1, -13, -28, Blocks.SANDSTONE.getDefaultState());
        structure.fillWithBlocks(world, start, 0, -13, -27, 0, -13, -26, Blocks.AIR.getDefaultState());
        structure.fillWithBlocks(world, start, 0, -13, -25, 1, -13, -21, Blocks.SANDSTONE.getDefaultState());
        structure.fillWithBlocks(world, start, 0, -13, -20, 0, -12, -20, Blocks.AIR.getDefaultState());
        structure.fillWithBlocks(world, start, 0, -13, -15, 2, -13, -8, Blocks.SANDSTONE.getDefaultState());
        structure.fillWithBlocks(world, start, 0, -12, -32, 1, -12, -30, Blocks.SANDSTONE.getDefaultState());
        structure.fillWithBlocks(world, start, 0, -12, -15, 1, -12, -14, Blocks.SANDSTONE.getDefaultState());
        structure.fillWithBlocks(world, start, 0, -12, -12, 1, -12, -11, Blocks.SANDSTONE.getDefaultState());
        structure.fillWithBlocks(world, start, 0, -12, -10, 2, -12, -10, Blocks.AIR.getDefaultState());
        structure.fillWithBlocks(world, start, 0, -12, -9, 2, -12, -3, Blocks.SANDSTONE.getDefaultState());
        structure.fillWithBlocks(world, start, 0, -12, 22, 2, -12, 26, Blocks.SANDSTONE.getDefaultState());
        structure.fillWithBlocks(world, start, 0, -12, 29, 2, -12, 32, Blocks.SANDSTONE.getDefaultState());
        structure.fillWithBlocks(world, start, 0, -12, 33, 0, -12, 34, Blocks.SANDSTONE.getDefaultState());
        structure.fillWithBlocks(world, start, 0, -11, -26, 0, -11, -26, Blocks.SANDSTONE.getDefaultState());
        structure.fillWithBlocks(world, start, 0, -11, -24, 1, -11, -23, Blocks.SANDSTONE.getDefaultState());
        structure.fillWithBlocks(world, start, 0, -11, -21, 1, -11, -20, Blocks.SANDSTONE.getDefaultState());
        structure.fillWithBlocks(world, start, 0, -11, 22, 2, -11, 25, Blocks.SANDSTONE.getDefaultState());
        structure.fillWithBlocks(world, start, 0, -7, -12, 1, -7, -12, Blocks.STONE_BRICKS.getDefaultState());
        structure.fillWithBlocks(world, start, 0, -7, -6, 1, -7, -6, Blocks.STONE_BRICKS.getDefaultState());
        structure.fillWithBlocks(world, start, 0, -6, -11, 4, -6, -7, Blocks.SANDSTONE.getDefaultState());
        structure.fillWithBlocks(world, start, 1, -52, -13, 2, -52, -12, Blocks.SANDSTONE.getDefaultState());
        structure.fillWithBlocks(world, start, 1, -52, -11, 1, -51, -11, Blocks.SHROOMLIGHT.getDefaultState());
        structure.fillWithBlocks(world, start, 1, -52, -10, 3, -52, -8, Blocks.SANDSTONE.getDefaultState());
        structure.fillWithBlocks(world, start, 1, -52, -7, 1, -51, -7, Blocks.SHROOMLIGHT.getDefaultState());
        structure.fillWithBlocks(world, start, 1, -52, -6, 5, -52, 0, Blocks.SANDSTONE.getDefaultState());
        structure.fillWithBlocks(world, start, 1, -51, -16, 3, -51, -14, Blocks.SANDSTONE.getDefaultState());
        structure.fillWithBlocks(world, start, 1, -51, -13, 1, -51, -12, Blocks.SANDSTONE_STAIRS.getDefaultState().with(StairsBlock.FACING, Direction.EAST).with(StairsBlock.WATERLOGGED, false).with(StairsBlock.SHAPE, StairsShape.STRAIGHT).with(StairsBlock.HALF, Half.BOTTOM));
        structure.fillWithBlocks(world, start, 1, -51, -10, 3, -51, -8, Blocks.SANDSTONE.getDefaultState());
        structure.fillWithBlocks(world, start, 1, -51, -6, 1, -51, -5, Blocks.SANDSTONE_STAIRS.getDefaultState().with(StairsBlock.FACING, Direction.EAST).with(StairsBlock.WATERLOGGED, false).with(StairsBlock.SHAPE, StairsShape.STRAIGHT).with(StairsBlock.HALF, Half.BOTTOM));
        structure.fillWithBlocks(world, start, 1, -50, -20, 2, -50, -19, Blocks.SANDSTONE.getDefaultState());
        structure.fillWithBlocks(world, start, 1, -50, -14, 3, -50, -12, Blocks.AIR.getDefaultState());
        structure.fillWithBlocks(world, start, 1, -50, -6, 3, -50, 0, Blocks.AIR.getDefaultState());
        structure.fillWithBlocks(world, start, 1, -49, -20, 1, -49, -20, Blocks.SANDSTONE.getDefaultState());
        structure.fillWithBlocks(world, start, 1, -49, -14, 3, -49, 0, Blocks.AIR.getDefaultState());
        structure.fillWithBlocks(world, start, 1, -49, 15, 4, -49, 18, Blocks.SANDSTONE.getDefaultState());
        structure.fillWithBlocks(world, start, 1, -49, 21, 1, -48, 22, Blocks.AIR.getDefaultState());
        structure.fillWithBlocks(world, start, 1, -49, 23, 1, -49, 23, Blocks.SANDSTONE.getDefaultState());
        structure.fillWithBlocks(world, start, 1, -49, 24, 1, -46, 24, Blocks.AIR.getDefaultState());
        structure.fillWithBlocks(world, start, 1, -49, 26, 1, -46, 26, Blocks.AIR.getDefaultState());
        structure.fillWithBlocks(world, start, 1, -49, 27, 1, -49, 27, Blocks.SANDSTONE.getDefaultState());
        structure.fillWithBlocks(world, start, 1, -49, 28, 1, -48, 29, Blocks.AIR.getDefaultState());
        structure.fillWithBlocks(world, start, 1, -49, 32, 4, -49, 35, Blocks.SANDSTONE.getDefaultState());
        structure.fillWithBlocks(world, start, 1, -48, -20, 1, -48, -20, Blocks.SANDSTONE.getDefaultState());
        structure.fillWithBlocks(world, start, 1, -48, -14, 3, -48, 0, Blocks.AIR.getDefaultState());
        structure.fillWithBlocks(world, start, 1, -48, 18, 1, -48, 18, Blocks.SANDSTONE.getDefaultState());
        structure.fillWithBlocks(world, start, 1, -48, 20, 1, -48, 20, Blocks.SANDSTONE.getDefaultState());
        structure.fillWithBlocks(world, start, 1, -48, 23, 1, -48, 23, Blocks.SANDSTONE.getDefaultState());
        structure.fillWithBlocks(world, start, 1, -48, 25, 1, -47, 26, Blocks.AIR.getDefaultState());
        structure.fillWithBlocks(world, start, 1, -48, 27, 1, -48, 27, Blocks.SANDSTONE.getDefaultState());
        structure.fillWithBlocks(world, start, 1, -48, 30, 1, -48, 30, Blocks.SANDSTONE.getDefaultState());
        structure.fillWithBlocks(world, start, 1, -48, 32, 4, -48, 35, Blocks.SANDSTONE.getDefaultState());
        structure.fillWithBlocks(world, start, 1, -47, -20, 1, -47, -20, Blocks.SANDSTONE.getDefaultState());
        structure.fillWithBlocks(world, start, 1, -47, -14, 3, -47, 0, Blocks.AIR.getDefaultState());
        structure.fillWithBlocks(world, start, 1, -47, 15, 4, -47, 20, Blocks.SANDSTONE.getDefaultState());
        structure.fillWithBlocks(world, start, 1, -47, 21, 1, -46, 22, Blocks.AIR.getDefaultState());
        structure.fillWithBlocks(world, start, 1, -47, 23, 1, -47, 23, Blocks.SANDSTONE.getDefaultState());
        structure.fillWithBlocks(world, start, 1, -47, 27, 1, -47, 27, Blocks.SANDSTONE.getDefaultState());
        structure.fillWithBlocks(world, start, 1, -47, 28, 1, -46, 29, Blocks.AIR.getDefaultState());
        structure.fillWithBlocks(world, start, 1, -47, 30, 1, -47, 30, Blocks.SANDSTONE.getDefaultState());
        structure.fillWithBlocks(world, start, 1, -47, 32, 4, -47, 35, Blocks.SANDSTONE.getDefaultState());
        structure.fillWithBlocks(world, start, 1, -46, -20, 2, -46, -19, Blocks.SANDSTONE.getDefaultState());
        structure.fillWithBlocks(world, start, 1, -46, -18, 3, -46, -16, Blocks.AIR.getDefaultState());
        structure.fillWithBlocks(world, start, 1, -46, -14, 3, -46, -12, Blocks.AIR.getDefaultState());
        structure.fillWithBlocks(world, start, 1, -46, -10, 3, -46, -8, Blocks.AIR.getDefaultState());
        structure.fillWithBlocks(world, start, 1, -46, -6, 3, -46, -4, Blocks.AIR.getDefaultState());
        structure.fillWithBlocks(world, start, 1, -46, -2, 3, -46, 0, Blocks.AIR.getDefaultState());
        structure.fillWithBlocks(world, start, 1, -46, 1, 2, -46, 2, Blocks.SANDSTONE.getDefaultState());
        structure.fillWithBlocks(world, start, 1, -46, 23, 1, -46, 23, Blocks.SANDSTONE.getDefaultState());
        structure.fillWithBlocks(world, start, 1, -46, 25, 1, -46, 26, Blocks.AIR.getDefaultState());
        structure.fillWithBlocks(world, start, 1, -46, 27, 1, -46, 27, Blocks.SANDSTONE.getDefaultState());
        structure.fillWithBlocks(world, start, 1, -46, 30, 4, -46, 35, Blocks.SANDSTONE.getDefaultState());
        structure.fillWithBlocks(world, start, 1, -45, -18, 1, -41, 1, Blocks.SANDSTONE.getDefaultState());
        structure.fillWithBlocks(world, start, 1, -45, 22, 7, -45, 28, Blocks.SANDSTONE.getDefaultState());
        structure.fillWithBlocks(world, start, 1, -44, 22, 7, -44, 28, Blocks.SANDSTONE.getDefaultState());
        structure.fillWithBlocks(world, start, 1, -43, 15, 6, -43, 28, Blocks.SANDSTONE.getDefaultState());
        structure.fillWithBlocks(world, start, 1, -42, 34, 1, -40, 34, Blocks.STONE_BRICKS.getDefaultState());
        structure.fillWithBlocks(world, start, 1, -42, 35, 1, -41, 35, Blocks.AIR.getDefaultState());
        structure.fillWithBlocks(world, start, 1, -42, 37, 1, -42, 37, Blocks.STONE_BRICKS.getDefaultState());
        structure.fillWithBlocks(world, start, 1, -42, 39, 1, -42, 40, Blocks.STONE_BRICKS.getDefaultState());
        structure.fillWithBlocks(world, start, 1, -41, 29, 3, -41, 31, Blocks.SANDSTONE.getDefaultState());
        structure.fillWithBlocks(world, start, 1, -41, 38, 2, -40, 38, Blocks.STONE_BRICKS.getDefaultState());
        structure.fillWithBlocks(world, start, 1, -40, -4, 1, -40, -4, Blocks.STONE_BRICKS.getDefaultState());
        structure.fillWithBlocks(world, start, 1, -40, -2, 2, -40, -1, Blocks.STONE_BRICKS.getDefaultState());
        structure.fillWithBlocks(world, start, 1, -40, 0, 1, -40, 16, Blocks.STONE_BRICKS.getDefaultState());
        structure.fillWithBlocks(world, start, 1, -40, 18, 3, -40, 20, Blocks.STONE_BRICKS.getDefaultState());
        structure.fillWithBlocks(world, start, 1, -40, 26, 1, -40, 43, Blocks.STONE_BRICKS.getDefaultState());
        structure.fillWithBlocks(world, start, 1, -39, -42, 2, -39, -41, Blocks.STONE_BRICKS.getDefaultState());
        structure.fillWithBlocks(world, start, 1, -39, -28, 2, -39, -26, Blocks.STONE_BRICKS.getDefaultState());
        structure.fillWithBlocks(world, start, 1, -39, -25, 1, -37, -25, Blocks.AIR.getDefaultState());
        structure.fillWithBlocks(world, start, 1, -39, -24, 1, -36, -24, Blocks.STONE_BRICKS.getDefaultState());
        structure.fillWithBlocks(world, start, 1, -39, -23, 1, -37, -21, Blocks.AIR.getDefaultState());
        structure.fillWithBlocks(world, start, 1, -39, -20, 1, -39, -20, Blocks.STONE_BRICKS.getDefaultState());
        structure.fillWithBlocks(world, start, 1, -39, -19, 1, -37, -19, Blocks.AIR.getDefaultState());
        structure.fillWithBlocks(world, start, 1, -39, -18, 1, -36, -18, Blocks.STONE_BRICKS.getDefaultState());
        structure.fillWithBlocks(world, start, 1, -39, -17, 1, -37, -15, Blocks.AIR.getDefaultState());
        structure.fillWithBlocks(world, start, 1, -39, -14, 1, -39, -13, Blocks.STONE_BRICKS.getDefaultState());
        structure.fillWithBlocks(world, start, 1, -39, -5, 2, -39, -3, Blocks.STONE_BRICKS.getDefaultState());
        structure.fillWithBlocks(world, start, 1, -39, -2, 1, -37, 0, Blocks.AIR.getDefaultState());
        structure.fillWithBlocks(world, start, 1, -39, 1, 1, -39, 1, Blocks.STONE_BRICKS.getDefaultState());
        structure.fillWithBlocks(world, start, 1, -39, 2, 1, -37, 2, Blocks.AIR.getDefaultState());
        structure.fillWithBlocks(world, start, 1, -39, 3, 1, -39, 3, Blocks.STONE_BRICKS.getDefaultState());
        structure.fillWithBlocks(world, start, 1, -39, 4, 1, -37, 6, Blocks.AIR.getDefaultState());
        structure.fillWithBlocks(world, start, 1, -39, 7, 3, -39, 9, Blocks.STONE_BRICKS.getDefaultState());
        structure.fillWithBlocks(world, start, 1, -39, 17, 1, -38, 18, Blocks.STONE_BRICKS.getDefaultState());
        structure.fillWithBlocks(world, start, 1, -39, 19, 1, -37, 19, Blocks.AIR.getDefaultState());
        structure.fillWithBlocks(world, start, 1, -39, 20, 1, -39, 20, Blocks.STONE_BRICKS.getDefaultState());
        structure.fillWithBlocks(world, start, 1, -39, 21, 1, -37, 23, Blocks.AIR.getDefaultState());
        structure.fillWithBlocks(world, start, 1, -39, 24, 1, -31, 24, Blocks.STONE_BRICKS.getDefaultState());
        structure.fillWithBlocks(world, start, 1, -39, 25, 1, -37, 27, Blocks.AIR.getDefaultState());
        structure.fillWithBlocks(world, start, 1, -39, 28, 1, -36, 28, Blocks.STONE_BRICKS.getDefaultState());
        structure.fillWithBlocks(world, start, 1, -39, 29, 1, -37, 29, Blocks.AIR.getDefaultState());
        structure.fillWithBlocks(world, start, 1, -39, 30, 2, -39, 32, Blocks.STONE_BRICKS.getDefaultState());
        structure.fillWithBlocks(world, start, 1, -39, 33, 2, -39, 39, Blocks.AIR.getDefaultState());
        structure.fillWithBlocks(world, start, 1, -39, 41, 2, -39, 41, Blocks.AIR.getDefaultState());
        structure.fillWithBlocks(world, start, 1, -39, 42, 2, -39, 43, Blocks.STONE_BRICKS.getDefaultState());
        structure.fillWithBlocks(world, start, 1, -38, -45, 1, -38, -44, Blocks.STONE_BRICKS.getDefaultState());
        structure.fillWithBlocks(world, start, 1, -38, -43, 1, -38, -41, Blocks.SHROOMLIGHT.getDefaultState());
        structure.fillWithBlocks(world, start, 1, -38, -28, 2, -38, -27, Blocks.STONE_BRICKS.getDefaultState());
        structure.fillWithBlocks(world, start, 1, -38, -26, 1, -36, -26, Blocks.STONE_BRICKS.getDefaultState());
        structure.fillWithBlocks(world, start, 1, -38, -20, 1, -36, -20, Blocks.STONE_BRICKS.getDefaultState());
        structure.fillWithBlocks(world, start, 1, -38, -14, 2, -38, -13, Blocks.STONE_BRICKS.getDefaultState());
        structure.fillWithBlocks(world, start, 1, -38, -5, 2, -38, -4, Blocks.STONE_BRICKS.getDefaultState());
        structure.fillWithBlocks(world, start, 1, -38, -3, 1, -35, -3, Blocks.STONE_BRICKS.getDefaultState());
        structure.fillWithBlocks(world, start, 1, -38, 1, 1, -31, 1, Blocks.STONE_BRICKS.getDefaultState());
        structure.fillWithBlocks(world, start, 1, -38, 3, 1, -38, 3, Blocks.STONE_BRICKS.getDefaultState());
        structure.fillWithBlocks(world, start, 1, -38, 7, 3, -38, 9, Blocks.STONE_BRICKS.getDefaultState());
        structure.fillWithBlocks(world, start, 1, -38, 20, 1, -31, 20, Blocks.STONE_BRICKS.getDefaultState());
        structure.fillWithBlocks(world, start, 1, -38, 30, 3, -38, 32, Blocks.STONE_BRICKS.getDefaultState());
        structure.fillWithBlocks(world, start, 1, -38, 33, 2, -38, 39, Blocks.AIR.getDefaultState());
        structure.fillWithBlocks(world, start, 1, -38, 40, 2, -38, 43, Blocks.STONE_BRICKS.getDefaultState());
        structure.fillWithBlocks(world, start, 1, -37, -45, 1, -37, -45, Blocks.STONE_BRICKS.getDefaultState());
        structure.fillWithBlocks(world, start, 1, -37, -44, 1, -37, -42, Blocks.AIR.getDefaultState());
        structure.fillWithBlocks(world, start, 1, -37, -28, 2, -37, -27, Blocks.STONE_BRICKS.getDefaultState());
        structure.fillWithBlocks(world, start, 1, -37, -14, 2, -37, -13, Blocks.STONE_BRICKS.getDefaultState());
        structure.fillWithBlocks(world, start, 1, -37, -5, 2, -37, -3, Blocks.STONE_BRICKS.getDefaultState());
        structure.fillWithBlocks(world, start, 1, -37, 3, 1, -37, 3, Blocks.STONE_BRICKS.getDefaultState());
        structure.fillWithBlocks(world, start, 1, -37, 7, 3, -37, 9, Blocks.STONE_BRICKS.getDefaultState());
        structure.fillWithBlocks(world, start, 1, -37, 17, 2, -37, 18, Blocks.STONE_BRICKS.getDefaultState());
        structure.fillWithBlocks(world, start, 1, -37, 30, 3, -37, 32, Blocks.STONE_BRICKS.getDefaultState());
        structure.fillWithBlocks(world, start, 1, -37, 40, 4, -37, 43, Blocks.STONE_BRICKS.getDefaultState());
        structure.fillWithBlocks(world, start, 1, -36, -46, 1, -36, -45, Blocks.AIR.getDefaultState());
        structure.fillWithBlocks(world, start, 1, -36, -44, 1, -36, -44, Blocks.STONE_BRICKS.getDefaultState());
        structure.fillWithBlocks(world, start, 1, -36, -43, 1, -36, -41, Blocks.SHROOMLIGHT.getDefaultState());
        structure.fillWithBlocks(world, start, 1, -36, 8, 2, -36, 9, Blocks.STONE_BRICKS.getDefaultState());
        structure.fillWithBlocks(world, start, 1, -36, 22, 4, -36, 25, Blocks.STONE_BRICKS.getDefaultState());
        structure.fillWithBlocks(world, start, 1, -36, 29, 1, -36, 32, Blocks.STONE_BRICKS.getDefaultState());
        structure.fillWithBlocks(world, start, 1, -35, -46, 1, -35, -45, Blocks.STONE_BRICKS.getDefaultState());
        structure.fillWithBlocks(world, start, 1, -35, -44, 1, -35, -42, Blocks.AIR.getDefaultState());
        structure.fillWithBlocks(world, start, 1, -35, -28, 2, -35, -27, Blocks.STONE_BRICKS.getDefaultState());
        structure.fillWithBlocks(world, start, 1, -35, 3, 3, -35, 5, Blocks.STONE_BRICKS.getDefaultState());
        structure.fillWithBlocks(world, start, 1, -35, 6, 1, -34, 6, Blocks.AIR.getDefaultState());
        structure.fillWithBlocks(world, start, 1, -35, 7, 2, -35, 8, Blocks.STONE_BRICKS.getDefaultState());
        structure.fillWithBlocks(world, start, 1, -35, 9, 1, -35, 10, Blocks.STONE_BRICKS.getDefaultState());
        structure.fillWithBlocks(world, start, 1, -35, 11, 5, -35, 15, Blocks.AIR.getDefaultState());
        structure.fillWithBlocks(world, start, 1, -35, 16, 4, -35, 21, Blocks.STONE_BRICKS.getDefaultState());
        structure.fillWithBlocks(world, start, 1, -35, 29, 1, -35, 29, Blocks.STONE_BRICKS.getDefaultState());
        structure.fillWithBlocks(world, start, 1, -35, 30, 1, -32, 30, Blocks.AIR.getDefaultState());
        structure.fillWithBlocks(world, start, 1, -35, 31, 2, -35, 32, Blocks.STONE_BRICKS.getDefaultState());
        structure.fillWithBlocks(world, start, 1, -35, 40, 3, -35, 43, Blocks.STONE_BRICKS.getDefaultState());
        structure.fillWithBlocks(world, start, 1, -34, -46, 1, -34, -46, Blocks.STONE_BRICKS.getDefaultState());
        structure.fillWithBlocks(world, start, 1, -34, -44, 1, -34, -27, Blocks.STONE_BRICKS.getDefaultState());
        structure.fillWithBlocks(world, start, 1, -34, -15, 2, -34, -14, Blocks.STONE_BRICKS.getDefaultState());
        structure.fillWithBlocks(world, start, 1, -34, -12, 1, -34, -10, Blocks.STONE_BRICKS.getDefaultState());
        structure.fillWithBlocks(world, start, 1, -34, -7, 2, -34, -6, Blocks.AIR.getDefaultState());
        structure.fillWithBlocks(world, start, 1, -34, 2, 2, -34, 3, Blocks.STONE_BRICKS.getDefaultState());
        structure.fillWithBlocks(world, start, 1, -34, 4, 1, -34, 6, Blocks.AIR.getDefaultState());
        structure.fillWithBlocks(world, start, 1, -34, 7, 1, -34, 7, Blocks.STONE_BRICKS.getDefaultState());
        structure.fillWithBlocks(world, start, 1, -34, 8, 1, -34, 8, Blocks.AIR.getDefaultState());
        structure.fillWithBlocks(world, start, 1, -34, 9, 1, -33, 10, Blocks.STONE_BRICKS.getDefaultState());
        structure.fillWithBlocks(world, start, 1, -34, 11, 11, -34, 11, Blocks.STONE_BRICKS.getDefaultState());
        structure.fillWithBlocks(world, start, 1, -34, 15, 1, -34, 21, Blocks.STONE_BRICKS.getDefaultState());
        structure.fillWithBlocks(world, start, 1, -34, 22, 1, -34, 23, Blocks.AIR.getDefaultState());
        structure.fillWithBlocks(world, start, 1, -34, 29, 1, -34, 29, Blocks.STONE_BRICKS.getDefaultState());
        structure.fillWithBlocks(world, start, 1, -34, 31, 2, -34, 43, Blocks.STONE_BRICKS.getDefaultState());
        structure.fillWithBlocks(world, start, 1, -33, -46, 3, -33, -44, Blocks.STONE_BRICKS.getDefaultState());
        structure.fillWithBlocks(world, start, 1, -33, -42, 2, -33, -41, Blocks.STONE_BRICKS.getDefaultState());
        structure.fillWithBlocks(world, start, 1, -33, -40, 1, -32, -35, Blocks.STONE_BRICKS.getDefaultState());
        structure.fillWithBlocks(world, start, 1, -33, -33, 4, -33, -29, Blocks.STONE_BRICKS.getDefaultState());
        structure.fillWithBlocks(world, start, 1, -33, -28, 2, -33, -28, Blocks.AIR.getDefaultState());
        structure.fillWithBlocks(world, start, 1, -33, -15, 2, -33, -14, Blocks.STONE_BRICKS.getDefaultState());
        structure.fillWithBlocks(world, start, 1, -33, -13, 1, -33, -12, Blocks.AIR.getDefaultState());
        structure.fillWithBlocks(world, start, 1, -33, -11, 2, -33, -11, Blocks.STONE_BRICKS.getDefaultState());
        structure.fillWithBlocks(world, start, 1, -33, -10, 1, -33, -9, Blocks.AIR.getDefaultState());
        structure.fillWithBlocks(world, start, 1, -33, -7, 1, -33, -6, Blocks.AIR.getDefaultState());
        structure.fillWithBlocks(world, start, 1, -33, -5, 2, -33, -2, Blocks.STONE_BRICKS.getDefaultState());
        structure.fillWithBlocks(world, start, 1, -33, 12, 1, -33, 12, Blocks.STONE_BRICKS.getDefaultState());
        structure.fillWithBlocks(world, start, 1, -33, 14, 2, -33, 25, Blocks.STONE_BRICKS.getDefaultState());
        structure.fillWithBlocks(world, start, 1, -33, 29, 1, -33, 29, Blocks.STONE_BRICKS.getDefaultState());
        structure.fillWithBlocks(world, start, 1, -33, 31, 1, -31, 34, Blocks.STONE_BRICKS.getDefaultState());
        structure.fillWithBlocks(world, start, 1, -33, 36, 2, -33, 37, Blocks.STONE_BRICKS.getDefaultState());
        structure.fillWithBlocks(world, start, 1, -33, 39, 3, -33, 43, Blocks.STONE_BRICKS.getDefaultState());
        structure.fillWithBlocks(world, start, 1, -32, -47, 3, -32, -44, Blocks.STONE_BRICKS.getDefaultState());
        structure.fillWithBlocks(world, start, 1, -32, -43, 1, -32, -27, Blocks.STONE_BRICKS.getDefaultState());
        structure.fillWithBlocks(world, start, 1, -32, -15, 4, -32, -12, Blocks.STONE_BRICKS.getDefaultState());
        structure.fillWithBlocks(world, start, 1, -32, -11, 1, -31, -11, Blocks.AIR.getDefaultState());
        structure.fillWithBlocks(world, start, 1, -32, -9, 1, -32, -8, Blocks.AIR.getDefaultState());
        structure.fillWithBlocks(world, start, 1, -32, -5, 2, -32, -5, Blocks.AIR.getDefaultState());
        structure.fillWithBlocks(world, start, 1, -32, -4, 1, -32, -4, Blocks.STONE_BRICKS.getDefaultState());
        structure.fillWithBlocks(world, start, 1, -32, 6, 2, -32, 7, Blocks.STONE_BRICKS.getDefaultState());
        structure.fillWithBlocks(world, start, 1, -32, 14, 3, -32, 21, Blocks.STONE_BRICKS.getDefaultState());
        structure.fillWithBlocks(world, start, 1, -32, 23, 3, -32, 25, Blocks.STONE_BRICKS.getDefaultState());
        structure.fillWithBlocks(world, start, 1, -31, -47, 2, -31, -46, Blocks.STONE_BRICKS.getDefaultState());
        structure.fillWithBlocks(world, start, 1, -31, -44, 3, -31, -40, Blocks.STONE_BRICKS.getDefaultState());
        structure.fillWithBlocks(world, start, 1, -31, -39, 1, -31, -39, Blocks.STONE_BRICKS.getDefaultState());
        structure.fillWithBlocks(world, start, 1, -31, -37, 3, -31, -35, Blocks.STONE_BRICKS.getDefaultState());
        structure.fillWithBlocks(world, start, 1, -31, -30, 3, -31, -27, Blocks.STONE_BRICKS.getDefaultState());
        structure.fillWithBlocks(world, start, 1, -31, -12, 7, -31, -12, Blocks.STONE_BRICKS.getDefaultState());
        structure.fillWithBlocks(world, start, 1, -31, -9, 2, -31, -8, Blocks.SANDSTONE.getDefaultState());
        structure.fillWithBlocks(world, start, 1, -31, -6, 1, -22, -6, Blocks.SANDSTONE.getDefaultState());
        structure.fillWithBlocks(world, start, 1, -31, 10, 1, -31, 10, Blocks.STONE_BRICKS.getDefaultState());
        structure.fillWithBlocks(world, start, 1, -31, 11, 1, -31, 12, Blocks.AIR.getDefaultState());
        structure.fillWithBlocks(world, start, 1, -31, 13, 1, -31, 14, Blocks.STONE_BRICKS.getDefaultState());
        structure.fillWithBlocks(world, start, 1, -31, 16, 2, -31, 17, Blocks.STONE_BRICKS.getDefaultState());
        structure.fillWithBlocks(world, start, 1, -30, -53, 2, -30, -53, Blocks.SANDSTONE.getDefaultState());
        structure.fillWithBlocks(world, start, 1, -30, -52, 1, -29, -51, Blocks.STONE_BRICKS.getDefaultState());
        structure.fillWithBlocks(world, start, 1, -30, -33, 1, -27, -33, Blocks.SANDSTONE.getDefaultState());
        structure.fillWithBlocks(world, start, 1, -30, -14, 1, -29, -13, Blocks.SANDSTONE.getDefaultState());
        structure.fillWithBlocks(world, start, 1, -30, -11, 2, -30, -9, Blocks.SANDSTONE.getDefaultState());
        structure.fillWithBlocks(world, start, 1, -30, -8, 1, -23, -8, Blocks.SANDSTONE.getDefaultState());
        structure.fillWithBlocks(world, start, 1, -30, -5, 1, -23, -5, Blocks.SANDSTONE.getDefaultState());
        structure.fillWithBlocks(world, start, 1, -30, -3, 2, -30, -2, Blocks.SANDSTONE.getDefaultState());
        structure.fillWithBlocks(world, start, 1, -30, -1, 1, -29, 0, Blocks.SANDSTONE.getDefaultState());
        structure.fillWithBlocks(world, start, 1, -29, -42, 1, -27, -37, Blocks.AIR.getDefaultState());
        structure.fillWithBlocks(world, start, 1, -29, -36, 2, -29, -35, Blocks.SANDSTONE.getDefaultState());
        structure.fillWithBlocks(world, start, 1, -29, -34, 1, -29, -34, Blocks.AIR.getDefaultState());
        structure.fillWithBlocks(world, start, 1, -29, -29, 1, -27, -29, Blocks.SANDSTONE.getDefaultState());
        structure.fillWithBlocks(world, start, 1, -29, -12, 1, -29, -12, Blocks.SANDSTONE.getDefaultState());
        structure.fillWithBlocks(world, start, 1, -29, -11, 1, -29, -9, Blocks.AIR.getDefaultState());
        structure.fillWithBlocks(world, start, 1, -29, -7, 1, -29, 0, Blocks.SANDSTONE.getDefaultState());
        structure.fillWithBlocks(world, start, 1, -29, 16, 2, -29, 17, Blocks.SANDSTONE.getDefaultState());
        structure.fillWithBlocks(world, start, 1, -29, 18, 1, -25, 18, Blocks.SANDSTONE.getDefaultState());
        structure.fillWithBlocks(world, start, 1, -28, -52, 1, -28, -51, Blocks.SANDSTONE.getDefaultState());
        structure.fillWithBlocks(world, start, 1, -28, -35, 2, -28, -34, Blocks.SANDSTONE.getDefaultState());
        structure.fillWithBlocks(world, start, 1, -28, -23, 1, -26, -23, Blocks.SANDSTONE.getDefaultState());
        structure.fillWithBlocks(world, start, 1, -28, -11, 1, -28, -9, Blocks.DIRT.getDefaultState());
        structure.fillWithBlocks(world, start, 1, -28, 0, 1, -28, 16, Blocks.AIR.getDefaultState());
        structure.fillWithBlocks(world, start, 1, -28, 17, 1, -27, 18, Blocks.SANDSTONE.getDefaultState());
        structure.fillWithBlocks(world, start, 1, -27, -52, 1, -26, -52, Blocks.SANDSTONE.getDefaultState());
        structure.fillWithBlocks(world, start, 1, -27, -51, 1, -27, -51, Blocks.DIRT.getDefaultState());
        structure.fillWithBlocks(world, start, 1, -27, -3, 2, -27, -2, Blocks.SANDSTONE.getDefaultState());
        structure.fillWithBlocks(world, start, 1, -27, -1, 1, -21, -1, Blocks.SANDSTONE.getDefaultState());
        structure.fillWithBlocks(world, start, 1, -27, 0, 3, -27, 16, Blocks.AIR.getDefaultState());
        structure.fillWithBlocks(world, start, 1, -26, -45, 3, -25, -45, Blocks.SANDSTONE.getDefaultState());
        structure.fillWithBlocks(world, start, 1, -26, -44, 2, -26, -42, Blocks.AIR.getDefaultState());
        structure.fillWithBlocks(world, start, 1, -26, -41, 2, -25, -41, Blocks.SANDSTONE.getDefaultState());
        structure.fillWithBlocks(world, start, 1, -26, -40, 2, -26, -38, Blocks.AIR.getDefaultState());
        structure.fillWithBlocks(world, start, 1, -26, -37, 1, -25, -37, Blocks.AIR.getDefaultState());
        structure.fillWithBlocks(world, start, 1, -26, -35, 2, -26, -35, Blocks.SANDSTONE.getDefaultState());
        structure.fillWithBlocks(world, start, 1, -26, -34, 1, -26, -33, Blocks.DIRT.getDefaultState());
        structure.fillWithBlocks(world, start, 1, -26, -28, 5, -26, -24, Blocks.SANDSTONE.getDefaultState());
        structure.fillWithBlocks(world, start, 1, -26, -15, 1, -26, -14, Blocks.SANDSTONE.getDefaultState());
        structure.fillWithBlocks(world, start, 1, -26, -13, 1, -26, -13, Blocks.AIR.getDefaultState());
        structure.fillWithBlocks(world, start, 1, -26, -12, 1, -25, -4, Blocks.SANDSTONE.getDefaultState());
        structure.fillWithBlocks(world, start, 1, -26, -3, 2, -26, -3, Blocks.AIR.getDefaultState());
        structure.fillWithBlocks(world, start, 1, -26, 0, 3, -26, 16, Blocks.AIR.getDefaultState());
        structure.fillWithBlocks(world, start, 1, -26, 17, 2, -26, 18, Blocks.SANDSTONE.getDefaultState());
        structure.fillWithBlocks(world, start, 1, -25, -53, 1, -25, -53, Blocks.STONE_BRICKS.getDefaultState());
        structure.fillWithBlocks(world, start, 1, -25, -35, 1, -24, -35, Blocks.SANDSTONE.getDefaultState());
        structure.fillWithBlocks(world, start, 1, -25, -34, 1, -25, -34, Blocks.DIRT.getDefaultState());
        structure.fillWithBlocks(world, start, 1, -25, -33, 1, -21, -33, Blocks.SANDSTONE.getDefaultState());
        structure.fillWithBlocks(world, start, 1, -25, 16, 2, -25, 17, Blocks.SANDSTONE.getDefaultState());
        structure.fillWithBlocks(world, start, 1, -24, -53, 1, -24, -51, Blocks.SANDSTONE.getDefaultState());
        structure.fillWithBlocks(world, start, 1, -24, -47, 2, -24, -46, Blocks.SANDSTONE.getDefaultState());
        structure.fillWithBlocks(world, start, 1, -24, -44, 1, -24, -42, Blocks.SANDSTONE.getDefaultState());
        structure.fillWithBlocks(world, start, 1, -24, -41, 1, -23, -41, Blocks.STONE_BRICKS.getDefaultState());
        structure.fillWithBlocks(world, start, 1, -24, -39, 2, -24, -37, Blocks.SANDSTONE.getDefaultState());
        structure.fillWithBlocks(world, start, 1, -24, -15, 1, -23, -14, Blocks.SANDSTONE.getDefaultState());
        structure.fillWithBlocks(world, start, 1, -24, -12, 2, -24, -11, Blocks.SANDSTONE.getDefaultState());
        structure.fillWithBlocks(world, start, 1, -24, -3, 2, -24, -2, Blocks.SANDSTONE.getDefaultState());
        structure.fillWithBlocks(world, start, 1, -24, 0, 4, -24, 17, Blocks.SANDSTONE.getDefaultState());
        structure.fillWithBlocks(world, start, 1, -23, -53, 2, -23, -53, Blocks.SANDSTONE.getDefaultState());
        structure.fillWithBlocks(world, start, 1, -23, -52, 1, -21, -49, Blocks.STONE_BRICKS.getDefaultState());
        structure.fillWithBlocks(world, start, 1, -23, -44, 1, -22, -42, Blocks.STONE_BRICKS.getDefaultState());
        structure.fillWithBlocks(world, start, 1, -23, -40, 1, -23, -36, Blocks.SANDSTONE.getDefaultState());
        structure.fillWithBlocks(world, start, 1, -23, -34, 2, -23, -33, Blocks.SANDSTONE.getDefaultState());
        structure.fillWithBlocks(world, start, 1, -23, -12, 1, -23, -12, Blocks.SANDSTONE.getDefaultState());
        structure.fillWithBlocks(world, start, 1, -23, -10, 2, -23, -7, Blocks.SANDSTONE.getDefaultState());
        structure.fillWithBlocks(world, start, 1, -23, 0, 1, -23, 0, Blocks.SANDSTONE.getDefaultState());
        structure.fillWithBlocks(world, start, 1, -23, 1, 1, -23, 2, Blocks.DIRT.getDefaultState());
        structure.fillWithBlocks(world, start, 1, -23, 6, 1, -23, 6, Blocks.AIR.getDefaultState());
        structure.fillWithBlocks(world, start, 1, -23, 7, 1, -21, 7, Blocks.SANDSTONE.getDefaultState());
        structure.fillWithBlocks(world, start, 1, -23, 9, 1, -22, 16, Blocks.SANDSTONE.getDefaultState());
        structure.fillWithBlocks(world, start, 1, -23, 17, 1, -22, 17, Blocks.DIRT.getDefaultState());
        structure.fillWithBlocks(world, start, 1, -22, -47, 1, -22, -46, Blocks.SANDSTONE.getDefaultState());
        structure.fillWithBlocks(world, start, 1, -22, -40, 1, -22, -40, Blocks.STONE_BRICKS.getDefaultState());
        structure.fillWithBlocks(world, start, 1, -22, -39, 1, -21, -39, Blocks.AIR.getDefaultState());
        structure.fillWithBlocks(world, start, 1, -22, -38, 1, -21, -38, Blocks.SANDSTONE.getDefaultState());
        structure.fillWithBlocks(world, start, 1, -22, -36, 1, -21, -33, Blocks.SANDSTONE.getDefaultState());
        structure.fillWithBlocks(world, start, 1, -22, -15, 1, -18, -11, Blocks.SANDSTONE.getDefaultState());
        structure.fillWithBlocks(world, start, 1, -22, -10, 1, -22, -10, Blocks.SANDSTONE.getDefaultState());
        structure.fillWithBlocks(world, start, 1, -22, -7, 1, -22, -6, Blocks.SANDSTONE.getDefaultState());
        structure.fillWithBlocks(world, start, 1, -22, -5, 1, -22, -3, Blocks.DIRT.getDefaultState());
        structure.fillWithBlocks(world, start, 1, -22, -2, 1, -21, -1, Blocks.SANDSTONE.getDefaultState());
        structure.fillWithBlocks(world, start, 1, -22, 1, 1, -22, 1, Blocks.SANDSTONE.getDefaultState());
        structure.fillWithBlocks(world, start, 1, -22, 4, 2, -22, 10, Blocks.SANDSTONE.getDefaultState());
        structure.fillWithBlocks(world, start, 1, -21, -47, 1, -21, -43, Blocks.STONE_BRICKS.getDefaultState());
        structure.fillWithBlocks(world, start, 1, -21, -9, 2, -21, -8, Blocks.SANDSTONE.getDefaultState());
        structure.fillWithBlocks(world, start, 1, -21, -7, 1, -21, -6, Blocks.DIRT.getDefaultState());
        structure.fillWithBlocks(world, start, 1, -21, -5, 2, -21, -2, Blocks.SANDSTONE.getDefaultState());
        structure.fillWithBlocks(world, start, 1, -21, 6, 2, -21, 7, Blocks.SANDSTONE.getDefaultState());
        structure.fillWithBlocks(world, start, 1, -21, 9, 1, -21, 9, Blocks.SANDSTONE.getDefaultState());
        structure.fillWithBlocks(world, start, 1, -21, 12, 4, -21, 15, Blocks.SANDSTONE.getDefaultState());
        structure.fillWithBlocks(world, start, 1, -21, 16, 1, -21, 18, Blocks.SANDSTONE.getDefaultState());
        structure.fillWithBlocks(world, start, 1, -20, -32, 1, -20, -32, Blocks.SANDSTONE.getDefaultState());
        structure.fillWithBlocks(world, start, 1, -20, -30, 2, -20, -20, Blocks.SANDSTONE.getDefaultState());
        structure.fillWithBlocks(world, start, 1, -20, 34, 2, -19, 34, Blocks.SANDSTONE.getDefaultState());
        structure.fillWithBlocks(world, start, 1, -19, -7, 1, -19, -3, Blocks.SANDSTONE.getDefaultState());
        structure.fillWithBlocks(world, start, 1, -19, 22, 2, -19, 24, Blocks.SANDSTONE.getDefaultState());
        structure.fillWithBlocks(world, start, 1, -19, 26, 2, -19, 28, Blocks.SANDSTONE.getDefaultState());
        structure.fillWithBlocks(world, start, 1, -19, 29, 1, -19, 34, Blocks.SANDSTONE.getDefaultState());
        structure.fillWithBlocks(world, start, 1, -18, -29, 1, -17, -28, Blocks.SANDSTONE.getDefaultState());
        structure.fillWithBlocks(world, start, 1, -18, -7, 1, -18, -3, Blocks.SANDSTONE.getDefaultState());
        structure.fillWithBlocks(world, start, 1, -18, 22, 2, -18, 34, Blocks.SANDSTONE.getDefaultState());
        structure.fillWithBlocks(world, start, 1, -17, -7, 1, -17, -3, Blocks.SANDSTONE.getDefaultState());
        structure.fillWithBlocks(world, start, 1, -17, 22, 2, -17, 27, Blocks.SANDSTONE.getDefaultState());
        structure.fillWithBlocks(world, start, 1, -17, 28, 1, -17, 28, Blocks.AIR.getDefaultState());
        structure.fillWithBlocks(world, start, 1, -17, 29, 1, -11, 29, Blocks.SANDSTONE.getDefaultState());
        structure.fillWithBlocks(world, start, 1, -17, 31, 2, -17, 34, Blocks.SANDSTONE.getDefaultState());
        structure.fillWithBlocks(world, start, 1, -16, -28, 5, -16, -24, Blocks.SANDSTONE.getDefaultState());
        structure.fillWithBlocks(world, start, 1, -16, -21, 1, -16, -21, Blocks.AIR.getDefaultState());
        structure.fillWithBlocks(world, start, 1, -16, -20, 1, -11, -20, Blocks.SANDSTONE.getDefaultState());
        structure.fillWithBlocks(world, start, 1, -16, -11, 3, -16, -7, Blocks.SANDSTONE.getDefaultState());
        structure.fillWithBlocks(world, start, 1, -16, -4, 2, -16, -3, Blocks.SANDSTONE.getDefaultState());
        structure.fillWithBlocks(world, start, 1, -16, 22, 2, -16, 22, Blocks.AIR.getDefaultState());
        structure.fillWithBlocks(world, start, 1, -16, 23, 2, -16, 34, Blocks.SANDSTONE.getDefaultState());
        structure.fillWithBlocks(world, start, 1, -15, -31, 1, -13, -20, Blocks.SANDSTONE.getDefaultState());
        structure.fillWithBlocks(world, start, 1, -15, -15, 2, -15, -14, Blocks.SANDSTONE.getDefaultState());
        structure.fillWithBlocks(world, start, 1, -15, -11, 2, -15, -8, Blocks.SANDSTONE.getDefaultState());
        structure.fillWithBlocks(world, start, 1, -14, -5, 2, -14, -3, Blocks.SANDSTONE.getDefaultState());
        structure.fillWithBlocks(world, start, 1, -14, 28, 2, -14, 34, Blocks.SANDSTONE.getDefaultState());
        structure.fillWithBlocks(world, start, 1, -13, -4, 2, -13, -3, Blocks.SANDSTONE.getDefaultState());
        structure.fillWithBlocks(world, start, 1, -12, -27, 2, -12, -20, Blocks.SANDSTONE.getDefaultState());
        structure.fillWithBlocks(world, start, 1, -12, -13, 2, -12, -11, Blocks.SANDSTONE.getDefaultState());
        structure.fillWithBlocks(world, start, 1, -12, 28, 2, -12, 32, Blocks.SANDSTONE.getDefaultState());
        structure.fillWithBlocks(world, start, 1, -11, -32, 2, -11, -27, Blocks.SANDSTONE.getDefaultState());
        structure.fillWithBlocks(world, start, 1, -11, -25, 2, -11, -20, Blocks.SANDSTONE.getDefaultState());
        structure.fillWithBlocks(world, start, 1, -11, -15, 2, -11, -3, Blocks.SANDSTONE.getDefaultState());
        structure.fillWithBlocks(world, start, 1, -11, 27, 2, -11, 34, Blocks.SANDSTONE.getDefaultState());
        structure.fillWithBlocks(world, start, 1, -10, -11, 5, -10, -7, Blocks.SANDSTONE.getDefaultState());
        structure.fillWithBlocks(world, start, 1, -8, -12, 1, -7, -12, Blocks.STONE_BRICKS.getDefaultState());
        structure.fillWithBlocks(world, start, 1, -8, -6, 1, -7, -6, Blocks.STONE_BRICKS.getDefaultState());
        structure.fillWithBlocks(world, start, 1, 0, 18, 3, 0, 24, Blocks.SANDSTONE.getDefaultState());
        structure.fillWithBlocks(world, start, 2, -52, -15, 5, -52, 0, Blocks.SANDSTONE.getDefaultState());
        structure.fillWithBlocks(world, start, 2, -51, -20, 3, -51, 2, Blocks.SANDSTONE.getDefaultState());
        structure.fillWithBlocks(world, start, 2, -50, -11, 3, -50, -11, Blocks.SANDSTONE_STAIRS.getDefaultState().with(StairsBlock.FACING, Direction.SOUTH).with(StairsBlock.WATERLOGGED, false).with(StairsBlock.SHAPE, StairsShape.STRAIGHT).with(StairsBlock.HALF, Half.BOTTOM));
        structure.fillWithBlocks(world, start, 2, -50, -10, 4, -50, -8, Blocks.SANDSTONE.getDefaultState());
        structure.fillWithBlocks(world, start, 2, -50, -7, 3, -50, -7, Blocks.SANDSTONE_STAIRS.getDefaultState().with(StairsBlock.FACING, Direction.NORTH).with(StairsBlock.WATERLOGGED, false).with(StairsBlock.SHAPE, StairsShape.STRAIGHT).with(StairsBlock.HALF, Half.BOTTOM));
        structure.fillWithBlocks(world, start, 2, -50, 1, 3, -50, 2, Blocks.SANDSTONE.getDefaultState());
        structure.fillWithBlocks(world, start, 2, -50, 8, 8, -50, 28, Blocks.SANDSTONE.getDefaultState());
        structure.fillWithBlocks(world, start, 2, -49, -20, 2, -48, -19, Blocks.SANDSTONE.getDefaultState());
        structure.fillWithBlocks(world, start, 2, -49, -18, 3, -49, 0, Blocks.AIR.getDefaultState());
        structure.fillWithBlocks(world, start, 2, -49, 1, 2, -49, 2, Blocks.SANDSTONE.getDefaultState());
        structure.fillWithBlocks(world, start, 2, -49, 8, 5, -49, 11, Blocks.SANDSTONE.getDefaultState());
        structure.fillWithBlocks(world, start, 2, -49, 12, 4, -49, 35, Blocks.SANDSTONE.getDefaultState());
        structure.fillWithBlocks(world, start, 2, -48, -18, 3, -48, 0, Blocks.AIR.getDefaultState());
        structure.fillWithBlocks(world, start, 2, -48, 1, 2, -48, 2, Blocks.SANDSTONE.getDefaultState());
        structure.fillWithBlocks(world, start, 2, -48, 8, 5, -48, 11, Blocks.SANDSTONE.getDefaultState());
        structure.fillWithBlocks(world, start, 2, -48, 12, 4, -48, 17, Blocks.SANDSTONE.getDefaultState());
        structure.fillWithBlocks(world, start, 2, -48, 18, 3, -48, 24, Blocks.SANDSTONE.getDefaultState());
        structure.fillWithBlocks(world, start, 2, -48, 26, 4, -48, 35, Blocks.SANDSTONE.getDefaultState());
        structure.fillWithBlocks(world, start, 2, -47, -20, 2, -46, -19, Blocks.SANDSTONE.getDefaultState());
        structure.fillWithBlocks(world, start, 2, -47, -18, 3, -47, 0, Blocks.AIR.getDefaultState());
        structure.fillWithBlocks(world, start, 2, -47, 1, 2, -47, 2, Blocks.SANDSTONE.getDefaultState());
        structure.fillWithBlocks(world, start, 2, -47, 8, 5, -47, 11, Blocks.SANDSTONE.getDefaultState());
        structure.fillWithBlocks(world, start, 2, -47, 12, 4, -47, 35, Blocks.SANDSTONE.getDefaultState());
        structure.fillWithBlocks(world, start, 2, -46, 8, 7, -46, 13, Blocks.SANDSTONE.getDefaultState());
        structure.fillWithBlocks(world, start, 2, -46, 14, 4, -46, 35, Blocks.SANDSTONE.getDefaultState());
        structure.fillWithBlocks(world, start, 2, -45, -18, 2, -45, -18, Blocks.SANDSTONE.getDefaultState());
        structure.fillWithBlocks(world, start, 2, -45, -16, 4, -45, -14, Blocks.SANDSTONE.getDefaultState());
        structure.fillWithBlocks(world, start, 2, -45, -12, 4, -45, -10, Blocks.SANDSTONE.getDefaultState());
        structure.fillWithBlocks(world, start, 2, -45, -8, 4, -45, -6, Blocks.SANDSTONE.getDefaultState());
        structure.fillWithBlocks(world, start, 2, -45, -4, 4, -45, -2, Blocks.SANDSTONE.getDefaultState());
        structure.fillWithBlocks(world, start, 2, -45, 0, 3, -45, 1, Blocks.SANDSTONE.getDefaultState());
        structure.fillWithBlocks(world, start, 2, -45, 8, 8, -45, 14, Blocks.SANDSTONE.getDefaultState());
        structure.fillWithBlocks(world, start, 2, -44, -18, 4, -44, 1, Blocks.SANDSTONE.getDefaultState());
        structure.fillWithBlocks(world, start, 2, -44, 8, 8, -44, 14, Blocks.SANDSTONE.getDefaultState());
        structure.fillWithBlocks(world, start, 2, -43, 8, 8, -43, 14, Blocks.SANDSTONE.getDefaultState());
        structure.fillWithBlocks(world, start, 2, -42, 8, 22, -42, 28, Blocks.SANDSTONE.getDefaultState());
        structure.fillWithBlocks(world, start, 2, -42, 35, 3, -42, 36, Blocks.STONE_BRICKS.getDefaultState());
        structure.fillWithBlocks(world, start, 2, -42, 38, 2, -42, 38, Blocks.STONE_BRICKS.getDefaultState());
        structure.fillWithBlocks(world, start, 2, -41, -18, 4, -41, 1, Blocks.SANDSTONE.getDefaultState());
        structure.fillWithBlocks(world, start, 2, -41, 8, 10, -41, 28, Blocks.SANDSTONE.getDefaultState());
        structure.fillWithBlocks(world, start, 2, -41, 33, 3, -41, 36, Blocks.STONE_BRICKS.getDefaultState());
        structure.fillWithBlocks(world, start, 2, -40, -47, 5, -40, -44, Blocks.STONE_BRICKS.getDefaultState());
        structure.fillWithBlocks(world, start, 2, -40, -26, 3, -40, -26, Blocks.STONE_BRICKS.getDefaultState());
        structure.fillWithBlocks(world, start, 2, -40, -16, 3, -40, -15, Blocks.STONE_BRICKS.getDefaultState());
        structure.fillWithBlocks(world, start, 2, -40, -14, 2, -39, -14, Blocks.AIR.getDefaultState());
        structure.fillWithBlocks(world, start, 2, -40, -13, 2, -40, -13, Blocks.SANDSTONE.getDefaultState());
        structure.fillWithBlocks(world, start, 2, -40, -4, 4, -40, -2, Blocks.STONE_BRICKS.getDefaultState());
        structure.fillWithBlocks(world, start, 2, -40, 1, 2, -40, 1, Blocks.STONE_BRICKS.getDefaultState());
        structure.fillWithBlocks(world, start, 2, -40, 5, 6, -40, 20, Blocks.STONE_BRICKS.getDefaultState());
        structure.fillWithBlocks(world, start, 2, -40, 21, 2, -40, 22, Blocks.AIR.getDefaultState());
        structure.fillWithBlocks(world, start, 2, -40, 23, 3, -40, 25, Blocks.STONE_BRICKS.getDefaultState());
        structure.fillWithBlocks(world, start, 2, -40, 29, 3, -40, 30, Blocks.STONE_BRICKS.getDefaultState());
        structure.fillWithBlocks(world, start, 2, -40, 31, 2, -40, 43, Blocks.STONE_BRICKS.getDefaultState());
        structure.fillWithBlocks(world, start, 2, -39, -40, 2, -39, -40, Blocks.STONE_BRICKS.getDefaultState());
        structure.fillWithBlocks(world, start, 2, -39, -39, 2, -35, -35, Blocks.AIR.getDefaultState());
        structure.fillWithBlocks(world, start, 2, -39, -34, 3, -38, -34, Blocks.STONE_BRICKS.getDefaultState());
        structure.fillWithBlocks(world, start, 2, -39, -33, 5, -39, -29, Blocks.AIR.getDefaultState());
        structure.fillWithBlocks(world, start, 2, -39, -25, 2, -37, -25, Blocks.STONE_BRICKS.getDefaultState());
        structure.fillWithBlocks(world, start, 2, -39, -23, 2, -39, -19, Blocks.STONE_BRICKS.getDefaultState());
        structure.fillWithBlocks(world, start, 2, -39, -17, 2, -39, -15, Blocks.STONE_BRICKS.getDefaultState());
        structure.fillWithBlocks(world, start, 2, -39, -13, 2, -36, -13, Blocks.STONE_BRICKS.getDefaultState());
        structure.fillWithBlocks(world, start, 2, -39, -2, 2, -39, 10, Blocks.STONE_BRICKS.getDefaultState());
        structure.fillWithBlocks(world, start, 2, -39, 11, 7, -39, 16, Blocks.AIR.getDefaultState());
        structure.fillWithBlocks(world, start, 2, -39, 17, 2, -39, 17, Blocks.STONE_BRICKS.getDefaultState());
        structure.fillWithBlocks(world, start, 2, -39, 19, 3, -39, 23, Blocks.STONE_BRICKS.getDefaultState());
        structure.fillWithBlocks(world, start, 2, -39, 25, 2, -39, 27, Blocks.STONE_BRICKS.getDefaultState());
        structure.fillWithBlocks(world, start, 2, -39, 29, 4, -39, 31, Blocks.STONE_BRICKS.getDefaultState());
        structure.fillWithBlocks(world, start, 2, -38, -46, 2, -38, -46, Blocks.STONE_BRICKS.getDefaultState());
        structure.fillWithBlocks(world, start, 2, -38, -45, 2, -38, -44, Blocks.AIR.getDefaultState());
        structure.fillWithBlocks(world, start, 2, -38, -43, 5, -38, -40, Blocks.STONE_BRICKS.getDefaultState());
        structure.fillWithBlocks(world, start, 2, -38, -33, 6, -38, -29, Blocks.AIR.getDefaultState());
        structure.fillWithBlocks(world, start, 2, -38, -23, 5, -38, -23, Blocks.STONE_BRICKS.getDefaultState());
        structure.fillWithBlocks(world, start, 2, -38, -22, 4, -38, -22, Blocks.SHROOMLIGHT.getDefaultState());
        structure.fillWithBlocks(world, start, 2, -38, -21, 5, -37, -21, Blocks.STONE_BRICKS.getDefaultState());
        structure.fillWithBlocks(world, start, 2, -38, -19, 2, -37, -19, Blocks.STONE_BRICKS.getDefaultState());
        structure.fillWithBlocks(world, start, 2, -38, -17, 2, -37, -17, Blocks.STONE_BRICKS.getDefaultState());
        structure.fillWithBlocks(world, start, 2, -38, -15, 2, -36, -13, Blocks.STONE_BRICKS.getDefaultState());
        structure.fillWithBlocks(world, start, 2, -38, -2, 6, -34, -2, Blocks.STONE_BRICKS.getDefaultState());
        structure.fillWithBlocks(world, start, 2, -38, 0, 2, -36, 0, Blocks.STONE_BRICKS.getDefaultState());
        structure.fillWithBlocks(world, start, 2, -38, 2, 3, -38, 4, Blocks.STONE_BRICKS.getDefaultState());
        structure.fillWithBlocks(world, start, 2, -38, 6, 3, -38, 9, Blocks.STONE_BRICKS.getDefaultState());
        structure.fillWithBlocks(world, start, 2, -38, 10, 2, -35, 10, Blocks.STONE_BRICKS.getDefaultState());
        structure.fillWithBlocks(world, start, 2, -38, 11, 7, -38, 16, Blocks.AIR.getDefaultState());
        structure.fillWithBlocks(world, start, 2, -38, 17, 3, -38, 19, Blocks.STONE_BRICKS.getDefaultState());
        structure.fillWithBlocks(world, start, 2, -38, 20, 2, -37, 20, Blocks.AIR.getDefaultState());
        structure.fillWithBlocks(world, start, 2, -38, 21, 2, -38, 21, Blocks.STONE_BRICKS.getDefaultState());
        structure.fillWithBlocks(world, start, 2, -38, 23, 2, -38, 25, Blocks.STONE_BRICKS.getDefaultState());
        structure.fillWithBlocks(world, start, 2, -38, 27, 2, -37, 27, Blocks.STONE_BRICKS.getDefaultState());
        structure.fillWithBlocks(world, start, 2, -38, 29, 5, -38, 32, Blocks.STONE_BRICKS.getDefaultState());
        structure.fillWithBlocks(world, start, 2, -37, -46, 5, -37, -41, Blocks.STONE_BRICKS.getDefaultState());
        structure.fillWithBlocks(world, start, 2, -37, -34, 9, -34, -34, Blocks.STONE_BRICKS.getDefaultState());
        structure.fillWithBlocks(world, start, 2, -37, -33, 6, -37, -29, Blocks.AIR.getDefaultState());
        structure.fillWithBlocks(world, start, 2, -37, -23, 2, -36, -21, Blocks.STONE_BRICKS.getDefaultState());
        structure.fillWithBlocks(world, start, 2, -37, -16, 4, -37, -14, Blocks.STONE_BRICKS.getDefaultState());
        structure.fillWithBlocks(world, start, 2, -37, -1, 2, -36, 1, Blocks.STONE_BRICKS.getDefaultState());
        structure.fillWithBlocks(world, start, 2, -37, 2, 2, -37, 10, Blocks.STONE_BRICKS.getDefaultState());
        structure.fillWithBlocks(world, start, 2, -37, 11, 7, -37, 16, Blocks.AIR.getDefaultState());
        structure.fillWithBlocks(world, start, 2, -37, 19, 2, -37, 19, Blocks.STONE_BRICKS.getDefaultState());
        structure.fillWithBlocks(world, start, 2, -37, 21, 4, -37, 25, Blocks.STONE_BRICKS.getDefaultState());
        structure.fillWithBlocks(world, start, 2, -37, 26, 2, -37, 27, Blocks.STONE_BRICKS.getDefaultState());
        structure.fillWithBlocks(world, start, 2, -37, 29, 3, -37, 32, Blocks.STONE_BRICKS.getDefaultState());
        structure.fillWithBlocks(world, start, 2, -36, -46, 2, -36, -42, Blocks.STONE_BRICKS.getDefaultState());
