package mod.arcalitegames.odyssey.world.structure.structures.dungeons.desert_pyramid;

import mod.arcalitegames.odyssey.world.structure.StructureBase;
import net.minecraft.block.Blocks;
import net.minecraft.block.FourWayBlock;
import net.minecraft.block.RedstoneWireBlock;
import net.minecraft.state.properties.RedstoneSide;
import net.minecraft.util.math.BlockPos;
import net.minecraft.world.World;

public class PyramidComponent3
{

	public static BlockPos start;
    public static World world;
    public static StructureBase structure;

    public static void init(World worldIn, BlockPos blockPos, StructureBase structureIn)
    {
        world = worldIn; start = blockPos; structure = structureIn;
    }
    
    public static void generatePart31()
    {
        structure.fillWithBlocks(world, start, 29, -36, 19, 29, -36, 19, Blocks.STONE_BRICKS.getDefaultState());
        structure.fillWithBlocks(world, start, 29, -36, 25, 29, -35, 26, Blocks.STONE_BRICKS.getDefaultState());
        structure.fillWithBlocks(world, start, 29, -35, -57, 29, -34, -48, Blocks.STONE_BRICKS.getDefaultState());
        structure.fillWithBlocks(world, start, 29, -35, -47, 29, -35, -35, Blocks.STONE_BRICKS.getDefaultState());
        structure.fillWithBlocks(world, start, 29, -35, -11, 30, -35, -5, Blocks.SANDSTONE.getDefaultState());
        structure.fillWithBlocks(world, start, 29, -35, 14, 33, -35, 18, Blocks.STONE_BRICKS.getDefaultState());
        structure.fillWithBlocks(world, start, 29, -35, 19, 29, -35, 19, Blocks.STONE_BRICKS.getDefaultState());
        structure.fillWithBlocks(world, start, 29, -35, 28, 31, -35, 34, Blocks.STONE_BRICKS.getDefaultState());
        structure.fillWithBlocks(world, start, 29, -34, -47, 29, -34, -46, Blocks.AIR.getDefaultState());
        structure.fillWithBlocks(world, start, 29, -34, -45, 31, -34, -43, Blocks.STONE_BRICKS.getDefaultState());
        structure.fillWithBlocks(world, start, 29, -34, -42, 30, -34, -37, Blocks.STONE_BRICKS.getDefaultState());
        structure.fillWithBlocks(world, start, 29, -34, -15, 30, -34, -14, Blocks.STONE_BRICKS.getDefaultState());
        structure.fillWithBlocks(world, start, 29, -34, 15, 29, -34, 27, Blocks.STONE_BRICKS.getDefaultState());
        structure.fillWithBlocks(world, start, 29, -33, -57, 29, -33, -57, Blocks.AIR.getDefaultState());
        structure.fillWithBlocks(world, start, 29, -33, -56, 29, -33, -48, Blocks.STONE_BRICKS.getDefaultState());
        structure.fillWithBlocks(world, start, 29, -33, -46, 30, -33, -43, Blocks.STONE_BRICKS.getDefaultState());
        structure.fillWithBlocks(world, start, 29, -33, -36, 30, -33, -35, Blocks.STONE_BRICKS.getDefaultState());
        structure.fillWithBlocks(world, start, 29, -33, -13, 31, -33, -11, Blocks.STONE_BRICKS.getDefaultState());
        structure.fillWithBlocks(world, start, 29, -33, -10, 29, -33, -9, Blocks.AIR.getDefaultState());
        structure.fillWithBlocks(world, start, 29, -33, -8, 30, -33, -3, Blocks.STONE_BRICKS.getDefaultState());
        structure.fillWithBlocks(world, start, 29, -33, 10, 29, -33, 10, Blocks.STONE_BRICKS.getDefaultState());
        structure.fillWithBlocks(world, start, 29, -33, 11, 29, -32, 11, Blocks.AIR.getDefaultState());
        structure.fillWithBlocks(world, start, 29, -33, 12, 29, -33, 12, Blocks.STONE_BRICKS.getDefaultState());
        structure.fillWithBlocks(world, start, 29, -33, 14, 29, -31, 19, Blocks.STONE_BRICKS.getDefaultState());
        structure.fillWithBlocks(world, start, 29, -33, 30, 31, -33, 34, Blocks.STONE_BRICKS.getDefaultState());
        structure.fillWithBlocks(world, start, 29, -32, -46, 29, -32, -46, Blocks.STONE_BRICKS.getDefaultState());
        structure.fillWithBlocks(world, start, 29, -32, -44, 30, -32, -35, Blocks.STONE_BRICKS.getDefaultState());
        structure.fillWithBlocks(world, start, 29, -32, -15, 30, -32, -7, Blocks.STONE_BRICKS.getDefaultState());
        structure.fillWithBlocks(world, start, 29, -32, 10, 29, -32, 10, Blocks.STONE_BRICKS.getDefaultState());
        structure.fillWithBlocks(world, start, 29, -32, 12, 30, -32, 14, Blocks.STONE_BRICKS.getDefaultState());
        structure.fillWithBlocks(world, start, 29, -32, 21, 29, -31, 34, Blocks.STONE_BRICKS.getDefaultState());
        structure.fillWithBlocks(world, start, 29, -31, -57, 34, -31, -43, Blocks.STONE_BRICKS.getDefaultState());
        structure.fillWithBlocks(world, start, 29, -31, -6, 31, -31, -3, Blocks.STONE_BRICKS.getDefaultState());
        structure.fillWithBlocks(world, start, 29, -21, -28, 29, -20, -27, Blocks.SANDSTONE.getDefaultState());
        structure.fillWithBlocks(world, start, 29, -21, -25, 29, -20, -24, Blocks.SANDSTONE.getDefaultState());
        structure.fillWithBlocks(world, start, 29, -20, -31, 33, -20, -27, Blocks.SANDSTONE.getDefaultState());
        structure.fillWithBlocks(world, start, 29, -20, -22, 30, -20, -21, Blocks.SANDSTONE.getDefaultState());
        structure.fillWithBlocks(world, start, 29, -20, -20, 29, -19, -20, Blocks.AIR.getDefaultState());
        structure.fillWithBlocks(world, start, 29, -19, -29, 30, -19, -23, Blocks.AIR.getDefaultState());
        structure.fillWithBlocks(world, start, 29, -19, -12, 31, -19, -12, Blocks.STONE_BRICKS.getDefaultState());
        structure.fillWithBlocks(world, start, 29, -19, -11, 31, -19, -7, Blocks.AIR.getDefaultState());
        structure.fillWithBlocks(world, start, 29, -19, -6, 31, -19, -6, Blocks.STONE_BRICKS.getDefaultState());
        structure.fillWithBlocks(world, start, 29, -19, 22, 31, -19, 22, Blocks.STONE_BRICKS.getDefaultState());
        structure.fillWithBlocks(world, start, 29, -19, 23, 31, -19, 27, Blocks.AIR.getDefaultState());
        structure.fillWithBlocks(world, start, 29, -19, 28, 31, -19, 28, Blocks.STONE_BRICKS.getDefaultState());
        structure.fillWithBlocks(world, start, 29, -18, -32, 29, -18, -30, Blocks.SANDSTONE.getDefaultState());
        structure.fillWithBlocks(world, start, 29, -18, -29, 30, -18, -23, Blocks.AIR.getDefaultState());
        structure.fillWithBlocks(world, start, 29, -18, -22, 31, -18, -20, Blocks.SANDSTONE.getDefaultState());
        structure.fillWithBlocks(world, start, 29, -18, -12, 29, -17, -12, Blocks.STONE_BRICKS.getDefaultState());
        structure.fillWithBlocks(world, start, 29, -18, -11, 31, -18, -7, Blocks.AIR.getDefaultState());
        structure.fillWithBlocks(world, start, 29, -18, -6, 29, -17, -6, Blocks.STONE_BRICKS.getDefaultState());
        structure.fillWithBlocks(world, start, 29, -18, 22, 29, -17, 22, Blocks.STONE_BRICKS.getDefaultState());
        structure.fillWithBlocks(world, start, 29, -18, 23, 31, -18, 27, Blocks.AIR.getDefaultState());
        structure.fillWithBlocks(world, start, 29, -18, 28, 29, -17, 28, Blocks.STONE_BRICKS.getDefaultState());
        structure.fillWithBlocks(world, start, 29, -17, -11, 31, -17, -7, Blocks.AIR.getDefaultState());
        structure.fillWithBlocks(world, start, 29, -17, 23, 31, -17, 27, Blocks.AIR.getDefaultState());
        structure.fillWithBlocks(world, start, 29, -16, -32, 31, -16, -30, Blocks.SANDSTONE.getDefaultState());
        structure.fillWithBlocks(world, start, 29, -15, -23, 30, -15, -22, Blocks.SANDSTONE.getDefaultState());
        structure.fillWithBlocks(world, start, 29, -15, -20, 34, -12, -20, Blocks.SANDSTONE.getDefaultState());
        structure.fillWithBlocks(world, start, 29, -14, -27, 30, -14, -23, Blocks.SANDSTONE.getDefaultState());
        structure.fillWithBlocks(world, start, 29, -14, -22, 29, -13, -22, Blocks.AIR.getDefaultState());
        structure.fillWithBlocks(world, start, 29, -14, -21, 30, -14, -20, Blocks.SANDSTONE.getDefaultState());
        structure.fillWithBlocks(world, start, 29, -13, -32, 32, -13, -29, Blocks.SANDSTONE.getDefaultState());
        structure.fillWithBlocks(world, start, 29, -12, -32, 33, -12, -24, Blocks.SANDSTONE.getDefaultState());
        structure.fillWithBlocks(world, start, 29, -12, -22, 30, -12, -20, Blocks.SANDSTONE.getDefaultState());
        structure.fillWithBlocks(world, start, 29, -11, -30, 29, -11, -20, Blocks.SANDSTONE.getDefaultState());
        structure.fillWithBlocks(world, start, 29, -9, -28, 31, -9, -28, Blocks.STONE_BRICKS.getDefaultState());
        structure.fillWithBlocks(world, start, 29, -9, -27, 31, -9, -23, Blocks.AIR.getDefaultState());
        structure.fillWithBlocks(world, start, 29, -9, -22, 31, -9, -22, Blocks.STONE_BRICKS.getDefaultState());
        structure.fillWithBlocks(world, start, 29, -9, -14, 30, -9, -13, Blocks.SANDSTONE.getDefaultState());
        structure.fillWithBlocks(world, start, 29, -9, -12, 31, -9, -12, Blocks.STONE_BRICKS.getDefaultState());
        structure.fillWithBlocks(world, start, 29, -9, -11, 31, -9, -7, Blocks.AIR.getDefaultState());
        structure.fillWithBlocks(world, start, 29, -9, -5, 30, -9, -4, Blocks.SANDSTONE.getDefaultState());
        structure.fillWithBlocks(world, start, 29, -9, 18, 31, -9, 18, Blocks.STONE_BRICKS.getDefaultState());
        structure.fillWithBlocks(world, start, 29, -9, 19, 30, -9, 20, Blocks.AIR.getDefaultState());
        structure.fillWithBlocks(world, start, 29, -9, 21, 29, -9, 23, Blocks.AIR.getDefaultState());
        structure.fillWithBlocks(world, start, 29, -9, 24, 31, -9, 24, Blocks.STONE_BRICKS.getDefaultState());
        structure.fillWithBlocks(world, start, 29, -8, -28, 29, -7, -28, Blocks.STONE_BRICKS.getDefaultState());
        structure.fillWithBlocks(world, start, 29, -8, -27, 31, -8, -23, Blocks.AIR.getDefaultState());
        structure.fillWithBlocks(world, start, 29, -8, -22, 29, -7, -22, Blocks.STONE_BRICKS.getDefaultState());
        structure.fillWithBlocks(world, start, 29, -8, -14, 29, -7, -13, Blocks.SANDSTONE.getDefaultState());
        structure.fillWithBlocks(world, start, 29, -8, -12, 29, -7, -12, Blocks.STONE_BRICKS.getDefaultState());
        structure.fillWithBlocks(world, start, 29, -8, -11, 31, -8, -7, Blocks.AIR.getDefaultState());
        structure.fillWithBlocks(world, start, 29, -8, -5, 29, -8, -4, Blocks.SANDSTONE.getDefaultState());
        structure.fillWithBlocks(world, start, 29, -8, 18, 29, -7, 18, Blocks.STONE_BRICKS.getDefaultState());
        structure.fillWithBlocks(world, start, 29, -8, 19, 31, -8, 23, Blocks.AIR.getDefaultState());
        structure.fillWithBlocks(world, start, 29, -8, 24, 29, -7, 24, Blocks.STONE_BRICKS.getDefaultState());
        structure.fillWithBlocks(world, start, 29, -7, -27, 31, -7, -23, Blocks.AIR.getDefaultState());
        structure.fillWithBlocks(world, start, 29, -7, -11, 31, -7, -7, Blocks.AIR.getDefaultState());
        structure.fillWithBlocks(world, start, 29, -7, -5, 30, -7, -4, Blocks.SANDSTONE.getDefaultState());
        structure.fillWithBlocks(world, start, 29, -7, 19, 31, -7, 23, Blocks.AIR.getDefaultState());
        structure.fillWithBlocks(world, start, 29, -6, -14, 29, -5, -11, Blocks.SANDSTONE.getDefaultState());
        structure.fillWithBlocks(world, start, 29, -6, -10, 31, -6, -8, Blocks.AIR.getDefaultState());
        structure.fillWithBlocks(world, start, 29, -6, -7, 30, -6, -6, Blocks.SANDSTONE.getDefaultState());
        structure.fillWithBlocks(world, start, 29, -6, -5, 29, -6, -4, Blocks.SANDSTONE.getDefaultState());
        structure.fillWithBlocks(world, start, 29, -5, -10, 29, -5, -8, Blocks.STONE_BRICKS.getDefaultState());
        structure.fillWithBlocks(world, start, 29, -5, -7, 31, -5, -4, Blocks.SANDSTONE.getDefaultState());
        structure.fillWithBlocks(world, start, 29, -4, -13, 30, -4, -13, Blocks.AIR.getDefaultState());
        structure.fillWithBlocks(world, start, 29, -4, -12, 29, -4, -4, Blocks.SANDSTONE.getDefaultState());
        structure.fillWithBlocks(world, start, 29, -3, -14, 29, -3, -14, Blocks.AIR.getDefaultState());
        structure.fillWithBlocks(world, start, 29, -3, -13, 29, -3, -13, Blocks.SANDSTONE.getDefaultState());
        structure.fillWithBlocks(world, start, 29, -3, -12, 29, -3, -12, Blocks.AIR.getDefaultState());
        structure.fillWithBlocks(world, start, 29, -3, -11, 29, -3, -6, Blocks.SANDSTONE.getDefaultState());
        structure.fillWithBlocks(world, start, 29, -3, -5, 30, -3, -5, Blocks.AIR.getDefaultState());
        structure.fillWithBlocks(world, start, 29, -3, -4, 31, -3, -4, Blocks.SANDSTONE.getDefaultState());
        structure.fillWithBlocks(world, start, 29, 0, 3, 30, 0, 5, Blocks.SANDSTONE.getDefaultState());
        structure.fillWithBlocks(world, start, 29, 0, 6, 30, 0, 35, Blocks.STONE.getDefaultState());
        structure.fillWithBlocks(world, start, 29, 1, 4, 30, 1, 5, Blocks.SAND.getDefaultState());
        structure.fillWithBlocks(world, start, 29, 1, 23, 35, 1, 30, Blocks.STONE.getDefaultState());
        structure.fillWithBlocks(world, start, 29, 2, 28, 32, 2, 32, Blocks.STONE.getDefaultState());
        structure.fillWithBlocks(world, start, 29, 3, 32, 32, 3, 35, Blocks.SAND.getDefaultState());
        structure.fillWithBlocks(world, start, 29, 3, 36, 30, 3, 37, Blocks.SAND.getDefaultState());
        structure.fillWithBlocks(world, start, 29, 4, 8, 31, 4, 10, Blocks.SAND.getDefaultState());
        structure.fillWithBlocks(world, start, 29, 6, 11, 31, 6, 31, Blocks.SANDSTONE.getDefaultState());
        structure.fillWithBlocks(world, start, 29, 8, 28, 29, 8, 28, Blocks.SANDSTONE.getDefaultState());
        structure.fillWithBlocks(world, start, 29, 9, 14, 29, 9, 28, Blocks.SANDSTONE.getDefaultState());
        structure.fillWithBlocks(world, start, 29, 9, 31, 29, 10, 31, Blocks.ORANGE_TERRACOTTA.getDefaultState());
        structure.fillWithBlocks(world, start, 29, 10, 20, 30, 10, 26, Blocks.SANDSTONE.getDefaultState());
        structure.fillWithBlocks(world, start, 29, 11, 20, 30, 11, 25, Blocks.SANDSTONE.getDefaultState());
        structure.fillWithBlocks(world, start, 29, 14, 27, 31, 16, 27, Blocks.SANDSTONE.getDefaultState());
        structure.fillWithBlocks(world, start, 29, 14, 31, 30, 14, 31, Blocks.ORANGE_TERRACOTTA.getDefaultState());
        structure.fillWithBlocks(world, start, 30, -52, -67, 30, -50, -60, Blocks.SANDSTONE.getDefaultState());
        structure.fillWithBlocks(world, start, 30, -52, -43, 30, -50, -36, Blocks.SANDSTONE.getDefaultState());
        structure.fillWithBlocks(world, start, 30, -51, -53, 30, -49, -51, Blocks.STONE_BRICKS.getDefaultState());
        structure.fillWithBlocks(world, start, 30, -50, -74, 37, -50, -61, Blocks.SANDSTONE.getDefaultState());
        structure.fillWithBlocks(world, start, 30, -50, -50, 36, -50, -27, Blocks.SANDSTONE.getDefaultState());
        structure.fillWithBlocks(world, start, 30, -49, -43, 32, -49, -36, Blocks.AIR.getDefaultState());
        structure.fillWithBlocks(world, start, 30, -49, -27, 31, -49, -26, Blocks.SANDSTONE.getDefaultState());
        structure.fillWithBlocks(world, start, 30, -49, -15, 32, -49, -12, Blocks.SANDSTONE.getDefaultState());
        structure.fillWithBlocks(world, start, 30, -49, -11, 31, -48, -11, Blocks.SANDSTONE.getDefaultState());
        structure.fillWithBlocks(world, start, 30, -49, -10, 30, -47, -10, Blocks.IRON_BARS.getDefaultState().with(FourWayBlock.WATERLOGGED, false).with(FourWayBlock.NORTH, true).with(FourWayBlock.SOUTH, true).with(FourWayBlock.EAST, true).with(FourWayBlock.WEST, true));
        structure.fillWithBlocks(world, start, 30, -49, -9, 30, -49, -9, Blocks.AIR.getDefaultState());
        structure.fillWithBlocks(world, start, 30, -49, -8, 30, -47, -8, Blocks.IRON_BARS.getDefaultState().with(FourWayBlock.WATERLOGGED, false).with(FourWayBlock.NORTH, true).with(FourWayBlock.SOUTH, true).with(FourWayBlock.EAST, true).with(FourWayBlock.WEST, true));
        structure.fillWithBlocks(world, start, 30, -49, -7, 31, -49, -3, Blocks.SANDSTONE.getDefaultState());
        structure.fillWithBlocks(world, start, 30, -48, -53, 30, -46, -51, Blocks.STONE_BRICKS.getDefaultState());
        structure.fillWithBlocks(world, start, 30, -48, -27, 31, -48, -26, Blocks.SANDSTONE.getDefaultState());
        structure.fillWithBlocks(world, start, 30, -48, -9, 30, -48, -9, Blocks.AIR.getDefaultState());
        structure.fillWithBlocks(world, start, 30, -48, -7, 31, -48, -3, Blocks.SANDSTONE.getDefaultState());
        structure.fillWithBlocks(world, start, 30, -47, -27, 31, -47, -26, Blocks.SANDSTONE.getDefaultState());
        structure.fillWithBlocks(world, start, 30, -47, -15, 32, -47, -12, Blocks.SANDSTONE.getDefaultState());
        structure.fillWithBlocks(world, start, 30, -47, -11, 31, -46, -11, Blocks.SANDSTONE.getDefaultState());
        structure.fillWithBlocks(world, start, 30, -47, -9, 30, -47, -8, Blocks.IRON_BARS.getDefaultState().with(FourWayBlock.WATERLOGGED, false).with(FourWayBlock.NORTH, true).with(FourWayBlock.SOUTH, true).with(FourWayBlock.EAST, true).with(FourWayBlock.WEST, true));
        structure.fillWithBlocks(world, start, 30, -47, -7, 31, -47, -3, Blocks.SANDSTONE.getDefaultState());
        structure.fillWithBlocks(world, start, 30, -47, 15, 31, -47, 15, Blocks.SANDSTONE.getDefaultState());
        structure.fillWithBlocks(world, start, 30, -46, -56, 32, -46, -54, Blocks.SANDSTONE.getDefaultState());
        structure.fillWithBlocks(world, start, 30, -46, -50, 32, -46, -48, Blocks.SANDSTONE.getDefaultState());
        structure.fillWithBlocks(world, start, 30, -46, -10, 33, -46, -7, Blocks.SANDSTONE.getDefaultState());
        structure.fillWithBlocks(world, start, 30, -45, -70, 32, -45, -68, Blocks.SANDSTONE.getDefaultState());
        structure.fillWithBlocks(world, start, 30, -45, -67, 32, -45, -61, Blocks.AIR.getDefaultState());
        structure.fillWithBlocks(world, start, 30, -45, -60, 36, -45, -54, Blocks.SANDSTONE.getDefaultState());
        structure.fillWithBlocks(world, start, 30, -45, -46, 32, -45, -44, Blocks.SANDSTONE.getDefaultState());
        structure.fillWithBlocks(world, start, 30, -45, -43, 32, -45, -37, Blocks.AIR.getDefaultState());
        structure.fillWithBlocks(world, start, 30, -45, -36, 36, -45, -30, Blocks.SANDSTONE.getDefaultState());
        structure.fillWithBlocks(world, start, 30, -45, -15, 32, -45, -3, Blocks.SANDSTONE.getDefaultState());
        structure.fillWithBlocks(world, start, 30, -44, -70, 32, -44, -68, Blocks.SANDSTONE.getDefaultState());
        structure.fillWithBlocks(world, start, 30, -44, -67, 32, -44, -61, Blocks.AIR.getDefaultState());
        structure.fillWithBlocks(world, start, 30, -44, -60, 36, -44, -54, Blocks.SANDSTONE.getDefaultState());
        structure.fillWithBlocks(world, start, 30, -44, -46, 32, -44, -44, Blocks.SANDSTONE.getDefaultState());
        structure.fillWithBlocks(world, start, 30, -44, -43, 32, -44, -37, Blocks.AIR.getDefaultState());
        structure.fillWithBlocks(world, start, 30, -44, -36, 36, -44, -30, Blocks.SANDSTONE.getDefaultState());
        structure.fillWithBlocks(world, start, 30, -44, -15, 32, -44, -3, Blocks.SANDSTONE.getDefaultState());
        structure.fillWithBlocks(world, start, 30, -43, -69, 31, -43, -68, Blocks.SANDSTONE.getDefaultState());
        structure.fillWithBlocks(world, start, 30, -43, -67, 31, -43, -61, Blocks.AIR.getDefaultState());
        structure.fillWithBlocks(world, start, 30, -43, -60, 36, -43, -54, Blocks.SANDSTONE.getDefaultState());
        structure.fillWithBlocks(world, start, 30, -43, -45, 31, -43, -44, Blocks.SANDSTONE.getDefaultState());
        structure.fillWithBlocks(world, start, 30, -43, -43, 31, -43, -37, Blocks.AIR.getDefaultState());
        structure.fillWithBlocks(world, start, 30, -43, -36, 36, -43, -30, Blocks.SANDSTONE.getDefaultState());
        structure.fillWithBlocks(world, start, 30, -43, -15, 32, -43, -3, Blocks.SANDSTONE.getDefaultState());
        structure.fillWithBlocks(world, start, 30, -42, -12, 32, -42, -10, Blocks.SANDSTONE.getDefaultState());
        structure.fillWithBlocks(world, start, 30, -42, -8, 32, -42, -3, Blocks.SANDSTONE.getDefaultState());
        structure.fillWithBlocks(world, start, 30, -41, -54, 31, -41, -45, Blocks.STONE_BRICKS.getDefaultState());
        structure.fillWithBlocks(world, start, 30, -41, -44, 36, -41, -30, Blocks.SANDSTONE.getDefaultState());
        structure.fillWithBlocks(world, start, 30, -41, -15, 32, -41, -3, Blocks.SANDSTONE.getDefaultState());
        structure.fillWithBlocks(world, start, 30, -40, -59, 31, -40, -58, Blocks.STONE_BRICKS.getDefaultState());
        structure.fillWithBlocks(world, start, 30, -40, -57, 32, -40, -55, Blocks.AIR.getDefaultState());
        structure.fillWithBlocks(world, start, 30, -40, -54, 30, -40, -45, Blocks.AIR.getDefaultState());
        structure.fillWithBlocks(world, start, 30, -40, -44, 31, -40, -43, Blocks.STONE_BRICKS.getDefaultState());
        structure.fillWithBlocks(world, start, 30, -40, -42, 30, -33, -35, Blocks.STONE_BRICKS.getDefaultState());
        structure.fillWithBlocks(world, start, 30, -40, 25, 32, -40, 27, Blocks.STONE_BRICKS.getDefaultState());
        structure.fillWithBlocks(world, start, 30, -40, 30, 30, -40, 30, Blocks.STONE_BRICKS.getDefaultState());
        structure.fillWithBlocks(world, start, 30, -40, 32, 30, -40, 32, Blocks.STONE_BRICKS.getDefaultState());
        structure.fillWithBlocks(world, start, 30, -39, -58, 32, -39, -58, Blocks.IRON_BARS.getDefaultState().with(FourWayBlock.WATERLOGGED, false).with(FourWayBlock.NORTH, true).with(FourWayBlock.SOUTH, true).with(FourWayBlock.EAST, true).with(FourWayBlock.WEST, true));
        structure.fillWithBlocks(world, start, 30, -39, -54, 32, -39, -45, Blocks.AIR.getDefaultState());
        structure.fillWithBlocks(world, start, 30, -39, -44, 32, -39, -44, Blocks.IRON_BARS.getDefaultState().with(FourWayBlock.WATERLOGGED, false).with(FourWayBlock.NORTH, true).with(FourWayBlock.SOUTH, true).with(FourWayBlock.EAST, true).with(FourWayBlock.WEST, true));
        structure.fillWithBlocks(world, start, 30, -39, -15, 31, -39, -14, Blocks.STONE_BRICKS.getDefaultState());
        structure.fillWithBlocks(world, start, 30, -39, -11, 30, -34, -11, Blocks.SANDSTONE.getDefaultState());
        structure.fillWithBlocks(world, start, 30, -39, -10, 32, -39, -8, Blocks.AIR.getDefaultState());
        structure.fillWithBlocks(world, start, 30, -39, -7, 30, -37, -5, Blocks.SANDSTONE.getDefaultState());
        structure.fillWithBlocks(world, start, 30, -39, -4, 31, -39, -3, Blocks.STONE_BRICKS.getDefaultState());
        structure.fillWithBlocks(world, start, 30, -39, 10, 31, -39, 11, Blocks.STONE_BRICKS.getDefaultState());
        structure.fillWithBlocks(world, start, 30, -39, 18, 31, -39, 20, Blocks.STONE_BRICKS.getDefaultState());
        structure.fillWithBlocks(world, start, 30, -39, 21, 30, -39, 34, Blocks.STONE_BRICKS.getDefaultState());
        structure.fillWithBlocks(world, start, 30, -38, -58, 32, -38, -44, Blocks.AIR.getDefaultState());
        structure.fillWithBlocks(world, start, 30, -38, -43, 30, -32, -35, Blocks.STONE_BRICKS.getDefaultState());
        structure.fillWithBlocks(world, start, 30, -38, -10, 32, -38, -8, Blocks.AIR.getDefaultState());
        structure.fillWithBlocks(world, start, 30, -38, -4, 31, -38, -3, Blocks.STONE_BRICKS.getDefaultState());
        structure.fillWithBlocks(world, start, 30, -38, 10, 30, -38, 11, Blocks.STONE_BRICKS.getDefaultState());
        structure.fillWithBlocks(world, start, 30, -38, 18, 31, -38, 19, Blocks.STONE_BRICKS.getDefaultState());
        structure.fillWithBlocks(world, start, 30, -38, 20, 30, -37, 21, Blocks.STONE_BRICKS.getDefaultState());
        structure.fillWithBlocks(world, start, 30, -38, 23, 30, -38, 34, Blocks.STONE_BRICKS.getDefaultState());
        structure.fillWithBlocks(world, start, 30, -37, -58, 32, -37, -44, Blocks.AIR.getDefaultState());
        structure.fillWithBlocks(world, start, 30, -37, -15, 31, -37, -14, Blocks.STONE_BRICKS.getDefaultState());
        structure.fillWithBlocks(world, start, 30, -37, -10, 32, -37, -8, Blocks.AIR.getDefaultState());
        structure.fillWithBlocks(world, start, 30, -37, 10, 31, -37, 11, Blocks.STONE_BRICKS.getDefaultState());
        structure.fillWithBlocks(world, start, 30, -37, 18, 31, -37, 29, Blocks.STONE_BRICKS.getDefaultState());
        structure.fillWithBlocks(world, start, 30, -37, 31, 31, -37, 32, Blocks.STONE_BRICKS.getDefaultState());
        structure.fillWithBlocks(world, start, 30, -37, 33, 30, -37, 34, Blocks.STONE_BRICKS.getDefaultState());
        structure.fillWithBlocks(world, start, 30, -36, -58, 32, -36, -44, Blocks.AIR.getDefaultState());
        structure.fillWithBlocks(world, start, 30, -36, -15, 30, -36, -15, Blocks.STONE_BRICKS.getDefaultState());
        structure.fillWithBlocks(world, start, 30, -36, -10, 30, -34, -5, Blocks.SANDSTONE.getDefaultState());
        structure.fillWithBlocks(world, start, 30, -36, -4, 31, -36, -3, Blocks.STONE_BRICKS.getDefaultState());
        structure.fillWithBlocks(world, start, 30, -36, 18, 33, -36, 22, Blocks.STONE_BRICKS.getDefaultState());
        structure.fillWithBlocks(world, start, 30, -36, 24, 31, -36, 25, Blocks.STONE_BRICKS.getDefaultState());
        structure.fillWithBlocks(world, start, 30, -36, 27, 31, -36, 28, Blocks.STONE_BRICKS.getDefaultState());
        structure.fillWithBlocks(world, start, 30, -36, 30, 33, -36, 34, Blocks.STONE_BRICKS.getDefaultState());
        structure.fillWithBlocks(world, start, 30, -35, -57, 32, -35, -55, Blocks.AIR.getDefaultState());
        structure.fillWithBlocks(world, start, 30, -35, -54, 34, -34, -54, Blocks.STONE_BRICKS.getDefaultState());
        structure.fillWithBlocks(world, start, 30, -35, -53, 32, -35, -49, Blocks.AIR.getDefaultState());
        structure.fillWithBlocks(world, start, 30, -35, -48, 34, -34, -48, Blocks.STONE_BRICKS.getDefaultState());
        structure.fillWithBlocks(world, start, 30, -35, -47, 32, -35, -45, Blocks.AIR.getDefaultState());
        structure.fillWithBlocks(world, start, 30, -35, -44, 31, -35, -43, Blocks.STONE_BRICKS.getDefaultState());
        structure.fillWithBlocks(world, start, 30, -35, -15, 31, -35, -14, Blocks.STONE_BRICKS.getDefaultState());
        structure.fillWithBlocks(world, start, 30, -35, -4, 31, -35, -3, Blocks.STONE_BRICKS.getDefaultState());
        structure.fillWithBlocks(world, start, 30, -35, 19, 31, -35, 34, Blocks.STONE_BRICKS.getDefaultState());
        structure.fillWithBlocks(world, start, 30, -34, -47, 30, -31, -42, Blocks.STONE_BRICKS.getDefaultState());
        structure.fillWithBlocks(world, start, 30, -34, -4, 31, -34, -3, Blocks.STONE_BRICKS.getDefaultState());
        structure.fillWithBlocks(world, start, 30, -34, 10, 30, -32, 12, Blocks.STONE_BRICKS.getDefaultState());
        structure.fillWithBlocks(world, start, 30, -34, 13, 30, -34, 15, Blocks.AIR.getDefaultState());
        structure.fillWithBlocks(world, start, 30, -34, 16, 33, -34, 23, Blocks.STONE_BRICKS.getDefaultState());
        structure.fillWithBlocks(world, start, 30, -34, 24, 31, -34, 26, Blocks.STONE_BRICKS.getDefaultState());
        structure.fillWithBlocks(world, start, 30, -34, 27, 30, -34, 27, Blocks.AIR.getDefaultState());
        structure.fillWithBlocks(world, start, 30, -34, 28, 30, -34, 34, Blocks.STONE_BRICKS.getDefaultState());
        structure.fillWithBlocks(world, start, 30, -33, -58, 30, -33, -57, Blocks.STONE_BRICKS.getDefaultState());
        structure.fillWithBlocks(world, start, 30, -33, -56, 30, -32, -56, Blocks.AIR.getDefaultState());
        structure.fillWithBlocks(world, start, 30, -33, -55, 30, -33, -55, Blocks.STONE_BRICKS.getDefaultState());
        structure.fillWithBlocks(world, start, 30, -33, -53, 30, -33, -53, Blocks.STONE_BRICKS.getDefaultState());
        structure.fillWithBlocks(world, start, 30, -33, -52, 30, -33, -51, Blocks.AIR.getDefaultState());
        structure.fillWithBlocks(world, start, 30, -33, -50, 30, -32, -49, Blocks.STONE_BRICKS.getDefaultState());
        structure.fillWithBlocks(world, start, 30, -33, -15, 30, -33, -15, Blocks.STONE_BRICKS.getDefaultState());
        structure.fillWithBlocks(world, start, 30, -33, -10, 30, -33, -3, Blocks.STONE_BRICKS.getDefaultState());
        structure.fillWithBlocks(world, start, 30, -33, 13, 30, -33, 14, Blocks.STONE_BRICKS.getDefaultState());
        structure.fillWithBlocks(world, start, 30, -33, 15, 30, -33, 16, Blocks.AIR.getDefaultState());
        structure.fillWithBlocks(world, start, 30, -33, 17, 31, -33, 18, Blocks.STONE_BRICKS.getDefaultState());
        structure.fillWithBlocks(world, start, 30, -33, 19, 30, -33, 19, Blocks.AIR.getDefaultState());
        structure.fillWithBlocks(world, start, 30, -33, 20, 30, -33, 34, Blocks.STONE_BRICKS.getDefaultState());
        structure.fillWithBlocks(world, start, 30, -32, -58, 30, -31, -57, Blocks.STONE_BRICKS.getDefaultState());
        structure.fillWithBlocks(world, start, 30, -32, -55, 31, -32, -54, Blocks.STONE_BRICKS.getDefaultState());
        structure.fillWithBlocks(world, start, 30, -32, -52, 30, -32, -52, Blocks.STONE_BRICKS.getDefaultState());
        structure.fillWithBlocks(world, start, 30, -32, -48, 31, -32, -43, Blocks.STONE_BRICKS.getDefaultState());
        structure.fillWithBlocks(world, start, 30, -32, -6, 32, -32, -3, Blocks.STONE_BRICKS.getDefaultState());
        structure.fillWithBlocks(world, start, 30, -32, 16, 31, -32, 21, Blocks.STONE_BRICKS.getDefaultState());
        structure.fillWithBlocks(world, start, 30, -32, 22, 31, -32, 22, Blocks.AIR.getDefaultState());
        structure.fillWithBlocks(world, start, 30, -32, 23, 31, -32, 24, Blocks.STONE_BRICKS.getDefaultState());
        structure.fillWithBlocks(world, start, 30, -32, 26, 32, -32, 28, Blocks.STONE_BRICKS.getDefaultState());
        structure.fillWithBlocks(world, start, 30, -32, 29, 30, -32, 34, Blocks.STONE_BRICKS.getDefaultState());
        structure.fillWithBlocks(world, start, 30, -31, -40, 30, -31, -35, Blocks.STONE_BRICKS.getDefaultState());
        structure.fillWithBlocks(world, start, 30, -20, -32, 34, -20, -27, Blocks.SANDSTONE.getDefaultState());
        structure.fillWithBlocks(world, start, 30, -20, -20, 34, -20, -20, Blocks.SANDSTONE.getDefaultState());
        structure.fillWithBlocks(world, start, 30, -19, -32, 32, -19, -30, Blocks.SANDSTONE.getDefaultState());
        structure.fillWithBlocks(world, start, 30, -19, -22, 31, -19, -21, Blocks.SANDSTONE.getDefaultState());
        structure.fillWithBlocks(world, start, 30, -18, -32, 30, -18, -32, Blocks.AIR.getDefaultState());
        structure.fillWithBlocks(world, start, 30, -18, -31, 30, -18, -30, Blocks.SANDSTONE.getDefaultState());
        structure.fillWithBlocks(world, start, 30, -17, -12, 31, -17, -12, Blocks.STONE_BRICKS.getDefaultState());
        structure.fillWithBlocks(world, start, 30, -17, -6, 31, -17, -6, Blocks.STONE_BRICKS.getDefaultState());
        structure.fillWithBlocks(world, start, 30, -17, 22, 31, -17, 22, Blocks.STONE_BRICKS.getDefaultState());
        structure.fillWithBlocks(world, start, 30, -17, 28, 31, -17, 28, Blocks.STONE_BRICKS.getDefaultState());
        structure.fillWithBlocks(world, start, 30, -16, -22, 30, -16, -22, Blocks.SANDSTONE.getDefaultState());
        structure.fillWithBlocks(world, start, 30, -15, -28, 30, -15, -28, Blocks.SANDSTONE.getDefaultState());
        structure.fillWithBlocks(world, start, 30, -15, -27, 30, -15, -25, Blocks.AIR.getDefaultState());
        structure.fillWithBlocks(world, start, 30, -15, -24, 34, -15, -20, Blocks.SANDSTONE.getDefaultState());
        structure.fillWithBlocks(world, start, 30, -14, -22, 32, -14, -20, Blocks.SANDSTONE.getDefaultState());
        structure.fillWithBlocks(world, start, 30, -13, -27, 30, -13, -27, Blocks.SANDSTONE.getDefaultState());
        structure.fillWithBlocks(world, start, 30, -13, -25, 33, -13, -22, Blocks.SANDSTONE.getDefaultState());
        structure.fillWithBlocks(world, start, 30, -12, -23, 31, -12, -22, Blocks.SANDSTONE.getDefaultState());
        structure.fillWithBlocks(world, start, 30, -11, -32, 30, -11, -30, Blocks.SANDSTONE.getDefaultState());
        structure.fillWithBlocks(world, start, 30, -11, -28, 30, -10, -23, Blocks.SANDSTONE.getDefaultState());
        structure.fillWithBlocks(world, start, 30, -9, -6, 31, -9, -6, Blocks.STONE_BRICKS.getDefaultState());
        structure.fillWithBlocks(world, start, 30, -9, 22, 31, -9, 23, Blocks.AIR.getDefaultState());
        structure.fillWithBlocks(world, start, 30, -8, -14, 30, -8, -14, Blocks.SANDSTONE.getDefaultState());
        structure.fillWithBlocks(world, start, 30, -8, -13, 30, -8, -12, Blocks.SHROOMLIGHT.getDefaultState());
        structure.fillWithBlocks(world, start, 30, -8, -4, 31, -7, -4, Blocks.SANDSTONE.getDefaultState());
        structure.fillWithBlocks(world, start, 30, -7, -28, 31, -7, -28, Blocks.STONE_BRICKS.getDefaultState());
        structure.fillWithBlocks(world, start, 30, -7, -22, 31, -7, -22, Blocks.STONE_BRICKS.getDefaultState());
        structure.fillWithBlocks(world, start, 30, -7, -13, 31, -7, -13, Blocks.SANDSTONE.getDefaultState());
        structure.fillWithBlocks(world, start, 30, -7, -12, 31, -7, -12, Blocks.STONE_BRICKS.getDefaultState());
        structure.fillWithBlocks(world, start, 30, -7, 18, 31, -7, 18, Blocks.STONE_BRICKS.getDefaultState());
        structure.fillWithBlocks(world, start, 30, -7, 24, 31, -7, 24, Blocks.STONE_BRICKS.getDefaultState());
        structure.fillWithBlocks(world, start, 30, -6, -14, 30, -6, -14, Blocks.SANDSTONE.getDefaultState());
        structure.fillWithBlocks(world, start, 30, -6, -12, 31, -6, -11, Blocks.SANDSTONE.getDefaultState());
        structure.fillWithBlocks(world, start, 30, -6, -4, 31, -5, -4, Blocks.SANDSTONE.getDefaultState());
        structure.fillWithBlocks(world, start, 30, -5, -14, 31, -5, -14, Blocks.SANDSTONE.getDefaultState());
        structure.fillWithBlocks(world, start, 30, -5, -13, 31, -5, -13, Blocks.AIR.getDefaultState());
        structure.fillWithBlocks(world, start, 30, -5, -12, 31, -5, -11, Blocks.SANDSTONE.getDefaultState());
        structure.fillWithBlocks(world, start, 30, -5, -10, 30, -5, -10, Blocks.STONE_BRICKS.getDefaultState());
        structure.fillWithBlocks(world, start, 30, -5, -9, 30, -4, -9, Blocks.SHROOMLIGHT.getDefaultState());
        structure.fillWithBlocks(world, start, 30, -5, -8, 31, -5, -8, Blocks.STONE_BRICKS.getDefaultState());
        structure.fillWithBlocks(world, start, 30, -4, -14, 30, -4, -13, Blocks.AIR.getDefaultState());
        structure.fillWithBlocks(world, start, 30, -4, -12, 30, -4, -11, Blocks.REDSTONE_WIRE.getDefaultState().with(RedstoneWireBlock.POWER, 0).with(RedstoneWireBlock.NORTH, RedstoneSide.SIDE).with(RedstoneWireBlock.SOUTH, RedstoneSide.SIDE).with(RedstoneWireBlock.EAST, RedstoneSide.NONE).with(RedstoneWireBlock.WEST, RedstoneSide.NONE));
        structure.fillWithBlocks(world, start, 30, -4, -10, 30, -4, -10, Blocks.SANDSTONE.getDefaultState());
        structure.fillWithBlocks(world, start, 30, -4, -8, 30, -4, -8, Blocks.SANDSTONE.getDefaultState());
        structure.fillWithBlocks(world, start, 30, -4, -4, 31, -3, -4, Blocks.SANDSTONE.getDefaultState());
        structure.fillWithBlocks(world, start, 30, -3, -14, 30, -3, -14, Blocks.SANDSTONE.getDefaultState());
        structure.fillWithBlocks(world, start, 30, -3, -12, 30, -3, -12, Blocks.SANDSTONE.getDefaultState());
        structure.fillWithBlocks(world, start, 30, -3, -10, 31, -3, -8, Blocks.SANDSTONE.getDefaultState());
        structure.fillWithBlocks(world, start, 30, -3, -6, 30, -3, -6, Blocks.SANDSTONE.getDefaultState());
        structure.fillWithBlocks(world, start, 30, 0, 36, 32, 0, 38, Blocks.SANDSTONE.getDefaultState());
        structure.fillWithBlocks(world, start, 30, 1, 6, 30, 1, 6, Blocks.SAND.getDefaultState());
        structure.fillWithBlocks(world, start, 30, 1, 7, 30, 1, 17, Blocks.STONE.getDefaultState());
        structure.fillWithBlocks(world, start, 30, 1, 19, 31, 1, 21, Blocks.DIRT.getDefaultState());
        structure.fillWithBlocks(world, start, 30, 1, 22, 35, 1, 30, Blocks.STONE.getDefaultState());
        structure.fillWithBlocks(world, start, 30, 1, 34, 32, 1, 37, Blocks.SAND.getDefaultState());
        structure.fillWithBlocks(world, start, 30, 2, 6, 32, 2, 8, Blocks.SAND.getDefaultState());
        structure.fillWithBlocks(world, start, 30, 2, 9, 31, 2, 11, Blocks.STONE.getDefaultState());
        structure.fillWithBlocks(world, start, 30, 2, 12, 31, 2, 27, Blocks.DIRT.getDefaultState());
        structure.fillWithBlocks(world, start, 30, 3, 6, 31, 3, 10, Blocks.SAND.getDefaultState());
        structure.fillWithBlocks(world, start, 30, 4, 6, 30, 4, 10, Blocks.SAND.getDefaultState());
        structure.fillWithBlocks(world, start, 30, 5, 32, 31, 5, 34, Blocks.SAND.getDefaultState());
        structure.fillWithBlocks(world, start, 30, 6, 9, 31, 6, 10, Blocks.SAND.getDefaultState());
        structure.fillWithBlocks(world, start, 30, 6, 32, 31, 6, 33, Blocks.SAND.getDefaultState());
        structure.fillWithBlocks(world, start, 30, 8, 13, 30, 8, 29, Blocks.SANDSTONE.getDefaultState());
        structure.fillWithBlocks(world, start, 30, 9, 31, 30, 10, 31, Blocks.CUT_SANDSTONE.getDefaultState());
        structure.fillWithBlocks(world, start, 30, 10, 27, 31, 11, 27, Blocks.SANDSTONE.getDefaultState());
        structure.fillWithBlocks(world, start, 30, 11, 26, 30, 11, 27, Blocks.SANDSTONE.getDefaultState());
        structure.fillWithBlocks(world, start, 30, 12, 27, 31, 13, 27, Blocks.SANDSTONE.getDefaultState());
        structure.fillWithBlocks(world, start, 30, 13, 31, 30, 14, 31, Blocks.ORANGE_TERRACOTTA.getDefaultState());
        structure.fillWithBlocks(world, start, 31, -50, -60, 36, -50, -54, Blocks.SANDSTONE.getDefaultState());
        structure.fillWithBlocks(world, start, 31, -49, -71, 31, -49, -69, Blocks.SANDSTONE.getDefaultState());
        structure.fillWithBlocks(world, start, 31, -49, -68, 32, -49, -60, Blocks.AIR.getDefaultState());
        structure.fillWithBlocks(world, start, 31, -49, -59, 31, -49, -54, Blocks.SANDSTONE.getDefaultState());
        structure.fillWithBlocks(world, start, 31, -49, -50, 33, -49, -48, Blocks.SANDSTONE.getDefaultState());
        structure.fillWithBlocks(world, start, 31, -49, -47, 31, -49, -45, Blocks.SANDSTONE.getDefaultState());
        structure.fillWithBlocks(world, start, 31, -49, -44, 32, -49, -36, Blocks.AIR.getDefaultState());
        structure.fillWithBlocks(world, start, 31, -49, -35, 31, -49, -31, Blocks.SANDSTONE.getDefaultState());
        structure.fillWithBlocks(world, start, 31, -49, -30, 33, -49, -28, Blocks.AIR.getDefaultState());
        structure.fillWithBlocks(world, start, 31, -49, -10, 33, -49, -8, Blocks.AIR.getDefaultState());
        structure.fillWithBlocks(world, start, 31, -48, -74, 33, -48, -72, Blocks.SANDSTONE.getDefaultState());
        structure.fillWithBlocks(world, start, 31, -48, -71, 31, -41, -71, Blocks.SANDSTONE.getDefaultState());
        structure.fillWithBlocks(world, start, 31, -48, -70, 31, -48, -70, Blocks.IRON_BARS.getDefaultState().with(FourWayBlock.WATERLOGGED, false).with(FourWayBlock.NORTH, true).with(FourWayBlock.SOUTH, true).with(FourWayBlock.EAST, true).with(FourWayBlock.WEST, true));
        structure.fillWithBlocks(world, start, 31, -48, -69, 31, -41, -69, Blocks.SANDSTONE.getDefaultState());
        structure.fillWithBlocks(world, start, 31, -48, -68, 32, -48, -60, Blocks.AIR.getDefaultState());
        structure.fillWithBlocks(world, start, 31, -48, -59, 31, -41, -59, Blocks.SANDSTONE.getDefaultState());
        structure.fillWithBlocks(world, start, 31, -48, -58, 31, -48, -58, Blocks.IRON_BARS.getDefaultState().with(FourWayBlock.WATERLOGGED, false).with(FourWayBlock.NORTH, true).with(FourWayBlock.SOUTH, true).with(FourWayBlock.EAST, true).with(FourWayBlock.WEST, true));
        structure.fillWithBlocks(world, start, 31, -48, -57, 31, -48, -54, Blocks.SANDSTONE.getDefaultState());
        structure.fillWithBlocks(world, start, 31, -48, -50, 33, -48, -48, Blocks.SANDSTONE.getDefaultState());
        structure.fillWithBlocks(world, start, 31, -48, -47, 31, -42, -47, Blocks.SANDSTONE.getDefaultState());
        structure.fillWithBlocks(world, start, 31, -48, -46, 31, -48, -46, Blocks.IRON_BARS.getDefaultState().with(FourWayBlock.WATERLOGGED, false).with(FourWayBlock.NORTH, true).with(FourWayBlock.SOUTH, true).with(FourWayBlock.EAST, true).with(FourWayBlock.WEST, true));
        structure.fillWithBlocks(world, start, 31, -48, -45, 31, -42, -45, Blocks.SANDSTONE.getDefaultState());
        structure.fillWithBlocks(world, start, 31, -48, -44, 32, -48, -36, Blocks.AIR.getDefaultState());
        structure.fillWithBlocks(world, start, 31, -48, -35, 31, -41, -35, Blocks.SANDSTONE.getDefaultState());
        structure.fillWithBlocks(world, start, 31, -48, -34, 31, -48, -34, Blocks.IRON_BARS.getDefaultState().with(FourWayBlock.WATERLOGGED, false).with(FourWayBlock.NORTH, true).with(FourWayBlock.SOUTH, true).with(FourWayBlock.EAST, true).with(FourWayBlock.WEST, true));
        structure.fillWithBlocks(world, start, 31, -48, -33, 31, -48, -31, Blocks.SANDSTONE.getDefaultState());
        structure.fillWithBlocks(world, start, 31, -48, -30, 33, -48, -28, Blocks.AIR.getDefaultState());
        structure.fillWithBlocks(world, start, 31, -48, -10, 33, -48, -8, Blocks.AIR.getDefaultState());
        structure.fillWithBlocks(world, start, 31, -48, 15, 31, -47, 15, Blocks.SANDSTONE.getDefaultState());
        structure.fillWithBlocks(world, start, 31, -48, 21, 36, -47, 21, Blocks.SANDSTONE.getDefaultState());
        structure.fillWithBlocks(world, start, 31, -47, -70, 32, -47, -69, Blocks.SANDSTONE.getDefaultState());
        structure.fillWithBlocks(world, start, 31, -47, -68, 32, -47, -60, Blocks.AIR.getDefaultState());
        structure.fillWithBlocks(world, start, 31, -47, -58, 32, -47, -54, Blocks.SANDSTONE.getDefaultState());
        structure.fillWithBlocks(world, start, 31, -47, -50, 33, -47, -48, Blocks.SANDSTONE.getDefaultState());
        structure.fillWithBlocks(world, start, 31, -47, -46, 31, -47, -45, Blocks.SANDSTONE.getDefaultState());
        structure.fillWithBlocks(world, start, 31, -47, -44, 32, -47, -36, Blocks.AIR.getDefaultState());
        structure.fillWithBlocks(world, start, 31, -47, -34, 31, -44, -31, Blocks.SANDSTONE.getDefaultState());
        structure.fillWithBlocks(world, start, 31, -47, -30, 33, -47, -28, Blocks.AIR.getDefaultState());
        structure.fillWithBlocks(world, start, 31, -47, -10, 33, -47, -8, Blocks.AIR.getDefaultState());
        structure.fillWithBlocks(world, start, 31, -46, -74, 36, -46, -69, Blocks.SANDSTONE.getDefaultState());
        structure.fillWithBlocks(world, start, 31, -46, -68, 32, -46, -60, Blocks.AIR.getDefaultState());
        structure.fillWithBlocks(world, start, 31, -46, -58, 35, -46, -54, Blocks.SANDSTONE.getDefaultState());
        structure.fillWithBlocks(world, start, 31, -46, -46, 32, -46, -45, Blocks.SANDSTONE.getDefaultState());
        structure.fillWithBlocks(world, start, 31, -46, -44, 32, -46, -36, Blocks.AIR.getDefaultState());
        structure.fillWithBlocks(world, start, 31, -45, -74, 37, -45, -68, Blocks.SANDSTONE.getDefaultState());
        structure.fillWithBlocks(world, start, 31, -45, -50, 36, -45, -44, Blocks.SANDSTONE.getDefaultState());
        structure.fillWithBlocks(world, start, 31, -44, -74, 37, -44, -68, Blocks.SANDSTONE.getDefaultState());
        structure.fillWithBlocks(world, start, 31, -44, -50, 36, -44, -44, Blocks.SANDSTONE.getDefaultState());
        structure.fillWithBlocks(world, start, 31, -42, -15, 32, -42, -3, Blocks.SANDSTONE.getDefaultState());
        structure.fillWithBlocks(world, start, 31, -40, -53, 32, -40, -49, Blocks.AIR.getDefaultState());
        structure.fillWithBlocks(world, start, 31, -40, -47, 32, -40, -45, Blocks.AIR.getDefaultState());
        structure.fillWithBlocks(world, start, 31, -40, -15, 32, -40, -5, Blocks.STONE_BRICKS.getDefaultState());
        structure.fillWithBlocks(world, start, 31, -40, -3, 32, -39, -3, Blocks.STONE_BRICKS.getDefaultState());
        structure.fillWithBlocks(world, start, 31, -40, 24, 34, -40, 29, Blocks.STONE_BRICKS.getDefaultState());
        structure.fillWithBlocks(world, start, 31, -40, 30, 31, -40, 34, Blocks.STONE_BRICKS.getDefaultState());
        structure.fillWithBlocks(world, start, 31, -39, -43, 34, -36, -43, Blocks.STONE_BRICKS.getDefaultState());
        structure.fillWithBlocks(world, start, 31, -39, -13, 32, -39, -11, Blocks.STONE_BRICKS.getDefaultState());
        structure.fillWithBlocks(world, start, 31, -39, -7, 32, -39, -3, Blocks.STONE_BRICKS.getDefaultState());
        structure.fillWithBlocks(world, start, 31, -39, 21, 31, -38, 21, Blocks.AIR.getDefaultState());
        structure.fillWithBlocks(world, start, 31, -39, 22, 31, -39, 22, Blocks.STONE_BRICKS.getDefaultState());
        structure.fillWithBlocks(world, start, 31, -39, 23, 31, -38, 23, Blocks.AIR.getDefaultState());
        structure.fillWithBlocks(world, start, 31, -39, 24, 34, -36, 24, Blocks.STONE_BRICKS.getDefaultState());
        structure.fillWithBlocks(world, start, 31, -39, 25, 32, -39, 25, Blocks.AIR.getDefaultState());
        structure.fillWithBlocks(world, start, 31, -39, 26, 32, -39, 27, Blocks.STONE_BRICKS.getDefaultState());
        structure.fillWithBlocks(world, start, 31, -39, 28, 31, -39, 29, Blocks.STONE_BRICKS.getDefaultState());
        structure.fillWithBlocks(world, start, 31, -39, 30, 31, -39, 31, Blocks.AIR.getDefaultState());
        structure.fillWithBlocks(world, start, 31, -39, 32, 33, -39, 34, Blocks.STONE_BRICKS.getDefaultState());
        structure.fillWithBlocks(world, start, 31, -38, -15, 32, -38, -11, Blocks.STONE_BRICKS.getDefaultState());
        structure.fillWithBlocks(world, start, 31, -38, -7, 32, -38, -3, Blocks.STONE_BRICKS.getDefaultState());
        structure.fillWithBlocks(world, start, 31, -38, 20, 31, -38, 21, Blocks.AIR.getDefaultState());
        structure.fillWithBlocks(world, start, 31, -38, 22, 31, -38, 22, Blocks.STONE_BRICKS.getDefaultState());
        structure.fillWithBlocks(world, start, 31, -38, 32, 31, -38, 34, Blocks.STONE_BRICKS.getDefaultState());
        structure.fillWithBlocks(world, start, 31, -37, -13, 31, -37, -13, Blocks.STONE_BRICKS.getDefaultState());
        structure.fillWithBlocks(world, start, 31, -37, -11, 32, -36, -11, Blocks.STONE_BRICKS.getDefaultState());
        structure.fillWithBlocks(world, start, 31, -37, -7, 32, -37, -3, Blocks.STONE_BRICKS.getDefaultState());
        structure.fillWithBlocks(world, start, 31, -37, 30, 33, -37, 32, Blocks.STONE_BRICKS.getDefaultState());
        structure.fillWithBlocks(world, start, 31, -36, -15, 32, -36, -3, Blocks.STONE_BRICKS.getDefaultState());
        structure.fillWithBlocks(world, start, 31, -36, 10, 32, -36, 11, Blocks.STONE_BRICKS.getDefaultState());
        structure.fillWithBlocks(world, start, 31, -36, 12, 34, -36, 15, Blocks.AIR.getDefaultState());
        structure.fillWithBlocks(world, start, 31, -36, 16, 32, -36, 17, Blocks.AIR.getDefaultState());
        structure.fillWithBlocks(world, start, 31, -36, 23, 32, -36, 24, Blocks.STONE_BRICKS.getDefaultState());
        structure.fillWithBlocks(world, start, 31, -36, 26, 33, -36, 28, Blocks.STONE_BRICKS.getDefaultState());
        structure.fillWithBlocks(world, start, 31, -36, 29, 31, -36, 34, Blocks.STONE_BRICKS.getDefaultState());
        structure.fillWithBlocks(world, start, 31, -35, -13, 32, -35, -11, Blocks.STONE_BRICKS.getDefaultState());
        structure.fillWithBlocks(world, start, 31, -35, -9, 32, -35, -3, Blocks.STONE_BRICKS.getDefaultState());
        structure.fillWithBlocks(world, start, 31, -35, 10, 34, -35, 18, Blocks.STONE_BRICKS.getDefaultState());
        structure.fillWithBlocks(world, start, 31, -34, -58, 32, -34, -57, Blocks.STONE_BRICKS.getDefaultState());
        structure.fillWithBlocks(world, start, 31, -34, -55, 34, -34, -52, Blocks.STONE_BRICKS.getDefaultState());
        structure.fillWithBlocks(world, start, 31, -34, -50, 34, -34, -47, Blocks.STONE_BRICKS.getDefaultState());
        structure.fillWithBlocks(world, start, 31, -34, -15, 32, -34, -14, Blocks.STONE_BRICKS.getDefaultState());
        structure.fillWithBlocks(world, start, 31, -34, -12, 32, -34, -3, Blocks.STONE_BRICKS.getDefaultState());
        structure.fillWithBlocks(world, start, 31, -34, 10, 31, -34, 10, Blocks.STONE_BRICKS.getDefaultState());
        structure.fillWithBlocks(world, start, 31, -34, 12, 31, -34, 14, Blocks.STONE_BRICKS.getDefaultState());
        structure.fillWithBlocks(world, start, 31, -34, 15, 31, -33, 15, Blocks.AIR.getDefaultState());
        structure.fillWithBlocks(world, start, 31, -34, 27, 31, -34, 28, Blocks.AIR.getDefaultState());
        structure.fillWithBlocks(world, start, 31, -34, 29, 32, -34, 30, Blocks.STONE_BRICKS.getDefaultState());
        structure.fillWithBlocks(world, start, 31, -34, 31, 31, -34, 34, Blocks.STONE_BRICKS.getDefaultState());
        structure.fillWithBlocks(world, start, 31, -33, -57, 32, -33, -56, Blocks.STONE_BRICKS.getDefaultState());
        structure.fillWithBlocks(world, start, 31, -33, -55, 31, -33, -50, Blocks.STONE_BRICKS.getDefaultState());
        structure.fillWithBlocks(world, start, 31, -33, -49, 31, -32, -49, Blocks.AIR.getDefaultState());
        structure.fillWithBlocks(world, start, 31, -33, -48, 34, -33, -45, Blocks.STONE_BRICKS.getDefaultState());
        structure.fillWithBlocks(world, start, 31, -33, -43, 34, -31, -43, Blocks.STONE_BRICKS.getDefaultState());
        structure.fillWithBlocks(world, start, 31, -33, -15, 32, -33, -11, Blocks.STONE_BRICKS.getDefaultState());
        structure.fillWithBlocks(world, start, 31, -33, -9, 32, -33, -8, Blocks.STONE_BRICKS.getDefaultState());
        structure.fillWithBlocks(world, start, 31, -33, -5, 32, -33, -3, Blocks.STONE_BRICKS.getDefaultState());
        structure.fillWithBlocks(world, start, 31, -33, 10, 33, -33, 12, Blocks.STONE_BRICKS.getDefaultState());
        structure.fillWithBlocks(world, start, 31, -33, 13, 31, -32, 13, Blocks.AIR.getDefaultState());
        structure.fillWithBlocks(world, start, 31, -33, 14, 33, -31, 14, Blocks.STONE_BRICKS.getDefaultState());
        structure.fillWithBlocks(world, start, 31, -33, 16, 31, -33, 19, Blocks.STONE_BRICKS.getDefaultState());
        structure.fillWithBlocks(world, start, 31, -33, 21, 32, -33, 26, Blocks.STONE_BRICKS.getDefaultState());
        structure.fillWithBlocks(world, start, 31, -33, 27, 31, -33, 34, Blocks.STONE_BRICKS.getDefaultState());
        structure.fillWithBlocks(world, start, 31, -32, -58, 31, -32, -58, Blocks.STONE_BRICKS.getDefaultState());
        structure.fillWithBlocks(world, start, 31, -32, -56, 33, -32, -54, Blocks.STONE_BRICKS.getDefaultState());
        structure.fillWithBlocks(world, start, 31, -32, -53, 32, -32, -50, Blocks.STONE_BRICKS.getDefaultState());
        structure.fillWithBlocks(world, start, 31, -32, -15, 31, -32, -15, Blocks.STONE_BRICKS.getDefaultState());
        structure.fillWithBlocks(world, start, 31, -32, -13, 32, -32, -8, Blocks.STONE_BRICKS.getDefaultState());
        structure.fillWithBlocks(world, start, 31, -32, -7, 31, -32, -3, Blocks.STONE_BRICKS.getDefaultState());
        structure.fillWithBlocks(world, start, 31, -32, 10, 33, -32, 12, Blocks.STONE_BRICKS.getDefaultState());
        structure.fillWithBlocks(world, start, 31, -32, 15, 31, -31, 21, Blocks.STONE_BRICKS.getDefaultState());
        structure.fillWithBlocks(world, start, 31, -32, 29, 31, -32, 29, Blocks.AIR.getDefaultState());
        structure.fillWithBlocks(world, start, 31, -32, 30, 31, -32, 34, Blocks.STONE_BRICKS.getDefaultState());
        structure.fillWithBlocks(world, start, 31, -31, -58, 34, -31, -43, Blocks.STONE_BRICKS.getDefaultState());
        structure.fillWithBlocks(world, start, 31, -20, -22, 31, -20, -20, Blocks.SANDSTONE.getDefaultState());
        structure.fillWithBlocks(world, start, 31, -19, -29, 31, -19, -29, Blocks.SANDSTONE.getDefaultState());
        structure.fillWithBlocks(world, start, 31, -19, -28, 31, -16, -24, Blocks.AIR.getDefaultState());
        structure.fillWithBlocks(world, start, 31, -19, -23, 33, -19, -20, Blocks.SANDSTONE.getDefaultState());
        structure.fillWithBlocks(world, start, 31, -18, -32, 31, -18, -32, Blocks.SANDSTONE.getDefaultState());
        structure.fillWithBlocks(world, start, 31, -18, -30, 32, -18, -29, Blocks.SANDSTONE.getDefaultState());
        structure.fillWithBlocks(world, start, 31, -18, -23, 31, -15, -20, Blocks.SANDSTONE.getDefaultState());
        structure.fillWithBlocks(world, start, 31, -18, -12, 31, -17, -12, Blocks.STONE_BRICKS.getDefaultState());
        structure.fillWithBlocks(world, start, 31, -18, -6, 31, -17, -6, Blocks.STONE_BRICKS.getDefaultState());
        structure.fillWithBlocks(world, start, 31, -18, 22, 31, -17, 22, Blocks.STONE_BRICKS.getDefaultState());
        structure.fillWithBlocks(world, start, 31, -18, 28, 31, -17, 28, Blocks.STONE_BRICKS.getDefaultState());
        structure.fillWithBlocks(world, start, 31, -17, -32, 34, -17, -29, Blocks.SANDSTONE.getDefaultState());
        structure.fillWithBlocks(world, start, 31, -16, -29, 31, -16, -29, Blocks.SANDSTONE.getDefaultState());
        structure.fillWithBlocks(world, start, 31, -16, 23, 34, -16, 27, Blocks.SANDSTONE.getDefaultState());
        structure.fillWithBlocks(world, start, 31, -15, -28, 33, -15, -26, Blocks.SANDSTONE.getDefaultState());
        structure.fillWithBlocks(world, start, 31, -15, -25, 32, -15, -20, Blocks.SANDSTONE.getDefaultState());
        structure.fillWithBlocks(world, start, 31, -14, -27, 31, -14, -27, Blocks.AIR.getDefaultState());
        structure.fillWithBlocks(world, start, 31, -14, -26, 31, -14, -20, Blocks.SANDSTONE.getDefaultState());
        structure.fillWithBlocks(world, start, 31, -13, -28, 33, -13, -20, Blocks.SANDSTONE.getDefaultState());
        structure.fillWithBlocks(world, start, 31, -12, -21, 32, -12, -21, Blocks.AIR.getDefaultState());
        structure.fillWithBlocks(world, start, 31, -11, -32, 31, -11, -32, Blocks.SANDSTONE.getDefaultState());
        structure.fillWithBlocks(world, start, 31, -11, -31, 31, -11, -30, Blocks.AIR.getDefaultState());
        structure.fillWithBlocks(world, start, 31, -11, -29, 32, -11, -28, Blocks.SANDSTONE.getDefaultState());
        structure.fillWithBlocks(world, start, 31, -11, -25, 32, -11, -24, Blocks.SANDSTONE.getDefaultState());
        structure.fillWithBlocks(world, start, 31, -11, -22, 31, -11, -20, Blocks.SANDSTONE.getDefaultState());
        structure.fillWithBlocks(world, start, 31, -9, -14, 31, -8, -13, Blocks.SANDSTONE.getDefaultState());
        structure.fillWithBlocks(world, start, 31, -9, -5, 31, -8, -4, Blocks.SANDSTONE.getDefaultState());
        structure.fillWithBlocks(world, start, 31, -9, 19, 31, -9, 23, Blocks.AIR.getDefaultState());
        structure.fillWithBlocks(world, start, 31, -8, -28, 31, -7, -28, Blocks.STONE_BRICKS.getDefaultState());
        structure.fillWithBlocks(world, start, 31, -8, -22, 31, -7, -22, Blocks.STONE_BRICKS.getDefaultState());
        structure.fillWithBlocks(world, start, 31, -8, -12, 31, -7, -12, Blocks.STONE_BRICKS.getDefaultState());
        structure.fillWithBlocks(world, start, 31, -8, -6, 31, -7, -6, Blocks.STONE_BRICKS.getDefaultState());
        structure.fillWithBlocks(world, start, 31, -8, 18, 31, -7, 18, Blocks.STONE_BRICKS.getDefaultState());
        structure.fillWithBlocks(world, start, 31, -8, 24, 31, -7, 24, Blocks.STONE_BRICKS.getDefaultState());
        structure.fillWithBlocks(world, start, 31, -7, -14, 31, -6, -13, Blocks.SANDSTONE.getDefaultState());
        structure.fillWithBlocks(world, start, 31, -7, -5, 31, -6, -4, Blocks.SANDSTONE.getDefaultState());
        structure.fillWithBlocks(world, start, 31, -6, -7, 31, -5, -4, Blocks.SANDSTONE.getDefaultState());
        structure.fillWithBlocks(world, start, 31, -6, 19, 35, -6, 23, Blocks.SANDSTONE.getDefaultState());
        structure.fillWithBlocks(world, start, 31, -5, -10, 31, -5, -8, Blocks.STONE_BRICKS.getDefaultState());
        structure.fillWithBlocks(world, start, 31, -4, -14, 31, -3, -7, Blocks.SANDSTONE.getDefaultState());
        structure.fillWithBlocks(world, start, 31, -4, -5, 31, -3, -4, Blocks.SANDSTONE.getDefaultState());
        structure.fillWithBlocks(world, start, 31, -3, -6, 31, -3, -4, Blocks.SANDSTONE.getDefaultState());
        structure.fillWithBlocks(world, start, 31, 0, 4, 32, 0, 6, Blocks.SANDSTONE.getDefaultState());
        structure.fillWithBlocks(world, start, 31, 0, 7, 31, 0, 34, Blocks.STONE.getDefaultState());
        structure.fillWithBlocks(world, start, 31, 0, 35, 33, 0, 37, Blocks.SANDSTONE.getDefaultState());
        structure.fillWithBlocks(world, start, 31, 1, 5, 32, 1, 7, Blocks.SAND.getDefaultState());
        structure.fillWithBlocks(world, start, 31, 1, 8, 31, 1, 18, Blocks.STONE.getDefaultState());
        structure.fillWithBlocks(world, start, 31, 2, 5, 31, 2, 8, Blocks.SAND.getDefaultState());
        structure.fillWithBlocks(world, start, 31, 4, 32, 33, 4, 34, Blocks.SAND.getDefaultState());
        structure.fillWithBlocks(world, start, 31, 5, 8, 31, 5, 10, Blocks.SAND.getDefaultState());
        structure.fillWithBlocks(world, start, 31, 8, 27, 31, 8, 31, Blocks.SANDSTONE.getDefaultState());
        structure.fillWithBlocks(world, start, 31, 9, 27, 31, 16, 27, Blocks.SANDSTONE.getDefaultState());
        structure.fillWithBlocks(world, start, 31, 9, 28, 31, 10, 28, Blocks.CUT_SANDSTONE.getDefaultState());
        structure.fillWithBlocks(world, start, 31, 9, 29, 31, 10, 29, Blocks.ORANGE_TERRACOTTA.getDefaultState());
        structure.fillWithBlocks(world, start, 31, 9, 30, 31, 10, 30, Blocks.CUT_SANDSTONE.getDefaultState());
        structure.fillWithBlocks(world, start, 31, 9, 31, 31, 16, 31, Blocks.SANDSTONE.getDefaultState());
        structure.fillWithBlocks(world, start, 31, 13, 28, 31, 14, 28, Blocks.ORANGE_TERRACOTTA.getDefaultState());
        structure.fillWithBlocks(world, start, 31, 13, 30, 31, 14, 30, Blocks.ORANGE_TERRACOTTA.getDefaultState());
        structure.fillWithBlocks(world, start, 31, 14, 29, 31, 14, 30, Blocks.ORANGE_TERRACOTTA.getDefaultState());
        structure.fillWithBlocks(world, start, 31, 15, 28, 31, 15, 30, Blocks.CUT_SANDSTONE.getDefaultState());
        structure.fillWithBlocks(world, start, 32, -49, -74, 34, -49, -72, Blocks.SANDSTONE.getDefaultState());
        structure.fillWithBlocks(world, start, 32, -49, -71, 32, -49, -70, Blocks.SHROOMLIGHT.getDefaultState());
        structure.fillWithBlocks(world, start, 32, -49, -69, 36, -49, -69, Blocks.SANDSTONE.getDefaultState());
        structure.fillWithBlocks(world, start, 32, -49, -59, 36, -49, -59, Blocks.SANDSTONE.getDefaultState());
        structure.fillWithBlocks(world, start, 32, -49, -58, 33, -49, -58, Blocks.SHROOMLIGHT.getDefaultState());
        structure.fillWithBlocks(world, start, 32, -49, -56, 34, -49, -54, Blocks.SANDSTONE.getDefaultState());
        structure.fillWithBlocks(world, start, 32, -49, -47, 32, -49, -47, Blocks.AIR.getDefaultState());
        structure.fillWithBlocks(world, start, 32, -49, -46, 32, -48, -46, Blocks.SHROOMLIGHT.getDefaultState());
        structure.fillWithBlocks(world, start, 32, -49, -45, 36, -49, -45, Blocks.SANDSTONE.getDefaultState());
        structure.fillWithBlocks(world, start, 32, -49, -35, 36, -49, -35, Blocks.SANDSTONE.getDefaultState());
        structure.fillWithBlocks(world, start, 32, -49, -34, 33, -49, -34, Blocks.SHROOMLIGHT.getDefaultState());
        structure.fillWithBlocks(world, start, 32, -49, -32, 36, -49, -32, Blocks.SANDSTONE.getDefaultState());
        structure.fillWithBlocks(world, start, 32, -49, -31, 34, -49, -27, Blocks.AIR.getDefaultState());
        structure.fillWithBlocks(world, start, 32, -49, -26, 36, -49, -26, Blocks.SANDSTONE.getDefaultState());
        structure.fillWithBlocks(world, start, 32, -49, -11, 34, -49, -7, Blocks.AIR.getDefaultState());
        structure.fillWithBlocks(world, start, 32, -49, 16, 37, -46, 16, Blocks.SANDSTONE.getDefaultState());
        structure.fillWithBlocks(world, start, 32, -49, 17, 34, -49, 19, Blocks.AIR.getDefaultState());
        structure.fillWithBlocks(world, start, 32, -49, 20, 32, -49, 21, Blocks.SANDSTONE.getDefaultState());
        structure.fillWithBlocks(world, start, 32, -48, -71, 32, -48, -71, Blocks.IRON_BARS.getDefaultState().with(FourWayBlock.WATERLOGGED, false).with(FourWayBlock.NORTH, true).with(FourWayBlock.SOUTH, true).with(FourWayBlock.EAST, true).with(FourWayBlock.WEST, true));
        structure.fillWithBlocks(world, start, 32, -48, -59, 32, -48, -59, Blocks.IRON_BARS.getDefaultState().with(FourWayBlock.WATERLOGGED, false).with(FourWayBlock.NORTH, true).with(FourWayBlock.SOUTH, true).with(FourWayBlock.EAST, true).with(FourWayBlock.WEST, true));
        structure.fillWithBlocks(world, start, 32, -48, -56, 34, -48, -54, Blocks.SANDSTONE.getDefaultState());
        structure.fillWithBlocks(world, start, 32, -48, -47, 32, -48, -47, Blocks.IRON_BARS.getDefaultState().with(FourWayBlock.WATERLOGGED, false).with(FourWayBlock.NORTH, true).with(FourWayBlock.SOUTH, true).with(FourWayBlock.EAST, true).with(FourWayBlock.WEST, true));
        structure.fillWithBlocks(world, start, 32, -48, -35, 32, -48, -35, Blocks.IRON_BARS.getDefaultState().with(FourWayBlock.WATERLOGGED, false).with(FourWayBlock.NORTH, true).with(FourWayBlock.SOUTH, true).with(FourWayBlock.EAST, true).with(FourWayBlock.WEST, true));
        structure.fillWithBlocks(world, start, 32, -48, -32, 32, -41, -32, Blocks.SANDSTONE.getDefaultState());
        structure.fillWithBlocks(world, start, 32, -48, -31, 34, -48, -27, Blocks.AIR.getDefaultState());
        structure.fillWithBlocks(world, start, 32, -48, -26, 32, -47, -26, Blocks.SANDSTONE.getDefaultState());
        structure.fillWithBlocks(world, start, 32, -48, -11, 34, -48, -7, Blocks.AIR.getDefaultState());
        structure.fillWithBlocks(world, start, 32, -48, 17, 34, -48, 19, Blocks.AIR.getDefaultState());
        structure.fillWithBlocks(world, start, 32, -48, 20, 32, -48, 21, Blocks.SANDSTONE.getDefaultState());
        structure.fillWithBlocks(world, start, 32, -47, -74, 34, -47, -72, Blocks.SANDSTONE.getDefaultState());
        structure.fillWithBlocks(world, start, 32, -47, -59, 32, -42, -54, Blocks.SANDSTONE.getDefaultState());
        structure.fillWithBlocks(world, start, 32, -47, -47, 32, -47, -46, Blocks.AIR.getDefaultState());
        structure.fillWithBlocks(world, start, 32, -47, -45, 36, -43, -45, Blocks.SANDSTONE.getDefaultState());
        structure.fillWithBlocks(world, start, 32, -47, -35, 36, -43, -35, Blocks.SANDSTONE.getDefaultState());
        structure.fillWithBlocks(world, start, 32, -47, -34, 32, -47, -33, Blocks.AIR.getDefaultState());
        structure.fillWithBlocks(world, start, 32, -47, -31, 34, -47, -27, Blocks.AIR.getDefaultState());
        structure.fillWithBlocks(world, start, 32, -47, -11, 34, -47, -7, Blocks.AIR.getDefaultState());
        structure.fillWithBlocks(world, start, 32, -47, 17, 34, -47, 19, Blocks.AIR.getDefaultState());
        structure.fillWithBlocks(world, start, 32, -47, 20, 32, -47, 21, Blocks.SANDSTONE.getDefaultState());
        structure.fillWithBlocks(world, start, 32, -46, -47, 34, -46, -45, Blocks.SANDSTONE.getDefaultState());
        structure.fillWithBlocks(world, start, 32, -46, -34, 36, -46, -27, Blocks.SANDSTONE.getDefaultState());
        structure.fillWithBlocks(world, start, 32, -46, -11, 36, -46, -7, Blocks.SANDSTONE.getDefaultState());
        structure.fillWithBlocks(world, start, 32, -43, -69, 40, -43, -61, Blocks.SANDSTONE.getDefaultState());
        structure.fillWithBlocks(world, start, 32, -43, -44, 36, -43, -30, Blocks.SANDSTONE.getDefaultState());
        structure.fillWithBlocks(world, start, 32, -41, -57, 32, -41, -54, Blocks.STONE_BRICKS.getDefaultState());
        structure.fillWithBlocks(world, start, 32, -41, -52, 32, -41, -45, Blocks.STONE_BRICKS.getDefaultState());
        structure.fillWithBlocks(world, start, 32, -40, -59, 33, -40, -58, Blocks.STONE_BRICKS.getDefaultState());
        structure.fillWithBlocks(world, start, 32, -40, -54, 32, -36, -45, Blocks.AIR.getDefaultState());
        structure.fillWithBlocks(world, start, 32, -40, -44, 33, -40, -43, Blocks.STONE_BRICKS.getDefaultState());
        structure.fillWithBlocks(world, start, 32, -40, -4, 32, -39, -3, Blocks.STONE_BRICKS.getDefaultState());
        structure.fillWithBlocks(world, start, 32, -40, 17, 33, -40, 18, Blocks.STONE_BRICKS.getDefaultState());
        structure.fillWithBlocks(world, start, 32, -40, 19, 32, -40, 21, Blocks.AIR.getDefaultState());
        structure.fillWithBlocks(world, start, 32, -40, 22, 32, -40, 29, Blocks.STONE_BRICKS.getDefaultState());
        structure.fillWithBlocks(world, start, 32, -40, 30, 32, -38, 30, Blocks.AIR.getDefaultState());
        structure.fillWithBlocks(world, start, 32, -40, 31, 34, -40, 34, Blocks.STONE_BRICKS.getDefaultState());
        structure.fillWithBlocks(world, start, 32, -39, -57, 32, -36, -45, Blocks.AIR.getDefaultState());
        structure.fillWithBlocks(world, start, 32, -39, -15, 32, -35, -11, Blocks.STONE_BRICKS.getDefaultState());
        structure.fillWithBlocks(world, start, 32, -39, 10, 32, -39, 11, Blocks.STONE_BRICKS.getDefaultState());
        structure.fillWithBlocks(world, start, 32, -39, 18, 32, -39, 18, Blocks.STONE_BRICKS.getDefaultState());
        structure.fillWithBlocks(world, start, 32, -39, 19, 32, -39, 19, Blocks.AIR.getDefaultState());
        structure.fillWithBlocks(world, start, 32, -39, 20, 32, -39, 24, Blocks.STONE_BRICKS.getDefaultState());
        structure.fillWithBlocks(world, start, 32, -39, 29, 32, -39, 29, Blocks.STONE_BRICKS.getDefaultState());
        structure.fillWithBlocks(world, start, 32, -39, 31, 33, -39, 34, Blocks.STONE_BRICKS.getDefaultState());
        structure.fillWithBlocks(world, start, 32, -38, 10, 33, -38, 11, Blocks.STONE_BRICKS.getDefaultState());
        structure.fillWithBlocks(world, start, 32, -38, 18, 33, -38, 29, Blocks.STONE_BRICKS.getDefaultState());
        structure.fillWithBlocks(world, start, 32, -38, 31, 32, -38, 31, Blocks.STONE_BRICKS.getDefaultState());
        structure.fillWithBlocks(world, start, 32, -38, 33, 32, -38, 33, Blocks.STONE_BRICKS.getDefaultState());
        structure.fillWithBlocks(world, start, 32, -37, 10, 33, -37, 11, Blocks.STONE_BRICKS.getDefaultState());
        structure.fillWithBlocks(world, start, 32, -37, 18, 32, -37, 18, Blocks.STONE_BRICKS.getDefaultState());
        structure.fillWithBlocks(world, start, 32, -37, 20, 33, -37, 34, Blocks.STONE_BRICKS.getDefaultState());
        structure.fillWithBlocks(world, start, 32, -35, -44, 33, -35, -43, Blocks.STONE_BRICKS.getDefaultState());
        structure.fillWithBlocks(world, start, 32, -35, -10, 32, -33, -3, Blocks.STONE_BRICKS.getDefaultState());
        structure.fillWithBlocks(world, start, 32, -35, 20, 32, -34, 21, Blocks.STONE_BRICKS.getDefaultState());
        structure.fillWithBlocks(world, start, 32, -35, 23, 34, -35, 25, Blocks.STONE_BRICKS.getDefaultState());
        structure.fillWithBlocks(world, start, 32, -35, 26, 32, -35, 29, Blocks.STONE_BRICKS.getDefaultState());
        structure.fillWithBlocks(world, start, 32, -35, 31, 32, -35, 31, Blocks.STONE_BRICKS.getDefaultState());
        structure.fillWithBlocks(world, start, 32, -35, 33, 33, -35, 34, Blocks.STONE_BRICKS.getDefaultState());
        structure.fillWithBlocks(world, start, 32, -34, -56, 34, -34, -45, Blocks.STONE_BRICKS.getDefaultState());
        structure.fillWithBlocks(world, start, 32, -34, -43, 34, -32, -43, Blocks.STONE_BRICKS.getDefaultState());
        structure.fillWithBlocks(world, start, 32, -34, -13, 32, -31, -8, Blocks.STONE_BRICKS.getDefaultState());
        structure.fillWithBlocks(world, start, 32, -34, 10, 33, -34, 12, Blocks.STONE_BRICKS.getDefaultState());
        structure.fillWithBlocks(world, start, 32, -34, 14, 32, -34, 23, Blocks.STONE_BRICKS.getDefaultState());
        structure.fillWithBlocks(world, start, 32, -34, 24, 32, -34, 25, Blocks.AIR.getDefaultState());
        structure.fillWithBlocks(world, start, 32, -34, 26, 33, -33, 26, Blocks.STONE_BRICKS.getDefaultState());
        structure.fillWithBlocks(world, start, 32, -34, 27, 33, -34, 27, Blocks.AIR.getDefaultState());
        structure.fillWithBlocks(world, start, 32, -34, 28, 34, -34, 30, Blocks.STONE_BRICKS.getDefaultState());
        structure.fillWithBlocks(world, start, 32, -34, 32, 34, -34, 34, Blocks.STONE_BRICKS.getDefaultState());
        structure.fillWithBlocks(world, start, 32, -33, -58, 33, -33, -57, Blocks.STONE_BRICKS.getDefaultState());
        structure.fillWithBlocks(world, start, 32, -33, -54, 34, -33, -50, Blocks.STONE_BRICKS.getDefaultState());
        structure.fillWithBlocks(world, start, 32, -33, -49, 32, -33, -43, Blocks.STONE_BRICKS.getDefaultState());
        structure.fillWithBlocks(world, start, 32, -33, 13, 33, -33, 14, Blocks.STONE_BRICKS.getDefaultState());
        structure.fillWithBlocks(world, start, 32, -33, 15, 32, -33, 16, Blocks.AIR.getDefaultState());
        structure.fillWithBlocks(world, start, 32, -33, 17, 33, -33, 20, Blocks.STONE_BRICKS.getDefaultState());
        structure.fillWithBlocks(world, start, 32, -33, 28, 33, -33, 29, Blocks.STONE_BRICKS.getDefaultState());
        structure.fillWithBlocks(world, start, 32, -33, 30, 32, -32, 30, Blocks.AIR.getDefaultState());
        structure.fillWithBlocks(world, start, 32, -33, 31, 33, -33, 34, Blocks.STONE_BRICKS.getDefaultState());
        structure.fillWithBlocks(world, start, 32, -32, -58, 34, -32, -54, Blocks.STONE_BRICKS.getDefaultState());
        structure.fillWithBlocks(world, start, 32, -32, -49, 33, -32, -48, Blocks.STONE_BRICKS.getDefaultState());
        structure.fillWithBlocks(world, start, 32, -32, -46, 34, -32, -43, Blocks.STONE_BRICKS.getDefaultState());
        structure.fillWithBlocks(world, start, 32, -32, -15, 32, -31, -8, Blocks.STONE_BRICKS.getDefaultState());
        structure.fillWithBlocks(world, start, 32, -32, 13, 32, -32, 15, Blocks.STONE_BRICKS.getDefaultState());
        structure.fillWithBlocks(world, start, 32, -32, 17, 34, -32, 19, Blocks.STONE_BRICKS.getDefaultState());
        structure.fillWithBlocks(world, start, 32, -32, 20, 32, -32, 20, Blocks.AIR.getDefaultState());
        structure.fillWithBlocks(world, start, 32, -32, 21, 32, -31, 28, Blocks.STONE_BRICKS.getDefaultState());
        structure.fillWithBlocks(world, start, 32, -32, 29, 32, -32, 30, Blocks.AIR.getDefaultState());
        structure.fillWithBlocks(world, start, 32, -32, 31, 34, -32, 33, Blocks.STONE_BRICKS.getDefaultState());
        structure.fillWithBlocks(world, start, 32, -32, 34, 32, -32, 34, Blocks.STONE_BRICKS.getDefaultState());
        structure.fillWithBlocks(world, start, 32, -31, -4, 32, -31, -3, Blocks.STONE_BRICKS.getDefaultState());
        structure.fillWithBlocks(world, start, 32, -20, -22, 33, -20, -22, Blocks.AIR.getDefaultState());
        structure.fillWithBlocks(world, start, 32, -20, -21, 33, -20, -20, Blocks.SANDSTONE.getDefaultState());
        structure.fillWithBlocks(world, start, 32, -20, 13, 56, -20, 37, Blocks.SANDSTONE.getDefaultState());
        structure.fillWithBlocks(world, start, 32, -19, -29, 34, -19, -24, Blocks.SANDSTONE.getDefaultState());
        structure.fillWithBlocks(world, start, 32, -19, -11, 32, -17, -11, Blocks.STONE.getDefaultState());
        structure.fillWithBlocks(world, start, 32, -19, -10, 34, -19, -8, Blocks.AIR.getDefaultState());
        structure.fillWithBlocks(world, start, 32, -19, -7, 32, -17, -7, Blocks.STONE.getDefaultState());
        structure.fillWithBlocks(world, start, 32, -19, 13, 32, -19, 22, Blocks.SANDSTONE.getDefaultState());
        structure.fillWithBlocks(world, start, 32, -19, 23, 32, -17, 23, Blocks.STONE.getDefaultState());
        structure.fillWithBlocks(world, start, 32, -19, 24, 34, -19, 26, Blocks.AIR.getDefaultState());
        structure.fillWithBlocks(world, start, 32, -19, 27, 32, -17, 27, Blocks.STONE.getDefaultState());
        structure.fillWithBlocks(world, start, 32, -19, 28, 34, -19, 33, Blocks.SANDSTONE.getDefaultState());
        structure.fillWithBlocks(world, start, 32, -19, 34, 32, -19, 36, Blocks.SANDSTONE.getDefaultState());
        structure.fillWithBlocks(world, start, 32, -18, -32, 33, -18, -23, Blocks.SANDSTONE.getDefaultState());
        structure.fillWithBlocks(world, start, 32, -18, -22, 33, -18, -22, Blocks.AIR.getDefaultState());
        structure.fillWithBlocks(world, start, 32, -18, -21, 33, -18, -20, Blocks.SANDSTONE.getDefaultState());
        structure.fillWithBlocks(world, start, 32, -18, -10, 34, -18, -8, Blocks.AIR.getDefaultState());
        structure.fillWithBlocks(world, start, 32, -18, 13, 33, -18, 21, Blocks.SANDSTONE.getDefaultState());
        structure.fillWithBlocks(world, start, 32, -18, 22, 32, -10, 22, Blocks.SANDSTONE.getDefaultState());
        structure.fillWithBlocks(world, start, 32, -18, 24, 34, -18, 26, Blocks.AIR.getDefaultState());
        structure.fillWithBlocks(world, start, 32, -18, 28, 34, -18, 30, Blocks.SANDSTONE.getDefaultState());
        structure.fillWithBlocks(world, start, 32, -18, 31, 32, -18, 33, Blocks.SANDSTONE.getDefaultState());
        structure.fillWithBlocks(world, start, 32, -18, 34, 32, -18, 34, Blocks.AIR.getDefaultState());
        structure.fillWithBlocks(world, start, 32, -18, 35, 32, -18, 37, Blocks.SANDSTONE.getDefaultState());
        structure.fillWithBlocks(world, start, 32, -17, -28, 34, -17, -24, Blocks.SANDSTONE.getDefaultState());
        structure.fillWithBlocks(world, start, 32, -17, -23, 32, -16, -22, Blocks.SANDSTONE.getDefaultState());
        structure.fillWithBlocks(world, start, 32, -17, -10, 34, -17, -8, Blocks.AIR.getDefaultState());
        structure.fillWithBlocks(world, start, 32, -17, 13, 34, -17, 15, Blocks.SANDSTONE.getDefaultState());
        structure.fillWithBlocks(world, start, 32, -17, 17, 34, -17, 19, Blocks.SANDSTONE.getDefaultState());
        structure.fillWithBlocks(world, start, 32, -17, 20, 33, -17, 22, Blocks.SANDSTONE.getDefaultState());
        structure.fillWithBlocks(world, start, 32, -17, 24, 34, -17, 26, Blocks.AIR.getDefaultState());
        structure.fillWithBlocks(world, start, 32, -17, 28, 35, -17, 35, Blocks.SANDSTONE.getDefaultState());
        structure.fillWithBlocks(world, start, 32, -17, 36, 32, -17, 37, Blocks.SANDSTONE.getDefaultState());
        structure.fillWithBlocks(world, start, 32, -16, -32, 33, -16, -31, Blocks.SANDSTONE.getDefaultState());
        structure.fillWithBlocks(world, start, 32, -16, -29, 33, -16, -20, Blocks.SANDSTONE.getDefaultState());
        structure.fillWithBlocks(world, start, 32, -16, 13, 32, -16, 13, Blocks.SANDSTONE.getDefaultState());
        structure.fillWithBlocks(world, start, 32, -16, 15, 36, -16, 21, Blocks.SANDSTONE.getDefaultState());
        structure.fillWithBlocks(world, start, 32, -16, 28, 33, -16, 35, Blocks.SANDSTONE.getDefaultState());
        structure.fillWithBlocks(world, start, 32, -16, 36, 32, -16, 37, Blocks.SANDSTONE.getDefaultState());
        structure.fillWithBlocks(world, start, 32, -15, -32, 34, -15, -26, Blocks.SANDSTONE.getDefaultState());
        structure.fillWithBlocks(world, start, 32, -15, 13, 34, -15, 29, Blocks.SANDSTONE.getDefaultState());
        structure.fillWithBlocks(world, start, 32, -15, 31, 34, -15, 34, Blocks.SANDSTONE.getDefaultState());
        structure.fillWithBlocks(world, start, 32, -15, 35, 33, -15, 35, Blocks.AIR.getDefaultState());
        structure.fillWithBlocks(world, start, 32, -15, 36, 33, -15, 37, Blocks.SANDSTONE.getDefaultState());
        structure.fillWithBlocks(world, start, 32, -14, -27, 33, -13, -27, Blocks.SANDSTONE.getDefaultState());
        structure.fillWithBlocks(world, start, 32, -14, -26, 33, -14, -26, Blocks.AIR.getDefaultState());
        structure.fillWithBlocks(world, start, 32, -14, -25, 34, -14, -20, Blocks.SANDSTONE.getDefaultState());
        structure.fillWithBlocks(world, start, 32, -14, 13, 32, -14, 23, Blocks.SANDSTONE.getDefaultState());
        structure.fillWithBlocks(world, start, 32, -14, 24, 32, -14, 25, Blocks.AIR.getDefaultState());
        structure.fillWithBlocks(world, start, 32, -14, 26, 34, -14, 35, Blocks.SANDSTONE.getDefaultState());
        structure.fillWithBlocks(world, start, 32, -14, 36, 32, -14, 37, Blocks.SANDSTONE.getDefaultState());
        structure.fillWithBlocks(world, start, 32, -13, 13, 32, -12, 14, Blocks.SANDSTONE.getDefaultState());
        structure.fillWithBlocks(world, start, 32, -13, 15, 34, -13, 17, Blocks.SANDSTONE.getDefaultState());
        structure.fillWithBlocks(world, start, 32, -13, 18, 33, -13, 37, Blocks.SANDSTONE.getDefaultState());
        structure.fillWithBlocks(world, start, 32, -12, -23, 32, -12, -23, Blocks.SANDSTONE.getDefaultState());
        structure.fillWithBlocks(world, start, 32, -12, -22, 32, -12, -21, Blocks.AIR.getDefaultState());
        structure.fillWithBlocks(world, start, 32, -12, 16, 37, -12, 21, Blocks.SANDSTONE.getDefaultState());
        structure.fillWithBlocks(world, start, 32, -12, 23, 34, -12, 26, Blocks.SANDSTONE.getDefaultState());
        structure.fillWithBlocks(world, start, 32, -12, 27, 33, -12, 37, Blocks.SANDSTONE.getDefaultState());
        structure.fillWithBlocks(world, start, 32, -11, -32, 34, -11, -24, Blocks.SANDSTONE.getDefaultState());
        structure.fillWithBlocks(world, start, 32, -11, -23, 32, -11, -22, Blocks.SANDSTONE.getDefaultState());
        structure.fillWithBlocks(world, start, 32, -11, -21, 32, -11, -21, Blocks.AIR.getDefaultState());
        structure.fillWithBlocks(world, start, 32, -11, 13, 35, -11, 20, Blocks.SANDSTONE.getDefaultState());
        structure.fillWithBlocks(world, start, 32, -11, 21, 33, -11, 22, Blocks.SANDSTONE.getDefaultState());
        structure.fillWithBlocks(world, start, 32, -11, 24, 35, -11, 27, Blocks.SANDSTONE.getDefaultState());
        structure.fillWithBlocks(world, start, 32, -11, 29, 34, -11, 37, Blocks.SANDSTONE.getDefaultState());
        structure.fillWithBlocks(world, start, 32, -9, -27, 32, -7, -27, Blocks.STONE.getDefaultState());
        structure.fillWithBlocks(world, start, 32, -9, -26, 34, -9, -24, Blocks.AIR.getDefaultState());
        structure.fillWithBlocks(world, start, 32, -9, -23, 32, -7, -23, Blocks.STONE.getDefaultState());
        structure.fillWithBlocks(world, start, 32, -9, -11, 32, -7, -11, Blocks.STONE.getDefaultState());
        structure.fillWithBlocks(world, start, 32, -9, -10, 32, -7, -8, Blocks.AIR.getDefaultState());
        structure.fillWithBlocks(world, start, 32, -9, -7, 32, -7, -7, Blocks.STONE.getDefaultState());
        structure.fillWithBlocks(world, start, 32, -9, 19, 32, -7, 19, Blocks.STONE.getDefaultState());
        structure.fillWithBlocks(world, start, 32, -9, 20, 34, -9, 22, Blocks.AIR.getDefaultState());
        structure.fillWithBlocks(world, start, 32, -9, 23, 32, -7, 23, Blocks.STONE.getDefaultState());
        structure.fillWithBlocks(world, start, 32, -8, -26, 34, -8, -24, Blocks.AIR.getDefaultState());
        structure.fillWithBlocks(world, start, 32, -8, 20, 34, -8, 22, Blocks.AIR.getDefaultState());
        structure.fillWithBlocks(world, start, 32, -7, -26, 34, -7, -24, Blocks.AIR.getDefaultState());
        structure.fillWithBlocks(world, start, 32, -7, 20, 34, -7, 22, Blocks.AIR.getDefaultState());
        structure.fillWithBlocks(world, start, 32, -6, -11, 36, -6, -7, Blocks.SANDSTONE.getDefaultState());
        structure.fillWithBlocks(world, start, 32, -5, -10, 32, -5, -7, Blocks.SANDSTONE.getDefaultState());
        structure.fillWithBlocks(world, start, 32, 0, 7, 35, 0, 7, Blocks.SANDSTONE.getDefaultState());
        structure.fillWithBlocks(world, start, 32, 0, 8, 33, 0, 33, Blocks.STONE.getDefaultState());
        structure.fillWithBlocks(world, start, 32, 0, 34, 34, 0, 36, Blocks.SANDSTONE.getDefaultState());
        structure.fillWithBlocks(world, start, 32, 1, 8, 34, 2, 8, Blocks.SAND.getDefaultState());
        structure.fillWithBlocks(world, start, 32, 1, 9, 33, 1, 32, Blocks.STONE.getDefaultState());
        structure.fillWithBlocks(world, start, 32, 1, 33, 34, 1, 35, Blocks.SAND.getDefaultState());
        structure.fillWithBlocks(world, start, 32, 2, 9, 32, 2, 9, Blocks.SAND.getDefaultState());
        structure.fillWithBlocks(world, start, 32, 2, 10, 32, 2, 11, Blocks.STONE.getDefaultState());
        structure.fillWithBlocks(world, start, 32, 2, 12, 37, 2, 26, Blocks.SAND.getDefaultState());
        structure.fillWithBlocks(world, start, 32, 2, 27, 34, 2, 29, Blocks.STONE.getDefaultState());
        structure.fillWithBlocks(world, start, 32, 2, 33, 33, 2, 35, Blocks.SAND.getDefaultState());
        structure.fillWithBlocks(world, start, 32, 3, 7, 32, 3, 35, Blocks.SAND.getDefaultState());
        structure.fillWithBlocks(world, start, 32, 4, 8, 33, 4, 34, Blocks.SAND.getDefaultState());
        structure.fillWithBlocks(world, start, 32, 5, 9, 33, 5, 33, Blocks.SAND.getDefaultState());
        structure.fillWithBlocks(world, start, 32, 6, 10, 32, 6, 32, Blocks.SAND.getDefaultState());
        structure.fillWithBlocks(world, start, 33, -50, -11, 37, -50, -7, Blocks.SANDSTONE.getDefaultState());
        structure.fillWithBlocks(world, start, 33, -50, 16, 37, -50, 20, Blocks.SANDSTONE.getDefaultState());
        structure.fillWithBlocks(world, start, 33, -49, -71, 33, -49, -71, Blocks.SANDSTONE.getDefaultState());
        structure.fillWithBlocks(world, start, 33, -49, -68, 33, -48, -67, Blocks.AIR.getDefaultState());
        structure.fillWithBlocks(world, start, 33, -49, -66, 33, -49, -66, Blocks.SANDSTONE.getDefaultState());
        structure.fillWithBlocks(world, start, 33, -49, -65, 33, -46, -65, Blocks.AIR.getDefaultState());
        structure.fillWithBlocks(world, start, 33, -49, -63, 33, -46, -63, Blocks.AIR.getDefaultState());
        structure.fillWithBlocks(world, start, 33, -49, -62, 33, -49, -62, Blocks.SANDSTONE.getDefaultState());
        structure.fillWithBlocks(world, start, 33, -49, -61, 33, -48, -60, Blocks.AIR.getDefaultState());
        structure.fillWithBlocks(world, start, 33, -49, -57, 36, -49, -54, Blocks.SANDSTONE.getDefaultState());
        structure.fillWithBlocks(world, start, 33, -49, -47, 33, -49, -47, Blocks.SANDSTONE.getDefaultState());
        structure.fillWithBlocks(world, start, 33, -49, -44, 33, -48, -43, Blocks.AIR.getDefaultState());
        structure.fillWithBlocks(world, start, 33, -49, -42, 33, -49, -42, Blocks.SANDSTONE.getDefaultState());
        structure.fillWithBlocks(world, start, 33, -49, -41, 33, -46, -41, Blocks.AIR.getDefaultState());
        structure.fillWithBlocks(world, start, 33, -49, -39, 33, -46, -39, Blocks.AIR.getDefaultState());
        structure.fillWithBlocks(world, start, 33, -49, -38, 33, -49, -38, Blocks.SANDSTONE.getDefaultState());
        structure.fillWithBlocks(world, start, 33, -49, -37, 33, -48, -36, Blocks.AIR.getDefaultState());
        structure.fillWithBlocks(world, start, 33, -49, -33, 34, -49, -32, Blocks.SANDSTONE.getDefaultState());
        structure.fillWithBlocks(world, start, 33, -49, -12, 38, -49, -12, Blocks.SANDSTONE.getDefaultState());
        structure.fillWithBlocks(world, start, 33, -49, -6, 38, -49, -6, Blocks.SANDSTONE.getDefaultState());
        structure.fillWithBlocks(world, start, 33, -49, 20, 33, -47, 20, Blocks.AIR.getDefaultState());
        structure.fillWithBlocks(world, start, 33, -48, -71, 33, -48, -71, Blocks.SANDSTONE.getDefaultState());
        structure.fillWithBlocks(world, start, 33, -48, -69, 33, -48, -69, Blocks.SANDSTONE.getDefaultState());
        structure.fillWithBlocks(world, start, 33, -48, -66, 33, -48, -66, Blocks.SANDSTONE.getDefaultState());
        structure.fillWithBlocks(world, start, 33, -48, -64, 33, -47, -63, Blocks.AIR.getDefaultState());
        structure.fillWithBlocks(world, start, 33, -48, -62, 33, -48, -62, Blocks.SANDSTONE.getDefaultState());
        structure.fillWithBlocks(world, start, 33, -48, -59, 33, -48, -59, Blocks.SANDSTONE.getDefaultState());
        structure.fillWithBlocks(world, start, 33, -48, -57, 36, -48, -54, Blocks.SANDSTONE.getDefaultState());
        structure.fillWithBlocks(world, start, 33, -48, -47, 33, -48, -47, Blocks.SANDSTONE.getDefaultState());
        structure.fillWithBlocks(world, start, 33, -48, -45, 33, -48, -45, Blocks.SANDSTONE.getDefaultState());
        structure.fillWithBlocks(world, start, 33, -48, -42, 33, -48, -42, Blocks.SANDSTONE.getDefaultState());
        structure.fillWithBlocks(world, start, 33, -48, -40, 33, -47, -39, Blocks.AIR.getDefaultState());
        structure.fillWithBlocks(world, start, 33, -48, -38, 33, -48, -38, Blocks.SANDSTONE.getDefaultState());
        structure.fillWithBlocks(world, start, 33, -48, -35, 33, -48, -35, Blocks.SANDSTONE.getDefaultState());
        structure.fillWithBlocks(world, start, 33, -48, -33, 33, -48, -33, Blocks.SANDSTONE.getDefaultState());
        structure.fillWithBlocks(world, start, 33, -47, -71, 35, -47, -69, Blocks.SANDSTONE.getDefaultState());
        structure.fillWithBlocks(world, start, 33, -47, -68, 33, -46, -67, Blocks.AIR.getDefaultState());
        structure.fillWithBlocks(world, start, 33, -47, -66, 33, -47, -66, Blocks.SANDSTONE.getDefaultState());
        structure.fillWithBlocks(world, start, 33, -47, -62, 33, -47, -62, Blocks.SANDSTONE.getDefaultState());
        structure.fillWithBlocks(world, start, 33, -47, -61, 33, -46, -60, Blocks.AIR.getDefaultState());
        structure.fillWithBlocks(world, start, 33, -47, -59, 33, -47, -59, Blocks.SANDSTONE.getDefaultState());
        structure.fillWithBlocks(world, start, 33, -47, -57, 36, -47, -54, Blocks.SANDSTONE.getDefaultState());
        structure.fillWithBlocks(world, start, 33, -47, -47, 33, -47, -47, Blocks.SANDSTONE.getDefaultState());
        structure.fillWithBlocks(world, start, 33, -47, -44, 33, -46, -43, Blocks.AIR.getDefaultState());
        structure.fillWithBlocks(world, start, 33, -47, -42, 33, -47, -42, Blocks.SANDSTONE.getDefaultState());
        structure.fillWithBlocks(world, start, 33, -47, -38, 33, -47, -38, Blocks.SANDSTONE.getDefaultState());
        structure.fillWithBlocks(world, start, 33, -47, -37, 33, -46, -36, Blocks.AIR.getDefaultState());
        structure.fillWithBlocks(world, start, 33, -47, -33, 34, -47, -32, Blocks.SANDSTONE.getDefaultState());
        structure.fillWithBlocks(world, start, 33, -47, -26, 33, -47, -26, Blocks.SANDSTONE.getDefaultState());
        structure.fillWithBlocks(world, start, 33, -47, -12, 38, -47, -12, Blocks.SANDSTONE.getDefaultState());
        structure.fillWithBlocks(world, start, 33, -47, -6, 38, -47, -6, Blocks.SANDSTONE.getDefaultState());
        structure.fillWithBlocks(world, start, 33, -46, -66, 33, -46, -66, Blocks.SANDSTONE.getDefaultState());
        structure.fillWithBlocks(world, start, 33, -46, -64, 33, -46, -63, Blocks.AIR.getDefaultState());
        structure.fillWithBlocks(world, start, 33, -46, -62, 33, -46, -62, Blocks.SANDSTONE.getDefaultState());
        structure.fillWithBlocks(world, start, 33, -46, -59, 36, -46, -54, Blocks.SANDSTONE.getDefaultState());
        structure.fillWithBlocks(world, start, 33, -46, -50, 36, -46, -45, Blocks.SANDSTONE.getDefaultState());
        structure.fillWithBlocks(world, start, 33, -46, -42, 33, -46, -42, Blocks.SANDSTONE.getDefaultState());
        structure.fillWithBlocks(world, start, 33, -46, -40, 33, -46, -39, Blocks.AIR.getDefaultState());
        structure.fillWithBlocks(world, start, 33, -46, -38, 33, -46, -38, Blocks.SANDSTONE.getDefaultState());
        structure.fillWithBlocks(world, start, 33, -45, -67, 37, -45, -61, Blocks.SANDSTONE.getDefaultState());
        structure.fillWithBlocks(world, start, 33, -45, -43, 36, -45, -30, Blocks.SANDSTONE.getDefaultState());
        structure.fillWithBlocks(world, start, 33, -44, -67, 38, -44, -61, Blocks.SANDSTONE.getDefaultState());
        structure.fillWithBlocks(world, start, 33, -44, -43, 36, -44, -30, Blocks.SANDSTONE.getDefaultState());
        structure.fillWithBlocks(world, start, 33, -43, -74, 46, -43, -61, Blocks.SANDSTONE.getDefaultState());
        structure.fillWithBlocks(world, start, 33, -43, -50, 36, -43, -30, Blocks.SANDSTONE.getDefaultState());
        structure.fillWithBlocks(world, start, 33, -41, -74, 46, -41, -61, Blocks.SANDSTONE.getDefaultState());
        structure.fillWithBlocks(world, start, 33, -41, -60, 36, -41, -54, Blocks.SANDSTONE.getDefaultState());
        structure.fillWithBlocks(world, start, 33, -41, -50, 36, -41, -30, Blocks.SANDSTONE.getDefaultState());
        structure.fillWithBlocks(world, start, 33, -40, -57, 34, -40, -43, Blocks.STONE_BRICKS.getDefaultState());
        structure.fillWithBlocks(world, start, 33, -40, -12, 38, -40, -7, Blocks.STONE_BRICKS.getDefaultState());
        structure.fillWithBlocks(world, start, 33, -40, -6, 35, -38, -6, Blocks.STONE_BRICKS.getDefaultState());
        structure.fillWithBlocks(world, start, 33, -40, 5, 34, -40, 18, Blocks.STONE_BRICKS.getDefaultState());
        structure.fillWithBlocks(world, start, 33, -40, 20, 34, -40, 21, Blocks.STONE_BRICKS.getDefaultState());
        structure.fillWithBlocks(world, start, 33, -40, 23, 34, -40, 35, Blocks.STONE_BRICKS.getDefaultState());
        structure.fillWithBlocks(world, start, 33, -39, -58, 33, -39, -58, Blocks.STONE_BRICKS.getDefaultState());
        structure.fillWithBlocks(world, start, 33, -39, -57, 33, -39, -55, Blocks.IRON_BARS.getDefaultState().with(FourWayBlock.WATERLOGGED, false).with(FourWayBlock.NORTH, true).with(FourWayBlock.SOUTH, true).with(FourWayBlock.EAST, true).with(FourWayBlock.WEST, true));
        structure.fillWithBlocks(world, start, 33, -39, -54, 33, -39, -54, Blocks.STONE_BRICKS.getDefaultState());
        structure.fillWithBlocks(world, start, 33, -39, -53, 33, -39, -49, Blocks.IRON_BARS.getDefaultState().with(FourWayBlock.WATERLOGGED, false).with(FourWayBlock.NORTH, true).with(FourWayBlock.SOUTH, true).with(FourWayBlock.EAST, true).with(FourWayBlock.WEST, true));
        structure.fillWithBlocks(world, start, 33, -39, -48, 33, -39, -48, Blocks.STONE_BRICKS.getDefaultState());
        structure.fillWithBlocks(world, start, 33, -39, -47, 33, -39, -45, Blocks.IRON_BARS.getDefaultState().with(FourWayBlock.WATERLOGGED, false).with(FourWayBlock.NORTH, true).with(FourWayBlock.SOUTH, true).with(FourWayBlock.EAST, true).with(FourWayBlock.WEST, true));
        structure.fillWithBlocks(world, start, 33, -39, -44, 34, -39, -43, Blocks.STONE_BRICKS.getDefaultState());
        structure.fillWithBlocks(world, start, 33, -39, -12, 33, -39, -12, Blocks.STONE_BRICKS.getDefaultState());
        structure.fillWithBlocks(world, start, 33, -39, -11, 33, -39, -7, Blocks.AIR.getDefaultState());
        structure.fillWithBlocks(world, start, 33, -39, 5, 34, -39, 6, Blocks.STONE_BRICKS.getDefaultState());
        structure.fillWithBlocks(world, start, 33, -39, 7, 33, -37, 9, Blocks.STONE_BRICKS.getDefaultState());
        structure.fillWithBlocks(world, start, 33, -39, 10, 33, -39, 10, Blocks.AIR.getDefaultState());
        structure.fillWithBlocks(world, start, 33, -39, 11, 33, -31, 11, Blocks.STONE_BRICKS.getDefaultState());
        structure.fillWithBlocks(world, start, 33, -39, 12, 36, -39, 15, Blocks.AIR.getDefaultState());
        structure.fillWithBlocks(world, start, 33, -39, 16, 33, -36, 19, Blocks.STONE_BRICKS.getDefaultState());
        structure.fillWithBlocks(world, start, 33, -39, 21, 33, -36, 35, Blocks.STONE_BRICKS.getDefaultState());
        structure.fillWithBlocks(world, start, 33, -38, -58, 33, -38, -58, Blocks.STONE_BRICKS.getDefaultState());
        structure.fillWithBlocks(world, start, 33, -38, -57, 33, -36, -55, Blocks.AIR.getDefaultState());
        structure.fillWithBlocks(world, start, 33, -38, -54, 33, -38, -54, Blocks.STONE_BRICKS.getDefaultState());
        structure.fillWithBlocks(world, start, 33, -38, -48, 33, -38, -48, Blocks.STONE_BRICKS.getDefaultState());
        structure.fillWithBlocks(world, start, 33, -38, -47, 33, -36, -45, Blocks.AIR.getDefaultState());
        structure.fillWithBlocks(world, start, 33, -38, -44, 34, -38, -43, Blocks.STONE_BRICKS.getDefaultState());
        structure.fillWithBlocks(world, start, 33, -38, -12, 33, -38, -12, Blocks.STONE_BRICKS.getDefaultState());
        structure.fillWithBlocks(world, start, 33, -38, -11, 33, -38, -7, Blocks.AIR.getDefaultState());
        structure.fillWithBlocks(world, start, 33, -38, 5, 34, -38, 6, Blocks.STONE_BRICKS.getDefaultState());
        structure.fillWithBlocks(world, start, 33, -38, 12, 36, -38, 15, Blocks.AIR.getDefaultState());
        structure.fillWithBlocks(world, start, 33, -37, -58, 33, -37, -58, Blocks.STONE_BRICKS.getDefaultState());
        structure.fillWithBlocks(world, start, 33, -37, -54, 33, -37, -54, Blocks.STONE_BRICKS.getDefaultState());
        structure.fillWithBlocks(world, start, 33, -37, -48, 33, -31, -48, Blocks.STONE_BRICKS.getDefaultState());
        structure.fillWithBlocks(world, start, 33, -37, -44, 34, -37, -43, Blocks.STONE_BRICKS.getDefaultState());
        structure.fillWithBlocks(world, start, 33, -37, -12, 33, -37, -12, Blocks.STONE_BRICKS.getDefaultState());
        structure.fillWithBlocks(world, start, 33, -37, -11, 33, -37, -7, Blocks.AIR.getDefaultState());
        structure.fillWithBlocks(world, start, 33, -37, -6, 37, -37, -6, Blocks.STONE_BRICKS.getDefaultState());
        structure.fillWithBlocks(world, start, 33, -37, 5, 34, -37, 6, Blocks.STONE_BRICKS.getDefaultState());
        structure.fillWithBlocks(world, start, 33, -37, 12, 36, -37, 15, Blocks.AIR.getDefaultState());
        structure.fillWithBlocks(world, start, 33, -36, -58, 33, -36, -58, Blocks.STONE_BRICKS.getDefaultState());
        structure.fillWithBlocks(world, start, 33, -36, -54, 33, -36, -54, Blocks.STONE_BRICKS.getDefaultState());
        structure.fillWithBlocks(world, start, 33, -36, -44, 34, -36, -43, Blocks.STONE_BRICKS.getDefaultState());
        structure.fillWithBlocks(world, start, 33, -36, -12, 36, -36, -8, Blocks.STONE_BRICKS.getDefaultState());
        structure.fillWithBlocks(world, start, 33, -36, -7, 35, -36, -7, Blocks.STONE_BRICKS.getDefaultState());
        structure.fillWithBlocks(world, start, 33, -36, 5, 34, -36, 6, Blocks.STONE_BRICKS.getDefaultState());
        structure.fillWithBlocks(world, start, 33, -36, 7, 33, -32, 11, Blocks.STONE_BRICKS.getDefaultState());
        structure.fillWithBlocks(world, start, 33, -35, -57, 34, -35, -43, Blocks.STONE_BRICKS.getDefaultState());
        structure.fillWithBlocks(world, start, 33, -35, 5, 34, -35, 20, Blocks.STONE_BRICKS.getDefaultState());
        structure.fillWithBlocks(world, start, 33, -35, 22, 34, -35, 25, Blocks.STONE_BRICKS.getDefaultState());
        structure.fillWithBlocks(world, start, 33, -35, 27, 34, -35, 28, Blocks.STONE_BRICKS.getDefaultState());
        structure.fillWithBlocks(world, start, 33, -35, 30, 33, -35, 30, Blocks.STONE_BRICKS.getDefaultState());
        structure.fillWithBlocks(world, start, 33, -35, 32, 34, -35, 35, Blocks.STONE_BRICKS.getDefaultState());
        structure.fillWithBlocks(world, start, 33, -34, -58, 34, -34, -43, Blocks.STONE_BRICKS.getDefaultState());
        structure.fillWithBlocks(world, start, 33, -34, 5, 33, -34, 5, Blocks.STONE_BRICKS.getDefaultState());
        structure.fillWithBlocks(world, start, 33, -34, 13, 34, -34, 14, Blocks.STONE_BRICKS.getDefaultState());
        structure.fillWithBlocks(world, start, 33, -34, 24, 34, -34, 25, Blocks.STONE_BRICKS.getDefaultState());
        structure.fillWithBlocks(world, start, 33, -34, 31, 35, -34, 35, Blocks.STONE_BRICKS.getDefaultState());
        structure.fillWithBlocks(world, start, 33, -33, -56, 33, -33, -55, Blocks.AIR.getDefaultState());
        structure.fillWithBlocks(world, start, 33, -33, -44, 34, -33, -43, Blocks.STONE_BRICKS.getDefaultState());
        structure.fillWithBlocks(world, start, 33, -33, 5, 33, -31, 12, Blocks.STONE_BRICKS.getDefaultState());
        structure.fillWithBlocks(world, start, 33, -33, 15, 35, -33, 17, Blocks.STONE_BRICKS.getDefaultState());
        structure.fillWithBlocks(world, start, 33, -33, 21, 34, -33, 21, Blocks.AIR.getDefaultState());
        structure.fillWithBlocks(world, start, 33, -33, 22, 37, -33, 28, Blocks.STONE_BRICKS.getDefaultState());
        structure.fillWithBlocks(world, start, 33, -33, 30, 35, -33, 32, Blocks.STONE_BRICKS.getDefaultState());
        structure.fillWithBlocks(world, start, 33, -33, 35, 49, -31, 35, Blocks.STONE_BRICKS.getDefaultState());
        structure.fillWithBlocks(world, start, 33, -32, -52, 34, -32, -43, Blocks.STONE_BRICKS.getDefaultState());
        structure.fillWithBlocks(world, start, 33, -32, 13, 33, -32, 13, Blocks.AIR.getDefaultState());
        structure.fillWithBlocks(world, start, 33, -32, 15, 34, -32, 20, Blocks.STONE_BRICKS.getDefaultState());
        structure.fillWithBlocks(world, start, 33, -32, 21, 33, -32, 22, Blocks.AIR.getDefaultState());
        structure.fillWithBlocks(world, start, 33, -32, 23, 34, -32, 29, Blocks.STONE_BRICKS.getDefaultState());
        structure.fillWithBlocks(world, start, 33, -32, 34, 33, -32, 35, Blocks.STONE_BRICKS.getDefaultState());
        structure.fillWithBlocks(world, start, 33, -20, -26, 33, -20, -25, Blocks.AIR.getDefaultState());
        structure.fillWithBlocks(world, start, 33, -20, -23, 33, -20, -23, Blocks.SANDSTONE.getDefaultState());
        structure.fillWithBlocks(world, start, 33, -20, -12, 33, -20, -6, Blocks.SANDSTONE.getDefaultState());
        structure.fillWithBlocks(world, start, 33, -19, -32, 34, -19, -24, Blocks.SANDSTONE.getDefaultState());
        structure.fillWithBlocks(world, start, 33, -19, -12, 33, -16, -12, Blocks.SANDSTONE.getDefaultState());
        structure.fillWithBlocks(world, start, 33, -19, -11, 33, -19, -7, Blocks.AIR.getDefaultState());
        structure.fillWithBlocks(world, start, 33, -19, -6, 33, -16, -6, Blocks.SANDSTONE.getDefaultState());
        structure.fillWithBlocks(world, start, 33, -19, 14, 34, -19, 15, Blocks.SANDSTONE.getDefaultState());
        structure.fillWithBlocks(world, start, 33, -19, 17, 34, -19, 23, Blocks.SANDSTONE.getDefaultState());
        structure.fillWithBlocks(world, start, 33, -19, 27, 34, -19, 33, Blocks.SANDSTONE.getDefaultState());
        structure.fillWithBlocks(world, start, 33, -19, 35, 35, -19, 37, Blocks.SANDSTONE.getDefaultState());
        structure.fillWithBlocks(world, start, 33, -18, -11, 33, -18, -7, Blocks.AIR.getDefaultState());
        structure.fillWithBlocks(world, start, 33, -18, 23, 34, -17, 23, Blocks.SANDSTONE.getDefaultState());
        structure.fillWithBlocks(world, start, 33, -18, 27, 34, -18, 30, Blocks.SANDSTONE.getDefaultState());
        structure.fillWithBlocks(world, start, 33, -18, 32, 35, -18, 34, Blocks.SANDSTONE.getDefaultState());
        structure.fillWithBlocks(world, start, 33, -18, 35, 34, -18, 35, Blocks.AIR.getDefaultState());
        structure.fillWithBlocks(world, start, 33, -18, 36, 33, -18, 36, Blocks.SANDSTONE.getDefaultState());
        structure.fillWithBlocks(world, start, 33, -17, -23, 33, -17, -22, Blocks.AIR.getDefaultState());
        structure.fillWithBlocks(world, start, 33, -17, -21, 34, -17, -20, Blocks.SANDSTONE.getDefaultState());
        structure.fillWithBlocks(world, start, 33, -17, -11, 33, -17, -7, Blocks.AIR.getDefaultState());
        structure.fillWithBlocks(world, start, 33, -17, 16, 35, -17, 18, Blocks.SANDSTONE.getDefaultState());
        structure.fillWithBlocks(world, start, 33, -17, 27, 34, -17, 35, Blocks.SANDSTONE.getDefaultState());
        structure.fillWithBlocks(world, start, 33, -17, 36, 33, -16, 36, Blocks.AIR.getDefaultState());
