package mod.arcalitegames.odyssey.world.structure.structures.forts.neograd;

import mod.arcalitegames.buildersaddition.Index;
import mod.arcalitegames.buildersaddition.blocks.Bookshelf;
import mod.arcalitegames.buildersaddition.blocks.Candle;
import mod.arcalitegames.buildersaddition.blocks.Counter;
import mod.arcalitegames.buildersaddition.blocks.Shelf;
import mod.arcalitegames.buildersaddition.blocks.Table;
import mod.arcalitegames.buildersaddition.blocks.VerticalSlab;
import mod.arcalitegames.buildersaddition.state.VerticalSlabState;
import mod.arcalitegames.odyssey.world.structure.StructureBase;
import net.minecraft.block.AbstractFurnaceBlock;
import net.minecraft.block.BarrelBlock;
import net.minecraft.block.Blocks;
import net.minecraft.block.CampfireBlock;
import net.minecraft.block.ChainBlock;
import net.minecraft.block.ChestBlock;
import net.minecraft.block.FourWayBlock;
import net.minecraft.block.HorizontalBlock;
import net.minecraft.block.LadderBlock;
import net.minecraft.block.LeavesBlock;
import net.minecraft.block.SlabBlock;
import net.minecraft.block.SnowyDirtBlock;
import net.minecraft.block.StairsBlock;
import net.minecraft.block.TrapDoorBlock;
import net.minecraft.block.WallBlock;
import net.minecraft.block.WallHeight;
import net.minecraft.state.properties.ChestType;
import net.minecraft.state.properties.Half;
import net.minecraft.state.properties.SlabType;
import net.minecraft.state.properties.StairsShape;
import net.minecraft.util.Direction;
import net.minecraft.util.math.BlockPos;
import net.minecraft.world.World;

public class NeogradComponent1
{

	public static BlockPos start;
    public static World world;
    public static StructureBase structure;

    public static void init(World worldIn, BlockPos blockPos, StructureBase structureIn)
    {
        world = worldIn; start = blockPos; structure = structureIn;
    }
    
    public static void generatePart11()
    {
        structure.fillWithBlocks(world, start, 42, 27, 98, 42, 29, 98, Blocks.COBBLESTONE.getDefaultState());
        structure.fillWithBlocks(world, start, 42, 29, 86, 42, 29, 87, Blocks.COBBLESTONE.getDefaultState());
        structure.fillWithBlocks(world, start, 43, 0, 5, 48, 0, 130, Blocks.STONE.getDefaultState());
        structure.fillWithBlocks(world, start, 43, 1, 113, 43, 1, 113, Blocks.STONE.getDefaultState());
        structure.fillWithBlocks(world, start, 43, 1, 114, 43, 3, 116, Blocks.DIRT.getDefaultState());
        structure.fillWithBlocks(world, start, 43, 1, 117, 52, 1, 126, Blocks.STONE.getDefaultState());
        structure.fillWithBlocks(world, start, 43, 1, 128, 48, 1, 133, Blocks.DIRT.getDefaultState());
        structure.fillWithBlocks(world, start, 43, 2, 7, 48, 2, 13, Blocks.STONE.getDefaultState());
        structure.fillWithBlocks(world, start, 43, 2, 17, 64, 2, 48, Blocks.DIRT.getDefaultState());
        structure.fillWithBlocks(world, start, 43, 2, 65, 43, 2, 65, Blocks.DIRT.getDefaultState());
        structure.fillWithBlocks(world, start, 43, 2, 66, 43, 2, 76, Blocks.STONE.getDefaultState());
        structure.fillWithBlocks(world, start, 43, 2, 77, 64, 2, 98, Blocks.DIRT.getDefaultState());
        structure.fillWithBlocks(world, start, 43, 2, 99, 45, 2, 101, Blocks.STONE.getDefaultState());
        structure.fillWithBlocks(world, start, 43, 2, 103, 46, 2, 132, Blocks.DIRT.getDefaultState());
        structure.fillWithBlocks(world, start, 43, 6, 23, 46, 6, 27, Blocks.DIRT.getDefaultState());
        structure.fillWithBlocks(world, start, 43, 6, 30, 48, 6, 35, Blocks.GRASS_BLOCK.getDefaultState().with(SnowyDirtBlock.SNOWY, false));
        structure.fillWithBlocks(world, start, 43, 6, 53, 43, 6, 53, Blocks.GRASS_BLOCK.getDefaultState().with(SnowyDirtBlock.SNOWY, false));
        structure.fillWithBlocks(world, start, 43, 6, 54, 43, 6, 56, Blocks.STONE_BRICKS.getDefaultState());
        structure.fillWithBlocks(world, start, 43, 6, 58, 49, 6, 58, Blocks.STONE_BRICKS.getDefaultState());
        structure.fillWithBlocks(world, start, 43, 6, 65, 46, 6, 96, Blocks.DIRT.getDefaultState());
        structure.fillWithBlocks(world, start, 43, 6, 105, 45, 6, 107, Blocks.GRASS_BLOCK.getDefaultState().with(SnowyDirtBlock.SNOWY, false));
        structure.fillWithBlocks(world, start, 43, 6, 108, 44, 6, 114, Blocks.GRASS_BLOCK.getDefaultState().with(SnowyDirtBlock.SNOWY, false));
        structure.fillWithBlocks(world, start, 43, 6, 116, 47, 6, 120, Blocks.DIRT.getDefaultState());
        structure.fillWithBlocks(world, start, 43, 6, 121, 43, 6, 127, Blocks.GRASS_BLOCK.getDefaultState().with(SnowyDirtBlock.SNOWY, false));
        structure.fillWithBlocks(world, start, 43, 7, 23, 46, 7, 26, Blocks.COBBLESTONE.getDefaultState());
        structure.fillWithBlocks(world, start, 43, 7, 36, 43, 11, 36, Blocks.OAK_LOG.getDefaultState());
        structure.fillWithBlocks(world, start, 43, 7, 40, 43, 11, 40, Blocks.OAK_LOG.getDefaultState());
        structure.fillWithBlocks(world, start, 43, 7, 44, 43, 11, 44, Blocks.OAK_LOG.getDefaultState());
        structure.fillWithBlocks(world, start, 43, 7, 48, 43, 11, 48, Blocks.OAK_LOG.getDefaultState());
        structure.fillWithBlocks(world, start, 43, 7, 52, 43, 11, 52, Blocks.OAK_LOG.getDefaultState());
        structure.fillWithBlocks(world, start, 43, 7, 65, 46, 7, 70, Blocks.COBBLESTONE.getDefaultState());
        structure.fillWithBlocks(world, start, 43, 7, 86, 43, 7, 86, Blocks.GRASS_BLOCK.getDefaultState().with(SnowyDirtBlock.SNOWY, false));
        structure.fillWithBlocks(world, start, 43, 7, 97, 43, 7, 98, Blocks.COBBLESTONE.getDefaultState());
        structure.fillWithBlocks(world, start, 43, 7, 104, 43, 12, 104, Blocks.OAK_LOG.getDefaultState());
        structure.fillWithBlocks(world, start, 43, 7, 116, 44, 7, 120, Blocks.COBBLESTONE.getDefaultState());
        structure.fillWithBlocks(world, start, 43, 8, 23, 46, 8, 26, Blocks.COBBLESTONE.getDefaultState());
        structure.fillWithBlocks(world, start, 43, 8, 65, 46, 8, 69, Blocks.COBBLESTONE.getDefaultState());
        structure.fillWithBlocks(world, start, 43, 8, 87, 43, 32, 87, Blocks.STONE_BRICKS.getDefaultState());
        structure.fillWithBlocks(world, start, 43, 8, 97, 43, 32, 97, Blocks.STONE_BRICKS.getDefaultState());
        structure.fillWithBlocks(world, start, 43, 8, 106, 43, 9, 106, Blocks.OAK_LEAVES.getDefaultState().with(LeavesBlock.PERSISTENT, false).with(LeavesBlock.DISTANCE, 3));
        structure.fillWithBlocks(world, start, 43, 8, 107, 43, 9, 107, Blocks.OAK_LEAVES.getDefaultState().with(LeavesBlock.PERSISTENT, false).with(LeavesBlock.DISTANCE, 2));
        structure.fillWithBlocks(world, start, 43, 8, 108, 43, 10, 108, Blocks.OAK_LEAVES.getDefaultState().with(LeavesBlock.PERSISTENT, false).with(LeavesBlock.DISTANCE, 1));
        structure.fillWithBlocks(world, start, 43, 8, 109, 43, 9, 110, Blocks.OAK_LEAVES.getDefaultState().with(LeavesBlock.PERSISTENT, false).with(LeavesBlock.DISTANCE, 2));
        structure.fillWithBlocks(world, start, 43, 8, 117, 44, 8, 119, Blocks.COBBLESTONE.getDefaultState());
        structure.fillWithBlocks(world, start, 43, 9, 23, 46, 9, 26, Blocks.COBBLESTONE.getDefaultState());
        structure.fillWithBlocks(world, start, 43, 9, 65, 46, 9, 68, Blocks.COBBLESTONE.getDefaultState());
        structure.fillWithBlocks(world, start, 43, 9, 111, 43, 11, 111, Blocks.OAK_LEAVES.getDefaultState().with(LeavesBlock.PERSISTENT, false).with(LeavesBlock.DISTANCE, 1));
        structure.fillWithBlocks(world, start, 43, 9, 112, 43, 10, 112, Blocks.OAK_LEAVES.getDefaultState().with(LeavesBlock.PERSISTENT, false).with(LeavesBlock.DISTANCE, 2));
        structure.fillWithBlocks(world, start, 43, 9, 113, 43, 10, 113, Blocks.OAK_LEAVES.getDefaultState().with(LeavesBlock.PERSISTENT, false).with(LeavesBlock.DISTANCE, 3));
        structure.fillWithBlocks(world, start, 43, 9, 118, 43, 9, 118, Blocks.COBBLESTONE.getDefaultState());
        structure.fillWithBlocks(world, start, 43, 10, 23, 46, 10, 26, Blocks.COBBLESTONE.getDefaultState());
        structure.fillWithBlocks(world, start, 43, 10, 37, 43, 10, 39, Blocks.OAK_LOG.getDefaultState());
        structure.fillWithBlocks(world, start, 43, 10, 41, 43, 10, 43, Blocks.OAK_LOG.getDefaultState());
        structure.fillWithBlocks(world, start, 43, 10, 45, 43, 10, 47, Blocks.OAK_LOG.getDefaultState());
        structure.fillWithBlocks(world, start, 43, 10, 49, 43, 10, 51, Blocks.OAK_LOG.getDefaultState());
        structure.fillWithBlocks(world, start, 43, 10, 65, 46, 10, 68, Blocks.COBBLESTONE.getDefaultState());
        structure.fillWithBlocks(world, start, 43, 10, 102, 43, 11, 102, Blocks.OAK_LEAVES.getDefaultState().with(LeavesBlock.PERSISTENT, false).with(LeavesBlock.DISTANCE, 2));
        structure.fillWithBlocks(world, start, 43, 10, 103, 43, 12, 103, Blocks.OAK_LEAVES.getDefaultState().with(LeavesBlock.PERSISTENT, false).with(LeavesBlock.DISTANCE, 1));
        structure.fillWithBlocks(world, start, 43, 10, 105, 43, 12, 105, Blocks.OAK_LEAVES.getDefaultState().with(LeavesBlock.PERSISTENT, false).with(LeavesBlock.DISTANCE, 1));
        structure.fillWithBlocks(world, start, 43, 10, 106, 43, 11, 106, Blocks.OAK_LEAVES.getDefaultState().with(LeavesBlock.PERSISTENT, false).with(LeavesBlock.DISTANCE, 2));
        structure.fillWithBlocks(world, start, 43, 10, 109, 43, 10, 110, Blocks.OAK_LEAVES.getDefaultState().with(LeavesBlock.PERSISTENT, false).with(LeavesBlock.DISTANCE, 2));
        structure.fillWithBlocks(world, start, 43, 10, 118, 43, 10, 118, Blocks.COBBLESTONE.getDefaultState());
        structure.fillWithBlocks(world, start, 43, 10, 124, 43, 11, 124, Blocks.OAK_LEAVES.getDefaultState().with(LeavesBlock.PERSISTENT, false).with(LeavesBlock.DISTANCE, 3));
        structure.fillWithBlocks(world, start, 43, 10, 125, 43, 12, 125, Blocks.OAK_LEAVES.getDefaultState().with(LeavesBlock.PERSISTENT, false).with(LeavesBlock.DISTANCE, 2));
        structure.fillWithBlocks(world, start, 43, 10, 126, 43, 12, 126, Blocks.OAK_LEAVES.getDefaultState().with(LeavesBlock.PERSISTENT, false).with(LeavesBlock.DISTANCE, 1));
        structure.fillWithBlocks(world, start, 43, 10, 127, 43, 11, 127, Blocks.OAK_LEAVES.getDefaultState().with(LeavesBlock.PERSISTENT, false).with(LeavesBlock.DISTANCE, 2));
        structure.fillWithBlocks(world, start, 43, 10, 128, 43, 11, 128, Blocks.OAK_LEAVES.getDefaultState().with(LeavesBlock.PERSISTENT, false).with(LeavesBlock.DISTANCE, 3));
        structure.fillWithBlocks(world, start, 43, 11, 23, 46, 11, 26, Blocks.COBBLESTONE.getDefaultState());
        structure.fillWithBlocks(world, start, 43, 11, 37, 43, 12, 39, Blocks.OAK_PLANKS.getDefaultState());
        structure.fillWithBlocks(world, start, 43, 11, 41, 43, 12, 43, Blocks.OAK_PLANKS.getDefaultState());
        structure.fillWithBlocks(world, start, 43, 11, 45, 43, 12, 47, Blocks.OAK_PLANKS.getDefaultState());
        structure.fillWithBlocks(world, start, 43, 11, 49, 43, 12, 51, Blocks.OAK_PLANKS.getDefaultState());
        structure.fillWithBlocks(world, start, 43, 11, 64, 44, 11, 68, Blocks.COBBLESTONE.getDefaultState());
        structure.fillWithBlocks(world, start, 43, 12, 23, 46, 12, 26, Blocks.COBBLESTONE.getDefaultState());
        structure.fillWithBlocks(world, start, 43, 12, 62, 43, 12, 69, Blocks.COBBLESTONE.getDefaultState());
        structure.fillWithBlocks(world, start, 43, 12, 86, 43, 14, 86, Blocks.COBBLESTONE.getDefaultState());
        structure.fillWithBlocks(world, start, 43, 12, 117, 43, 12, 117, Blocks.COBBLESTONE.getDefaultState());
        structure.fillWithBlocks(world, start, 43, 12, 119, 44, 13, 119, Blocks.COBBLESTONE.getDefaultState());
        structure.fillWithBlocks(world, start, 43, 13, 23, 46, 13, 26, Blocks.COBBLESTONE.getDefaultState());
        structure.fillWithBlocks(world, start, 43, 13, 62, 43, 13, 70, Blocks.COBBLESTONE.getDefaultState());
        structure.fillWithBlocks(world, start, 43, 13, 98, 43, 15, 98, Blocks.COBBLESTONE.getDefaultState());
        structure.fillWithBlocks(world, start, 43, 13, 103, 43, 13, 103, Blocks.OAK_LEAVES.getDefaultState().with(LeavesBlock.PERSISTENT, false).with(LeavesBlock.DISTANCE, 2));
        structure.fillWithBlocks(world, start, 43, 13, 116, 43, 13, 120, Blocks.COBBLESTONE.getDefaultState());
        structure.fillWithBlocks(world, start, 43, 14, 23, 43, 15, 23, Blocks.COBBLESTONE.getDefaultState());
        structure.fillWithBlocks(world, start, 43, 14, 24, 44, 14, 26, Blocks.STONE_BRICKS.getDefaultState());
        structure.fillWithBlocks(world, start, 43, 14, 62, 43, 14, 62, Blocks.COBBLESTONE.getDefaultState());
        structure.fillWithBlocks(world, start, 43, 14, 63, 43, 14, 66, Blocks.STONE_BRICKS.getDefaultState());
        structure.fillWithBlocks(world, start, 43, 14, 67, 44, 14, 69, Blocks.COBBLESTONE.getDefaultState());
        structure.fillWithBlocks(world, start, 43, 14, 88, 45, 14, 96, Blocks.COBBLESTONE.getDefaultState());
        structure.fillWithBlocks(world, start, 43, 14, 116, 43, 14, 120, Blocks.COBBLESTONE.getDefaultState());
        structure.fillWithBlocks(world, start, 43, 15, 62, 43, 15, 62, Blocks.COBBLESTONE_SLAB.getDefaultState().with(SlabBlock.TYPE, SlabType.BOTTOM).with(SlabBlock.WATERLOGGED, false));
        structure.fillWithBlocks(world, start, 43, 15, 66, 43, 15, 67, Blocks.COBBLESTONE.getDefaultState());
        structure.fillWithBlocks(world, start, 43, 15, 69, 43, 15, 70, Blocks.COBBLESTONE.getDefaultState());
        structure.fillWithBlocks(world, start, 43, 15, 91, 45, 15, 94, Blocks.STONE_BRICKS.getDefaultState());
        structure.fillWithBlocks(world, start, 43, 15, 95, 43, 15, 97, Blocks.STONE_BRICKS.getDefaultState());
        structure.fillWithBlocks(world, start, 43, 15, 116, 43, 15, 120, Blocks.COBBLESTONE.getDefaultState());
        structure.fillWithBlocks(world, start, 43, 16, 67, 44, 16, 67, Blocks.COBBLESTONE.getDefaultState());
        structure.fillWithBlocks(world, start, 43, 16, 69, 44, 16, 69, Blocks.COBBLESTONE.getDefaultState());
        structure.fillWithBlocks(world, start, 43, 16, 89, 43, 16, 90, Blocks.STONE_BRICK_SLAB.getDefaultState().with(SlabBlock.TYPE, SlabType.DOUBLE).with(SlabBlock.WATERLOGGED, false));
        structure.fillWithBlocks(world, start, 43, 16, 117, 44, 16, 119, Blocks.COBBLESTONE.getDefaultState());
        structure.fillWithBlocks(world, start, 43, 17, 68, 43, 17, 68, Blocks.COBBLESTONE.getDefaultState());
        structure.fillWithBlocks(world, start, 43, 17, 118, 43, 17, 118, Blocks.COBBLESTONE.getDefaultState());
        structure.fillWithBlocks(world, start, 43, 18, 68, 43, 18, 68, Blocks.COBBLESTONE.getDefaultState());
        structure.fillWithBlocks(world, start, 43, 18, 118, 43, 18, 118, Blocks.COBBLESTONE.getDefaultState());
        structure.fillWithBlocks(world, start, 43, 20, 67, 43, 20, 67, Blocks.COBBLESTONE.getDefaultState());
        structure.fillWithBlocks(world, start, 43, 20, 69, 44, 21, 69, Blocks.COBBLESTONE.getDefaultState());
        structure.fillWithBlocks(world, start, 43, 20, 96, 43, 21, 97, Blocks.STONE_BRICKS.getDefaultState());
        structure.fillWithBlocks(world, start, 43, 20, 117, 43, 20, 117, Blocks.COBBLESTONE.getDefaultState());
        structure.fillWithBlocks(world, start, 43, 20, 119, 44, 21, 119, Blocks.COBBLESTONE.getDefaultState());
        structure.fillWithBlocks(world, start, 43, 21, 66, 43, 21, 70, Blocks.COBBLESTONE.getDefaultState());
        structure.fillWithBlocks(world, start, 43, 21, 86, 43, 22, 86, Blocks.COBBLESTONE.getDefaultState());
        structure.fillWithBlocks(world, start, 43, 21, 116, 43, 21, 120, Blocks.COBBLESTONE.getDefaultState());
        structure.fillWithBlocks(world, start, 43, 22, 67, 43, 22, 67, Blocks.COBBLESTONE.getDefaultState());
        structure.fillWithBlocks(world, start, 43, 22, 69, 44, 22, 69, Blocks.COBBLESTONE.getDefaultState());
        structure.fillWithBlocks(world, start, 43, 22, 92, 44, 22, 92, Blocks.STONE_BRICK_SLAB.getDefaultState().with(SlabBlock.TYPE, SlabType.TOP).with(SlabBlock.WATERLOGGED, false));
        structure.fillWithBlocks(world, start, 43, 22, 93, 44, 22, 95, Blocks.STONE_BRICKS.getDefaultState());
        structure.fillWithBlocks(world, start, 43, 22, 117, 44, 22, 117, Blocks.COBBLESTONE.getDefaultState());
        structure.fillWithBlocks(world, start, 43, 22, 119, 44, 22, 119, Blocks.COBBLESTONE.getDefaultState());
        structure.fillWithBlocks(world, start, 43, 23, 92, 45, 23, 92, Blocks.STONE_BRICKS.getDefaultState());
        structure.fillWithBlocks(world, start, 43, 23, 93, 44, 23, 93, Blocks.STONE_BRICK_STAIRS.getDefaultState().with(StairsBlock.FACING, Direction.NORTH).with(StairsBlock.WATERLOGGED, false).with(StairsBlock.SHAPE, StairsShape.STRAIGHT).with(StairsBlock.HALF, Half.BOTTOM));
        structure.fillWithBlocks(world, start, 43, 23, 95, 43, 23, 96, Blocks.STONE_BRICK_SLAB.getDefaultState().with(SlabBlock.TYPE, SlabType.BOTTOM).with(SlabBlock.WATERLOGGED, false));
        structure.fillWithBlocks(world, start, 43, 24, 92, 45, 24, 92, Blocks.STONE_BRICK_SLAB.getDefaultState().with(SlabBlock.TYPE, SlabType.BOTTOM).with(SlabBlock.WATERLOGGED, false));
        structure.fillWithBlocks(world, start, 43, 25, 88, 43, 25, 89, Blocks.STONE_BRICKS.getDefaultState());
        structure.fillWithBlocks(world, start, 43, 25, 90, 45, 25, 90, Blocks.STONE_BRICK_SLAB.getDefaultState().with(SlabBlock.TYPE, SlabType.BOTTOM).with(SlabBlock.WATERLOGGED, false));
        structure.fillWithBlocks(world, start, 43, 28, 86, 43, 28, 86, Blocks.COBBLESTONE.getDefaultState());
        structure.fillWithBlocks(world, start, 44, 0, 3, 45, 0, 4, Blocks.DIRT.getDefaultState());
        structure.fillWithBlocks(world, start, 44, 1, 4, 46, 1, 6, Blocks.DIRT.getDefaultState());
        structure.fillWithBlocks(world, start, 44, 1, 113, 57, 1, 126, Blocks.STONE.getDefaultState());
        structure.fillWithBlocks(world, start, 44, 2, 4, 46, 2, 6, Blocks.DIRT.getDefaultState());
        structure.fillWithBlocks(world, start, 44, 2, 16, 64, 2, 48, Blocks.DIRT.getDefaultState());
        structure.fillWithBlocks(world, start, 44, 2, 49, 44, 5, 49, Blocks.DIRT.getDefaultState());
        structure.fillWithBlocks(world, start, 44, 2, 50, 47, 2, 53, Blocks.STONE.getDefaultState());
        structure.fillWithBlocks(world, start, 44, 2, 54, 44, 5, 66, Blocks.DIRT.getDefaultState());
        structure.fillWithBlocks(world, start, 44, 2, 67, 44, 2, 76, Blocks.STONE.getDefaultState());
        structure.fillWithBlocks(world, start, 44, 2, 102, 44, 2, 133, Blocks.DIRT.getDefaultState());
        structure.fillWithBlocks(world, start, 44, 3, 129, 46, 3, 132, Blocks.DIRT.getDefaultState());
        structure.fillWithBlocks(world, start, 44, 5, 128, 46, 5, 130, Blocks.GRASS_BLOCK.getDefaultState().with(SnowyDirtBlock.SNOWY, false));
        structure.fillWithBlocks(world, start, 44, 6, 22, 47, 6, 25, Blocks.DIRT.getDefaultState());
        structure.fillWithBlocks(world, start, 44, 6, 29, 48, 6, 35, Blocks.GRASS_BLOCK.getDefaultState().with(SnowyDirtBlock.SNOWY, false));
        structure.fillWithBlocks(world, start, 44, 6, 36, 47, 6, 36, Blocks.GRAVEL.getDefaultState());
        structure.fillWithBlocks(world, start, 44, 6, 37, 44, 6, 40, Blocks.HAY_BLOCK.getDefaultState());
        structure.fillWithBlocks(world, start, 44, 6, 41, 46, 6, 43, Blocks.OAK_PLANKS.getDefaultState());
        structure.fillWithBlocks(world, start, 44, 6, 44, 45, 6, 45, Blocks.HAY_BLOCK.getDefaultState());
        structure.fillWithBlocks(world, start, 44, 6, 46, 44, 6, 52, Blocks.HAY_BLOCK.getDefaultState());
        structure.fillWithBlocks(world, start, 44, 6, 53, 46, 6, 55, Blocks.GRASS_BLOCK.getDefaultState().with(SnowyDirtBlock.SNOWY, false));
        structure.fillWithBlocks(world, start, 44, 6, 56, 44, 6, 56, Blocks.GRASS_BLOCK.getDefaultState().with(SnowyDirtBlock.SNOWY, false));
        structure.fillWithBlocks(world, start, 44, 6, 57, 44, 6, 58, Blocks.STONE_BRICKS.getDefaultState());
        structure.fillWithBlocks(world, start, 44, 6, 59, 45, 6, 59, Blocks.GRASS_BLOCK.getDefaultState().with(SnowyDirtBlock.SNOWY, false));
        structure.fillWithBlocks(world, start, 44, 6, 60, 45, 6, 62, Blocks.STONE_BRICKS.getDefaultState());
        structure.fillWithBlocks(world, start, 44, 6, 64, 46, 6, 96, Blocks.DIRT.getDefaultState());
        structure.fillWithBlocks(world, start, 44, 6, 97, 45, 7, 97, Blocks.COBBLESTONE.getDefaultState());
        structure.fillWithBlocks(world, start, 44, 6, 98, 44, 6, 114, Blocks.GRASS_BLOCK.getDefaultState().with(SnowyDirtBlock.SNOWY, false));
        structure.fillWithBlocks(world, start, 44, 6, 115, 50, 6, 121, Blocks.DIRT.getDefaultState());
        structure.fillWithBlocks(world, start, 44, 6, 122, 44, 6, 127, Blocks.GRASS_BLOCK.getDefaultState().with(SnowyDirtBlock.SNOWY, false));
        structure.fillWithBlocks(world, start, 44, 7, 22, 47, 7, 25, Blocks.COBBLESTONE.getDefaultState());
        structure.fillWithBlocks(world, start, 44, 7, 29, 45, 7, 29, Blocks.GRASS.getDefaultState());
        structure.fillWithBlocks(world, start, 44, 7, 36, 46, 7, 36, Blocks.COBBLESTONE.getDefaultState());
        structure.fillWithBlocks(world, start, 44, 7, 40, 46, 7, 40, Blocks.COBBLESTONE.getDefaultState());
        structure.fillWithBlocks(world, start, 44, 7, 44, 46, 7, 44, Blocks.COBBLESTONE.getDefaultState());
        structure.fillWithBlocks(world, start, 44, 7, 48, 46, 7, 48, Blocks.COBBLESTONE.getDefaultState());
        structure.fillWithBlocks(world, start, 44, 7, 52, 46, 7, 52, Blocks.COBBLESTONE.getDefaultState());
        structure.fillWithBlocks(world, start, 44, 7, 64, 46, 7, 70, Blocks.COBBLESTONE.getDefaultState());
        structure.fillWithBlocks(world, start, 44, 7, 86, 44, 7, 87, Blocks.GRASS_BLOCK.getDefaultState().with(SnowyDirtBlock.SNOWY, false));
        structure.fillWithBlocks(world, start, 44, 7, 88, 44, 7, 88, Blocks.COBBLESTONE.getDefaultState());
        structure.fillWithBlocks(world, start, 44, 7, 89, 44, 7, 95, Blocks.COARSE_DIRT.getDefaultState());
        structure.fillWithBlocks(world, start, 44, 7, 96, 45, 7, 97, Blocks.COBBLESTONE.getDefaultState());
        structure.fillWithBlocks(world, start, 44, 7, 115, 44, 7, 121, Blocks.COBBLESTONE.getDefaultState());
        structure.fillWithBlocks(world, start, 44, 8, 22, 47, 8, 25, Blocks.COBBLESTONE.getDefaultState());
        structure.fillWithBlocks(world, start, 44, 8, 40, 46, 8, 40, Blocks.OAK_FENCE.getDefaultState().with(FourWayBlock.WATERLOGGED, false).with(FourWayBlock.NORTH, false).with(FourWayBlock.SOUTH, false).with(FourWayBlock.EAST, true).with(FourWayBlock.WEST, true));
        structure.fillWithBlocks(world, start, 44, 8, 48, 46, 8, 48, Blocks.OAK_FENCE.getDefaultState().with(FourWayBlock.WATERLOGGED, false).with(FourWayBlock.NORTH, false).with(FourWayBlock.SOUTH, false).with(FourWayBlock.EAST, true).with(FourWayBlock.WEST, true));
        structure.fillWithBlocks(world, start, 44, 8, 52, 45, 8, 52, Blocks.OAK_FENCE.getDefaultState().with(FourWayBlock.WATERLOGGED, false).with(FourWayBlock.NORTH, false).with(FourWayBlock.SOUTH, false).with(FourWayBlock.EAST, true).with(FourWayBlock.WEST, true));
        structure.fillWithBlocks(world, start, 44, 8, 64, 44, 8, 69, Blocks.COBBLESTONE.getDefaultState());
        structure.fillWithBlocks(world, start, 44, 8, 70, 44, 24, 70, Blocks.STONE_BRICKS.getDefaultState());
        structure.fillWithBlocks(world, start, 44, 8, 88, 44, 8, 88, Blocks.COBBLESTONE.getDefaultState());
        structure.fillWithBlocks(world, start, 44, 8, 89, 44, 8, 95, Blocks.COARSE_DIRT.getDefaultState());
        structure.fillWithBlocks(world, start, 44, 8, 96, 45, 8, 97, Blocks.COBBLESTONE.getDefaultState());
        structure.fillWithBlocks(world, start, 44, 8, 106, 44, 9, 106, Blocks.OAK_LEAVES.getDefaultState().with(LeavesBlock.PERSISTENT, false).with(LeavesBlock.DISTANCE, 4));
        structure.fillWithBlocks(world, start, 44, 8, 107, 44, 9, 107, Blocks.OAK_LEAVES.getDefaultState().with(LeavesBlock.PERSISTENT, false).with(LeavesBlock.DISTANCE, 3));
        structure.fillWithBlocks(world, start, 44, 8, 108, 44, 9, 108, Blocks.OAK_LEAVES.getDefaultState().with(LeavesBlock.PERSISTENT, false).with(LeavesBlock.DISTANCE, 2));
        structure.fillWithBlocks(world, start, 44, 8, 109, 44, 10, 109, Blocks.OAK_LEAVES.getDefaultState().with(LeavesBlock.PERSISTENT, false).with(LeavesBlock.DISTANCE, 3));
        structure.fillWithBlocks(world, start, 44, 8, 116, 44, 24, 116, Blocks.STONE_BRICKS.getDefaultState());
        structure.fillWithBlocks(world, start, 44, 8, 120, 44, 24, 120, Blocks.STONE_BRICKS.getDefaultState());
        structure.fillWithBlocks(world, start, 44, 9, 22, 47, 9, 25, Blocks.COBBLESTONE.getDefaultState());
        structure.fillWithBlocks(world, start, 44, 9, 36, 46, 9, 36, Blocks.OAK_LOG.getDefaultState());
        structure.fillWithBlocks(world, start, 44, 9, 40, 46, 9, 40, Blocks.OAK_LOG.getDefaultState());
        structure.fillWithBlocks(world, start, 44, 9, 44, 46, 9, 44, Blocks.OAK_LOG.getDefaultState());
        structure.fillWithBlocks(world, start, 44, 9, 48, 46, 9, 48, Blocks.OAK_LOG.getDefaultState());
        structure.fillWithBlocks(world, start, 44, 9, 52, 46, 9, 52, Blocks.OAK_LOG.getDefaultState());
        structure.fillWithBlocks(world, start, 44, 9, 64, 44, 9, 69, Blocks.COBBLESTONE.getDefaultState());
        structure.fillWithBlocks(world, start, 44, 9, 88, 44, 9, 88, Blocks.COBBLESTONE.getDefaultState());
        structure.fillWithBlocks(world, start, 44, 9, 89, 44, 9, 95, Blocks.COARSE_DIRT.getDefaultState());
        structure.fillWithBlocks(world, start, 44, 9, 96, 44, 9, 97, Blocks.COBBLESTONE.getDefaultState());
        structure.fillWithBlocks(world, start, 44, 9, 110, 44, 10, 110, Blocks.OAK_LEAVES.getDefaultState().with(LeavesBlock.PERSISTENT, false).with(LeavesBlock.DISTANCE, 3));
        structure.fillWithBlocks(world, start, 44, 9, 111, 44, 10, 111, Blocks.OAK_LEAVES.getDefaultState().with(LeavesBlock.PERSISTENT, false).with(LeavesBlock.DISTANCE, 2));
        structure.fillWithBlocks(world, start, 44, 9, 112, 44, 10, 112, Blocks.OAK_LEAVES.getDefaultState().with(LeavesBlock.PERSISTENT, false).with(LeavesBlock.DISTANCE, 3));
        structure.fillWithBlocks(world, start, 44, 9, 113, 44, 10, 113, Blocks.OAK_LEAVES.getDefaultState().with(LeavesBlock.PERSISTENT, false).with(LeavesBlock.DISTANCE, 4));
        structure.fillWithBlocks(world, start, 44, 9, 117, 44, 11, 119, Blocks.COBBLESTONE.getDefaultState());
        structure.fillWithBlocks(world, start, 44, 10, 22, 47, 10, 25, Blocks.COBBLESTONE.getDefaultState());
        structure.fillWithBlocks(world, start, 44, 10, 64, 44, 10, 69, Blocks.COBBLESTONE.getDefaultState());
        structure.fillWithBlocks(world, start, 44, 10, 88, 44, 10, 88, Blocks.COBBLESTONE.getDefaultState());
        structure.fillWithBlocks(world, start, 44, 10, 89, 44, 10, 95, Blocks.COARSE_DIRT.getDefaultState());
        structure.fillWithBlocks(world, start, 44, 10, 96, 44, 10, 97, Blocks.COBBLESTONE.getDefaultState());
        structure.fillWithBlocks(world, start, 44, 10, 102, 44, 11, 102, Blocks.OAK_LEAVES.getDefaultState().with(LeavesBlock.PERSISTENT, false).with(LeavesBlock.DISTANCE, 3));
        structure.fillWithBlocks(world, start, 44, 10, 103, 44, 12, 103, Blocks.OAK_LEAVES.getDefaultState().with(LeavesBlock.PERSISTENT, false).with(LeavesBlock.DISTANCE, 2));
        structure.fillWithBlocks(world, start, 44, 10, 104, 44, 12, 104, Blocks.OAK_LEAVES.getDefaultState().with(LeavesBlock.PERSISTENT, false).with(LeavesBlock.DISTANCE, 1));
        structure.fillWithBlocks(world, start, 44, 10, 105, 44, 12, 105, Blocks.OAK_LEAVES.getDefaultState().with(LeavesBlock.PERSISTENT, false).with(LeavesBlock.DISTANCE, 2));
        structure.fillWithBlocks(world, start, 44, 10, 106, 44, 11, 106, Blocks.OAK_LEAVES.getDefaultState().with(LeavesBlock.PERSISTENT, false).with(LeavesBlock.DISTANCE, 3));
        structure.fillWithBlocks(world, start, 44, 10, 125, 44, 11, 125, Blocks.OAK_LEAVES.getDefaultState().with(LeavesBlock.PERSISTENT, false).with(LeavesBlock.DISTANCE, 3));
        structure.fillWithBlocks(world, start, 44, 10, 126, 44, 11, 126, Blocks.OAK_LEAVES.getDefaultState().with(LeavesBlock.PERSISTENT, false).with(LeavesBlock.DISTANCE, 2));
        structure.fillWithBlocks(world, start, 44, 10, 127, 44, 11, 127, Blocks.OAK_LEAVES.getDefaultState().with(LeavesBlock.PERSISTENT, false).with(LeavesBlock.DISTANCE, 3));
        structure.fillWithBlocks(world, start, 44, 11, 22, 47, 11, 25, Blocks.COBBLESTONE.getDefaultState());
        structure.fillWithBlocks(world, start, 44, 11, 35, 44, 11, 53, Blocks.OAK_SLAB.getDefaultState().with(SlabBlock.TYPE, SlabType.TOP).with(SlabBlock.WATERLOGGED, false));
        structure.fillWithBlocks(world, start, 44, 11, 69, 44, 11, 69, Blocks.COBBLESTONE.getDefaultState());
        structure.fillWithBlocks(world, start, 44, 11, 88, 44, 11, 88, Blocks.COBBLESTONE.getDefaultState());
        structure.fillWithBlocks(world, start, 44, 11, 89, 44, 11, 95, Blocks.COARSE_DIRT.getDefaultState());
        structure.fillWithBlocks(world, start, 44, 11, 96, 44, 11, 97, Blocks.COBBLESTONE.getDefaultState());
        structure.fillWithBlocks(world, start, 44, 12, 22, 47, 12, 25, Blocks.COBBLESTONE.getDefaultState());
        structure.fillWithBlocks(world, start, 44, 12, 35, 44, 12, 53, Blocks.OAK_SLAB.getDefaultState().with(SlabBlock.TYPE, SlabType.BOTTOM).with(SlabBlock.WATERLOGGED, false));
        structure.fillWithBlocks(world, start, 44, 12, 63, 44, 12, 69, Blocks.COBBLESTONE.getDefaultState());
        structure.fillWithBlocks(world, start, 44, 12, 87, 44, 12, 88, Blocks.COBBLESTONE.getDefaultState());
        structure.fillWithBlocks(world, start, 44, 12, 89, 44, 12, 95, Blocks.COARSE_DIRT.getDefaultState());
        structure.fillWithBlocks(world, start, 44, 12, 96, 45, 12, 97, Blocks.COBBLESTONE.getDefaultState());
        structure.fillWithBlocks(world, start, 44, 12, 117, 44, 14, 119, Blocks.COBBLESTONE.getDefaultState());
        structure.fillWithBlocks(world, start, 44, 13, 22, 47, 13, 25, Blocks.COBBLESTONE.getDefaultState());
        structure.fillWithBlocks(world, start, 44, 13, 63, 44, 13, 69, Blocks.COBBLESTONE.getDefaultState());
        structure.fillWithBlocks(world, start, 44, 13, 71, 44, 13, 71, Blocks.COBBLESTONE.getDefaultState());
        structure.fillWithBlocks(world, start, 44, 13, 87, 44, 13, 97, Blocks.COBBLESTONE.getDefaultState());
        structure.fillWithBlocks(world, start, 44, 13, 115, 45, 14, 115, Blocks.COBBLESTONE.getDefaultState());
        structure.fillWithBlocks(world, start, 44, 13, 121, 44, 13, 121, Blocks.COBBLESTONE.getDefaultState());
        structure.fillWithBlocks(world, start, 44, 14, 22, 44, 15, 22, Blocks.COBBLESTONE.getDefaultState());
        structure.fillWithBlocks(world, start, 44, 14, 23, 46, 14, 25, Blocks.STONE_BRICKS.getDefaultState());
        structure.fillWithBlocks(world, start, 44, 14, 27, 44, 14, 28, Blocks.COBBLESTONE.getDefaultState());
        structure.fillWithBlocks(world, start, 44, 14, 63, 44, 14, 63, Blocks.COBBLESTONE.getDefaultState());
        structure.fillWithBlocks(world, start, 44, 14, 64, 44, 14, 66, Blocks.STONE_BRICKS.getDefaultState());
        structure.fillWithBlocks(world, start, 44, 14, 87, 44, 14, 98, Blocks.COBBLESTONE.getDefaultState());
        structure.fillWithBlocks(world, start, 44, 14, 121, 44, 14, 121, Blocks.COBBLESTONE.getDefaultState());
        structure.fillWithBlocks(world, start, 44, 15, 27, 44, 15, 28, Blocks.COBBLESTONE_SLAB.getDefaultState().with(SlabBlock.TYPE, SlabType.BOTTOM).with(SlabBlock.WATERLOGGED, false));
        structure.fillWithBlocks(world, start, 44, 15, 67, 44, 25, 67, Blocks.COBBLESTONE.getDefaultState());
        structure.fillWithBlocks(world, start, 44, 15, 69, 44, 25, 69, Blocks.COBBLESTONE.getDefaultState());
        structure.fillWithBlocks(world, start, 44, 15, 71, 44, 15, 71, Blocks.COBBLESTONE.getDefaultState());
        structure.fillWithBlocks(world, start, 44, 15, 88, 44, 15, 88, Blocks.COBBLESTONE.getDefaultState());
        structure.fillWithBlocks(world, start, 44, 15, 89, 44, 15, 95, Blocks.STONE_BRICKS.getDefaultState());
        structure.fillWithBlocks(world, start, 44, 15, 96, 44, 15, 97, Blocks.COBBLESTONE.getDefaultState());
        structure.fillWithBlocks(world, start, 44, 15, 115, 45, 15, 115, Blocks.COBBLESTONE.getDefaultState());
        structure.fillWithBlocks(world, start, 44, 15, 117, 44, 17, 119, Blocks.COBBLESTONE.getDefaultState());
        structure.fillWithBlocks(world, start, 44, 15, 121, 44, 15, 121, Blocks.COBBLESTONE.getDefaultState());
        structure.fillWithBlocks(world, start, 44, 16, 88, 44, 16, 88, Blocks.COBBLESTONE.getDefaultState());
        structure.fillWithBlocks(world, start, 44, 16, 89, 44, 16, 90, Blocks.STONE_BRICK_SLAB.getDefaultState().with(SlabBlock.TYPE, SlabType.BOTTOM).with(SlabBlock.WATERLOGGED, false));
        structure.fillWithBlocks(world, start, 44, 16, 96, 45, 17, 96, Blocks.COBBLESTONE.getDefaultState());
        structure.fillWithBlocks(world, start, 44, 17, 66, 44, 24, 66, Blocks.STONE_BRICKS.getDefaultState());
        structure.fillWithBlocks(world, start, 44, 17, 68, 44, 18, 69, Blocks.COBBLESTONE.getDefaultState());
        structure.fillWithBlocks(world, start, 44, 17, 88, 44, 17, 88, Blocks.COBBLESTONE.getDefaultState());
        structure.fillWithBlocks(world, start, 44, 18, 88, 44, 33, 88, Blocks.COBBLESTONE.getDefaultState());
        structure.fillWithBlocks(world, start, 44, 18, 96, 44, 33, 96, Blocks.COBBLESTONE.getDefaultState());
        structure.fillWithBlocks(world, start, 44, 18, 117, 44, 20, 119, Blocks.COBBLESTONE.getDefaultState());
        structure.fillWithBlocks(world, start, 44, 19, 68, 44, 20, 69, Blocks.COBBLESTONE.getDefaultState());
        structure.fillWithBlocks(world, start, 44, 20, 95, 44, 22, 95, Blocks.STONE_BRICKS.getDefaultState());
        structure.fillWithBlocks(world, start, 44, 21, 65, 45, 21, 65, Blocks.COBBLESTONE.getDefaultState());
        structure.fillWithBlocks(world, start, 44, 21, 68, 44, 22, 69, Blocks.COBBLESTONE.getDefaultState());
        structure.fillWithBlocks(world, start, 44, 21, 71, 44, 21, 71, Blocks.COBBLESTONE.getDefaultState());
        structure.fillWithBlocks(world, start, 44, 21, 87, 44, 21, 88, Blocks.COBBLESTONE.getDefaultState());
        structure.fillWithBlocks(world, start, 44, 21, 94, 44, 22, 95, Blocks.STONE_BRICKS.getDefaultState());
        structure.fillWithBlocks(world, start, 44, 21, 97, 44, 22, 97, Blocks.COBBLESTONE.getDefaultState());
        structure.fillWithBlocks(world, start, 44, 21, 115, 45, 21, 115, Blocks.COBBLESTONE.getDefaultState());
        structure.fillWithBlocks(world, start, 44, 21, 117, 44, 21, 119, Blocks.COBBLESTONE.getDefaultState());
        structure.fillWithBlocks(world, start, 44, 21, 121, 44, 21, 121, Blocks.COBBLESTONE.getDefaultState());
        structure.fillWithBlocks(world, start, 44, 22, 87, 44, 22, 88, Blocks.COBBLESTONE.getDefaultState());
        structure.fillWithBlocks(world, start, 44, 23, 68, 44, 24, 69, Blocks.COBBLESTONE.getDefaultState());
        structure.fillWithBlocks(world, start, 44, 23, 94, 44, 23, 95, Blocks.STONE_BRICK_SLAB.getDefaultState().with(SlabBlock.TYPE, SlabType.BOTTOM).with(SlabBlock.WATERLOGGED, false));
        structure.fillWithBlocks(world, start, 44, 23, 117, 44, 25, 117, Blocks.COBBLESTONE.getDefaultState());
        structure.fillWithBlocks(world, start, 44, 23, 119, 44, 25, 119, Blocks.COBBLESTONE.getDefaultState());
        structure.fillWithBlocks(world, start, 44, 24, 89, 44, 24, 91, Blocks.STONE_BRICKS.getDefaultState());
        structure.fillWithBlocks(world, start, 44, 25, 68, 44, 25, 69, Blocks.COBBLESTONE.getDefaultState());
        structure.fillWithBlocks(world, start, 44, 25, 118, 44, 25, 119, Blocks.COBBLESTONE.getDefaultState());
        structure.fillWithBlocks(world, start, 44, 28, 87, 44, 28, 88, Blocks.COBBLESTONE.getDefaultState());
        structure.fillWithBlocks(world, start, 45, 2, 49, 47, 2, 56, Blocks.STONE.getDefaultState());
        structure.fillWithBlocks(world, start, 45, 2, 57, 55, 2, 67, Blocks.DIRT.getDefaultState());
        structure.fillWithBlocks(world, start, 45, 2, 68, 45, 2, 76, Blocks.STONE.getDefaultState());
        structure.fillWithBlocks(world, start, 45, 2, 102, 54, 2, 102, Blocks.STONE.getDefaultState());
        structure.fillWithBlocks(world, start, 45, 6, 13, 46, 6, 17, Blocks.DIRT.getDefaultState());
        structure.fillWithBlocks(world, start, 45, 6, 18, 45, 6, 20, Blocks.GRASS_BLOCK.getDefaultState().with(SnowyDirtBlock.SNOWY, false));
        structure.fillWithBlocks(world, start, 45, 6, 21, 48, 6, 24, Blocks.DIRT.getDefaultState());
        structure.fillWithBlocks(world, start, 45, 6, 37, 45, 6, 37, Blocks.HAY_BLOCK.getDefaultState());
        structure.fillWithBlocks(world, start, 45, 6, 39, 46, 6, 40, Blocks.HAY_BLOCK.getDefaultState());
        structure.fillWithBlocks(world, start, 45, 6, 47, 46, 6, 49, Blocks.HAY_BLOCK.getDefaultState());
        structure.fillWithBlocks(world, start, 45, 6, 51, 46, 6, 52, Blocks.HAY_BLOCK.getDefaultState());
        structure.fillWithBlocks(world, start, 45, 6, 56, 45, 6, 57, Blocks.GRASS_BLOCK.getDefaultState().with(SnowyDirtBlock.SNOWY, false));
        structure.fillWithBlocks(world, start, 45, 6, 63, 46, 6, 96, Blocks.DIRT.getDefaultState());
        structure.fillWithBlocks(world, start, 45, 6, 98, 45, 6, 98, Blocks.DIRT.getDefaultState());
        structure.fillWithBlocks(world, start, 45, 6, 99, 45, 6, 102, Blocks.GRASS_BLOCK.getDefaultState().with(SnowyDirtBlock.SNOWY, false));
        structure.fillWithBlocks(world, start, 45, 6, 103, 45, 6, 103, Blocks.DIRT.getDefaultState());
        structure.fillWithBlocks(world, start, 45, 6, 104, 45, 6, 107, Blocks.GRASS_BLOCK.getDefaultState().with(SnowyDirtBlock.SNOWY, false));
        structure.fillWithBlocks(world, start, 45, 6, 108, 45, 6, 108, Blocks.DIRT.getDefaultState());
        structure.fillWithBlocks(world, start, 45, 6, 109, 45, 6, 112, Blocks.GRASS_BLOCK.getDefaultState().with(SnowyDirtBlock.SNOWY, false));
        structure.fillWithBlocks(world, start, 45, 6, 113, 53, 6, 122, Blocks.DIRT.getDefaultState());
        structure.fillWithBlocks(world, start, 45, 6, 123, 45, 6, 127, Blocks.GRASS_BLOCK.getDefaultState().with(SnowyDirtBlock.SNOWY, false));
        structure.fillWithBlocks(world, start, 45, 7, 13, 46, 7, 17, Blocks.COBBLESTONE.getDefaultState());
        structure.fillWithBlocks(world, start, 45, 7, 21, 48, 7, 24, Blocks.COBBLESTONE.getDefaultState());
        structure.fillWithBlocks(world, start, 45, 7, 27, 45, 12, 27, Blocks.STONE_BRICKS.getDefaultState());
        structure.fillWithBlocks(world, start, 45, 7, 71, 45, 7, 72, Blocks.DIRT.getDefaultState());
        structure.fillWithBlocks(world, start, 45, 7, 73, 45, 7, 76, Blocks.GRASS_BLOCK.getDefaultState().with(SnowyDirtBlock.SNOWY, false));
        structure.fillWithBlocks(world, start, 45, 7, 78, 45, 7, 81, Blocks.GRASS_BLOCK.getDefaultState().with(SnowyDirtBlock.SNOWY, false));
        structure.fillWithBlocks(world, start, 45, 7, 83, 45, 7, 86, Blocks.GRASS_BLOCK.getDefaultState().with(SnowyDirtBlock.SNOWY, false));
        structure.fillWithBlocks(world, start, 45, 7, 88, 45, 7, 89, Blocks.COBBLESTONE.getDefaultState());
        structure.fillWithBlocks(world, start, 45, 7, 90, 45, 11, 94, Blocks.COARSE_DIRT.getDefaultState());
        structure.fillWithBlocks(world, start, 45, 7, 95, 45, 8, 97, Blocks.COBBLESTONE.getDefaultState());
        structure.fillWithBlocks(world, start, 45, 7, 114, 45, 8, 115, Blocks.COBBLESTONE.getDefaultState());
        structure.fillWithBlocks(world, start, 45, 7, 116, 49, 7, 120, Blocks.COARSE_DIRT.getDefaultState());
        structure.fillWithBlocks(world, start, 45, 7, 121, 45, 7, 122, Blocks.COBBLESTONE.getDefaultState());
        structure.fillWithBlocks(world, start, 45, 8, 14, 46, 8, 16, Blocks.COBBLESTONE.getDefaultState());
        structure.fillWithBlocks(world, start, 45, 8, 21, 48, 8, 24, Blocks.COBBLESTONE.getDefaultState());
        structure.fillWithBlocks(world, start, 45, 8, 36, 46, 8, 36, Blocks.OAK_FENCE.getDefaultState().with(FourWayBlock.WATERLOGGED, false).with(FourWayBlock.NORTH, false).with(FourWayBlock.SOUTH, false).with(FourWayBlock.EAST, true).with(FourWayBlock.WEST, true));
        structure.fillWithBlocks(world, start, 45, 8, 44, 46, 8, 44, Blocks.OAK_FENCE.getDefaultState().with(FourWayBlock.WATERLOGGED, false).with(FourWayBlock.NORTH, false).with(FourWayBlock.SOUTH, false).with(FourWayBlock.EAST, true).with(FourWayBlock.WEST, true));
        structure.fillWithBlocks(world, start, 45, 8, 64, 45, 11, 64, Blocks.STONE_BRICKS.getDefaultState());
        structure.fillWithBlocks(world, start, 45, 8, 70, 47, 8, 72, Blocks.COBBLESTONE.getDefaultState());
        structure.fillWithBlocks(world, start, 45, 8, 88, 46, 8, 89, Blocks.COBBLESTONE.getDefaultState());
        structure.fillWithBlocks(world, start, 45, 8, 116, 49, 8, 120, Blocks.COARSE_DIRT.getDefaultState());
        structure.fillWithBlocks(world, start, 45, 8, 121, 45, 8, 122, Blocks.COBBLESTONE.getDefaultState());
        structure.fillWithBlocks(world, start, 45, 9, 15, 45, 9, 15, Blocks.COBBLESTONE.getDefaultState());
        structure.fillWithBlocks(world, start, 45, 9, 21, 48, 9, 24, Blocks.COBBLESTONE.getDefaultState());
        structure.fillWithBlocks(world, start, 45, 9, 69, 47, 9, 71, Blocks.COBBLESTONE.getDefaultState());
        structure.fillWithBlocks(world, start, 45, 9, 88, 46, 9, 89, Blocks.COBBLESTONE.getDefaultState());
        structure.fillWithBlocks(world, start, 45, 9, 95, 45, 33, 95, Blocks.COBBLESTONE.getDefaultState());
        structure.fillWithBlocks(world, start, 45, 9, 96, 45, 9, 96, Blocks.COARSE_DIRT.getDefaultState());
        structure.fillWithBlocks(world, start, 45, 9, 97, 45, 12, 97, Blocks.COBBLESTONE.getDefaultState());
        structure.fillWithBlocks(world, start, 45, 9, 115, 45, 25, 115, Blocks.COBBLESTONE.getDefaultState());
        structure.fillWithBlocks(world, start, 45, 9, 116, 49, 9, 120, Blocks.COARSE_DIRT.getDefaultState());
        structure.fillWithBlocks(world, start, 45, 9, 121, 45, 25, 121, Blocks.COBBLESTONE.getDefaultState());
        structure.fillWithBlocks(world, start, 45, 10, 15, 45, 10, 15, Blocks.COBBLESTONE.getDefaultState());
        structure.fillWithBlocks(world, start, 45, 10, 21, 48, 10, 24, Blocks.COBBLESTONE.getDefaultState());
        structure.fillWithBlocks(world, start, 45, 10, 69, 47, 10, 71, Blocks.COBBLESTONE.getDefaultState());
        structure.fillWithBlocks(world, start, 45, 10, 88, 46, 10, 89, Blocks.COBBLESTONE.getDefaultState());
        structure.fillWithBlocks(world, start, 45, 10, 96, 45, 10, 96, Blocks.COARSE_DIRT.getDefaultState());
        structure.fillWithBlocks(world, start, 45, 10, 103, 45, 11, 103, Blocks.OAK_LEAVES.getDefaultState().with(LeavesBlock.PERSISTENT, false).with(LeavesBlock.DISTANCE, 3));
        structure.fillWithBlocks(world, start, 45, 10, 104, 45, 11, 104, Blocks.OAK_LEAVES.getDefaultState().with(LeavesBlock.PERSISTENT, false).with(LeavesBlock.DISTANCE, 2));
        structure.fillWithBlocks(world, start, 45, 10, 105, 45, 11, 105, Blocks.OAK_LEAVES.getDefaultState().with(LeavesBlock.PERSISTENT, false).with(LeavesBlock.DISTANCE, 3));
        structure.fillWithBlocks(world, start, 45, 10, 116, 49, 10, 120, Blocks.COARSE_DIRT.getDefaultState());
        structure.fillWithBlocks(world, start, 45, 11, 21, 48, 11, 24, Blocks.COBBLESTONE.getDefaultState());
        structure.fillWithBlocks(world, start, 45, 11, 35, 45, 11, 53, Blocks.OAK_PLANKS.getDefaultState());
        structure.fillWithBlocks(world, start, 45, 11, 65, 46, 11, 71, Blocks.COBBLESTONE.getDefaultState());
        structure.fillWithBlocks(world, start, 45, 11, 88, 46, 11, 89, Blocks.COBBLESTONE.getDefaultState());
        structure.fillWithBlocks(world, start, 45, 11, 96, 45, 11, 96, Blocks.COARSE_DIRT.getDefaultState());
        structure.fillWithBlocks(world, start, 45, 11, 116, 49, 11, 120, Blocks.COARSE_DIRT.getDefaultState());
        structure.fillWithBlocks(world, start, 45, 12, 14, 45, 12, 14, Blocks.COBBLESTONE.getDefaultState());
        structure.fillWithBlocks(world, start, 45, 12, 16, 46, 13, 16, Blocks.COBBLESTONE.getDefaultState());
        structure.fillWithBlocks(world, start, 45, 12, 21, 48, 12, 24, Blocks.COBBLESTONE.getDefaultState());
        structure.fillWithBlocks(world, start, 45, 12, 64, 46, 12, 72, Blocks.COBBLESTONE.getDefaultState());
        structure.fillWithBlocks(world, start, 45, 12, 88, 45, 12, 89, Blocks.COBBLESTONE.getDefaultState());
        structure.fillWithBlocks(world, start, 45, 12, 90, 45, 13, 91, Blocks.COARSE_DIRT.getDefaultState());
        structure.fillWithBlocks(world, start, 45, 12, 92, 45, 12, 94, Blocks.COARSE_DIRT.getDefaultState());
        structure.fillWithBlocks(world, start, 45, 12, 114, 45, 13, 115, Blocks.COBBLESTONE.getDefaultState());
        structure.fillWithBlocks(world, start, 45, 12, 116, 49, 12, 120, Blocks.COARSE_DIRT.getDefaultState());
        structure.fillWithBlocks(world, start, 45, 12, 122, 46, 13, 122, Blocks.COBBLESTONE.getDefaultState());
        structure.fillWithBlocks(world, start, 45, 13, 13, 45, 13, 17, Blocks.COBBLESTONE.getDefaultState());
        structure.fillWithBlocks(world, start, 45, 13, 21, 48, 13, 24, Blocks.COBBLESTONE.getDefaultState());
        structure.fillWithBlocks(world, start, 45, 13, 64, 46, 13, 72, Blocks.COBBLESTONE.getDefaultState());
        structure.fillWithBlocks(world, start, 45, 13, 88, 45, 13, 89, Blocks.COBBLESTONE.getDefaultState());
        structure.fillWithBlocks(world, start, 45, 13, 92, 45, 13, 92, Blocks.COBBLESTONE.getDefaultState());
        structure.fillWithBlocks(world, start, 45, 13, 93, 45, 13, 94, Blocks.COARSE_DIRT.getDefaultState());
        structure.fillWithBlocks(world, start, 45, 13, 96, 45, 17, 96, Blocks.COBBLESTONE.getDefaultState());
        structure.fillWithBlocks(world, start, 45, 13, 97, 51, 14, 97, Blocks.COARSE_DIRT.getDefaultState());
        structure.fillWithBlocks(world, start, 45, 13, 98, 45, 16, 98, Blocks.COBBLESTONE.getDefaultState());
        structure.fillWithBlocks(world, start, 45, 13, 116, 49, 13, 120, Blocks.COARSE_DIRT.getDefaultState());
        structure.fillWithBlocks(world, start, 45, 14, 13, 45, 14, 17, Blocks.COBBLESTONE.getDefaultState());
        structure.fillWithBlocks(world, start, 45, 14, 21, 45, 15, 21, Blocks.COBBLESTONE.getDefaultState());
        structure.fillWithBlocks(world, start, 45, 14, 22, 47, 14, 24, Blocks.STONE_BRICKS.getDefaultState());
        structure.fillWithBlocks(world, start, 45, 14, 26, 46, 14, 26, Blocks.COBBLESTONE.getDefaultState());
        structure.fillWithBlocks(world, start, 45, 14, 64, 45, 14, 65, Blocks.COBBLESTONE.getDefaultState());
        structure.fillWithBlocks(world, start, 45, 14, 66, 49, 14, 70, Blocks.STONE_BRICKS.getDefaultState());
        structure.fillWithBlocks(world, start, 45, 14, 71, 45, 14, 72, Blocks.COBBLESTONE.getDefaultState());
        structure.fillWithBlocks(world, start, 45, 14, 99, 45, 14, 99, Blocks.COBBLESTONE.getDefaultState());
        structure.fillWithBlocks(world, start, 45, 14, 114, 45, 15, 115, Blocks.COBBLESTONE.getDefaultState());
        structure.fillWithBlocks(world, start, 45, 14, 116, 49, 14, 120, Blocks.STONE_BRICKS.getDefaultState());
        structure.fillWithBlocks(world, start, 45, 14, 122, 45, 14, 122, Blocks.COBBLESTONE.getDefaultState());
        structure.fillWithBlocks(world, start, 45, 15, 13, 45, 15, 14, Blocks.COBBLESTONE.getDefaultState());
        structure.fillWithBlocks(world, start, 45, 15, 16, 45, 15, 17, Blocks.COBBLESTONE.getDefaultState());
        structure.fillWithBlocks(world, start, 45, 15, 26, 46, 15, 26, Blocks.COBBLESTONE_SLAB.getDefaultState().with(SlabBlock.TYPE, SlabType.BOTTOM).with(SlabBlock.WATERLOGGED, false));
        structure.fillWithBlocks(world, start, 45, 15, 64, 46, 16, 64, Blocks.COBBLESTONE.getDefaultState());
        structure.fillWithBlocks(world, start, 45, 15, 71, 45, 15, 72, Blocks.COBBLESTONE.getDefaultState());
        structure.fillWithBlocks(world, start, 45, 15, 88, 45, 15, 89, Blocks.COBBLESTONE.getDefaultState());
        structure.fillWithBlocks(world, start, 45, 15, 97, 45, 15, 97, Blocks.STONE_BRICKS.getDefaultState());
        structure.fillWithBlocks(world, start, 45, 15, 116, 45, 15, 120, Blocks.STONE_BRICKS.getDefaultState());
        structure.fillWithBlocks(world, start, 45, 15, 122, 45, 15, 122, Blocks.COBBLESTONE.getDefaultState());
        structure.fillWithBlocks(world, start, 45, 16, 71, 45, 16, 72, Blocks.COBBLESTONE.getDefaultState());
        structure.fillWithBlocks(world, start, 45, 16, 88, 45, 17, 89, Blocks.COBBLESTONE.getDefaultState());
        structure.fillWithBlocks(world, start, 45, 16, 114, 45, 16, 115, Blocks.COBBLESTONE.getDefaultState());
        structure.fillWithBlocks(world, start, 45, 16, 117, 47, 16, 117, Blocks.STONE_BRICK_SLAB.getDefaultState().with(SlabBlock.TYPE, SlabType.BOTTOM).with(SlabBlock.WATERLOGGED, false));
        structure.fillWithBlocks(world, start, 45, 16, 118, 47, 16, 120, Blocks.STONE_BRICKS.getDefaultState());
        structure.fillWithBlocks(world, start, 45, 16, 122, 46, 16, 122, Blocks.COBBLESTONE.getDefaultState());
        structure.fillWithBlocks(world, start, 45, 17, 15, 45, 18, 15, Blocks.COBBLESTONE.getDefaultState());
        structure.fillWithBlocks(world, start, 45, 17, 65, 45, 25, 65, Blocks.COBBLESTONE.getDefaultState());
        structure.fillWithBlocks(world, start, 45, 17, 71, 45, 25, 71, Blocks.COBBLESTONE.getDefaultState());
        structure.fillWithBlocks(world, start, 45, 17, 119, 47, 17, 119, Blocks.STONE_BRICK_SLAB.getDefaultState().with(SlabBlock.TYPE, SlabType.BOTTOM).with(SlabBlock.WATERLOGGED, false));
        structure.fillWithBlocks(world, start, 45, 17, 120, 45, 17, 120, Blocks.STONE_BRICKS.getDefaultState());
        structure.fillWithBlocks(world, start, 45, 18, 66, 46, 18, 67, Blocks.STONE_BRICKS.getDefaultState());
        structure.fillWithBlocks(world, start, 45, 18, 68, 45, 21, 68, Blocks.STONE_BRICKS.getDefaultState());
        structure.fillWithBlocks(world, start, 45, 18, 89, 45, 33, 89, Blocks.COBBLESTONE.getDefaultState());
        structure.fillWithBlocks(world, start, 45, 19, 66, 47, 19, 68, Blocks.STONE_BRICKS.getDefaultState());
        structure.fillWithBlocks(world, start, 45, 19, 69, 45, 20, 70, Blocks.STONE_BRICKS.getDefaultState());
        structure.fillWithBlocks(world, start, 45, 20, 14, 45, 20, 14, Blocks.COBBLESTONE.getDefaultState());
        structure.fillWithBlocks(world, start, 45, 20, 16, 46, 21, 16, Blocks.COBBLESTONE.getDefaultState());
        structure.fillWithBlocks(world, start, 45, 20, 64, 45, 21, 65, Blocks.COBBLESTONE.getDefaultState());
        structure.fillWithBlocks(world, start, 45, 20, 66, 45, 20, 70, Blocks.STONE_BRICKS.getDefaultState());
        structure.fillWithBlocks(world, start, 45, 20, 72, 46, 21, 72, Blocks.COBBLESTONE.getDefaultState());
        structure.fillWithBlocks(world, start, 45, 20, 114, 45, 21, 115, Blocks.COBBLESTONE.getDefaultState());
        structure.fillWithBlocks(world, start, 45, 20, 122, 46, 21, 122, Blocks.COBBLESTONE.getDefaultState());
        structure.fillWithBlocks(world, start, 45, 21, 13, 45, 21, 17, Blocks.COBBLESTONE.getDefaultState());
        structure.fillWithBlocks(world, start, 45, 21, 67, 45, 21, 67, Blocks.STONE_BRICK_SLAB.getDefaultState().with(SlabBlock.TYPE, SlabType.BOTTOM).with(SlabBlock.WATERLOGGED, false));
        structure.fillWithBlocks(world, start, 45, 21, 69, 46, 21, 70, Blocks.STONE_BRICKS.getDefaultState());
        structure.fillWithBlocks(world, start, 45, 21, 88, 45, 21, 89, Blocks.COBBLESTONE.getDefaultState());
        structure.fillWithBlocks(world, start, 45, 21, 94, 46, 22, 94, Blocks.STONE_BRICKS.getDefaultState());
        structure.fillWithBlocks(world, start, 45, 21, 96, 45, 23, 96, Blocks.COBBLESTONE.getDefaultState());
        structure.fillWithBlocks(world, start, 45, 22, 14, 45, 22, 14, Blocks.COBBLESTONE.getDefaultState());
        structure.fillWithBlocks(world, start, 45, 22, 16, 46, 22, 16, Blocks.COBBLESTONE.getDefaultState());
        structure.fillWithBlocks(world, start, 45, 22, 64, 45, 22, 65, Blocks.COBBLESTONE.getDefaultState());
        structure.fillWithBlocks(world, start, 45, 22, 70, 45, 22, 70, Blocks.STONE_BRICK_SLAB.getDefaultState().with(SlabBlock.TYPE, SlabType.BOTTOM).with(SlabBlock.WATERLOGGED, false));
        structure.fillWithBlocks(world, start, 45, 22, 72, 46, 22, 72, Blocks.COBBLESTONE.getDefaultState());
        structure.fillWithBlocks(world, start, 45, 22, 88, 45, 22, 89, Blocks.COBBLESTONE.getDefaultState());
        structure.fillWithBlocks(world, start, 45, 22, 93, 45, 22, 94, Blocks.STONE_BRICKS.getDefaultState());
        structure.fillWithBlocks(world, start, 45, 22, 114, 45, 22, 115, Blocks.COBBLESTONE.getDefaultState());
        structure.fillWithBlocks(world, start, 45, 22, 122, 46, 22, 122, Blocks.COBBLESTONE.getDefaultState());
        structure.fillWithBlocks(world, start, 45, 23, 88, 45, 23, 89, Blocks.COBBLESTONE.getDefaultState());
        structure.fillWithBlocks(world, start, 45, 23, 93, 45, 23, 94, Blocks.STONE_BRICKS.getDefaultState());
        structure.fillWithBlocks(world, start, 45, 23, 116, 46, 23, 117, Blocks.STONE_BRICKS.getDefaultState());
        structure.fillWithBlocks(world, start, 45, 23, 119, 46, 23, 120, Blocks.STONE_BRICKS.getDefaultState());
        structure.fillWithBlocks(world, start, 45, 24, 66, 54, 24, 66, Blocks.STONE_BRICKS.getDefaultState());
        structure.fillWithBlocks(world, start, 45, 24, 90, 45, 24, 91, Blocks.STONE_BRICKS.getDefaultState());
        structure.fillWithBlocks(world, start, 45, 24, 116, 46, 24, 120, Blocks.STONE_BRICKS.getDefaultState());
        structure.fillWithBlocks(world, start, 45, 27, 88, 45, 28, 89, Blocks.COBBLESTONE.getDefaultState());
        structure.fillWithBlocks(world, start, 45, 27, 96, 45, 29, 96, Blocks.COBBLESTONE.getDefaultState());
        structure.fillWithBlocks(world, start, 45, 29, 88, 45, 29, 89, Blocks.COBBLESTONE.getDefaultState());
        structure.fillWithBlocks(world, start, 45, 32, 90, 45, 32, 94, Blocks.STONE_BRICKS.getDefaultState());
        structure.fillWithBlocks(world, start, 46, 0, 3, 47, 0, 4, Blocks.DIRT.getDefaultState());
        structure.fillWithBlocks(world, start, 46, 0, 131, 48, 0, 133, Blocks.DIRT.getDefaultState());
        structure.fillWithBlocks(world, start, 46, 1, 84, 51, 1, 89, Blocks.DIRT.getDefaultState());
        structure.fillWithBlocks(world, start, 46, 1, 90, 46, 1, 127, Blocks.STONE.getDefaultState());
        structure.fillWithBlocks(world, start, 46, 2, 15, 65, 2, 34, Blocks.DIRT.getDefaultState());
        structure.fillWithBlocks(world, start, 46, 2, 68, 46, 2, 68, Blocks.DIRT.getDefaultState());
        structure.fillWithBlocks(world, start, 46, 2, 69, 46, 2, 76, Blocks.STONE.getDefaultState());
        structure.fillWithBlocks(world, start, 46, 2, 99, 49, 2, 102, Blocks.STONE.getDefaultState());
        structure.fillWithBlocks(world, start, 46, 2, 133, 49, 2, 133, Blocks.GRASS_BLOCK.getDefaultState().with(SnowyDirtBlock.SNOWY, false));
        structure.fillWithBlocks(world, start, 46, 4, 127, 48, 4, 130, Blocks.DIRT.getDefaultState());
        structure.fillWithBlocks(world, start, 46, 6, 12, 46, 6, 18, Blocks.DIRT.getDefaultState());
        structure.fillWithBlocks(world, start, 46, 6, 20, 49, 6, 23, Blocks.DIRT.getDefaultState());
        structure.fillWithBlocks(world, start, 46, 6, 28, 48, 6, 35, Blocks.GRASS_BLOCK.getDefaultState().with(SnowyDirtBlock.SNOWY, false));
        structure.fillWithBlocks(world, start, 46, 6, 37, 46, 6, 40, Blocks.HAY_BLOCK.getDefaultState());
        structure.fillWithBlocks(world, start, 46, 6, 44, 46, 6, 52, Blocks.HAY_BLOCK.getDefaultState());
        structure.fillWithBlocks(world, start, 46, 6, 56, 48, 6, 58, Blocks.STONE_BRICKS.getDefaultState());
        structure.fillWithBlocks(world, start, 46, 6, 59, 46, 6, 60, Blocks.STONE_BRICKS.getDefaultState());
        structure.fillWithBlocks(world, start, 46, 6, 61, 46, 6, 62, Blocks.GRASS_BLOCK.getDefaultState().with(SnowyDirtBlock.SNOWY, false));
        structure.fillWithBlocks(world, start, 46, 6, 97, 52, 6, 123, Blocks.DIRT.getDefaultState());
        structure.fillWithBlocks(world, start, 46, 6, 124, 46, 6, 127, Blocks.GRASS_BLOCK.getDefaultState().with(SnowyDirtBlock.SNOWY, false));
        structure.fillWithBlocks(world, start, 46, 7, 12, 46, 7, 18, Blocks.COBBLESTONE.getDefaultState());
        structure.fillWithBlocks(world, start, 46, 7, 20, 49, 7, 23, Blocks.COBBLESTONE.getDefaultState());
        structure.fillWithBlocks(world, start, 46, 7, 63, 46, 7, 76, Blocks.COBBLESTONE.getDefaultState());
        structure.fillWithBlocks(world, start, 46, 7, 77, 47, 8, 77, Blocks.STONE_BRICKS.getDefaultState());
        structure.fillWithBlocks(world, start, 46, 7, 78, 49, 7, 81, Blocks.COBBLESTONE.getDefaultState());
        structure.fillWithBlocks(world, start, 46, 7, 82, 47, 8, 82, Blocks.STONE_BRICKS.getDefaultState());
        structure.fillWithBlocks(world, start, 46, 7, 83, 49, 7, 86, Blocks.COBBLESTONE.getDefaultState());
        structure.fillWithBlocks(world, start, 46, 7, 87, 47, 8, 87, Blocks.STONE_BRICKS.getDefaultState());
        structure.fillWithBlocks(world, start, 46, 7, 89, 49, 7, 92, Blocks.COBBLESTONE.getDefaultState());
        structure.fillWithBlocks(world, start, 46, 7, 93, 47, 7, 94, Blocks.COBBLESTONE.getDefaultState());
        structure.fillWithBlocks(world, start, 46, 7, 96, 47, 7, 97, Blocks.COARSE_DIRT.getDefaultState());
        structure.fillWithBlocks(world, start, 46, 7, 98, 47, 8, 98, Blocks.STONE_BRICKS.getDefaultState());
        structure.fillWithBlocks(world, start, 46, 7, 99, 49, 7, 102, Blocks.COBBLESTONE.getDefaultState());
        structure.fillWithBlocks(world, start, 46, 7, 103, 47, 8, 103, Blocks.STONE_BRICKS.getDefaultState());
        structure.fillWithBlocks(world, start, 46, 7, 104, 49, 7, 107, Blocks.COBBLESTONE.getDefaultState());
        structure.fillWithBlocks(world, start, 46, 7, 108, 47, 8, 108, Blocks.STONE_BRICKS.getDefaultState());
        structure.fillWithBlocks(world, start, 46, 7, 109, 50, 7, 113, Blocks.COBBLESTONE.getDefaultState());
        structure.fillWithBlocks(world, start, 46, 7, 114, 46, 25, 114, Blocks.COBBLESTONE.getDefaultState());
        structure.fillWithBlocks(world, start, 46, 7, 115, 52, 7, 121, Blocks.COARSE_DIRT.getDefaultState());
        structure.fillWithBlocks(world, start, 46, 7, 122, 46, 7, 123, Blocks.COBBLESTONE.getDefaultState());
        structure.fillWithBlocks(world, start, 46, 8, 13, 46, 8, 13, Blocks.STONE_BRICKS.getDefaultState());
        structure.fillWithBlocks(world, start, 46, 8, 17, 49, 9, 17, Blocks.STONE_BRICKS.getDefaultState());
        structure.fillWithBlocks(world, start, 46, 8, 20, 49, 8, 23, Blocks.COBBLESTONE.getDefaultState());
        structure.fillWithBlocks(world, start, 46, 8, 64, 46, 13, 72, Blocks.COBBLESTONE.getDefaultState());
        structure.fillWithBlocks(world, start, 46, 8, 73, 49, 8, 76, Blocks.COBBLESTONE.getDefaultState());
        structure.fillWithBlocks(world, start, 46, 8, 78, 49, 8, 81, Blocks.COBBLESTONE.getDefaultState());
        structure.fillWithBlocks(world, start, 46, 8, 83, 49, 8, 86, Blocks.COBBLESTONE.getDefaultState());
        structure.fillWithBlocks(world, start, 46, 8, 90, 48, 8, 92, Blocks.COBBLESTONE.getDefaultState());
        structure.fillWithBlocks(world, start, 46, 8, 93, 46, 9, 94, Blocks.COBBLESTONE.getDefaultState());
        structure.fillWithBlocks(world, start, 46, 8, 95, 48, 8, 97, Blocks.COARSE_DIRT.getDefaultState());
        structure.fillWithBlocks(world, start, 46, 8, 99, 49, 8, 102, Blocks.COBBLESTONE.getDefaultState());
        structure.fillWithBlocks(world, start, 46, 8, 104, 49, 8, 107, Blocks.COBBLESTONE.getDefaultState());
        structure.fillWithBlocks(world, start, 46, 8, 109, 49, 8, 112, Blocks.COBBLESTONE.getDefaultState());
        structure.fillWithBlocks(world, start, 46, 8, 113, 46, 12, 113, Blocks.STONE_BRICKS.getDefaultState());
        structure.fillWithBlocks(world, start, 46, 8, 115, 52, 8, 121, Blocks.COARSE_DIRT.getDefaultState());
        structure.fillWithBlocks(world, start, 46, 8, 122, 46, 25, 122, Blocks.COBBLESTONE.getDefaultState());
        structure.fillWithBlocks(world, start, 46, 9, 13, 46, 24, 13, Blocks.STONE_BRICKS.getDefaultState());
        structure.fillWithBlocks(world, start, 46, 9, 14, 46, 11, 16, Blocks.COBBLESTONE.getDefaultState());
        structure.fillWithBlocks(world, start, 46, 9, 20, 49, 9, 23, Blocks.COBBLESTONE.getDefaultState());
        structure.fillWithBlocks(world, start, 46, 9, 73, 46, 9, 73, Blocks.COBBLESTONE.getDefaultState());
        structure.fillWithBlocks(world, start, 46, 9, 74, 46, 9, 75, Blocks.COBBLESTONE_STAIRS.getDefaultState().with(StairsBlock.FACING, Direction.EAST).with(StairsBlock.WATERLOGGED, false).with(StairsBlock.SHAPE, StairsShape.STRAIGHT).with(StairsBlock.HALF, Half.BOTTOM));
        structure.fillWithBlocks(world, start, 46, 9, 76, 51, 10, 76, Blocks.COBBLESTONE.getDefaultState());
        structure.fillWithBlocks(world, start, 46, 9, 77, 47, 10, 77, Blocks.STONE_BRICKS.getDefaultState());
        structure.fillWithBlocks(world, start, 46, 9, 78, 46, 9, 78, Blocks.COBBLESTONE.getDefaultState());
        structure.fillWithBlocks(world, start, 46, 9, 79, 46, 9, 80, Blocks.COBBLESTONE_STAIRS.getDefaultState().with(StairsBlock.FACING, Direction.EAST).with(StairsBlock.WATERLOGGED, false).with(StairsBlock.SHAPE, StairsShape.STRAIGHT).with(StairsBlock.HALF, Half.BOTTOM));
        structure.fillWithBlocks(world, start, 46, 9, 81, 51, 10, 81, Blocks.COBBLESTONE.getDefaultState());
        structure.fillWithBlocks(world, start, 46, 9, 82, 47, 10, 82, Blocks.STONE_BRICKS.getDefaultState());
        structure.fillWithBlocks(world, start, 46, 9, 83, 46, 9, 83, Blocks.COBBLESTONE.getDefaultState());
        structure.fillWithBlocks(world, start, 46, 9, 84, 46, 9, 85, Blocks.COBBLESTONE_STAIRS.getDefaultState().with(StairsBlock.FACING, Direction.EAST).with(StairsBlock.WATERLOGGED, false).with(StairsBlock.SHAPE, StairsShape.STRAIGHT).with(StairsBlock.HALF, Half.BOTTOM));
        structure.fillWithBlocks(world, start, 46, 9, 86, 51, 10, 86, Blocks.COBBLESTONE.getDefaultState());
        structure.fillWithBlocks(world, start, 46, 9, 87, 47, 10, 87, Blocks.STONE_BRICKS.getDefaultState());
        structure.fillWithBlocks(world, start, 46, 9, 90, 48, 9, 92, Blocks.COBBLESTONE.getDefaultState());
        structure.fillWithBlocks(world, start, 46, 9, 95, 48, 9, 97, Blocks.COARSE_DIRT.getDefaultState());
        structure.fillWithBlocks(world, start, 46, 9, 98, 47, 10, 98, Blocks.STONE_BRICKS.getDefaultState());
        structure.fillWithBlocks(world, start, 46, 9, 99, 46, 9, 99, Blocks.COBBLESTONE.getDefaultState());
        structure.fillWithBlocks(world, start, 46, 9, 100, 46, 9, 101, Blocks.COBBLESTONE_STAIRS.getDefaultState().with(StairsBlock.FACING, Direction.EAST).with(StairsBlock.WATERLOGGED, false).with(StairsBlock.SHAPE, StairsShape.STRAIGHT).with(StairsBlock.HALF, Half.BOTTOM));
        structure.fillWithBlocks(world, start, 46, 9, 102, 52, 10, 102, Blocks.COBBLESTONE.getDefaultState());
        structure.fillWithBlocks(world, start, 46, 9, 103, 47, 10, 103, Blocks.STONE_BRICKS.getDefaultState());
        structure.fillWithBlocks(world, start, 46, 9, 104, 46, 9, 104, Blocks.COBBLESTONE.getDefaultState());
        structure.fillWithBlocks(world, start, 46, 9, 105, 46, 9, 106, Blocks.COBBLESTONE_STAIRS.getDefaultState().with(StairsBlock.FACING, Direction.EAST).with(StairsBlock.WATERLOGGED, false).with(StairsBlock.SHAPE, StairsShape.STRAIGHT).with(StairsBlock.HALF, Half.BOTTOM));
        structure.fillWithBlocks(world, start, 46, 9, 107, 52, 10, 107, Blocks.COBBLESTONE.getDefaultState());
        structure.fillWithBlocks(world, start, 46, 9, 108, 47, 10, 108, Blocks.STONE_BRICKS.getDefaultState());
        structure.fillWithBlocks(world, start, 46, 9, 109, 46, 9, 109, Blocks.COBBLESTONE.getDefaultState());
        structure.fillWithBlocks(world, start, 46, 9, 110, 46, 9, 111, Blocks.COBBLESTONE_STAIRS.getDefaultState().with(StairsBlock.FACING, Direction.EAST).with(StairsBlock.WATERLOGGED, false).with(StairsBlock.SHAPE, StairsShape.STRAIGHT).with(StairsBlock.HALF, Half.BOTTOM));
        structure.fillWithBlocks(world, start, 46, 9, 112, 46, 9, 112, Blocks.COBBLESTONE.getDefaultState());
        structure.fillWithBlocks(world, start, 46, 9, 115, 52, 9, 121, Blocks.COARSE_DIRT.getDefaultState());
        structure.fillWithBlocks(world, start, 46, 10, 17, 46, 24, 17, Blocks.STONE_BRICKS.getDefaultState());
        structure.fillWithBlocks(world, start, 46, 10, 20, 49, 10, 23, Blocks.COBBLESTONE.getDefaultState());
        structure.fillWithBlocks(world, start, 46, 10, 35, 46, 10, 53, Blocks.OAK_SLAB.getDefaultState().with(SlabBlock.TYPE, SlabType.TOP).with(SlabBlock.WATERLOGGED, false));
        structure.fillWithBlocks(world, start, 46, 10, 73, 46, 10, 73, Blocks.COBBLESTONE.getDefaultState());
        structure.fillWithBlocks(world, start, 46, 10, 78, 46, 10, 78, Blocks.COBBLESTONE.getDefaultState());
        structure.fillWithBlocks(world, start, 46, 10, 83, 46, 10, 83, Blocks.COBBLESTONE.getDefaultState());
        structure.fillWithBlocks(world, start, 46, 10, 90, 48, 10, 92, Blocks.COBBLESTONE.getDefaultState());
        structure.fillWithBlocks(world, start, 46, 10, 93, 46, 11, 94, Blocks.COBBLESTONE.getDefaultState());
        structure.fillWithBlocks(world, start, 46, 10, 95, 48, 10, 97, Blocks.COARSE_DIRT.getDefaultState());
        structure.fillWithBlocks(world, start, 46, 10, 99, 46, 10, 99, Blocks.COBBLESTONE.getDefaultState());
        structure.fillWithBlocks(world, start, 46, 10, 104, 46, 10, 104, Blocks.COBBLESTONE.getDefaultState());
        structure.fillWithBlocks(world, start, 46, 10, 109, 46, 10, 109, Blocks.COBBLESTONE.getDefaultState());
        structure.fillWithBlocks(world, start, 46, 10, 112, 46, 10, 112, Blocks.COBBLESTONE.getDefaultState());
        structure.fillWithBlocks(world, start, 46, 10, 115, 52, 10, 121, Blocks.COARSE_DIRT.getDefaultState());
        structure.fillWithBlocks(world, start, 46, 11, 20, 49, 11, 23, Blocks.COBBLESTONE.getDefaultState());
        structure.fillWithBlocks(world, start, 46, 11, 35, 46, 11, 53, Blocks.OAK_SLAB.getDefaultState().with(SlabBlock.TYPE, SlabType.BOTTOM).with(SlabBlock.WATERLOGGED, false));
        structure.fillWithBlocks(world, start, 46, 11, 77, 47, 12, 77, Blocks.STONE_BRICKS.getDefaultState());
        structure.fillWithBlocks(world, start, 46, 11, 82, 47, 12, 82, Blocks.STONE_BRICKS.getDefaultState());
        structure.fillWithBlocks(world, start, 46, 11, 87, 47, 12, 87, Blocks.STONE_BRICKS.getDefaultState());
        structure.fillWithBlocks(world, start, 46, 11, 90, 47, 11, 91, Blocks.COBBLESTONE.getDefaultState());
        structure.fillWithBlocks(world, start, 46, 11, 92, 46, 13, 94, Blocks.COBBLESTONE.getDefaultState());
        structure.fillWithBlocks(world, start, 46, 11, 95, 48, 11, 97, Blocks.COARSE_DIRT.getDefaultState());
        structure.fillWithBlocks(world, start, 46, 11, 98, 47, 12, 98, Blocks.STONE_BRICKS.getDefaultState());
        structure.fillWithBlocks(world, start, 46, 11, 103, 47, 12, 103, Blocks.STONE_BRICKS.getDefaultState());
        structure.fillWithBlocks(world, start, 46, 11, 108, 47, 12, 108, Blocks.STONE_BRICKS.getDefaultState());
        structure.fillWithBlocks(world, start, 46, 11, 115, 52, 11, 121, Blocks.COARSE_DIRT.getDefaultState());
        structure.fillWithBlocks(world, start, 46, 12, 14, 46, 14, 16, Blocks.COBBLESTONE.getDefaultState());
        structure.fillWithBlocks(world, start, 46, 12, 20, 49, 12, 23, Blocks.COBBLESTONE.getDefaultState());
        structure.fillWithBlocks(world, start, 46, 12, 89, 48, 12, 91, Blocks.COBBLESTONE.getDefaultState());
        structure.fillWithBlocks(world, start, 46, 12, 95, 48, 12, 97, Blocks.COARSE_DIRT.getDefaultState());
        structure.fillWithBlocks(world, start, 46, 12, 115, 52, 12, 121, Blocks.COARSE_DIRT.getDefaultState());
        structure.fillWithBlocks(world, start, 46, 13, 12, 47, 14, 12, Blocks.COBBLESTONE.getDefaultState());
        structure.fillWithBlocks(world, start, 46, 13, 18, 46, 13, 18, Blocks.COBBLESTONE.getDefaultState());
        structure.fillWithBlocks(world, start, 46, 13, 20, 49, 13, 23, Blocks.COBBLESTONE.getDefaultState());
        structure.fillWithBlocks(world, start, 46, 13, 63, 46, 14, 64, Blocks.COBBLESTONE.getDefaultState());
        structure.fillWithBlocks(world, start, 46, 13, 73, 46, 13, 73, Blocks.COBBLESTONE.getDefaultState());
        structure.fillWithBlocks(world, start, 46, 13, 77, 47, 13, 77, Blocks.STONE_BRICKS.getDefaultState());
        structure.fillWithBlocks(world, start, 46, 13, 89, 49, 13, 92, Blocks.COBBLESTONE.getDefaultState());
        structure.fillWithBlocks(world, start, 46, 13, 96, 47, 13, 97, Blocks.COARSE_DIRT.getDefaultState());
        structure.fillWithBlocks(world, start, 46, 13, 98, 47, 13, 98, Blocks.STONE_BRICKS.getDefaultState());
        structure.fillWithBlocks(world, start, 46, 13, 99, 46, 13, 99, Blocks.COBBLESTONE.getDefaultState());
        structure.fillWithBlocks(world, start, 46, 13, 103, 47, 13, 103, Blocks.STONE_BRICKS.getDefaultState());
        structure.fillWithBlocks(world, start, 46, 13, 108, 47, 13, 108, Blocks.STONE_BRICKS.getDefaultState());
        structure.fillWithBlocks(world, start, 46, 13, 113, 46, 13, 114, Blocks.COBBLESTONE.getDefaultState());
        structure.fillWithBlocks(world, start, 46, 13, 115, 52, 13, 121, Blocks.COARSE_DIRT.getDefaultState());
        structure.fillWithBlocks(world, start, 46, 13, 123, 46, 15, 123, Blocks.COBBLESTONE.getDefaultState());
        structure.fillWithBlocks(world, start, 46, 14, 18, 46, 14, 18, Blocks.COBBLESTONE.getDefaultState());
        structure.fillWithBlocks(world, start, 46, 14, 21, 48, 14, 23, Blocks.STONE_BRICKS.getDefaultState());
        structure.fillWithBlocks(world, start, 46, 14, 65, 52, 14, 71, Blocks.STONE_BRICKS.getDefaultState());
        structure.fillWithBlocks(world, start, 46, 14, 72, 46, 25, 72, Blocks.COBBLESTONE.getDefaultState());
        structure.fillWithBlocks(world, start, 46, 14, 89, 46, 14, 89, Blocks.COBBLESTONE.getDefaultState());
        structure.fillWithBlocks(world, start, 46, 14, 90, 46, 32, 90, Blocks.STONE_BRICKS.getDefaultState());
        structure.fillWithBlocks(world, start, 46, 14, 91, 47, 14, 93, Blocks.COBBLESTONE.getDefaultState());
        structure.fillWithBlocks(world, start, 46, 14, 94, 46, 15, 94, Blocks.COBBLESTONE.getDefaultState());
        structure.fillWithBlocks(world, start, 46, 14, 95, 48, 14, 97, Blocks.COARSE_DIRT.getDefaultState());
        structure.fillWithBlocks(world, start, 46, 14, 98, 46, 15, 98, Blocks.STONE_BRICKS.getDefaultState());
        structure.fillWithBlocks(world, start, 46, 14, 99, 47, 14, 100, Blocks.COBBLESTONE.getDefaultState());
        structure.fillWithBlocks(world, start, 46, 14, 113, 46, 14, 113, Blocks.STONE_BRICKS.getDefaultState());
        structure.fillWithBlocks(world, start, 46, 14, 115, 52, 14, 121, Blocks.STONE_BRICKS.getDefaultState());
        structure.fillWithBlocks(world, start, 46, 15, 12, 47, 15, 12, Blocks.COBBLESTONE.getDefaultState());
        structure.fillWithBlocks(world, start, 46, 15, 18, 46, 15, 18, Blocks.COBBLESTONE.getDefaultState());
        structure.fillWithBlocks(world, start, 46, 15, 63, 46, 15, 64, Blocks.COBBLESTONE.getDefaultState());
        structure.fillWithBlocks(world, start, 46, 15, 65, 50, 18, 65, Blocks.STONE_BRICKS.getDefaultState());
        structure.fillWithBlocks(world, start, 46, 15, 73, 46, 15, 73, Blocks.COBBLESTONE.getDefaultState());
        structure.fillWithBlocks(world, start, 46, 15, 89, 46, 15, 89, Blocks.COBBLESTONE.getDefaultState());
        structure.fillWithBlocks(world, start, 46, 15, 91, 47, 16, 91, Blocks.COBBLESTONE.getDefaultState());
        structure.fillWithBlocks(world, start, 46, 15, 92, 52, 15, 92, Blocks.STONE_BRICKS.getDefaultState());
        structure.fillWithBlocks(world, start, 46, 15, 93, 47, 15, 94, Blocks.COBBLESTONE.getDefaultState());
        structure.fillWithBlocks(world, start, 46, 15, 96, 48, 15, 98, Blocks.STONE_BRICKS.getDefaultState());
        structure.fillWithBlocks(world, start, 46, 15, 99, 46, 16, 99, Blocks.COBBLESTONE.getDefaultState());
        structure.fillWithBlocks(world, start, 46, 15, 113, 46, 15, 114, Blocks.COBBLESTONE.getDefaultState());
        structure.fillWithBlocks(world, start, 46, 15, 115, 47, 15, 115, Blocks.STONE_BRICK_SLAB.getDefaultState().with(SlabBlock.TYPE, SlabType.BOTTOM).with(SlabBlock.WATERLOGGED, false));
        structure.fillWithBlocks(world, start, 46, 15, 116, 46, 15, 116, Blocks.STONE_BRICK_SLAB.getDefaultState().with(SlabBlock.TYPE, SlabType.DOUBLE).with(SlabBlock.WATERLOGGED, false));
        structure.fillWithBlocks(world, start, 46, 15, 117, 46, 15, 121, Blocks.STONE_BRICKS.getDefaultState());
        structure.fillWithBlocks(world, start, 46, 16, 93, 47, 17, 93, Blocks.COBBLESTONE.getDefaultState());
        structure.fillWithBlocks(world, start, 46, 16, 94, 46, 32, 94, Blocks.STONE_BRICKS.getDefaultState());
        structure.fillWithBlocks(world, start, 46, 16, 121, 46, 16, 121, Blocks.STONE_BRICKS.getDefaultState());
        structure.fillWithBlocks(world, start, 46, 17, 14, 46, 25, 14, Blocks.COBBLESTONE.getDefaultState());
        structure.fillWithBlocks(world, start, 46, 17, 16, 46, 25, 16, Blocks.COBBLESTONE.getDefaultState());
        structure.fillWithBlocks(world, start, 46, 17, 64, 46, 25, 64, Blocks.COBBLESTONE.getDefaultState());
        structure.fillWithBlocks(world, start, 46, 17, 91, 47, 17, 91, Blocks.COBBLESTONE.getDefaultState());
        structure.fillWithBlocks(world, start, 46, 17, 120, 47, 17, 121, Blocks.STONE_BRICKS.getDefaultState());
        structure.fillWithBlocks(world, start, 46, 18, 15, 46, 19, 16, Blocks.COBBLESTONE.getDefaultState());
        structure.fillWithBlocks(world, start, 46, 18, 91, 46, 18, 93, Blocks.COBBLESTONE.getDefaultState());
        structure.fillWithBlocks(world, start, 46, 18, 121, 47, 18, 121, Blocks.STONE_BRICK_SLAB.getDefaultState().with(SlabBlock.TYPE, SlabType.BOTTOM).with(SlabBlock.WATERLOGGED, false));
        structure.fillWithBlocks(world, start, 46, 19, 65, 47, 19, 68, Blocks.STONE_BRICKS.getDefaultState());
        structure.fillWithBlocks(world, start, 46, 19, 71, 46, 21, 71, Blocks.STONE_BRICKS.getDefaultState());
        structure.fillWithBlocks(world, start, 46, 19, 91, 46, 21, 93, Blocks.COBBLESTONE.getDefaultState());
        structure.fillWithBlocks(world, start, 46, 20, 15, 46, 21, 16, Blocks.COBBLESTONE.getDefaultState());
        structure.fillWithBlocks(world, start, 46, 20, 65, 46, 20, 66, Blocks.STONE_BRICK_SLAB.getDefaultState().with(SlabBlock.TYPE, SlabType.BOTTOM).with(SlabBlock.WATERLOGGED, false));
        structure.fillWithBlocks(world, start, 46, 20, 67, 46, 20, 71, Blocks.STONE_BRICKS.getDefaultState());
        structure.fillWithBlocks(world, start, 46, 21, 12, 47, 21, 12, Blocks.COBBLESTONE.getDefaultState());
        structure.fillWithBlocks(world, start, 46, 21, 18, 46, 21, 18, Blocks.COBBLESTONE.getDefaultState());
        structure.fillWithBlocks(world, start, 46, 21, 63, 46, 21, 64, Blocks.COBBLESTONE.getDefaultState());
        structure.fillWithBlocks(world, start, 46, 21, 68, 46, 21, 68, Blocks.STONE_BRICK_SLAB.getDefaultState().with(SlabBlock.TYPE, SlabType.BOTTOM).with(SlabBlock.WATERLOGGED, false));
        structure.fillWithBlocks(world, start, 46, 21, 73, 46, 21, 73, Blocks.COBBLESTONE.getDefaultState());
        structure.fillWithBlocks(world, start, 46, 21, 89, 46, 22, 89, Blocks.COBBLESTONE.getDefaultState());
        structure.fillWithBlocks(world, start, 46, 21, 95, 46, 22, 95, Blocks.COBBLESTONE.getDefaultState());
        structure.fillWithBlocks(world, start, 46, 21, 113, 46, 21, 114, Blocks.COBBLESTONE.getDefaultState());
        structure.fillWithBlocks(world, start, 46, 21, 123, 46, 21, 123, Blocks.COBBLESTONE.getDefaultState());
        structure.fillWithBlocks(world, start, 46, 22, 15, 46, 23, 16, Blocks.COBBLESTONE.getDefaultState());
        structure.fillWithBlocks(world, start, 46, 22, 70, 46, 22, 71, Blocks.STONE_BRICK_SLAB.getDefaultState().with(SlabBlock.TYPE, SlabType.BOTTOM).with(SlabBlock.WATERLOGGED, false));
        structure.fillWithBlocks(world, start, 46, 22, 91, 47, 22, 93, Blocks.COBBLESTONE.getDefaultState());
        structure.fillWithBlocks(world, start, 46, 23, 65, 52, 24, 65, Blocks.STONE_BRICKS.getDefaultState());
        structure.fillWithBlocks(world, start, 46, 23, 91, 47, 23, 93, Blocks.COBBLESTONE.getDefaultState());
        structure.fillWithBlocks(world, start, 46, 23, 115, 48, 23, 121, Blocks.STONE_BRICKS.getDefaultState());
        structure.fillWithBlocks(world, start, 46, 24, 15, 46, 25, 16, Blocks.COBBLESTONE.getDefaultState());
        structure.fillWithBlocks(world, start, 46, 24, 91, 46, 24, 93, Blocks.COBBLESTONE.getDefaultState());
        structure.fillWithBlocks(world, start, 46, 24, 115, 46, 24, 121, Blocks.STONE_BRICKS.getDefaultState());
        structure.fillWithBlocks(world, start, 46, 25, 91, 46, 25, 93, Blocks.COBBLESTONE.getDefaultState());
        structure.fillWithBlocks(world, start, 46, 26, 91, 46, 28, 93, Blocks.COBBLESTONE.getDefaultState());
        structure.fillWithBlocks(world, start, 46, 28, 89, 46, 28, 89, Blocks.COBBLESTONE.getDefaultState());
        structure.fillWithBlocks(world, start, 46, 29, 91, 46, 31, 93, Blocks.COBBLESTONE.getDefaultState());
        structure.fillWithBlocks(world, start, 46, 32, 91, 46, 33, 93, Blocks.COBBLESTONE.getDefaultState());
        structure.fillWithBlocks(world, start, 47, 1, 4, 48, 1, 5, Blocks.DIRT.getDefaultState());
        structure.fillWithBlocks(world, start, 47, 1, 6, 49, 1, 81, Blocks.STONE.getDefaultState());
        structure.fillWithBlocks(world, start, 47, 1, 83, 55, 1, 91, Blocks.DIRT.getDefaultState());
        structure.fillWithBlocks(world, start, 47, 1, 92, 47, 1, 126, Blocks.STONE.getDefaultState());
        structure.fillWithBlocks(world, start, 47, 1, 127, 52, 1, 132, Blocks.DIRT.getDefaultState());
        structure.fillWithBlocks(world, start, 47, 2, 4, 49, 2, 6, Blocks.DIRT.getDefaultState());
        structure.fillWithBlocks(world, start, 47, 2, 14, 66, 2, 33, Blocks.DIRT.getDefaultState());
        structure.fillWithBlocks(world, start, 47, 2, 68, 49, 2, 70, Blocks.DIRT.getDefaultState());
        structure.fillWithBlocks(world, start, 47, 2, 71, 47, 2, 75, Blocks.STONE.getDefaultState());
        structure.fillWithBlocks(world, start, 47, 2, 76, 69, 2, 98, Blocks.DIRT.getDefaultState());
        structure.fillWithBlocks(world, start, 47, 2, 103, 53, 2, 103, Blocks.STONE.getDefaultState());
        structure.fillWithBlocks(world, start, 47, 3, 129, 49, 3, 131, Blocks.DIRT.getDefaultState());
        structure.fillWithBlocks(world, start, 47, 3, 132, 53, 3, 132, Blocks.GRASS_BLOCK.getDefaultState().with(SnowyDirtBlock.SNOWY, false));
        structure.fillWithBlocks(world, start, 47, 4, 6, 50, 4, 129, Blocks.DIRT.getDefaultState());
        structure.fillWithBlocks(world, start, 47, 5, 6, 50, 5, 6, Blocks.GRASS_BLOCK.getDefaultState().with(SnowyDirtBlock.SNOWY, false));
        structure.fillWithBlocks(world, start, 47, 5, 127, 49, 5, 129, Blocks.GRASS_BLOCK.getDefaultState().with(SnowyDirtBlock.SNOWY, false));
        structure.fillWithBlocks(world, start, 47, 5, 130, 48, 5, 130, Blocks.GRASS_BLOCK.getDefaultState().with(SnowyDirtBlock.SNOWY, false));
        structure.fillWithBlocks(world, start, 47, 6, 7, 48, 6, 9, Blocks.GRASS_BLOCK.getDefaultState().with(SnowyDirtBlock.SNOWY, false));
        structure.fillWithBlocks(world, start, 47, 6, 11, 47, 7, 12, Blocks.COBBLESTONE.getDefaultState());
        structure.fillWithBlocks(world, start, 47, 6, 13, 49, 6, 15, Blocks.STONE_BRICKS.getDefaultState());
        structure.fillWithBlocks(world, start, 47, 6, 16, 48, 6, 17, Blocks.STONE_BRICKS.getDefaultState());
        structure.fillWithBlocks(world, start, 47, 6, 18, 47, 6, 19, Blocks.COBBLESTONE.getDefaultState());
        structure.fillWithBlocks(world, start, 47, 6, 26, 48, 6, 35, Blocks.GRASS_BLOCK.getDefaultState().with(SnowyDirtBlock.SNOWY, false));
        structure.fillWithBlocks(world, start, 47, 6, 37, 47, 6, 40, Blocks.GRAVEL.getDefaultState());
        structure.fillWithBlocks(world, start, 47, 6, 41, 47, 6, 43, Blocks.OAK_PLANKS.getDefaultState());
        structure.fillWithBlocks(world, start, 47, 6, 44, 47, 6, 52, Blocks.GRAVEL.getDefaultState());
        structure.fillWithBlocks(world, start, 47, 6, 53, 48, 6, 55, Blocks.GRASS_BLOCK.getDefaultState().with(SnowyDirtBlock.SNOWY, false));
        structure.fillWithBlocks(world, start, 47, 6, 59, 49, 6, 61, Blocks.GRASS_BLOCK.getDefaultState().with(SnowyDirtBlock.SNOWY, false));
        structure.fillWithBlocks(world, start, 47, 6, 62, 48, 6, 63, Blocks.DIRT.getDefaultState());
        structure.fillWithBlocks(world, start, 47, 6, 64, 48, 6, 65, Blocks.GRASS_BLOCK.getDefaultState().with(SnowyDirtBlock.SNOWY, false));
        structure.fillWithBlocks(world, start, 47, 6, 66, 47, 6, 77, Blocks.DIRT.getDefaultState());
        structure.fillWithBlocks(world, start, 47, 6, 78, 50, 6, 81, Blocks.COBBLESTONE.getDefaultState());
        structure.fillWithBlocks(world, start, 47, 6, 94, 52, 6, 123, Blocks.DIRT.getDefaultState());
        structure.fillWithBlocks(world, start, 47, 6, 124, 51, 6, 124, Blocks.DIRT.getDefaultState());
        structure.fillWithBlocks(world, start, 47, 6, 125, 48, 6, 126, Blocks.GRASS_BLOCK.getDefaultState().with(SnowyDirtBlock.SNOWY, false));
        structure.fillWithBlocks(world, start, 47, 7, 13, 49, 7, 15, Blocks.STONE_BRICKS.getDefaultState());
        structure.fillWithBlocks(world, start, 47, 7, 16, 48, 7, 17, Blocks.STONE_BRICKS.getDefaultState());
        structure.fillWithBlocks(world, start, 47, 7, 18, 47, 7, 25, Blocks.COBBLESTONE.getDefaultState());
        structure.fillWithBlocks(world, start, 47, 7, 36, 47, 9, 36, Blocks.OAK_LOG.getDefaultState());
        structure.fillWithBlocks(world, start, 47, 7, 37, 47, 7, 39, Blocks.COBBLESTONE.getDefaultState());
        structure.fillWithBlocks(world, start, 47, 7, 40, 47, 9, 40, Blocks.OAK_LOG.getDefaultState());
        structure.fillWithBlocks(world, start, 47, 7, 44, 47, 9, 44, Blocks.OAK_LOG.getDefaultState());
        structure.fillWithBlocks(world, start, 47, 7, 45, 47, 7, 47, Blocks.COBBLESTONE.getDefaultState());
        structure.fillWithBlocks(world, start, 47, 7, 48, 47, 9, 48, Blocks.OAK_LOG.getDefaultState());
        structure.fillWithBlocks(world, start, 47, 7, 49, 47, 7, 51, Blocks.COBBLESTONE.getDefaultState());
        structure.fillWithBlocks(world, start, 47, 7, 52, 47, 9, 52, Blocks.OAK_LOG.getDefaultState());
        structure.fillWithBlocks(world, start, 47, 7, 62, 48, 7, 63, Blocks.COBBLESTONE.getDefaultState());
        structure.fillWithBlocks(world, start, 47, 7, 66, 47, 13, 72, Blocks.COBBLESTONE.getDefaultState());
        structure.fillWithBlocks(world, start, 47, 7, 73, 50, 7, 76, Blocks.COBBLESTONE.getDefaultState());
        structure.fillWithBlocks(world, start, 47, 7, 88, 50, 7, 92, Blocks.COBBLESTONE.getDefaultState());
        structure.fillWithBlocks(world, start, 47, 7, 95, 49, 7, 97, Blocks.COARSE_DIRT.getDefaultState());
        structure.fillWithBlocks(world, start, 47, 7, 114, 51, 7, 122, Blocks.COARSE_DIRT.getDefaultState());
        structure.fillWithBlocks(world, start, 47, 7, 123, 48, 7, 124, Blocks.COBBLESTONE.getDefaultState());
        structure.fillWithBlocks(world, start, 47, 8, 11, 47, 8, 12, Blocks.COBBLESTONE.getDefaultState());
        structure.fillWithBlocks(world, start, 47, 8, 13, 47, 8, 17, Blocks.STONE_BRICKS.getDefaultState());
        structure.fillWithBlocks(world, start, 47, 8, 18, 47, 8, 25, Blocks.COBBLESTONE.getDefaultState());
        structure.fillWithBlocks(world, start, 47, 8, 37, 47, 8, 38, Blocks.OAK_FENCE.getDefaultState().with(FourWayBlock.WATERLOGGED, false).with(FourWayBlock.NORTH, true).with(FourWayBlock.SOUTH, true).with(FourWayBlock.EAST, false).with(FourWayBlock.WEST, false));
        structure.fillWithBlocks(world, start, 47, 8, 45, 47, 8, 47, Blocks.OAK_FENCE.getDefaultState().with(FourWayBlock.WATERLOGGED, false).with(FourWayBlock.NORTH, true).with(FourWayBlock.SOUTH, true).with(FourWayBlock.EAST, false).with(FourWayBlock.WEST, false));
        structure.fillWithBlocks(world, start, 47, 8, 49, 47, 8, 51, Blocks.OAK_FENCE.getDefaultState().with(FourWayBlock.WATERLOGGED, false).with(FourWayBlock.NORTH, true).with(FourWayBlock.SOUTH, true).with(FourWayBlock.EAST, false).with(FourWayBlock.WEST, false));
        structure.fillWithBlocks(world, start, 47, 8, 63, 47, 24, 63, Blocks.STONE_BRICKS.getDefaultState());
        structure.fillWithBlocks(world, start, 47, 8, 88, 50, 8, 92, Blocks.COBBLESTONE.getDefaultState());
        structure.fillWithBlocks(world, start, 47, 8, 94, 50, 8, 97, Blocks.COARSE_DIRT.getDefaultState());
        structure.fillWithBlocks(world, start, 47, 8, 113, 51, 12, 113, Blocks.COBBLESTONE.getDefaultState());
        structure.fillWithBlocks(world, start, 47, 8, 114, 51, 8, 122, Blocks.COARSE_DIRT.getDefaultState());
        structure.fillWithBlocks(world, start, 47, 8, 123, 47, 24, 123, Blocks.STONE_BRICKS.getDefaultState());
        structure.fillWithBlocks(world, start, 47, 8, 125, 47, 9, 125, Blocks.OAK_LEAVES.getDefaultState().with(LeavesBlock.PERSISTENT, false).with(LeavesBlock.DISTANCE, 3));
        structure.fillWithBlocks(world, start, 47, 8, 126, 47, 9, 126, Blocks.OAK_LEAVES.getDefaultState().with(LeavesBlock.PERSISTENT, false).with(LeavesBlock.DISTANCE, 2));
        structure.fillWithBlocks(world, start, 47, 8, 127, 47, 9, 127, Blocks.OAK_LEAVES.getDefaultState().with(LeavesBlock.PERSISTENT, false).with(LeavesBlock.DISTANCE, 3));
        structure.fillWithBlocks(world, start, 47, 9, 12, 47, 25, 12, Blocks.COBBLESTONE.getDefaultState());
        structure.fillWithBlocks(world, start, 47, 9, 13, 48, 9, 14, Blocks.COARSE_DIRT.getDefaultState());
        structure.fillWithBlocks(world, start, 47, 9, 15, 48, 9, 15, Blocks.STONE_BRICK_SLAB.getDefaultState().with(SlabBlock.TYPE, SlabType.BOTTOM).with(SlabBlock.WATERLOGGED, false));
        structure.fillWithBlocks(world, start, 47, 9, 16, 48, 9, 17, Blocks.STONE_BRICKS.getDefaultState());
        structure.fillWithBlocks(world, start, 47, 9, 18, 47, 9, 25, Blocks.COBBLESTONE.getDefaultState());
        structure.fillWithBlocks(world, start, 47, 9, 37, 47, 9, 39, Blocks.OAK_LOG.getDefaultState());
        structure.fillWithBlocks(world, start, 47, 9, 41, 47, 9, 43, Blocks.OAK_LOG.getDefaultState());
        structure.fillWithBlocks(world, start, 47, 9, 45, 47, 9, 47, Blocks.OAK_LOG.getDefaultState());
        structure.fillWithBlocks(world, start, 47, 9, 49, 47, 9, 51, Blocks.OAK_LOG.getDefaultState());
        structure.fillWithBlocks(world, start, 47, 9, 73, 50, 9, 76, Blocks.COBBLESTONE.getDefaultState());
        structure.fillWithBlocks(world, start, 47, 9, 78, 50, 9, 81, Blocks.COBBLESTONE.getDefaultState());
        structure.fillWithBlocks(world, start, 47, 9, 83, 50, 9, 86, Blocks.COBBLESTONE.getDefaultState());
        structure.fillWithBlocks(world, start, 47, 9, 88, 50, 9, 92, Blocks.COBBLESTONE.getDefaultState());
        structure.fillWithBlocks(world, start, 47, 9, 93, 51, 9, 97, Blocks.COARSE_DIRT.getDefaultState());
        structure.fillWithBlocks(world, start, 47, 9, 99, 50, 9, 102, Blocks.COBBLESTONE.getDefaultState());
        structure.fillWithBlocks(world, start, 47, 9, 104, 50, 9, 107, Blocks.COBBLESTONE.getDefaultState());
        structure.fillWithBlocks(world, start, 47, 9, 109, 51, 9, 113, Blocks.COBBLESTONE.getDefaultState());
        structure.fillWithBlocks(world, start, 47, 9, 114, 51, 9, 122, Blocks.COARSE_DIRT.getDefaultState());
        structure.fillWithBlocks(world, start, 47, 10, 11, 47, 11, 12, Blocks.COBBLESTONE.getDefaultState());
        structure.fillWithBlocks(world, start, 47, 10, 13, 49, 10, 16, Blocks.COARSE_DIRT.getDefaultState());
        structure.fillWithBlocks(world, start, 47, 10, 17, 48, 11, 17, Blocks.COARSE_DIRT.getDefaultState());
        structure.fillWithBlocks(world, start, 47, 10, 18, 47, 10, 25, Blocks.COBBLESTONE.getDefaultState());
        structure.fillWithBlocks(world, start, 47, 10, 35, 47, 10, 53, Blocks.OAK_PLANKS.getDefaultState());
        structure.fillWithBlocks(world, start, 47, 10, 73, 47, 24, 73, Blocks.STONE_BRICKS.getDefaultState());
        structure.fillWithBlocks(world, start, 47, 10, 74, 49, 10, 76, Blocks.COBBLESTONE.getDefaultState());
        structure.fillWithBlocks(world, start, 47, 10, 78, 50, 10, 81, Blocks.COBBLESTONE.getDefaultState());
        structure.fillWithBlocks(world, start, 47, 10, 83, 50, 10, 86, Blocks.COBBLESTONE.getDefaultState());
        structure.fillWithBlocks(world, start, 47, 10, 88, 50, 10, 92, Blocks.COBBLESTONE.getDefaultState());
        structure.fillWithBlocks(world, start, 47, 10, 93, 51, 10, 97, Blocks.COARSE_DIRT.getDefaultState());
        structure.fillWithBlocks(world, start, 47, 10, 99, 50, 10, 102, Blocks.COBBLESTONE.getDefaultState());
        structure.fillWithBlocks(world, start, 47, 10, 104, 50, 10, 107, Blocks.COBBLESTONE.getDefaultState());
        structure.fillWithBlocks(world, start, 47, 10, 109, 51, 10, 113, Blocks.COBBLESTONE.getDefaultState());
        structure.fillWithBlocks(world, start, 47, 10, 114, 51, 10, 122, Blocks.COARSE_DIRT.getDefaultState());
        structure.fillWithBlocks(world, start, 47, 11, 13, 49, 11, 16, Blocks.COARSE_DIRT.getDefaultState());
        structure.fillWithBlocks(world, start, 47, 11, 18, 49, 11, 23, Blocks.COBBLESTONE.getDefaultState());
        structure.fillWithBlocks(world, start, 47, 11, 74, 49, 11, 76, Blocks.COBBLESTONE.getDefaultState());
        structure.fillWithBlocks(world, start, 47, 11, 78, 50, 11, 81, Blocks.COBBLESTONE.getDefaultState());
        structure.fillWithBlocks(world, start, 47, 11, 83, 50, 11, 86, Blocks.COBBLESTONE.getDefaultState());
        structure.fillWithBlocks(world, start, 47, 11, 88, 50, 11, 91, Blocks.COBBLESTONE.getDefaultState());
        structure.fillWithBlocks(world, start, 47, 11, 92, 47, 12, 92, Blocks.STONE_BRICKS.getDefaultState());
        structure.fillWithBlocks(world, start, 47, 11, 93, 51, 11, 97, Blocks.COARSE_DIRT.getDefaultState());
        structure.fillWithBlocks(world, start, 47, 11, 99, 50, 11, 102, Blocks.COBBLESTONE.getDefaultState());
        structure.fillWithBlocks(world, start, 47, 11, 104, 50, 11, 107, Blocks.COBBLESTONE.getDefaultState());
        structure.fillWithBlocks(world, start, 47, 11, 109, 51, 11, 113, Blocks.COBBLESTONE.getDefaultState());
        structure.fillWithBlocks(world, start, 47, 11, 114, 51, 11, 122, Blocks.COARSE_DIRT.getDefaultState());
        structure.fillWithBlocks(world, start, 47, 12, 11, 47, 13, 12, Blocks.COBBLESTONE.getDefaultState());
        structure.fillWithBlocks(world, start, 47, 12, 13, 49, 12, 16, Blocks.COARSE_DIRT.getDefaultState());
        structure.fillWithBlocks(world, start, 47, 12, 17, 48, 12, 17, Blocks.COARSE_DIRT.getDefaultState());
        structure.fillWithBlocks(world, start, 47, 12, 18, 50, 12, 21, Blocks.COBBLESTONE.getDefaultState());
        structure.fillWithBlocks(world, start, 47, 12, 74, 49, 12, 76, Blocks.COBBLESTONE.getDefaultState());
        structure.fillWithBlocks(world, start, 47, 12, 78, 50, 12, 81, Blocks.COBBLESTONE.getDefaultState());
        structure.fillWithBlocks(world, start, 47, 12, 83, 50, 12, 86, Blocks.COBBLESTONE.getDefaultState());
        structure.fillWithBlocks(world, start, 47, 12, 88, 50, 12, 91, Blocks.COBBLESTONE.getDefaultState());
        structure.fillWithBlocks(world, start, 47, 12, 93, 47, 17, 93, Blocks.COBBLESTONE.getDefaultState());
        structure.fillWithBlocks(world, start, 47, 12, 94, 50, 12, 97, Blocks.COARSE_DIRT.getDefaultState());
        structure.fillWithBlocks(world, start, 47, 12, 99, 50, 12, 102, Blocks.COBBLESTONE.getDefaultState());
        structure.fillWithBlocks(world, start, 47, 12, 104, 50, 12, 107, Blocks.COBBLESTONE.getDefaultState());
        structure.fillWithBlocks(world, start, 47, 12, 109, 51, 12, 113, Blocks.COBBLESTONE.getDefaultState());
        structure.fillWithBlocks(world, start, 47, 12, 114, 51, 12, 122, Blocks.COARSE_DIRT.getDefaultState());
        structure.fillWithBlocks(world, start, 47, 13, 13, 48, 13, 14, Blocks.STONE_BRICKS.getDefaultState());
        structure.fillWithBlocks(world, start, 47, 13, 16, 48, 13, 17, Blocks.STONE_BRICKS.getDefaultState());
        structure.fillWithBlocks(world, start, 47, 13, 18, 47, 13, 25, Blocks.COBBLESTONE.getDefaultState());
        structure.fillWithBlocks(world, start, 47, 13, 62, 47, 13, 62, Blocks.COBBLESTONE.getDefaultState());
        structure.fillWithBlocks(world, start, 47, 13, 74, 49, 13, 76, Blocks.COBBLESTONE.getDefaultState());
        structure.fillWithBlocks(world, start, 47, 13, 78, 50, 13, 81, Blocks.COBBLESTONE.getDefaultState());
        structure.fillWithBlocks(world, start, 47, 13, 83, 50, 13, 86, Blocks.COBBLESTONE.getDefaultState());
        structure.fillWithBlocks(world, start, 47, 13, 88, 50, 13, 92, Blocks.COBBLESTONE.getDefaultState());
        structure.fillWithBlocks(world, start, 47, 13, 95, 49, 13, 97, Blocks.COARSE_DIRT.getDefaultState());
        structure.fillWithBlocks(world, start, 47, 13, 99, 50, 13, 102, Blocks.COBBLESTONE.getDefaultState());
        structure.fillWithBlocks(world, start, 47, 13, 104, 50, 13, 107, Blocks.COBBLESTONE.getDefaultState());
        structure.fillWithBlocks(world, start, 47, 13, 109, 51, 13, 113, Blocks.COBBLESTONE.getDefaultState());
        structure.fillWithBlocks(world, start, 47, 13, 114, 51, 13, 122, Blocks.COARSE_DIRT.getDefaultState());
        structure.fillWithBlocks(world, start, 47, 13, 124, 51, 15, 124, Blocks.COBBLESTONE.getDefaultState());
        structure.fillWithBlocks(world, start, 47, 14, 11, 47, 15, 12, Blocks.COBBLESTONE.getDefaultState());
        structure.fillWithBlocks(world, start, 47, 14, 13, 51, 14, 17, Blocks.STONE_BRICKS.getDefaultState());
        structure.fillWithBlocks(world, start, 47, 14, 18, 47, 15, 19, Blocks.COBBLESTONE.getDefaultState());
        structure.fillWithBlocks(world, start, 47, 14, 20, 48, 14, 23, Blocks.STONE_BRICKS.getDefaultState());
        structure.fillWithBlocks(world, start, 47, 14, 62, 47, 14, 62, Blocks.COBBLESTONE.getDefaultState());
        structure.fillWithBlocks(world, start, 47, 14, 64, 51, 14, 72, Blocks.STONE_BRICKS.getDefaultState());
        structure.fillWithBlocks(world, start, 47, 14, 74, 47, 14, 93, Blocks.COBBLESTONE.getDefaultState());
        structure.fillWithBlocks(world, start, 47, 14, 94, 50, 14, 97, Blocks.COARSE_DIRT.getDefaultState());
        structure.fillWithBlocks(world, start, 47, 14, 98, 48, 14, 99, Blocks.COBBLESTONE.getDefaultState());
        structure.fillWithBlocks(world, start, 47, 14, 101, 47, 14, 113, Blocks.COBBLESTONE.getDefaultState());
        structure.fillWithBlocks(world, start, 47, 14, 114, 51, 14, 122, Blocks.STONE_BRICKS.getDefaultState());
        structure.fillWithBlocks(world, start, 47, 15, 13, 49, 15, 15, Blocks.STONE_BRICKS.getDefaultState());
        structure.fillWithBlocks(world, start, 47, 15, 16, 47, 16, 17, Blocks.STONE_BRICKS.getDefaultState());
        structure.fillWithBlocks(world, start, 47, 15, 62, 48, 15, 62, Blocks.COBBLESTONE.getDefaultState());
        structure.fillWithBlocks(world, start, 47, 15, 64, 48, 15, 65, Blocks.STONE_BRICKS.getDefaultState());
        structure.fillWithBlocks(world, start, 47, 15, 66, 48, 15, 66, Blocks.FURNACE.getDefaultState().with(AbstractFurnaceBlock.FACING, Direction.SOUTH).with(AbstractFurnaceBlock.LIT, false));
        structure.fillWithBlocks(world, start, 47, 15, 74, 48, 15, 74, Blocks.COBBLESTONE.getDefaultState());
        structure.fillWithBlocks(world, start, 47, 15, 75, 47, 15, 76, Blocks.COBBLESTONE_SLAB.getDefaultState().with(SlabBlock.TYPE, SlabType.BOTTOM).with(SlabBlock.WATERLOGGED, false));
        structure.fillWithBlocks(world, start, 47, 15, 77, 47, 15, 79, Blocks.COBBLESTONE.getDefaultState());
        structure.fillWithBlocks(world, start, 47, 15, 81, 47, 15, 83, Blocks.COBBLESTONE.getDefaultState());
        structure.fillWithBlocks(world, start, 47, 15, 85, 47, 15, 87, Blocks.COBBLESTONE.getDefaultState());
        structure.fillWithBlocks(world, start, 47, 15, 89, 47, 15, 91, Blocks.COBBLESTONE.getDefaultState());
        structure.fillWithBlocks(world, start, 47, 15, 95, 51, 15, 99, Blocks.STONE_BRICKS.getDefaultState());
        structure.fillWithBlocks(world, start, 47, 15, 102, 47, 15, 104, Blocks.COBBLESTONE.getDefaultState());
        structure.fillWithBlocks(world, start, 47, 15, 106, 47, 15, 107, Blocks.COBBLESTONE.getDefaultState());
        structure.fillWithBlocks(world, start, 47, 15, 109, 47, 15, 110, Blocks.COBBLESTONE.getDefaultState());
        structure.fillWithBlocks(world, start, 47, 15, 112, 48, 15, 113, Blocks.COBBLESTONE.getDefaultState());
        structure.fillWithBlocks(world, start, 47, 15, 116, 47, 15, 117, Blocks.STONE_BRICK_SLAB.getDefaultState().with(SlabBlock.TYPE, SlabType.DOUBLE).with(SlabBlock.WATERLOGGED, false));
        structure.fillWithBlocks(world, start, 47, 15, 118, 47, 16, 123, Blocks.STONE_BRICKS.getDefaultState());
        structure.fillWithBlocks(world, start, 47, 16, 11, 47, 16, 12, Blocks.COBBLESTONE.getDefaultState());
        structure.fillWithBlocks(world, start, 47, 16, 13, 49, 16, 15, Blocks.STONE_BRICKS.getDefaultState());
        structure.fillWithBlocks(world, start, 47, 16, 18, 47, 16, 19, Blocks.COBBLESTONE.getDefaultState());
        structure.fillWithBlocks(world, start, 47, 16, 64, 48, 16, 65, Blocks.STONE_BRICKS.getDefaultState());
        structure.fillWithBlocks(world, start, 47, 16, 113, 47, 24, 113, Blocks.STONE_BRICKS.getDefaultState());
        structure.fillWithBlocks(world, start, 47, 17, 13, 49, 17, 15, Blocks.STONE_BRICKS.getDefaultState());
        structure.fillWithBlocks(world, start, 47, 17, 16, 48, 17, 17, Blocks.STONE_BRICKS.getDefaultState());
        structure.fillWithBlocks(world, start, 47, 17, 18, 47, 25, 18, Blocks.COBBLESTONE.getDefaultState());
        structure.fillWithBlocks(world, start, 47, 17, 64, 48, 17, 65, Blocks.STONE_BRICKS.getDefaultState());
        structure.fillWithBlocks(world, start, 47, 17, 122, 47, 18, 123, Blocks.STONE_BRICKS.getDefaultState());
        structure.fillWithBlocks(world, start, 47, 18, 13, 47, 18, 17, Blocks.STONE_BRICKS.getDefaultState());
        structure.fillWithBlocks(world, start, 47, 18, 64, 49, 18, 66, Blocks.STONE_BRICKS.getDefaultState());
        structure.fillWithBlocks(world, start, 47, 18, 67, 47, 19, 67, Blocks.STONE_BRICKS.getDefaultState());
        structure.fillWithBlocks(world, start, 47, 19, 15, 48, 19, 15, Blocks.STONE_BRICK_SLAB.getDefaultState().with(SlabBlock.TYPE, SlabType.BOTTOM).with(SlabBlock.WATERLOGGED, false));
        structure.fillWithBlocks(world, start, 47, 19, 16, 48, 19, 17, Blocks.STONE_BRICKS.getDefaultState());
        structure.fillWithBlocks(world, start, 47, 19, 64, 48, 19, 65, Blocks.STONE_BRICKS.getDefaultState());
        structure.fillWithBlocks(world, start, 47, 20, 11, 47, 21, 12, Blocks.COBBLESTONE.getDefaultState());
        structure.fillWithBlocks(world, start, 47, 20, 19, 48, 21, 19, Blocks.COBBLESTONE.getDefaultState());
