package mod.arcalitegames.odyssey.world.structure.structures.dungeons.highguard_castle;

import mod.arcalitegames.odyssey.world.structure.StructureBase;
import net.minecraft.block.Blocks;
import net.minecraft.block.SnowyDirtBlock;
import net.minecraft.block.WallBlock;
import net.minecraft.block.WallHeight;
import net.minecraft.util.math.BlockPos;
import net.minecraft.world.World;

public class HighguardComponent3
{
	public static BlockPos start;
    public static World world;
    public static StructureBase structure;

    public static void init(World worldIn, BlockPos blockPos, StructureBase structureIn)
    {
        world = worldIn; start = blockPos; structure = structureIn;
    }
    
    public static void generatePart31()
    {
        structure.fillWithBlocks(world, start, -18, -30, 38, -18, -30, 39, Blocks.STONE_BRICKS.getDefaultState());
        structure.fillWithBlocks(world, start, -18, -29, -24, -17, -29, -22, Blocks.STONE_BRICKS.getDefaultState());
        structure.fillWithBlocks(world, start, -18, -29, -19, -17, -29, -17, Blocks.STONE_BRICKS.getDefaultState());
        structure.fillWithBlocks(world, start, -18, -29, -16, -18, -28, -15, Blocks.STONE_BRICKS.getDefaultState());
        structure.fillWithBlocks(world, start, -18, -29, -14, -18, -29, -13, Blocks.CRACKED_STONE_BRICKS.getDefaultState());
        structure.fillWithBlocks(world, start, -18, -29, -12, -18, -29, -12, Blocks.STONE_BRICKS.getDefaultState());
        structure.fillWithBlocks(world, start, -18, -29, -6, -18, -29, -6, Blocks.STONE_BRICKS.getDefaultState());
        structure.fillWithBlocks(world, start, -18, -29, -4, -17, -29, -3, Blocks.STONE_BRICKS.getDefaultState());
        structure.fillWithBlocks(world, start, -18, -29, -1, -18, -29, 1, Blocks.STONE_BRICKS.getDefaultState());
        structure.fillWithBlocks(world, start, -18, -29, 8, -17, -29, 9, Blocks.STONE_BRICKS.getDefaultState());
        structure.fillWithBlocks(world, start, -18, -29, 13, -18, -29, 18, Blocks.STONE_BRICKS.getDefaultState());
        structure.fillWithBlocks(world, start, -18, -29, 20, -18, -29, 20, Blocks.STONE_BRICKS.getDefaultState());
        structure.fillWithBlocks(world, start, -18, -29, 21, -18, -28, 21, Blocks.MOSSY_STONE_BRICKS.getDefaultState());
        structure.fillWithBlocks(world, start, -18, -29, 27, -18, -29, 29, Blocks.MOSSY_STONE_BRICKS.getDefaultState());
        structure.fillWithBlocks(world, start, -18, -29, 30, -18, -27, 30, Blocks.STONE_BRICKS.getDefaultState());
        structure.fillWithBlocks(world, start, -18, -29, 33, -16, -29, 33, Blocks.MOSSY_STONE_BRICKS.getDefaultState());
        structure.fillWithBlocks(world, start, -18, -29, 36, -18, -29, 36, Blocks.MOSSY_STONE_BRICKS.getDefaultState());
        structure.fillWithBlocks(world, start, -18, -29, 37, -18, -27, 37, Blocks.STONE_BRICKS.getDefaultState());
        structure.fillWithBlocks(world, start, -18, -29, 38, -18, -29, 39, Blocks.MOSSY_STONE_BRICKS.getDefaultState());
        structure.fillWithBlocks(world, start, -18, -28, -30, -15, -27, -30, Blocks.STONE_BRICKS.getDefaultState());
        structure.fillWithBlocks(world, start, -18, -28, -29, -16, -28, -29, Blocks.MOSSY_STONE_BRICKS.getDefaultState());
        structure.fillWithBlocks(world, start, -18, -28, -28, -18, -28, -28, Blocks.STONE_BRICKS.getDefaultState());
        structure.fillWithBlocks(world, start, -18, -28, -24, -18, -27, -24, Blocks.STONE_BRICKS.getDefaultState());
        structure.fillWithBlocks(world, start, -18, -28, -23, -18, -27, -23, Blocks.MOSSY_STONE_BRICKS.getDefaultState());
        structure.fillWithBlocks(world, start, -18, -28, -21, -17, -28, -20, Blocks.STONE_BRICKS.getDefaultState());
        structure.fillWithBlocks(world, start, -18, -28, -19, -18, -28, -18, Blocks.STONE_BRICKS.getDefaultState());
        structure.fillWithBlocks(world, start, -18, -28, -17, -17, -28, -17, Blocks.MOSSY_STONE_BRICKS.getDefaultState());
        structure.fillWithBlocks(world, start, -18, -28, -14, -17, -28, -13, Blocks.STONE_BRICKS.getDefaultState());
        structure.fillWithBlocks(world, start, -18, -28, -11, -17, -28, -10, Blocks.STONE_BRICKS.getDefaultState());
        structure.fillWithBlocks(world, start, -18, -28, -7, -18, -28, -2, Blocks.STONE_BRICKS.getDefaultState());
        structure.fillWithBlocks(world, start, -18, -28, -1, -18, -28, 0, Blocks.MOSSY_STONE_BRICKS.getDefaultState());
        structure.fillWithBlocks(world, start, -18, -28, 8, -18, -28, 10, Blocks.STONE_BRICKS.getDefaultState());
        structure.fillWithBlocks(world, start, -18, -28, 11, -18, -28, 13, Blocks.MOSSY_STONE_BRICKS.getDefaultState());
        structure.fillWithBlocks(world, start, -18, -28, 23, -18, -28, 23, Blocks.MOSSY_STONE_BRICKS.getDefaultState());
        structure.fillWithBlocks(world, start, -18, -28, 26, -17, -28, 27, Blocks.STONE_BRICKS.getDefaultState());
        structure.fillWithBlocks(world, start, -18, -28, 28, -18, -28, 29, Blocks.CRACKED_STONE_BRICKS.getDefaultState());
        structure.fillWithBlocks(world, start, -18, -28, 31, -18, -28, 31, Blocks.STONE_BRICKS.getDefaultState());
        structure.fillWithBlocks(world, start, -18, -28, 33, -18, -28, 38, Blocks.STONE_BRICKS.getDefaultState());
        structure.fillWithBlocks(world, start, -18, -27, -25, -18, -27, -25, Blocks.MOSSY_STONE_BRICKS.getDefaultState());
        structure.fillWithBlocks(world, start, -18, -27, -21, -17, -27, -20, Blocks.STONE_BRICKS.getDefaultState());
        structure.fillWithBlocks(world, start, -18, -27, -19, -16, -27, -19, Blocks.MOSSY_STONE_BRICKS.getDefaultState());
        structure.fillWithBlocks(world, start, -18, -27, -12, -18, -27, -12, Blocks.STONE_BRICKS.getDefaultState());
        structure.fillWithBlocks(world, start, -18, -27, -6, -18, -27, -5, Blocks.STONE_BRICKS.getDefaultState());
        structure.fillWithBlocks(world, start, -18, -27, -4, -18, -27, -2, Blocks.MOSSY_STONE_BRICKS.getDefaultState());
        structure.fillWithBlocks(world, start, -18, -27, -1, -18, -27, 0, Blocks.STONE_BRICKS.getDefaultState());
        structure.fillWithBlocks(world, start, -18, -27, 8, -18, -26, 9, Blocks.STONE_BRICKS.getDefaultState());
        structure.fillWithBlocks(world, start, -18, -27, 11, -18, -27, 11, Blocks.STONE_BRICKS.getDefaultState());
        structure.fillWithBlocks(world, start, -18, -27, 12, -18, -27, 12, Blocks.MOSSY_STONE_BRICKS.getDefaultState());
        structure.fillWithBlocks(world, start, -18, -27, 15, -17, -27, 18, Blocks.STONE_BRICKS.getDefaultState());
        structure.fillWithBlocks(world, start, -18, -27, 21, -18, -26, 21, Blocks.STONE_BRICKS.getDefaultState());
        structure.fillWithBlocks(world, start, -18, -27, 23, -18, -27, 28, Blocks.STONE_BRICKS.getDefaultState());
        structure.fillWithBlocks(world, start, -18, -27, 31, -18, -27, 31, Blocks.STONE_BRICKS.getDefaultState());
        structure.fillWithBlocks(world, start, -18, -27, 38, -18, -27, 39, Blocks.STONE_BRICKS.getDefaultState());
        structure.fillWithBlocks(world, start, -18, -26, 7, -18, -25, 7, Blocks.CRACKED_STONE_BRICKS.getDefaultState());
        structure.fillWithBlocks(world, start, -18, -26, 10, -18, -26, 10, Blocks.STONE_BRICKS.getDefaultState());
        structure.fillWithBlocks(world, start, -18, -26, 12, -16, -26, 15, Blocks.STONE_BRICKS.getDefaultState());
        structure.fillWithBlocks(world, start, -18, -26, 16, -17, -26, 16, Blocks.CRACKED_STONE_BRICKS.getDefaultState());
        structure.fillWithBlocks(world, start, -18, -26, 17, -18, -26, 18, Blocks.STONE_BRICKS.getDefaultState());
        structure.fillWithBlocks(world, start, -18, -26, 19, -17, -26, 19, Blocks.AIR.getDefaultState());
        structure.fillWithBlocks(world, start, -18, -26, 20, -18, -26, 21, Blocks.STONE_BRICKS.getDefaultState());
        structure.fillWithBlocks(world, start, -18, -26, 46, -17, -26, 46, Blocks.MOSSY_STONE_BRICKS.getDefaultState());
        structure.fillWithBlocks(world, start, -18, -26, 69, -17, -26, 71, Blocks.STONE_BRICKS.getDefaultState());
        structure.fillWithBlocks(world, start, -18, -26, 72, -18, -26, 79, Blocks.STONE_BRICKS.getDefaultState());
        structure.fillWithBlocks(world, start, -18, -26, 80, -18, -26, 81, Blocks.CRACKED_STONE_BRICKS.getDefaultState());
        structure.fillWithBlocks(world, start, -18, -26, 82, -18, -26, 82, Blocks.STONE_BRICKS.getDefaultState());
        structure.fillWithBlocks(world, start, -18, -26, 83, -18, -25, 83, Blocks.CRACKED_STONE_BRICKS.getDefaultState());
        structure.fillWithBlocks(world, start, -18, -26, 87, -18, -25, 87, Blocks.MOSSY_STONE_BRICKS.getDefaultState());
        structure.fillWithBlocks(world, start, -18, -26, 88, -17, -26, 88, Blocks.CRACKED_STONE_BRICKS.getDefaultState());
        structure.fillWithBlocks(world, start, -18, -26, 89, -18, -26, 98, Blocks.STONE_BRICKS.getDefaultState());
        structure.fillWithBlocks(world, start, -18, -26, 100, -17, -26, 101, Blocks.STONE_BRICKS.getDefaultState());
        structure.fillWithBlocks(world, start, -18, -25, 8, -18, -21, 8, Blocks.STONE_BRICKS.getDefaultState());
        structure.fillWithBlocks(world, start, -18, -25, 20, -18, -24, 20, Blocks.STONE_BRICKS.getDefaultState());
        structure.fillWithBlocks(world, start, -18, -25, 42, -18, -24, 42, Blocks.STONE_BRICKS.getDefaultState());
        structure.fillWithBlocks(world, start, -18, -25, 46, -18, -24, 46, Blocks.STONE_BRICKS.getDefaultState());
        structure.fillWithBlocks(world, start, -18, -25, 69, -18, -25, 70, Blocks.STONE_BRICKS.getDefaultState());
        structure.fillWithBlocks(world, start, -18, -25, 71, -17, -25, 81, Blocks.AIR.getDefaultState());
        structure.fillWithBlocks(world, start, -18, -25, 82, -18, -25, 83, Blocks.CRACKED_STONE_BRICKS.getDefaultState());
        structure.fillWithBlocks(world, start, -18, -25, 88, -18, -22, 88, Blocks.STONE_BRICKS.getDefaultState());
        structure.fillWithBlocks(world, start, -18, -25, 89, -17, -25, 99, Blocks.AIR.getDefaultState());
        structure.fillWithBlocks(world, start, -18, -25, 100, -17, -25, 101, Blocks.STONE_BRICKS.getDefaultState());
        structure.fillWithBlocks(world, start, -18, -24, 69, -18, -24, 69, Blocks.STONE_BRICKS.getDefaultState());
        structure.fillWithBlocks(world, start, -18, -24, 71, -17, -24, 81, Blocks.AIR.getDefaultState());
        structure.fillWithBlocks(world, start, -18, -24, 82, -18, -24, 83, Blocks.STONE_BRICKS.getDefaultState());
        structure.fillWithBlocks(world, start, -18, -24, 87, -18, -23, 88, Blocks.STONE_BRICKS.getDefaultState());
        structure.fillWithBlocks(world, start, -18, -24, 89, -17, -24, 99, Blocks.AIR.getDefaultState());
        structure.fillWithBlocks(world, start, -18, -24, 100, -18, -23, 100, Blocks.STONE_BRICKS.getDefaultState());
        structure.fillWithBlocks(world, start, -18, -24, 101, -18, -23, 101, Blocks.CRACKED_STONE_BRICKS.getDefaultState());
        structure.fillWithBlocks(world, start, -18, -23, 7, -18, -22, 8, Blocks.STONE_BRICKS.getDefaultState());
        structure.fillWithBlocks(world, start, -18, -23, 21, -17, -23, 21, Blocks.STONE_BRICKS.getDefaultState());
        structure.fillWithBlocks(world, start, -18, -23, 70, -18, -18, 70, Blocks.STONE_BRICKS.getDefaultState());
        structure.fillWithBlocks(world, start, -18, -23, 71, -17, -23, 81, Blocks.AIR.getDefaultState());
        structure.fillWithBlocks(world, start, -18, -23, 85, -18, -23, 88, Blocks.STONE_BRICKS.getDefaultState());
        structure.fillWithBlocks(world, start, -18, -23, 89, -17, -23, 99, Blocks.AIR.getDefaultState());
        structure.fillWithBlocks(world, start, -18, -22, 20, -18, -22, 21, Blocks.STONE_BRICKS.getDefaultState());
        structure.fillWithBlocks(world, start, -18, -22, 46, -17, -22, 46, Blocks.STONE_BRICKS.getDefaultState());
        structure.fillWithBlocks(world, start, -18, -22, 69, -18, -22, 70, Blocks.STONE_BRICKS.getDefaultState());
        structure.fillWithBlocks(world, start, -18, -22, 71, -17, -22, 81, Blocks.AIR.getDefaultState());
        structure.fillWithBlocks(world, start, -18, -22, 83, -17, -22, 83, Blocks.STONE_BRICKS.getDefaultState());
        structure.fillWithBlocks(world, start, -18, -22, 87, -18, -22, 87, Blocks.CRACKED_STONE_BRICKS.getDefaultState());
        structure.fillWithBlocks(world, start, -18, -22, 89, -17, -22, 99, Blocks.AIR.getDefaultState());
        structure.fillWithBlocks(world, start, -18, -22, 100, -16, -22, 100, Blocks.CRACKED_STONE_BRICKS.getDefaultState());
        structure.fillWithBlocks(world, start, -18, -21, 10, -18, -21, 10, Blocks.CRACKED_STONE_BRICKS.getDefaultState());
        structure.fillWithBlocks(world, start, -18, -21, 12, -18, -21, 14, Blocks.CRACKED_STONE_BRICKS.getDefaultState());
        structure.fillWithBlocks(world, start, -18, -21, 15, -18, -21, 17, Blocks.STONE_BRICKS.getDefaultState());
        structure.fillWithBlocks(world, start, -18, -21, 20, -18, -20, 20, Blocks.CRACKED_STONE_BRICKS.getDefaultState());
        structure.fillWithBlocks(world, start, -18, -21, 21, -18, -19, 21, Blocks.STONE_BRICKS.getDefaultState());
        structure.fillWithBlocks(world, start, -18, -21, 69, -18, -21, 69, Blocks.MOSSY_STONE_BRICKS.getDefaultState());
        structure.fillWithBlocks(world, start, -18, -21, 71, -16, -21, 71, Blocks.CRACKED_STONE_BRICKS.getDefaultState());
        structure.fillWithBlocks(world, start, -18, -21, 80, -18, -21, 82, Blocks.STONE_BRICKS.getDefaultState());
        structure.fillWithBlocks(world, start, -18, -21, 87, -18, -21, 88, Blocks.MOSSY_STONE_BRICKS.getDefaultState());
        structure.fillWithBlocks(world, start, -18, -21, 89, -18, -20, 90, Blocks.STONE_BRICKS.getDefaultState());
        structure.fillWithBlocks(world, start, -18, -20, 11, -17, -20, 12, Blocks.CRACKED_STONE_BRICKS.getDefaultState());
        structure.fillWithBlocks(world, start, -18, -20, 13, -18, -20, 13, Blocks.STONE_BRICKS.getDefaultState());
        structure.fillWithBlocks(world, start, -18, -20, 14, -18, -20, 15, Blocks.CRACKED_STONE_BRICKS.getDefaultState());
        structure.fillWithBlocks(world, start, -18, -20, 16, -18, -18, 16, Blocks.STONE_BRICKS.getDefaultState());
        structure.fillWithBlocks(world, start, -18, -20, 18, -15, -20, 18, Blocks.STONE_BRICKS.getDefaultState());
        structure.fillWithBlocks(world, start, -18, -20, 19, -18, -20, 20, Blocks.CRACKED_STONE_BRICKS.getDefaultState());
        structure.fillWithBlocks(world, start, -18, -20, 69, -18, -19, 70, Blocks.STONE_BRICKS.getDefaultState());
        structure.fillWithBlocks(world, start, -18, -20, 71, -18, -20, 72, Blocks.MOSSY_STONE_BRICKS.getDefaultState());
        structure.fillWithBlocks(world, start, -18, -20, 73, -18, -20, 73, Blocks.STONE_BRICKS.getDefaultState());
        structure.fillWithBlocks(world, start, -18, -20, 75, -18, -20, 76, Blocks.MOSSY_STONE_BRICKS.getDefaultState());
        structure.fillWithBlocks(world, start, -18, -20, 77, -18, -20, 77, Blocks.STONE_BRICKS.getDefaultState());
        structure.fillWithBlocks(world, start, -18, -20, 79, -17, -19, 79, Blocks.STONE_BRICKS.getDefaultState());
        structure.fillWithBlocks(world, start, -18, -20, 80, -18, -19, 81, Blocks.CRACKED_STONE_BRICKS.getDefaultState());
        structure.fillWithBlocks(world, start, -18, -20, 83, -18, -19, 83, Blocks.STONE_BRICKS.getDefaultState());
        structure.fillWithBlocks(world, start, -18, -20, 88, -18, -20, 90, Blocks.STONE_BRICKS.getDefaultState());
        structure.fillWithBlocks(world, start, -18, -20, 91, -17, -19, 91, Blocks.CRACKED_STONE_BRICKS.getDefaultState());
        structure.fillWithBlocks(world, start, -18, -20, 92, -17, -20, 93, Blocks.STONE_BRICKS.getDefaultState());
        structure.fillWithBlocks(world, start, -18, -20, 94, -18, -20, 97, Blocks.STONE_BRICKS.getDefaultState());
        structure.fillWithBlocks(world, start, -18, -20, 98, -18, -20, 99, Blocks.MOSSY_STONE_BRICKS.getDefaultState());
        structure.fillWithBlocks(world, start, -18, -20, 100, -18, -20, 101, Blocks.STONE_BRICKS.getDefaultState());
        structure.fillWithBlocks(world, start, -18, -19, 8, -17, -19, 8, Blocks.STONE_BRICKS.getDefaultState());
        structure.fillWithBlocks(world, start, -18, -19, 11, -17, -19, 12, Blocks.STONE_BRICKS.getDefaultState());
        structure.fillWithBlocks(world, start, -18, -19, 14, -17, -19, 15, Blocks.STONE_BRICKS.getDefaultState());
        structure.fillWithBlocks(world, start, -18, -19, 18, -18, -19, 18, Blocks.STONE_BRICKS.getDefaultState());
        structure.fillWithBlocks(world, start, -18, -19, 20, -18, -19, 21, Blocks.STONE_BRICKS.getDefaultState());
        structure.fillWithBlocks(world, start, -18, -19, 72, -16, -19, 72, Blocks.STONE_BRICKS.getDefaultState());
        structure.fillWithBlocks(world, start, -18, -19, 73, -18, -19, 73, Blocks.CRACKED_STONE_BRICKS.getDefaultState());
        structure.fillWithBlocks(world, start, -18, -19, 77, -18, -19, 77, Blocks.MOSSY_STONE_BRICKS.getDefaultState());
        structure.fillWithBlocks(world, start, -18, -19, 78, -18, -19, 79, Blocks.STONE_BRICKS.getDefaultState());
        structure.fillWithBlocks(world, start, -18, -19, 92, -18, -18, 95, Blocks.STONE_BRICKS.getDefaultState());
        structure.fillWithBlocks(world, start, -18, -19, 96, -18, -19, 97, Blocks.STONE_BRICKS.getDefaultState());
        structure.fillWithBlocks(world, start, -18, -19, 98, -18, -19, 98, Blocks.MOSSY_STONE_BRICKS.getDefaultState());
        structure.fillWithBlocks(world, start, -18, -19, 99, -18, -19, 99, Blocks.CRACKED_STONE_BRICKS.getDefaultState());
        structure.fillWithBlocks(world, start, -18, -18, 7, -17, -17, 7, Blocks.STONE_BRICKS.getDefaultState());
        structure.fillWithBlocks(world, start, -18, -18, 8, -17, -18, 8, Blocks.CRACKED_STONE_BRICKS.getDefaultState());
        structure.fillWithBlocks(world, start, -18, -18, 9, -18, -18, 11, Blocks.STONE_BRICKS.getDefaultState());
        structure.fillWithBlocks(world, start, -18, -18, 12, -17, -18, 12, Blocks.MOSSY_STONE_BRICKS.getDefaultState());
        structure.fillWithBlocks(world, start, -18, -18, 18, -17, -18, 18, Blocks.CRACKED_STONE_BRICKS.getDefaultState());
        structure.fillWithBlocks(world, start, -18, -18, 19, -18, -17, 19, Blocks.STONE_BRICKS.getDefaultState());
        structure.fillWithBlocks(world, start, -18, -18, 20, -18, -18, 21, Blocks.CRACKED_STONE_BRICKS.getDefaultState());
        structure.fillWithBlocks(world, start, -18, -18, 69, -18, -18, 71, Blocks.STONE_BRICKS.getDefaultState());
        structure.fillWithBlocks(world, start, -18, -18, 73, -18, -18, 75, Blocks.STONE_BRICKS.getDefaultState());
        structure.fillWithBlocks(world, start, -18, -18, 76, -18, -18, 77, Blocks.CRACKED_STONE_BRICKS.getDefaultState());
        structure.fillWithBlocks(world, start, -18, -18, 78, -18, -17, 78, Blocks.STONE_BRICKS.getDefaultState());
        structure.fillWithBlocks(world, start, -18, -18, 79, -16, -18, 79, Blocks.MOSSY_STONE_BRICKS.getDefaultState());
        structure.fillWithBlocks(world, start, -18, -18, 81, -18, -17, 82, Blocks.STONE_BRICKS.getDefaultState());
        structure.fillWithBlocks(world, start, -18, -18, 91, -18, -18, 91, Blocks.CRACKED_STONE_BRICKS.getDefaultState());
        structure.fillWithBlocks(world, start, -18, -18, 96, -18, -18, 97, Blocks.CRACKED_STONE_BRICKS.getDefaultState());
        structure.fillWithBlocks(world, start, -18, -18, 98, -18, -18, 100, Blocks.STONE_BRICKS.getDefaultState());
        structure.fillWithBlocks(world, start, -18, -17, 8, -17, -17, 9, Blocks.STONE_BRICKS.getDefaultState());
        structure.fillWithBlocks(world, start, -18, -17, 11, -16, -17, 11, Blocks.STONE_BRICKS.getDefaultState());
        structure.fillWithBlocks(world, start, -18, -17, 12, -17, -17, 12, Blocks.CRACKED_STONE_BRICKS.getDefaultState());
        structure.fillWithBlocks(world, start, -18, -17, 16, -18, -17, 17, Blocks.CRACKED_STONE_BRICKS.getDefaultState());
        structure.fillWithBlocks(world, start, -18, -17, 18, -18, -17, 19, Blocks.STONE_BRICKS.getDefaultState());
        structure.fillWithBlocks(world, start, -18, -17, 20, -17, -17, 20, Blocks.MOSSY_STONE_BRICKS.getDefaultState());
        structure.fillWithBlocks(world, start, -18, -17, 21, -15, -17, 21, Blocks.STONE_BRICKS.getDefaultState());
        structure.fillWithBlocks(world, start, -18, -17, 69, -18, -17, 69, Blocks.STONE_BRICKS.getDefaultState());
        structure.fillWithBlocks(world, start, -18, -17, 71, -18, -17, 72, Blocks.STONE_BRICKS.getDefaultState());
        structure.fillWithBlocks(world, start, -18, -17, 74, -17, -17, 74, Blocks.CRACKED_STONE_BRICKS.getDefaultState());
        structure.fillWithBlocks(world, start, -18, -17, 75, -18, -17, 75, Blocks.STONE_BRICKS.getDefaultState());
        structure.fillWithBlocks(world, start, -18, -17, 77, -18, -17, 77, Blocks.CRACKED_STONE_BRICKS.getDefaultState());
        structure.fillWithBlocks(world, start, -18, -17, 79, -18, -17, 83, Blocks.STONE_BRICKS.getDefaultState());
        structure.fillWithBlocks(world, start, -18, -17, 88, -18, -17, 88, Blocks.STONE_BRICKS.getDefaultState());
        structure.fillWithBlocks(world, start, -18, -17, 91, -18, -17, 91, Blocks.STONE_BRICKS.getDefaultState());
        structure.fillWithBlocks(world, start, -18, -17, 93, -18, -17, 97, Blocks.STONE_BRICKS.getDefaultState());
        structure.fillWithBlocks(world, start, -18, -17, 99, -17, -17, 101, Blocks.STONE_BRICKS.getDefaultState());
        structure.fillWithBlocks(world, start, -18, -16, 48, -18, -13, 51, Blocks.STONE_BRICKS.getDefaultState());
        structure.fillWithBlocks(world, start, -18, -13, 42, -18, -9, 42, Blocks.STONE_BRICKS.getDefaultState());
        structure.fillWithBlocks(world, start, -18, -12, 48, -18, -9, 51, Blocks.STONE_BRICKS.getDefaultState());
        structure.fillWithBlocks(world, start, -18, -10, 46, -18, -9, 51, Blocks.STONE_BRICKS.getDefaultState());
        structure.fillWithBlocks(world, start, -18, -8, 43, -18, -7, 46, Blocks.STONE_BRICKS.getDefaultState());
        structure.fillWithBlocks(world, start, -18, -8, 48, -18, -7, 51, Blocks.STONE_BRICKS.getDefaultState());
        structure.fillWithBlocks(world, start, -18, -7, 37, -18, -7, 51, Blocks.STONE_BRICKS.getDefaultState());
        structure.fillWithBlocks(world, start, -17, -56, -2, -16, -56, -1, Blocks.STONE_BRICKS.getDefaultState());
        structure.fillWithBlocks(world, start, -17, -56, 1, -15, -56, 3, Blocks.STONE_BRICKS.getDefaultState());
        structure.fillWithBlocks(world, start, -17, -55, 4, -15, -55, 6, Blocks.STONE_BRICKS.getDefaultState());
        structure.fillWithBlocks(world, start, -17, -55, 14, -15, -55, 19, Blocks.STONE_BRICKS.getDefaultState());
        structure.fillWithBlocks(world, start, -17, -55, 21, -16, -55, 22, Blocks.STONE_BRICKS.getDefaultState());
        structure.fillWithBlocks(world, start, -17, -54, -2, -15, -54, 0, Blocks.STONE_BRICKS.getDefaultState());
        structure.fillWithBlocks(world, start, -17, -54, 2, -15, -54, 6, Blocks.STONE_BRICKS.getDefaultState());
        structure.fillWithBlocks(world, start, -17, -54, 19, -14, -54, 22, Blocks.STONE_BRICKS.getDefaultState());
        structure.fillWithBlocks(world, start, -17, -53, 14, -17, -53, 14, Blocks.STONE_BRICKS.getDefaultState());
        structure.fillWithBlocks(world, start, -17, -53, 16, -17, -53, 16, Blocks.STONE_BRICKS.getDefaultState());
        structure.fillWithBlocks(world, start, -17, -53, 18, -14, -53, 21, Blocks.STONE_BRICKS.getDefaultState());
        structure.fillWithBlocks(world, start, -17, -51, 3, -14, -51, 6, Blocks.STONE_BRICKS.getDefaultState());
        structure.fillWithBlocks(world, start, -17, -51, 20, -15, -51, 22, Blocks.STONE_BRICKS.getDefaultState());
        structure.fillWithBlocks(world, start, -17, -50, 2, -16, -50, 3, Blocks.STONE_BRICKS.getDefaultState());
        structure.fillWithBlocks(world, start, -17, -50, 9, -15, -50, 11, Blocks.AIR.getDefaultState());
        structure.fillWithBlocks(world, start, -17, -49, 14, -17, -48, 14, Blocks.AIR.getDefaultState());
        structure.fillWithBlocks(world, start, -17, -49, 15, -16, -49, 16, Blocks.STONE_BRICKS.getDefaultState());
        structure.fillWithBlocks(world, start, -17, -49, 17, -17, -48, 17, Blocks.AIR.getDefaultState());
        structure.fillWithBlocks(world, start, -17, -49, 18, -13, -49, 22, Blocks.STONE_BRICKS.getDefaultState());
        structure.fillWithBlocks(world, start, -17, -48, 12, -16, -48, 13, Blocks.STONE_BRICKS.getDefaultState());
        structure.fillWithBlocks(world, start, -17, -48, 15, -16, -48, 16, Blocks.STONE_BRICKS.getDefaultState());
        structure.fillWithBlocks(world, start, -17, -48, 18, -15, -46, 18, Blocks.STONE_BRICKS.getDefaultState());
        structure.fillWithBlocks(world, start, -17, -48, 19, -16, -48, 19, Blocks.AIR.getDefaultState());
        structure.fillWithBlocks(world, start, -17, -48, 20, -15, -48, 22, Blocks.STONE_BRICKS.getDefaultState());
        structure.fillWithBlocks(world, start, -17, -47, 0, -15, -47, 5, Blocks.STONE_BRICKS.getDefaultState());
        structure.fillWithBlocks(world, start, -17, -47, 9, -14, -47, 19, Blocks.STONE_BRICKS.getDefaultState());
        structure.fillWithBlocks(world, start, -17, -47, 24, -17, -46, 24, Blocks.STONE_BRICKS.getDefaultState());
        structure.fillWithBlocks(world, start, -17, -47, 25, -17, -47, 26, Blocks.MOSSY_STONE_BRICKS.getDefaultState());
        structure.fillWithBlocks(world, start, -17, -47, 32, -13, -47, 32, Blocks.STONE_BRICKS.getDefaultState());
        structure.fillWithBlocks(world, start, -17, -46, 2, -17, -46, 3, Blocks.MOSSY_STONE_BRICKS.getDefaultState());
        structure.fillWithBlocks(world, start, -17, -46, 4, -17, -46, 6, Blocks.STONE_BRICKS.getDefaultState());
        structure.fillWithBlocks(world, start, -17, -46, 7, -17, -46, 8, Blocks.MOSSY_STONE_BRICKS.getDefaultState());
        structure.fillWithBlocks(world, start, -17, -46, 9, -16, -46, 9, Blocks.MOSSY_COBBLESTONE.getDefaultState());
        structure.fillWithBlocks(world, start, -17, -46, 12, -17, -46, 12, Blocks.MOSSY_COBBLESTONE.getDefaultState());
        structure.fillWithBlocks(world, start, -17, -46, 13, -17, -46, 13, Blocks.MOSSY_STONE_BRICKS.getDefaultState());
        structure.fillWithBlocks(world, start, -17, -46, 14, -17, -46, 16, Blocks.MOSSY_COBBLESTONE.getDefaultState());
        structure.fillWithBlocks(world, start, -17, -46, 27, -17, -46, 28, Blocks.MOSSY_COBBLESTONE.getDefaultState());
        structure.fillWithBlocks(world, start, -17, -46, 34, -16, -46, 34, Blocks.STONE_BRICKS.getDefaultState());
        structure.fillWithBlocks(world, start, -17, -45, 3, -17, -45, 3, Blocks.MOSSY_STONE_BRICKS.getDefaultState());
        structure.fillWithBlocks(world, start, -17, -45, 4, -17, -44, 4, Blocks.STONE_BRICKS.getDefaultState());
        structure.fillWithBlocks(world, start, -17, -45, 6, -16, -45, 6, Blocks.STONE_BRICKS.getDefaultState());
        structure.fillWithBlocks(world, start, -17, -45, 7, -17, -45, 7, Blocks.AIR.getDefaultState());
        structure.fillWithBlocks(world, start, -17, -45, 9, -17, -44, 17, Blocks.AIR.getDefaultState());
        structure.fillWithBlocks(world, start, -17, -45, 19, -14, -45, 19, Blocks.STONE_BRICK_WALL.getDefaultState().with(WallBlock.WATERLOGGED, false).with(WallBlock.UP, true).with(WallBlock.WALL_HEIGHT_NORTH, WallHeight.LOW).with(WallBlock.WALL_HEIGHT_SOUTH, WallHeight.LOW).with(WallBlock.WALL_HEIGHT_EAST, WallHeight.LOW).with(WallBlock.WALL_HEIGHT_WEST, WallHeight.LOW));
        structure.fillWithBlocks(world, start, -17, -44, 6, -17, -40, 6, Blocks.STONE_BRICKS.getDefaultState());
        structure.fillWithBlocks(world, start, -17, -44, 7, -16, -44, 9, Blocks.AIR.getDefaultState());
        structure.fillWithBlocks(world, start, -17, -43, 2, -17, -40, 2, Blocks.STONE_BRICKS.getDefaultState());
        structure.fillWithBlocks(world, start, -17, -43, 4, -15, -43, 4, Blocks.AIR.getDefaultState());
        structure.fillWithBlocks(world, start, -17, -43, 5, -16, -43, 5, Blocks.MOSSY_STONE_BRICKS.getDefaultState());
        structure.fillWithBlocks(world, start, -17, -43, 7, -16, -43, 9, Blocks.AIR.getDefaultState());
        structure.fillWithBlocks(world, start, -17, -42, 3, -17, -41, 4, Blocks.STONE_BRICKS.getDefaultState());
        structure.fillWithBlocks(world, start, -17, -41, 5, -17, -41, 7, Blocks.STONE_BRICKS.getDefaultState());
        structure.fillWithBlocks(world, start, -17, -41, 9, -17, -39, 9, Blocks.MOSSY_STONE_BRICKS.getDefaultState());
        structure.fillWithBlocks(world, start, -17, -41, 11, -16, -40, 11, Blocks.STONE_BRICKS.getDefaultState());
        structure.fillWithBlocks(world, start, -17, -41, 23, -17, -39, 23, Blocks.STONE_BRICKS.getDefaultState());
        structure.fillWithBlocks(world, start, -17, -40, 3, -17, -39, 3, Blocks.MOSSY_STONE_BRICKS.getDefaultState());
        structure.fillWithBlocks(world, start, -17, -40, 4, -17, -39, 4, Blocks.STONE_BRICKS.getDefaultState());
        structure.fillWithBlocks(world, start, -17, -40, 8, -17, -40, 9, Blocks.MOSSY_STONE_BRICKS.getDefaultState());
        structure.fillWithBlocks(world, start, -17, -40, 10, -16, -40, 10, Blocks.MOSSY_COBBLESTONE.getDefaultState());
        structure.fillWithBlocks(world, start, -17, -40, 12, -15, -40, 12, Blocks.STONE_BRICKS.getDefaultState());
        structure.fillWithBlocks(world, start, -17, -40, 16, -14, -40, 16, Blocks.STONE_BRICKS.getDefaultState());
        structure.fillWithBlocks(world, start, -17, -40, 17, -17, -40, 17, Blocks.AIR.getDefaultState());
        structure.fillWithBlocks(world, start, -17, -40, 19, -17, -40, 19, Blocks.MOSSY_STONE_BRICKS.getDefaultState());
        structure.fillWithBlocks(world, start, -17, -40, 20, -17, -36, 20, Blocks.STONE_BRICKS.getDefaultState());
        structure.fillWithBlocks(world, start, -17, -40, 21, -17, -40, 22, Blocks.MOSSY_STONE_BRICKS.getDefaultState());
        structure.fillWithBlocks(world, start, -17, -40, 24, -16, -40, 25, Blocks.STONE_BRICKS.getDefaultState());
        structure.fillWithBlocks(world, start, -17, -40, 26, -17, -40, 30, Blocks.STONE_BRICKS.getDefaultState());
        structure.fillWithBlocks(world, start, -17, -40, 32, -14, -39, 32, Blocks.STONE_BRICKS.getDefaultState());
        structure.fillWithBlocks(world, start, -17, -40, 34, -16, -39, 34, Blocks.STONE_BRICKS.getDefaultState());
        structure.fillWithBlocks(world, start, -17, -39, 2, -17, -39, 3, Blocks.MOSSY_STONE_BRICKS.getDefaultState());
        structure.fillWithBlocks(world, start, -17, -39, 6, -17, -38, 7, Blocks.MOSSY_STONE_BRICKS.getDefaultState());
        structure.fillWithBlocks(world, start, -17, -39, 10, -17, -39, 11, Blocks.STONE_BRICKS.getDefaultState());
        structure.fillWithBlocks(world, start, -17, -39, 12, -17, -39, 13, Blocks.MOSSY_STONE_BRICKS.getDefaultState());
        structure.fillWithBlocks(world, start, -17, -39, 16, -17, -39, 16, Blocks.MOSSY_STONE_BRICKS.getDefaultState());
        structure.fillWithBlocks(world, start, -17, -39, 17, -17, -38, 17, Blocks.STONE_BRICKS.getDefaultState());
        structure.fillWithBlocks(world, start, -17, -39, 18, -17, -38, 18, Blocks.MOSSY_COBBLESTONE.getDefaultState());
        structure.fillWithBlocks(world, start, -17, -39, 19, -17, -38, 20, Blocks.STONE_BRICKS.getDefaultState());
        structure.fillWithBlocks(world, start, -17, -39, 21, -17, -38, 21, Blocks.MOSSY_STONE_BRICKS.getDefaultState());
        structure.fillWithBlocks(world, start, -17, -39, 22, -16, -39, 23, Blocks.STONE_BRICKS.getDefaultState());
        structure.fillWithBlocks(world, start, -17, -39, 25, -17, -39, 26, Blocks.STONE_BRICKS.getDefaultState());
        structure.fillWithBlocks(world, start, -17, -39, 28, -17, -38, 29, Blocks.STONE_BRICKS.getDefaultState());
        structure.fillWithBlocks(world, start, -17, -39, 30, -17, -39, 30, Blocks.MOSSY_STONE_BRICKS.getDefaultState());
        structure.fillWithBlocks(world, start, -17, -39, 31, -17, -39, 32, Blocks.STONE_BRICKS.getDefaultState());
        structure.fillWithBlocks(world, start, -17, -38, 2, -17, -38, 3, Blocks.STONE_BRICKS.getDefaultState());
        structure.fillWithBlocks(world, start, -17, -38, 4, -17, -37, 4, Blocks.AIR.getDefaultState());
        structure.fillWithBlocks(world, start, -17, -38, 5, -17, -38, 7, Blocks.MOSSY_STONE_BRICKS.getDefaultState());
        structure.fillWithBlocks(world, start, -17, -38, 9, -17, -38, 9, Blocks.MOSSY_COBBLESTONE.getDefaultState());
        structure.fillWithBlocks(world, start, -17, -38, 13, -17, -38, 14, Blocks.STONE_BRICKS.getDefaultState());
        structure.fillWithBlocks(world, start, -17, -38, 15, -16, -38, 16, Blocks.AIR.getDefaultState());
        structure.fillWithBlocks(world, start, -17, -38, 22, -17, -38, 23, Blocks.MOSSY_STONE_BRICKS.getDefaultState());
        structure.fillWithBlocks(world, start, -17, -38, 24, -17, -38, 25, Blocks.STONE_BRICKS.getDefaultState());
        structure.fillWithBlocks(world, start, -17, -38, 26, -16, -38, 26, Blocks.MOSSY_STONE_BRICKS.getDefaultState());
        structure.fillWithBlocks(world, start, -17, -38, 27, -16, -38, 28, Blocks.STONE_BRICKS.getDefaultState());
        structure.fillWithBlocks(world, start, -17, -38, 33, -17, -38, 34, Blocks.STONE_BRICKS.getDefaultState());
        structure.fillWithBlocks(world, start, -17, -37, -2, -16, -37, -2, Blocks.MOSSY_STONE_BRICKS.getDefaultState());
        structure.fillWithBlocks(world, start, -17, -37, 2, -15, -36, 2, Blocks.STONE_BRICKS.getDefaultState());
        structure.fillWithBlocks(world, start, -17, -37, 3, -17, -37, 7, Blocks.AIR.getDefaultState());
        structure.fillWithBlocks(world, start, -17, -37, 8, -17, -37, 9, Blocks.MOSSY_STONE_BRICKS.getDefaultState());
        structure.fillWithBlocks(world, start, -17, -37, 11, -17, -37, 11, Blocks.AIR.getDefaultState());
        structure.fillWithBlocks(world, start, -17, -37, 12, -17, -36, 12, Blocks.STONE_BRICKS.getDefaultState());
        structure.fillWithBlocks(world, start, -17, -37, 13, -16, -37, 14, Blocks.AIR.getDefaultState());
        structure.fillWithBlocks(world, start, -17, -37, 15, -17, -36, 15, Blocks.STONE_BRICKS.getDefaultState());
        structure.fillWithBlocks(world, start, -17, -37, 16, -16, -37, 17, Blocks.AIR.getDefaultState());
        structure.fillWithBlocks(world, start, -17, -37, 18, -17, -37, 19, Blocks.MOSSY_STONE_BRICKS.getDefaultState());
        structure.fillWithBlocks(world, start, -17, -37, 21, -17, -36, 22, Blocks.STONE_BRICKS.getDefaultState());
        structure.fillWithBlocks(world, start, -17, -37, 24, -15, -37, 24, Blocks.STONE_BRICKS.getDefaultState());
        structure.fillWithBlocks(world, start, -17, -37, 26, -17, -37, 26, Blocks.STONE_BRICKS.getDefaultState());
        structure.fillWithBlocks(world, start, -17, -37, 28, -16, -37, 28, Blocks.STONE_BRICKS.getDefaultState());
        structure.fillWithBlocks(world, start, -17, -37, 31, -16, -37, 32, Blocks.STONE_BRICKS.getDefaultState());
        structure.fillWithBlocks(world, start, -17, -37, 37, -11, -37, 37, Blocks.STONE_BRICKS.getDefaultState());
        structure.fillWithBlocks(world, start, -17, -36, -30, -16, -36, -21, Blocks.STONE_BRICKS.getDefaultState());
        structure.fillWithBlocks(world, start, -17, -36, -10, -16, -36, -2, Blocks.STONE_BRICKS.getDefaultState());
        structure.fillWithBlocks(world, start, -17, -36, 3, -16, -36, 9, Blocks.STONE_BRICKS.getDefaultState());
        structure.fillWithBlocks(world, start, -17, -36, 10, -16, -36, 10, Blocks.MOSSY_COBBLESTONE.getDefaultState());
        structure.fillWithBlocks(world, start, -17, -36, 11, -14, -36, 18, Blocks.STONE_BRICKS.getDefaultState());
        structure.fillWithBlocks(world, start, -17, -36, 25, -17, -36, 25, Blocks.STONE_BRICKS.getDefaultState());
        structure.fillWithBlocks(world, start, -17, -36, 27, -17, -36, 27, Blocks.STONE_BRICKS.getDefaultState());
        structure.fillWithBlocks(world, start, -17, -36, 28, -17, -36, 28, Blocks.MOSSY_STONE_BRICKS.getDefaultState());
        structure.fillWithBlocks(world, start, -17, -36, 29, -17, -36, 33, Blocks.STONE_BRICKS.getDefaultState());
        structure.fillWithBlocks(world, start, -17, -36, 35, -15, -36, 37, Blocks.AIR.getDefaultState());
        structure.fillWithBlocks(world, start, -17, -36, 38, -17, -36, 39, Blocks.STONE_BRICKS.getDefaultState());
        structure.fillWithBlocks(world, start, -17, -35, -30, -16, -35, -29, Blocks.STONE_BRICKS.getDefaultState());
        structure.fillWithBlocks(world, start, -17, -35, -19, -12, -35, -12, Blocks.AIR.getDefaultState());
        structure.fillWithBlocks(world, start, -17, -35, -11, -16, -35, -10, Blocks.STONE_BRICKS.getDefaultState());
        structure.fillWithBlocks(world, start, -17, -35, 28, -15, -35, 30, Blocks.AIR.getDefaultState());
        structure.fillWithBlocks(world, start, -17, -35, 32, -16, -35, 33, Blocks.AIR.getDefaultState());
        structure.fillWithBlocks(world, start, -17, -35, 35, -15, -35, 37, Blocks.AIR.getDefaultState());
        structure.fillWithBlocks(world, start, -17, -34, -30, -17, -33, -30, Blocks.MOSSY_STONE_BRICKS.getDefaultState());
        structure.fillWithBlocks(world, start, -17, -34, -11, -16, -34, -10, Blocks.STONE_BRICKS.getDefaultState());
        structure.fillWithBlocks(world, start, -17, -34, 28, -15, -34, 38, Blocks.AIR.getDefaultState());
        structure.fillWithBlocks(world, start, -17, -34, 39, -17, -31, 39, Blocks.STONE_BRICKS.getDefaultState());
        structure.fillWithBlocks(world, start, -17, -33, -29, -12, -33, -29, Blocks.STONE_BRICKS.getDefaultState());
        structure.fillWithBlocks(world, start, -17, -32, -29, -17, -31, -29, Blocks.CRACKED_STONE_BRICKS.getDefaultState());
        structure.fillWithBlocks(world, start, -17, -32, -6, -17, -32, -6, Blocks.STONE_BRICKS.getDefaultState());
        structure.fillWithBlocks(world, start, -17, -32, -4, -15, -32, -4, Blocks.STONE_BRICKS.getDefaultState());
        structure.fillWithBlocks(world, start, -17, -32, -3, -17, -32, -1, Blocks.MOSSY_STONE_BRICKS.getDefaultState());
        structure.fillWithBlocks(world, start, -17, -32, 0, -17, -31, 2, Blocks.STONE_BRICKS.getDefaultState());
        structure.fillWithBlocks(world, start, -17, -32, 3, -17, -32, 3, Blocks.STONE_BRICKS.getDefaultState());
        structure.fillWithBlocks(world, start, -17, -32, 6, -17, -32, 7, Blocks.MOSSY_STONE_BRICKS.getDefaultState());
        structure.fillWithBlocks(world, start, -17, -32, 8, -16, -32, 9, Blocks.STONE_BRICKS.getDefaultState());
        structure.fillWithBlocks(world, start, -17, -32, 10, -15, -32, 10, Blocks.MOSSY_COBBLESTONE.getDefaultState());
        structure.fillWithBlocks(world, start, -17, -32, 18, -17, -32, 23, Blocks.STONE_BRICKS.getDefaultState());
        structure.fillWithBlocks(world, start, -17, -31, -6, -17, -30, -6, Blocks.MOSSY_STONE_BRICKS.getDefaultState());
        structure.fillWithBlocks(world, start, -17, -31, -4, -17, -31, -4, Blocks.MOSSY_STONE_BRICKS.getDefaultState());
        structure.fillWithBlocks(world, start, -17, -31, -3, -17, -29, -3, Blocks.STONE_BRICKS.getDefaultState());
        structure.fillWithBlocks(world, start, -17, -31, 18, -17, -30, 18, Blocks.MOSSY_COBBLESTONE.getDefaultState());
        structure.fillWithBlocks(world, start, -17, -31, 20, -17, -31, 20, Blocks.STONE_BRICKS.getDefaultState());
        structure.fillWithBlocks(world, start, -17, -31, 38, -17, -30, 38, Blocks.MOSSY_STONE_BRICKS.getDefaultState());
        structure.fillWithBlocks(world, start, -17, -30, -29, -15, -29, -29, Blocks.STONE_BRICKS.getDefaultState());
        structure.fillWithBlocks(world, start, -17, -30, -28, -17, -30, -25, Blocks.MOSSY_STONE_BRICKS.getDefaultState());
        structure.fillWithBlocks(world, start, -17, -30, -24, -17, -29, -24, Blocks.STONE_BRICKS.getDefaultState());
        structure.fillWithBlocks(world, start, -17, -30, -23, -17, -30, -22, Blocks.MOSSY_STONE_BRICKS.getDefaultState());
        structure.fillWithBlocks(world, start, -17, -30, -21, -17, -30, -21, Blocks.STONE_BRICKS.getDefaultState());
        structure.fillWithBlocks(world, start, -17, -30, -19, -16, -30, -18, Blocks.STONE_BRICKS.getDefaultState());
        structure.fillWithBlocks(world, start, -17, -30, -16, -17, -30, -14, Blocks.STONE_BRICKS.getDefaultState());
        structure.fillWithBlocks(world, start, -17, -30, -12, -17, -30, -10, Blocks.STONE_BRICKS.getDefaultState());
        structure.fillWithBlocks(world, start, -17, -30, -7, -17, -30, -6, Blocks.MOSSY_STONE_BRICKS.getDefaultState());
        structure.fillWithBlocks(world, start, -17, -30, -5, -17, -29, -3, Blocks.STONE_BRICKS.getDefaultState());
        structure.fillWithBlocks(world, start, -17, -30, -1, -17, -30, 0, Blocks.STONE_BRICKS.getDefaultState());
        structure.fillWithBlocks(world, start, -17, -30, 7, -17, -30, 9, Blocks.MOSSY_STONE_BRICKS.getDefaultState());
        structure.fillWithBlocks(world, start, -17, -30, 10, -17, -30, 10, Blocks.STONE_BRICKS.getDefaultState());
        structure.fillWithBlocks(world, start, -17, -30, 11, -17, -30, 11, Blocks.MOSSY_COBBLESTONE.getDefaultState());
        structure.fillWithBlocks(world, start, -17, -30, 12, -17, -22, 12, Blocks.STONE_BRICKS.getDefaultState());
        structure.fillWithBlocks(world, start, -17, -30, 17, -17, -30, 18, Blocks.MOSSY_COBBLESTONE.getDefaultState());
        structure.fillWithBlocks(world, start, -17, -30, 19, -17, -29, 21, Blocks.STONE_BRICKS.getDefaultState());
        structure.fillWithBlocks(world, start, -17, -30, 23, -17, -30, 25, Blocks.STONE_BRICKS.getDefaultState());
        structure.fillWithBlocks(world, start, -17, -30, 27, -16, -30, 27, Blocks.STONE_BRICKS.getDefaultState());
        structure.fillWithBlocks(world, start, -17, -30, 28, -15, -30, 28, Blocks.MOSSY_STONE_BRICKS.getDefaultState());
        structure.fillWithBlocks(world, start, -17, -30, 29, -16, -30, 30, Blocks.STONE_BRICKS.getDefaultState());
        structure.fillWithBlocks(world, start, -17, -30, 32, -17, -30, 34, Blocks.STONE_BRICKS.getDefaultState());
        structure.fillWithBlocks(world, start, -17, -30, 37, -17, -30, 39, Blocks.MOSSY_STONE_BRICKS.getDefaultState());
        structure.fillWithBlocks(world, start, -17, -29, -30, -16, -29, -29, Blocks.STONE_BRICKS.getDefaultState());
        structure.fillWithBlocks(world, start, -17, -29, -28, -17, -29, -28, Blocks.MOSSY_STONE_BRICKS.getDefaultState());
        structure.fillWithBlocks(world, start, -17, -29, -27, -17, -29, -22, Blocks.STONE_BRICKS.getDefaultState());
        structure.fillWithBlocks(world, start, -17, -29, -21, -17, -29, -21, Blocks.MOSSY_STONE_BRICKS.getDefaultState());
        structure.fillWithBlocks(world, start, -17, -29, -20, -17, -29, -17, Blocks.STONE_BRICKS.getDefaultState());
        structure.fillWithBlocks(world, start, -17, -29, -16, -17, -29, -15, Blocks.MOSSY_STONE_BRICKS.getDefaultState());
        structure.fillWithBlocks(world, start, -17, -29, -13, -16, -28, -13, Blocks.STONE_BRICKS.getDefaultState());
        structure.fillWithBlocks(world, start, -17, -29, -12, -15, -29, -12, Blocks.MOSSY_STONE_BRICKS.getDefaultState());
        structure.fillWithBlocks(world, start, -17, -29, -11, -17, -28, -10, Blocks.STONE_BRICKS.getDefaultState());
        structure.fillWithBlocks(world, start, -17, -29, -7, -16, -29, -3, Blocks.STONE_BRICKS.getDefaultState());
        structure.fillWithBlocks(world, start, -17, -29, -1, -17, -29, -1, Blocks.STONE_BRICKS.getDefaultState());
        structure.fillWithBlocks(world, start, -17, -29, 0, -17, -29, 0, Blocks.MOSSY_STONE_BRICKS.getDefaultState());
        structure.fillWithBlocks(world, start, -17, -29, 7, -17, -29, 7, Blocks.MOSSY_STONE_BRICKS.getDefaultState());
        structure.fillWithBlocks(world, start, -17, -29, 10, -17, -29, 13, Blocks.STONE_BRICKS.getDefaultState());
        structure.fillWithBlocks(world, start, -17, -29, 14, -17, -28, 14, Blocks.MOSSY_STONE_BRICKS.getDefaultState());
        structure.fillWithBlocks(world, start, -17, -29, 15, -16, -29, 17, Blocks.STONE_BRICKS.getDefaultState());
        structure.fillWithBlocks(world, start, -17, -29, 24, -17, -29, 29, Blocks.STONE_BRICKS.getDefaultState());
        structure.fillWithBlocks(world, start, -17, -29, 31, -17, -27, 31, Blocks.STONE_BRICKS.getDefaultState());
        structure.fillWithBlocks(world, start, -17, -29, 34, -15, -29, 36, Blocks.STONE_BRICKS.getDefaultState());
        structure.fillWithBlocks(world, start, -17, -29, 38, -15, -29, 38, Blocks.STONE_BRICKS.getDefaultState());
        structure.fillWithBlocks(world, start, -17, -28, -28, -17, -28, -25, Blocks.STONE_BRICKS.getDefaultState());
        structure.fillWithBlocks(world, start, -17, -28, -24, -17, -27, -24, Blocks.MOSSY_STONE_BRICKS.getDefaultState());
        structure.fillWithBlocks(world, start, -17, -28, -23, -17, -28, -20, Blocks.STONE_BRICKS.getDefaultState());
        structure.fillWithBlocks(world, start, -17, -28, -19, -17, -27, -19, Blocks.MOSSY_STONE_BRICKS.getDefaultState());
        structure.fillWithBlocks(world, start, -17, -28, -18, -17, -27, -18, Blocks.STONE_BRICKS.getDefaultState());
        structure.fillWithBlocks(world, start, -17, -28, -15, -16, -28, -13, Blocks.STONE_BRICKS.getDefaultState());
        structure.fillWithBlocks(world, start, -17, -28, -12, -17, -28, -10, Blocks.STONE_BRICKS.getDefaultState());
        structure.fillWithBlocks(world, start, -17, -28, -7, -17, -27, -7, Blocks.STONE_BRICKS.getDefaultState());
        structure.fillWithBlocks(world, start, -17, -28, -6, -17, -28, -3, Blocks.MOSSY_STONE_BRICKS.getDefaultState());
        structure.fillWithBlocks(world, start, -17, -28, -2, -17, -28, -2, Blocks.STONE_BRICKS.getDefaultState());
        structure.fillWithBlocks(world, start, -17, -28, 0, -17, -28, 0, Blocks.STONE_BRICKS.getDefaultState());
        structure.fillWithBlocks(world, start, -17, -28, 7, -17, -26, 7, Blocks.STONE_BRICKS.getDefaultState());
        structure.fillWithBlocks(world, start, -17, -28, 8, -17, -28, 8, Blocks.MOSSY_STONE_BRICKS.getDefaultState());
        structure.fillWithBlocks(world, start, -17, -28, 9, -17, -28, 13, Blocks.STONE_BRICKS.getDefaultState());
        structure.fillWithBlocks(world, start, -17, -28, 15, -17, -28, 15, Blocks.STONE_BRICKS.getDefaultState());
        structure.fillWithBlocks(world, start, -17, -28, 16, -17, -28, 18, Blocks.MOSSY_STONE_BRICKS.getDefaultState());
        structure.fillWithBlocks(world, start, -17, -28, 19, -16, -28, 19, Blocks.CRACKED_STONE_BRICKS.getDefaultState());
        structure.fillWithBlocks(world, start, -17, -28, 20, -17, -28, 21, Blocks.MOSSY_STONE_BRICKS.getDefaultState());
        structure.fillWithBlocks(world, start, -17, -28, 23, -17, -28, 23, Blocks.STONE_BRICKS.getDefaultState());
        structure.fillWithBlocks(world, start, -17, -28, 25, -17, -28, 32, Blocks.STONE_BRICKS.getDefaultState());
        structure.fillWithBlocks(world, start, -17, -28, 33, -17, -28, 33, Blocks.MOSSY_STONE_BRICKS.getDefaultState());
        structure.fillWithBlocks(world, start, -17, -28, 34, -17, -28, 39, Blocks.STONE_BRICKS.getDefaultState());
        structure.fillWithBlocks(world, start, -17, -27, -29, -17, -27, -29, Blocks.STONE_BRICKS.getDefaultState());
        structure.fillWithBlocks(world, start, -17, -27, -28, -17, -27, -28, Blocks.MOSSY_STONE_BRICKS.getDefaultState());
        structure.fillWithBlocks(world, start, -17, -27, -27, -17, -27, -25, Blocks.STONE_BRICKS.getDefaultState());
        structure.fillWithBlocks(world, start, -17, -27, -23, -17, -27, -23, Blocks.STONE_BRICKS.getDefaultState());
        structure.fillWithBlocks(world, start, -17, -27, -17, -17, -27, -17, Blocks.STONE_BRICKS.getDefaultState());
        structure.fillWithBlocks(world, start, -17, -27, -16, -17, -27, -16, Blocks.MOSSY_STONE_BRICKS.getDefaultState());
        structure.fillWithBlocks(world, start, -17, -27, -15, -17, -27, -13, Blocks.STONE_BRICKS.getDefaultState());
        structure.fillWithBlocks(world, start, -17, -27, -11, -17, -27, -10, Blocks.STONE_BRICKS.getDefaultState());
        structure.fillWithBlocks(world, start, -17, -27, -5, -14, -27, -5, Blocks.STONE_BRICKS.getDefaultState());
        structure.fillWithBlocks(world, start, -17, -27, -4, -16, -27, -4, Blocks.MOSSY_STONE_BRICKS.getDefaultState());
        structure.fillWithBlocks(world, start, -17, -27, -3, -15, -27, -3, Blocks.CRACKED_STONE_BRICKS.getDefaultState());
        structure.fillWithBlocks(world, start, -17, -27, -2, -16, -27, -1, Blocks.STONE_BRICKS.getDefaultState());
        structure.fillWithBlocks(world, start, -17, -27, 1, -11, -27, 1, Blocks.STONE_BRICKS.getDefaultState());
        structure.fillWithBlocks(world, start, -17, -27, 9, -17, -27, 9, Blocks.MOSSY_STONE_BRICKS.getDefaultState());
        structure.fillWithBlocks(world, start, -17, -27, 10, -17, -27, 12, Blocks.STONE_BRICKS.getDefaultState());
        structure.fillWithBlocks(world, start, -17, -27, 14, -17, -27, 20, Blocks.STONE_BRICKS.getDefaultState());
        structure.fillWithBlocks(world, start, -17, -27, 21, -16, -27, 21, Blocks.MOSSY_STONE_BRICKS.getDefaultState());
        structure.fillWithBlocks(world, start, -17, -27, 25, -17, -27, 25, Blocks.MOSSY_STONE_BRICKS.getDefaultState());
        structure.fillWithBlocks(world, start, -17, -27, 30, -16, -27, 34, Blocks.STONE_BRICKS.getDefaultState());
        structure.fillWithBlocks(world, start, -17, -27, 35, -17, -27, 36, Blocks.STONE_BRICKS.getDefaultState());
        structure.fillWithBlocks(world, start, -17, -27, 38, -17, -27, 38, Blocks.STONE_BRICKS.getDefaultState());
        structure.fillWithBlocks(world, start, -17, -26, 8, -17, -25, 8, Blocks.CRACKED_STONE_BRICKS.getDefaultState());
        structure.fillWithBlocks(world, start, -17, -26, 11, -16, -26, 15, Blocks.STONE_BRICKS.getDefaultState());
        structure.fillWithBlocks(world, start, -17, -26, 20, -17, -26, 20, Blocks.STONE_BRICKS.getDefaultState());
        structure.fillWithBlocks(world, start, -17, -26, 43, -15, -26, 45, Blocks.STONE_BRICKS.getDefaultState());
        structure.fillWithBlocks(world, start, -17, -26, 73, -17, -26, 73, Blocks.STONE_BRICKS.getDefaultState());
        structure.fillWithBlocks(world, start, -17, -26, 75, -14, -26, 78, Blocks.STONE_BRICKS.getDefaultState());
        structure.fillWithBlocks(world, start, -17, -26, 79, -17, -26, 79, Blocks.CRACKED_STONE_BRICKS.getDefaultState());
        structure.fillWithBlocks(world, start, -17, -26, 80, -17, -26, 81, Blocks.STONE_BRICKS.getDefaultState());
        structure.fillWithBlocks(world, start, -17, -26, 87, -17, -26, 88, Blocks.CRACKED_STONE_BRICKS.getDefaultState());
        structure.fillWithBlocks(world, start, -17, -26, 89, -17, -26, 89, Blocks.STONE_BRICKS.getDefaultState());
        structure.fillWithBlocks(world, start, -17, -26, 91, -14, -26, 91, Blocks.STONE_BRICKS.getDefaultState());
        structure.fillWithBlocks(world, start, -17, -26, 92, -17, -26, 93, Blocks.CRACKED_STONE_BRICKS.getDefaultState());
        structure.fillWithBlocks(world, start, -17, -26, 94, -17, -26, 96, Blocks.STONE_BRICKS.getDefaultState());
        structure.fillWithBlocks(world, start, -17, -26, 98, -16, -26, 100, Blocks.STONE_BRICKS.getDefaultState());
        structure.fillWithBlocks(world, start, -17, -25, 9, -17, -20, 9, Blocks.STONE_BRICKS.getDefaultState());
        structure.fillWithBlocks(world, start, -17, -25, 10, -17, -24, 11, Blocks.AIR.getDefaultState());
        structure.fillWithBlocks(world, start, -17, -25, 13, -15, -25, 15, Blocks.AIR.getDefaultState());
        structure.fillWithBlocks(world, start, -17, -25, 16, -17, -22, 16, Blocks.STONE_BRICKS.getDefaultState());
        structure.fillWithBlocks(world, start, -17, -25, 17, -17, -24, 18, Blocks.AIR.getDefaultState());
        structure.fillWithBlocks(world, start, -17, -25, 19, -17, -22, 19, Blocks.STONE_BRICKS.getDefaultState());
        structure.fillWithBlocks(world, start, -17, -25, 21, -15, -25, 21, Blocks.STONE_BRICKS.getDefaultState());
        structure.fillWithBlocks(world, start, -17, -25, 42, -15, -25, 46, Blocks.AIR.getDefaultState());
        structure.fillWithBlocks(world, start, -17, -25, 47, -17, -23, 47, Blocks.STONE_BRICKS.getDefaultState());
        structure.fillWithBlocks(world, start, -17, -25, 69, -17, -25, 70, Blocks.CRACKED_STONE_BRICKS.getDefaultState());
        structure.fillWithBlocks(world, start, -17, -24, 7, -16, -24, 8, Blocks.STONE_BRICKS.getDefaultState());
        structure.fillWithBlocks(world, start, -17, -24, 13, -15, -24, 15, Blocks.AIR.getDefaultState());
        structure.fillWithBlocks(world, start, -17, -24, 20, -16, -23, 20, Blocks.STONE_BRICKS.getDefaultState());
        structure.fillWithBlocks(world, start, -17, -24, 21, -16, -24, 21, Blocks.CRACKED_STONE_BRICKS.getDefaultState());
        structure.fillWithBlocks(world, start, -17, -24, 41, -17, -23, 41, Blocks.STONE_BRICKS.getDefaultState());
        structure.fillWithBlocks(world, start, -17, -24, 42, -15, -24, 46, Blocks.AIR.getDefaultState());
        structure.fillWithBlocks(world, start, -17, -24, 69, -17, -24, 70, Blocks.STONE_BRICKS.getDefaultState());
        structure.fillWithBlocks(world, start, -17, -24, 82, -16, -24, 82, Blocks.CRACKED_STONE_BRICKS.getDefaultState());
        structure.fillWithBlocks(world, start, -17, -24, 83, -17, -23, 83, Blocks.MOSSY_STONE_BRICKS.getDefaultState());
        structure.fillWithBlocks(world, start, -17, -24, 87, -17, -24, 87, Blocks.STONE_BRICKS.getDefaultState());
        structure.fillWithBlocks(world, start, -17, -24, 100, -16, -24, 100, Blocks.CRACKED_STONE_BRICKS.getDefaultState());
        structure.fillWithBlocks(world, start, -17, -23, 7, -17, -23, 7, Blocks.STONE_BRICKS.getDefaultState());
        structure.fillWithBlocks(world, start, -17, -23, 10, -17, -22, 11, Blocks.AIR.getDefaultState());
        structure.fillWithBlocks(world, start, -17, -23, 13, -15, -23, 15, Blocks.AIR.getDefaultState());
        structure.fillWithBlocks(world, start, -17, -23, 17, -17, -22, 18, Blocks.AIR.getDefaultState());
        structure.fillWithBlocks(world, start, -17, -23, 42, -15, -23, 46, Blocks.AIR.getDefaultState());
        structure.fillWithBlocks(world, start, -17, -23, 69, -17, -23, 69, Blocks.STONE_BRICKS.getDefaultState());
        structure.fillWithBlocks(world, start, -17, -23, 70, -17, -22, 70, Blocks.CRACKED_STONE_BRICKS.getDefaultState());
        structure.fillWithBlocks(world, start, -17, -23, 87, -17, -23, 88, Blocks.STONE_BRICKS.getDefaultState());
        structure.fillWithBlocks(world, start, -17, -23, 100, -16, -23, 100, Blocks.STONE_BRICKS.getDefaultState());
        structure.fillWithBlocks(world, start, -17, -22, 7, -17, -22, 7, Blocks.CRACKED_STONE_BRICKS.getDefaultState());
        structure.fillWithBlocks(world, start, -17, -22, 13, -17, -22, 15, Blocks.AIR.getDefaultState());
        structure.fillWithBlocks(world, start, -17, -22, 20, -17, -22, 20, Blocks.STONE_BRICKS.getDefaultState());
        structure.fillWithBlocks(world, start, -17, -22, 21, -17, -20, 21, Blocks.CRACKED_STONE_BRICKS.getDefaultState());
        structure.fillWithBlocks(world, start, -17, -22, 43, -17, -22, 44, Blocks.CRACKED_STONE_BRICKS.getDefaultState());
        structure.fillWithBlocks(world, start, -17, -22, 69, -17, -22, 70, Blocks.CRACKED_STONE_BRICKS.getDefaultState());
        structure.fillWithBlocks(world, start, -17, -22, 82, -17, -21, 83, Blocks.STONE_BRICKS.getDefaultState());
        structure.fillWithBlocks(world, start, -17, -22, 87, -17, -22, 87, Blocks.STONE_BRICKS.getDefaultState());
        structure.fillWithBlocks(world, start, -17, -21, 7, -16, -21, 10, Blocks.STONE_BRICKS.getDefaultState());
        structure.fillWithBlocks(world, start, -17, -21, 11, -17, -20, 12, Blocks.CRACKED_STONE_BRICKS.getDefaultState());
        structure.fillWithBlocks(world, start, -17, -21, 13, -17, -17, 13, Blocks.STONE_BRICKS.getDefaultState());
        structure.fillWithBlocks(world, start, -17, -21, 14, -17, -21, 15, Blocks.MOSSY_STONE_BRICKS.getDefaultState());
        structure.fillWithBlocks(world, start, -17, -21, 16, -17, -20, 16, Blocks.CRACKED_STONE_BRICKS.getDefaultState());
        structure.fillWithBlocks(world, start, -17, -21, 17, -17, -21, 18, Blocks.STONE_BRICKS.getDefaultState());
        structure.fillWithBlocks(world, start, -17, -21, 19, -17, -21, 20, Blocks.MOSSY_STONE_BRICKS.getDefaultState());
        structure.fillWithBlocks(world, start, -17, -21, 69, -17, -21, 69, Blocks.STONE_BRICKS.getDefaultState());
        structure.fillWithBlocks(world, start, -17, -21, 73, -16, -21, 73, Blocks.CRACKED_STONE_BRICKS.getDefaultState());
        structure.fillWithBlocks(world, start, -17, -21, 74, -17, -20, 74, Blocks.STONE_BRICKS.getDefaultState());
        structure.fillWithBlocks(world, start, -17, -21, 76, -17, -21, 77, Blocks.STONE_BRICKS.getDefaultState());
        structure.fillWithBlocks(world, start, -17, -21, 78, -17, -21, 78, Blocks.CRACKED_STONE_BRICKS.getDefaultState());
        structure.fillWithBlocks(world, start, -17, -21, 80, -17, -21, 80, Blocks.CRACKED_STONE_BRICKS.getDefaultState());
        structure.fillWithBlocks(world, start, -17, -21, 81, -17, -21, 83, Blocks.STONE_BRICKS.getDefaultState());
        structure.fillWithBlocks(world, start, -17, -21, 87, -17, -20, 87, Blocks.CRACKED_STONE_BRICKS.getDefaultState());
        structure.fillWithBlocks(world, start, -17, -21, 88, -16, -20, 88, Blocks.STONE_BRICKS.getDefaultState());
        structure.fillWithBlocks(world, start, -17, -21, 89, -17, -20, 89, Blocks.MOSSY_STONE_BRICKS.getDefaultState());
        structure.fillWithBlocks(world, start, -17, -21, 90, -17, -21, 91, Blocks.CRACKED_STONE_BRICKS.getDefaultState());
        structure.fillWithBlocks(world, start, -17, -21, 92, -17, -20, 93, Blocks.STONE_BRICKS.getDefaultState());
        structure.fillWithBlocks(world, start, -17, -21, 94, -17, -21, 94, Blocks.STONE_BRICKS.getDefaultState());
        structure.fillWithBlocks(world, start, -17, -21, 95, -17, -21, 96, Blocks.CRACKED_STONE_BRICKS.getDefaultState());
        structure.fillWithBlocks(world, start, -17, -21, 97, -17, -21, 98, Blocks.STONE_BRICKS.getDefaultState());
        structure.fillWithBlocks(world, start, -17, -21, 99, -15, -21, 99, Blocks.CRACKED_STONE_BRICKS.getDefaultState());
        structure.fillWithBlocks(world, start, -17, -21, 100, -17, -21, 100, Blocks.STONE_BRICKS.getDefaultState());
        structure.fillWithBlocks(world, start, -17, -21, 101, -17, -19, 101, Blocks.CRACKED_STONE_BRICKS.getDefaultState());
        structure.fillWithBlocks(world, start, -17, -20, 8, -17, -20, 10, Blocks.STONE_BRICKS.getDefaultState());
        structure.fillWithBlocks(world, start, -17, -20, 14, -17, -20, 14, Blocks.STONE_BRICKS.getDefaultState());
        structure.fillWithBlocks(world, start, -17, -20, 17, -17, -20, 18, Blocks.STONE_BRICKS.getDefaultState());
        structure.fillWithBlocks(world, start, -17, -20, 69, -17, -19, 69, Blocks.STONE_BRICKS.getDefaultState());
        structure.fillWithBlocks(world, start, -17, -20, 70, -17, -20, 71, Blocks.CRACKED_STONE_BRICKS.getDefaultState());
        structure.fillWithBlocks(world, start, -17, -20, 72, -17, -20, 75, Blocks.STONE_BRICKS.getDefaultState());
        structure.fillWithBlocks(world, start, -17, -20, 76, -16, -19, 76, Blocks.CRACKED_STONE_BRICKS.getDefaultState());
        structure.fillWithBlocks(world, start, -17, -20, 77, -16, -20, 78, Blocks.STONE_BRICKS.getDefaultState());
        structure.fillWithBlocks(world, start, -17, -20, 81, -15, -19, 81, Blocks.STONE_BRICKS.getDefaultState());
        structure.fillWithBlocks(world, start, -17, -20, 82, -16, -20, 82, Blocks.MOSSY_STONE_BRICKS.getDefaultState());
        structure.fillWithBlocks(world, start, -17, -20, 83, -17, -19, 83, Blocks.CRACKED_STONE_BRICKS.getDefaultState());
        structure.fillWithBlocks(world, start, -17, -20, 95, -14, -20, 95, Blocks.STONE_BRICKS.getDefaultState());
        structure.fillWithBlocks(world, start, -17, -20, 97, -17, -20, 97, Blocks.CRACKED_STONE_BRICKS.getDefaultState());
        structure.fillWithBlocks(world, start, -17, -20, 100, -15, -20, 100, Blocks.STONE_BRICKS.getDefaultState());
        structure.fillWithBlocks(world, start, -17, -19, 7, -17, -19, 8, Blocks.STONE_BRICKS.getDefaultState());
        structure.fillWithBlocks(world, start, -17, -19, 9, -17, -19, 10, Blocks.CRACKED_STONE_BRICKS.getDefaultState());
        structure.fillWithBlocks(world, start, -17, -19, 17, -15, -19, 17, Blocks.STONE_BRICKS.getDefaultState());
        structure.fillWithBlocks(world, start, -17, -19, 18, -17, -18, 18, Blocks.CRACKED_STONE_BRICKS.getDefaultState());
        structure.fillWithBlocks(world, start, -17, -19, 20, -17, -18, 20, Blocks.CRACKED_STONE_BRICKS.getDefaultState());
        structure.fillWithBlocks(world, start, -17, -19, 21, -17, -17, 21, Blocks.STONE_BRICKS.getDefaultState());
        structure.fillWithBlocks(world, start, -17, -19, 70, -17, -19, 71, Blocks.CRACKED_STONE_BRICKS.getDefaultState());
        structure.fillWithBlocks(world, start, -17, -19, 73, -17, -19, 74, Blocks.CRACKED_STONE_BRICKS.getDefaultState());
        structure.fillWithBlocks(world, start, -17, -19, 77, -17, -19, 77, Blocks.STONE_BRICKS.getDefaultState());
        structure.fillWithBlocks(world, start, -17, -19, 82, -17, -19, 83, Blocks.CRACKED_STONE_BRICKS.getDefaultState());
        structure.fillWithBlocks(world, start, -17, -19, 87, -17, -19, 87, Blocks.MOSSY_STONE_BRICKS.getDefaultState());
        structure.fillWithBlocks(world, start, -17, -19, 88, -17, -17, 88, Blocks.STONE_BRICKS.getDefaultState());
        structure.fillWithBlocks(world, start, -17, -19, 90, -16, -18, 90, Blocks.STONE_BRICKS.getDefaultState());
        structure.fillWithBlocks(world, start, -17, -19, 92, -17, -19, 92, Blocks.STONE_BRICKS.getDefaultState());
        structure.fillWithBlocks(world, start, -17, -19, 93, -17, -18, 93, Blocks.CRACKED_STONE_BRICKS.getDefaultState());
        structure.fillWithBlocks(world, start, -17, -19, 94, -17, -18, 95, Blocks.STONE_BRICKS.getDefaultState());
        structure.fillWithBlocks(world, start, -17, -19, 97, -16, -19, 97, Blocks.CRACKED_STONE_BRICKS.getDefaultState());
        structure.fillWithBlocks(world, start, -17, -19, 98, -17, -19, 98, Blocks.STONE_BRICKS.getDefaultState());
        structure.fillWithBlocks(world, start, -17, -19, 100, -16, -19, 101, Blocks.CRACKED_STONE_BRICKS.getDefaultState());
        structure.fillWithBlocks(world, start, -17, -18, 10, -17, -17, 11, Blocks.STONE_BRICKS.getDefaultState());
        structure.fillWithBlocks(world, start, -17, -18, 14, -17, -18, 16, Blocks.STONE_BRICKS.getDefaultState());
        structure.fillWithBlocks(world, start, -17, -18, 17, -17, -18, 18, Blocks.CRACKED_STONE_BRICKS.getDefaultState());
        structure.fillWithBlocks(world, start, -17, -18, 19, -17, -18, 19, Blocks.MOSSY_STONE_BRICKS.getDefaultState());
        structure.fillWithBlocks(world, start, -17, -18, 69, -15, -18, 69, Blocks.CRACKED_STONE_BRICKS.getDefaultState());
        structure.fillWithBlocks(world, start, -17, -18, 70, -16, -18, 71, Blocks.STONE_BRICKS.getDefaultState());
        structure.fillWithBlocks(world, start, -17, -18, 72, -17, -18, 73, Blocks.MOSSY_STONE_BRICKS.getDefaultState());
        structure.fillWithBlocks(world, start, -17, -18, 74, -17, -18, 74, Blocks.STONE_BRICKS.getDefaultState());
        structure.fillWithBlocks(world, start, -17, -18, 76, -17, -18, 76, Blocks.STONE_BRICKS.getDefaultState());
        structure.fillWithBlocks(world, start, -17, -18, 77, -17, -18, 78, Blocks.CRACKED_STONE_BRICKS.getDefaultState());
        structure.fillWithBlocks(world, start, -17, -18, 80, -17, -18, 80, Blocks.STONE_BRICKS.getDefaultState());
        structure.fillWithBlocks(world, start, -17, -18, 81, -17, -18, 82, Blocks.MOSSY_STONE_BRICKS.getDefaultState());
        structure.fillWithBlocks(world, start, -17, -18, 83, -17, -17, 83, Blocks.STONE_BRICKS.getDefaultState());
        structure.fillWithBlocks(world, start, -17, -18, 89, -16, -18, 90, Blocks.STONE_BRICKS.getDefaultState());
        structure.fillWithBlocks(world, start, -17, -18, 91, -17, -18, 93, Blocks.CRACKED_STONE_BRICKS.getDefaultState());
        structure.fillWithBlocks(world, start, -17, -18, 97, -16, -18, 97, Blocks.STONE_BRICKS.getDefaultState());
        structure.fillWithBlocks(world, start, -17, -18, 98, -17, -17, 98, Blocks.CRACKED_STONE_BRICKS.getDefaultState());
        structure.fillWithBlocks(world, start, -17, -18, 99, -16, -18, 101, Blocks.STONE_BRICKS.getDefaultState());
        structure.fillWithBlocks(world, start, -17, -17, 16, -15, -17, 16, Blocks.STONE_BRICKS.getDefaultState());
        structure.fillWithBlocks(world, start, -17, -17, 18, -17, -17, 18, Blocks.STONE_BRICKS.getDefaultState());
        structure.fillWithBlocks(world, start, -17, -17, 70, -17, -17, 70, Blocks.STONE_BRICKS.getDefaultState());
        structure.fillWithBlocks(world, start, -17, -17, 71, -17, -17, 71, Blocks.CRACKED_STONE_BRICKS.getDefaultState());
        structure.fillWithBlocks(world, start, -17, -17, 72, -17, -17, 73, Blocks.STONE_BRICKS.getDefaultState());
        structure.fillWithBlocks(world, start, -17, -17, 76, -17, -17, 77, Blocks.STONE_BRICKS.getDefaultState());
        structure.fillWithBlocks(world, start, -17, -17, 78, -16, -17, 78, Blocks.CRACKED_STONE_BRICKS.getDefaultState());
        structure.fillWithBlocks(world, start, -17, -17, 79, -14, -17, 79, Blocks.STONE_BRICKS.getDefaultState());
        structure.fillWithBlocks(world, start, -17, -17, 81, -16, -17, 82, Blocks.STONE_BRICKS.getDefaultState());
        structure.fillWithBlocks(world, start, -17, -17, 87, -17, -17, 93, Blocks.STONE_BRICKS.getDefaultState());
        structure.fillWithBlocks(world, start, -17, -17, 94, -17, -17, 96, Blocks.CRACKED_STONE_BRICKS.getDefaultState());
        structure.fillWithBlocks(world, start, -17, -16, 43, -14, -16, 46, Blocks.STONE_BRICKS.getDefaultState());
        structure.fillWithBlocks(world, start, -17, -15, 41, -14, -15, 41, Blocks.STONE_BRICKS.getDefaultState());
        structure.fillWithBlocks(world, start, -17, -15, 42, -15, -15, 46, Blocks.AIR.getDefaultState());
        structure.fillWithBlocks(world, start, -17, -14, 41, -17, -13, 41, Blocks.STONE_BRICKS.getDefaultState());
        structure.fillWithBlocks(world, start, -17, -14, 42, -15, -14, 46, Blocks.AIR.getDefaultState());
        structure.fillWithBlocks(world, start, -17, -14, 47, -17, -13, 47, Blocks.STONE_BRICKS.getDefaultState());
        structure.fillWithBlocks(world, start, -17, -13, 42, -15, -13, 46, Blocks.AIR.getDefaultState());
        structure.fillWithBlocks(world, start, -17, -12, 42, -15, -12, 46, Blocks.STONE_BRICKS.getDefaultState());
        structure.fillWithBlocks(world, start, -16, -56, 0, -13, -56, 3, Blocks.STONE_BRICKS.getDefaultState());
        structure.fillWithBlocks(world, start, -16, -56, 16, -15, -56, 19, Blocks.STONE_BRICKS.getDefaultState());
        structure.fillWithBlocks(world, start, -16, -56, 21, -15, -56, 22, Blocks.STONE_BRICKS.getDefaultState());
        structure.fillWithBlocks(world, start, -16, -55, 7, -16, -47, 7, Blocks.STONE_BRICKS.getDefaultState());
        structure.fillWithBlocks(world, start, -16, -55, 8, -12, -55, 12, Blocks.AIR.getDefaultState());
        structure.fillWithBlocks(world, start, -16, -55, 13, -16, -55, 22, Blocks.STONE_BRICKS.getDefaultState());
        structure.fillWithBlocks(world, start, -16, -54, 1, -15, -54, 6, Blocks.STONE_BRICKS.getDefaultState());
        structure.fillWithBlocks(world, start, -16, -54, 8, -12, -54, 12, Blocks.AIR.getDefaultState());
        structure.fillWithBlocks(world, start, -16, -54, 13, -16, -54, 22, Blocks.STONE_BRICKS.getDefaultState());
        structure.fillWithBlocks(world, start, -16, -53, -2, -16, -49, 7, Blocks.STONE_BRICKS.getDefaultState());
        structure.fillWithBlocks(world, start, -16, -53, 8, -12, -53, 12, Blocks.AIR.getDefaultState());
        structure.fillWithBlocks(world, start, -16, -53, 13, -16, -53, 21, Blocks.STONE_BRICKS.getDefaultState());
        structure.fillWithBlocks(world, start, -16, -52, 8, -12, -52, 12, Blocks.AIR.getDefaultState());
        structure.fillWithBlocks(world, start, -16, -52, 13, -16, -52, 22, Blocks.STONE_BRICKS.getDefaultState());
        structure.fillWithBlocks(world, start, -16, -51, 8, -12, -51, 12, Blocks.AIR.getDefaultState());
        structure.fillWithBlocks(world, start, -16, -51, 13, -14, -51, 17, Blocks.STONE_BRICKS.getDefaultState());
        structure.fillWithBlocks(world, start, -16, -50, 12, -14, -50, 14, Blocks.STONE_BRICKS.getDefaultState());
        structure.fillWithBlocks(world, start, -16, -50, 15, -15, -50, 16, Blocks.STONE_BRICKS.getDefaultState());
        structure.fillWithBlocks(world, start, -16, -50, 18, -15, -50, 19, Blocks.STONE_BRICKS.getDefaultState());
        structure.fillWithBlocks(world, start, -16, -50, 20, -16, -50, 22, Blocks.STONE_BRICKS.getDefaultState());
        structure.fillWithBlocks(world, start, -16, -49, 14, -15, -49, 15, Blocks.STONE_BRICKS.getDefaultState());
        structure.fillWithBlocks(world, start, -16, -49, 17, -12, -49, 22, Blocks.STONE_BRICKS.getDefaultState());
        structure.fillWithBlocks(world, start, -16, -48, 2, -14, -48, 4, Blocks.STONE_BRICKS.getDefaultState());
        structure.fillWithBlocks(world, start, -16, -48, 5, -15, -48, 14, Blocks.STONE_BRICKS.getDefaultState());
        structure.fillWithBlocks(world, start, -16, -48, 17, -15, -48, 18, Blocks.STONE_BRICKS.getDefaultState());
        structure.fillWithBlocks(world, start, -16, -47, -2, -13, -47, 1, Blocks.STONE_BRICKS.getDefaultState());
        structure.fillWithBlocks(world, start, -16, -47, 8, -13, -47, 11, Blocks.STONE_BRICKS.getDefaultState());
        structure.fillWithBlocks(world, start, -16, -47, 30, -16, -47, 32, Blocks.STONE_BRICKS.getDefaultState());
        structure.fillWithBlocks(world, start, -16, -46, 2, -16, -45, 3, Blocks.STONE_BRICKS.getDefaultState());
        structure.fillWithBlocks(world, start, -16, -46, 4, -16, -46, 4, Blocks.STONE_BRICKS.getDefaultState());
        structure.fillWithBlocks(world, start, -16, -46, 6, -11, -46, 6, Blocks.STONE_BRICKS.getDefaultState());
        structure.fillWithBlocks(world, start, -16, -46, 7, -16, -46, 9, Blocks.MOSSY_COBBLESTONE.getDefaultState());
        structure.fillWithBlocks(world, start, -16, -46, 12, -16, -46, 13, Blocks.MOSSY_COBBLESTONE.getDefaultState());
        structure.fillWithBlocks(world, start, -16, -46, 14, -16, -46, 15, Blocks.MOSSY_STONE_BRICKS.getDefaultState());
        structure.fillWithBlocks(world, start, -16, -46, 20, -14, -46, 22, Blocks.AIR.getDefaultState());
        structure.fillWithBlocks(world, start, -16, -46, 23, -15, -46, 26, Blocks.STONE_BRICKS.getDefaultState());
        structure.fillWithBlocks(world, start, -16, -46, 27, -16, -46, 28, Blocks.STONE_BRICKS.getDefaultState());
        structure.fillWithBlocks(world, start, -16, -46, 30, -14, -46, 32, Blocks.AIR.getDefaultState());
        structure.fillWithBlocks(world, start, -16, -45, 4, -16, -44, 4, Blocks.MOSSY_STONE_BRICKS.getDefaultState());
        structure.fillWithBlocks(world, start, -16, -45, 7, -16, -43, 9, Blocks.AIR.getDefaultState());
        structure.fillWithBlocks(world, start, -16, -45, 10, -16, -44, 10, Blocks.STONE_BRICK_WALL.getDefaultState().with(WallBlock.WATERLOGGED, false).with(WallBlock.UP, true).with(WallBlock.WALL_HEIGHT_NORTH, WallHeight.LOW).with(WallBlock.WALL_HEIGHT_SOUTH, WallHeight.LOW).with(WallBlock.WALL_HEIGHT_EAST, WallHeight.LOW).with(WallBlock.WALL_HEIGHT_WEST, WallHeight.LOW));
        structure.fillWithBlocks(world, start, -16, -45, 20, -14, -45, 22, Blocks.AIR.getDefaultState());
        structure.fillWithBlocks(world, start, -16, -45, 30, -14, -45, 32, Blocks.AIR.getDefaultState());
        structure.fillWithBlocks(world, start, -16, -45, 34, -15, -44, 34, Blocks.STONE_BRICKS.getDefaultState());
        structure.fillWithBlocks(world, start, -16, -44, 2, -16, -44, 4, Blocks.MOSSY_STONE_BRICKS.getDefaultState());
        structure.fillWithBlocks(world, start, -16, -44, 5, -16, -44, 6, Blocks.MOSSY_COBBLESTONE.getDefaultState());
        structure.fillWithBlocks(world, start, -16, -43, 2, -16, -42, 2, Blocks.MOSSY_STONE_BRICKS.getDefaultState());
        structure.fillWithBlocks(world, start, -16, -43, 3, -16, -43, 4, Blocks.AIR.getDefaultState());
        structure.fillWithBlocks(world, start, -16, -43, 6, -16, -42, 6, Blocks.STONE_BRICKS.getDefaultState());
        structure.fillWithBlocks(world, start, -16, -43, 34, -13, -43, 34, Blocks.STONE_BRICKS.getDefaultState());
        structure.fillWithBlocks(world, start, -16, -42, 3, -16, -42, 3, Blocks.STONE_BRICKS.getDefaultState());
        structure.fillWithBlocks(world, start, -16, -42, 5, -16, -42, 6, Blocks.STONE_BRICKS.getDefaultState());
        structure.fillWithBlocks(world, start, -16, -42, 18, -16, -41, 18, Blocks.MOSSY_STONE_BRICKS.getDefaultState());
        structure.fillWithBlocks(world, start, -16, -41, 2, -15, -41, 2, Blocks.MOSSY_COBBLESTONE.getDefaultState());
        structure.fillWithBlocks(world, start, -16, -41, 4, -15, -41, 4, Blocks.STONE_BRICKS.getDefaultState());
        structure.fillWithBlocks(world, start, -16, -41, 5, -15, -41, 5, Blocks.MOSSY_STONE_BRICKS.getDefaultState());
        structure.fillWithBlocks(world, start, -16, -41, 7, -16, -41, 11, Blocks.STONE_BRICKS.getDefaultState());
        structure.fillWithBlocks(world, start, -16, -41, 17, -16, -41, 17, Blocks.STONE_BRICKS.getDefaultState());
        structure.fillWithBlocks(world, start, -16, -41, 33, -16, -41, 34, Blocks.STONE_BRICKS.getDefaultState());
        structure.fillWithBlocks(world, start, -16, -40, 3, -16, -40, 3, Blocks.STONE_BRICKS.getDefaultState());
        structure.fillWithBlocks(world, start, -16, -40, 4, -16, -37, 4, Blocks.MOSSY_STONE_BRICKS.getDefaultState());
        structure.fillWithBlocks(world, start, -16, -40, 5, -16, -40, 5, Blocks.AIR.getDefaultState());
        structure.fillWithBlocks(world, start, -16, -40, 6, -16, -36, 6, Blocks.STONE_BRICKS.getDefaultState());
        structure.fillWithBlocks(world, start, -16, -40, 8, -16, -39, 8, Blocks.MOSSY_COBBLESTONE.getDefaultState());
        structure.fillWithBlocks(world, start, -16, -40, 9, -16, -40, 9, Blocks.STONE_BRICKS.getDefaultState());
        structure.fillWithBlocks(world, start, -16, -40, 20, -16, -40, 20, Blocks.MOSSY_STONE_BRICKS.getDefaultState());
        structure.fillWithBlocks(world, start, -16, -40, 22, -16, -40, 25, Blocks.STONE_BRICKS.getDefaultState());
        structure.fillWithBlocks(world, start, -16, -40, 27, -16, -40, 30, Blocks.MOSSY_STONE_BRICKS.getDefaultState());
        structure.fillWithBlocks(world, start, -16, -40, 33, -16, -40, 33, Blocks.MOSSY_STONE_BRICKS.getDefaultState());
        structure.fillWithBlocks(world, start, -16, -39, 2, -16, -39, 2, Blocks.STONE_BRICKS.getDefaultState());
        structure.fillWithBlocks(world, start, -16, -39, 3, -16, -38, 4, Blocks.MOSSY_STONE_BRICKS.getDefaultState());
        structure.fillWithBlocks(world, start, -16, -39, 5, -15, -39, 6, Blocks.STONE_BRICKS.getDefaultState());
        structure.fillWithBlocks(world, start, -16, -39, 9, -16, -39, 9, Blocks.MOSSY_STONE_BRICKS.getDefaultState());
        structure.fillWithBlocks(world, start, -16, -39, 10, -16, -36, 10, Blocks.MOSSY_COBBLESTONE.getDefaultState());
        structure.fillWithBlocks(world, start, -16, -39, 11, -14, -39, 11, Blocks.MOSSY_STONE_BRICKS.getDefaultState());
        structure.fillWithBlocks(world, start, -16, -39, 12, -15, -39, 13, Blocks.STONE_BRICKS.getDefaultState());
        structure.fillWithBlocks(world, start, -16, -39, 16, -16, -39, 19, Blocks.MOSSY_STONE_BRICKS.getDefaultState());
        structure.fillWithBlocks(world, start, -16, -39, 20, -16, -39, 20, Blocks.AIR.getDefaultState());
        structure.fillWithBlocks(world, start, -16, -39, 21, -16, -39, 23, Blocks.STONE_BRICKS.getDefaultState());
        structure.fillWithBlocks(world, start, -16, -39, 25, -14, -39, 25, Blocks.MOSSY_STONE_BRICKS.getDefaultState());
        structure.fillWithBlocks(world, start, -16, -39, 26, -15, -39, 27, Blocks.STONE_BRICKS.getDefaultState());
        structure.fillWithBlocks(world, start, -16, -39, 28, -16, -39, 29, Blocks.MOSSY_STONE_BRICKS.getDefaultState());
        structure.fillWithBlocks(world, start, -16, -39, 30, -16, -37, 30, Blocks.STONE_BRICKS.getDefaultState());
        structure.fillWithBlocks(world, start, -16, -38, 2, -16, -38, 2, Blocks.STONE_BRICKS.getDefaultState());
        structure.fillWithBlocks(world, start, -16, -38, 5, -16, -37, 6, Blocks.STONE_BRICKS.getDefaultState());
        structure.fillWithBlocks(world, start, -16, -38, 7, -16, -38, 7, Blocks.MOSSY_STONE_BRICKS.getDefaultState());
        structure.fillWithBlocks(world, start, -16, -38, 9, -16, -38, 10, Blocks.MOSSY_COBBLESTONE.getDefaultState());
        structure.fillWithBlocks(world, start, -16, -38, 11, -16, -38, 12, Blocks.AIR.getDefaultState());
        structure.fillWithBlocks(world, start, -16, -38, 13, -15, -38, 13, Blocks.STONE_BRICKS.getDefaultState());
        structure.fillWithBlocks(world, start, -16, -38, 14, -16, -37, 16, Blocks.AIR.getDefaultState());
        structure.fillWithBlocks(world, start, -16, -38, 17, -16, -38, 19, Blocks.STONE_BRICKS.getDefaultState());
        structure.fillWithBlocks(world, start, -16, -38, 20, -16, -37, 20, Blocks.MOSSY_STONE_BRICKS.getDefaultState());
        structure.fillWithBlocks(world, start, -16, -38, 21, -16, -36, 21, Blocks.STONE_BRICKS.getDefaultState());
        structure.fillWithBlocks(world, start, -16, -38, 22, -16, -37, 22, Blocks.MOSSY_STONE_BRICKS.getDefaultState());
        structure.fillWithBlocks(world, start, -16, -38, 31, -16, -37, 32, Blocks.STONE_BRICKS.getDefaultState());
        structure.fillWithBlocks(world, start, -16, -38, 33, -16, -38, 34, Blocks.MOSSY_STONE_BRICKS.getDefaultState());
        structure.fillWithBlocks(world, start, -16, -37, 7, -16, -36, 8, Blocks.STONE_BRICKS.getDefaultState());
        structure.fillWithBlocks(world, start, -16, -37, 9, -16, -37, 10, Blocks.MOSSY_COBBLESTONE.getDefaultState());
        structure.fillWithBlocks(world, start, -16, -37, 11, -15, -37, 13, Blocks.AIR.getDefaultState());
        structure.fillWithBlocks(world, start, -16, -37, 19, -16, -37, 20, Blocks.MOSSY_STONE_BRICKS.getDefaultState());
        structure.fillWithBlocks(world, start, -16, -37, 23, -16, -37, 24, Blocks.STONE_BRICKS.getDefaultState());
        structure.fillWithBlocks(world, start, -16, -37, 25, -16, -37, 26, Blocks.MOSSY_COBBLESTONE.getDefaultState());
        structure.fillWithBlocks(world, start, -16, -37, 27, -16, -36, 28, Blocks.STONE_BRICKS.getDefaultState());
        structure.fillWithBlocks(world, start, -16, -37, 33, -13, -37, 33, Blocks.STONE_BRICKS.getDefaultState());
        structure.fillWithBlocks(world, start, -16, -37, 34, -16, -36, 34, Blocks.MOSSY_STONE_BRICKS.getDefaultState());
        structure.fillWithBlocks(world, start, -16, -37, 36, -15, -37, 37, Blocks.STONE_BRICKS.getDefaultState());
        structure.fillWithBlocks(world, start, -16, -36, -20, -8, -36, -11, Blocks.STONE_BRICKS.getDefaultState());
        structure.fillWithBlocks(world, start, -16, -36, 0, -15, -36, 2, Blocks.STONE_BRICKS.getDefaultState());
        structure.fillWithBlocks(world, start, -16, -36, 25, -15, -36, 27, Blocks.STONE_BRICKS.getDefaultState());
        structure.fillWithBlocks(world, start, -16, -36, 29, -16, -36, 30, Blocks.MOSSY_STONE_BRICKS.getDefaultState());
        structure.fillWithBlocks(world, start, -16, -36, 32, -16, -36, 32, Blocks.STONE_BRICKS.getDefaultState());
        structure.fillWithBlocks(world, start, -16, -36, 33, -16, -36, 34, Blocks.MOSSY_STONE_BRICKS.getDefaultState());
        structure.fillWithBlocks(world, start, -16, -36, 38, -16, -36, 38, Blocks.MOSSY_STONE_BRICKS.getDefaultState());
        structure.fillWithBlocks(world, start, -16, -35, -20, -11, -35, -15, Blocks.AIR.getDefaultState());
        structure.fillWithBlocks(world, start, -16, -35, 31, -14, -35, 33, Blocks.AIR.getDefaultState());
        structure.fillWithBlocks(world, start, -16, -35, 39, -9, -35, 39, Blocks.STONE_BRICKS.getDefaultState());
        structure.fillWithBlocks(world, start, -16, -34, -30, -16, -34, -29, Blocks.STONE_BRICKS.getDefaultState());
        structure.fillWithBlocks(world, start, -16, -34, 39, -15, -34, 39, Blocks.MOSSY_STONE_BRICKS.getDefaultState());
        structure.fillWithBlocks(world, start, -16, -33, -30, -15, -33, -29, Blocks.STONE_BRICKS.getDefaultState());
        structure.fillWithBlocks(world, start, -16, -33, -11, -15, -33, -10, Blocks.STONE_BRICKS.getDefaultState());
        structure.fillWithBlocks(world, start, -16, -32, -30, -14, -32, -30, Blocks.MOSSY_STONE_BRICKS.getDefaultState());
        structure.fillWithBlocks(world, start, -16, -32, -29, -14, -32, -29, Blocks.STONE_BRICKS.getDefaultState());
        structure.fillWithBlocks(world, start, -16, -32, -11, -16, -32, -10, Blocks.STONE_BRICKS.getDefaultState());
        structure.fillWithBlocks(world, start, -16, -32, -7, -14, -31, -7, Blocks.STONE_BRICKS.getDefaultState());
        structure.fillWithBlocks(world, start, -16, -32, -6, -16, -32, -6, Blocks.MOSSY_STONE_BRICKS.getDefaultState());
        structure.fillWithBlocks(world, start, -16, -32, -5, -16, -32, -4, Blocks.STONE_BRICKS.getDefaultState());
        structure.fillWithBlocks(world, start, -16, -32, -2, -16, -32, -2, Blocks.STONE_BRICKS.getDefaultState());
        structure.fillWithBlocks(world, start, -16, -32, 0, -13, -31, 0, Blocks.STONE_BRICKS.getDefaultState());
        structure.fillWithBlocks(world, start, -16, -32, 1, -15, -32, 1, Blocks.MOSSY_STONE_BRICKS.getDefaultState());
        structure.fillWithBlocks(world, start, -16, -32, 3, -15, -32, 3, Blocks.MOSSY_STONE_BRICKS.getDefaultState());
        structure.fillWithBlocks(world, start, -16, -32, 4, -15, -32, 5, Blocks.STONE_BRICKS.getDefaultState());
        structure.fillWithBlocks(world, start, -16, -32, 7, -15, -32, 9, Blocks.STONE_BRICKS.getDefaultState());
        structure.fillWithBlocks(world, start, -16, -32, 39, -16, -30, 39, Blocks.STONE_BRICKS.getDefaultState());
        structure.fillWithBlocks(world, start, -16, -31, -30, -16, -31, -29, Blocks.MOSSY_STONE_BRICKS.getDefaultState());
        structure.fillWithBlocks(world, start, -16, -31, -11, -15, -31, -10, Blocks.STONE_BRICKS.getDefaultState());
        structure.fillWithBlocks(world, start, -16, -31, -6, -16, -31, -4, Blocks.STONE_BRICKS.getDefaultState());
        structure.fillWithBlocks(world, start, -16, -31, -3, -16, -31, -2, Blocks.MOSSY_STONE_BRICKS.getDefaultState());
        structure.fillWithBlocks(world, start, -16, -31, 10, -16, -30, 10, Blocks.STONE_BRICKS.getDefaultState());
        structure.fillWithBlocks(world, start, -16, -31, 19, -16, -31, 21, Blocks.STONE_BRICKS.getDefaultState());
        structure.fillWithBlocks(world, start, -16, -31, 35, -15, -31, 37, Blocks.AIR.getDefaultState());
        structure.fillWithBlocks(world, start, -16, -31, 38, -16, -30, 39, Blocks.STONE_BRICKS.getDefaultState());
        structure.fillWithBlocks(world, start, -16, -30, -30, -15, -30, -29, Blocks.STONE_BRICKS.getDefaultState());
        structure.fillWithBlocks(world, start, -16, -30, -27, -16, -29, -27, Blocks.MOSSY_STONE_BRICKS.getDefaultState());
        structure.fillWithBlocks(world, start, -16, -30, -26, -16, -29, -26, Blocks.STONE_BRICKS.getDefaultState());
        structure.fillWithBlocks(world, start, -16, -30, -25, -16, -30, -24, Blocks.MOSSY_STONE_BRICKS.getDefaultState());
        structure.fillWithBlocks(world, start, -16, -30, -23, -16, -30, -22, Blocks.STONE_BRICKS.getDefaultState());
        structure.fillWithBlocks(world, start, -16, -30, -20, -16, -30, -16, Blocks.STONE_BRICKS.getDefaultState());
        structure.fillWithBlocks(world, start, -16, -30, -13, -15, -30, -12, Blocks.STONE_BRICKS.getDefaultState());
        structure.fillWithBlocks(world, start, -16, -30, -5, -16, -30, -3, Blocks.MOSSY_STONE_BRICKS.getDefaultState());
        structure.fillWithBlocks(world, start, -16, -30, -2, -16, -30, -1, Blocks.STONE_BRICKS.getDefaultState());
        structure.fillWithBlocks(world, start, -16, -30, 1, -15, -30, 1, Blocks.STONE_BRICKS.getDefaultState());
        structure.fillWithBlocks(world, start, -16, -30, 8, -16, -29, 8, Blocks.MOSSY_STONE_BRICKS.getDefaultState());
        structure.fillWithBlocks(world, start, -16, -30, 9, -14, -30, 11, Blocks.STONE_BRICKS.getDefaultState());
        structure.fillWithBlocks(world, start, -16, -30, 12, -16, -30, 13, Blocks.MOSSY_COBBLESTONE.getDefaultState());
        structure.fillWithBlocks(world, start, -16, -30, 14, -15, -30, 15, Blocks.STONE_BRICKS.getDefaultState());
        structure.fillWithBlocks(world, start, -16, -30, 16, -16, -30, 16, Blocks.MOSSY_COBBLESTONE.getDefaultState());
        structure.fillWithBlocks(world, start, -16, -30, 17, -16, -30, 19, Blocks.STONE_BRICKS.getDefaultState());
        structure.fillWithBlocks(world, start, -16, -30, 20, -16, -30, 21, Blocks.CRACKED_STONE_BRICKS.getDefaultState());
        structure.fillWithBlocks(world, start, -16, -30, 23, -16, -30, 23, Blocks.MOSSY_STONE_BRICKS.getDefaultState());
        structure.fillWithBlocks(world, start, -16, -30, 24, -16, -30, 25, Blocks.STONE_BRICKS.getDefaultState());
        structure.fillWithBlocks(world, start, -16, -30, 26, -16, -30, 26, Blocks.MOSSY_STONE_BRICKS.getDefaultState());
        structure.fillWithBlocks(world, start, -16, -30, 31, -16, -30, 32, Blocks.MOSSY_STONE_BRICKS.getDefaultState());
        structure.fillWithBlocks(world, start, -16, -30, 33, -16, -30, 35, Blocks.STONE_BRICKS.getDefaultState());
        structure.fillWithBlocks(world, start, -16, -30, 36, -16, -30, 36, Blocks.MOSSY_STONE_BRICKS.getDefaultState());
        structure.fillWithBlocks(world, start, -16, -30, 37, -16, -30, 39, Blocks.STONE_BRICKS.getDefaultState());
        structure.fillWithBlocks(world, start, -16, -29, -28, -14, -28, -28, Blocks.STONE_BRICKS.getDefaultState());
        structure.fillWithBlocks(world, start, -16, -29, -25, -16, -28, -25, Blocks.STONE_BRICKS.getDefaultState());
        structure.fillWithBlocks(world, start, -16, -29, -24, -16, -29, -22, Blocks.MOSSY_STONE_BRICKS.getDefaultState());
        structure.fillWithBlocks(world, start, -16, -29, -21, -16, -29, -21, Blocks.STONE_BRICKS.getDefaultState());
        structure.fillWithBlocks(world, start, -16, -29, -20, -16, -29, -19, Blocks.MOSSY_STONE_BRICKS.getDefaultState());
        structure.fillWithBlocks(world, start, -16, -29, -18, -16, -29, -18, Blocks.STONE_BRICKS.getDefaultState());
        structure.fillWithBlocks(world, start, -16, -29, -16, -16, -28, -13, Blocks.STONE_BRICKS.getDefaultState());
        structure.fillWithBlocks(world, start, -16, -29, -11, -16, -27, -11, Blocks.STONE_BRICKS.getDefaultState());
        structure.fillWithBlocks(world, start, -16, -29, -10, -15, -29, -10, Blocks.CRACKED_STONE_BRICKS.getDefaultState());
        structure.fillWithBlocks(world, start, -16, -29, -1, -15, -29, 0, Blocks.STONE_BRICKS.getDefaultState());
        structure.fillWithBlocks(world, start, -16, -29, 9, -16, -29, 9, Blocks.STONE_BRICKS.getDefaultState());
        structure.fillWithBlocks(world, start, -16, -29, 11, -15, -29, 11, Blocks.STONE_BRICKS.getDefaultState());
        structure.fillWithBlocks(world, start, -16, -29, 13, -16, -29, 13, Blocks.MOSSY_STONE_BRICKS.getDefaultState());
        structure.fillWithBlocks(world, start, -16, -29, 14, -16, -29, 18, Blocks.STONE_BRICKS.getDefaultState());
        structure.fillWithBlocks(world, start, -16, -29, 20, -16, -29, 20, Blocks.STONE_BRICKS.getDefaultState());
        structure.fillWithBlocks(world, start, -16, -29, 23, -14, -28, 23, Blocks.STONE_BRICKS.getDefaultState());
        structure.fillWithBlocks(world, start, -16, -29, 26, -16, -28, 26, Blocks.CRACKED_STONE_BRICKS.getDefaultState());
        structure.fillWithBlocks(world, start, -16, -29, 27, -15, -29, 28, Blocks.MOSSY_STONE_BRICKS.getDefaultState());
        structure.fillWithBlocks(world, start, -16, -29, 29, -16, -27, 29, Blocks.STONE_BRICKS.getDefaultState());
        structure.fillWithBlocks(world, start, -16, -29, 30, -16, -29, 31, Blocks.MOSSY_STONE_BRICKS.getDefaultState());
        structure.fillWithBlocks(world, start, -16, -29, 32, -13, -29, 32, Blocks.STONE_BRICKS.getDefaultState());
        structure.fillWithBlocks(world, start, -16, -29, 37, -15, -29, 38, Blocks.STONE_BRICKS.getDefaultState());
        structure.fillWithBlocks(world, start, -16, -28, -27, -16, -28, -26, Blocks.CRACKED_STONE_BRICKS.getDefaultState());
        structure.fillWithBlocks(world, start, -16, -28, -24, -14, -28, -24, Blocks.STONE_BRICKS.getDefaultState());
        structure.fillWithBlocks(world, start, -16, -28, -23, -16, -28, -23, Blocks.MOSSY_STONE_BRICKS.getDefaultState());
        structure.fillWithBlocks(world, start, -16, -28, -22, -16, -27, -22, Blocks.STONE_BRICKS.getDefaultState());
        structure.fillWithBlocks(world, start, -16, -28, -20, -16, -28, -20, Blocks.STONE_BRICKS.getDefaultState());
        structure.fillWithBlocks(world, start, -16, -28, -18, -16, -27, -18, Blocks.MOSSY_STONE_BRICKS.getDefaultState());
        structure.fillWithBlocks(world, start, -16, -28, -17, -16, -27, -16, Blocks.STONE_BRICKS.getDefaultState());
        structure.fillWithBlocks(world, start, -16, -28, -7, -15, -28, -7, Blocks.MOSSY_STONE_BRICKS.getDefaultState());
        structure.fillWithBlocks(world, start, -16, -28, -5, -16, -28, -4, Blocks.MOSSY_STONE_BRICKS.getDefaultState());
        structure.fillWithBlocks(world, start, -16, -28, -3, -13, -28, 0, Blocks.STONE_BRICKS.getDefaultState());
        structure.fillWithBlocks(world, start, -16, -28, 1, -16, -27, 1, Blocks.STONE_BRICKS.getDefaultState());
        structure.fillWithBlocks(world, start, -16, -28, 8, -16, -28, 8, Blocks.STONE_BRICKS.getDefaultState());
        structure.fillWithBlocks(world, start, -16, -28, 10, -16, -28, 12, Blocks.STONE_BRICKS.getDefaultState());
        structure.fillWithBlocks(world, start, -16, -28, 13, -16, -28, 14, Blocks.MOSSY_STONE_BRICKS.getDefaultState());
        structure.fillWithBlocks(world, start, -16, -28, 15, -16, -27, 16, Blocks.STONE_BRICKS.getDefaultState());
        structure.fillWithBlocks(world, start, -16, -28, 17, -16, -28, 18, Blocks.STONE_BRICKS.getDefaultState());
        structure.fillWithBlocks(world, start, -16, -28, 20, -16, -28, 20, Blocks.STONE_BRICKS.getDefaultState());
        structure.fillWithBlocks(world, start, -16, -28, 21, -16, -27, 21, Blocks.MOSSY_STONE_BRICKS.getDefaultState());
        structure.fillWithBlocks(world, start, -16, -28, 24, -13, -28, 24, Blocks.STONE_BRICKS.getDefaultState());
        structure.fillWithBlocks(world, start, -16, -28, 25, -16, -28, 26, Blocks.CRACKED_STONE_BRICKS.getDefaultState());
        structure.fillWithBlocks(world, start, -16, -28, 27, -16, -28, 27, Blocks.STONE_BRICKS.getDefaultState());
        structure.fillWithBlocks(world, start, -16, -28, 31, -16, -27, 32, Blocks.STONE_BRICKS.getDefaultState());
        structure.fillWithBlocks(world, start, -16, -28, 35, -15, -28, 36, Blocks.STONE_BRICKS.getDefaultState());
        structure.fillWithBlocks(world, start, -16, -28, 37, -16, -27, 37, Blocks.STONE_BRICKS.getDefaultState());
        structure.fillWithBlocks(world, start, -16, -28, 38, -16, -28, 38, Blocks.MOSSY_STONE_BRICKS.getDefaultState());
        structure.fillWithBlocks(world, start, -16, -28, 39, -16, -27, 39, Blocks.STONE_BRICKS.getDefaultState());
        structure.fillWithBlocks(world, start, -16, -27, -29, -16, -27, -28, Blocks.STONE_BRICKS.getDefaultState());
        structure.fillWithBlocks(world, start, -16, -27, -27, -16, -27, -25, Blocks.MOSSY_STONE_BRICKS.getDefaultState());
        structure.fillWithBlocks(world, start, -16, -27, -23, -15, -27, -23, Blocks.MOSSY_STONE_BRICKS.getDefaultState());
        structure.fillWithBlocks(world, start, -16, -27, -21, -16, -27, -20, Blocks.STONE_BRICKS.getDefaultState());
        structure.fillWithBlocks(world, start, -16, -27, -15, -14, -27, -15, Blocks.MOSSY_STONE_BRICKS.getDefaultState());
        structure.fillWithBlocks(world, start, -16, -27, -13, -15, -27, -12, Blocks.STONE_BRICKS.getDefaultState());
        structure.fillWithBlocks(world, start, -16, -27, -7, -16, -27, -5, Blocks.STONE_BRICKS.getDefaultState());
        structure.fillWithBlocks(world, start, -16, -27, 0, -15, -27, 1, Blocks.STONE_BRICKS.getDefaultState());
        structure.fillWithBlocks(world, start, -16, -27, 7, -16, -27, 9, Blocks.CRACKED_STONE_BRICKS.getDefaultState());
        structure.fillWithBlocks(world, start, -16, -27, 10, -16, -25, 10, Blocks.MOSSY_STONE_BRICKS.getDefaultState());
        structure.fillWithBlocks(world, start, -16, -27, 11, -16, -27, 11, Blocks.STONE_BRICKS.getDefaultState());
        structure.fillWithBlocks(world, start, -16, -27, 13, -16, -26, 13, Blocks.STONE_BRICKS.getDefaultState());
        structure.fillWithBlocks(world, start, -16, -27, 17, -16, -27, 18, Blocks.MOSSY_STONE_BRICKS.getDefaultState());
        structure.fillWithBlocks(world, start, -16, -27, 19, -15, -27, 20, Blocks.STONE_BRICKS.getDefaultState());
        structure.fillWithBlocks(world, start, -16, -27, 23, -16, -27, 26, Blocks.MOSSY_STONE_BRICKS.getDefaultState());
        structure.fillWithBlocks(world, start, -16, -27, 27, -15, -27, 30, Blocks.STONE_BRICKS.getDefaultState());
        structure.fillWithBlocks(world, start, -16, -27, 36, -15, -27, 38, Blocks.STONE_BRICKS.getDefaultState());
        structure.fillWithBlocks(world, start, -16, -26, 7, -15, -26, 7, Blocks.CRACKED_STONE_BRICKS.getDefaultState());
        structure.fillWithBlocks(world, start, -16, -26, 8, -16, -26, 8, Blocks.STONE_BRICKS.getDefaultState());
        structure.fillWithBlocks(world, start, -16, -26, 9, -16, -25, 9, Blocks.CRACKED_STONE_BRICKS.getDefaultState());
        structure.fillWithBlocks(world, start, -16, -26, 16, -16, -26, 21, Blocks.STONE_BRICKS.getDefaultState());
        structure.fillWithBlocks(world, start, -16, -26, 42, -15, -26, 46, Blocks.STONE_BRICKS.getDefaultState());
        structure.fillWithBlocks(world, start, -16, -26, 70, -16, -25, 70, Blocks.STONE_BRICKS.getDefaultState());
        structure.fillWithBlocks(world, start, -16, -26, 71, -15, -26, 71, Blocks.CRACKED_STONE_BRICKS.getDefaultState());
        structure.fillWithBlocks(world, start, -16, -26, 72, -16, -26, 78, Blocks.STONE_BRICKS.getDefaultState());
        structure.fillWithBlocks(world, start, -16, -26, 79, -16, -26, 80, Blocks.CRACKED_STONE_BRICKS.getDefaultState());
        structure.fillWithBlocks(world, start, -16, -26, 88, -15, -26, 91, Blocks.STONE_BRICKS.getDefaultState());
        structure.fillWithBlocks(world, start, -16, -26, 94, -16, -26, 94, Blocks.CRACKED_STONE_BRICKS.getDefaultState());
        structure.fillWithBlocks(world, start, -16, -26, 96, -16, -26, 100, Blocks.STONE_BRICKS.getDefaultState());
        structure.fillWithBlocks(world, start, -16, -25, 7, -16, -25, 8, Blocks.STONE_BRICKS.getDefaultState());
        structure.fillWithBlocks(world, start, -16, -25, 11, -16, -24, 11, Blocks.STONE_BRICKS.getDefaultState());
        structure.fillWithBlocks(world, start, -16, -25, 12, -16, -25, 16, Blocks.AIR.getDefaultState());
        structure.fillWithBlocks(world, start, -16, -25, 17, -15, -25, 17, Blocks.MOSSY_STONE_BRICKS.getDefaultState());
        structure.fillWithBlocks(world, start, -16, -25, 18, -16, -25, 19, Blocks.CRACKED_STONE_BRICKS.getDefaultState());
        structure.fillWithBlocks(world, start, -16, -25, 20, -16, -25, 21, Blocks.STONE_BRICKS.getDefaultState());
        structure.fillWithBlocks(world, start, -16, -25, 69, -15, -25, 70, Blocks.STONE_BRICKS.getDefaultState());
        structure.fillWithBlocks(world, start, -16, -25, 71, -16, -22, 71, Blocks.STONE_BRICKS.getDefaultState());
        structure.fillWithBlocks(world, start, -16, -25, 72, -16, -24, 73, Blocks.AIR.getDefaultState());
        structure.fillWithBlocks(world, start, -16, -25, 74, -16, -22, 74, Blocks.STONE_BRICKS.getDefaultState());
        structure.fillWithBlocks(world, start, -16, -25, 75, -14, -25, 77, Blocks.AIR.getDefaultState());
        structure.fillWithBlocks(world, start, -16, -25, 78, -16, -18, 78, Blocks.STONE_BRICKS.getDefaultState());
        structure.fillWithBlocks(world, start, -16, -25, 79, -16, -24, 80, Blocks.AIR.getDefaultState());
        structure.fillWithBlocks(world, start, -16, -25, 81, -15, -24, 81, Blocks.STONE_BRICKS.getDefaultState());
        structure.fillWithBlocks(world, start, -16, -25, 82, -16, -24, 82, Blocks.CRACKED_STONE_BRICKS.getDefaultState());
        structure.fillWithBlocks(world, start, -16, -25, 87, -16, -25, 87, Blocks.CRACKED_STONE_BRICKS.getDefaultState());
        structure.fillWithBlocks(world, start, -16, -25, 88, -16, -25, 89, Blocks.STONE_BRICKS.getDefaultState());
        structure.fillWithBlocks(world, start, -16, -25, 90, -16, -24, 91, Blocks.AIR.getDefaultState());
        structure.fillWithBlocks(world, start, -16, -25, 92, -16, -21, 92, Blocks.STONE_BRICKS.getDefaultState());
        structure.fillWithBlocks(world, start, -16, -25, 93, -16, -22, 93, Blocks.AIR.getDefaultState());
        structure.fillWithBlocks(world, start, -16, -25, 95, -16, -22, 95, Blocks.AIR.getDefaultState());
        structure.fillWithBlocks(world, start, -16, -25, 96, -16, -21, 96, Blocks.STONE_BRICKS.getDefaultState());
        structure.fillWithBlocks(world, start, -16, -25, 97, -16, -24, 98, Blocks.AIR.getDefaultState());
        structure.fillWithBlocks(world, start, -16, -25, 99, -16, -25, 101, Blocks.STONE_BRICKS.getDefaultState());
        structure.fillWithBlocks(world, start, -16, -24, 9, -15, -24, 9, Blocks.MOSSY_STONE_BRICKS.getDefaultState());
        structure.fillWithBlocks(world, start, -16, -24, 10, -16, -24, 11, Blocks.STONE_BRICKS.getDefaultState());
        structure.fillWithBlocks(world, start, -16, -24, 12, -16, -24, 16, Blocks.AIR.getDefaultState());
        structure.fillWithBlocks(world, start, -16, -24, 17, -16, -24, 17, Blocks.STONE_BRICKS.getDefaultState());
        structure.fillWithBlocks(world, start, -16, -24, 19, -16, -24, 20, Blocks.STONE_BRICKS.getDefaultState());
        structure.fillWithBlocks(world, start, -16, -24, 69, -16, -23, 69, Blocks.STONE_BRICKS.getDefaultState());
        structure.fillWithBlocks(world, start, -16, -24, 75, -14, -24, 77, Blocks.AIR.getDefaultState());
        structure.fillWithBlocks(world, start, -16, -24, 83, -16, -23, 83, Blocks.STONE_BRICKS.getDefaultState());
        structure.fillWithBlocks(world, start, -16, -24, 87, -16, -24, 89, Blocks.STONE_BRICKS.getDefaultState());
        structure.fillWithBlocks(world, start, -16, -24, 94, -16, -23, 95, Blocks.AIR.getDefaultState());
        structure.fillWithBlocks(world, start, -16, -24, 99, -16, -24, 99, Blocks.STONE_BRICKS.getDefaultState());
        structure.fillWithBlocks(world, start, -16, -24, 101, -14, -24, 101, Blocks.STONE_BRICKS.getDefaultState());
        structure.fillWithBlocks(world, start, -16, -23, 8, -15, -23, 9, Blocks.STONE_BRICKS.getDefaultState());
        structure.fillWithBlocks(world, start, -16, -23, 10, -16, -23, 11, Blocks.MOSSY_STONE_BRICKS.getDefaultState());
        structure.fillWithBlocks(world, start, -16, -23, 12, -16, -23, 16, Blocks.AIR.getDefaultState());
        structure.fillWithBlocks(world, start, -16, -23, 17, -15, -23, 18, Blocks.STONE_BRICKS.getDefaultState());
        structure.fillWithBlocks(world, start, -16, -23, 47, -15, -23, 47, Blocks.STONE_BRICKS.getDefaultState());
        structure.fillWithBlocks(world, start, -16, -23, 70, -15, -23, 71, Blocks.STONE_BRICKS.getDefaultState());
