package mod.arcalitegames.odyssey.world.structure.structures.dungeons.highguard_castle;

import mod.arcalitegames.odyssey.world.structure.StructureBase;
import net.minecraft.block.Blocks;
import net.minecraft.block.FourWayBlock;
import net.minecraft.block.LeavesBlock;
import net.minecraft.block.SnowyDirtBlock;
import net.minecraft.block.StairsBlock;
import net.minecraft.block.WallBlock;
import net.minecraft.block.WallHeight;
import net.minecraft.state.properties.Half;
import net.minecraft.state.properties.StairsShape;
import net.minecraft.util.Direction;
import net.minecraft.util.math.BlockPos;
import net.minecraft.world.World;

public class HighguardComponent8
{
	public static BlockPos start;
    public static World world;
    public static StructureBase structure;

    public static void init(World worldIn, BlockPos blockPos, StructureBase structureIn)
    {
        world = worldIn; start = blockPos; structure = structureIn;
    }
    
    public static void generatePart81()
    {
        structure.fillWithBlocks(world, start, 54, -39, 48, 54, -39, 48, Blocks.MOSSY_COBBLESTONE.getDefaultState());
        structure.fillWithBlocks(world, start, 54, -39, 49, 54, -38, 49, Blocks.STONE_BRICKS.getDefaultState());
        structure.fillWithBlocks(world, start, 54, -39, 54, 54, -38, 55, Blocks.STONE_BRICKS.getDefaultState());
        structure.fillWithBlocks(world, start, 54, -39, 57, 54, -39, 58, Blocks.STONE_BRICKS.getDefaultState());
        structure.fillWithBlocks(world, start, 54, -39, 59, 54, -39, 60, Blocks.MOSSY_COBBLESTONE.getDefaultState());
        structure.fillWithBlocks(world, start, 54, -39, 61, 54, -38, 61, Blocks.MOSSY_STONE_BRICKS.getDefaultState());
        structure.fillWithBlocks(world, start, 54, -39, 62, 54, -39, 63, Blocks.STONE_BRICKS.getDefaultState());
        structure.fillWithBlocks(world, start, 54, -38, 18, 55, -38, 18, Blocks.MOSSY_STONE_BRICKS.getDefaultState());
        structure.fillWithBlocks(world, start, 54, -38, 19, 54, -38, 19, Blocks.MOSSY_COBBLESTONE.getDefaultState());
        structure.fillWithBlocks(world, start, 54, -38, 24, 54, -37, 24, Blocks.STONE_BRICKS.getDefaultState());
        structure.fillWithBlocks(world, start, 54, -38, 25, 54, -38, 25, Blocks.MOSSY_COBBLESTONE.getDefaultState());
        structure.fillWithBlocks(world, start, 54, -38, 26, 54, -38, 27, Blocks.STONE_BRICKS.getDefaultState());
        structure.fillWithBlocks(world, start, 54, -38, 32, 54, -38, 33, Blocks.STONE_BRICKS.getDefaultState());
        structure.fillWithBlocks(world, start, 54, -38, 37, 54, -38, 37, Blocks.MOSSY_STONE_BRICKS.getDefaultState());
        structure.fillWithBlocks(world, start, 54, -38, 38, 54, -37, 38, Blocks.STONE_BRICKS.getDefaultState());
        structure.fillWithBlocks(world, start, 54, -38, 41, 55, -38, 42, Blocks.STONE_BRICKS.getDefaultState());
        structure.fillWithBlocks(world, start, 54, -38, 44, 55, -38, 45, Blocks.STONE_BRICKS.getDefaultState());
        structure.fillWithBlocks(world, start, 54, -38, 47, 54, -38, 51, Blocks.STONE_BRICKS.getDefaultState());
        structure.fillWithBlocks(world, start, 54, -38, 52, 54, -37, 52, Blocks.MOSSY_STONE_BRICKS.getDefaultState());
        structure.fillWithBlocks(world, start, 54, -38, 53, 54, -38, 53, Blocks.AIR.getDefaultState());
        structure.fillWithBlocks(world, start, 54, -38, 58, 54, -38, 59, Blocks.MOSSY_STONE_BRICKS.getDefaultState());
        structure.fillWithBlocks(world, start, 54, -38, 60, 54, -37, 60, Blocks.STONE_BRICKS.getDefaultState());
        structure.fillWithBlocks(world, start, 54, -38, 62, 54, -37, 63, Blocks.MOSSY_STONE_BRICKS.getDefaultState());
        structure.fillWithBlocks(world, start, 54, -37, 14, 54, -37, 14, Blocks.MOSSY_STONE_BRICKS.getDefaultState());
        structure.fillWithBlocks(world, start, 54, -37, 15, 54, -37, 20, Blocks.STONE_BRICKS.getDefaultState());
        structure.fillWithBlocks(world, start, 54, -37, 23, 54, -37, 26, Blocks.STONE_BRICKS.getDefaultState());
        structure.fillWithBlocks(world, start, 54, -37, 27, 54, -37, 27, Blocks.MOSSY_COBBLESTONE.getDefaultState());
        structure.fillWithBlocks(world, start, 54, -37, 28, 54, -37, 29, Blocks.MOSSY_STONE_BRICKS.getDefaultState());
        structure.fillWithBlocks(world, start, 54, -37, 30, 55, -37, 31, Blocks.STONE_BRICKS.getDefaultState());
        structure.fillWithBlocks(world, start, 54, -37, 32, 54, -37, 32, Blocks.STONE_BRICKS.getDefaultState());
        structure.fillWithBlocks(world, start, 54, -37, 33, 54, -37, 33, Blocks.MOSSY_STONE_BRICKS.getDefaultState());
        structure.fillWithBlocks(world, start, 54, -37, 34, 54, -37, 38, Blocks.STONE_BRICKS.getDefaultState());
        structure.fillWithBlocks(world, start, 54, -37, 41, 54, -37, 42, Blocks.STONE_BRICKS.getDefaultState());
        structure.fillWithBlocks(world, start, 54, -37, 43, 56, -37, 43, Blocks.MOSSY_STONE_BRICKS.getDefaultState());
        structure.fillWithBlocks(world, start, 54, -37, 44, 54, -37, 46, Blocks.STONE_BRICKS.getDefaultState());
        structure.fillWithBlocks(world, start, 54, -37, 48, 54, -37, 48, Blocks.STONE_BRICKS.getDefaultState());
        structure.fillWithBlocks(world, start, 54, -37, 50, 54, -37, 51, Blocks.STONE_BRICKS.getDefaultState());
        structure.fillWithBlocks(world, start, 54, -37, 54, 55, -37, 56, Blocks.STONE_BRICKS.getDefaultState());
        structure.fillWithBlocks(world, start, 54, -26, 34, 57, -26, 34, Blocks.STONE_BRICKS.getDefaultState());
        structure.fillWithBlocks(world, start, 54, -26, 35, 54, -26, 36, Blocks.CRACKED_STONE_BRICKS.getDefaultState());
        structure.fillWithBlocks(world, start, 54, -26, 37, 56, -26, 37, Blocks.STONE_BRICKS.getDefaultState());
        structure.fillWithBlocks(world, start, 54, -26, 38, 54, -26, 38, Blocks.MOSSY_STONE_BRICKS.getDefaultState());
        structure.fillWithBlocks(world, start, 54, -26, 39, 54, -26, 45, Blocks.STONE_BRICKS.getDefaultState());
        structure.fillWithBlocks(world, start, 54, -26, 47, 54, -26, 47, Blocks.STONE_BRICKS.getDefaultState());
        structure.fillWithBlocks(world, start, 54, -26, 48, 54, -26, 48, Blocks.CRACKED_STONE_BRICKS.getDefaultState());
        structure.fillWithBlocks(world, start, 54, -26, 50, 54, -26, 51, Blocks.STONE_BRICKS.getDefaultState());
        structure.fillWithBlocks(world, start, 54, -26, 52, 54, -24, 52, Blocks.MOSSY_STONE_BRICKS.getDefaultState());
        structure.fillWithBlocks(world, start, 54, -26, 53, 54, -25, 54, Blocks.STONE_BRICKS.getDefaultState());
        structure.fillWithBlocks(world, start, 54, -26, 75, 56, -26, 77, Blocks.STONE_BRICKS.getDefaultState());
        structure.fillWithBlocks(world, start, 54, -25, 35, 54, -25, 40, Blocks.STONE_BRICKS.getDefaultState());
        structure.fillWithBlocks(world, start, 54, -25, 42, 54, -24, 42, Blocks.STONE_BRICKS.getDefaultState());
        structure.fillWithBlocks(world, start, 54, -25, 46, 54, -23, 46, Blocks.STONE_BRICKS.getDefaultState());
        structure.fillWithBlocks(world, start, 54, -25, 48, 54, -25, 48, Blocks.STONE_BRICKS.getDefaultState());
        structure.fillWithBlocks(world, start, 54, -25, 74, 54, -24, 74, Blocks.STONE_BRICKS.getDefaultState());
        structure.fillWithBlocks(world, start, 54, -25, 78, 54, -22, 78, Blocks.STONE_BRICKS.getDefaultState());
        structure.fillWithBlocks(world, start, 54, -24, 37, 54, -23, 37, Blocks.CRACKED_STONE_BRICKS.getDefaultState());
        structure.fillWithBlocks(world, start, 54, -24, 38, 54, -23, 39, Blocks.STONE_BRICKS.getDefaultState());
        structure.fillWithBlocks(world, start, 54, -24, 40, 54, -21, 40, Blocks.MOSSY_STONE_BRICKS.getDefaultState());
        structure.fillWithBlocks(world, start, 54, -24, 41, 54, -23, 41, Blocks.CRACKED_STONE_BRICKS.getDefaultState());
        structure.fillWithBlocks(world, start, 54, -24, 47, 54, -24, 47, Blocks.STONE_BRICKS.getDefaultState());
        structure.fillWithBlocks(world, start, 54, -24, 48, 54, -24, 49, Blocks.MOSSY_STONE_BRICKS.getDefaultState());
        structure.fillWithBlocks(world, start, 54, -24, 53, 54, -24, 54, Blocks.STONE_BRICKS.getDefaultState());
        structure.fillWithBlocks(world, start, 54, -23, 34, 54, -23, 34, Blocks.STONE_BRICKS.getDefaultState());
        structure.fillWithBlocks(world, start, 54, -23, 47, 54, -23, 47, Blocks.MOSSY_STONE_BRICKS.getDefaultState());
        structure.fillWithBlocks(world, start, 54, -23, 49, 54, -23, 52, Blocks.STONE_BRICKS.getDefaultState());
        structure.fillWithBlocks(world, start, 54, -23, 53, 55, -23, 54, Blocks.CRACKED_STONE_BRICKS.getDefaultState());
        structure.fillWithBlocks(world, start, 54, -23, 74, 54, -22, 74, Blocks.CRACKED_STONE_BRICKS.getDefaultState());
        structure.fillWithBlocks(world, start, 54, -22, 34, 54, -21, 35, Blocks.STONE_BRICKS.getDefaultState());
        structure.fillWithBlocks(world, start, 54, -22, 39, 54, -21, 39, Blocks.STONE_BRICKS.getDefaultState());
        structure.fillWithBlocks(world, start, 54, -22, 41, 54, -22, 42, Blocks.STONE_BRICKS.getDefaultState());
        structure.fillWithBlocks(world, start, 54, -22, 46, 54, -22, 47, Blocks.CRACKED_STONE_BRICKS.getDefaultState());
        structure.fillWithBlocks(world, start, 54, -22, 51, 54, -21, 52, Blocks.STONE_BRICKS.getDefaultState());
        structure.fillWithBlocks(world, start, 54, -22, 54, 54, -20, 54, Blocks.STONE_BRICKS.getDefaultState());
        structure.fillWithBlocks(world, start, 54, -22, 75, 55, -22, 77, Blocks.STONE_BRICKS.getDefaultState());
        structure.fillWithBlocks(world, start, 54, -21, 37, 54, -18, 37, Blocks.STONE_BRICKS.getDefaultState());
        structure.fillWithBlocks(world, start, 54, -21, 38, 54, -21, 38, Blocks.CRACKED_STONE_BRICKS.getDefaultState());
        structure.fillWithBlocks(world, start, 54, -21, 42, 55, -21, 42, Blocks.MOSSY_STONE_BRICKS.getDefaultState());
        structure.fillWithBlocks(world, start, 54, -21, 43, 54, -20, 43, Blocks.CRACKED_STONE_BRICKS.getDefaultState());
        structure.fillWithBlocks(world, start, 54, -21, 48, 56, -21, 48, Blocks.CRACKED_STONE_BRICKS.getDefaultState());
        structure.fillWithBlocks(world, start, 54, -21, 53, 54, -20, 54, Blocks.STONE_BRICKS.getDefaultState());
        structure.fillWithBlocks(world, start, 54, -20, 34, 54, -19, 34, Blocks.CRACKED_STONE_BRICKS.getDefaultState());
        structure.fillWithBlocks(world, start, 54, -20, 35, 55, -20, 38, Blocks.STONE_BRICKS.getDefaultState());
        structure.fillWithBlocks(world, start, 54, -20, 39, 54, -19, 39, Blocks.CRACKED_STONE_BRICKS.getDefaultState());
        structure.fillWithBlocks(world, start, 54, -20, 40, 54, -20, 40, Blocks.STONE_BRICKS.getDefaultState());
        structure.fillWithBlocks(world, start, 54, -20, 42, 54, -20, 42, Blocks.STONE_BRICKS.getDefaultState());
        structure.fillWithBlocks(world, start, 54, -20, 44, 55, -20, 45, Blocks.STONE_BRICKS.getDefaultState());
        structure.fillWithBlocks(world, start, 54, -20, 46, 54, -20, 46, Blocks.CRACKED_STONE_BRICKS.getDefaultState());
        structure.fillWithBlocks(world, start, 54, -20, 48, 55, -20, 49, Blocks.STONE_BRICKS.getDefaultState());
        structure.fillWithBlocks(world, start, 54, -20, 50, 54, -20, 51, Blocks.STONE_BRICKS.getDefaultState());
        structure.fillWithBlocks(world, start, 54, -19, 35, 55, -19, 37, Blocks.STONE_BRICKS.getDefaultState());
        structure.fillWithBlocks(world, start, 54, -19, 38, 54, -19, 40, Blocks.CRACKED_STONE_BRICKS.getDefaultState());
        structure.fillWithBlocks(world, start, 54, -19, 41, 55, -19, 41, Blocks.STONE_BRICKS.getDefaultState());
        structure.fillWithBlocks(world, start, 54, -19, 42, 54, -19, 42, Blocks.CRACKED_STONE_BRICKS.getDefaultState());
        structure.fillWithBlocks(world, start, 54, -19, 43, 54, -19, 43, Blocks.STONE_BRICKS.getDefaultState());
        structure.fillWithBlocks(world, start, 54, -19, 46, 55, -19, 47, Blocks.STONE_BRICKS.getDefaultState());
        structure.fillWithBlocks(world, start, 54, -19, 48, 54, -19, 48, Blocks.MOSSY_STONE_BRICKS.getDefaultState());
        structure.fillWithBlocks(world, start, 54, -19, 49, 54, -19, 50, Blocks.STONE_BRICKS.getDefaultState());
        structure.fillWithBlocks(world, start, 54, -19, 51, 55, -19, 51, Blocks.CRACKED_STONE_BRICKS.getDefaultState());
        structure.fillWithBlocks(world, start, 54, -19, 52, 54, -19, 52, Blocks.STONE_BRICKS.getDefaultState());
        structure.fillWithBlocks(world, start, 54, -18, 34, 54, -18, 34, Blocks.STONE_BRICKS.getDefaultState());
        structure.fillWithBlocks(world, start, 54, -18, 36, 54, -18, 39, Blocks.STONE_BRICKS.getDefaultState());
        structure.fillWithBlocks(world, start, 54, -18, 41, 54, -17, 41, Blocks.STONE_BRICKS.getDefaultState());
        structure.fillWithBlocks(world, start, 54, -18, 44, 54, -16, 44, Blocks.STONE_BRICKS.getDefaultState());
        structure.fillWithBlocks(world, start, 54, -18, 45, 54, -18, 47, Blocks.CRACKED_STONE_BRICKS.getDefaultState());
        structure.fillWithBlocks(world, start, 54, -18, 48, 54, -18, 48, Blocks.STONE_BRICKS.getDefaultState());
        structure.fillWithBlocks(world, start, 54, -18, 50, 54, -18, 54, Blocks.STONE_BRICKS.getDefaultState());
        structure.fillWithBlocks(world, start, 54, -17, 38, 55, -17, 38, Blocks.CRACKED_STONE_BRICKS.getDefaultState());
        structure.fillWithBlocks(world, start, 54, -17, 39, 54, -17, 41, Blocks.STONE_BRICKS.getDefaultState());
        structure.fillWithBlocks(world, start, 54, -17, 42, 55, -17, 42, Blocks.CRACKED_STONE_BRICKS.getDefaultState());
        structure.fillWithBlocks(world, start, 54, -17, 43, 54, -17, 46, Blocks.STONE_BRICKS.getDefaultState());
        structure.fillWithBlocks(world, start, 54, -17, 49, 55, -17, 50, Blocks.STONE_BRICKS.getDefaultState());
        structure.fillWithBlocks(world, start, 54, -17, 53, 54, -17, 54, Blocks.CRACKED_STONE_BRICKS.getDefaultState());
        structure.fillWithBlocks(world, start, 54, -15, 42, 54, -12, 42, Blocks.STONE_BRICKS.getDefaultState());
        structure.fillWithBlocks(world, start, 54, -15, 46, 54, -15, 47, Blocks.STONE_BRICKS.getDefaultState());
        structure.fillWithBlocks(world, start, 54, -14, 41, 54, -13, 42, Blocks.STONE_BRICKS.getDefaultState());
        structure.fillWithBlocks(world, start, 54, -14, 46, 54, -14, 47, Blocks.STONE_BRICKS.getDefaultState());
        structure.fillWithBlocks(world, start, 54, -13, 46, 54, -13, 47, Blocks.STONE_BRICKS.getDefaultState());
        structure.fillWithBlocks(world, start, 54, 0, 30, 58, 0, 34, Blocks.DIRT.getDefaultState());
        structure.fillWithBlocks(world, start, 54, 0, 38, 55, 0, 39, Blocks.DIRT.getDefaultState());
        structure.fillWithBlocks(world, start, 54, 0, 42, 55, 0, 46, Blocks.DIRT.getDefaultState());
        structure.fillWithBlocks(world, start, 54, 0, 64, 56, 0, 66, Blocks.DIRT.getDefaultState());
        structure.fillWithBlocks(world, start, 54, 0, 67, 54, 0, 69, Blocks.COAL_ORE.getDefaultState());
        structure.fillWithBlocks(world, start, 54, 0, 70, 56, 0, 79, Blocks.DIRT.getDefaultState());
        structure.fillWithBlocks(world, start, 54, 1, 12, 55, 1, 12, Blocks.GRASS_BLOCK.getDefaultState().with(SnowyDirtBlock.SNOWY, false));
        structure.fillWithBlocks(world, start, 54, 1, 13, 55, 1, 39, Blocks.DIRT.getDefaultState());
        structure.fillWithBlocks(world, start, 54, 1, 42, 55, 1, 46, Blocks.DIRT.getDefaultState());
        structure.fillWithBlocks(world, start, 54, 1, 64, 57, 1, 67, Blocks.DIRT.getDefaultState());
        structure.fillWithBlocks(world, start, 54, 1, 68, 54, 3, 68, Blocks.STONE.getDefaultState());
        structure.fillWithBlocks(world, start, 54, 1, 69, 54, 1, 69, Blocks.DIRT.getDefaultState());
        structure.fillWithBlocks(world, start, 54, 1, 70, 54, 1, 72, Blocks.GRASS_BLOCK.getDefaultState().with(SnowyDirtBlock.SNOWY, false));
        structure.fillWithBlocks(world, start, 54, 1, 73, 59, 1, 78, Blocks.DIRT.getDefaultState());
        structure.fillWithBlocks(world, start, 54, 2, 67, 55, 3, 67, Blocks.IRON_ORE.getDefaultState());
        structure.fillWithBlocks(world, start, 54, 2, 73, 56, 2, 75, Blocks.DIRT.getDefaultState());
        structure.fillWithBlocks(world, start, 54, 3, 13, 54, 3, 14, Blocks.STONE_BRICKS.getDefaultState());
        structure.fillWithBlocks(world, start, 54, 3, 15, 55, 3, 16, Blocks.DIRT.getDefaultState());
        structure.fillWithBlocks(world, start, 54, 3, 17, 54, 4, 17, Blocks.DIRT.getDefaultState());
        structure.fillWithBlocks(world, start, 54, 3, 33, 55, 3, 34, Blocks.DIRT.getDefaultState());
        structure.fillWithBlocks(world, start, 54, 3, 45, 55, 3, 62, Blocks.DIRT.getDefaultState());
        structure.fillWithBlocks(world, start, 54, 3, 73, 55, 3, 75, Blocks.DIRT.getDefaultState());
        structure.fillWithBlocks(world, start, 54, 4, 13, 54, 4, 16, Blocks.STONE_BRICKS.getDefaultState());
        structure.fillWithBlocks(world, start, 54, 4, 33, 55, 4, 34, Blocks.DIRT.getDefaultState());
        structure.fillWithBlocks(world, start, 54, 4, 35, 54, 4, 36, Blocks.DIRT.getDefaultState());
        structure.fillWithBlocks(world, start, 54, 4, 50, 54, 4, 51, Blocks.GRASS_BLOCK.getDefaultState().with(SnowyDirtBlock.SNOWY, false));
        structure.fillWithBlocks(world, start, 54, 4, 52, 55, 4, 57, Blocks.DIRT.getDefaultState());
        structure.fillWithBlocks(world, start, 54, 4, 58, 54, 4, 67, Blocks.DIRT.getDefaultState());
        structure.fillWithBlocks(world, start, 54, 4, 73, 55, 4, 73, Blocks.DIRT.getDefaultState());
        structure.fillWithBlocks(world, start, 54, 5, 17, 54, 7, 17, Blocks.STONE_BRICKS.getDefaultState());
        structure.fillWithBlocks(world, start, 54, 5, 20, 54, 5, 20, Blocks.STONE_BRICKS.getDefaultState());
        structure.fillWithBlocks(world, start, 54, 5, 21, 54, 5, 24, Blocks.DIRT.getDefaultState());
        structure.fillWithBlocks(world, start, 54, 5, 32, 56, 5, 34, Blocks.STONE_BRICKS.getDefaultState());
        structure.fillWithBlocks(world, start, 54, 5, 35, 54, 5, 36, Blocks.STONE_BRICKS.getDefaultState());
        structure.fillWithBlocks(world, start, 54, 5, 52, 55, 5, 56, Blocks.STONE_BRICKS.getDefaultState());
        structure.fillWithBlocks(world, start, 54, 5, 57, 54, 5, 59, Blocks.STONE_BRICKS.getDefaultState());
        structure.fillWithBlocks(world, start, 54, 5, 60, 55, 6, 60, Blocks.OAK_LOG.getDefaultState());
        structure.fillWithBlocks(world, start, 54, 5, 61, 55, 5, 62, Blocks.STONE_BRICKS.getDefaultState());
        structure.fillWithBlocks(world, start, 54, 5, 66, 55, 5, 67, Blocks.DIRT.getDefaultState());
        structure.fillWithBlocks(world, start, 54, 5, 70, 54, 5, 71, Blocks.STONE_BRICKS.getDefaultState());
        structure.fillWithBlocks(world, start, 54, 5, 73, 54, 6, 74, Blocks.STONE_BRICKS.getDefaultState());
        structure.fillWithBlocks(world, start, 54, 6, 13, 54, 6, 15, Blocks.STONE_BRICKS.getDefaultState());
        structure.fillWithBlocks(world, start, 54, 6, 20, 54, 6, 29, Blocks.STONE_BRICKS.getDefaultState());
        structure.fillWithBlocks(world, start, 54, 6, 33, 55, 6, 34, Blocks.STONE_BRICKS.getDefaultState());
        structure.fillWithBlocks(world, start, 54, 6, 35, 54, 6, 36, Blocks.STONE_BRICKS.getDefaultState());
        structure.fillWithBlocks(world, start, 54, 6, 42, 54, 8, 42, Blocks.OAK_LOG.getDefaultState());
        structure.fillWithBlocks(world, start, 54, 6, 43, 54, 7, 43, Blocks.OAK_LEAVES.getDefaultState().with(LeavesBlock.PERSISTENT, false).with(LeavesBlock.DISTANCE, 1));
        structure.fillWithBlocks(world, start, 54, 6, 46, 55, 6, 49, Blocks.STONE_BRICKS.getDefaultState());
        structure.fillWithBlocks(world, start, 54, 6, 52, 55, 6, 56, Blocks.STONE_BRICKS.getDefaultState());
        structure.fillWithBlocks(world, start, 54, 6, 57, 54, 6, 57, Blocks.OAK_LOG.getDefaultState());
        structure.fillWithBlocks(world, start, 54, 6, 58, 54, 6, 59, Blocks.STONE_BRICKS.getDefaultState());
        structure.fillWithBlocks(world, start, 54, 6, 62, 54, 7, 65, Blocks.STONE_BRICKS.getDefaultState());
        structure.fillWithBlocks(world, start, 54, 6, 66, 55, 6, 66, Blocks.DIRT.getDefaultState());
        structure.fillWithBlocks(world, start, 54, 6, 67, 65, 6, 67, Blocks.GRASS_BLOCK.getDefaultState().with(SnowyDirtBlock.SNOWY, false));
        structure.fillWithBlocks(world, start, 54, 6, 70, 54, 6, 71, Blocks.STONE_BRICKS.getDefaultState());
        structure.fillWithBlocks(world, start, 54, 7, 21, 54, 10, 27, Blocks.STONE_BRICKS.getDefaultState());
        structure.fillWithBlocks(world, start, 54, 7, 28, 55, 7, 29, Blocks.STONE_BRICKS.getDefaultState());
        structure.fillWithBlocks(world, start, 54, 7, 31, 55, 7, 34, Blocks.STONE_BRICKS.getDefaultState());
        structure.fillWithBlocks(world, start, 54, 7, 39, 54, 7, 39, Blocks.STONE_BRICKS.getDefaultState());
        structure.fillWithBlocks(world, start, 54, 7, 41, 54, 7, 41, Blocks.STONE_BRICKS.getDefaultState());
        structure.fillWithBlocks(world, start, 54, 7, 46, 55, 7, 49, Blocks.STONE_BRICKS.getDefaultState());
        structure.fillWithBlocks(world, start, 54, 7, 53, 55, 7, 55, Blocks.STONE_BRICKS.getDefaultState());
        structure.fillWithBlocks(world, start, 54, 7, 56, 54, 9, 56, Blocks.STONE_BRICKS.getDefaultState());
        structure.fillWithBlocks(world, start, 54, 7, 57, 55, 7, 57, Blocks.OAK_LOG.getDefaultState());
        structure.fillWithBlocks(world, start, 54, 7, 58, 54, 7, 59, Blocks.STONE_BRICKS.getDefaultState());
        structure.fillWithBlocks(world, start, 54, 7, 60, 55, 7, 60, Blocks.OAK_LOG.getDefaultState());
        structure.fillWithBlocks(world, start, 54, 7, 66, 55, 7, 66, Blocks.STONE_BRICKS.getDefaultState());
        structure.fillWithBlocks(world, start, 54, 7, 70, 54, 7, 71, Blocks.STONE_BRICKS.getDefaultState());
        structure.fillWithBlocks(world, start, 54, 7, 73, 54, 8, 74, Blocks.STONE_BRICKS.getDefaultState());
        structure.fillWithBlocks(world, start, 54, 8, 28, 55, 8, 29, Blocks.STONE_BRICKS.getDefaultState());
        structure.fillWithBlocks(world, start, 54, 8, 33, 54, 8, 34, Blocks.STONE_BRICKS.getDefaultState());
        structure.fillWithBlocks(world, start, 54, 8, 41, 54, 8, 41, Blocks.STONE_BRICKS.getDefaultState());
        structure.fillWithBlocks(world, start, 54, 8, 46, 55, 8, 49, Blocks.STONE_BRICKS.getDefaultState());
        structure.fillWithBlocks(world, start, 54, 8, 58, 54, 8, 62, Blocks.STONE_BRICKS.getDefaultState());
        structure.fillWithBlocks(world, start, 54, 8, 63, 54, 10, 63, Blocks.OAK_LOG.getDefaultState());
        structure.fillWithBlocks(world, start, 54, 8, 64, 54, 10, 66, Blocks.STONE_BRICKS.getDefaultState());
        structure.fillWithBlocks(world, start, 54, 8, 70, 54, 8, 71, Blocks.STONE_BRICKS.getDefaultState());
        structure.fillWithBlocks(world, start, 54, 9, 28, 55, 9, 29, Blocks.STONE_BRICKS.getDefaultState());
        structure.fillWithBlocks(world, start, 54, 9, 33, 54, 10, 33, Blocks.STONE_BRICKS.getDefaultState());
        structure.fillWithBlocks(world, start, 54, 9, 37, 54, 9, 37, Blocks.STONE_BRICKS.getDefaultState());
        structure.fillWithBlocks(world, start, 54, 9, 49, 54, 9, 49, Blocks.STONE_BRICKS.getDefaultState());
        structure.fillWithBlocks(world, start, 54, 9, 58, 54, 9, 62, Blocks.STONE_BRICKS.getDefaultState());
        structure.fillWithBlocks(world, start, 54, 9, 70, 54, 10, 70, Blocks.STONE_BRICKS.getDefaultState());
        structure.fillWithBlocks(world, start, 54, 10, 29, 58, 14, 29, Blocks.STONE_BRICKS.getDefaultState());
        structure.fillWithBlocks(world, start, 54, 10, 39, 54, 10, 39, Blocks.STONE_BRICKS.getDefaultState());
        structure.fillWithBlocks(world, start, 54, 10, 49, 54, 10, 49, Blocks.STONE_BRICKS.getDefaultState());
        structure.fillWithBlocks(world, start, 54, 10, 58, 54, 10, 59, Blocks.STONE_BRICKS.getDefaultState());
        structure.fillWithBlocks(world, start, 54, 10, 62, 55, 11, 62, Blocks.STONE_BRICKS.getDefaultState());
        structure.fillWithBlocks(world, start, 54, 11, 23, 54, 12, 27, Blocks.STONE_BRICKS.getDefaultState());
        structure.fillWithBlocks(world, start, 54, 11, 49, 54, 11, 49, Blocks.STONE_BRICKS.getDefaultState());
        structure.fillWithBlocks(world, start, 54, 11, 58, 54, 13, 58, Blocks.OAK_LOG.getDefaultState());
        structure.fillWithBlocks(world, start, 54, 11, 59, 58, 12, 59, Blocks.STONE_BRICKS.getDefaultState());
        structure.fillWithBlocks(world, start, 54, 11, 65, 54, 12, 65, Blocks.STONE_BRICKS.getDefaultState());
        structure.fillWithBlocks(world, start, 54, 12, 49, 54, 12, 49, Blocks.STONE_BRICKS.getDefaultState());
        structure.fillWithBlocks(world, start, 54, 12, 62, 55, 13, 62, Blocks.STONE_BRICKS.getDefaultState());
        structure.fillWithBlocks(world, start, 54, 13, 26, 55, 13, 27, Blocks.STONE_BRICKS.getDefaultState());
        structure.fillWithBlocks(world, start, 54, 13, 59, 56, 15, 59, Blocks.OAK_LOG.getDefaultState());
        structure.fillWithBlocks(world, start, 54, 14, 26, 55, 14, 27, Blocks.STONE_BRICKS.getDefaultState());
        structure.fillWithBlocks(world, start, 54, 14, 62, 55, 15, 62, Blocks.STONE_BRICKS.getDefaultState());
        structure.fillWithBlocks(world, start, 54, 15, 26, 55, 15, 27, Blocks.STONE_BRICKS.getDefaultState());
        structure.fillWithBlocks(world, start, 54, 15, 29, 58, 15, 29, Blocks.STONE_BRICKS.getDefaultState());
        structure.fillWithBlocks(world, start, 54, 15, 61, 55, 15, 62, Blocks.STONE_BRICKS.getDefaultState());
        structure.fillWithBlocks(world, start, 54, 16, 26, 55, 16, 27, Blocks.STONE_BRICKS.getDefaultState());
        structure.fillWithBlocks(world, start, 54, 16, 61, 55, 16, 62, Blocks.STONE_BRICKS.getDefaultState());
        structure.fillWithBlocks(world, start, 54, 17, 26, 55, 17, 27, Blocks.STONE_BRICKS.getDefaultState());
        structure.fillWithBlocks(world, start, 54, 17, 61, 54, 17, 62, Blocks.STONE_BRICKS.getDefaultState());
        structure.fillWithBlocks(world, start, 54, 18, 26, 55, 18, 27, Blocks.STONE_BRICKS.getDefaultState());
        structure.fillWithBlocks(world, start, 54, 18, 61, 54, 18, 61, Blocks.STONE_BRICKS.getDefaultState());
        structure.fillWithBlocks(world, start, 54, 18, 62, 54, 20, 62, Blocks.OAK_LOG.getDefaultState());
        structure.fillWithBlocks(world, start, 54, 19, 26, 54, 19, 26, Blocks.STONE_BRICKS.getDefaultState());
        structure.fillWithBlocks(world, start, 54, 20, 26, 55, 20, 27, Blocks.STONE_BRICKS.getDefaultState());
        structure.fillWithBlocks(world, start, 54, 21, 26, 55, 21, 27, Blocks.STONE_BRICKS.getDefaultState());
        structure.fillWithBlocks(world, start, 54, 22, 26, 55, 22, 27, Blocks.STONE_BRICKS.getDefaultState());
        structure.fillWithBlocks(world, start, 54, 22, 39, 54, 22, 40, Blocks.OAK_LEAVES.getDefaultState().with(LeavesBlock.PERSISTENT, false).with(LeavesBlock.DISTANCE, 6));
        structure.fillWithBlocks(world, start, 54, 23, 26, 54, 23, 27, Blocks.STONE_BRICKS.getDefaultState());
        structure.fillWithBlocks(world, start, 54, 23, 39, 54, 23, 40, Blocks.OAK_LEAVES.getDefaultState().with(LeavesBlock.PERSISTENT, false).with(LeavesBlock.DISTANCE, 5));
        structure.fillWithBlocks(world, start, 54, 24, 26, 54, 24, 27, Blocks.STONE_BRICKS.getDefaultState());
        structure.fillWithBlocks(world, start, 54, 24, 39, 54, 24, 40, Blocks.OAK_LEAVES.getDefaultState().with(LeavesBlock.PERSISTENT, false).with(LeavesBlock.DISTANCE, 4));
        structure.fillWithBlocks(world, start, 54, 24, 72, 54, 26, 72, Blocks.STONE_BRICKS.getDefaultState());
        structure.fillWithBlocks(world, start, 54, 26, 30, 54, 36, 30, Blocks.STONE_BRICKS.getDefaultState());
        structure.fillWithBlocks(world, start, 54, 28, 71, 54, 28, 72, Blocks.OAK_LEAVES.getDefaultState().with(LeavesBlock.PERSISTENT, false).with(LeavesBlock.DISTANCE, 1));
        structure.fillWithBlocks(world, start, 55, -59, 39, 57, -59, 41, Blocks.STONE_BRICKS.getDefaultState());
        structure.fillWithBlocks(world, start, 55, -59, 43, 57, -59, 45, Blocks.STONE_BRICKS.getDefaultState());
        structure.fillWithBlocks(world, start, 55, -59, 55, 55, -59, 56, Blocks.AIR.getDefaultState());
        structure.fillWithBlocks(world, start, 55, -59, 57, 57, -59, 59, Blocks.STONE_BRICKS.getDefaultState());
        structure.fillWithBlocks(world, start, 55, -58, 38, 58, -55, 38, Blocks.STONE_BRICKS.getDefaultState());
        structure.fillWithBlocks(world, start, 55, -58, 39, 57, -58, 39, Blocks.AIR.getDefaultState());
        structure.fillWithBlocks(world, start, 55, -58, 40, 58, -58, 48, Blocks.STONE_BRICKS.getDefaultState());
        structure.fillWithBlocks(world, start, 55, -57, 39, 56, -57, 58, Blocks.STONE_BRICKS.getDefaultState());
        structure.fillWithBlocks(world, start, 55, -56, -57, 57, -56, -46, Blocks.STONE_BRICKS.getDefaultState());
        structure.fillWithBlocks(world, start, 55, -56, -45, 55, -56, -40, Blocks.STONE_BRICKS.getDefaultState());
        structure.fillWithBlocks(world, start, 55, -56, 59, 56, -56, 60, Blocks.STONE_BRICKS.getDefaultState());
        structure.fillWithBlocks(world, start, 55, -55, -57, 57, -55, -41, Blocks.STONE_BRICKS.getDefaultState());
        structure.fillWithBlocks(world, start, 55, -55, -18, 57, -55, -14, Blocks.AIR.getDefaultState());
        structure.fillWithBlocks(world, start, 55, -55, -13, 77, -55, -13, Blocks.STONE_BRICKS.getDefaultState());
        structure.fillWithBlocks(world, start, 55, -55, 39, 55, -47, 39, Blocks.STONE_BRICKS.getDefaultState());
        structure.fillWithBlocks(world, start, 55, -55, 40, 56, -55, 58, Blocks.AIR.getDefaultState());
        structure.fillWithBlocks(world, start, 55, -55, 59, 55, -55, 60, Blocks.STONE_BRICKS.getDefaultState());
        structure.fillWithBlocks(world, start, 55, -54, -57, 57, -54, -49, Blocks.STONE_BRICKS.getDefaultState());
        structure.fillWithBlocks(world, start, 55, -54, -47, 55, -51, -40, Blocks.STONE_BRICKS.getDefaultState());
        structure.fillWithBlocks(world, start, 55, -54, -20, 55, -54, -19, Blocks.STONE_BRICKS.getDefaultState());
        structure.fillWithBlocks(world, start, 55, -54, -18, 57, -54, -14, Blocks.AIR.getDefaultState());
        structure.fillWithBlocks(world, start, 55, -54, -13, 55, -53, -13, Blocks.STONE_BRICKS.getDefaultState());
        structure.fillWithBlocks(world, start, 55, -54, 40, 56, -54, 58, Blocks.AIR.getDefaultState());
        structure.fillWithBlocks(world, start, 55, -54, 59, 55, -54, 60, Blocks.STONE_BRICKS.getDefaultState());
        structure.fillWithBlocks(world, start, 55, -53, -60, 56, -53, -51, Blocks.STONE_BRICKS.getDefaultState());
        structure.fillWithBlocks(world, start, 55, -53, -49, 56, -53, -40, Blocks.STONE_BRICKS.getDefaultState());
        structure.fillWithBlocks(world, start, 55, -53, -19, 77, -53, -19, Blocks.STONE_BRICKS.getDefaultState());
        structure.fillWithBlocks(world, start, 55, -53, -18, 57, -53, -14, Blocks.AIR.getDefaultState());
        structure.fillWithBlocks(world, start, 55, -53, 40, 56, -53, 58, Blocks.AIR.getDefaultState());
        structure.fillWithBlocks(world, start, 55, -53, 59, 55, -53, 60, Blocks.STONE_BRICKS.getDefaultState());
        structure.fillWithBlocks(world, start, 55, -52, -60, 56, -52, -55, Blocks.STONE_BRICKS.getDefaultState());
        structure.fillWithBlocks(world, start, 55, -52, -54, 55, -52, -40, Blocks.STONE_BRICKS.getDefaultState());
        structure.fillWithBlocks(world, start, 55, -52, -18, 57, -52, -14, Blocks.STONE_BRICKS.getDefaultState());
        structure.fillWithBlocks(world, start, 55, -51, -57, 57, -51, -50, Blocks.STONE_BRICKS.getDefaultState());
        structure.fillWithBlocks(world, start, 55, -51, -49, 56, -51, -44, Blocks.STONE_BRICKS.getDefaultState());
        structure.fillWithBlocks(world, start, 55, -51, 40, 55, -51, 40, Blocks.STONE_BRICKS.getDefaultState());
        structure.fillWithBlocks(world, start, 55, -51, 42, 56, -51, 44, Blocks.STONE_BRICKS.getDefaultState());
        structure.fillWithBlocks(world, start, 55, -51, 46, 57, -51, 48, Blocks.STONE_BRICKS.getDefaultState());
        structure.fillWithBlocks(world, start, 55, -51, 50, 57, -51, 52, Blocks.STONE_BRICKS.getDefaultState());
        structure.fillWithBlocks(world, start, 55, -51, 54, 55, -51, 54, Blocks.STONE_BRICKS.getDefaultState());
        structure.fillWithBlocks(world, start, 55, -51, 56, 56, -51, 57, Blocks.STONE_BRICKS.getDefaultState());
        structure.fillWithBlocks(world, start, 55, -50, -57, 56, -50, -56, Blocks.STONE_BRICKS.getDefaultState());
        structure.fillWithBlocks(world, start, 55, -50, -55, 55, -50, -48, Blocks.STONE_BRICKS.getDefaultState());
        structure.fillWithBlocks(world, start, 55, -50, -46, 57, -50, -41, Blocks.STONE_BRICKS.getDefaultState());
        structure.fillWithBlocks(world, start, 55, -50, 55, 57, -50, 59, Blocks.STONE_BRICKS.getDefaultState());
        structure.fillWithBlocks(world, start, 55, -49, -57, 55, -48, -57, Blocks.AIR.getDefaultState());
        structure.fillWithBlocks(world, start, 55, -49, -56, 57, -49, -54, Blocks.STONE_BRICKS.getDefaultState());
        structure.fillWithBlocks(world, start, 55, -49, -53, 55, -49, -40, Blocks.STONE_BRICKS.getDefaultState());
        structure.fillWithBlocks(world, start, 55, -49, 40, 57, -49, 44, Blocks.STONE_BRICKS.getDefaultState());
        structure.fillWithBlocks(world, start, 55, -49, 49, 57, -49, 56, Blocks.STONE_BRICKS.getDefaultState());
        structure.fillWithBlocks(world, start, 55, -48, -56, 57, -48, -47, Blocks.STONE_BRICKS.getDefaultState());
        structure.fillWithBlocks(world, start, 55, -48, 40, 57, -48, 56, Blocks.STONE_BRICKS.getDefaultState());
        structure.fillWithBlocks(world, start, 55, -48, 59, 57, -47, 59, Blocks.STONE_BRICKS.getDefaultState());
        structure.fillWithBlocks(world, start, 55, -47, -60, 55, -47, -40, Blocks.STONE_BRICKS.getDefaultState());
        structure.fillWithBlocks(world, start, 55, -47, 44, 56, -47, 46, Blocks.STONE_BRICKS.getDefaultState());
        structure.fillWithBlocks(world, start, 55, -47, 56, 57, -47, 59, Blocks.STONE_BRICKS.getDefaultState());
        structure.fillWithBlocks(world, start, 55, -46, -24, 56, -46, -24, Blocks.AIR.getDefaultState());
        structure.fillWithBlocks(world, start, 55, -46, -23, 55, -46, -23, Blocks.STONE_BRICKS.getDefaultState());
        structure.fillWithBlocks(world, start, 55, -46, -22, 55, -46, -19, Blocks.AIR.getDefaultState());
        structure.fillWithBlocks(world, start, 55, -46, -18, 55, -46, -17, Blocks.MOSSY_STONE_BRICKS.getDefaultState());
        structure.fillWithBlocks(world, start, 55, -46, -16, 55, -46, -15, Blocks.STONE_BRICKS.getDefaultState());
        structure.fillWithBlocks(world, start, 55, -46, -13, 55, -46, -12, Blocks.INFESTED_CRACKED_STONE_BRICKS.getDefaultState());
        structure.fillWithBlocks(world, start, 55, -46, -11, 56, -46, -10, Blocks.STONE_BRICKS.getDefaultState());
        structure.fillWithBlocks(world, start, 55, -46, -8, 56, -46, -8, Blocks.MOSSY_STONE_BRICKS.getDefaultState());
        structure.fillWithBlocks(world, start, 55, -46, 15, 55, -46, 18, Blocks.STONE_BRICKS.getDefaultState());
        structure.fillWithBlocks(world, start, 55, -46, 20, 55, -45, 20, Blocks.STONE_BRICKS.getDefaultState());
        structure.fillWithBlocks(world, start, 55, -46, 31, 55, -46, 31, Blocks.MOSSY_STONE_BRICKS.getDefaultState());
        structure.fillWithBlocks(world, start, 55, -46, 32, 55, -44, 32, Blocks.STONE_BRICKS.getDefaultState());
        structure.fillWithBlocks(world, start, 55, -46, 33, 55, -45, 33, Blocks.MOSSY_STONE_BRICKS.getDefaultState());
        structure.fillWithBlocks(world, start, 55, -46, 35, 57, -46, 35, Blocks.STONE_BRICKS.getDefaultState());
        structure.fillWithBlocks(world, start, 55, -46, 36, 58, -46, 36, Blocks.MOSSY_STONE_BRICKS.getDefaultState());
        structure.fillWithBlocks(world, start, 55, -46, 37, 55, -46, 37, Blocks.STONE_BRICKS.getDefaultState());
        structure.fillWithBlocks(world, start, 55, -46, 40, 55, -46, 43, Blocks.STONE_BRICKS.getDefaultState());
        structure.fillWithBlocks(world, start, 55, -46, 44, 55, -46, 46, Blocks.MOSSY_STONE_BRICKS.getDefaultState());
        structure.fillWithBlocks(world, start, 55, -46, 47, 60, -46, 47, Blocks.STONE_BRICKS.getDefaultState());
        structure.fillWithBlocks(world, start, 55, -46, 48, 55, -46, 48, Blocks.MOSSY_COBBLESTONE.getDefaultState());
        structure.fillWithBlocks(world, start, 55, -46, 49, 55, -46, 49, Blocks.STONE_BRICKS.getDefaultState());
        structure.fillWithBlocks(world, start, 55, -46, 51, 56, -46, 51, Blocks.MOSSY_STONE_BRICKS.getDefaultState());
        structure.fillWithBlocks(world, start, 55, -46, 52, 55, -46, 55, Blocks.STONE_BRICKS.getDefaultState());
        structure.fillWithBlocks(world, start, 55, -45, -23, 55, -45, -22, Blocks.STONE_BRICKS.getDefaultState());
        structure.fillWithBlocks(world, start, 55, -45, -21, 55, -43, -21, Blocks.MOSSY_STONE_BRICKS.getDefaultState());
        structure.fillWithBlocks(world, start, 55, -45, -20, 55, -44, -20, Blocks.STONE_BRICKS.getDefaultState());
        structure.fillWithBlocks(world, start, 55, -45, -19, 55, -44, -19, Blocks.MOSSY_STONE_BRICKS.getDefaultState());
        structure.fillWithBlocks(world, start, 55, -45, -18, 58, -45, -15, Blocks.AIR.getDefaultState());
        structure.fillWithBlocks(world, start, 55, -45, -13, 55, -44, -13, Blocks.STONE_BRICKS.getDefaultState());
        structure.fillWithBlocks(world, start, 55, -45, -11, 55, -45, -10, Blocks.STONE_BRICKS.getDefaultState());
        structure.fillWithBlocks(world, start, 55, -45, 18, 55, -44, 19, Blocks.STONE_BRICKS.getDefaultState());
        structure.fillWithBlocks(world, start, 55, -45, 22, 55, -45, 22, Blocks.STONE_BRICKS.getDefaultState());
        structure.fillWithBlocks(world, start, 55, -45, 30, 55, -44, 32, Blocks.STONE_BRICKS.getDefaultState());
        structure.fillWithBlocks(world, start, 55, -45, 34, 55, -44, 36, Blocks.STONE_BRICKS.getDefaultState());
        structure.fillWithBlocks(world, start, 55, -45, 40, 55, -44, 41, Blocks.STONE_BRICKS.getDefaultState());
        structure.fillWithBlocks(world, start, 55, -45, 42, 55, -45, 44, Blocks.STONE_BRICK_WALL.getDefaultState().with(WallBlock.WATERLOGGED, false).with(WallBlock.UP, false).with(WallBlock.WALL_HEIGHT_NORTH, WallHeight.LOW).with(WallBlock.WALL_HEIGHT_SOUTH, WallHeight.LOW).with(WallBlock.WALL_HEIGHT_EAST, WallHeight.LOW).with(WallBlock.WALL_HEIGHT_WEST, WallHeight.LOW));
        structure.fillWithBlocks(world, start, 55, -45, 46, 59, -45, 50, Blocks.AIR.getDefaultState());
        structure.fillWithBlocks(world, start, 55, -45, 51, 55, -42, 51, Blocks.STONE_BRICKS.getDefaultState());
        structure.fillWithBlocks(world, start, 55, -45, 52, 55, -45, 54, Blocks.STONE_BRICK_WALL.getDefaultState().with(WallBlock.WATERLOGGED, false).with(WallBlock.UP, false).with(WallBlock.WALL_HEIGHT_NORTH, WallHeight.LOW).with(WallBlock.WALL_HEIGHT_SOUTH, WallHeight.LOW).with(WallBlock.WALL_HEIGHT_EAST, WallHeight.LOW).with(WallBlock.WALL_HEIGHT_WEST, WallHeight.LOW));
        structure.fillWithBlocks(world, start, 55, -44, -24, 55, -42, -24, Blocks.MOSSY_STONE_BRICKS.getDefaultState());
        structure.fillWithBlocks(world, start, 55, -44, -23, 55, -43, -23, Blocks.STONE_BRICKS.getDefaultState());
        structure.fillWithBlocks(world, start, 55, -44, -22, 55, -44, -21, Blocks.MOSSY_STONE_BRICKS.getDefaultState());
        structure.fillWithBlocks(world, start, 55, -44, -18, 58, -44, -15, Blocks.AIR.getDefaultState());
        structure.fillWithBlocks(world, start, 55, -44, -14, 55, -44, -11, Blocks.STONE_BRICKS.getDefaultState());
        structure.fillWithBlocks(world, start, 55, -44, -9, 55, -44, -8, Blocks.STONE_BRICKS.getDefaultState());
        structure.fillWithBlocks(world, start, 55, -44, 17, 55, -44, 17, Blocks.MOSSY_STONE_BRICKS.getDefaultState());
        structure.fillWithBlocks(world, start, 55, -44, 21, 55, -44, 21, Blocks.STONE_BRICKS.getDefaultState());
        structure.fillWithBlocks(world, start, 55, -44, 22, 55, -44, 22, Blocks.MOSSY_STONE_BRICKS.getDefaultState());
        structure.fillWithBlocks(world, start, 55, -44, 33, 55, -43, 35, Blocks.STONE_BRICKS.getDefaultState());
        structure.fillWithBlocks(world, start, 55, -44, 42, 57, -44, 44, Blocks.AIR.getDefaultState());
        structure.fillWithBlocks(world, start, 55, -44, 46, 59, -44, 50, Blocks.AIR.getDefaultState());
        structure.fillWithBlocks(world, start, 55, -44, 52, 57, -44, 54, Blocks.AIR.getDefaultState());
        structure.fillWithBlocks(world, start, 55, -44, 55, 55, -44, 56, Blocks.STONE_BRICKS.getDefaultState());
        structure.fillWithBlocks(world, start, 55, -43, -22, 55, -42, -22, Blocks.STONE_BRICKS.getDefaultState());
        structure.fillWithBlocks(world, start, 55, -43, -18, 58, -43, -15, Blocks.AIR.getDefaultState());
        structure.fillWithBlocks(world, start, 55, -43, -14, 55, -42, -14, Blocks.STONE_BRICKS.getDefaultState());
        structure.fillWithBlocks(world, start, 55, -43, -13, 55, -41, -13, Blocks.MOSSY_STONE_BRICKS.getDefaultState());
        structure.fillWithBlocks(world, start, 55, -43, -12, 55, -43, -10, Blocks.STONE_BRICKS.getDefaultState());
        structure.fillWithBlocks(world, start, 55, -43, -8, 55, -42, -8, Blocks.STONE_BRICKS.getDefaultState());
        structure.fillWithBlocks(world, start, 55, -43, 20, 55, -43, 20, Blocks.STONE_BRICKS.getDefaultState());
        structure.fillWithBlocks(world, start, 55, -43, 22, 55, -39, 22, Blocks.STONE_BRICKS.getDefaultState());
        structure.fillWithBlocks(world, start, 55, -43, 31, 56, -43, 32, Blocks.MOSSY_STONE_BRICKS.getDefaultState());
        structure.fillWithBlocks(world, start, 55, -43, 37, 55, -42, 37, Blocks.AIR.getDefaultState());
        structure.fillWithBlocks(world, start, 55, -43, 38, 55, -42, 38, Blocks.STONE_BRICKS.getDefaultState());
        structure.fillWithBlocks(world, start, 55, -43, 40, 55, -43, 41, Blocks.STONE_BRICKS.getDefaultState());
        structure.fillWithBlocks(world, start, 55, -43, 42, 57, -43, 44, Blocks.AIR.getDefaultState());
        structure.fillWithBlocks(world, start, 55, -43, 46, 59, -43, 50, Blocks.AIR.getDefaultState());
        structure.fillWithBlocks(world, start, 55, -43, 52, 57, -43, 54, Blocks.AIR.getDefaultState());
        structure.fillWithBlocks(world, start, 55, -43, 56, 56, -43, 56, Blocks.STONE_BRICKS.getDefaultState());
        structure.fillWithBlocks(world, start, 55, -42, -23, 56, -42, -23, Blocks.MOSSY_STONE_BRICKS.getDefaultState());
        structure.fillWithBlocks(world, start, 55, -42, -21, 55, -42, -18, Blocks.STONE_BRICKS.getDefaultState());
        structure.fillWithBlocks(world, start, 55, -42, -16, 55, -42, -14, Blocks.STONE_BRICKS.getDefaultState());
        structure.fillWithBlocks(world, start, 55, -42, -10, 55, -42, -10, Blocks.STONE_BRICKS.getDefaultState());
        structure.fillWithBlocks(world, start, 55, -42, 14, 55, -42, 14, Blocks.MOSSY_STONE_BRICKS.getDefaultState());
        structure.fillWithBlocks(world, start, 55, -42, 15, 55, -41, 15, Blocks.STONE_BRICKS.getDefaultState());
        structure.fillWithBlocks(world, start, 55, -42, 16, 55, -42, 16, Blocks.MOSSY_STONE_BRICKS.getDefaultState());
        structure.fillWithBlocks(world, start, 55, -42, 17, 55, -42, 20, Blocks.STONE_BRICKS.getDefaultState());
        structure.fillWithBlocks(world, start, 55, -42, 21, 55, -41, 21, Blocks.MOSSY_STONE_BRICKS.getDefaultState());
        structure.fillWithBlocks(world, start, 55, -42, 31, 55, -42, 33, Blocks.STONE_BRICKS.getDefaultState());
        structure.fillWithBlocks(world, start, 55, -42, 34, 55, -42, 34, Blocks.MOSSY_STONE_BRICKS.getDefaultState());
        structure.fillWithBlocks(world, start, 55, -42, 41, 55, -41, 41, Blocks.STONE_BRICKS.getDefaultState());
        structure.fillWithBlocks(world, start, 55, -42, 42, 57, -42, 44, Blocks.AIR.getDefaultState());
        structure.fillWithBlocks(world, start, 55, -42, 46, 59, -42, 50, Blocks.AIR.getDefaultState());
        structure.fillWithBlocks(world, start, 55, -42, 52, 57, -42, 54, Blocks.AIR.getDefaultState());
        structure.fillWithBlocks(world, start, 55, -42, 55, 55, -40, 55, Blocks.STONE_BRICKS.getDefaultState());
        structure.fillWithBlocks(world, start, 55, -42, 56, 58, -42, 56, Blocks.MOSSY_STONE_BRICKS.getDefaultState());
        structure.fillWithBlocks(world, start, 55, -41, -23, 55, -41, -23, Blocks.STONE_BRICKS.getDefaultState());
        structure.fillWithBlocks(world, start, 55, -41, -22, 55, -41, -21, Blocks.MOSSY_STONE_BRICKS.getDefaultState());
        structure.fillWithBlocks(world, start, 55, -41, -18, 55, -40, -16, Blocks.STONE_BRICKS.getDefaultState());
        structure.fillWithBlocks(world, start, 55, -41, -14, 55, -41, -13, Blocks.MOSSY_STONE_BRICKS.getDefaultState());
        structure.fillWithBlocks(world, start, 55, -41, -11, 55, -41, -11, Blocks.STONE_BRICKS.getDefaultState());
        structure.fillWithBlocks(world, start, 55, -41, -9, 57, -41, -9, Blocks.STONE_BRICKS.getDefaultState());
        structure.fillWithBlocks(world, start, 55, -41, 14, 56, -41, 16, Blocks.STONE_BRICKS.getDefaultState());
        structure.fillWithBlocks(world, start, 55, -41, 17, 55, -41, 17, Blocks.MOSSY_STONE_BRICKS.getDefaultState());
        structure.fillWithBlocks(world, start, 55, -41, 24, 55, -41, 28, Blocks.AIR.getDefaultState());
        structure.fillWithBlocks(world, start, 55, -41, 30, 55, -41, 32, Blocks.STONE_BRICKS.getDefaultState());
        structure.fillWithBlocks(world, start, 55, -41, 33, 55, -40, 33, Blocks.MOSSY_STONE_BRICKS.getDefaultState());
        structure.fillWithBlocks(world, start, 55, -41, 34, 55, -40, 34, Blocks.STONE_BRICKS.getDefaultState());
        structure.fillWithBlocks(world, start, 55, -41, 35, 57, -41, 35, Blocks.MOSSY_STONE_BRICKS.getDefaultState());
        structure.fillWithBlocks(world, start, 55, -41, 37, 55, -41, 37, Blocks.STONE_BRICKS.getDefaultState());
        structure.fillWithBlocks(world, start, 55, -41, 40, 56, -41, 41, Blocks.STONE_BRICKS.getDefaultState());
        structure.fillWithBlocks(world, start, 55, -41, 44, 55, -40, 44, Blocks.STONE_BRICKS.getDefaultState());
        structure.fillWithBlocks(world, start, 55, -41, 48, 55, -41, 50, Blocks.STONE_BRICKS.getDefaultState());
        structure.fillWithBlocks(world, start, 55, -41, 52, 55, -41, 53, Blocks.STONE_BRICKS.getDefaultState());
        structure.fillWithBlocks(world, start, 55, -40, -23, 55, -39, -22, Blocks.STONE_BRICKS.getDefaultState());
        structure.fillWithBlocks(world, start, 55, -40, -21, 56, -40, -21, Blocks.MOSSY_STONE_BRICKS.getDefaultState());
        structure.fillWithBlocks(world, start, 55, -40, -20, 55, -40, -20, Blocks.STONE_BRICKS.getDefaultState());
        structure.fillWithBlocks(world, start, 55, -40, -14, 55, -40, -13, Blocks.STONE_BRICKS.getDefaultState());
        structure.fillWithBlocks(world, start, 55, -40, -9, 55, -38, -9, Blocks.MOSSY_STONE_BRICKS.getDefaultState());
        structure.fillWithBlocks(world, start, 55, -40, -8, 59, -40, -8, Blocks.STONE_BRICKS.getDefaultState());
        structure.fillWithBlocks(world, start, 55, -40, 16, 57, -40, 16, Blocks.MOSSY_STONE_BRICKS.getDefaultState());
        structure.fillWithBlocks(world, start, 55, -40, 17, 55, -39, 17, Blocks.STONE_BRICKS.getDefaultState());
        structure.fillWithBlocks(world, start, 55, -40, 19, 55, -39, 20, Blocks.STONE_BRICKS.getDefaultState());
        structure.fillWithBlocks(world, start, 55, -40, 23, 55, -40, 27, Blocks.STONE_BRICKS.getDefaultState());
        structure.fillWithBlocks(world, start, 55, -40, 29, 55, -40, 30, Blocks.STONE_BRICKS.getDefaultState());
        structure.fillWithBlocks(world, start, 55, -40, 31, 55, -40, 33, Blocks.MOSSY_STONE_BRICKS.getDefaultState());
        structure.fillWithBlocks(world, start, 55, -40, 35, 56, -40, 35, Blocks.STONE_BRICKS.getDefaultState());
        structure.fillWithBlocks(world, start, 55, -40, 36, 55, -40, 37, Blocks.MOSSY_STONE_BRICKS.getDefaultState());
        structure.fillWithBlocks(world, start, 55, -40, 38, 57, -40, 38, Blocks.STONE_BRICKS.getDefaultState());
        structure.fillWithBlocks(world, start, 55, -40, 40, 55, -37, 40, Blocks.STONE_BRICKS.getDefaultState());
        structure.fillWithBlocks(world, start, 55, -40, 45, 55, -40, 45, Blocks.STONE_BRICKS.getDefaultState());
        structure.fillWithBlocks(world, start, 55, -40, 46, 55, -40, 47, Blocks.MOSSY_STONE_BRICKS.getDefaultState());
        structure.fillWithBlocks(world, start, 55, -40, 51, 55, -38, 51, Blocks.STONE_BRICKS.getDefaultState());
        structure.fillWithBlocks(world, start, 55, -40, 53, 56, -40, 55, Blocks.STONE_BRICKS.getDefaultState());
        structure.fillWithBlocks(world, start, 55, -39, -24, 55, -39, -24, Blocks.MOSSY_STONE_BRICKS.getDefaultState());
        structure.fillWithBlocks(world, start, 55, -39, -21, 55, -39, -18, Blocks.STONE_BRICKS.getDefaultState());
        structure.fillWithBlocks(world, start, 55, -39, -16, 55, -39, -14, Blocks.STONE_BRICKS.getDefaultState());
        structure.fillWithBlocks(world, start, 55, -39, -12, 55, -38, -11, Blocks.STONE_BRICKS.getDefaultState());
        structure.fillWithBlocks(world, start, 55, -39, -10, 55, -38, -9, Blocks.MOSSY_STONE_BRICKS.getDefaultState());
        structure.fillWithBlocks(world, start, 55, -39, 15, 55, -39, 15, Blocks.STONE_BRICKS.getDefaultState());
        structure.fillWithBlocks(world, start, 55, -39, 16, 55, -38, 16, Blocks.MOSSY_STONE_BRICKS.getDefaultState());
        structure.fillWithBlocks(world, start, 55, -39, 18, 55, -37, 18, Blocks.MOSSY_STONE_BRICKS.getDefaultState());
        structure.fillWithBlocks(world, start, 55, -39, 21, 56, -39, 22, Blocks.STONE_BRICKS.getDefaultState());
        structure.fillWithBlocks(world, start, 55, -39, 23, 55, -39, 23, Blocks.STONE_BRICKS.getDefaultState());
        structure.fillWithBlocks(world, start, 55, -39, 26, 56, -39, 27, Blocks.STONE_BRICKS.getDefaultState());
        structure.fillWithBlocks(world, start, 55, -39, 29, 55, -39, 29, Blocks.STONE_BRICKS.getDefaultState());
        structure.fillWithBlocks(world, start, 55, -39, 32, 56, -39, 33, Blocks.STONE_BRICKS.getDefaultState());
        structure.fillWithBlocks(world, start, 55, -39, 41, 55, -38, 42, Blocks.STONE_BRICKS.getDefaultState());
        structure.fillWithBlocks(world, start, 55, -39, 43, 55, -37, 43, Blocks.MOSSY_STONE_BRICKS.getDefaultState());
        structure.fillWithBlocks(world, start, 55, -39, 45, 57, -38, 45, Blocks.STONE_BRICKS.getDefaultState());
        structure.fillWithBlocks(world, start, 55, -39, 46, 55, -39, 46, Blocks.MOSSY_STONE_BRICKS.getDefaultState());
        structure.fillWithBlocks(world, start, 55, -39, 47, 55, -39, 48, Blocks.AIR.getDefaultState());
        structure.fillWithBlocks(world, start, 55, -39, 50, 55, -38, 51, Blocks.STONE_BRICKS.getDefaultState());
        structure.fillWithBlocks(world, start, 55, -39, 53, 55, -39, 54, Blocks.STONE_BRICKS.getDefaultState());
        structure.fillWithBlocks(world, start, 55, -38, -24, 55, -37, -24, Blocks.STONE_BRICKS.getDefaultState());
        structure.fillWithBlocks(world, start, 55, -38, -23, 55, -38, -23, Blocks.MOSSY_STONE_BRICKS.getDefaultState());
        structure.fillWithBlocks(world, start, 55, -38, -22, 55, -38, -21, Blocks.STONE_BRICKS.getDefaultState());
        structure.fillWithBlocks(world, start, 55, -38, -19, 56, -38, -19, Blocks.AIR.getDefaultState());
        structure.fillWithBlocks(world, start, 55, -38, -18, 55, -37, -18, Blocks.MOSSY_STONE_BRICKS.getDefaultState());
        structure.fillWithBlocks(world, start, 55, -38, -17, 55, -37, -17, Blocks.STONE_BRICKS.getDefaultState());
        structure.fillWithBlocks(world, start, 55, -38, -15, 55, -38, -14, Blocks.MOSSY_STONE_BRICKS.getDefaultState());
        structure.fillWithBlocks(world, start, 55, -38, -13, 55, -38, -11, Blocks.STONE_BRICKS.getDefaultState());
        structure.fillWithBlocks(world, start, 55, -38, -8, 55, -37, -8, Blocks.MOSSY_STONE_BRICKS.getDefaultState());
        structure.fillWithBlocks(world, start, 55, -38, 14, 55, -38, 18, Blocks.MOSSY_STONE_BRICKS.getDefaultState());
        structure.fillWithBlocks(world, start, 55, -38, 19, 55, -37, 19, Blocks.STONE_BRICKS.getDefaultState());
        structure.fillWithBlocks(world, start, 55, -38, 20, 56, -38, 20, Blocks.MOSSY_COBBLESTONE.getDefaultState());
        structure.fillWithBlocks(world, start, 55, -38, 21, 55, -38, 23, Blocks.MOSSY_STONE_BRICKS.getDefaultState());
        structure.fillWithBlocks(world, start, 55, -38, 25, 55, -37, 25, Blocks.MOSSY_STONE_BRICKS.getDefaultState());
        structure.fillWithBlocks(world, start, 55, -38, 28, 55, -37, 28, Blocks.MOSSY_COBBLESTONE.getDefaultState());
        structure.fillWithBlocks(world, start, 55, -38, 30, 57, -38, 30, Blocks.STONE_BRICKS.getDefaultState());
        structure.fillWithBlocks(world, start, 55, -38, 31, 56, -38, 31, Blocks.MOSSY_STONE_BRICKS.getDefaultState());
        structure.fillWithBlocks(world, start, 55, -38, 33, 55, -37, 33, Blocks.STONE_BRICKS.getDefaultState());
        structure.fillWithBlocks(world, start, 55, -38, 35, 55, -38, 35, Blocks.STONE_BRICKS.getDefaultState());
        structure.fillWithBlocks(world, start, 55, -38, 36, 55, -38, 36, Blocks.AIR.getDefaultState());
        structure.fillWithBlocks(world, start, 55, -38, 37, 55, -38, 38, Blocks.MOSSY_STONE_BRICKS.getDefaultState());
        structure.fillWithBlocks(world, start, 55, -38, 46, 55, -38, 46, Blocks.STONE_BRICKS.getDefaultState());
        structure.fillWithBlocks(world, start, 55, -38, 48, 55, -37, 49, Blocks.STONE_BRICKS.getDefaultState());
        structure.fillWithBlocks(world, start, 55, -38, 52, 55, -37, 52, Blocks.STONE_BRICKS.getDefaultState());
        structure.fillWithBlocks(world, start, 55, -38, 55, 55, -37, 56, Blocks.STONE_BRICKS.getDefaultState());
        structure.fillWithBlocks(world, start, 55, -37, -23, 56, -37, -22, Blocks.STONE_BRICKS.getDefaultState());
        structure.fillWithBlocks(world, start, 55, -37, -21, 55, -37, -19, Blocks.STONE_BRICKS.getDefaultState());
        structure.fillWithBlocks(world, start, 55, -37, -14, 55, -37, -14, Blocks.STONE_BRICKS.getDefaultState());
        structure.fillWithBlocks(world, start, 55, -37, -11, 56, -37, -11, Blocks.STONE_BRICKS.getDefaultState());
        structure.fillWithBlocks(world, start, 55, -37, -9, 55, -37, -9, Blocks.MOSSY_COBBLESTONE.getDefaultState());
        structure.fillWithBlocks(world, start, 55, -37, 15, 55, -37, 15, Blocks.MOSSY_STONE_BRICKS.getDefaultState());
        structure.fillWithBlocks(world, start, 55, -37, 17, 55, -37, 18, Blocks.MOSSY_STONE_BRICKS.getDefaultState());
        structure.fillWithBlocks(world, start, 55, -37, 21, 55, -37, 23, Blocks.STONE_BRICKS.getDefaultState());
        structure.fillWithBlocks(world, start, 55, -37, 26, 55, -37, 26, Blocks.MOSSY_STONE_BRICKS.getDefaultState());
        structure.fillWithBlocks(world, start, 55, -37, 29, 55, -37, 31, Blocks.STONE_BRICKS.getDefaultState());
        structure.fillWithBlocks(world, start, 55, -37, 34, 55, -37, 34, Blocks.MOSSY_STONE_BRICKS.getDefaultState());
        structure.fillWithBlocks(world, start, 55, -37, 35, 55, -37, 37, Blocks.STONE_BRICKS.getDefaultState());
        structure.fillWithBlocks(world, start, 55, -37, 41, 58, -37, 41, Blocks.STONE_BRICKS.getDefaultState());
        structure.fillWithBlocks(world, start, 55, -37, 42, 56, -37, 43, Blocks.MOSSY_STONE_BRICKS.getDefaultState());
        structure.fillWithBlocks(world, start, 55, -37, 45, 55, -37, 45, Blocks.STONE_BRICKS.getDefaultState());
        structure.fillWithBlocks(world, start, 55, -37, 50, 55, -37, 51, Blocks.MOSSY_STONE_BRICKS.getDefaultState());
        structure.fillWithBlocks(world, start, 55, -26, 35, 55, -25, 35, Blocks.CRACKED_STONE_BRICKS.getDefaultState());
        structure.fillWithBlocks(world, start, 55, -26, 40, 55, -26, 43, Blocks.STONE_BRICKS.getDefaultState());
        structure.fillWithBlocks(world, start, 55, -26, 45, 55, -26, 45, Blocks.STONE_BRICKS.getDefaultState());
        structure.fillWithBlocks(world, start, 55, -26, 47, 55, -26, 48, Blocks.STONE_BRICKS.getDefaultState());
        structure.fillWithBlocks(world, start, 55, -26, 50, 55, -25, 50, Blocks.STONE_BRICKS.getDefaultState());
        structure.fillWithBlocks(world, start, 55, -26, 51, 55, -26, 52, Blocks.CRACKED_STONE_BRICKS.getDefaultState());
        structure.fillWithBlocks(world, start, 55, -26, 53, 55, -24, 53, Blocks.STONE_BRICKS.getDefaultState());
        structure.fillWithBlocks(world, start, 55, -26, 54, 56, -26, 54, Blocks.CRACKED_STONE_BRICKS.getDefaultState());
        structure.fillWithBlocks(world, start, 55, -26, 74, 56, -26, 77, Blocks.STONE_BRICKS.getDefaultState());
        structure.fillWithBlocks(world, start, 55, -26, 78, 56, -26, 78, Blocks.CRACKED_STONE_BRICKS.getDefaultState());
        structure.fillWithBlocks(world, start, 55, -25, 34, 55, -25, 35, Blocks.CRACKED_STONE_BRICKS.getDefaultState());
        structure.fillWithBlocks(world, start, 55, -25, 36, 55, -17, 36, Blocks.STONE_BRICKS.getDefaultState());
        structure.fillWithBlocks(world, start, 55, -25, 37, 56, -25, 37, Blocks.CRACKED_STONE_BRICKS.getDefaultState());
        structure.fillWithBlocks(world, start, 55, -25, 38, 55, -25, 41, Blocks.STONE_BRICKS.getDefaultState());
        structure.fillWithBlocks(world, start, 55, -25, 43, 57, -25, 45, Blocks.AIR.getDefaultState());
        structure.fillWithBlocks(world, start, 55, -25, 47, 56, -24, 47, Blocks.STONE_BRICKS.getDefaultState());
        structure.fillWithBlocks(world, start, 55, -25, 49, 55, -25, 51, Blocks.STONE_BRICKS.getDefaultState());
        structure.fillWithBlocks(world, start, 55, -25, 54, 60, -25, 54, Blocks.STONE_BRICKS.getDefaultState());
        structure.fillWithBlocks(world, start, 55, -25, 74, 57, -25, 78, Blocks.AIR.getDefaultState());
        structure.fillWithBlocks(world, start, 55, -24, 34, 55, -24, 34, Blocks.STONE_BRICKS.getDefaultState());
        structure.fillWithBlocks(world, start, 55, -24, 37, 55, -24, 38, Blocks.STONE_BRICKS.getDefaultState());
        structure.fillWithBlocks(world, start, 55, -24, 41, 55, -24, 42, Blocks.STONE_BRICKS.getDefaultState());
        structure.fillWithBlocks(world, start, 55, -24, 43, 57, -24, 45, Blocks.AIR.getDefaultState());
        structure.fillWithBlocks(world, start, 55, -24, 46, 55, -24, 48, Blocks.STONE_BRICKS.getDefaultState());
        structure.fillWithBlocks(world, start, 55, -24, 50, 55, -24, 51, Blocks.CRACKED_STONE_BRICKS.getDefaultState());
        structure.fillWithBlocks(world, start, 55, -24, 52, 55, -24, 53, Blocks.STONE_BRICKS.getDefaultState());
        structure.fillWithBlocks(world, start, 55, -24, 54, 55, -23, 54, Blocks.CRACKED_STONE_BRICKS.getDefaultState());
        structure.fillWithBlocks(world, start, 55, -24, 74, 57, -24, 78, Blocks.AIR.getDefaultState());
        structure.fillWithBlocks(world, start, 55, -23, 34, 55, -23, 36, Blocks.STONE_BRICKS.getDefaultState());
        structure.fillWithBlocks(world, start, 55, -23, 38, 55, -23, 39, Blocks.STONE_BRICKS.getDefaultState());
        structure.fillWithBlocks(world, start, 55, -23, 43, 57, -23, 45, Blocks.AIR.getDefaultState());
        structure.fillWithBlocks(world, start, 55, -23, 46, 55, -16, 46, Blocks.STONE_BRICKS.getDefaultState());
        structure.fillWithBlocks(world, start, 55, -23, 47, 55, -22, 47, Blocks.CRACKED_STONE_BRICKS.getDefaultState());
        structure.fillWithBlocks(world, start, 55, -23, 49, 55, -20, 49, Blocks.STONE_BRICKS.getDefaultState());
        structure.fillWithBlocks(world, start, 55, -23, 52, 55, -23, 52, Blocks.STONE_BRICKS.getDefaultState());
        structure.fillWithBlocks(world, start, 55, -23, 74, 57, -23, 78, Blocks.AIR.getDefaultState());
        structure.fillWithBlocks(world, start, 55, -23, 79, 56, -23, 79, Blocks.STONE_BRICKS.getDefaultState());
        structure.fillWithBlocks(world, start, 55, -22, 34, 55, -19, 34, Blocks.STONE_BRICKS.getDefaultState());
        structure.fillWithBlocks(world, start, 55, -22, 35, 55, -21, 35, Blocks.MOSSY_STONE_BRICKS.getDefaultState());
        structure.fillWithBlocks(world, start, 55, -22, 37, 55, -22, 38, Blocks.STONE_BRICKS.getDefaultState());
        structure.fillWithBlocks(world, start, 55, -22, 39, 55, -21, 39, Blocks.CRACKED_STONE_BRICKS.getDefaultState());
        structure.fillWithBlocks(world, start, 55, -22, 40, 56, -22, 41, Blocks.STONE_BRICKS.getDefaultState());
        structure.fillWithBlocks(world, start, 55, -22, 42, 55, -21, 42, Blocks.MOSSY_STONE_BRICKS.getDefaultState());
        structure.fillWithBlocks(world, start, 55, -22, 44, 56, -22, 44, Blocks.CRACKED_STONE_BRICKS.getDefaultState());
        structure.fillWithBlocks(world, start, 55, -22, 45, 55, -21, 46, Blocks.STONE_BRICKS.getDefaultState());
        structure.fillWithBlocks(world, start, 55, -22, 50, 55, -21, 51, Blocks.STONE_BRICKS.getDefaultState());
        structure.fillWithBlocks(world, start, 55, -22, 52, 56, -22, 52, Blocks.CRACKED_STONE_BRICKS.getDefaultState());
        structure.fillWithBlocks(world, start, 55, -22, 53, 55, -22, 53, Blocks.STONE_BRICKS.getDefaultState());
        structure.fillWithBlocks(world, start, 55, -22, 74, 55, -22, 77, Blocks.STONE_BRICKS.getDefaultState());
        structure.fillWithBlocks(world, start, 55, -22, 78, 56, -22, 78, Blocks.MOSSY_STONE_BRICKS.getDefaultState());
        structure.fillWithBlocks(world, start, 55, -21, 38, 57, -21, 38, Blocks.STONE_BRICKS.getDefaultState());
        structure.fillWithBlocks(world, start, 55, -21, 41, 55, -21, 41, Blocks.CRACKED_STONE_BRICKS.getDefaultState());
        structure.fillWithBlocks(world, start, 55, -21, 43, 56, -21, 45, Blocks.STONE_BRICKS.getDefaultState());
        structure.fillWithBlocks(world, start, 55, -21, 53, 55, -21, 54, Blocks.CRACKED_STONE_BRICKS.getDefaultState());
        structure.fillWithBlocks(world, start, 55, -20, 41, 56, -20, 42, Blocks.STONE_BRICKS.getDefaultState());
        structure.fillWithBlocks(world, start, 55, -20, 43, 55, -20, 46, Blocks.STONE_BRICKS.getDefaultState());
        structure.fillWithBlocks(world, start, 55, -20, 50, 55, -20, 52, Blocks.CRACKED_STONE_BRICKS.getDefaultState());
        structure.fillWithBlocks(world, start, 55, -20, 53, 56, -20, 54, Blocks.STONE_BRICKS.getDefaultState());
        structure.fillWithBlocks(world, start, 55, -19, 38, 56, -19, 38, Blocks.AIR.getDefaultState());
        structure.fillWithBlocks(world, start, 55, -19, 40, 55, -19, 41, Blocks.STONE_BRICKS.getDefaultState());
        structure.fillWithBlocks(world, start, 55, -19, 42, 55, -18, 43, Blocks.CRACKED_STONE_BRICKS.getDefaultState());
        structure.fillWithBlocks(world, start, 55, -19, 44, 55, -19, 48, Blocks.STONE_BRICKS.getDefaultState());
        structure.fillWithBlocks(world, start, 55, -19, 49, 55, -19, 49, Blocks.MOSSY_STONE_BRICKS.getDefaultState());
        structure.fillWithBlocks(world, start, 55, -19, 50, 55, -19, 50, Blocks.STONE_BRICKS.getDefaultState());
        structure.fillWithBlocks(world, start, 55, -19, 52, 55, -19, 54, Blocks.STONE_BRICKS.getDefaultState());
        structure.fillWithBlocks(world, start, 55, -18, 35, 55, -17, 36, Blocks.STONE_BRICKS.getDefaultState());
        structure.fillWithBlocks(world, start, 55, -18, 38, 55, -18, 40, Blocks.STONE_BRICKS.getDefaultState());
        structure.fillWithBlocks(world, start, 55, -18, 44, 55, -18, 45, Blocks.CRACKED_STONE_BRICKS.getDefaultState());
        structure.fillWithBlocks(world, start, 55, -18, 47, 56, -18, 47, Blocks.CRACKED_STONE_BRICKS.getDefaultState());
        structure.fillWithBlocks(world, start, 55, -18, 48, 55, -17, 49, Blocks.STONE_BRICKS.getDefaultState());
        structure.fillWithBlocks(world, start, 55, -18, 51, 55, -18, 51, Blocks.CRACKED_STONE_BRICKS.getDefaultState());
        structure.fillWithBlocks(world, start, 55, -18, 52, 55, -17, 54, Blocks.STONE_BRICKS.getDefaultState());
        structure.fillWithBlocks(world, start, 55, -17, 34, 56, -17, 35, Blocks.STONE_BRICKS.getDefaultState());
        structure.fillWithBlocks(world, start, 55, -17, 37, 56, -17, 37, Blocks.STONE_BRICKS.getDefaultState());
        structure.fillWithBlocks(world, start, 55, -17, 40, 55, -17, 41, Blocks.STONE_BRICKS.getDefaultState());
        structure.fillWithBlocks(world, start, 55, -17, 43, 56, -17, 43, Blocks.MOSSY_STONE_BRICKS.getDefaultState());
        structure.fillWithBlocks(world, start, 55, -17, 44, 55, -16, 46, Blocks.STONE_BRICKS.getDefaultState());
        structure.fillWithBlocks(world, start, 55, -17, 47, 55, -17, 50, Blocks.STONE_BRICKS.getDefaultState());
        structure.fillWithBlocks(world, start, 55, -15, 39, 57, -15, 41, Blocks.STONE_BRICKS.getDefaultState());
        structure.fillWithBlocks(world, start, 55, -15, 42, 56, -15, 43, Blocks.AIR.getDefaultState());
        structure.fillWithBlocks(world, start, 55, -15, 44, 55, -15, 46, Blocks.AIR.getDefaultState());
        structure.fillWithBlocks(world, start, 55, -14, 39, 55, -12, 41, Blocks.STONE_BRICKS.getDefaultState());
        structure.fillWithBlocks(world, start, 55, -14, 42, 57, -14, 46, Blocks.AIR.getDefaultState());
        structure.fillWithBlocks(world, start, 55, -13, 42, 57, -13, 46, Blocks.AIR.getDefaultState());
        structure.fillWithBlocks(world, start, 55, -12, 42, 57, -11, 42, Blocks.STONE_BRICKS.getDefaultState());
        structure.fillWithBlocks(world, start, 55, -12, 43, 57, -12, 45, Blocks.AIR.getDefaultState());
        structure.fillWithBlocks(world, start, 55, -12, 46, 63, -12, 46, Blocks.STONE_BRICKS.getDefaultState());
        structure.fillWithBlocks(world, start, 55, -11, 39, 57, -11, 43, Blocks.STONE_BRICKS.getDefaultState());
        structure.fillWithBlocks(world, start, 55, -11, 44, 55, -11, 45, Blocks.STONE_BRICKS.getDefaultState());
        structure.fillWithBlocks(world, start, 55, -10, 39, 55, -9, 45, Blocks.STONE_BRICKS.getDefaultState());
        structure.fillWithBlocks(world, start, 55, 0, 40, 55, 0, 40, Blocks.DIRT.getDefaultState());
        structure.fillWithBlocks(world, start, 55, 0, 48, 58, 0, 69, Blocks.DIRT.getDefaultState());
        structure.fillWithBlocks(world, start, 55, 1, 40, 55, 1, 40, Blocks.DIRT.getDefaultState());
        structure.fillWithBlocks(world, start, 55, 1, 48, 58, 1, 70, Blocks.DIRT.getDefaultState());
        structure.fillWithBlocks(world, start, 55, 1, 72, 61, 1, 78, Blocks.DIRT.getDefaultState());
        structure.fillWithBlocks(world, start, 55, 2, 14, 55, 2, 16, Blocks.DIRT.getDefaultState());
        structure.fillWithBlocks(world, start, 55, 2, 17, 55, 2, 18, Blocks.GRASS_BLOCK.getDefaultState().with(SnowyDirtBlock.SNOWY, false));
        structure.fillWithBlocks(world, start, 55, 2, 19, 64, 2, 28, Blocks.DIRT.getDefaultState());
        structure.fillWithBlocks(world, start, 55, 2, 44, 55, 4, 50, Blocks.DIRT.getDefaultState());
        structure.fillWithBlocks(world, start, 55, 2, 68, 55, 2, 68, Blocks.DIRT.getDefaultState());
        structure.fillWithBlocks(world, start, 55, 2, 69, 55, 2, 70, Blocks.GRASS_BLOCK.getDefaultState().with(SnowyDirtBlock.SNOWY, false));
        structure.fillWithBlocks(world, start, 55, 2, 72, 55, 4, 72, Blocks.STONE_BRICKS.getDefaultState());
        structure.fillWithBlocks(world, start, 55, 2, 76, 56, 2, 77, Blocks.DIRT.getDefaultState());
        structure.fillWithBlocks(world, start, 55, 3, 14, 55, 7, 14, Blocks.STONE_BRICKS.getDefaultState());
        structure.fillWithBlocks(world, start, 55, 3, 19, 59, 3, 29, Blocks.DIRT.getDefaultState());
        structure.fillWithBlocks(world, start, 55, 3, 35, 57, 3, 35, Blocks.GRASS_BLOCK.getDefaultState().with(SnowyDirtBlock.SNOWY, false));
        structure.fillWithBlocks(world, start, 55, 3, 36, 57, 3, 41, Blocks.DIRT.getDefaultState());
        structure.fillWithBlocks(world, start, 55, 3, 43, 55, 4, 50, Blocks.DIRT.getDefaultState());
        structure.fillWithBlocks(world, start, 55, 3, 63, 56, 4, 63, Blocks.OAK_LOG.getDefaultState());
        structure.fillWithBlocks(world, start, 55, 3, 64, 57, 3, 66, Blocks.DIRT.getDefaultState());
        structure.fillWithBlocks(world, start, 55, 3, 68, 55, 3, 68, Blocks.DIRT.getDefaultState());
        structure.fillWithBlocks(world, start, 55, 3, 76, 56, 3, 77, Blocks.GRASS_BLOCK.getDefaultState().with(SnowyDirtBlock.SNOWY, false));
        structure.fillWithBlocks(world, start, 55, 4, 15, 55, 5, 16, Blocks.STONE_BRICKS.getDefaultState());
        structure.fillWithBlocks(world, start, 55, 4, 19, 55, 4, 19, Blocks.GRASS_BLOCK.getDefaultState().with(SnowyDirtBlock.SNOWY, false));
        structure.fillWithBlocks(world, start, 55, 4, 36, 58, 4, 36, Blocks.DIRT.getDefaultState());
        structure.fillWithBlocks(world, start, 55, 4, 37, 56, 4, 37, Blocks.GRASS_BLOCK.getDefaultState().with(SnowyDirtBlock.SNOWY, false));
        structure.fillWithBlocks(world, start, 55, 4, 38, 57, 4, 41, Blocks.DIRT.getDefaultState());
        structure.fillWithBlocks(world, start, 55, 4, 58, 57, 6, 58, Blocks.OAK_LOG.getDefaultState());
        structure.fillWithBlocks(world, start, 55, 4, 64, 58, 4, 67, Blocks.DIRT.getDefaultState());
        structure.fillWithBlocks(world, start, 55, 4, 74, 55, 4, 75, Blocks.STONE_BRICKS.getDefaultState());
        structure.fillWithBlocks(world, start, 55, 5, 20, 55, 5, 21, Blocks.STONE_BRICKS.getDefaultState());
        structure.fillWithBlocks(world, start, 55, 5, 22, 55, 5, 22, Blocks.GRASS_BLOCK.getDefaultState().with(SnowyDirtBlock.SNOWY, false));
        structure.fillWithBlocks(world, start, 55, 5, 24, 55, 5, 24, Blocks.GRASS_BLOCK.getDefaultState().with(SnowyDirtBlock.SNOWY, false));
        structure.fillWithBlocks(world, start, 55, 5, 36, 57, 7, 36, Blocks.STONE_BRICKS.getDefaultState());
        structure.fillWithBlocks(world, start, 55, 5, 38, 56, 5, 50, Blocks.STONE_BRICKS.getDefaultState());
        structure.fillWithBlocks(world, start, 55, 5, 57, 56, 5, 58, Blocks.OAK_LOG.getDefaultState());
        structure.fillWithBlocks(world, start, 55, 5, 59, 55, 5, 59, Blocks.STONE_BRICKS.getDefaultState());
        structure.fillWithBlocks(world, start, 55, 5, 63, 56, 5, 63, Blocks.OAK_LOG.getDefaultState());
        structure.fillWithBlocks(world, start, 55, 5, 64, 55, 5, 65, Blocks.STONE_BRICKS.getDefaultState());
        structure.fillWithBlocks(world, start, 55, 5, 73, 55, 9, 73, Blocks.STONE_BRICKS.getDefaultState());
        structure.fillWithBlocks(world, start, 55, 6, 15, 55, 9, 15, Blocks.STONE_BRICKS.getDefaultState());
        structure.fillWithBlocks(world, start, 55, 6, 25, 55, 6, 34, Blocks.STONE_BRICKS.getDefaultState());
        structure.fillWithBlocks(world, start, 55, 6, 38, 57, 6, 41, Blocks.STONE_BRICKS.getDefaultState());
        structure.fillWithBlocks(world, start, 55, 6, 42, 55, 7, 43, Blocks.STONE_BRICKS.getDefaultState());
        structure.fillWithBlocks(world, start, 55, 6, 44, 55, 6, 50, Blocks.STONE_BRICKS.getDefaultState());
        structure.fillWithBlocks(world, start, 55, 6, 57, 56, 6, 58, Blocks.OAK_LOG.getDefaultState());
        structure.fillWithBlocks(world, start, 55, 6, 59, 55, 6, 59, Blocks.STONE_BRICKS.getDefaultState());
        structure.fillWithBlocks(world, start, 55, 6, 62, 56, 7, 62, Blocks.STONE_BRICKS.getDefaultState());
        structure.fillWithBlocks(world, start, 55, 7, 26, 56, 7, 29, Blocks.STONE_BRICKS.getDefaultState());
        structure.fillWithBlocks(world, start, 55, 7, 38, 57, 7, 41, Blocks.STONE_BRICKS.getDefaultState());
        structure.fillWithBlocks(world, start, 55, 7, 50, 57, 9, 50, Blocks.STONE_BRICKS.getDefaultState());
        structure.fillWithBlocks(world, start, 55, 7, 59, 55, 7, 59, Blocks.STONE_BRICKS.getDefaultState());
        structure.fillWithBlocks(world, start, 55, 8, 26, 56, 8, 29, Blocks.STONE_BRICKS.getDefaultState());
        structure.fillWithBlocks(world, start, 55, 8, 40, 56, 8, 41, Blocks.STONE_BRICKS.getDefaultState());
        structure.fillWithBlocks(world, start, 55, 8, 42, 55, 9, 42, Blocks.STONE_BRICKS.getDefaultState());
        structure.fillWithBlocks(world, start, 55, 8, 45, 55, 10, 45, Blocks.OAK_LOG.getDefaultState());
        structure.fillWithBlocks(world, start, 55, 8, 60, 55, 8, 62, Blocks.STONE_BRICKS.getDefaultState());
        structure.fillWithBlocks(world, start, 55, 9, 26, 56, 9, 27, Blocks.STONE_BRICKS.getDefaultState());
        structure.fillWithBlocks(world, start, 55, 9, 37, 55, 9, 42, Blocks.STONE_BRICKS.getDefaultState());
        structure.fillWithBlocks(world, start, 55, 9, 43, 55, 11, 43, Blocks.OAK_LOG.getDefaultState());
        structure.fillWithBlocks(world, start, 55, 9, 46, 55, 9, 50, Blocks.STONE_BRICKS.getDefaultState());
        structure.fillWithBlocks(world, start, 55, 9, 59, 55, 9, 62, Blocks.STONE_BRICKS.getDefaultState());
        structure.fillWithBlocks(world, start, 55, 10, 26, 56, 10, 27, Blocks.STONE_BRICKS.getDefaultState());
        structure.fillWithBlocks(world, start, 55, 10, 38, 57, 10, 41, Blocks.STONE_BRICKS.getDefaultState());
        structure.fillWithBlocks(world, start, 55, 10, 42, 55, 11, 44, Blocks.OAK_LOG.getDefaultState());
        structure.fillWithBlocks(world, start, 55, 10, 46, 55, 10, 50, Blocks.STONE_BRICKS.getDefaultState());
        structure.fillWithBlocks(world, start, 55, 11, 26, 56, 11, 27, Blocks.STONE_BRICKS.getDefaultState());
        structure.fillWithBlocks(world, start, 55, 11, 38, 57, 11, 41, Blocks.STONE_BRICKS.getDefaultState());
        structure.fillWithBlocks(world, start, 55, 11, 46, 55, 11, 50, Blocks.STONE_BRICKS.getDefaultState());
        structure.fillWithBlocks(world, start, 55, 12, 26, 55, 12, 27, Blocks.STONE_BRICKS.getDefaultState());
        structure.fillWithBlocks(world, start, 55, 12, 38, 56, 12, 39, Blocks.STONE_BRICKS.getDefaultState());
        structure.fillWithBlocks(world, start, 55, 12, 40, 55, 17, 40, Blocks.STONE_BRICKS.getDefaultState());
        structure.fillWithBlocks(world, start, 55, 12, 46, 55, 12, 50, Blocks.STONE_BRICKS.getDefaultState());
        structure.fillWithBlocks(world, start, 55, 13, 38, 56, 13, 39, Blocks.STONE_BRICKS.getDefaultState());
        structure.fillWithBlocks(world, start, 55, 13, 47, 57, 13, 50, Blocks.STONE_BRICKS.getDefaultState());
        structure.fillWithBlocks(world, start, 55, 14, 38, 56, 14, 39, Blocks.STONE_BRICKS.getDefaultState());
        structure.fillWithBlocks(world, start, 55, 14, 48, 57, 14, 50, Blocks.STONE_BRICKS.getDefaultState());
        structure.fillWithBlocks(world, start, 55, 15, 38, 56, 15, 39, Blocks.STONE_BRICKS.getDefaultState());
        structure.fillWithBlocks(world, start, 55, 15, 48, 57, 15, 50, Blocks.STONE_BRICKS.getDefaultState());
        structure.fillWithBlocks(world, start, 55, 15, 52, 59, 15, 52, Blocks.STONE_BRICKS.getDefaultState());
        structure.fillWithBlocks(world, start, 55, 16, 38, 56, 16, 39, Blocks.STONE_BRICKS.getDefaultState());
        structure.fillWithBlocks(world, start, 55, 16, 48, 56, 16, 50, Blocks.STONE_BRICKS.getDefaultState());
        structure.fillWithBlocks(world, start, 55, 17, 38, 56, 17, 39, Blocks.STONE_BRICKS.getDefaultState());
        structure.fillWithBlocks(world, start, 55, 17, 48, 56, 17, 50, Blocks.STONE_BRICKS.getDefaultState());
        structure.fillWithBlocks(world, start, 55, 17, 62, 55, 18, 62, Blocks.STONE_BRICKS.getDefaultState());
        structure.fillWithBlocks(world, start, 55, 18, 38, 56, 18, 39, Blocks.STONE_BRICKS.getDefaultState());
        structure.fillWithBlocks(world, start, 55, 18, 48, 56, 18, 50, Blocks.STONE_BRICKS.getDefaultState());
        structure.fillWithBlocks(world, start, 55, 19, 26, 55, 19, 27, Blocks.STONE_BRICKS.getDefaultState());
        structure.fillWithBlocks(world, start, 55, 19, 38, 56, 19, 39, Blocks.STONE_BRICKS.getDefaultState());
        structure.fillWithBlocks(world, start, 55, 19, 48, 56, 19, 50, Blocks.STONE_BRICKS.getDefaultState());
        structure.fillWithBlocks(world, start, 55, 19, 62, 55, 21, 62, Blocks.OAK_LOG.getDefaultState());
        structure.fillWithBlocks(world, start, 55, 20, 38, 56, 20, 39, Blocks.STONE_BRICKS.getDefaultState());
        structure.fillWithBlocks(world, start, 55, 20, 49, 56, 20, 50, Blocks.STONE_BRICKS.getDefaultState());
        structure.fillWithBlocks(world, start, 55, 21, 39, 56, 22, 39, Blocks.STONE_BRICKS.getDefaultState());
        structure.fillWithBlocks(world, start, 55, 21, 49, 56, 21, 50, Blocks.STONE_BRICKS.getDefaultState());
        structure.fillWithBlocks(world, start, 55, 22, 49, 55, 22, 49, Blocks.STONE_BRICKS.getDefaultState());
        structure.fillWithBlocks(world, start, 55, 23, 39, 56, 24, 39, Blocks.STONE_BRICKS.getDefaultState());
        structure.fillWithBlocks(world, start, 55, 23, 49, 55, 23, 49, Blocks.STONE_BRICKS.getDefaultState());
        structure.fillWithBlocks(world, start, 55, 24, 38, 56, 24, 39, Blocks.STONE_BRICKS.getDefaultState());
        structure.fillWithBlocks(world, start, 55, 24, 49, 55, 24, 49, Blocks.STONE_BRICKS.getDefaultState());
        structure.fillWithBlocks(world, start, 55, 25, 49, 55, 25, 49, Blocks.STONE_BRICKS.getDefaultState());
        structure.fillWithBlocks(world, start, 55, 26, 72, 55, 27, 72, Blocks.STONE_BRICKS.getDefaultState());
        structure.fillWithBlocks(world, start, 55, 28, 27, 56, 29, 27, Blocks.STONE_BRICKS.getDefaultState());
        structure.fillWithBlocks(world, start, 55, 29, 72, 55, 31, 72, Blocks.STONE_BRICKS.getDefaultState());
        structure.fillWithBlocks(world, start, 55, 30, 27, 56, 30, 27, Blocks.STONE_BRICKS.getDefaultState());
        structure.fillWithBlocks(world, start, 56, -59, 42, 57, -59, 45, Blocks.STONE_BRICKS.getDefaultState());
        structure.fillWithBlocks(world, start, 56, -59, 47, 57, -59, 59, Blocks.STONE_BRICKS.getDefaultState());
        structure.fillWithBlocks(world, start, 56, -58, 50, 58, -58, 58, Blocks.STONE_BRICKS.getDefaultState());
        structure.fillWithBlocks(world, start, 56, -58, 59, 56, -58, 60, Blocks.STONE_BRICKS.getDefaultState());
        structure.fillWithBlocks(world, start, 56, -56, -44, 57, -56, -43, Blocks.STONE_BRICKS.getDefaultState());
        structure.fillWithBlocks(world, start, 56, -56, -42, 56, -56, -40, Blocks.STONE_BRICKS.getDefaultState());
        structure.fillWithBlocks(world, start, 56, -55, -40, 57, -54, -40, Blocks.STONE_BRICKS.getDefaultState());
        structure.fillWithBlocks(world, start, 56, -55, -20, 57, -55, -19, Blocks.STONE_BRICKS.getDefaultState());
        structure.fillWithBlocks(world, start, 56, -55, 39, 57, -55, 40, Blocks.AIR.getDefaultState());
        structure.fillWithBlocks(world, start, 56, -55, 59, 57, -54, 59, Blocks.AIR.getDefaultState());
        structure.fillWithBlocks(world, start, 56, -54, -60, 57, -54, -47, Blocks.STONE_BRICKS.getDefaultState());
        structure.fillWithBlocks(world, start, 56, -54, -45, 57, -54, -40, Blocks.STONE_BRICKS.getDefaultState());
        structure.fillWithBlocks(world, start, 56, -54, -20, 56, -54, -20, Blocks.STONE_BRICKS.getDefaultState());
        structure.fillWithBlocks(world, start, 56, -54, 39, 57, -54, 40, Blocks.AIR.getDefaultState());
        structure.fillWithBlocks(world, start, 56, -53, -50, 56, -52, -49, Blocks.STONE_BRICKS.getDefaultState());
        structure.fillWithBlocks(world, start, 56, -53, -13, 77, -53, -13, Blocks.STONE_BRICKS.getDefaultState());
        structure.fillWithBlocks(world, start, 56, -53, 39, 57, -53, 40, Blocks.AIR.getDefaultState());
        structure.fillWithBlocks(world, start, 56, -53, 59, 57, -53, 59, Blocks.AIR.getDefaultState());
        structure.fillWithBlocks(world, start, 56, -52, -53, 57, -52, -49, Blocks.STONE_BRICKS.getDefaultState());
        structure.fillWithBlocks(world, start, 56, -52, -47, 57, -52, -43, Blocks.STONE_BRICKS.getDefaultState());
        structure.fillWithBlocks(world, start, 56, -52, -42, 56, -52, -40, Blocks.STONE_BRICKS.getDefaultState());
        structure.fillWithBlocks(world, start, 56, -52, 59, 56, -52, 60, Blocks.STONE_BRICKS.getDefaultState());
        structure.fillWithBlocks(world, start, 56, -51, -42, 57, -51, -40, Blocks.STONE_BRICKS.getDefaultState());
        structure.fillWithBlocks(world, start, 56, -51, 40, 57, -51, 42, Blocks.STONE_BRICKS.getDefaultState());
        structure.fillWithBlocks(world, start, 56, -51, 45, 57, -51, 57, Blocks.STONE_BRICKS.getDefaultState());
        structure.fillWithBlocks(world, start, 56, -51, 58, 56, -51, 59, Blocks.AIR.getDefaultState());
        structure.fillWithBlocks(world, start, 56, -50, -54, 57, -50, -41, Blocks.STONE_BRICKS.getDefaultState());
        structure.fillWithBlocks(world, start, 56, -50, 47, 57, -50, 59, Blocks.STONE_BRICKS.getDefaultState());
        structure.fillWithBlocks(world, start, 56, -49, -60, 56, -49, -60, Blocks.STONE_BRICKS.getDefaultState());
        structure.fillWithBlocks(world, start, 56, -49, -58, 57, -49, -54, Blocks.STONE_BRICKS.getDefaultState());
        structure.fillWithBlocks(world, start, 56, -49, -52, 57, -49, -46, Blocks.STONE_BRICKS.getDefaultState());
        structure.fillWithBlocks(world, start, 56, -49, -44, 57, -49, -40, Blocks.STONE_BRICKS.getDefaultState());
        structure.fillWithBlocks(world, start, 56, -49, 39, 57, -49, 44, Blocks.STONE_BRICKS.getDefaultState());
        structure.fillWithBlocks(world, start, 56, -49, 46, 57, -49, 56, Blocks.STONE_BRICKS.getDefaultState());
        structure.fillWithBlocks(world, start, 56, -48, -59, 57, -48, -44, Blocks.STONE_BRICKS.getDefaultState());
        structure.fillWithBlocks(world, start, 56, -48, 39, 57, -48, 56, Blocks.STONE_BRICKS.getDefaultState());
        structure.fillWithBlocks(world, start, 56, -48, 58, 57, -48, 59, Blocks.STONE_BRICKS.getDefaultState());
        structure.fillWithBlocks(world, start, 56, -47, -60, 56, -47, -60, Blocks.STONE_BRICKS.getDefaultState());
        structure.fillWithBlocks(world, start, 56, -47, -52, 57, -47, -46, Blocks.STONE_BRICKS.getDefaultState());
        structure.fillWithBlocks(world, start, 56, -47, -42, 57, -47, -40, Blocks.STONE_BRICKS.getDefaultState());
        structure.fillWithBlocks(world, start, 56, -47, 43, 56, -47, 59, Blocks.STONE_BRICKS.getDefaultState());
        structure.fillWithBlocks(world, start, 56, -46, -23, 56, -46, -20, Blocks.STONE_BRICKS.getDefaultState());
        structure.fillWithBlocks(world, start, 56, -46, -19, 56, -46, -19, Blocks.MOSSY_STONE_BRICKS.getDefaultState());
        structure.fillWithBlocks(world, start, 56, -46, -18, 56, -46, -18, Blocks.STONE_BRICKS.getDefaultState());
        structure.fillWithBlocks(world, start, 56, -46, -17, 56, -46, -16, Blocks.MOSSY_STONE_BRICKS.getDefaultState());
        structure.fillWithBlocks(world, start, 56, -46, -15, 56, -46, -15, Blocks.STONE_BRICKS.getDefaultState());
        structure.fillWithBlocks(world, start, 56, -46, -13, 56, -46, -10, Blocks.STONE_BRICKS.getDefaultState());
        structure.fillWithBlocks(world, start, 56, -46, 15, 56, -45, 15, Blocks.MOSSY_COBBLESTONE.getDefaultState());
        structure.fillWithBlocks(world, start, 56, -46, 16, 57, -46, 17, Blocks.STONE_BRICKS.getDefaultState());
        structure.fillWithBlocks(world, start, 56, -46, 18, 56, -46, 19, Blocks.STONE_BRICKS.getDefaultState());
        structure.fillWithBlocks(world, start, 56, -46, 20, 56, -46, 21, Blocks.MOSSY_STONE_BRICKS.getDefaultState());
        structure.fillWithBlocks(world, start, 56, -46, 24, 56, -46, 24, Blocks.MOSSY_COBBLESTONE.getDefaultState());
        structure.fillWithBlocks(world, start, 56, -46, 26, 57, -46, 27, Blocks.MOSSY_COBBLESTONE.getDefaultState());
        structure.fillWithBlocks(world, start, 56, -46, 28, 56, -46, 29, Blocks.MOSSY_COBBLESTONE.getDefaultState());
        structure.fillWithBlocks(world, start, 56, -46, 30, 56, -44, 30, Blocks.STONE_BRICKS.getDefaultState());
        structure.fillWithBlocks(world, start, 56, -46, 31, 56, -45, 32, Blocks.MOSSY_STONE_BRICKS.getDefaultState());
        structure.fillWithBlocks(world, start, 56, -46, 33, 57, -46, 35, Blocks.STONE_BRICKS.getDefaultState());
        structure.fillWithBlocks(world, start, 56, -46, 37, 56, -46, 38, Blocks.STONE_BRICKS.getDefaultState());
        structure.fillWithBlocks(world, start, 56, -46, 42, 58, -46, 44, Blocks.AIR.getDefaultState());
        structure.fillWithBlocks(world, start, 56, -46, 46, 57, -46, 47, Blocks.STONE_BRICKS.getDefaultState());
        structure.fillWithBlocks(world, start, 56, -46, 50, 56, -46, 50, Blocks.STONE_BRICKS.getDefaultState());
        structure.fillWithBlocks(world, start, 56, -46, 52, 58, -46, 54, Blocks.AIR.getDefaultState());
        structure.fillWithBlocks(world, start, 56, -46, 55, 57, -46, 56, Blocks.STONE_BRICKS.getDefaultState());
        structure.fillWithBlocks(world, start, 56, -45, -24, 57, -45, -24, Blocks.STONE_BRICKS.getDefaultState());
        structure.fillWithBlocks(world, start, 56, -45, -23, 56, -44, -23, Blocks.MOSSY_STONE_BRICKS.getDefaultState());
        structure.fillWithBlocks(world, start, 56, -45, -21, 56, -45, -20, Blocks.STONE_BRICK_WALL.getDefaultState().with(WallBlock.WATERLOGGED, false).with(WallBlock.UP, true).with(WallBlock.WALL_HEIGHT_NORTH, WallHeight.LOW).with(WallBlock.WALL_HEIGHT_SOUTH, WallHeight.LOW).with(WallBlock.WALL_HEIGHT_EAST, WallHeight.LOW).with(WallBlock.WALL_HEIGHT_WEST, WallHeight.LOW));
        structure.fillWithBlocks(world, start, 56, -45, -19, 56, -40, -19, Blocks.STONE_BRICKS.getDefaultState());
        structure.fillWithBlocks(world, start, 56, -45, -14, 65, -42, -14, Blocks.AIR.getDefaultState());
        structure.fillWithBlocks(world, start, 56, -45, -11, 56, -45, -10, Blocks.STONE_BRICK_WALL.getDefaultState().with(WallBlock.WATERLOGGED, false).with(WallBlock.UP, true).with(WallBlock.WALL_HEIGHT_NORTH, WallHeight.LOW).with(WallBlock.WALL_HEIGHT_SOUTH, WallHeight.LOW).with(WallBlock.WALL_HEIGHT_EAST, WallHeight.LOW).with(WallBlock.WALL_HEIGHT_WEST, WallHeight.LOW));
        structure.fillWithBlocks(world, start, 56, -45, -8, 58, -45, -8, Blocks.STONE_BRICKS.getDefaultState());
        structure.fillWithBlocks(world, start, 56, -45, 16, 56, -45, 17, Blocks.AIR.getDefaultState());
        structure.fillWithBlocks(world, start, 56, -45, 18, 56, -45, 18, Blocks.STONE_BRICKS.getDefaultState());
        structure.fillWithBlocks(world, start, 56, -45, 19, 56, -45, 20, Blocks.AIR.getDefaultState());
        structure.fillWithBlocks(world, start, 56, -45, 21, 57, -45, 23, Blocks.STONE_BRICKS.getDefaultState());
        structure.fillWithBlocks(world, start, 56, -45, 24, 56, -45, 28, Blocks.AIR.getDefaultState());
        structure.fillWithBlocks(world, start, 56, -45, 29, 57, -45, 29, Blocks.MOSSY_STONE_BRICKS.getDefaultState());
        structure.fillWithBlocks(world, start, 56, -45, 33, 56, -45, 34, Blocks.MOSSY_STONE_BRICKS.getDefaultState());
        structure.fillWithBlocks(world, start, 56, -45, 36, 56, -45, 36, Blocks.STONE_BRICKS.getDefaultState());
        structure.fillWithBlocks(world, start, 56, -45, 40, 60, -45, 40, Blocks.STONE_BRICKS.getDefaultState());
        structure.fillWithBlocks(world, start, 56, -45, 42, 58, -45, 44, Blocks.AIR.getDefaultState());
        structure.fillWithBlocks(world, start, 56, -45, 51, 57, -45, 51, Blocks.STONE_BRICK_WALL.getDefaultState().with(WallBlock.WATERLOGGED, false).with(WallBlock.UP, false).with(WallBlock.WALL_HEIGHT_NORTH, WallHeight.LOW).with(WallBlock.WALL_HEIGHT_SOUTH, WallHeight.LOW).with(WallBlock.WALL_HEIGHT_EAST, WallHeight.LOW).with(WallBlock.WALL_HEIGHT_WEST, WallHeight.LOW));
        structure.fillWithBlocks(world, start, 56, -45, 52, 58, -45, 54, Blocks.AIR.getDefaultState());
        structure.fillWithBlocks(world, start, 56, -45, 56, 57, -45, 56, Blocks.MOSSY_STONE_BRICKS.getDefaultState());
        structure.fillWithBlocks(world, start, 56, -44, -24, 56, -44, -24, Blocks.AIR.getDefaultState());
        structure.fillWithBlocks(world, start, 56, -44, -22, 58, -44, -20, Blocks.AIR.getDefaultState());
        structure.fillWithBlocks(world, start, 56, -44, -12, 58, -44, -10, Blocks.AIR.getDefaultState());
        structure.fillWithBlocks(world, start, 56, -44, -9, 56, -40, -9, Blocks.STONE_BRICKS.getDefaultState());
        structure.fillWithBlocks(world, start, 56, -44, 14, 56, -43, 14, Blocks.STONE_BRICKS.getDefaultState());
        structure.fillWithBlocks(world, start, 56, -44, 15, 56, -44, 15, Blocks.MOSSY_STONE_BRICKS.getDefaultState());
        structure.fillWithBlocks(world, start, 56, -44, 16, 56, -44, 17, Blocks.STONE_BRICKS.getDefaultState());
        structure.fillWithBlocks(world, start, 56, -44, 18, 57, -44, 18, Blocks.MOSSY_STONE_BRICKS.getDefaultState());
        structure.fillWithBlocks(world, start, 56, -44, 19, 56, -42, 19, Blocks.STONE_BRICKS.getDefaultState());
        structure.fillWithBlocks(world, start, 56, -44, 21, 56, -44, 22, Blocks.STONE_BRICKS.getDefaultState());
        structure.fillWithBlocks(world, start, 56, -44, 24, 56, -44, 28, Blocks.AIR.getDefaultState());
        structure.fillWithBlocks(world, start, 56, -44, 29, 56, -44, 30, Blocks.STONE_BRICKS.getDefaultState());
        structure.fillWithBlocks(world, start, 56, -44, 31, 56, -43, 31, Blocks.MOSSY_STONE_BRICKS.getDefaultState());
        structure.fillWithBlocks(world, start, 56, -44, 32, 56, -44, 33, Blocks.STONE_BRICKS.getDefaultState());
        structure.fillWithBlocks(world, start, 56, -44, 34, 56, -44, 34, Blocks.MOSSY_STONE_BRICKS.getDefaultState());
        structure.fillWithBlocks(world, start, 56, -44, 37, 56, -43, 37, Blocks.STONE_BRICKS.getDefaultState());
        structure.fillWithBlocks(world, start, 56, -44, 41, 58, -44, 55, Blocks.AIR.getDefaultState());
        structure.fillWithBlocks(world, start, 56, -44, 56, 60, -44, 56, Blocks.STONE_BRICKS.getDefaultState());
        structure.fillWithBlocks(world, start, 56, -43, -24, 56, -43, -23, Blocks.STONE_BRICKS.getDefaultState());
        structure.fillWithBlocks(world, start, 56, -43, -22, 58, -43, -20, Blocks.AIR.getDefaultState());
        structure.fillWithBlocks(world, start, 56, -43, -13, 56, -42, -13, Blocks.MOSSY_COBBLESTONE.getDefaultState());
        structure.fillWithBlocks(world, start, 56, -43, -12, 58, -43, -10, Blocks.AIR.getDefaultState());
        structure.fillWithBlocks(world, start, 56, -43, 20, 57, -43, 21, Blocks.STONE_BRICKS.getDefaultState());
        structure.fillWithBlocks(world, start, 56, -43, 23, 56, -43, 23, Blocks.STONE_BRICKS.getDefaultState());
        structure.fillWithBlocks(world, start, 56, -43, 24, 56, -43, 28, Blocks.AIR.getDefaultState());
        structure.fillWithBlocks(world, start, 56, -43, 29, 56, -37, 29, Blocks.STONE_BRICKS.getDefaultState());
        structure.fillWithBlocks(world, start, 56, -43, 30, 56, -43, 32, Blocks.MOSSY_STONE_BRICKS.getDefaultState());
        structure.fillWithBlocks(world, start, 56, -43, 33, 56, -42, 34, Blocks.STONE_BRICKS.getDefaultState());
        structure.fillWithBlocks(world, start, 56, -43, 36, 56, -43, 37, Blocks.STONE_BRICKS.getDefaultState());
        structure.fillWithBlocks(world, start, 56, -43, 40, 57, -43, 40, Blocks.MOSSY_STONE_BRICKS.getDefaultState());
        structure.fillWithBlocks(world, start, 56, -43, 41, 58, -43, 55, Blocks.AIR.getDefaultState());
        structure.fillWithBlocks(world, start, 56, -42, -24, 56, -42, -24, Blocks.AIR.getDefaultState());
        structure.fillWithBlocks(world, start, 56, -42, -22, 58, -42, -20, Blocks.AIR.getDefaultState());
        structure.fillWithBlocks(world, start, 56, -42, -18, 60, -42, -14, Blocks.AIR.getDefaultState());
        structure.fillWithBlocks(world, start, 56, -42, -12, 58, -42, -10, Blocks.AIR.getDefaultState());
        structure.fillWithBlocks(world, start, 56, -42, -8, 57, -42, -8, Blocks.MOSSY_STONE_BRICKS.getDefaultState());
        structure.fillWithBlocks(world, start, 56, -42, 16, 56, -42, 16, Blocks.STONE_BRICKS.getDefaultState());
        structure.fillWithBlocks(world, start, 56, -42, 17, 56, -41, 17, Blocks.MOSSY_STONE_BRICKS.getDefaultState());
        structure.fillWithBlocks(world, start, 56, -42, 18, 56, -42, 20, Blocks.STONE_BRICKS.getDefaultState());
        structure.fillWithBlocks(world, start, 56, -42, 23, 56, -42, 23, Blocks.STONE_BRICKS.getDefaultState());
        structure.fillWithBlocks(world, start, 56, -42, 24, 56, -42, 28, Blocks.AIR.getDefaultState());
        structure.fillWithBlocks(world, start, 56, -42, 30, 56, -41, 30, Blocks.STONE_BRICKS.getDefaultState());
        structure.fillWithBlocks(world, start, 56, -42, 32, 57, -42, 34, Blocks.STONE_BRICKS.getDefaultState());
        structure.fillWithBlocks(world, start, 56, -42, 35, 57, -41, 35, Blocks.MOSSY_STONE_BRICKS.getDefaultState());
        structure.fillWithBlocks(world, start, 56, -42, 36, 56, -42, 36, Blocks.STONE_BRICKS.getDefaultState());
        structure.fillWithBlocks(world, start, 56, -42, 38, 59, -42, 38, Blocks.STONE_BRICKS.getDefaultState());
        structure.fillWithBlocks(world, start, 56, -42, 41, 58, -42, 55, Blocks.AIR.getDefaultState());
        structure.fillWithBlocks(world, start, 56, -41, -24, 57, -41, -23, Blocks.STONE_BRICKS.getDefaultState());
        structure.fillWithBlocks(world, start, 56, -41, -21, 56, -39, -21, Blocks.MOSSY_STONE_BRICKS.getDefaultState());
        structure.fillWithBlocks(world, start, 56, -41, -20, 56, -41, -18, Blocks.STONE_BRICKS.getDefaultState());
        structure.fillWithBlocks(world, start, 56, -41, -17, 56, -40, -17, Blocks.MOSSY_COBBLESTONE.getDefaultState());
        structure.fillWithBlocks(world, start, 56, -41, -16, 56, -41, -14, Blocks.MOSSY_STONE_BRICKS.getDefaultState());
        structure.fillWithBlocks(world, start, 56, -41, -13, 56, -41, -9, Blocks.STONE_BRICKS.getDefaultState());
        structure.fillWithBlocks(world, start, 56, -41, 18, 56, -41, 19, Blocks.MOSSY_STONE_BRICKS.getDefaultState());
        structure.fillWithBlocks(world, start, 56, -41, 20, 56, -41, 22, Blocks.STONE_BRICKS.getDefaultState());
        structure.fillWithBlocks(world, start, 56, -41, 24, 57, -40, 24, Blocks.STONE_BRICKS.getDefaultState());
        structure.fillWithBlocks(world, start, 56, -41, 26, 56, -41, 26, Blocks.STONE_BRICKS.getDefaultState());
        structure.fillWithBlocks(world, start, 56, -41, 28, 56, -40, 29, Blocks.STONE_BRICKS.getDefaultState());
        structure.fillWithBlocks(world, start, 56, -41, 32, 56, -37, 32, Blocks.STONE_BRICKS.getDefaultState());
        structure.fillWithBlocks(world, start, 56, -41, 33, 56, -41, 34, Blocks.AIR.getDefaultState());
        structure.fillWithBlocks(world, start, 56, -41, 36, 56, -41, 36, Blocks.STONE_BRICKS.getDefaultState());
        structure.fillWithBlocks(world, start, 56, -41, 37, 56, -41, 37, Blocks.MOSSY_STONE_BRICKS.getDefaultState());
        structure.fillWithBlocks(world, start, 56, -41, 38, 56, -40, 38, Blocks.STONE_BRICKS.getDefaultState());
        structure.fillWithBlocks(world, start, 56, -41, 42, 58, -41, 44, Blocks.AIR.getDefaultState());
        structure.fillWithBlocks(world, start, 56, -41, 45, 58, -41, 45, Blocks.STONE_BRICKS.getDefaultState());
        structure.fillWithBlocks(world, start, 56, -41, 46, 58, -41, 50, Blocks.AIR.getDefaultState());
        structure.fillWithBlocks(world, start, 56, -41, 52, 58, -41, 54, Blocks.AIR.getDefaultState());
        structure.fillWithBlocks(world, start, 56, -41, 55, 57, -41, 56, Blocks.STONE_BRICKS.getDefaultState());
        structure.fillWithBlocks(world, start, 56, -40, -24, 56, -40, -23, Blocks.STONE_BRICKS.getDefaultState());
        structure.fillWithBlocks(world, start, 56, -40, -20, 56, -40, -18, Blocks.STONE_BRICKS.getDefaultState());
        structure.fillWithBlocks(world, start, 56, -40, -15, 56, -40, -15, Blocks.STONE_BRICKS.getDefaultState());
        structure.fillWithBlocks(world, start, 56, -40, -13, 57, -40, -13, Blocks.STONE_BRICKS.getDefaultState());
        structure.fillWithBlocks(world, start, 56, -40, -11, 57, -40, -10, Blocks.STONE_BRICKS.getDefaultState());
        structure.fillWithBlocks(world, start, 56, -40, 14, 56, -39, 15, Blocks.STONE_BRICKS.getDefaultState());
        structure.fillWithBlocks(world, start, 56, -40, 18, 56, -40, 19, Blocks.STONE_BRICKS.getDefaultState());
        structure.fillWithBlocks(world, start, 56, -40, 20, 56, -40, 21, Blocks.MOSSY_STONE_BRICKS.getDefaultState());
        structure.fillWithBlocks(world, start, 56, -40, 27, 57, -40, 29, Blocks.STONE_BRICKS.getDefaultState());
        structure.fillWithBlocks(world, start, 56, -40, 34, 56, -40, 35, Blocks.STONE_BRICKS.getDefaultState());
        structure.fillWithBlocks(world, start, 56, -40, 36, 56, -39, 36, Blocks.MOSSY_STONE_BRICKS.getDefaultState());
        structure.fillWithBlocks(world, start, 56, -40, 37, 57, -40, 38, Blocks.STONE_BRICKS.getDefaultState());
        structure.fillWithBlocks(world, start, 56, -40, 42, 57, -40, 42, Blocks.MOSSY_STONE_BRICKS.getDefaultState());
        structure.fillWithBlocks(world, start, 56, -40, 43, 56, -38, 43, Blocks.STONE_BRICKS.getDefaultState());
        structure.fillWithBlocks(world, start, 56, -40, 44, 56, -37, 44, Blocks.MOSSY_STONE_BRICKS.getDefaultState());
        structure.fillWithBlocks(world, start, 56, -40, 45, 56, -40, 48, Blocks.STONE_BRICKS.getDefaultState());
        structure.fillWithBlocks(world, start, 56, -40, 49, 57, -40, 50, Blocks.MOSSY_STONE_BRICKS.getDefaultState());
        structure.fillWithBlocks(world, start, 56, -40, 56, 57, -39, 56, Blocks.STONE_BRICKS.getDefaultState());
        structure.fillWithBlocks(world, start, 56, -39, -23, 56, -38, -22, Blocks.MOSSY_STONE_BRICKS.getDefaultState());
        structure.fillWithBlocks(world, start, 56, -39, -19, 57, -39, -19, Blocks.MOSSY_STONE_BRICKS.getDefaultState());
        structure.fillWithBlocks(world, start, 56, -39, -18, 56, -39, -17, Blocks.STONE_BRICKS.getDefaultState());
        structure.fillWithBlocks(world, start, 56, -39, -15, 56, -38, -14, Blocks.STONE_BRICKS.getDefaultState());
        structure.fillWithBlocks(world, start, 56, -39, -9, 56, -39, -8, Blocks.AIR.getDefaultState());
        structure.fillWithBlocks(world, start, 56, -39, 16, 59, -39, 16, Blocks.STONE_BRICKS.getDefaultState());
        structure.fillWithBlocks(world, start, 56, -39, 18, 56, -37, 18, Blocks.STONE_BRICKS.getDefaultState());
        structure.fillWithBlocks(world, start, 56, -39, 24, 56, -39, 24, Blocks.STONE_BRICKS.getDefaultState());
        structure.fillWithBlocks(world, start, 56, -39, 25, 56, -38, 25, Blocks.MOSSY_COBBLESTONE.getDefaultState());
        structure.fillWithBlocks(world, start, 56, -39, 28, 56, -39, 34, Blocks.STONE_BRICKS.getDefaultState());
        structure.fillWithBlocks(world, start, 56, -39, 37, 56, -39, 37, Blocks.STONE_BRICKS.getDefaultState());
        structure.fillWithBlocks(world, start, 56, -39, 40, 56, -39, 41, Blocks.STONE_BRICKS.getDefaultState());
        structure.fillWithBlocks(world, start, 56, -39, 48, 56, -39, 49, Blocks.STONE_BRICKS.getDefaultState());
        structure.fillWithBlocks(world, start, 56, -39, 51, 56, -39, 51, Blocks.MOSSY_COBBLESTONE.getDefaultState());
        structure.fillWithBlocks(world, start, 56, -39, 52, 56, -39, 53, Blocks.STONE_BRICKS.getDefaultState());
        structure.fillWithBlocks(world, start, 56, -39, 55, 57, -39, 56, Blocks.STONE_BRICKS.getDefaultState());
        structure.fillWithBlocks(world, start, 56, -38, -24, 56, -38, -22, Blocks.MOSSY_STONE_BRICKS.getDefaultState());
        structure.fillWithBlocks(world, start, 56, -38, -21, 56, -38, -20, Blocks.STONE_BRICKS.getDefaultState());
        structure.fillWithBlocks(world, start, 56, -38, -18, 57, -37, -18, Blocks.STONE_BRICKS.getDefaultState());
