package mod.arcalitegames.odyssey.world.structure.structures.dungeons.highguard_castle;

import mod.arcalitegames.odyssey.world.structure.StructureBase;
import net.minecraft.block.Blocks;
import net.minecraft.block.DirectionalBlock;
import net.minecraft.block.FenceGateBlock;
import net.minecraft.block.FourWayBlock;
import net.minecraft.block.HorizontalBlock;
import net.minecraft.block.LeavesBlock;
import net.minecraft.block.PistonBlock;
import net.minecraft.block.RedstoneTorchBlock;
import net.minecraft.block.RedstoneWireBlock;
import net.minecraft.block.SnowyDirtBlock;
import net.minecraft.block.StairsBlock;
import net.minecraft.block.TrapDoorBlock;
import net.minecraft.block.WallBlock;
import net.minecraft.block.WallHeight;
import net.minecraft.state.properties.Half;
import net.minecraft.state.properties.RedstoneSide;
import net.minecraft.state.properties.StairsShape;
import net.minecraft.util.Direction;
import net.minecraft.util.math.BlockPos;
import net.minecraft.world.World;

public class HighguardComponent2
{
	public static BlockPos start;
    public static World world;
    public static StructureBase structure;

    public static void init(World worldIn, BlockPos blockPos, StructureBase structureIn)
    {
        world = worldIn; start = blockPos; structure = structureIn;
    }
    
    public static void generatePart21()
    {
        structure.setBlockState(world, Blocks.MOSSY_STONE_BRICKS.getDefaultState(), 48, -40, 37, start);
        structure.setBlockState(world, Blocks.AIR.getDefaultState(), 48, -40, 38, start);
        structure.setBlockState(world, Blocks.MOSSY_STONE_BRICKS.getDefaultState(), 48, -40, 49, start);
        structure.setBlockState(world, Blocks.MOSSY_STONE_BRICKS.getDefaultState(), 48, -39, 4, start);
        structure.setBlockState(world, Blocks.AIR.getDefaultState(), 48, -39, 8, start);
        structure.setBlockState(world, Blocks.MOSSY_STONE_BRICKS.getDefaultState(), 48, -39, 19, start);
        structure.setBlockState(world, Blocks.MOSSY_COBBLESTONE.getDefaultState(), 48, -39, 20, start);
        structure.setBlockState(world, Blocks.MOSSY_STONE_BRICKS.getDefaultState(), 48, -39, 28, start);
        structure.setBlockState(world, Blocks.MOSSY_STONE_BRICKS.getDefaultState(), 48, -39, 32, start);
        structure.setBlockState(world, Blocks.AIR.getDefaultState(), 48, -39, 51, start);
        structure.setBlockState(world, Blocks.INFESTED_COBBLESTONE.getDefaultState(), 48, -39, 53, start);
        structure.setBlockState(world, Blocks.MOSSY_COBBLESTONE.getDefaultState(), 48, -39, 55, start);
        structure.setBlockState(world, Blocks.MOSSY_COBBLESTONE.getDefaultState(), 48, -39, 60, start);
        structure.setBlockState(world, Blocks.AIR.getDefaultState(), 48, -38, 11, start);
        structure.setBlockState(world, Blocks.AIR.getDefaultState(), 48, -38, 20, start);
        structure.setBlockState(world, Blocks.AIR.getDefaultState(), 48, -38, 27, start);
        structure.setBlockState(world, Blocks.AIR.getDefaultState(), 48, -38, 37, start);
        structure.setBlockState(world, Blocks.AIR.getDefaultState(), 48, -38, 50, start);
        structure.setBlockState(world, Blocks.AIR.getDefaultState(), 48, -38, 56, start);
        structure.setBlockState(world, Blocks.MOSSY_COBBLESTONE.getDefaultState(), 48, -38, 61, start);
        structure.setBlockState(world, Blocks.STONE_BRICKS.getDefaultState(), 48, -38, 63, start);
        structure.setBlockState(world, Blocks.MOSSY_COBBLESTONE.getDefaultState(), 48, -37, 7, start);
        structure.setBlockState(world, Blocks.INFESTED_CRACKED_STONE_BRICKS.getDefaultState(), 48, -37, 10, start);
        structure.setBlockState(world, Blocks.MOSSY_COBBLESTONE.getDefaultState(), 48, -37, 22, start);
        structure.setBlockState(world, Blocks.MOSSY_COBBLESTONE.getDefaultState(), 48, -37, 25, start);
        structure.setBlockState(world, Blocks.MOSSY_COBBLESTONE.getDefaultState(), 48, -37, 30, start);
        structure.setBlockState(world, Blocks.INFESTED_COBBLESTONE.getDefaultState(), 48, -37, 32, start);
        structure.setBlockState(world, Blocks.MOSSY_STONE_BRICKS.getDefaultState(), 48, -37, 36, start);
        structure.setBlockState(world, Blocks.MOSSY_COBBLESTONE.getDefaultState(), 48, -37, 49, start);
        structure.setBlockState(world, Blocks.CRACKED_STONE_BRICKS.getDefaultState(), 48, -23, 42, start);
        structure.setBlockState(world, Blocks.MOSSY_STONE_BRICKS.getDefaultState(), 48, -16, 30, start);
        structure.setBlockState(world, Blocks.MOSSY_STONE_BRICKS.getDefaultState(), 48, -16, 32, start);
        structure.setBlockState(world, Blocks.CRACKED_STONE_BRICKS.getDefaultState(), 48, -16, 33, start);
        structure.setBlockState(world, Blocks.MOSSY_STONE_BRICKS.getDefaultState(), 48, -16, 55, start);
        structure.setBlockState(world, Blocks.SHROOMLIGHT.getDefaultState(), 48, -14, 34, start);
        structure.setBlockState(world, Blocks.MOSSY_STONE_BRICKS.getDefaultState(), 48, -14, 50, start);
        structure.setBlockState(world, Blocks.SHROOMLIGHT.getDefaultState(), 48, -14, 54, start);
        structure.setBlockState(world, Blocks.CRACKED_STONE_BRICKS.getDefaultState(), 48, -13, 50, start);
        structure.setBlockState(world, Blocks.MOSSY_STONE_BRICKS.getDefaultState(), 48, -13, 52, start);
        structure.setBlockState(world, Blocks.MOSSY_STONE_BRICKS.getDefaultState(), 48, -12, 44, start);
        structure.setBlockState(world, Blocks.CRACKED_STONE_BRICKS.getDefaultState(), 48, -11, 32, start);
        structure.setBlockState(world, Blocks.DIRT.getDefaultState(), 48, 2, 43, start);
        structure.setBlockState(world, Blocks.GRASS_BLOCK.getDefaultState().with(SnowyDirtBlock.SNOWY, false), 48, 2, 47, start);
        structure.setBlockState(world, Blocks.GRASS_BLOCK.getDefaultState().with(SnowyDirtBlock.SNOWY, false), 48, 2, 72, start);
        structure.setBlockState(world, Blocks.DIRT.getDefaultState(), 48, 3, 42, start);
        structure.setBlockState(world, Blocks.GRASS_BLOCK.getDefaultState().with(SnowyDirtBlock.SNOWY, false), 48, 3, 43, start);
        structure.setBlockState(world, Blocks.DIRT.getDefaultState(), 48, 3, 46, start);
        structure.setBlockState(world, Blocks.OAK_LEAVES.getDefaultState().with(LeavesBlock.PERSISTENT, false).with(LeavesBlock.DISTANCE, 2), 48, 3, 47, start);
        structure.setBlockState(world, Blocks.GRASS_BLOCK.getDefaultState().with(SnowyDirtBlock.SNOWY, false), 48, 4, 15, start);
        structure.setBlockState(world, Blocks.OAK_LEAVES.getDefaultState().with(LeavesBlock.PERSISTENT, false).with(LeavesBlock.DISTANCE, 6), 48, 4, 52, start);
        structure.setBlockState(world, Blocks.OAK_LEAVES.getDefaultState().with(LeavesBlock.PERSISTENT, false).with(LeavesBlock.DISTANCE, 5), 48, 4, 53, start);
        structure.setBlockState(world, Blocks.GRASS_BLOCK.getDefaultState().with(SnowyDirtBlock.SNOWY, false), 48, 4, 69, start);
        structure.setBlockState(world, Blocks.GRASS_BLOCK.getDefaultState().with(SnowyDirtBlock.SNOWY, false), 48, 4, 73, start);
        structure.setBlockState(world, Blocks.OAK_PLANKS.getDefaultState(), 48, 7, 30, start);
        structure.setBlockState(world, Blocks.OAK_LEAVES.getDefaultState().with(LeavesBlock.PERSISTENT, false).with(LeavesBlock.DISTANCE, 2), 48, 7, 41, start);
        structure.setBlockState(world, Blocks.OAK_PLANKS.getDefaultState(), 48, 7, 58, start);
        structure.setBlockState(world, Blocks.OAK_FENCE.getDefaultState().with(FourWayBlock.WATERLOGGED, false).with(FourWayBlock.NORTH, true).with(FourWayBlock.SOUTH, false).with(FourWayBlock.EAST, true).with(FourWayBlock.WEST, true), 48, 8, 30, start);
        structure.setBlockState(world, Blocks.OAK_LEAVES.getDefaultState().with(LeavesBlock.PERSISTENT, false).with(LeavesBlock.DISTANCE, 1), 48, 8, 56, start);
        structure.setBlockState(world, Blocks.OAK_FENCE.getDefaultState().with(FourWayBlock.WATERLOGGED, false).with(FourWayBlock.NORTH, false).with(FourWayBlock.SOUTH, true).with(FourWayBlock.EAST, true).with(FourWayBlock.WEST, true), 48, 8, 58, start);
        structure.setBlockState(world, Blocks.OAK_LEAVES.getDefaultState().with(LeavesBlock.PERSISTENT, false).with(LeavesBlock.DISTANCE, 2), 48, 9, 56, start);
        structure.setBlockState(world, Blocks.STONE_BRICKS.getDefaultState(), 48, 9, 58, start);
        structure.setBlockState(world, Blocks.OAK_LEAVES.getDefaultState().with(LeavesBlock.PERSISTENT, false).with(LeavesBlock.DISTANCE, 3), 48, 10, 56, start);
        structure.setBlockState(world, Blocks.STONE_BRICKS.getDefaultState(), 48, 11, 46, start);
        structure.setBlockState(world, Blocks.OAK_LEAVES.getDefaultState().with(LeavesBlock.PERSISTENT, false).with(LeavesBlock.DISTANCE, 3), 48, 18, 34, start);
        structure.setBlockState(world, Blocks.OAK_LEAVES.getDefaultState().with(LeavesBlock.PERSISTENT, false).with(LeavesBlock.DISTANCE, 1), 48, 18, 38, start);
        structure.setBlockState(world, Blocks.OAK_LEAVES.getDefaultState().with(LeavesBlock.PERSISTENT, false).with(LeavesBlock.DISTANCE, 2), 48, 18, 39, start);
        structure.setBlockState(world, Blocks.STONE_BRICKS.getDefaultState(), 48, 19, 26, start);
        structure.setBlockState(world, Blocks.OAK_FENCE.getDefaultState().with(FourWayBlock.WATERLOGGED, false).with(FourWayBlock.NORTH, true).with(FourWayBlock.SOUTH, false).with(FourWayBlock.EAST, true).with(FourWayBlock.WEST, true), 48, 19, 27, start);
        structure.setBlockState(world, Blocks.OAK_LEAVES.getDefaultState().with(LeavesBlock.PERSISTENT, false).with(LeavesBlock.DISTANCE, 3), 48, 23, 32, start);
        structure.setBlockState(world, Blocks.OAK_LEAVES.getDefaultState().with(LeavesBlock.PERSISTENT, false).with(LeavesBlock.DISTANCE, 2), 48, 24, 32, start);
        structure.setBlockState(world, Blocks.OAK_LEAVES.getDefaultState().with(LeavesBlock.PERSISTENT, false).with(LeavesBlock.DISTANCE, 1), 48, 25, 32, start);
        structure.setBlockState(world, Blocks.OAK_LEAVES.getDefaultState().with(LeavesBlock.PERSISTENT, false).with(LeavesBlock.DISTANCE, 2), 48, 25, 33, start);
        structure.setBlockState(world, Blocks.OAK_LEAVES.getDefaultState().with(LeavesBlock.PERSISTENT, false).with(LeavesBlock.DISTANCE, 2), 48, 26, 32, start);
        structure.setBlockState(world, Blocks.OAK_LEAVES.getDefaultState().with(LeavesBlock.PERSISTENT, false).with(LeavesBlock.DISTANCE, 3), 48, 26, 33, start);
        structure.setBlockState(world, Blocks.OAK_LEAVES.getDefaultState().with(LeavesBlock.PERSISTENT, false).with(LeavesBlock.DISTANCE, 4), 48, 27, 33, start);
        structure.setBlockState(world, Blocks.AIR.getDefaultState(), 49, -57, 48, start);
        structure.setBlockState(world, Blocks.AIR.getDefaultState(), 49, -50, -58, start);
        structure.setBlockState(world, Blocks.AIR.getDefaultState(), 49, -50, -40, start);
        structure.setBlockState(world, Blocks.AIR.getDefaultState(), 49, -49, 50, start);
        structure.setBlockState(world, Blocks.AIR.getDefaultState(), 49, -49, 77, start);
        structure.setBlockState(world, Blocks.AIR.getDefaultState(), 49, -48, 45, start);
        structure.setBlockState(world, Blocks.MOSSY_STONE_BRICKS.getDefaultState(), 49, -48, 56, start);
        structure.setBlockState(world, Blocks.AIR.getDefaultState(), 49, -48, 74, start);
        structure.setBlockState(world, Blocks.AIR.getDefaultState(), 49, -47, -16, start);
        structure.setBlockState(world, Blocks.MOSSY_STONE_BRICKS.getDefaultState(), 49, -46, 5, start);
        structure.setBlockState(world, Blocks.MOSSY_STONE_BRICKS.getDefaultState(), 49, -46, 17, start);
        structure.setBlockState(world, Blocks.STONE_BRICKS.getDefaultState(), 49, -46, 18, start);
        structure.setBlockState(world, Blocks.STONE_BRICKS.getDefaultState(), 49, -46, 22, start);
        structure.setBlockState(world, Blocks.STONE_BRICKS.getDefaultState(), 49, -46, 32, start);
        structure.setBlockState(world, Blocks.MOSSY_STONE_BRICKS.getDefaultState(), 49, -46, 33, start);
        structure.setBlockState(world, Blocks.INFESTED_CRACKED_STONE_BRICKS.getDefaultState(), 49, -46, 39, start);
        structure.setBlockState(world, Blocks.MOSSY_COBBLESTONE.getDefaultState(), 49, -46, 43, start);
        structure.setBlockState(world, Blocks.MOSSY_COBBLESTONE.getDefaultState(), 49, -46, 52, start);
        structure.setBlockState(world, Blocks.MOSSY_COBBLESTONE.getDefaultState(), 49, -45, -13, start);
        structure.setBlockState(world, Blocks.MOSSY_STONE_BRICKS.getDefaultState(), 49, -45, 15, start);
        structure.setBlockState(world, Blocks.MOSSY_COBBLESTONE.getDefaultState(), 49, -45, 42, start);
        structure.setBlockState(world, Blocks.MOSSY_STONE_BRICKS.getDefaultState(), 49, -45, 52, start);
        structure.setBlockState(world, Blocks.MOSSY_STONE_BRICKS.getDefaultState(), 49, -44, 40, start);
        structure.setBlockState(world, Blocks.MOSSY_STONE_BRICKS.getDefaultState(), 49, -44, 45, start);
        structure.setBlockState(world, Blocks.MOSSY_COBBLESTONE.getDefaultState(), 49, -44, 60, start);
        structure.setBlockState(world, Blocks.MOSSY_STONE_BRICKS.getDefaultState(), 49, -43, 52, start);
        structure.setBlockState(world, Blocks.INFESTED_STONE_BRICKS.getDefaultState(), 49, -43, 61, start);
        structure.setBlockState(world, Blocks.MOSSY_COBBLESTONE.getDefaultState(), 49, -42, -14, start);
        structure.setBlockState(world, Blocks.AIR.getDefaultState(), 49, -42, 15, start);
        structure.setBlockState(world, Blocks.MOSSY_COBBLESTONE.getDefaultState(), 49, -42, 16, start);
        structure.setBlockState(world, Blocks.MOSSY_STONE_BRICKS.getDefaultState(), 49, -42, 44, start);
        structure.setBlockState(world, Blocks.MOSSY_STONE_BRICKS.getDefaultState(), 49, -42, 48, start);
        structure.setBlockState(world, Blocks.INFESTED_CRACKED_STONE_BRICKS.getDefaultState(), 49, -42, 49, start);
        structure.setBlockState(world, Blocks.MOSSY_STONE_BRICKS.getDefaultState(), 49, -42, 62, start);
        structure.setBlockState(world, Blocks.STONE_BRICK_STAIRS.getDefaultState().with(StairsBlock.FACING, Direction.NORTH).with(StairsBlock.WATERLOGGED, false).with(StairsBlock.SHAPE, StairsShape.INNER_RIGHT).with(StairsBlock.HALF, Half.TOP), 49, -41, 8, start);
        structure.setBlockState(world, Blocks.STONE_BRICK_STAIRS.getDefaultState().with(StairsBlock.FACING, Direction.SOUTH).with(StairsBlock.WATERLOGGED, false).with(StairsBlock.SHAPE, StairsShape.INNER_LEFT).with(StairsBlock.HALF, Half.TOP), 49, -41, 12, start);
        structure.setBlockState(world, Blocks.INFESTED_CRACKED_STONE_BRICKS.getDefaultState(), 49, -41, 36, start);
        structure.setBlockState(world, Blocks.MOSSY_STONE_BRICKS.getDefaultState(), 49, -41, 37, start);
        structure.setBlockState(world, Blocks.STONE_BRICKS.getDefaultState(), 49, -41, 49, start);
        structure.setBlockState(world, Blocks.AIR.getDefaultState(), 49, -41, 50, start);
        structure.setBlockState(world, Blocks.STONE_BRICKS.getDefaultState(), 49, -41, 62, start);
        structure.setBlockState(world, Blocks.MOSSY_COBBLESTONE.getDefaultState(), 49, -40, 23, start);
        structure.setBlockState(world, Blocks.MOSSY_STONE_BRICKS.getDefaultState(), 49, -40, 24, start);
        structure.setBlockState(world, Blocks.AIR.getDefaultState(), 49, -40, 49, start);
        structure.setBlockState(world, Blocks.INFESTED_COBBLESTONE.getDefaultState(), 49, -40, 51, start);
        structure.setBlockState(world, Blocks.MOSSY_COBBLESTONE.getDefaultState(), 49, -40, 54, start);
        structure.setBlockState(world, Blocks.MOSSY_COBBLESTONE.getDefaultState(), 49, -40, 56, start);
        structure.setBlockState(world, Blocks.AIR.getDefaultState(), 49, -39, 5, start);
        structure.setBlockState(world, Blocks.MOSSY_STONE_BRICKS.getDefaultState(), 49, -39, 6, start);
        structure.setBlockState(world, Blocks.MOSSY_COBBLESTONE.getDefaultState(), 49, -39, 13, start);
        structure.setBlockState(world, Blocks.MOSSY_COBBLESTONE.getDefaultState(), 49, -39, 19, start);
        structure.setBlockState(world, Blocks.AIR.getDefaultState(), 49, -39, 36, start);
        structure.setBlockState(world, Blocks.MOSSY_COBBLESTONE.getDefaultState(), 49, -39, 37, start);
        structure.setBlockState(world, Blocks.MOSSY_COBBLESTONE.getDefaultState(), 49, -39, 59, start);
        structure.setBlockState(world, Blocks.STONE_BRICKS.getDefaultState(), 49, -38, 5, start);
        structure.setBlockState(world, Blocks.MOSSY_COBBLESTONE.getDefaultState(), 49, -38, 6, start);
        structure.setBlockState(world, Blocks.AIR.getDefaultState(), 49, -38, 9, start);
        structure.setBlockState(world, Blocks.STONE_BRICKS.getDefaultState(), 49, -38, 11, start);
        structure.setBlockState(world, Blocks.MOSSY_STONE_BRICKS.getDefaultState(), 49, -38, 12, start);
        structure.setBlockState(world, Blocks.MOSSY_STONE_BRICKS.getDefaultState(), 49, -38, 36, start);
        structure.setBlockState(world, Blocks.MOSSY_COBBLESTONE.getDefaultState(), 49, -38, 38, start);
        structure.setBlockState(world, Blocks.INFESTED_COBBLESTONE.getDefaultState(), 49, -37, 13, start);
        structure.setBlockState(world, Blocks.MOSSY_STONE_BRICKS.getDefaultState(), 49, -37, 15, start);
        structure.setBlockState(world, Blocks.STONE_BRICKS.getDefaultState(), 49, -37, 25, start);
        structure.setBlockState(world, Blocks.STONE_BRICKS.getDefaultState(), 49, -37, 27, start);
        structure.setBlockState(world, Blocks.MOSSY_COBBLESTONE.getDefaultState(), 49, -37, 36, start);
        structure.setBlockState(world, Blocks.MOSSY_STONE_BRICKS.getDefaultState(), 49, -37, 51, start);
        structure.setBlockState(world, Blocks.INFESTED_CRACKED_STONE_BRICKS.getDefaultState(), 49, -37, 60, start);
        structure.setBlockState(world, Blocks.CRACKED_STONE_BRICKS.getDefaultState(), 49, -25, 47, start);
        structure.setBlockState(world, Blocks.MOSSY_STONE_BRICKS.getDefaultState(), 49, -25, 73, start);
        structure.setBlockState(world, Blocks.CRACKED_STONE_BRICKS.getDefaultState(), 49, -24, 41, start);
        structure.setBlockState(world, Blocks.STONE_BRICKS.getDefaultState(), 49, -24, 47, start);
        structure.setBlockState(world, Blocks.CRACKED_STONE_BRICKS.getDefaultState(), 49, -24, 73, start);
        structure.setBlockState(world, Blocks.CRACKED_STONE_BRICKS.getDefaultState(), 49, -23, 47, start);
        structure.setBlockState(world, Blocks.MOSSY_STONE_BRICKS.getDefaultState(), 49, -23, 73, start);
        structure.setBlockState(world, Blocks.CRACKED_STONE_BRICKS.getDefaultState(), 49, -23, 79, start);
        structure.setBlockState(world, Blocks.MOSSY_STONE_BRICKS.getDefaultState(), 49, -22, 44, start);
        structure.setBlockState(world, Blocks.STONE_BRICKS.getDefaultState(), 49, -22, 46, start);
        structure.setBlockState(world, Blocks.MOSSY_STONE_BRICKS.getDefaultState(), 49, -22, 74, start);
        structure.setBlockState(world, Blocks.MOSSY_STONE_BRICKS.getDefaultState(), 49, -22, 78, start);
        structure.setBlockState(world, Blocks.GRASS_BLOCK.getDefaultState().with(SnowyDirtBlock.SNOWY, false), 49, 1, 44, start);
        structure.setBlockState(world, Blocks.OAK_LEAVES.getDefaultState().with(LeavesBlock.PERSISTENT, false).with(LeavesBlock.DISTANCE, 5), 49, 2, 44, start);
        structure.setBlockState(world, Blocks.GRASS_BLOCK.getDefaultState().with(SnowyDirtBlock.SNOWY, false), 49, 2, 45, start);
        structure.setBlockState(world, Blocks.GRASS_BLOCK.getDefaultState().with(SnowyDirtBlock.SNOWY, false), 49, 3, 13, start);
        structure.setBlockState(world, Blocks.GRASS_BLOCK.getDefaultState().with(SnowyDirtBlock.SNOWY, false), 49, 3, 19, start);
        structure.setBlockState(world, Blocks.OAK_LEAVES.getDefaultState().with(LeavesBlock.PERSISTENT, false).with(LeavesBlock.DISTANCE, 4), 49, 3, 44, start);
        structure.setBlockState(world, Blocks.OAK_LEAVES.getDefaultState().with(LeavesBlock.PERSISTENT, false).with(LeavesBlock.DISTANCE, 3), 49, 3, 45, start);
        structure.setBlockState(world, Blocks.GRASS_BLOCK.getDefaultState().with(SnowyDirtBlock.SNOWY, false), 49, 3, 50, start);
        structure.setBlockState(world, Blocks.GRASS_BLOCK.getDefaultState().with(SnowyDirtBlock.SNOWY, false), 49, 3, 52, start);
        structure.setBlockState(world, Blocks.GRASS_BLOCK.getDefaultState().with(SnowyDirtBlock.SNOWY, false), 49, 4, 20, start);
        structure.setBlockState(world, Blocks.GRASS_BLOCK.getDefaultState().with(SnowyDirtBlock.SNOWY, false), 49, 4, 36, start);
        structure.setBlockState(world, Blocks.OAK_LEAVES.getDefaultState().with(LeavesBlock.PERSISTENT, false).with(LeavesBlock.DISTANCE, 3), 49, 4, 44, start);
        structure.setBlockState(world, Blocks.GRASS_BLOCK.getDefaultState().with(SnowyDirtBlock.SNOWY, false), 49, 4, 55, start);
        structure.setBlockState(world, Blocks.STONE_BRICKS.getDefaultState(), 49, 5, 44, start);
        structure.setBlockState(world, Blocks.OAK_PLANKS.getDefaultState(), 49, 6, 30, start);
        structure.setBlockState(world, Blocks.OAK_LEAVES.getDefaultState().with(LeavesBlock.PERSISTENT, false).with(LeavesBlock.DISTANCE, 1), 49, 6, 46, start);
        structure.setBlockState(world, Blocks.OAK_LEAVES.getDefaultState().with(LeavesBlock.PERSISTENT, false).with(LeavesBlock.DISTANCE, 2), 49, 6, 47, start);
        structure.setBlockState(world, Blocks.OAK_PLANKS.getDefaultState(), 49, 6, 58, start);
        structure.setBlockState(world, Blocks.OAK_FENCE.getDefaultState().with(FourWayBlock.WATERLOGGED, false).with(FourWayBlock.NORTH, true).with(FourWayBlock.SOUTH, false).with(FourWayBlock.EAST, true).with(FourWayBlock.WEST, true), 49, 7, 30, start);
        structure.setBlockState(world, Blocks.OAK_LEAVES.getDefaultState().with(LeavesBlock.PERSISTENT, false).with(LeavesBlock.DISTANCE, 2), 49, 7, 36, start);
        structure.setBlockState(world, Blocks.OAK_LEAVES.getDefaultState().with(LeavesBlock.PERSISTENT, false).with(LeavesBlock.DISTANCE, 3), 49, 7, 41, start);
        structure.setBlockState(world, Blocks.OAK_LEAVES.getDefaultState().with(LeavesBlock.PERSISTENT, false).with(LeavesBlock.DISTANCE, 5), 49, 7, 54, start);
        structure.setBlockState(world, Blocks.OAK_FENCE.getDefaultState().with(FourWayBlock.WATERLOGGED, false).with(FourWayBlock.NORTH, false).with(FourWayBlock.SOUTH, true).with(FourWayBlock.EAST, true).with(FourWayBlock.WEST, true), 49, 7, 58, start);
        structure.setBlockState(world, Blocks.STONE_BRICKS.getDefaultState(), 49, 8, 15, start);
        structure.setBlockState(world, Blocks.OAK_LEAVES.getDefaultState().with(LeavesBlock.PERSISTENT, false).with(LeavesBlock.DISTANCE, 6), 49, 8, 54, start);
        structure.setBlockState(world, Blocks.OAK_LEAVES.getDefaultState().with(LeavesBlock.PERSISTENT, false).with(LeavesBlock.DISTANCE, 2), 49, 8, 56, start);
        structure.setBlockState(world, Blocks.OAK_LEAVES.getDefaultState().with(LeavesBlock.PERSISTENT, false).with(LeavesBlock.DISTANCE, 3), 49, 9, 56, start);
        structure.setBlockState(world, Blocks.STONE_BRICKS.getDefaultState(), 49, 9, 71, start);
        structure.setBlockState(world, Blocks.OAK_LEAVES.getDefaultState().with(LeavesBlock.PERSISTENT, false).with(LeavesBlock.DISTANCE, 4), 49, 10, 56, start);
        structure.setBlockState(world, Blocks.STONE_BRICKS.getDefaultState(), 49, 15, 34, start);
        structure.setBlockState(world, Blocks.OAK_LEAVES.getDefaultState().with(LeavesBlock.PERSISTENT, false).with(LeavesBlock.DISTANCE, 2), 49, 18, 38, start);
        structure.setBlockState(world, Blocks.OAK_LEAVES.getDefaultState().with(LeavesBlock.PERSISTENT, false).with(LeavesBlock.DISTANCE, 3), 49, 18, 39, start);
        structure.setBlockState(world, Blocks.OAK_LEAVES.getDefaultState().with(LeavesBlock.PERSISTENT, false).with(LeavesBlock.DISTANCE, 4), 49, 18, 40, start);
        structure.setBlockState(world, Blocks.OAK_FENCE.getDefaultState().with(FourWayBlock.WATERLOGGED, false).with(FourWayBlock.NORTH, false).with(FourWayBlock.SOUTH, false).with(FourWayBlock.EAST, true).with(FourWayBlock.WEST, true), 49, 19, 27, start);
        structure.setBlockState(world, Blocks.OAK_LEAVES.getDefaultState().with(LeavesBlock.PERSISTENT, false).with(LeavesBlock.DISTANCE, 4), 49, 23, 32, start);
        structure.setBlockState(world, Blocks.OAK_LEAVES.getDefaultState().with(LeavesBlock.PERSISTENT, false).with(LeavesBlock.DISTANCE, 3), 49, 24, 32, start);
        structure.setBlockState(world, Blocks.OAK_FENCE.getDefaultState().with(FourWayBlock.WATERLOGGED, false).with(FourWayBlock.NORTH, false).with(FourWayBlock.SOUTH, false).with(FourWayBlock.EAST, true).with(FourWayBlock.WEST, false), 49, 24, 33, start);
        structure.setBlockState(world, Blocks.OAK_LEAVES.getDefaultState().with(LeavesBlock.PERSISTENT, false).with(LeavesBlock.DISTANCE, 2), 49, 25, 32, start);
        structure.setBlockState(world, Blocks.OAK_LEAVES.getDefaultState().with(LeavesBlock.PERSISTENT, false).with(LeavesBlock.DISTANCE, 3), 49, 26, 32, start);
        structure.setBlockState(world, Blocks.OAK_LEAVES.getDefaultState().with(LeavesBlock.PERSISTENT, false).with(LeavesBlock.DISTANCE, 5), 49, 26, 34, start);
        structure.setBlockState(world, Blocks.STONE_BRICKS.getDefaultState(), 49, 27, 72, start);
        structure.setBlockState(world, Blocks.STICKY_PISTON.getDefaultState().with(DirectionalBlock.FACING, Direction.NORTH).with(PistonBlock.EXTENDED, false), 49, 28, 37, start);
        structure.setBlockState(world, Blocks.GLASS_PANE.getDefaultState().with(FourWayBlock.WATERLOGGED, false).with(FourWayBlock.NORTH, false).with(FourWayBlock.SOUTH, false).with(FourWayBlock.EAST, false).with(FourWayBlock.WEST, false), 49, 28, 72, start);
        structure.setBlockState(world, Blocks.STONE_BRICKS.getDefaultState(), 49, 29, 37, start);
        structure.setBlockState(world, Blocks.AIR.getDefaultState(), 50, -59, 41, start);
        structure.setBlockState(world, Blocks.AIR.getDefaultState(), 50, -59, 57, start);
        structure.setBlockState(world, Blocks.STONE_BRICK_STAIRS.getDefaultState().with(StairsBlock.FACING, Direction.NORTH).with(StairsBlock.WATERLOGGED, false).with(StairsBlock.SHAPE, StairsShape.INNER_RIGHT).with(StairsBlock.HALF, Half.BOTTOM), 50, -57, -53, start);
        structure.setBlockState(world, Blocks.STONE_BRICK_STAIRS.getDefaultState().with(StairsBlock.FACING, Direction.SOUTH).with(StairsBlock.WATERLOGGED, false).with(StairsBlock.SHAPE, StairsShape.INNER_LEFT).with(StairsBlock.HALF, Half.BOTTOM), 50, -57, -47, start);
        structure.setBlockState(world, Blocks.REDSTONE_BLOCK.getDefaultState(), 50, -56, 14, start);
        structure.setBlockState(world, Blocks.AIR.getDefaultState(), 50, -56, 73, start);
        structure.setBlockState(world, Blocks.REDSTONE_BLOCK.getDefaultState(), 50, -56, 81, start);
        structure.setBlockState(world, Blocks.AIR.getDefaultState(), 50, -55, 4, start);
        structure.setBlockState(world, Blocks.SHROOMLIGHT.getDefaultState(), 50, -54, -40, start);
        structure.setBlockState(world, Blocks.SHROOMLIGHT.getDefaultState(), 50, -54, -34, start);
        structure.setBlockState(world, Blocks.SHROOMLIGHT.getDefaultState(), 50, -54, -30, start);
        structure.setBlockState(world, Blocks.SHROOMLIGHT.getDefaultState(), 50, -54, -26, start);
        structure.setBlockState(world, Blocks.SHROOMLIGHT.getDefaultState(), 50, -54, -22, start);
        structure.setBlockState(world, Blocks.SHROOMLIGHT.getDefaultState(), 50, -54, -10, start);
        structure.setBlockState(world, Blocks.SHROOMLIGHT.getDefaultState(), 50, -54, -4, start);
        structure.setBlockState(world, Blocks.SHROOMLIGHT.getDefaultState(), 50, -54, 2, start);
        structure.setBlockState(world, Blocks.SHROOMLIGHT.getDefaultState(), 50, -54, 16, start);
        structure.setBlockState(world, Blocks.SHROOMLIGHT.getDefaultState(), 50, -54, 20, start);
        structure.setBlockState(world, Blocks.SHROOMLIGHT.getDefaultState(), 50, -54, 26, start);
        structure.setBlockState(world, Blocks.SHROOMLIGHT.getDefaultState(), 50, -54, 32, start);
        structure.setBlockState(world, Blocks.SHROOMLIGHT.getDefaultState(), 50, -54, 36, start);
        structure.setBlockState(world, Blocks.SHROOMLIGHT.getDefaultState(), 50, -54, 62, start);
        structure.setBlockState(world, Blocks.SHROOMLIGHT.getDefaultState(), 50, -54, 68, start);
        structure.setBlockState(world, Blocks.AIR.getDefaultState(), 50, -53, -32, start);
        structure.setBlockState(world, Blocks.AIR.getDefaultState(), 50, -53, -2, start);
        structure.setBlockState(world, Blocks.STONE_BRICKS.getDefaultState(), 50, -53, -1, start);
        structure.setBlockState(world, Blocks.AIR.getDefaultState(), 50, -53, 0, start);
        structure.setBlockState(world, Blocks.STONE_BRICKS.getDefaultState(), 50, -53, 65, start);
        structure.setBlockState(world, Blocks.AIR.getDefaultState(), 50, -51, 4, start);
        structure.setBlockState(world, Blocks.AIR.getDefaultState(), 50, -51, 58, start);
        structure.setBlockState(world, Blocks.STONE_BRICK_STAIRS.getDefaultState().with(StairsBlock.FACING, Direction.EAST).with(StairsBlock.WATERLOGGED, false).with(StairsBlock.SHAPE, StairsShape.INNER_LEFT).with(StairsBlock.HALF, Half.TOP), 50, -50, -53, start);
        structure.setBlockState(world, Blocks.STONE_BRICK_STAIRS.getDefaultState().with(StairsBlock.FACING, Direction.SOUTH).with(StairsBlock.WATERLOGGED, false).with(StairsBlock.SHAPE, StairsShape.INNER_LEFT).with(StairsBlock.HALF, Half.TOP), 50, -50, -47, start);
        structure.setBlockState(world, Blocks.AIR.getDefaultState(), 50, -50, -17, start);
        structure.setBlockState(world, Blocks.AIR.getDefaultState(), 50, -50, 82, start);
        structure.setBlockState(world, Blocks.AIR.getDefaultState(), 50, -49, -60, start);
        structure.setBlockState(world, Blocks.AIR.getDefaultState(), 50, -49, -21, start);
        structure.setBlockState(world, Blocks.AIR.getDefaultState(), 50, -49, 4, start);
        structure.setBlockState(world, Blocks.MOSSY_COBBLESTONE.getDefaultState(), 50, -49, 58, start);
        structure.setBlockState(world, Blocks.AIR.getDefaultState(), 50, -48, -57, start);
        structure.setBlockState(world, Blocks.AIR.getDefaultState(), 50, -48, -52, start);
        structure.setBlockState(world, Blocks.STONE_BRICKS.getDefaultState(), 50, -46, -16, start);
        structure.setBlockState(world, Blocks.STONE_BRICKS.getDefaultState(), 50, -46, -14, start);
        structure.setBlockState(world, Blocks.MOSSY_COBBLESTONE.getDefaultState(), 50, -46, 5, start);
        structure.setBlockState(world, Blocks.REDSTONE_BLOCK.getDefaultState(), 50, -46, 6, start);
        structure.setBlockState(world, Blocks.MOSSY_STONE_BRICKS.getDefaultState(), 50, -46, 19, start);
        structure.setBlockState(world, Blocks.MOSSY_COBBLESTONE.getDefaultState(), 50, -46, 20, start);
        structure.setBlockState(world, Blocks.STONE_BRICKS.getDefaultState(), 50, -46, 25, start);
        structure.setBlockState(world, Blocks.MOSSY_STONE_BRICKS.getDefaultState(), 50, -46, 26, start);
        structure.setBlockState(world, Blocks.MOSSY_STONE_BRICKS.getDefaultState(), 50, -46, 32, start);
        structure.setBlockState(world, Blocks.MOSSY_STONE_BRICKS.getDefaultState(), 50, -46, 35, start);
        structure.setBlockState(world, Blocks.INFESTED_CRACKED_STONE_BRICKS.getDefaultState(), 50, -46, 37, start);
        structure.setBlockState(world, Blocks.STONE_BRICKS.getDefaultState(), 50, -46, 48, start);
        structure.setBlockState(world, Blocks.MOSSY_STONE_BRICKS.getDefaultState(), 50, -46, 50, start);
        structure.setBlockState(world, Blocks.MOSSY_STONE_BRICKS.getDefaultState(), 50, -46, 52, start);
        structure.setBlockState(world, Blocks.STONE_BRICKS.getDefaultState(), 50, -46, 63, start);
        structure.setBlockState(world, Blocks.STONE_BRICKS.getDefaultState(), 50, -45, -13, start);
        structure.setBlockState(world, Blocks.MOSSY_COBBLESTONE.getDefaultState(), 50, -45, 4, start);
        structure.setBlockState(world, Blocks.MOSSY_STONE_BRICKS.getDefaultState(), 50, -45, 5, start);
        structure.setBlockState(world, Blocks.MOSSY_COBBLESTONE.getDefaultState(), 50, -45, 17, start);
        structure.setBlockState(world, Blocks.STONE_BRICKS.getDefaultState(), 50, -45, 29, start);
        structure.setBlockState(world, Blocks.MOSSY_COBBLESTONE.getDefaultState(), 50, -45, 35, start);
        structure.setBlockState(world, Blocks.MOSSY_STONE_BRICKS.getDefaultState(), 50, -45, 43, start);
        structure.setBlockState(world, Blocks.INFESTED_STONE_BRICKS.getDefaultState(), 50, -45, 44, start);
        structure.setBlockState(world, Blocks.MOSSY_STONE_BRICKS.getDefaultState(), 50, -45, 51, start);
        structure.setBlockState(world, Blocks.AIR.getDefaultState(), 50, -45, 63, start);
        structure.setBlockState(world, Blocks.SHROOMLIGHT.getDefaultState(), 50, -44, -19, start);
        structure.setBlockState(world, Blocks.SHROOMLIGHT.getDefaultState(), 50, -44, -13, start);
        structure.setBlockState(world, Blocks.MOSSY_STONE_BRICKS.getDefaultState(), 50, -44, 29, start);
        structure.setBlockState(world, Blocks.SHROOMLIGHT.getDefaultState(), 50, -44, 38, start);
        structure.setBlockState(world, Blocks.MOSSY_COBBLESTONE.getDefaultState(), 50, -44, 43, start);
        structure.setBlockState(world, Blocks.MOSSY_COBBLESTONE.getDefaultState(), 50, -43, 5, start);
        structure.setBlockState(world, Blocks.INFESTED_STONE_BRICKS.getDefaultState(), 50, -43, 15, start);
        structure.setBlockState(world, Blocks.MOSSY_STONE_BRICKS.getDefaultState(), 50, -43, 16, start);
        structure.setBlockState(world, Blocks.MOSSY_STONE_BRICKS.getDefaultState(), 50, -43, 39, start);
        structure.setBlockState(world, Blocks.STONE_BRICKS.getDefaultState(), 50, -43, 43, start);
        structure.setBlockState(world, Blocks.MOSSY_STONE_BRICKS.getDefaultState(), 50, -43, 44, start);
        structure.setBlockState(world, Blocks.MOSSY_COBBLESTONE.getDefaultState(), 50, -42, -18, start);
        structure.setBlockState(world, Blocks.MOSSY_STONE_BRICKS.getDefaultState(), 50, -42, -14, start);
        structure.setBlockState(world, Blocks.STONE_BRICKS.getDefaultState(), 50, -42, 4, start);
        structure.setBlockState(world, Blocks.AIR.getDefaultState(), 50, -42, 5, start);
        structure.setBlockState(world, Blocks.MOSSY_STONE_BRICKS.getDefaultState(), 50, -42, 15, start);
        structure.setBlockState(world, Blocks.MOSSY_STONE_BRICKS.getDefaultState(), 50, -42, 47, start);
        structure.setBlockState(world, Blocks.STONE_BRICKS.getDefaultState(), 50, -42, 60, start);
        structure.setBlockState(world, Blocks.MOSSY_COBBLESTONE.getDefaultState(), 50, -41, 16, start);
        structure.setBlockState(world, Blocks.INFESTED_COBBLESTONE.getDefaultState(), 50, -41, 21, start);
        structure.setBlockState(world, Blocks.INFESTED_COBBLESTONE.getDefaultState(), 50, -41, 23, start);
        structure.setBlockState(world, Blocks.MOSSY_COBBLESTONE.getDefaultState(), 50, -41, 60, start);
        structure.setBlockState(world, Blocks.INFESTED_COBBLESTONE.getDefaultState(), 50, -41, 63, start);
        structure.setBlockState(world, Blocks.MOSSY_STONE_BRICKS.getDefaultState(), 50, -40, 4, start);
        structure.setBlockState(world, Blocks.MOSSY_STONE_BRICKS.getDefaultState(), 50, -40, 17, start);
        structure.setBlockState(world, Blocks.AIR.getDefaultState(), 50, -40, 23, start);
        structure.setBlockState(world, Blocks.MOSSY_COBBLESTONE.getDefaultState(), 50, -40, 49, start);
        structure.setBlockState(world, Blocks.STONE_BRICKS.getDefaultState(), 50, -40, 58, start);
        structure.setBlockState(world, Blocks.AIR.getDefaultState(), 50, -40, 60, start);
        structure.setBlockState(world, Blocks.AIR.getDefaultState(), 50, -40, 63, start);
        structure.setBlockState(world, Blocks.MOSSY_COBBLESTONE.getDefaultState(), 50, -39, 4, start);
        structure.setBlockState(world, Blocks.MOSSY_COBBLESTONE.getDefaultState(), 50, -39, 8, start);
        structure.setBlockState(world, Blocks.MOSSY_STONE_BRICKS.getDefaultState(), 50, -39, 21, start);
        structure.setBlockState(world, Blocks.INFESTED_STONE_BRICKS.getDefaultState(), 50, -39, 29, start);
        structure.setBlockState(world, Blocks.AIR.getDefaultState(), 50, -39, 31, start);
        structure.setBlockState(world, Blocks.MOSSY_STONE_BRICKS.getDefaultState(), 50, -39, 52, start);
        structure.setBlockState(world, Blocks.MOSSY_COBBLESTONE.getDefaultState(), 50, -39, 63, start);
        structure.setBlockState(world, Blocks.AIR.getDefaultState(), 50, -38, 4, start);
        structure.setBlockState(world, Blocks.INFESTED_CRACKED_STONE_BRICKS.getDefaultState(), 50, -38, 6, start);
        structure.setBlockState(world, Blocks.MOSSY_COBBLESTONE.getDefaultState(), 50, -38, 9, start);
        structure.setBlockState(world, Blocks.MOSSY_STONE_BRICKS.getDefaultState(), 50, -38, 11, start);
        structure.setBlockState(world, Blocks.MOSSY_STONE_BRICKS.getDefaultState(), 50, -38, 14, start);
        structure.setBlockState(world, Blocks.MOSSY_STONE_BRICKS.getDefaultState(), 50, -38, 23, start);
        structure.setBlockState(world, Blocks.AIR.getDefaultState(), 50, -38, 24, start);
        structure.setBlockState(world, Blocks.MOSSY_STONE_BRICKS.getDefaultState(), 50, -38, 28, start);
        structure.setBlockState(world, Blocks.INFESTED_CRACKED_STONE_BRICKS.getDefaultState(), 50, -38, 29, start);
        structure.setBlockState(world, Blocks.MOSSY_STONE_BRICKS.getDefaultState(), 50, -38, 31, start);
        structure.setBlockState(world, Blocks.INFESTED_COBBLESTONE.getDefaultState(), 50, -38, 35, start);
        structure.setBlockState(world, Blocks.AIR.getDefaultState(), 50, -38, 36, start);
        structure.setBlockState(world, Blocks.MOSSY_STONE_BRICKS.getDefaultState(), 50, -38, 51, start);
        structure.setBlockState(world, Blocks.MOSSY_STONE_BRICKS.getDefaultState(), 50, -37, 10, start);
        structure.setBlockState(world, Blocks.INFESTED_COBBLESTONE.getDefaultState(), 50, -37, 18, start);
        structure.setBlockState(world, Blocks.INFESTED_COBBLESTONE.getDefaultState(), 50, -37, 26, start);
        structure.setBlockState(world, Blocks.MOSSY_STONE_BRICKS.getDefaultState(), 50, -37, 27, start);
        structure.setBlockState(world, Blocks.INFESTED_STONE_BRICKS.getDefaultState(), 50, -37, 28, start);
        structure.setBlockState(world, Blocks.INFESTED_STONE_BRICKS.getDefaultState(), 50, -37, 30, start);
        structure.setBlockState(world, Blocks.STONE_BRICKS.getDefaultState(), 50, -37, 34, start);
        structure.setBlockState(world, Blocks.INFESTED_STONE_BRICKS.getDefaultState(), 50, -37, 36, start);
        structure.setBlockState(world, Blocks.INFESTED_STONE_BRICKS.getDefaultState(), 50, -37, 50, start);
        structure.setBlockState(world, Blocks.MOSSY_COBBLESTONE.getDefaultState(), 50, -37, 54, start);
        structure.setBlockState(world, Blocks.CRACKED_STONE_BRICKS.getDefaultState(), 50, -26, 78, start);
        structure.setBlockState(world, Blocks.STONE_BRICKS.getDefaultState(), 50, -25, 47, start);
        structure.setBlockState(world, Blocks.CRACKED_STONE_BRICKS.getDefaultState(), 50, -25, 73, start);
        structure.setBlockState(world, Blocks.SHROOMLIGHT.getDefaultState(), 50, -24, 41, start);
        structure.setBlockState(world, Blocks.SHROOMLIGHT.getDefaultState(), 50, -24, 47, start);
        structure.setBlockState(world, Blocks.SHROOMLIGHT.getDefaultState(), 50, -24, 73, start);
        structure.setBlockState(world, Blocks.SHROOMLIGHT.getDefaultState(), 50, -24, 79, start);
        structure.setBlockState(world, Blocks.STONE_BRICKS.getDefaultState(), 50, -23, 47, start);
        structure.setBlockState(world, Blocks.MOSSY_STONE_BRICKS.getDefaultState(), 50, -22, 42, start);
        structure.setBlockState(world, Blocks.CRACKED_STONE_BRICKS.getDefaultState(), 50, -22, 78, start);
        structure.setBlockState(world, Blocks.SHROOMLIGHT.getDefaultState(), 50, -14, 41, start);
        structure.setBlockState(world, Blocks.SHROOMLIGHT.getDefaultState(), 50, -14, 47, start);
        structure.setBlockState(world, Blocks.GRASS_BLOCK.getDefaultState().with(SnowyDirtBlock.SNOWY, false), 50, 1, 19, start);
        structure.setBlockState(world, Blocks.GRASS_BLOCK.getDefaultState().with(SnowyDirtBlock.SNOWY, false), 50, 2, 18, start);
        structure.setBlockState(world, Blocks.GRASS_BLOCK.getDefaultState().with(SnowyDirtBlock.SNOWY, false), 50, 2, 44, start);
        structure.setBlockState(world, Blocks.OAK_LEAVES.getDefaultState().with(LeavesBlock.PERSISTENT, false).with(LeavesBlock.DISTANCE, 3), 50, 3, 44, start);
        structure.setBlockState(world, Blocks.GRASS_BLOCK.getDefaultState().with(SnowyDirtBlock.SNOWY, false), 50, 3, 55, start);
        structure.setBlockState(world, Blocks.GRASS_BLOCK.getDefaultState().with(SnowyDirtBlock.SNOWY, false), 50, 4, 16, start);
        structure.setBlockState(world, Blocks.OAK_LEAVES.getDefaultState().with(LeavesBlock.PERSISTENT, false).with(LeavesBlock.DISTANCE, 5), 50, 4, 55, start);
        structure.setBlockState(world, Blocks.OAK_FENCE.getDefaultState().with(FourWayBlock.WATERLOGGED, false).with(FourWayBlock.NORTH, true).with(FourWayBlock.SOUTH, true).with(FourWayBlock.EAST, false).with(FourWayBlock.WEST, true), 50, 6, 30, start);
        structure.setBlockState(world, Blocks.OAK_LEAVES.getDefaultState().with(LeavesBlock.PERSISTENT, false).with(LeavesBlock.DISTANCE, 4), 50, 6, 43, start);
        structure.setBlockState(world, Blocks.OAK_LEAVES.getDefaultState().with(LeavesBlock.PERSISTENT, false).with(LeavesBlock.DISTANCE, 2), 50, 6, 45, start);
        structure.setBlockState(world, Blocks.OAK_FENCE.getDefaultState().with(FourWayBlock.WATERLOGGED, false).with(FourWayBlock.NORTH, true).with(FourWayBlock.SOUTH, false).with(FourWayBlock.EAST, true).with(FourWayBlock.WEST, true), 50, 6, 58, start);
        structure.setBlockState(world, Blocks.OAK_LEAVES.getDefaultState().with(LeavesBlock.PERSISTENT, false).with(LeavesBlock.DISTANCE, 4), 50, 7, 56, start);
        structure.setBlockState(world, Blocks.OAK_LEAVES.getDefaultState().with(LeavesBlock.PERSISTENT, false).with(LeavesBlock.DISTANCE, 3), 50, 8, 56, start);
        structure.setBlockState(world, Blocks.STONE_BRICKS.getDefaultState(), 50, 8, 62, start);
        structure.setBlockState(world, Blocks.OAK_FENCE_GATE.getDefaultState().with(FenceGateBlock.IN_WALL, false).with(FenceGateBlock.OPEN, true).with(FenceGateBlock.POWERED, false), 50, 9, 28, start);
        structure.setBlockState(world, Blocks.OAK_LEAVES.getDefaultState().with(LeavesBlock.PERSISTENT, false).with(LeavesBlock.DISTANCE, 4), 50, 9, 56, start);
        structure.setBlockState(world, Blocks.OAK_TRAPDOOR.getDefaultState().with(HorizontalBlock.HORIZONTAL_FACING, Direction.SOUTH).with(TrapDoorBlock.HALF, Half.BOTTOM).with(TrapDoorBlock.WATERLOGGED, false).with(TrapDoorBlock.POWERED, false).with(TrapDoorBlock.OPEN, false), 50, 10, 28, start);
        structure.setBlockState(world, Blocks.STONE_BRICKS.getDefaultState(), 50, 12, 67, start);
        structure.setBlockState(world, Blocks.OAK_LEAVES.getDefaultState().with(LeavesBlock.PERSISTENT, false).with(LeavesBlock.DISTANCE, 4), 50, 18, 39, start);
        structure.setBlockState(world, Blocks.OAK_LEAVES.getDefaultState().with(LeavesBlock.PERSISTENT, false).with(LeavesBlock.DISTANCE, 5), 50, 18, 40, start);
        structure.setBlockState(world, Blocks.OAK_LEAVES.getDefaultState().with(LeavesBlock.PERSISTENT, false).with(LeavesBlock.DISTANCE, 6), 50, 18, 41, start);
        structure.setBlockState(world, Blocks.OAK_LEAVES.getDefaultState().with(LeavesBlock.PERSISTENT, false).with(LeavesBlock.DISTANCE, 5), 50, 19, 39, start);
        structure.setBlockState(world, Blocks.OAK_LEAVES.getDefaultState().with(LeavesBlock.PERSISTENT, false).with(LeavesBlock.DISTANCE, 6), 50, 19, 40, start);
        structure.setBlockState(world, Blocks.OAK_LEAVES.getDefaultState().with(LeavesBlock.PERSISTENT, false).with(LeavesBlock.DISTANCE, 4), 50, 20, 39, start);
        structure.setBlockState(world, Blocks.OAK_LEAVES.getDefaultState().with(LeavesBlock.PERSISTENT, false).with(LeavesBlock.DISTANCE, 3), 50, 21, 39, start);
        structure.setBlockState(world, Blocks.OAK_LEAVES.getDefaultState().with(LeavesBlock.PERSISTENT, false).with(LeavesBlock.DISTANCE, 2), 50, 22, 39, start);
        structure.setBlockState(world, Blocks.OAK_LEAVES.getDefaultState().with(LeavesBlock.PERSISTENT, false).with(LeavesBlock.DISTANCE, 1), 50, 23, 39, start);
        structure.setBlockState(world, Blocks.OAK_FENCE.getDefaultState().with(FourWayBlock.WATERLOGGED, false).with(FourWayBlock.NORTH, false).with(FourWayBlock.SOUTH, false).with(FourWayBlock.EAST, false).with(FourWayBlock.WEST, true), 50, 24, 31, start);
        structure.setBlockState(world, Blocks.OAK_LEAVES.getDefaultState().with(LeavesBlock.PERSISTENT, false).with(LeavesBlock.DISTANCE, 4), 50, 24, 32, start);
        structure.setBlockState(world, Blocks.OAK_FENCE.getDefaultState().with(FourWayBlock.WATERLOGGED, false).with(FourWayBlock.NORTH, false).with(FourWayBlock.SOUTH, false).with(FourWayBlock.EAST, true).with(FourWayBlock.WEST, true), 50, 24, 33, start);
        structure.setBlockState(world, Blocks.OAK_LEAVES.getDefaultState().with(LeavesBlock.PERSISTENT, false).with(LeavesBlock.DISTANCE, 4), 50, 24, 34, start);
        structure.setBlockState(world, Blocks.OAK_LOG.getDefaultState(), 50, 24, 39, start);
        structure.setBlockState(world, Blocks.OAK_LEAVES.getDefaultState().with(LeavesBlock.PERSISTENT, false).with(LeavesBlock.DISTANCE, 5), 50, 25, 35, start);
        structure.setBlockState(world, Blocks.OAK_LEAVES.getDefaultState().with(LeavesBlock.PERSISTENT, false).with(LeavesBlock.DISTANCE, 3), 50, 25, 42, start);
        structure.setBlockState(world, Blocks.OAK_LEAVES.getDefaultState().with(LeavesBlock.PERSISTENT, false).with(LeavesBlock.DISTANCE, 4), 50, 26, 37, start);
        structure.setBlockState(world, Blocks.OAK_LEAVES.getDefaultState().with(LeavesBlock.PERSISTENT, false).with(LeavesBlock.DISTANCE, 3), 50, 26, 41, start);
        structure.setBlockState(world, Blocks.OAK_LOG.getDefaultState(), 50, 29, 73, start);
        structure.setBlockState(world, Blocks.AIR.getDefaultState(), 51, -58, 45, start);
        structure.setBlockState(world, Blocks.AIR.getDefaultState(), 51, -58, 53, start);
        structure.setBlockState(world, Blocks.AIR.getDefaultState(), 51, -55, 81, start);
        structure.setBlockState(world, Blocks.AIR.getDefaultState(), 51, -55, 83, start);
        structure.setBlockState(world, Blocks.SHROOMLIGHT.getDefaultState(), 51, -54, -19, start);
        structure.setBlockState(world, Blocks.SHROOMLIGHT.getDefaultState(), 51, -54, -13, start);
        structure.setBlockState(world, Blocks.AIR.getDefaultState(), 51, -53, 72, start);
        structure.setBlockState(world, Blocks.AIR.getDefaultState(), 51, -52, -41, start);
        structure.setBlockState(world, Blocks.SHROOMLIGHT.getDefaultState(), 51, -51, 41, start);
        structure.setBlockState(world, Blocks.SHROOMLIGHT.getDefaultState(), 51, -51, 45, start);
        structure.setBlockState(world, Blocks.SHROOMLIGHT.getDefaultState(), 51, -51, 53, start);
        structure.setBlockState(world, Blocks.AIR.getDefaultState(), 51, -51, 55, start);
        structure.setBlockState(world, Blocks.AIR.getDefaultState(), 51, -50, -18, start);
        structure.setBlockState(world, Blocks.AIR.getDefaultState(), 51, -50, 15, start);
        structure.setBlockState(world, Blocks.AIR.getDefaultState(), 51, -50, 41, start);
        structure.setBlockState(world, Blocks.AIR.getDefaultState(), 51, -50, 46, start);
        structure.setBlockState(world, Blocks.AIR.getDefaultState(), 51, -50, 79, start);
        structure.setBlockState(world, Blocks.AIR.getDefaultState(), 51, -49, -43, start);
        structure.setBlockState(world, Blocks.AIR.getDefaultState(), 51, -49, -40, start);
        structure.setBlockState(world, Blocks.AIR.getDefaultState(), 51, -49, -22, start);
        structure.setBlockState(world, Blocks.AIR.getDefaultState(), 51, -49, 44, start);
        structure.setBlockState(world, Blocks.AIR.getDefaultState(), 51, -49, 56, start);
        structure.setBlockState(world, Blocks.AIR.getDefaultState(), 51, -48, -48, start);
        structure.setBlockState(world, Blocks.AIR.getDefaultState(), 51, -48, 54, start);
        structure.setBlockState(world, Blocks.MOSSY_COBBLESTONE.getDefaultState(), 51, -48, 57, start);
        structure.setBlockState(world, Blocks.AIR.getDefaultState(), 51, -47, -58, start);
        structure.setBlockState(world, Blocks.AIR.getDefaultState(), 51, -47, -55, start);
        structure.setBlockState(world, Blocks.AIR.getDefaultState(), 51, -47, 41, start);
        structure.setBlockState(world, Blocks.AIR.getDefaultState(), 51, -47, 46, start);
        structure.setBlockState(world, Blocks.AIR.getDefaultState(), 51, -47, 50, start);
        structure.setBlockState(world, Blocks.MOSSY_COBBLESTONE.getDefaultState(), 51, -47, 55, start);
        structure.setBlockState(world, Blocks.AIR.getDefaultState(), 51, -47, 73, start);
        structure.setBlockState(world, Blocks.MOSSY_STONE_BRICKS.getDefaultState(), 51, -46, -14, start);
        structure.setBlockState(world, Blocks.MOSSY_STONE_BRICKS.getDefaultState(), 51, -46, 15, start);
        structure.setBlockState(world, Blocks.AIR.getDefaultState(), 51, -46, 16, start);
        structure.setBlockState(world, Blocks.INFESTED_STONE_BRICKS.getDefaultState(), 51, -46, 20, start);
        structure.setBlockState(world, Blocks.MOSSY_STONE_BRICKS.getDefaultState(), 51, -46, 21, start);
        structure.setBlockState(world, Blocks.MOSSY_STONE_BRICKS.getDefaultState(), 51, -46, 25, start);
        structure.setBlockState(world, Blocks.AIR.getDefaultState(), 51, -46, 35, start);
        structure.setBlockState(world, Blocks.INFESTED_COBBLESTONE.getDefaultState(), 51, -46, 50, start);
        structure.setBlockState(world, Blocks.MOSSY_COBBLESTONE.getDefaultState(), 51, -46, 57, start);
        structure.setBlockState(world, Blocks.MOSSY_COBBLESTONE.getDefaultState(), 51, -46, 60, start);
        structure.setBlockState(world, Blocks.STONE_BRICK_WALL.getDefaultState().with(WallBlock.WATERLOGGED, false).with(WallBlock.UP, true).with(WallBlock.WALL_HEIGHT_NORTH, WallHeight.LOW).with(WallBlock.WALL_HEIGHT_SOUTH, WallHeight.LOW).with(WallBlock.WALL_HEIGHT_EAST, WallHeight.LOW).with(WallBlock.WALL_HEIGHT_WEST, WallHeight.LOW), 51, -45, 19, start);
        structure.setBlockState(world, Blocks.STONE_BRICK_WALL.getDefaultState().with(WallBlock.WATERLOGGED, false).with(WallBlock.UP, true).with(WallBlock.WALL_HEIGHT_NORTH, WallHeight.LOW).with(WallBlock.WALL_HEIGHT_SOUTH, WallHeight.LOW).with(WallBlock.WALL_HEIGHT_EAST, WallHeight.LOW).with(WallBlock.WALL_HEIGHT_WEST, WallHeight.LOW), 51, -45, 21, start);
        structure.setBlockState(world, Blocks.MOSSY_COBBLESTONE.getDefaultState(), 51, -45, 22, start);
        structure.setBlockState(world, Blocks.MOSSY_STONE_BRICKS.getDefaultState(), 51, -45, 30, start);
        structure.setBlockState(world, Blocks.AIR.getDefaultState(), 51, -45, 37, start);
        structure.setBlockState(world, Blocks.SHROOMLIGHT.getDefaultState(), 51, -44, 10, start);
        structure.setBlockState(world, Blocks.STONE_BRICK_WALL.getDefaultState().with(WallBlock.WATERLOGGED, false).with(WallBlock.UP, true).with(WallBlock.WALL_HEIGHT_NORTH, WallHeight.LOW).with(WallBlock.WALL_HEIGHT_SOUTH, WallHeight.LOW).with(WallBlock.WALL_HEIGHT_EAST, WallHeight.LOW).with(WallBlock.WALL_HEIGHT_WEST, WallHeight.LOW), 51, -44, 19, start);
        structure.setBlockState(world, Blocks.SHROOMLIGHT.getDefaultState(), 51, -44, 56, start);
        structure.setBlockState(world, Blocks.MOSSY_COBBLESTONE.getDefaultState(), 51, -44, 57, start);
        structure.setBlockState(world, Blocks.STONE_BRICKS.getDefaultState(), 51, -44, 61, start);
        structure.setBlockState(world, Blocks.MOSSY_COBBLESTONE.getDefaultState(), 51, -44, 62, start);
        structure.setBlockState(world, Blocks.AIR.getDefaultState(), 51, -43, 16, start);
        structure.setBlockState(world, Blocks.STONE_BRICK_WALL.getDefaultState().with(WallBlock.WATERLOGGED, false).with(WallBlock.UP, true).with(WallBlock.WALL_HEIGHT_NORTH, WallHeight.LOW).with(WallBlock.WALL_HEIGHT_SOUTH, WallHeight.LOW).with(WallBlock.WALL_HEIGHT_EAST, WallHeight.LOW).with(WallBlock.WALL_HEIGHT_WEST, WallHeight.LOW), 51, -43, 19, start);
        structure.setBlockState(world, Blocks.STONE_BRICKS.getDefaultState(), 51, -42, -14, start);
        structure.setBlockState(world, Blocks.AIR.getDefaultState(), 51, -42, 4, start);
        structure.setBlockState(world, Blocks.MOSSY_STONE_BRICKS.getDefaultState(), 51, -42, 21, start);
        structure.setBlockState(world, Blocks.MOSSY_STONE_BRICKS.getDefaultState(), 51, -42, 34, start);
        structure.setBlockState(world, Blocks.AIR.getDefaultState(), 51, -42, 36, start);
        structure.setBlockState(world, Blocks.STONE_BRICKS.getDefaultState(), 51, -42, 59, start);
        structure.setBlockState(world, Blocks.MOSSY_COBBLESTONE.getDefaultState(), 51, -41, 15, start);
        structure.setBlockState(world, Blocks.MOSSY_STONE_BRICKS.getDefaultState(), 51, -41, 18, start);
        structure.setBlockState(world, Blocks.INFESTED_STONE_BRICKS.getDefaultState(), 51, -41, 23, start);
        structure.setBlockState(world, Blocks.MOSSY_STONE_BRICKS.getDefaultState(), 51, -41, 60, start);
        structure.setBlockState(world, Blocks.MOSSY_COBBLESTONE.getDefaultState(), 51, -41, 62, start);
        structure.setBlockState(world, Blocks.MOSSY_STONE_BRICKS.getDefaultState(), 51, -41, 63, start);
        structure.setBlockState(world, Blocks.AIR.getDefaultState(), 51, -40, 19, start);
        structure.setBlockState(world, Blocks.MOSSY_COBBLESTONE.getDefaultState(), 51, -40, 21, start);
        structure.setBlockState(world, Blocks.AIR.getDefaultState(), 51, -40, 29, start);
        structure.setBlockState(world, Blocks.AIR.getDefaultState(), 51, -40, 37, start);
        structure.setBlockState(world, Blocks.INFESTED_COBBLESTONE.getDefaultState(), 51, -40, 49, start);
        structure.setBlockState(world, Blocks.MOSSY_COBBLESTONE.getDefaultState(), 51, -40, 53, start);
        structure.setBlockState(world, Blocks.MOSSY_STONE_BRICKS.getDefaultState(), 51, -39, 6, start);
        structure.setBlockState(world, Blocks.MOSSY_COBBLESTONE.getDefaultState(), 51, -39, 11, start);
        structure.setBlockState(world, Blocks.MOSSY_STONE_BRICKS.getDefaultState(), 51, -39, 13, start);
        structure.setBlockState(world, Blocks.MOSSY_STONE_BRICKS.getDefaultState(), 51, -39, 16, start);
        structure.setBlockState(world, Blocks.STONE_BRICKS.getDefaultState(), 51, -39, 21, start);
        structure.setBlockState(world, Blocks.MOSSY_COBBLESTONE.getDefaultState(), 51, -39, 22, start);
        structure.setBlockState(world, Blocks.MOSSY_STONE_BRICKS.getDefaultState(), 51, -39, 23, start);
        structure.setBlockState(world, Blocks.MOSSY_STONE_BRICKS.getDefaultState(), 51, -39, 25, start);
        structure.setBlockState(world, Blocks.AIR.getDefaultState(), 51, -39, 33, start);
        structure.setBlockState(world, Blocks.STONE_BRICKS.getDefaultState(), 51, -39, 54, start);
        structure.setBlockState(world, Blocks.MOSSY_COBBLESTONE.getDefaultState(), 51, -39, 59, start);
        structure.setBlockState(world, Blocks.MOSSY_STONE_BRICKS.getDefaultState(), 51, -39, 62, start);
        structure.setBlockState(world, Blocks.INFESTED_CRACKED_STONE_BRICKS.getDefaultState(), 51, -38, 8, start);
        structure.setBlockState(world, Blocks.AIR.getDefaultState(), 51, -38, 12, start);
        structure.setBlockState(world, Blocks.AIR.getDefaultState(), 51, -38, 15, start);
        structure.setBlockState(world, Blocks.INFESTED_CRACKED_STONE_BRICKS.getDefaultState(), 51, -38, 21, start);
        structure.setBlockState(world, Blocks.AIR.getDefaultState(), 51, -38, 23, start);
        structure.setBlockState(world, Blocks.AIR.getDefaultState(), 51, -38, 56, start);
        structure.setBlockState(world, Blocks.AIR.getDefaultState(), 51, -38, 60, start);
        structure.setBlockState(world, Blocks.AIR.getDefaultState(), 51, -38, 62, start);
        structure.setBlockState(world, Blocks.STONE_BRICKS.getDefaultState(), 51, -37, 6, start);
        structure.setBlockState(world, Blocks.MOSSY_STONE_BRICKS.getDefaultState(), 51, -37, 13, start);
        structure.setBlockState(world, Blocks.MOSSY_COBBLESTONE.getDefaultState(), 51, -37, 23, start);
        structure.setBlockState(world, Blocks.MOSSY_STONE_BRICKS.getDefaultState(), 51, -37, 24, start);
        structure.setBlockState(world, Blocks.MOSSY_STONE_BRICKS.getDefaultState(), 51, -37, 26, start);
        structure.setBlockState(world, Blocks.MOSSY_COBBLESTONE.getDefaultState(), 51, -37, 29, start);
        structure.setBlockState(world, Blocks.MOSSY_COBBLESTONE.getDefaultState(), 51, -37, 52, start);
        structure.setBlockState(world, Blocks.MOSSY_STONE_BRICKS.getDefaultState(), 51, -37, 55, start);
        structure.setBlockState(world, Blocks.STONE_BRICKS.getDefaultState(), 51, -37, 58, start);
        structure.setBlockState(world, Blocks.MOSSY_COBBLESTONE.getDefaultState(), 51, -37, 61, start);
        structure.setBlockState(world, Blocks.CRACKED_STONE_BRICKS.getDefaultState(), 51, -26, 42, start);
        structure.setBlockState(world, Blocks.MOSSY_STONE_BRICKS.getDefaultState(), 51, -25, 47, start);
        structure.setBlockState(world, Blocks.STONE_BRICKS.getDefaultState(), 51, -24, 47, start);
        structure.setBlockState(world, Blocks.CRACKED_STONE_BRICKS.getDefaultState(), 51, -23, 41, start);
        structure.setBlockState(world, Blocks.CRACKED_STONE_BRICKS.getDefaultState(), 51, -23, 47, start);
        structure.setBlockState(world, Blocks.CRACKED_STONE_BRICKS.getDefaultState(), 51, -22, 76, start);
        structure.setBlockState(world, Blocks.GRASS_BLOCK.getDefaultState().with(SnowyDirtBlock.SNOWY, false), 51, 0, 48, start);
        structure.setBlockState(world, Blocks.GRASS_BLOCK.getDefaultState().with(SnowyDirtBlock.SNOWY, false), 51, 1, 44, start);
        structure.setBlockState(world, Blocks.OAK_LEAVES.getDefaultState().with(LeavesBlock.PERSISTENT, false).with(LeavesBlock.DISTANCE, 5), 51, 2, 44, start);
        structure.setBlockState(world, Blocks.OAK_LEAVES.getDefaultState().with(LeavesBlock.PERSISTENT, false).with(LeavesBlock.DISTANCE, 4), 51, 3, 44, start);
        structure.setBlockState(world, Blocks.OAK_LEAVES.getDefaultState().with(LeavesBlock.PERSISTENT, false).with(LeavesBlock.DISTANCE, 3), 51, 4, 44, start);
        structure.setBlockState(world, Blocks.OAK_LEAVES.getDefaultState().with(LeavesBlock.PERSISTENT, false).with(LeavesBlock.DISTANCE, 5), 51, 6, 43, start);
        structure.setBlockState(world, Blocks.OAK_LEAVES.getDefaultState().with(LeavesBlock.PERSISTENT, false).with(LeavesBlock.DISTANCE, 3), 51, 6, 45, start);
        structure.setBlockState(world, Blocks.OAK_LEAVES.getDefaultState().with(LeavesBlock.PERSISTENT, false).with(LeavesBlock.DISTANCE, 5), 51, 6, 55, start);
        structure.setBlockState(world, Blocks.OAK_LEAVES.getDefaultState().with(LeavesBlock.PERSISTENT, false).with(LeavesBlock.DISTANCE, 6), 51, 7, 55, start);
        structure.setBlockState(world, Blocks.STONE_BRICKS.getDefaultState(), 51, 8, 47, start);
        structure.setBlockState(world, Blocks.OAK_FENCE.getDefaultState().with(FourWayBlock.WATERLOGGED, false).with(FourWayBlock.NORTH, true).with(FourWayBlock.SOUTH, false).with(FourWayBlock.EAST, true).with(FourWayBlock.WEST, true), 51, 9, 28, start);
        structure.setBlockState(world, Blocks.STONE_BRICKS.getDefaultState(), 51, 10, 25, start);
        structure.setBlockState(world, Blocks.TORCH.getDefaultState(), 51, 10, 28, start);
        structure.setBlockState(world, Blocks.OAK_FENCE.getDefaultState().with(FourWayBlock.WATERLOGGED, false).with(FourWayBlock.NORTH, false).with(FourWayBlock.SOUTH, true).with(FourWayBlock.EAST, true).with(FourWayBlock.WEST, false), 51, 10, 60, start);
        structure.setBlockState(world, Blocks.STONE_BRICKS.getDefaultState(), 51, 11, 53, start);
        structure.setBlockState(world, Blocks.STONE_BRICKS.getDefaultState(), 51, 12, 21, start);
        structure.setBlockState(world, Blocks.STONE_BRICKS.getDefaultState(), 51, 13, 39, start);
        structure.setBlockState(world, Blocks.OAK_LEAVES.getDefaultState().with(LeavesBlock.PERSISTENT, false).with(LeavesBlock.DISTANCE, 4), 51, 18, 38, start);
        structure.setBlockState(world, Blocks.OAK_LEAVES.getDefaultState().with(LeavesBlock.PERSISTENT, false).with(LeavesBlock.DISTANCE, 5), 51, 18, 39, start);
        structure.setBlockState(world, Blocks.OAK_LEAVES.getDefaultState().with(LeavesBlock.PERSISTENT, false).with(LeavesBlock.DISTANCE, 6), 51, 18, 40, start);
        structure.setBlockState(world, Blocks.OAK_LEAVES.getDefaultState().with(LeavesBlock.PERSISTENT, false).with(LeavesBlock.DISTANCE, 6), 51, 19, 39, start);
        structure.setBlockState(world, Blocks.OAK_FENCE.getDefaultState().with(FourWayBlock.WATERLOGGED, false).with(FourWayBlock.NORTH, false).with(FourWayBlock.SOUTH, false).with(FourWayBlock.EAST, false).with(FourWayBlock.WEST, true), 51, 24, 33, start);
        structure.setBlockState(world, Blocks.STONE_BRICKS.getDefaultState(), 51, 25, 30, start);
        structure.setBlockState(world, Blocks.OAK_FENCE.getDefaultState().with(FourWayBlock.WATERLOGGED, false).with(FourWayBlock.NORTH, true).with(FourWayBlock.SOUTH, false).with(FourWayBlock.EAST, false).with(FourWayBlock.WEST, true), 51, 25, 31, start);
        structure.setBlockState(world, Blocks.OAK_LOG.getDefaultState(), 51, 25, 40, start);
        structure.setBlockState(world, Blocks.OAK_LEAVES.getDefaultState().with(LeavesBlock.PERSISTENT, false).with(LeavesBlock.DISTANCE, 1), 51, 25, 41, start);
        structure.setBlockState(world, Blocks.OAK_LEAVES.getDefaultState().with(LeavesBlock.PERSISTENT, false).with(LeavesBlock.DISTANCE, 2), 51, 25, 42, start);
        structure.setBlockState(world, Blocks.OAK_LEAVES.getDefaultState().with(LeavesBlock.PERSISTENT, false).with(LeavesBlock.DISTANCE, 4), 51, 25, 71, start);
        structure.setBlockState(world, Blocks.OAK_LEAVES.getDefaultState().with(LeavesBlock.PERSISTENT, false).with(LeavesBlock.DISTANCE, 3), 51, 25, 73, start);
        structure.setBlockState(world, Blocks.OAK_FENCE.getDefaultState().with(FourWayBlock.WATERLOGGED, false).with(FourWayBlock.NORTH, false).with(FourWayBlock.SOUTH, true).with(FourWayBlock.EAST, true).with(FourWayBlock.WEST, false), 51, 26, 30, start);
        structure.setBlockState(world, Blocks.OAK_LEAVES.getDefaultState().with(LeavesBlock.PERSISTENT, false).with(LeavesBlock.DISTANCE, 1), 51, 26, 40, start);
        structure.setBlockState(world, Blocks.OAK_LEAVES.getDefaultState().with(LeavesBlock.PERSISTENT, false).with(LeavesBlock.DISTANCE, 2), 51, 26, 41, start);
        structure.setBlockState(world, Blocks.OAK_LEAVES.getDefaultState().with(LeavesBlock.PERSISTENT, false).with(LeavesBlock.DISTANCE, 4), 51, 26, 70, start);
        structure.setBlockState(world, Blocks.OAK_FENCE.getDefaultState().with(FourWayBlock.WATERLOGGED, false).with(FourWayBlock.NORTH, false).with(FourWayBlock.SOUTH, true).with(FourWayBlock.EAST, true).with(FourWayBlock.WEST, true), 51, 27, 29, start);
        structure.setBlockState(world, Blocks.OAK_LEAVES.getDefaultState().with(LeavesBlock.PERSISTENT, false).with(LeavesBlock.DISTANCE, 6), 51, 27, 67, start);
        structure.setBlockState(world, Blocks.OAK_LEAVES.getDefaultState().with(LeavesBlock.PERSISTENT, false).with(LeavesBlock.DISTANCE, 3), 51, 27, 70, start);
        structure.setBlockState(world, Blocks.STONE_BRICKS.getDefaultState(), 51, 28, 40, start);
        structure.setBlockState(world, Blocks.OAK_LEAVES.getDefaultState().with(LeavesBlock.PERSISTENT, false).with(LeavesBlock.DISTANCE, 5), 51, 28, 67, start);
        structure.setBlockState(world, Blocks.OAK_LEAVES.getDefaultState().with(LeavesBlock.PERSISTENT, false).with(LeavesBlock.DISTANCE, 4), 51, 28, 68, start);
        structure.setBlockState(world, Blocks.OAK_LEAVES.getDefaultState().with(LeavesBlock.PERSISTENT, false).with(LeavesBlock.DISTANCE, 1), 51, 28, 74, start);
        structure.setBlockState(world, Blocks.OAK_LEAVES.getDefaultState().with(LeavesBlock.PERSISTENT, false).with(LeavesBlock.DISTANCE, 6), 51, 29, 67, start);
        structure.setBlockState(world, Blocks.OAK_LEAVES.getDefaultState().with(LeavesBlock.PERSISTENT, false).with(LeavesBlock.DISTANCE, 5), 51, 29, 68, start);
        structure.setBlockState(world, Blocks.OAK_LEAVES.getDefaultState().with(LeavesBlock.PERSISTENT, false).with(LeavesBlock.DISTANCE, 1), 51, 29, 71, start);
        structure.setBlockState(world, Blocks.OAK_LEAVES.getDefaultState().with(LeavesBlock.PERSISTENT, false).with(LeavesBlock.DISTANCE, 2), 51, 29, 74, start);
        structure.setBlockState(world, Blocks.OAK_LOG.getDefaultState(), 51, 30, 71, start);
        structure.setBlockState(world, Blocks.OAK_LEAVES.getDefaultState().with(LeavesBlock.PERSISTENT, false).with(LeavesBlock.DISTANCE, 1), 51, 30, 74, start);
        structure.setBlockState(world, Blocks.STONE_BRICKS.getDefaultState(), 51, 35, 33, start);
        structure.setBlockState(world, Blocks.STONE_BRICKS.getDefaultState(), 51, 36, 30, start);
        structure.setBlockState(world, Blocks.AIR.getDefaultState(), 52, -56, 13, start);
        structure.setBlockState(world, Blocks.AIR.getDefaultState(), 52, -55, 12, start);
        structure.setBlockState(world, Blocks.AIR.getDefaultState(), 52, -55, 72, start);
        structure.setBlockState(world, Blocks.AIR.getDefaultState(), 52, -55, 77, start);
        structure.setBlockState(world, Blocks.AIR.getDefaultState(), 52, -54, -40, start);
        structure.setBlockState(world, Blocks.AIR.getDefaultState(), 52, -54, 71, start);
        structure.setBlockState(world, Blocks.AIR.getDefaultState(), 52, -53, 12, start);
        structure.setBlockState(world, Blocks.AIR.getDefaultState(), 52, -52, 6, start);
        structure.setBlockState(world, Blocks.AIR.getDefaultState(), 52, -52, 10, start);
        structure.setBlockState(world, Blocks.AIR.getDefaultState(), 52, -52, 82, start);
        structure.setBlockState(world, Blocks.AIR.getDefaultState(), 52, -51, -41, start);
        structure.setBlockState(world, Blocks.AIR.getDefaultState(), 52, -50, -55, start);
        structure.setBlockState(world, Blocks.AIR.getDefaultState(), 52, -50, 8, start);
        structure.setBlockState(world, Blocks.AIR.getDefaultState(), 52, -50, 13, start);
        structure.setBlockState(world, Blocks.AIR.getDefaultState(), 52, -50, 72, start);
        structure.setBlockState(world, Blocks.AIR.getDefaultState(), 52, -49, -58, start);
        structure.setBlockState(world, Blocks.AIR.getDefaultState(), 52, -49, -12, start);
        structure.setBlockState(world, Blocks.AIR.getDefaultState(), 52, -49, 6, start);
        structure.setBlockState(world, Blocks.AIR.getDefaultState(), 52, -49, 51, start);
        structure.setBlockState(world, Blocks.AIR.getDefaultState(), 52, -48, -49, start);
        structure.setBlockState(world, Blocks.AIR.getDefaultState(), 52, -48, -43, start);
        structure.setBlockState(world, Blocks.AIR.getDefaultState(), 52, -48, -17, start);
        structure.setBlockState(world, Blocks.AIR.getDefaultState(), 52, -48, 43, start);
        structure.setBlockState(world, Blocks.AIR.getDefaultState(), 52, -47, -21, start);
        structure.setBlockState(world, Blocks.AIR.getDefaultState(), 52, -47, 10, start);
        structure.setBlockState(world, Blocks.AIR.getDefaultState(), 52, -47, 45, start);
        structure.setBlockState(world, Blocks.STONE_BRICKS.getDefaultState(), 52, -46, -17, start);
        structure.setBlockState(world, Blocks.MOSSY_STONE_BRICKS.getDefaultState(), 52, -46, -16, start);
        structure.setBlockState(world, Blocks.MOSSY_COBBLESTONE.getDefaultState(), 52, -46, -14, start);
        structure.setBlockState(world, Blocks.STONE_BRICKS.getDefaultState(), 52, -46, 10, start);
        structure.setBlockState(world, Blocks.AIR.getDefaultState(), 52, -46, 14, start);
        structure.setBlockState(world, Blocks.STONE_BRICKS.getDefaultState(), 52, -46, 20, start);
        structure.setBlockState(world, Blocks.MOSSY_COBBLESTONE.getDefaultState(), 52, -46, 54, start);
        structure.setBlockState(world, Blocks.MOSSY_STONE_BRICKS.getDefaultState(), 52, -46, 55, start);
        structure.setBlockState(world, Blocks.STONE_BRICKS.getDefaultState(), 52, -45, -18, start);
        structure.setBlockState(world, Blocks.MOSSY_STONE_BRICKS.getDefaultState(), 52, -45, 5, start);
        structure.setBlockState(world, Blocks.STONE_BRICK_WALL.getDefaultState().with(WallBlock.WATERLOGGED, false).with(WallBlock.UP, true).with(WallBlock.WALL_HEIGHT_NORTH, WallHeight.LOW).with(WallBlock.WALL_HEIGHT_SOUTH, WallHeight.LOW).with(WallBlock.WALL_HEIGHT_EAST, WallHeight.LOW).with(WallBlock.WALL_HEIGHT_WEST, WallHeight.LOW), 52, -45, 30, start);
        structure.setBlockState(world, Blocks.MOSSY_STONE_BRICKS.getDefaultState(), 52, -45, 34, start);
        structure.setBlockState(world, Blocks.INFESTED_COBBLESTONE.getDefaultState(), 52, -45, 35, start);
        structure.setBlockState(world, Blocks.MOSSY_COBBLESTONE.getDefaultState(), 52, -45, 36, start);
        structure.setBlockState(world, Blocks.STONE_BRICKS.getDefaultState(), 52, -45, 46, start);
        structure.setBlockState(world, Blocks.MOSSY_COBBLESTONE.getDefaultState(), 52, -45, 51, start);
        structure.setBlockState(world, Blocks.MOSSY_STONE_BRICKS.getDefaultState(), 52, -44, -18, start);
        structure.setBlockState(world, Blocks.MOSSY_STONE_BRICKS.getDefaultState(), 52, -44, 4, start);
        structure.setBlockState(world, Blocks.MOSSY_COBBLESTONE.getDefaultState(), 52, -44, 7, start);
        structure.setBlockState(world, Blocks.AIR.getDefaultState(), 52, -44, 9, start);
        structure.setBlockState(world, Blocks.AIR.getDefaultState(), 52, -44, 15, start);
        structure.setBlockState(world, Blocks.MOSSY_COBBLESTONE.getDefaultState(), 52, -44, 16, start);
        structure.setBlockState(world, Blocks.INFESTED_COBBLESTONE.getDefaultState(), 52, -44, 46, start);
        structure.setBlockState(world, Blocks.AIR.getDefaultState(), 52, -44, 53, start);
        structure.setBlockState(world, Blocks.AIR.getDefaultState(), 52, -44, 58, start);
        structure.setBlockState(world, Blocks.AIR.getDefaultState(), 52, -44, 60, start);
        structure.setBlockState(world, Blocks.AIR.getDefaultState(), 52, -44, 62, start);
        structure.setBlockState(world, Blocks.STONE_BRICKS.getDefaultState(), 52, -43, -18, start);
        structure.setBlockState(world, Blocks.INFESTED_STONE_BRICKS.getDefaultState(), 52, -43, -14, start);
        structure.setBlockState(world, Blocks.MOSSY_STONE_BRICKS.getDefaultState(), 52, -43, 5, start);
        structure.setBlockState(world, Blocks.AIR.getDefaultState(), 52, -43, 6, start);
        structure.setBlockState(world, Blocks.STONE_BRICKS.getDefaultState(), 52, -43, 7, start);
        structure.setBlockState(world, Blocks.STONE_BRICKS.getDefaultState(), 52, -43, 9, start);
        structure.setBlockState(world, Blocks.MOSSY_COBBLESTONE.getDefaultState(), 52, -43, 14, start);
        structure.setBlockState(world, Blocks.INFESTED_STONE_BRICKS.getDefaultState(), 52, -43, 15, start);
        structure.setBlockState(world, Blocks.INFESTED_COBBLESTONE.getDefaultState(), 52, -43, 34, start);
        structure.setBlockState(world, Blocks.MOSSY_STONE_BRICKS.getDefaultState(), 52, -43, 36, start);
        structure.setBlockState(world, Blocks.AIR.getDefaultState(), 52, -43, 37, start);
        structure.setBlockState(world, Blocks.MOSSY_COBBLESTONE.getDefaultState(), 52, -43, 57, start);
        structure.setBlockState(world, Blocks.MOSSY_STONE_BRICKS.getDefaultState(), 52, -43, 58, start);
        structure.setBlockState(world, Blocks.MOSSY_STONE_BRICKS.getDefaultState(), 52, -42, -14, start);
        structure.setBlockState(world, Blocks.MOSSY_STONE_BRICKS.getDefaultState(), 52, -42, 4, start);
        structure.setBlockState(world, Blocks.MOSSY_COBBLESTONE.getDefaultState(), 52, -42, 15, start);
        structure.setBlockState(world, Blocks.MOSSY_STONE_BRICKS.getDefaultState(), 52, -42, 30, start);
        structure.setBlockState(world, Blocks.AIR.getDefaultState(), 52, -42, 35, start);
        structure.setBlockState(world, Blocks.MOSSY_COBBLESTONE.getDefaultState(), 52, -42, 47, start);
        structure.setBlockState(world, Blocks.INFESTED_COBBLESTONE.getDefaultState(), 52, -42, 57, start);
        structure.setBlockState(world, Blocks.STONE_BRICKS.getDefaultState(), 52, -42, 58, start);
        structure.setBlockState(world, Blocks.MOSSY_STONE_BRICKS.getDefaultState(), 52, -42, 59, start);
        structure.setBlockState(world, Blocks.STONE_BRICKS.getDefaultState(), 52, -41, 11, start);
        structure.setBlockState(world, Blocks.MOSSY_COBBLESTONE.getDefaultState(), 52, -41, 12, start);
        structure.setBlockState(world, Blocks.AIR.getDefaultState(), 52, -41, 15, start);
        structure.setBlockState(world, Blocks.MOSSY_STONE_BRICKS.getDefaultState(), 52, -41, 23, start);
        structure.setBlockState(world, Blocks.MOSSY_COBBLESTONE.getDefaultState(), 52, -41, 34, start);
        structure.setBlockState(world, Blocks.INFESTED_CRACKED_STONE_BRICKS.getDefaultState(), 52, -41, 49, start);
        structure.setBlockState(world, Blocks.MOSSY_COBBLESTONE.getDefaultState(), 52, -41, 51, start);
        structure.setBlockState(world, Blocks.INFESTED_CRACKED_STONE_BRICKS.getDefaultState(), 52, -41, 57, start);
        structure.setBlockState(world, Blocks.STONE_BRICKS.getDefaultState(), 52, -41, 59, start);
        structure.setBlockState(world, Blocks.AIR.getDefaultState(), 52, -41, 60, start);
        structure.setBlockState(world, Blocks.AIR.getDefaultState(), 52, -41, 62, start);
        structure.setBlockState(world, Blocks.AIR.getDefaultState(), 52, -40, 7, start);
        structure.setBlockState(world, Blocks.INFESTED_COBBLESTONE.getDefaultState(), 52, -40, 10, start);
        structure.setBlockState(world, Blocks.INFESTED_STONE_BRICKS.getDefaultState(), 52, -40, 14, start);
        structure.setBlockState(world, Blocks.INFESTED_CRACKED_STONE_BRICKS.getDefaultState(), 52, -40, 36, start);
        structure.setBlockState(world, Blocks.MOSSY_COBBLESTONE.getDefaultState(), 52, -40, 50, start);
        structure.setBlockState(world, Blocks.INFESTED_CRACKED_STONE_BRICKS.getDefaultState(), 52, -40, 53, start);
        structure.setBlockState(world, Blocks.STONE_BRICKS.getDefaultState(), 52, -40, 54, start);
        structure.setBlockState(world, Blocks.INFESTED_STONE_BRICKS.getDefaultState(), 52, -40, 62, start);
        structure.setBlockState(world, Blocks.AIR.getDefaultState(), 52, -39, 6, start);
        structure.setBlockState(world, Blocks.MOSSY_COBBLESTONE.getDefaultState(), 52, -39, 7, start);
        structure.setBlockState(world, Blocks.STONE_BRICKS.getDefaultState(), 52, -39, 10, start);
        structure.setBlockState(world, Blocks.MOSSY_COBBLESTONE.getDefaultState(), 52, -39, 13, start);
        structure.setBlockState(world, Blocks.MOSSY_COBBLESTONE.getDefaultState(), 52, -39, 21, start);
        structure.setBlockState(world, Blocks.INFESTED_CRACKED_STONE_BRICKS.getDefaultState(), 52, -39, 30, start);
        structure.setBlockState(world, Blocks.STONE_BRICKS.getDefaultState(), 52, -39, 52, start);
        structure.setBlockState(world, Blocks.STONE_BRICKS.getDefaultState(), 52, -39, 59, start);
        structure.setBlockState(world, Blocks.AIR.getDefaultState(), 52, -39, 62, start);
        structure.setBlockState(world, Blocks.AIR.getDefaultState(), 52, -38, 4, start);
        structure.setBlockState(world, Blocks.MOSSY_COBBLESTONE.getDefaultState(), 52, -38, 6, start);
        structure.setBlockState(world, Blocks.MOSSY_STONE_BRICKS.getDefaultState(), 52, -38, 10, start);
        structure.setBlockState(world, Blocks.MOSSY_COBBLESTONE.getDefaultState(), 52, -38, 11, start);
        structure.setBlockState(world, Blocks.MOSSY_COBBLESTONE.getDefaultState(), 52, -38, 25, start);
        structure.setBlockState(world, Blocks.AIR.getDefaultState(), 52, -38, 26, start);
        structure.setBlockState(world, Blocks.INFESTED_STONE_BRICKS.getDefaultState(), 52, -38, 35, start);
        structure.setBlockState(world, Blocks.INFESTED_COBBLESTONE.getDefaultState(), 52, -38, 51, start);
        structure.setBlockState(world, Blocks.INFESTED_STONE_BRICKS.getDefaultState(), 52, -38, 55, start);
        structure.setBlockState(world, Blocks.MOSSY_STONE_BRICKS.getDefaultState(), 52, -38, 59, start);
        structure.setBlockState(world, Blocks.MOSSY_COBBLESTONE.getDefaultState(), 52, -37, 17, start);
        structure.setBlockState(world, Blocks.MOSSY_STONE_BRICKS.getDefaultState(), 52, -37, 18, start);
        structure.setBlockState(world, Blocks.MOSSY_COBBLESTONE.getDefaultState(), 52, -37, 19, start);
        structure.setBlockState(world, Blocks.MOSSY_STONE_BRICKS.getDefaultState(), 52, -37, 23, start);
        structure.setBlockState(world, Blocks.MOSSY_STONE_BRICKS.getDefaultState(), 52, -37, 58, start);
        structure.setBlockState(world, Blocks.MOSSY_COBBLESTONE.getDefaultState(), 52, -37, 60, start);
        structure.setBlockState(world, Blocks.CRACKED_STONE_BRICKS.getDefaultState(), 52, -26, 74, start);
        structure.setBlockState(world, Blocks.MOSSY_STONE_BRICKS.getDefaultState(), 52, -23, 46, start);
        structure.setBlockState(world, Blocks.MOSSY_STONE_BRICKS.getDefaultState(), 52, -22, 44, start);
        structure.setBlockState(world, Blocks.CRACKED_STONE_BRICKS.getDefaultState(), 52, -22, 45, start);
        structure.setBlockState(world, Blocks.MOSSY_STONE_BRICKS.getDefaultState(), 52, -22, 74, start);
        structure.setBlockState(world, Blocks.AIR.getDefaultState(), 52, -22, 77, start);
        structure.setBlockState(world, Blocks.GRASS_BLOCK.getDefaultState().with(SnowyDirtBlock.SNOWY, false), 52, 1, 13, start);
        structure.setBlockState(world, Blocks.COAL_ORE.getDefaultState(), 52, 1, 29, start);
        structure.setBlockState(world, Blocks.GRASS_BLOCK.getDefaultState().with(SnowyDirtBlock.SNOWY, false), 52, 3, 20, start);
        structure.setBlockState(world, Blocks.GRASS_BLOCK.getDefaultState().with(SnowyDirtBlock.SNOWY, false), 52, 3, 54, start);
        structure.setBlockState(world, Blocks.GRASS_BLOCK.getDefaultState().with(SnowyDirtBlock.SNOWY, false), 52, 3, 75, start);
        structure.setBlockState(world, Blocks.STONE_BRICKS.getDefaultState(), 52, 3, 76, start);
        structure.setBlockState(world, Blocks.GRASS_BLOCK.getDefaultState().with(SnowyDirtBlock.SNOWY, false), 52, 4, 32, start);
        structure.setBlockState(world, Blocks.GRASS_BLOCK.getDefaultState().with(SnowyDirtBlock.SNOWY, false), 52, 4, 53, start);
        structure.setBlockState(world, Blocks.GRASS_BLOCK.getDefaultState().with(SnowyDirtBlock.SNOWY, false), 52, 4, 62, start);
        structure.setBlockState(world, Blocks.AIR.getDefaultState(), 52, 6, 29, start);
        structure.setBlockState(world, Blocks.STONE_BRICKS.getDefaultState(), 52, 6, 57, start);
        structure.setBlockState(world, Blocks.STONE_BRICKS.getDefaultState(), 52, 7, 56, start);
        structure.setBlockState(world, Blocks.AIR.getDefaultState(), 52, 8, 49, start);
        structure.setBlockState(world, Blocks.OAK_FENCE_GATE.getDefaultState().with(FenceGateBlock.IN_WALL, false).with(FenceGateBlock.OPEN, true).with(FenceGateBlock.POWERED, false), 52, 9, 28, start);
        structure.setBlockState(world, Blocks.STONE_BRICKS.getDefaultState(), 52, 9, 64, start);
        structure.setBlockState(world, Blocks.STONE_BRICKS.getDefaultState(), 52, 10, 13, start);
        structure.setBlockState(world, Blocks.OAK_TRAPDOOR.getDefaultState().with(HorizontalBlock.HORIZONTAL_FACING, Direction.SOUTH).with(TrapDoorBlock.HALF, Half.BOTTOM).with(TrapDoorBlock.WATERLOGGED, false).with(TrapDoorBlock.POWERED, false).with(TrapDoorBlock.OPEN, false), 52, 10, 28, start);
        structure.setBlockState(world, Blocks.OAK_FENCE_GATE.getDefaultState().with(FenceGateBlock.IN_WALL, false).with(FenceGateBlock.OPEN, true).with(FenceGateBlock.POWERED, false), 52, 10, 60, start);
        structure.setBlockState(world, Blocks.OAK_TRAPDOOR.getDefaultState().with(HorizontalBlock.HORIZONTAL_FACING, Direction.NORTH).with(TrapDoorBlock.HALF, Half.BOTTOM).with(TrapDoorBlock.WATERLOGGED, false).with(TrapDoorBlock.POWERED, false).with(TrapDoorBlock.OPEN, false), 52, 11, 60, start);
        structure.setBlockState(world, Blocks.STONE_BRICKS.getDefaultState(), 52, 12, 67, start);
        structure.setBlockState(world, Blocks.STONE_BRICKS.getDefaultState(), 52, 16, 36, start);
        structure.setBlockState(world, Blocks.OAK_LEAVES.getDefaultState().with(LeavesBlock.PERSISTENT, false).with(LeavesBlock.DISTANCE, 6), 52, 18, 39, start);
        structure.setBlockState(world, Blocks.OAK_LEAVES.getDefaultState().with(LeavesBlock.PERSISTENT, false).with(LeavesBlock.DISTANCE, 6), 52, 19, 38, start);
        structure.setBlockState(world, Blocks.OAK_LEAVES.getDefaultState().with(LeavesBlock.PERSISTENT, false).with(LeavesBlock.DISTANCE, 6), 52, 21, 41, start);
        structure.setBlockState(world, Blocks.OAK_LEAVES.getDefaultState().with(LeavesBlock.PERSISTENT, false).with(LeavesBlock.DISTANCE, 5), 52, 22, 41, start);
        structure.setBlockState(world, Blocks.OAK_LEAVES.getDefaultState().with(LeavesBlock.PERSISTENT, false).with(LeavesBlock.DISTANCE, 6), 52, 22, 42, start);
        structure.setBlockState(world, Blocks.OAK_LEAVES.getDefaultState().with(LeavesBlock.PERSISTENT, false).with(LeavesBlock.DISTANCE, 4), 52, 23, 41, start);
        structure.setBlockState(world, Blocks.OAK_LEAVES.getDefaultState().with(LeavesBlock.PERSISTENT, false).with(LeavesBlock.DISTANCE, 5), 52, 23, 42, start);
        structure.setBlockState(world, Blocks.OAK_LEAVES.getDefaultState().with(LeavesBlock.PERSISTENT, false).with(LeavesBlock.DISTANCE, 3), 52, 24, 41, start);
        structure.setBlockState(world, Blocks.OAK_LEAVES.getDefaultState().with(LeavesBlock.PERSISTENT, false).with(LeavesBlock.DISTANCE, 4), 52, 24, 42, start);
        structure.setBlockState(world, Blocks.OAK_LEAVES.getDefaultState().with(LeavesBlock.PERSISTENT, false).with(LeavesBlock.DISTANCE, 5), 52, 24, 43, start);
        structure.setBlockState(world, Blocks.STONE_BRICK_STAIRS.getDefaultState().with(StairsBlock.FACING, Direction.NORTH).with(StairsBlock.WATERLOGGED, false).with(StairsBlock.SHAPE, StairsShape.STRAIGHT).with(StairsBlock.HALF, Half.BOTTOM), 52, 25, 30, start);
        structure.setBlockState(world, Blocks.OAK_LEAVES.getDefaultState().with(LeavesBlock.PERSISTENT, false).with(LeavesBlock.DISTANCE, 1), 52, 25, 40, start);
        structure.setBlockState(world, Blocks.OAK_LEAVES.getDefaultState().with(LeavesBlock.PERSISTENT, false).with(LeavesBlock.DISTANCE, 2), 52, 25, 41, start);
        structure.setBlockState(world, Blocks.OAK_LEAVES.getDefaultState().with(LeavesBlock.PERSISTENT, false).with(LeavesBlock.DISTANCE, 3), 52, 25, 42, start);
        structure.setBlockState(world, Blocks.STONE_BRICK_STAIRS.getDefaultState().with(StairsBlock.FACING, Direction.NORTH).with(StairsBlock.WATERLOGGED, false).with(StairsBlock.SHAPE, StairsShape.STRAIGHT).with(StairsBlock.HALF, Half.BOTTOM), 52, 26, 29, start);
        structure.setBlockState(world, Blocks.STONE_BRICKS.getDefaultState(), 52, 26, 33, start);
        structure.setBlockState(world, Blocks.OAK_LEAVES.getDefaultState().with(LeavesBlock.PERSISTENT, false).with(LeavesBlock.DISTANCE, 3), 52, 26, 39, start);
        structure.setBlockState(world, Blocks.OAK_LEAVES.getDefaultState().with(LeavesBlock.PERSISTENT, false).with(LeavesBlock.DISTANCE, 2), 52, 26, 40, start);
        structure.setBlockState(world, Blocks.OAK_LEAVES.getDefaultState().with(LeavesBlock.PERSISTENT, false).with(LeavesBlock.DISTANCE, 3), 52, 26, 41, start);
        structure.setBlockState(world, Blocks.STONE_BRICKS.getDefaultState(), 52, 26, 72, start);
        structure.setBlockState(world, Blocks.STONE_BRICK_STAIRS.getDefaultState().with(StairsBlock.FACING, Direction.NORTH).with(StairsBlock.WATERLOGGED, false).with(StairsBlock.SHAPE, StairsShape.STRAIGHT).with(StairsBlock.HALF, Half.BOTTOM), 52, 27, 28, start);
        structure.setBlockState(world, Blocks.OAK_LEAVES.getDefaultState().with(LeavesBlock.PERSISTENT, false).with(LeavesBlock.DISTANCE, 5), 52, 27, 67, start);
        structure.setBlockState(world, Blocks.OAK_LEAVES.getDefaultState().with(LeavesBlock.PERSISTENT, false).with(LeavesBlock.DISTANCE, 4), 52, 27, 68, start);
        structure.setBlockState(world, Blocks.OAK_LEAVES.getDefaultState().with(LeavesBlock.PERSISTENT, false).with(LeavesBlock.DISTANCE, 3), 52, 27, 69, start);
        structure.setBlockState(world, Blocks.OAK_LEAVES.getDefaultState().with(LeavesBlock.PERSISTENT, false).with(LeavesBlock.DISTANCE, 2), 52, 27, 70, start);
        structure.setBlockState(world, Blocks.OAK_LEAVES.getDefaultState().with(LeavesBlock.PERSISTENT, false).with(LeavesBlock.DISTANCE, 3), 52, 28, 68, start);
        structure.setBlockState(world, Blocks.OAK_LEAVES.getDefaultState().with(LeavesBlock.PERSISTENT, false).with(LeavesBlock.DISTANCE, 1), 52, 29, 74, start);
        structure.setBlockState(world, Blocks.AIR.getDefaultState(), 53, -58, 49, start);
        structure.setBlockState(world, Blocks.AIR.getDefaultState(), 53, -57, 48, start);
        structure.setBlockState(world, Blocks.AIR.getDefaultState(), 53, -56, 11, start);
        structure.setBlockState(world, Blocks.AIR.getDefaultState(), 53, -56, 79, start);
        structure.setBlockState(world, Blocks.AIR.getDefaultState(), 53, -55, 6, start);
        structure.setBlockState(world, Blocks.AIR.getDefaultState(), 53, -54, -22, start);
        structure.setBlockState(world, Blocks.AIR.getDefaultState(), 53, -54, 11, start);
        structure.setBlockState(world, Blocks.AIR.getDefaultState(), 53, -54, 74, start);
        structure.setBlockState(world, Blocks.AIR.getDefaultState(), 53, -54, 80, start);
        structure.setBlockState(world, Blocks.AIR.getDefaultState(), 53, -54, 83, start);
        structure.setBlockState(world, Blocks.AIR.getDefaultState(), 53, -53, 7, start);
        structure.setBlockState(world, Blocks.AIR.getDefaultState(), 53, -53, 14, start);
        structure.setBlockState(world, Blocks.AIR.getDefaultState(), 53, -53, 71, start);
        structure.setBlockState(world, Blocks.AIR.getDefaultState(), 53, -52, -22, start);
        structure.setBlockState(world, Blocks.AIR.getDefaultState(), 53, -52, 77, start);
        structure.setBlockState(world, Blocks.AIR.getDefaultState(), 53, -51, -18, start);
        structure.setBlockState(world, Blocks.AIR.getDefaultState(), 53, -51, 57, start);
        structure.setBlockState(world, Blocks.AIR.getDefaultState(), 53, -50, -60, start);
        structure.setBlockState(world, Blocks.AIR.getDefaultState(), 53, -50, -14, start);
        structure.setBlockState(world, Blocks.AIR.getDefaultState(), 53, -50, 55, start);
        structure.setBlockState(world, Blocks.AIR.getDefaultState(), 53, -50, 75, start);
        structure.setBlockState(world, Blocks.AIR.getDefaultState(), 53, -49, -40, start);
        structure.setBlockState(world, Blocks.AIR.getDefaultState(), 53, -49, -18, start);
        structure.setBlockState(world, Blocks.AIR.getDefaultState(), 53, -49, 50, start);
        structure.setBlockState(world, Blocks.AIR.getDefaultState(), 53, -49, 53, start);
        structure.setBlockState(world, Blocks.AIR.getDefaultState(), 53, -49, 76, start);
        structure.setBlockState(world, Blocks.AIR.getDefaultState(), 53, -48, 10, start);
        structure.setBlockState(world, Blocks.AIR.getDefaultState(), 53, -48, 81, start);
        structure.setBlockState(world, Blocks.STONE_BRICKS.getDefaultState(), 53, -48, 82, start);
        structure.setBlockState(world, Blocks.AIR.getDefaultState(), 53, -48, 83, start);
        structure.setBlockState(world, Blocks.AIR.getDefaultState(), 53, -47, -51, start);
        structure.setBlockState(world, Blocks.AIR.getDefaultState(), 53, -47, -42, start);
        structure.setBlockState(world, Blocks.AIR.getDefaultState(), 53, -47, 4, start);
        structure.setBlockState(world, Blocks.AIR.getDefaultState(), 53, -47, 9, start);
        structure.setBlockState(world, Blocks.AIR.getDefaultState(), 53, -47, 47, start);
        structure.setBlockState(world, Blocks.AIR.getDefaultState(), 53, -47, 76, start);
        structure.setBlockState(world, Blocks.STONE_BRICKS.getDefaultState(), 53, -47, 81, start);
        structure.setBlockState(world, Blocks.AIR.getDefaultState(), 53, -47, 82, start);
        structure.setBlockState(world, Blocks.MOSSY_STONE_BRICKS.getDefaultState(), 53, -46, -17, start);
        structure.setBlockState(world, Blocks.MOSSY_COBBLESTONE.getDefaultState(), 53, -46, 4, start);
        structure.setBlockState(world, Blocks.MOSSY_STONE_BRICKS.getDefaultState(), 53, -46, 5, start);
        structure.setBlockState(world, Blocks.STONE_BRICKS.getDefaultState(), 53, -46, 7, start);
        structure.setBlockState(world, Blocks.MOSSY_STONE_BRICKS.getDefaultState(), 53, -46, 8, start);
        structure.setBlockState(world, Blocks.STONE_BRICKS.getDefaultState(), 53, -46, 9, start);
        structure.setBlockState(world, Blocks.MOSSY_COBBLESTONE.getDefaultState(), 53, -46, 10, start);
        structure.setBlockState(world, Blocks.STONE_BRICKS.getDefaultState(), 53, -46, 14, start);
        structure.setBlockState(world, Blocks.STONE_BRICKS.getDefaultState(), 53, -46, 17, start);
        structure.setBlockState(world, Blocks.MOSSY_COBBLESTONE.getDefaultState(), 53, -46, 18, start);
        structure.setBlockState(world, Blocks.STONE_BRICKS.getDefaultState(), 53, -46, 27, start);
        structure.setBlockState(world, Blocks.MOSSY_COBBLESTONE.getDefaultState(), 53, -46, 28, start);
        structure.setBlockState(world, Blocks.MOSSY_STONE_BRICKS.getDefaultState(), 53, -46, 32, start);
        structure.setBlockState(world, Blocks.MOSSY_COBBLESTONE.getDefaultState(), 53, -46, 33, start);
        structure.setBlockState(world, Blocks.MOSSY_STONE_BRICKS.getDefaultState(), 53, -46, 34, start);
        structure.setBlockState(world, Blocks.MOSSY_COBBLESTONE.getDefaultState(), 53, -46, 36, start);
        structure.setBlockState(world, Blocks.MOSSY_COBBLESTONE.getDefaultState(), 53, -46, 47, start);
        structure.setBlockState(world, Blocks.MOSSY_STONE_BRICKS.getDefaultState(), 53, -46, 48, start);
        structure.setBlockState(world, Blocks.STONE_BRICKS.getDefaultState(), 53, -46, 55, start);
        structure.setBlockState(world, Blocks.AIR.getDefaultState(), 53, -46, 57, start);
        structure.setBlockState(world, Blocks.MOSSY_STONE_BRICKS.getDefaultState(), 53, -46, 60, start);
        structure.setBlockState(world, Blocks.MOSSY_COBBLESTONE.getDefaultState(), 53, -45, 7, start);
        structure.setBlockState(world, Blocks.STONE_BRICKS.getDefaultState(), 53, -45, 8, start);
        structure.setBlockState(world, Blocks.MOSSY_COBBLESTONE.getDefaultState(), 53, -45, 14, start);
        structure.setBlockState(world, Blocks.AIR.getDefaultState(), 53, -45, 17, start);
        structure.setBlockState(world, Blocks.AIR.getDefaultState(), 53, -45, 20, start);
        structure.setBlockState(world, Blocks.AIR.getDefaultState(), 53, -45, 32, start);
        structure.setBlockState(world, Blocks.MOSSY_COBBLESTONE.getDefaultState(), 53, -45, 38, start);
        structure.setBlockState(world, Blocks.AIR.getDefaultState(), 53, -45, 55, start);
        structure.setBlockState(world, Blocks.MOSSY_COBBLESTONE.getDefaultState(), 53, -45, 57, start);
        structure.setBlockState(world, Blocks.STONE_BRICKS.getDefaultState(), 53, -45, 60, start);
        structure.setBlockState(world, Blocks.INFESTED_STONE_BRICKS.getDefaultState(), 53, -44, 4, start);
        structure.setBlockState(world, Blocks.INFESTED_CRACKED_STONE_BRICKS.getDefaultState(), 53, -44, 6, start);
        structure.setBlockState(world, Blocks.MOSSY_STONE_BRICKS.getDefaultState(), 53, -44, 37, start);
        structure.setBlockState(world, Blocks.MOSSY_STONE_BRICKS.getDefaultState(), 53, -44, 53, start);
        structure.setBlockState(world, Blocks.AIR.getDefaultState(), 53, -44, 57, start);
        structure.setBlockState(world, Blocks.MOSSY_COBBLESTONE.getDefaultState(), 53, -43, 4, start);
        structure.setBlockState(world, Blocks.AIR.getDefaultState(), 53, -43, 9, start);
        structure.setBlockState(world, Blocks.MOSSY_STONE_BRICKS.getDefaultState(), 53, -43, 10, start);
        structure.setBlockState(world, Blocks.STONE_BRICKS.getDefaultState(), 53, -43, 11, start);
        structure.setBlockState(world, Blocks.AIR.getDefaultState(), 53, -43, 12, start);
        structure.setBlockState(world, Blocks.MOSSY_COBBLESTONE.getDefaultState(), 53, -43, 17, start);
        structure.setBlockState(world, Blocks.STONE_BRICK_WALL.getDefaultState().with(WallBlock.WATERLOGGED, false).with(WallBlock.UP, false).with(WallBlock.WALL_HEIGHT_NORTH, WallHeight.LOW).with(WallBlock.WALL_HEIGHT_SOUTH, WallHeight.LOW).with(WallBlock.WALL_HEIGHT_EAST, WallHeight.LOW).with(WallBlock.WALL_HEIGHT_WEST, WallHeight.LOW), 53, -43, 30, start);
        structure.setBlockState(world, Blocks.MOSSY_COBBLESTONE.getDefaultState(), 53, -43, 36, start);
        structure.setBlockState(world, Blocks.INFESTED_COBBLESTONE.getDefaultState(), 53, -43, 53, start);
        structure.setBlockState(world, Blocks.MOSSY_COBBLESTONE.getDefaultState(), 53, -43, 61, start);
        structure.setBlockState(world, Blocks.STONE_BRICKS.getDefaultState(), 53, -42, 4, start);
        structure.setBlockState(world, Blocks.AIR.getDefaultState(), 53, -42, 5, start);
        structure.setBlockState(world, Blocks.MOSSY_STONE_BRICKS.getDefaultState(), 53, -42, 8, start);
        structure.setBlockState(world, Blocks.MOSSY_STONE_BRICKS.getDefaultState(), 53, -42, 11, start);
        structure.setBlockState(world, Blocks.INFESTED_CRACKED_STONE_BRICKS.getDefaultState(), 53, -42, 12, start);
        structure.setBlockState(world, Blocks.STONE_BRICKS.getDefaultState(), 53, -42, 30, start);
        structure.setBlockState(world, Blocks.STONE_BRICKS.getDefaultState(), 53, -42, 63, start);
        structure.setBlockState(world, Blocks.MOSSY_COBBLESTONE.getDefaultState(), 53, -41, 4, start);
        structure.setBlockState(world, Blocks.STONE_BRICKS.getDefaultState(), 53, -41, 5, start);
        structure.setBlockState(world, Blocks.MOSSY_COBBLESTONE.getDefaultState(), 53, -41, 7, start);
        structure.setBlockState(world, Blocks.MOSSY_STONE_BRICKS.getDefaultState(), 53, -41, 10, start);
        structure.setBlockState(world, Blocks.INFESTED_COBBLESTONE.getDefaultState(), 53, -41, 11, start);
        structure.setBlockState(world, Blocks.SHROOMLIGHT.getDefaultState(), 53, -41, 20, start);
        structure.setBlockState(world, Blocks.INFESTED_STONE_BRICKS.getDefaultState(), 53, -41, 21, start);
        structure.setBlockState(world, Blocks.MOSSY_COBBLESTONE.getDefaultState(), 53, -41, 22, start);
        structure.setBlockState(world, Blocks.SHROOMLIGHT.getDefaultState(), 53, -41, 32, start);
        structure.setBlockState(world, Blocks.INFESTED_CRACKED_STONE_BRICKS.getDefaultState(), 53, -41, 34, start);
        structure.setBlockState(world, Blocks.MOSSY_STONE_BRICKS.getDefaultState(), 53, -41, 57, start);
        structure.setBlockState(world, Blocks.STONE_BRICKS.getDefaultState(), 53, -41, 61, start);
        structure.setBlockState(world, Blocks.STONE_BRICKS.getDefaultState(), 53, -40, 4, start);
        structure.setBlockState(world, Blocks.MOSSY_STONE_BRICKS.getDefaultState(), 53, -40, 31, start);
        structure.setBlockState(world, Blocks.MOSSY_STONE_BRICKS.getDefaultState(), 53, -40, 36, start);
        structure.setBlockState(world, Blocks.INFESTED_COBBLESTONE.getDefaultState(), 53, -40, 37, start);
        structure.setBlockState(world, Blocks.MOSSY_STONE_BRICKS.getDefaultState(), 53, -40, 51, start);
        structure.setBlockState(world, Blocks.AIR.getDefaultState(), 53, -40, 52, start);
        structure.setBlockState(world, Blocks.INFESTED_STONE_BRICKS.getDefaultState(), 53, -40, 55, start);
        structure.setBlockState(world, Blocks.INFESTED_CRACKED_STONE_BRICKS.getDefaultState(), 53, -40, 56, start);
        structure.setBlockState(world, Blocks.MOSSY_STONE_BRICKS.getDefaultState(), 53, -40, 58, start);
        structure.setBlockState(world, Blocks.AIR.getDefaultState(), 53, -39, 4, start);
        structure.setBlockState(world, Blocks.STONE_BRICKS.getDefaultState(), 53, -39, 5, start);
        structure.setBlockState(world, Blocks.MOSSY_COBBLESTONE.getDefaultState(), 53, -39, 6, start);
        structure.setBlockState(world, Blocks.MOSSY_STONE_BRICKS.getDefaultState(), 53, -39, 19, start);
        structure.setBlockState(world, Blocks.MOSSY_COBBLESTONE.getDefaultState(), 53, -39, 20, start);
        structure.setBlockState(world, Blocks.STONE_BRICKS.getDefaultState(), 53, -39, 23, start);
        structure.setBlockState(world, Blocks.MOSSY_COBBLESTONE.getDefaultState(), 53, -39, 24, start);
        structure.setBlockState(world, Blocks.SHROOMLIGHT.getDefaultState(), 53, -39, 26, start);
        structure.setBlockState(world, Blocks.AIR.getDefaultState(), 53, -39, 30, start);
        structure.setBlockState(world, Blocks.STONE_BRICKS.getDefaultState(), 53, -39, 33, start);
        structure.setBlockState(world, Blocks.AIR.getDefaultState(), 53, -39, 34, start);
        structure.setBlockState(world, Blocks.MOSSY_COBBLESTONE.getDefaultState(), 53, -39, 36, start);
        structure.setBlockState(world, Blocks.AIR.getDefaultState(), 53, -39, 55, start);
        structure.setBlockState(world, Blocks.AIR.getDefaultState(), 53, -39, 57, start);
        structure.setBlockState(world, Blocks.MOSSY_COBBLESTONE.getDefaultState(), 53, -39, 62, start);
        structure.setBlockState(world, Blocks.MOSSY_STONE_BRICKS.getDefaultState(), 53, -39, 63, start);
        structure.setBlockState(world, Blocks.MOSSY_STONE_BRICKS.getDefaultState(), 53, -38, 9, start);
        structure.setBlockState(world, Blocks.INFESTED_CRACKED_STONE_BRICKS.getDefaultState(), 53, -38, 26, start);
        structure.setBlockState(world, Blocks.AIR.getDefaultState(), 53, -38, 37, start);
        structure.setBlockState(world, Blocks.MOSSY_STONE_BRICKS.getDefaultState(), 53, -38, 50, start);
        structure.setBlockState(world, Blocks.MOSSY_COBBLESTONE.getDefaultState(), 53, -38, 63, start);
        structure.setBlockState(world, Blocks.MOSSY_COBBLESTONE.getDefaultState(), 53, -37, 4, start);
        structure.setBlockState(world, Blocks.MOSSY_STONE_BRICKS.getDefaultState(), 53, -37, 5, start);
        structure.setBlockState(world, Blocks.STONE_BRICKS.getDefaultState(), 53, -37, 6, start);
        structure.setBlockState(world, Blocks.MOSSY_STONE_BRICKS.getDefaultState(), 53, -37, 11, start);
        structure.setBlockState(world, Blocks.STONE_BRICKS.getDefaultState(), 53, -37, 12, start);
        structure.setBlockState(world, Blocks.MOSSY_COBBLESTONE.getDefaultState(), 53, -37, 21, start);
        structure.setBlockState(world, Blocks.MOSSY_COBBLESTONE.getDefaultState(), 53, -37, 24, start);
        structure.setBlockState(world, Blocks.STONE_BRICKS.getDefaultState(), 53, -37, 27, start);
