package mod.arcalitegames.odyssey.world.structure.structures.towers.small_watch_tower;

import mod.arcalitegames.odyssey.world.structure.StructureBase;
import net.minecraft.block.AbstractButtonBlock;
import net.minecraft.block.AbstractFurnaceBlock;
import net.minecraft.block.Blocks;
import net.minecraft.block.ChestBlock;
import net.minecraft.block.DoorBlock;
import net.minecraft.block.FourWayBlock;
import net.minecraft.block.HorizontalBlock;
import net.minecraft.block.HorizontalFaceBlock;
import net.minecraft.block.LadderBlock;
import net.minecraft.block.LanternBlock;
import net.minecraft.block.PressurePlateBlock;
import net.minecraft.block.SlabBlock;
import net.minecraft.block.SnowyDirtBlock;
import net.minecraft.block.StairsBlock;
import net.minecraft.block.TrapDoorBlock;
import net.minecraft.block.WallBlock;
import net.minecraft.block.WallHeight;
import net.minecraft.block.WallTorchBlock;
import net.minecraft.state.properties.AttachFace;
import net.minecraft.state.properties.ChestType;
import net.minecraft.state.properties.DoorHingeSide;
import net.minecraft.state.properties.DoubleBlockHalf;
import net.minecraft.state.properties.Half;
import net.minecraft.state.properties.SlabType;
import net.minecraft.state.properties.StairsShape;
import net.minecraft.util.Direction;
import net.minecraft.util.math.BlockPos;
import net.minecraft.world.World;

public class SmallTowerComponents
{

	public static BlockPos start;
    public static World world;
    public static StructureBase structure;

    public static void init(World worldIn, BlockPos blockPos, StructureBase structureIn)
    {
        world = worldIn; start = blockPos; structure = structureIn;
    }
    
    public static void generatePart1()
    {
        structure.setBlockState(world, Blocks.GRASS_BLOCK.getDefaultState().with(SnowyDirtBlock.SNOWY, false), 2, 0, 6, start);
        structure.setBlockState(world, Blocks.GRASS_BLOCK.getDefaultState().with(SnowyDirtBlock.SNOWY, false), 2, 0, 16, start);
        structure.setBlockState(world, Blocks.GRASS_BLOCK.getDefaultState().with(SnowyDirtBlock.SNOWY, false), 3, 0, 4, start);
        structure.setBlockState(world, Blocks.GRASS_BLOCK.getDefaultState().with(SnowyDirtBlock.SNOWY, false), 3, 2, 7, start);
        structure.setBlockState(world, Blocks.GRASS_BLOCK.getDefaultState().with(SnowyDirtBlock.SNOWY, false), 3, 2, 15, start);
        structure.setBlockState(world, Blocks.GRASS_BLOCK.getDefaultState().with(SnowyDirtBlock.SNOWY, false), 4, 0, 3, start);
        structure.setBlockState(world, Blocks.STONE.getDefaultState(), 4, 0, 9, start);
        structure.setBlockState(world, Blocks.GRASS_BLOCK.getDefaultState().with(SnowyDirtBlock.SNOWY, false), 4, 0, 19, start);
        structure.setBlockState(world, Blocks.GRASS_BLOCK.getDefaultState().with(SnowyDirtBlock.SNOWY, false), 4, 1, 4, start);
        structure.setBlockState(world, Blocks.GRASS_BLOCK.getDefaultState().with(SnowyDirtBlock.SNOWY, false), 4, 2, 5, start);
        structure.setBlockState(world, Blocks.GRASS_BLOCK.getDefaultState().with(SnowyDirtBlock.SNOWY, false), 4, 3, 6, start);
        structure.setBlockState(world, Blocks.GRASS_BLOCK.getDefaultState().with(SnowyDirtBlock.SNOWY, false), 5, 2, 4, start);
        structure.setBlockState(world, Blocks.GRASS_BLOCK.getDefaultState().with(SnowyDirtBlock.SNOWY, false), 5, 2, 18, start);
        structure.setBlockState(world, Blocks.GRASS_BLOCK.getDefaultState().with(SnowyDirtBlock.SNOWY, false), 5, 3, 5, start);
        structure.setBlockState(world, Blocks.GRASS_BLOCK.getDefaultState().with(SnowyDirtBlock.SNOWY, false), 5, 4, 6, start);
        structure.setBlockState(world, Blocks.GRASS_BLOCK.getDefaultState().with(SnowyDirtBlock.SNOWY, false), 6, 0, 2, start);
        structure.setBlockState(world, Blocks.GRASS_BLOCK.getDefaultState().with(SnowyDirtBlock.SNOWY, false), 6, 0, 20, start);
        structure.setBlockState(world, Blocks.STONE.getDefaultState(), 6, 1, 16, start);
        structure.setBlockState(world, Blocks.GRASS_BLOCK.getDefaultState().with(SnowyDirtBlock.SNOWY, false), 6, 3, 4, start);
        structure.setBlockState(world, Blocks.GRASS_BLOCK.getDefaultState().with(SnowyDirtBlock.SNOWY, false), 6, 3, 18, start);
        structure.setBlockState(world, Blocks.GRASS_BLOCK.getDefaultState().with(SnowyDirtBlock.SNOWY, false), 6, 4, 5, start);
        structure.setBlockState(world, Blocks.AIR.getDefaultState(), 6, 7, 11, start);
        structure.setBlockState(world, Blocks.GRASS_BLOCK.getDefaultState().with(SnowyDirtBlock.SNOWY, false), 7, 2, 3, start);
        structure.setBlockState(world, Blocks.GRASS_BLOCK.getDefaultState().with(SnowyDirtBlock.SNOWY, false), 7, 2, 19, start);
        structure.setBlockState(world, Blocks.STONE_BRICK_STAIRS.getDefaultState().with(StairsBlock.FACING, Direction.EAST).with(StairsBlock.WATERLOGGED, false).with(StairsBlock.SHAPE, StairsShape.STRAIGHT).with(StairsBlock.HALF, Half.BOTTOM), 7, 7, 10, start);
        structure.setBlockState(world, Blocks.COBBLESTONE_SLAB.getDefaultState().with(SlabBlock.TYPE, SlabType.BOTTOM).with(SlabBlock.WATERLOGGED, false), 7, 7, 11, start);
        structure.setBlockState(world, Blocks.DIORITE.getDefaultState(), 8, 6, 12, start);
        structure.setBlockState(world, Blocks.STONE_BRICK_STAIRS.getDefaultState().with(StairsBlock.FACING, Direction.EAST).with(StairsBlock.WATERLOGGED, false).with(StairsBlock.SHAPE, StairsShape.STRAIGHT).with(StairsBlock.HALF, Half.BOTTOM), 8, 7, 9, start);
        structure.setBlockState(world, Blocks.STONE_BRICK_STAIRS.getDefaultState().with(StairsBlock.FACING, Direction.EAST).with(StairsBlock.WATERLOGGED, false).with(StairsBlock.SHAPE, StairsShape.STRAIGHT).with(StairsBlock.HALF, Half.BOTTOM), 8, 7, 13, start);
        structure.setBlockState(world, Blocks.DARK_OAK_STAIRS.getDefaultState().with(StairsBlock.FACING, Direction.SOUTH).with(StairsBlock.WATERLOGGED, false).with(StairsBlock.SHAPE, StairsShape.STRAIGHT).with(StairsBlock.HALF, Half.BOTTOM), 8, 15, 10, start);
        structure.setBlockState(world, Blocks.DARK_OAK_LOG.getDefaultState(), 8, 15, 11, start);
        structure.setBlockState(world, Blocks.DARK_OAK_STAIRS.getDefaultState().with(StairsBlock.FACING, Direction.NORTH).with(StairsBlock.WATERLOGGED, false).with(StairsBlock.SHAPE, StairsShape.STRAIGHT).with(StairsBlock.HALF, Half.BOTTOM), 8, 15, 12, start);
        structure.setBlockState(world, Blocks.DARK_OAK_SLAB.getDefaultState().with(SlabBlock.TYPE, SlabType.BOTTOM).with(SlabBlock.WATERLOGGED, false), 8, 16, 11, start);
        structure.setBlockState(world, Blocks.LANTERN.getDefaultState().with(LanternBlock.WATERLOGGED, false).with(LanternBlock.HANGING, true), 8, 22, 10, start);
        structure.setBlockState(world, Blocks.LANTERN.getDefaultState().with(LanternBlock.WATERLOGGED, false).with(LanternBlock.HANGING, true), 8, 22, 12, start);
        structure.setBlockState(world, Blocks.STONE_BRICK_WALL.getDefaultState().with(WallBlock.WATERLOGGED, false).with(WallBlock.UP, true).with(WallBlock.WALL_HEIGHT_NORTH, WallHeight.LOW).with(WallBlock.WALL_HEIGHT_SOUTH, WallHeight.LOW).with(WallBlock.WALL_HEIGHT_EAST, WallHeight.LOW).with(WallBlock.WALL_HEIGHT_WEST, WallHeight.LOW), 8, 23, 10, start);
        structure.setBlockState(world, Blocks.STONE_BRICK_WALL.getDefaultState().with(WallBlock.WATERLOGGED, false).with(WallBlock.UP, true).with(WallBlock.WALL_HEIGHT_NORTH, WallHeight.LOW).with(WallBlock.WALL_HEIGHT_SOUTH, WallHeight.LOW).with(WallBlock.WALL_HEIGHT_EAST, WallHeight.LOW).with(WallBlock.WALL_HEIGHT_WEST, WallHeight.LOW), 8, 23, 12, start);
        structure.setBlockState(world, Blocks.STONE.getDefaultState(), 9, 0, 18, start);
        structure.setBlockState(world, Blocks.OAK_TRAPDOOR.getDefaultState().with(HorizontalBlock.HORIZONTAL_FACING, Direction.EAST).with(TrapDoorBlock.HALF, Half.TOP).with(TrapDoorBlock.WATERLOGGED, false).with(TrapDoorBlock.POWERED, false).with(TrapDoorBlock.OPEN, false), 9, 6, 12, start);
        structure.setBlockState(world, Blocks.COBBLESTONE_SLAB.getDefaultState().with(SlabBlock.TYPE, SlabType.BOTTOM).with(SlabBlock.WATERLOGGED, false), 9, 7, 8, start);
        structure.setBlockState(world, Blocks.COBBLESTONE_SLAB.getDefaultState().with(SlabBlock.TYPE, SlabType.BOTTOM).with(SlabBlock.WATERLOGGED, false), 9, 7, 14, start);
        structure.setBlockState(world, Blocks.WALL_TORCH.getDefaultState().with(WallTorchBlock.HORIZONTAL_FACING, Direction.EAST), 9, 9, 12, start);
        structure.setBlockState(world, Blocks.COBBLESTONE.getDefaultState(), 9, 14, 9, start);
        structure.setBlockState(world, Blocks.COBBLESTONE.getDefaultState(), 9, 14, 13, start);
        structure.setBlockState(world, Blocks.COBBLESTONE_STAIRS.getDefaultState().with(StairsBlock.FACING, Direction.WEST).with(StairsBlock.WATERLOGGED, false).with(StairsBlock.SHAPE, StairsShape.STRAIGHT).with(StairsBlock.HALF, Half.TOP), 9, 15, 11, start);
        structure.setBlockState(world, Blocks.STONE_BRICK_WALL.getDefaultState().with(WallBlock.WATERLOGGED, false).with(WallBlock.UP, true).with(WallBlock.WALL_HEIGHT_NORTH, WallHeight.LOW).with(WallBlock.WALL_HEIGHT_SOUTH, WallHeight.LOW).with(WallBlock.WALL_HEIGHT_EAST, WallHeight.LOW).with(WallBlock.WALL_HEIGHT_WEST, WallHeight.LOW), 9, 18, 9, start);
        structure.setBlockState(world, Blocks.STONE_BRICK_WALL.getDefaultState().with(WallBlock.WATERLOGGED, false).with(WallBlock.UP, true).with(WallBlock.WALL_HEIGHT_NORTH, WallHeight.LOW).with(WallBlock.WALL_HEIGHT_SOUTH, WallHeight.LOW).with(WallBlock.WALL_HEIGHT_EAST, WallHeight.LOW).with(WallBlock.WALL_HEIGHT_WEST, WallHeight.LOW), 9, 21, 9, start);
        structure.setBlockState(world, Blocks.STONE_BRICK_WALL.getDefaultState().with(WallBlock.WATERLOGGED, false).with(WallBlock.UP, true).with(WallBlock.WALL_HEIGHT_NORTH, WallHeight.LOW).with(WallBlock.WALL_HEIGHT_SOUTH, WallHeight.LOW).with(WallBlock.WALL_HEIGHT_EAST, WallHeight.LOW).with(WallBlock.WALL_HEIGHT_WEST, WallHeight.LOW), 9, 21, 13, start);
        structure.setBlockState(world, Blocks.COBBLESTONE_WALL.getDefaultState().with(WallBlock.WATERLOGGED, false).with(WallBlock.UP, true).with(WallBlock.WALL_HEIGHT_NORTH, WallHeight.LOW).with(WallBlock.WALL_HEIGHT_SOUTH, WallHeight.LOW).with(WallBlock.WALL_HEIGHT_EAST, WallHeight.LOW).with(WallBlock.WALL_HEIGHT_WEST, WallHeight.LOW), 9, 27, 9, start);
        structure.setBlockState(world, Blocks.COBBLESTONE_WALL.getDefaultState().with(WallBlock.WATERLOGGED, false).with(WallBlock.UP, true).with(WallBlock.WALL_HEIGHT_NORTH, WallHeight.LOW).with(WallBlock.WALL_HEIGHT_SOUTH, WallHeight.LOW).with(WallBlock.WALL_HEIGHT_EAST, WallHeight.LOW).with(WallBlock.WALL_HEIGHT_WEST, WallHeight.LOW), 9, 27, 11, start);
        structure.setBlockState(world, Blocks.COBBLESTONE_WALL.getDefaultState().with(WallBlock.WATERLOGGED, false).with(WallBlock.UP, true).with(WallBlock.WALL_HEIGHT_NORTH, WallHeight.LOW).with(WallBlock.WALL_HEIGHT_SOUTH, WallHeight.LOW).with(WallBlock.WALL_HEIGHT_EAST, WallHeight.LOW).with(WallBlock.WALL_HEIGHT_WEST, WallHeight.LOW), 9, 27, 13, start);
        structure.setBlockState(world, Blocks.GRASS_BLOCK.getDefaultState().with(SnowyDirtBlock.SNOWY, false), 10, 5, 7, start);
        structure.setBlockState(world, Blocks.DIORITE.getDefaultState(), 10, 6, 14, start);
        structure.setBlockState(world, Blocks.DIRT.getDefaultState(), 10, 6, 15, start);
        structure.setBlockState(world, Blocks.STONE_BRICK_STAIRS.getDefaultState().with(StairsBlock.FACING, Direction.NORTH).with(StairsBlock.WATERLOGGED, false).with(StairsBlock.SHAPE, StairsShape.STRAIGHT).with(StairsBlock.HALF, Half.BOTTOM), 10, 7, 15, start);
        structure.setBlockState(world, Blocks.WALL_TORCH.getDefaultState().with(WallTorchBlock.HORIZONTAL_FACING, Direction.SOUTH), 10, 9, 9, start);
        structure.setBlockState(world, Blocks.WALL_TORCH.getDefaultState().with(WallTorchBlock.HORIZONTAL_FACING, Direction.NORTH), 10, 9, 13, start);
        structure.setBlockState(world, Blocks.DARK_OAK_SLAB.getDefaultState().with(SlabBlock.TYPE, SlabType.BOTTOM).with(SlabBlock.WATERLOGGED, false), 10, 12, 13, start);
        structure.setBlockState(world, Blocks.LANTERN.getDefaultState().with(LanternBlock.WATERLOGGED, false).with(LanternBlock.HANGING, true), 10, 14, 13, start);
        structure.setBlockState(world, Blocks.DARK_OAK_STAIRS.getDefaultState().with(StairsBlock.FACING, Direction.EAST).with(StairsBlock.WATERLOGGED, false).with(StairsBlock.SHAPE, StairsShape.STRAIGHT).with(StairsBlock.HALF, Half.BOTTOM), 10, 18, 8, start);
        structure.setBlockState(world, Blocks.DARK_OAK_STAIRS.getDefaultState().with(StairsBlock.FACING, Direction.EAST).with(StairsBlock.WATERLOGGED, false).with(StairsBlock.SHAPE, StairsShape.STRAIGHT).with(StairsBlock.HALF, Half.BOTTOM), 10, 18, 14, start);
        structure.setBlockState(world, Blocks.LANTERN.getDefaultState().with(LanternBlock.WATERLOGGED, false).with(LanternBlock.HANGING, true), 10, 19, 11, start);
        structure.setBlockState(world, Blocks.DARK_OAK_SLAB.getDefaultState().with(SlabBlock.TYPE, SlabType.DOUBLE).with(SlabBlock.WATERLOGGED, false), 10, 20, 12, start);
        structure.setBlockState(world, Blocks.CRAFTING_TABLE.getDefaultState(), 10, 21, 10, start);
        structure.setBlockState(world, Blocks.LANTERN.getDefaultState().with(LanternBlock.WATERLOGGED, false).with(LanternBlock.HANGING, true), 10, 22, 8, start);
        structure.setBlockState(world, Blocks.LANTERN.getDefaultState().with(LanternBlock.WATERLOGGED, false).with(LanternBlock.HANGING, true), 10, 22, 14, start);
        structure.setBlockState(world, Blocks.STONE_BRICK_WALL.getDefaultState().with(WallBlock.WATERLOGGED, false).with(WallBlock.UP, true).with(WallBlock.WALL_HEIGHT_NORTH, WallHeight.LOW).with(WallBlock.WALL_HEIGHT_SOUTH, WallHeight.LOW).with(WallBlock.WALL_HEIGHT_EAST, WallHeight.LOW).with(WallBlock.WALL_HEIGHT_WEST, WallHeight.LOW), 10, 23, 8, start);
        structure.setBlockState(world, Blocks.STONE_BRICK_WALL.getDefaultState().with(WallBlock.WATERLOGGED, false).with(WallBlock.UP, true).with(WallBlock.WALL_HEIGHT_NORTH, WallHeight.LOW).with(WallBlock.WALL_HEIGHT_SOUTH, WallHeight.LOW).with(WallBlock.WALL_HEIGHT_EAST, WallHeight.LOW).with(WallBlock.WALL_HEIGHT_WEST, WallHeight.LOW), 10, 23, 14, start);
        structure.setBlockState(world, Blocks.LANTERN.getDefaultState().with(LanternBlock.WATERLOGGED, false).with(LanternBlock.HANGING, true), 10, 24, 10, start);
        structure.setBlockState(world, Blocks.LANTERN.getDefaultState().with(LanternBlock.WATERLOGGED, false).with(LanternBlock.HANGING, true), 10, 24, 12, start);
        structure.setBlockState(world, Blocks.DARK_OAK_SLAB.getDefaultState().with(SlabBlock.TYPE, SlabType.DOUBLE).with(SlabBlock.WATERLOGGED, false), 10, 25, 10, start);
        structure.setBlockState(world, Blocks.LANTERN.getDefaultState().with(LanternBlock.WATERLOGGED, false).with(LanternBlock.HANGING, false), 10, 26, 10, start);
        structure.setBlockState(world, Blocks.GRASS_BLOCK.getDefaultState().with(SnowyDirtBlock.SNOWY, false), 11, 5, 15, start);
        structure.setBlockState(world, Blocks.COBBLESTONE.getDefaultState(), 11, 6, 8, start);
        structure.setBlockState(world, Blocks.COBBLESTONE_SLAB.getDefaultState().with(SlabBlock.TYPE, SlabType.TOP).with(SlabBlock.WATERLOGGED, false), 11, 6, 15, start);
        structure.setBlockState(world, Blocks.AIR.getDefaultState(), 11, 7, 6, start);
        structure.setBlockState(world, Blocks.IRON_DOOR.getDefaultState().with(DoorBlock.FACING, Direction.SOUTH).with(DoorBlock.HALF, DoubleBlockHalf.LOWER).with(DoorBlock.HINGE, DoorHingeSide.LEFT).with(DoorBlock.OPEN, false).with(DoorBlock.POWERED, false), 11, 7, 8, start);
        structure.setBlockState(world, Blocks.OAK_PRESSURE_PLATE.getDefaultState().with(PressurePlateBlock.POWERED, false), 11, 7, 9, start);
        structure.setBlockState(world, Blocks.AIR.getDefaultState(), 11, 7, 11, start);
        structure.setBlockState(world, Blocks.AIR.getDefaultState(), 11, 7, 16, start);
        structure.setBlockState(world, Blocks.IRON_DOOR.getDefaultState().with(DoorBlock.FACING, Direction.SOUTH).with(DoorBlock.HALF, DoubleBlockHalf.UPPER).with(DoorBlock.HINGE, DoorHingeSide.LEFT).with(DoorBlock.OPEN, false).with(DoorBlock.POWERED, false), 11, 8, 8, start);
        structure.setBlockState(world, Blocks.LANTERN.getDefaultState().with(LanternBlock.WATERLOGGED, false).with(LanternBlock.HANGING, true), 11, 12, 7, start);
        structure.setBlockState(world, Blocks.DARK_OAK_SLAB.getDefaultState().with(SlabBlock.TYPE, SlabType.DOUBLE).with(SlabBlock.WATERLOGGED, false), 11, 12, 13, start);
        structure.setBlockState(world, Blocks.LANTERN.getDefaultState().with(LanternBlock.WATERLOGGED, false).with(LanternBlock.HANGING, true), 11, 12, 15, start);
        structure.setBlockState(world, Blocks.COBBLESTONE_WALL.getDefaultState().with(WallBlock.WATERLOGGED, false).with(WallBlock.UP, true).with(WallBlock.WALL_HEIGHT_NORTH, WallHeight.LOW).with(WallBlock.WALL_HEIGHT_SOUTH, WallHeight.LOW).with(WallBlock.WALL_HEIGHT_EAST, WallHeight.LOW).with(WallBlock.WALL_HEIGHT_WEST, WallHeight.LOW), 11, 13, 7, start);
        structure.setBlockState(world, Blocks.AIR.getDefaultState(), 11, 13, 11, start);
        structure.setBlockState(world, Blocks.COBBLESTONE_WALL.getDefaultState().with(WallBlock.WATERLOGGED, false).with(WallBlock.UP, true).with(WallBlock.WALL_HEIGHT_NORTH, WallHeight.LOW).with(WallBlock.WALL_HEIGHT_SOUTH, WallHeight.LOW).with(WallBlock.WALL_HEIGHT_EAST, WallHeight.LOW).with(WallBlock.WALL_HEIGHT_WEST, WallHeight.LOW), 11, 13, 15, start);
        structure.setBlockState(world, Blocks.LANTERN.getDefaultState().with(LanternBlock.WATERLOGGED, false).with(LanternBlock.HANGING, true), 11, 14, 9, start);
        structure.setBlockState(world, Blocks.DARK_OAK_LOG.getDefaultState(), 11, 18, 14, start);
        structure.setBlockState(world, Blocks.DARK_OAK_SLAB.getDefaultState().with(SlabBlock.TYPE, SlabType.BOTTOM).with(SlabBlock.WATERLOGGED, false), 11, 19, 8, start);
        structure.setBlockState(world, Blocks.DARK_OAK_SLAB.getDefaultState().with(SlabBlock.TYPE, SlabType.BOTTOM).with(SlabBlock.WATERLOGGED, false), 11, 19, 14, start);
        structure.setBlockState(world, Blocks.AIR.getDefaultState(), 11, 21, 10, start);
        structure.setBlockState(world, Blocks.COBBLESTONE_WALL.getDefaultState().with(WallBlock.WATERLOGGED, false).with(WallBlock.UP, true).with(WallBlock.WALL_HEIGHT_NORTH, WallHeight.LOW).with(WallBlock.WALL_HEIGHT_SOUTH, WallHeight.LOW).with(WallBlock.WALL_HEIGHT_EAST, WallHeight.LOW).with(WallBlock.WALL_HEIGHT_WEST, WallHeight.LOW), 11, 27, 9, start);
        structure.setBlockState(world, Blocks.COBBLESTONE_WALL.getDefaultState().with(WallBlock.WATERLOGGED, false).with(WallBlock.UP, true).with(WallBlock.WALL_HEIGHT_NORTH, WallHeight.LOW).with(WallBlock.WALL_HEIGHT_SOUTH, WallHeight.LOW).with(WallBlock.WALL_HEIGHT_EAST, WallHeight.LOW).with(WallBlock.WALL_HEIGHT_WEST, WallHeight.LOW), 11, 27, 13, start);
        structure.setBlockState(world, Blocks.GRASS_BLOCK.getDefaultState().with(SnowyDirtBlock.SNOWY, false), 12, 5, 7, start);
        structure.setBlockState(world, Blocks.DIORITE.getDefaultState(), 12, 6, 14, start);
        structure.setBlockState(world, Blocks.DIRT.getDefaultState(), 12, 6, 15, start);
        structure.setBlockState(world, Blocks.STONE_BRICK_STAIRS.getDefaultState().with(StairsBlock.FACING, Direction.NORTH).with(StairsBlock.WATERLOGGED, false).with(StairsBlock.SHAPE, StairsShape.STRAIGHT).with(StairsBlock.HALF, Half.BOTTOM), 12, 7, 15, start);
        structure.setBlockState(world, Blocks.OAK_BUTTON.getDefaultState().with(HorizontalBlock.HORIZONTAL_FACING, Direction.NORTH).with(HorizontalFaceBlock.FACE, AttachFace.WALL).with(AbstractButtonBlock.POWERED, false), 12, 8, 7, start);
        structure.setBlockState(world, Blocks.WALL_TORCH.getDefaultState().with(WallTorchBlock.HORIZONTAL_FACING, Direction.SOUTH), 12, 9, 9, start);
        structure.setBlockState(world, Blocks.WALL_TORCH.getDefaultState().with(WallTorchBlock.HORIZONTAL_FACING, Direction.NORTH), 12, 9, 13, start);
        structure.setBlockState(world, Blocks.DARK_OAK_SLAB.getDefaultState().with(SlabBlock.TYPE, SlabType.BOTTOM).with(SlabBlock.WATERLOGGED, false), 12, 12, 13, start);
        structure.setBlockState(world, Blocks.LANTERN.getDefaultState().with(LanternBlock.WATERLOGGED, false).with(LanternBlock.HANGING, true), 12, 14, 13, start);
        structure.setBlockState(world, Blocks.DARK_OAK_STAIRS.getDefaultState().with(StairsBlock.FACING, Direction.WEST).with(StairsBlock.WATERLOGGED, false).with(StairsBlock.SHAPE, StairsShape.STRAIGHT).with(StairsBlock.HALF, Half.BOTTOM), 12, 18, 8, start);
        structure.setBlockState(world, Blocks.DARK_OAK_STAIRS.getDefaultState().with(StairsBlock.FACING, Direction.WEST).with(StairsBlock.WATERLOGGED, false).with(StairsBlock.SHAPE, StairsShape.STRAIGHT).with(StairsBlock.HALF, Half.BOTTOM), 12, 18, 14, start);
        structure.setBlockState(world, Blocks.LANTERN.getDefaultState().with(LanternBlock.WATERLOGGED, false).with(LanternBlock.HANGING, true), 12, 19, 11, start);
        structure.setBlockState(world, Blocks.AIR.getDefaultState(), 12, 21, 10, start);
        structure.setBlockState(world, Blocks.LANTERN.getDefaultState().with(LanternBlock.WATERLOGGED, false).with(LanternBlock.HANGING, true), 12, 22, 8, start);
        structure.setBlockState(world, Blocks.LANTERN.getDefaultState().with(LanternBlock.WATERLOGGED, false).with(LanternBlock.HANGING, true), 12, 22, 14, start);
        structure.setBlockState(world, Blocks.STONE_BRICK_WALL.getDefaultState().with(WallBlock.WATERLOGGED, false).with(WallBlock.UP, true).with(WallBlock.WALL_HEIGHT_NORTH, WallHeight.LOW).with(WallBlock.WALL_HEIGHT_SOUTH, WallHeight.LOW).with(WallBlock.WALL_HEIGHT_EAST, WallHeight.LOW).with(WallBlock.WALL_HEIGHT_WEST, WallHeight.LOW), 12, 23, 8, start);
        structure.setBlockState(world, Blocks.STONE_BRICK_WALL.getDefaultState().with(WallBlock.WATERLOGGED, false).with(WallBlock.UP, true).with(WallBlock.WALL_HEIGHT_NORTH, WallHeight.LOW).with(WallBlock.WALL_HEIGHT_SOUTH, WallHeight.LOW).with(WallBlock.WALL_HEIGHT_EAST, WallHeight.LOW).with(WallBlock.WALL_HEIGHT_WEST, WallHeight.LOW), 12, 23, 14, start);
        structure.setBlockState(world, Blocks.LANTERN.getDefaultState().with(LanternBlock.WATERLOGGED, false).with(LanternBlock.HANGING, true), 12, 24, 10, start);
        structure.setBlockState(world, Blocks.DARK_OAK_SLAB.getDefaultState().with(SlabBlock.TYPE, SlabType.DOUBLE).with(SlabBlock.WATERLOGGED, false), 12, 25, 10, start);
        structure.setBlockState(world, Blocks.DARK_OAK_SLAB.getDefaultState().with(SlabBlock.TYPE, SlabType.BOTTOM).with(SlabBlock.WATERLOGGED, false), 12, 25, 11, start);
        structure.setBlockState(world, Blocks.OAK_TRAPDOOR.getDefaultState().with(HorizontalBlock.HORIZONTAL_FACING, Direction.WEST).with(TrapDoorBlock.HALF, Half.BOTTOM).with(TrapDoorBlock.WATERLOGGED, false).with(TrapDoorBlock.POWERED, false).with(TrapDoorBlock.OPEN, true), 12, 25, 12, start);
        structure.setBlockState(world, Blocks.LANTERN.getDefaultState().with(LanternBlock.WATERLOGGED, false).with(LanternBlock.HANGING, false), 12, 26, 10, start);
        structure.setBlockState(world, Blocks.STONE.getDefaultState(), 13, 0, 4, start);
        structure.setBlockState(world, Blocks.STONE.getDefaultState(), 13, 0, 18, start);
        structure.setBlockState(world, Blocks.DIRT.getDefaultState(), 13, 6, 14, start);
        structure.setBlockState(world, Blocks.CRAFTING_TABLE.getDefaultState(), 13, 7, 10, start);
        structure.setBlockState(world, Blocks.CHEST.getDefaultState().with(ChestBlock.FACING, Direction.WEST).with(ChestBlock.WATERLOGGED, false).with(ChestBlock.TYPE, ChestType.RIGHT), 13, 7, 11, start);
        structure.setBlockState(world, Blocks.CHEST.getDefaultState().with(ChestBlock.FACING, Direction.WEST).with(ChestBlock.WATERLOGGED, false).with(ChestBlock.TYPE, ChestType.LEFT), 13, 7, 12, start);
        structure.setBlockState(world, Blocks.COBBLESTONE_SLAB.getDefaultState().with(SlabBlock.TYPE, SlabType.BOTTOM).with(SlabBlock.WATERLOGGED, false), 13, 7, 14, start);
        structure.setBlockState(world, Blocks.FURNACE.getDefaultState().with(AbstractFurnaceBlock.FACING, Direction.WEST).with(AbstractFurnaceBlock.LIT, false), 13, 8, 10, start);
        structure.setBlockState(world, Blocks.WALL_TORCH.getDefaultState().with(WallTorchBlock.HORIZONTAL_FACING, Direction.WEST), 13, 10, 10, start);
        structure.setBlockState(world, Blocks.WALL_TORCH.getDefaultState().with(WallTorchBlock.HORIZONTAL_FACING, Direction.WEST), 13, 10, 12, start);
        structure.setBlockState(world, Blocks.COBBLESTONE.getDefaultState(), 13, 14, 9, start);
        structure.setBlockState(world, Blocks.LANTERN.getDefaultState().with(LanternBlock.WATERLOGGED, false).with(LanternBlock.HANGING, true), 13, 14, 11, start);
        structure.setBlockState(world, Blocks.COBBLESTONE.getDefaultState(), 13, 14, 13, start);
        structure.setBlockState(world, Blocks.STONE_BRICK_WALL.getDefaultState().with(WallBlock.WATERLOGGED, false).with(WallBlock.UP, true).with(WallBlock.WALL_HEIGHT_NORTH, WallHeight.LOW).with(WallBlock.WALL_HEIGHT_SOUTH, WallHeight.LOW).with(WallBlock.WALL_HEIGHT_EAST, WallHeight.LOW).with(WallBlock.WALL_HEIGHT_WEST, WallHeight.LOW), 13, 19, 13, start);
        structure.setBlockState(world, Blocks.STONE_BRICK_WALL.getDefaultState().with(WallBlock.WATERLOGGED, false).with(WallBlock.UP, true).with(WallBlock.WALL_HEIGHT_NORTH, WallHeight.LOW).with(WallBlock.WALL_HEIGHT_SOUTH, WallHeight.LOW).with(WallBlock.WALL_HEIGHT_EAST, WallHeight.LOW).with(WallBlock.WALL_HEIGHT_WEST, WallHeight.LOW), 13, 20, 13, start);
        structure.setBlockState(world, Blocks.STONE_BRICK_WALL.getDefaultState().with(WallBlock.WATERLOGGED, false).with(WallBlock.UP, true).with(WallBlock.WALL_HEIGHT_NORTH, WallHeight.LOW).with(WallBlock.WALL_HEIGHT_SOUTH, WallHeight.LOW).with(WallBlock.WALL_HEIGHT_EAST, WallHeight.LOW).with(WallBlock.WALL_HEIGHT_WEST, WallHeight.LOW), 13, 21, 13, start);
        structure.setBlockState(world, Blocks.COBBLESTONE_WALL.getDefaultState().with(WallBlock.WATERLOGGED, false).with(WallBlock.UP, true).with(WallBlock.WALL_HEIGHT_NORTH, WallHeight.LOW).with(WallBlock.WALL_HEIGHT_SOUTH, WallHeight.LOW).with(WallBlock.WALL_HEIGHT_EAST, WallHeight.LOW).with(WallBlock.WALL_HEIGHT_WEST, WallHeight.LOW), 13, 27, 9, start);
        structure.setBlockState(world, Blocks.COBBLESTONE_WALL.getDefaultState().with(WallBlock.WATERLOGGED, false).with(WallBlock.UP, true).with(WallBlock.WALL_HEIGHT_NORTH, WallHeight.LOW).with(WallBlock.WALL_HEIGHT_SOUTH, WallHeight.LOW).with(WallBlock.WALL_HEIGHT_EAST, WallHeight.LOW).with(WallBlock.WALL_HEIGHT_WEST, WallHeight.LOW), 13, 27, 11, start);
        structure.setBlockState(world, Blocks.COBBLESTONE_WALL.getDefaultState().with(WallBlock.WATERLOGGED, false).with(WallBlock.UP, true).with(WallBlock.WALL_HEIGHT_NORTH, WallHeight.LOW).with(WallBlock.WALL_HEIGHT_SOUTH, WallHeight.LOW).with(WallBlock.WALL_HEIGHT_EAST, WallHeight.LOW).with(WallBlock.WALL_HEIGHT_WEST, WallHeight.LOW), 13, 27, 13, start);
        structure.setBlockState(world, Blocks.DIORITE.getDefaultState(), 14, 6, 12, start);
        structure.setBlockState(world, Blocks.DIRT.getDefaultState(), 14, 6, 13, start);
        structure.setBlockState(world, Blocks.COBBLESTONE_SLAB.getDefaultState().with(SlabBlock.TYPE, SlabType.BOTTOM).with(SlabBlock.WATERLOGGED, false), 14, 7, 9, start);
        structure.setBlockState(world, Blocks.COBBLESTONE_SLAB.getDefaultState().with(SlabBlock.TYPE, SlabType.BOTTOM).with(SlabBlock.WATERLOGGED, false), 14, 7, 13, start);
        structure.setBlockState(world, Blocks.DANDELION.getDefaultState(), 14, 7, 15, start);
        structure.setBlockState(world, Blocks.DARK_OAK_STAIRS.getDefaultState().with(StairsBlock.FACING, Direction.SOUTH).with(StairsBlock.WATERLOGGED, false).with(StairsBlock.SHAPE, StairsShape.STRAIGHT).with(StairsBlock.HALF, Half.BOTTOM), 14, 18, 10, start);
        structure.setBlockState(world, Blocks.DARK_OAK_LOG.getDefaultState(), 14, 18, 11, start);
        structure.setBlockState(world, Blocks.DARK_OAK_STAIRS.getDefaultState().with(StairsBlock.FACING, Direction.NORTH).with(StairsBlock.WATERLOGGED, false).with(StairsBlock.SHAPE, StairsShape.STRAIGHT).with(StairsBlock.HALF, Half.BOTTOM), 14, 18, 12, start);
        structure.setBlockState(world, Blocks.DARK_OAK_SLAB.getDefaultState().with(SlabBlock.TYPE, SlabType.BOTTOM).with(SlabBlock.WATERLOGGED, false), 14, 19, 11, start);
        structure.setBlockState(world, Blocks.LANTERN.getDefaultState().with(LanternBlock.WATERLOGGED, false).with(LanternBlock.HANGING, true), 14, 22, 10, start);
        structure.setBlockState(world, Blocks.LANTERN.getDefaultState().with(LanternBlock.WATERLOGGED, false).with(LanternBlock.HANGING, true), 14, 22, 12, start);
        structure.setBlockState(world, Blocks.STONE_BRICK_WALL.getDefaultState().with(WallBlock.WATERLOGGED, false).with(WallBlock.UP, true).with(WallBlock.WALL_HEIGHT_NORTH, WallHeight.LOW).with(WallBlock.WALL_HEIGHT_SOUTH, WallHeight.LOW).with(WallBlock.WALL_HEIGHT_EAST, WallHeight.LOW).with(WallBlock.WALL_HEIGHT_WEST, WallHeight.LOW), 14, 23, 10, start);
        structure.setBlockState(world, Blocks.STONE_BRICK_WALL.getDefaultState().with(WallBlock.WATERLOGGED, false).with(WallBlock.UP, true).with(WallBlock.WALL_HEIGHT_NORTH, WallHeight.LOW).with(WallBlock.WALL_HEIGHT_SOUTH, WallHeight.LOW).with(WallBlock.WALL_HEIGHT_EAST, WallHeight.LOW).with(WallBlock.WALL_HEIGHT_WEST, WallHeight.LOW), 14, 23, 12, start);
        structure.setBlockState(world, Blocks.STONE.getDefaultState(), 15, 0, 5, start);
        structure.setBlockState(world, Blocks.STONE.getDefaultState(), 15, 0, 17, start);
        structure.setBlockState(world, Blocks.GRASS_BLOCK.getDefaultState().with(SnowyDirtBlock.SNOWY, false), 15, 2, 3, start);
        structure.setBlockState(world, Blocks.GRASS_BLOCK.getDefaultState().with(SnowyDirtBlock.SNOWY, false), 15, 2, 19, start);
        structure.setBlockState(world, Blocks.STONE_BRICK_STAIRS.getDefaultState().with(StairsBlock.FACING, Direction.WEST).with(StairsBlock.WATERLOGGED, false).with(StairsBlock.SHAPE, StairsShape.STRAIGHT).with(StairsBlock.HALF, Half.BOTTOM), 15, 7, 10, start);
        structure.setBlockState(world, Blocks.COBBLESTONE_SLAB.getDefaultState().with(SlabBlock.TYPE, SlabType.BOTTOM).with(SlabBlock.WATERLOGGED, false), 15, 7, 11, start);
        structure.setBlockState(world, Blocks.STONE_BRICK_STAIRS.getDefaultState().with(StairsBlock.FACING, Direction.WEST).with(StairsBlock.WATERLOGGED, false).with(StairsBlock.SHAPE, StairsShape.STRAIGHT).with(StairsBlock.HALF, Half.BOTTOM), 15, 7, 12, start);
        structure.setBlockState(world, Blocks.LANTERN.getDefaultState().with(LanternBlock.WATERLOGGED, false).with(LanternBlock.HANGING, true), 15, 12, 11, start);
        structure.setBlockState(world, Blocks.COBBLESTONE_WALL.getDefaultState().with(WallBlock.WATERLOGGED, false).with(WallBlock.UP, true).with(WallBlock.WALL_HEIGHT_NORTH, WallHeight.LOW).with(WallBlock.WALL_HEIGHT_SOUTH, WallHeight.LOW).with(WallBlock.WALL_HEIGHT_EAST, WallHeight.LOW).with(WallBlock.WALL_HEIGHT_WEST, WallHeight.LOW), 15, 13, 11, start);
        structure.setBlockState(world, Blocks.GRASS_BLOCK.getDefaultState().with(SnowyDirtBlock.SNOWY, false), 16, 0, 2, start);
        structure.setBlockState(world, Blocks.GRASS_BLOCK.getDefaultState().with(SnowyDirtBlock.SNOWY, false), 16, 0, 20, start);
        structure.setBlockState(world, Blocks.GRASS_BLOCK.getDefaultState().with(SnowyDirtBlock.SNOWY, false), 16, 3, 18, start);
        structure.setBlockState(world, Blocks.GRASS_BLOCK.getDefaultState().with(SnowyDirtBlock.SNOWY, false), 16, 4, 17, start);
        structure.setBlockState(world, Blocks.AIR.getDefaultState(), 16, 7, 11, start);
        structure.setBlockState(world, Blocks.STONE.getDefaultState(), 17, 0, 15, start);
        structure.setBlockState(world, Blocks.GRASS_BLOCK.getDefaultState().with(SnowyDirtBlock.SNOWY, false), 17, 2, 18, start);
        structure.setBlockState(world, Blocks.GRASS_BLOCK.getDefaultState().with(SnowyDirtBlock.SNOWY, false), 17, 3, 17, start);
        structure.setBlockState(world, Blocks.GRASS_BLOCK.getDefaultState().with(SnowyDirtBlock.SNOWY, false), 17, 4, 16, start);
        structure.setBlockState(world, Blocks.GRASS_BLOCK.getDefaultState().with(SnowyDirtBlock.SNOWY, false), 18, 0, 19, start);
        structure.setBlockState(world, Blocks.GRASS_BLOCK.getDefaultState().with(SnowyDirtBlock.SNOWY, false), 18, 1, 18, start);
        structure.setBlockState(world, Blocks.GRASS_BLOCK.getDefaultState().with(SnowyDirtBlock.SNOWY, false), 18, 2, 5, start);
        structure.setBlockState(world, Blocks.GRASS_BLOCK.getDefaultState().with(SnowyDirtBlock.SNOWY, false), 18, 2, 17, start);
        structure.setBlockState(world, Blocks.GRASS_BLOCK.getDefaultState().with(SnowyDirtBlock.SNOWY, false), 18, 3, 6, start);
        structure.setBlockState(world, Blocks.GRASS_BLOCK.getDefaultState().with(SnowyDirtBlock.SNOWY, false), 18, 3, 16, start);
        structure.setBlockState(world, Blocks.GRASS_BLOCK.getDefaultState().with(SnowyDirtBlock.SNOWY, false), 19, 0, 4, start);
        structure.setBlockState(world, Blocks.GRASS_BLOCK.getDefaultState().with(SnowyDirtBlock.SNOWY, false), 19, 0, 18, start);
        structure.setBlockState(world, Blocks.GRASS_BLOCK.getDefaultState().with(SnowyDirtBlock.SNOWY, false), 19, 2, 7, start);
        structure.setBlockState(world, Blocks.GRASS_BLOCK.getDefaultState().with(SnowyDirtBlock.SNOWY, false), 19, 2, 15, start);
        structure.setBlockState(world, Blocks.GRASS_BLOCK.getDefaultState().with(SnowyDirtBlock.SNOWY, false), 20, 0, 6, start);
        structure.setBlockState(world, Blocks.GRASS_BLOCK.getDefaultState().with(SnowyDirtBlock.SNOWY, false), 20, 0, 16, start);
        structure.fillWithBlocks(world, start, 1, 0, 8, 1, 0, 9, Blocks.GRASS_BLOCK.getDefaultState().with(SnowyDirtBlock.SNOWY, false));
        structure.fillWithBlocks(world, start, 1, 0, 10, 2, 0, 12, Blocks.DIRT.getDefaultState());
        structure.fillWithBlocks(world, start, 1, 0, 13, 1, 0, 14, Blocks.GRASS_BLOCK.getDefaultState().with(SnowyDirtBlock.SNOWY, false));
        structure.fillWithBlocks(world, start, 1, 1, 10, 1, 1, 12, Blocks.GRASS_BLOCK.getDefaultState().with(SnowyDirtBlock.SNOWY, false));
        structure.fillWithBlocks(world, start, 2, 0, 7, 3, 0, 10, Blocks.DIRT.getDefaultState());
        structure.fillWithBlocks(world, start, 2, 0, 13, 3, 0, 15, Blocks.DIRT.getDefaultState());
        structure.fillWithBlocks(world, start, 2, 1, 7, 2, 1, 8, Blocks.GRASS_BLOCK.getDefaultState().with(SnowyDirtBlock.SNOWY, false));
        structure.fillWithBlocks(world, start, 2, 1, 9, 4, 1, 11, Blocks.DIRT.getDefaultState());
        structure.fillWithBlocks(world, start, 2, 1, 12, 3, 1, 13, Blocks.DIRT.getDefaultState());
        structure.fillWithBlocks(world, start, 2, 1, 14, 2, 1, 15, Blocks.GRASS_BLOCK.getDefaultState().with(SnowyDirtBlock.SNOWY, false));
        structure.fillWithBlocks(world, start, 2, 2, 9, 2, 2, 13, Blocks.GRASS_BLOCK.getDefaultState().with(SnowyDirtBlock.SNOWY, false));
        structure.fillWithBlocks(world, start, 3, 0, 5, 6, 0, 8, Blocks.DIRT.getDefaultState());
        structure.fillWithBlocks(world, start, 3, 0, 11, 3, 0, 12, Blocks.STONE.getDefaultState());
        structure.fillWithBlocks(world, start, 3, 0, 16, 4, 0, 17, Blocks.DIRT.getDefaultState());
        structure.fillWithBlocks(world, start, 3, 0, 18, 3, 0, 18, Blocks.GRASS_BLOCK.getDefaultState().with(SnowyDirtBlock.SNOWY, false));
        structure.fillWithBlocks(world, start, 3, 1, 5, 3, 1, 6, Blocks.GRASS_BLOCK.getDefaultState().with(SnowyDirtBlock.SNOWY, false));
        structure.fillWithBlocks(world, start, 3, 1, 7, 6, 1, 11, Blocks.DIRT.getDefaultState());
        structure.fillWithBlocks(world, start, 3, 1, 14, 4, 1, 15, Blocks.DIRT.getDefaultState());
        structure.fillWithBlocks(world, start, 3, 1, 16, 3, 1, 17, Blocks.GRASS_BLOCK.getDefaultState().with(SnowyDirtBlock.SNOWY, false));
        structure.fillWithBlocks(world, start, 3, 2, 8, 9, 2, 14, Blocks.DIRT.getDefaultState());
        structure.fillWithBlocks(world, start, 3, 3, 8, 3, 3, 9, Blocks.GRASS_BLOCK.getDefaultState().with(SnowyDirtBlock.SNOWY, false));
        structure.fillWithBlocks(world, start, 3, 3, 10, 5, 3, 12, Blocks.DIRT.getDefaultState());
        structure.fillWithBlocks(world, start, 3, 3, 13, 3, 3, 14, Blocks.GRASS_BLOCK.getDefaultState().with(SnowyDirtBlock.SNOWY, false));
        structure.fillWithBlocks(world, start, 3, 4, 10, 3, 4, 12, Blocks.GRASS_BLOCK.getDefaultState().with(SnowyDirtBlock.SNOWY, false));
        structure.fillWithBlocks(world, start, 4, 0, 4, 8, 0, 8, Blocks.DIRT.getDefaultState());
        structure.fillWithBlocks(world, start, 4, 0, 10, 5, 0, 12, Blocks.DIRT.getDefaultState());
        structure.fillWithBlocks(world, start, 4, 0, 13, 4, 0, 15, Blocks.STONE.getDefaultState());
        structure.fillWithBlocks(world, start, 4, 0, 18, 4, 0, 18, Blocks.DIRT.getDefaultState());
        structure.fillWithBlocks(world, start, 4, 1, 5, 8, 1, 9, Blocks.DIRT.getDefaultState());
        structure.fillWithBlocks(world, start, 4, 1, 12, 4, 1, 13, Blocks.STONE.getDefaultState());
        structure.fillWithBlocks(world, start, 4, 1, 16, 5, 1, 17, Blocks.DIRT.getDefaultState());
        structure.fillWithBlocks(world, start, 4, 1, 18, 4, 1, 18, Blocks.GRASS_BLOCK.getDefaultState().with(SnowyDirtBlock.SNOWY, false));
        structure.fillWithBlocks(world, start, 4, 2, 6, 14, 2, 16, Blocks.DIRT.getDefaultState());
        structure.fillWithBlocks(world, start, 4, 2, 17, 4, 2, 17, Blocks.GRASS_BLOCK.getDefaultState().with(SnowyDirtBlock.SNOWY, false));
        structure.fillWithBlocks(world, start, 4, 3, 7, 12, 3, 15, Blocks.DIRT.getDefaultState());
        structure.fillWithBlocks(world, start, 4, 3, 16, 4, 3, 16, Blocks.GRASS_BLOCK.getDefaultState().with(SnowyDirtBlock.SNOWY, false));
        structure.fillWithBlocks(world, start, 4, 4, 7, 4, 4, 8, Blocks.GRASS_BLOCK.getDefaultState().with(SnowyDirtBlock.SNOWY, false));
        structure.fillWithBlocks(world, start, 4, 4, 9, 8, 4, 13, Blocks.DIRT.getDefaultState());
        structure.fillWithBlocks(world, start, 4, 4, 14, 4, 4, 15, Blocks.GRASS_BLOCK.getDefaultState().with(SnowyDirtBlock.SNOWY, false));
        structure.fillWithBlocks(world, start, 4, 5, 9, 4, 5, 13, Blocks.GRASS_BLOCK.getDefaultState().with(SnowyDirtBlock.SNOWY, false));
        structure.fillWithBlocks(world, start, 5, 0, 3, 8, 0, 8, Blocks.DIRT.getDefaultState());
        structure.fillWithBlocks(world, start, 5, 0, 9, 5, 4, 14, Blocks.DIRT.getDefaultState());
        structure.fillWithBlocks(world, start, 5, 0, 15, 5, 0, 16, Blocks.STONE.getDefaultState());
        structure.fillWithBlocks(world, start, 5, 0, 17, 5, 0, 19, Blocks.DIRT.getDefaultState());
        structure.fillWithBlocks(world, start, 5, 1, 3, 6, 1, 3, Blocks.GRASS_BLOCK.getDefaultState().with(SnowyDirtBlock.SNOWY, false));
        structure.fillWithBlocks(world, start, 5, 1, 4, 10, 1, 9, Blocks.DIRT.getDefaultState());
        structure.fillWithBlocks(world, start, 5, 1, 15, 5, 1, 15, Blocks.STONE.getDefaultState());
        structure.fillWithBlocks(world, start, 5, 1, 18, 17, 1, 18, Blocks.DIRT.getDefaultState());
        structure.fillWithBlocks(world, start, 5, 1, 19, 6, 1, 19, Blocks.GRASS_BLOCK.getDefaultState().with(SnowyDirtBlock.SNOWY, false));
        structure.fillWithBlocks(world, start, 5, 2, 5, 17, 2, 17, Blocks.DIRT.getDefaultState());
        structure.fillWithBlocks(world, start, 5, 3, 6, 15, 3, 16, Blocks.DIRT.getDefaultState());
        structure.fillWithBlocks(world, start, 5, 3, 17, 5, 3, 17, Blocks.GRASS_BLOCK.getDefaultState().with(SnowyDirtBlock.SNOWY, false));
        structure.fillWithBlocks(world, start, 5, 4, 7, 13, 4, 15, Blocks.DIRT.getDefaultState());
        structure.fillWithBlocks(world, start, 5, 4, 16, 5, 4, 16, Blocks.GRASS_BLOCK.getDefaultState().with(SnowyDirtBlock.SNOWY, false));
        structure.fillWithBlocks(world, start, 5, 5, 7, 5, 5, 9, Blocks.GRASS_BLOCK.getDefaultState().with(SnowyDirtBlock.SNOWY, false));
        structure.fillWithBlocks(world, start, 5, 5, 10, 7, 5, 12, Blocks.DIRT.getDefaultState());
        structure.fillWithBlocks(world, start, 5, 5, 13, 5, 5, 15, Blocks.GRASS_BLOCK.getDefaultState().with(SnowyDirtBlock.SNOWY, false));
        structure.fillWithBlocks(world, start, 5, 6, 10, 6, 6, 12, Blocks.GRASS_BLOCK.getDefaultState().with(SnowyDirtBlock.SNOWY, false));
        structure.fillWithBlocks(world, start, 6, 0, 9, 6, 5, 9, Blocks.DIRT.getDefaultState());
        structure.fillWithBlocks(world, start, 6, 0, 10, 7, 0, 12, Blocks.STONE.getDefaultState());
        structure.fillWithBlocks(world, start, 6, 0, 13, 6, 2, 15, Blocks.DIRT.getDefaultState());
        structure.fillWithBlocks(world, start, 6, 0, 16, 9, 0, 16, Blocks.DIRT.getDefaultState());
        structure.fillWithBlocks(world, start, 6, 0, 17, 7, 0, 17, Blocks.STONE.getDefaultState());
        structure.fillWithBlocks(world, start, 6, 0, 18, 7, 0, 19, Blocks.DIRT.getDefaultState());
        structure.fillWithBlocks(world, start, 6, 1, 12, 6, 4, 15, Blocks.DIRT.getDefaultState());
        structure.fillWithBlocks(world, start, 6, 1, 17, 7, 1, 18, Blocks.DIRT.getDefaultState());
        structure.fillWithBlocks(world, start, 6, 2, 4, 16, 2, 18, Blocks.DIRT.getDefaultState());
        structure.fillWithBlocks(world, start, 6, 3, 5, 16, 3, 17, Blocks.DIRT.getDefaultState());
        structure.fillWithBlocks(world, start, 6, 4, 6, 16, 4, 16, Blocks.DIRT.getDefaultState());
        structure.fillWithBlocks(world, start, 6, 4, 17, 6, 4, 17, Blocks.GRASS_BLOCK.getDefaultState().with(SnowyDirtBlock.SNOWY, false));
        structure.fillWithBlocks(world, start, 6, 5, 6, 6, 5, 7, Blocks.GRASS_BLOCK.getDefaultState().with(SnowyDirtBlock.SNOWY, false));
        structure.fillWithBlocks(world, start, 6, 5, 8, 12, 5, 14, Blocks.DIRT.getDefaultState());
        structure.fillWithBlocks(world, start, 6, 5, 15, 6, 5, 16, Blocks.GRASS_BLOCK.getDefaultState().with(SnowyDirtBlock.SNOWY, false));
        structure.fillWithBlocks(world, start, 6, 6, 8, 7, 6, 9, Blocks.GRASS_BLOCK.getDefaultState().with(SnowyDirtBlock.SNOWY, false));
        structure.fillWithBlocks(world, start, 6, 6, 13, 7, 6, 14, Blocks.GRASS_BLOCK.getDefaultState().with(SnowyDirtBlock.SNOWY, false));
        structure.fillWithBlocks(world, start, 7, 0, 2, 11, 0, 6, Blocks.DIRT.getDefaultState());
        structure.fillWithBlocks(world, start, 7, 0, 9, 7, 0, 14, Blocks.STONE.getDefaultState());
        structure.fillWithBlocks(world, start, 7, 0, 15, 7, 0, 16, Blocks.DIRT.getDefaultState());
        structure.fillWithBlocks(world, start, 7, 0, 20, 15, 0, 20, Blocks.DIRT.getDefaultState());
        structure.fillWithBlocks(world, start, 7, 1, 2, 8, 1, 2, Blocks.GRASS_BLOCK.getDefaultState().with(SnowyDirtBlock.SNOWY, false));
        structure.fillWithBlocks(world, start, 7, 1, 3, 13, 1, 9, Blocks.DIRT.getDefaultState());
        structure.fillWithBlocks(world, start, 7, 1, 10, 7, 1, 13, Blocks.STONE.getDefaultState());
        structure.fillWithBlocks(world, start, 7, 1, 14, 8, 1, 19, Blocks.DIRT.getDefaultState());
        structure.fillWithBlocks(world, start, 7, 1, 20, 8, 1, 20, Blocks.GRASS_BLOCK.getDefaultState().with(SnowyDirtBlock.SNOWY, false));
        structure.fillWithBlocks(world, start, 7, 3, 4, 15, 3, 18, Blocks.DIRT.getDefaultState());
        structure.fillWithBlocks(world, start, 7, 4, 4, 8, 4, 4, Blocks.GRASS_BLOCK.getDefaultState().with(SnowyDirtBlock.SNOWY, false));
        structure.fillWithBlocks(world, start, 7, 4, 5, 15, 4, 17, Blocks.DIRT.getDefaultState());
        structure.fillWithBlocks(world, start, 7, 4, 18, 8, 4, 18, Blocks.GRASS_BLOCK.getDefaultState().with(SnowyDirtBlock.SNOWY, false));
        structure.fillWithBlocks(world, start, 7, 5, 5, 7, 5, 6, Blocks.GRASS_BLOCK.getDefaultState().with(SnowyDirtBlock.SNOWY, false));
        structure.fillWithBlocks(world, start, 7, 5, 7, 9, 5, 15, Blocks.DIRT.getDefaultState());
        structure.fillWithBlocks(world, start, 7, 5, 16, 7, 5, 17, Blocks.GRASS_BLOCK.getDefaultState().with(SnowyDirtBlock.SNOWY, false));
        structure.fillWithBlocks(world, start, 7, 6, 7, 7, 6, 9, Blocks.GRASS_BLOCK.getDefaultState().with(SnowyDirtBlock.SNOWY, false));
        structure.fillWithBlocks(world, start, 7, 6, 10, 7, 6, 12, Blocks.DIRT.getDefaultState());
        structure.fillWithBlocks(world, start, 7, 6, 15, 7, 6, 15, Blocks.GRASS_BLOCK.getDefaultState().with(SnowyDirtBlock.SNOWY, false));
        structure.fillWithBlocks(world, start, 7, 7, 12, 7, 7, 12, Blocks.STONE_BRICK_STAIRS.getDefaultState().with(StairsBlock.FACING, Direction.EAST).with(StairsBlock.WATERLOGGED, false).with(StairsBlock.SHAPE, StairsShape.STRAIGHT).with(StairsBlock.HALF, Half.BOTTOM));
        structure.fillWithBlocks(world, start, 8, 0, 1, 9, 0, 1, Blocks.GRASS_BLOCK.getDefaultState().with(SnowyDirtBlock.SNOWY, false));
        structure.fillWithBlocks(world, start, 8, 0, 9, 13, 0, 14, Blocks.DIRT.getDefaultState());
        structure.fillWithBlocks(world, start, 8, 0, 15, 14, 0, 15, Blocks.STONE.getDefaultState());
        structure.fillWithBlocks(world, start, 8, 0, 17, 8, 2, 19, Blocks.DIRT.getDefaultState());
        structure.fillWithBlocks(world, start, 8, 0, 21, 9, 0, 21, Blocks.GRASS_BLOCK.getDefaultState().with(SnowyDirtBlock.SNOWY, false));
        structure.fillWithBlocks(world, start, 8, 1, 10, 12, 1, 14, Blocks.DIRT.getDefaultState());
        structure.fillWithBlocks(world, start, 8, 2, 3, 14, 2, 19, Blocks.DIRT.getDefaultState());
        structure.fillWithBlocks(world, start, 8, 3, 3, 9, 3, 3, Blocks.GRASS_BLOCK.getDefaultState().with(SnowyDirtBlock.SNOWY, false));
        structure.fillWithBlocks(world, start, 8, 3, 19, 9, 3, 19, Blocks.GRASS_BLOCK.getDefaultState().with(SnowyDirtBlock.SNOWY, false));
        structure.fillWithBlocks(world, start, 8, 5, 5, 9, 5, 5, Blocks.GRASS_BLOCK.getDefaultState().with(SnowyDirtBlock.SNOWY, false));
        structure.fillWithBlocks(world, start, 8, 5, 6, 9, 5, 16, Blocks.DIRT.getDefaultState());
        structure.fillWithBlocks(world, start, 8, 5, 17, 8, 5, 17, Blocks.GRASS_BLOCK.getDefaultState().with(SnowyDirtBlock.SNOWY, false));
        structure.fillWithBlocks(world, start, 8, 6, 6, 9, 6, 7, Blocks.GRASS_BLOCK.getDefaultState().with(SnowyDirtBlock.SNOWY, false));
        structure.fillWithBlocks(world, start, 8, 6, 8, 8, 6, 8, Blocks.COBBLESTONE.getDefaultState());
        structure.fillWithBlocks(world, start, 8, 6, 9, 8, 6, 10, Blocks.DIORITE.getDefaultState());
        structure.fillWithBlocks(world, start, 8, 6, 11, 8, 8, 11, Blocks.COBBLESTONE.getDefaultState());
        structure.fillWithBlocks(world, start, 8, 6, 13, 8, 6, 13, Blocks.DIRT.getDefaultState());
        structure.fillWithBlocks(world, start, 8, 6, 14, 8, 6, 16, Blocks.GRASS_BLOCK.getDefaultState().with(SnowyDirtBlock.SNOWY, false));
        structure.fillWithBlocks(world, start, 8, 7, 10, 8, 14, 10, Blocks.DARK_OAK_LOG.getDefaultState());
        structure.fillWithBlocks(world, start, 8, 7, 12, 8, 14, 12, Blocks.DARK_OAK_LOG.getDefaultState());
        structure.fillWithBlocks(world, start, 8, 9, 11, 8, 14, 11, Blocks.STONE_BRICKS.getDefaultState());
        structure.fillWithBlocks(world, start, 9, 0, 7, 13, 0, 7, Blocks.STONE.getDefaultState());
        structure.fillWithBlocks(world, start, 9, 0, 8, 14, 0, 14, Blocks.DIRT.getDefaultState());
        structure.fillWithBlocks(world, start, 9, 0, 17, 9, 0, 17, Blocks.DIRT.getDefaultState());
        structure.fillWithBlocks(world, start, 9, 0, 19, 10, 0, 20, Blocks.DIRT.getDefaultState());
        structure.fillWithBlocks(world, start, 9, 1, 2, 13, 1, 14, Blocks.DIRT.getDefaultState());
        structure.fillWithBlocks(world, start, 9, 1, 15, 13, 1, 15, Blocks.STONE.getDefaultState());
        structure.fillWithBlocks(world, start, 9, 1, 16, 13, 1, 20, Blocks.DIRT.getDefaultState());
        structure.fillWithBlocks(world, start, 9, 2, 2, 13, 2, 2, Blocks.GRASS_BLOCK.getDefaultState().with(SnowyDirtBlock.SNOWY, false));
        structure.fillWithBlocks(world, start, 9, 2, 20, 13, 2, 20, Blocks.GRASS_BLOCK.getDefaultState().with(SnowyDirtBlock.SNOWY, false));
        structure.fillWithBlocks(world, start, 9, 4, 4, 13, 4, 18, Blocks.DIRT.getDefaultState());
        structure.fillWithBlocks(world, start, 9, 5, 4, 9, 5, 5, Blocks.GRASS_BLOCK.getDefaultState().with(SnowyDirtBlock.SNOWY, false));
        structure.fillWithBlocks(world, start, 9, 5, 17, 9, 5, 18, Blocks.GRASS_BLOCK.getDefaultState().with(SnowyDirtBlock.SNOWY, false));
        structure.fillWithBlocks(world, start, 9, 6, 8, 10, 6, 8, Blocks.DIORITE.getDefaultState());
        structure.fillWithBlocks(world, start, 9, 6, 9, 9, 8, 9, Blocks.COBBLESTONE.getDefaultState());
        structure.fillWithBlocks(world, start, 9, 6, 10, 10, 6, 11, Blocks.BIRCH_PLANKS.getDefaultState());
        structure.fillWithBlocks(world, start, 9, 6, 13, 9, 8, 13, Blocks.COBBLESTONE.getDefaultState());
        structure.fillWithBlocks(world, start, 9, 6, 14, 9, 6, 14, Blocks.DIRT.getDefaultState());
        structure.fillWithBlocks(world, start, 9, 6, 15, 9, 6, 16, Blocks.GRASS_BLOCK.getDefaultState().with(SnowyDirtBlock.SNOWY, false));
        structure.fillWithBlocks(world, start, 9, 8, 10, 9, 13, 10, Blocks.LADDER.getDefaultState().with(LadderBlock.FACING, Direction.EAST).with(LadderBlock.WATERLOGGED, false));
        structure.fillWithBlocks(world, start, 9, 9, 9, 9, 13, 9, Blocks.STONE_BRICKS.getDefaultState());
        structure.fillWithBlocks(world, start, 9, 9, 13, 9, 13, 13, Blocks.STONE_BRICKS.getDefaultState());
        structure.fillWithBlocks(world, start, 9, 12, 11, 10, 12, 12, Blocks.DARK_OAK_SLAB.getDefaultState().with(SlabBlock.TYPE, SlabType.BOTTOM).with(SlabBlock.WATERLOGGED, false));
        structure.fillWithBlocks(world, start, 9, 14, 12, 9, 14, 12, Blocks.LANTERN.getDefaultState().with(LanternBlock.WATERLOGGED, false).with(LanternBlock.HANGING, true));
        structure.fillWithBlocks(world, start, 9, 15, 9, 9, 17, 9, Blocks.STONE_BRICK_WALL.getDefaultState().with(WallBlock.WATERLOGGED, false).with(WallBlock.UP, true).with(WallBlock.WALL_HEIGHT_NORTH, WallHeight.LOW).with(WallBlock.WALL_HEIGHT_SOUTH, WallHeight.LOW).with(WallBlock.WALL_HEIGHT_EAST, WallHeight.LOW).with(WallBlock.WALL_HEIGHT_WEST, WallHeight.LOW));
        structure.fillWithBlocks(world, start, 9, 15, 10, 9, 24, 10, Blocks.COBBLESTONE.getDefaultState());
        structure.fillWithBlocks(world, start, 9, 15, 12, 9, 24, 12, Blocks.COBBLESTONE.getDefaultState());
        structure.fillWithBlocks(world, start, 9, 15, 13, 9, 18, 13, Blocks.STONE_BRICK_WALL.getDefaultState().with(WallBlock.WATERLOGGED, false).with(WallBlock.UP, true).with(WallBlock.WALL_HEIGHT_NORTH, WallHeight.LOW).with(WallBlock.WALL_HEIGHT_SOUTH, WallHeight.LOW).with(WallBlock.WALL_HEIGHT_EAST, WallHeight.LOW).with(WallBlock.WALL_HEIGHT_WEST, WallHeight.LOW));
        structure.fillWithBlocks(world, start, 9, 16, 11, 9, 21, 11, Blocks.DARK_OAK_LOG.getDefaultState());
        structure.fillWithBlocks(world, start, 9, 19, 9, 9, 20, 9, Blocks.STONE_BRICK_WALL.getDefaultState().with(WallBlock.WATERLOGGED, false).with(WallBlock.UP, true).with(WallBlock.WALL_HEIGHT_NORTH, WallHeight.LOW).with(WallBlock.WALL_HEIGHT_SOUTH, WallHeight.LOW).with(WallBlock.WALL_HEIGHT_EAST, WallHeight.LOW).with(WallBlock.WALL_HEIGHT_WEST, WallHeight.LOW));
        structure.fillWithBlocks(world, start, 9, 19, 13, 9, 20, 13, Blocks.STONE_BRICK_WALL.getDefaultState().with(WallBlock.WATERLOGGED, false).with(WallBlock.UP, true).with(WallBlock.WALL_HEIGHT_NORTH, WallHeight.LOW).with(WallBlock.WALL_HEIGHT_SOUTH, WallHeight.LOW).with(WallBlock.WALL_HEIGHT_EAST, WallHeight.LOW).with(WallBlock.WALL_HEIGHT_WEST, WallHeight.LOW));
        structure.fillWithBlocks(world, start, 9, 22, 9, 9, 23, 10, Blocks.COBBLESTONE.getDefaultState());
        structure.fillWithBlocks(world, start, 9, 22, 11, 9, 23, 11, Blocks.IRON_BARS.getDefaultState().with(FourWayBlock.WATERLOGGED, false).with(FourWayBlock.NORTH, true).with(FourWayBlock.SOUTH, true).with(FourWayBlock.EAST, false).with(FourWayBlock.WEST, false));
        structure.fillWithBlocks(world, start, 9, 22, 13, 10, 23, 13, Blocks.COBBLESTONE.getDefaultState());
        structure.fillWithBlocks(world, start, 9, 24, 9, 9, 26, 9, Blocks.STONE_BRICKS.getDefaultState());
        structure.fillWithBlocks(world, start, 9, 24, 11, 9, 26, 11, Blocks.STONE_BRICKS.getDefaultState());
        structure.fillWithBlocks(world, start, 9, 24, 13, 9, 26, 13, Blocks.STONE_BRICKS.getDefaultState());
        structure.fillWithBlocks(world, start, 9, 25, 10, 9, 25, 13, Blocks.STONE_BRICKS.getDefaultState());
        structure.fillWithBlocks(world, start, 10, 0, 1, 12, 0, 6, Blocks.DIRT.getDefaultState());
        structure.fillWithBlocks(world, start, 10, 0, 16, 12, 0, 16, Blocks.STONE.getDefaultState());
        structure.fillWithBlocks(world, start, 10, 0, 17, 12, 0, 21, Blocks.DIRT.getDefaultState());
        structure.fillWithBlocks(world, start, 10, 1, 1, 12, 1, 1, Blocks.GRASS_BLOCK.getDefaultState().with(SnowyDirtBlock.SNOWY, false));
        structure.fillWithBlocks(world, start, 10, 1, 21, 12, 1, 21, Blocks.GRASS_BLOCK.getDefaultState().with(SnowyDirtBlock.SNOWY, false));
        structure.fillWithBlocks(world, start, 10, 3, 3, 12, 3, 19, Blocks.DIRT.getDefaultState());
        structure.fillWithBlocks(world, start, 10, 4, 3, 12, 4, 3, Blocks.GRASS_BLOCK.getDefaultState().with(SnowyDirtBlock.SNOWY, false));
        structure.fillWithBlocks(world, start, 10, 4, 19, 12, 4, 19, Blocks.GRASS_BLOCK.getDefaultState().with(SnowyDirtBlock.SNOWY, false));
        structure.fillWithBlocks(world, start, 10, 5, 4, 13, 5, 4, Blocks.GRASS_BLOCK.getDefaultState().with(SnowyDirtBlock.SNOWY, false));
        structure.fillWithBlocks(world, start, 10, 5, 5, 11, 5, 6, Blocks.DIRT.getDefaultState());
        structure.fillWithBlocks(world, start, 10, 5, 15, 10, 5, 17, Blocks.DIRT.getDefaultState());
        structure.fillWithBlocks(world, start, 10, 5, 18, 13, 5, 18, Blocks.GRASS_BLOCK.getDefaultState().with(SnowyDirtBlock.SNOWY, false));
        structure.fillWithBlocks(world, start, 10, 6, 5, 11, 6, 6, Blocks.GRASS_BLOCK.getDefaultState().with(SnowyDirtBlock.SNOWY, false));
        structure.fillWithBlocks(world, start, 10, 6, 7, 12, 6, 7, Blocks.STONE_BRICK_SLAB.getDefaultState().with(SlabBlock.TYPE, SlabType.TOP).with(SlabBlock.WATERLOGGED, false));
        structure.fillWithBlocks(world, start, 10, 6, 9, 12, 6, 13, Blocks.BIRCH_PLANKS.getDefaultState());
        structure.fillWithBlocks(world, start, 10, 6, 16, 11, 6, 17, Blocks.GRASS_BLOCK.getDefaultState().with(SnowyDirtBlock.SNOWY, false));
        structure.fillWithBlocks(world, start, 10, 7, 8, 10, 17, 8, Blocks.DARK_OAK_LOG.getDefaultState());
        structure.fillWithBlocks(world, start, 10, 7, 13, 10, 8, 13, Blocks.FURNACE.getDefaultState().with(AbstractFurnaceBlock.FACING, Direction.NORTH).with(AbstractFurnaceBlock.LIT, false));
        structure.fillWithBlocks(world, start, 10, 7, 14, 10, 17, 14, Blocks.DARK_OAK_LOG.getDefaultState());
        structure.fillWithBlocks(world, start, 10, 12, 9, 12, 12, 12, Blocks.DARK_OAK_SLAB.getDefaultState().with(SlabBlock.TYPE, SlabType.BOTTOM).with(SlabBlock.WATERLOGGED, false));
        structure.fillWithBlocks(world, start, 10, 15, 9, 12, 15, 9, Blocks.COBBLESTONE.getDefaultState());
        structure.fillWithBlocks(world, start, 10, 15, 13, 12, 15, 13, Blocks.COBBLESTONE.getDefaultState());
        structure.fillWithBlocks(world, start, 10, 16, 9, 10, 24, 9, Blocks.COBBLESTONE.getDefaultState());
        structure.fillWithBlocks(world, start, 10, 16, 13, 10, 24, 13, Blocks.COBBLESTONE.getDefaultState());
        structure.fillWithBlocks(world, start, 10, 20, 10, 11, 20, 11, Blocks.DARK_OAK_SLAB.getDefaultState().with(SlabBlock.TYPE, SlabType.DOUBLE).with(SlabBlock.WATERLOGGED, false));
        structure.fillWithBlocks(world, start, 10, 25, 9, 13, 25, 9, Blocks.STONE_BRICKS.getDefaultState());
        structure.fillWithBlocks(world, start, 10, 25, 11, 11, 25, 12, Blocks.DARK_OAK_SLAB.getDefaultState().with(SlabBlock.TYPE, SlabType.BOTTOM).with(SlabBlock.WATERLOGGED, false));
        structure.fillWithBlocks(world, start, 10, 25, 13, 13, 25, 13, Blocks.STONE_BRICKS.getDefaultState());
        structure.fillWithBlocks(world, start, 11, 5, 7, 11, 5, 14, Blocks.DIRT.getDefaultState());
        structure.fillWithBlocks(world, start, 11, 5, 16, 12, 5, 17, Blocks.DIRT.getDefaultState());
        structure.fillWithBlocks(world, start, 11, 6, 14, 11, 8, 14, Blocks.COBBLESTONE.getDefaultState());
        structure.fillWithBlocks(world, start, 11, 9, 8, 12, 9, 8, Blocks.DARK_OAK_LOG.getDefaultState());
        structure.fillWithBlocks(world, start, 11, 9, 14, 11, 17, 14, Blocks.STONE_BRICKS.getDefaultState());
        structure.fillWithBlocks(world, start, 11, 10, 8, 11, 17, 8, Blocks.STONE_BRICKS.getDefaultState());
        structure.fillWithBlocks(world, start, 11, 13, 12, 11, 20, 12, Blocks.LADDER.getDefaultState().with(LadderBlock.FACING, Direction.NORTH).with(LadderBlock.WATERLOGGED, false));
        structure.fillWithBlocks(world, start, 11, 13, 13, 11, 14, 13, Blocks.DARK_OAK_LOG.getDefaultState());
        structure.fillWithBlocks(world, start, 11, 16, 9, 11, 21, 9, Blocks.DARK_OAK_LOG.getDefaultState());
        structure.fillWithBlocks(world, start, 11, 16, 13, 11, 21, 13, Blocks.DARK_OAK_LOG.getDefaultState());
        structure.fillWithBlocks(world, start, 11, 18, 8, 11, 18, 9, Blocks.DARK_OAK_LOG.getDefaultState());
        structure.fillWithBlocks(world, start, 11, 19, 10, 11, 19, 10, Blocks.LANTERN.getDefaultState().with(LanternBlock.WATERLOGGED, false).with(LanternBlock.HANGING, true));
        structure.fillWithBlocks(world, start, 11, 22, 9, 11, 23, 9, Blocks.IRON_BARS.getDefaultState().with(FourWayBlock.WATERLOGGED, false).with(FourWayBlock.NORTH, false).with(FourWayBlock.SOUTH, false).with(FourWayBlock.EAST, true).with(FourWayBlock.WEST, true));
        structure.fillWithBlocks(world, start, 11, 22, 13, 11, 23, 13, Blocks.IRON_BARS.getDefaultState().with(FourWayBlock.WATERLOGGED, false).with(FourWayBlock.NORTH, false).with(FourWayBlock.SOUTH, false).with(FourWayBlock.EAST, true).with(FourWayBlock.WEST, true));
        structure.fillWithBlocks(world, start, 11, 24, 9, 11, 26, 9, Blocks.STONE_BRICKS.getDefaultState());
        structure.fillWithBlocks(world, start, 11, 24, 13, 11, 26, 13, Blocks.STONE_BRICKS.getDefaultState());
        structure.fillWithBlocks(world, start, 11, 25, 10, 11, 25, 12, Blocks.DARK_OAK_SLAB.getDefaultState().with(SlabBlock.TYPE, SlabType.BOTTOM).with(SlabBlock.WATERLOGGED, false));
        structure.fillWithBlocks(world, start, 12, 5, 5, 12, 5, 6, Blocks.DIRT.getDefaultState());
        structure.fillWithBlocks(world, start, 12, 5, 15, 13, 5, 16, Blocks.DIRT.getDefaultState());
        structure.fillWithBlocks(world, start, 12, 6, 5, 12, 6, 6, Blocks.GRASS_BLOCK.getDefaultState().with(SnowyDirtBlock.SNOWY, false));
        structure.fillWithBlocks(world, start, 12, 6, 8, 13, 6, 8, Blocks.DIORITE.getDefaultState());
        structure.fillWithBlocks(world, start, 12, 6, 16, 12, 6, 17, Blocks.GRASS_BLOCK.getDefaultState().with(SnowyDirtBlock.SNOWY, false));
        structure.fillWithBlocks(world, start, 12, 7, 8, 12, 17, 8, Blocks.DARK_OAK_LOG.getDefaultState());
        structure.fillWithBlocks(world, start, 12, 7, 13, 12, 8, 13, Blocks.FURNACE.getDefaultState().with(AbstractFurnaceBlock.FACING, Direction.NORTH).with(AbstractFurnaceBlock.LIT, false));
        structure.fillWithBlocks(world, start, 12, 7, 14, 12, 17, 14, Blocks.DARK_OAK_LOG.getDefaultState());
        structure.fillWithBlocks(world, start, 12, 16, 9, 12, 24, 9, Blocks.COBBLESTONE.getDefaultState());
        structure.fillWithBlocks(world, start, 12, 16, 13, 12, 24, 13, Blocks.COBBLESTONE.getDefaultState());
        structure.fillWithBlocks(world, start, 12, 20, 10, 12, 20, 12, Blocks.DARK_OAK_SLAB.getDefaultState().with(SlabBlock.TYPE, SlabType.DOUBLE).with(SlabBlock.WATERLOGGED, false));
        structure.fillWithBlocks(world, start, 12, 21, 12, 12, 24, 12, Blocks.LADDER.getDefaultState().with(LadderBlock.FACING, Direction.NORTH).with(LadderBlock.WATERLOGGED, false));
        structure.fillWithBlocks(world, start, 13, 0, 1, 14, 0, 1, Blocks.GRASS_BLOCK.getDefaultState().with(SnowyDirtBlock.SNOWY, false));
        structure.fillWithBlocks(world, start, 13, 0, 2, 14, 0, 3, Blocks.DIRT.getDefaultState());
        structure.fillWithBlocks(world, start, 13, 0, 5, 14, 0, 6, Blocks.DIRT.getDefaultState());
        structure.fillWithBlocks(world, start, 13, 0, 16, 14, 0, 17, Blocks.DIRT.getDefaultState());
        structure.fillWithBlocks(world, start, 13, 0, 19, 14, 0, 20, Blocks.DIRT.getDefaultState());
        structure.fillWithBlocks(world, start, 13, 0, 21, 14, 0, 21, Blocks.GRASS_BLOCK.getDefaultState().with(SnowyDirtBlock.SNOWY, false));
        structure.fillWithBlocks(world, start, 13, 3, 3, 14, 3, 3, Blocks.GRASS_BLOCK.getDefaultState().with(SnowyDirtBlock.SNOWY, false));
        structure.fillWithBlocks(world, start, 13, 3, 19, 14, 3, 19, Blocks.GRASS_BLOCK.getDefaultState().with(SnowyDirtBlock.SNOWY, false));
        structure.fillWithBlocks(world, start, 13, 5, 5, 15, 5, 5, Blocks.GRASS_BLOCK.getDefaultState().with(SnowyDirtBlock.SNOWY, false));
        structure.fillWithBlocks(world, start, 13, 5, 6, 14, 5, 16, Blocks.DIRT.getDefaultState());
        structure.fillWithBlocks(world, start, 13, 5, 17, 13, 5, 18, Blocks.GRASS_BLOCK.getDefaultState().with(SnowyDirtBlock.SNOWY, false));
        structure.fillWithBlocks(world, start, 13, 6, 6, 14, 6, 7, Blocks.GRASS_BLOCK.getDefaultState().with(SnowyDirtBlock.SNOWY, false));
        structure.fillWithBlocks(world, start, 13, 6, 9, 13, 8, 9, Blocks.COBBLESTONE.getDefaultState());
        structure.fillWithBlocks(world, start, 13, 6, 10, 13, 6, 12, Blocks.BIRCH_PLANKS.getDefaultState());
        structure.fillWithBlocks(world, start, 13, 6, 13, 13, 8, 13, Blocks.COBBLESTONE.getDefaultState());
        structure.fillWithBlocks(world, start, 13, 6, 15, 14, 6, 16, Blocks.GRASS_BLOCK.getDefaultState().with(SnowyDirtBlock.SNOWY, false));
        structure.fillWithBlocks(world, start, 13, 7, 8, 13, 7, 8, Blocks.COBBLESTONE_SLAB.getDefaultState().with(SlabBlock.TYPE, SlabType.BOTTOM).with(SlabBlock.WATERLOGGED, false));
        structure.fillWithBlocks(world, start, 13, 9, 9, 13, 13, 9, Blocks.STONE_BRICKS.getDefaultState());
        structure.fillWithBlocks(world, start, 13, 9, 13, 13, 13, 13, Blocks.STONE_BRICKS.getDefaultState());
        structure.fillWithBlocks(world, start, 13, 12, 10, 13, 12, 12, Blocks.DARK_OAK_SLAB.getDefaultState().with(SlabBlock.TYPE, SlabType.BOTTOM).with(SlabBlock.WATERLOGGED, false));
        structure.fillWithBlocks(world, start, 13, 15, 9, 13, 21, 9, Blocks.STONE_BRICK_WALL.getDefaultState().with(WallBlock.WATERLOGGED, false).with(WallBlock.UP, true).with(WallBlock.WALL_HEIGHT_NORTH, WallHeight.LOW).with(WallBlock.WALL_HEIGHT_SOUTH, WallHeight.LOW).with(WallBlock.WALL_HEIGHT_EAST, WallHeight.LOW).with(WallBlock.WALL_HEIGHT_WEST, WallHeight.LOW));
        structure.fillWithBlocks(world, start, 13, 15, 10, 13, 15, 12, Blocks.COBBLESTONE.getDefaultState());
        structure.fillWithBlocks(world, start, 13, 15, 13, 13, 16, 13, Blocks.STONE_BRICK_WALL.getDefaultState().with(WallBlock.WATERLOGGED, false).with(WallBlock.UP, true).with(WallBlock.WALL_HEIGHT_NORTH, WallHeight.LOW).with(WallBlock.WALL_HEIGHT_SOUTH, WallHeight.LOW).with(WallBlock.WALL_HEIGHT_EAST, WallHeight.LOW).with(WallBlock.WALL_HEIGHT_WEST, WallHeight.LOW));
        structure.fillWithBlocks(world, start, 13, 16, 10, 13, 24, 10, Blocks.COBBLESTONE.getDefaultState());
        structure.fillWithBlocks(world, start, 13, 16, 11, 13, 21, 11, Blocks.DARK_OAK_LOG.getDefaultState());
        structure.fillWithBlocks(world, start, 13, 16, 12, 13, 24, 12, Blocks.COBBLESTONE.getDefaultState());
        structure.fillWithBlocks(world, start, 13, 17, 13, 13, 18, 13, Blocks.STONE_BRICK_WALL.getDefaultState().with(WallBlock.WATERLOGGED, false).with(WallBlock.UP, true).with(WallBlock.WALL_HEIGHT_NORTH, WallHeight.LOW).with(WallBlock.WALL_HEIGHT_SOUTH, WallHeight.LOW).with(WallBlock.WALL_HEIGHT_EAST, WallHeight.LOW).with(WallBlock.WALL_HEIGHT_WEST, WallHeight.LOW));
        structure.fillWithBlocks(world, start, 13, 22, 9, 13, 23, 10, Blocks.COBBLESTONE.getDefaultState());
        structure.fillWithBlocks(world, start, 13, 22, 11, 13, 23, 11, Blocks.IRON_BARS.getDefaultState().with(FourWayBlock.WATERLOGGED, false).with(FourWayBlock.NORTH, true).with(FourWayBlock.SOUTH, true).with(FourWayBlock.EAST, false).with(FourWayBlock.WEST, false));
        structure.fillWithBlocks(world, start, 13, 22, 13, 13, 23, 13, Blocks.COBBLESTONE.getDefaultState());
        structure.fillWithBlocks(world, start, 13, 24, 9, 13, 26, 9, Blocks.STONE_BRICKS.getDefaultState());
        structure.fillWithBlocks(world, start, 13, 24, 11, 13, 26, 11, Blocks.STONE_BRICKS.getDefaultState());
        structure.fillWithBlocks(world, start, 13, 24, 13, 13, 26, 13, Blocks.STONE_BRICKS.getDefaultState());
        structure.fillWithBlocks(world, start, 13, 25, 10, 13, 25, 13, Blocks.STONE_BRICKS.getDefaultState());
        structure.fillWithBlocks(world, start, 14, 0, 4, 14, 3, 14, Blocks.DIRT.getDefaultState());
        structure.fillWithBlocks(world, start, 14, 0, 18, 15, 0, 20, Blocks.DIRT.getDefaultState());
        structure.fillWithBlocks(world, start, 14, 1, 2, 15, 1, 2, Blocks.GRASS_BLOCK.getDefaultState().with(SnowyDirtBlock.SNOWY, false));
        structure.fillWithBlocks(world, start, 14, 1, 3, 15, 1, 11, Blocks.DIRT.getDefaultState());
        structure.fillWithBlocks(world, start, 14, 1, 15, 17, 1, 18, Blocks.DIRT.getDefaultState());
        structure.fillWithBlocks(world, start, 14, 1, 19, 15, 1, 19, Blocks.DIRT.getDefaultState());
        structure.fillWithBlocks(world, start, 14, 1, 20, 15, 1, 20, Blocks.GRASS_BLOCK.getDefaultState().with(SnowyDirtBlock.SNOWY, false));
        structure.fillWithBlocks(world, start, 14, 4, 4, 15, 4, 4, Blocks.GRASS_BLOCK.getDefaultState().with(SnowyDirtBlock.SNOWY, false));
        structure.fillWithBlocks(world, start, 14, 4, 18, 15, 4, 18, Blocks.GRASS_BLOCK.getDefaultState().with(SnowyDirtBlock.SNOWY, false));
        structure.fillWithBlocks(world, start, 14, 5, 17, 15, 5, 17, Blocks.GRASS_BLOCK.getDefaultState().with(SnowyDirtBlock.SNOWY, false));
        structure.fillWithBlocks(world, start, 14, 6, 8, 14, 6, 8, Blocks.GRASS_BLOCK.getDefaultState().with(SnowyDirtBlock.SNOWY, false));
        structure.fillWithBlocks(world, start, 14, 6, 9, 14, 6, 10, Blocks.DIORITE.getDefaultState());
        structure.fillWithBlocks(world, start, 14, 6, 11, 14, 8, 11, Blocks.COBBLESTONE.getDefaultState());
        structure.fillWithBlocks(world, start, 14, 6, 14, 15, 6, 15, Blocks.GRASS_BLOCK.getDefaultState().with(SnowyDirtBlock.SNOWY, false));
        structure.fillWithBlocks(world, start, 14, 7, 10, 14, 17, 10, Blocks.DARK_OAK_LOG.getDefaultState());
        structure.fillWithBlocks(world, start, 14, 7, 12, 14, 17, 12, Blocks.DARK_OAK_LOG.getDefaultState());
        structure.fillWithBlocks(world, start, 14, 9, 11, 14, 17, 11, Blocks.STONE_BRICKS.getDefaultState());
        structure.fillWithBlocks(world, start, 15, 0, 2, 15, 0, 4, Blocks.DIRT.getDefaultState());
        structure.fillWithBlocks(world, start, 15, 0, 6, 17, 0, 8, Blocks.DIRT.getDefaultState());
        structure.fillWithBlocks(world, start, 15, 0, 9, 15, 0, 14, Blocks.STONE.getDefaultState());
        structure.fillWithBlocks(world, start, 15, 0, 15, 16, 0, 16, Blocks.DIRT.getDefaultState());
        structure.fillWithBlocks(world, start, 15, 1, 12, 15, 1, 13, Blocks.STONE.getDefaultState());
        structure.fillWithBlocks(world, start, 15, 1, 14, 18, 1, 17, Blocks.DIRT.getDefaultState());
        structure.fillWithBlocks(world, start, 15, 5, 6, 15, 5, 6, Blocks.GRASS_BLOCK.getDefaultState().with(SnowyDirtBlock.SNOWY, false));
        structure.fillWithBlocks(world, start, 15, 5, 7, 15, 5, 15, Blocks.DIRT.getDefaultState());
        structure.fillWithBlocks(world, start, 15, 5, 16, 15, 5, 17, Blocks.GRASS_BLOCK.getDefaultState().with(SnowyDirtBlock.SNOWY, false));
        structure.fillWithBlocks(world, start, 15, 6, 7, 15, 6, 9, Blocks.GRASS_BLOCK.getDefaultState().with(SnowyDirtBlock.SNOWY, false));
        structure.fillWithBlocks(world, start, 15, 6, 10, 15, 6, 12, Blocks.DIRT.getDefaultState());
        structure.fillWithBlocks(world, start, 15, 6, 13, 16, 6, 14, Blocks.GRASS_BLOCK.getDefaultState().with(SnowyDirtBlock.SNOWY, false));
        structure.fillWithBlocks(world, start, 16, 0, 3, 17, 0, 14, Blocks.DIRT.getDefaultState());
        structure.fillWithBlocks(world, start, 16, 0, 17, 17, 0, 19, Blocks.DIRT.getDefaultState());
        structure.fillWithBlocks(world, start, 16, 1, 3, 17, 1, 3, Blocks.GRASS_BLOCK.getDefaultState().with(SnowyDirtBlock.SNOWY, false));
        structure.fillWithBlocks(world, start, 16, 1, 4, 17, 1, 18, Blocks.DIRT.getDefaultState());
        structure.fillWithBlocks(world, start, 16, 1, 19, 17, 1, 19, Blocks.GRASS_BLOCK.getDefaultState().with(SnowyDirtBlock.SNOWY, false));
        structure.fillWithBlocks(world, start, 16, 3, 4, 16, 3, 4, Blocks.GRASS_BLOCK.getDefaultState().with(SnowyDirtBlock.SNOWY, false));
        structure.fillWithBlocks(world, start, 16, 4, 5, 16, 4, 5, Blocks.GRASS_BLOCK.getDefaultState().with(SnowyDirtBlock.SNOWY, false));
        structure.fillWithBlocks(world, start, 16, 5, 6, 16, 5, 7, Blocks.GRASS_BLOCK.getDefaultState().with(SnowyDirtBlock.SNOWY, false));
        structure.fillWithBlocks(world, start, 16, 5, 8, 16, 5, 14, Blocks.DIRT.getDefaultState());
        structure.fillWithBlocks(world, start, 16, 5, 15, 16, 5, 16, Blocks.GRASS_BLOCK.getDefaultState().with(SnowyDirtBlock.SNOWY, false));
        structure.fillWithBlocks(world, start, 16, 6, 8, 16, 6, 14, Blocks.GRASS_BLOCK.getDefaultState().with(SnowyDirtBlock.SNOWY, false));
        structure.fillWithBlocks(world, start, 17, 0, 16, 18, 0, 18, Blocks.DIRT.getDefaultState());
        structure.fillWithBlocks(world, start, 17, 2, 4, 17, 2, 4, Blocks.GRASS_BLOCK.getDefaultState().with(SnowyDirtBlock.SNOWY, false));
        structure.fillWithBlocks(world, start, 17, 3, 5, 17, 3, 5, Blocks.GRASS_BLOCK.getDefaultState().with(SnowyDirtBlock.SNOWY, false));
        structure.fillWithBlocks(world, start, 17, 3, 6, 17, 3, 16, Blocks.DIRT.getDefaultState());
        structure.fillWithBlocks(world, start, 17, 4, 6, 17, 4, 6, Blocks.GRASS_BLOCK.getDefaultState().with(SnowyDirtBlock.SNOWY, false));
        structure.fillWithBlocks(world, start, 17, 4, 7, 17, 4, 15, Blocks.DIRT.getDefaultState());
        structure.fillWithBlocks(world, start, 17, 5, 7, 17, 5, 9, Blocks.GRASS_BLOCK.getDefaultState().with(SnowyDirtBlock.SNOWY, false));
        structure.fillWithBlocks(world, start, 17, 5, 10, 17, 5, 12, Blocks.DIRT.getDefaultState());
        structure.fillWithBlocks(world, start, 17, 5, 13, 17, 5, 15, Blocks.GRASS_BLOCK.getDefaultState().with(SnowyDirtBlock.SNOWY, false));
        structure.fillWithBlocks(world, start, 17, 6, 10, 17, 6, 12, Blocks.GRASS_BLOCK.getDefaultState().with(SnowyDirtBlock.SNOWY, false));
        structure.fillWithBlocks(world, start, 18, 0, 3, 18, 0, 3, Blocks.GRASS_BLOCK.getDefaultState().with(SnowyDirtBlock.SNOWY, false));
        structure.fillWithBlocks(world, start, 18, 0, 4, 18, 0, 18, Blocks.DIRT.getDefaultState());
        structure.fillWithBlocks(world, start, 18, 1, 4, 18, 1, 4, Blocks.GRASS_BLOCK.getDefaultState().with(SnowyDirtBlock.SNOWY, false));
        structure.fillWithBlocks(world, start, 18, 1, 5, 18, 1, 17, Blocks.DIRT.getDefaultState());
        structure.fillWithBlocks(world, start, 18, 2, 6, 18, 2, 16, Blocks.DIRT.getDefaultState());
        structure.fillWithBlocks(world, start, 18, 3, 7, 18, 3, 15, Blocks.DIRT.getDefaultState());
        structure.fillWithBlocks(world, start, 18, 4, 7, 18, 4, 8, Blocks.GRASS_BLOCK.getDefaultState().with(SnowyDirtBlock.SNOWY, false));
        structure.fillWithBlocks(world, start, 18, 4, 9, 18, 4, 13, Blocks.DIRT.getDefaultState());
        structure.fillWithBlocks(world, start, 18, 4, 14, 18, 4, 15, Blocks.GRASS_BLOCK.getDefaultState().with(SnowyDirtBlock.SNOWY, false));
        structure.fillWithBlocks(world, start, 18, 5, 9, 18, 5, 13, Blocks.GRASS_BLOCK.getDefaultState().with(SnowyDirtBlock.SNOWY, false));
        structure.fillWithBlocks(world, start, 19, 0, 5, 19, 0, 17, Blocks.DIRT.getDefaultState());
        structure.fillWithBlocks(world, start, 19, 1, 5, 19, 1, 6, Blocks.GRASS_BLOCK.getDefaultState().with(SnowyDirtBlock.SNOWY, false));
        structure.fillWithBlocks(world, start, 19, 1, 7, 19, 1, 15, Blocks.DIRT.getDefaultState());
        structure.fillWithBlocks(world, start, 19, 1, 16, 19, 1, 17, Blocks.GRASS_BLOCK.getDefaultState().with(SnowyDirtBlock.SNOWY, false));
        structure.fillWithBlocks(world, start, 19, 2, 8, 19, 2, 14, Blocks.DIRT.getDefaultState());
        structure.fillWithBlocks(world, start, 19, 3, 8, 19, 3, 9, Blocks.GRASS_BLOCK.getDefaultState().with(SnowyDirtBlock.SNOWY, false));
        structure.fillWithBlocks(world, start, 19, 3, 10, 19, 3, 12, Blocks.DIRT.getDefaultState());
        structure.fillWithBlocks(world, start, 19, 3, 13, 19, 3, 14, Blocks.GRASS_BLOCK.getDefaultState().with(SnowyDirtBlock.SNOWY, false));
        structure.fillWithBlocks(world, start, 19, 4, 10, 19, 4, 12, Blocks.GRASS_BLOCK.getDefaultState().with(SnowyDirtBlock.SNOWY, false));
        structure.fillWithBlocks(world, start, 20, 0, 7, 20, 0, 15, Blocks.DIRT.getDefaultState());
        structure.fillWithBlocks(world, start, 20, 1, 7, 20, 1, 8, Blocks.GRASS_BLOCK.getDefaultState().with(SnowyDirtBlock.SNOWY, false));
        structure.fillWithBlocks(world, start, 20, 1, 9, 20, 1, 13, Blocks.DIRT.getDefaultState());
        structure.fillWithBlocks(world, start, 20, 1, 14, 20, 1, 15, Blocks.GRASS_BLOCK.getDefaultState().with(SnowyDirtBlock.SNOWY, false));
        structure.fillWithBlocks(world, start, 20, 2, 9, 20, 2, 13, Blocks.GRASS_BLOCK.getDefaultState().with(SnowyDirtBlock.SNOWY, false));
        structure.fillWithBlocks(world, start, 21, 0, 8, 21, 0, 9, Blocks.GRASS_BLOCK.getDefaultState().with(SnowyDirtBlock.SNOWY, false));
        structure.fillWithBlocks(world, start, 21, 0, 10, 21, 0, 12, Blocks.DIRT.getDefaultState());
        structure.fillWithBlocks(world, start, 21, 0, 13, 21, 0, 14, Blocks.GRASS_BLOCK.getDefaultState().with(SnowyDirtBlock.SNOWY, false));
        structure.fillWithBlocks(world, start, 21, 1, 10, 21, 1, 12, Blocks.GRASS_BLOCK.getDefaultState().with(SnowyDirtBlock.SNOWY, false));

    }
    
}
