package mod.arcalitegames.odyssey.world.structure.structures.forts.abandoned_fort;

import mod.arcalitegames.buildersaddition.Index;
import mod.arcalitegames.buildersaddition.blocks.Bookshelf;
import mod.arcalitegames.buildersaddition.blocks.Stool;
import mod.arcalitegames.buildersaddition.state.StoolState;
import mod.arcalitegames.odyssey.world.structure.StructureBase;
import net.minecraft.block.AbstractFurnaceBlock;
import net.minecraft.block.BarrelBlock;
import net.minecraft.block.Blocks;
import net.minecraft.block.CampfireBlock;
import net.minecraft.block.ChestBlock;
import net.minecraft.block.ComposterBlock;
import net.minecraft.block.FenceGateBlock;
import net.minecraft.block.HorizontalBlock;
import net.minecraft.block.LadderBlock;
import net.minecraft.block.LeavesBlock;
import net.minecraft.block.SlabBlock;
import net.minecraft.block.SnowyDirtBlock;
import net.minecraft.block.StairsBlock;
import net.minecraft.block.TrapDoorBlock;
import net.minecraft.block.VineBlock;
import net.minecraft.block.WallBlock;
import net.minecraft.block.WallHeight;
import net.minecraft.block.WallTorchBlock;
import net.minecraft.state.properties.ChestType;
import net.minecraft.state.properties.Half;
import net.minecraft.state.properties.SlabType;
import net.minecraft.state.properties.StairsShape;
import net.minecraft.util.Direction;
import net.minecraft.util.math.BlockPos;
import net.minecraft.world.World;

public class AbandonedFortComponents
{

	public static BlockPos start;
    public static World world;
    public static StructureBase structure;

    public static void init(World worldIn, BlockPos blockPos, StructureBase structureIn)
    {
        world = worldIn; start = blockPos; structure = structureIn;
    }
    
    public static void generatePart1()
    {
        structure.setBlockState(world, Blocks.GRASS_BLOCK.getDefaultState().with(SnowyDirtBlock.SNOWY, false), 0, 0, 0, start);
        structure.setBlockState(world, Blocks.GRASS_BLOCK.getDefaultState().with(SnowyDirtBlock.SNOWY, false), 1, 0, 9, start);
        structure.setBlockState(world, Blocks.GRASS_BLOCK.getDefaultState().with(SnowyDirtBlock.SNOWY, false), 1, 0, 12, start);
        structure.setBlockState(world, Blocks.GRASS_BLOCK.getDefaultState().with(SnowyDirtBlock.SNOWY, false), 2, 0, 6, start);
        structure.setBlockState(world, Blocks.GRASS_BLOCK.getDefaultState().with(SnowyDirtBlock.SNOWY, false), 2, 0, 31, start);
        structure.setBlockState(world, Blocks.GRASS_BLOCK.getDefaultState().with(SnowyDirtBlock.SNOWY, false), 2, 0, 37, start);
        structure.setBlockState(world, Blocks.GRASS_BLOCK.getDefaultState().with(SnowyDirtBlock.SNOWY, false), 2, 1, 14, start);
        structure.setBlockState(world, Blocks.GRASS_BLOCK.getDefaultState().with(SnowyDirtBlock.SNOWY, false), 2, 1, 32, start);
        structure.setBlockState(world, Blocks.GRASS_BLOCK.getDefaultState().with(SnowyDirtBlock.SNOWY, false), 2, 1, 36, start);
        structure.setBlockState(world, Blocks.GRASS_BLOCK.getDefaultState().with(SnowyDirtBlock.SNOWY, false), 2, 2, 7, start);
        structure.setBlockState(world, Blocks.GRASS_BLOCK.getDefaultState().with(SnowyDirtBlock.SNOWY, false), 2, 2, 13, start);
        structure.setBlockState(world, Blocks.GRASS_BLOCK.getDefaultState().with(SnowyDirtBlock.SNOWY, false), 2, 2, 33, start);
        structure.setBlockState(world, Blocks.GRASS_BLOCK.getDefaultState().with(SnowyDirtBlock.SNOWY, false), 2, 2, 35, start);
        structure.setBlockState(world, Blocks.GRASS_BLOCK.getDefaultState().with(SnowyDirtBlock.SNOWY, false), 2, 3, 34, start);
        structure.setBlockState(world, Blocks.STONE.getDefaultState(), 3, 1, 19, start);
        structure.setBlockState(world, Blocks.GRASS_BLOCK.getDefaultState().with(SnowyDirtBlock.SNOWY, false), 3, 2, 38, start);
        structure.setBlockState(world, Blocks.GRASS_BLOCK.getDefaultState().with(SnowyDirtBlock.SNOWY, false), 3, 3, 5, start);
        structure.setBlockState(world, Blocks.GRASS_BLOCK.getDefaultState().with(SnowyDirtBlock.SNOWY, false), 3, 3, 31, start);
        structure.setBlockState(world, Blocks.GRASS_BLOCK.getDefaultState().with(SnowyDirtBlock.SNOWY, false), 3, 4, 6, start);
        structure.setBlockState(world, Blocks.GRASS_BLOCK.getDefaultState().with(SnowyDirtBlock.SNOWY, false), 3, 4, 37, start);
        structure.setBlockState(world, Blocks.GRASS_BLOCK.getDefaultState().with(SnowyDirtBlock.SNOWY, false), 4, 1, 39, start);
        structure.setBlockState(world, Blocks.GRASS_BLOCK.getDefaultState().with(SnowyDirtBlock.SNOWY, false), 5, 0, 3, start);
        structure.setBlockState(world, Blocks.GRASS_BLOCK.getDefaultState().with(SnowyDirtBlock.SNOWY, false), 5, 0, 40, start);
        structure.setBlockState(world, Blocks.GRASS_BLOCK.getDefaultState().with(SnowyDirtBlock.SNOWY, false), 5, 3, 39, start);
        structure.setBlockState(world, Blocks.AIR.getDefaultState(), 5, 6, 19, start);
        structure.setBlockState(world, Blocks.AIR.getDefaultState(), 5, 6, 37, start);
        structure.setBlockState(world, Blocks.COBBLESTONE_STAIRS.getDefaultState().with(StairsBlock.FACING, Direction.EAST).with(StairsBlock.WATERLOGGED, false).with(StairsBlock.SHAPE, StairsShape.STRAIGHT).with(StairsBlock.HALF, Half.TOP), 5, 10, 19, start);
        structure.setBlockState(world, Blocks.COBBLESTONE_WALL.getDefaultState().with(WallBlock.WATERLOGGED, false).with(WallBlock.UP, true).with(WallBlock.WALL_HEIGHT_NORTH, WallHeight.LOW).with(WallBlock.WALL_HEIGHT_SOUTH, WallHeight.LOW).with(WallBlock.WALL_HEIGHT_EAST, WallHeight.LOW).with(WallBlock.WALL_HEIGHT_WEST, WallHeight.LOW), 5, 11, 13, start);
        structure.setBlockState(world, Blocks.SPRUCE_SLAB.getDefaultState().with(SlabBlock.TYPE, SlabType.TOP).with(SlabBlock.WATERLOGGED, false), 5, 11, 14, start);
        structure.setBlockState(world, Blocks.VINE.getDefaultState().with(VineBlock.UP, true).with(VineBlock.NORTH, false).with(VineBlock.SOUTH, false).with(VineBlock.EAST, true).with(VineBlock.WEST, false), 5, 11, 16, start);
        structure.setBlockState(world, Blocks.VINE.getDefaultState().with(VineBlock.UP, true).with(VineBlock.NORTH, false).with(VineBlock.SOUTH, false).with(VineBlock.EAST, false).with(VineBlock.WEST, false), 5, 11, 17, start);
        structure.setBlockState(world, Blocks.SPRUCE_SLAB.getDefaultState().with(SlabBlock.TYPE, SlabType.TOP).with(SlabBlock.WATERLOGGED, false), 5, 11, 18, start);
        structure.setBlockState(world, Blocks.COBBLESTONE_WALL.getDefaultState().with(WallBlock.WATERLOGGED, false).with(WallBlock.UP, true).with(WallBlock.WALL_HEIGHT_NORTH, WallHeight.LOW).with(WallBlock.WALL_HEIGHT_SOUTH, WallHeight.LOW).with(WallBlock.WALL_HEIGHT_EAST, WallHeight.LOW).with(WallBlock.WALL_HEIGHT_WEST, WallHeight.LOW), 5, 11, 19, start);
        structure.setBlockState(world, Blocks.COBBLESTONE_STAIRS.getDefaultState().with(StairsBlock.FACING, Direction.EAST).with(StairsBlock.WATERLOGGED, false).with(StairsBlock.SHAPE, StairsShape.STRAIGHT).with(StairsBlock.HALF, Half.BOTTOM), 5, 12, 13, start);
        structure.setBlockState(world, Blocks.SPRUCE_WOOD.getDefaultState(), 5, 12, 14, start);
        structure.setBlockState(world, Blocks.SPRUCE_STAIRS.getDefaultState().with(StairsBlock.FACING, Direction.EAST).with(StairsBlock.WATERLOGGED, false).with(StairsBlock.SHAPE, StairsShape.STRAIGHT).with(StairsBlock.HALF, Half.BOTTOM), 5, 12, 15, start);
        structure.setBlockState(world, Blocks.COBBLESTONE_STAIRS.getDefaultState().with(StairsBlock.FACING, Direction.EAST).with(StairsBlock.WATERLOGGED, false).with(StairsBlock.SHAPE, StairsShape.STRAIGHT).with(StairsBlock.HALF, Half.BOTTOM), 5, 12, 19, start);
        structure.setBlockState(world, Blocks.GRASS_BLOCK.getDefaultState().with(SnowyDirtBlock.SNOWY, false), 6, 1, 3, start);
        structure.setBlockState(world, Blocks.COBBLESTONE_STAIRS.getDefaultState().with(StairsBlock.FACING, Direction.EAST).with(StairsBlock.WATERLOGGED, false).with(StairsBlock.SHAPE, StairsShape.STRAIGHT).with(StairsBlock.HALF, Half.BOTTOM), 6, 7, 8, start);
        structure.setBlockState(world, Blocks.STONE.getDefaultState(), 6, 7, 9, start);
        structure.setBlockState(world, Blocks.COBBLESTONE_STAIRS.getDefaultState().with(StairsBlock.FACING, Direction.EAST).with(StairsBlock.WATERLOGGED, false).with(StairsBlock.SHAPE, StairsShape.STRAIGHT).with(StairsBlock.HALF, Half.BOTTOM), 6, 7, 10, start);
        structure.setBlockState(world, Blocks.MOSSY_COBBLESTONE.getDefaultState(), 6, 7, 11, start);
        structure.setBlockState(world, Blocks.COBBLESTONE_STAIRS.getDefaultState().with(StairsBlock.FACING, Direction.EAST).with(StairsBlock.WATERLOGGED, false).with(StairsBlock.SHAPE, StairsShape.STRAIGHT).with(StairsBlock.HALF, Half.BOTTOM), 6, 7, 12, start);
        structure.setBlockState(world, Blocks.COBBLESTONE_STAIRS.getDefaultState().with(StairsBlock.FACING, Direction.EAST).with(StairsBlock.WATERLOGGED, false).with(StairsBlock.SHAPE, StairsShape.STRAIGHT).with(StairsBlock.HALF, Half.BOTTOM), 6, 7, 14, start);
        structure.setBlockState(world, Blocks.COBBLESTONE_STAIRS.getDefaultState().with(StairsBlock.FACING, Direction.EAST).with(StairsBlock.WATERLOGGED, false).with(StairsBlock.SHAPE, StairsShape.STRAIGHT).with(StairsBlock.HALF, Half.BOTTOM), 6, 7, 16, start);
        structure.setBlockState(world, Blocks.COBBLESTONE_STAIRS.getDefaultState().with(StairsBlock.FACING, Direction.EAST).with(StairsBlock.WATERLOGGED, false).with(StairsBlock.SHAPE, StairsShape.STRAIGHT).with(StairsBlock.HALF, Half.BOTTOM), 6, 7, 18, start);
        structure.setBlockState(world, Blocks.COBBLESTONE_STAIRS.getDefaultState().with(StairsBlock.FACING, Direction.EAST).with(StairsBlock.WATERLOGGED, false).with(StairsBlock.SHAPE, StairsShape.STRAIGHT).with(StairsBlock.HALF, Half.BOTTOM), 6, 7, 20, start);
        structure.setBlockState(world, Blocks.COBBLESTONE_STAIRS.getDefaultState().with(StairsBlock.FACING, Direction.EAST).with(StairsBlock.WATERLOGGED, false).with(StairsBlock.SHAPE, StairsShape.STRAIGHT).with(StairsBlock.HALF, Half.BOTTOM), 6, 7, 22, start);
        structure.setBlockState(world, Blocks.CHISELED_STONE_BRICKS.getDefaultState(), 6, 8, 7, start);
        structure.setBlockState(world, Blocks.COBBLESTONE_SLAB.getDefaultState().with(SlabBlock.TYPE, SlabType.BOTTOM).with(SlabBlock.WATERLOGGED, false), 6, 8, 8, start);
        structure.setBlockState(world, Blocks.COBBLESTONE_WALL.getDefaultState().with(WallBlock.WATERLOGGED, false).with(WallBlock.UP, true).with(WallBlock.WALL_HEIGHT_NORTH, WallHeight.LOW).with(WallBlock.WALL_HEIGHT_SOUTH, WallHeight.LOW).with(WallBlock.WALL_HEIGHT_EAST, WallHeight.LOW).with(WallBlock.WALL_HEIGHT_WEST, WallHeight.LOW), 6, 8, 9, start);
        structure.setBlockState(world, Blocks.COBBLESTONE_SLAB.getDefaultState().with(SlabBlock.TYPE, SlabType.BOTTOM).with(SlabBlock.WATERLOGGED, false), 6, 8, 10, start);
        structure.setBlockState(world, Blocks.MOSSY_COBBLESTONE_WALL.getDefaultState().with(WallBlock.WATERLOGGED, false).with(WallBlock.UP, true).with(WallBlock.WALL_HEIGHT_NORTH, WallHeight.LOW).with(WallBlock.WALL_HEIGHT_SOUTH, WallHeight.LOW).with(WallBlock.WALL_HEIGHT_EAST, WallHeight.LOW).with(WallBlock.WALL_HEIGHT_WEST, WallHeight.LOW), 6, 8, 11, start);
        structure.setBlockState(world, Blocks.COBBLESTONE_SLAB.getDefaultState().with(SlabBlock.TYPE, SlabType.BOTTOM).with(SlabBlock.WATERLOGGED, false), 6, 8, 12, start);
        structure.setBlockState(world, Blocks.MOSSY_COBBLESTONE.getDefaultState(), 6, 8, 13, start);
        structure.setBlockState(world, Blocks.COBBLESTONE_SLAB.getDefaultState().with(SlabBlock.TYPE, SlabType.BOTTOM).with(SlabBlock.WATERLOGGED, false), 6, 8, 14, start);
        structure.setBlockState(world, Blocks.COBBLESTONE_WALL.getDefaultState().with(WallBlock.WATERLOGGED, false).with(WallBlock.UP, true).with(WallBlock.WALL_HEIGHT_NORTH, WallHeight.LOW).with(WallBlock.WALL_HEIGHT_SOUTH, WallHeight.LOW).with(WallBlock.WALL_HEIGHT_EAST, WallHeight.LOW).with(WallBlock.WALL_HEIGHT_WEST, WallHeight.LOW), 6, 8, 15, start);
        structure.setBlockState(world, Blocks.MOSSY_COBBLESTONE_SLAB.getDefaultState().with(SlabBlock.TYPE, SlabType.BOTTOM).with(SlabBlock.WATERLOGGED, false), 6, 8, 16, start);
        structure.setBlockState(world, Blocks.COBBLESTONE_WALL.getDefaultState().with(WallBlock.WATERLOGGED, false).with(WallBlock.UP, true).with(WallBlock.WALL_HEIGHT_NORTH, WallHeight.LOW).with(WallBlock.WALL_HEIGHT_SOUTH, WallHeight.LOW).with(WallBlock.WALL_HEIGHT_EAST, WallHeight.LOW).with(WallBlock.WALL_HEIGHT_WEST, WallHeight.LOW), 6, 8, 17, start);
        structure.setBlockState(world, Blocks.COBBLESTONE_SLAB.getDefaultState().with(SlabBlock.TYPE, SlabType.BOTTOM).with(SlabBlock.WATERLOGGED, false), 6, 8, 18, start);
        structure.setBlockState(world, Blocks.STONE.getDefaultState(), 6, 8, 19, start);
        structure.setBlockState(world, Blocks.MOSSY_COBBLESTONE_SLAB.getDefaultState().with(SlabBlock.TYPE, SlabType.BOTTOM).with(SlabBlock.WATERLOGGED, false), 6, 8, 20, start);
        structure.setBlockState(world, Blocks.MOSSY_COBBLESTONE_WALL.getDefaultState().with(WallBlock.WATERLOGGED, false).with(WallBlock.UP, true).with(WallBlock.WALL_HEIGHT_NORTH, WallHeight.LOW).with(WallBlock.WALL_HEIGHT_SOUTH, WallHeight.LOW).with(WallBlock.WALL_HEIGHT_EAST, WallHeight.LOW).with(WallBlock.WALL_HEIGHT_WEST, WallHeight.LOW), 6, 8, 21, start);
        structure.setBlockState(world, Blocks.COBBLESTONE_SLAB.getDefaultState().with(SlabBlock.TYPE, SlabType.BOTTOM).with(SlabBlock.WATERLOGGED, false), 6, 8, 22, start);
        structure.setBlockState(world, Blocks.CHISELED_STONE_BRICKS.getDefaultState(), 6, 8, 23, start);
        structure.setBlockState(world, Blocks.MOSSY_COBBLESTONE_WALL.getDefaultState().with(WallBlock.WATERLOGGED, false).with(WallBlock.UP, true).with(WallBlock.WALL_HEIGHT_NORTH, WallHeight.LOW).with(WallBlock.WALL_HEIGHT_SOUTH, WallHeight.LOW).with(WallBlock.WALL_HEIGHT_EAST, WallHeight.LOW).with(WallBlock.WALL_HEIGHT_WEST, WallHeight.LOW), 6, 9, 7, start);
        structure.setBlockState(world, Blocks.COBBLESTONE.getDefaultState(), 6, 9, 19, start);
        structure.setBlockState(world, Blocks.JUNGLE_LEAVES.getDefaultState().with(LeavesBlock.PERSISTENT, true).with(LeavesBlock.DISTANCE, 7), 6, 9, 20, start);
        structure.setBlockState(world, Blocks.COBBLESTONE_WALL.getDefaultState().with(WallBlock.WATERLOGGED, false).with(WallBlock.UP, true).with(WallBlock.WALL_HEIGHT_NORTH, WallHeight.LOW).with(WallBlock.WALL_HEIGHT_SOUTH, WallHeight.LOW).with(WallBlock.WALL_HEIGHT_EAST, WallHeight.LOW).with(WallBlock.WALL_HEIGHT_WEST, WallHeight.LOW), 6, 9, 23, start);
        structure.setBlockState(world, Blocks.COBBLESTONE_STAIRS.getDefaultState().with(StairsBlock.FACING, Direction.EAST).with(StairsBlock.WATERLOGGED, false).with(StairsBlock.SHAPE, StairsShape.STRAIGHT).with(StairsBlock.HALF, Half.TOP), 6, 10, 14, start);
        structure.setBlockState(world, Blocks.COBBLESTONE_STAIRS.getDefaultState().with(StairsBlock.FACING, Direction.EAST).with(StairsBlock.WATERLOGGED, false).with(StairsBlock.SHAPE, StairsShape.STRAIGHT).with(StairsBlock.HALF, Half.TOP), 6, 10, 16, start);
        structure.setBlockState(world, Blocks.MOSSY_COBBLESTONE_STAIRS.getDefaultState().with(StairsBlock.FACING, Direction.EAST).with(StairsBlock.WATERLOGGED, false).with(StairsBlock.SHAPE, StairsShape.STRAIGHT).with(StairsBlock.HALF, Half.TOP), 6, 10, 18, start);
        structure.setBlockState(world, Blocks.MOSSY_COBBLESTONE.getDefaultState(), 6, 11, 14, start);
        structure.setBlockState(world, Blocks.COBBLESTONE_SLAB.getDefaultState().with(SlabBlock.TYPE, SlabType.TOP).with(SlabBlock.WATERLOGGED, false), 6, 11, 15, start);
        structure.setBlockState(world, Blocks.COBBLESTONE_SLAB.getDefaultState().with(SlabBlock.TYPE, SlabType.TOP).with(SlabBlock.WATERLOGGED, false), 6, 11, 17, start);
        structure.setBlockState(world, Blocks.COBBLESTONE.getDefaultState(), 6, 11, 19, start);
        structure.setBlockState(world, Blocks.SPRUCE_WOOD.getDefaultState(), 6, 12, 18, start);
        structure.setBlockState(world, Blocks.MOSSY_COBBLESTONE.getDefaultState(), 6, 12, 19, start);
        structure.setBlockState(world, Blocks.COBBLESTONE_STAIRS.getDefaultState().with(StairsBlock.FACING, Direction.EAST).with(StairsBlock.WATERLOGGED, false).with(StairsBlock.SHAPE, StairsShape.STRAIGHT).with(StairsBlock.HALF, Half.BOTTOM), 6, 13, 13, start);
        structure.setBlockState(world, Blocks.SPRUCE_SLAB.getDefaultState().with(SlabBlock.TYPE, SlabType.BOTTOM).with(SlabBlock.WATERLOGGED, false), 6, 13, 15, start);
        structure.setBlockState(world, Blocks.SPRUCE_STAIRS.getDefaultState().with(StairsBlock.FACING, Direction.EAST).with(StairsBlock.WATERLOGGED, false).with(StairsBlock.SHAPE, StairsShape.STRAIGHT).with(StairsBlock.HALF, Half.BOTTOM), 6, 13, 17, start);
        structure.setBlockState(world, Blocks.SPRUCE_SLAB.getDefaultState().with(SlabBlock.TYPE, SlabType.BOTTOM).with(SlabBlock.WATERLOGGED, false), 6, 13, 18, start);
        structure.setBlockState(world, Blocks.COBBLESTONE_STAIRS.getDefaultState().with(StairsBlock.FACING, Direction.EAST).with(StairsBlock.WATERLOGGED, false).with(StairsBlock.SHAPE, StairsShape.STRAIGHT).with(StairsBlock.HALF, Half.BOTTOM), 6, 13, 19, start);
        structure.setBlockState(world, Blocks.STONE.getDefaultState(), 7, 7, 8, start);
        structure.setBlockState(world, Blocks.COBBLESTONE.getDefaultState(), 7, 7, 10, start);
        structure.setBlockState(world, Blocks.STONE.getDefaultState(), 7, 7, 22, start);
        structure.setBlockState(world, Blocks.COBBLESTONE_STAIRS.getDefaultState().with(StairsBlock.FACING, Direction.NORTH).with(StairsBlock.WATERLOGGED, false).with(StairsBlock.SHAPE, StairsShape.STRAIGHT).with(StairsBlock.HALF, Half.BOTTOM), 7, 7, 23, start);
        structure.setBlockState(world, Blocks.COBBLESTONE_STAIRS.getDefaultState().with(StairsBlock.FACING, Direction.EAST).with(StairsBlock.WATERLOGGED, false).with(StairsBlock.SHAPE, StairsShape.STRAIGHT).with(StairsBlock.HALF, Half.BOTTOM), 7, 8, 11, start);
        structure.setBlockState(world, Blocks.COBBLESTONE.getDefaultState(), 7, 8, 12, start);
        structure.setBlockState(world, Blocks.MOSSY_COBBLESTONE.getDefaultState(), 7, 8, 17, start);
        structure.setBlockState(world, Blocks.STONE.getDefaultState(), 7, 8, 18, start);
        structure.setBlockState(world, Blocks.MOSSY_COBBLESTONE_SLAB.getDefaultState().with(SlabBlock.TYPE, SlabType.BOTTOM).with(SlabBlock.WATERLOGGED, false), 7, 8, 23, start);
        structure.setBlockState(world, Blocks.COBBLESTONE_STAIRS.getDefaultState().with(StairsBlock.FACING, Direction.SOUTH).with(StairsBlock.WATERLOGGED, false).with(StairsBlock.SHAPE, StairsShape.STRAIGHT).with(StairsBlock.HALF, Half.TOP), 7, 9, 11, start);
        structure.setBlockState(world, Blocks.STONE.getDefaultState(), 7, 9, 14, start);
        structure.setBlockState(world, Blocks.MOSSY_COBBLESTONE.getDefaultState(), 7, 9, 16, start);
        structure.setBlockState(world, Blocks.COBBLESTONE.getDefaultState(), 7, 9, 17, start);
        structure.setBlockState(world, Blocks.MOSSY_COBBLESTONE_STAIRS.getDefaultState().with(StairsBlock.FACING, Direction.EAST).with(StairsBlock.WATERLOGGED, false).with(StairsBlock.SHAPE, StairsShape.STRAIGHT).with(StairsBlock.HALF, Half.BOTTOM), 7, 9, 21, start);
        structure.setBlockState(world, Blocks.JUNGLE_LEAVES.getDefaultState().with(LeavesBlock.PERSISTENT, true).with(LeavesBlock.DISTANCE, 7), 7, 9, 22, start);
        structure.setBlockState(world, Blocks.COBBLESTONE_WALL.getDefaultState().with(WallBlock.WATERLOGGED, false).with(WallBlock.UP, true).with(WallBlock.WALL_HEIGHT_NORTH, WallHeight.LOW).with(WallBlock.WALL_HEIGHT_SOUTH, WallHeight.LOW).with(WallBlock.WALL_HEIGHT_EAST, WallHeight.LOW).with(WallBlock.WALL_HEIGHT_WEST, WallHeight.LOW), 7, 10, 11, start);
        structure.setBlockState(world, Blocks.COBBLESTONE_STAIRS.getDefaultState().with(StairsBlock.FACING, Direction.EAST).with(StairsBlock.WATERLOGGED, false).with(StairsBlock.SHAPE, StairsShape.STRAIGHT).with(StairsBlock.HALF, Half.BOTTOM), 7, 10, 12, start);
        structure.setBlockState(world, Blocks.STONE.getDefaultState(), 7, 10, 18, start);
        structure.setBlockState(world, Blocks.STONE.getDefaultState(), 7, 10, 20, start);
        structure.setBlockState(world, Blocks.OAK_LEAVES.getDefaultState().with(LeavesBlock.PERSISTENT, true).with(LeavesBlock.DISTANCE, 7), 7, 10, 21, start);
        structure.setBlockState(world, Blocks.COBBLESTONE_SLAB.getDefaultState().with(SlabBlock.TYPE, SlabType.BOTTOM).with(SlabBlock.WATERLOGGED, false), 7, 11, 12, start);
        structure.setBlockState(world, Blocks.COBBLESTONE.getDefaultState(), 7, 11, 14, start);
        structure.setBlockState(world, Blocks.MOSSY_COBBLESTONE_WALL.getDefaultState().with(WallBlock.WATERLOGGED, false).with(WallBlock.UP, true).with(WallBlock.WALL_HEIGHT_NORTH, WallHeight.LOW).with(WallBlock.WALL_HEIGHT_SOUTH, WallHeight.LOW).with(WallBlock.WALL_HEIGHT_EAST, WallHeight.LOW).with(WallBlock.WALL_HEIGHT_WEST, WallHeight.LOW), 7, 11, 20, start);
        structure.setBlockState(world, Blocks.VINE.getDefaultState().with(VineBlock.UP, false).with(VineBlock.NORTH, false).with(VineBlock.SOUTH, true).with(VineBlock.EAST, true).with(VineBlock.WEST, false), 7, 12, 12, start);
        structure.setBlockState(world, Blocks.SPRUCE_WOOD.getDefaultState(), 7, 13, 15, start);
        structure.setBlockState(world, Blocks.COBBLESTONE_STAIRS.getDefaultState().with(StairsBlock.FACING, Direction.EAST).with(StairsBlock.WATERLOGGED, false).with(StairsBlock.SHAPE, StairsShape.STRAIGHT).with(StairsBlock.HALF, Half.BOTTOM), 7, 14, 13, start);
        structure.setBlockState(world, Blocks.SPRUCE_STAIRS.getDefaultState().with(StairsBlock.FACING, Direction.EAST).with(StairsBlock.WATERLOGGED, false).with(StairsBlock.SHAPE, StairsShape.STRAIGHT).with(StairsBlock.HALF, Half.BOTTOM), 7, 14, 14, start);
        structure.setBlockState(world, Blocks.SPRUCE_SLAB.getDefaultState().with(SlabBlock.TYPE, SlabType.BOTTOM).with(SlabBlock.WATERLOGGED, false), 7, 14, 15, start);
        structure.setBlockState(world, Blocks.SPRUCE_WOOD.getDefaultState(), 7, 14, 16, start);
        structure.setBlockState(world, Blocks.SPRUCE_SLAB.getDefaultState().with(SlabBlock.TYPE, SlabType.BOTTOM).with(SlabBlock.WATERLOGGED, false), 7, 14, 17, start);
        structure.setBlockState(world, Blocks.SPRUCE_WOOD.getDefaultState(), 7, 14, 18, start);
        structure.setBlockState(world, Blocks.COBBLESTONE_STAIRS.getDefaultState().with(StairsBlock.FACING, Direction.EAST).with(StairsBlock.WATERLOGGED, false).with(StairsBlock.SHAPE, StairsShape.STRAIGHT).with(StairsBlock.HALF, Half.BOTTOM), 7, 14, 19, start);
        structure.setBlockState(world, Blocks.COBBLESTONE_STAIRS.getDefaultState().with(StairsBlock.FACING, Direction.EAST).with(StairsBlock.WATERLOGGED, false).with(StairsBlock.SHAPE, StairsShape.STRAIGHT).with(StairsBlock.HALF, Half.TOP), 7, 15, 14, start);
        structure.setBlockState(world, Blocks.COBBLESTONE_WALL.getDefaultState().with(WallBlock.WATERLOGGED, false).with(WallBlock.UP, true).with(WallBlock.WALL_HEIGHT_NORTH, WallHeight.LOW).with(WallBlock.WALL_HEIGHT_SOUTH, WallHeight.LOW).with(WallBlock.WALL_HEIGHT_EAST, WallHeight.LOW).with(WallBlock.WALL_HEIGHT_WEST, WallHeight.LOW), 7, 15, 16, start);
        structure.setBlockState(world, Blocks.MOSSY_COBBLESTONE_STAIRS.getDefaultState().with(StairsBlock.FACING, Direction.EAST).with(StairsBlock.WATERLOGGED, false).with(StairsBlock.SHAPE, StairsShape.STRAIGHT).with(StairsBlock.HALF, Half.TOP), 7, 15, 18, start);
        structure.setBlockState(world, Blocks.COBBLESTONE_WALL.getDefaultState().with(WallBlock.WATERLOGGED, false).with(WallBlock.UP, true).with(WallBlock.WALL_HEIGHT_NORTH, WallHeight.LOW).with(WallBlock.WALL_HEIGHT_SOUTH, WallHeight.LOW).with(WallBlock.WALL_HEIGHT_EAST, WallHeight.LOW).with(WallBlock.WALL_HEIGHT_WEST, WallHeight.LOW), 7, 16, 14, start);
        structure.setBlockState(world, Blocks.MOSSY_STONE_BRICK_STAIRS.getDefaultState().with(StairsBlock.FACING, Direction.SOUTH).with(StairsBlock.WATERLOGGED, false).with(StairsBlock.SHAPE, StairsShape.STRAIGHT).with(StairsBlock.HALF, Half.TOP), 7, 16, 15, start);
        structure.setBlockState(world, Blocks.COBBLESTONE_WALL.getDefaultState().with(WallBlock.WATERLOGGED, false).with(WallBlock.UP, true).with(WallBlock.WALL_HEIGHT_NORTH, WallHeight.LOW).with(WallBlock.WALL_HEIGHT_SOUTH, WallHeight.LOW).with(WallBlock.WALL_HEIGHT_EAST, WallHeight.LOW).with(WallBlock.WALL_HEIGHT_WEST, WallHeight.LOW), 7, 16, 16, start);
        structure.setBlockState(world, Blocks.STONE_BRICK_STAIRS.getDefaultState().with(StairsBlock.FACING, Direction.NORTH).with(StairsBlock.WATERLOGGED, false).with(StairsBlock.SHAPE, StairsShape.STRAIGHT).with(StairsBlock.HALF, Half.TOP), 7, 16, 17, start);
        structure.setBlockState(world, Blocks.COBBLESTONE_WALL.getDefaultState().with(WallBlock.WATERLOGGED, false).with(WallBlock.UP, true).with(WallBlock.WALL_HEIGHT_NORTH, WallHeight.LOW).with(WallBlock.WALL_HEIGHT_SOUTH, WallHeight.LOW).with(WallBlock.WALL_HEIGHT_EAST, WallHeight.LOW).with(WallBlock.WALL_HEIGHT_WEST, WallHeight.LOW), 7, 16, 18, start);
        structure.setBlockState(world, Blocks.MOSSY_COBBLESTONE_STAIRS.getDefaultState().with(StairsBlock.FACING, Direction.EAST).with(StairsBlock.WATERLOGGED, false).with(StairsBlock.SHAPE, StairsShape.STRAIGHT).with(StairsBlock.HALF, Half.BOTTOM), 7, 17, 14, start);
        structure.setBlockState(world, Blocks.STONE_BRICK_SLAB.getDefaultState().with(SlabBlock.TYPE, SlabType.BOTTOM).with(SlabBlock.WATERLOGGED, false), 7, 17, 15, start);
        structure.setBlockState(world, Blocks.MOSSY_STONE_BRICK_STAIRS.getDefaultState().with(StairsBlock.FACING, Direction.EAST).with(StairsBlock.WATERLOGGED, false).with(StairsBlock.SHAPE, StairsShape.STRAIGHT).with(StairsBlock.HALF, Half.TOP), 7, 17, 16, start);
        structure.setBlockState(world, Blocks.STONE_BRICK_SLAB.getDefaultState().with(SlabBlock.TYPE, SlabType.BOTTOM).with(SlabBlock.WATERLOGGED, false), 7, 17, 17, start);
        structure.setBlockState(world, Blocks.COBBLESTONE_STAIRS.getDefaultState().with(StairsBlock.FACING, Direction.EAST).with(StairsBlock.WATERLOGGED, false).with(StairsBlock.SHAPE, StairsShape.STRAIGHT).with(StairsBlock.HALF, Half.BOTTOM), 7, 17, 18, start);
        structure.setBlockState(world, Blocks.MOSSY_COBBLESTONE_WALL.getDefaultState().with(WallBlock.WATERLOGGED, false).with(WallBlock.UP, true).with(WallBlock.WALL_HEIGHT_NORTH, WallHeight.LOW).with(WallBlock.WALL_HEIGHT_SOUTH, WallHeight.LOW).with(WallBlock.WALL_HEIGHT_EAST, WallHeight.LOW).with(WallBlock.WALL_HEIGHT_WEST, WallHeight.LOW), 7, 18, 16, start);
        structure.setBlockState(world, Blocks.VINE.getDefaultState().with(VineBlock.UP, false).with(VineBlock.NORTH, false).with(VineBlock.SOUTH, false).with(VineBlock.EAST, true).with(VineBlock.WEST, false), 7, 19, 15, start);
        structure.setBlockState(world, Blocks.GRASS_BLOCK.getDefaultState().with(SnowyDirtBlock.SNOWY, false), 8, 2, 40, start);
        structure.setBlockState(world, Blocks.STONE.getDefaultState(), 8, 6, 9, start);
        structure.setBlockState(world, Blocks.STONE.getDefaultState(), 8, 6, 11, start);
        structure.setBlockState(world, Blocks.MOSSY_COBBLESTONE.getDefaultState(), 8, 6, 23, start);
        structure.setBlockState(world, Blocks.COBBLESTONE.getDefaultState(), 8, 7, 12, start);
        structure.setBlockState(world, Blocks.STONE.getDefaultState(), 8, 7, 16, start);
        structure.setBlockState(world, Blocks.COBBLESTONE_STAIRS.getDefaultState().with(StairsBlock.FACING, Direction.EAST).with(StairsBlock.WATERLOGGED, false).with(StairsBlock.SHAPE, StairsShape.STRAIGHT).with(StairsBlock.HALF, Half.BOTTOM), 8, 8, 10, start);
        structure.setBlockState(world, Blocks.JUNGLE_LEAVES.getDefaultState().with(LeavesBlock.PERSISTENT, true).with(LeavesBlock.DISTANCE, 7), 8, 8, 22, start);
        structure.setBlockState(world, Blocks.MOSSY_COBBLESTONE_WALL.getDefaultState().with(WallBlock.WATERLOGGED, false).with(WallBlock.UP, true).with(WallBlock.WALL_HEIGHT_NORTH, WallHeight.LOW).with(WallBlock.WALL_HEIGHT_SOUTH, WallHeight.LOW).with(WallBlock.WALL_HEIGHT_EAST, WallHeight.LOW).with(WallBlock.WALL_HEIGHT_WEST, WallHeight.LOW), 8, 8, 23, start);
        structure.setBlockState(world, Blocks.MOSSY_COBBLESTONE_WALL.getDefaultState().with(WallBlock.WATERLOGGED, false).with(WallBlock.UP, true).with(WallBlock.WALL_HEIGHT_NORTH, WallHeight.LOW).with(WallBlock.WALL_HEIGHT_SOUTH, WallHeight.LOW).with(WallBlock.WALL_HEIGHT_EAST, WallHeight.LOW).with(WallBlock.WALL_HEIGHT_WEST, WallHeight.LOW), 8, 9, 8, start);
        structure.setBlockState(world, Blocks.COBBLESTONE.getDefaultState(), 8, 9, 13, start);
        structure.setBlockState(world, Blocks.STONE.getDefaultState(), 8, 9, 20, start);
        structure.setBlockState(world, Blocks.COBBLESTONE.getDefaultState(), 8, 9, 21, start);
        structure.setBlockState(world, Blocks.COBBLESTONE_WALL.getDefaultState().with(WallBlock.WATERLOGGED, false).with(WallBlock.UP, true).with(WallBlock.WALL_HEIGHT_NORTH, WallHeight.LOW).with(WallBlock.WALL_HEIGHT_SOUTH, WallHeight.LOW).with(WallBlock.WALL_HEIGHT_EAST, WallHeight.LOW).with(WallBlock.WALL_HEIGHT_WEST, WallHeight.LOW), 8, 10, 8, start);
        structure.setBlockState(world, Blocks.COBBLESTONE_STAIRS.getDefaultState().with(StairsBlock.FACING, Direction.NORTH).with(StairsBlock.WATERLOGGED, false).with(StairsBlock.SHAPE, StairsShape.STRAIGHT).with(StairsBlock.HALF, Half.BOTTOM), 8, 10, 9, start);
        structure.setBlockState(world, Blocks.MOSSY_COBBLESTONE.getDefaultState(), 8, 10, 12, start);
        structure.setBlockState(world, Blocks.STONE.getDefaultState(), 8, 10, 13, start);
        structure.setBlockState(world, Blocks.COBBLESTONE.getDefaultState(), 8, 11, 8, start);
        structure.setBlockState(world, Blocks.COBBLESTONE_STAIRS.getDefaultState().with(StairsBlock.FACING, Direction.NORTH).with(StairsBlock.WATERLOGGED, false).with(StairsBlock.SHAPE, StairsShape.STRAIGHT).with(StairsBlock.HALF, Half.TOP), 8, 11, 9, start);
        structure.setBlockState(world, Blocks.VINE.getDefaultState().with(VineBlock.UP, false).with(VineBlock.NORTH, false).with(VineBlock.SOUTH, true).with(VineBlock.EAST, false).with(VineBlock.WEST, false), 8, 11, 10, start);
        structure.setBlockState(world, Blocks.COBBLESTONE.getDefaultState(), 8, 11, 12, start);
        structure.setBlockState(world, Blocks.WALL_TORCH.getDefaultState().with(WallTorchBlock.HORIZONTAL_FACING, Direction.EAST), 8, 11, 16, start);
        structure.setBlockState(world, Blocks.MOSSY_COBBLESTONE_STAIRS.getDefaultState().with(StairsBlock.FACING, Direction.SOUTH).with(StairsBlock.WATERLOGGED, false).with(StairsBlock.SHAPE, StairsShape.STRAIGHT).with(StairsBlock.HALF, Half.BOTTOM), 8, 12, 8, start);
        structure.setBlockState(world, Blocks.MOSSY_COBBLESTONE.getDefaultState(), 8, 12, 9, start);
        structure.setBlockState(world, Blocks.COBBLESTONE_STAIRS.getDefaultState().with(StairsBlock.FACING, Direction.NORTH).with(StairsBlock.WATERLOGGED, false).with(StairsBlock.SHAPE, StairsShape.STRAIGHT).with(StairsBlock.HALF, Half.TOP), 8, 12, 10, start);
        structure.setBlockState(world, Blocks.COBBLESTONE.getDefaultState(), 8, 12, 20, start);
        structure.setBlockState(world, Blocks.MOSSY_COBBLESTONE.getDefaultState(), 8, 12, 21, start);
        structure.setBlockState(world, Blocks.MOSSY_COBBLESTONE_STAIRS.getDefaultState().with(StairsBlock.FACING, Direction.NORTH).with(StairsBlock.WATERLOGGED, false).with(StairsBlock.SHAPE, StairsShape.STRAIGHT).with(StairsBlock.HALF, Half.TOP), 8, 12, 22, start);
        structure.setBlockState(world, Blocks.COBBLESTONE_STAIRS.getDefaultState().with(StairsBlock.FACING, Direction.SOUTH).with(StairsBlock.WATERLOGGED, false).with(StairsBlock.SHAPE, StairsShape.STRAIGHT).with(StairsBlock.HALF, Half.BOTTOM), 8, 13, 9, start);
        structure.setBlockState(world, Blocks.STONE.getDefaultState(), 8, 13, 12, start);
        structure.setBlockState(world, Blocks.MOSSY_COBBLESTONE.getDefaultState(), 8, 13, 17, start);
        structure.setBlockState(world, Blocks.MOSSY_COBBLESTONE.getDefaultState(), 8, 13, 20, start);
        structure.setBlockState(world, Blocks.MOSSY_COBBLESTONE_WALL.getDefaultState().with(WallBlock.WATERLOGGED, false).with(WallBlock.UP, true).with(WallBlock.WALL_HEIGHT_NORTH, WallHeight.LOW).with(WallBlock.WALL_HEIGHT_SOUTH, WallHeight.LOW).with(WallBlock.WALL_HEIGHT_EAST, WallHeight.LOW).with(WallBlock.WALL_HEIGHT_WEST, WallHeight.LOW), 8, 13, 22, start);
        structure.setBlockState(world, Blocks.MOSSY_COBBLESTONE_STAIRS.getDefaultState().with(StairsBlock.FACING, Direction.SOUTH).with(StairsBlock.WATERLOGGED, false).with(StairsBlock.SHAPE, StairsShape.STRAIGHT).with(StairsBlock.HALF, Half.BOTTOM), 8, 14, 10, start);
        structure.setBlockState(world, Blocks.COBBLESTONE.getDefaultState(), 8, 14, 11, start);
        structure.setBlockState(world, Blocks.MOSSY_COBBLESTONE.getDefaultState(), 8, 14, 12, start);
        structure.setBlockState(world, Blocks.COBBLESTONE.getDefaultState(), 8, 14, 17, start);
        structure.setBlockState(world, Blocks.COBBLESTONE_STAIRS.getDefaultState().with(StairsBlock.FACING, Direction.NORTH).with(StairsBlock.WATERLOGGED, false).with(StairsBlock.SHAPE, StairsShape.STRAIGHT).with(StairsBlock.HALF, Half.BOTTOM), 8, 14, 22, start);
        structure.setBlockState(world, Blocks.COBBLESTONE_STAIRS.getDefaultState().with(StairsBlock.FACING, Direction.SOUTH).with(StairsBlock.WATERLOGGED, false).with(StairsBlock.SHAPE, StairsShape.STRAIGHT).with(StairsBlock.HALF, Half.BOTTOM), 8, 15, 11, start);
        structure.setBlockState(world, Blocks.COBBLESTONE.getDefaultState(), 8, 15, 12, start);
        structure.setBlockState(world, Blocks.MOSSY_COBBLESTONE.getDefaultState(), 8, 15, 20, start);
        structure.setBlockState(world, Blocks.COBBLESTONE_STAIRS.getDefaultState().with(StairsBlock.FACING, Direction.NORTH).with(StairsBlock.WATERLOGGED, false).with(StairsBlock.SHAPE, StairsShape.STRAIGHT).with(StairsBlock.HALF, Half.BOTTOM), 8, 15, 21, start);
        structure.setBlockState(world, Blocks.COBBLESTONE_STAIRS.getDefaultState().with(StairsBlock.FACING, Direction.SOUTH).with(StairsBlock.WATERLOGGED, false).with(StairsBlock.SHAPE, StairsShape.STRAIGHT).with(StairsBlock.HALF, Half.TOP), 8, 16, 12, start);
        structure.setBlockState(world, Blocks.MOSSY_COBBLESTONE.getDefaultState(), 8, 16, 13, start);
        structure.setBlockState(world, Blocks.COBBLESTONE_STAIRS.getDefaultState().with(StairsBlock.FACING, Direction.NORTH).with(StairsBlock.WATERLOGGED, false).with(StairsBlock.SHAPE, StairsShape.STRAIGHT).with(StairsBlock.HALF, Half.TOP), 8, 16, 20, start);
        structure.setBlockState(world, Blocks.COBBLESTONE_WALL.getDefaultState().with(WallBlock.WATERLOGGED, false).with(WallBlock.UP, true).with(WallBlock.WALL_HEIGHT_NORTH, WallHeight.LOW).with(WallBlock.WALL_HEIGHT_SOUTH, WallHeight.LOW).with(WallBlock.WALL_HEIGHT_EAST, WallHeight.LOW).with(WallBlock.WALL_HEIGHT_WEST, WallHeight.LOW), 8, 17, 12, start);
        structure.setBlockState(world, Blocks.COBBLESTONE_WALL.getDefaultState().with(WallBlock.WATERLOGGED, false).with(WallBlock.UP, true).with(WallBlock.WALL_HEIGHT_NORTH, WallHeight.LOW).with(WallBlock.WALL_HEIGHT_SOUTH, WallHeight.LOW).with(WallBlock.WALL_HEIGHT_EAST, WallHeight.LOW).with(WallBlock.WALL_HEIGHT_WEST, WallHeight.LOW), 8, 17, 20, start);
        structure.setBlockState(world, Blocks.COBBLESTONE_SLAB.getDefaultState().with(SlabBlock.TYPE, SlabType.BOTTOM).with(SlabBlock.WATERLOGGED, false), 8, 18, 13, start);
        structure.setBlockState(world, Blocks.COBBLESTONE.getDefaultState(), 8, 18, 14, start);
        structure.setBlockState(world, Blocks.MOSSY_COBBLESTONE.getDefaultState(), 8, 18, 15, start);
        structure.setBlockState(world, Blocks.MOSSY_COBBLESTONE_SLAB.getDefaultState().with(SlabBlock.TYPE, SlabType.BOTTOM).with(SlabBlock.WATERLOGGED, false), 8, 18, 19, start);
        structure.setBlockState(world, Blocks.STONE.getDefaultState(), 9, 6, 8, start);
        structure.setBlockState(world, Blocks.STONE.getDefaultState(), 9, 6, 13, start);
        structure.setBlockState(world, Blocks.COBBLESTONE.getDefaultState(), 9, 6, 14, start);
        structure.setBlockState(world, Blocks.STONE.getDefaultState(), 9, 6, 23, start);
        structure.setBlockState(world, Blocks.COBBLESTONE.getDefaultState(), 9, 7, 20, start);
        structure.setBlockState(world, Blocks.MOSSY_COBBLESTONE_STAIRS.getDefaultState().with(StairsBlock.FACING, Direction.WEST).with(StairsBlock.WATERLOGGED, false).with(StairsBlock.SHAPE, StairsShape.STRAIGHT).with(StairsBlock.HALF, Half.TOP), 9, 7, 23, start);
        structure.setBlockState(world, Blocks.MOSSY_COBBLESTONE.getDefaultState(), 9, 8, 13, start);
        structure.setBlockState(world, Blocks.STONE.getDefaultState(), 9, 8, 17, start);
        structure.setBlockState(world, Blocks.COBBLESTONE_STAIRS.getDefaultState().with(StairsBlock.FACING, Direction.NORTH).with(StairsBlock.WATERLOGGED, false).with(StairsBlock.SHAPE, StairsShape.STRAIGHT).with(StairsBlock.HALF, Half.BOTTOM), 9, 8, 21, start);
        structure.setBlockState(world, Blocks.COBBLESTONE_STAIRS.getDefaultState().with(StairsBlock.FACING, Direction.EAST).with(StairsBlock.WATERLOGGED, false).with(StairsBlock.SHAPE, StairsShape.STRAIGHT).with(StairsBlock.HALF, Half.BOTTOM), 9, 8, 23, start);
        structure.setBlockState(world, Blocks.COBBLESTONE.getDefaultState(), 9, 9, 11, start);
        structure.setBlockState(world, Blocks.COBBLESTONE_SLAB.getDefaultState().with(SlabBlock.TYPE, SlabType.BOTTOM).with(SlabBlock.WATERLOGGED, false), 9, 9, 21, start);
        structure.setBlockState(world, Blocks.JUNGLE_LEAVES.getDefaultState().with(LeavesBlock.PERSISTENT, true).with(LeavesBlock.DISTANCE, 7), 9, 9, 23, start);
        structure.setBlockState(world, Blocks.COBBLESTONE_SLAB.getDefaultState().with(SlabBlock.TYPE, SlabType.TOP).with(SlabBlock.WATERLOGGED, false), 9, 11, 19, start);
        structure.setBlockState(world, Blocks.MOSSY_COBBLESTONE_STAIRS.getDefaultState().with(StairsBlock.FACING, Direction.WEST).with(StairsBlock.WATERLOGGED, false).with(StairsBlock.SHAPE, StairsShape.STRAIGHT).with(StairsBlock.HALF, Half.TOP), 9, 11, 21, start);
        structure.setBlockState(world, Blocks.SPRUCE_WOOD.getDefaultState(), 9, 12, 8, start);
        structure.setBlockState(world, Blocks.COBBLESTONE_STAIRS.getDefaultState().with(StairsBlock.FACING, Direction.NORTH).with(StairsBlock.WATERLOGGED, false).with(StairsBlock.SHAPE, StairsShape.STRAIGHT).with(StairsBlock.HALF, Half.BOTTOM), 9, 12, 21, start);
        structure.setBlockState(world, Blocks.SPRUCE_SLAB.getDefaultState().with(SlabBlock.TYPE, SlabType.BOTTOM).with(SlabBlock.WATERLOGGED, false), 9, 13, 8, start);
        structure.setBlockState(world, Blocks.SPRUCE_WOOD.getDefaultState(), 9, 13, 9, start);
        structure.setBlockState(world, Blocks.STONE.getDefaultState(), 9, 13, 19, start);
        structure.setBlockState(world, Blocks.MOSSY_COBBLESTONE_STAIRS.getDefaultState().with(StairsBlock.FACING, Direction.NORTH).with(StairsBlock.WATERLOGGED, false).with(StairsBlock.SHAPE, StairsShape.STRAIGHT).with(StairsBlock.HALF, Half.TOP), 9, 13, 21, start);
        structure.setBlockState(world, Blocks.CHEST.getDefaultState().with(ChestBlock.FACING, Direction.SOUTH).with(ChestBlock.WATERLOGGED, false).with(ChestBlock.TYPE, ChestType.SINGLE), 9, 14, 13, start);
        structure.setBlockState(world, Blocks.COBBLESTONE.getDefaultState(), 9, 14, 21, start);
        structure.setBlockState(world, Blocks.COBBLESTONE_WALL.getDefaultState().with(WallBlock.WATERLOGGED, false).with(WallBlock.UP, true).with(WallBlock.WALL_HEIGHT_NORTH, WallHeight.LOW).with(WallBlock.WALL_HEIGHT_SOUTH, WallHeight.LOW).with(WallBlock.WALL_HEIGHT_EAST, WallHeight.LOW).with(WallBlock.WALL_HEIGHT_WEST, WallHeight.LOW), 9, 15, 11, start);
        structure.setBlockState(world, Blocks.SPRUCE_WOOD.getDefaultState(), 9, 15, 12, start);
        structure.setBlockState(world, Blocks.SPRUCE_SLAB.getDefaultState().with(SlabBlock.TYPE, SlabType.TOP).with(SlabBlock.WATERLOGGED, false), 9, 15, 13, start);
        structure.setBlockState(world, Blocks.SPRUCE_WOOD.getDefaultState(), 9, 15, 20, start);
        structure.setBlockState(world, Blocks.COBBLESTONE_WALL.getDefaultState().with(WallBlock.WATERLOGGED, false).with(WallBlock.UP, true).with(WallBlock.WALL_HEIGHT_NORTH, WallHeight.LOW).with(WallBlock.WALL_HEIGHT_SOUTH, WallHeight.LOW).with(WallBlock.WALL_HEIGHT_EAST, WallHeight.LOW).with(WallBlock.WALL_HEIGHT_WEST, WallHeight.LOW), 9, 15, 21, start);
        structure.setBlockState(world, Blocks.SPRUCE_WOOD.getDefaultState(), 9, 16, 13, start);
        structure.setBlockState(world, Blocks.SPRUCE_STAIRS.getDefaultState().with(StairsBlock.FACING, Direction.SOUTH).with(StairsBlock.WATERLOGGED, false).with(StairsBlock.SHAPE, StairsShape.STRAIGHT).with(StairsBlock.HALF, Half.TOP), 9, 16, 18, start);
        structure.setBlockState(world, Blocks.SPRUCE_WOOD.getDefaultState(), 9, 16, 19, start);
        structure.setBlockState(world, Blocks.SPRUCE_STAIRS.getDefaultState().with(StairsBlock.FACING, Direction.SOUTH).with(StairsBlock.WATERLOGGED, false).with(StairsBlock.SHAPE, StairsShape.STRAIGHT).with(StairsBlock.HALF, Half.BOTTOM), 9, 17, 13, start);
        structure.setBlockState(world, Blocks.SPRUCE_STAIRS.getDefaultState().with(StairsBlock.FACING, Direction.NORTH).with(StairsBlock.WATERLOGGED, false).with(StairsBlock.SHAPE, StairsShape.STRAIGHT).with(StairsBlock.HALF, Half.TOP), 9, 17, 14, start);
        structure.setBlockState(world, Blocks.WALL_TORCH.getDefaultState().with(WallTorchBlock.HORIZONTAL_FACING, Direction.EAST), 9, 17, 16, start);
        structure.setBlockState(world, Blocks.SPRUCE_SLAB.getDefaultState().with(SlabBlock.TYPE, SlabType.TOP).with(SlabBlock.WATERLOGGED, false), 9, 17, 17, start);
        structure.setBlockState(world, Blocks.SPRUCE_STAIRS.getDefaultState().with(StairsBlock.FACING, Direction.NORTH).with(StairsBlock.WATERLOGGED, false).with(StairsBlock.SHAPE, StairsShape.STRAIGHT).with(StairsBlock.HALF, Half.BOTTOM), 9, 17, 19, start);
        structure.setBlockState(world, Blocks.SPRUCE_SLAB.getDefaultState().with(SlabBlock.TYPE, SlabType.BOTTOM).with(SlabBlock.WATERLOGGED, false), 9, 18, 14, start);
        structure.setBlockState(world, Blocks.SPRUCE_WOOD.getDefaultState(), 9, 18, 15, start);
        structure.setBlockState(world, Blocks.SPRUCE_SLAB.getDefaultState().with(SlabBlock.TYPE, SlabType.TOP).with(SlabBlock.WATERLOGGED, false), 9, 18, 16, start);
        structure.setBlockState(world, Blocks.SPRUCE_SLAB.getDefaultState().with(SlabBlock.TYPE, SlabType.BOTTOM).with(SlabBlock.WATERLOGGED, false), 9, 18, 18, start);
        structure.setBlockState(world, Blocks.COBBLESTONE.getDefaultState(), 10, 6, 19, start);
        structure.setBlockState(world, Blocks.STONE.getDefaultState(), 10, 6, 22, start);
        structure.setBlockState(world, Blocks.COBBLESTONE.getDefaultState(), 10, 6, 23, start);
        structure.setBlockState(world, Blocks.STONE.getDefaultState(), 10, 7, 8, start);
        structure.setBlockState(world, Blocks.MOSSY_COBBLESTONE.getDefaultState(), 10, 7, 9, start);
        structure.setBlockState(world, Blocks.COBBLESTONE.getDefaultState(), 10, 7, 15, start);
        structure.setBlockState(world, Blocks.STONE.getDefaultState(), 10, 7, 21, start);
        structure.setBlockState(world, Blocks.COBBLESTONE_STAIRS.getDefaultState().with(StairsBlock.FACING, Direction.EAST).with(StairsBlock.WATERLOGGED, false).with(StairsBlock.SHAPE, StairsShape.STRAIGHT).with(StairsBlock.HALF, Half.TOP), 10, 7, 23, start);
        structure.setBlockState(world, Blocks.STONE.getDefaultState(), 10, 8, 11, start);
        structure.setBlockState(world, Blocks.COBBLESTONE.getDefaultState(), 10, 8, 19, start);
        structure.setBlockState(world, Blocks.COBBLESTONE_STAIRS.getDefaultState().with(StairsBlock.FACING, Direction.NORTH).with(StairsBlock.WATERLOGGED, false).with(StairsBlock.SHAPE, StairsShape.STRAIGHT).with(StairsBlock.HALF, Half.TOP), 10, 8, 21, start);
        structure.setBlockState(world, Blocks.MOSSY_COBBLESTONE_STAIRS.getDefaultState().with(StairsBlock.FACING, Direction.WEST).with(StairsBlock.WATERLOGGED, false).with(StairsBlock.SHAPE, StairsShape.STRAIGHT).with(StairsBlock.HALF, Half.BOTTOM), 10, 8, 23, start);
        structure.setBlockState(world, Blocks.VINE.getDefaultState().with(VineBlock.UP, false).with(VineBlock.NORTH, false).with(VineBlock.SOUTH, true).with(VineBlock.EAST, false).with(VineBlock.WEST, false), 10, 9, 10, start);
        structure.setBlockState(world, Blocks.COBBLESTONE_WALL.getDefaultState().with(WallBlock.WATERLOGGED, false).with(WallBlock.UP, true).with(WallBlock.WALL_HEIGHT_NORTH, WallHeight.LOW).with(WallBlock.WALL_HEIGHT_SOUTH, WallHeight.LOW).with(WallBlock.WALL_HEIGHT_EAST, WallHeight.LOW).with(WallBlock.WALL_HEIGHT_WEST, WallHeight.LOW), 10, 9, 21, start);
        structure.setBlockState(world, Blocks.STONE.getDefaultState(), 10, 10, 11, start);
        structure.setBlockState(world, Blocks.MOSSY_COBBLESTONE.getDefaultState(), 10, 10, 19, start);
        structure.setBlockState(world, Blocks.MOSSY_COBBLESTONE_WALL.getDefaultState().with(WallBlock.WATERLOGGED, false).with(WallBlock.UP, true).with(WallBlock.WALL_HEIGHT_NORTH, WallHeight.LOW).with(WallBlock.WALL_HEIGHT_SOUTH, WallHeight.LOW).with(WallBlock.WALL_HEIGHT_EAST, WallHeight.LOW).with(WallBlock.WALL_HEIGHT_WEST, WallHeight.LOW), 10, 10, 21, start);
        structure.setBlockState(world, Blocks.WALL_TORCH.getDefaultState().with(WallTorchBlock.HORIZONTAL_FACING, Direction.NORTH), 10, 11, 18, start);
        structure.setBlockState(world, Blocks.STONE.getDefaultState(), 10, 11, 19, start);
        structure.setBlockState(world, Blocks.COBBLESTONE_WALL.getDefaultState().with(WallBlock.WATERLOGGED, false).with(WallBlock.UP, true).with(WallBlock.WALL_HEIGHT_NORTH, WallHeight.LOW).with(WallBlock.WALL_HEIGHT_SOUTH, WallHeight.LOW).with(WallBlock.WALL_HEIGHT_EAST, WallHeight.LOW).with(WallBlock.WALL_HEIGHT_WEST, WallHeight.LOW), 10, 11, 21, start);
        structure.setBlockState(world, Blocks.SPRUCE_TRAPDOOR.getDefaultState().with(HorizontalBlock.HORIZONTAL_FACING, Direction.NORTH).with(TrapDoorBlock.HALF, Half.TOP).with(TrapDoorBlock.WATERLOGGED, false).with(TrapDoorBlock.POWERED, false).with(TrapDoorBlock.OPEN, false), 10, 12, 8, start);
        structure.setBlockState(world, Blocks.WALL_TORCH.getDefaultState().with(WallTorchBlock.HORIZONTAL_FACING, Direction.SOUTH), 10, 12, 12, start);
        structure.setBlockState(world, Blocks.COBBLESTONE.getDefaultState(), 10, 12, 21, start);
        structure.setBlockState(world, Blocks.MOSSY_COBBLESTONE_WALL.getDefaultState().with(WallBlock.WATERLOGGED, false).with(WallBlock.UP, true).with(WallBlock.WALL_HEIGHT_NORTH, WallHeight.LOW).with(WallBlock.WALL_HEIGHT_SOUTH, WallHeight.LOW).with(WallBlock.WALL_HEIGHT_EAST, WallHeight.LOW).with(WallBlock.WALL_HEIGHT_WEST, WallHeight.LOW), 10, 13, 21, start);
        structure.setBlockState(world, Blocks.SPRUCE_SLAB.getDefaultState().with(SlabBlock.TYPE, SlabType.BOTTOM).with(SlabBlock.WATERLOGGED, false), 10, 14, 9, start);
        structure.setBlockState(world, Blocks.COBBLESTONE_STAIRS.getDefaultState().with(StairsBlock.FACING, Direction.SOUTH).with(StairsBlock.WATERLOGGED, false).with(StairsBlock.SHAPE, StairsShape.STRAIGHT).with(StairsBlock.HALF, Half.BOTTOM), 10, 14, 11, start);
        structure.setBlockState(world, Blocks.MOSSY_COBBLESTONE_STAIRS.getDefaultState().with(StairsBlock.FACING, Direction.NORTH).with(StairsBlock.WATERLOGGED, false).with(StairsBlock.SHAPE, StairsShape.STRAIGHT).with(StairsBlock.HALF, Half.BOTTOM), 10, 14, 21, start);
        structure.setBlockState(world, Blocks.MOSSY_COBBLESTONE_SLAB.getDefaultState().with(SlabBlock.TYPE, SlabType.BOTTOM).with(SlabBlock.WATERLOGGED, false), 10, 15, 11, start);
        structure.setBlockState(world, Blocks.MOSSY_COBBLESTONE_SLAB.getDefaultState().with(SlabBlock.TYPE, SlabType.BOTTOM).with(SlabBlock.WATERLOGGED, false), 10, 15, 21, start);
        structure.setBlockState(world, Blocks.SPRUCE_STAIRS.getDefaultState().with(StairsBlock.FACING, Direction.SOUTH).with(StairsBlock.WATERLOGGED, false).with(StairsBlock.SHAPE, StairsShape.STRAIGHT).with(StairsBlock.HALF, Half.BOTTOM), 10, 16, 12, start);
        structure.setBlockState(world, Blocks.SPRUCE_STAIRS.getDefaultState().with(StairsBlock.FACING, Direction.NORTH).with(StairsBlock.WATERLOGGED, false).with(StairsBlock.SHAPE, StairsShape.STRAIGHT).with(StairsBlock.HALF, Half.TOP), 10, 16, 13, start);
        structure.setBlockState(world, Blocks.SPRUCE_STAIRS.getDefaultState().with(StairsBlock.FACING, Direction.NORTH).with(StairsBlock.WATERLOGGED, false).with(StairsBlock.SHAPE, StairsShape.STRAIGHT).with(StairsBlock.HALF, Half.BOTTOM), 10, 16, 20, start);
        structure.setBlockState(world, Blocks.SPRUCE_WOOD.getDefaultState(), 10, 17, 13, start);
        structure.setBlockState(world, Blocks.SPRUCE_SLAB.getDefaultState().with(SlabBlock.TYPE, SlabType.TOP).with(SlabBlock.WATERLOGGED, false), 10, 17, 14, start);
        structure.setBlockState(world, Blocks.SPRUCE_WOOD.getDefaultState(), 10, 17, 19, start);
        structure.setBlockState(world, Blocks.SPRUCE_STAIRS.getDefaultState().with(StairsBlock.FACING, Direction.SOUTH).with(StairsBlock.WATERLOGGED, false).with(StairsBlock.SHAPE, StairsShape.STRAIGHT).with(StairsBlock.HALF, Half.TOP), 10, 18, 17, start);
        structure.setBlockState(world, Blocks.SPRUCE_SLAB.getDefaultState().with(SlabBlock.TYPE, SlabType.BOTTOM).with(SlabBlock.WATERLOGGED, false), 10, 19, 15, start);
        structure.setBlockState(world, Blocks.SPRUCE_SLAB.getDefaultState().with(SlabBlock.TYPE, SlabType.BOTTOM).with(SlabBlock.WATERLOGGED, false), 10, 19, 17, start);
        structure.setBlockState(world, Blocks.COBBLESTONE.getDefaultState(), 11, 6, 15, start);
        structure.setBlockState(world, Blocks.MOSSY_COBBLESTONE.getDefaultState(), 11, 6, 23, start);
        structure.setBlockState(world, Blocks.COBBLESTONE.getDefaultState(), 11, 7, 9, start);
        structure.setBlockState(world, Blocks.MOSSY_COBBLESTONE.getDefaultState(), 11, 7, 19, start);
        structure.setBlockState(world, Blocks.COBBLESTONE.getDefaultState(), 11, 7, 23, start);
        structure.setBlockState(world, Blocks.STONE.getDefaultState(), 11, 8, 10, start);
        structure.setBlockState(world, Blocks.MOSSY_COBBLESTONE.getDefaultState(), 11, 8, 13, start);
        structure.setBlockState(world, Blocks.STONE.getDefaultState(), 11, 8, 16, start);
        structure.setBlockState(world, Blocks.STONE.getDefaultState(), 11, 8, 19, start);
        structure.setBlockState(world, Blocks.MOSSY_COBBLESTONE.getDefaultState(), 11, 8, 20, start);
        structure.setBlockState(world, Blocks.MOSSY_COBBLESTONE_STAIRS.getDefaultState().with(StairsBlock.FACING, Direction.NORTH).with(StairsBlock.WATERLOGGED, false).with(StairsBlock.SHAPE, StairsShape.STRAIGHT).with(StairsBlock.HALF, Half.BOTTOM), 11, 8, 21, start);
        structure.setBlockState(world, Blocks.COBBLESTONE_WALL.getDefaultState().with(WallBlock.WATERLOGGED, false).with(WallBlock.UP, true).with(WallBlock.WALL_HEIGHT_NORTH, WallHeight.LOW).with(WallBlock.WALL_HEIGHT_SOUTH, WallHeight.LOW).with(WallBlock.WALL_HEIGHT_EAST, WallHeight.LOW).with(WallBlock.WALL_HEIGHT_WEST, WallHeight.LOW), 11, 8, 23, start);
        structure.setBlockState(world, Blocks.COBBLESTONE_SLAB.getDefaultState().with(SlabBlock.TYPE, SlabType.BOTTOM).with(SlabBlock.WATERLOGGED, false), 11, 9, 21, start);
        structure.setBlockState(world, Blocks.COBBLESTONE_SLAB.getDefaultState().with(SlabBlock.TYPE, SlabType.TOP).with(SlabBlock.WATERLOGGED, false), 11, 11, 19, start);
        structure.setBlockState(world, Blocks.COBBLESTONE_STAIRS.getDefaultState().with(StairsBlock.FACING, Direction.EAST).with(StairsBlock.WATERLOGGED, false).with(StairsBlock.SHAPE, StairsShape.STRAIGHT).with(StairsBlock.HALF, Half.TOP), 11, 11, 21, start);
        structure.setBlockState(world, Blocks.SPRUCE_STAIRS.getDefaultState().with(StairsBlock.FACING, Direction.EAST).with(StairsBlock.WATERLOGGED, false).with(StairsBlock.SHAPE, StairsShape.OUTER_RIGHT).with(StairsBlock.HALF, Half.TOP), 11, 12, 8, start);
        structure.setBlockState(world, Blocks.VINE.getDefaultState().with(VineBlock.UP, false).with(VineBlock.NORTH, false).with(VineBlock.SOUTH, true).with(VineBlock.EAST, false).with(VineBlock.WEST, false), 11, 12, 18, start);
        structure.setBlockState(world, Blocks.COBBLESTONE_STAIRS.getDefaultState().with(StairsBlock.FACING, Direction.NORTH).with(StairsBlock.WATERLOGGED, false).with(StairsBlock.SHAPE, StairsShape.STRAIGHT).with(StairsBlock.HALF, Half.BOTTOM), 11, 12, 21, start);
        structure.setBlockState(world, Blocks.SPRUCE_STAIRS.getDefaultState().with(StairsBlock.FACING, Direction.SOUTH).with(StairsBlock.WATERLOGGED, false).with(StairsBlock.SHAPE, StairsShape.STRAIGHT).with(StairsBlock.HALF, Half.BOTTOM), 11, 13, 8, start);
        structure.setBlockState(world, Blocks.SPRUCE_STAIRS.getDefaultState().with(StairsBlock.FACING, Direction.NORTH).with(StairsBlock.WATERLOGGED, false).with(StairsBlock.SHAPE, StairsShape.OUTER_RIGHT).with(StairsBlock.HALF, Half.TOP), 11, 13, 14, start);
        structure.setBlockState(world, Blocks.COBBLESTONE.getDefaultState(), 11, 13, 19, start);
        structure.setBlockState(world, Blocks.COBBLESTONE_STAIRS.getDefaultState().with(StairsBlock.FACING, Direction.NORTH).with(StairsBlock.WATERLOGGED, false).with(StairsBlock.SHAPE, StairsShape.STRAIGHT).with(StairsBlock.HALF, Half.TOP), 11, 13, 21, start);
        structure.setBlockState(world, Blocks.SPRUCE_TRAPDOOR.getDefaultState().with(HorizontalBlock.HORIZONTAL_FACING, Direction.NORTH).with(TrapDoorBlock.HALF, Half.BOTTOM).with(TrapDoorBlock.WATERLOGGED, false).with(TrapDoorBlock.POWERED, false).with(TrapDoorBlock.OPEN, false), 11, 14, 9, start);
        structure.setBlockState(world, Blocks.AIR.getDefaultState(), 11, 14, 13, start);
        structure.setBlockState(world, Blocks.AIR.getDefaultState(), 11, 14, 16, start);
        structure.setBlockState(world, Blocks.MOSSY_COBBLESTONE_WALL.getDefaultState().with(WallBlock.WATERLOGGED, false).with(WallBlock.UP, true).with(WallBlock.WALL_HEIGHT_NORTH, WallHeight.LOW).with(WallBlock.WALL_HEIGHT_SOUTH, WallHeight.LOW).with(WallBlock.WALL_HEIGHT_EAST, WallHeight.LOW).with(WallBlock.WALL_HEIGHT_WEST, WallHeight.LOW), 11, 15, 11, start);
        structure.setBlockState(world, Blocks.COBBLESTONE_WALL.getDefaultState().with(WallBlock.WATERLOGGED, false).with(WallBlock.UP, true).with(WallBlock.WALL_HEIGHT_NORTH, WallHeight.LOW).with(WallBlock.WALL_HEIGHT_SOUTH, WallHeight.LOW).with(WallBlock.WALL_HEIGHT_EAST, WallHeight.LOW).with(WallBlock.WALL_HEIGHT_WEST, WallHeight.LOW), 11, 15, 21, start);
        structure.setBlockState(world, Blocks.SPRUCE_WOOD.getDefaultState(), 11, 16, 12, start);
        structure.setBlockState(world, Blocks.SPRUCE_SLAB.getDefaultState().with(SlabBlock.TYPE, SlabType.TOP).with(SlabBlock.WATERLOGGED, false), 11, 16, 13, start);
        structure.setBlockState(world, Blocks.SPRUCE_STAIRS.getDefaultState().with(StairsBlock.FACING, Direction.SOUTH).with(StairsBlock.WATERLOGGED, false).with(StairsBlock.SHAPE, StairsShape.STRAIGHT).with(StairsBlock.HALF, Half.BOTTOM), 11, 17, 13, start);
        structure.setBlockState(world, Blocks.WALL_TORCH.getDefaultState().with(WallTorchBlock.HORIZONTAL_FACING, Direction.WEST), 11, 17, 16, start);
        structure.setBlockState(world, Blocks.SPRUCE_SLAB.getDefaultState().with(SlabBlock.TYPE, SlabType.TOP).with(SlabBlock.WATERLOGGED, false), 11, 18, 17, start);
        structure.setBlockState(world, Blocks.SPRUCE_STAIRS.getDefaultState().with(StairsBlock.FACING, Direction.SOUTH).with(StairsBlock.WATERLOGGED, false).with(StairsBlock.SHAPE, StairsShape.STRAIGHT).with(StairsBlock.HALF, Half.BOTTOM), 11, 19, 15, start);
        structure.setBlockState(world, Blocks.SPRUCE_PLANKS.getDefaultState(), 11, 19, 16, start);
        structure.setBlockState(world, Blocks.SPRUCE_STAIRS.getDefaultState().with(StairsBlock.FACING, Direction.NORTH).with(StairsBlock.WATERLOGGED, false).with(StairsBlock.SHAPE, StairsShape.STRAIGHT).with(StairsBlock.HALF, Half.BOTTOM), 11, 19, 17, start);
        structure.setBlockState(world, Blocks.MOSSY_COBBLESTONE.getDefaultState(), 12, 6, 11, start);
        structure.setBlockState(world, Blocks.STONE.getDefaultState(), 12, 6, 18, start);
        structure.setBlockState(world, Blocks.COBBLESTONE.getDefaultState(), 12, 7, 11, start);
        structure.setBlockState(world, Blocks.COBBLESTONE.getDefaultState(), 12, 7, 22, start);
        structure.setBlockState(world, Blocks.MOSSY_COBBLESTONE_STAIRS.getDefaultState().with(StairsBlock.FACING, Direction.NORTH).with(StairsBlock.WATERLOGGED, false).with(StairsBlock.SHAPE, StairsShape.STRAIGHT).with(StairsBlock.HALF, Half.BOTTOM), 12, 7, 23, start);
        structure.setBlockState(world, Blocks.STONE.getDefaultState(), 12, 8, 12, start);
        structure.setBlockState(world, Blocks.COBBLESTONE_SLAB.getDefaultState().with(SlabBlock.TYPE, SlabType.BOTTOM).with(SlabBlock.WATERLOGGED, false), 12, 8, 23, start);
        structure.setBlockState(world, Blocks.COBBLESTONE_WALL.getDefaultState().with(WallBlock.WATERLOGGED, false).with(WallBlock.UP, true).with(WallBlock.WALL_HEIGHT_NORTH, WallHeight.LOW).with(WallBlock.WALL_HEIGHT_SOUTH, WallHeight.LOW).with(WallBlock.WALL_HEIGHT_EAST, WallHeight.LOW).with(WallBlock.WALL_HEIGHT_WEST, WallHeight.LOW), 12, 9, 8, start);
        structure.setBlockState(world, Blocks.MOSSY_COBBLESTONE.getDefaultState(), 12, 9, 13, start);
        structure.setBlockState(world, Blocks.COBBLESTONE.getDefaultState(), 12, 9, 21, start);
        structure.setBlockState(world, Blocks.VINE.getDefaultState().with(VineBlock.UP, false).with(VineBlock.NORTH, true).with(VineBlock.SOUTH, false).with(VineBlock.EAST, false).with(VineBlock.WEST, false), 12, 9, 22, start);
        structure.setBlockState(world, Blocks.MOSSY_COBBLESTONE_WALL.getDefaultState().with(WallBlock.WATERLOGGED, false).with(WallBlock.UP, true).with(WallBlock.WALL_HEIGHT_NORTH, WallHeight.LOW).with(WallBlock.WALL_HEIGHT_SOUTH, WallHeight.LOW).with(WallBlock.WALL_HEIGHT_EAST, WallHeight.LOW).with(WallBlock.WALL_HEIGHT_WEST, WallHeight.LOW), 12, 10, 8, start);
        structure.setBlockState(world, Blocks.COBBLESTONE_STAIRS.getDefaultState().with(StairsBlock.FACING, Direction.NORTH).with(StairsBlock.WATERLOGGED, false).with(StairsBlock.SHAPE, StairsShape.STRAIGHT).with(StairsBlock.HALF, Half.BOTTOM), 12, 10, 9, start);
        structure.setBlockState(world, Blocks.MOSSY_COBBLESTONE.getDefaultState(), 12, 10, 12, start);
        structure.setBlockState(world, Blocks.MOSSY_COBBLESTONE.getDefaultState(), 12, 10, 21, start);
        structure.setBlockState(world, Blocks.COBBLESTONE_STAIRS.getDefaultState().with(StairsBlock.FACING, Direction.SOUTH).with(StairsBlock.WATERLOGGED, false).with(StairsBlock.SHAPE, StairsShape.STRAIGHT).with(StairsBlock.HALF, Half.BOTTOM), 12, 11, 8, start);
        structure.setBlockState(world, Blocks.COBBLESTONE_STAIRS.getDefaultState().with(StairsBlock.FACING, Direction.NORTH).with(StairsBlock.WATERLOGGED, false).with(StairsBlock.SHAPE, StairsShape.STRAIGHT).with(StairsBlock.HALF, Half.TOP), 12, 11, 9, start);
        structure.setBlockState(world, Blocks.COBBLESTONE.getDefaultState(), 12, 11, 19, start);
        structure.setBlockState(world, Blocks.SPRUCE_STAIRS.getDefaultState().with(StairsBlock.FACING, Direction.SOUTH).with(StairsBlock.WATERLOGGED, false).with(StairsBlock.SHAPE, StairsShape.STRAIGHT).with(StairsBlock.HALF, Half.TOP), 12, 12, 8, start);
        structure.setBlockState(world, Blocks.COBBLESTONE.getDefaultState(), 12, 12, 9, start);
        structure.setBlockState(world, Blocks.COBBLESTONE_STAIRS.getDefaultState().with(StairsBlock.FACING, Direction.NORTH).with(StairsBlock.WATERLOGGED, false).with(StairsBlock.SHAPE, StairsShape.STRAIGHT).with(StairsBlock.HALF, Half.TOP), 12, 12, 10, start);
        structure.setBlockState(world, Blocks.STONE.getDefaultState(), 12, 12, 11, start);
        structure.setBlockState(world, Blocks.VINE.getDefaultState().with(VineBlock.UP, true).with(VineBlock.NORTH, false).with(VineBlock.SOUTH, true).with(VineBlock.EAST, false).with(VineBlock.WEST, false), 12, 12, 18, start);
        structure.setBlockState(world, Blocks.MOSSY_COBBLESTONE_STAIRS.getDefaultState().with(StairsBlock.FACING, Direction.NORTH).with(StairsBlock.WATERLOGGED, false).with(StairsBlock.SHAPE, StairsShape.STRAIGHT).with(StairsBlock.HALF, Half.TOP), 12, 12, 22, start);
        structure.setBlockState(world, Blocks.SPRUCE_SLAB.getDefaultState().with(SlabBlock.TYPE, SlabType.BOTTOM).with(SlabBlock.WATERLOGGED, false), 12, 13, 8, start);
        structure.setBlockState(world, Blocks.COBBLESTONE.getDefaultState(), 12, 13, 10, start);
        structure.setBlockState(world, Blocks.COBBLESTONE.getDefaultState(), 12, 13, 12, start);
        structure.setBlockState(world, Blocks.MOSSY_COBBLESTONE.getDefaultState(), 12, 13, 13, start);
        structure.setBlockState(world, Blocks.COBBLESTONE_WALL.getDefaultState().with(WallBlock.WATERLOGGED, false).with(WallBlock.UP, true).with(WallBlock.WALL_HEIGHT_NORTH, WallHeight.LOW).with(WallBlock.WALL_HEIGHT_SOUTH, WallHeight.LOW).with(WallBlock.WALL_HEIGHT_EAST, WallHeight.LOW).with(WallBlock.WALL_HEIGHT_WEST, WallHeight.LOW), 12, 13, 22, start);
        structure.setBlockState(world, Blocks.SPRUCE_STAIRS.getDefaultState().with(StairsBlock.FACING, Direction.SOUTH).with(StairsBlock.WATERLOGGED, false).with(StairsBlock.SHAPE, StairsShape.STRAIGHT).with(StairsBlock.HALF, Half.BOTTOM), 12, 14, 10, start);
        structure.setBlockState(world, Blocks.STONE.getDefaultState(), 12, 14, 11, start);
        structure.setBlockState(world, Blocks.MOSSY_COBBLESTONE.getDefaultState(), 12, 14, 12, start);
        structure.setBlockState(world, Blocks.COBBLESTONE.getDefaultState(), 12, 14, 13, start);
        structure.setBlockState(world, Blocks.COBBLESTONE.getDefaultState(), 12, 14, 19, start);
        structure.setBlockState(world, Blocks.MOSSY_COBBLESTONE.getDefaultState(), 12, 14, 20, start);
        structure.setBlockState(world, Blocks.MOSSY_COBBLESTONE_STAIRS.getDefaultState().with(StairsBlock.FACING, Direction.NORTH).with(StairsBlock.WATERLOGGED, false).with(StairsBlock.SHAPE, StairsShape.STRAIGHT).with(StairsBlock.HALF, Half.BOTTOM), 12, 14, 22, start);
        structure.setBlockState(world, Blocks.COBBLESTONE_STAIRS.getDefaultState().with(StairsBlock.FACING, Direction.SOUTH).with(StairsBlock.WATERLOGGED, false).with(StairsBlock.SHAPE, StairsShape.STRAIGHT).with(StairsBlock.HALF, Half.BOTTOM), 12, 15, 11, start);
        structure.setBlockState(world, Blocks.COBBLESTONE.getDefaultState(), 12, 15, 12, start);
        structure.setBlockState(world, Blocks.MOSSY_COBBLESTONE.getDefaultState(), 12, 15, 13, start);
        structure.setBlockState(world, Blocks.COBBLESTONE_STAIRS.getDefaultState().with(StairsBlock.FACING, Direction.NORTH).with(StairsBlock.WATERLOGGED, false).with(StairsBlock.SHAPE, StairsShape.STRAIGHT).with(StairsBlock.HALF, Half.TOP), 12, 15, 14, start);
        structure.setBlockState(world, Blocks.COBBLESTONE_STAIRS.getDefaultState().with(StairsBlock.FACING, Direction.SOUTH).with(StairsBlock.WATERLOGGED, false).with(StairsBlock.SHAPE, StairsShape.STRAIGHT).with(StairsBlock.HALF, Half.TOP), 12, 15, 18, start);
        structure.setBlockState(world, Blocks.MOSSY_COBBLESTONE.getDefaultState(), 12, 15, 19, start);
        structure.setBlockState(world, Blocks.COBBLESTONE.getDefaultState(), 12, 15, 20, start);
        structure.setBlockState(world, Blocks.COBBLESTONE_STAIRS.getDefaultState().with(StairsBlock.FACING, Direction.NORTH).with(StairsBlock.WATERLOGGED, false).with(StairsBlock.SHAPE, StairsShape.STRAIGHT).with(StairsBlock.HALF, Half.BOTTOM), 12, 15, 21, start);
        structure.setBlockState(world, Blocks.SPRUCE_STAIRS.getDefaultState().with(StairsBlock.FACING, Direction.SOUTH).with(StairsBlock.WATERLOGGED, false).with(StairsBlock.SHAPE, StairsShape.STRAIGHT).with(StairsBlock.HALF, Half.BOTTOM), 12, 16, 12, start);
        structure.setBlockState(world, Blocks.COBBLESTONE_SLAB.getDefaultState().with(SlabBlock.TYPE, SlabType.TOP).with(SlabBlock.WATERLOGGED, false), 12, 16, 16, start);
        structure.setBlockState(world, Blocks.COBBLESTONE.getDefaultState(), 12, 16, 19, start);
        structure.setBlockState(world, Blocks.SPRUCE_STAIRS.getDefaultState().with(StairsBlock.FACING, Direction.SOUTH).with(StairsBlock.WATERLOGGED, false).with(StairsBlock.SHAPE, StairsShape.STRAIGHT).with(StairsBlock.HALF, Half.BOTTOM), 12, 18, 14, start);
        structure.setBlockState(world, Blocks.SPRUCE_STAIRS.getDefaultState().with(StairsBlock.FACING, Direction.NORTH).with(StairsBlock.WATERLOGGED, false).with(StairsBlock.SHAPE, StairsShape.STRAIGHT).with(StairsBlock.HALF, Half.BOTTOM), 12, 18, 18, start);
        structure.setBlockState(world, Blocks.COBBLESTONE.getDefaultState(), 13, 6, 10, start);
        structure.setBlockState(world, Blocks.STONE.getDefaultState(), 13, 6, 16, start);
        structure.setBlockState(world, Blocks.COBBLESTONE.getDefaultState(), 13, 6, 19, start);
        structure.setBlockState(world, Blocks.STONE.getDefaultState(), 13, 7, 7, start);
        structure.setBlockState(world, Blocks.MOSSY_COBBLESTONE.getDefaultState(), 13, 8, 9, start);
        structure.setBlockState(world, Blocks.COBBLESTONE.getDefaultState(), 13, 8, 17, start);
        structure.setBlockState(world, Blocks.STONE.getDefaultState(), 13, 8, 18, start);
        structure.setBlockState(world, Blocks.COBBLESTONE.getDefaultState(), 13, 8, 20, start);
        structure.setBlockState(world, Blocks.MOSSY_COBBLESTONE.getDefaultState(), 13, 8, 21, start);
        structure.setBlockState(world, Blocks.CHISELED_STONE_BRICKS.getDefaultState(), 13, 8, 23, start);
        structure.setBlockState(world, Blocks.MOSSY_COBBLESTONE.getDefaultState(), 13, 9, 11, start);
        structure.setBlockState(world, Index.STOOL_OAK.getDefaultState().with(Stool.PILLOW, StoolState.NONE), 13, 9, 15, start);
        structure.setBlockState(world, Blocks.COBBLESTONE_WALL.getDefaultState().with(WallBlock.WATERLOGGED, false).with(WallBlock.UP, true).with(WallBlock.WALL_HEIGHT_NORTH, WallHeight.LOW).with(WallBlock.WALL_HEIGHT_SOUTH, WallHeight.LOW).with(WallBlock.WALL_HEIGHT_EAST, WallHeight.LOW).with(WallBlock.WALL_HEIGHT_WEST, WallHeight.LOW), 13, 9, 21, start);
        structure.setBlockState(world, Blocks.COBBLESTONE_WALL.getDefaultState().with(WallBlock.WATERLOGGED, false).with(WallBlock.UP, true).with(WallBlock.WALL_HEIGHT_NORTH, WallHeight.LOW).with(WallBlock.WALL_HEIGHT_SOUTH, WallHeight.LOW).with(WallBlock.WALL_HEIGHT_EAST, WallHeight.LOW).with(WallBlock.WALL_HEIGHT_WEST, WallHeight.LOW), 13, 9, 23, start);
        structure.setBlockState(world, Blocks.COBBLESTONE_WALL.getDefaultState().with(WallBlock.WATERLOGGED, false).with(WallBlock.UP, true).with(WallBlock.WALL_HEIGHT_NORTH, WallHeight.LOW).with(WallBlock.WALL_HEIGHT_SOUTH, WallHeight.LOW).with(WallBlock.WALL_HEIGHT_EAST, WallHeight.LOW).with(WallBlock.WALL_HEIGHT_WEST, WallHeight.LOW), 13, 10, 21, start);
        structure.setBlockState(world, Blocks.MOSSY_COBBLESTONE.getDefaultState(), 13, 11, 19, start);
        structure.setBlockState(world, Blocks.MOSSY_COBBLESTONE_STAIRS.getDefaultState().with(StairsBlock.FACING, Direction.WEST).with(StairsBlock.WATERLOGGED, false).with(StairsBlock.SHAPE, StairsShape.STRAIGHT).with(StairsBlock.HALF, Half.TOP), 13, 11, 21, start);
        structure.setBlockState(world, Blocks.SPRUCE_WOOD.getDefaultState(), 13, 12, 8, start);
        structure.setBlockState(world, Blocks.COBBLESTONE_STAIRS.getDefaultState().with(StairsBlock.FACING, Direction.NORTH).with(StairsBlock.WATERLOGGED, false).with(StairsBlock.SHAPE, StairsShape.STRAIGHT).with(StairsBlock.HALF, Half.BOTTOM), 13, 12, 21, start);
        structure.setBlockState(world, Blocks.SPRUCE_STAIRS.getDefaultState().with(StairsBlock.FACING, Direction.SOUTH).with(StairsBlock.WATERLOGGED, false).with(StairsBlock.SHAPE, StairsShape.STRAIGHT).with(StairsBlock.HALF, Half.BOTTOM), 13, 13, 9, start);
        structure.setBlockState(world, Blocks.SPRUCE_STAIRS.getDefaultState().with(StairsBlock.FACING, Direction.NORTH).with(StairsBlock.WATERLOGGED, false).with(StairsBlock.SHAPE, StairsShape.OUTER_LEFT).with(StairsBlock.HALF, Half.TOP), 13, 13, 14, start);
        structure.setBlockState(world, Blocks.COBBLESTONE_WALL.getDefaultState().with(WallBlock.WATERLOGGED, false).with(WallBlock.UP, false).with(WallBlock.WALL_HEIGHT_NORTH, WallHeight.LOW).with(WallBlock.WALL_HEIGHT_SOUTH, WallHeight.LOW).with(WallBlock.WALL_HEIGHT_EAST, WallHeight.LOW).with(WallBlock.WALL_HEIGHT_WEST, WallHeight.LOW), 13, 13, 21, start);
        structure.setBlockState(world, Blocks.CHEST.getDefaultState().with(ChestBlock.FACING, Direction.SOUTH).with(ChestBlock.WATERLOGGED, false).with(ChestBlock.TYPE, ChestType.SINGLE), 13, 14, 13, start);
        structure.setBlockState(world, Blocks.STONE.getDefaultState(), 13, 14, 20, start);
        structure.setBlockState(world, Blocks.MOSSY_COBBLESTONE_STAIRS.getDefaultState().with(StairsBlock.FACING, Direction.NORTH).with(StairsBlock.WATERLOGGED, false).with(StairsBlock.SHAPE, StairsShape.STRAIGHT).with(StairsBlock.HALF, Half.TOP), 13, 14, 21, start);
        structure.setBlockState(world, Blocks.COBBLESTONE_WALL.getDefaultState().with(WallBlock.WATERLOGGED, false).with(WallBlock.UP, true).with(WallBlock.WALL_HEIGHT_NORTH, WallHeight.LOW).with(WallBlock.WALL_HEIGHT_SOUTH, WallHeight.LOW).with(WallBlock.WALL_HEIGHT_EAST, WallHeight.LOW).with(WallBlock.WALL_HEIGHT_WEST, WallHeight.LOW), 13, 15, 11, start);
        structure.setBlockState(world, Blocks.SPRUCE_SLAB.getDefaultState().with(SlabBlock.TYPE, SlabType.TOP).with(SlabBlock.WATERLOGGED, false), 13, 15, 13, start);
        structure.setBlockState(world, Blocks.COBBLESTONE_WALL.getDefaultState().with(WallBlock.WATERLOGGED, false).with(WallBlock.UP, true).with(WallBlock.WALL_HEIGHT_NORTH, WallHeight.LOW).with(WallBlock.WALL_HEIGHT_SOUTH, WallHeight.LOW).with(WallBlock.WALL_HEIGHT_EAST, WallHeight.LOW).with(WallBlock.WALL_HEIGHT_WEST, WallHeight.LOW), 13, 15, 21, start);
        structure.setBlockState(world, Blocks.SPRUCE_SLAB.getDefaultState().with(SlabBlock.TYPE, SlabType.BOTTOM).with(SlabBlock.WATERLOGGED, false), 13, 16, 12, start);
        structure.setBlockState(world, Blocks.SPRUCE_STAIRS.getDefaultState().with(StairsBlock.FACING, Direction.SOUTH).with(StairsBlock.WATERLOGGED, false).with(StairsBlock.SHAPE, StairsShape.STRAIGHT).with(StairsBlock.HALF, Half.TOP), 13, 16, 18, start);
        structure.setBlockState(world, Blocks.SPRUCE_SLAB.getDefaultState().with(SlabBlock.TYPE, SlabType.BOTTOM).with(SlabBlock.WATERLOGGED, false), 13, 16, 20, start);
        structure.setBlockState(world, Blocks.WALL_TORCH.getDefaultState().with(WallTorchBlock.HORIZONTAL_FACING, Direction.EAST), 13, 17, 16, start);
        structure.setBlockState(world, Blocks.SPRUCE_STAIRS.getDefaultState().with(StairsBlock.FACING, Direction.NORTH).with(StairsBlock.WATERLOGGED, false).with(StairsBlock.SHAPE, StairsShape.STRAIGHT).with(StairsBlock.HALF, Half.TOP), 13, 18, 15, start);
        structure.setBlockState(world, Blocks.SPRUCE_STAIRS.getDefaultState().with(StairsBlock.FACING, Direction.SOUTH).with(StairsBlock.WATERLOGGED, false).with(StairsBlock.SHAPE, StairsShape.STRAIGHT).with(StairsBlock.HALF, Half.TOP), 13, 18, 17, start);
        structure.setBlockState(world, Blocks.AIR.getDefaultState(), 14, 6, 5, start);
        structure.setBlockState(world, Blocks.STONE.getDefaultState(), 14, 6, 22, start);
        structure.setBlockState(world, Blocks.MOSSY_COBBLESTONE.getDefaultState(), 14, 7, 21, start);
        structure.setBlockState(world, Blocks.MOSSY_COBBLESTONE_STAIRS.getDefaultState().with(StairsBlock.FACING, Direction.NORTH).with(StairsBlock.WATERLOGGED, false).with(StairsBlock.SHAPE, StairsShape.STRAIGHT).with(StairsBlock.HALF, Half.BOTTOM), 14, 7, 23, start);
        structure.setBlockState(world, Blocks.MOSSY_COBBLESTONE.getDefaultState(), 14, 8, 12, start);
        structure.setBlockState(world, Blocks.COBBLESTONE_STAIRS.getDefaultState().with(StairsBlock.FACING, Direction.NORTH).with(StairsBlock.WATERLOGGED, false).with(StairsBlock.SHAPE, StairsShape.STRAIGHT).with(StairsBlock.HALF, Half.BOTTOM), 14, 8, 21, start);
        structure.setBlockState(world, Blocks.AIR.getDefaultState(), 14, 9, 15, start);
        structure.setBlockState(world, Blocks.COBBLESTONE_STAIRS.getDefaultState().with(StairsBlock.FACING, Direction.WEST).with(StairsBlock.WATERLOGGED, false).with(StairsBlock.SHAPE, StairsShape.STRAIGHT).with(StairsBlock.HALF, Half.TOP), 14, 11, 11, start);
        structure.setBlockState(world, Blocks.COBBLESTONE_STAIRS.getDefaultState().with(StairsBlock.FACING, Direction.WEST).with(StairsBlock.WATERLOGGED, false).with(StairsBlock.SHAPE, StairsShape.STRAIGHT).with(StairsBlock.HALF, Half.TOP), 14, 11, 19, start);
        structure.setBlockState(world, Blocks.SPRUCE_SLAB.getDefaultState().with(SlabBlock.TYPE, SlabType.TOP).with(SlabBlock.WATERLOGGED, false), 14, 12, 8, start);
        structure.setBlockState(world, Blocks.STONE.getDefaultState(), 14, 12, 11, start);
        structure.setBlockState(world, Blocks.COBBLESTONE.getDefaultState(), 14, 12, 21, start);
        structure.setBlockState(world, Blocks.SPRUCE_SLAB.getDefaultState().with(SlabBlock.TYPE, SlabType.BOTTOM).with(SlabBlock.WATERLOGGED, false), 14, 13, 8, start);
        structure.setBlockState(world, Blocks.STONE_BRICK_STAIRS.getDefaultState().with(StairsBlock.FACING, Direction.WEST).with(StairsBlock.WATERLOGGED, false).with(StairsBlock.SHAPE, StairsShape.STRAIGHT).with(StairsBlock.HALF, Half.TOP), 14, 13, 21, start);
        structure.setBlockState(world, Blocks.COBBLESTONE_STAIRS.getDefaultState().with(StairsBlock.FACING, Direction.SOUTH).with(StairsBlock.WATERLOGGED, false).with(StairsBlock.SHAPE, StairsShape.STRAIGHT).with(StairsBlock.HALF, Half.BOTTOM), 14, 14, 11, start);
        structure.setBlockState(world, Blocks.COBBLESTONE.getDefaultState(), 14, 14, 20, start);
        structure.setBlockState(world, Blocks.STONE_BRICK_STAIRS.getDefaultState().with(StairsBlock.FACING, Direction.EAST).with(StairsBlock.WATERLOGGED, false).with(StairsBlock.SHAPE, StairsShape.INNER_LEFT).with(StairsBlock.HALF, Half.TOP), 14, 14, 21, start);
        structure.setBlockState(world, Blocks.MOSSY_STONE_BRICK_STAIRS.getDefaultState().with(StairsBlock.FACING, Direction.NORTH).with(StairsBlock.WATERLOGGED, false).with(StairsBlock.SHAPE, StairsShape.OUTER_RIGHT).with(StairsBlock.HALF, Half.TOP), 14, 14, 22, start);
        structure.setBlockState(world, Blocks.MOSSY_COBBLESTONE_SLAB.getDefaultState().with(SlabBlock.TYPE, SlabType.BOTTOM).with(SlabBlock.WATERLOGGED, false), 14, 15, 11, start);
        structure.setBlockState(world, Blocks.STONE_BRICK_STAIRS.getDefaultState().with(StairsBlock.FACING, Direction.EAST).with(StairsBlock.WATERLOGGED, false).with(StairsBlock.SHAPE, StairsShape.STRAIGHT).with(StairsBlock.HALF, Half.BOTTOM), 14, 15, 21, start);
        structure.setBlockState(world, Blocks.SPRUCE_STAIRS.getDefaultState().with(StairsBlock.FACING, Direction.NORTH).with(StairsBlock.WATERLOGGED, false).with(StairsBlock.SHAPE, StairsShape.STRAIGHT).with(StairsBlock.HALF, Half.TOP), 14, 16, 13, start);
        structure.setBlockState(world, Blocks.SPRUCE_STAIRS.getDefaultState().with(StairsBlock.FACING, Direction.SOUTH).with(StairsBlock.WATERLOGGED, false).with(StairsBlock.SHAPE, StairsShape.STRAIGHT).with(StairsBlock.HALF, Half.BOTTOM), 14, 17, 13, start);
        structure.setBlockState(world, Blocks.SPRUCE_SLAB.getDefaultState().with(SlabBlock.TYPE, SlabType.TOP).with(SlabBlock.WATERLOGGED, false), 14, 17, 14, start);
        structure.setBlockState(world, Blocks.SPRUCE_STAIRS.getDefaultState().with(StairsBlock.FACING, Direction.SOUTH).with(StairsBlock.WATERLOGGED, false).with(StairsBlock.SHAPE, StairsShape.STRAIGHT).with(StairsBlock.HALF, Half.TOP), 14, 17, 18, start);
        structure.setBlockState(world, Blocks.SPRUCE_STAIRS.getDefaultState().with(StairsBlock.FACING, Direction.NORTH).with(StairsBlock.WATERLOGGED, false).with(StairsBlock.SHAPE, StairsShape.STRAIGHT).with(StairsBlock.HALF, Half.BOTTOM), 14, 17, 19, start);
        structure.setBlockState(world, Blocks.SPRUCE_STAIRS.getDefaultState().with(StairsBlock.FACING, Direction.SOUTH).with(StairsBlock.WATERLOGGED, false).with(StairsBlock.SHAPE, StairsShape.STRAIGHT).with(StairsBlock.HALF, Half.BOTTOM), 14, 19, 16, start);
        structure.setBlockState(world, Blocks.GRASS_BLOCK.getDefaultState().with(SnowyDirtBlock.SNOWY, false), 15, 3, 39, start);
        structure.setBlockState(world, Blocks.MOSSY_COBBLESTONE.getDefaultState(), 15, 6, 7, start);
        structure.setBlockState(world, Blocks.STONE.getDefaultState(), 15, 6, 8, start);
        structure.setBlockState(world, Blocks.STONE.getDefaultState(), 15, 7, 12, start);
        structure.setBlockState(world, Blocks.MOSSY_COBBLESTONE.getDefaultState(), 15, 7, 16, start);
        structure.setBlockState(world, Blocks.COBBLESTONE_STAIRS.getDefaultState().with(StairsBlock.FACING, Direction.NORTH).with(StairsBlock.WATERLOGGED, false).with(StairsBlock.SHAPE, StairsShape.STRAIGHT).with(StairsBlock.HALF, Half.BOTTOM), 15, 7, 23, start);
        structure.setBlockState(world, Blocks.MOSSY_COBBLESTONE.getDefaultState(), 15, 8, 15, start);
        structure.setBlockState(world, Blocks.MOSSY_COBBLESTONE_STAIRS.getDefaultState().with(StairsBlock.FACING, Direction.NORTH).with(StairsBlock.WATERLOGGED, false).with(StairsBlock.SHAPE, StairsShape.STRAIGHT).with(StairsBlock.HALF, Half.BOTTOM), 15, 8, 21, start);
        structure.setBlockState(world, Index.STOOL_OAK.getDefaultState().with(Stool.PILLOW, StoolState.NONE), 15, 9, 13, start);
        structure.setBlockState(world, Blocks.AIR.getDefaultState(), 15, 9, 14, start);
        structure.setBlockState(world, Blocks.CAMPFIRE.getDefaultState().with(CampfireBlock.FACING, Direction.NORTH).with(CampfireBlock.LIT, true).with(CampfireBlock.SIGNAL_FIRE, false).with(CampfireBlock.WATERLOGGED, false), 15, 9, 15, start);
        structure.setBlockState(world, Blocks.AIR.getDefaultState(), 15, 9, 16, start);
        structure.setBlockState(world, Index.STOOL_OAK.getDefaultState().with(Stool.PILLOW, StoolState.NONE), 15, 9, 17, start);
        structure.setBlockState(world, Blocks.COBBLESTONE_SLAB.getDefaultState().with(SlabBlock.TYPE, SlabType.TOP).with(SlabBlock.WATERLOGGED, false), 15, 12, 21, start);
        structure.setBlockState(world, Blocks.STONE_BRICK_STAIRS.getDefaultState().with(StairsBlock.FACING, Direction.NORTH).with(StairsBlock.WATERLOGGED, false).with(StairsBlock.SHAPE, StairsShape.STRAIGHT).with(StairsBlock.HALF, Half.BOTTOM), 15, 13, 21, start);
        structure.setBlockState(world, Blocks.SPRUCE_TRAPDOOR.getDefaultState().with(HorizontalBlock.HORIZONTAL_FACING, Direction.NORTH).with(TrapDoorBlock.HALF, Half.BOTTOM).with(TrapDoorBlock.WATERLOGGED, false).with(TrapDoorBlock.POWERED, false).with(TrapDoorBlock.OPEN, false), 15, 14, 9, start);
        structure.setBlockState(world, Blocks.SPRUCE_SLAB.getDefaultState().with(SlabBlock.TYPE, SlabType.BOTTOM).with(SlabBlock.WATERLOGGED, false), 15, 14, 10, start);
        structure.setBlockState(world, Blocks.MOSSY_COBBLESTONE.getDefaultState(), 15, 14, 11, start);
        structure.setBlockState(world, Blocks.AIR.getDefaultState(), 15, 14, 13, start);
        structure.setBlockState(world, Blocks.STONE.getDefaultState(), 15, 14, 20, start);
        structure.setBlockState(world, Blocks.CHISELED_STONE_BRICKS.getDefaultState(), 15, 14, 21, start);
        structure.setBlockState(world, Blocks.MOSSY_COBBLESTONE_WALL.getDefaultState().with(WallBlock.WATERLOGGED, false).with(WallBlock.UP, true).with(WallBlock.WALL_HEIGHT_NORTH, WallHeight.LOW).with(WallBlock.WALL_HEIGHT_SOUTH, WallHeight.LOW).with(WallBlock.WALL_HEIGHT_EAST, WallHeight.LOW).with(WallBlock.WALL_HEIGHT_WEST, WallHeight.LOW), 15, 15, 11, start);
        structure.setBlockState(world, Blocks.COBBLESTONE.getDefaultState(), 15, 15, 20, start);
        structure.setBlockState(world, Blocks.STONE_BRICKS.getDefaultState(), 15, 15, 21, start);
        structure.setBlockState(world, Blocks.MOSSY_STONE_BRICK_STAIRS.getDefaultState().with(StairsBlock.FACING, Direction.NORTH).with(StairsBlock.WATERLOGGED, false).with(StairsBlock.SHAPE, StairsShape.STRAIGHT).with(StairsBlock.HALF, Half.TOP), 15, 15, 22, start);
        structure.setBlockState(world, Blocks.SPRUCE_SLAB.getDefaultState().with(SlabBlock.TYPE, SlabType.TOP).with(SlabBlock.WATERLOGGED, false), 15, 16, 13, start);
        structure.setBlockState(world, Blocks.SPRUCE_SLAB.getDefaultState().with(SlabBlock.TYPE, SlabType.BOTTOM).with(SlabBlock.WATERLOGGED, false), 15, 18, 14, start);
        structure.setBlockState(world, Blocks.SPRUCE_WOOD.getDefaultState(), 15, 18, 15, start);
        structure.setBlockState(world, Blocks.SPRUCE_SLAB.getDefaultState().with(SlabBlock.TYPE, SlabType.BOTTOM).with(SlabBlock.WATERLOGGED, false), 15, 18, 18, start);
        structure.setBlockState(world, Blocks.SPRUCE_STAIRS.getDefaultState().with(StairsBlock.FACING, Direction.SOUTH).with(StairsBlock.WATERLOGGED, false).with(StairsBlock.SHAPE, StairsShape.STRAIGHT).with(StairsBlock.HALF, Half.BOTTOM), 15, 19, 15, start);
        structure.setBlockState(world, Blocks.SPRUCE_STAIRS.getDefaultState().with(StairsBlock.FACING, Direction.NORTH).with(StairsBlock.WATERLOGGED, false).with(StairsBlock.SHAPE, StairsShape.STRAIGHT).with(StairsBlock.HALF, Half.BOTTOM), 15, 19, 17, start);
        structure.setBlockState(world, Blocks.COBBLESTONE.getDefaultState(), 16, 7, 8, start);
        structure.setBlockState(world, Blocks.MOSSY_COBBLESTONE_STAIRS.getDefaultState().with(StairsBlock.FACING, Direction.NORTH).with(StairsBlock.WATERLOGGED, false).with(StairsBlock.SHAPE, StairsShape.STRAIGHT).with(StairsBlock.HALF, Half.BOTTOM), 16, 7, 23, start);
        structure.setBlockState(world, Blocks.MOSSY_COBBLESTONE.getDefaultState(), 16, 8, 11, start);
        structure.setBlockState(world, Blocks.MOSSY_COBBLESTONE.getDefaultState(), 16, 8, 19, start);
        structure.setBlockState(world, Blocks.STONE.getDefaultState(), 16, 8, 20, start);
        structure.setBlockState(world, Blocks.COBBLESTONE_STAIRS.getDefaultState().with(StairsBlock.FACING, Direction.NORTH).with(StairsBlock.WATERLOGGED, false).with(StairsBlock.SHAPE, StairsShape.STRAIGHT).with(StairsBlock.HALF, Half.BOTTOM), 16, 8, 21, start);
        structure.setBlockState(world, Blocks.AIR.getDefaultState(), 16, 9, 15, start);
        structure.setBlockState(world, Blocks.COBBLESTONE_STAIRS.getDefaultState().with(StairsBlock.FACING, Direction.EAST).with(StairsBlock.WATERLOGGED, false).with(StairsBlock.SHAPE, StairsShape.STRAIGHT).with(StairsBlock.HALF, Half.TOP), 16, 11, 11, start);
        structure.setBlockState(world, Blocks.COBBLESTONE_STAIRS.getDefaultState().with(StairsBlock.FACING, Direction.EAST).with(StairsBlock.WATERLOGGED, false).with(StairsBlock.SHAPE, StairsShape.STRAIGHT).with(StairsBlock.HALF, Half.TOP), 16, 11, 19, start);
        structure.setBlockState(world, Blocks.SPRUCE_SLAB.getDefaultState().with(SlabBlock.TYPE, SlabType.TOP).with(SlabBlock.WATERLOGGED, false), 16, 12, 8, start);
        structure.setBlockState(world, Blocks.STONE.getDefaultState(), 16, 12, 11, start);
        structure.setBlockState(world, Blocks.MOSSY_COBBLESTONE.getDefaultState(), 16, 12, 21, start);
        structure.setBlockState(world, Blocks.SPRUCE_SLAB.getDefaultState().with(SlabBlock.TYPE, SlabType.BOTTOM).with(SlabBlock.WATERLOGGED, false), 16, 13, 8, start);
        structure.setBlockState(world, Blocks.MOSSY_COBBLESTONE.getDefaultState(), 16, 13, 11, start);
        structure.setBlockState(world, Blocks.MOSSY_STONE_BRICK_STAIRS.getDefaultState().with(StairsBlock.FACING, Direction.EAST).with(StairsBlock.WATERLOGGED, false).with(StairsBlock.SHAPE, StairsShape.STRAIGHT).with(StairsBlock.HALF, Half.TOP), 16, 13, 21, start);
        structure.setBlockState(world, Blocks.SPRUCE_WOOD.getDefaultState(), 16, 14, 10, start);
        structure.setBlockState(world, Blocks.COBBLESTONE_STAIRS.getDefaultState().with(StairsBlock.FACING, Direction.SOUTH).with(StairsBlock.WATERLOGGED, false).with(StairsBlock.SHAPE, StairsShape.STRAIGHT).with(StairsBlock.HALF, Half.BOTTOM), 16, 14, 11, start);
        structure.setBlockState(world, Blocks.STONE_BRICK_STAIRS.getDefaultState().with(StairsBlock.FACING, Direction.WEST).with(StairsBlock.WATERLOGGED, false).with(StairsBlock.SHAPE, StairsShape.STRAIGHT).with(StairsBlock.HALF, Half.TOP), 16, 14, 21, start);
        structure.setBlockState(world, Blocks.STONE_BRICK_STAIRS.getDefaultState().with(StairsBlock.FACING, Direction.NORTH).with(StairsBlock.WATERLOGGED, false).with(StairsBlock.SHAPE, StairsShape.OUTER_LEFT).with(StairsBlock.HALF, Half.TOP), 16, 14, 22, start);
        structure.setBlockState(world, Blocks.COBBLESTONE_SLAB.getDefaultState().with(SlabBlock.TYPE, SlabType.BOTTOM).with(SlabBlock.WATERLOGGED, false), 16, 15, 11, start);
        structure.setBlockState(world, Blocks.STONE_BRICK_STAIRS.getDefaultState().with(StairsBlock.FACING, Direction.WEST).with(StairsBlock.WATERLOGGED, false).with(StairsBlock.SHAPE, StairsShape.STRAIGHT).with(StairsBlock.HALF, Half.BOTTOM), 16, 15, 21, start);
        structure.setBlockState(world, Blocks.SPRUCE_STAIRS.getDefaultState().with(StairsBlock.FACING, Direction.SOUTH).with(StairsBlock.WATERLOGGED, false).with(StairsBlock.SHAPE, StairsShape.STRAIGHT).with(StairsBlock.HALF, Half.BOTTOM), 16, 16, 12, start);
        structure.setBlockState(world, Blocks.SPRUCE_STAIRS.getDefaultState().with(StairsBlock.FACING, Direction.NORTH).with(StairsBlock.WATERLOGGED, false).with(StairsBlock.SHAPE, StairsShape.STRAIGHT).with(StairsBlock.HALF, Half.TOP), 16, 16, 13, start);
        structure.setBlockState(world, Blocks.SPRUCE_SLAB.getDefaultState().with(SlabBlock.TYPE, SlabType.TOP).with(SlabBlock.WATERLOGGED, false), 16, 16, 18, start);
        structure.setBlockState(world, Blocks.SPRUCE_STAIRS.getDefaultState().with(StairsBlock.FACING, Direction.NORTH).with(StairsBlock.WATERLOGGED, false).with(StairsBlock.SHAPE, StairsShape.STRAIGHT).with(StairsBlock.HALF, Half.BOTTOM), 16, 16, 20, start);
        structure.setBlockState(world, Blocks.SPRUCE_SLAB.getDefaultState().with(SlabBlock.TYPE, SlabType.BOTTOM).with(SlabBlock.WATERLOGGED, false), 16, 17, 13, start);
        structure.setBlockState(world, Blocks.SPRUCE_SLAB.getDefaultState().with(SlabBlock.TYPE, SlabType.BOTTOM).with(SlabBlock.WATERLOGGED, false), 16, 17, 19, start);
        structure.setBlockState(world, Blocks.SPRUCE_STAIRS.getDefaultState().with(StairsBlock.FACING, Direction.NORTH).with(StairsBlock.WATERLOGGED, false).with(StairsBlock.SHAPE, StairsShape.STRAIGHT).with(StairsBlock.HALF, Half.TOP), 16, 18, 15, start);
        structure.setBlockState(world, Blocks.SPRUCE_STAIRS.getDefaultState().with(StairsBlock.FACING, Direction.SOUTH).with(StairsBlock.WATERLOGGED, false).with(StairsBlock.SHAPE, StairsShape.STRAIGHT).with(StairsBlock.HALF, Half.TOP), 16, 18, 17, start);
        structure.setBlockState(world, Blocks.DIRT.getDefaultState(), 17, 0, 41, start);
        structure.setBlockState(world, Blocks.GRASS_BLOCK.getDefaultState().with(SnowyDirtBlock.SNOWY, false), 17, 1, 41, start);
        structure.setBlockState(world, Blocks.COBBLESTONE.getDefaultState(), 17, 6, 9, start);
        structure.setBlockState(world, Blocks.COBBLESTONE.getDefaultState(), 17, 6, 12, start);
        structure.setBlockState(world, Blocks.STONE.getDefaultState(), 17, 6, 13, start);
        structure.setBlockState(world, Blocks.COBBLESTONE.getDefaultState(), 17, 6, 15, start);
        structure.setBlockState(world, Blocks.MOSSY_COBBLESTONE.getDefaultState(), 17, 6, 17, start);
        structure.setBlockState(world, Blocks.COBBLESTONE.getDefaultState(), 17, 7, 7, start);
        structure.setBlockState(world, Blocks.STONE.getDefaultState(), 17, 8, 15, start);
        structure.setBlockState(world, Blocks.CHISELED_STONE_BRICKS.getDefaultState(), 17, 8, 23, start);
        structure.setBlockState(world, Index.STOOL_OAK.getDefaultState().with(Stool.PILLOW, StoolState.NONE), 17, 9, 15, start);
        structure.setBlockState(world, Blocks.MOSSY_COBBLESTONE_WALL.getDefaultState().with(WallBlock.WATERLOGGED, false).with(WallBlock.UP, true).with(WallBlock.WALL_HEIGHT_NORTH, WallHeight.LOW).with(WallBlock.WALL_HEIGHT_SOUTH, WallHeight.LOW).with(WallBlock.WALL_HEIGHT_EAST, WallHeight.LOW).with(WallBlock.WALL_HEIGHT_WEST, WallHeight.LOW), 17, 9, 21, start);
        structure.setBlockState(world, Blocks.COBBLESTONE_WALL.getDefaultState().with(WallBlock.WATERLOGGED, false).with(WallBlock.UP, true).with(WallBlock.WALL_HEIGHT_NORTH, WallHeight.LOW).with(WallBlock.WALL_HEIGHT_SOUTH, WallHeight.LOW).with(WallBlock.WALL_HEIGHT_EAST, WallHeight.LOW).with(WallBlock.WALL_HEIGHT_WEST, WallHeight.LOW), 17, 9, 23, start);
        structure.setBlockState(world, Blocks.MOSSY_COBBLESTONE_WALL.getDefaultState().with(WallBlock.WATERLOGGED, false).with(WallBlock.UP, true).with(WallBlock.WALL_HEIGHT_NORTH, WallHeight.LOW).with(WallBlock.WALL_HEIGHT_SOUTH, WallHeight.LOW).with(WallBlock.WALL_HEIGHT_EAST, WallHeight.LOW).with(WallBlock.WALL_HEIGHT_WEST, WallHeight.LOW), 17, 10, 21, start);
        structure.setBlockState(world, Blocks.STONE.getDefaultState(), 17, 11, 11, start);
        structure.setBlockState(world, Blocks.COBBLESTONE_STAIRS.getDefaultState().with(StairsBlock.FACING, Direction.EAST).with(StairsBlock.WATERLOGGED, false).with(StairsBlock.SHAPE, StairsShape.STRAIGHT).with(StairsBlock.HALF, Half.TOP), 17, 11, 21, start);
        structure.setBlockState(world, Blocks.SPRUCE_WOOD.getDefaultState(), 17, 12, 8, start);
        structure.setBlockState(world, Blocks.STONE.getDefaultState(), 17, 12, 19, start);
        structure.setBlockState(world, Blocks.MOSSY_COBBLESTONE_STAIRS.getDefaultState().with(StairsBlock.FACING, Direction.NORTH).with(StairsBlock.WATERLOGGED, false).with(StairsBlock.SHAPE, StairsShape.STRAIGHT).with(StairsBlock.HALF, Half.BOTTOM), 17, 12, 21, start);
        structure.setBlockState(world, Blocks.SPRUCE_TRAPDOOR.getDefaultState().with(HorizontalBlock.HORIZONTAL_FACING, Direction.NORTH).with(TrapDoorBlock.HALF, Half.BOTTOM).with(TrapDoorBlock.WATERLOGGED, false).with(TrapDoorBlock.POWERED, false).with(TrapDoorBlock.OPEN, false), 17, 13, 8, start);
        structure.setBlockState(world, Blocks.SPRUCE_STAIRS.getDefaultState().with(StairsBlock.FACING, Direction.NORTH).with(StairsBlock.WATERLOGGED, false).with(StairsBlock.SHAPE, StairsShape.OUTER_RIGHT).with(StairsBlock.HALF, Half.TOP), 17, 13, 14, start);
        structure.setBlockState(world, Blocks.COBBLESTONE_WALL.getDefaultState().with(WallBlock.WATERLOGGED, false).with(WallBlock.UP, false).with(WallBlock.WALL_HEIGHT_NORTH, WallHeight.LOW).with(WallBlock.WALL_HEIGHT_SOUTH, WallHeight.LOW).with(WallBlock.WALL_HEIGHT_EAST, WallHeight.LOW).with(WallBlock.WALL_HEIGHT_WEST, WallHeight.LOW), 17, 13, 21, start);
        structure.setBlockState(world, Blocks.CHEST.getDefaultState().with(ChestBlock.FACING, Direction.SOUTH).with(ChestBlock.WATERLOGGED, false).with(ChestBlock.TYPE, ChestType.SINGLE), 17, 14, 13, start);
        structure.setBlockState(world, Blocks.COBBLESTONE_WALL.getDefaultState().with(WallBlock.WATERLOGGED, false).with(WallBlock.UP, true).with(WallBlock.WALL_HEIGHT_NORTH, WallHeight.LOW).with(WallBlock.WALL_HEIGHT_SOUTH, WallHeight.LOW).with(WallBlock.WALL_HEIGHT_EAST, WallHeight.LOW).with(WallBlock.WALL_HEIGHT_WEST, WallHeight.LOW), 17, 15, 11, start);
        structure.setBlockState(world, Blocks.SPRUCE_SLAB.getDefaultState().with(SlabBlock.TYPE, SlabType.TOP).with(SlabBlock.WATERLOGGED, false), 17, 15, 13, start);
        structure.setBlockState(world, Blocks.COBBLESTONE_WALL.getDefaultState().with(WallBlock.WATERLOGGED, false).with(WallBlock.UP, true).with(WallBlock.WALL_HEIGHT_NORTH, WallHeight.LOW).with(WallBlock.WALL_HEIGHT_SOUTH, WallHeight.LOW).with(WallBlock.WALL_HEIGHT_EAST, WallHeight.LOW).with(WallBlock.WALL_HEIGHT_WEST, WallHeight.LOW), 17, 15, 21, start);
        structure.setBlockState(world, Blocks.SPRUCE_STAIRS.getDefaultState().with(StairsBlock.FACING, Direction.NORTH).with(StairsBlock.WATERLOGGED, false).with(StairsBlock.SHAPE, StairsShape.STRAIGHT).with(StairsBlock.HALF, Half.TOP), 17, 17, 14, start);
        structure.setBlockState(world, Blocks.WALL_TORCH.getDefaultState().with(WallTorchBlock.HORIZONTAL_FACING, Direction.WEST), 17, 17, 16, start);
        structure.setBlockState(world, Blocks.SPRUCE_STAIRS.getDefaultState().with(StairsBlock.FACING, Direction.SOUTH).with(StairsBlock.WATERLOGGED, false).with(StairsBlock.SHAPE, StairsShape.STRAIGHT).with(StairsBlock.HALF, Half.TOP), 17, 17, 18, start);
        structure.setBlockState(world, Blocks.SPRUCE_WOOD.getDefaultState(), 17, 17, 19, start);
        structure.setBlockState(world, Blocks.SPRUCE_SLAB.getDefaultState().with(SlabBlock.TYPE, SlabType.TOP).with(SlabBlock.WATERLOGGED, false), 17, 18, 15, start);
        structure.setBlockState(world, Blocks.SPRUCE_SLAB.getDefaultState().with(SlabBlock.TYPE, SlabType.TOP).with(SlabBlock.WATERLOGGED, false), 17, 18, 17, start);
        structure.setBlockState(world, Blocks.SPRUCE_SLAB.getDefaultState().with(SlabBlock.TYPE, SlabType.BOTTOM).with(SlabBlock.WATERLOGGED, false), 17, 19, 15, start);
        structure.setBlockState(world, Blocks.SPRUCE_SLAB.getDefaultState().with(SlabBlock.TYPE, SlabType.BOTTOM).with(SlabBlock.WATERLOGGED, false), 17, 19, 17, start);
        structure.setBlockState(world, Blocks.GRASS_BLOCK.getDefaultState().with(SnowyDirtBlock.SNOWY, false), 18, 1, 3, start);
        structure.setBlockState(world, Blocks.STONE.getDefaultState(), 18, 6, 18, start);
        structure.setBlockState(world, Blocks.STONE.getDefaultState(), 18, 6, 23, start);
        structure.setBlockState(world, Blocks.AIR.getDefaultState(), 18, 6, 30, start);
        structure.setBlockState(world, Blocks.STONE.getDefaultState(), 18, 7, 20, start);
        structure.setBlockState(world, Blocks.COBBLESTONE_STAIRS.getDefaultState().with(StairsBlock.FACING, Direction.NORTH).with(StairsBlock.WATERLOGGED, false).with(StairsBlock.SHAPE, StairsShape.STRAIGHT).with(StairsBlock.HALF, Half.BOTTOM), 18, 7, 23, start);
        structure.setBlockState(world, Blocks.MOSSY_COBBLESTONE_SLAB.getDefaultState().with(SlabBlock.TYPE, SlabType.BOTTOM).with(SlabBlock.WATERLOGGED, false), 18, 8, 23, start);
        structure.setBlockState(world, Blocks.COBBLESTONE.getDefaultState(), 18, 9, 9, start);
        structure.setBlockState(world, Blocks.COBBLESTONE_STAIRS.getDefaultState().with(StairsBlock.FACING, Direction.NORTH).with(StairsBlock.WATERLOGGED, false).with(StairsBlock.SHAPE, StairsShape.STRAIGHT).with(StairsBlock.HALF, Half.BOTTOM), 18, 10, 9, start);
        structure.setBlockState(world, Blocks.MOSSY_COBBLESTONE.getDefaultState(), 18, 10, 12, start);
        structure.setBlockState(world, Blocks.COBBLESTONE_STAIRS.getDefaultState().with(StairsBlock.FACING, Direction.SOUTH).with(StairsBlock.WATERLOGGED, false).with(StairsBlock.SHAPE, StairsShape.STRAIGHT).with(StairsBlock.HALF, Half.BOTTOM), 18, 11, 8, start);
        structure.setBlockState(world, Blocks.COBBLESTONE_STAIRS.getDefaultState().with(StairsBlock.FACING, Direction.NORTH).with(StairsBlock.WATERLOGGED, false).with(StairsBlock.SHAPE, StairsShape.STRAIGHT).with(StairsBlock.HALF, Half.TOP), 18, 11, 9, start);
        structure.setBlockState(world, Blocks.SPRUCE_STAIRS.getDefaultState().with(StairsBlock.FACING, Direction.SOUTH).with(StairsBlock.WATERLOGGED, false).with(StairsBlock.SHAPE, StairsShape.STRAIGHT).with(StairsBlock.HALF, Half.TOP), 18, 12, 8, start);
        structure.setBlockState(world, Blocks.COBBLESTONE.getDefaultState(), 18, 12, 9, start);
        structure.setBlockState(world, Blocks.COBBLESTONE_STAIRS.getDefaultState().with(StairsBlock.FACING, Direction.NORTH).with(StairsBlock.WATERLOGGED, false).with(StairsBlock.SHAPE, StairsShape.STRAIGHT).with(StairsBlock.HALF, Half.TOP), 18, 12, 10, start);
        structure.setBlockState(world, Blocks.STONE.getDefaultState(), 18, 12, 11, start);
        structure.setBlockState(world, Blocks.VINE.getDefaultState().with(VineBlock.UP, true).with(VineBlock.NORTH, true).with(VineBlock.SOUTH, false).with(VineBlock.EAST, false).with(VineBlock.WEST, false), 18, 12, 14, start);
        structure.setBlockState(world, Blocks.MOSSY_COBBLESTONE_STAIRS.getDefaultState().with(StairsBlock.FACING, Direction.NORTH).with(StairsBlock.WATERLOGGED, false).with(StairsBlock.SHAPE, StairsShape.STRAIGHT).with(StairsBlock.HALF, Half.TOP), 18, 12, 22, start);
        structure.setBlockState(world, Blocks.COBBLESTONE.getDefaultState(), 18, 13, 10, start);
        structure.setBlockState(world, Blocks.STONE.getDefaultState(), 18, 13, 12, start);
        structure.setBlockState(world, Blocks.MOSSY_COBBLESTONE.getDefaultState(), 18, 13, 13, start);
        structure.setBlockState(world, Blocks.COBBLESTONE.getDefaultState(), 18, 13, 19, start);
        structure.setBlockState(world, Blocks.COBBLESTONE_WALL.getDefaultState().with(WallBlock.WATERLOGGED, false).with(WallBlock.UP, true).with(WallBlock.WALL_HEIGHT_NORTH, WallHeight.LOW).with(WallBlock.WALL_HEIGHT_SOUTH, WallHeight.LOW).with(WallBlock.WALL_HEIGHT_EAST, WallHeight.LOW).with(WallBlock.WALL_HEIGHT_WEST, WallHeight.LOW), 18, 13, 22, start);
        structure.setBlockState(world, Blocks.STONE.getDefaultState(), 18, 14, 13, start);
        structure.setBlockState(world, Blocks.AIR.getDefaultState(), 18, 14, 16, start);
        structure.setBlockState(world, Blocks.MOSSY_COBBLESTONE_STAIRS.getDefaultState().with(StairsBlock.FACING, Direction.NORTH).with(StairsBlock.WATERLOGGED, false).with(StairsBlock.SHAPE, StairsShape.STRAIGHT).with(StairsBlock.HALF, Half.BOTTOM), 18, 14, 22, start);
        structure.setBlockState(world, Blocks.MOSSY_COBBLESTONE_STAIRS.getDefaultState().with(StairsBlock.FACING, Direction.SOUTH).with(StairsBlock.WATERLOGGED, false).with(StairsBlock.SHAPE, StairsShape.STRAIGHT).with(StairsBlock.HALF, Half.BOTTOM), 18, 15, 11, start);
        structure.setBlockState(world, Blocks.MOSSY_COBBLESTONE.getDefaultState(), 18, 15, 13, start);
        structure.setBlockState(world, Blocks.COBBLESTONE_STAIRS.getDefaultState().with(StairsBlock.FACING, Direction.NORTH).with(StairsBlock.WATERLOGGED, false).with(StairsBlock.SHAPE, StairsShape.STRAIGHT).with(StairsBlock.HALF, Half.TOP), 18, 15, 14, start);
        structure.setBlockState(world, Blocks.COBBLESTONE_STAIRS.getDefaultState().with(StairsBlock.FACING, Direction.SOUTH).with(StairsBlock.WATERLOGGED, false).with(StairsBlock.SHAPE, StairsShape.STRAIGHT).with(StairsBlock.HALF, Half.TOP), 18, 15, 18, start);
        structure.setBlockState(world, Blocks.MOSSY_COBBLESTONE.getDefaultState(), 18, 15, 19, start);
        structure.setBlockState(world, Blocks.COBBLESTONE.getDefaultState(), 18, 15, 20, start);
        structure.setBlockState(world, Blocks.COBBLESTONE_STAIRS.getDefaultState().with(StairsBlock.FACING, Direction.NORTH).with(StairsBlock.WATERLOGGED, false).with(StairsBlock.SHAPE, StairsShape.STRAIGHT).with(StairsBlock.HALF, Half.BOTTOM), 18, 15, 21, start);
        structure.setBlockState(world, Blocks.COBBLESTONE_SLAB.getDefaultState().with(SlabBlock.TYPE, SlabType.TOP).with(SlabBlock.WATERLOGGED, false), 18, 16, 16, start);
