package mod.arcalitegames.odyssey.world.structure.structures.camps.abandoned_house;

import mod.arcalitegames.odyssey.world.structure.StructureBase;
import net.minecraft.block.Blocks;
import net.minecraft.block.DoorBlock;
import net.minecraft.block.FourWayBlock;
import net.minecraft.block.LadderBlock;
import net.minecraft.block.RedstoneWireBlock;
import net.minecraft.block.SlabBlock;
import net.minecraft.block.SnowyDirtBlock;
import net.minecraft.block.StairsBlock;
import net.minecraft.block.VineBlock;
import net.minecraft.block.WallTorchBlock;
import net.minecraft.state.properties.DoorHingeSide;
import net.minecraft.state.properties.DoubleBlockHalf;
import net.minecraft.state.properties.Half;
import net.minecraft.state.properties.RedstoneSide;
import net.minecraft.state.properties.SlabType;
import net.minecraft.state.properties.StairsShape;
import net.minecraft.util.Direction;
import net.minecraft.util.math.BlockPos;
import net.minecraft.world.World;

public class AbandonedHouseComponents
{
	public static BlockPos start;
    public static World world;
    public static StructureBase structure;

    public static void init(World worldIn, BlockPos blockPos, StructureBase structureIn)
    {
        world = worldIn; start = blockPos; structure = structureIn;
    }
    
    public static void generatePart1()
    {
        structure.setBlockState(world, Blocks.GRASS_BLOCK.getDefaultState().with(SnowyDirtBlock.SNOWY, false), 3, 0, 5, start);
        structure.setBlockState(world, Blocks.GRASS_BLOCK.getDefaultState().with(SnowyDirtBlock.SNOWY, false), 3, 1, 6, start);
        structure.setBlockState(world, Blocks.GRASS_BLOCK.getDefaultState().with(SnowyDirtBlock.SNOWY, false), 3, 2, 7, start);
        structure.setBlockState(world, Blocks.GRASS_BLOCK.getDefaultState().with(SnowyDirtBlock.SNOWY, false), 3, 2, 13, start);
        structure.setBlockState(world, Blocks.GRASS_BLOCK.getDefaultState().with(SnowyDirtBlock.SNOWY, false), 4, 0, 4, start);
        structure.setBlockState(world, Blocks.GRASS_BLOCK.getDefaultState().with(SnowyDirtBlock.SNOWY, false), 4, 0, 23, start);
        structure.setBlockState(world, Blocks.GRASS_BLOCK.getDefaultState().with(SnowyDirtBlock.SNOWY, false), 4, 1, 5, start);
        structure.setBlockState(world, Blocks.GRASS_BLOCK.getDefaultState().with(SnowyDirtBlock.SNOWY, false), 5, 1, 4, start);
        structure.setBlockState(world, Blocks.GRASS_BLOCK.getDefaultState().with(SnowyDirtBlock.SNOWY, false), 5, 2, 5, start);
        structure.setBlockState(world, Blocks.GRASS_BLOCK.getDefaultState().with(SnowyDirtBlock.SNOWY, false), 5, 3, 6, start);
        structure.setBlockState(world, Blocks.VINE.getDefaultState().with(VineBlock.UP, true).with(VineBlock.NORTH, false).with(VineBlock.SOUTH, false).with(VineBlock.EAST, true).with(VineBlock.WEST, false), 6, 8, 9, start);
        structure.setBlockState(world, Blocks.VINE.getDefaultState().with(VineBlock.UP, false).with(VineBlock.NORTH, false).with(VineBlock.SOUTH, false).with(VineBlock.EAST, true).with(VineBlock.WEST, false), 6, 8, 10, start);
        structure.setBlockState(world, Blocks.STONE_BRICK_STAIRS.getDefaultState().with(StairsBlock.FACING, Direction.NORTH).with(StairsBlock.WATERLOGGED, false).with(StairsBlock.SHAPE, StairsShape.STRAIGHT).with(StairsBlock.HALF, Half.TOP), 6, 9, 9, start);
        structure.setBlockState(world, Blocks.STONE_BRICK_STAIRS.getDefaultState().with(StairsBlock.FACING, Direction.SOUTH).with(StairsBlock.WATERLOGGED, false).with(StairsBlock.SHAPE, StairsShape.STRAIGHT).with(StairsBlock.HALF, Half.TOP), 6, 9, 17, start);
        structure.setBlockState(world, Blocks.STONE_BRICK_STAIRS.getDefaultState().with(StairsBlock.FACING, Direction.NORTH).with(StairsBlock.WATERLOGGED, false).with(StairsBlock.SHAPE, StairsShape.STRAIGHT).with(StairsBlock.HALF, Half.TOP), 6, 10, 10, start);
        structure.setBlockState(world, Blocks.VINE.getDefaultState().with(VineBlock.UP, false).with(VineBlock.NORTH, false).with(VineBlock.SOUTH, false).with(VineBlock.EAST, true).with(VineBlock.WEST, false), 6, 10, 14, start);
        structure.setBlockState(world, Blocks.VINE.getDefaultState().with(VineBlock.UP, true).with(VineBlock.NORTH, false).with(VineBlock.SOUTH, false).with(VineBlock.EAST, true).with(VineBlock.WEST, false), 6, 10, 15, start);
        structure.setBlockState(world, Blocks.STONE_BRICK_STAIRS.getDefaultState().with(StairsBlock.FACING, Direction.SOUTH).with(StairsBlock.WATERLOGGED, false).with(StairsBlock.SHAPE, StairsShape.STRAIGHT).with(StairsBlock.HALF, Half.TOP), 6, 10, 16, start);
        structure.setBlockState(world, Blocks.STONE_BRICK_STAIRS.getDefaultState().with(StairsBlock.FACING, Direction.SOUTH).with(StairsBlock.WATERLOGGED, false).with(StairsBlock.SHAPE, StairsShape.STRAIGHT).with(StairsBlock.HALF, Half.BOTTOM), 6, 11, 10, start);
        structure.setBlockState(world, Blocks.STONE_BRICK_STAIRS.getDefaultState().with(StairsBlock.FACING, Direction.NORTH).with(StairsBlock.WATERLOGGED, false).with(StairsBlock.SHAPE, StairsShape.STRAIGHT).with(StairsBlock.HALF, Half.TOP), 6, 11, 11, start);
        structure.setBlockState(world, Blocks.STONE_BRICK_STAIRS.getDefaultState().with(StairsBlock.FACING, Direction.SOUTH).with(StairsBlock.WATERLOGGED, false).with(StairsBlock.SHAPE, StairsShape.STRAIGHT).with(StairsBlock.HALF, Half.TOP), 6, 11, 15, start);
        structure.setBlockState(world, Blocks.STONE_BRICK_STAIRS.getDefaultState().with(StairsBlock.FACING, Direction.NORTH).with(StairsBlock.WATERLOGGED, false).with(StairsBlock.SHAPE, StairsShape.STRAIGHT).with(StairsBlock.HALF, Half.TOP), 6, 12, 12, start);
        structure.setBlockState(world, Blocks.VINE.getDefaultState().with(VineBlock.UP, false).with(VineBlock.NORTH, true).with(VineBlock.SOUTH, false).with(VineBlock.EAST, true).with(VineBlock.WEST, false), 6, 12, 13, start);
        structure.setBlockState(world, Blocks.STONE_BRICK_STAIRS.getDefaultState().with(StairsBlock.FACING, Direction.SOUTH).with(StairsBlock.WATERLOGGED, false).with(StairsBlock.SHAPE, StairsShape.STRAIGHT).with(StairsBlock.HALF, Half.TOP), 6, 12, 14, start);
        structure.setBlockState(world, Blocks.VINE.getDefaultState().with(VineBlock.UP, true).with(VineBlock.NORTH, true).with(VineBlock.SOUTH, true).with(VineBlock.EAST, true).with(VineBlock.WEST, false), 6, 13, 13, start);
        structure.setBlockState(world, Blocks.SPRUCE_LOG.getDefaultState(), 7, 7, 10, start);
        structure.setBlockState(world, Blocks.GLASS_PANE.getDefaultState().with(FourWayBlock.WATERLOGGED, false).with(FourWayBlock.NORTH, true).with(FourWayBlock.SOUTH, true).with(FourWayBlock.EAST, false).with(FourWayBlock.WEST, false), 7, 7, 15, start);
        structure.setBlockState(world, Blocks.VINE.getDefaultState().with(VineBlock.UP, true).with(VineBlock.NORTH, false).with(VineBlock.SOUTH, true).with(VineBlock.EAST, false).with(VineBlock.WEST, false), 7, 8, 8, start);
        structure.setBlockState(world, Blocks.VINE.getDefaultState().with(VineBlock.UP, true).with(VineBlock.NORTH, true).with(VineBlock.SOUTH, false).with(VineBlock.EAST, false).with(VineBlock.WEST, false), 7, 8, 18, start);
        structure.setBlockState(world, Blocks.SPRUCE_LOG.getDefaultState(), 7, 10, 10, start);
        structure.setBlockState(world, Blocks.SPRUCE_PLANKS.getDefaultState(), 7, 10, 11, start);
        structure.setBlockState(world, Blocks.SPRUCE_LOG.getDefaultState(), 7, 10, 16, start);
        structure.setBlockState(world, Blocks.SPRUCE_LOG.getDefaultState(), 7, 11, 11, start);
        structure.setBlockState(world, Blocks.SPRUCE_PLANKS.getDefaultState(), 7, 11, 12, start);
        structure.setBlockState(world, Blocks.SPRUCE_LOG.getDefaultState(), 7, 11, 15, start);
        structure.setBlockState(world, Blocks.SPRUCE_LOG.getDefaultState(), 7, 12, 12, start);
        structure.setBlockState(world, Blocks.SPRUCE_PLANKS.getDefaultState(), 7, 12, 13, start);
        structure.setBlockState(world, Blocks.SPRUCE_LOG.getDefaultState(), 7, 12, 14, start);
        structure.setBlockState(world, Blocks.SPRUCE_LOG.getDefaultState(), 7, 13, 13, start);
        structure.setBlockState(world, Blocks.SPRUCE_PLANKS.getDefaultState(), 8, 5, 14, start);
        structure.setBlockState(world, Blocks.SPRUCE_PLANKS.getDefaultState(), 8, 5, 16, start);
        structure.setBlockState(world, Blocks.REDSTONE_WIRE.getDefaultState().with(RedstoneWireBlock.POWER, 0).with(RedstoneWireBlock.NORTH, RedstoneSide.SIDE).with(RedstoneWireBlock.SOUTH, RedstoneSide.SIDE).with(RedstoneWireBlock.EAST, RedstoneSide.SIDE).with(RedstoneWireBlock.WEST, RedstoneSide.SIDE), 8, 6, 13, start);
        structure.setBlockState(world, Blocks.SPRUCE_LOG.getDefaultState(), 8, 7, 9, start);
        structure.setBlockState(world, Blocks.SPRUCE_LOG.getDefaultState(), 8, 7, 17, start);
        structure.setBlockState(world, Blocks.COBWEB.getDefaultState(), 8, 8, 10, start);
        structure.setBlockState(world, Blocks.VINE.getDefaultState().with(VineBlock.UP, false).with(VineBlock.NORTH, true).with(VineBlock.SOUTH, false).with(VineBlock.EAST, false).with(VineBlock.WEST, false), 8, 8, 18, start);
        structure.setBlockState(world, Blocks.REDSTONE_WIRE.getDefaultState().with(RedstoneWireBlock.POWER, 0).with(RedstoneWireBlock.NORTH, RedstoneSide.NONE).with(RedstoneWireBlock.SOUTH, RedstoneSide.SIDE).with(RedstoneWireBlock.EAST, RedstoneSide.SIDE).with(RedstoneWireBlock.WEST, RedstoneSide.NONE), 8, 10, 13, start);
        structure.setBlockState(world, Blocks.REDSTONE_WIRE.getDefaultState().with(RedstoneWireBlock.POWER, 0).with(RedstoneWireBlock.NORTH, RedstoneSide.SIDE).with(RedstoneWireBlock.SOUTH, RedstoneSide.SIDE).with(RedstoneWireBlock.EAST, RedstoneSide.NONE).with(RedstoneWireBlock.WEST, RedstoneSide.NONE), 8, 10, 14, start);
        structure.setBlockState(world, Blocks.COBWEB.getDefaultState(), 8, 12, 14, start);
        structure.setBlockState(world, Blocks.WALL_TORCH.getDefaultState().with(WallTorchBlock.HORIZONTAL_FACING, Direction.EAST), 8, 13, 13, start);
        structure.setBlockState(world, Blocks.OAK_PLANKS.getDefaultState(), 9, 5, 10, start);
        structure.setBlockState(world, Blocks.TALL_GRASS.getDefaultState(), 9, 5, 15, start);
        structure.setBlockState(world, Blocks.OAK_PLANKS.getDefaultState(), 9, 5, 16, start);
        structure.setBlockState(world, Blocks.TALL_GRASS.getDefaultState(), 9, 6, 15, start);
        structure.setBlockState(world, Blocks.GLASS_PANE.getDefaultState().with(FourWayBlock.WATERLOGGED, false).with(FourWayBlock.NORTH, false).with(FourWayBlock.SOUTH, false).with(FourWayBlock.EAST, false).with(FourWayBlock.WEST, true), 9, 7, 17, start);
        structure.setBlockState(world, Blocks.VINE.getDefaultState().with(VineBlock.UP, true).with(VineBlock.NORTH, true).with(VineBlock.SOUTH, false).with(VineBlock.EAST, false).with(VineBlock.WEST, false), 9, 8, 18, start);
        structure.setBlockState(world, Blocks.REDSTONE_WIRE.getDefaultState().with(RedstoneWireBlock.POWER, 0).with(RedstoneWireBlock.NORTH, RedstoneSide.NONE).with(RedstoneWireBlock.SOUTH, RedstoneSide.NONE).with(RedstoneWireBlock.EAST, RedstoneSide.SIDE).with(RedstoneWireBlock.WEST, RedstoneSide.SIDE), 9, 10, 13, start);
        structure.setBlockState(world, Blocks.GRASS_BLOCK.getDefaultState().with(SnowyDirtBlock.SNOWY, false), 10, 5, 9, start);
        structure.setBlockState(world, Blocks.TALL_GRASS.getDefaultState(), 10, 5, 10, start);
        structure.setBlockState(world, Blocks.SPRUCE_PLANKS.getDefaultState(), 10, 5, 12, start);
        structure.setBlockState(world, Blocks.SPRUCE_PLANKS.getDefaultState(), 10, 5, 16, start);
        structure.setBlockState(world, Blocks.TALL_GRASS.getDefaultState(), 10, 6, 10, start);
        structure.setBlockState(world, Blocks.GLASS_PANE.getDefaultState().with(FourWayBlock.WATERLOGGED, false).with(FourWayBlock.NORTH, false).with(FourWayBlock.SOUTH, false).with(FourWayBlock.EAST, true).with(FourWayBlock.WEST, false), 10, 7, 9, start);
        structure.setBlockState(world, Blocks.REDSTONE_WIRE.getDefaultState().with(RedstoneWireBlock.POWER, 0).with(RedstoneWireBlock.NORTH, RedstoneSide.SIDE).with(RedstoneWireBlock.SOUTH, RedstoneSide.SIDE).with(RedstoneWireBlock.EAST, RedstoneSide.NONE).with(RedstoneWireBlock.WEST, RedstoneSide.NONE), 10, 10, 12, start);
        structure.setBlockState(world, Blocks.REDSTONE_WIRE.getDefaultState().with(RedstoneWireBlock.POWER, 0).with(RedstoneWireBlock.NORTH, RedstoneSide.SIDE).with(RedstoneWireBlock.SOUTH, RedstoneSide.NONE).with(RedstoneWireBlock.EAST, RedstoneSide.NONE).with(RedstoneWireBlock.WEST, RedstoneSide.SIDE), 10, 10, 13, start);
        structure.setBlockState(world, Blocks.REDSTONE_WIRE.getDefaultState().with(RedstoneWireBlock.POWER, 0).with(RedstoneWireBlock.NORTH, RedstoneSide.SIDE).with(RedstoneWireBlock.SOUTH, RedstoneSide.SIDE).with(RedstoneWireBlock.EAST, RedstoneSide.SIDE).with(RedstoneWireBlock.WEST, RedstoneSide.SIDE), 10, 10, 15, start);
        structure.setBlockState(world, Blocks.COBWEB.getDefaultState(), 10, 12, 12, start);
        structure.setBlockState(world, Blocks.COBWEB.getDefaultState(), 10, 13, 13, start);
        structure.setBlockState(world, Blocks.SPRUCE_PLANKS.getDefaultState(), 11, 5, 11, start);
        structure.setBlockState(world, Blocks.OAK_PLANKS.getDefaultState(), 11, 5, 16, start);
        structure.setBlockState(world, Blocks.REDSTONE_WIRE.getDefaultState().with(RedstoneWireBlock.POWER, 0).with(RedstoneWireBlock.NORTH, RedstoneSide.SIDE).with(RedstoneWireBlock.SOUTH, RedstoneSide.SIDE).with(RedstoneWireBlock.EAST, RedstoneSide.SIDE).with(RedstoneWireBlock.WEST, RedstoneSide.SIDE), 11, 6, 10, start);
        structure.setBlockState(world, Blocks.REDSTONE_WIRE.getDefaultState().with(RedstoneWireBlock.POWER, 0).with(RedstoneWireBlock.NORTH, RedstoneSide.SIDE).with(RedstoneWireBlock.SOUTH, RedstoneSide.SIDE).with(RedstoneWireBlock.EAST, RedstoneSide.SIDE).with(RedstoneWireBlock.WEST, RedstoneSide.SIDE), 11, 6, 12, start);
        structure.setBlockState(world, Blocks.REDSTONE_WIRE.getDefaultState().with(RedstoneWireBlock.POWER, 0).with(RedstoneWireBlock.NORTH, RedstoneSide.SIDE).with(RedstoneWireBlock.SOUTH, RedstoneSide.SIDE).with(RedstoneWireBlock.EAST, RedstoneSide.SIDE).with(RedstoneWireBlock.WEST, RedstoneSide.SIDE), 11, 6, 14, start);
        structure.setBlockState(world, Blocks.SPRUCE_PLANKS.getDefaultState(), 11, 6, 17, start);
        structure.setBlockState(world, Blocks.VINE.getDefaultState().with(VineBlock.UP, true).with(VineBlock.NORTH, true).with(VineBlock.SOUTH, false).with(VineBlock.EAST, false).with(VineBlock.WEST, false), 11, 8, 18, start);
        structure.setBlockState(world, Blocks.STONE_BRICKS.getDefaultState(), 11, 9, 18, start);
        structure.setBlockState(world, Blocks.STONE_BRICK_STAIRS.getDefaultState().with(StairsBlock.FACING, Direction.EAST).with(StairsBlock.WATERLOGGED, false).with(StairsBlock.SHAPE, StairsShape.INNER_LEFT).with(StairsBlock.HALF, Half.BOTTOM), 11, 10, 17, start);
        structure.setBlockState(world, Blocks.STONE_BRICK_STAIRS.getDefaultState().with(StairsBlock.FACING, Direction.EAST).with(StairsBlock.WATERLOGGED, false).with(StairsBlock.SHAPE, StairsShape.STRAIGHT).with(StairsBlock.HALF, Half.BOTTOM), 11, 10, 18, start);
        structure.setBlockState(world, Blocks.COBWEB.getDefaultState(), 11, 12, 14, start);
        structure.setBlockState(world, Blocks.VINE.getDefaultState().with(VineBlock.UP, true).with(VineBlock.NORTH, false).with(VineBlock.SOUTH, true).with(VineBlock.EAST, false).with(VineBlock.WEST, false), 12, 8, 8, start);
        structure.setBlockState(world, Blocks.REDSTONE_WIRE.getDefaultState().with(RedstoneWireBlock.POWER, 0).with(RedstoneWireBlock.NORTH, RedstoneSide.SIDE).with(RedstoneWireBlock.SOUTH, RedstoneSide.SIDE).with(RedstoneWireBlock.EAST, RedstoneSide.SIDE).with(RedstoneWireBlock.WEST, RedstoneSide.SIDE), 12, 10, 11, start);
        structure.setBlockState(world, Blocks.REDSTONE_WIRE.getDefaultState().with(RedstoneWireBlock.POWER, 0).with(RedstoneWireBlock.NORTH, RedstoneSide.SIDE).with(RedstoneWireBlock.SOUTH, RedstoneSide.SIDE).with(RedstoneWireBlock.EAST, RedstoneSide.SIDE).with(RedstoneWireBlock.WEST, RedstoneSide.SIDE), 12, 10, 14, start);
        structure.setBlockState(world, Blocks.SPRUCE_PLANKS.getDefaultState(), 12, 10, 18, start);
        structure.setBlockState(world, Blocks.STONE_BRICK_STAIRS.getDefaultState().with(StairsBlock.FACING, Direction.EAST).with(StairsBlock.WATERLOGGED, false).with(StairsBlock.SHAPE, StairsShape.INNER_LEFT).with(StairsBlock.HALF, Half.BOTTOM), 12, 11, 16, start);
        structure.setBlockState(world, Blocks.SPRUCE_PLANKS.getDefaultState(), 13, 5, 11, start);
        structure.setBlockState(world, Blocks.SPRUCE_PLANKS.getDefaultState(), 13, 5, 13, start);
        structure.setBlockState(world, Blocks.OAK_PLANKS.getDefaultState(), 13, 5, 18, start);
        structure.setBlockState(world, Blocks.OAK_DOOR.getDefaultState().with(DoorBlock.FACING, Direction.NORTH).with(DoorBlock.HALF, DoubleBlockHalf.LOWER).with(DoorBlock.HINGE, DoorHingeSide.LEFT).with(DoorBlock.OPEN, true).with(DoorBlock.POWERED, false), 13, 6, 18, start);
        structure.setBlockState(world, Blocks.OAK_DOOR.getDefaultState().with(DoorBlock.FACING, Direction.NORTH).with(DoorBlock.HALF, DoubleBlockHalf.UPPER).with(DoorBlock.HINGE, DoorHingeSide.LEFT).with(DoorBlock.OPEN, true).with(DoorBlock.POWERED, false), 13, 7, 18, start);
        structure.setBlockState(world, Blocks.VINE.getDefaultState().with(VineBlock.UP, false).with(VineBlock.NORTH, false).with(VineBlock.SOUTH, true).with(VineBlock.EAST, false).with(VineBlock.WEST, false), 13, 8, 8, start);
        structure.setBlockState(world, Blocks.WALL_TORCH.getDefaultState().with(WallTorchBlock.HORIZONTAL_FACING, Direction.NORTH), 13, 8, 17, start);
        structure.setBlockState(world, Blocks.REDSTONE_WIRE.getDefaultState().with(RedstoneWireBlock.POWER, 0).with(RedstoneWireBlock.NORTH, RedstoneSide.SIDE).with(RedstoneWireBlock.SOUTH, RedstoneSide.SIDE).with(RedstoneWireBlock.EAST, RedstoneSide.SIDE).with(RedstoneWireBlock.WEST, RedstoneSide.SIDE), 13, 10, 10, start);
        structure.setBlockState(world, Blocks.REDSTONE_WIRE.getDefaultState().with(RedstoneWireBlock.POWER, 0).with(RedstoneWireBlock.NORTH, RedstoneSide.SIDE).with(RedstoneWireBlock.SOUTH, RedstoneSide.SIDE).with(RedstoneWireBlock.EAST, RedstoneSide.SIDE).with(RedstoneWireBlock.WEST, RedstoneSide.SIDE), 13, 10, 13, start);
        structure.setBlockState(world, Blocks.REDSTONE_WIRE.getDefaultState().with(RedstoneWireBlock.POWER, 0).with(RedstoneWireBlock.NORTH, RedstoneSide.NONE).with(RedstoneWireBlock.SOUTH, RedstoneSide.SIDE).with(RedstoneWireBlock.EAST, RedstoneSide.SIDE).with(RedstoneWireBlock.WEST, RedstoneSide.NONE), 13, 10, 17, start);
        structure.setBlockState(world, Blocks.REDSTONE_WIRE.getDefaultState().with(RedstoneWireBlock.POWER, 0).with(RedstoneWireBlock.NORTH, RedstoneSide.SIDE).with(RedstoneWireBlock.SOUTH, RedstoneSide.SIDE).with(RedstoneWireBlock.EAST, RedstoneSide.NONE).with(RedstoneWireBlock.WEST, RedstoneSide.NONE), 13, 10, 18, start);
        structure.setBlockState(world, Blocks.GRASS.getDefaultState(), 14, 5, 12, start);
        structure.setBlockState(world, Blocks.SPRUCE_PLANKS.getDefaultState(), 14, 5, 16, start);
        structure.setBlockState(world, Blocks.OAK_PLANKS.getDefaultState(), 14, 5, 17, start);
        structure.setBlockState(world, Blocks.SPRUCE_PLANKS.getDefaultState(), 14, 5, 18, start);
        structure.setBlockState(world, Blocks.COBWEB.getDefaultState(), 14, 6, 17, start);
        structure.setBlockState(world, Blocks.VINE.getDefaultState().with(VineBlock.UP, false).with(VineBlock.NORTH, false).with(VineBlock.SOUTH, false).with(VineBlock.EAST, true).with(VineBlock.WEST, false), 14, 6, 18, start);
        structure.setBlockState(world, Blocks.REDSTONE_WIRE.getDefaultState().with(RedstoneWireBlock.POWER, 0).with(RedstoneWireBlock.NORTH, RedstoneSide.SIDE).with(RedstoneWireBlock.SOUTH, RedstoneSide.SIDE).with(RedstoneWireBlock.EAST, RedstoneSide.SIDE).with(RedstoneWireBlock.WEST, RedstoneSide.SIDE), 14, 10, 12, start);
        structure.setBlockState(world, Blocks.REDSTONE_WIRE.getDefaultState().with(RedstoneWireBlock.POWER, 0).with(RedstoneWireBlock.NORTH, RedstoneSide.SIDE).with(RedstoneWireBlock.SOUTH, RedstoneSide.SIDE).with(RedstoneWireBlock.EAST, RedstoneSide.NONE).with(RedstoneWireBlock.WEST, RedstoneSide.NONE), 14, 10, 16, start);
        structure.setBlockState(world, Blocks.REDSTONE_WIRE.getDefaultState().with(RedstoneWireBlock.POWER, 0).with(RedstoneWireBlock.NORTH, RedstoneSide.SIDE).with(RedstoneWireBlock.SOUTH, RedstoneSide.NONE).with(RedstoneWireBlock.EAST, RedstoneSide.SIDE).with(RedstoneWireBlock.WEST, RedstoneSide.SIDE), 14, 10, 17, start);
        structure.setBlockState(world, Blocks.GLASS_PANE.getDefaultState().with(FourWayBlock.WATERLOGGED, false).with(FourWayBlock.NORTH, false).with(FourWayBlock.SOUTH, false).with(FourWayBlock.EAST, true).with(FourWayBlock.WEST, false), 14, 10, 18, start);
        structure.setBlockState(world, Blocks.STONE_BRICK_STAIRS.getDefaultState().with(StairsBlock.FACING, Direction.WEST).with(StairsBlock.WATERLOGGED, false).with(StairsBlock.SHAPE, StairsShape.INNER_RIGHT).with(StairsBlock.HALF, Half.BOTTOM), 14, 12, 15, start);
        structure.setBlockState(world, Blocks.OAK_PLANKS.getDefaultState(), 15, 5, 12, start);
        structure.setBlockState(world, Blocks.OAK_PLANKS.getDefaultState(), 15, 5, 16, start);
        structure.setBlockState(world, Blocks.REDSTONE_WIRE.getDefaultState().with(RedstoneWireBlock.POWER, 0).with(RedstoneWireBlock.NORTH, RedstoneSide.SIDE).with(RedstoneWireBlock.SOUTH, RedstoneSide.SIDE).with(RedstoneWireBlock.EAST, RedstoneSide.SIDE).with(RedstoneWireBlock.WEST, RedstoneSide.SIDE), 15, 6, 15, start);
        structure.setBlockState(world, Blocks.SPRUCE_LOG.getDefaultState(), 15, 8, 17, start);
        structure.setBlockState(world, Blocks.REDSTONE_WIRE.getDefaultState().with(RedstoneWireBlock.POWER, 0).with(RedstoneWireBlock.NORTH, RedstoneSide.NONE).with(RedstoneWireBlock.SOUTH, RedstoneSide.NONE).with(RedstoneWireBlock.EAST, RedstoneSide.SIDE).with(RedstoneWireBlock.WEST, RedstoneSide.SIDE), 15, 10, 17, start);
        structure.setBlockState(world, Blocks.SPRUCE_PLANKS.getDefaultState(), 15, 10, 18, start);
        structure.setBlockState(world, Blocks.STONE_BRICK_STAIRS.getDefaultState().with(StairsBlock.FACING, Direction.WEST).with(StairsBlock.WATERLOGGED, false).with(StairsBlock.SHAPE, StairsShape.INNER_RIGHT).with(StairsBlock.HALF, Half.BOTTOM), 15, 11, 16, start);
        structure.setBlockState(world, Blocks.TALL_GRASS.getDefaultState(), 16, 5, 12, start);
        structure.setBlockState(world, Blocks.GRASS.getDefaultState(), 16, 5, 13, start);
        structure.setBlockState(world, Blocks.SPRUCE_PLANKS.getDefaultState(), 16, 5, 14, start);
        structure.setBlockState(world, Blocks.SPRUCE_PLANKS.getDefaultState(), 16, 5, 16, start);
        structure.setBlockState(world, Blocks.GRASS.getDefaultState(), 16, 6, 8, start);
        structure.setBlockState(world, Blocks.TALL_GRASS.getDefaultState(), 16, 6, 12, start);
        structure.setBlockState(world, Blocks.WALL_TORCH.getDefaultState().with(WallTorchBlock.HORIZONTAL_FACING, Direction.NORTH), 16, 7, 16, start);
        structure.setBlockState(world, Blocks.SPRUCE_LOG.getDefaultState(), 16, 7, 17, start);
        structure.setBlockState(world, Blocks.VINE.getDefaultState().with(VineBlock.UP, false).with(VineBlock.NORTH, false).with(VineBlock.SOUTH, true).with(VineBlock.EAST, false).with(VineBlock.WEST, false), 16, 8, 8, start);
        structure.setBlockState(world, Blocks.STONE_BRICKS.getDefaultState(), 16, 9, 18, start);
        structure.setBlockState(world, Blocks.REDSTONE_WIRE.getDefaultState().with(RedstoneWireBlock.POWER, 0).with(RedstoneWireBlock.NORTH, RedstoneSide.NONE).with(RedstoneWireBlock.SOUTH, RedstoneSide.SIDE).with(RedstoneWireBlock.EAST, RedstoneSide.SIDE).with(RedstoneWireBlock.WEST, RedstoneSide.NONE), 16, 10, 12, start);
        structure.setBlockState(world, Blocks.REDSTONE_WIRE.getDefaultState().with(RedstoneWireBlock.POWER, 0).with(RedstoneWireBlock.NORTH, RedstoneSide.SIDE).with(RedstoneWireBlock.SOUTH, RedstoneSide.NONE).with(RedstoneWireBlock.EAST, RedstoneSide.SIDE).with(RedstoneWireBlock.WEST, RedstoneSide.NONE), 16, 10, 13, start);
        structure.setBlockState(world, Blocks.REDSTONE_WIRE.getDefaultState().with(RedstoneWireBlock.POWER, 0).with(RedstoneWireBlock.NORTH, RedstoneSide.SIDE).with(RedstoneWireBlock.SOUTH, RedstoneSide.SIDE).with(RedstoneWireBlock.EAST, RedstoneSide.SIDE).with(RedstoneWireBlock.WEST, RedstoneSide.SIDE), 16, 10, 16, start);
        structure.setBlockState(world, Blocks.STONE_BRICK_STAIRS.getDefaultState().with(StairsBlock.FACING, Direction.WEST).with(StairsBlock.WATERLOGGED, false).with(StairsBlock.SHAPE, StairsShape.INNER_RIGHT).with(StairsBlock.HALF, Half.BOTTOM), 16, 10, 17, start);
        structure.setBlockState(world, Blocks.STONE_BRICK_STAIRS.getDefaultState().with(StairsBlock.FACING, Direction.WEST).with(StairsBlock.WATERLOGGED, false).with(StairsBlock.SHAPE, StairsShape.STRAIGHT).with(StairsBlock.HALF, Half.BOTTOM), 16, 10, 18, start);
        structure.setBlockState(world, Blocks.GRASS_BLOCK.getDefaultState().with(SnowyDirtBlock.SNOWY, false), 17, 3, 5, start);
        structure.setBlockState(world, Blocks.SPRUCE_PLANKS.getDefaultState(), 17, 5, 13, start);
        structure.setBlockState(world, Blocks.LARGE_FERN.getDefaultState(), 17, 5, 15, start);
        structure.setBlockState(world, Blocks.OAK_PLANKS.getDefaultState(), 17, 5, 16, start);
        structure.setBlockState(world, Blocks.REDSTONE_WIRE.getDefaultState().with(RedstoneWireBlock.POWER, 0).with(RedstoneWireBlock.NORTH, RedstoneSide.SIDE).with(RedstoneWireBlock.SOUTH, RedstoneSide.SIDE).with(RedstoneWireBlock.EAST, RedstoneSide.SIDE).with(RedstoneWireBlock.WEST, RedstoneSide.SIDE), 17, 6, 14, start);
        structure.setBlockState(world, Blocks.LARGE_FERN.getDefaultState(), 17, 6, 15, start);
        structure.setBlockState(world, Blocks.VINE.getDefaultState().with(VineBlock.UP, true).with(VineBlock.NORTH, false).with(VineBlock.SOUTH, true).with(VineBlock.EAST, false).with(VineBlock.WEST, false), 17, 8, 8, start);
        structure.setBlockState(world, Blocks.REDSTONE_WIRE.getDefaultState().with(RedstoneWireBlock.POWER, 0).with(RedstoneWireBlock.NORTH, RedstoneSide.SIDE).with(RedstoneWireBlock.SOUTH, RedstoneSide.SIDE).with(RedstoneWireBlock.EAST, RedstoneSide.SIDE).with(RedstoneWireBlock.WEST, RedstoneSide.SIDE), 17, 10, 10, start);
        structure.setBlockState(world, Blocks.REDSTONE_WIRE.getDefaultState().with(RedstoneWireBlock.POWER, 0).with(RedstoneWireBlock.NORTH, RedstoneSide.NONE).with(RedstoneWireBlock.SOUTH, RedstoneSide.SIDE).with(RedstoneWireBlock.EAST, RedstoneSide.NONE).with(RedstoneWireBlock.WEST, RedstoneSide.SIDE), 17, 10, 12, start);
        structure.setBlockState(world, Blocks.REDSTONE_WIRE.getDefaultState().with(RedstoneWireBlock.POWER, 0).with(RedstoneWireBlock.NORTH, RedstoneSide.SIDE).with(RedstoneWireBlock.SOUTH, RedstoneSide.NONE).with(RedstoneWireBlock.EAST, RedstoneSide.NONE).with(RedstoneWireBlock.WEST, RedstoneSide.SIDE), 17, 10, 13, start);
        structure.setBlockState(world, Blocks.SPRUCE_PLANKS.getDefaultState(), 18, 5, 16, start);
        structure.setBlockState(world, Blocks.GLASS_PANE.getDefaultState().with(FourWayBlock.WATERLOGGED, false).with(FourWayBlock.NORTH, false).with(FourWayBlock.SOUTH, false).with(FourWayBlock.EAST, true).with(FourWayBlock.WEST, false), 18, 7, 9, start);
        structure.setBlockState(world, Blocks.WALL_TORCH.getDefaultState().with(WallTorchBlock.HORIZONTAL_FACING, Direction.SOUTH), 18, 8, 10, start);
        structure.setBlockState(world, Blocks.GRASS_BLOCK.getDefaultState().with(SnowyDirtBlock.SNOWY, false), 19, 4, 11, start);
        structure.setBlockState(world, Blocks.OAK_PLANKS.getDefaultState(), 19, 5, 10, start);
        structure.setBlockState(world, Blocks.GRASS.getDefaultState(), 19, 5, 11, start);
        structure.setBlockState(world, Blocks.OAK_PLANKS.getDefaultState(), 19, 5, 12, start);
        structure.setBlockState(world, Blocks.SPRUCE_PLANKS.getDefaultState(), 19, 5, 13, start);
        structure.setBlockState(world, Blocks.OAK_PLANKS.getDefaultState(), 19, 5, 14, start);
        structure.setBlockState(world, Blocks.SPRUCE_PLANKS.getDefaultState(), 19, 5, 15, start);
        structure.setBlockState(world, Blocks.OAK_PLANKS.getDefaultState(), 19, 5, 16, start);
        structure.setBlockState(world, Blocks.LADDER.getDefaultState().with(LadderBlock.FACING, Direction.WEST).with(LadderBlock.WATERLOGGED, false), 19, 6, 14, start);
        structure.setBlockState(world, Blocks.VINE.getDefaultState().with(VineBlock.UP, false).with(VineBlock.NORTH, false).with(VineBlock.SOUTH, true).with(VineBlock.EAST, false).with(VineBlock.WEST, false), 19, 7, 8, start);
        structure.setBlockState(world, Blocks.VINE.getDefaultState().with(VineBlock.UP, false).with(VineBlock.NORTH, false).with(VineBlock.SOUTH, false).with(VineBlock.EAST, true).with(VineBlock.WEST, false), 19, 7, 14, start);
        structure.setBlockState(world, Blocks.VINE.getDefaultState().with(VineBlock.UP, true).with(VineBlock.NORTH, false).with(VineBlock.SOUTH, true).with(VineBlock.EAST, false).with(VineBlock.WEST, false), 19, 8, 8, start);
        structure.setBlockState(world, Blocks.REDSTONE_WIRE.getDefaultState().with(RedstoneWireBlock.POWER, 0).with(RedstoneWireBlock.NORTH, RedstoneSide.SIDE).with(RedstoneWireBlock.SOUTH, RedstoneSide.SIDE).with(RedstoneWireBlock.EAST, RedstoneSide.NONE).with(RedstoneWireBlock.WEST, RedstoneSide.NONE), 19, 10, 11, start);
        structure.setBlockState(world, Blocks.REDSTONE_WIRE.getDefaultState().with(RedstoneWireBlock.POWER, 0).with(RedstoneWireBlock.NORTH, RedstoneSide.SIDE).with(RedstoneWireBlock.SOUTH, RedstoneSide.NONE).with(RedstoneWireBlock.EAST, RedstoneSide.UP).with(RedstoneWireBlock.WEST, RedstoneSide.NONE), 19, 10, 12, start);
        structure.setBlockState(world, Blocks.REDSTONE_WIRE.getDefaultState().with(RedstoneWireBlock.POWER, 0).with(RedstoneWireBlock.NORTH, RedstoneSide.SIDE).with(RedstoneWireBlock.SOUTH, RedstoneSide.SIDE).with(RedstoneWireBlock.EAST, RedstoneSide.SIDE).with(RedstoneWireBlock.WEST, RedstoneSide.SIDE), 19, 10, 16, start);
        structure.setBlockState(world, Blocks.COBWEB.getDefaultState(), 19, 12, 12, start);
        structure.setBlockState(world, Blocks.GRASS.getDefaultState(), 20, 6, 18, start);
        structure.setBlockState(world, Blocks.SPRUCE_LOG.getDefaultState(), 20, 7, 10, start);
        structure.setBlockState(world, Blocks.GLASS_PANE.getDefaultState().with(FourWayBlock.WATERLOGGED, false).with(FourWayBlock.NORTH, true).with(FourWayBlock.SOUTH, true).with(FourWayBlock.EAST, false).with(FourWayBlock.WEST, false), 20, 7, 11, start);
        structure.setBlockState(world, Blocks.SPRUCE_LOG.getDefaultState(), 20, 7, 12, start);
        structure.setBlockState(world, Blocks.SPRUCE_LOG.getDefaultState(), 20, 7, 14, start);
        structure.setBlockState(world, Blocks.GLASS_PANE.getDefaultState().with(FourWayBlock.WATERLOGGED, false).with(FourWayBlock.NORTH, true).with(FourWayBlock.SOUTH, true).with(FourWayBlock.EAST, false).with(FourWayBlock.WEST, false), 20, 7, 15, start);
        structure.setBlockState(world, Blocks.VINE.getDefaultState().with(VineBlock.UP, false).with(VineBlock.NORTH, true).with(VineBlock.SOUTH, false).with(VineBlock.EAST, false).with(VineBlock.WEST, false), 20, 7, 18, start);
        structure.setBlockState(world, Blocks.VINE.getDefaultState().with(VineBlock.UP, true).with(VineBlock.NORTH, true).with(VineBlock.SOUTH, false).with(VineBlock.EAST, false).with(VineBlock.WEST, false), 20, 8, 18, start);
        structure.setBlockState(world, Blocks.SPRUCE_LOG.getDefaultState(), 20, 10, 10, start);
        structure.setBlockState(world, Blocks.SPRUCE_LOG.getDefaultState(), 20, 10, 16, start);
        structure.setBlockState(world, Blocks.SPRUCE_LOG.getDefaultState(), 20, 11, 11, start);
        structure.setBlockState(world, Blocks.REDSTONE_WIRE.getDefaultState().with(RedstoneWireBlock.POWER, 0).with(RedstoneWireBlock.NORTH, RedstoneSide.NONE).with(RedstoneWireBlock.SOUTH, RedstoneSide.NONE).with(RedstoneWireBlock.EAST, RedstoneSide.SIDE).with(RedstoneWireBlock.WEST, RedstoneSide.SIDE), 20, 11, 12, start);
        structure.setBlockState(world, Blocks.SPRUCE_LOG.getDefaultState(), 20, 11, 15, start);
        structure.setBlockState(world, Blocks.SPRUCE_LOG.getDefaultState(), 20, 12, 12, start);
        structure.setBlockState(world, Blocks.SPRUCE_PLANKS.getDefaultState(), 20, 12, 13, start);
        structure.setBlockState(world, Blocks.SPRUCE_LOG.getDefaultState(), 20, 12, 14, start);
        structure.setBlockState(world, Blocks.SPRUCE_LOG.getDefaultState(), 20, 13, 13, start);
        structure.setBlockState(world, Blocks.VINE.getDefaultState().with(VineBlock.UP, true).with(VineBlock.NORTH, false).with(VineBlock.SOUTH, false).with(VineBlock.EAST, false).with(VineBlock.WEST, true), 21, 8, 9, start);
        structure.setBlockState(world, Blocks.STONE_BRICK_STAIRS.getDefaultState().with(StairsBlock.FACING, Direction.NORTH).with(StairsBlock.WATERLOGGED, false).with(StairsBlock.SHAPE, StairsShape.STRAIGHT).with(StairsBlock.HALF, Half.TOP), 21, 9, 9, start);
        structure.setBlockState(world, Blocks.STONE_BRICK_STAIRS.getDefaultState().with(StairsBlock.FACING, Direction.SOUTH).with(StairsBlock.WATERLOGGED, false).with(StairsBlock.SHAPE, StairsShape.STRAIGHT).with(StairsBlock.HALF, Half.TOP), 21, 9, 17, start);
        structure.setBlockState(world, Blocks.STONE_BRICK_STAIRS.getDefaultState().with(StairsBlock.FACING, Direction.NORTH).with(StairsBlock.WATERLOGGED, false).with(StairsBlock.SHAPE, StairsShape.STRAIGHT).with(StairsBlock.HALF, Half.TOP), 21, 10, 10, start);
        structure.setBlockState(world, Blocks.STONE_BRICK_STAIRS.getDefaultState().with(StairsBlock.FACING, Direction.SOUTH).with(StairsBlock.WATERLOGGED, false).with(StairsBlock.SHAPE, StairsShape.STRAIGHT).with(StairsBlock.HALF, Half.TOP), 21, 10, 16, start);
        structure.setBlockState(world, Blocks.STONE_BRICK_STAIRS.getDefaultState().with(StairsBlock.FACING, Direction.NORTH).with(StairsBlock.WATERLOGGED, false).with(StairsBlock.SHAPE, StairsShape.STRAIGHT).with(StairsBlock.HALF, Half.BOTTOM), 21, 10, 17, start);
        structure.setBlockState(world, Blocks.STONE_BRICK_STAIRS.getDefaultState().with(StairsBlock.FACING, Direction.NORTH).with(StairsBlock.WATERLOGGED, false).with(StairsBlock.SHAPE, StairsShape.STRAIGHT).with(StairsBlock.HALF, Half.TOP), 21, 11, 11, start);
        structure.setBlockState(world, Blocks.VINE.getDefaultState().with(VineBlock.UP, false).with(VineBlock.NORTH, false).with(VineBlock.SOUTH, false).with(VineBlock.EAST, false).with(VineBlock.WEST, true), 21, 11, 13, start);
        structure.setBlockState(world, Blocks.STONE_BRICK_STAIRS.getDefaultState().with(StairsBlock.FACING, Direction.SOUTH).with(StairsBlock.WATERLOGGED, false).with(StairsBlock.SHAPE, StairsShape.STRAIGHT).with(StairsBlock.HALF, Half.TOP), 21, 11, 15, start);
        structure.setBlockState(world, Blocks.STONE_BRICK_STAIRS.getDefaultState().with(StairsBlock.FACING, Direction.NORTH).with(StairsBlock.WATERLOGGED, false).with(StairsBlock.SHAPE, StairsShape.STRAIGHT).with(StairsBlock.HALF, Half.BOTTOM), 21, 11, 16, start);
        structure.setBlockState(world, Blocks.STONE_BRICK_STAIRS.getDefaultState().with(StairsBlock.FACING, Direction.NORTH).with(StairsBlock.WATERLOGGED, false).with(StairsBlock.SHAPE, StairsShape.STRAIGHT).with(StairsBlock.HALF, Half.TOP), 21, 12, 12, start);
        structure.setBlockState(world, Blocks.VINE.getDefaultState().with(VineBlock.UP, false).with(VineBlock.NORTH, false).with(VineBlock.SOUTH, true).with(VineBlock.EAST, false).with(VineBlock.WEST, true), 21, 12, 13, start);
        structure.setBlockState(world, Blocks.STONE_BRICK_STAIRS.getDefaultState().with(StairsBlock.FACING, Direction.SOUTH).with(StairsBlock.WATERLOGGED, false).with(StairsBlock.SHAPE, StairsShape.STRAIGHT).with(StairsBlock.HALF, Half.TOP), 21, 12, 14, start);
        structure.setBlockState(world, Blocks.VINE.getDefaultState().with(VineBlock.UP, false).with(VineBlock.NORTH, true).with(VineBlock.SOUTH, true).with(VineBlock.EAST, false).with(VineBlock.WEST, true), 21, 13, 13, start);
        structure.setBlockState(world, Blocks.GRASS_BLOCK.getDefaultState().with(SnowyDirtBlock.SNOWY, false), 22, 0, 23, start);
        structure.setBlockState(world, Blocks.GRASS_BLOCK.getDefaultState().with(SnowyDirtBlock.SNOWY, false), 23, 1, 5, start);
        structure.setBlockState(world, Blocks.DIRT.getDefaultState(), 23, 1, 21, start);
        structure.setBlockState(world, Blocks.GRASS_BLOCK.getDefaultState().with(SnowyDirtBlock.SNOWY, false), 23, 1, 22, start);
        structure.setBlockState(world, Blocks.GRASS_BLOCK.getDefaultState().with(SnowyDirtBlock.SNOWY, false), 23, 2, 6, start);
        structure.setBlockState(world, Blocks.GRASS_BLOCK.getDefaultState().with(SnowyDirtBlock.SNOWY, false), 23, 2, 21, start);
        structure.fillWithBlocks(world, start, 1, 0, 9, 1, 0, 19, Blocks.GRASS_BLOCK.getDefaultState().with(SnowyDirtBlock.SNOWY, false));
        structure.fillWithBlocks(world, start, 2, 0, 6, 2, 0, 7, Blocks.GRASS_BLOCK.getDefaultState().with(SnowyDirtBlock.SNOWY, false));
        structure.fillWithBlocks(world, start, 2, 0, 8, 3, 0, 13, Blocks.DIRT.getDefaultState());
        structure.fillWithBlocks(world, start, 2, 0, 14, 2, 0, 19, Blocks.DIRT.getDefaultState());
        structure.fillWithBlocks(world, start, 2, 0, 20, 2, 0, 21, Blocks.GRASS_BLOCK.getDefaultState().with(SnowyDirtBlock.SNOWY, false));
        structure.fillWithBlocks(world, start, 2, 1, 8, 2, 1, 15, Blocks.GRASS_BLOCK.getDefaultState().with(SnowyDirtBlock.SNOWY, false));
        structure.fillWithBlocks(world, start, 2, 1, 16, 3, 1, 17, Blocks.DIRT.getDefaultState());
        structure.fillWithBlocks(world, start, 2, 1, 18, 2, 1, 19, Blocks.GRASS_BLOCK.getDefaultState().with(SnowyDirtBlock.SNOWY, false));
        structure.fillWithBlocks(world, start, 2, 2, 16, 2, 2, 17, Blocks.GRASS_BLOCK.getDefaultState().with(SnowyDirtBlock.SNOWY, false));
        structure.fillWithBlocks(world, start, 3, 0, 6, 4, 0, 9, Blocks.DIRT.getDefaultState());
        structure.fillWithBlocks(world, start, 3, 0, 14, 5, 0, 16, Blocks.STONE.getDefaultState());
        structure.fillWithBlocks(world, start, 3, 0, 17, 3, 1, 20, Blocks.DIRT.getDefaultState());
        structure.fillWithBlocks(world, start, 3, 0, 21, 3, 0, 21, Blocks.DIRT.getDefaultState());
        structure.fillWithBlocks(world, start, 3, 0, 22, 3, 0, 22, Blocks.GRASS_BLOCK.getDefaultState().with(SnowyDirtBlock.SNOWY, false));
        structure.fillWithBlocks(world, start, 3, 1, 7, 4, 1, 14, Blocks.DIRT.getDefaultState());
        structure.fillWithBlocks(world, start, 3, 1, 15, 3, 2, 18, Blocks.DIRT.getDefaultState());
        structure.fillWithBlocks(world, start, 3, 1, 21, 3, 1, 21, Blocks.GRASS_BLOCK.getDefaultState().with(SnowyDirtBlock.SNOWY, false));
        structure.fillWithBlocks(world, start, 3, 2, 8, 7, 2, 12, Blocks.DIRT.getDefaultState());
        structure.fillWithBlocks(world, start, 3, 2, 14, 7, 2, 18, Blocks.DIRT.getDefaultState());
        structure.fillWithBlocks(world, start, 3, 2, 19, 3, 2, 20, Blocks.GRASS_BLOCK.getDefaultState().with(SnowyDirtBlock.SNOWY, false));
        structure.fillWithBlocks(world, start, 3, 3, 8, 3, 3, 12, Blocks.GRASS_BLOCK.getDefaultState().with(SnowyDirtBlock.SNOWY, false));
        structure.fillWithBlocks(world, start, 3, 3, 14, 3, 3, 18, Blocks.GRASS_BLOCK.getDefaultState().with(SnowyDirtBlock.SNOWY, false));
        structure.fillWithBlocks(world, start, 4, 0, 5, 5, 0, 7, Blocks.DIRT.getDefaultState());
        structure.fillWithBlocks(world, start, 4, 0, 10, 13, 0, 19, Blocks.STONE.getDefaultState());
        structure.fillWithBlocks(world, start, 4, 0, 20, 4, 0, 22, Blocks.DIRT.getDefaultState());
        structure.fillWithBlocks(world, start, 4, 1, 6, 5, 1, 7, Blocks.DIRT.getDefaultState());
        structure.fillWithBlocks(world, start, 4, 1, 15, 7, 1, 18, Blocks.STONE.getDefaultState());
        structure.fillWithBlocks(world, start, 4, 1, 19, 4, 2, 20, Blocks.DIRT.getDefaultState());
        structure.fillWithBlocks(world, start, 4, 1, 21, 4, 1, 21, Blocks.DIRT.getDefaultState());
        structure.fillWithBlocks(world, start, 4, 1, 22, 4, 1, 22, Blocks.GRASS_BLOCK.getDefaultState().with(SnowyDirtBlock.SNOWY, false));
        structure.fillWithBlocks(world, start, 4, 2, 6, 18, 2, 20, Blocks.DIRT.getDefaultState());
        structure.fillWithBlocks(world, start, 4, 2, 21, 4, 2, 21, Blocks.GRASS_BLOCK.getDefaultState().with(SnowyDirtBlock.SNOWY, false));
        structure.fillWithBlocks(world, start, 4, 3, 6, 4, 3, 7, Blocks.GRASS_BLOCK.getDefaultState().with(SnowyDirtBlock.SNOWY, false));
        structure.fillWithBlocks(world, start, 4, 3, 8, 8, 3, 12, Blocks.DIRT.getDefaultState());
        structure.fillWithBlocks(world, start, 4, 3, 13, 4, 3, 14, Blocks.GRASS_BLOCK.getDefaultState().with(SnowyDirtBlock.SNOWY, false));
        structure.fillWithBlocks(world, start, 4, 3, 15, 7, 3, 18, Blocks.DIRT.getDefaultState());
        structure.fillWithBlocks(world, start, 4, 3, 19, 4, 3, 20, Blocks.GRASS_BLOCK.getDefaultState().with(SnowyDirtBlock.SNOWY, false));
        structure.fillWithBlocks(world, start, 4, 4, 8, 5, 4, 12, Blocks.GRASS_BLOCK.getDefaultState().with(SnowyDirtBlock.SNOWY, false));
        structure.fillWithBlocks(world, start, 4, 4, 15, 5, 4, 18, Blocks.GRASS_BLOCK.getDefaultState().with(SnowyDirtBlock.SNOWY, false));
        structure.fillWithBlocks(world, start, 5, 0, 4, 6, 0, 6, Blocks.DIRT.getDefaultState());
        structure.fillWithBlocks(world, start, 5, 0, 8, 17, 0, 20, Blocks.STONE.getDefaultState());
        structure.fillWithBlocks(world, start, 5, 0, 21, 5, 1, 22, Blocks.DIRT.getDefaultState());
        structure.fillWithBlocks(world, start, 5, 0, 23, 21, 0, 23, Blocks.DIRT.getDefaultState());
        structure.fillWithBlocks(world, start, 5, 1, 5, 6, 1, 6, Blocks.DIRT.getDefaultState());
        structure.fillWithBlocks(world, start, 5, 1, 8, 17, 1, 20, Blocks.STONE.getDefaultState());
        structure.fillWithBlocks(world, start, 5, 1, 23, 21, 1, 23, Blocks.GRASS_BLOCK.getDefaultState().with(SnowyDirtBlock.SNOWY, false));
        structure.fillWithBlocks(world, start, 5, 2, 21, 22, 2, 21, Blocks.DIRT.getDefaultState());
        structure.fillWithBlocks(world, start, 5, 2, 22, 22, 2, 22, Blocks.GRASS_BLOCK.getDefaultState().with(SnowyDirtBlock.SNOWY, false));
        structure.fillWithBlocks(world, start, 5, 3, 7, 17, 3, 19, Blocks.DIRT.getDefaultState());
        structure.fillWithBlocks(world, start, 5, 3, 20, 5, 3, 21, Blocks.GRASS_BLOCK.getDefaultState().with(SnowyDirtBlock.SNOWY, false));
        structure.fillWithBlocks(world, start, 5, 4, 7, 5, 4, 19, Blocks.GRASS_BLOCK.getDefaultState().with(SnowyDirtBlock.SNOWY, false));
        structure.fillWithBlocks(world, start, 6, 0, 3, 7, 0, 3, Blocks.GRASS_BLOCK.getDefaultState().with(SnowyDirtBlock.SNOWY, false));
        structure.fillWithBlocks(world, start, 6, 0, 7, 21, 0, 22, Blocks.STONE.getDefaultState());
        structure.fillWithBlocks(world, start, 6, 1, 4, 7, 1, 6, Blocks.DIRT.getDefaultState());
        structure.fillWithBlocks(world, start, 6, 1, 7, 20, 1, 21, Blocks.STONE.getDefaultState());
        structure.fillWithBlocks(world, start, 6, 1, 22, 8, 1, 22, Blocks.DIRT.getDefaultState());
        structure.fillWithBlocks(world, start, 6, 2, 4, 9, 2, 4, Blocks.GRASS_BLOCK.getDefaultState().with(SnowyDirtBlock.SNOWY, false));
        structure.fillWithBlocks(world, start, 6, 2, 5, 21, 2, 21, Blocks.DIRT.getDefaultState());
        structure.fillWithBlocks(world, start, 6, 3, 5, 12, 3, 5, Blocks.GRASS_BLOCK.getDefaultState().with(SnowyDirtBlock.SNOWY, false));
        structure.fillWithBlocks(world, start, 6, 3, 6, 20, 3, 20, Blocks.DIRT.getDefaultState());
        structure.fillWithBlocks(world, start, 6, 3, 21, 22, 3, 21, Blocks.GRASS_BLOCK.getDefaultState().with(SnowyDirtBlock.SNOWY, false));
        structure.fillWithBlocks(world, start, 6, 4, 6, 7, 4, 7, Blocks.GRASS_BLOCK.getDefaultState().with(SnowyDirtBlock.SNOWY, false));
        structure.fillWithBlocks(world, start, 6, 4, 8, 9, 4, 18, Blocks.DIRT.getDefaultState());
        structure.fillWithBlocks(world, start, 6, 4, 19, 6, 4, 20, Blocks.GRASS_BLOCK.getDefaultState().with(SnowyDirtBlock.SNOWY, false));
        structure.fillWithBlocks(world, start, 6, 5, 8, 6, 5, 18, Blocks.GRASS_BLOCK.getDefaultState().with(SnowyDirtBlock.SNOWY, false));
        structure.fillWithBlocks(world, start, 6, 6, 8, 6, 8, 8, Blocks.OAK_FENCE.getDefaultState().with(FourWayBlock.WATERLOGGED, false).with(FourWayBlock.NORTH, false).with(FourWayBlock.SOUTH, false).with(FourWayBlock.EAST, false).with(FourWayBlock.WEST, false));
        structure.fillWithBlocks(world, start, 6, 6, 9, 6, 7, 10, Blocks.VINE.getDefaultState().with(VineBlock.UP, false).with(VineBlock.NORTH, false).with(VineBlock.SOUTH, false).with(VineBlock.EAST, true).with(VineBlock.WEST, false));
        structure.fillWithBlocks(world, start, 6, 6, 11, 6, 6, 14, Blocks.GRASS.getDefaultState());
        structure.fillWithBlocks(world, start, 6, 6, 18, 6, 8, 18, Blocks.OAK_FENCE.getDefaultState().with(FourWayBlock.WATERLOGGED, false).with(FourWayBlock.NORTH, false).with(FourWayBlock.SOUTH, false).with(FourWayBlock.EAST, false).with(FourWayBlock.WEST, false));
        structure.fillWithBlocks(world, start, 6, 7, 13, 6, 11, 13, Blocks.VINE.getDefaultState().with(VineBlock.UP, false).with(VineBlock.NORTH, false).with(VineBlock.SOUTH, false).with(VineBlock.EAST, true).with(VineBlock.WEST, false));
        structure.fillWithBlocks(world, start, 6, 7, 16, 6, 8, 16, Blocks.VINE.getDefaultState().with(VineBlock.UP, false).with(VineBlock.NORTH, false).with(VineBlock.SOUTH, false).with(VineBlock.EAST, true).with(VineBlock.WEST, false));
        structure.fillWithBlocks(world, start, 6, 8, 12, 6, 8, 16, Blocks.VINE.getDefaultState().with(VineBlock.UP, false).with(VineBlock.NORTH, false).with(VineBlock.SOUTH, false).with(VineBlock.EAST, true).with(VineBlock.WEST, false));
        structure.fillWithBlocks(world, start, 6, 9, 8, 21, 9, 8, Blocks.STONE_BRICK_STAIRS.getDefaultState().with(StairsBlock.FACING, Direction.SOUTH).with(StairsBlock.WATERLOGGED, false).with(StairsBlock.SHAPE, StairsShape.STRAIGHT).with(StairsBlock.HALF, Half.BOTTOM));
        structure.fillWithBlocks(world, start, 6, 9, 14, 6, 9, 15, Blocks.VINE.getDefaultState().with(VineBlock.UP, false).with(VineBlock.NORTH, false).with(VineBlock.SOUTH, false).with(VineBlock.EAST, true).with(VineBlock.WEST, false));
        structure.fillWithBlocks(world, start, 6, 9, 18, 10, 9, 18, Blocks.STONE_BRICK_STAIRS.getDefaultState().with(StairsBlock.FACING, Direction.NORTH).with(StairsBlock.WATERLOGGED, false).with(StairsBlock.SHAPE, StairsShape.STRAIGHT).with(StairsBlock.HALF, Half.BOTTOM));
        structure.fillWithBlocks(world, start, 6, 10, 9, 9, 10, 9, Blocks.STONE_BRICK_STAIRS.getDefaultState().with(StairsBlock.FACING, Direction.SOUTH).with(StairsBlock.WATERLOGGED, false).with(StairsBlock.SHAPE, StairsShape.STRAIGHT).with(StairsBlock.HALF, Half.BOTTOM));
        structure.fillWithBlocks(world, start, 6, 10, 17, 7, 10, 17, Blocks.STONE_BRICK_STAIRS.getDefaultState().with(StairsBlock.FACING, Direction.NORTH).with(StairsBlock.WATERLOGGED, false).with(StairsBlock.SHAPE, StairsShape.STRAIGHT).with(StairsBlock.HALF, Half.BOTTOM));
        structure.fillWithBlocks(world, start, 6, 11, 16, 11, 11, 16, Blocks.STONE_BRICK_STAIRS.getDefaultState().with(StairsBlock.FACING, Direction.NORTH).with(StairsBlock.WATERLOGGED, false).with(StairsBlock.SHAPE, StairsShape.STRAIGHT).with(StairsBlock.HALF, Half.BOTTOM));
        structure.fillWithBlocks(world, start, 6, 12, 11, 7, 12, 11, Blocks.STONE_BRICK_STAIRS.getDefaultState().with(StairsBlock.FACING, Direction.SOUTH).with(StairsBlock.WATERLOGGED, false).with(StairsBlock.SHAPE, StairsShape.STRAIGHT).with(StairsBlock.HALF, Half.BOTTOM));
        structure.fillWithBlocks(world, start, 6, 12, 15, 8, 12, 15, Blocks.STONE_BRICK_STAIRS.getDefaultState().with(StairsBlock.FACING, Direction.NORTH).with(StairsBlock.WATERLOGGED, false).with(StairsBlock.SHAPE, StairsShape.STRAIGHT).with(StairsBlock.HALF, Half.BOTTOM));
        structure.fillWithBlocks(world, start, 6, 13, 12, 17, 13, 12, Blocks.STONE_BRICK_STAIRS.getDefaultState().with(StairsBlock.FACING, Direction.SOUTH).with(StairsBlock.WATERLOGGED, false).with(StairsBlock.SHAPE, StairsShape.STRAIGHT).with(StairsBlock.HALF, Half.BOTTOM));
        structure.fillWithBlocks(world, start, 6, 13, 14, 13, 13, 14, Blocks.STONE_BRICK_STAIRS.getDefaultState().with(StairsBlock.FACING, Direction.NORTH).with(StairsBlock.WATERLOGGED, false).with(StairsBlock.SHAPE, StairsShape.STRAIGHT).with(StairsBlock.HALF, Half.BOTTOM));
        structure.fillWithBlocks(world, start, 6, 14, 13, 21, 14, 13, Blocks.STONE_BRICK_SLAB.getDefaultState().with(SlabBlock.TYPE, SlabType.BOTTOM).with(SlabBlock.WATERLOGGED, false));
        structure.fillWithBlocks(world, start, 7, 0, 4, 7, 1, 5, Blocks.DIRT.getDefaultState());
        structure.fillWithBlocks(world, start, 7, 0, 6, 21, 0, 22, Blocks.STONE.getDefaultState());
        structure.fillWithBlocks(world, start, 7, 4, 19, 20, 4, 19, Blocks.DIRT.getDefaultState());
        structure.fillWithBlocks(world, start, 7, 4, 20, 22, 4, 20, Blocks.GRASS_BLOCK.getDefaultState().with(SnowyDirtBlock.SNOWY, false));
        structure.fillWithBlocks(world, start, 7, 5, 8, 21, 5, 8, Blocks.GRASS_BLOCK.getDefaultState().with(SnowyDirtBlock.SNOWY, false));
        structure.fillWithBlocks(world, start, 7, 5, 9, 7, 5, 17, Blocks.DIRT.getDefaultState());
        structure.fillWithBlocks(world, start, 7, 5, 18, 8, 5, 19, Blocks.GRASS_BLOCK.getDefaultState().with(SnowyDirtBlock.SNOWY, false));
        structure.fillWithBlocks(world, start, 7, 6, 8, 8, 7, 8, Blocks.VINE.getDefaultState().with(VineBlock.UP, false).with(VineBlock.NORTH, false).with(VineBlock.SOUTH, true).with(VineBlock.EAST, false).with(VineBlock.WEST, false));
        structure.fillWithBlocks(world, start, 7, 6, 9, 7, 9, 9, Blocks.SPRUCE_LOG.getDefaultState());
        structure.fillWithBlocks(world, start, 7, 6, 10, 7, 6, 16, Blocks.SPRUCE_PLANKS.getDefaultState());
        structure.fillWithBlocks(world, start, 7, 6, 17, 7, 9, 17, Blocks.SPRUCE_LOG.getDefaultState());
        structure.fillWithBlocks(world, start, 7, 6, 18, 8, 6, 18, Blocks.GRASS.getDefaultState());
        structure.fillWithBlocks(world, start, 7, 7, 12, 7, 7, 14, Blocks.SPRUCE_LOG.getDefaultState());
        structure.fillWithBlocks(world, start, 7, 7, 16, 7, 7, 17, Blocks.SPRUCE_LOG.getDefaultState());
        structure.fillWithBlocks(world, start, 7, 7, 18, 9, 7, 18, Blocks.VINE.getDefaultState().with(VineBlock.UP, false).with(VineBlock.NORTH, true).with(VineBlock.SOUTH, false).with(VineBlock.EAST, false).with(VineBlock.WEST, false));
        structure.fillWithBlocks(world, start, 7, 8, 10, 7, 8, 16, Blocks.SPRUCE_PLANKS.getDefaultState());
        structure.fillWithBlocks(world, start, 7, 9, 10, 7, 9, 16, Blocks.SPRUCE_STAIRS.getDefaultState().with(StairsBlock.FACING, Direction.EAST).with(StairsBlock.WATERLOGGED, false).with(StairsBlock.SHAPE, StairsShape.STRAIGHT).with(StairsBlock.HALF, Half.BOTTOM));
        structure.fillWithBlocks(world, start, 7, 10, 13, 7, 10, 15, Blocks.SPRUCE_PLANKS.getDefaultState());
        structure.fillWithBlocks(world, start, 8, 0, 2, 10, 0, 2, Blocks.GRASS_BLOCK.getDefaultState().with(SnowyDirtBlock.SNOWY, false));
        structure.fillWithBlocks(world, start, 8, 0, 3, 9, 0, 4, Blocks.DIRT.getDefaultState());
        structure.fillWithBlocks(world, start, 8, 0, 5, 20, 0, 22, Blocks.STONE.getDefaultState());
        structure.fillWithBlocks(world, start, 8, 1, 3, 10, 1, 3, Blocks.GRASS_BLOCK.getDefaultState().with(SnowyDirtBlock.SNOWY, false));
        structure.fillWithBlocks(world, start, 8, 1, 4, 9, 1, 5, Blocks.DIRT.getDefaultState());
        structure.fillWithBlocks(world, start, 8, 1, 6, 20, 1, 21, Blocks.STONE.getDefaultState());
        structure.fillWithBlocks(world, start, 8, 4, 6, 9, 4, 7, Blocks.GRASS_BLOCK.getDefaultState().with(SnowyDirtBlock.SNOWY, false));
        structure.fillWithBlocks(world, start, 8, 5, 9, 9, 5, 9, Blocks.DIRT.getDefaultState());
        structure.fillWithBlocks(world, start, 8, 5, 10, 8, 5, 10, Blocks.SPRUCE_PLANKS.getDefaultState());
        structure.fillWithBlocks(world, start, 8, 5, 11, 8, 5, 11, Blocks.OAK_PLANKS.getDefaultState());
        structure.fillWithBlocks(world, start, 8, 5, 12, 8, 5, 12, Blocks.SPRUCE_PLANKS.getDefaultState());
        structure.fillWithBlocks(world, start, 8, 5, 13, 8, 5, 13, Blocks.OAK_PLANKS.getDefaultState());
        structure.fillWithBlocks(world, start, 8, 5, 15, 8, 5, 15, Blocks.OAK_PLANKS.getDefaultState());
        structure.fillWithBlocks(world, start, 8, 5, 17, 9, 5, 17, Blocks.DIRT.getDefaultState());
        structure.fillWithBlocks(world, start, 8, 6, 9, 9, 6, 9, Blocks.SPRUCE_PLANKS.getDefaultState());
        structure.fillWithBlocks(world, start, 8, 6, 17, 9, 6, 17, Blocks.SPRUCE_PLANKS.getDefaultState());
        structure.fillWithBlocks(world, start, 8, 8, 8, 11, 8, 8, Blocks.VINE.getDefaultState().with(VineBlock.UP, false).with(VineBlock.NORTH, false).with(VineBlock.SOUTH, true).with(VineBlock.EAST, false).with(VineBlock.WEST, false));
        structure.fillWithBlocks(world, start, 8, 8, 9, 19, 9, 9, Blocks.SPRUCE_PLANKS.getDefaultState());
        structure.fillWithBlocks(world, start, 8, 8, 14, 8, 8, 15, Blocks.COBWEB.getDefaultState());
        structure.fillWithBlocks(world, start, 8, 8, 17, 11, 9, 17, Blocks.SPRUCE_PLANKS.getDefaultState());
        structure.fillWithBlocks(world, start, 8, 9, 10, 9, 9, 17, Blocks.SPRUCE_PLANKS.getDefaultState());
        structure.fillWithBlocks(world, start, 8, 11, 10, 9, 11, 10, Blocks.STONE_BRICK_STAIRS.getDefaultState().with(StairsBlock.FACING, Direction.SOUTH).with(StairsBlock.WATERLOGGED, false).with(StairsBlock.SHAPE, StairsShape.STRAIGHT).with(StairsBlock.HALF, Half.BOTTOM));
        structure.fillWithBlocks(world, start, 9, 1, 22, 18, 1, 22, Blocks.STONE.getDefaultState());
        structure.fillWithBlocks(world, start, 9, 5, 11, 9, 5, 11, Blocks.SPRUCE_PLANKS.getDefaultState());
        structure.fillWithBlocks(world, start, 9, 5, 12, 9, 5, 12, Blocks.OAK_PLANKS.getDefaultState());
        structure.fillWithBlocks(world, start, 9, 5, 13, 9, 5, 13, Blocks.SPRUCE_PLANKS.getDefaultState());
        structure.fillWithBlocks(world, start, 9, 5, 14, 9, 5, 14, Blocks.OAK_PLANKS.getDefaultState());
        structure.fillWithBlocks(world, start, 9, 5, 18, 10, 5, 19, Blocks.GRASS_BLOCK.getDefaultState().with(SnowyDirtBlock.SNOWY, false));
        structure.fillWithBlocks(world, start, 9, 6, 18, 9, 7, 18, Blocks.VINE.getDefaultState().with(VineBlock.UP, false).with(VineBlock.NORTH, true).with(VineBlock.SOUTH, false).with(VineBlock.EAST, false).with(VineBlock.WEST, false));
        structure.fillWithBlocks(world, start, 9, 10, 17, 10, 10, 17, Blocks.STONE_BRICK_STAIRS.getDefaultState().with(StairsBlock.FACING, Direction.NORTH).with(StairsBlock.WATERLOGGED, false).with(StairsBlock.SHAPE, StairsShape.STRAIGHT).with(StairsBlock.HALF, Half.BOTTOM));
        structure.fillWithBlocks(world, start, 9, 12, 11, 12, 12, 11, Blocks.STONE_BRICK_STAIRS.getDefaultState().with(StairsBlock.FACING, Direction.SOUTH).with(StairsBlock.WATERLOGGED, false).with(StairsBlock.SHAPE, StairsShape.STRAIGHT).with(StairsBlock.HALF, Half.BOTTOM));
        structure.fillWithBlocks(world, start, 10, 0, 1, 10, 0, 2, Blocks.GRASS_BLOCK.getDefaultState().with(SnowyDirtBlock.SNOWY, false));
        structure.fillWithBlocks(world, start, 10, 0, 3, 21, 0, 3, Blocks.DIRT.getDefaultState());
        structure.fillWithBlocks(world, start, 10, 0, 4, 19, 0, 22, Blocks.STONE.getDefaultState());
        structure.fillWithBlocks(world, start, 10, 1, 4, 11, 1, 5, Blocks.DIRT.getDefaultState());
        structure.fillWithBlocks(world, start, 10, 2, 4, 20, 2, 21, Blocks.DIRT.getDefaultState());
        structure.fillWithBlocks(world, start, 10, 3, 4, 11, 3, 5, Blocks.GRASS_BLOCK.getDefaultState().with(SnowyDirtBlock.SNOWY, false));
        structure.fillWithBlocks(world, start, 10, 4, 6, 11, 4, 7, Blocks.GRASS_BLOCK.getDefaultState().with(SnowyDirtBlock.SNOWY, false));
        structure.fillWithBlocks(world, start, 10, 4, 8, 11, 4, 9, Blocks.DIRT.getDefaultState());
        structure.fillWithBlocks(world, start, 10, 4, 10, 10, 4, 11, Blocks.GRASS_BLOCK.getDefaultState().with(SnowyDirtBlock.SNOWY, false));
        structure.fillWithBlocks(world, start, 10, 4, 12, 17, 4, 19, Blocks.DIRT.getDefaultState());
        structure.fillWithBlocks(world, start, 10, 5, 13, 10, 5, 13, Blocks.OAK_PLANKS.getDefaultState());
        structure.fillWithBlocks(world, start, 10, 5, 14, 10, 5, 14, Blocks.SPRUCE_PLANKS.getDefaultState());
        structure.fillWithBlocks(world, start, 10, 5, 15, 10, 5, 15, Blocks.OAK_PLANKS.getDefaultState());
        structure.fillWithBlocks(world, start, 10, 5, 17, 10, 5, 19, Blocks.GRASS_BLOCK.getDefaultState().with(SnowyDirtBlock.SNOWY, false));
        structure.fillWithBlocks(world, start, 10, 7, 8, 11, 8, 8, Blocks.VINE.getDefaultState().with(VineBlock.UP, false).with(VineBlock.NORTH, false).with(VineBlock.SOUTH, true).with(VineBlock.EAST, false).with(VineBlock.WEST, false));
        structure.fillWithBlocks(world, start, 10, 9, 11, 11, 9, 12, Blocks.SPRUCE_PLANKS.getDefaultState());
        structure.fillWithBlocks(world, start, 10, 9, 13, 10, 9, 17, Blocks.SPRUCE_PLANKS.getDefaultState());
        structure.fillWithBlocks(world, start, 10, 12, 15, 11, 12, 15, Blocks.STONE_BRICK_STAIRS.getDefaultState().with(StairsBlock.FACING, Direction.NORTH).with(StairsBlock.WATERLOGGED, false).with(StairsBlock.SHAPE, StairsShape.STRAIGHT).with(StairsBlock.HALF, Half.BOTTOM));
        structure.fillWithBlocks(world, start, 11, 0, 1, 18, 0, 1, Blocks.GRASS_BLOCK.getDefaultState().with(SnowyDirtBlock.SNOWY, false));
        structure.fillWithBlocks(world, start, 11, 0, 2, 12, 0, 3, Blocks.DIRT.getDefaultState());
        structure.fillWithBlocks(world, start, 11, 1, 2, 17, 1, 2, Blocks.GRASS_BLOCK.getDefaultState().with(SnowyDirtBlock.SNOWY, false));
        structure.fillWithBlocks(world, start, 11, 1, 3, 12, 1, 5, Blocks.DIRT.getDefaultState());
        structure.fillWithBlocks(world, start, 11, 2, 3, 17, 2, 3, Blocks.GRASS_BLOCK.getDefaultState().with(SnowyDirtBlock.SNOWY, false));
        structure.fillWithBlocks(world, start, 11, 4, 10, 17, 4, 19, Blocks.DIRT.getDefaultState());
        structure.fillWithBlocks(world, start, 11, 5, 9, 20, 5, 9, Blocks.DIRT.getDefaultState());
        structure.fillWithBlocks(world, start, 11, 5, 10, 11, 5, 10, Blocks.OAK_PLANKS.getDefaultState());
        structure.fillWithBlocks(world, start, 11, 5, 12, 11, 5, 12, Blocks.OAK_PLANKS.getDefaultState());
        structure.fillWithBlocks(world, start, 11, 5, 14, 11, 5, 14, Blocks.OAK_PLANKS.getDefaultState());
        structure.fillWithBlocks(world, start, 11, 5, 15, 11, 5, 15, Blocks.SPRUCE_PLANKS.getDefaultState());
        structure.fillWithBlocks(world, start, 11, 5, 17, 11, 5, 17, Blocks.DIRT.getDefaultState());
        structure.fillWithBlocks(world, start, 11, 5, 18, 11, 5, 19, Blocks.GRASS_BLOCK.getDefaultState().with(SnowyDirtBlock.SNOWY, false));
        structure.fillWithBlocks(world, start, 11, 6, 8, 13, 7, 8, Blocks.VINE.getDefaultState().with(VineBlock.UP, false).with(VineBlock.NORTH, false).with(VineBlock.SOUTH, true).with(VineBlock.EAST, false).with(VineBlock.WEST, false));
        structure.fillWithBlocks(world, start, 11, 6, 9, 19, 6, 9, Blocks.SPRUCE_PLANKS.getDefaultState());
        structure.fillWithBlocks(world, start, 11, 6, 18, 11, 7, 18, Blocks.VINE.getDefaultState().with(VineBlock.UP, false).with(VineBlock.NORTH, true).with(VineBlock.SOUTH, false).with(VineBlock.EAST, false).with(VineBlock.WEST, false));
        structure.fillWithBlocks(world, start, 11, 7, 9, 12, 7, 9, Blocks.SPRUCE_LOG.getDefaultState());
        structure.fillWithBlocks(world, start, 11, 7, 17, 11, 7, 17, Blocks.SPRUCE_LOG.getDefaultState());
        structure.fillWithBlocks(world, start, 11, 9, 10, 13, 9, 12, Blocks.SPRUCE_PLANKS.getDefaultState());
        structure.fillWithBlocks(world, start, 11, 9, 14, 12, 9, 17, Blocks.SPRUCE_PLANKS.getDefaultState());
        structure.fillWithBlocks(world, start, 11, 10, 9, 15, 10, 9, Blocks.STONE_BRICK_STAIRS.getDefaultState().with(StairsBlock.FACING, Direction.SOUTH).with(StairsBlock.WATERLOGGED, false).with(StairsBlock.SHAPE, StairsShape.STRAIGHT).with(StairsBlock.HALF, Half.BOTTOM));
        structure.fillWithBlocks(world, start, 11, 11, 10, 17, 11, 10, Blocks.STONE_BRICK_STAIRS.getDefaultState().with(StairsBlock.FACING, Direction.SOUTH).with(StairsBlock.WATERLOGGED, false).with(StairsBlock.SHAPE, StairsShape.STRAIGHT).with(StairsBlock.HALF, Half.BOTTOM));
        structure.fillWithBlocks(world, start, 12, 3, 4, 12, 3, 5, Blocks.GRASS_BLOCK.getDefaultState().with(SnowyDirtBlock.SNOWY, false));
        structure.fillWithBlocks(world, start, 12, 4, 6, 13, 4, 7, Blocks.GRASS_BLOCK.getDefaultState().with(SnowyDirtBlock.SNOWY, false));
        structure.fillWithBlocks(world, start, 12, 4, 8, 17, 4, 19, Blocks.DIRT.getDefaultState());
        structure.fillWithBlocks(world, start, 12, 5, 11, 12, 5, 11, Blocks.OAK_PLANKS.getDefaultState());
        structure.fillWithBlocks(world, start, 12, 5, 13, 12, 5, 13, Blocks.OAK_PLANKS.getDefaultState());
        structure.fillWithBlocks(world, start, 12, 5, 14, 12, 5, 14, Blocks.SPRUCE_PLANKS.getDefaultState());
        structure.fillWithBlocks(world, start, 12, 5, 15, 12, 5, 15, Blocks.OAK_PLANKS.getDefaultState());
        structure.fillWithBlocks(world, start, 12, 5, 16, 12, 5, 16, Blocks.SPRUCE_PLANKS.getDefaultState());
        structure.fillWithBlocks(world, start, 12, 5, 17, 12, 5, 18, Blocks.DIRT.getDefaultState());
        structure.fillWithBlocks(world, start, 12, 5, 19, 20, 5, 19, Blocks.GRASS_BLOCK.getDefaultState().with(SnowyDirtBlock.SNOWY, false));
        structure.fillWithBlocks(world, start, 12, 6, 17, 12, 7, 18, Blocks.SPRUCE_LOG.getDefaultState());
        structure.fillWithBlocks(world, start, 12, 6, 19, 12, 8, 19, Blocks.VINE.getDefaultState().with(VineBlock.UP, false).with(VineBlock.NORTH, true).with(VineBlock.SOUTH, false).with(VineBlock.EAST, false).with(VineBlock.WEST, false));
        structure.fillWithBlocks(world, start, 12, 8, 17, 12, 8, 18, Blocks.SPRUCE_LOG.getDefaultState());
        structure.fillWithBlocks(world, start, 12, 9, 13, 13, 9, 15, Blocks.SPRUCE_PLANKS.getDefaultState());
        structure.fillWithBlocks(world, start, 12, 9, 18, 15, 9, 18, Blocks.SPRUCE_STAIRS.getDefaultState().with(StairsBlock.FACING, Direction.NORTH).with(StairsBlock.WATERLOGGED, false).with(StairsBlock.SHAPE, StairsShape.STRAIGHT).with(StairsBlock.HALF, Half.TOP));
        structure.fillWithBlocks(world, start, 12, 11, 17, 12, 11, 18, Blocks.STONE_BRICK_STAIRS.getDefaultState().with(StairsBlock.FACING, Direction.EAST).with(StairsBlock.WATERLOGGED, false).with(StairsBlock.SHAPE, StairsShape.STRAIGHT).with(StairsBlock.HALF, Half.BOTTOM));
        structure.fillWithBlocks(world, start, 13, 0, 2, 14, 0, 3, Blocks.DIRT.getDefaultState());
        structure.fillWithBlocks(world, start, 13, 1, 3, 14, 1, 4, Blocks.DIRT.getDefaultState());
        structure.fillWithBlocks(world, start, 13, 1, 5, 16, 1, 22, Blocks.STONE.getDefaultState());
        structure.fillWithBlocks(world, start, 13, 3, 4, 20, 3, 4, Blocks.GRASS_BLOCK.getDefaultState().with(SnowyDirtBlock.SNOWY, false));
        structure.fillWithBlocks(world, start, 13, 3, 5, 16, 3, 20, Blocks.DIRT.getDefaultState());
        structure.fillWithBlocks(world, start, 13, 4, 5, 15, 4, 7, Blocks.GRASS_BLOCK.getDefaultState().with(SnowyDirtBlock.SNOWY, false));
        structure.fillWithBlocks(world, start, 13, 5, 10, 13, 5, 10, Blocks.OAK_PLANKS.getDefaultState());
        structure.fillWithBlocks(world, start, 13, 5, 12, 13, 5, 12, Blocks.OAK_PLANKS.getDefaultState());
        structure.fillWithBlocks(world, start, 13, 5, 14, 13, 5, 14, Blocks.OAK_PLANKS.getDefaultState());
        structure.fillWithBlocks(world, start, 13, 5, 15, 13, 5, 15, Blocks.SPRUCE_PLANKS.getDefaultState());
        structure.fillWithBlocks(world, start, 13, 5, 16, 13, 5, 16, Blocks.OAK_PLANKS.getDefaultState());
        structure.fillWithBlocks(world, start, 13, 5, 17, 13, 5, 17, Blocks.SPRUCE_PLANKS.getDefaultState());
        structure.fillWithBlocks(world, start, 13, 8, 18, 15, 8, 18, Blocks.SPRUCE_LOG.getDefaultState());
        structure.fillWithBlocks(world, start, 13, 9, 17, 19, 9, 17, Blocks.SPRUCE_PLANKS.getDefaultState());
        structure.fillWithBlocks(world, start, 13, 11, 18, 14, 11, 18, Blocks.SPRUCE_PLANKS.getDefaultState());
        structure.fillWithBlocks(world, start, 13, 11, 19, 14, 11, 19, Blocks.VINE.getDefaultState().with(VineBlock.UP, false).with(VineBlock.NORTH, true).with(VineBlock.SOUTH, false).with(VineBlock.EAST, false).with(VineBlock.WEST, false));
        structure.fillWithBlocks(world, start, 13, 12, 15, 13, 12, 18, Blocks.STONE_BRICK_STAIRS.getDefaultState().with(StairsBlock.FACING, Direction.EAST).with(StairsBlock.WATERLOGGED, false).with(StairsBlock.SHAPE, StairsShape.STRAIGHT).with(StairsBlock.HALF, Half.BOTTOM));
        structure.fillWithBlocks(world, start, 14, 5, 11, 14, 5, 11, Blocks.OAK_PLANKS.getDefaultState());
        structure.fillWithBlocks(world, start, 14, 5, 13, 14, 5, 13, Blocks.OAK_PLANKS.getDefaultState());
        structure.fillWithBlocks(world, start, 14, 5, 15, 14, 5, 15, Blocks.OAK_PLANKS.getDefaultState());
        structure.fillWithBlocks(world, start, 14, 9, 10, 14, 9, 14, Blocks.SPRUCE_PLANKS.getDefaultState());
        structure.fillWithBlocks(world, start, 14, 9, 16, 15, 9, 17, Blocks.SPRUCE_PLANKS.getDefaultState());
        structure.fillWithBlocks(world, start, 14, 10, 19, 14, 11, 19, Blocks.VINE.getDefaultState().with(VineBlock.UP, false).with(VineBlock.NORTH, true).with(VineBlock.SOUTH, false).with(VineBlock.EAST, false).with(VineBlock.WEST, false));
        structure.fillWithBlocks(world, start, 14, 12, 16, 14, 12, 18, Blocks.STONE_BRICK_STAIRS.getDefaultState().with(StairsBlock.FACING, Direction.WEST).with(StairsBlock.WATERLOGGED, false).with(StairsBlock.SHAPE, StairsShape.STRAIGHT).with(StairsBlock.HALF, Half.BOTTOM));
        structure.fillWithBlocks(world, start, 15, 0, 2, 16, 0, 3, Blocks.DIRT.getDefaultState());
        structure.fillWithBlocks(world, start, 15, 1, 3, 16, 1, 4, Blocks.DIRT.getDefaultState());
        structure.fillWithBlocks(world, start, 15, 5, 10, 15, 5, 10, Blocks.OAK_PLANKS.getDefaultState());
        structure.fillWithBlocks(world, start, 15, 5, 13, 15, 5, 13, Blocks.SPRUCE_PLANKS.getDefaultState());
        structure.fillWithBlocks(world, start, 15, 5, 14, 15, 5, 14, Blocks.OAK_PLANKS.getDefaultState());
        structure.fillWithBlocks(world, start, 15, 5, 15, 15, 5, 15, Blocks.SPRUCE_PLANKS.getDefaultState());
        structure.fillWithBlocks(world, start, 15, 5, 17, 15, 5, 18, Blocks.DIRT.getDefaultState());
        structure.fillWithBlocks(world, start, 15, 6, 17, 15, 7, 18, Blocks.SPRUCE_LOG.getDefaultState());
        structure.fillWithBlocks(world, start, 15, 6, 19, 15, 8, 19, Blocks.VINE.getDefaultState().with(VineBlock.UP, false).with(VineBlock.NORTH, true).with(VineBlock.SOUTH, false).with(VineBlock.EAST, false).with(VineBlock.WEST, false));
        structure.fillWithBlocks(world, start, 15, 7, 8, 17, 7, 8, Blocks.VINE.getDefaultState().with(VineBlock.UP, false).with(VineBlock.NORTH, false).with(VineBlock.SOUTH, true).with(VineBlock.EAST, false).with(VineBlock.WEST, false));
        structure.fillWithBlocks(world, start, 15, 7, 9, 16, 7, 9, Blocks.SPRUCE_LOG.getDefaultState());
        structure.fillWithBlocks(world, start, 15, 9, 10, 15, 9, 10, Blocks.SPRUCE_PLANKS.getDefaultState());
        structure.fillWithBlocks(world, start, 15, 9, 12, 16, 9, 13, Blocks.SPRUCE_PLANKS.getDefaultState());
        structure.fillWithBlocks(world, start, 15, 9, 15, 15, 9, 17, Blocks.SPRUCE_PLANKS.getDefaultState());
        structure.fillWithBlocks(world, start, 15, 10, 15, 15, 10, 15, Blocks.REDSTONE_WIRE.getDefaultState().with(RedstoneWireBlock.POWER, 0).with(RedstoneWireBlock.NORTH, RedstoneSide.SIDE).with(RedstoneWireBlock.SOUTH, RedstoneSide.SIDE).with(RedstoneWireBlock.EAST, RedstoneSide.SIDE).with(RedstoneWireBlock.WEST, RedstoneSide.SIDE));
        structure.fillWithBlocks(world, start, 15, 11, 17, 15, 11, 18, Blocks.STONE_BRICK_STAIRS.getDefaultState().with(StairsBlock.FACING, Direction.WEST).with(StairsBlock.WATERLOGGED, false).with(StairsBlock.SHAPE, StairsShape.STRAIGHT).with(StairsBlock.HALF, Half.BOTTOM));
        structure.fillWithBlocks(world, start, 15, 12, 11, 21, 12, 11, Blocks.STONE_BRICK_STAIRS.getDefaultState().with(StairsBlock.FACING, Direction.SOUTH).with(StairsBlock.WATERLOGGED, false).with(StairsBlock.SHAPE, StairsShape.STRAIGHT).with(StairsBlock.HALF, Half.BOTTOM));
        structure.fillWithBlocks(world, start, 15, 12, 15, 16, 12, 15, Blocks.STONE_BRICK_STAIRS.getDefaultState().with(StairsBlock.FACING, Direction.NORTH).with(StairsBlock.WATERLOGGED, false).with(StairsBlock.SHAPE, StairsShape.STRAIGHT).with(StairsBlock.HALF, Half.BOTTOM));
        structure.fillWithBlocks(world, start, 15, 13, 14, 16, 13, 14, Blocks.STONE_BRICK_STAIRS.getDefaultState().with(StairsBlock.FACING, Direction.NORTH).with(StairsBlock.WATERLOGGED, false).with(StairsBlock.SHAPE, StairsShape.STRAIGHT).with(StairsBlock.HALF, Half.BOTTOM));
        structure.fillWithBlocks(world, start, 16, 4, 5, 16, 4, 7, Blocks.GRASS_BLOCK.getDefaultState().with(SnowyDirtBlock.SNOWY, false));
        structure.fillWithBlocks(world, start, 16, 5, 10, 16, 5, 10, Blocks.SPRUCE_PLANKS.getDefaultState());
        structure.fillWithBlocks(world, start, 16, 5, 11, 16, 5, 11, Blocks.OAK_PLANKS.getDefaultState());
        structure.fillWithBlocks(world, start, 16, 5, 15, 16, 5, 15, Blocks.OAK_PLANKS.getDefaultState());
        structure.fillWithBlocks(world, start, 16, 5, 17, 20, 5, 17, Blocks.DIRT.getDefaultState());
        structure.fillWithBlocks(world, start, 16, 5, 18, 17, 5, 19, Blocks.GRASS_BLOCK.getDefaultState().with(SnowyDirtBlock.SNOWY, false));
        structure.fillWithBlocks(world, start, 16, 6, 17, 19, 6, 17, Blocks.SPRUCE_PLANKS.getDefaultState());
        structure.fillWithBlocks(world, start, 16, 6, 18, 17, 6, 18, Blocks.GRASS.getDefaultState());
        structure.fillWithBlocks(world, start, 16, 8, 17, 19, 9, 17, Blocks.SPRUCE_PLANKS.getDefaultState());
        structure.fillWithBlocks(world, start, 16, 9, 10, 16, 9, 14, Blocks.SPRUCE_PLANKS.getDefaultState());
        structure.fillWithBlocks(world, start, 16, 9, 16, 17, 9, 17, Blocks.SPRUCE_PLANKS.getDefaultState());
        structure.fillWithBlocks(world, start, 16, 11, 16, 19, 11, 16, Blocks.STONE_BRICK_STAIRS.getDefaultState().with(StairsBlock.FACING, Direction.NORTH).with(StairsBlock.WATERLOGGED, false).with(StairsBlock.SHAPE, StairsShape.STRAIGHT).with(StairsBlock.HALF, Half.BOTTOM));
        structure.fillWithBlocks(world, start, 17, 0, 2, 17, 0, 3, Blocks.DIRT.getDefaultState());
        structure.fillWithBlocks(world, start, 17, 1, 3, 17, 1, 5, Blocks.DIRT.getDefaultState());
        structure.fillWithBlocks(world, start, 17, 4, 6, 18, 4, 7, Blocks.GRASS_BLOCK.getDefaultState().with(SnowyDirtBlock.SNOWY, false));
        structure.fillWithBlocks(world, start, 17, 5, 10, 17, 5, 10, Blocks.OAK_PLANKS.getDefaultState());
        structure.fillWithBlocks(world, start, 17, 5, 11, 17, 5, 11, Blocks.SPRUCE_PLANKS.getDefaultState());
        structure.fillWithBlocks(world, start, 17, 5, 12, 17, 5, 12, Blocks.OAK_PLANKS.getDefaultState());
        structure.fillWithBlocks(world, start, 17, 5, 14, 17, 5, 14, Blocks.OAK_PLANKS.getDefaultState());
        structure.fillWithBlocks(world, start, 17, 6, 8, 17, 7, 8, Blocks.VINE.getDefaultState().with(VineBlock.UP, false).with(VineBlock.NORTH, false).with(VineBlock.SOUTH, true).with(VineBlock.EAST, false).with(VineBlock.WEST, false));
        structure.fillWithBlocks(world, start, 17, 9, 10, 17, 9, 10, Blocks.SPRUCE_PLANKS.getDefaultState());
        structure.fillWithBlocks(world, start, 17, 9, 12, 18, 9, 17, Blocks.SPRUCE_PLANKS.getDefaultState());
        structure.fillWithBlocks(world, start, 17, 9, 18, 21, 9, 18, Blocks.STONE_BRICK_STAIRS.getDefaultState().with(StairsBlock.FACING, Direction.NORTH).with(StairsBlock.WATERLOGGED, false).with(StairsBlock.SHAPE, StairsShape.STRAIGHT).with(StairsBlock.HALF, Half.BOTTOM));
        structure.fillWithBlocks(world, start, 17, 10, 9, 18, 10, 9, Blocks.STONE_BRICK_STAIRS.getDefaultState().with(StairsBlock.FACING, Direction.SOUTH).with(StairsBlock.WATERLOGGED, false).with(StairsBlock.SHAPE, StairsShape.STRAIGHT).with(StairsBlock.HALF, Half.BOTTOM));
        structure.fillWithBlocks(world, start, 17, 10, 17, 19, 10, 17, Blocks.STONE_BRICK_STAIRS.getDefaultState().with(StairsBlock.FACING, Direction.NORTH).with(StairsBlock.WATERLOGGED, false).with(StairsBlock.SHAPE, StairsShape.STRAIGHT).with(StairsBlock.HALF, Half.BOTTOM));
        structure.fillWithBlocks(world, start, 17, 13, 13, 19, 13, 13, Blocks.COBWEB.getDefaultState());
        structure.fillWithBlocks(world, start, 18, 0, 2, 20, 0, 2, Blocks.GRASS_BLOCK.getDefaultState().with(SnowyDirtBlock.SNOWY, false));
        structure.fillWithBlocks(world, start, 18, 1, 3, 21, 1, 3, Blocks.GRASS_BLOCK.getDefaultState().with(SnowyDirtBlock.SNOWY, false));
        structure.fillWithBlocks(world, start, 18, 1, 4, 20, 2, 4, Blocks.DIRT.getDefaultState());
        structure.fillWithBlocks(world, start, 18, 1, 5, 19, 1, 21, Blocks.STONE.getDefaultState());
        structure.fillWithBlocks(world, start, 18, 3, 5, 19, 3, 20, Blocks.DIRT.getDefaultState());
        structure.fillWithBlocks(world, start, 18, 4, 5, 19, 4, 7, Blocks.GRASS_BLOCK.getDefaultState().with(SnowyDirtBlock.SNOWY, false));
        structure.fillWithBlocks(world, start, 18, 4, 8, 19, 4, 9, Blocks.DIRT.getDefaultState());
        structure.fillWithBlocks(world, start, 18, 4, 10, 18, 4, 10, Blocks.GRASS_BLOCK.getDefaultState().with(SnowyDirtBlock.SNOWY, false));
        structure.fillWithBlocks(world, start, 18, 4, 11, 18, 4, 19, Blocks.DIRT.getDefaultState());
        structure.fillWithBlocks(world, start, 18, 5, 10, 18, 5, 10, Blocks.GRASS.getDefaultState());
        structure.fillWithBlocks(world, start, 18, 5, 11, 18, 5, 11, Blocks.OAK_PLANKS.getDefaultState());
        structure.fillWithBlocks(world, start, 18, 5, 12, 18, 5, 12, Blocks.SPRUCE_PLANKS.getDefaultState());
        structure.fillWithBlocks(world, start, 18, 5, 13, 18, 5, 13, Blocks.OAK_PLANKS.getDefaultState());
        structure.fillWithBlocks(world, start, 18, 5, 15, 18, 5, 15, Blocks.OAK_PLANKS.getDefaultState());
        structure.fillWithBlocks(world, start, 18, 5, 18, 19, 5, 19, Blocks.GRASS_BLOCK.getDefaultState().with(SnowyDirtBlock.SNOWY, false));
        structure.fillWithBlocks(world, start, 18, 9, 10, 19, 9, 13, Blocks.SPRUCE_PLANKS.getDefaultState());
        structure.fillWithBlocks(world, start, 18, 12, 15, 21, 12, 15, Blocks.STONE_BRICK_STAIRS.getDefaultState().with(StairsBlock.FACING, Direction.NORTH).with(StairsBlock.WATERLOGGED, false).with(StairsBlock.SHAPE, StairsShape.STRAIGHT).with(StairsBlock.HALF, Half.BOTTOM));
        structure.fillWithBlocks(world, start, 18, 13, 14, 21, 13, 14, Blocks.STONE_BRICK_STAIRS.getDefaultState().with(StairsBlock.FACING, Direction.NORTH).with(StairsBlock.WATERLOGGED, false).with(StairsBlock.SHAPE, StairsShape.STRAIGHT).with(StairsBlock.HALF, Half.BOTTOM));
        structure.fillWithBlocks(world, start, 19, 1, 22, 22, 1, 22, Blocks.DIRT.getDefaultState());
        structure.fillWithBlocks(world, start, 19, 4, 10, 19, 4, 10, Blocks.DIRT.getDefaultState());
        structure.fillWithBlocks(world, start, 19, 4, 12, 21, 4, 18, Blocks.DIRT.getDefaultState());
        structure.fillWithBlocks(world, start, 19, 6, 8, 20, 6, 8, Blocks.VINE.getDefaultState().with(VineBlock.UP, false).with(VineBlock.NORTH, false).with(VineBlock.SOUTH, true).with(VineBlock.EAST, false).with(VineBlock.WEST, false));
        structure.fillWithBlocks(world, start, 19, 6, 18, 19, 8, 18, Blocks.VINE.getDefaultState().with(VineBlock.UP, false).with(VineBlock.NORTH, true).with(VineBlock.SOUTH, false).with(VineBlock.EAST, false).with(VineBlock.WEST, false));
        structure.fillWithBlocks(world, start, 19, 7, 9, 19, 7, 9, Blocks.SPRUCE_LOG.getDefaultState());
        structure.fillWithBlocks(world, start, 19, 7, 17, 20, 7, 17, Blocks.SPRUCE_LOG.getDefaultState());
        structure.fillWithBlocks(world, start, 19, 8, 10, 19, 8, 11, Blocks.COBWEB.getDefaultState());
        structure.fillWithBlocks(world, start, 19, 8, 14, 19, 9, 14, Blocks.LADDER.getDefaultState().with(LadderBlock.FACING, Direction.WEST).with(LadderBlock.WATERLOGGED, false));
        structure.fillWithBlocks(world, start, 19, 9, 15, 19, 9, 17, Blocks.SPRUCE_PLANKS.getDefaultState());
        structure.fillWithBlocks(world, start, 19, 11, 10, 21, 11, 10, Blocks.STONE_BRICK_STAIRS.getDefaultState().with(StairsBlock.FACING, Direction.SOUTH).with(StairsBlock.WATERLOGGED, false).with(StairsBlock.SHAPE, StairsShape.STRAIGHT).with(StairsBlock.HALF, Half.BOTTOM));
        structure.fillWithBlocks(world, start, 19, 13, 12, 21, 13, 12, Blocks.STONE_BRICK_STAIRS.getDefaultState().with(StairsBlock.FACING, Direction.SOUTH).with(StairsBlock.WATERLOGGED, false).with(StairsBlock.SHAPE, StairsShape.STRAIGHT).with(StairsBlock.HALF, Half.BOTTOM));
        structure.fillWithBlocks(world, start, 20, 0, 4, 20, 0, 4, Blocks.DIRT.getDefaultState());
        structure.fillWithBlocks(world, start, 20, 1, 5, 20, 1, 5, Blocks.DIRT.getDefaultState());
        structure.fillWithBlocks(world, start, 20, 3, 5, 20, 3, 5, Blocks.GRASS_BLOCK.getDefaultState().with(SnowyDirtBlock.SNOWY, false));
        structure.fillWithBlocks(world, start, 20, 4, 6, 20, 4, 7, Blocks.GRASS_BLOCK.getDefaultState().with(SnowyDirtBlock.SNOWY, false));
        structure.fillWithBlocks(world, start, 20, 4, 8, 21, 4, 18, Blocks.DIRT.getDefaultState());
        structure.fillWithBlocks(world, start, 20, 5, 10, 20, 5, 11, Blocks.DIRT.getDefaultState());
        structure.fillWithBlocks(world, start, 20, 5, 12, 20, 5, 12, Blocks.GRASS_BLOCK.getDefaultState().with(SnowyDirtBlock.SNOWY, false));
        structure.fillWithBlocks(world, start, 20, 5, 13, 20, 5, 17, Blocks.DIRT.getDefaultState());
        structure.fillWithBlocks(world, start, 20, 5, 18, 20, 5, 19, Blocks.GRASS_BLOCK.getDefaultState().with(SnowyDirtBlock.SNOWY, false));
        structure.fillWithBlocks(world, start, 20, 6, 9, 20, 9, 9, Blocks.SPRUCE_LOG.getDefaultState());
        structure.fillWithBlocks(world, start, 20, 6, 10, 20, 6, 11, Blocks.SPRUCE_PLANKS.getDefaultState());
        structure.fillWithBlocks(world, start, 20, 6, 13, 20, 6, 16, Blocks.SPRUCE_PLANKS.getDefaultState());
        structure.fillWithBlocks(world, start, 20, 6, 17, 20, 9, 17, Blocks.SPRUCE_LOG.getDefaultState());
        structure.fillWithBlocks(world, start, 20, 7, 16, 20, 7, 17, Blocks.SPRUCE_LOG.getDefaultState());
        structure.fillWithBlocks(world, start, 20, 8, 10, 20, 8, 16, Blocks.SPRUCE_PLANKS.getDefaultState());
        structure.fillWithBlocks(world, start, 20, 9, 10, 20, 9, 16, Blocks.SPRUCE_STAIRS.getDefaultState().with(StairsBlock.FACING, Direction.WEST).with(StairsBlock.WATERLOGGED, false).with(StairsBlock.SHAPE, StairsShape.STRAIGHT).with(StairsBlock.HALF, Half.BOTTOM));
        structure.fillWithBlocks(world, start, 20, 10, 9, 21, 10, 9, Blocks.STONE_BRICK_STAIRS.getDefaultState().with(StairsBlock.FACING, Direction.SOUTH).with(StairsBlock.WATERLOGGED, false).with(StairsBlock.SHAPE, StairsShape.STRAIGHT).with(StairsBlock.HALF, Half.BOTTOM));
        structure.fillWithBlocks(world, start, 20, 10, 11, 20, 10, 12, Blocks.SPRUCE_PLANKS.getDefaultState());
        structure.fillWithBlocks(world, start, 20, 10, 14, 20, 11, 14, Blocks.SPRUCE_PLANKS.getDefaultState());
        structure.fillWithBlocks(world, start, 21, 0, 4, 22, 0, 5, Blocks.DIRT.getDefaultState());
        structure.fillWithBlocks(world, start, 21, 1, 4, 21, 1, 6, Blocks.DIRT.getDefaultState());
        structure.fillWithBlocks(world, start, 21, 1, 7, 23, 1, 20, Blocks.STONE.getDefaultState());
        structure.fillWithBlocks(world, start, 21, 1, 21, 22, 1, 21, Blocks.STONE.getDefaultState());
        structure.fillWithBlocks(world, start, 21, 2, 4, 21, 2, 4, Blocks.GRASS_BLOCK.getDefaultState().with(SnowyDirtBlock.SNOWY, false));
        structure.fillWithBlocks(world, start, 21, 3, 5, 21, 3, 6, Blocks.GRASS_BLOCK.getDefaultState().with(SnowyDirtBlock.SNOWY, false));
        structure.fillWithBlocks(world, start, 21, 3, 7, 22, 3, 20, Blocks.DIRT.getDefaultState());
        structure.fillWithBlocks(world, start, 21, 4, 7, 21, 4, 7, Blocks.GRASS_BLOCK.getDefaultState().with(SnowyDirtBlock.SNOWY, false));
        structure.fillWithBlocks(world, start, 21, 4, 19, 22, 4, 20, Blocks.GRASS_BLOCK.getDefaultState().with(SnowyDirtBlock.SNOWY, false));
        structure.fillWithBlocks(world, start, 21, 5, 9, 21, 5, 18, Blocks.GRASS_BLOCK.getDefaultState().with(SnowyDirtBlock.SNOWY, false));
        structure.fillWithBlocks(world, start, 21, 6, 8, 21, 8, 8, Blocks.OAK_FENCE.getDefaultState().with(FourWayBlock.WATERLOGGED, false).with(FourWayBlock.NORTH, false).with(FourWayBlock.SOUTH, false).with(FourWayBlock.EAST, false).with(FourWayBlock.WEST, false));
        structure.fillWithBlocks(world, start, 21, 6, 9, 21, 7, 9, Blocks.VINE.getDefaultState().with(VineBlock.UP, false).with(VineBlock.NORTH, false).with(VineBlock.SOUTH, false).with(VineBlock.EAST, false).with(VineBlock.WEST, true));
        structure.fillWithBlocks(world, start, 21, 6, 10, 21, 6, 11, Blocks.GRASS.getDefaultState());
        structure.fillWithBlocks(world, start, 21, 6, 13, 21, 8, 15, Blocks.VINE.getDefaultState().with(VineBlock.UP, false).with(VineBlock.NORTH, false).with(VineBlock.SOUTH, false).with(VineBlock.EAST, false).with(VineBlock.WEST, true));
        structure.fillWithBlocks(world, start, 21, 6, 17, 21, 7, 17, Blocks.VINE.getDefaultState().with(VineBlock.UP, false).with(VineBlock.NORTH, false).with(VineBlock.SOUTH, false).with(VineBlock.EAST, false).with(VineBlock.WEST, true));
        structure.fillWithBlocks(world, start, 21, 6, 18, 21, 8, 18, Blocks.OAK_FENCE.getDefaultState().with(FourWayBlock.WATERLOGGED, false).with(FourWayBlock.NORTH, false).with(FourWayBlock.SOUTH, false).with(FourWayBlock.EAST, false).with(FourWayBlock.WEST, false));
        structure.fillWithBlocks(world, start, 21, 7, 10, 21, 8, 10, Blocks.VINE.getDefaultState().with(VineBlock.UP, false).with(VineBlock.NORTH, false).with(VineBlock.SOUTH, false).with(VineBlock.EAST, false).with(VineBlock.WEST, true));
        structure.fillWithBlocks(world, start, 21, 9, 13, 21, 10, 14, Blocks.VINE.getDefaultState().with(VineBlock.UP, false).with(VineBlock.NORTH, false).with(VineBlock.SOUTH, false).with(VineBlock.EAST, false).with(VineBlock.WEST, true));
        structure.fillWithBlocks(world, start, 21, 10, 12, 21, 10, 14, Blocks.VINE.getDefaultState().with(VineBlock.UP, false).with(VineBlock.NORTH, false).with(VineBlock.SOUTH, false).with(VineBlock.EAST, false).with(VineBlock.WEST, true));
        structure.fillWithBlocks(world, start, 22, 0, 3, 22, 0, 3, Blocks.GRASS_BLOCK.getDefaultState().with(SnowyDirtBlock.SNOWY, false));
        structure.fillWithBlocks(world, start, 22, 0, 6, 23, 1, 6, Blocks.DIRT.getDefaultState());
        structure.fillWithBlocks(world, start, 22, 0, 7, 23, 0, 21, Blocks.STONE.getDefaultState());
        structure.fillWithBlocks(world, start, 22, 0, 22, 23, 0, 22, Blocks.DIRT.getDefaultState());
        structure.fillWithBlocks(world, start, 22, 1, 4, 22, 1, 4, Blocks.GRASS_BLOCK.getDefaultState().with(SnowyDirtBlock.SNOWY, false));
        structure.fillWithBlocks(world, start, 22, 1, 5, 22, 1, 6, Blocks.DIRT.getDefaultState());
        structure.fillWithBlocks(world, start, 22, 2, 5, 22, 2, 5, Blocks.GRASS_BLOCK.getDefaultState().with(SnowyDirtBlock.SNOWY, false));
        structure.fillWithBlocks(world, start, 22, 2, 6, 22, 2, 21, Blocks.DIRT.getDefaultState());
        structure.fillWithBlocks(world, start, 22, 3, 6, 22, 3, 6, Blocks.GRASS_BLOCK.getDefaultState().with(SnowyDirtBlock.SNOWY, false));
        structure.fillWithBlocks(world, start, 22, 4, 7, 22, 4, 20, Blocks.GRASS_BLOCK.getDefaultState().with(SnowyDirtBlock.SNOWY, false));
        structure.fillWithBlocks(world, start, 23, 0, 3, 23, 0, 4, Blocks.GRASS_BLOCK.getDefaultState().with(SnowyDirtBlock.SNOWY, false));
        structure.fillWithBlocks(world, start, 23, 0, 5, 23, 0, 6, Blocks.DIRT.getDefaultState());
        structure.fillWithBlocks(world, start, 23, 2, 7, 23, 2, 20, Blocks.DIRT.getDefaultState());
        structure.fillWithBlocks(world, start, 23, 3, 7, 23, 3, 20, Blocks.GRASS_BLOCK.getDefaultState().with(SnowyDirtBlock.SNOWY, false));

    }
}
