package mod.arcalitegames.odyssey.world.structure.structures.towers.watch_tower;

import mod.arcalitegames.odyssey.world.structure.StructureBase;
import net.minecraft.block.AbstractButtonBlock;
import net.minecraft.block.Blocks;
import net.minecraft.block.DoorBlock;
import net.minecraft.block.FourWayBlock;
import net.minecraft.block.HorizontalBlock;
import net.minecraft.block.HorizontalFaceBlock;
import net.minecraft.block.LadderBlock;
import net.minecraft.block.PressurePlateBlock;
import net.minecraft.block.SlabBlock;
import net.minecraft.block.SnowyDirtBlock;
import net.minecraft.block.StairsBlock;
import net.minecraft.block.WallBlock;
import net.minecraft.block.WallHeight;
import net.minecraft.block.WallTorchBlock;
import net.minecraft.state.properties.AttachFace;
import net.minecraft.state.properties.DoorHingeSide;
import net.minecraft.state.properties.DoubleBlockHalf;
import net.minecraft.state.properties.Half;
import net.minecraft.state.properties.SlabType;
import net.minecraft.state.properties.StairsShape;
import net.minecraft.util.Direction;
import net.minecraft.util.math.BlockPos;
import net.minecraft.world.World;

public class WatchTowerComponents
{

	public static BlockPos start;
    public static World world;
    public static StructureBase structure;

    public static void init(World worldIn, BlockPos blockPos, StructureBase structureIn)
    {
        world = worldIn; start = blockPos; structure = structureIn;
    }
    
    public static void generatePart1()
    {
        structure.setBlockState(world, Blocks.GRASS_BLOCK.getDefaultState().with(SnowyDirtBlock.SNOWY, false), -194, 4, -52, start);
        structure.setBlockState(world, Blocks.COBBLESTONE_STAIRS.getDefaultState().with(StairsBlock.FACING, Direction.EAST).with(StairsBlock.WATERLOGGED, false).with(StairsBlock.SHAPE, StairsShape.STRAIGHT).with(StairsBlock.HALF, Half.BOTTOM), -194, 5, -51, start);
        structure.setBlockState(world, Blocks.STONE_BRICK_STAIRS.getDefaultState().with(StairsBlock.FACING, Direction.EAST).with(StairsBlock.WATERLOGGED, false).with(StairsBlock.SHAPE, StairsShape.STRAIGHT).with(StairsBlock.HALF, Half.BOTTOM), -193, 5, -52, start);
        structure.setBlockState(world, Blocks.GRASS.getDefaultState(), -193, 5, -48, start);
        structure.setBlockState(world, Blocks.COBBLESTONE_STAIRS.getDefaultState().with(StairsBlock.FACING, Direction.EAST).with(StairsBlock.WATERLOGGED, false).with(StairsBlock.SHAPE, StairsShape.STRAIGHT).with(StairsBlock.HALF, Half.BOTTOM), -193, 8, -51, start);
        structure.setBlockState(world, Blocks.STONE_BRICK_STAIRS.getDefaultState().with(StairsBlock.FACING, Direction.EAST).with(StairsBlock.WATERLOGGED, false).with(StairsBlock.SHAPE, StairsShape.STRAIGHT).with(StairsBlock.HALF, Half.TOP), -193, 12, -52, start);
        structure.setBlockState(world, Blocks.COBBLESTONE_STAIRS.getDefaultState().with(StairsBlock.FACING, Direction.EAST).with(StairsBlock.WATERLOGGED, false).with(StairsBlock.SHAPE, StairsShape.STRAIGHT).with(StairsBlock.HALF, Half.TOP), -193, 12, -51, start);
        structure.setBlockState(world, Blocks.STONE_BRICK_STAIRS.getDefaultState().with(StairsBlock.FACING, Direction.EAST).with(StairsBlock.WATERLOGGED, false).with(StairsBlock.SHAPE, StairsShape.STRAIGHT).with(StairsBlock.HALF, Half.TOP), -193, 12, -50, start);
        structure.setBlockState(world, Blocks.STONE_BRICK_STAIRS.getDefaultState().with(StairsBlock.FACING, Direction.SOUTH).with(StairsBlock.WATERLOGGED, false).with(StairsBlock.SHAPE, StairsShape.STRAIGHT).with(StairsBlock.HALF, Half.TOP), -193, 13, -52, start);
        structure.setBlockState(world, Blocks.COBBLESTONE_WALL.getDefaultState().with(WallBlock.WATERLOGGED, false).with(WallBlock.UP, false).with(WallBlock.WALL_HEIGHT_NORTH, WallHeight.LOW).with(WallBlock.WALL_HEIGHT_SOUTH, WallHeight.LOW).with(WallBlock.WALL_HEIGHT_EAST, WallHeight.LOW).with(WallBlock.WALL_HEIGHT_WEST, WallHeight.LOW), -193, 13, -51, start);
        structure.setBlockState(world, Blocks.STONE_BRICK_STAIRS.getDefaultState().with(StairsBlock.FACING, Direction.NORTH).with(StairsBlock.WATERLOGGED, false).with(StairsBlock.SHAPE, StairsShape.STRAIGHT).with(StairsBlock.HALF, Half.TOP), -193, 13, -50, start);
        structure.setBlockState(world, Blocks.STONE_BRICKS.getDefaultState(), -193, 14, -52, start);
        structure.setBlockState(world, Blocks.STONE_BRICK_SLAB.getDefaultState().with(SlabBlock.TYPE, SlabType.BOTTOM).with(SlabBlock.WATERLOGGED, false), -193, 14, -51, start);
        structure.setBlockState(world, Blocks.STONE_BRICKS.getDefaultState(), -193, 14, -50, start);
        structure.setBlockState(world, Blocks.GRASS_BLOCK.getDefaultState().with(SnowyDirtBlock.SNOWY, false), -192, 0, -49, start);
        structure.setBlockState(world, Blocks.AIR.getDefaultState(), -192, 5, -55, start);
        structure.setBlockState(world, Blocks.STONE_BRICK_STAIRS.getDefaultState().with(StairsBlock.FACING, Direction.EAST).with(StairsBlock.WATERLOGGED, false).with(StairsBlock.SHAPE, StairsShape.STRAIGHT).with(StairsBlock.HALF, Half.BOTTOM), -192, 5, -53, start);
        structure.setBlockState(world, Blocks.STONE_BRICK_STAIRS.getDefaultState().with(StairsBlock.FACING, Direction.EAST).with(StairsBlock.WATERLOGGED, false).with(StairsBlock.SHAPE, StairsShape.STRAIGHT).with(StairsBlock.HALF, Half.BOTTOM), -192, 5, -49, start);
        structure.setBlockState(world, Blocks.AIR.getDefaultState(), -192, 5, -47, start);
        structure.setBlockState(world, Blocks.COBBLESTONE_STAIRS.getDefaultState().with(StairsBlock.FACING, Direction.EAST).with(StairsBlock.WATERLOGGED, false).with(StairsBlock.SHAPE, StairsShape.STRAIGHT).with(StairsBlock.HALF, Half.BOTTOM), -192, 6, -54, start);
        structure.setBlockState(world, Blocks.COBBLESTONE_STAIRS.getDefaultState().with(StairsBlock.FACING, Direction.EAST).with(StairsBlock.WATERLOGGED, false).with(StairsBlock.SHAPE, StairsShape.STRAIGHT).with(StairsBlock.HALF, Half.BOTTOM), -192, 6, -48, start);
        structure.setBlockState(world, Blocks.COBBLESTONE_STAIRS.getDefaultState().with(StairsBlock.FACING, Direction.EAST).with(StairsBlock.WATERLOGGED, false).with(StairsBlock.SHAPE, StairsShape.STRAIGHT).with(StairsBlock.HALF, Half.TOP), -192, 7, -54, start);
        structure.setBlockState(world, Blocks.COBBLESTONE_SLAB.getDefaultState().with(SlabBlock.TYPE, SlabType.TOP).with(SlabBlock.WATERLOGGED, false), -192, 7, -53, start);
        structure.setBlockState(world, Blocks.COBBLESTONE_SLAB.getDefaultState().with(SlabBlock.TYPE, SlabType.TOP).with(SlabBlock.WATERLOGGED, false), -192, 7, -49, start);
        structure.setBlockState(world, Blocks.COBBLESTONE_STAIRS.getDefaultState().with(StairsBlock.FACING, Direction.EAST).with(StairsBlock.WATERLOGGED, false).with(StairsBlock.SHAPE, StairsShape.STRAIGHT).with(StairsBlock.HALF, Half.TOP), -192, 7, -48, start);
        structure.setBlockState(world, Blocks.OAK_FENCE.getDefaultState().with(FourWayBlock.WATERLOGGED, false).with(FourWayBlock.NORTH, false).with(FourWayBlock.SOUTH, false).with(FourWayBlock.EAST, true).with(FourWayBlock.WEST, false), -192, 8, -55, start);
        structure.setBlockState(world, Blocks.OAK_FENCE.getDefaultState().with(FourWayBlock.WATERLOGGED, false).with(FourWayBlock.NORTH, false).with(FourWayBlock.SOUTH, true).with(FourWayBlock.EAST, true).with(FourWayBlock.WEST, false), -192, 8, -53, start);
        structure.setBlockState(world, Blocks.OAK_FENCE.getDefaultState().with(FourWayBlock.WATERLOGGED, false).with(FourWayBlock.NORTH, false).with(FourWayBlock.SOUTH, false).with(FourWayBlock.EAST, true).with(FourWayBlock.WEST, false), -192, 8, -49, start);
        structure.setBlockState(world, Blocks.OAK_FENCE.getDefaultState().with(FourWayBlock.WATERLOGGED, false).with(FourWayBlock.NORTH, true).with(FourWayBlock.SOUTH, false).with(FourWayBlock.EAST, true).with(FourWayBlock.WEST, false), -192, 8, -47, start);
        structure.setBlockState(world, Blocks.STONE_BRICK_STAIRS.getDefaultState().with(StairsBlock.FACING, Direction.SOUTH).with(StairsBlock.WATERLOGGED, false).with(StairsBlock.SHAPE, StairsShape.STRAIGHT).with(StairsBlock.HALF, Half.TOP), -192, 12, -53, start);
        structure.setBlockState(world, Blocks.STONE_BRICK_STAIRS.getDefaultState().with(StairsBlock.FACING, Direction.NORTH).with(StairsBlock.WATERLOGGED, false).with(StairsBlock.SHAPE, StairsShape.STRAIGHT).with(StairsBlock.HALF, Half.TOP), -192, 12, -49, start);
        structure.setBlockState(world, Blocks.STONE_BRICK_STAIRS.getDefaultState().with(StairsBlock.FACING, Direction.EAST).with(StairsBlock.WATERLOGGED, false).with(StairsBlock.SHAPE, StairsShape.STRAIGHT).with(StairsBlock.HALF, Half.TOP), -192, 13, -53, start);
        structure.setBlockState(world, Blocks.STONE_BRICK_STAIRS.getDefaultState().with(StairsBlock.FACING, Direction.EAST).with(StairsBlock.WATERLOGGED, false).with(StairsBlock.SHAPE, StairsShape.STRAIGHT).with(StairsBlock.HALF, Half.TOP), -192, 13, -49, start);
        structure.setBlockState(world, Blocks.STONE_BRICK_SLAB.getDefaultState().with(SlabBlock.TYPE, SlabType.BOTTOM).with(SlabBlock.WATERLOGGED, false), -192, 14, -53, start);
        structure.setBlockState(world, Blocks.STONE_BRICK_SLAB.getDefaultState().with(SlabBlock.TYPE, SlabType.BOTTOM).with(SlabBlock.WATERLOGGED, false), -192, 14, -49, start);
        structure.setBlockState(world, Blocks.DIRT.getDefaultState(), -191, 4, -52, start);
        structure.setBlockState(world, Blocks.STONE_BRICKS.getDefaultState(), -191, 5, -47, start);
        structure.setBlockState(world, Blocks.COBBLESTONE_STAIRS.getDefaultState().with(StairsBlock.FACING, Direction.SOUTH).with(StairsBlock.WATERLOGGED, false).with(StairsBlock.SHAPE, StairsShape.STRAIGHT).with(StairsBlock.HALF, Half.BOTTOM), -191, 6, -55, start);
        structure.setBlockState(world, Blocks.COBBLESTONE_STAIRS.getDefaultState().with(StairsBlock.FACING, Direction.NORTH).with(StairsBlock.WATERLOGGED, false).with(StairsBlock.SHAPE, StairsShape.STRAIGHT).with(StairsBlock.HALF, Half.BOTTOM), -191, 6, -47, start);
        structure.setBlockState(world, Blocks.COBBLESTONE_STAIRS.getDefaultState().with(StairsBlock.FACING, Direction.SOUTH).with(StairsBlock.WATERLOGGED, false).with(StairsBlock.SHAPE, StairsShape.STRAIGHT).with(StairsBlock.HALF, Half.TOP), -191, 7, -55, start);
        structure.setBlockState(world, Blocks.COBBLESTONE_STAIRS.getDefaultState().with(StairsBlock.FACING, Direction.NORTH).with(StairsBlock.WATERLOGGED, false).with(StairsBlock.SHAPE, StairsShape.STRAIGHT).with(StairsBlock.HALF, Half.TOP), -191, 7, -47, start);
        structure.setBlockState(world, Blocks.STONE_BRICKS.getDefaultState(), -191, 8, -47, start);
        structure.setBlockState(world, Blocks.STONE_BRICK_STAIRS.getDefaultState().with(StairsBlock.FACING, Direction.SOUTH).with(StairsBlock.WATERLOGGED, false).with(StairsBlock.SHAPE, StairsShape.STRAIGHT).with(StairsBlock.HALF, Half.BOTTOM), -191, 9, -53, start);
        structure.setBlockState(world, Blocks.STONE_BRICK_STAIRS.getDefaultState().with(StairsBlock.FACING, Direction.NORTH).with(StairsBlock.WATERLOGGED, false).with(StairsBlock.SHAPE, StairsShape.STRAIGHT).with(StairsBlock.HALF, Half.BOTTOM), -191, 9, -49, start);
        structure.setBlockState(world, Blocks.STONE_BRICK_STAIRS.getDefaultState().with(StairsBlock.FACING, Direction.SOUTH).with(StairsBlock.WATERLOGGED, false).with(StairsBlock.SHAPE, StairsShape.STRAIGHT).with(StairsBlock.HALF, Half.TOP), -191, 10, -53, start);
        structure.setBlockState(world, Blocks.STONE_BRICK_STAIRS.getDefaultState().with(StairsBlock.FACING, Direction.NORTH).with(StairsBlock.WATERLOGGED, false).with(StairsBlock.SHAPE, StairsShape.STRAIGHT).with(StairsBlock.HALF, Half.TOP), -191, 10, -49, start);
        structure.setBlockState(world, Blocks.OAK_FENCE.getDefaultState().with(FourWayBlock.WATERLOGGED, false).with(FourWayBlock.NORTH, false).with(FourWayBlock.SOUTH, false).with(FourWayBlock.EAST, false).with(FourWayBlock.WEST, false), -191, 13, -54, start);
        structure.setBlockState(world, Blocks.OAK_FENCE.getDefaultState().with(FourWayBlock.WATERLOGGED, false).with(FourWayBlock.NORTH, true).with(FourWayBlock.SOUTH, false).with(FourWayBlock.EAST, true).with(FourWayBlock.WEST, false), -191, 13, -48, start);
        structure.setBlockState(world, Blocks.WALL_TORCH.getDefaultState().with(WallTorchBlock.HORIZONTAL_FACING, Direction.WEST), -191, 15, -53, start);
        structure.setBlockState(world, Blocks.WALL_TORCH.getDefaultState().with(WallTorchBlock.HORIZONTAL_FACING, Direction.WEST), -191, 15, -49, start);
        structure.setBlockState(world, Blocks.STONE_BRICK_STAIRS.getDefaultState().with(StairsBlock.FACING, Direction.EAST).with(StairsBlock.WATERLOGGED, false).with(StairsBlock.SHAPE, StairsShape.STRAIGHT).with(StairsBlock.HALF, Half.TOP), -191, 16, -51, start);
        structure.setBlockState(world, Blocks.STONE_BRICK_STAIRS.getDefaultState().with(StairsBlock.FACING, Direction.SOUTH).with(StairsBlock.WATERLOGGED, false).with(StairsBlock.SHAPE, StairsShape.STRAIGHT).with(StairsBlock.HALF, Half.TOP), -191, 17, -52, start);
        structure.setBlockState(world, Blocks.STONE_BRICK_STAIRS.getDefaultState().with(StairsBlock.FACING, Direction.NORTH).with(StairsBlock.WATERLOGGED, false).with(StairsBlock.SHAPE, StairsShape.STRAIGHT).with(StairsBlock.HALF, Half.TOP), -191, 17, -50, start);
        structure.setBlockState(world, Blocks.STONE_BUTTON.getDefaultState().with(HorizontalBlock.HORIZONTAL_FACING, Direction.WEST).with(HorizontalFaceBlock.FACE, AttachFace.WALL).with(AbstractButtonBlock.POWERED, false), -191, 20, -52, start);
        structure.setBlockState(world, Blocks.STONE_BRICK_STAIRS.getDefaultState().with(StairsBlock.FACING, Direction.EAST).with(StairsBlock.WATERLOGGED, false).with(StairsBlock.SHAPE, StairsShape.STRAIGHT).with(StairsBlock.HALF, Half.BOTTOM), -191, 20, -51, start);
        structure.setBlockState(world, Blocks.STONE_BUTTON.getDefaultState().with(HorizontalBlock.HORIZONTAL_FACING, Direction.WEST).with(HorizontalFaceBlock.FACE, AttachFace.WALL).with(AbstractButtonBlock.POWERED, false), -191, 20, -50, start);
        structure.setBlockState(world, Blocks.STONE_BRICK_STAIRS.getDefaultState().with(StairsBlock.FACING, Direction.EAST).with(StairsBlock.WATERLOGGED, false).with(StairsBlock.SHAPE, StairsShape.STRAIGHT).with(StairsBlock.HALF, Half.TOP), -191, 25, -51, start);
        structure.setBlockState(world, Blocks.STONE_BRICK_STAIRS.getDefaultState().with(StairsBlock.FACING, Direction.SOUTH).with(StairsBlock.WATERLOGGED, false).with(StairsBlock.SHAPE, StairsShape.STRAIGHT).with(StairsBlock.HALF, Half.TOP), -191, 26, -52, start);
        structure.setBlockState(world, Blocks.STONE_BRICKS.getDefaultState(), -191, 26, -51, start);
        structure.setBlockState(world, Blocks.STONE_BRICK_STAIRS.getDefaultState().with(StairsBlock.FACING, Direction.NORTH).with(StairsBlock.WATERLOGGED, false).with(StairsBlock.SHAPE, StairsShape.STRAIGHT).with(StairsBlock.HALF, Half.TOP), -191, 26, -50, start);
        structure.setBlockState(world, Blocks.STONE_BRICK_SLAB.getDefaultState().with(SlabBlock.TYPE, SlabType.BOTTOM).with(SlabBlock.WATERLOGGED, false), -191, 27, -52, start);
        structure.setBlockState(world, Blocks.STONE_BRICK_SLAB.getDefaultState().with(SlabBlock.TYPE, SlabType.BOTTOM).with(SlabBlock.WATERLOGGED, false), -191, 27, -50, start);
        structure.setBlockState(world, Blocks.OAK_SLAB.getDefaultState().with(SlabBlock.TYPE, SlabType.BOTTOM).with(SlabBlock.WATERLOGGED, false), -191, 29, -53, start);
        structure.setBlockState(world, Blocks.DIRT.getDefaultState(), -190, 3, -52, start);
        structure.setBlockState(world, Blocks.STONE_BRICK_STAIRS.getDefaultState().with(StairsBlock.FACING, Direction.SOUTH).with(StairsBlock.WATERLOGGED, false).with(StairsBlock.SHAPE, StairsShape.STRAIGHT).with(StairsBlock.HALF, Half.BOTTOM), -190, 5, -55, start);
        structure.setBlockState(world, Blocks.WALL_TORCH.getDefaultState().with(WallTorchBlock.HORIZONTAL_FACING, Direction.EAST), -190, 6, -49, start);
        structure.setBlockState(world, Blocks.COBBLESTONE_SLAB.getDefaultState().with(SlabBlock.TYPE, SlabType.TOP).with(SlabBlock.WATERLOGGED, false), -190, 7, -55, start);
        structure.setBlockState(world, Blocks.COBBLESTONE_SLAB.getDefaultState().with(SlabBlock.TYPE, SlabType.TOP).with(SlabBlock.WATERLOGGED, false), -190, 7, -47, start);
        structure.setBlockState(world, Blocks.OAK_FENCE.getDefaultState().with(FourWayBlock.WATERLOGGED, false).with(FourWayBlock.NORTH, false).with(FourWayBlock.SOUTH, false).with(FourWayBlock.EAST, false).with(FourWayBlock.WEST, true), -190, 8, -55, start);
        structure.setBlockState(world, Blocks.OAK_FENCE.getDefaultState().with(FourWayBlock.WATERLOGGED, false).with(FourWayBlock.NORTH, false).with(FourWayBlock.SOUTH, false).with(FourWayBlock.EAST, false).with(FourWayBlock.WEST, true), -190, 8, -47, start);
        structure.setBlockState(world, Blocks.STONE_BRICK_STAIRS.getDefaultState().with(StairsBlock.FACING, Direction.EAST).with(StairsBlock.WATERLOGGED, false).with(StairsBlock.SHAPE, StairsShape.STRAIGHT).with(StairsBlock.HALF, Half.BOTTOM), -190, 9, -54, start);
        structure.setBlockState(world, Blocks.STONE_BRICK_STAIRS.getDefaultState().with(StairsBlock.FACING, Direction.EAST).with(StairsBlock.WATERLOGGED, false).with(StairsBlock.SHAPE, StairsShape.STRAIGHT).with(StairsBlock.HALF, Half.BOTTOM), -190, 9, -48, start);
        structure.setBlockState(world, Blocks.STONE_BRICK_STAIRS.getDefaultState().with(StairsBlock.FACING, Direction.EAST).with(StairsBlock.WATERLOGGED, false).with(StairsBlock.SHAPE, StairsShape.STRAIGHT).with(StairsBlock.HALF, Half.TOP), -190, 10, -54, start);
        structure.setBlockState(world, Blocks.WALL_TORCH.getDefaultState().with(WallTorchBlock.HORIZONTAL_FACING, Direction.EAST), -190, 10, -51, start);
        structure.setBlockState(world, Blocks.STONE_BRICK_STAIRS.getDefaultState().with(StairsBlock.FACING, Direction.EAST).with(StairsBlock.WATERLOGGED, false).with(StairsBlock.SHAPE, StairsShape.STRAIGHT).with(StairsBlock.HALF, Half.TOP), -190, 10, -48, start);
        structure.setBlockState(world, Blocks.STONE_BRICK_STAIRS.getDefaultState().with(StairsBlock.FACING, Direction.EAST).with(StairsBlock.WATERLOGGED, false).with(StairsBlock.SHAPE, StairsShape.STRAIGHT).with(StairsBlock.HALF, Half.TOP), -190, 12, -55, start);
        structure.setBlockState(world, Blocks.STONE_BRICK_STAIRS.getDefaultState().with(StairsBlock.FACING, Direction.EAST).with(StairsBlock.WATERLOGGED, false).with(StairsBlock.SHAPE, StairsShape.STRAIGHT).with(StairsBlock.HALF, Half.TOP), -190, 12, -47, start);
        structure.setBlockState(world, Blocks.STONE_BRICK_STAIRS.getDefaultState().with(StairsBlock.FACING, Direction.SOUTH).with(StairsBlock.WATERLOGGED, false).with(StairsBlock.SHAPE, StairsShape.STRAIGHT).with(StairsBlock.HALF, Half.TOP), -190, 13, -55, start);
        structure.setBlockState(world, Blocks.STONE_BRICK_STAIRS.getDefaultState().with(StairsBlock.FACING, Direction.NORTH).with(StairsBlock.WATERLOGGED, false).with(StairsBlock.SHAPE, StairsShape.STRAIGHT).with(StairsBlock.HALF, Half.TOP), -190, 13, -47, start);
        structure.setBlockState(world, Blocks.STONE_BRICK_SLAB.getDefaultState().with(SlabBlock.TYPE, SlabType.BOTTOM).with(SlabBlock.WATERLOGGED, false), -190, 14, -55, start);
        structure.setBlockState(world, Blocks.STONE_BRICK_SLAB.getDefaultState().with(SlabBlock.TYPE, SlabType.BOTTOM).with(SlabBlock.WATERLOGGED, false), -190, 14, -47, start);
        structure.setBlockState(world, Blocks.WALL_TORCH.getDefaultState().with(WallTorchBlock.HORIZONTAL_FACING, Direction.NORTH), -190, 15, -54, start);
        structure.setBlockState(world, Blocks.WALL_TORCH.getDefaultState().with(WallTorchBlock.HORIZONTAL_FACING, Direction.SOUTH), -190, 15, -48, start);
        structure.setBlockState(world, Blocks.COBBLESTONE_WALL.getDefaultState().with(WallBlock.WATERLOGGED, false).with(WallBlock.UP, true).with(WallBlock.WALL_HEIGHT_NORTH, WallHeight.LOW).with(WallBlock.WALL_HEIGHT_SOUTH, WallHeight.LOW).with(WallBlock.WALL_HEIGHT_EAST, WallHeight.LOW).with(WallBlock.WALL_HEIGHT_WEST, WallHeight.LOW), -190, 17, -53, start);
        structure.setBlockState(world, Blocks.COBBLESTONE_WALL.getDefaultState().with(WallBlock.WATERLOGGED, false).with(WallBlock.UP, true).with(WallBlock.WALL_HEIGHT_NORTH, WallHeight.LOW).with(WallBlock.WALL_HEIGHT_SOUTH, WallHeight.LOW).with(WallBlock.WALL_HEIGHT_EAST, WallHeight.LOW).with(WallBlock.WALL_HEIGHT_WEST, WallHeight.LOW), -190, 17, -49, start);
        structure.setBlockState(world, Blocks.STONE_BRICK_SLAB.getDefaultState().with(SlabBlock.TYPE, SlabType.BOTTOM).with(SlabBlock.WATERLOGGED, false), -190, 18, -53, start);
        structure.setBlockState(world, Blocks.STONE_BRICK_SLAB.getDefaultState().with(SlabBlock.TYPE, SlabType.BOTTOM).with(SlabBlock.WATERLOGGED, false), -190, 18, -49, start);
        structure.setBlockState(world, Blocks.OAK_LOG.getDefaultState(), -190, 20, -52, start);
        structure.setBlockState(world, Blocks.OAK_LOG.getDefaultState(), -190, 20, -50, start);
        structure.setBlockState(world, Blocks.OAK_FENCE.getDefaultState().with(FourWayBlock.WATERLOGGED, false).with(FourWayBlock.NORTH, false).with(FourWayBlock.SOUTH, false).with(FourWayBlock.EAST, true).with(FourWayBlock.WEST, false), -190, 21, -52, start);
        structure.setBlockState(world, Blocks.STONE_BRICK_STAIRS.getDefaultState().with(StairsBlock.FACING, Direction.EAST).with(StairsBlock.WATERLOGGED, false).with(StairsBlock.SHAPE, StairsShape.STRAIGHT).with(StairsBlock.HALF, Half.BOTTOM), -190, 21, -51, start);
        structure.setBlockState(world, Blocks.OAK_FENCE.getDefaultState().with(FourWayBlock.WATERLOGGED, false).with(FourWayBlock.NORTH, false).with(FourWayBlock.SOUTH, false).with(FourWayBlock.EAST, true).with(FourWayBlock.WEST, false), -190, 21, -50, start);
        structure.setBlockState(world, Blocks.WALL_TORCH.getDefaultState().with(WallTorchBlock.HORIZONTAL_FACING, Direction.WEST), -190, 22, -51, start);
        structure.setBlockState(world, Blocks.COBBLESTONE_STAIRS.getDefaultState().with(StairsBlock.FACING, Direction.EAST).with(StairsBlock.WATERLOGGED, false).with(StairsBlock.SHAPE, StairsShape.STRAIGHT).with(StairsBlock.HALF, Half.TOP), -190, 24, -51, start);
        structure.setBlockState(world, Blocks.OAK_SLAB.getDefaultState().with(SlabBlock.TYPE, SlabType.TOP).with(SlabBlock.WATERLOGGED, false), -190, 25, -52, start);
        structure.setBlockState(world, Blocks.STONE_BRICKS.getDefaultState(), -190, 27, -53, start);
        structure.setBlockState(world, Blocks.STONE_BRICKS.getDefaultState(), -190, 27, -49, start);
        structure.setBlockState(world, Blocks.COBBLESTONE_WALL.getDefaultState().with(WallBlock.WATERLOGGED, false).with(WallBlock.UP, true).with(WallBlock.WALL_HEIGHT_NORTH, WallHeight.LOW).with(WallBlock.WALL_HEIGHT_SOUTH, WallHeight.LOW).with(WallBlock.WALL_HEIGHT_EAST, WallHeight.LOW).with(WallBlock.WALL_HEIGHT_WEST, WallHeight.LOW), -190, 28, -53, start);
        structure.setBlockState(world, Blocks.COBBLESTONE_WALL.getDefaultState().with(WallBlock.WATERLOGGED, false).with(WallBlock.UP, true).with(WallBlock.WALL_HEIGHT_NORTH, WallHeight.LOW).with(WallBlock.WALL_HEIGHT_SOUTH, WallHeight.LOW).with(WallBlock.WALL_HEIGHT_EAST, WallHeight.LOW).with(WallBlock.WALL_HEIGHT_WEST, WallHeight.LOW), -190, 28, -49, start);
        structure.setBlockState(world, Blocks.OAK_SLAB.getDefaultState().with(SlabBlock.TYPE, SlabType.BOTTOM).with(SlabBlock.WATERLOGGED, false), -190, 29, -54, start);
        structure.setBlockState(world, Blocks.OAK_PLANKS.getDefaultState(), -190, 29, -53, start);
        structure.setBlockState(world, Blocks.OAK_PLANKS.getDefaultState(), -190, 29, -49, start);
        structure.setBlockState(world, Blocks.OAK_SLAB.getDefaultState().with(SlabBlock.TYPE, SlabType.BOTTOM).with(SlabBlock.WATERLOGGED, false), -190, 29, -48, start);
        structure.setBlockState(world, Blocks.OAK_STAIRS.getDefaultState().with(StairsBlock.FACING, Direction.EAST).with(StairsBlock.WATERLOGGED, false).with(StairsBlock.SHAPE, StairsShape.STRAIGHT).with(StairsBlock.HALF, Half.BOTTOM), -190, 30, -52, start);
        structure.setBlockState(world, Blocks.OAK_STAIRS.getDefaultState().with(StairsBlock.FACING, Direction.EAST).with(StairsBlock.WATERLOGGED, false).with(StairsBlock.SHAPE, StairsShape.STRAIGHT).with(StairsBlock.HALF, Half.BOTTOM), -190, 30, -50, start);
        structure.setBlockState(world, Blocks.GRASS_BLOCK.getDefaultState().with(SnowyDirtBlock.SNOWY, false), -189, 4, -57, start);
        structure.setBlockState(world, Blocks.GRASS_BLOCK.getDefaultState().with(SnowyDirtBlock.SNOWY, false), -189, 4, -45, start);
        structure.setBlockState(world, Blocks.STONE_BRICK_STAIRS.getDefaultState().with(StairsBlock.FACING, Direction.SOUTH).with(StairsBlock.WATERLOGGED, false).with(StairsBlock.SHAPE, StairsShape.STRAIGHT).with(StairsBlock.HALF, Half.BOTTOM), -189, 5, -56, start);
        structure.setBlockState(world, Blocks.STONE_BRICK_STAIRS.getDefaultState().with(StairsBlock.FACING, Direction.NORTH).with(StairsBlock.WATERLOGGED, false).with(StairsBlock.SHAPE, StairsShape.STRAIGHT).with(StairsBlock.HALF, Half.BOTTOM), -189, 5, -46, start);
        structure.setBlockState(world, Blocks.STONE_BRICK_STAIRS.getDefaultState().with(StairsBlock.FACING, Direction.SOUTH).with(StairsBlock.WATERLOGGED, false).with(StairsBlock.SHAPE, StairsShape.STRAIGHT).with(StairsBlock.HALF, Half.TOP), -189, 12, -56, start);
        structure.setBlockState(world, Blocks.STONE_BRICKS.getDefaultState(), -189, 12, -55, start);
        structure.setBlockState(world, Blocks.STONE_BRICKS.getDefaultState(), -189, 12, -47, start);
        structure.setBlockState(world, Blocks.STONE_BRICK_STAIRS.getDefaultState().with(StairsBlock.FACING, Direction.NORTH).with(StairsBlock.WATERLOGGED, false).with(StairsBlock.SHAPE, StairsShape.STRAIGHT).with(StairsBlock.HALF, Half.TOP), -189, 12, -46, start);
        structure.setBlockState(world, Blocks.STONE_BRICK_STAIRS.getDefaultState().with(StairsBlock.FACING, Direction.EAST).with(StairsBlock.WATERLOGGED, false).with(StairsBlock.SHAPE, StairsShape.STRAIGHT).with(StairsBlock.HALF, Half.TOP), -189, 13, -56, start);
        structure.setBlockState(world, Blocks.STONE_BRICK_STAIRS.getDefaultState().with(StairsBlock.FACING, Direction.EAST).with(StairsBlock.WATERLOGGED, false).with(StairsBlock.SHAPE, StairsShape.STRAIGHT).with(StairsBlock.HALF, Half.TOP), -189, 13, -46, start);
        structure.setBlockState(world, Blocks.STONE_BRICKS.getDefaultState(), -189, 14, -56, start);
        structure.setBlockState(world, Blocks.STONE_BRICKS.getDefaultState(), -189, 14, -46, start);
        structure.setBlockState(world, Blocks.STONE_BRICK_STAIRS.getDefaultState().with(StairsBlock.FACING, Direction.EAST).with(StairsBlock.WATERLOGGED, false).with(StairsBlock.SHAPE, StairsShape.STRAIGHT).with(StairsBlock.HALF, Half.TOP), -189, 17, -54, start);
        structure.setBlockState(world, Blocks.STONE_BRICK_STAIRS.getDefaultState().with(StairsBlock.FACING, Direction.EAST).with(StairsBlock.WATERLOGGED, false).with(StairsBlock.SHAPE, StairsShape.STRAIGHT).with(StairsBlock.HALF, Half.TOP), -189, 17, -48, start);
        structure.setBlockState(world, Blocks.STONE_BUTTON.getDefaultState().with(HorizontalBlock.HORIZONTAL_FACING, Direction.NORTH).with(HorizontalFaceBlock.FACE, AttachFace.WALL).with(AbstractButtonBlock.POWERED, false), -189, 20, -54, start);
        structure.setBlockState(world, Blocks.OAK_LOG.getDefaultState(), -189, 20, -53, start);
        structure.setBlockState(world, Blocks.OAK_LOG.getDefaultState(), -189, 20, -49, start);
        structure.setBlockState(world, Blocks.STONE_BUTTON.getDefaultState().with(HorizontalBlock.HORIZONTAL_FACING, Direction.SOUTH).with(HorizontalFaceBlock.FACE, AttachFace.WALL).with(AbstractButtonBlock.POWERED, false), -189, 20, -48, start);
        structure.setBlockState(world, Blocks.OAK_FENCE.getDefaultState().with(FourWayBlock.WATERLOGGED, false).with(FourWayBlock.NORTH, false).with(FourWayBlock.SOUTH, false).with(FourWayBlock.EAST, false).with(FourWayBlock.WEST, false), -189, 21, -53, start);
        structure.setBlockState(world, Blocks.OAK_FENCE.getDefaultState().with(FourWayBlock.WATERLOGGED, false).with(FourWayBlock.NORTH, false).with(FourWayBlock.SOUTH, false).with(FourWayBlock.EAST, false).with(FourWayBlock.WEST, false), -189, 21, -49, start);
        structure.setBlockState(world, Blocks.OAK_SLAB.getDefaultState().with(SlabBlock.TYPE, SlabType.TOP).with(SlabBlock.WATERLOGGED, false), -189, 25, -53, start);
        structure.setBlockState(world, Blocks.OAK_SLAB.getDefaultState().with(SlabBlock.TYPE, SlabType.TOP).with(SlabBlock.WATERLOGGED, false), -189, 25, -49, start);
        structure.setBlockState(world, Blocks.STONE_BRICK_STAIRS.getDefaultState().with(StairsBlock.FACING, Direction.EAST).with(StairsBlock.WATERLOGGED, false).with(StairsBlock.SHAPE, StairsShape.STRAIGHT).with(StairsBlock.HALF, Half.TOP), -189, 26, -54, start);
        structure.setBlockState(world, Blocks.STONE_BRICK_STAIRS.getDefaultState().with(StairsBlock.FACING, Direction.EAST).with(StairsBlock.WATERLOGGED, false).with(StairsBlock.SHAPE, StairsShape.STRAIGHT).with(StairsBlock.HALF, Half.TOP), -189, 26, -48, start);
        structure.setBlockState(world, Blocks.STONE_BRICK_SLAB.getDefaultState().with(SlabBlock.TYPE, SlabType.BOTTOM).with(SlabBlock.WATERLOGGED, false), -189, 27, -54, start);
        structure.setBlockState(world, Blocks.STONE_BRICK_SLAB.getDefaultState().with(SlabBlock.TYPE, SlabType.BOTTOM).with(SlabBlock.WATERLOGGED, false), -189, 27, -48, start);
        structure.setBlockState(world, Blocks.OAK_STAIRS.getDefaultState().with(StairsBlock.FACING, Direction.SOUTH).with(StairsBlock.WATERLOGGED, false).with(StairsBlock.SHAPE, StairsShape.STRAIGHT).with(StairsBlock.HALF, Half.BOTTOM), -189, 30, -53, start);
        structure.setBlockState(world, Blocks.OAK_PLANKS.getDefaultState(), -189, 30, -52, start);
        structure.setBlockState(world, Blocks.OAK_STAIRS.getDefaultState().with(StairsBlock.FACING, Direction.NORTH).with(StairsBlock.WATERLOGGED, false).with(StairsBlock.SHAPE, StairsShape.STRAIGHT).with(StairsBlock.HALF, Half.BOTTOM), -189, 30, -49, start);
        structure.setBlockState(world, Blocks.OAK_SLAB.getDefaultState().with(SlabBlock.TYPE, SlabType.BOTTOM).with(SlabBlock.WATERLOGGED, false), -189, 31, -52, start);
        structure.setBlockState(world, Blocks.OAK_SLAB.getDefaultState().with(SlabBlock.TYPE, SlabType.BOTTOM).with(SlabBlock.WATERLOGGED, false), -189, 31, -50, start);
        structure.setBlockState(world, Blocks.OAK_STAIRS.getDefaultState().with(StairsBlock.FACING, Direction.EAST).with(StairsBlock.WATERLOGGED, false).with(StairsBlock.SHAPE, StairsShape.STRAIGHT).with(StairsBlock.HALF, Half.BOTTOM), -189, 32, -51, start);
        structure.setBlockState(world, Blocks.AIR.getDefaultState(), -188, 4, -51, start);
        structure.setBlockState(world, Blocks.DIRT.getDefaultState(), -188, 4, -45, start);
        structure.setBlockState(world, Blocks.COBBLESTONE_STAIRS.getDefaultState().with(StairsBlock.FACING, Direction.SOUTH).with(StairsBlock.WATERLOGGED, false).with(StairsBlock.SHAPE, StairsShape.STRAIGHT).with(StairsBlock.HALF, Half.BOTTOM), -188, 5, -57, start);
        structure.setBlockState(world, Blocks.COBBLESTONE_STAIRS.getDefaultState().with(StairsBlock.FACING, Direction.NORTH).with(StairsBlock.WATERLOGGED, false).with(StairsBlock.SHAPE, StairsShape.STRAIGHT).with(StairsBlock.HALF, Half.BOTTOM), -188, 5, -45, start);
        structure.setBlockState(world, Blocks.COBBLESTONE_STAIRS.getDefaultState().with(StairsBlock.FACING, Direction.SOUTH).with(StairsBlock.WATERLOGGED, false).with(StairsBlock.SHAPE, StairsShape.STRAIGHT).with(StairsBlock.HALF, Half.BOTTOM), -188, 8, -56, start);
        structure.setBlockState(world, Blocks.COBBLESTONE_STAIRS.getDefaultState().with(StairsBlock.FACING, Direction.NORTH).with(StairsBlock.WATERLOGGED, false).with(StairsBlock.SHAPE, StairsShape.STRAIGHT).with(StairsBlock.HALF, Half.BOTTOM), -188, 8, -46, start);
        structure.setBlockState(world, Blocks.COBBLESTONE_STAIRS.getDefaultState().with(StairsBlock.FACING, Direction.SOUTH).with(StairsBlock.WATERLOGGED, false).with(StairsBlock.SHAPE, StairsShape.STRAIGHT).with(StairsBlock.HALF, Half.TOP), -188, 12, -56, start);
        structure.setBlockState(world, Blocks.COBBLESTONE_STAIRS.getDefaultState().with(StairsBlock.FACING, Direction.NORTH).with(StairsBlock.WATERLOGGED, false).with(StairsBlock.SHAPE, StairsShape.STRAIGHT).with(StairsBlock.HALF, Half.TOP), -188, 12, -46, start);
        structure.setBlockState(world, Blocks.COBBLESTONE_WALL.getDefaultState().with(WallBlock.WATERLOGGED, false).with(WallBlock.UP, false).with(WallBlock.WALL_HEIGHT_NORTH, WallHeight.LOW).with(WallBlock.WALL_HEIGHT_SOUTH, WallHeight.LOW).with(WallBlock.WALL_HEIGHT_EAST, WallHeight.LOW).with(WallBlock.WALL_HEIGHT_WEST, WallHeight.LOW), -188, 13, -56, start);
        structure.setBlockState(world, Blocks.COBBLESTONE_WALL.getDefaultState().with(WallBlock.WATERLOGGED, false).with(WallBlock.UP, true).with(WallBlock.WALL_HEIGHT_NORTH, WallHeight.LOW).with(WallBlock.WALL_HEIGHT_SOUTH, WallHeight.LOW).with(WallBlock.WALL_HEIGHT_EAST, WallHeight.LOW).with(WallBlock.WALL_HEIGHT_WEST, WallHeight.LOW), -188, 13, -46, start);
        structure.setBlockState(world, Blocks.STONE_BRICK_SLAB.getDefaultState().with(SlabBlock.TYPE, SlabType.BOTTOM).with(SlabBlock.WATERLOGGED, false), -188, 14, -56, start);
        structure.setBlockState(world, Blocks.STONE_BRICK_SLAB.getDefaultState().with(SlabBlock.TYPE, SlabType.BOTTOM).with(SlabBlock.WATERLOGGED, false), -188, 14, -46, start);
        structure.setBlockState(world, Blocks.STONE_BRICK_STAIRS.getDefaultState().with(StairsBlock.FACING, Direction.SOUTH).with(StairsBlock.WATERLOGGED, false).with(StairsBlock.SHAPE, StairsShape.STRAIGHT).with(StairsBlock.HALF, Half.TOP), -188, 16, -54, start);
        structure.setBlockState(world, Blocks.STONE_BRICK_STAIRS.getDefaultState().with(StairsBlock.FACING, Direction.NORTH).with(StairsBlock.WATERLOGGED, false).with(StairsBlock.SHAPE, StairsShape.STRAIGHT).with(StairsBlock.HALF, Half.TOP), -188, 16, -48, start);
        structure.setBlockState(world, Blocks.STONE_BRICK_STAIRS.getDefaultState().with(StairsBlock.FACING, Direction.SOUTH).with(StairsBlock.WATERLOGGED, false).with(StairsBlock.SHAPE, StairsShape.STRAIGHT).with(StairsBlock.HALF, Half.BOTTOM), -188, 20, -54, start);
        structure.setBlockState(world, Blocks.STONE_BRICK_STAIRS.getDefaultState().with(StairsBlock.FACING, Direction.NORTH).with(StairsBlock.WATERLOGGED, false).with(StairsBlock.SHAPE, StairsShape.STRAIGHT).with(StairsBlock.HALF, Half.BOTTOM), -188, 20, -48, start);
        structure.setBlockState(world, Blocks.STONE_BRICK_STAIRS.getDefaultState().with(StairsBlock.FACING, Direction.SOUTH).with(StairsBlock.WATERLOGGED, false).with(StairsBlock.SHAPE, StairsShape.STRAIGHT).with(StairsBlock.HALF, Half.BOTTOM), -188, 21, -53, start);
        structure.setBlockState(world, Blocks.STONE_BRICK_STAIRS.getDefaultState().with(StairsBlock.FACING, Direction.NORTH).with(StairsBlock.WATERLOGGED, false).with(StairsBlock.SHAPE, StairsShape.STRAIGHT).with(StairsBlock.HALF, Half.BOTTOM), -188, 21, -49, start);
        structure.setBlockState(world, Blocks.WALL_TORCH.getDefaultState().with(WallTorchBlock.HORIZONTAL_FACING, Direction.NORTH), -188, 22, -53, start);
        structure.setBlockState(world, Blocks.WALL_TORCH.getDefaultState().with(WallTorchBlock.HORIZONTAL_FACING, Direction.SOUTH), -188, 22, -49, start);
        structure.setBlockState(world, Blocks.COBBLESTONE_STAIRS.getDefaultState().with(StairsBlock.FACING, Direction.SOUTH).with(StairsBlock.WATERLOGGED, false).with(StairsBlock.SHAPE, StairsShape.STRAIGHT).with(StairsBlock.HALF, Half.TOP), -188, 24, -53, start);
        structure.setBlockState(world, Blocks.COBBLESTONE_STAIRS.getDefaultState().with(StairsBlock.FACING, Direction.NORTH).with(StairsBlock.WATERLOGGED, false).with(StairsBlock.SHAPE, StairsShape.STRAIGHT).with(StairsBlock.HALF, Half.TOP), -188, 24, -49, start);
        structure.setBlockState(world, Blocks.STONE_BRICK_STAIRS.getDefaultState().with(StairsBlock.FACING, Direction.SOUTH).with(StairsBlock.WATERLOGGED, false).with(StairsBlock.SHAPE, StairsShape.STRAIGHT).with(StairsBlock.HALF, Half.TOP), -188, 25, -54, start);
        structure.setBlockState(world, Blocks.STONE_BRICKS.getDefaultState(), -188, 25, -49, start);
        structure.setBlockState(world, Blocks.STONE_BRICK_STAIRS.getDefaultState().with(StairsBlock.FACING, Direction.NORTH).with(StairsBlock.WATERLOGGED, false).with(StairsBlock.SHAPE, StairsShape.STRAIGHT).with(StairsBlock.HALF, Half.TOP), -188, 25, -48, start);
        structure.setBlockState(world, Blocks.STONE_BRICKS.getDefaultState(), -188, 26, -54, start);
        structure.setBlockState(world, Blocks.STONE_BRICKS.getDefaultState(), -188, 26, -48, start);
        structure.setBlockState(world, Blocks.WALL_TORCH.getDefaultState().with(WallTorchBlock.HORIZONTAL_FACING, Direction.EAST), -188, 31, -51, start);
        structure.setBlockState(world, Blocks.OAK_PLANKS.getDefaultState(), -188, 31, -50, start);
        structure.setBlockState(world, Blocks.OAK_STAIRS.getDefaultState().with(StairsBlock.FACING, Direction.SOUTH).with(StairsBlock.WATERLOGGED, false).with(StairsBlock.SHAPE, StairsShape.STRAIGHT).with(StairsBlock.HALF, Half.BOTTOM), -188, 32, -52, start);
        structure.setBlockState(world, Blocks.OAK_STAIRS.getDefaultState().with(StairsBlock.FACING, Direction.NORTH).with(StairsBlock.WATERLOGGED, false).with(StairsBlock.SHAPE, StairsShape.STRAIGHT).with(StairsBlock.HALF, Half.BOTTOM), -188, 32, -50, start);
        structure.setBlockState(world, Blocks.OAK_FENCE.getDefaultState().with(FourWayBlock.WATERLOGGED, false).with(FourWayBlock.NORTH, false).with(FourWayBlock.SOUTH, false).with(FourWayBlock.EAST, false).with(FourWayBlock.WEST, false), -188, 34, -51, start);
        structure.setBlockState(world, Blocks.OAK_PLANKS.getDefaultState(), -188, 37, -51, start);
        structure.setBlockState(world, Blocks.OAK_SLAB.getDefaultState().with(SlabBlock.TYPE, SlabType.BOTTOM).with(SlabBlock.WATERLOGGED, false), -188, 37, -50, start);
        structure.setBlockState(world, Blocks.TORCH.getDefaultState(), -188, 38, -51, start);
        structure.setBlockState(world, Blocks.STONE_BRICK_STAIRS.getDefaultState().with(StairsBlock.FACING, Direction.NORTH).with(StairsBlock.WATERLOGGED, false).with(StairsBlock.SHAPE, StairsShape.STRAIGHT).with(StairsBlock.HALF, Half.BOTTOM), -187, 5, -46, start);
        structure.setBlockState(world, Blocks.STONE_BRICK_STAIRS.getDefaultState().with(StairsBlock.FACING, Direction.SOUTH).with(StairsBlock.WATERLOGGED, false).with(StairsBlock.SHAPE, StairsShape.STRAIGHT).with(StairsBlock.HALF, Half.TOP), -187, 12, -56, start);
        structure.setBlockState(world, Blocks.STONE_BRICKS.getDefaultState(), -187, 12, -47, start);
        structure.setBlockState(world, Blocks.STONE_BRICK_STAIRS.getDefaultState().with(StairsBlock.FACING, Direction.NORTH).with(StairsBlock.WATERLOGGED, false).with(StairsBlock.SHAPE, StairsShape.STRAIGHT).with(StairsBlock.HALF, Half.TOP), -187, 12, -46, start);
        structure.setBlockState(world, Blocks.STONE_BRICK_STAIRS.getDefaultState().with(StairsBlock.FACING, Direction.WEST).with(StairsBlock.WATERLOGGED, false).with(StairsBlock.SHAPE, StairsShape.STRAIGHT).with(StairsBlock.HALF, Half.TOP), -187, 13, -56, start);
        structure.setBlockState(world, Blocks.STONE_BRICK_STAIRS.getDefaultState().with(StairsBlock.FACING, Direction.WEST).with(StairsBlock.WATERLOGGED, false).with(StairsBlock.SHAPE, StairsShape.STRAIGHT).with(StairsBlock.HALF, Half.TOP), -187, 13, -46, start);
        structure.setBlockState(world, Blocks.STONE_BRICKS.getDefaultState(), -187, 14, -56, start);
        structure.setBlockState(world, Blocks.STONE_BRICKS.getDefaultState(), -187, 14, -46, start);
        structure.setBlockState(world, Blocks.WALL_TORCH.getDefaultState().with(WallTorchBlock.HORIZONTAL_FACING, Direction.WEST), -187, 15, -50, start);
        structure.setBlockState(world, Blocks.STONE_BRICK_STAIRS.getDefaultState().with(StairsBlock.FACING, Direction.WEST).with(StairsBlock.WATERLOGGED, false).with(StairsBlock.SHAPE, StairsShape.STRAIGHT).with(StairsBlock.HALF, Half.TOP), -187, 17, -54, start);
        structure.setBlockState(world, Blocks.AIR.getDefaultState(), -187, 17, -52, start);
        structure.setBlockState(world, Blocks.AIR.getDefaultState(), -187, 17, -50, start);
        structure.setBlockState(world, Blocks.STONE_BRICK_STAIRS.getDefaultState().with(StairsBlock.FACING, Direction.WEST).with(StairsBlock.WATERLOGGED, false).with(StairsBlock.SHAPE, StairsShape.STRAIGHT).with(StairsBlock.HALF, Half.TOP), -187, 17, -48, start);
        structure.setBlockState(world, Blocks.WALL_TORCH.getDefaultState().with(WallTorchBlock.HORIZONTAL_FACING, Direction.WEST), -187, 19, -52, start);
        structure.setBlockState(world, Blocks.WALL_TORCH.getDefaultState().with(WallTorchBlock.HORIZONTAL_FACING, Direction.WEST), -187, 19, -50, start);
        structure.setBlockState(world, Blocks.STONE_BUTTON.getDefaultState().with(HorizontalBlock.HORIZONTAL_FACING, Direction.NORTH).with(HorizontalFaceBlock.FACE, AttachFace.WALL).with(AbstractButtonBlock.POWERED, false), -187, 20, -54, start);
        structure.setBlockState(world, Blocks.OAK_LOG.getDefaultState(), -187, 20, -53, start);
        structure.setBlockState(world, Blocks.OAK_LOG.getDefaultState(), -187, 20, -49, start);
        structure.setBlockState(world, Blocks.STONE_BUTTON.getDefaultState().with(HorizontalBlock.HORIZONTAL_FACING, Direction.SOUTH).with(HorizontalFaceBlock.FACE, AttachFace.WALL).with(AbstractButtonBlock.POWERED, false), -187, 20, -48, start);
        structure.setBlockState(world, Blocks.OAK_FENCE.getDefaultState().with(FourWayBlock.WATERLOGGED, false).with(FourWayBlock.NORTH, false).with(FourWayBlock.SOUTH, true).with(FourWayBlock.EAST, false).with(FourWayBlock.WEST, false), -187, 21, -53, start);
        structure.setBlockState(world, Blocks.OAK_FENCE.getDefaultState().with(FourWayBlock.WATERLOGGED, false).with(FourWayBlock.NORTH, true).with(FourWayBlock.SOUTH, false).with(FourWayBlock.EAST, false).with(FourWayBlock.WEST, false), -187, 21, -49, start);
        structure.setBlockState(world, Blocks.OAK_SLAB.getDefaultState().with(SlabBlock.TYPE, SlabType.TOP).with(SlabBlock.WATERLOGGED, false), -187, 25, -49, start);
        structure.setBlockState(world, Blocks.STONE_BRICK_STAIRS.getDefaultState().with(StairsBlock.FACING, Direction.WEST).with(StairsBlock.WATERLOGGED, false).with(StairsBlock.SHAPE, StairsShape.STRAIGHT).with(StairsBlock.HALF, Half.TOP), -187, 26, -54, start);
        structure.setBlockState(world, Blocks.STONE_BRICK_STAIRS.getDefaultState().with(StairsBlock.FACING, Direction.WEST).with(StairsBlock.WATERLOGGED, false).with(StairsBlock.SHAPE, StairsShape.STRAIGHT).with(StairsBlock.HALF, Half.TOP), -187, 26, -48, start);
        structure.setBlockState(world, Blocks.STONE_BRICK_SLAB.getDefaultState().with(SlabBlock.TYPE, SlabType.BOTTOM).with(SlabBlock.WATERLOGGED, false), -187, 27, -54, start);
        structure.setBlockState(world, Blocks.STONE_BRICK_SLAB.getDefaultState().with(SlabBlock.TYPE, SlabType.BOTTOM).with(SlabBlock.WATERLOGGED, false), -187, 27, -48, start);
        structure.setBlockState(world, Blocks.OAK_STAIRS.getDefaultState().with(StairsBlock.FACING, Direction.SOUTH).with(StairsBlock.WATERLOGGED, false).with(StairsBlock.SHAPE, StairsShape.STRAIGHT).with(StairsBlock.HALF, Half.BOTTOM), -187, 30, -53, start);
        structure.setBlockState(world, Blocks.OAK_PLANKS.getDefaultState(), -187, 30, -50, start);
        structure.setBlockState(world, Blocks.OAK_STAIRS.getDefaultState().with(StairsBlock.FACING, Direction.NORTH).with(StairsBlock.WATERLOGGED, false).with(StairsBlock.SHAPE, StairsShape.STRAIGHT).with(StairsBlock.HALF, Half.BOTTOM), -187, 30, -49, start);
        structure.setBlockState(world, Blocks.OAK_SLAB.getDefaultState().with(SlabBlock.TYPE, SlabType.BOTTOM).with(SlabBlock.WATERLOGGED, false), -187, 31, -52, start);
        structure.setBlockState(world, Blocks.OAK_PLANKS.getDefaultState(), -187, 31, -51, start);
        structure.setBlockState(world, Blocks.OAK_SLAB.getDefaultState().with(SlabBlock.TYPE, SlabType.BOTTOM).with(SlabBlock.WATERLOGGED, false), -187, 31, -50, start);
        structure.setBlockState(world, Blocks.OAK_STAIRS.getDefaultState().with(StairsBlock.FACING, Direction.WEST).with(StairsBlock.WATERLOGGED, false).with(StairsBlock.SHAPE, StairsShape.STRAIGHT).with(StairsBlock.HALF, Half.BOTTOM), -187, 32, -51, start);
        structure.setBlockState(world, Blocks.OAK_SLAB.getDefaultState().with(SlabBlock.TYPE, SlabType.BOTTOM).with(SlabBlock.WATERLOGGED, false), -187, 37, -51, start);
        structure.setBlockState(world, Blocks.GRASS_BLOCK.getDefaultState().with(SnowyDirtBlock.SNOWY, false), -186, 3, -53, start);
        structure.setBlockState(world, Blocks.GRASS_BLOCK.getDefaultState().with(SnowyDirtBlock.SNOWY, false), -186, 3, -49, start);
        structure.setBlockState(world, Blocks.STONE_BRICK_STAIRS.getDefaultState().with(StairsBlock.FACING, Direction.SOUTH).with(StairsBlock.WATERLOGGED, false).with(StairsBlock.SHAPE, StairsShape.STRAIGHT).with(StairsBlock.HALF, Half.BOTTOM), -186, 5, -55, start);
        structure.setBlockState(world, Blocks.STONE_BRICK_STAIRS.getDefaultState().with(StairsBlock.FACING, Direction.NORTH).with(StairsBlock.WATERLOGGED, false).with(StairsBlock.SHAPE, StairsShape.STRAIGHT).with(StairsBlock.HALF, Half.BOTTOM), -186, 5, -47, start);
        structure.setBlockState(world, Blocks.WALL_TORCH.getDefaultState().with(WallTorchBlock.HORIZONTAL_FACING, Direction.WEST), -186, 6, -53, start);
        structure.setBlockState(world, Blocks.COBBLESTONE_SLAB.getDefaultState().with(SlabBlock.TYPE, SlabType.TOP).with(SlabBlock.WATERLOGGED, false), -186, 7, -55, start);
        structure.setBlockState(world, Blocks.COBBLESTONE_SLAB.getDefaultState().with(SlabBlock.TYPE, SlabType.TOP).with(SlabBlock.WATERLOGGED, false), -186, 7, -47, start);
        structure.setBlockState(world, Blocks.OAK_FENCE.getDefaultState().with(FourWayBlock.WATERLOGGED, false).with(FourWayBlock.NORTH, false).with(FourWayBlock.SOUTH, false).with(FourWayBlock.EAST, false).with(FourWayBlock.WEST, true), -186, 8, -55, start);
        structure.setBlockState(world, Blocks.OAK_FENCE.getDefaultState().with(FourWayBlock.WATERLOGGED, false).with(FourWayBlock.NORTH, false).with(FourWayBlock.SOUTH, false).with(FourWayBlock.EAST, false).with(FourWayBlock.WEST, false), -186, 8, -47, start);
        structure.setBlockState(world, Blocks.STONE_BRICK_STAIRS.getDefaultState().with(StairsBlock.FACING, Direction.WEST).with(StairsBlock.WATERLOGGED, false).with(StairsBlock.SHAPE, StairsShape.STRAIGHT).with(StairsBlock.HALF, Half.BOTTOM), -186, 9, -54, start);
        structure.setBlockState(world, Blocks.STONE_BRICK_STAIRS.getDefaultState().with(StairsBlock.FACING, Direction.WEST).with(StairsBlock.WATERLOGGED, false).with(StairsBlock.SHAPE, StairsShape.STRAIGHT).with(StairsBlock.HALF, Half.BOTTOM), -186, 9, -48, start);
        structure.setBlockState(world, Blocks.STONE_BRICK_STAIRS.getDefaultState().with(StairsBlock.FACING, Direction.WEST).with(StairsBlock.WATERLOGGED, false).with(StairsBlock.SHAPE, StairsShape.STRAIGHT).with(StairsBlock.HALF, Half.TOP), -186, 10, -54, start);
        structure.setBlockState(world, Blocks.WALL_TORCH.getDefaultState().with(WallTorchBlock.HORIZONTAL_FACING, Direction.WEST), -186, 10, -51, start);
        structure.setBlockState(world, Blocks.STONE_BRICK_STAIRS.getDefaultState().with(StairsBlock.FACING, Direction.WEST).with(StairsBlock.WATERLOGGED, false).with(StairsBlock.SHAPE, StairsShape.STRAIGHT).with(StairsBlock.HALF, Half.TOP), -186, 10, -48, start);
        structure.setBlockState(world, Blocks.STONE_BRICK_STAIRS.getDefaultState().with(StairsBlock.FACING, Direction.WEST).with(StairsBlock.WATERLOGGED, false).with(StairsBlock.SHAPE, StairsShape.STRAIGHT).with(StairsBlock.HALF, Half.TOP), -186, 12, -55, start);
        structure.setBlockState(world, Blocks.STONE_BRICK_STAIRS.getDefaultState().with(StairsBlock.FACING, Direction.WEST).with(StairsBlock.WATERLOGGED, false).with(StairsBlock.SHAPE, StairsShape.STRAIGHT).with(StairsBlock.HALF, Half.TOP), -186, 12, -47, start);
        structure.setBlockState(world, Blocks.STONE_BRICK_STAIRS.getDefaultState().with(StairsBlock.FACING, Direction.SOUTH).with(StairsBlock.WATERLOGGED, false).with(StairsBlock.SHAPE, StairsShape.STRAIGHT).with(StairsBlock.HALF, Half.TOP), -186, 13, -55, start);
        structure.setBlockState(world, Blocks.OAK_PLANKS.getDefaultState(), -186, 13, -53, start);
        structure.setBlockState(world, Blocks.STONE_BRICK_STAIRS.getDefaultState().with(StairsBlock.FACING, Direction.NORTH).with(StairsBlock.WATERLOGGED, false).with(StairsBlock.SHAPE, StairsShape.STRAIGHT).with(StairsBlock.HALF, Half.TOP), -186, 13, -47, start);
        structure.setBlockState(world, Blocks.STONE_BRICK_SLAB.getDefaultState().with(SlabBlock.TYPE, SlabType.BOTTOM).with(SlabBlock.WATERLOGGED, false), -186, 14, -55, start);
        structure.setBlockState(world, Blocks.STONE_BRICK_SLAB.getDefaultState().with(SlabBlock.TYPE, SlabType.BOTTOM).with(SlabBlock.WATERLOGGED, false), -186, 14, -47, start);
        structure.setBlockState(world, Blocks.WALL_TORCH.getDefaultState().with(WallTorchBlock.HORIZONTAL_FACING, Direction.NORTH), -186, 15, -54, start);
        structure.setBlockState(world, Blocks.WALL_TORCH.getDefaultState().with(WallTorchBlock.HORIZONTAL_FACING, Direction.SOUTH), -186, 15, -48, start);
        structure.setBlockState(world, Blocks.COBBLESTONE_WALL.getDefaultState().with(WallBlock.WATERLOGGED, false).with(WallBlock.UP, true).with(WallBlock.WALL_HEIGHT_NORTH, WallHeight.LOW).with(WallBlock.WALL_HEIGHT_SOUTH, WallHeight.LOW).with(WallBlock.WALL_HEIGHT_EAST, WallHeight.LOW).with(WallBlock.WALL_HEIGHT_WEST, WallHeight.LOW), -186, 17, -53, start);
        structure.setBlockState(world, Blocks.COBBLESTONE_WALL.getDefaultState().with(WallBlock.WATERLOGGED, false).with(WallBlock.UP, true).with(WallBlock.WALL_HEIGHT_NORTH, WallHeight.LOW).with(WallBlock.WALL_HEIGHT_SOUTH, WallHeight.LOW).with(WallBlock.WALL_HEIGHT_EAST, WallHeight.LOW).with(WallBlock.WALL_HEIGHT_WEST, WallHeight.LOW), -186, 17, -49, start);
        structure.setBlockState(world, Blocks.STONE_BRICK_SLAB.getDefaultState().with(SlabBlock.TYPE, SlabType.BOTTOM).with(SlabBlock.WATERLOGGED, false), -186, 18, -53, start);
        structure.setBlockState(world, Blocks.STONE_BRICK_SLAB.getDefaultState().with(SlabBlock.TYPE, SlabType.BOTTOM).with(SlabBlock.WATERLOGGED, false), -186, 18, -49, start);
        structure.setBlockState(world, Blocks.OAK_LOG.getDefaultState(), -186, 20, -52, start);
        structure.setBlockState(world, Blocks.OAK_LOG.getDefaultState(), -186, 20, -50, start);
        structure.setBlockState(world, Blocks.OAK_FENCE.getDefaultState().with(FourWayBlock.WATERLOGGED, false).with(FourWayBlock.NORTH, false).with(FourWayBlock.SOUTH, false).with(FourWayBlock.EAST, false).with(FourWayBlock.WEST, true), -186, 21, -52, start);
        structure.setBlockState(world, Blocks.STONE_BRICK_STAIRS.getDefaultState().with(StairsBlock.FACING, Direction.WEST).with(StairsBlock.WATERLOGGED, false).with(StairsBlock.SHAPE, StairsShape.STRAIGHT).with(StairsBlock.HALF, Half.BOTTOM), -186, 21, -51, start);
        structure.setBlockState(world, Blocks.OAK_FENCE.getDefaultState().with(FourWayBlock.WATERLOGGED, false).with(FourWayBlock.NORTH, false).with(FourWayBlock.SOUTH, false).with(FourWayBlock.EAST, false).with(FourWayBlock.WEST, true), -186, 21, -50, start);
        structure.setBlockState(world, Blocks.WALL_TORCH.getDefaultState().with(WallTorchBlock.HORIZONTAL_FACING, Direction.EAST), -186, 22, -51, start);
        structure.setBlockState(world, Blocks.COBBLESTONE_STAIRS.getDefaultState().with(StairsBlock.FACING, Direction.WEST).with(StairsBlock.WATERLOGGED, false).with(StairsBlock.SHAPE, StairsShape.STRAIGHT).with(StairsBlock.HALF, Half.TOP), -186, 24, -51, start);
        structure.setBlockState(world, Blocks.OAK_SLAB.getDefaultState().with(SlabBlock.TYPE, SlabType.TOP).with(SlabBlock.WATERLOGGED, false), -186, 25, -52, start);
        structure.setBlockState(world, Blocks.STONE_BRICKS.getDefaultState(), -186, 25, -51, start);
        structure.setBlockState(world, Blocks.OAK_SLAB.getDefaultState().with(SlabBlock.TYPE, SlabType.TOP).with(SlabBlock.WATERLOGGED, false), -186, 25, -50, start);
        structure.setBlockState(world, Blocks.STONE_BRICKS.getDefaultState(), -186, 27, -53, start);
        structure.setBlockState(world, Blocks.STONE_BRICKS.getDefaultState(), -186, 27, -49, start);
        structure.setBlockState(world, Blocks.COBBLESTONE_WALL.getDefaultState().with(WallBlock.WATERLOGGED, false).with(WallBlock.UP, true).with(WallBlock.WALL_HEIGHT_NORTH, WallHeight.LOW).with(WallBlock.WALL_HEIGHT_SOUTH, WallHeight.LOW).with(WallBlock.WALL_HEIGHT_EAST, WallHeight.LOW).with(WallBlock.WALL_HEIGHT_WEST, WallHeight.LOW), -186, 28, -53, start);
        structure.setBlockState(world, Blocks.COBBLESTONE_WALL.getDefaultState().with(WallBlock.WATERLOGGED, false).with(WallBlock.UP, true).with(WallBlock.WALL_HEIGHT_NORTH, WallHeight.LOW).with(WallBlock.WALL_HEIGHT_SOUTH, WallHeight.LOW).with(WallBlock.WALL_HEIGHT_EAST, WallHeight.LOW).with(WallBlock.WALL_HEIGHT_WEST, WallHeight.LOW), -186, 28, -49, start);
        structure.setBlockState(world, Blocks.OAK_PLANKS.getDefaultState(), -186, 29, -53, start);
        structure.setBlockState(world, Blocks.OAK_PLANKS.getDefaultState(), -186, 29, -49, start);
        structure.setBlockState(world, Blocks.OAK_SLAB.getDefaultState().with(SlabBlock.TYPE, SlabType.BOTTOM).with(SlabBlock.WATERLOGGED, false), -186, 29, -48, start);
        structure.setBlockState(world, Blocks.OAK_STAIRS.getDefaultState().with(StairsBlock.FACING, Direction.WEST).with(StairsBlock.WATERLOGGED, false).with(StairsBlock.SHAPE, StairsShape.STRAIGHT).with(StairsBlock.HALF, Half.BOTTOM), -186, 30, -52, start);
        structure.setBlockState(world, Blocks.OAK_STAIRS.getDefaultState().with(StairsBlock.FACING, Direction.WEST).with(StairsBlock.WATERLOGGED, false).with(StairsBlock.SHAPE, StairsShape.STRAIGHT).with(StairsBlock.HALF, Half.BOTTOM), -186, 30, -50, start);
        structure.setBlockState(world, Blocks.GRASS_BLOCK.getDefaultState().with(SnowyDirtBlock.SNOWY, false), -185, 1, -45, start);
        structure.setBlockState(world, Blocks.STONE_PRESSURE_PLATE.getDefaultState().with(PressurePlateBlock.POWERED, false), -185, 5, -51, start);
        structure.setBlockState(world, Blocks.STONE_BRICKS.getDefaultState(), -185, 5, -47, start);
        structure.setBlockState(world, Blocks.COBBLESTONE_STAIRS.getDefaultState().with(StairsBlock.FACING, Direction.SOUTH).with(StairsBlock.WATERLOGGED, false).with(StairsBlock.SHAPE, StairsShape.STRAIGHT).with(StairsBlock.HALF, Half.BOTTOM), -185, 6, -55, start);
        structure.setBlockState(world, Blocks.COBBLESTONE_STAIRS.getDefaultState().with(StairsBlock.FACING, Direction.NORTH).with(StairsBlock.WATERLOGGED, false).with(StairsBlock.SHAPE, StairsShape.STRAIGHT).with(StairsBlock.HALF, Half.BOTTOM), -185, 6, -47, start);
        structure.setBlockState(world, Blocks.COBBLESTONE_STAIRS.getDefaultState().with(StairsBlock.FACING, Direction.SOUTH).with(StairsBlock.WATERLOGGED, false).with(StairsBlock.SHAPE, StairsShape.STRAIGHT).with(StairsBlock.HALF, Half.TOP), -185, 7, -55, start);
        structure.setBlockState(world, Blocks.COBBLESTONE_STAIRS.getDefaultState().with(StairsBlock.FACING, Direction.NORTH).with(StairsBlock.WATERLOGGED, false).with(StairsBlock.SHAPE, StairsShape.STRAIGHT).with(StairsBlock.HALF, Half.TOP), -185, 7, -47, start);
        structure.setBlockState(world, Blocks.STONE_BRICKS.getDefaultState(), -185, 8, -47, start);
        structure.setBlockState(world, Blocks.STONE_BRICK_STAIRS.getDefaultState().with(StairsBlock.FACING, Direction.SOUTH).with(StairsBlock.WATERLOGGED, false).with(StairsBlock.SHAPE, StairsShape.STRAIGHT).with(StairsBlock.HALF, Half.BOTTOM), -185, 9, -53, start);
        structure.setBlockState(world, Blocks.STONE_BRICK_STAIRS.getDefaultState().with(StairsBlock.FACING, Direction.NORTH).with(StairsBlock.WATERLOGGED, false).with(StairsBlock.SHAPE, StairsShape.STRAIGHT).with(StairsBlock.HALF, Half.BOTTOM), -185, 9, -49, start);
        structure.setBlockState(world, Blocks.STONE_BRICK_STAIRS.getDefaultState().with(StairsBlock.FACING, Direction.SOUTH).with(StairsBlock.WATERLOGGED, false).with(StairsBlock.SHAPE, StairsShape.STRAIGHT).with(StairsBlock.HALF, Half.TOP), -185, 10, -53, start);
        structure.setBlockState(world, Blocks.STONE_BRICK_STAIRS.getDefaultState().with(StairsBlock.FACING, Direction.NORTH).with(StairsBlock.WATERLOGGED, false).with(StairsBlock.SHAPE, StairsShape.STRAIGHT).with(StairsBlock.HALF, Half.TOP), -185, 10, -49, start);
        structure.setBlockState(world, Blocks.OAK_FENCE.getDefaultState().with(FourWayBlock.WATERLOGGED, false).with(FourWayBlock.NORTH, false).with(FourWayBlock.SOUTH, true).with(FourWayBlock.EAST, false).with(FourWayBlock.WEST, false), -185, 13, -54, start);
        structure.setBlockState(world, Blocks.OAK_FENCE.getDefaultState().with(FourWayBlock.WATERLOGGED, false).with(FourWayBlock.NORTH, true).with(FourWayBlock.SOUTH, false).with(FourWayBlock.EAST, false).with(FourWayBlock.WEST, true), -185, 13, -48, start);
        structure.setBlockState(world, Blocks.WALL_TORCH.getDefaultState().with(WallTorchBlock.HORIZONTAL_FACING, Direction.EAST), -185, 15, -53, start);
        structure.setBlockState(world, Blocks.WALL_TORCH.getDefaultState().with(WallTorchBlock.HORIZONTAL_FACING, Direction.EAST), -185, 15, -49, start);
        structure.setBlockState(world, Blocks.STONE_BRICK_STAIRS.getDefaultState().with(StairsBlock.FACING, Direction.WEST).with(StairsBlock.WATERLOGGED, false).with(StairsBlock.SHAPE, StairsShape.STRAIGHT).with(StairsBlock.HALF, Half.TOP), -185, 16, -51, start);
        structure.setBlockState(world, Blocks.STONE_BRICK_STAIRS.getDefaultState().with(StairsBlock.FACING, Direction.SOUTH).with(StairsBlock.WATERLOGGED, false).with(StairsBlock.SHAPE, StairsShape.STRAIGHT).with(StairsBlock.HALF, Half.TOP), -185, 17, -52, start);
        structure.setBlockState(world, Blocks.STONE_BRICKS.getDefaultState(), -185, 17, -51, start);
        structure.setBlockState(world, Blocks.STONE_BRICK_STAIRS.getDefaultState().with(StairsBlock.FACING, Direction.NORTH).with(StairsBlock.WATERLOGGED, false).with(StairsBlock.SHAPE, StairsShape.STRAIGHT).with(StairsBlock.HALF, Half.TOP), -185, 17, -50, start);
        structure.setBlockState(world, Blocks.STONE_BUTTON.getDefaultState().with(HorizontalBlock.HORIZONTAL_FACING, Direction.EAST).with(HorizontalFaceBlock.FACE, AttachFace.WALL).with(AbstractButtonBlock.POWERED, false), -185, 20, -52, start);
        structure.setBlockState(world, Blocks.STONE_BRICK_STAIRS.getDefaultState().with(StairsBlock.FACING, Direction.WEST).with(StairsBlock.WATERLOGGED, false).with(StairsBlock.SHAPE, StairsShape.STRAIGHT).with(StairsBlock.HALF, Half.BOTTOM), -185, 20, -51, start);
        structure.setBlockState(world, Blocks.STONE_BUTTON.getDefaultState().with(HorizontalBlock.HORIZONTAL_FACING, Direction.EAST).with(HorizontalFaceBlock.FACE, AttachFace.WALL).with(AbstractButtonBlock.POWERED, false), -185, 20, -50, start);
        structure.setBlockState(world, Blocks.STONE_BRICK_STAIRS.getDefaultState().with(StairsBlock.FACING, Direction.WEST).with(StairsBlock.WATERLOGGED, false).with(StairsBlock.SHAPE, StairsShape.STRAIGHT).with(StairsBlock.HALF, Half.TOP), -185, 25, -51, start);
        structure.setBlockState(world, Blocks.STONE_BRICK_STAIRS.getDefaultState().with(StairsBlock.FACING, Direction.SOUTH).with(StairsBlock.WATERLOGGED, false).with(StairsBlock.SHAPE, StairsShape.STRAIGHT).with(StairsBlock.HALF, Half.TOP), -185, 26, -52, start);
        structure.setBlockState(world, Blocks.STONE_BRICKS.getDefaultState(), -185, 26, -51, start);
        structure.setBlockState(world, Blocks.STONE_BRICK_STAIRS.getDefaultState().with(StairsBlock.FACING, Direction.NORTH).with(StairsBlock.WATERLOGGED, false).with(StairsBlock.SHAPE, StairsShape.STRAIGHT).with(StairsBlock.HALF, Half.TOP), -185, 26, -50, start);
        structure.setBlockState(world, Blocks.STONE_BRICK_SLAB.getDefaultState().with(SlabBlock.TYPE, SlabType.BOTTOM).with(SlabBlock.WATERLOGGED, false), -185, 27, -52, start);
        structure.setBlockState(world, Blocks.STONE_BRICK_SLAB.getDefaultState().with(SlabBlock.TYPE, SlabType.BOTTOM).with(SlabBlock.WATERLOGGED, false), -185, 27, -50, start);
        structure.setBlockState(world, Blocks.OAK_SLAB.getDefaultState().with(SlabBlock.TYPE, SlabType.BOTTOM).with(SlabBlock.WATERLOGGED, false), -185, 29, -53, start);
        structure.setBlockState(world, Blocks.OAK_SLAB.getDefaultState().with(SlabBlock.TYPE, SlabType.BOTTOM).with(SlabBlock.WATERLOGGED, false), -185, 29, -49, start);
        structure.setBlockState(world, Blocks.STONE_BRICKS.getDefaultState(), -184, 5, -54, start);
        structure.setBlockState(world, Blocks.SPRUCE_DOOR.getDefaultState().with(DoorBlock.FACING, Direction.EAST).with(DoorBlock.HALF, DoubleBlockHalf.LOWER).with(DoorBlock.HINGE, DoorHingeSide.LEFT).with(DoorBlock.OPEN, false).with(DoorBlock.POWERED, false), -184, 5, -51, start);
        structure.setBlockState(world, Blocks.STONE_BRICK_STAIRS.getDefaultState().with(StairsBlock.FACING, Direction.WEST).with(StairsBlock.WATERLOGGED, false).with(StairsBlock.SHAPE, StairsShape.STRAIGHT).with(StairsBlock.HALF, Half.BOTTOM), -184, 5, -49, start);
        structure.setBlockState(world, Blocks.STONE_BRICKS.getDefaultState(), -184, 5, -48, start);
        structure.setBlockState(world, Blocks.COBBLESTONE_STAIRS.getDefaultState().with(StairsBlock.FACING, Direction.WEST).with(StairsBlock.WATERLOGGED, false).with(StairsBlock.SHAPE, StairsShape.STRAIGHT).with(StairsBlock.HALF, Half.BOTTOM), -184, 6, -54, start);
        structure.setBlockState(world, Blocks.SPRUCE_DOOR.getDefaultState().with(DoorBlock.FACING, Direction.EAST).with(DoorBlock.HALF, DoubleBlockHalf.UPPER).with(DoorBlock.HINGE, DoorHingeSide.LEFT).with(DoorBlock.OPEN, false).with(DoorBlock.POWERED, false), -184, 6, -51, start);
        structure.setBlockState(world, Blocks.COBBLESTONE_STAIRS.getDefaultState().with(StairsBlock.FACING, Direction.WEST).with(StairsBlock.WATERLOGGED, false).with(StairsBlock.SHAPE, StairsShape.STRAIGHT).with(StairsBlock.HALF, Half.BOTTOM), -184, 6, -48, start);
        structure.setBlockState(world, Blocks.COBBLESTONE_STAIRS.getDefaultState().with(StairsBlock.FACING, Direction.WEST).with(StairsBlock.WATERLOGGED, false).with(StairsBlock.SHAPE, StairsShape.STRAIGHT).with(StairsBlock.HALF, Half.TOP), -184, 7, -54, start);
        structure.setBlockState(world, Blocks.COBBLESTONE_SLAB.getDefaultState().with(SlabBlock.TYPE, SlabType.TOP).with(SlabBlock.WATERLOGGED, false), -184, 7, -53, start);
        structure.setBlockState(world, Blocks.COBBLESTONE_SLAB.getDefaultState().with(SlabBlock.TYPE, SlabType.TOP).with(SlabBlock.WATERLOGGED, false), -184, 7, -49, start);
        structure.setBlockState(world, Blocks.COBBLESTONE_STAIRS.getDefaultState().with(StairsBlock.FACING, Direction.WEST).with(StairsBlock.WATERLOGGED, false).with(StairsBlock.SHAPE, StairsShape.STRAIGHT).with(StairsBlock.HALF, Half.TOP), -184, 7, -48, start);
        structure.setBlockState(world, Blocks.OAK_FENCE.getDefaultState().with(FourWayBlock.WATERLOGGED, false).with(FourWayBlock.NORTH, false).with(FourWayBlock.SOUTH, true).with(FourWayBlock.EAST, false).with(FourWayBlock.WEST, true), -184, 8, -55, start);
        structure.setBlockState(world, Blocks.STONE_BRICKS.getDefaultState(), -184, 8, -54, start);
        structure.setBlockState(world, Blocks.OAK_FENCE.getDefaultState().with(FourWayBlock.WATERLOGGED, false).with(FourWayBlock.NORTH, true).with(FourWayBlock.SOUTH, false).with(FourWayBlock.EAST, false).with(FourWayBlock.WEST, true), -184, 8, -53, start);
        structure.setBlockState(world, Blocks.OAK_FENCE.getDefaultState().with(FourWayBlock.WATERLOGGED, false).with(FourWayBlock.NORTH, true).with(FourWayBlock.SOUTH, true).with(FourWayBlock.EAST, false).with(FourWayBlock.WEST, true), -184, 8, -49, start);
        structure.setBlockState(world, Blocks.STONE_BRICKS.getDefaultState(), -184, 8, -48, start);
        structure.setBlockState(world, Blocks.OAK_FENCE.getDefaultState().with(FourWayBlock.WATERLOGGED, false).with(FourWayBlock.NORTH, true).with(FourWayBlock.SOUTH, false).with(FourWayBlock.EAST, false).with(FourWayBlock.WEST, true), -184, 8, -47, start);
        structure.setBlockState(world, Blocks.STONE_BRICK_STAIRS.getDefaultState().with(StairsBlock.FACING, Direction.SOUTH).with(StairsBlock.WATERLOGGED, false).with(StairsBlock.SHAPE, StairsShape.STRAIGHT).with(StairsBlock.HALF, Half.TOP), -184, 12, -53, start);
        structure.setBlockState(world, Blocks.STONE_BRICKS.getDefaultState(), -184, 12, -52, start);
        structure.setBlockState(world, Blocks.STONE_BRICKS.getDefaultState(), -184, 12, -50, start);
        structure.setBlockState(world, Blocks.STONE_BRICK_STAIRS.getDefaultState().with(StairsBlock.FACING, Direction.NORTH).with(StairsBlock.WATERLOGGED, false).with(StairsBlock.SHAPE, StairsShape.STRAIGHT).with(StairsBlock.HALF, Half.TOP), -184, 12, -49, start);
        structure.setBlockState(world, Blocks.STONE_BRICK_STAIRS.getDefaultState().with(StairsBlock.FACING, Direction.WEST).with(StairsBlock.WATERLOGGED, false).with(StairsBlock.SHAPE, StairsShape.STRAIGHT).with(StairsBlock.HALF, Half.TOP), -184, 13, -53, start);
        structure.setBlockState(world, Blocks.STONE_BRICK_STAIRS.getDefaultState().with(StairsBlock.FACING, Direction.WEST).with(StairsBlock.WATERLOGGED, false).with(StairsBlock.SHAPE, StairsShape.STRAIGHT).with(StairsBlock.HALF, Half.TOP), -184, 13, -49, start);
        structure.setBlockState(world, Blocks.STONE_BRICK_SLAB.getDefaultState().with(SlabBlock.TYPE, SlabType.BOTTOM).with(SlabBlock.WATERLOGGED, false), -184, 14, -53, start);
        structure.setBlockState(world, Blocks.STONE_BRICK_SLAB.getDefaultState().with(SlabBlock.TYPE, SlabType.BOTTOM).with(SlabBlock.WATERLOGGED, false), -184, 14, -49, start);
        structure.setBlockState(world, Blocks.DIRT.getDefaultState(), -183, 4, -52, start);
        structure.setBlockState(world, Blocks.DIRT.getDefaultState(), -183, 4, -50, start);
        structure.setBlockState(world, Blocks.STONE_BRICK_STAIRS.getDefaultState().with(StairsBlock.FACING, Direction.WEST).with(StairsBlock.WATERLOGGED, false).with(StairsBlock.SHAPE, StairsShape.STRAIGHT).with(StairsBlock.HALF, Half.BOTTOM), -183, 5, -52, start);
        structure.setBlockState(world, Blocks.AIR.getDefaultState(), -183, 5, -51, start);
        structure.setBlockState(world, Blocks.STONE_BRICK_STAIRS.getDefaultState().with(StairsBlock.FACING, Direction.WEST).with(StairsBlock.WATERLOGGED, false).with(StairsBlock.SHAPE, StairsShape.STRAIGHT).with(StairsBlock.HALF, Half.BOTTOM), -183, 5, -50, start);
        structure.setBlockState(world, Blocks.STONE_BUTTON.getDefaultState().with(HorizontalBlock.HORIZONTAL_FACING, Direction.EAST).with(HorizontalFaceBlock.FACE, AttachFace.WALL).with(AbstractButtonBlock.POWERED, false), -183, 6, -52, start);
        structure.setBlockState(world, Blocks.COBBLESTONE_STAIRS.getDefaultState().with(StairsBlock.FACING, Direction.WEST).with(StairsBlock.WATERLOGGED, false).with(StairsBlock.SHAPE, StairsShape.STRAIGHT).with(StairsBlock.HALF, Half.TOP), -183, 7, -51, start);
        structure.setBlockState(world, Blocks.COBBLESTONE_STAIRS.getDefaultState().with(StairsBlock.FACING, Direction.WEST).with(StairsBlock.WATERLOGGED, false).with(StairsBlock.SHAPE, StairsShape.STRAIGHT).with(StairsBlock.HALF, Half.BOTTOM), -183, 8, -51, start);
        structure.setBlockState(world, Blocks.STONE_BRICK_STAIRS.getDefaultState().with(StairsBlock.FACING, Direction.WEST).with(StairsBlock.WATERLOGGED, false).with(StairsBlock.SHAPE, StairsShape.STRAIGHT).with(StairsBlock.HALF, Half.TOP), -183, 12, -52, start);
        structure.setBlockState(world, Blocks.COBBLESTONE_STAIRS.getDefaultState().with(StairsBlock.FACING, Direction.WEST).with(StairsBlock.WATERLOGGED, false).with(StairsBlock.SHAPE, StairsShape.STRAIGHT).with(StairsBlock.HALF, Half.TOP), -183, 12, -51, start);
        structure.setBlockState(world, Blocks.STONE_BRICK_STAIRS.getDefaultState().with(StairsBlock.FACING, Direction.WEST).with(StairsBlock.WATERLOGGED, false).with(StairsBlock.SHAPE, StairsShape.STRAIGHT).with(StairsBlock.HALF, Half.TOP), -183, 12, -50, start);
        structure.setBlockState(world, Blocks.STONE_BRICK_STAIRS.getDefaultState().with(StairsBlock.FACING, Direction.SOUTH).with(StairsBlock.WATERLOGGED, false).with(StairsBlock.SHAPE, StairsShape.STRAIGHT).with(StairsBlock.HALF, Half.TOP), -183, 13, -52, start);
        structure.setBlockState(world, Blocks.COBBLESTONE_WALL.getDefaultState().with(WallBlock.WATERLOGGED, false).with(WallBlock.UP, true).with(WallBlock.WALL_HEIGHT_NORTH, WallHeight.LOW).with(WallBlock.WALL_HEIGHT_SOUTH, WallHeight.LOW).with(WallBlock.WALL_HEIGHT_EAST, WallHeight.LOW).with(WallBlock.WALL_HEIGHT_WEST, WallHeight.LOW), -183, 13, -51, start);
        structure.setBlockState(world, Blocks.STONE_BRICK_STAIRS.getDefaultState().with(StairsBlock.FACING, Direction.NORTH).with(StairsBlock.WATERLOGGED, false).with(StairsBlock.SHAPE, StairsShape.STRAIGHT).with(StairsBlock.HALF, Half.TOP), -183, 13, -50, start);
        structure.setBlockState(world, Blocks.STONE_BRICKS.getDefaultState(), -183, 14, -52, start);
        structure.setBlockState(world, Blocks.STONE_BRICK_SLAB.getDefaultState().with(SlabBlock.TYPE, SlabType.BOTTOM).with(SlabBlock.WATERLOGGED, false), -183, 14, -51, start);
        structure.setBlockState(world, Blocks.STONE_BRICKS.getDefaultState(), -183, 14, -50, start);
        structure.setBlockState(world, Blocks.GRASS_BLOCK.getDefaultState().with(SnowyDirtBlock.SNOWY, false), -182, 4, -52, start);
        structure.fillWithBlocks(world, start, -198, 0, -61, -198, 0, -41, Blocks.GRASS_BLOCK.getDefaultState().with(SnowyDirtBlock.SNOWY, false));
        structure.fillWithBlocks(world, start, -197, 0, -61, -178, 0, -61, Blocks.GRASS_BLOCK.getDefaultState().with(SnowyDirtBlock.SNOWY, false));
        structure.fillWithBlocks(world, start, -197, 0, -60, -187, 0, -50, Blocks.DIRT.getDefaultState());
        structure.fillWithBlocks(world, start, -197, 0, -49, -193, 0, -42, Blocks.DIRT.getDefaultState());
        structure.fillWithBlocks(world, start, -197, 0, -41, -178, 0, -41, Blocks.GRASS_BLOCK.getDefaultState().with(SnowyDirtBlock.SNOWY, false));
        structure.fillWithBlocks(world, start, -197, 1, -60, -197, 1, -42, Blocks.GRASS_BLOCK.getDefaultState().with(SnowyDirtBlock.SNOWY, false));
        structure.fillWithBlocks(world, start, -196, 1, -60, -179, 1, -60, Blocks.GRASS_BLOCK.getDefaultState().with(SnowyDirtBlock.SNOWY, false));
        structure.fillWithBlocks(world, start, -196, 1, -59, -183, 1, -46, Blocks.DIRT.getDefaultState());
        structure.fillWithBlocks(world, start, -196, 1, -45, -194, 1, -43, Blocks.DIRT.getDefaultState());
        structure.fillWithBlocks(world, start, -196, 1, -42, -179, 1, -42, Blocks.GRASS_BLOCK.getDefaultState().with(SnowyDirtBlock.SNOWY, false));
        structure.fillWithBlocks(world, start, -196, 2, -59, -196, 2, -43, Blocks.GRASS_BLOCK.getDefaultState().with(SnowyDirtBlock.SNOWY, false));
        structure.fillWithBlocks(world, start, -195, 2, -59, -180, 2, -59, Blocks.GRASS_BLOCK.getDefaultState().with(SnowyDirtBlock.SNOWY, false));
        structure.fillWithBlocks(world, start, -195, 2, -58, -181, 2, -44, Blocks.DIRT.getDefaultState());
        structure.fillWithBlocks(world, start, -195, 2, -43, -180, 2, -43, Blocks.GRASS_BLOCK.getDefaultState().with(SnowyDirtBlock.SNOWY, false));
        structure.fillWithBlocks(world, start, -195, 3, -58, -195, 3, -44, Blocks.GRASS_BLOCK.getDefaultState().with(SnowyDirtBlock.SNOWY, false));
        structure.fillWithBlocks(world, start, -194, 3, -58, -181, 3, -58, Blocks.GRASS_BLOCK.getDefaultState().with(SnowyDirtBlock.SNOWY, false));
        structure.fillWithBlocks(world, start, -194, 3, -57, -191, 3, -45, Blocks.DIRT.getDefaultState());
        structure.fillWithBlocks(world, start, -194, 3, -44, -181, 3, -44, Blocks.GRASS_BLOCK.getDefaultState().with(SnowyDirtBlock.SNOWY, false));
        structure.fillWithBlocks(world, start, -194, 4, -57, -192, 4, -55, Blocks.GRASS_BLOCK.getDefaultState().with(SnowyDirtBlock.SNOWY, false));
        structure.fillWithBlocks(world, start, -194, 4, -54, -193, 4, -53, Blocks.GRASS_BLOCK.getDefaultState().with(SnowyDirtBlock.SNOWY, false));
        structure.fillWithBlocks(world, start, -194, 4, -51, -194, 4, -51, Blocks.DIRT.getDefaultState());
        structure.fillWithBlocks(world, start, -194, 4, -50, -194, 4, -45, Blocks.GRASS_BLOCK.getDefaultState().with(SnowyDirtBlock.SNOWY, false));
        structure.fillWithBlocks(world, start, -194, 5, -53, -193, 5, -53, Blocks.GRASS.getDefaultState());
        structure.fillWithBlocks(world, start, -194, 5, -49, -194, 5, -48, Blocks.GRASS.getDefaultState());
        structure.fillWithBlocks(world, start, -194, 5, -46, -193, 5, -46, Blocks.GRASS.getDefaultState());
        structure.fillWithBlocks(world, start, -193, 1, -45, -191, 1, -43, Blocks.DIRT.getDefaultState());
        structure.fillWithBlocks(world, start, -193, 4, -52, -192, 4, -50, Blocks.DIRT.getDefaultState());
        structure.fillWithBlocks(world, start, -193, 4, -49, -193, 4, -45, Blocks.GRASS_BLOCK.getDefaultState().with(SnowyDirtBlock.SNOWY, false));
        structure.fillWithBlocks(world, start, -193, 5, -54, -193, 5, -53, Blocks.GRASS.getDefaultState());
        structure.fillWithBlocks(world, start, -193, 5, -51, -192, 6, -51, Blocks.COBBLESTONE.getDefaultState());
        structure.fillWithBlocks(world, start, -193, 5, -50, -193, 5, -50, Blocks.STONE_BRICK_STAIRS.getDefaultState().with(StairsBlock.FACING, Direction.EAST).with(StairsBlock.WATERLOGGED, false).with(StairsBlock.SHAPE, StairsShape.STRAIGHT).with(StairsBlock.HALF, Half.BOTTOM));
        structure.fillWithBlocks(world, start, -193, 7, -51, -192, 7, -51, Blocks.COBBLESTONE.getDefaultState());
        structure.fillWithBlocks(world, start, -192, 0, -48, -186, 0, -42, Blocks.DIRT.getDefaultState());
        structure.fillWithBlocks(world, start, -192, 4, -54, -192, 4, -48, Blocks.DIRT.getDefaultState());
        structure.fillWithBlocks(world, start, -192, 4, -47, -192, 4, -45, Blocks.GRASS_BLOCK.getDefaultState().with(SnowyDirtBlock.SNOWY, false));
        structure.fillWithBlocks(world, start, -192, 5, -54, -192, 5, -54, Blocks.STONE_BRICKS.getDefaultState());
        structure.fillWithBlocks(world, start, -192, 5, -52, -191, 6, -52, Blocks.STONE_BRICKS.getDefaultState());
        structure.fillWithBlocks(world, start, -192, 5, -50, -192, 5, -50, Blocks.STONE_BRICKS.getDefaultState());
        structure.fillWithBlocks(world, start, -192, 5, -48, -192, 5, -48, Blocks.STONE_BRICKS.getDefaultState());
        structure.fillWithBlocks(world, start, -192, 6, -50, -192, 6, -50, Blocks.STONE_BRICKS.getDefaultState());
        structure.fillWithBlocks(world, start, -192, 7, -52, -191, 8, -52, Blocks.STONE_BRICKS.getDefaultState());
        structure.fillWithBlocks(world, start, -192, 7, -50, -192, 7, -50, Blocks.STONE_BRICKS.getDefaultState());
        structure.fillWithBlocks(world, start, -192, 8, -54, -192, 8, -54, Blocks.STONE_BRICKS.getDefaultState());
        structure.fillWithBlocks(world, start, -192, 8, -51, -192, 12, -51, Blocks.COBBLESTONE.getDefaultState());
        structure.fillWithBlocks(world, start, -192, 8, -50, -192, 8, -50, Blocks.STONE_BRICKS.getDefaultState());
        structure.fillWithBlocks(world, start, -192, 8, -48, -192, 8, -48, Blocks.STONE_BRICKS.getDefaultState());
        structure.fillWithBlocks(world, start, -192, 9, -52, -191, 9, -52, Blocks.STONE_BRICKS.getDefaultState());
        structure.fillWithBlocks(world, start, -192, 9, -50, -191, 9, -50, Blocks.STONE_BRICKS.getDefaultState());
        structure.fillWithBlocks(world, start, -192, 10, -52, -192, 11, -52, Blocks.STONE_BRICK_STAIRS.getDefaultState().with(StairsBlock.FACING, Direction.EAST).with(StairsBlock.WATERLOGGED, false).with(StairsBlock.SHAPE, StairsShape.STRAIGHT).with(StairsBlock.HALF, Half.TOP));
        structure.fillWithBlocks(world, start, -192, 10, -50, -192, 11, -50, Blocks.STONE_BRICK_STAIRS.getDefaultState().with(StairsBlock.FACING, Direction.EAST).with(StairsBlock.WATERLOGGED, false).with(StairsBlock.SHAPE, StairsShape.STRAIGHT).with(StairsBlock.HALF, Half.TOP));
        structure.fillWithBlocks(world, start, -192, 12, -52, -191, 12, -52, Blocks.STONE_BRICKS.getDefaultState());
        structure.fillWithBlocks(world, start, -192, 12, -50, -192, 12, -50, Blocks.STONE_BRICKS.getDefaultState());
        structure.fillWithBlocks(world, start, -192, 13, -52, -191, 13, -50, Blocks.STONE_BRICK_SLAB.getDefaultState().with(SlabBlock.TYPE, SlabType.BOTTOM).with(SlabBlock.WATERLOGGED, false));
        structure.fillWithBlocks(world, start, -191, 0, -49, -184, 0, -42, Blocks.DIRT.getDefaultState());
        structure.fillWithBlocks(world, start, -191, 4, -57, -190, 4, -56, Blocks.GRASS_BLOCK.getDefaultState().with(SnowyDirtBlock.SNOWY, false));
        structure.fillWithBlocks(world, start, -191, 4, -55, -191, 4, -54, Blocks.DIRT.getDefaultState());
        structure.fillWithBlocks(world, start, -191, 4, -53, -191, 8, -53, Blocks.STONE_BRICKS.getDefaultState());
        structure.fillWithBlocks(world, start, -191, 4, -51, -191, 12, -51, Blocks.OAK_LOG.getDefaultState());
        structure.fillWithBlocks(world, start, -191, 4, -50, -191, 5, -49, Blocks.STONE_BRICKS.getDefaultState());
        structure.fillWithBlocks(world, start, -191, 4, -48, -191, 4, -47, Blocks.DIRT.getDefaultState());
        structure.fillWithBlocks(world, start, -191, 4, -46, -190, 4, -45, Blocks.GRASS_BLOCK.getDefaultState().with(SnowyDirtBlock.SNOWY, false));
        structure.fillWithBlocks(world, start, -191, 5, -55, -191, 5, -55, Blocks.STONE_BRICKS.getDefaultState());
        structure.fillWithBlocks(world, start, -191, 5, -54, -191, 12, -54, Blocks.OAK_LOG.getDefaultState());
        structure.fillWithBlocks(world, start, -191, 5, -48, -191, 12, -48, Blocks.OAK_LOG.getDefaultState());
        structure.fillWithBlocks(world, start, -191, 6, -50, -191, 7, -49, Blocks.STONE_BRICKS.getDefaultState());
        structure.fillWithBlocks(world, start, -191, 8, -55, -191, 8, -55, Blocks.STONE_BRICKS.getDefaultState());
        structure.fillWithBlocks(world, start, -191, 8, -50, -191, 8, -49, Blocks.STONE_BRICKS.getDefaultState());
        structure.fillWithBlocks(world, start, -191, 10, -52, -191, 12, -52, Blocks.STONE_BRICKS.getDefaultState());
        structure.fillWithBlocks(world, start, -191, 10, -50, -191, 12, -50, Blocks.STONE_BRICKS.getDefaultState());
        structure.fillWithBlocks(world, start, -191, 11, -53, -191, 12, -52, Blocks.STONE_BRICKS.getDefaultState());
        structure.fillWithBlocks(world, start, -191, 11, -49, -191, 11, -49, Blocks.STONE_BRICKS.getDefaultState());
        structure.fillWithBlocks(world, start, -191, 12, -49, -191, 14, -49, Blocks.STONE_BRICKS.getDefaultState());
        structure.fillWithBlocks(world, start, -191, 13, -53, -191, 14, -53, Blocks.STONE_BRICKS.getDefaultState());
        structure.fillWithBlocks(world, start, -191, 17, -51, -190, 17, -51, Blocks.STONE_BRICKS.getDefaultState());
        structure.fillWithBlocks(world, start, -191, 18, -51, -191, 19, -51, Blocks.COBBLESTONE_WALL.getDefaultState().with(WallBlock.WATERLOGGED, false).with(WallBlock.UP, true).with(WallBlock.WALL_HEIGHT_NORTH, WallHeight.LOW).with(WallBlock.WALL_HEIGHT_SOUTH, WallHeight.LOW).with(WallBlock.WALL_HEIGHT_EAST, WallHeight.LOW).with(WallBlock.WALL_HEIGHT_WEST, WallHeight.LOW));
        structure.fillWithBlocks(world, start, -191, 29, -52, -191, 29, -50, Blocks.OAK_STAIRS.getDefaultState().with(StairsBlock.FACING, Direction.EAST).with(StairsBlock.WATERLOGGED, false).with(StairsBlock.SHAPE, StairsShape.STRAIGHT).with(StairsBlock.HALF, Half.BOTTOM));
        structure.fillWithBlocks(world, start, -191, 29, -49, -191, 29, -49, Blocks.OAK_SLAB.getDefaultState().with(SlabBlock.TYPE, SlabType.BOTTOM).with(SlabBlock.WATERLOGGED, false));
        structure.fillWithBlocks(world, start, -190, 1, -45, -188, 1, -43, Blocks.DIRT.getDefaultState());
        structure.fillWithBlocks(world, start, -190, 3, -57, -187, 3, -54, Blocks.DIRT.getDefaultState());
        structure.fillWithBlocks(world, start, -190, 3, -53, -190, 3, -53, Blocks.GRASS_BLOCK.getDefaultState().with(SnowyDirtBlock.SNOWY, false));
        structure.fillWithBlocks(world, start, -190, 3, -51, -188, 3, -49, Blocks.GRASS_BLOCK.getDefaultState().with(SnowyDirtBlock.SNOWY, false));
        structure.fillWithBlocks(world, start, -190, 3, -48, -187, 3, -45, Blocks.DIRT.getDefaultState());
        structure.fillWithBlocks(world, start, -190, 4, -55, -189, 4, -54, Blocks.STONE_BRICKS.getDefaultState());
        structure.fillWithBlocks(world, start, -190, 4, -52, -190, 19, -52, Blocks.OAK_LOG.getDefaultState());
        structure.fillWithBlocks(world, start, -190, 4, -48, -189, 5, -48, Blocks.STONE_BRICKS.getDefaultState());
        structure.fillWithBlocks(world, start, -190, 4, -47, -190, 4, -47, Blocks.DIRT.getDefaultState());
        structure.fillWithBlocks(world, start, -190, 5, -54, -189, 6, -54, Blocks.STONE_BRICKS.getDefaultState());
        structure.fillWithBlocks(world, start, -190, 5, -47, -190, 5, -47, Blocks.STONE_BRICK_STAIRS.getDefaultState().with(StairsBlock.FACING, Direction.NORTH).with(StairsBlock.WATERLOGGED, false).with(StairsBlock.SHAPE, StairsShape.STRAIGHT).with(StairsBlock.HALF, Half.BOTTOM));
        structure.fillWithBlocks(world, start, -190, 6, -48, -190, 6, -48, Blocks.STONE_BRICKS.getDefaultState());
        structure.fillWithBlocks(world, start, -190, 7, -54, -189, 7, -53, Blocks.STONE_BRICKS.getDefaultState());
        structure.fillWithBlocks(world, start, -190, 7, -51, -188, 7, -49, Blocks.STONE_BRICKS.getDefaultState());
        structure.fillWithBlocks(world, start, -190, 7, -48, -190, 7, -48, Blocks.STONE_BRICKS.getDefaultState());
        structure.fillWithBlocks(world, start, -190, 8, -54, -189, 8, -54, Blocks.STONE_BRICKS.getDefaultState());
        structure.fillWithBlocks(world, start, -190, 8, -53, -186, 8, -53, Blocks.SMOOTH_STONE_SLAB.getDefaultState().with(SlabBlock.TYPE, SlabType.BOTTOM).with(SlabBlock.WATERLOGGED, false));
        structure.fillWithBlocks(world, start, -190, 8, -51, -190, 8, -49, Blocks.SMOOTH_STONE_SLAB.getDefaultState().with(SlabBlock.TYPE, SlabType.BOTTOM).with(SlabBlock.WATERLOGGED, false));
        structure.fillWithBlocks(world, start, -190, 8, -48, -190, 8, -48, Blocks.STONE_BRICKS.getDefaultState());
        structure.fillWithBlocks(world, start, -190, 11, -54, -189, 11, -53, Blocks.STONE_BRICKS.getDefaultState());
        structure.fillWithBlocks(world, start, -190, 11, -51, -188, 11, -49, Blocks.STONE_BRICKS.getDefaultState());
        structure.fillWithBlocks(world, start, -190, 11, -48, -189, 12, -48, Blocks.STONE_BRICKS.getDefaultState());
        structure.fillWithBlocks(world, start, -190, 12, -54, -190, 14, -54, Blocks.STONE_BRICKS.getDefaultState());
        structure.fillWithBlocks(world, start, -190, 12, -53, -186, 12, -53, Blocks.OAK_PLANKS.getDefaultState());
        structure.fillWithBlocks(world, start, -190, 12, -51, -188, 12, -49, Blocks.OAK_PLANKS.getDefaultState());
        structure.fillWithBlocks(world, start, -190, 13, -50, -190, 19, -50, Blocks.OAK_LOG.getDefaultState());
        structure.fillWithBlocks(world, start, -190, 13, -48, -190, 14, -48, Blocks.STONE_BRICKS.getDefaultState());
        structure.fillWithBlocks(world, start, -190, 14, -53, -190, 16, -53, Blocks.STONE_BRICKS.getDefaultState());
        structure.fillWithBlocks(world, start, -190, 14, -49, -190, 14, -48, Blocks.STONE_BRICKS.getDefaultState());
        structure.fillWithBlocks(world, start, -190, 15, -49, -190, 16, -49, Blocks.STONE_BRICKS.getDefaultState());
        structure.fillWithBlocks(world, start, -190, 16, -51, -190, 16, -51, Blocks.STONE_BRICKS.getDefaultState());
        structure.fillWithBlocks(world, start, -190, 18, -51, -190, 20, -51, Blocks.STONE_BRICKS.getDefaultState());
        structure.fillWithBlocks(world, start, -190, 25, -51, -190, 25, -51, Blocks.STONE_BRICKS.getDefaultState());
        structure.fillWithBlocks(world, start, -190, 25, -50, -190, 25, -50, Blocks.OAK_SLAB.getDefaultState().with(SlabBlock.TYPE, SlabType.TOP).with(SlabBlock.WATERLOGGED, false));
        structure.fillWithBlocks(world, start, -190, 26, -52, -190, 29, -52, Blocks.OAK_LOG.getDefaultState());
        structure.fillWithBlocks(world, start, -190, 26, -50, -190, 29, -50, Blocks.OAK_LOG.getDefaultState());
        structure.fillWithBlocks(world, start, -190, 29, -51, -190, 30, -51, Blocks.OAK_PLANKS.getDefaultState());
        structure.fillWithBlocks(world, start, -189, 3, -53, -187, 3, -49, Blocks.GRASS_BLOCK.getDefaultState().with(SnowyDirtBlock.SNOWY, false));
        structure.fillWithBlocks(world, start, -189, 4, -56, -187, 4, -56, Blocks.DIRT.getDefaultState());
        structure.fillWithBlocks(world, start, -189, 4, -52, -189, 16, -52, Blocks.LADDER.getDefaultState().with(LadderBlock.FACING, Direction.EAST).with(LadderBlock.WATERLOGGED, false));
        structure.fillWithBlocks(world, start, -189, 4, -47, -188, 4, -46, Blocks.DIRT.getDefaultState());
        structure.fillWithBlocks(world, start, -189, 5, -55, -189, 6, -54, Blocks.STONE_BRICKS.getDefaultState());
        structure.fillWithBlocks(world, start, -189, 5, -47, -189, 9, -47, Blocks.STONE_BRICKS.getDefaultState());
        structure.fillWithBlocks(world, start, -189, 6, -48, -189, 7, -47, Blocks.STONE_BRICKS.getDefaultState());
        structure.fillWithBlocks(world, start, -189, 7, -55, -189, 8, -54, Blocks.STONE_BRICKS.getDefaultState());
        structure.fillWithBlocks(world, start, -189, 8, -49, -186, 8, -49, Blocks.SMOOTH_STONE_SLAB.getDefaultState().with(SlabBlock.TYPE, SlabType.BOTTOM).with(SlabBlock.WATERLOGGED, false));
        structure.fillWithBlocks(world, start, -189, 8, -48, -189, 9, -47, Blocks.STONE_BRICKS.getDefaultState());
        structure.fillWithBlocks(world, start, -189, 9, -55, -189, 9, -54, Blocks.STONE_BRICKS.getDefaultState());
        structure.fillWithBlocks(world, start, -189, 10, -55, -189, 11, -55, Blocks.STONE_BRICK_STAIRS.getDefaultState().with(StairsBlock.FACING, Direction.SOUTH).with(StairsBlock.WATERLOGGED, false).with(StairsBlock.SHAPE, StairsShape.STRAIGHT).with(StairsBlock.HALF, Half.TOP));
        structure.fillWithBlocks(world, start, -189, 10, -54, -189, 11, -54, Blocks.STONE_BRICKS.getDefaultState());
        structure.fillWithBlocks(world, start, -189, 10, -48, -189, 12, -48, Blocks.STONE_BRICKS.getDefaultState());
        structure.fillWithBlocks(world, start, -189, 10, -47, -189, 11, -47, Blocks.STONE_BRICK_STAIRS.getDefaultState().with(StairsBlock.FACING, Direction.NORTH).with(StairsBlock.WATERLOGGED, false).with(StairsBlock.SHAPE, StairsShape.STRAIGHT).with(StairsBlock.HALF, Half.TOP));
        structure.fillWithBlocks(world, start, -189, 12, -54, -187, 12, -54, Blocks.SMOOTH_STONE_SLAB.getDefaultState().with(SlabBlock.TYPE, SlabType.DOUBLE).with(SlabBlock.WATERLOGGED, false));
        structure.fillWithBlocks(world, start, -189, 13, -55, -188, 13, -54, Blocks.STONE_BRICK_SLAB.getDefaultState().with(SlabBlock.TYPE, SlabType.BOTTOM).with(SlabBlock.WATERLOGGED, false));
        structure.fillWithBlocks(world, start, -189, 13, -53, -189, 19, -53, Blocks.OAK_LOG.getDefaultState());
        structure.fillWithBlocks(world, start, -189, 13, -49, -189, 19, -49, Blocks.OAK_LOG.getDefaultState());
        structure.fillWithBlocks(world, start, -189, 13, -48, -188, 13, -47, Blocks.STONE_BRICK_SLAB.getDefaultState().with(SlabBlock.TYPE, SlabType.BOTTOM).with(SlabBlock.WATERLOGGED, false));
        structure.fillWithBlocks(world, start, -189, 16, -51, -188, 16, -50, Blocks.STONE_BRICKS.getDefaultState());
        structure.fillWithBlocks(world, start, -189, 20, -52, -189, 20, -50, Blocks.STONE_BRICKS.getDefaultState());
        structure.fillWithBlocks(world, start, -189, 21, -52, -189, 24, -52, Blocks.OAK_LOG.getDefaultState());
        structure.fillWithBlocks(world, start, -189, 21, -51, -189, 23, -51, Blocks.COBBLESTONE.getDefaultState());
        structure.fillWithBlocks(world, start, -189, 21, -50, -189, 24, -50, Blocks.OAK_LOG.getDefaultState());
        structure.fillWithBlocks(world, start, -189, 24, -51, -189, 25, -51, Blocks.STONE_BRICKS.getDefaultState());
        structure.fillWithBlocks(world, start, -189, 25, -52, -189, 25, -50, Blocks.STONE_BRICKS.getDefaultState());
        structure.fillWithBlocks(world, start, -189, 26, -53, -189, 29, -53, Blocks.OAK_LOG.getDefaultState());
        structure.fillWithBlocks(world, start, -189, 26, -49, -189, 29, -49, Blocks.OAK_LOG.getDefaultState());
        structure.fillWithBlocks(world, start, -189, 29, -54, -187, 29, -54, Blocks.OAK_STAIRS.getDefaultState().with(StairsBlock.FACING, Direction.SOUTH).with(StairsBlock.WATERLOGGED, false).with(StairsBlock.SHAPE, StairsShape.STRAIGHT).with(StairsBlock.HALF, Half.BOTTOM));
        structure.fillWithBlocks(world, start, -189, 29, -48, -187, 29, -48, Blocks.OAK_STAIRS.getDefaultState().with(StairsBlock.FACING, Direction.NORTH).with(StairsBlock.WATERLOGGED, false).with(StairsBlock.SHAPE, StairsShape.STRAIGHT).with(StairsBlock.HALF, Half.BOTTOM));
        structure.fillWithBlocks(world, start, -189, 30, -50, -189, 30, -50, Blocks.OAK_PLANKS.getDefaultState());
        structure.fillWithBlocks(world, start, -189, 31, -51, -189, 31, -51, Blocks.OAK_PLANKS.getDefaultState());
        structure.fillWithBlocks(world, start, -189, 37, -51, -189, 37, -51, Blocks.OAK_SLAB.getDefaultState().with(SlabBlock.TYPE, SlabType.BOTTOM).with(SlabBlock.WATERLOGGED, false));
        structure.fillWithBlocks(world, start, -188, 4, -57, -188, 4, -56, Blocks.DIRT.getDefaultState());
        structure.fillWithBlocks(world, start, -188, 4, -55, -188, 4, -55, Blocks.STONE_BRICKS.getDefaultState());
        structure.fillWithBlocks(world, start, -188, 4, -54, -188, 11, -54, Blocks.OAK_LOG.getDefaultState());
        structure.fillWithBlocks(world, start, -188, 4, -48, -188, 12, -48, Blocks.OAK_LOG.getDefaultState());
        structure.fillWithBlocks(world, start, -188, 5, -56, -188, 6, -55, Blocks.COBBLESTONE.getDefaultState());
        structure.fillWithBlocks(world, start, -188, 5, -47, -188, 6, -46, Blocks.COBBLESTONE.getDefaultState());
        structure.fillWithBlocks(world, start, -188, 7, -56, -188, 7, -55, Blocks.COBBLESTONE.getDefaultState());
        structure.fillWithBlocks(world, start, -188, 7, -53, -185, 7, -49, Blocks.STONE_BRICKS.getDefaultState());
        structure.fillWithBlocks(world, start, -188, 7, -47, -188, 7, -46, Blocks.COBBLESTONE.getDefaultState());
        structure.fillWithBlocks(world, start, -188, 8, -55, -188, 12, -55, Blocks.COBBLESTONE.getDefaultState());
        structure.fillWithBlocks(world, start, -188, 8, -47, -188, 12, -47, Blocks.COBBLESTONE.getDefaultState());
        structure.fillWithBlocks(world, start, -188, 11, -53, -186, 11, -49, Blocks.STONE_BRICKS.getDefaultState());
        structure.fillWithBlocks(world, start, -188, 12, -52, -186, 12, -49, Blocks.OAK_PLANKS.getDefaultState());
        structure.fillWithBlocks(world, start, -188, 16, -53, -188, 16, -49, Blocks.STONE_BRICKS.getDefaultState());
        structure.fillWithBlocks(world, start, -188, 17, -54, -188, 17, -53, Blocks.STONE_BRICKS.getDefaultState());
        structure.fillWithBlocks(world, start, -188, 17, -51, -188, 25, -51, Blocks.LADDER.getDefaultState().with(LadderBlock.FACING, Direction.WEST).with(LadderBlock.WATERLOGGED, false));
        structure.fillWithBlocks(world, start, -188, 17, -49, -188, 17, -48, Blocks.STONE_BRICKS.getDefaultState());
        structure.fillWithBlocks(world, start, -188, 18, -54, -188, 19, -54, Blocks.COBBLESTONE_WALL.getDefaultState().with(WallBlock.WATERLOGGED, false).with(WallBlock.UP, true).with(WallBlock.WALL_HEIGHT_NORTH, WallHeight.LOW).with(WallBlock.WALL_HEIGHT_SOUTH, WallHeight.LOW).with(WallBlock.WALL_HEIGHT_EAST, WallHeight.LOW).with(WallBlock.WALL_HEIGHT_WEST, WallHeight.LOW));
        structure.fillWithBlocks(world, start, -188, 18, -53, -188, 20, -53, Blocks.STONE_BRICKS.getDefaultState());
        structure.fillWithBlocks(world, start, -188, 18, -49, -188, 20, -49, Blocks.STONE_BRICKS.getDefaultState());
        structure.fillWithBlocks(world, start, -188, 18, -48, -188, 19, -48, Blocks.COBBLESTONE_WALL.getDefaultState().with(WallBlock.WATERLOGGED, false).with(WallBlock.UP, true).with(WallBlock.WALL_HEIGHT_NORTH, WallHeight.LOW).with(WallBlock.WALL_HEIGHT_SOUTH, WallHeight.LOW).with(WallBlock.WALL_HEIGHT_EAST, WallHeight.LOW).with(WallBlock.WALL_HEIGHT_WEST, WallHeight.LOW));
        structure.fillWithBlocks(world, start, -188, 20, -52, -188, 20, -52, Blocks.STONE_BRICKS.getDefaultState());
        structure.fillWithBlocks(world, start, -188, 20, -50, -188, 20, -49, Blocks.STONE_BRICKS.getDefaultState());
        structure.fillWithBlocks(world, start, -188, 21, -52, -188, 23, -52, Blocks.COBBLESTONE.getDefaultState());
        structure.fillWithBlocks(world, start, -188, 21, -50, -188, 23, -50, Blocks.COBBLESTONE.getDefaultState());
        structure.fillWithBlocks(world, start, -188, 24, -52, -188, 25, -52, Blocks.STONE_BRICKS.getDefaultState());
        structure.fillWithBlocks(world, start, -188, 24, -50, -188, 25, -50, Blocks.STONE_BRICKS.getDefaultState());
        structure.fillWithBlocks(world, start, -188, 25, -53, -188, 25, -52, Blocks.STONE_BRICKS.getDefaultState());
        structure.fillWithBlocks(world, start, -188, 29, -53, -188, 30, -53, Blocks.OAK_PLANKS.getDefaultState());
        structure.fillWithBlocks(world, start, -188, 29, -49, -188, 30, -49, Blocks.OAK_PLANKS.getDefaultState());
        structure.fillWithBlocks(world, start, -188, 31, -52, -188, 31, -52, Blocks.OAK_PLANKS.getDefaultState());
        structure.fillWithBlocks(world, start, -188, 32, -51, -188, 33, -51, Blocks.OAK_PLANKS.getDefaultState());
        structure.fillWithBlocks(world, start, -188, 34, -48, -188, 34, -47, Blocks.RED_WOOL.getDefaultState());
        structure.fillWithBlocks(world, start, -188, 35, -51, -188, 36, -51, Blocks.OAK_FENCE.getDefaultState().with(FourWayBlock.WATERLOGGED, false).with(FourWayBlock.NORTH, false).with(FourWayBlock.SOUTH, true).with(FourWayBlock.EAST, false).with(FourWayBlock.WEST, false));
        structure.fillWithBlocks(world, start, -188, 35, -50, -188, 35, -49, Blocks.RED_WOOL.getDefaultState());
        structure.fillWithBlocks(world, start, -188, 35, -48, -188, 35, -47, Blocks.WHITE_WOOL.getDefaultState());
        structure.fillWithBlocks(world, start, -188, 36, -50, -188, 36, -49, Blocks.WHITE_WOOL.getDefaultState());
        structure.fillWithBlocks(world, start, -188, 37, -52, -188, 37, -52, Blocks.OAK_SLAB.getDefaultState().with(SlabBlock.TYPE, SlabType.BOTTOM).with(SlabBlock.WATERLOGGED, false));
        structure.fillWithBlocks(world, start, -187, 1, -45, -186, 1, -43, Blocks.DIRT.getDefaultState());
        structure.fillWithBlocks(world, start, -187, 4, -57, -187, 4, -57, Blocks.GRASS_BLOCK.getDefaultState().with(SnowyDirtBlock.SNOWY, false));
        structure.fillWithBlocks(world, start, -187, 4, -55, -186, 4, -54, Blocks.STONE_BRICKS.getDefaultState());
        structure.fillWithBlocks(world, start, -187, 4, -48, -186, 5, -48, Blocks.STONE_BRICKS.getDefaultState());
        structure.fillWithBlocks(world, start, -187, 4, -47, -187, 4, -46, Blocks.DIRT.getDefaultState());
        structure.fillWithBlocks(world, start, -187, 4, -45, -182, 4, -45, Blocks.GRASS_BLOCK.getDefaultState().with(SnowyDirtBlock.SNOWY, false));
        structure.fillWithBlocks(world, start, -187, 5, -56, -187, 5, -56, Blocks.STONE_BRICK_STAIRS.getDefaultState().with(StairsBlock.FACING, Direction.SOUTH).with(StairsBlock.WATERLOGGED, false).with(StairsBlock.SHAPE, StairsShape.STRAIGHT).with(StairsBlock.HALF, Half.BOTTOM));
        structure.fillWithBlocks(world, start, -187, 5, -55, -187, 5, -54, Blocks.STONE_BRICKS.getDefaultState());
        structure.fillWithBlocks(world, start, -187, 5, -47, -187, 9, -47, Blocks.STONE_BRICKS.getDefaultState());
        structure.fillWithBlocks(world, start, -187, 6, -55, -187, 6, -54, Blocks.STONE_BRICKS.getDefaultState());
        structure.fillWithBlocks(world, start, -187, 6, -48, -187, 7, -47, Blocks.STONE_BRICKS.getDefaultState());
        structure.fillWithBlocks(world, start, -187, 7, -55, -187, 7, -47, Blocks.STONE_BRICKS.getDefaultState());
        structure.fillWithBlocks(world, start, -187, 8, -55, -187, 8, -54, Blocks.STONE_BRICKS.getDefaultState());
        structure.fillWithBlocks(world, start, -187, 8, -48, -187, 9, -47, Blocks.STONE_BRICKS.getDefaultState());
        structure.fillWithBlocks(world, start, -187, 9, -55, -187, 9, -54, Blocks.STONE_BRICKS.getDefaultState());
        structure.fillWithBlocks(world, start, -187, 10, -55, -187, 11, -55, Blocks.STONE_BRICK_STAIRS.getDefaultState().with(StairsBlock.FACING, Direction.SOUTH).with(StairsBlock.WATERLOGGED, false).with(StairsBlock.SHAPE, StairsShape.STRAIGHT).with(StairsBlock.HALF, Half.TOP));
        structure.fillWithBlocks(world, start, -187, 10, -54, -187, 11, -54, Blocks.STONE_BRICKS.getDefaultState());
        structure.fillWithBlocks(world, start, -187, 10, -48, -187, 12, -48, Blocks.STONE_BRICKS.getDefaultState());
        structure.fillWithBlocks(world, start, -187, 10, -47, -187, 11, -47, Blocks.STONE_BRICK_STAIRS.getDefaultState().with(StairsBlock.FACING, Direction.NORTH).with(StairsBlock.WATERLOGGED, false).with(StairsBlock.SHAPE, StairsShape.STRAIGHT).with(StairsBlock.HALF, Half.TOP));
        structure.fillWithBlocks(world, start, -187, 12, -55, -187, 12, -55, Blocks.STONE_BRICKS.getDefaultState());
        structure.fillWithBlocks(world, start, -187, 13, -55, -187, 13, -54, Blocks.STONE_BRICK_SLAB.getDefaultState().with(SlabBlock.TYPE, SlabType.BOTTOM).with(SlabBlock.WATERLOGGED, false));
        structure.fillWithBlocks(world, start, -187, 13, -53, -187, 19, -53, Blocks.OAK_LOG.getDefaultState());
        structure.fillWithBlocks(world, start, -187, 13, -49, -187, 19, -49, Blocks.OAK_LOG.getDefaultState());
        structure.fillWithBlocks(world, start, -187, 13, -48, -187, 13, -47, Blocks.STONE_BRICK_SLAB.getDefaultState().with(SlabBlock.TYPE, SlabType.BOTTOM).with(SlabBlock.WATERLOGGED, false));
        structure.fillWithBlocks(world, start, -187, 16, -52, -187, 16, -50, Blocks.STONE_BRICKS.getDefaultState());
        structure.fillWithBlocks(world, start, -187, 17, -51, -186, 18, -51, Blocks.STONE_BRICKS.getDefaultState());
        structure.fillWithBlocks(world, start, -187, 19, -51, -186, 20, -51, Blocks.STONE_BRICKS.getDefaultState());
        structure.fillWithBlocks(world, start, -187, 20, -52, -187, 20, -50, Blocks.STONE_BRICKS.getDefaultState());
        structure.fillWithBlocks(world, start, -187, 21, -52, -187, 24, -52, Blocks.OAK_LOG.getDefaultState());
        structure.fillWithBlocks(world, start, -187, 21, -51, -187, 23, -51, Blocks.COBBLESTONE.getDefaultState());
        structure.fillWithBlocks(world, start, -187, 21, -50, -187, 24, -50, Blocks.OAK_LOG.getDefaultState());
