package mod.arcalitegames.odyssey.world.structure.structures.ruins.stone_hedge;

import mod.arcalitegames.odyssey.world.structure.StructureBase;
import net.minecraft.block.Blocks;
import net.minecraft.block.SnowyDirtBlock;
import net.minecraft.util.math.BlockPos;
import net.minecraft.world.World;

public class StoneHedgeComponent1
{

	public static BlockPos start;
    public static World world;
    public static StructureBase structure;

    public static void init(World worldIn, BlockPos blockPos, StructureBase structureIn)
    {
        world = worldIn; start = blockPos; structure = structureIn;
    }
    
    public static void generatePart11()
    {
        structure.fillWithBlocks(world, start, 169, 7, 89, 174, 7, 94, Blocks.DIRT.getDefaultState());
        structure.fillWithBlocks(world, start, 169, 7, 103, 170, 7, 105, Blocks.GRASS_BLOCK.getDefaultState().with(SnowyDirtBlock.SNOWY, false));
        structure.fillWithBlocks(world, start, 169, 7, 107, 169, 7, 109, Blocks.WATER.getDefaultState());
        structure.fillWithBlocks(world, start, 169, 7, 110, 184, 7, 129, Blocks.GRASS_BLOCK.getDefaultState().with(SnowyDirtBlock.SNOWY, false));
        structure.fillWithBlocks(world, start, 169, 8, 26, 169, 8, 26, Blocks.GRASS.getDefaultState());
        structure.fillWithBlocks(world, start, 169, 8, 28, 170, 8, 30, Blocks.GRASS.getDefaultState());
        structure.fillWithBlocks(world, start, 169, 8, 32, 172, 8, 32, Blocks.GRASS.getDefaultState());
        structure.fillWithBlocks(world, start, 169, 8, 40, 169, 8, 42, Blocks.GRASS_BLOCK.getDefaultState().with(SnowyDirtBlock.SNOWY, false));
        structure.fillWithBlocks(world, start, 169, 8, 43, 169, 8, 46, Blocks.DIRT.getDefaultState());
        structure.fillWithBlocks(world, start, 169, 8, 47, 169, 8, 53, Blocks.GRASS_BLOCK.getDefaultState().with(SnowyDirtBlock.SNOWY, false));
        structure.fillWithBlocks(world, start, 169, 8, 56, 170, 8, 57, Blocks.GRASS.getDefaultState());
        structure.fillWithBlocks(world, start, 169, 8, 59, 170, 8, 61, Blocks.GRASS.getDefaultState());
        structure.fillWithBlocks(world, start, 169, 8, 63, 169, 8, 63, Blocks.GRASS.getDefaultState());
        structure.fillWithBlocks(world, start, 169, 8, 66, 169, 8, 66, Blocks.GRASS.getDefaultState());
        structure.fillWithBlocks(world, start, 169, 8, 68, 169, 8, 71, Blocks.GRASS.getDefaultState());
        structure.fillWithBlocks(world, start, 169, 8, 78, 170, 8, 79, Blocks.GRASS.getDefaultState());
        structure.fillWithBlocks(world, start, 169, 8, 80, 169, 8, 83, Blocks.GRASS.getDefaultState());
        structure.fillWithBlocks(world, start, 169, 8, 89, 171, 8, 91, Blocks.GRASS_BLOCK.getDefaultState().with(SnowyDirtBlock.SNOWY, false));
        structure.fillWithBlocks(world, start, 169, 8, 96, 170, 8, 97, Blocks.DIRT.getDefaultState());
        structure.fillWithBlocks(world, start, 169, 8, 100, 170, 8, 101, Blocks.GRASS_BLOCK.getDefaultState().with(SnowyDirtBlock.SNOWY, false));
        structure.fillWithBlocks(world, start, 169, 9, 40, 169, 9, 42, Blocks.GRASS.getDefaultState());
        structure.fillWithBlocks(world, start, 169, 9, 43, 169, 9, 46, Blocks.GRASS_BLOCK.getDefaultState().with(SnowyDirtBlock.SNOWY, false));
        structure.fillWithBlocks(world, start, 169, 9, 51, 169, 9, 52, Blocks.GRASS.getDefaultState());
        structure.fillWithBlocks(world, start, 169, 9, 89, 172, 9, 89, Blocks.GRASS.getDefaultState());
        structure.fillWithBlocks(world, start, 169, 9, 93, 169, 9, 95, Blocks.GRASS.getDefaultState());
        structure.fillWithBlocks(world, start, 169, 9, 96, 170, 9, 97, Blocks.GRASS_BLOCK.getDefaultState().with(SnowyDirtBlock.SNOWY, false));
        structure.fillWithBlocks(world, start, 169, 10, 43, 169, 10, 44, Blocks.GRASS.getDefaultState());
        structure.fillWithBlocks(world, start, 169, 10, 46, 169, 10, 46, Blocks.GRASS.getDefaultState());
        structure.fillWithBlocks(world, start, 169, 10, 96, 169, 10, 97, Blocks.GRASS.getDefaultState());
        structure.fillWithBlocks(world, start, 170, 1, 38, 177, 1, 46, Blocks.DIRT.getDefaultState());
        structure.fillWithBlocks(world, start, 170, 1, 51, 170, 1, 51, Blocks.DIRT.getDefaultState());
        structure.fillWithBlocks(world, start, 170, 1, 52, 170, 1, 109, Blocks.STONE.getDefaultState());
        structure.fillWithBlocks(world, start, 170, 1, 110, 176, 1, 118, Blocks.DIRT.getDefaultState());
        structure.fillWithBlocks(world, start, 170, 2, 12, 178, 2, 22, Blocks.STONE.getDefaultState());
        structure.fillWithBlocks(world, start, 170, 2, 31, 184, 2, 77, Blocks.DIRT.getDefaultState());
        structure.fillWithBlocks(world, start, 170, 2, 78, 172, 2, 87, Blocks.STONE.getDefaultState());
        structure.fillWithBlocks(world, start, 170, 2, 89, 189, 2, 129, Blocks.DIRT.getDefaultState());
        structure.fillWithBlocks(world, start, 170, 2, 130, 170, 2, 138, Blocks.STONE.getDefaultState());
        structure.fillWithBlocks(world, start, 170, 2, 139, 173, 2, 142, Blocks.DIRT.getDefaultState());
        structure.fillWithBlocks(world, start, 170, 2, 143, 170, 2, 150, Blocks.STONE.getDefaultState());
        structure.fillWithBlocks(world, start, 170, 4, 60, 170, 4, 60, Blocks.DIRT.getDefaultState());
        structure.fillWithBlocks(world, start, 170, 4, 61, 170, 4, 64, Blocks.GRASS_BLOCK.getDefaultState().with(SnowyDirtBlock.SNOWY, false));
        structure.fillWithBlocks(world, start, 170, 4, 65, 170, 4, 66, Blocks.DIRT.getDefaultState());
        structure.fillWithBlocks(world, start, 170, 5, 14, 171, 5, 15, Blocks.DIRT.getDefaultState());
        structure.fillWithBlocks(world, start, 170, 5, 16, 170, 5, 17, Blocks.DIRT.getDefaultState());
        structure.fillWithBlocks(world, start, 170, 5, 18, 170, 6, 18, Blocks.GRAVEL.getDefaultState());
        structure.fillWithBlocks(world, start, 170, 5, 19, 170, 5, 60, Blocks.DIRT.getDefaultState());
        structure.fillWithBlocks(world, start, 170, 5, 72, 171, 5, 73, Blocks.WATER.getDefaultState());
        structure.fillWithBlocks(world, start, 170, 5, 74, 170, 5, 78, Blocks.STONE.getDefaultState());
        structure.fillWithBlocks(world, start, 170, 5, 79, 170, 5, 80, Blocks.COAL_ORE.getDefaultState());
        structure.fillWithBlocks(world, start, 170, 5, 81, 173, 5, 85, Blocks.STONE.getDefaultState());
        structure.fillWithBlocks(world, start, 170, 5, 89, 170, 7, 93, Blocks.DIRT.getDefaultState());
        structure.fillWithBlocks(world, start, 170, 5, 94, 173, 5, 97, Blocks.STONE.getDefaultState());
        structure.fillWithBlocks(world, start, 170, 5, 98, 170, 6, 99, Blocks.DIRT.getDefaultState());
        structure.fillWithBlocks(world, start, 170, 5, 102, 172, 5, 102, Blocks.ANDESITE.getDefaultState());
        structure.fillWithBlocks(world, start, 170, 5, 103, 171, 5, 120, Blocks.STONE.getDefaultState());
        structure.fillWithBlocks(world, start, 170, 6, 14, 171, 6, 15, Blocks.GRASS_BLOCK.getDefaultState().with(SnowyDirtBlock.SNOWY, false));
        structure.fillWithBlocks(world, start, 170, 6, 16, 170, 6, 17, Blocks.GRASS_BLOCK.getDefaultState().with(SnowyDirtBlock.SNOWY, false));
        structure.fillWithBlocks(world, start, 170, 6, 19, 170, 6, 22, Blocks.GRASS_BLOCK.getDefaultState().with(SnowyDirtBlock.SNOWY, false));
        structure.fillWithBlocks(world, start, 170, 6, 117, 174, 6, 124, Blocks.DIRT.getDefaultState());
        structure.fillWithBlocks(world, start, 170, 6, 125, 170, 7, 125, Blocks.GRASS_BLOCK.getDefaultState().with(SnowyDirtBlock.SNOWY, false));
        structure.fillWithBlocks(world, start, 170, 6, 127, 172, 6, 129, Blocks.DIRT.getDefaultState());
        structure.fillWithBlocks(world, start, 170, 7, 10, 170, 7, 11, Blocks.GRASS.getDefaultState());
        structure.fillWithBlocks(world, start, 170, 7, 15, 170, 7, 17, Blocks.GRASS.getDefaultState());
        structure.fillWithBlocks(world, start, 170, 7, 32, 172, 7, 34, Blocks.GRASS_BLOCK.getDefaultState().with(SnowyDirtBlock.SNOWY, false));
        structure.fillWithBlocks(world, start, 170, 7, 35, 170, 7, 36, Blocks.WATER.getDefaultState());
        structure.fillWithBlocks(world, start, 170, 7, 37, 170, 7, 40, Blocks.GRASS_BLOCK.getDefaultState().with(SnowyDirtBlock.SNOWY, false));
        structure.fillWithBlocks(world, start, 170, 7, 41, 170, 7, 55, Blocks.DIRT.getDefaultState());
        structure.fillWithBlocks(world, start, 170, 7, 56, 170, 7, 86, Blocks.GRASS_BLOCK.getDefaultState().with(SnowyDirtBlock.SNOWY, false));
        structure.fillWithBlocks(world, start, 170, 7, 87, 175, 7, 92, Blocks.DIRT.getDefaultState());
        structure.fillWithBlocks(world, start, 170, 7, 102, 171, 7, 103, Blocks.GRASS_BLOCK.getDefaultState().with(SnowyDirtBlock.SNOWY, false));
        structure.fillWithBlocks(world, start, 170, 7, 106, 170, 7, 107, Blocks.WATER.getDefaultState());
        structure.fillWithBlocks(world, start, 170, 7, 108, 184, 7, 129, Blocks.GRASS_BLOCK.getDefaultState().with(SnowyDirtBlock.SNOWY, false));
        structure.fillWithBlocks(world, start, 170, 7, 142, 170, 7, 143, Blocks.GRASS.getDefaultState());
        structure.fillWithBlocks(world, start, 170, 8, 27, 171, 8, 29, Blocks.GRASS.getDefaultState());
        structure.fillWithBlocks(world, start, 170, 8, 39, 171, 8, 40, Blocks.GRASS.getDefaultState());
        structure.fillWithBlocks(world, start, 170, 8, 41, 170, 8, 44, Blocks.GRASS_BLOCK.getDefaultState().with(SnowyDirtBlock.SNOWY, false));
        structure.fillWithBlocks(world, start, 170, 8, 45, 170, 8, 48, Blocks.DIRT.getDefaultState());
        structure.fillWithBlocks(world, start, 170, 8, 49, 170, 8, 55, Blocks.GRASS_BLOCK.getDefaultState().with(SnowyDirtBlock.SNOWY, false));
        structure.fillWithBlocks(world, start, 170, 8, 58, 170, 8, 61, Blocks.GRASS.getDefaultState());
        structure.fillWithBlocks(world, start, 170, 8, 63, 170, 8, 68, Blocks.GRASS.getDefaultState());
        structure.fillWithBlocks(world, start, 170, 8, 71, 171, 8, 74, Blocks.GRASS.getDefaultState());
        structure.fillWithBlocks(world, start, 170, 8, 77, 170, 8, 79, Blocks.GRASS.getDefaultState());
        structure.fillWithBlocks(world, start, 170, 8, 83, 170, 8, 84, Blocks.GRASS.getDefaultState());
        structure.fillWithBlocks(world, start, 170, 8, 87, 172, 8, 89, Blocks.GRASS_BLOCK.getDefaultState().with(SnowyDirtBlock.SNOWY, false));
        structure.fillWithBlocks(world, start, 170, 8, 92, 170, 8, 93, Blocks.GRASS_BLOCK.getDefaultState().with(SnowyDirtBlock.SNOWY, false));
        structure.fillWithBlocks(world, start, 170, 8, 94, 171, 8, 95, Blocks.DIRT.getDefaultState());
        structure.fillWithBlocks(world, start, 170, 8, 98, 171, 8, 99, Blocks.GRASS_BLOCK.getDefaultState().with(SnowyDirtBlock.SNOWY, false));
        structure.fillWithBlocks(world, start, 170, 9, 43, 171, 9, 44, Blocks.GRASS.getDefaultState());
        structure.fillWithBlocks(world, start, 170, 9, 45, 170, 9, 48, Blocks.GRASS_BLOCK.getDefaultState().with(SnowyDirtBlock.SNOWY, false));
        structure.fillWithBlocks(world, start, 170, 9, 51, 170, 9, 51, Blocks.GRASS.getDefaultState());
        structure.fillWithBlocks(world, start, 170, 9, 53, 171, 9, 54, Blocks.GRASS.getDefaultState());
        structure.fillWithBlocks(world, start, 170, 9, 88, 171, 9, 89, Blocks.GRASS.getDefaultState());
        structure.fillWithBlocks(world, start, 170, 9, 94, 171, 9, 95, Blocks.GRASS_BLOCK.getDefaultState().with(SnowyDirtBlock.SNOWY, false));
        structure.fillWithBlocks(world, start, 170, 10, 46, 170, 10, 48, Blocks.GRASS.getDefaultState());
        structure.fillWithBlocks(world, start, 171, 0, 156, 172, 0, 157, Blocks.STONE.getDefaultState());
        structure.fillWithBlocks(world, start, 171, 0, 163, 172, 0, 164, Blocks.GRASS_BLOCK.getDefaultState().with(SnowyDirtBlock.SNOWY, false));
        structure.fillWithBlocks(world, start, 171, 1, 37, 178, 1, 44, Blocks.DIRT.getDefaultState());
        structure.fillWithBlocks(world, start, 171, 1, 51, 172, 1, 52, Blocks.DIRT.getDefaultState());
        structure.fillWithBlocks(world, start, 171, 1, 53, 171, 1, 59, Blocks.STONE.getDefaultState());
        structure.fillWithBlocks(world, start, 171, 1, 60, 174, 1, 63, Blocks.DIRT.getDefaultState());
        structure.fillWithBlocks(world, start, 171, 1, 64, 171, 1, 108, Blocks.STONE.getDefaultState());
        structure.fillWithBlocks(world, start, 171, 1, 109, 177, 1, 116, Blocks.DIRT.getDefaultState());
        structure.fillWithBlocks(world, start, 171, 1, 153, 172, 1, 154, Blocks.STONE.getDefaultState());
        structure.fillWithBlocks(world, start, 171, 1, 155, 175, 1, 159, Blocks.DIRT.getDefaultState());
        structure.fillWithBlocks(world, start, 171, 2, 1, 171, 3, 2, Blocks.DIRT.getDefaultState());
        structure.fillWithBlocks(world, start, 171, 2, 10, 178, 2, 22, Blocks.STONE.getDefaultState());
        structure.fillWithBlocks(world, start, 171, 2, 88, 189, 2, 130, Blocks.DIRT.getDefaultState());
        structure.fillWithBlocks(world, start, 171, 2, 131, 171, 2, 135, Blocks.STONE.getDefaultState());
        structure.fillWithBlocks(world, start, 171, 2, 136, 178, 2, 143, Blocks.DIRT.getDefaultState());
        structure.fillWithBlocks(world, start, 171, 2, 144, 171, 2, 149, Blocks.STONE.getDefaultState());
        structure.fillWithBlocks(world, start, 171, 2, 150, 178, 2, 157, Blocks.DIRT.getDefaultState());
        structure.fillWithBlocks(world, start, 171, 2, 159, 172, 2, 160, Blocks.GRASS_BLOCK.getDefaultState().with(SnowyDirtBlock.SNOWY, false));
        structure.fillWithBlocks(world, start, 171, 4, 60, 172, 4, 61, Blocks.DIRT.getDefaultState());
        structure.fillWithBlocks(world, start, 171, 4, 62, 172, 4, 67, Blocks.GRASS_BLOCK.getDefaultState().with(SnowyDirtBlock.SNOWY, false));
        structure.fillWithBlocks(world, start, 171, 4, 155, 172, 4, 157, Blocks.GRASS_BLOCK.getDefaultState().with(SnowyDirtBlock.SNOWY, false));
        structure.fillWithBlocks(world, start, 171, 5, 1, 171, 5, 2, Blocks.GRASS_BLOCK.getDefaultState().with(SnowyDirtBlock.SNOWY, false));
        structure.fillWithBlocks(world, start, 171, 5, 18, 173, 5, 20, Blocks.WATER.getDefaultState());
        structure.fillWithBlocks(world, start, 171, 5, 22, 171, 6, 59, Blocks.DIRT.getDefaultState());
        structure.fillWithBlocks(world, start, 171, 5, 74, 173, 5, 74, Blocks.STONE.getDefaultState());
        structure.fillWithBlocks(world, start, 171, 5, 75, 172, 5, 76, Blocks.COAL_ORE.getDefaultState());
        structure.fillWithBlocks(world, start, 171, 5, 77, 172, 5, 78, Blocks.STONE.getDefaultState());
        structure.fillWithBlocks(world, start, 171, 5, 79, 171, 5, 98, Blocks.STONE.getDefaultState());
        structure.fillWithBlocks(world, start, 171, 5, 99, 171, 5, 102, Blocks.ANDESITE.getDefaultState());
        structure.fillWithBlocks(world, start, 171, 5, 150, 174, 5, 154, Blocks.GRASS_BLOCK.getDefaultState().with(SnowyDirtBlock.SNOWY, false));
        structure.fillWithBlocks(world, start, 171, 6, 115, 177, 6, 121, Blocks.DIRT.getDefaultState());
        structure.fillWithBlocks(world, start, 171, 6, 125, 175, 6, 129, Blocks.DIRT.getDefaultState());
        structure.fillWithBlocks(world, start, 171, 7, 13, 171, 7, 14, Blocks.GRASS.getDefaultState());
        structure.fillWithBlocks(world, start, 171, 7, 22, 171, 7, 35, Blocks.GRASS_BLOCK.getDefaultState().with(SnowyDirtBlock.SNOWY, false));
        structure.fillWithBlocks(world, start, 171, 7, 36, 171, 7, 38, Blocks.WATER.getDefaultState());
        structure.fillWithBlocks(world, start, 171, 7, 39, 171, 7, 42, Blocks.GRASS_BLOCK.getDefaultState().with(SnowyDirtBlock.SNOWY, false));
        structure.fillWithBlocks(world, start, 171, 7, 43, 171, 7, 59, Blocks.DIRT.getDefaultState());
        structure.fillWithBlocks(world, start, 171, 7, 60, 171, 7, 82, Blocks.GRASS_BLOCK.getDefaultState().with(SnowyDirtBlock.SNOWY, false));
        structure.fillWithBlocks(world, start, 171, 7, 83, 176, 7, 89, Blocks.DIRT.getDefaultState());
        structure.fillWithBlocks(world, start, 171, 7, 100, 172, 7, 102, Blocks.GRASS_BLOCK.getDefaultState().with(SnowyDirtBlock.SNOWY, false));
        structure.fillWithBlocks(world, start, 171, 7, 104, 172, 7, 105, Blocks.WATER.getDefaultState());
        structure.fillWithBlocks(world, start, 171, 7, 107, 184, 7, 129, Blocks.GRASS_BLOCK.getDefaultState().with(SnowyDirtBlock.SNOWY, false));
        structure.fillWithBlocks(world, start, 171, 7, 145, 171, 7, 146, Blocks.GRASS.getDefaultState());
        structure.fillWithBlocks(world, start, 171, 8, 26, 171, 8, 29, Blocks.GRASS.getDefaultState());
        structure.fillWithBlocks(world, start, 171, 8, 31, 172, 8, 32, Blocks.GRASS.getDefaultState());
        structure.fillWithBlocks(world, start, 171, 8, 43, 171, 8, 46, Blocks.GRASS_BLOCK.getDefaultState().with(SnowyDirtBlock.SNOWY, false));
        structure.fillWithBlocks(world, start, 171, 8, 47, 171, 8, 50, Blocks.DIRT.getDefaultState());
        structure.fillWithBlocks(world, start, 171, 8, 51, 171, 8, 59, Blocks.GRASS_BLOCK.getDefaultState().with(SnowyDirtBlock.SNOWY, false));
        structure.fillWithBlocks(world, start, 171, 8, 64, 171, 8, 69, Blocks.GRASS.getDefaultState());
        structure.fillWithBlocks(world, start, 171, 8, 78, 171, 8, 80, Blocks.GRASS.getDefaultState());
        structure.fillWithBlocks(world, start, 171, 8, 83, 173, 8, 86, Blocks.GRASS_BLOCK.getDefaultState().with(SnowyDirtBlock.SNOWY, false));
        structure.fillWithBlocks(world, start, 171, 8, 92, 172, 8, 94, Blocks.DIRT.getDefaultState());
        structure.fillWithBlocks(world, start, 171, 8, 96, 172, 8, 98, Blocks.GRASS_BLOCK.getDefaultState().with(SnowyDirtBlock.SNOWY, false));
        structure.fillWithBlocks(world, start, 171, 8, 100, 172, 8, 101, Blocks.GRASS.getDefaultState());
        structure.fillWithBlocks(world, start, 171, 9, 45, 172, 9, 46, Blocks.GRASS.getDefaultState());
        structure.fillWithBlocks(world, start, 171, 9, 47, 171, 9, 50, Blocks.GRASS_BLOCK.getDefaultState().with(SnowyDirtBlock.SNOWY, false));
        structure.fillWithBlocks(world, start, 171, 9, 51, 171, 9, 59, Blocks.GRASS.getDefaultState());
        structure.fillWithBlocks(world, start, 171, 9, 87, 171, 9, 90, Blocks.GRASS.getDefaultState());
        structure.fillWithBlocks(world, start, 171, 9, 92, 172, 9, 94, Blocks.GRASS_BLOCK.getDefaultState().with(SnowyDirtBlock.SNOWY, false));
        structure.fillWithBlocks(world, start, 171, 10, 48, 171, 10, 48, Blocks.GRASS.getDefaultState());
        structure.fillWithBlocks(world, start, 171, 10, 93, 171, 10, 93, Blocks.GRASS.getDefaultState());
        structure.fillWithBlocks(world, start, 172, 1, 36, 178, 1, 44, Blocks.DIRT.getDefaultState());
        structure.fillWithBlocks(world, start, 172, 1, 53, 172, 1, 53, Blocks.DIRT.getDefaultState());
        structure.fillWithBlocks(world, start, 172, 1, 54, 172, 1, 56, Blocks.STONE.getDefaultState());
        structure.fillWithBlocks(world, start, 172, 1, 57, 179, 1, 64, Blocks.DIRT.getDefaultState());
        structure.fillWithBlocks(world, start, 172, 1, 65, 172, 1, 96, Blocks.STONE.getDefaultState());
        structure.fillWithBlocks(world, start, 172, 1, 97, 174, 1, 99, Blocks.DIRT.getDefaultState());
        structure.fillWithBlocks(world, start, 172, 1, 100, 172, 1, 106, Blocks.STONE.getDefaultState());
        structure.fillWithBlocks(world, start, 172, 1, 107, 177, 1, 116, Blocks.DIRT.getDefaultState());
        structure.fillWithBlocks(world, start, 172, 2, 1, 180, 4, 1, Blocks.DIRT.getDefaultState());
        structure.fillWithBlocks(world, start, 172, 2, 2, 175, 2, 28, Blocks.STONE.getDefaultState());
        structure.fillWithBlocks(world, start, 172, 2, 30, 185, 2, 45, Blocks.DIRT.getDefaultState());
        structure.fillWithBlocks(world, start, 172, 2, 131, 185, 2, 144, Blocks.DIRT.getDefaultState());
        structure.fillWithBlocks(world, start, 172, 2, 145, 172, 2, 149, Blocks.STONE.getDefaultState());
        structure.fillWithBlocks(world, start, 172, 4, 68, 200, 4, 123, Blocks.DIRT.getDefaultState());
        structure.fillWithBlocks(world, start, 172, 5, 1, 180, 5, 1, Blocks.GRASS_BLOCK.getDefaultState().with(SnowyDirtBlock.SNOWY, false));
        structure.fillWithBlocks(world, start, 172, 5, 2, 175, 5, 13, Blocks.DIRT.getDefaultState());
        structure.fillWithBlocks(world, start, 172, 5, 15, 175, 5, 15, Blocks.GRASS_BLOCK.getDefaultState().with(SnowyDirtBlock.SNOWY, false));
        structure.fillWithBlocks(world, start, 172, 5, 16, 174, 5, 19, Blocks.WATER.getDefaultState());
        structure.fillWithBlocks(world, start, 172, 5, 21, 172, 5, 22, Blocks.WATER.getDefaultState());
        structure.fillWithBlocks(world, start, 172, 5, 24, 195, 5, 59, Blocks.DIRT.getDefaultState());
        structure.fillWithBlocks(world, start, 172, 5, 60, 172, 7, 60, Blocks.DIRT.getDefaultState());
        structure.fillWithBlocks(world, start, 172, 5, 68, 174, 5, 73, Blocks.STONE.getDefaultState());
        structure.fillWithBlocks(world, start, 172, 5, 79, 172, 7, 79, Blocks.DIRT.getDefaultState());
        structure.fillWithBlocks(world, start, 172, 5, 80, 173, 5, 85, Blocks.STONE.getDefaultState());
        structure.fillWithBlocks(world, start, 172, 5, 86, 173, 5, 88, Blocks.GRAVEL.getDefaultState());
        structure.fillWithBlocks(world, start, 172, 5, 89, 172, 5, 98, Blocks.STONE.getDefaultState());
        structure.fillWithBlocks(world, start, 172, 5, 100, 173, 5, 101, Blocks.COAL_ORE.getDefaultState());
        structure.fillWithBlocks(world, start, 172, 5, 103, 173, 5, 104, Blocks.STONE.getDefaultState());
        structure.fillWithBlocks(world, start, 172, 5, 105, 173, 5, 107, Blocks.DIORITE.getDefaultState());
        structure.fillWithBlocks(world, start, 172, 5, 108, 172, 5, 120, Blocks.STONE.getDefaultState());
        structure.fillWithBlocks(world, start, 172, 5, 121, 173, 5, 122, Blocks.DIRT.getDefaultState());
        structure.fillWithBlocks(world, start, 172, 6, 2, 175, 6, 13, Blocks.GRASS_BLOCK.getDefaultState().with(SnowyDirtBlock.SNOWY, false));
        structure.fillWithBlocks(world, start, 172, 6, 24, 172, 6, 129, Blocks.DIRT.getDefaultState());
        structure.fillWithBlocks(world, start, 172, 7, 13, 174, 7, 13, Blocks.GRASS.getDefaultState());
        structure.fillWithBlocks(world, start, 172, 7, 35, 173, 7, 36, Blocks.GRASS_BLOCK.getDefaultState().with(SnowyDirtBlock.SNOWY, false));
        structure.fillWithBlocks(world, start, 172, 7, 37, 172, 7, 39, Blocks.WATER.getDefaultState());
        structure.fillWithBlocks(world, start, 172, 7, 40, 172, 7, 43, Blocks.GRASS_BLOCK.getDefaultState().with(SnowyDirtBlock.SNOWY, false));
        structure.fillWithBlocks(world, start, 172, 7, 44, 172, 7, 64, Blocks.DIRT.getDefaultState());
        structure.fillWithBlocks(world, start, 172, 7, 65, 172, 7, 77, Blocks.GRASS_BLOCK.getDefaultState().with(SnowyDirtBlock.SNOWY, false));
        structure.fillWithBlocks(world, start, 172, 7, 78, 177, 7, 87, Blocks.DIRT.getDefaultState());
        structure.fillWithBlocks(world, start, 172, 7, 99, 173, 7, 100, Blocks.GRASS_BLOCK.getDefaultState().with(SnowyDirtBlock.SNOWY, false));
        structure.fillWithBlocks(world, start, 172, 7, 103, 172, 7, 105, Blocks.WATER.getDefaultState());
        structure.fillWithBlocks(world, start, 172, 7, 106, 184, 7, 129, Blocks.GRASS_BLOCK.getDefaultState().with(SnowyDirtBlock.SNOWY, false));
        structure.fillWithBlocks(world, start, 172, 7, 139, 172, 7, 141, Blocks.GRASS.getDefaultState());
        structure.fillWithBlocks(world, start, 172, 8, 33, 172, 8, 34, Blocks.GRASS.getDefaultState());
        structure.fillWithBlocks(world, start, 172, 8, 44, 172, 8, 47, Blocks.GRASS_BLOCK.getDefaultState().with(SnowyDirtBlock.SNOWY, false));
        structure.fillWithBlocks(world, start, 172, 8, 48, 172, 8, 52, Blocks.DIRT.getDefaultState());
        structure.fillWithBlocks(world, start, 172, 8, 53, 172, 8, 64, Blocks.GRASS_BLOCK.getDefaultState().with(SnowyDirtBlock.SNOWY, false));
        structure.fillWithBlocks(world, start, 172, 8, 72, 172, 8, 73, Blocks.GRASS.getDefaultState());
        structure.fillWithBlocks(world, start, 172, 8, 78, 174, 8, 83, Blocks.GRASS_BLOCK.getDefaultState().with(SnowyDirtBlock.SNOWY, false));
        structure.fillWithBlocks(world, start, 172, 8, 90, 173, 8, 91, Blocks.DIRT.getDefaultState());
        structure.fillWithBlocks(world, start, 172, 8, 95, 173, 8, 96, Blocks.GRASS_BLOCK.getDefaultState().with(SnowyDirtBlock.SNOWY, false));
        structure.fillWithBlocks(world, start, 172, 8, 99, 172, 8, 101, Blocks.GRASS.getDefaultState());
        structure.fillWithBlocks(world, start, 172, 9, 44, 172, 9, 47, Blocks.GRASS.getDefaultState());
        structure.fillWithBlocks(world, start, 172, 9, 48, 172, 9, 52, Blocks.GRASS_BLOCK.getDefaultState().with(SnowyDirtBlock.SNOWY, false));
        structure.fillWithBlocks(world, start, 172, 9, 53, 172, 9, 55, Blocks.GRASS.getDefaultState());
        structure.fillWithBlocks(world, start, 172, 9, 57, 173, 9, 59, Blocks.GRASS.getDefaultState());
        structure.fillWithBlocks(world, start, 172, 9, 60, 172, 9, 61, Blocks.GRASS.getDefaultState());
        structure.fillWithBlocks(world, start, 172, 9, 64, 173, 9, 64, Blocks.GRASS.getDefaultState());
        structure.fillWithBlocks(world, start, 172, 9, 79, 172, 9, 79, Blocks.GRASS.getDefaultState());
        structure.fillWithBlocks(world, start, 172, 9, 81, 173, 9, 84, Blocks.GRASS.getDefaultState());
        structure.fillWithBlocks(world, start, 172, 9, 88, 172, 9, 89, Blocks.GRASS.getDefaultState());
        structure.fillWithBlocks(world, start, 172, 9, 90, 173, 9, 91, Blocks.GRASS_BLOCK.getDefaultState().with(SnowyDirtBlock.SNOWY, false));
        structure.fillWithBlocks(world, start, 172, 9, 95, 173, 9, 96, Blocks.GRASS.getDefaultState());
        structure.fillWithBlocks(world, start, 172, 10, 48, 172, 10, 52, Blocks.GRASS.getDefaultState());
        structure.fillWithBlocks(world, start, 172, 10, 90, 172, 10, 91, Blocks.GRASS.getDefaultState());
        structure.fillWithBlocks(world, start, 173, 0, 156, 175, 0, 156, Blocks.STONE.getDefaultState());
        structure.fillWithBlocks(world, start, 173, 0, 157, 177, 0, 161, Blocks.DIRT.getDefaultState());
        structure.fillWithBlocks(world, start, 173, 0, 162, 174, 0, 163, Blocks.GRASS_BLOCK.getDefaultState().with(SnowyDirtBlock.SNOWY, false));
        structure.fillWithBlocks(world, start, 173, 1, 1, 180, 4, 1, Blocks.DIRT.getDefaultState());
        structure.fillWithBlocks(world, start, 173, 1, 35, 179, 1, 42, Blocks.DIRT.getDefaultState());
        structure.fillWithBlocks(world, start, 173, 1, 51, 176, 1, 65, Blocks.DIRT.getDefaultState());
        structure.fillWithBlocks(world, start, 173, 1, 66, 173, 1, 94, Blocks.STONE.getDefaultState());
        structure.fillWithBlocks(world, start, 173, 1, 95, 183, 1, 105, Blocks.DIRT.getDefaultState());
        structure.fillWithBlocks(world, start, 173, 1, 106, 178, 1, 112, Blocks.DIRT.getDefaultState());
        structure.fillWithBlocks(world, start, 173, 1, 119, 174, 2, 119, Blocks.DIRT.getDefaultState());
        structure.fillWithBlocks(world, start, 173, 1, 120, 188, 1, 137, Blocks.STONE.getDefaultState());
        structure.fillWithBlocks(world, start, 173, 1, 153, 174, 1, 154, Blocks.STONE.getDefaultState());
        structure.fillWithBlocks(world, start, 173, 2, 78, 173, 2, 78, Blocks.DIRT.getDefaultState());
        structure.fillWithBlocks(world, start, 173, 2, 87, 190, 2, 105, Blocks.DIRT.getDefaultState());
        structure.fillWithBlocks(world, start, 173, 2, 145, 180, 5, 145, Blocks.DIRT.getDefaultState());
        structure.fillWithBlocks(world, start, 173, 2, 146, 174, 2, 148, Blocks.STONE.getDefaultState());
        structure.fillWithBlocks(world, start, 173, 2, 159, 174, 2, 160, Blocks.GRASS_BLOCK.getDefaultState().with(SnowyDirtBlock.SNOWY, false));
        structure.fillWithBlocks(world, start, 173, 3, 157, 174, 3, 158, Blocks.GRASS_BLOCK.getDefaultState().with(SnowyDirtBlock.SNOWY, false));
        structure.fillWithBlocks(world, start, 173, 4, 60, 176, 4, 63, Blocks.DIRT.getDefaultState());
        structure.fillWithBlocks(world, start, 173, 4, 64, 173, 4, 66, Blocks.GRASS_BLOCK.getDefaultState().with(SnowyDirtBlock.SNOWY, false));
        structure.fillWithBlocks(world, start, 173, 4, 67, 200, 4, 123, Blocks.DIRT.getDefaultState());
        structure.fillWithBlocks(world, start, 173, 4, 155, 174, 4, 156, Blocks.GRASS_BLOCK.getDefaultState().with(SnowyDirtBlock.SNOWY, false));
        structure.fillWithBlocks(world, start, 173, 5, 14, 173, 5, 15, Blocks.GRASS_BLOCK.getDefaultState().with(SnowyDirtBlock.SNOWY, false));
        structure.fillWithBlocks(world, start, 173, 5, 23, 180, 5, 59, Blocks.DIRT.getDefaultState());
        structure.fillWithBlocks(world, start, 173, 5, 60, 174, 5, 60, Blocks.STONE.getDefaultState());
        structure.fillWithBlocks(world, start, 173, 5, 67, 174, 5, 73, Blocks.STONE.getDefaultState());
        structure.fillWithBlocks(world, start, 173, 5, 75, 173, 5, 85, Blocks.STONE.getDefaultState());
        structure.fillWithBlocks(world, start, 173, 5, 89, 173, 5, 89, Blocks.GRAVEL.getDefaultState());
        structure.fillWithBlocks(world, start, 173, 5, 90, 173, 5, 98, Blocks.STONE.getDefaultState());
        structure.fillWithBlocks(world, start, 173, 5, 99, 174, 5, 100, Blocks.COAL_ORE.getDefaultState());
        structure.fillWithBlocks(world, start, 173, 5, 102, 173, 5, 104, Blocks.STONE.getDefaultState());
        structure.fillWithBlocks(world, start, 173, 5, 108, 173, 5, 109, Blocks.DIORITE.getDefaultState());
        structure.fillWithBlocks(world, start, 173, 5, 110, 173, 5, 120, Blocks.STONE.getDefaultState());
        structure.fillWithBlocks(world, start, 173, 5, 123, 180, 5, 145, Blocks.DIRT.getDefaultState());
        structure.fillWithBlocks(world, start, 173, 6, 14, 173, 6, 15, Blocks.GRASS.getDefaultState());
        structure.fillWithBlocks(world, start, 173, 6, 23, 175, 6, 25, Blocks.GRASS_BLOCK.getDefaultState().with(SnowyDirtBlock.SNOWY, false));
        structure.fillWithBlocks(world, start, 173, 6, 26, 173, 6, 107, Blocks.DIRT.getDefaultState());
        structure.fillWithBlocks(world, start, 173, 6, 109, 178, 6, 121, Blocks.DIRT.getDefaultState());
        structure.fillWithBlocks(world, start, 173, 7, 24, 173, 7, 24, Blocks.GRASS.getDefaultState());
        structure.fillWithBlocks(world, start, 173, 7, 26, 173, 7, 38, Blocks.GRASS_BLOCK.getDefaultState().with(SnowyDirtBlock.SNOWY, false));
        structure.fillWithBlocks(world, start, 173, 7, 39, 173, 7, 41, Blocks.WATER.getDefaultState());
        structure.fillWithBlocks(world, start, 173, 7, 42, 173, 7, 45, Blocks.GRASS_BLOCK.getDefaultState().with(SnowyDirtBlock.SNOWY, false));
        structure.fillWithBlocks(world, start, 173, 7, 46, 173, 7, 96, Blocks.DIRT.getDefaultState());
        structure.fillWithBlocks(world, start, 173, 7, 97, 174, 7, 99, Blocks.GRASS_BLOCK.getDefaultState().with(SnowyDirtBlock.SNOWY, false));
        structure.fillWithBlocks(world, start, 173, 7, 101, 174, 7, 102, Blocks.WATER.getDefaultState());
        structure.fillWithBlocks(world, start, 173, 7, 104, 184, 7, 129, Blocks.GRASS_BLOCK.getDefaultState().with(SnowyDirtBlock.SNOWY, false));
        structure.fillWithBlocks(world, start, 173, 8, 31, 173, 8, 31, Blocks.GRASS.getDefaultState());
        structure.fillWithBlocks(world, start, 173, 8, 33, 173, 8, 33, Blocks.GRASS.getDefaultState());
        structure.fillWithBlocks(world, start, 173, 8, 46, 173, 8, 50, Blocks.GRASS_BLOCK.getDefaultState().with(SnowyDirtBlock.SNOWY, false));
        structure.fillWithBlocks(world, start, 173, 8, 51, 173, 8, 55, Blocks.DIRT.getDefaultState());
        structure.fillWithBlocks(world, start, 173, 8, 56, 173, 8, 86, Blocks.GRASS_BLOCK.getDefaultState().with(SnowyDirtBlock.SNOWY, false));
        structure.fillWithBlocks(world, start, 173, 8, 87, 174, 8, 89, Blocks.DIRT.getDefaultState());
        structure.fillWithBlocks(world, start, 173, 8, 92, 174, 8, 94, Blocks.GRASS_BLOCK.getDefaultState().with(SnowyDirtBlock.SNOWY, false));
        structure.fillWithBlocks(world, start, 173, 8, 97, 173, 8, 99, Blocks.GRASS.getDefaultState());
        structure.fillWithBlocks(world, start, 173, 9, 46, 173, 9, 50, Blocks.GRASS.getDefaultState());
        structure.fillWithBlocks(world, start, 173, 9, 51, 173, 9, 55, Blocks.GRASS_BLOCK.getDefaultState().with(SnowyDirtBlock.SNOWY, false));
        structure.fillWithBlocks(world, start, 173, 9, 56, 173, 9, 59, Blocks.GRASS.getDefaultState());
        structure.fillWithBlocks(world, start, 173, 9, 66, 175, 9, 77, Blocks.GRASS.getDefaultState());
        structure.fillWithBlocks(world, start, 173, 9, 78, 173, 9, 78, Blocks.GRASS.getDefaultState());
        structure.fillWithBlocks(world, start, 173, 9, 80, 173, 9, 85, Blocks.GRASS.getDefaultState());
        structure.fillWithBlocks(world, start, 173, 9, 87, 174, 9, 89, Blocks.GRASS_BLOCK.getDefaultState().with(SnowyDirtBlock.SNOWY, false));
        structure.fillWithBlocks(world, start, 173, 10, 54, 174, 10, 55, Blocks.GRASS.getDefaultState());
        structure.fillWithBlocks(world, start, 173, 10, 87, 173, 10, 88, Blocks.GRASS.getDefaultState());
        structure.fillWithBlocks(world, start, 174, 0, 0, 175, 0, 156, Blocks.STONE.getDefaultState());
        structure.fillWithBlocks(world, start, 174, 1, 34, 180, 1, 41, Blocks.DIRT.getDefaultState());
        structure.fillWithBlocks(world, start, 174, 1, 66, 174, 1, 66, Blocks.DIRT.getDefaultState());
        structure.fillWithBlocks(world, start, 174, 1, 67, 174, 1, 93, Blocks.STONE.getDefaultState());
        structure.fillWithBlocks(world, start, 174, 1, 94, 184, 1, 104, Blocks.DIRT.getDefaultState());
        structure.fillWithBlocks(world, start, 174, 2, 29, 186, 2, 42, Blocks.DIRT.getDefaultState());
        structure.fillWithBlocks(world, start, 174, 2, 78, 175, 2, 79, Blocks.DIRT.getDefaultState());
        structure.fillWithBlocks(world, start, 174, 2, 80, 174, 2, 85, Blocks.STONE.getDefaultState());
        structure.fillWithBlocks(world, start, 174, 2, 86, 191, 2, 103, Blocks.DIRT.getDefaultState());
        structure.fillWithBlocks(world, start, 174, 2, 149, 181, 2, 156, Blocks.DIRT.getDefaultState());
        structure.fillWithBlocks(world, start, 174, 4, 0, 175, 4, 153, Blocks.DIRT.getDefaultState());
        structure.fillWithBlocks(world, start, 174, 5, 0, 175, 5, 1, Blocks.GRASS_BLOCK.getDefaultState().with(SnowyDirtBlock.SNOWY, false));
        structure.fillWithBlocks(world, start, 174, 5, 14, 191, 5, 14, Blocks.DIRT.getDefaultState());
        structure.fillWithBlocks(world, start, 174, 5, 21, 179, 5, 59, Blocks.DIRT.getDefaultState());
        structure.fillWithBlocks(world, start, 174, 5, 66, 179, 7, 66, Blocks.DIRT.getDefaultState());
        structure.fillWithBlocks(world, start, 174, 5, 74, 174, 5, 74, Blocks.GRAVEL.getDefaultState());
        structure.fillWithBlocks(world, start, 174, 5, 75, 174, 5, 75, Blocks.STONE.getDefaultState());
        structure.fillWithBlocks(world, start, 174, 5, 76, 174, 5, 76, Blocks.GRAVEL.getDefaultState());
        structure.fillWithBlocks(world, start, 174, 5, 77, 174, 5, 77, Blocks.STONE.getDefaultState());
        structure.fillWithBlocks(world, start, 174, 5, 78, 174, 7, 78, Blocks.DIRT.getDefaultState());
        structure.fillWithBlocks(world, start, 174, 5, 81, 175, 5, 82, Blocks.ANDESITE.getDefaultState());
        structure.fillWithBlocks(world, start, 174, 5, 83, 174, 5, 83, Blocks.STONE.getDefaultState());
        structure.fillWithBlocks(world, start, 174, 5, 84, 174, 8, 84, Blocks.DIRT.getDefaultState());
        structure.fillWithBlocks(world, start, 174, 5, 85, 174, 5, 85, Blocks.STONE.getDefaultState());
        structure.fillWithBlocks(world, start, 174, 5, 86, 174, 8, 86, Blocks.DIRT.getDefaultState());
        structure.fillWithBlocks(world, start, 174, 5, 87, 175, 5, 90, Blocks.GRAVEL.getDefaultState());
        structure.fillWithBlocks(world, start, 174, 5, 91, 176, 5, 97, Blocks.STONE.getDefaultState());
        structure.fillWithBlocks(world, start, 174, 5, 98, 175, 5, 99, Blocks.COAL_ORE.getDefaultState());
        structure.fillWithBlocks(world, start, 174, 5, 102, 181, 5, 102, Blocks.STONE.getDefaultState());
        structure.fillWithBlocks(world, start, 174, 5, 103, 182, 5, 111, Blocks.DIRT.getDefaultState());
        structure.fillWithBlocks(world, start, 174, 5, 113, 181, 5, 125, Blocks.DIRT.getDefaultState());
        structure.fillWithBlocks(world, start, 174, 5, 146, 175, 5, 148, Blocks.DIRT.getDefaultState());
        structure.fillWithBlocks(world, start, 174, 5, 149, 177, 5, 152, Blocks.GRASS_BLOCK.getDefaultState().with(SnowyDirtBlock.SNOWY, false));
        structure.fillWithBlocks(world, start, 174, 6, 14, 191, 6, 14, Blocks.GRASS_BLOCK.getDefaultState().with(SnowyDirtBlock.SNOWY, false));
        structure.fillWithBlocks(world, start, 174, 6, 15, 175, 6, 15, Blocks.GRASS.getDefaultState());
        structure.fillWithBlocks(world, start, 174, 6, 21, 179, 6, 29, Blocks.GRASS_BLOCK.getDefaultState().with(SnowyDirtBlock.SNOWY, false));
        structure.fillWithBlocks(world, start, 174, 6, 30, 175, 6, 121, Blocks.DIRT.getDefaultState());
        structure.fillWithBlocks(world, start, 174, 7, 25, 175, 7, 25, Blocks.GRASS.getDefaultState());
        structure.fillWithBlocks(world, start, 174, 7, 30, 175, 7, 39, Blocks.GRASS_BLOCK.getDefaultState().with(SnowyDirtBlock.SNOWY, false));
        structure.fillWithBlocks(world, start, 174, 7, 40, 174, 7, 42, Blocks.WATER.getDefaultState());
        structure.fillWithBlocks(world, start, 174, 7, 43, 174, 7, 47, Blocks.GRASS_BLOCK.getDefaultState().with(SnowyDirtBlock.SNOWY, false));
        structure.fillWithBlocks(world, start, 174, 7, 48, 174, 7, 94, Blocks.DIRT.getDefaultState());
        structure.fillWithBlocks(world, start, 174, 7, 95, 175, 7, 97, Blocks.GRASS_BLOCK.getDefaultState().with(SnowyDirtBlock.SNOWY, false));
        structure.fillWithBlocks(world, start, 174, 7, 100, 174, 7, 102, Blocks.WATER.getDefaultState());
        structure.fillWithBlocks(world, start, 174, 7, 103, 184, 7, 129, Blocks.GRASS_BLOCK.getDefaultState().with(SnowyDirtBlock.SNOWY, false));
        structure.fillWithBlocks(world, start, 174, 7, 131, 174, 7, 131, Blocks.GRASS.getDefaultState());
        structure.fillWithBlocks(world, start, 174, 8, 32, 175, 8, 34, Blocks.GRASS.getDefaultState());
        structure.fillWithBlocks(world, start, 174, 8, 47, 174, 8, 47, Blocks.GRASS.getDefaultState());
        structure.fillWithBlocks(world, start, 174, 8, 48, 174, 8, 52, Blocks.GRASS_BLOCK.getDefaultState().with(SnowyDirtBlock.SNOWY, false));
        structure.fillWithBlocks(world, start, 174, 8, 53, 174, 8, 58, Blocks.DIRT.getDefaultState());
        structure.fillWithBlocks(world, start, 174, 8, 59, 174, 8, 83, Blocks.GRASS_BLOCK.getDefaultState().with(SnowyDirtBlock.SNOWY, false));
        structure.fillWithBlocks(world, start, 174, 8, 85, 175, 8, 86, Blocks.DIRT.getDefaultState());
        structure.fillWithBlocks(world, start, 174, 8, 90, 175, 8, 92, Blocks.GRASS_BLOCK.getDefaultState().with(SnowyDirtBlock.SNOWY, false));
        structure.fillWithBlocks(world, start, 174, 8, 95, 174, 8, 97, Blocks.GRASS.getDefaultState());
        structure.fillWithBlocks(world, start, 174, 9, 48, 174, 9, 50, Blocks.GRASS.getDefaultState());
        structure.fillWithBlocks(world, start, 174, 9, 53, 174, 9, 58, Blocks.GRASS_BLOCK.getDefaultState().with(SnowyDirtBlock.SNOWY, false));
        structure.fillWithBlocks(world, start, 174, 9, 79, 174, 9, 80, Blocks.GRASS.getDefaultState());
        structure.fillWithBlocks(world, start, 174, 9, 84, 175, 9, 86, Blocks.GRASS_BLOCK.getDefaultState().with(SnowyDirtBlock.SNOWY, false));
        structure.fillWithBlocks(world, start, 174, 9, 90, 174, 9, 90, Blocks.GRASS.getDefaultState());
        structure.fillWithBlocks(world, start, 174, 9, 92, 174, 9, 93, Blocks.GRASS.getDefaultState());
        structure.fillWithBlocks(world, start, 174, 10, 53, 174, 10, 58, Blocks.GRASS.getDefaultState());
        structure.fillWithBlocks(world, start, 174, 10, 85, 174, 10, 85, Blocks.GRASS.getDefaultState());
        structure.fillWithBlocks(world, start, 175, 0, 162, 176, 0, 163, Blocks.GRASS_BLOCK.getDefaultState().with(SnowyDirtBlock.SNOWY, false));
        structure.fillWithBlocks(world, start, 175, 1, 66, 176, 1, 67, Blocks.DIRT.getDefaultState());
        structure.fillWithBlocks(world, start, 175, 1, 93, 185, 1, 103, Blocks.DIRT.getDefaultState());
        structure.fillWithBlocks(world, start, 175, 1, 119, 190, 1, 134, Blocks.STONE.getDefaultState());
        structure.fillWithBlocks(world, start, 175, 1, 153, 176, 1, 153, Blocks.STONE.getDefaultState());
        structure.fillWithBlocks(world, start, 175, 1, 154, 179, 1, 158, Blocks.DIRT.getDefaultState());
        structure.fillWithBlocks(world, start, 175, 1, 160, 176, 1, 161, Blocks.GRASS_BLOCK.getDefaultState().with(SnowyDirtBlock.SNOWY, false));
        structure.fillWithBlocks(world, start, 175, 2, 80, 175, 2, 80, Blocks.DIRT.getDefaultState());
        structure.fillWithBlocks(world, start, 175, 2, 81, 175, 2, 84, Blocks.STONE.getDefaultState());
        structure.fillWithBlocks(world, start, 175, 2, 85, 190, 2, 105, Blocks.DIRT.getDefaultState());
        structure.fillWithBlocks(world, start, 175, 2, 146, 179, 5, 146, Blocks.DIRT.getDefaultState());
        structure.fillWithBlocks(world, start, 175, 2, 147, 175, 2, 148, Blocks.STONE.getDefaultState());
        structure.fillWithBlocks(world, start, 175, 2, 159, 178, 2, 159, Blocks.GRASS_BLOCK.getDefaultState().with(SnowyDirtBlock.SNOWY, false));
        structure.fillWithBlocks(world, start, 175, 3, 157, 175, 3, 158, Blocks.GRASS_BLOCK.getDefaultState().with(SnowyDirtBlock.SNOWY, false));
        structure.fillWithBlocks(world, start, 175, 4, 154, 176, 4, 155, Blocks.GRASS_BLOCK.getDefaultState().with(SnowyDirtBlock.SNOWY, false));
        structure.fillWithBlocks(world, start, 175, 5, 16, 176, 5, 18, Blocks.WATER.getDefaultState());
        structure.fillWithBlocks(world, start, 175, 5, 19, 179, 5, 61, Blocks.DIRT.getDefaultState());
        structure.fillWithBlocks(world, start, 175, 5, 65, 176, 5, 66, Blocks.DIRT.getDefaultState());
        structure.fillWithBlocks(world, start, 175, 5, 67, 175, 5, 67, Blocks.STONE.getDefaultState());
        structure.fillWithBlocks(world, start, 175, 5, 68, 175, 7, 68, Blocks.DIRT.getDefaultState());
        structure.fillWithBlocks(world, start, 175, 5, 69, 175, 5, 72, Blocks.STONE.getDefaultState());
        structure.fillWithBlocks(world, start, 175, 5, 74, 176, 5, 74, Blocks.STONE.getDefaultState());
        structure.fillWithBlocks(world, start, 175, 5, 75, 175, 5, 75, Blocks.GRAVEL.getDefaultState());
        structure.fillWithBlocks(world, start, 175, 5, 77, 180, 5, 77, Blocks.GRAVEL.getDefaultState());
        structure.fillWithBlocks(world, start, 175, 5, 78, 176, 5, 78, Blocks.STONE.getDefaultState());
        structure.fillWithBlocks(world, start, 175, 5, 79, 175, 5, 79, Blocks.GRAVEL.getDefaultState());
        structure.fillWithBlocks(world, start, 175, 5, 80, 175, 5, 82, Blocks.ANDESITE.getDefaultState());
        structure.fillWithBlocks(world, start, 175, 5, 83, 175, 5, 86, Blocks.STONE.getDefaultState());
        structure.fillWithBlocks(world, start, 175, 5, 101, 176, 5, 102, Blocks.STONE.getDefaultState());
        structure.fillWithBlocks(world, start, 175, 5, 112, 181, 5, 125, Blocks.DIRT.getDefaultState());
        structure.fillWithBlocks(world, start, 175, 5, 153, 176, 5, 153, Blocks.GRASS_BLOCK.getDefaultState().with(SnowyDirtBlock.SNOWY, false));
        structure.fillWithBlocks(world, start, 175, 6, 19, 179, 6, 29, Blocks.GRASS_BLOCK.getDefaultState().with(SnowyDirtBlock.SNOWY, false));
        structure.fillWithBlocks(world, start, 175, 6, 122, 175, 7, 122, Blocks.GRASS_BLOCK.getDefaultState().with(SnowyDirtBlock.SNOWY, false));
        structure.fillWithBlocks(world, start, 175, 6, 123, 177, 6, 125, Blocks.DIRT.getDefaultState());
        structure.fillWithBlocks(world, start, 175, 7, 24, 175, 7, 25, Blocks.GRASS.getDefaultState());
        structure.fillWithBlocks(world, start, 175, 7, 40, 176, 7, 41, Blocks.GRASS_BLOCK.getDefaultState().with(SnowyDirtBlock.SNOWY, false));
        structure.fillWithBlocks(world, start, 175, 7, 42, 175, 7, 44, Blocks.WATER.getDefaultState());
        structure.fillWithBlocks(world, start, 175, 7, 45, 175, 7, 49, Blocks.GRASS_BLOCK.getDefaultState().with(SnowyDirtBlock.SNOWY, false));
        structure.fillWithBlocks(world, start, 175, 7, 50, 175, 7, 92, Blocks.DIRT.getDefaultState());
        structure.fillWithBlocks(world, start, 175, 7, 93, 176, 7, 95, Blocks.GRASS_BLOCK.getDefaultState().with(SnowyDirtBlock.SNOWY, false));
        structure.fillWithBlocks(world, start, 175, 7, 98, 176, 7, 99, Blocks.WATER.getDefaultState());
        structure.fillWithBlocks(world, start, 175, 7, 101, 184, 7, 129, Blocks.GRASS_BLOCK.getDefaultState().with(SnowyDirtBlock.SNOWY, false));
        structure.fillWithBlocks(world, start, 175, 8, 31, 176, 8, 32, Blocks.GRASS.getDefaultState());
        structure.fillWithBlocks(world, start, 175, 8, 48, 175, 8, 48, Blocks.GRASS.getDefaultState());
        structure.fillWithBlocks(world, start, 175, 8, 50, 175, 8, 55, Blocks.GRASS_BLOCK.getDefaultState().with(SnowyDirtBlock.SNOWY, false));
        structure.fillWithBlocks(world, start, 175, 8, 56, 175, 8, 64, Blocks.DIRT.getDefaultState());
        structure.fillWithBlocks(world, start, 175, 8, 65, 175, 8, 77, Blocks.GRASS_BLOCK.getDefaultState().with(SnowyDirtBlock.SNOWY, false));
        structure.fillWithBlocks(world, start, 175, 8, 78, 176, 8, 83, Blocks.DIRT.getDefaultState());
        structure.fillWithBlocks(world, start, 175, 8, 84, 175, 8, 86, Blocks.DIRT.getDefaultState());
        structure.fillWithBlocks(world, start, 175, 8, 87, 176, 8, 89, Blocks.GRASS_BLOCK.getDefaultState().with(SnowyDirtBlock.SNOWY, false));
        structure.fillWithBlocks(world, start, 175, 8, 94, 175, 8, 95, Blocks.GRASS.getDefaultState());
        structure.fillWithBlocks(world, start, 175, 9, 50, 175, 9, 55, Blocks.GRASS.getDefaultState());
        structure.fillWithBlocks(world, start, 175, 9, 56, 175, 9, 64, Blocks.GRASS_BLOCK.getDefaultState().with(SnowyDirtBlock.SNOWY, false));
        structure.fillWithBlocks(world, start, 175, 9, 78, 176, 9, 83, Blocks.GRASS_BLOCK.getDefaultState().with(SnowyDirtBlock.SNOWY, false));
        structure.fillWithBlocks(world, start, 175, 9, 90, 175, 9, 92, Blocks.GRASS.getDefaultState());
        structure.fillWithBlocks(world, start, 175, 10, 57, 175, 10, 59, Blocks.GRASS.getDefaultState());
        structure.fillWithBlocks(world, start, 175, 10, 61, 175, 10, 61, Blocks.GRASS.getDefaultState());
        structure.fillWithBlocks(world, start, 175, 10, 63, 175, 10, 63, Blocks.GRASS.getDefaultState());
        structure.fillWithBlocks(world, start, 175, 10, 78, 175, 10, 83, Blocks.GRASS.getDefaultState());
        structure.fillWithBlocks(world, start, 175, 10, 85, 175, 10, 86, Blocks.GRASS.getDefaultState());
        structure.fillWithBlocks(world, start, 176, 0, 0, 182, 3, 0, Blocks.DIRT.getDefaultState());
        structure.fillWithBlocks(world, start, 176, 0, 156, 180, 0, 160, Blocks.DIRT.getDefaultState());
        structure.fillWithBlocks(world, start, 176, 1, 2, 183, 4, 2, Blocks.DIRT.getDefaultState());
        structure.fillWithBlocks(world, start, 176, 1, 3, 179, 1, 31, Blocks.STONE.getDefaultState());
        structure.fillWithBlocks(world, start, 176, 1, 33, 181, 1, 39, Blocks.DIRT.getDefaultState());
        structure.fillWithBlocks(world, start, 176, 1, 68, 176, 1, 68, Blocks.DIRT.getDefaultState());
        structure.fillWithBlocks(world, start, 176, 1, 69, 176, 1, 92, Blocks.STONE.getDefaultState());
        structure.fillWithBlocks(world, start, 176, 1, 159, 178, 1, 159, Blocks.DIRT.getDefaultState());
        structure.fillWithBlocks(world, start, 176, 2, 3, 178, 2, 22, Blocks.STONE.getDefaultState());
        structure.fillWithBlocks(world, start, 176, 2, 28, 187, 2, 40, Blocks.DIRT.getDefaultState());
        structure.fillWithBlocks(world, start, 176, 2, 78, 189, 2, 146, Blocks.DIRT.getDefaultState());
        structure.fillWithBlocks(world, start, 176, 2, 147, 177, 2, 147, Blocks.STONE.getDefaultState());
        structure.fillWithBlocks(world, start, 176, 2, 148, 182, 2, 155, Blocks.DIRT.getDefaultState());
        structure.fillWithBlocks(world, start, 176, 2, 158, 177, 2, 159, Blocks.GRASS_BLOCK.getDefaultState().with(SnowyDirtBlock.SNOWY, false));
        structure.fillWithBlocks(world, start, 176, 3, 156, 177, 3, 157, Blocks.GRASS_BLOCK.getDefaultState().with(SnowyDirtBlock.SNOWY, false));
        structure.fillWithBlocks(world, start, 176, 4, 0, 182, 4, 0, Blocks.GRASS_BLOCK.getDefaultState().with(SnowyDirtBlock.SNOWY, false));
        structure.fillWithBlocks(world, start, 176, 4, 64, 200, 4, 123, Blocks.DIRT.getDefaultState());
        structure.fillWithBlocks(world, start, 176, 4, 124, 192, 4, 140, Blocks.DIRT.getDefaultState());
        structure.fillWithBlocks(world, start, 176, 4, 141, 183, 4, 149, Blocks.DIRT.getDefaultState());
        structure.fillWithBlocks(world, start, 176, 4, 150, 178, 4, 152, Blocks.DIRT.getDefaultState());
        structure.fillWithBlocks(world, start, 176, 5, 2, 183, 5, 2, Blocks.GRASS_BLOCK.getDefaultState().with(SnowyDirtBlock.SNOWY, false));
        structure.fillWithBlocks(world, start, 176, 5, 3, 179, 5, 15, Blocks.DIRT.getDefaultState());
        structure.fillWithBlocks(world, start, 176, 5, 62, 176, 5, 62, Blocks.DIRT.getDefaultState());
        structure.fillWithBlocks(world, start, 176, 5, 64, 178, 5, 66, Blocks.DIRT.getDefaultState());
        structure.fillWithBlocks(world, start, 176, 5, 67, 177, 5, 69, Blocks.STONE.getDefaultState());
        structure.fillWithBlocks(world, start, 176, 5, 70, 179, 7, 70, Blocks.DIRT.getDefaultState());
        structure.fillWithBlocks(world, start, 176, 5, 72, 176, 5, 72, Blocks.GRAVEL.getDefaultState());
        structure.fillWithBlocks(world, start, 176, 5, 73, 176, 5, 74, Blocks.STONE.getDefaultState());
        structure.fillWithBlocks(world, start, 176, 5, 75, 178, 5, 77, Blocks.GRAVEL.getDefaultState());
        structure.fillWithBlocks(world, start, 176, 5, 79, 176, 5, 79, Blocks.ANDESITE.getDefaultState());
        structure.fillWithBlocks(world, start, 176, 5, 80, 176, 5, 81, Blocks.GRAVEL.getDefaultState());
        structure.fillWithBlocks(world, start, 176, 5, 82, 176, 5, 82, Blocks.ANDESITE.getDefaultState());
        structure.fillWithBlocks(world, start, 176, 5, 83, 176, 8, 83, Blocks.DIRT.getDefaultState());
        structure.fillWithBlocks(world, start, 176, 5, 84, 176, 5, 87, Blocks.STONE.getDefaultState());
        structure.fillWithBlocks(world, start, 176, 5, 88, 176, 5, 90, Blocks.GRAVEL.getDefaultState());
        structure.fillWithBlocks(world, start, 176, 5, 98, 180, 5, 102, Blocks.STONE.getDefaultState());
        structure.fillWithBlocks(world, start, 176, 5, 147, 177, 5, 147, Blocks.DIRT.getDefaultState());
        structure.fillWithBlocks(world, start, 176, 5, 148, 179, 5, 152, Blocks.GRASS_BLOCK.getDefaultState().with(SnowyDirtBlock.SNOWY, false));
        structure.fillWithBlocks(world, start, 176, 6, 3, 179, 6, 15, Blocks.GRASS_BLOCK.getDefaultState().with(SnowyDirtBlock.SNOWY, false));
        structure.fillWithBlocks(world, start, 176, 6, 30, 195, 6, 30, Blocks.GRASS_BLOCK.getDefaultState().with(SnowyDirtBlock.SNOWY, false));
        structure.fillWithBlocks(world, start, 176, 6, 32, 180, 6, 98, Blocks.DIRT.getDefaultState());
        structure.fillWithBlocks(world, start, 176, 6, 99, 179, 6, 108, Blocks.DIRT.getDefaultState());
        structure.fillWithBlocks(world, start, 176, 6, 122, 179, 6, 125, Blocks.DIRT.getDefaultState());
        structure.fillWithBlocks(world, start, 176, 6, 127, 178, 6, 129, Blocks.DIRT.getDefaultState());
        structure.fillWithBlocks(world, start, 176, 6, 130, 185, 6, 140, Blocks.GRASS_BLOCK.getDefaultState().with(SnowyDirtBlock.SNOWY, false));
        structure.fillWithBlocks(world, start, 176, 6, 141, 180, 6, 145, Blocks.GRASS_BLOCK.getDefaultState().with(SnowyDirtBlock.SNOWY, false));
        structure.fillWithBlocks(world, start, 176, 6, 146, 177, 6, 147, Blocks.GRASS_BLOCK.getDefaultState().with(SnowyDirtBlock.SNOWY, false));
        structure.fillWithBlocks(world, start, 176, 7, 4, 177, 7, 4, Blocks.GRASS.getDefaultState());
        structure.fillWithBlocks(world, start, 176, 7, 11, 177, 7, 11, Blocks.GRASS.getDefaultState());
        structure.fillWithBlocks(world, start, 176, 7, 13, 177, 7, 15, Blocks.GRASS.getDefaultState());
        structure.fillWithBlocks(world, start, 176, 7, 19, 176, 7, 19, Blocks.GRASS.getDefaultState());
        structure.fillWithBlocks(world, start, 176, 7, 26, 176, 7, 26, Blocks.GRASS.getDefaultState());
        structure.fillWithBlocks(world, start, 176, 7, 31, 178, 7, 42, Blocks.GRASS_BLOCK.getDefaultState().with(SnowyDirtBlock.SNOWY, false));
        structure.fillWithBlocks(world, start, 176, 7, 43, 176, 7, 46, Blocks.WATER.getDefaultState());
        structure.fillWithBlocks(world, start, 176, 7, 47, 176, 7, 52, Blocks.GRASS_BLOCK.getDefaultState().with(SnowyDirtBlock.SNOWY, false));
        structure.fillWithBlocks(world, start, 176, 7, 53, 176, 7, 89, Blocks.DIRT.getDefaultState());
        structure.fillWithBlocks(world, start, 176, 7, 90, 177, 7, 93, Blocks.GRASS_BLOCK.getDefaultState().with(SnowyDirtBlock.SNOWY, false));
        structure.fillWithBlocks(world, start, 176, 7, 96, 177, 7, 97, Blocks.WATER.getDefaultState());
        structure.fillWithBlocks(world, start, 176, 7, 100, 184, 7, 129, Blocks.GRASS_BLOCK.getDefaultState().with(SnowyDirtBlock.SNOWY, false));
        structure.fillWithBlocks(world, start, 176, 8, 36, 177, 8, 36, Blocks.TALL_GRASS.getDefaultState());
        structure.fillWithBlocks(world, start, 176, 8, 38, 176, 8, 38, Blocks.GRASS.getDefaultState());
        structure.fillWithBlocks(world, start, 176, 8, 49, 176, 8, 49, Blocks.GRASS.getDefaultState());
        structure.fillWithBlocks(world, start, 176, 8, 53, 176, 8, 58, Blocks.GRASS_BLOCK.getDefaultState().with(SnowyDirtBlock.SNOWY, false));
        structure.fillWithBlocks(world, start, 176, 8, 59, 176, 8, 83, Blocks.DIRT.getDefaultState());
        structure.fillWithBlocks(world, start, 176, 8, 84, 177, 8, 87, Blocks.GRASS_BLOCK.getDefaultState().with(SnowyDirtBlock.SNOWY, false));
        structure.fillWithBlocks(world, start, 176, 8, 90, 176, 8, 90, Blocks.GRASS.getDefaultState());
        structure.fillWithBlocks(world, start, 176, 8, 92, 177, 8, 92, Blocks.GRASS.getDefaultState());
        structure.fillWithBlocks(world, start, 176, 9, 53, 176, 9, 58, Blocks.GRASS.getDefaultState());
        structure.fillWithBlocks(world, start, 176, 9, 59, 176, 9, 83, Blocks.GRASS_BLOCK.getDefaultState().with(SnowyDirtBlock.SNOWY, false));
        structure.fillWithBlocks(world, start, 176, 10, 62, 176, 10, 67, Blocks.GRASS.getDefaultState());
        structure.fillWithBlocks(world, start, 176, 10, 75, 177, 10, 76, Blocks.GRASS.getDefaultState());
        structure.fillWithBlocks(world, start, 176, 10, 79, 176, 10, 83, Blocks.GRASS.getDefaultState());
        structure.fillWithBlocks(world, start, 177, 0, 162, 178, 0, 163, Blocks.GRASS_BLOCK.getDefaultState().with(SnowyDirtBlock.SNOWY, false));
        structure.fillWithBlocks(world, start, 177, 1, 47, 183, 1, 53, Blocks.STONE.getDefaultState());
        structure.fillWithBlocks(world, start, 177, 1, 54, 177, 1, 70, Blocks.DIRT.getDefaultState());
        structure.fillWithBlocks(world, start, 177, 1, 71, 177, 1, 91, Blocks.STONE.getDefaultState());
        structure.fillWithBlocks(world, start, 177, 1, 92, 186, 1, 102, Blocks.DIRT.getDefaultState());
        structure.fillWithBlocks(world, start, 177, 1, 117, 191, 1, 132, Blocks.STONE.getDefaultState());
        structure.fillWithBlocks(world, start, 177, 1, 153, 181, 1, 158, Blocks.DIRT.getDefaultState());
        structure.fillWithBlocks(world, start, 177, 1, 160, 178, 1, 161, Blocks.GRASS_BLOCK.getDefaultState().with(SnowyDirtBlock.SNOWY, false));
        structure.fillWithBlocks(world, start, 177, 2, 26, 188, 2, 39, Blocks.DIRT.getDefaultState());
        structure.fillWithBlocks(world, start, 177, 3, 155, 178, 3, 155, Blocks.DIRT.getDefaultState());
        structure.fillWithBlocks(world, start, 177, 4, 60, 199, 4, 126, Blocks.DIRT.getDefaultState());
        structure.fillWithBlocks(world, start, 177, 4, 153, 178, 4, 155, Blocks.GRASS_BLOCK.getDefaultState().with(SnowyDirtBlock.SNOWY, false));
        structure.fillWithBlocks(world, start, 177, 5, 16, 177, 5, 17, Blocks.WATER.getDefaultState());
        structure.fillWithBlocks(world, start, 177, 5, 18, 179, 5, 66, Blocks.DIRT.getDefaultState());
        structure.fillWithBlocks(world, start, 177, 5, 71, 177, 5, 79, Blocks.GRAVEL.getDefaultState());
        structure.fillWithBlocks(world, start, 177, 5, 81, 178, 5, 82, Blocks.DIRT.getDefaultState());
        structure.fillWithBlocks(world, start, 177, 5, 84, 177, 5, 86, Blocks.DIRT.getDefaultState());
        structure.fillWithBlocks(world, start, 177, 5, 87, 178, 5, 88, Blocks.COAL_ORE.getDefaultState());
        structure.fillWithBlocks(world, start, 177, 5, 89, 177, 5, 91, Blocks.GRAVEL.getDefaultState());
        structure.fillWithBlocks(world, start, 177, 5, 92, 182, 5, 100, Blocks.STONE.getDefaultState());
        structure.fillWithBlocks(world, start, 177, 6, 18, 179, 6, 30, Blocks.GRASS_BLOCK.getDefaultState().with(SnowyDirtBlock.SNOWY, false));
        structure.fillWithBlocks(world, start, 177, 6, 126, 177, 7, 126, Blocks.GRASS_BLOCK.getDefaultState().with(SnowyDirtBlock.SNOWY, false));
        structure.fillWithBlocks(world, start, 177, 7, 19, 177, 7, 22, Blocks.GRASS.getDefaultState());
        structure.fillWithBlocks(world, start, 177, 7, 26, 177, 7, 28, Blocks.GRASS.getDefaultState());
        structure.fillWithBlocks(world, start, 177, 7, 43, 178, 7, 44, Blocks.GRASS_BLOCK.getDefaultState().with(SnowyDirtBlock.SNOWY, false));
        structure.fillWithBlocks(world, start, 177, 7, 45, 177, 7, 48, Blocks.WATER.getDefaultState());
        structure.fillWithBlocks(world, start, 177, 7, 49, 177, 7, 54, Blocks.GRASS_BLOCK.getDefaultState().with(SnowyDirtBlock.SNOWY, false));
        structure.fillWithBlocks(world, start, 177, 7, 55, 177, 7, 87, Blocks.DIRT.getDefaultState());
        structure.fillWithBlocks(world, start, 177, 7, 88, 178, 7, 90, Blocks.GRASS_BLOCK.getDefaultState().with(SnowyDirtBlock.SNOWY, false));
        structure.fillWithBlocks(world, start, 177, 7, 94, 178, 7, 95, Blocks.WATER.getDefaultState());
        structure.fillWithBlocks(world, start, 177, 7, 98, 184, 7, 129, Blocks.GRASS_BLOCK.getDefaultState().with(SnowyDirtBlock.SNOWY, false));
        structure.fillWithBlocks(world, start, 177, 8, 32, 177, 8, 33, Blocks.GRASS.getDefaultState());
        structure.fillWithBlocks(world, start, 177, 8, 38, 178, 8, 39, Blocks.GRASS.getDefaultState());
        structure.fillWithBlocks(world, start, 177, 8, 50, 177, 8, 52, Blocks.GRASS.getDefaultState());
        structure.fillWithBlocks(world, start, 177, 8, 54, 178, 8, 54, Blocks.GRASS.getDefaultState());
        structure.fillWithBlocks(world, start, 177, 8, 55, 177, 8, 63, Blocks.GRASS_BLOCK.getDefaultState().with(SnowyDirtBlock.SNOWY, false));
        structure.fillWithBlocks(world, start, 177, 8, 64, 177, 8, 78, Blocks.DIRT.getDefaultState());
        structure.fillWithBlocks(world, start, 177, 8, 79, 178, 8, 83, Blocks.GRASS_BLOCK.getDefaultState().with(SnowyDirtBlock.SNOWY, false));
        structure.fillWithBlocks(world, start, 177, 8, 90, 177, 8, 92, Blocks.GRASS.getDefaultState());
        structure.fillWithBlocks(world, start, 177, 9, 55, 177, 9, 62, Blocks.GRASS.getDefaultState());
        structure.fillWithBlocks(world, start, 177, 9, 64, 177, 9, 78, Blocks.GRASS_BLOCK.getDefaultState().with(SnowyDirtBlock.SNOWY, false));
        structure.fillWithBlocks(world, start, 177, 9, 79, 177, 9, 81, Blocks.GRASS.getDefaultState());
        structure.fillWithBlocks(world, start, 178, 1, 32, 183, 1, 37, Blocks.DIRT.getDefaultState());
        structure.fillWithBlocks(world, start, 178, 1, 45, 187, 1, 54, Blocks.STONE.getDefaultState());
        structure.fillWithBlocks(world, start, 178, 1, 55, 179, 1, 71, Blocks.DIRT.getDefaultState());
        structure.fillWithBlocks(world, start, 178, 1, 72, 178, 1, 91, Blocks.STONE.getDefaultState());
        structure.fillWithBlocks(world, start, 178, 1, 113, 194, 1, 129, Blocks.STONE.getDefaultState());
        structure.fillWithBlocks(world, start, 178, 2, 23, 191, 2, 36, Blocks.DIRT.getDefaultState());
        structure.fillWithBlocks(world, start, 178, 2, 147, 184, 2, 154, Blocks.DIRT.getDefaultState());
        structure.fillWithBlocks(world, start, 178, 2, 158, 178, 2, 159, Blocks.GRASS_BLOCK.getDefaultState().with(SnowyDirtBlock.SNOWY, false));
        structure.fillWithBlocks(world, start, 178, 3, 156, 178, 3, 157, Blocks.GRASS_BLOCK.getDefaultState().with(SnowyDirtBlock.SNOWY, false));
        structure.fillWithBlocks(world, start, 178, 5, 16, 180, 5, 18, Blocks.DIRT.getDefaultState());
        structure.fillWithBlocks(world, start, 178, 5, 67, 178, 5, 67, Blocks.STONE.getDefaultState());
        structure.fillWithBlocks(world, start, 178, 5, 68, 178, 7, 68, Blocks.DIRT.getDefaultState());
        structure.fillWithBlocks(world, start, 178, 5, 71, 179, 5, 71, Blocks.STONE.getDefaultState());
        structure.fillWithBlocks(world, start, 178, 5, 72, 179, 5, 78, Blocks.GRAVEL.getDefaultState());
        structure.fillWithBlocks(world, start, 178, 5, 79, 181, 5, 82, Blocks.DIRT.getDefaultState());
        structure.fillWithBlocks(world, start, 178, 5, 83, 178, 5, 84, Blocks.STONE.getDefaultState());
        structure.fillWithBlocks(world, start, 178, 5, 85, 178, 6, 85, Blocks.DIRT.getDefaultState());
        structure.fillWithBlocks(world, start, 178, 5, 86, 182, 5, 86, Blocks.STONE.getDefaultState());
        structure.fillWithBlocks(world, start, 178, 5, 89, 178, 5, 90, Blocks.COAL_ORE.getDefaultState());
        structure.fillWithBlocks(world, start, 178, 5, 91, 182, 5, 100, Blocks.STONE.getDefaultState());
        structure.fillWithBlocks(world, start, 178, 5, 147, 181, 5, 150, Blocks.GRASS_BLOCK.getDefaultState().with(SnowyDirtBlock.SNOWY, false));
        structure.fillWithBlocks(world, start, 178, 6, 16, 180, 6, 18, Blocks.GRASS_BLOCK.getDefaultState().with(SnowyDirtBlock.SNOWY, false));
        structure.fillWithBlocks(world, start, 178, 6, 126, 181, 6, 129, Blocks.DIRT.getDefaultState());
        structure.fillWithBlocks(world, start, 178, 6, 146, 179, 6, 146, Blocks.GRASS_BLOCK.getDefaultState().with(SnowyDirtBlock.SNOWY, false));
        structure.fillWithBlocks(world, start, 178, 7, 14, 179, 7, 14, Blocks.GRASS.getDefaultState());
        structure.fillWithBlocks(world, start, 178, 7, 28, 178, 7, 29, Blocks.GRASS.getDefaultState());
        structure.fillWithBlocks(world, start, 178, 7, 45, 179, 7, 46, Blocks.GRASS_BLOCK.getDefaultState().with(SnowyDirtBlock.SNOWY, false));
        structure.fillWithBlocks(world, start, 178, 7, 47, 178, 7, 51, Blocks.WATER.getDefaultState());
        structure.fillWithBlocks(world, start, 178, 7, 52, 178, 7, 58, Blocks.GRASS_BLOCK.getDefaultState().with(SnowyDirtBlock.SNOWY, false));
        structure.fillWithBlocks(world, start, 178, 7, 59, 178, 7, 83, Blocks.DIRT.getDefaultState());
        structure.fillWithBlocks(world, start, 178, 7, 84, 179, 7, 87, Blocks.GRASS_BLOCK.getDefaultState().with(SnowyDirtBlock.SNOWY, false));
        structure.fillWithBlocks(world, start, 178, 7, 91, 179, 7, 93, Blocks.WATER.getDefaultState());
        structure.fillWithBlocks(world, start, 178, 7, 96, 184, 7, 129, Blocks.GRASS_BLOCK.getDefaultState().with(SnowyDirtBlock.SNOWY, false));
        structure.fillWithBlocks(world, start, 178, 7, 130, 178, 7, 130, Blocks.GRASS.getDefaultState());
        structure.fillWithBlocks(world, start, 178, 8, 35, 179, 8, 36, Blocks.GRASS.getDefaultState());
        structure.fillWithBlocks(world, start, 178, 8, 53, 178, 8, 54, Blocks.GRASS.getDefaultState());
        structure.fillWithBlocks(world, start, 178, 8, 59, 178, 8, 83, Blocks.GRASS_BLOCK.getDefaultState().with(SnowyDirtBlock.SNOWY, false));
        structure.fillWithBlocks(world, start, 178, 8, 85, 179, 8, 87, Blocks.GRASS.getDefaultState());
        structure.fillWithBlocks(world, start, 178, 9, 59, 178, 9, 61, Blocks.GRASS.getDefaultState());
        structure.fillWithBlocks(world, start, 178, 9, 63, 178, 9, 66, Blocks.GRASS.getDefaultState());
        structure.fillWithBlocks(world, start, 178, 9, 69, 178, 9, 69, Blocks.GRASS.getDefaultState());
        structure.fillWithBlocks(world, start, 178, 9, 72, 178, 9, 72, Blocks.GRASS.getDefaultState());
        structure.fillWithBlocks(world, start, 178, 9, 75, 178, 9, 75, Blocks.GRASS.getDefaultState());
        structure.fillWithBlocks(world, start, 179, 0, 155, 183, 0, 159, Blocks.DIRT.getDefaultState());
        structure.fillWithBlocks(world, start, 179, 0, 161, 180, 0, 162, Blocks.GRASS_BLOCK.getDefaultState().with(SnowyDirtBlock.SNOWY, false));
        structure.fillWithBlocks(world, start, 179, 1, 43, 190, 1, 54, Blocks.STONE.getDefaultState());
        structure.fillWithBlocks(world, start, 179, 1, 72, 180, 1, 73, Blocks.DIRT.getDefaultState());
        structure.fillWithBlocks(world, start, 179, 1, 74, 179, 1, 90, Blocks.STONE.getDefaultState());
        structure.fillWithBlocks(world, start, 179, 1, 91, 186, 1, 102, Blocks.DIRT.getDefaultState());
        structure.fillWithBlocks(world, start, 179, 1, 106, 180, 1, 108, Blocks.DIRT.getDefaultState());
        structure.fillWithBlocks(world, start, 179, 1, 109, 179, 5, 109, Blocks.DIRT.getDefaultState());
        structure.fillWithBlocks(world, start, 179, 1, 110, 198, 1, 129, Blocks.STONE.getDefaultState());
        structure.fillWithBlocks(world, start, 179, 1, 159, 180, 1, 160, Blocks.GRASS_BLOCK.getDefaultState().with(SnowyDirtBlock.SNOWY, false));
        structure.fillWithBlocks(world, start, 179, 2, 3, 185, 4, 3, Blocks.DIRT.getDefaultState());
        structure.fillWithBlocks(world, start, 179, 2, 4, 180, 2, 10, Blocks.STONE.getDefaultState());
        structure.fillWithBlocks(world, start, 179, 2, 12, 198, 2, 35, Blocks.DIRT.getDefaultState());
        structure.fillWithBlocks(world, start, 179, 2, 157, 180, 2, 158, Blocks.GRASS_BLOCK.getDefaultState().with(SnowyDirtBlock.SNOWY, false));
        structure.fillWithBlocks(world, start, 179, 3, 155, 180, 3, 156, Blocks.GRASS_BLOCK.getDefaultState().with(SnowyDirtBlock.SNOWY, false));
        structure.fillWithBlocks(world, start, 179, 4, 150, 180, 4, 151, Blocks.DIRT.getDefaultState());
        structure.fillWithBlocks(world, start, 179, 4, 153, 180, 4, 154, Blocks.GRASS_BLOCK.getDefaultState().with(SnowyDirtBlock.SNOWY, false));
        structure.fillWithBlocks(world, start, 179, 5, 67, 180, 5, 68, Blocks.STONE.getDefaultState());
        structure.fillWithBlocks(world, start, 179, 5, 69, 179, 6, 70, Blocks.DIRT.getDefaultState());
        structure.fillWithBlocks(world, start, 179, 5, 83, 179, 5, 83, Blocks.DIRT.getDefaultState());
        structure.fillWithBlocks(world, start, 179, 5, 84, 179, 5, 86, Blocks.STONE.getDefaultState());
        structure.fillWithBlocks(world, start, 179, 5, 87, 179, 5, 88, Blocks.COAL_ORE.getDefaultState());
        structure.fillWithBlocks(world, start, 179, 5, 89, 182, 5, 100, Blocks.STONE.getDefaultState());
        structure.fillWithBlocks(world, start, 179, 6, 31, 195, 6, 31, Blocks.GRASS_BLOCK.getDefaultState().with(SnowyDirtBlock.SNOWY, false));
        structure.fillWithBlocks(world, start, 179, 6, 109, 179, 7, 109, Blocks.GRASS_BLOCK.getDefaultState().with(SnowyDirtBlock.SNOWY, false));
        structure.fillWithBlocks(world, start, 179, 6, 110, 184, 6, 118, Blocks.DIRT.getDefaultState());
        structure.fillWithBlocks(world, start, 179, 6, 119, 182, 6, 129, Blocks.DIRT.getDefaultState());
        structure.fillWithBlocks(world, start, 179, 7, 3, 179, 7, 4, Blocks.GRASS.getDefaultState());
        structure.fillWithBlocks(world, start, 179, 7, 13, 179, 7, 14, Blocks.GRASS.getDefaultState());
        structure.fillWithBlocks(world, start, 179, 7, 18, 180, 7, 18, Blocks.GRASS.getDefaultState());
        structure.fillWithBlocks(world, start, 179, 7, 20, 179, 7, 23, Blocks.GRASS.getDefaultState());
        structure.fillWithBlocks(world, start, 179, 7, 26, 179, 7, 26, Blocks.GRASS.getDefaultState());
        structure.fillWithBlocks(world, start, 179, 7, 32, 180, 7, 48, Blocks.GRASS_BLOCK.getDefaultState().with(SnowyDirtBlock.SNOWY, false));
        structure.fillWithBlocks(world, start, 179, 7, 49, 179, 7, 54, Blocks.WATER.getDefaultState());
        structure.fillWithBlocks(world, start, 179, 7, 55, 179, 7, 63, Blocks.GRASS_BLOCK.getDefaultState().with(SnowyDirtBlock.SNOWY, false));
        structure.fillWithBlocks(world, start, 179, 7, 64, 179, 7, 78, Blocks.DIRT.getDefaultState());
        structure.fillWithBlocks(world, start, 179, 7, 79, 180, 7, 83, Blocks.GRASS_BLOCK.getDefaultState().with(SnowyDirtBlock.SNOWY, false));
        structure.fillWithBlocks(world, start, 179, 7, 88, 180, 7, 90, Blocks.WATER.getDefaultState());
        structure.fillWithBlocks(world, start, 179, 7, 94, 184, 7, 129, Blocks.GRASS_BLOCK.getDefaultState().with(SnowyDirtBlock.SNOWY, false));
        structure.fillWithBlocks(world, start, 179, 8, 33, 181, 8, 33, Blocks.GRASS.getDefaultState());
        structure.fillWithBlocks(world, start, 179, 8, 37, 179, 8, 38, Blocks.GRASS.getDefaultState());
        structure.fillWithBlocks(world, start, 179, 8, 40, 180, 8, 42, Blocks.GRASS.getDefaultState());
        structure.fillWithBlocks(world, start, 179, 8, 60, 179, 8, 61, Blocks.GRASS.getDefaultState());
        structure.fillWithBlocks(world, start, 179, 8, 63, 179, 8, 63, Blocks.GRASS.getDefaultState());
        structure.fillWithBlocks(world, start, 179, 8, 64, 179, 8, 78, Blocks.GRASS_BLOCK.getDefaultState().with(SnowyDirtBlock.SNOWY, false));
        structure.fillWithBlocks(world, start, 179, 8, 80, 180, 8, 82, Blocks.GRASS.getDefaultState());
        structure.fillWithBlocks(world, start, 179, 9, 64, 179, 9, 77, Blocks.GRASS.getDefaultState());
        structure.fillWithBlocks(world, start, 180, 1, 3, 185, 4, 3, Blocks.DIRT.getDefaultState());
        structure.fillWithBlocks(world, start, 180, 1, 4, 181, 1, 30, Blocks.STONE.getDefaultState());
        structure.fillWithBlocks(world, start, 180, 1, 42, 193, 1, 55, Blocks.STONE.getDefaultState());
        structure.fillWithBlocks(world, start, 180, 1, 56, 180, 1, 74, Blocks.DIRT.getDefaultState());
        structure.fillWithBlocks(world, start, 180, 1, 75, 180, 1, 90, Blocks.STONE.getDefaultState());
        structure.fillWithBlocks(world, start, 180, 1, 109, 198, 1, 129, Blocks.STONE.getDefaultState());
        structure.fillWithBlocks(world, start, 180, 1, 146, 187, 4, 146, Blocks.DIRT.getDefaultState());
        structure.fillWithBlocks(world, start, 180, 1, 148, 182, 1, 150, Blocks.STONE.getDefaultState());
        structure.fillWithBlocks(world, start, 180, 1, 152, 184, 1, 156, Blocks.DIRT.getDefaultState());
        structure.fillWithBlocks(world, start, 180, 2, 11, 198, 2, 35, Blocks.DIRT.getDefaultState());
        structure.fillWithBlocks(world, start, 180, 4, 152, 181, 4, 153, Blocks.GRASS_BLOCK.getDefaultState().with(SnowyDirtBlock.SNOWY, false));
        structure.fillWithBlocks(world, start, 180, 5, 3, 185, 5, 3, Blocks.GRASS_BLOCK.getDefaultState().with(SnowyDirtBlock.SNOWY, false));
        structure.fillWithBlocks(world, start, 180, 5, 4, 181, 5, 15, Blocks.DIRT.getDefaultState());
        structure.fillWithBlocks(world, start, 180, 5, 19, 180, 5, 22, Blocks.GRASS_BLOCK.getDefaultState().with(SnowyDirtBlock.SNOWY, false));
        structure.fillWithBlocks(world, start, 180, 5, 60, 186, 5, 66, Blocks.DIRT.getDefaultState());
        structure.fillWithBlocks(world, start, 180, 5, 69, 180, 5, 70, Blocks.STONE.getDefaultState());
        structure.fillWithBlocks(world, start, 180, 5, 71, 181, 5, 72, Blocks.DIRT.getDefaultState());
        structure.fillWithBlocks(world, start, 180, 5, 73, 180, 5, 77, Blocks.GRAVEL.getDefaultState());
        structure.fillWithBlocks(world, start, 180, 5, 78, 186, 5, 84, Blocks.DIRT.getDefaultState());
        structure.fillWithBlocks(world, start, 180, 5, 85, 180, 5, 102, Blocks.STONE.getDefaultState());
        structure.fillWithBlocks(world, start, 180, 5, 146, 183, 5, 149, Blocks.GRASS_BLOCK.getDefaultState().with(SnowyDirtBlock.SNOWY, false));
        structure.fillWithBlocks(world, start, 180, 6, 4, 181, 6, 15, Blocks.GRASS_BLOCK.getDefaultState().with(SnowyDirtBlock.SNOWY, false));
        structure.fillWithBlocks(world, start, 180, 6, 23, 180, 6, 31, Blocks.GRASS_BLOCK.getDefaultState().with(SnowyDirtBlock.SNOWY, false));
        structure.fillWithBlocks(world, start, 180, 6, 99, 180, 7, 99, Blocks.GRASS_BLOCK.getDefaultState().with(SnowyDirtBlock.SNOWY, false));
        structure.fillWithBlocks(world, start, 180, 6, 100, 184, 6, 108, Blocks.DIRT.getDefaultState());
        structure.fillWithBlocks(world, start, 180, 6, 109, 182, 6, 129, Blocks.DIRT.getDefaultState());
        structure.fillWithBlocks(world, start, 180, 7, 17, 180, 7, 18, Blocks.GRASS.getDefaultState());
        structure.fillWithBlocks(world, start, 180, 7, 27, 181, 7, 27, Blocks.GRASS.getDefaultState());
        structure.fillWithBlocks(world, start, 180, 7, 49, 181, 7, 51, Blocks.GRASS_BLOCK.getDefaultState().with(SnowyDirtBlock.SNOWY, false));
        structure.fillWithBlocks(world, start, 180, 7, 52, 180, 7, 58, Blocks.WATER.getDefaultState());
        structure.fillWithBlocks(world, start, 180, 7, 59, 180, 7, 83, Blocks.GRASS_BLOCK.getDefaultState().with(SnowyDirtBlock.SNOWY, false));
        structure.fillWithBlocks(world, start, 180, 7, 84, 181, 7, 87, Blocks.WATER.getDefaultState());
        structure.fillWithBlocks(world, start, 180, 7, 91, 184, 7, 129, Blocks.GRASS_BLOCK.getDefaultState().with(SnowyDirtBlock.SNOWY, false));
        structure.fillWithBlocks(world, start, 180, 8, 36, 180, 8, 37, Blocks.GRASS.getDefaultState());
        structure.fillWithBlocks(world, start, 180, 8, 39, 180, 8, 42, Blocks.GRASS.getDefaultState());
        structure.fillWithBlocks(world, start, 180, 8, 66, 180, 8, 67, Blocks.GRASS.getDefaultState());
        structure.fillWithBlocks(world, start, 181, 0, 1, 185, 3, 1, Blocks.DIRT.getDefaultState());
        structure.fillWithBlocks(world, start, 181, 0, 153, 182, 0, 153, Blocks.STONE.getDefaultState());
        structure.fillWithBlocks(world, start, 181, 0, 154, 185, 0, 158, Blocks.DIRT.getDefaultState());
        structure.fillWithBlocks(world, start, 181, 0, 161, 182, 0, 162, Blocks.GRASS_BLOCK.getDefaultState().with(SnowyDirtBlock.SNOWY, false));
        structure.fillWithBlocks(world, start, 181, 1, 31, 184, 1, 35, Blocks.DIRT.getDefaultState());
        structure.fillWithBlocks(world, start, 181, 1, 40, 196, 1, 56, Blocks.STONE.getDefaultState());
        structure.fillWithBlocks(world, start, 181, 1, 57, 181, 6, 66, Blocks.DIRT.getDefaultState());
        structure.fillWithBlocks(world, start, 181, 1, 67, 185, 1, 73, Blocks.DIRT.getDefaultState());
        structure.fillWithBlocks(world, start, 181, 1, 74, 182, 1, 75, Blocks.DIRT.getDefaultState());
        structure.fillWithBlocks(world, start, 181, 1, 76, 194, 1, 89, Blocks.STONE.getDefaultState());
        structure.fillWithBlocks(world, start, 181, 1, 106, 182, 1, 107, Blocks.DIRT.getDefaultState());
        structure.fillWithBlocks(world, start, 181, 1, 108, 198, 1, 129, Blocks.STONE.getDefaultState());
        structure.fillWithBlocks(world, start, 181, 1, 145, 182, 1, 146, Blocks.DIRT.getDefaultState());
        structure.fillWithBlocks(world, start, 181, 1, 151, 185, 1, 155, Blocks.DIRT.getDefaultState());
        structure.fillWithBlocks(world, start, 181, 1, 159, 181, 1, 160, Blocks.GRASS_BLOCK.getDefaultState().with(SnowyDirtBlock.SNOWY, false));
        structure.fillWithBlocks(world, start, 181, 2, 4, 186, 4, 4, Blocks.DIRT.getDefaultState());
        structure.fillWithBlocks(world, start, 181, 2, 5, 182, 2, 8, Blocks.STONE.getDefaultState());
        structure.fillWithBlocks(world, start, 181, 2, 10, 197, 2, 35, Blocks.DIRT.getDefaultState());
        structure.fillWithBlocks(world, start, 181, 2, 157, 181, 2, 158, Blocks.GRASS_BLOCK.getDefaultState().with(SnowyDirtBlock.SNOWY, false));
        structure.fillWithBlocks(world, start, 181, 3, 154, 182, 3, 155, Blocks.GRASS_BLOCK.getDefaultState().with(SnowyDirtBlock.SNOWY, false));
        structure.fillWithBlocks(world, start, 181, 4, 1, 185, 4, 1, Blocks.GRASS_BLOCK.getDefaultState().with(SnowyDirtBlock.SNOWY, false));
        structure.fillWithBlocks(world, start, 181, 4, 5, 188, 4, 145, Blocks.DIRT.getDefaultState());
        structure.fillWithBlocks(world, start, 181, 4, 150, 182, 4, 150, Blocks.DIRT.getDefaultState());
        structure.fillWithBlocks(world, start, 181, 4, 151, 182, 4, 153, Blocks.GRASS_BLOCK.getDefaultState().with(SnowyDirtBlock.SNOWY, false));
        structure.fillWithBlocks(world, start, 181, 5, 17, 181, 5, 17, Blocks.WATER.getDefaultState());
        structure.fillWithBlocks(world, start, 181, 5, 19, 182, 5, 22, Blocks.WATER.getDefaultState());
        structure.fillWithBlocks(world, start, 181, 5, 23, 182, 5, 23, Blocks.GRASS_BLOCK.getDefaultState().with(SnowyDirtBlock.SNOWY, false));
        structure.fillWithBlocks(world, start, 181, 5, 67, 181, 5, 69, Blocks.STONE.getDefaultState());
        structure.fillWithBlocks(world, start, 181, 5, 70, 185, 5, 74, Blocks.DIRT.getDefaultState());
        structure.fillWithBlocks(world, start, 181, 5, 76, 190, 5, 85, Blocks.DIRT.getDefaultState());
        structure.fillWithBlocks(world, start, 181, 5, 87, 181, 5, 87, Blocks.STONE.getDefaultState());
        structure.fillWithBlocks(world, start, 181, 5, 88, 181, 6, 88, Blocks.DIRT.getDefaultState());
        structure.fillWithBlocks(world, start, 181, 5, 101, 181, 5, 102, Blocks.STONE.getDefaultState());
        structure.fillWithBlocks(world, start, 181, 5, 127, 189, 5, 135, Blocks.DIRT.getDefaultState());
        structure.fillWithBlocks(world, start, 181, 5, 136, 185, 5, 140, Blocks.DIRT.getDefaultState());
        structure.fillWithBlocks(world, start, 181, 5, 141, 182, 5, 143, Blocks.DIRT.getDefaultState());
        structure.fillWithBlocks(world, start, 181, 5, 145, 184, 5, 148, Blocks.GRASS_BLOCK.getDefaultState().with(SnowyDirtBlock.SNOWY, false));
        structure.fillWithBlocks(world, start, 181, 6, 24, 189, 6, 32, Blocks.GRASS_BLOCK.getDefaultState().with(SnowyDirtBlock.SNOWY, false));
        structure.fillWithBlocks(world, start, 181, 6, 33, 181, 6, 47, Blocks.DIRT.getDefaultState());
        structure.fillWithBlocks(world, start, 181, 6, 48, 181, 6, 48, Blocks.GRASS_BLOCK.getDefaultState().with(SnowyDirtBlock.SNOWY, false));
        structure.fillWithBlocks(world, start, 181, 6, 49, 181, 6, 129, Blocks.DIRT.getDefaultState());
        structure.fillWithBlocks(world, start, 181, 6, 141, 182, 6, 143, Blocks.GRASS_BLOCK.getDefaultState().with(SnowyDirtBlock.SNOWY, false));
        structure.fillWithBlocks(world, start, 181, 7, 13, 181, 7, 14, Blocks.TALL_GRASS.getDefaultState());
        structure.fillWithBlocks(world, start, 181, 7, 29, 181, 7, 29, Blocks.GRASS.getDefaultState());
        structure.fillWithBlocks(world, start, 181, 7, 31, 182, 7, 32, Blocks.GRASS.getDefaultState());
        structure.fillWithBlocks(world, start, 181, 7, 33, 181, 7, 47, Blocks.GRASS_BLOCK.getDefaultState().with(SnowyDirtBlock.SNOWY, false));
        structure.fillWithBlocks(world, start, 181, 7, 52, 182, 7, 54, Blocks.GRASS_BLOCK.getDefaultState().with(SnowyDirtBlock.SNOWY, false));
        structure.fillWithBlocks(world, start, 181, 7, 55, 181, 7, 64, Blocks.WATER.getDefaultState());
        structure.fillWithBlocks(world, start, 181, 7, 65, 181, 7, 77, Blocks.GRASS_BLOCK.getDefaultState().with(SnowyDirtBlock.SNOWY, false));
        structure.fillWithBlocks(world, start, 181, 7, 78, 182, 7, 83, Blocks.WATER.getDefaultState());
        structure.fillWithBlocks(world, start, 181, 7, 88, 184, 7, 129, Blocks.GRASS_BLOCK.getDefaultState().with(SnowyDirtBlock.SNOWY, false));
        structure.fillWithBlocks(world, start, 181, 8, 13, 181, 8, 14, Blocks.TALL_GRASS.getDefaultState());
        structure.fillWithBlocks(world, start, 181, 8, 34, 182, 8, 35, Blocks.GRASS.getDefaultState());
        structure.fillWithBlocks(world, start, 181, 8, 43, 181, 8, 47, Blocks.GRASS.getDefaultState());
        structure.fillWithBlocks(world, start, 182, 0, 160, 183, 0, 161, Blocks.GRASS_BLOCK.getDefaultState().with(SnowyDirtBlock.SNOWY, false));
        structure.fillWithBlocks(world, start, 182, 1, 4, 186, 4, 4, Blocks.DIRT.getDefaultState());
        structure.fillWithBlocks(world, start, 182, 1, 5, 183, 1, 28, Blocks.STONE.getDefaultState());
        structure.fillWithBlocks(world, start, 182, 1, 30, 185, 1, 34, Blocks.DIRT.getDefaultState());
        structure.fillWithBlocks(world, start, 182, 1, 38, 182, 6, 38, Blocks.DIRT.getDefaultState());
        structure.fillWithBlocks(world, start, 182, 1, 39, 196, 1, 58, Blocks.STONE.getDefaultState());
        structure.fillWithBlocks(world, start, 182, 1, 59, 182, 1, 75, Blocks.DIRT.getDefaultState());
        structure.fillWithBlocks(world, start, 182, 1, 90, 184, 1, 104, Blocks.DIRT.getDefaultState());
        structure.fillWithBlocks(world, start, 182, 1, 144, 184, 1, 146, Blocks.DIRT.getDefaultState());
        structure.fillWithBlocks(world, start, 182, 1, 157, 183, 1, 157, Blocks.DIRT.getDefaultState());
        structure.fillWithBlocks(world, start, 182, 1, 158, 183, 1, 159, Blocks.GRASS_BLOCK.getDefaultState().with(SnowyDirtBlock.SNOWY, false));
        structure.fillWithBlocks(world, start, 182, 2, 9, 197, 2, 35, Blocks.DIRT.getDefaultState());
        structure.fillWithBlocks(world, start, 182, 2, 156, 183, 2, 157, Blocks.GRASS_BLOCK.getDefaultState().with(SnowyDirtBlock.SNOWY, false));
        structure.fillWithBlocks(world, start, 182, 5, 4, 186, 5, 4, Blocks.GRASS_BLOCK.getDefaultState().with(SnowyDirtBlock.SNOWY, false));
        structure.fillWithBlocks(world, start, 182, 5, 5, 183, 5, 14, Blocks.DIRT.getDefaultState());
        structure.fillWithBlocks(world, start, 182, 5, 15, 183, 5, 20, Blocks.WATER.getDefaultState());
        structure.fillWithBlocks(world, start, 182, 5, 67, 197, 5, 85, Blocks.DIRT.getDefaultState());
        structure.fillWithBlocks(world, start, 182, 5, 87, 182, 5, 100, Blocks.STONE.getDefaultState());
        structure.fillWithBlocks(world, start, 182, 5, 101, 194, 5, 113, Blocks.DIRT.getDefaultState());
        structure.fillWithBlocks(world, start, 182, 5, 114, 182, 5, 115, Blocks.GRASS_BLOCK.getDefaultState().with(SnowyDirtBlock.SNOWY, false));
        structure.fillWithBlocks(world, start, 182, 5, 116, 188, 5, 122, Blocks.DIRT.getDefaultState());
        structure.fillWithBlocks(world, start, 182, 5, 123, 183, 5, 142, Blocks.DIRT.getDefaultState());
        structure.fillWithBlocks(world, start, 182, 5, 144, 185, 5, 147, Blocks.GRASS_BLOCK.getDefaultState().with(SnowyDirtBlock.SNOWY, false));
        structure.fillWithBlocks(world, start, 182, 6, 5, 183, 6, 14, Blocks.GRASS_BLOCK.getDefaultState().with(SnowyDirtBlock.SNOWY, false));
        structure.fillWithBlocks(world, start, 182, 6, 33, 196, 6, 33, Blocks.GRASS_BLOCK.getDefaultState().with(SnowyDirtBlock.SNOWY, false));
        structure.fillWithBlocks(world, start, 182, 6, 34, 183, 6, 42, Blocks.DIRT.getDefaultState());
        structure.fillWithBlocks(world, start, 182, 6, 43, 182, 6, 47, Blocks.DIRT.getDefaultState());
        structure.fillWithBlocks(world, start, 182, 6, 48, 184, 6, 50, Blocks.GRASS_BLOCK.getDefaultState().with(SnowyDirtBlock.SNOWY, false));
        structure.fillWithBlocks(world, start, 182, 6, 51, 182, 6, 129, Blocks.DIRT.getDefaultState());
        structure.fillWithBlocks(world, start, 182, 7, 25, 182, 7, 26, Blocks.GRASS.getDefaultState());
        structure.fillWithBlocks(world, start, 182, 7, 29, 183, 7, 30, Blocks.GRASS.getDefaultState());
        structure.fillWithBlocks(world, start, 182, 7, 33, 183, 7, 33, Blocks.GRASS.getDefaultState());
        structure.fillWithBlocks(world, start, 182, 7, 34, 183, 7, 42, Blocks.GRASS_BLOCK.getDefaultState().with(SnowyDirtBlock.SNOWY, false));
        structure.fillWithBlocks(world, start, 182, 7, 43, 182, 7, 47, Blocks.GRASS_BLOCK.getDefaultState().with(SnowyDirtBlock.SNOWY, false));
        structure.fillWithBlocks(world, start, 182, 7, 48, 182, 7, 48, Blocks.GRASS.getDefaultState());
        structure.fillWithBlocks(world, start, 182, 7, 50, 182, 7, 50, Blocks.GRASS.getDefaultState());
        structure.fillWithBlocks(world, start, 182, 7, 51, 182, 7, 58, Blocks.GRASS_BLOCK.getDefaultState().with(SnowyDirtBlock.SNOWY, false));
        structure.fillWithBlocks(world, start, 182, 7, 59, 182, 7, 83, Blocks.WATER.getDefaultState());
        structure.fillWithBlocks(world, start, 182, 7, 84, 184, 7, 129, Blocks.GRASS_BLOCK.getDefaultState().with(SnowyDirtBlock.SNOWY, false));
        structure.fillWithBlocks(world, start, 182, 8, 36, 183, 8, 39, Blocks.GRASS.getDefaultState());
        structure.fillWithBlocks(world, start, 182, 8, 40, 182, 8, 41, Blocks.GRASS.getDefaultState());
        structure.fillWithBlocks(world, start, 183, 0, 0, 184, 0, 1, Blocks.DIRT.getDefaultState());
        structure.fillWithBlocks(world, start, 183, 0, 153, 186, 0, 157, Blocks.DIRT.getDefaultState());
        structure.fillWithBlocks(world, start, 183, 1, 0, 187, 1, 4, Blocks.DIRT.getDefaultState());
        structure.fillWithBlocks(world, start, 183, 1, 29, 186, 1, 33, Blocks.DIRT.getDefaultState());
        structure.fillWithBlocks(world, start, 183, 1, 38, 196, 1, 59, Blocks.STONE.getDefaultState());
        structure.fillWithBlocks(world, start, 183, 1, 60, 183, 6, 75, Blocks.DIRT.getDefaultState());
        structure.fillWithBlocks(world, start, 183, 1, 106, 198, 1, 129, Blocks.STONE.getDefaultState());
        structure.fillWithBlocks(world, start, 183, 1, 143, 186, 1, 146, Blocks.DIRT.getDefaultState());
        structure.fillWithBlocks(world, start, 183, 1, 148, 183, 1, 149, Blocks.STONE.getDefaultState());
        structure.fillWithBlocks(world, start, 183, 1, 150, 187, 1, 154, Blocks.DIRT.getDefaultState());
        structure.fillWithBlocks(world, start, 183, 2, 0, 186, 2, 5, Blocks.DIRT.getDefaultState());
        structure.fillWithBlocks(world, start, 183, 2, 6, 183, 2, 7, Blocks.STONE.getDefaultState());
        structure.fillWithBlocks(world, start, 183, 2, 8, 196, 2, 35, Blocks.DIRT.getDefaultState());
        structure.fillWithBlocks(world, start, 183, 2, 155, 184, 2, 156, Blocks.GRASS_BLOCK.getDefaultState().with(SnowyDirtBlock.SNOWY, false));
        structure.fillWithBlocks(world, start, 183, 3, 0, 186, 3, 0, Blocks.GRASS_BLOCK.getDefaultState().with(SnowyDirtBlock.SNOWY, false));
        structure.fillWithBlocks(world, start, 183, 3, 153, 184, 3, 154, Blocks.GRASS_BLOCK.getDefaultState().with(SnowyDirtBlock.SNOWY, false));
        structure.fillWithBlocks(world, start, 183, 4, 150, 184, 4, 151, Blocks.GRASS_BLOCK.getDefaultState().with(SnowyDirtBlock.SNOWY, false));
        structure.fillWithBlocks(world, start, 183, 5, 21, 183, 5, 22, Blocks.GRASS_BLOCK.getDefaultState().with(SnowyDirtBlock.SNOWY, false));
        structure.fillWithBlocks(world, start, 183, 5, 23, 195, 5, 90, Blocks.DIRT.getDefaultState());
        structure.fillWithBlocks(world, start, 183, 5, 92, 199, 5, 112, Blocks.DIRT.getDefaultState());
        structure.fillWithBlocks(world, start, 183, 5, 114, 191, 5, 122, Blocks.DIRT.getDefaultState());
        structure.fillWithBlocks(world, start, 183, 5, 143, 186, 5, 147, Blocks.GRASS_BLOCK.getDefaultState().with(SnowyDirtBlock.SNOWY, false));
        structure.fillWithBlocks(world, start, 183, 6, 23, 193, 6, 33, Blocks.GRASS_BLOCK.getDefaultState().with(SnowyDirtBlock.SNOWY, false));
        structure.fillWithBlocks(world, start, 183, 6, 43, 186, 6, 46, Blocks.GRASS_BLOCK.getDefaultState().with(SnowyDirtBlock.SNOWY, false));
        structure.fillWithBlocks(world, start, 183, 6, 51, 186, 6, 54, Blocks.GRASS_BLOCK.getDefaultState().with(SnowyDirtBlock.SNOWY, false));
        structure.fillWithBlocks(world, start, 183, 6, 55, 183, 6, 108, Blocks.DIRT.getDefaultState());
        structure.fillWithBlocks(world, start, 183, 6, 109, 183, 7, 109, Blocks.GRASS_BLOCK.getDefaultState().with(SnowyDirtBlock.SNOWY, false));
        structure.fillWithBlocks(world, start, 183, 6, 119, 183, 7, 119, Blocks.GRASS_BLOCK.getDefaultState().with(SnowyDirtBlock.SNOWY, false));
        structure.fillWithBlocks(world, start, 183, 6, 120, 184, 6, 129, Blocks.DIRT.getDefaultState());
        structure.fillWithBlocks(world, start, 183, 6, 141, 183, 6, 142, Blocks.GRASS_BLOCK.getDefaultState().with(SnowyDirtBlock.SNOWY, false));
        structure.fillWithBlocks(world, start, 183, 7, 27, 183, 7, 30, Blocks.GRASS.getDefaultState());
        structure.fillWithBlocks(world, start, 183, 7, 44, 183, 7, 45, Blocks.GRASS.getDefaultState());
        structure.fillWithBlocks(world, start, 183, 7, 49, 183, 7, 51, Blocks.GRASS.getDefaultState());
        structure.fillWithBlocks(world, start, 183, 7, 53, 183, 7, 53, Blocks.TALL_GRASS.getDefaultState());
        structure.fillWithBlocks(world, start, 183, 7, 55, 183, 7, 63, Blocks.GRASS_BLOCK.getDefaultState().with(SnowyDirtBlock.SNOWY, false));
        structure.fillWithBlocks(world, start, 183, 7, 64, 183, 7, 78, Blocks.WATER.getDefaultState());
        structure.fillWithBlocks(world, start, 183, 7, 79, 184, 7, 129, Blocks.GRASS_BLOCK.getDefaultState().with(SnowyDirtBlock.SNOWY, false));
        structure.fillWithBlocks(world, start, 183, 7, 131, 183, 7, 131, Blocks.GRASS.getDefaultState());
        structure.fillWithBlocks(world, start, 183, 8, 34, 183, 8, 39, Blocks.GRASS.getDefaultState());
        structure.fillWithBlocks(world, start, 183, 8, 53, 183, 8, 53, Blocks.TALL_GRASS.getDefaultState());
        structure.fillWithBlocks(world, start, 184, 0, 2, 189, 2, 2, Blocks.DIRT.getDefaultState());
        structure.fillWithBlocks(world, start, 184, 0, 148, 186, 0, 150, Blocks.STONE.getDefaultState());
        structure.fillWithBlocks(world, start, 184, 0, 151, 185, 0, 151, Blocks.STONE.getDefaultState());
        structure.fillWithBlocks(world, start, 184, 0, 152, 188, 0, 156, Blocks.DIRT.getDefaultState());
        structure.fillWithBlocks(world, start, 184, 0, 159, 185, 0, 160, Blocks.GRASS_BLOCK.getDefaultState().with(SnowyDirtBlock.SNOWY, false));
        structure.fillWithBlocks(world, start, 184, 1, 5, 184, 1, 5, Blocks.DIRT.getDefaultState());
        structure.fillWithBlocks(world, start, 184, 1, 6, 184, 1, 27, Blocks.STONE.getDefaultState());
        structure.fillWithBlocks(world, start, 184, 1, 28, 187, 1, 32, Blocks.DIRT.getDefaultState());
        structure.fillWithBlocks(world, start, 184, 1, 36, 196, 1, 61, Blocks.STONE.getDefaultState());
        structure.fillWithBlocks(world, start, 184, 1, 62, 184, 6, 75, Blocks.DIRT.getDefaultState());
        structure.fillWithBlocks(world, start, 184, 1, 105, 198, 1, 129, Blocks.STONE.getDefaultState());
        structure.fillWithBlocks(world, start, 184, 1, 138, 185, 1, 140, Blocks.STONE.getDefaultState());
        structure.fillWithBlocks(world, start, 184, 1, 142, 188, 1, 146, Blocks.DIRT.getDefaultState());
        structure.fillWithBlocks(world, start, 184, 1, 149, 188, 1, 153, Blocks.DIRT.getDefaultState());
        structure.fillWithBlocks(world, start, 184, 1, 157, 185, 1, 158, Blocks.GRASS_BLOCK.getDefaultState().with(SnowyDirtBlock.SNOWY, false));
        structure.fillWithBlocks(world, start, 184, 2, 6, 194, 2, 35, Blocks.DIRT.getDefaultState());
        structure.fillWithBlocks(world, start, 184, 3, 152, 185, 3, 153, Blocks.GRASS_BLOCK.getDefaultState().with(SnowyDirtBlock.SNOWY, false));
        structure.fillWithBlocks(world, start, 184, 4, 2, 186, 4, 2, Blocks.GRASS_BLOCK.getDefaultState().with(SnowyDirtBlock.SNOWY, false));
        structure.fillWithBlocks(world, start, 184, 4, 147, 184, 4, 148, Blocks.DIRT.getDefaultState());
        structure.fillWithBlocks(world, start, 184, 4, 149, 185, 4, 151, Blocks.GRASS_BLOCK.getDefaultState().with(SnowyDirtBlock.SNOWY, false));
        structure.fillWithBlocks(world, start, 184, 5, 5, 184, 5, 5, Blocks.GRASS_BLOCK.getDefaultState().with(SnowyDirtBlock.SNOWY, false));
        structure.fillWithBlocks(world, start, 184, 5, 6, 184, 5, 122, Blocks.DIRT.getDefaultState());
        structure.fillWithBlocks(world, start, 184, 5, 124, 191, 5, 132, Blocks.DIRT.getDefaultState());
        structure.fillWithBlocks(world, start, 184, 5, 142, 187, 5, 146, Blocks.GRASS_BLOCK.getDefaultState().with(SnowyDirtBlock.SNOWY, false));
        structure.fillWithBlocks(world, start, 184, 6, 6, 184, 6, 34, Blocks.GRASS_BLOCK.getDefaultState().with(SnowyDirtBlock.SNOWY, false));
        structure.fillWithBlocks(world, start, 184, 6, 35, 184, 6, 39, Blocks.DIRT.getDefaultState());
        structure.fillWithBlocks(world, start, 184, 6, 40, 196, 6, 57, Blocks.GRASS_BLOCK.getDefaultState().with(SnowyDirtBlock.SNOWY, false));
        structure.fillWithBlocks(world, start, 184, 6, 58, 184, 6, 129, Blocks.DIRT.getDefaultState());
        structure.fillWithBlocks(world, start, 184, 7, 19, 184, 7, 19, Blocks.GRASS.getDefaultState());
        structure.fillWithBlocks(world, start, 184, 7, 31, 184, 7, 32, Blocks.GRASS.getDefaultState());
        structure.fillWithBlocks(world, start, 184, 7, 35, 184, 7, 39, Blocks.GRASS_BLOCK.getDefaultState().with(SnowyDirtBlock.SNOWY, false));
        structure.fillWithBlocks(world, start, 184, 7, 40, 184, 7, 41, Blocks.GRASS.getDefaultState());
        structure.fillWithBlocks(world, start, 184, 7, 50, 184, 7, 53, Blocks.GRASS.getDefaultState());
        structure.fillWithBlocks(world, start, 184, 7, 58, 184, 7, 129, Blocks.GRASS_BLOCK.getDefaultState().with(SnowyDirtBlock.SNOWY, false));
        structure.fillWithBlocks(world, start, 184, 8, 66, 184, 8, 68, Blocks.GRASS.getDefaultState());
        structure.fillWithBlocks(world, start, 185, 0, 0, 187, 0, 2, Blocks.DIRT.getDefaultState());
        structure.fillWithBlocks(world, start, 185, 1, 5, 186, 1, 6, Blocks.DIRT.getDefaultState());
        structure.fillWithBlocks(world, start, 185, 1, 7, 185, 1, 24, Blocks.STONE.getDefaultState());
        structure.fillWithBlocks(world, start, 185, 1, 25, 189, 1, 30, Blocks.DIRT.getDefaultState());
        structure.fillWithBlocks(world, start, 185, 1, 35, 196, 1, 63, Blocks.STONE.getDefaultState());
        structure.fillWithBlocks(world, start, 185, 1, 64, 185, 5, 73, Blocks.DIRT.getDefaultState());
        structure.fillWithBlocks(world, start, 185, 1, 74, 197, 1, 90, Blocks.STONE.getDefaultState());
        structure.fillWithBlocks(world, start, 185, 1, 104, 198, 1, 129, Blocks.STONE.getDefaultState());
        structure.fillWithBlocks(world, start, 185, 1, 141, 190, 1, 146, Blocks.DIRT.getDefaultState());
        structure.fillWithBlocks(world, start, 185, 1, 148, 189, 1, 153, Blocks.DIRT.getDefaultState());
        structure.fillWithBlocks(world, start, 185, 1, 156, 186, 1, 157, Blocks.GRASS_BLOCK.getDefaultState().with(SnowyDirtBlock.SNOWY, false));
        structure.fillWithBlocks(world, start, 185, 2, 46, 187, 2, 48, Blocks.STONE.getDefaultState());
        structure.fillWithBlocks(world, start, 185, 2, 49, 185, 5, 140, Blocks.DIRT.getDefaultState());
        structure.fillWithBlocks(world, start, 185, 2, 147, 188, 2, 151, Blocks.DIRT.getDefaultState());
        structure.fillWithBlocks(world, start, 185, 2, 152, 186, 2, 153, Blocks.DIRT.getDefaultState());
        structure.fillWithBlocks(world, start, 185, 2, 154, 186, 2, 155, Blocks.GRASS_BLOCK.getDefaultState().with(SnowyDirtBlock.SNOWY, false));
        structure.fillWithBlocks(world, start, 185, 4, 147, 186, 4, 147, Blocks.DIRT.getDefaultState());
        structure.fillWithBlocks(world, start, 185, 4, 148, 186, 4, 150, Blocks.GRASS_BLOCK.getDefaultState().with(SnowyDirtBlock.SNOWY, false));
        structure.fillWithBlocks(world, start, 185, 5, 5, 186, 5, 6, Blocks.GRASS_BLOCK.getDefaultState().with(SnowyDirtBlock.SNOWY, false));
        structure.fillWithBlocks(world, start, 185, 5, 7, 185, 5, 140, Blocks.DIRT.getDefaultState());
        structure.fillWithBlocks(world, start, 185, 5, 141, 188, 5, 145, Blocks.GRASS_BLOCK.getDefaultState().with(SnowyDirtBlock.SNOWY, false));
        structure.fillWithBlocks(world, start, 185, 6, 7, 185, 6, 140, Blocks.GRASS_BLOCK.getDefaultState().with(SnowyDirtBlock.SNOWY, false));
        structure.fillWithBlocks(world, start, 185, 7, 20, 185, 7, 21, Blocks.GRASS.getDefaultState());
        structure.fillWithBlocks(world, start, 185, 7, 83, 186, 7, 83, Blocks.GRASS.getDefaultState());
        structure.fillWithBlocks(world, start, 186, 0, 3, 186, 0, 3, Blocks.DIRT.getDefaultState());
        structure.fillWithBlocks(world, start, 186, 0, 4, 186, 0, 150, Blocks.STONE.getDefaultState());
        structure.fillWithBlocks(world, start, 186, 0, 151, 189, 0, 155, Blocks.DIRT.getDefaultState());
        structure.fillWithBlocks(world, start, 186, 0, 158, 187, 0, 159, Blocks.GRASS_BLOCK.getDefaultState().with(SnowyDirtBlock.SNOWY, false));
        structure.fillWithBlocks(world, start, 186, 1, 7, 186, 1, 7, Blocks.DIRT.getDefaultState());
        structure.fillWithBlocks(world, start, 186, 1, 8, 186, 1, 21, Blocks.STONE.getDefaultState());
        structure.fillWithBlocks(world, start, 186, 1, 22, 191, 1, 27, Blocks.DIRT.getDefaultState());
        structure.fillWithBlocks(world, start, 186, 1, 34, 196, 1, 67, Blocks.STONE.getDefaultState());
        structure.fillWithBlocks(world, start, 186, 1, 68, 186, 2, 69, Blocks.DIRT.getDefaultState());
        structure.fillWithBlocks(world, start, 186, 1, 70, 197, 1, 90, Blocks.STONE.getDefaultState());
        structure.fillWithBlocks(world, start, 186, 1, 103, 198, 1, 129, Blocks.STONE.getDefaultState());
        structure.fillWithBlocks(world, start, 186, 1, 138, 186, 1, 139, Blocks.STONE.getDefaultState());
        structure.fillWithBlocks(world, start, 186, 1, 140, 192, 1, 146, Blocks.DIRT.getDefaultState());
        structure.fillWithBlocks(world, start, 186, 2, 43, 192, 2, 50, Blocks.STONE.getDefaultState());
        structure.fillWithBlocks(world, start, 186, 2, 51, 186, 2, 153, Blocks.DIRT.getDefaultState());
        structure.fillWithBlocks(world, start, 186, 3, 1, 186, 3, 1, Blocks.GRASS_BLOCK.getDefaultState().with(SnowyDirtBlock.SNOWY, false));
        structure.fillWithBlocks(world, start, 186, 3, 151, 187, 3, 152, Blocks.GRASS_BLOCK.getDefaultState().with(SnowyDirtBlock.SNOWY, false));
        structure.fillWithBlocks(world, start, 186, 4, 3, 186, 4, 3, Blocks.GRASS_BLOCK.getDefaultState().with(SnowyDirtBlock.SNOWY, false));
        structure.fillWithBlocks(world, start, 186, 5, 7, 186, 5, 7, Blocks.GRASS_BLOCK.getDefaultState().with(SnowyDirtBlock.SNOWY, false));
        structure.fillWithBlocks(world, start, 186, 5, 8, 186, 5, 139, Blocks.DIRT.getDefaultState());
        structure.fillWithBlocks(world, start, 186, 5, 140, 189, 5, 144, Blocks.GRASS_BLOCK.getDefaultState().with(SnowyDirtBlock.SNOWY, false));
        structure.fillWithBlocks(world, start, 186, 6, 8, 186, 6, 139, Blocks.GRASS_BLOCK.getDefaultState().with(SnowyDirtBlock.SNOWY, false));
        structure.fillWithBlocks(world, start, 186, 7, 19, 186, 7, 20, Blocks.GRASS.getDefaultState());
