package mod.arcalitegames.odyssey.world.structure.town.boromirtown;

import mod.arcalitegames.buildersaddition.Index;
import mod.arcalitegames.buildersaddition.blocks.Bookshelf;
import mod.arcalitegames.buildersaddition.blocks.Cabinet;
import mod.arcalitegames.buildersaddition.blocks.Hedge;
import mod.arcalitegames.buildersaddition.blocks.Shelf;
import mod.arcalitegames.buildersaddition.blocks.Stool;
import mod.arcalitegames.buildersaddition.state.HedgeState;
import mod.arcalitegames.buildersaddition.state.StoolState;
import mod.arcalitegames.odyssey.world.structure.StructureBase;
import net.minecraft.block.BarrelBlock;
import net.minecraft.block.BedBlock;
import net.minecraft.block.Blocks;
import net.minecraft.block.BrewingStandBlock;
import net.minecraft.block.ChainBlock;
import net.minecraft.block.ChestBlock;
import net.minecraft.block.FourWayBlock;
import net.minecraft.block.HorizontalBlock;
import net.minecraft.block.LadderBlock;
import net.minecraft.block.LeavesBlock;
import net.minecraft.block.NetherWartBlock;
import net.minecraft.block.SlabBlock;
import net.minecraft.block.SnowyDirtBlock;
import net.minecraft.block.StairsBlock;
import net.minecraft.block.TrapDoorBlock;
import net.minecraft.block.WallBlock;
import net.minecraft.block.WallHeight;
import net.minecraft.block.WallTorchBlock;
import net.minecraft.state.properties.BedPart;
import net.minecraft.state.properties.ChestType;
import net.minecraft.state.properties.Half;
import net.minecraft.state.properties.SlabType;
import net.minecraft.state.properties.StairsShape;
import net.minecraft.util.Direction;
import net.minecraft.util.math.BlockPos;
import net.minecraft.world.World;

public class BoromirComponent1
{
	public static BlockPos start;
    public static World world;
    public static StructureBase structure;

    public static void init(World worldIn, BlockPos blockPos, StructureBase structureIn)
    {
        world = worldIn; start = blockPos; structure = structureIn;
    }
    
    public static void generatePart11()
    {
        structure.setBlockState(world, Blocks.WALL_TORCH.getDefaultState().with(WallTorchBlock.HORIZONTAL_FACING, Direction.SOUTH), 36, 3, -1, start);
        structure.setBlockState(world, Blocks.WALL_TORCH.getDefaultState().with(WallTorchBlock.HORIZONTAL_FACING, Direction.NORTH), 36, 3, 54, start);
        structure.setBlockState(world, Blocks.WALL_TORCH.getDefaultState().with(WallTorchBlock.HORIZONTAL_FACING, Direction.SOUTH), 36, 3, 58, start);
        structure.setBlockState(world, Blocks.OAK_LEAVES.getDefaultState().with(LeavesBlock.PERSISTENT, false).with(LeavesBlock.DISTANCE, 3), 36, 4, 26, start);
        structure.setBlockState(world, Blocks.OAK_LEAVES.getDefaultState().with(LeavesBlock.PERSISTENT, false).with(LeavesBlock.DISTANCE, 3), 36, 5, 29, start);
        structure.setBlockState(world, Blocks.OAK_FENCE.getDefaultState().with(FourWayBlock.WATERLOGGED, false).with(FourWayBlock.NORTH, false).with(FourWayBlock.SOUTH, false).with(FourWayBlock.EAST, true).with(FourWayBlock.WEST, true), 36, 7, -5, start);
        structure.setBlockState(world, Blocks.OAK_FENCE.getDefaultState().with(FourWayBlock.WATERLOGGED, false).with(FourWayBlock.NORTH, false).with(FourWayBlock.SOUTH, false).with(FourWayBlock.EAST, true).with(FourWayBlock.WEST, true), 36, 7, -1, start);
        structure.setBlockState(world, Blocks.OAK_LEAVES.getDefaultState().with(LeavesBlock.PERSISTENT, false).with(LeavesBlock.DISTANCE, 2), 36, 7, 22, start);
        structure.setBlockState(world, Blocks.OAK_LOG.getDefaultState(), 36, 7, 24, start);
        structure.setBlockState(world, Blocks.OAK_LEAVES.getDefaultState().with(LeavesBlock.PERSISTENT, false).with(LeavesBlock.DISTANCE, 3), 36, 7, 28, start);
        structure.setBlockState(world, Blocks.OAK_FENCE.getDefaultState().with(FourWayBlock.WATERLOGGED, false).with(FourWayBlock.NORTH, false).with(FourWayBlock.SOUTH, false).with(FourWayBlock.EAST, true).with(FourWayBlock.WEST, true), 36, 7, 54, start);
        structure.setBlockState(world, Blocks.OAK_FENCE.getDefaultState().with(FourWayBlock.WATERLOGGED, false).with(FourWayBlock.NORTH, false).with(FourWayBlock.SOUTH, false).with(FourWayBlock.EAST, true).with(FourWayBlock.WEST, true), 36, 7, 58, start);
        structure.setBlockState(world, Blocks.OAK_LEAVES.getDefaultState().with(LeavesBlock.PERSISTENT, false).with(LeavesBlock.DISTANCE, 1), 36, 8, 24, start);
        structure.setBlockState(world, Blocks.OAK_LEAVES.getDefaultState().with(LeavesBlock.PERSISTENT, false).with(LeavesBlock.DISTANCE, 2), 36, 8, 25, start);
        structure.setBlockState(world, Blocks.OAK_LEAVES.getDefaultState().with(LeavesBlock.PERSISTENT, false).with(LeavesBlock.DISTANCE, 2), 36, 9, 24, start);
        structure.setBlockState(world, Blocks.STONE_BRICK_STAIRS.getDefaultState().with(StairsBlock.FACING, Direction.WEST).with(StairsBlock.WATERLOGGED, false).with(StairsBlock.SHAPE, StairsShape.STRAIGHT).with(StairsBlock.HALF, Half.BOTTOM), 36, 10, 5, start);
        structure.setBlockState(world, Blocks.STONE_BRICK_STAIRS.getDefaultState().with(StairsBlock.FACING, Direction.WEST).with(StairsBlock.WATERLOGGED, false).with(StairsBlock.SHAPE, StairsShape.STRAIGHT).with(StairsBlock.HALF, Half.BOTTOM), 36, 10, 9, start);
        structure.setBlockState(world, Blocks.OAK_LEAVES.getDefaultState().with(LeavesBlock.PERSISTENT, false).with(LeavesBlock.DISTANCE, 3), 36, 10, 24, start);
        structure.setBlockState(world, Blocks.OAK_LEAVES.getDefaultState().with(LeavesBlock.PERSISTENT, false).with(LeavesBlock.DISTANCE, 4), 36, 10, 25, start);
        structure.setBlockState(world, Blocks.STONE_BRICK_STAIRS.getDefaultState().with(StairsBlock.FACING, Direction.SOUTH).with(StairsBlock.WATERLOGGED, false).with(StairsBlock.SHAPE, StairsShape.OUTER_RIGHT).with(StairsBlock.HALF, Half.TOP), 36, 16, 4, start);
        structure.setBlockState(world, Blocks.STONE_BRICK_STAIRS.getDefaultState().with(StairsBlock.FACING, Direction.NORTH).with(StairsBlock.WATERLOGGED, false).with(StairsBlock.SHAPE, StairsShape.OUTER_LEFT).with(StairsBlock.HALF, Half.TOP), 36, 16, 10, start);
        structure.setBlockState(world, Blocks.GRASS_BLOCK.getDefaultState().with(SnowyDirtBlock.SNOWY, false), 37, 0, 57, start);
        structure.setBlockState(world, Blocks.GRASS.getDefaultState(), 37, 1, 0, start);
        structure.setBlockState(world, Blocks.DANDELION.getDefaultState(), 37, 1, 1, start);
        structure.setBlockState(world, Blocks.DANDELION.getDefaultState(), 37, 1, 8, start);
        structure.setBlockState(world, Blocks.GRASS.getDefaultState(), 37, 1, 13, start);
        structure.setBlockState(world, Blocks.GRASS.getDefaultState(), 37, 1, 15, start);
        structure.setBlockState(world, Blocks.POPPY.getDefaultState(), 37, 1, 17, start);
        structure.setBlockState(world, Blocks.DANDELION.getDefaultState(), 37, 1, 21, start);
        structure.setBlockState(world, Blocks.GRASS.getDefaultState(), 37, 1, 23, start);
        structure.setBlockState(world, Blocks.OXEYE_DAISY.getDefaultState(), 37, 1, 29, start);
        structure.setBlockState(world, Blocks.AZURE_BLUET.getDefaultState(), 37, 1, 32, start);
        structure.setBlockState(world, Blocks.OXEYE_DAISY.getDefaultState(), 37, 1, 39, start);
        structure.setBlockState(world, Blocks.OAK_LEAVES.getDefaultState().with(LeavesBlock.PERSISTENT, false).with(LeavesBlock.DISTANCE, 2), 37, 5, 25, start);
        structure.setBlockState(world, Blocks.OAK_LEAVES.getDefaultState().with(LeavesBlock.PERSISTENT, false).with(LeavesBlock.DISTANCE, 1), 37, 7, 24, start);
        structure.setBlockState(world, Blocks.OAK_LEAVES.getDefaultState().with(LeavesBlock.PERSISTENT, false).with(LeavesBlock.DISTANCE, 4), 37, 8, 22, start);
        structure.setBlockState(world, Blocks.OAK_LEAVES.getDefaultState().with(LeavesBlock.PERSISTENT, false).with(LeavesBlock.DISTANCE, 3), 37, 8, 23, start);
        structure.setBlockState(world, Blocks.OAK_LEAVES.getDefaultState().with(LeavesBlock.PERSISTENT, false).with(LeavesBlock.DISTANCE, 3), 37, 8, 25, start);
        structure.setBlockState(world, Blocks.OAK_LEAVES.getDefaultState().with(LeavesBlock.PERSISTENT, false).with(LeavesBlock.DISTANCE, 5), 37, 9, 22, start);
        structure.setBlockState(world, Blocks.OAK_LEAVES.getDefaultState().with(LeavesBlock.PERSISTENT, false).with(LeavesBlock.DISTANCE, 4), 37, 9, 23, start);
        structure.setBlockState(world, Blocks.OAK_LEAVES.getDefaultState().with(LeavesBlock.PERSISTENT, false).with(LeavesBlock.DISTANCE, 4), 37, 10, 24, start);
        structure.setBlockState(world, Blocks.GRASS_BLOCK.getDefaultState().with(SnowyDirtBlock.SNOWY, false), 38, -4, 89, start);
        structure.setBlockState(world, Blocks.DIRT.getDefaultState(), 38, -2, 62, start);
        structure.setBlockState(world, Blocks.POPPY.getDefaultState(), 38, 1, -1, start);
        structure.setBlockState(world, Blocks.WALL_TORCH.getDefaultState().with(WallTorchBlock.HORIZONTAL_FACING, Direction.NORTH), 38, 3, -5, start);
        structure.setBlockState(world, Blocks.WALL_TORCH.getDefaultState().with(WallTorchBlock.HORIZONTAL_FACING, Direction.WEST), 38, 3, 1, start);
        structure.setBlockState(world, Blocks.OAK_TRAPDOOR.getDefaultState().with(HorizontalBlock.HORIZONTAL_FACING, Direction.WEST).with(TrapDoorBlock.HALF, Half.TOP).with(TrapDoorBlock.WATERLOGGED, false).with(TrapDoorBlock.POWERED, false).with(TrapDoorBlock.OPEN, true), 38, 3, 2, start);
        structure.setBlockState(world, Blocks.WALL_TORCH.getDefaultState().with(WallTorchBlock.HORIZONTAL_FACING, Direction.WEST), 38, 3, 3, start);
        structure.setBlockState(world, Blocks.WALL_TORCH.getDefaultState().with(WallTorchBlock.HORIZONTAL_FACING, Direction.WEST), 38, 3, 5, start);
        structure.setBlockState(world, Blocks.OAK_TRAPDOOR.getDefaultState().with(HorizontalBlock.HORIZONTAL_FACING, Direction.WEST).with(TrapDoorBlock.HALF, Half.BOTTOM).with(TrapDoorBlock.WATERLOGGED, false).with(TrapDoorBlock.POWERED, false).with(TrapDoorBlock.OPEN, true), 38, 3, 6, start);
        structure.setBlockState(world, Blocks.WALL_TORCH.getDefaultState().with(WallTorchBlock.HORIZONTAL_FACING, Direction.WEST), 38, 3, 7, start);
        structure.setBlockState(world, Blocks.WALL_TORCH.getDefaultState().with(WallTorchBlock.HORIZONTAL_FACING, Direction.WEST), 38, 3, 10, start);
        structure.setBlockState(world, Blocks.OAK_TRAPDOOR.getDefaultState().with(HorizontalBlock.HORIZONTAL_FACING, Direction.WEST).with(TrapDoorBlock.HALF, Half.TOP).with(TrapDoorBlock.WATERLOGGED, false).with(TrapDoorBlock.POWERED, false).with(TrapDoorBlock.OPEN, true), 38, 3, 11, start);
        structure.setBlockState(world, Blocks.WALL_TORCH.getDefaultState().with(WallTorchBlock.HORIZONTAL_FACING, Direction.WEST), 38, 3, 12, start);
        structure.setBlockState(world, Blocks.WALL_TORCH.getDefaultState().with(WallTorchBlock.HORIZONTAL_FACING, Direction.WEST), 38, 3, 14, start);
        structure.setBlockState(world, Blocks.OAK_TRAPDOOR.getDefaultState().with(HorizontalBlock.HORIZONTAL_FACING, Direction.WEST).with(TrapDoorBlock.HALF, Half.BOTTOM).with(TrapDoorBlock.WATERLOGGED, false).with(TrapDoorBlock.POWERED, false).with(TrapDoorBlock.OPEN, true), 38, 3, 15, start);
        structure.setBlockState(world, Blocks.WALL_TORCH.getDefaultState().with(WallTorchBlock.HORIZONTAL_FACING, Direction.WEST), 38, 3, 16, start);
        structure.setBlockState(world, Blocks.WALL_TORCH.getDefaultState().with(WallTorchBlock.HORIZONTAL_FACING, Direction.WEST), 38, 3, 19, start);
        structure.setBlockState(world, Blocks.OAK_TRAPDOOR.getDefaultState().with(HorizontalBlock.HORIZONTAL_FACING, Direction.WEST).with(TrapDoorBlock.HALF, Half.TOP).with(TrapDoorBlock.WATERLOGGED, false).with(TrapDoorBlock.POWERED, false).with(TrapDoorBlock.OPEN, true), 38, 3, 20, start);
        structure.setBlockState(world, Blocks.WALL_TORCH.getDefaultState().with(WallTorchBlock.HORIZONTAL_FACING, Direction.WEST), 38, 3, 21, start);
        structure.setBlockState(world, Blocks.WALL_TORCH.getDefaultState().with(WallTorchBlock.HORIZONTAL_FACING, Direction.WEST), 38, 3, 23, start);
        structure.setBlockState(world, Blocks.OAK_TRAPDOOR.getDefaultState().with(HorizontalBlock.HORIZONTAL_FACING, Direction.WEST).with(TrapDoorBlock.HALF, Half.BOTTOM).with(TrapDoorBlock.WATERLOGGED, false).with(TrapDoorBlock.POWERED, false).with(TrapDoorBlock.OPEN, true), 38, 3, 24, start);
        structure.setBlockState(world, Blocks.WALL_TORCH.getDefaultState().with(WallTorchBlock.HORIZONTAL_FACING, Direction.WEST), 38, 3, 25, start);
        structure.setBlockState(world, Blocks.WALL_TORCH.getDefaultState().with(WallTorchBlock.HORIZONTAL_FACING, Direction.WEST), 38, 3, 28, start);
        structure.setBlockState(world, Blocks.OAK_TRAPDOOR.getDefaultState().with(HorizontalBlock.HORIZONTAL_FACING, Direction.WEST).with(TrapDoorBlock.HALF, Half.TOP).with(TrapDoorBlock.WATERLOGGED, false).with(TrapDoorBlock.POWERED, false).with(TrapDoorBlock.OPEN, true), 38, 3, 29, start);
        structure.setBlockState(world, Blocks.WALL_TORCH.getDefaultState().with(WallTorchBlock.HORIZONTAL_FACING, Direction.WEST), 38, 3, 30, start);
        structure.setBlockState(world, Blocks.WALL_TORCH.getDefaultState().with(WallTorchBlock.HORIZONTAL_FACING, Direction.WEST), 38, 3, 32, start);
        structure.setBlockState(world, Blocks.OAK_TRAPDOOR.getDefaultState().with(HorizontalBlock.HORIZONTAL_FACING, Direction.WEST).with(TrapDoorBlock.HALF, Half.BOTTOM).with(TrapDoorBlock.WATERLOGGED, false).with(TrapDoorBlock.POWERED, false).with(TrapDoorBlock.OPEN, true), 38, 3, 33, start);
        structure.setBlockState(world, Blocks.WALL_TORCH.getDefaultState().with(WallTorchBlock.HORIZONTAL_FACING, Direction.WEST), 38, 3, 34, start);
        structure.setBlockState(world, Blocks.WALL_TORCH.getDefaultState().with(WallTorchBlock.HORIZONTAL_FACING, Direction.WEST), 38, 3, 37, start);
        structure.setBlockState(world, Blocks.OAK_TRAPDOOR.getDefaultState().with(HorizontalBlock.HORIZONTAL_FACING, Direction.WEST).with(TrapDoorBlock.HALF, Half.TOP).with(TrapDoorBlock.WATERLOGGED, false).with(TrapDoorBlock.POWERED, false).with(TrapDoorBlock.OPEN, true), 38, 3, 38, start);
        structure.setBlockState(world, Blocks.WALL_TORCH.getDefaultState().with(WallTorchBlock.HORIZONTAL_FACING, Direction.WEST), 38, 3, 39, start);
        structure.setBlockState(world, Blocks.WALL_TORCH.getDefaultState().with(WallTorchBlock.HORIZONTAL_FACING, Direction.WEST), 38, 3, 41, start);
        structure.setBlockState(world, Blocks.OAK_TRAPDOOR.getDefaultState().with(HorizontalBlock.HORIZONTAL_FACING, Direction.WEST).with(TrapDoorBlock.HALF, Half.BOTTOM).with(TrapDoorBlock.WATERLOGGED, false).with(TrapDoorBlock.POWERED, false).with(TrapDoorBlock.OPEN, true), 38, 3, 42, start);
        structure.setBlockState(world, Blocks.WALL_TORCH.getDefaultState().with(WallTorchBlock.HORIZONTAL_FACING, Direction.WEST), 38, 3, 43, start);
        structure.setBlockState(world, Blocks.WALL_TORCH.getDefaultState().with(WallTorchBlock.HORIZONTAL_FACING, Direction.WEST), 38, 3, 46, start);
        structure.setBlockState(world, Blocks.OAK_TRAPDOOR.getDefaultState().with(HorizontalBlock.HORIZONTAL_FACING, Direction.WEST).with(TrapDoorBlock.HALF, Half.TOP).with(TrapDoorBlock.WATERLOGGED, false).with(TrapDoorBlock.POWERED, false).with(TrapDoorBlock.OPEN, true), 38, 3, 47, start);
        structure.setBlockState(world, Blocks.WALL_TORCH.getDefaultState().with(WallTorchBlock.HORIZONTAL_FACING, Direction.WEST), 38, 3, 48, start);
        structure.setBlockState(world, Blocks.WALL_TORCH.getDefaultState().with(WallTorchBlock.HORIZONTAL_FACING, Direction.WEST), 38, 3, 50, start);
        structure.setBlockState(world, Blocks.OAK_TRAPDOOR.getDefaultState().with(HorizontalBlock.HORIZONTAL_FACING, Direction.WEST).with(TrapDoorBlock.HALF, Half.BOTTOM).with(TrapDoorBlock.WATERLOGGED, false).with(TrapDoorBlock.POWERED, false).with(TrapDoorBlock.OPEN, true), 38, 3, 51, start);
        structure.setBlockState(world, Blocks.WALL_TORCH.getDefaultState().with(WallTorchBlock.HORIZONTAL_FACING, Direction.WEST), 38, 3, 52, start);
        structure.setBlockState(world, Blocks.WALL_TORCH.getDefaultState().with(WallTorchBlock.HORIZONTAL_FACING, Direction.SOUTH), 38, 3, 58, start);
        structure.setBlockState(world, Blocks.OAK_FENCE.getDefaultState().with(FourWayBlock.WATERLOGGED, false).with(FourWayBlock.NORTH, false).with(FourWayBlock.SOUTH, false).with(FourWayBlock.EAST, true).with(FourWayBlock.WEST, true), 38, 7, -5, start);
        structure.setBlockState(world, Blocks.OAK_FENCE.getDefaultState().with(FourWayBlock.WATERLOGGED, false).with(FourWayBlock.NORTH, false).with(FourWayBlock.SOUTH, true).with(FourWayBlock.EAST, false).with(FourWayBlock.WEST, true), 38, 7, -1, start);
        structure.setBlockState(world, Blocks.OAK_FENCE.getDefaultState().with(FourWayBlock.WATERLOGGED, false).with(FourWayBlock.NORTH, true).with(FourWayBlock.SOUTH, true).with(FourWayBlock.EAST, false).with(FourWayBlock.WEST, false), 38, 7, 1, start);
        structure.setBlockState(world, Blocks.OAK_LOG.getDefaultState(), 38, 7, 2, start);
        structure.setBlockState(world, Blocks.OAK_FENCE.getDefaultState().with(FourWayBlock.WATERLOGGED, false).with(FourWayBlock.NORTH, true).with(FourWayBlock.SOUTH, true).with(FourWayBlock.EAST, false).with(FourWayBlock.WEST, false), 38, 7, 3, start);
        structure.setBlockState(world, Blocks.OAK_FENCE.getDefaultState().with(FourWayBlock.WATERLOGGED, false).with(FourWayBlock.NORTH, true).with(FourWayBlock.SOUTH, true).with(FourWayBlock.EAST, false).with(FourWayBlock.WEST, false), 38, 7, 5, start);
        structure.setBlockState(world, Blocks.OAK_LOG.getDefaultState(), 38, 7, 6, start);
        structure.setBlockState(world, Blocks.OAK_FENCE.getDefaultState().with(FourWayBlock.WATERLOGGED, false).with(FourWayBlock.NORTH, true).with(FourWayBlock.SOUTH, true).with(FourWayBlock.EAST, false).with(FourWayBlock.WEST, false), 38, 7, 7, start);
        structure.setBlockState(world, Blocks.OAK_FENCE.getDefaultState().with(FourWayBlock.WATERLOGGED, false).with(FourWayBlock.NORTH, true).with(FourWayBlock.SOUTH, true).with(FourWayBlock.EAST, false).with(FourWayBlock.WEST, false), 38, 7, 10, start);
        structure.setBlockState(world, Blocks.OAK_LOG.getDefaultState(), 38, 7, 11, start);
        structure.setBlockState(world, Blocks.OAK_FENCE.getDefaultState().with(FourWayBlock.WATERLOGGED, false).with(FourWayBlock.NORTH, true).with(FourWayBlock.SOUTH, true).with(FourWayBlock.EAST, false).with(FourWayBlock.WEST, false), 38, 7, 12, start);
        structure.setBlockState(world, Blocks.OAK_FENCE.getDefaultState().with(FourWayBlock.WATERLOGGED, false).with(FourWayBlock.NORTH, true).with(FourWayBlock.SOUTH, true).with(FourWayBlock.EAST, false).with(FourWayBlock.WEST, false), 38, 7, 14, start);
        structure.setBlockState(world, Blocks.OAK_LOG.getDefaultState(), 38, 7, 15, start);
        structure.setBlockState(world, Blocks.OAK_FENCE.getDefaultState().with(FourWayBlock.WATERLOGGED, false).with(FourWayBlock.NORTH, true).with(FourWayBlock.SOUTH, true).with(FourWayBlock.EAST, false).with(FourWayBlock.WEST, false), 38, 7, 16, start);
        structure.setBlockState(world, Blocks.OAK_FENCE.getDefaultState().with(FourWayBlock.WATERLOGGED, false).with(FourWayBlock.NORTH, true).with(FourWayBlock.SOUTH, true).with(FourWayBlock.EAST, false).with(FourWayBlock.WEST, false), 38, 7, 19, start);
        structure.setBlockState(world, Blocks.OAK_LOG.getDefaultState(), 38, 7, 20, start);
        structure.setBlockState(world, Blocks.OAK_FENCE.getDefaultState().with(FourWayBlock.WATERLOGGED, false).with(FourWayBlock.NORTH, true).with(FourWayBlock.SOUTH, true).with(FourWayBlock.EAST, false).with(FourWayBlock.WEST, false), 38, 7, 21, start);
        structure.setBlockState(world, Blocks.OAK_FENCE.getDefaultState().with(FourWayBlock.WATERLOGGED, false).with(FourWayBlock.NORTH, true).with(FourWayBlock.SOUTH, true).with(FourWayBlock.EAST, false).with(FourWayBlock.WEST, false), 38, 7, 23, start);
        structure.setBlockState(world, Blocks.OAK_LOG.getDefaultState(), 38, 7, 24, start);
        structure.setBlockState(world, Blocks.OAK_FENCE.getDefaultState().with(FourWayBlock.WATERLOGGED, false).with(FourWayBlock.NORTH, true).with(FourWayBlock.SOUTH, true).with(FourWayBlock.EAST, false).with(FourWayBlock.WEST, false), 38, 7, 25, start);
        structure.setBlockState(world, Blocks.OAK_FENCE.getDefaultState().with(FourWayBlock.WATERLOGGED, false).with(FourWayBlock.NORTH, true).with(FourWayBlock.SOUTH, true).with(FourWayBlock.EAST, false).with(FourWayBlock.WEST, false), 38, 7, 28, start);
        structure.setBlockState(world, Blocks.OAK_LOG.getDefaultState(), 38, 7, 29, start);
        structure.setBlockState(world, Blocks.OAK_FENCE.getDefaultState().with(FourWayBlock.WATERLOGGED, false).with(FourWayBlock.NORTH, true).with(FourWayBlock.SOUTH, true).with(FourWayBlock.EAST, false).with(FourWayBlock.WEST, false), 38, 7, 30, start);
        structure.setBlockState(world, Blocks.OAK_FENCE.getDefaultState().with(FourWayBlock.WATERLOGGED, false).with(FourWayBlock.NORTH, true).with(FourWayBlock.SOUTH, true).with(FourWayBlock.EAST, false).with(FourWayBlock.WEST, false), 38, 7, 32, start);
        structure.setBlockState(world, Blocks.OAK_LOG.getDefaultState(), 38, 7, 33, start);
        structure.setBlockState(world, Blocks.OAK_FENCE.getDefaultState().with(FourWayBlock.WATERLOGGED, false).with(FourWayBlock.NORTH, true).with(FourWayBlock.SOUTH, true).with(FourWayBlock.EAST, false).with(FourWayBlock.WEST, false), 38, 7, 34, start);
        structure.setBlockState(world, Blocks.OAK_FENCE.getDefaultState().with(FourWayBlock.WATERLOGGED, false).with(FourWayBlock.NORTH, true).with(FourWayBlock.SOUTH, true).with(FourWayBlock.EAST, false).with(FourWayBlock.WEST, false), 38, 7, 37, start);
        structure.setBlockState(world, Blocks.OAK_LOG.getDefaultState(), 38, 7, 38, start);
        structure.setBlockState(world, Blocks.OAK_FENCE.getDefaultState().with(FourWayBlock.WATERLOGGED, false).with(FourWayBlock.NORTH, true).with(FourWayBlock.SOUTH, true).with(FourWayBlock.EAST, false).with(FourWayBlock.WEST, false), 38, 7, 39, start);
        structure.setBlockState(world, Blocks.OAK_FENCE.getDefaultState().with(FourWayBlock.WATERLOGGED, false).with(FourWayBlock.NORTH, true).with(FourWayBlock.SOUTH, true).with(FourWayBlock.EAST, false).with(FourWayBlock.WEST, false), 38, 7, 41, start);
        structure.setBlockState(world, Blocks.OAK_LOG.getDefaultState(), 38, 7, 42, start);
        structure.setBlockState(world, Blocks.OAK_FENCE.getDefaultState().with(FourWayBlock.WATERLOGGED, false).with(FourWayBlock.NORTH, true).with(FourWayBlock.SOUTH, true).with(FourWayBlock.EAST, false).with(FourWayBlock.WEST, false), 38, 7, 43, start);
        structure.setBlockState(world, Blocks.OAK_FENCE.getDefaultState().with(FourWayBlock.WATERLOGGED, false).with(FourWayBlock.NORTH, true).with(FourWayBlock.SOUTH, true).with(FourWayBlock.EAST, false).with(FourWayBlock.WEST, false), 38, 7, 46, start);
        structure.setBlockState(world, Blocks.OAK_LOG.getDefaultState(), 38, 7, 47, start);
        structure.setBlockState(world, Blocks.OAK_FENCE.getDefaultState().with(FourWayBlock.WATERLOGGED, false).with(FourWayBlock.NORTH, true).with(FourWayBlock.SOUTH, true).with(FourWayBlock.EAST, false).with(FourWayBlock.WEST, false), 38, 7, 48, start);
        structure.setBlockState(world, Blocks.OAK_FENCE.getDefaultState().with(FourWayBlock.WATERLOGGED, false).with(FourWayBlock.NORTH, true).with(FourWayBlock.SOUTH, true).with(FourWayBlock.EAST, false).with(FourWayBlock.WEST, false), 38, 7, 50, start);
        structure.setBlockState(world, Blocks.OAK_LOG.getDefaultState(), 38, 7, 51, start);
        structure.setBlockState(world, Blocks.OAK_FENCE.getDefaultState().with(FourWayBlock.WATERLOGGED, false).with(FourWayBlock.NORTH, true).with(FourWayBlock.SOUTH, true).with(FourWayBlock.EAST, false).with(FourWayBlock.WEST, false), 38, 7, 52, start);
        structure.setBlockState(world, Blocks.OAK_FENCE.getDefaultState().with(FourWayBlock.WATERLOGGED, false).with(FourWayBlock.NORTH, true).with(FourWayBlock.SOUTH, false).with(FourWayBlock.EAST, false).with(FourWayBlock.WEST, true), 38, 7, 54, start);
        structure.setBlockState(world, Blocks.OAK_FENCE.getDefaultState().with(FourWayBlock.WATERLOGGED, false).with(FourWayBlock.NORTH, false).with(FourWayBlock.SOUTH, false).with(FourWayBlock.EAST, true).with(FourWayBlock.WEST, true), 38, 7, 58, start);
        structure.setBlockState(world, Blocks.OAK_LEAVES.getDefaultState().with(LeavesBlock.PERSISTENT, false).with(LeavesBlock.DISTANCE, 2), 38, 8, 23, start);
        structure.setBlockState(world, Blocks.OAK_LEAVES.getDefaultState().with(LeavesBlock.PERSISTENT, false).with(LeavesBlock.DISTANCE, 1), 38, 8, 24, start);
        structure.setBlockState(world, Blocks.OAK_LEAVES.getDefaultState().with(LeavesBlock.PERSISTENT, false).with(LeavesBlock.DISTANCE, 2), 38, 8, 25, start);
        structure.setBlockState(world, Blocks.OAK_LEAVES.getDefaultState().with(LeavesBlock.PERSISTENT, false).with(LeavesBlock.DISTANCE, 3), 38, 9, 23, start);
        structure.setBlockState(world, Blocks.OAK_LEAVES.getDefaultState().with(LeavesBlock.PERSISTENT, false).with(LeavesBlock.DISTANCE, 2), 38, 9, 24, start);
        structure.setBlockState(world, Blocks.OAK_LEAVES.getDefaultState().with(LeavesBlock.PERSISTENT, false).with(LeavesBlock.DISTANCE, 3), 38, 9, 25, start);
        structure.setBlockState(world, Blocks.OAK_TRAPDOOR.getDefaultState().with(HorizontalBlock.HORIZONTAL_FACING, Direction.NORTH).with(TrapDoorBlock.HALF, Half.BOTTOM).with(TrapDoorBlock.WATERLOGGED, false).with(TrapDoorBlock.POWERED, false).with(TrapDoorBlock.OPEN, true), 39, 3, -5, start);
        structure.setBlockState(world, Blocks.WALL_TORCH.getDefaultState().with(WallTorchBlock.HORIZONTAL_FACING, Direction.EAST), 39, 3, 4, start);
        structure.setBlockState(world, Blocks.WALL_TORCH.getDefaultState().with(WallTorchBlock.HORIZONTAL_FACING, Direction.EAST), 39, 3, 13, start);
        structure.setBlockState(world, Blocks.WALL_TORCH.getDefaultState().with(WallTorchBlock.HORIZONTAL_FACING, Direction.EAST), 39, 3, 22, start);
        structure.setBlockState(world, Blocks.WALL_TORCH.getDefaultState().with(WallTorchBlock.HORIZONTAL_FACING, Direction.EAST), 39, 3, 31, start);
        structure.setBlockState(world, Blocks.WALL_TORCH.getDefaultState().with(WallTorchBlock.HORIZONTAL_FACING, Direction.EAST), 39, 3, 40, start);
        structure.setBlockState(world, Blocks.WALL_TORCH.getDefaultState().with(WallTorchBlock.HORIZONTAL_FACING, Direction.EAST), 39, 3, 49, start);
        structure.setBlockState(world, Blocks.STONE.getDefaultState(), 40, -10, 91, start);
        structure.setBlockState(world, Blocks.IRON_ORE.getDefaultState(), 40, -4, 45, start);
        structure.setBlockState(world, Blocks.GRASS.getDefaultState(), 40, 0, -9, start);
        structure.setBlockState(world, Blocks.OAK_TRAPDOOR.getDefaultState().with(HorizontalBlock.HORIZONTAL_FACING, Direction.NORTH).with(TrapDoorBlock.HALF, Half.TOP).with(TrapDoorBlock.WATERLOGGED, false).with(TrapDoorBlock.POWERED, false).with(TrapDoorBlock.OPEN, true), 40, 3, -5, start);
        structure.setBlockState(world, Blocks.STONE.getDefaultState(), 41, -8, -33, start);
        structure.setBlockState(world, Blocks.COAL_ORE.getDefaultState(), 41, -4, 59, start);
        structure.setBlockState(world, Blocks.STONE.getDefaultState(), 41, -4, 60, start);
        structure.setBlockState(world, Blocks.COAL_ORE.getDefaultState(), 41, -3, 53, start);
        structure.setBlockState(world, Blocks.DIRT.getDefaultState(), 41, -3, 64, start);
        structure.setBlockState(world, Blocks.GRASS.getDefaultState(), 41, -1, 63, start);
        structure.setBlockState(world, Blocks.GRASS_BLOCK.getDefaultState().with(SnowyDirtBlock.SNOWY, false), 41, 0, 0, start);
        structure.setBlockState(world, Blocks.GRASS_BLOCK.getDefaultState().with(SnowyDirtBlock.SNOWY, false), 41, 0, 4, start);
        structure.setBlockState(world, Blocks.GRASS_BLOCK.getDefaultState().with(SnowyDirtBlock.SNOWY, false), 41, 0, 13, start);
        structure.setBlockState(world, Blocks.GRASS_BLOCK.getDefaultState().with(SnowyDirtBlock.SNOWY, false), 41, 0, 22, start);
        structure.setBlockState(world, Blocks.GRASS_BLOCK.getDefaultState().with(SnowyDirtBlock.SNOWY, false), 41, 0, 31, start);
        structure.setBlockState(world, Blocks.GRASS_BLOCK.getDefaultState().with(SnowyDirtBlock.SNOWY, false), 41, 0, 40, start);
        structure.setBlockState(world, Blocks.GRASS_BLOCK.getDefaultState().with(SnowyDirtBlock.SNOWY, false), 41, 0, 49, start);
        structure.setBlockState(world, Blocks.GRASS_BLOCK.getDefaultState().with(SnowyDirtBlock.SNOWY, false), 41, 0, 53, start);
        structure.setBlockState(world, Blocks.WALL_TORCH.getDefaultState().with(WallTorchBlock.HORIZONTAL_FACING, Direction.NORTH), 41, 3, -5, start);
        structure.setBlockState(world, Blocks.WALL_TORCH.getDefaultState().with(WallTorchBlock.HORIZONTAL_FACING, Direction.WEST), 41, 3, 4, start);
        structure.setBlockState(world, Blocks.WALL_TORCH.getDefaultState().with(WallTorchBlock.HORIZONTAL_FACING, Direction.WEST), 41, 3, 13, start);
        structure.setBlockState(world, Blocks.WALL_TORCH.getDefaultState().with(WallTorchBlock.HORIZONTAL_FACING, Direction.WEST), 41, 3, 22, start);
        structure.setBlockState(world, Blocks.WALL_TORCH.getDefaultState().with(WallTorchBlock.HORIZONTAL_FACING, Direction.WEST), 41, 3, 31, start);
        structure.setBlockState(world, Blocks.WALL_TORCH.getDefaultState().with(WallTorchBlock.HORIZONTAL_FACING, Direction.WEST), 41, 3, 40, start);
        structure.setBlockState(world, Blocks.WALL_TORCH.getDefaultState().with(WallTorchBlock.HORIZONTAL_FACING, Direction.WEST), 41, 3, 49, start);
        structure.setBlockState(world, Blocks.WALL_TORCH.getDefaultState().with(WallTorchBlock.HORIZONTAL_FACING, Direction.SOUTH), 41, 3, 58, start);
        structure.setBlockState(world, Blocks.OAK_FENCE.getDefaultState().with(FourWayBlock.WATERLOGGED, false).with(FourWayBlock.NORTH, false).with(FourWayBlock.SOUTH, false).with(FourWayBlock.EAST, true).with(FourWayBlock.WEST, true), 41, 7, -5, start);
        structure.setBlockState(world, Blocks.OAK_FENCE.getDefaultState().with(FourWayBlock.WATERLOGGED, false).with(FourWayBlock.NORTH, false).with(FourWayBlock.SOUTH, false).with(FourWayBlock.EAST, true).with(FourWayBlock.WEST, true), 41, 7, 58, start);
        structure.setBlockState(world, Blocks.GRASS.getDefaultState(), 42, 1, -6, start);
        structure.setBlockState(world, Blocks.WALL_TORCH.getDefaultState().with(WallTorchBlock.HORIZONTAL_FACING, Direction.EAST), 42, 3, -4, start);
        structure.setBlockState(world, Blocks.WALL_TORCH.getDefaultState().with(WallTorchBlock.HORIZONTAL_FACING, Direction.EAST), 42, 3, -1, start);
        structure.setBlockState(world, Blocks.WALL_TORCH.getDefaultState().with(WallTorchBlock.HORIZONTAL_FACING, Direction.EAST), 42, 3, 1, start);
        structure.setBlockState(world, Blocks.OAK_TRAPDOOR.getDefaultState().with(HorizontalBlock.HORIZONTAL_FACING, Direction.EAST).with(TrapDoorBlock.HALF, Half.BOTTOM).with(TrapDoorBlock.WATERLOGGED, false).with(TrapDoorBlock.POWERED, false).with(TrapDoorBlock.OPEN, true), 42, 3, 2, start);
        structure.setBlockState(world, Blocks.WALL_TORCH.getDefaultState().with(WallTorchBlock.HORIZONTAL_FACING, Direction.EAST), 42, 3, 3, start);
        structure.setBlockState(world, Blocks.WALL_TORCH.getDefaultState().with(WallTorchBlock.HORIZONTAL_FACING, Direction.EAST), 42, 3, 5, start);
        structure.setBlockState(world, Blocks.OAK_TRAPDOOR.getDefaultState().with(HorizontalBlock.HORIZONTAL_FACING, Direction.EAST).with(TrapDoorBlock.HALF, Half.BOTTOM).with(TrapDoorBlock.WATERLOGGED, false).with(TrapDoorBlock.POWERED, false).with(TrapDoorBlock.OPEN, true), 42, 3, 6, start);
        structure.setBlockState(world, Blocks.WALL_TORCH.getDefaultState().with(WallTorchBlock.HORIZONTAL_FACING, Direction.EAST), 42, 3, 7, start);
        structure.setBlockState(world, Blocks.WALL_TORCH.getDefaultState().with(WallTorchBlock.HORIZONTAL_FACING, Direction.EAST), 42, 3, 10, start);
        structure.setBlockState(world, Blocks.OAK_TRAPDOOR.getDefaultState().with(HorizontalBlock.HORIZONTAL_FACING, Direction.EAST).with(TrapDoorBlock.HALF, Half.BOTTOM).with(TrapDoorBlock.WATERLOGGED, false).with(TrapDoorBlock.POWERED, false).with(TrapDoorBlock.OPEN, true), 42, 3, 11, start);
        structure.setBlockState(world, Blocks.WALL_TORCH.getDefaultState().with(WallTorchBlock.HORIZONTAL_FACING, Direction.EAST), 42, 3, 12, start);
        structure.setBlockState(world, Blocks.WALL_TORCH.getDefaultState().with(WallTorchBlock.HORIZONTAL_FACING, Direction.EAST), 42, 3, 14, start);
        structure.setBlockState(world, Blocks.OAK_TRAPDOOR.getDefaultState().with(HorizontalBlock.HORIZONTAL_FACING, Direction.EAST).with(TrapDoorBlock.HALF, Half.BOTTOM).with(TrapDoorBlock.WATERLOGGED, false).with(TrapDoorBlock.POWERED, false).with(TrapDoorBlock.OPEN, true), 42, 3, 15, start);
        structure.setBlockState(world, Blocks.WALL_TORCH.getDefaultState().with(WallTorchBlock.HORIZONTAL_FACING, Direction.EAST), 42, 3, 16, start);
        structure.setBlockState(world, Blocks.WALL_TORCH.getDefaultState().with(WallTorchBlock.HORIZONTAL_FACING, Direction.EAST), 42, 3, 19, start);
        structure.setBlockState(world, Blocks.OAK_TRAPDOOR.getDefaultState().with(HorizontalBlock.HORIZONTAL_FACING, Direction.EAST).with(TrapDoorBlock.HALF, Half.BOTTOM).with(TrapDoorBlock.WATERLOGGED, false).with(TrapDoorBlock.POWERED, false).with(TrapDoorBlock.OPEN, true), 42, 3, 20, start);
        structure.setBlockState(world, Blocks.WALL_TORCH.getDefaultState().with(WallTorchBlock.HORIZONTAL_FACING, Direction.EAST), 42, 3, 21, start);
        structure.setBlockState(world, Blocks.WALL_TORCH.getDefaultState().with(WallTorchBlock.HORIZONTAL_FACING, Direction.EAST), 42, 3, 23, start);
        structure.setBlockState(world, Blocks.OAK_TRAPDOOR.getDefaultState().with(HorizontalBlock.HORIZONTAL_FACING, Direction.EAST).with(TrapDoorBlock.HALF, Half.BOTTOM).with(TrapDoorBlock.WATERLOGGED, false).with(TrapDoorBlock.POWERED, false).with(TrapDoorBlock.OPEN, true), 42, 3, 24, start);
        structure.setBlockState(world, Blocks.WALL_TORCH.getDefaultState().with(WallTorchBlock.HORIZONTAL_FACING, Direction.EAST), 42, 3, 25, start);
        structure.setBlockState(world, Blocks.WALL_TORCH.getDefaultState().with(WallTorchBlock.HORIZONTAL_FACING, Direction.EAST), 42, 3, 28, start);
        structure.setBlockState(world, Blocks.OAK_TRAPDOOR.getDefaultState().with(HorizontalBlock.HORIZONTAL_FACING, Direction.EAST).with(TrapDoorBlock.HALF, Half.BOTTOM).with(TrapDoorBlock.WATERLOGGED, false).with(TrapDoorBlock.POWERED, false).with(TrapDoorBlock.OPEN, true), 42, 3, 29, start);
        structure.setBlockState(world, Blocks.WALL_TORCH.getDefaultState().with(WallTorchBlock.HORIZONTAL_FACING, Direction.EAST), 42, 3, 30, start);
        structure.setBlockState(world, Blocks.WALL_TORCH.getDefaultState().with(WallTorchBlock.HORIZONTAL_FACING, Direction.EAST), 42, 3, 32, start);
        structure.setBlockState(world, Blocks.OAK_TRAPDOOR.getDefaultState().with(HorizontalBlock.HORIZONTAL_FACING, Direction.EAST).with(TrapDoorBlock.HALF, Half.BOTTOM).with(TrapDoorBlock.WATERLOGGED, false).with(TrapDoorBlock.POWERED, false).with(TrapDoorBlock.OPEN, true), 42, 3, 33, start);
        structure.setBlockState(world, Blocks.WALL_TORCH.getDefaultState().with(WallTorchBlock.HORIZONTAL_FACING, Direction.EAST), 42, 3, 34, start);
        structure.setBlockState(world, Blocks.WALL_TORCH.getDefaultState().with(WallTorchBlock.HORIZONTAL_FACING, Direction.EAST), 42, 3, 37, start);
        structure.setBlockState(world, Blocks.OAK_TRAPDOOR.getDefaultState().with(HorizontalBlock.HORIZONTAL_FACING, Direction.EAST).with(TrapDoorBlock.HALF, Half.BOTTOM).with(TrapDoorBlock.WATERLOGGED, false).with(TrapDoorBlock.POWERED, false).with(TrapDoorBlock.OPEN, true), 42, 3, 38, start);
        structure.setBlockState(world, Blocks.WALL_TORCH.getDefaultState().with(WallTorchBlock.HORIZONTAL_FACING, Direction.EAST), 42, 3, 39, start);
        structure.setBlockState(world, Blocks.WALL_TORCH.getDefaultState().with(WallTorchBlock.HORIZONTAL_FACING, Direction.EAST), 42, 3, 41, start);
        structure.setBlockState(world, Blocks.OAK_TRAPDOOR.getDefaultState().with(HorizontalBlock.HORIZONTAL_FACING, Direction.EAST).with(TrapDoorBlock.HALF, Half.BOTTOM).with(TrapDoorBlock.WATERLOGGED, false).with(TrapDoorBlock.POWERED, false).with(TrapDoorBlock.OPEN, true), 42, 3, 42, start);
        structure.setBlockState(world, Blocks.WALL_TORCH.getDefaultState().with(WallTorchBlock.HORIZONTAL_FACING, Direction.EAST), 42, 3, 43, start);
        structure.setBlockState(world, Blocks.WALL_TORCH.getDefaultState().with(WallTorchBlock.HORIZONTAL_FACING, Direction.EAST), 42, 3, 46, start);
        structure.setBlockState(world, Blocks.OAK_TRAPDOOR.getDefaultState().with(HorizontalBlock.HORIZONTAL_FACING, Direction.EAST).with(TrapDoorBlock.HALF, Half.BOTTOM).with(TrapDoorBlock.WATERLOGGED, false).with(TrapDoorBlock.POWERED, false).with(TrapDoorBlock.OPEN, true), 42, 3, 47, start);
        structure.setBlockState(world, Blocks.WALL_TORCH.getDefaultState().with(WallTorchBlock.HORIZONTAL_FACING, Direction.EAST), 42, 3, 48, start);
        structure.setBlockState(world, Blocks.WALL_TORCH.getDefaultState().with(WallTorchBlock.HORIZONTAL_FACING, Direction.EAST), 42, 3, 50, start);
        structure.setBlockState(world, Blocks.OAK_TRAPDOOR.getDefaultState().with(HorizontalBlock.HORIZONTAL_FACING, Direction.EAST).with(TrapDoorBlock.HALF, Half.BOTTOM).with(TrapDoorBlock.WATERLOGGED, false).with(TrapDoorBlock.POWERED, false).with(TrapDoorBlock.OPEN, true), 42, 3, 51, start);
        structure.setBlockState(world, Blocks.WALL_TORCH.getDefaultState().with(WallTorchBlock.HORIZONTAL_FACING, Direction.EAST), 42, 3, 52, start);
        structure.setBlockState(world, Blocks.WALL_TORCH.getDefaultState().with(WallTorchBlock.HORIZONTAL_FACING, Direction.EAST), 42, 3, 54, start);
        structure.setBlockState(world, Blocks.OAK_TRAPDOOR.getDefaultState().with(HorizontalBlock.HORIZONTAL_FACING, Direction.EAST).with(TrapDoorBlock.HALF, Half.BOTTOM).with(TrapDoorBlock.WATERLOGGED, false).with(TrapDoorBlock.POWERED, false).with(TrapDoorBlock.OPEN, true), 42, 3, 55, start);
        structure.setBlockState(world, Blocks.OAK_TRAPDOOR.getDefaultState().with(HorizontalBlock.HORIZONTAL_FACING, Direction.EAST).with(TrapDoorBlock.HALF, Half.TOP).with(TrapDoorBlock.WATERLOGGED, false).with(TrapDoorBlock.POWERED, false).with(TrapDoorBlock.OPEN, true), 42, 3, 56, start);
        structure.setBlockState(world, Blocks.WALL_TORCH.getDefaultState().with(WallTorchBlock.HORIZONTAL_FACING, Direction.EAST), 42, 3, 57, start);
        structure.setBlockState(world, Blocks.OAK_FENCE.getDefaultState().with(FourWayBlock.WATERLOGGED, false).with(FourWayBlock.NORTH, true).with(FourWayBlock.SOUTH, true).with(FourWayBlock.EAST, false).with(FourWayBlock.WEST, false), 42, 7, -4, start);
        structure.setBlockState(world, Blocks.OAK_FENCE.getDefaultState().with(FourWayBlock.WATERLOGGED, false).with(FourWayBlock.NORTH, true).with(FourWayBlock.SOUTH, true).with(FourWayBlock.EAST, false).with(FourWayBlock.WEST, false), 42, 7, -1, start);
        structure.setBlockState(world, Blocks.OAK_FENCE.getDefaultState().with(FourWayBlock.WATERLOGGED, false).with(FourWayBlock.NORTH, true).with(FourWayBlock.SOUTH, true).with(FourWayBlock.EAST, false).with(FourWayBlock.WEST, false), 42, 7, 1, start);
        structure.setBlockState(world, Blocks.OAK_LOG.getDefaultState(), 42, 7, 2, start);
        structure.setBlockState(world, Blocks.OAK_FENCE.getDefaultState().with(FourWayBlock.WATERLOGGED, false).with(FourWayBlock.NORTH, true).with(FourWayBlock.SOUTH, true).with(FourWayBlock.EAST, false).with(FourWayBlock.WEST, false), 42, 7, 3, start);
        structure.setBlockState(world, Blocks.OAK_FENCE.getDefaultState().with(FourWayBlock.WATERLOGGED, false).with(FourWayBlock.NORTH, true).with(FourWayBlock.SOUTH, true).with(FourWayBlock.EAST, false).with(FourWayBlock.WEST, false), 42, 7, 5, start);
        structure.setBlockState(world, Blocks.OAK_LOG.getDefaultState(), 42, 7, 6, start);
        structure.setBlockState(world, Blocks.OAK_FENCE.getDefaultState().with(FourWayBlock.WATERLOGGED, false).with(FourWayBlock.NORTH, true).with(FourWayBlock.SOUTH, true).with(FourWayBlock.EAST, false).with(FourWayBlock.WEST, false), 42, 7, 7, start);
        structure.setBlockState(world, Blocks.OAK_FENCE.getDefaultState().with(FourWayBlock.WATERLOGGED, false).with(FourWayBlock.NORTH, true).with(FourWayBlock.SOUTH, true).with(FourWayBlock.EAST, false).with(FourWayBlock.WEST, false), 42, 7, 10, start);
        structure.setBlockState(world, Blocks.OAK_LOG.getDefaultState(), 42, 7, 11, start);
        structure.setBlockState(world, Blocks.OAK_FENCE.getDefaultState().with(FourWayBlock.WATERLOGGED, false).with(FourWayBlock.NORTH, true).with(FourWayBlock.SOUTH, true).with(FourWayBlock.EAST, false).with(FourWayBlock.WEST, false), 42, 7, 12, start);
        structure.setBlockState(world, Blocks.OAK_FENCE.getDefaultState().with(FourWayBlock.WATERLOGGED, false).with(FourWayBlock.NORTH, true).with(FourWayBlock.SOUTH, true).with(FourWayBlock.EAST, false).with(FourWayBlock.WEST, false), 42, 7, 14, start);
        structure.setBlockState(world, Blocks.OAK_LOG.getDefaultState(), 42, 7, 15, start);
        structure.setBlockState(world, Blocks.OAK_FENCE.getDefaultState().with(FourWayBlock.WATERLOGGED, false).with(FourWayBlock.NORTH, true).with(FourWayBlock.SOUTH, true).with(FourWayBlock.EAST, false).with(FourWayBlock.WEST, false), 42, 7, 16, start);
        structure.setBlockState(world, Blocks.OAK_FENCE.getDefaultState().with(FourWayBlock.WATERLOGGED, false).with(FourWayBlock.NORTH, true).with(FourWayBlock.SOUTH, true).with(FourWayBlock.EAST, false).with(FourWayBlock.WEST, false), 42, 7, 19, start);
        structure.setBlockState(world, Blocks.OAK_LOG.getDefaultState(), 42, 7, 20, start);
        structure.setBlockState(world, Blocks.OAK_FENCE.getDefaultState().with(FourWayBlock.WATERLOGGED, false).with(FourWayBlock.NORTH, true).with(FourWayBlock.SOUTH, true).with(FourWayBlock.EAST, false).with(FourWayBlock.WEST, false), 42, 7, 21, start);
        structure.setBlockState(world, Blocks.OAK_FENCE.getDefaultState().with(FourWayBlock.WATERLOGGED, false).with(FourWayBlock.NORTH, true).with(FourWayBlock.SOUTH, true).with(FourWayBlock.EAST, false).with(FourWayBlock.WEST, false), 42, 7, 23, start);
        structure.setBlockState(world, Blocks.OAK_LOG.getDefaultState(), 42, 7, 24, start);
        structure.setBlockState(world, Blocks.OAK_FENCE.getDefaultState().with(FourWayBlock.WATERLOGGED, false).with(FourWayBlock.NORTH, true).with(FourWayBlock.SOUTH, true).with(FourWayBlock.EAST, false).with(FourWayBlock.WEST, false), 42, 7, 25, start);
        structure.setBlockState(world, Blocks.OAK_FENCE.getDefaultState().with(FourWayBlock.WATERLOGGED, false).with(FourWayBlock.NORTH, true).with(FourWayBlock.SOUTH, true).with(FourWayBlock.EAST, false).with(FourWayBlock.WEST, false), 42, 7, 28, start);
        structure.setBlockState(world, Blocks.OAK_LOG.getDefaultState(), 42, 7, 29, start);
        structure.setBlockState(world, Blocks.OAK_FENCE.getDefaultState().with(FourWayBlock.WATERLOGGED, false).with(FourWayBlock.NORTH, true).with(FourWayBlock.SOUTH, true).with(FourWayBlock.EAST, false).with(FourWayBlock.WEST, false), 42, 7, 30, start);
        structure.setBlockState(world, Blocks.OAK_FENCE.getDefaultState().with(FourWayBlock.WATERLOGGED, false).with(FourWayBlock.NORTH, true).with(FourWayBlock.SOUTH, true).with(FourWayBlock.EAST, false).with(FourWayBlock.WEST, false), 42, 7, 32, start);
        structure.setBlockState(world, Blocks.OAK_LOG.getDefaultState(), 42, 7, 33, start);
        structure.setBlockState(world, Blocks.OAK_FENCE.getDefaultState().with(FourWayBlock.WATERLOGGED, false).with(FourWayBlock.NORTH, true).with(FourWayBlock.SOUTH, true).with(FourWayBlock.EAST, false).with(FourWayBlock.WEST, false), 42, 7, 34, start);
        structure.setBlockState(world, Blocks.OAK_FENCE.getDefaultState().with(FourWayBlock.WATERLOGGED, false).with(FourWayBlock.NORTH, true).with(FourWayBlock.SOUTH, true).with(FourWayBlock.EAST, false).with(FourWayBlock.WEST, false), 42, 7, 37, start);
        structure.setBlockState(world, Blocks.OAK_LOG.getDefaultState(), 42, 7, 38, start);
        structure.setBlockState(world, Blocks.OAK_FENCE.getDefaultState().with(FourWayBlock.WATERLOGGED, false).with(FourWayBlock.NORTH, true).with(FourWayBlock.SOUTH, true).with(FourWayBlock.EAST, false).with(FourWayBlock.WEST, false), 42, 7, 39, start);
        structure.setBlockState(world, Blocks.OAK_FENCE.getDefaultState().with(FourWayBlock.WATERLOGGED, false).with(FourWayBlock.NORTH, true).with(FourWayBlock.SOUTH, true).with(FourWayBlock.EAST, false).with(FourWayBlock.WEST, false), 42, 7, 41, start);
        structure.setBlockState(world, Blocks.OAK_LOG.getDefaultState(), 42, 7, 42, start);
        structure.setBlockState(world, Blocks.OAK_FENCE.getDefaultState().with(FourWayBlock.WATERLOGGED, false).with(FourWayBlock.NORTH, true).with(FourWayBlock.SOUTH, true).with(FourWayBlock.EAST, false).with(FourWayBlock.WEST, false), 42, 7, 43, start);
        structure.setBlockState(world, Blocks.OAK_FENCE.getDefaultState().with(FourWayBlock.WATERLOGGED, false).with(FourWayBlock.NORTH, true).with(FourWayBlock.SOUTH, true).with(FourWayBlock.EAST, false).with(FourWayBlock.WEST, false), 42, 7, 46, start);
        structure.setBlockState(world, Blocks.OAK_LOG.getDefaultState(), 42, 7, 47, start);
        structure.setBlockState(world, Blocks.OAK_FENCE.getDefaultState().with(FourWayBlock.WATERLOGGED, false).with(FourWayBlock.NORTH, true).with(FourWayBlock.SOUTH, true).with(FourWayBlock.EAST, false).with(FourWayBlock.WEST, false), 42, 7, 48, start);
        structure.setBlockState(world, Blocks.OAK_FENCE.getDefaultState().with(FourWayBlock.WATERLOGGED, false).with(FourWayBlock.NORTH, true).with(FourWayBlock.SOUTH, true).with(FourWayBlock.EAST, false).with(FourWayBlock.WEST, false), 42, 7, 50, start);
        structure.setBlockState(world, Blocks.OAK_LOG.getDefaultState(), 42, 7, 51, start);
        structure.setBlockState(world, Blocks.OAK_FENCE.getDefaultState().with(FourWayBlock.WATERLOGGED, false).with(FourWayBlock.NORTH, true).with(FourWayBlock.SOUTH, true).with(FourWayBlock.EAST, false).with(FourWayBlock.WEST, false), 42, 7, 52, start);
        structure.setBlockState(world, Blocks.OAK_FENCE.getDefaultState().with(FourWayBlock.WATERLOGGED, false).with(FourWayBlock.NORTH, true).with(FourWayBlock.SOUTH, true).with(FourWayBlock.EAST, false).with(FourWayBlock.WEST, false), 42, 7, 54, start);
        structure.setBlockState(world, Blocks.OAK_FENCE.getDefaultState().with(FourWayBlock.WATERLOGGED, false).with(FourWayBlock.NORTH, true).with(FourWayBlock.SOUTH, true).with(FourWayBlock.EAST, false).with(FourWayBlock.WEST, false), 42, 7, 57, start);
        structure.setBlockState(world, Blocks.STONE.getDefaultState(), 44, -9, 86, start);
        structure.setBlockState(world, Blocks.GRASS_BLOCK.getDefaultState().with(SnowyDirtBlock.SNOWY, false), 44, -4, 86, start);
        structure.setBlockState(world, Blocks.DIRT.getDefaultState(), 44, -2, 59, start);
        structure.setBlockState(world, Blocks.GRASS_BLOCK.getDefaultState().with(SnowyDirtBlock.SNOWY, false), 44, -2, 62, start);
        structure.setBlockState(world, Blocks.GRASS_BLOCK.getDefaultState().with(SnowyDirtBlock.SNOWY, false), 44, -1, 59, start);
        structure.setBlockState(world, Blocks.DIRT.getDefaultState(), 45, -4, 64, start);
        structure.setBlockState(world, Blocks.GRASS_BLOCK.getDefaultState().with(SnowyDirtBlock.SNOWY, false), 45, -3, -9, start);
        structure.setBlockState(world, Blocks.STONE.getDefaultState(), 46, -9, 85, start);
        structure.setBlockState(world, Blocks.GRASS_BLOCK.getDefaultState().with(SnowyDirtBlock.SNOWY, false), 46, -8, 93, start);
        structure.setBlockState(world, Blocks.DIRT.getDefaultState(), 46, -5, 85, start);
        structure.setBlockState(world, Blocks.GRASS_BLOCK.getDefaultState().with(SnowyDirtBlock.SNOWY, false), 46, -4, 85, start);
        structure.setBlockState(world, Blocks.DIRT.getDefaultState(), 46, -3, 42, start);
        structure.setBlockState(world, Blocks.DIRT.getDefaultState(), 46, -3, 58, start);
        structure.setBlockState(world, Blocks.DIRT.getDefaultState(), 46, -3, 60, start);
        structure.setBlockState(world, Blocks.GRASS_BLOCK.getDefaultState().with(SnowyDirtBlock.SNOWY, false), 46, -2, 42, start);
        structure.setBlockState(world, Blocks.GRASS_BLOCK.getDefaultState().with(SnowyDirtBlock.SNOWY, false), 46, -2, 58, start);
        structure.setBlockState(world, Blocks.GRASS_BLOCK.getDefaultState().with(SnowyDirtBlock.SNOWY, false), 46, -2, 60, start);
        structure.setBlockState(world, Blocks.STONE.getDefaultState(), 47, -10, 90, start);
        structure.setBlockState(world, Blocks.DIRT.getDefaultState(), 47, -10, 94, start);
        structure.setBlockState(world, Blocks.GRASS_BLOCK.getDefaultState().with(SnowyDirtBlock.SNOWY, false), 47, -10, 95, start);
        structure.setBlockState(world, Blocks.GRASS_BLOCK.getDefaultState().with(SnowyDirtBlock.SNOWY, false), 47, -3, 27, start);
        structure.setBlockState(world, Blocks.CAVE_AIR.getDefaultState(), 47, -2, 82, start);
        structure.setBlockState(world, Blocks.STONE.getDefaultState(), 48, -10, 87, start);
        structure.setBlockState(world, Blocks.DIRT.getDefaultState(), 48, -8, 91, start);
        structure.setBlockState(world, Blocks.GRASS_BLOCK.getDefaultState().with(SnowyDirtBlock.SNOWY, false), 48, -4, 83, start);
        structure.setBlockState(world, Blocks.DIRT.getDefaultState(), 49, -7, 88, start);
        structure.setBlockState(world, Blocks.CAVE_AIR.getDefaultState(), 49, -3, -38, start);
        structure.setBlockState(world, Blocks.STONE.getDefaultState(), 50, -10, 85, start);
        structure.setBlockState(world, Blocks.GRASS_BLOCK.getDefaultState().with(SnowyDirtBlock.SNOWY, false), 50, -9, 92, start);
        structure.setBlockState(world, Blocks.DIRT.getDefaultState(), 50, -8, 89, start);
        structure.setBlockState(world, Blocks.CAVE_AIR.getDefaultState(), 50, -3, -27, start);
        structure.setBlockState(world, Blocks.CAVE_AIR.getDefaultState(), 50, -1, 81, start);
        structure.setBlockState(world, Blocks.DIRT.getDefaultState(), 51, -10, 91, start);
        structure.setBlockState(world, Blocks.GRASS_BLOCK.getDefaultState().with(SnowyDirtBlock.SNOWY, false), 51, -9, 91, start);
        structure.setBlockState(world, Blocks.CAVE_AIR.getDefaultState(), 51, -3, -40, start);
        structure.setBlockState(world, Blocks.CAVE_AIR.getDefaultState(), 51, -2, -41, start);
        structure.setBlockState(world, Blocks.DIRT.getDefaultState(), 52, -11, 92, start);
        structure.setBlockState(world, Blocks.GRASS_BLOCK.getDefaultState().with(SnowyDirtBlock.SNOWY, false), 52, -9, 90, start);
        structure.setBlockState(world, Blocks.DIRT.getDefaultState(), 52, -8, 87, start);
        structure.setBlockState(world, Blocks.CAVE_AIR.getDefaultState(), 52, 1, 78, start);
        structure.setBlockState(world, Blocks.DIRT.getDefaultState(), 53, -9, 88, start);
        structure.setBlockState(world, Blocks.GRASS_BLOCK.getDefaultState().with(SnowyDirtBlock.SNOWY, false), 53, -9, 89, start);
        structure.setBlockState(world, Blocks.CAVE_AIR.getDefaultState(), 53, -4, -22, start);
        structure.setBlockState(world, Blocks.CAVE_AIR.getDefaultState(), 53, -1, 77, start);
        structure.setBlockState(world, Blocks.CAVE_AIR.getDefaultState(), 53, 0, -29, start);
        structure.setBlockState(world, Blocks.CAVE_AIR.getDefaultState(), 54, -11, 97, start);
        structure.setBlockState(world, Blocks.GRASS_BLOCK.getDefaultState().with(SnowyDirtBlock.SNOWY, false), 54, -9, 88, start);
        structure.setBlockState(world, Blocks.GRASS_BLOCK.getDefaultState().with(SnowyDirtBlock.SNOWY, false), 54, -6, 83, start);
        structure.setBlockState(world, Blocks.CAVE_AIR.getDefaultState(), 54, -3, -22, start);
        structure.setBlockState(world, Blocks.DIRT.getDefaultState(), 55, -10, 87, start);
        structure.setBlockState(world, Blocks.GRASS_BLOCK.getDefaultState().with(SnowyDirtBlock.SNOWY, false), 55, -9, 87, start);
        structure.setBlockState(world, Blocks.CAVE_AIR.getDefaultState(), 55, -4, -48, start);
        structure.setBlockState(world, Blocks.CAVE_AIR.getDefaultState(), 55, -4, -42, start);
        structure.setBlockState(world, Blocks.DIRT.getDefaultState(), 56, -9, 84, start);
        structure.setBlockState(world, Blocks.GRASS_BLOCK.getDefaultState().with(SnowyDirtBlock.SNOWY, false), 57, -10, 86, start);
        structure.setBlockState(world, Blocks.CAVE_AIR.getDefaultState(), 57, -10, 91, start);
        structure.setBlockState(world, Blocks.CAVE_AIR.getDefaultState(), 57, -8, 95, start);
        structure.setBlockState(world, Blocks.DIRT.getDefaultState(), 58, -10, 33, start);
        structure.setBlockState(world, Blocks.GRASS_BLOCK.getDefaultState().with(SnowyDirtBlock.SNOWY, false), 58, -9, 33, start);
        structure.setBlockState(world, Blocks.CAVE_AIR.getDefaultState(), 59, -11, 92, start);
        structure.setBlockState(world, Blocks.CAVE_AIR.getDefaultState(), 63, -11, 98, start);
        structure.fillWithBlocks(world, start, -113, -11, -23, -113, -11, -23, Blocks.CAVE_AIR.getDefaultState());
        structure.fillWithBlocks(world, start, -113, -11, 35, -113, -10, 35, Blocks.CAVE_AIR.getDefaultState());
        structure.fillWithBlocks(world, start, -113, -10, -22, -113, -10, -18, Blocks.CAVE_AIR.getDefaultState());
        structure.fillWithBlocks(world, start, -113, -10, -15, -113, -10, -14, Blocks.CAVE_AIR.getDefaultState());
        structure.fillWithBlocks(world, start, -113, -10, -1, -112, -10, 6, Blocks.CAVE_AIR.getDefaultState());
        structure.fillWithBlocks(world, start, -113, -10, 9, -112, -10, 10, Blocks.CAVE_AIR.getDefaultState());
        structure.fillWithBlocks(world, start, -113, -10, 15, -112, -10, 16, Blocks.CAVE_AIR.getDefaultState());
        structure.fillWithBlocks(world, start, -113, -10, 17, -113, -9, 20, Blocks.CAVE_AIR.getDefaultState());
        structure.fillWithBlocks(world, start, -113, -10, 21, -113, -10, 24, Blocks.CAVE_AIR.getDefaultState());
        structure.fillWithBlocks(world, start, -113, -10, 36, -112, -10, 37, Blocks.CAVE_AIR.getDefaultState());
        structure.fillWithBlocks(world, start, -113, -10, 62, -111, -10, 64, Blocks.CAVE_AIR.getDefaultState());
        structure.fillWithBlocks(world, start, -113, -10, 67, -112, -10, 68, Blocks.CAVE_AIR.getDefaultState());
        structure.fillWithBlocks(world, start, -113, -9, -22, -113, -9, -18, Blocks.CAVE_AIR.getDefaultState());
        structure.fillWithBlocks(world, start, -113, -9, 2, -113, -9, 2, Blocks.CAVE_AIR.getDefaultState());
        structure.fillWithBlocks(world, start, -113, -9, 5, -110, -9, 8, Blocks.CAVE_AIR.getDefaultState());
        structure.fillWithBlocks(world, start, -113, -9, 9, -112, -9, 10, Blocks.CAVE_AIR.getDefaultState());
        structure.fillWithBlocks(world, start, -113, -9, 15, -112, -9, 20, Blocks.CAVE_AIR.getDefaultState());
        structure.fillWithBlocks(world, start, -113, -9, 22, -111, -9, 24, Blocks.CAVE_AIR.getDefaultState());
        structure.fillWithBlocks(world, start, -113, -9, 36, -112, -9, 37, Blocks.CAVE_AIR.getDefaultState());
        structure.fillWithBlocks(world, start, -113, -9, 62, -112, -9, 68, Blocks.CAVE_AIR.getDefaultState());
        structure.fillWithBlocks(world, start, -113, -8, -21, -113, -8, -20, Blocks.CAVE_AIR.getDefaultState());
        structure.fillWithBlocks(world, start, -113, -8, 7, -112, -8, 8, Blocks.CAVE_AIR.getDefaultState());
        structure.fillWithBlocks(world, start, -113, -8, 22, -111, -8, 24, Blocks.CAVE_AIR.getDefaultState());
        structure.fillWithBlocks(world, start, -113, -8, 64, -110, -8, 67, Blocks.CAVE_AIR.getDefaultState());
        structure.fillWithBlocks(world, start, -113, -7, 7, -112, -7, 7, Blocks.CAVE_AIR.getDefaultState());
        structure.fillWithBlocks(world, start, -113, -7, 65, -112, -7, 66, Blocks.CAVE_AIR.getDefaultState());
        structure.fillWithBlocks(world, start, -112, -11, -55, -111, -11, -52, Blocks.GRASS_BLOCK.getDefaultState().with(SnowyDirtBlock.SNOWY, false));
        structure.fillWithBlocks(world, start, -112, -10, -21, -112, -9, -19, Blocks.CAVE_AIR.getDefaultState());
        structure.fillWithBlocks(world, start, -112, -10, 22, -112, -8, 22, Blocks.CAVE_AIR.getDefaultState());
        structure.fillWithBlocks(world, start, -112, -10, 24, -112, -10, 24, Blocks.CAVE_AIR.getDefaultState());
        structure.fillWithBlocks(world, start, -112, -10, 28, -112, -9, 31, Blocks.CAVE_AIR.getDefaultState());
        structure.fillWithBlocks(world, start, -112, -10, 35, -112, -9, 37, Blocks.CAVE_AIR.getDefaultState());
        structure.fillWithBlocks(world, start, -112, -9, 1, -108, -9, 6, Blocks.CAVE_AIR.getDefaultState());
        structure.fillWithBlocks(world, start, -112, -9, 21, -110, -9, 23, Blocks.CAVE_AIR.getDefaultState());
        structure.fillWithBlocks(world, start, -112, -8, 3, -112, -8, 3, Blocks.CAVE_AIR.getDefaultState());
        structure.fillWithBlocks(world, start, -112, -8, 17, -109, -8, 22, Blocks.CAVE_AIR.getDefaultState());
        structure.fillWithBlocks(world, start, -111, -11, -61, -111, -11, -46, Blocks.GRASS_BLOCK.getDefaultState().with(SnowyDirtBlock.SNOWY, false));
        structure.fillWithBlocks(world, start, -111, -11, 10, -111, -11, 11, Blocks.CAVE_AIR.getDefaultState());
        structure.fillWithBlocks(world, start, -111, -11, 25, -111, -11, 26, Blocks.CAVE_AIR.getDefaultState());
        structure.fillWithBlocks(world, start, -111, -11, 29, -111, -11, 38, Blocks.GRASS_BLOCK.getDefaultState().with(SnowyDirtBlock.SNOWY, false));
        structure.fillWithBlocks(world, start, -111, -11, 39, -111, -11, 39, Blocks.DIRT.getDefaultState());
        structure.fillWithBlocks(world, start, -111, -11, 40, -111, -11, 47, Blocks.GRASS_BLOCK.getDefaultState().with(SnowyDirtBlock.SNOWY, false));
        structure.fillWithBlocks(world, start, -111, -11, 67, -111, -11, 75, Blocks.GRASS_BLOCK.getDefaultState().with(SnowyDirtBlock.SNOWY, false));
        structure.fillWithBlocks(world, start, -111, -10, 0, -111, -9, 1, Blocks.CAVE_AIR.getDefaultState());
        structure.fillWithBlocks(world, start, -111, -10, 5, -111, -10, 9, Blocks.CAVE_AIR.getDefaultState());
        structure.fillWithBlocks(world, start, -111, -10, 12, -111, -10, 12, Blocks.CAVE_AIR.getDefaultState());
        structure.fillWithBlocks(world, start, -111, -10, 15, -110, -10, 16, Blocks.CAVE_AIR.getDefaultState());
        structure.fillWithBlocks(world, start, -111, -10, 23, -110, -10, 24, Blocks.CAVE_AIR.getDefaultState());
        structure.fillWithBlocks(world, start, -111, -10, 27, -111, -9, 28, Blocks.CAVE_AIR.getDefaultState());
        structure.fillWithBlocks(world, start, -111, -10, 65, -111, -9, 66, Blocks.CAVE_AIR.getDefaultState());
        structure.fillWithBlocks(world, start, -111, -10, 68, -111, -9, 68, Blocks.CAVE_AIR.getDefaultState());
        structure.fillWithBlocks(world, start, -111, -9, 12, -111, -9, 12, Blocks.CAVE_AIR.getDefaultState());
        structure.fillWithBlocks(world, start, -111, -9, 16, -110, -9, 23, Blocks.CAVE_AIR.getDefaultState());
        structure.fillWithBlocks(world, start, -111, -9, 29, -111, -8, 32, Blocks.CAVE_AIR.getDefaultState());
        structure.fillWithBlocks(world, start, -111, -9, 35, -111, -8, 37, Blocks.CAVE_AIR.getDefaultState());
        structure.fillWithBlocks(world, start, -111, -9, 40, -111, -8, 41, Blocks.CAVE_AIR.getDefaultState());
        structure.fillWithBlocks(world, start, -111, -9, 63, -110, -9, 68, Blocks.CAVE_AIR.getDefaultState());
        structure.fillWithBlocks(world, start, -111, -8, 1, -108, -8, 4, Blocks.CAVE_AIR.getDefaultState());
        structure.fillWithBlocks(world, start, -111, -7, 2, -109, -7, 4, Blocks.CAVE_AIR.getDefaultState());
        structure.fillWithBlocks(world, start, -110, -11, -64, -110, -11, -61, Blocks.GRASS_BLOCK.getDefaultState().with(SnowyDirtBlock.SNOWY, false));
        structure.fillWithBlocks(world, start, -110, -11, -60, -105, -11, -52, Blocks.DIRT.getDefaultState());
        structure.fillWithBlocks(world, start, -110, -11, -51, -106, -11, -47, Blocks.DIRT.getDefaultState());
        structure.fillWithBlocks(world, start, -110, -11, -46, -110, -11, -44, Blocks.GRASS_BLOCK.getDefaultState().with(SnowyDirtBlock.SNOWY, false));
        structure.fillWithBlocks(world, start, -110, -11, -20, -110, -11, -18, Blocks.GRASS_BLOCK.getDefaultState().with(SnowyDirtBlock.SNOWY, false));
        structure.fillWithBlocks(world, start, -110, -11, 9, -110, -10, 9, Blocks.CAVE_AIR.getDefaultState());
        structure.fillWithBlocks(world, start, -110, -11, 15, -110, -10, 15, Blocks.CAVE_AIR.getDefaultState());
        structure.fillWithBlocks(world, start, -110, -11, 24, -110, -10, 24, Blocks.CAVE_AIR.getDefaultState());
        structure.fillWithBlocks(world, start, -110, -11, 25, -110, -11, 28, Blocks.GRASS_BLOCK.getDefaultState().with(SnowyDirtBlock.SNOWY, false));
        structure.fillWithBlocks(world, start, -110, -11, 29, -107, -11, 32, Blocks.DIRT.getDefaultState());
        structure.fillWithBlocks(world, start, -110, -11, 33, -108, -11, 47, Blocks.DIRT.getDefaultState());
        structure.fillWithBlocks(world, start, -110, -11, 48, -110, -11, 51, Blocks.GRASS_BLOCK.getDefaultState().with(SnowyDirtBlock.SNOWY, false));
        structure.fillWithBlocks(world, start, -110, -11, 63, -110, -11, 66, Blocks.GRASS_BLOCK.getDefaultState().with(SnowyDirtBlock.SNOWY, false));
        structure.fillWithBlocks(world, start, -110, -11, 67, -104, -11, 75, Blocks.DIRT.getDefaultState());
        structure.fillWithBlocks(world, start, -110, -11, 76, -110, -11, 80, Blocks.GRASS_BLOCK.getDefaultState().with(SnowyDirtBlock.SNOWY, false));
        structure.fillWithBlocks(world, start, -110, -10, -60, -109, -10, -59, Blocks.GRASS_BLOCK.getDefaultState().with(SnowyDirtBlock.SNOWY, false));
        structure.fillWithBlocks(world, start, -110, -10, -58, -110, -10, -47, Blocks.GRASS_BLOCK.getDefaultState().with(SnowyDirtBlock.SNOWY, false));
        structure.fillWithBlocks(world, start, -110, -10, 0, -109, -9, 0, Blocks.CAVE_AIR.getDefaultState());
        structure.fillWithBlocks(world, start, -110, -10, 6, -109, -10, 9, Blocks.CAVE_AIR.getDefaultState());
        structure.fillWithBlocks(world, start, -110, -10, 11, -110, -9, 13, Blocks.CAVE_AIR.getDefaultState());
        structure.fillWithBlocks(world, start, -110, -10, 29, -110, -10, 34, Blocks.GRASS_BLOCK.getDefaultState().with(SnowyDirtBlock.SNOWY, false));
        structure.fillWithBlocks(world, start, -110, -10, 35, -106, -10, 42, Blocks.DIRT.getDefaultState());
        structure.fillWithBlocks(world, start, -110, -10, 43, -110, -10, 47, Blocks.GRASS_BLOCK.getDefaultState().with(SnowyDirtBlock.SNOWY, false));
        structure.fillWithBlocks(world, start, -110, -10, 67, -110, -10, 75, Blocks.GRASS_BLOCK.getDefaultState().with(SnowyDirtBlock.SNOWY, false));
        structure.fillWithBlocks(world, start, -110, -9, 27, -110, -8, 28, Blocks.CAVE_AIR.getDefaultState());
        structure.fillWithBlocks(world, start, -110, -9, 35, -110, -9, 42, Blocks.GRASS_BLOCK.getDefaultState().with(SnowyDirtBlock.SNOWY, false));
        structure.fillWithBlocks(world, start, -110, -8, 5, -108, -8, 5, Blocks.CAVE_AIR.getDefaultState());
        structure.fillWithBlocks(world, start, -110, -8, 29, -110, -7, 32, Blocks.CAVE_AIR.getDefaultState());
        structure.fillWithBlocks(world, start, -110, -7, 1, -109, -7, 4, Blocks.CAVE_AIR.getDefaultState());
        structure.fillWithBlocks(world, start, -110, -7, 19, -110, -7, 19, Blocks.CAVE_AIR.getDefaultState());
        structure.fillWithBlocks(world, start, -110, -7, 36, -110, -6, 36, Blocks.CAVE_AIR.getDefaultState());
        structure.fillWithBlocks(world, start, -110, -7, 39, -110, -6, 41, Blocks.CAVE_AIR.getDefaultState());
        structure.fillWithBlocks(world, start, -109, -11, -66, -109, -11, -64, Blocks.GRASS_BLOCK.getDefaultState().with(SnowyDirtBlock.SNOWY, false));
        structure.fillWithBlocks(world, start, -109, -11, -63, -104, -11, -55, Blocks.DIRT.getDefaultState());
        structure.fillWithBlocks(world, start, -109, -11, -46, -107, -11, -44, Blocks.DIRT.getDefaultState());
        structure.fillWithBlocks(world, start, -109, -11, -43, -109, -11, -41, Blocks.GRASS_BLOCK.getDefaultState().with(SnowyDirtBlock.SNOWY, false));
        structure.fillWithBlocks(world, start, -109, -11, -26, -109, -11, -22, Blocks.GRASS_BLOCK.getDefaultState().with(SnowyDirtBlock.SNOWY, false));
        structure.fillWithBlocks(world, start, -109, -11, -21, -105, -11, -17, Blocks.DIRT.getDefaultState());
        structure.fillWithBlocks(world, start, -109, -11, -16, -109, -11, -12, Blocks.GRASS_BLOCK.getDefaultState().with(SnowyDirtBlock.SNOWY, false));
        structure.fillWithBlocks(world, start, -109, -11, 7, -109, -10, 8, Blocks.CAVE_AIR.getDefaultState());
        structure.fillWithBlocks(world, start, -109, -11, 10, -109, -10, 10, Blocks.CAVE_AIR.getDefaultState());
        structure.fillWithBlocks(world, start, -109, -11, 13, -108, -11, 14, Blocks.GRASS_BLOCK.getDefaultState().with(SnowyDirtBlock.SNOWY, false));
        structure.fillWithBlocks(world, start, -109, -11, 15, -109, -11, 22, Blocks.GRASS_BLOCK.getDefaultState().with(SnowyDirtBlock.SNOWY, false));
        structure.fillWithBlocks(world, start, -109, -11, 23, -108, -11, 51, Blocks.DIRT.getDefaultState());
        structure.fillWithBlocks(world, start, -109, -11, 52, -109, -11, 55, Blocks.GRASS_BLOCK.getDefaultState().with(SnowyDirtBlock.SNOWY, false));
        structure.fillWithBlocks(world, start, -109, -11, 59, -109, -11, 61, Blocks.GRASS_BLOCK.getDefaultState().with(SnowyDirtBlock.SNOWY, false));
        structure.fillWithBlocks(world, start, -109, -11, 62, -106, -11, 79, Blocks.DIRT.getDefaultState());
        structure.fillWithBlocks(world, start, -109, -11, 80, -109, -11, 83, Blocks.GRASS_BLOCK.getDefaultState().with(SnowyDirtBlock.SNOWY, false));
        structure.fillWithBlocks(world, start, -109, -10, -63, -109, -10, -59, Blocks.GRASS_BLOCK.getDefaultState().with(SnowyDirtBlock.SNOWY, false));
        structure.fillWithBlocks(world, start, -109, -10, -58, -102, -10, -51, Blocks.DIRT.getDefaultState());
        structure.fillWithBlocks(world, start, -109, -10, -50, -106, -10, -47, Blocks.DIRT.getDefaultState());
        structure.fillWithBlocks(world, start, -109, -10, -46, -109, -10, -44, Blocks.GRASS_BLOCK.getDefaultState().with(SnowyDirtBlock.SNOWY, false));
        structure.fillWithBlocks(world, start, -109, -10, -21, -109, -10, -17, Blocks.GRASS_BLOCK.getDefaultState().with(SnowyDirtBlock.SNOWY, false));
        structure.fillWithBlocks(world, start, -109, -10, 5, -109, -9, 6, Blocks.CAVE_AIR.getDefaultState());
        structure.fillWithBlocks(world, start, -109, -10, 11, -109, -9, 11, Blocks.CAVE_AIR.getDefaultState());
        structure.fillWithBlocks(world, start, -109, -10, 23, -109, -10, 26, Blocks.GRASS_BLOCK.getDefaultState().with(SnowyDirtBlock.SNOWY, false));
        structure.fillWithBlocks(world, start, -109, -10, 27, -107, -10, 48, Blocks.DIRT.getDefaultState());
        structure.fillWithBlocks(world, start, -109, -10, 49, -109, -10, 51, Blocks.GRASS_BLOCK.getDefaultState().with(SnowyDirtBlock.SNOWY, false));
        structure.fillWithBlocks(world, start, -109, -10, 62, -109, -10, 67, Blocks.GRASS_BLOCK.getDefaultState().with(SnowyDirtBlock.SNOWY, false));
        structure.fillWithBlocks(world, start, -109, -10, 68, -104, -10, 73, Blocks.DIRT.getDefaultState());
        structure.fillWithBlocks(world, start, -109, -10, 74, -109, -10, 79, Blocks.GRASS_BLOCK.getDefaultState().with(SnowyDirtBlock.SNOWY, false));
        structure.fillWithBlocks(world, start, -109, -9, -58, -109, -9, -47, Blocks.GRASS_BLOCK.getDefaultState().with(SnowyDirtBlock.SNOWY, false));
        structure.fillWithBlocks(world, start, -109, -9, 12, -109, -9, 16, Blocks.CAVE_AIR.getDefaultState());
        structure.fillWithBlocks(world, start, -109, -9, 22, -109, -8, 22, Blocks.CAVE_AIR.getDefaultState());
        structure.fillWithBlocks(world, start, -109, -9, 27, -109, -9, 34, Blocks.GRASS_BLOCK.getDefaultState().with(SnowyDirtBlock.SNOWY, false));
        structure.fillWithBlocks(world, start, -109, -9, 35, -104, -9, 43, Blocks.DIRT.getDefaultState());
        structure.fillWithBlocks(world, start, -109, -9, 44, -109, -9, 48, Blocks.GRASS_BLOCK.getDefaultState().with(SnowyDirtBlock.SNOWY, false));
        structure.fillWithBlocks(world, start, -109, -9, 68, -108, -9, 73, Blocks.GRASS_BLOCK.getDefaultState().with(SnowyDirtBlock.SNOWY, false));
        structure.fillWithBlocks(world, start, -109, -8, 12, -108, -8, 15, Blocks.CAVE_AIR.getDefaultState());
        structure.fillWithBlocks(world, start, -109, -8, 16, -109, -8, 24, Blocks.CAVE_AIR.getDefaultState());
        structure.fillWithBlocks(world, start, -109, -8, 35, -109, -8, 43, Blocks.GRASS_BLOCK.getDefaultState().with(SnowyDirtBlock.SNOWY, false));
        structure.fillWithBlocks(world, start, -109, -7, 12, -107, -7, 12, Blocks.CAVE_AIR.getDefaultState());
        structure.fillWithBlocks(world, start, -109, -7, 17, -109, -7, 21, Blocks.CAVE_AIR.getDefaultState());
        structure.fillWithBlocks(world, start, -109, -7, 23, -108, -7, 24, Blocks.CAVE_AIR.getDefaultState());
        structure.fillWithBlocks(world, start, -109, -7, 28, -109, -6, 31, Blocks.CAVE_AIR.getDefaultState());
        structure.fillWithBlocks(world, start, -109, -7, 34, -109, -6, 34, Blocks.CAVE_AIR.getDefaultState());
        structure.fillWithBlocks(world, start, -109, -6, 35, -109, -5, 41, Blocks.CAVE_AIR.getDefaultState());
        structure.fillWithBlocks(world, start, -108, -11, -68, -108, -11, -66, Blocks.GRASS_BLOCK.getDefaultState().with(SnowyDirtBlock.SNOWY, false));
        structure.fillWithBlocks(world, start, -108, -11, -65, -103, -11, -59, Blocks.DIRT.getDefaultState());
        structure.fillWithBlocks(world, start, -108, -11, -43, -106, -11, -41, Blocks.DIRT.getDefaultState());
        structure.fillWithBlocks(world, start, -108, -11, -40, -108, -11, -39, Blocks.GRASS_BLOCK.getDefaultState().with(SnowyDirtBlock.SNOWY, false));
        structure.fillWithBlocks(world, start, -108, -11, -29, -108, -11, -27, Blocks.GRASS_BLOCK.getDefaultState().with(SnowyDirtBlock.SNOWY, false));
        structure.fillWithBlocks(world, start, -108, -11, -26, -105, -11, -17, Blocks.DIRT.getDefaultState());
        structure.fillWithBlocks(world, start, -108, -11, -16, -106, -11, -8, Blocks.DIRT.getDefaultState());
        structure.fillWithBlocks(world, start, -108, -11, -7, -108, -11, 14, Blocks.GRASS_BLOCK.getDefaultState().with(SnowyDirtBlock.SNOWY, false));
        structure.fillWithBlocks(world, start, -108, -11, 15, -106, -11, 21, Blocks.DIRT.getDefaultState());
        structure.fillWithBlocks(world, start, -108, -11, 22, -108, -10, 53, Blocks.DIRT.getDefaultState());
        structure.fillWithBlocks(world, start, -108, -11, 54, -107, -11, 81, Blocks.DIRT.getDefaultState());
        structure.fillWithBlocks(world, start, -108, -11, 82, -108, -11, 85, Blocks.GRASS_BLOCK.getDefaultState().with(SnowyDirtBlock.SNOWY, false));
        structure.fillWithBlocks(world, start, -108, -10, -65, -108, -10, -63, Blocks.GRASS_BLOCK.getDefaultState().with(SnowyDirtBlock.SNOWY, false));
        structure.fillWithBlocks(world, start, -108, -10, -62, -102, -10, -51, Blocks.DIRT.getDefaultState());
        structure.fillWithBlocks(world, start, -108, -10, -46, -106, -10, -44, Blocks.DIRT.getDefaultState());
        structure.fillWithBlocks(world, start, -108, -10, -43, -108, -10, -41, Blocks.GRASS_BLOCK.getDefaultState().with(SnowyDirtBlock.SNOWY, false));
        structure.fillWithBlocks(world, start, -108, -10, -26, -108, -10, -23, Blocks.GRASS_BLOCK.getDefaultState().with(SnowyDirtBlock.SNOWY, false));
        structure.fillWithBlocks(world, start, -108, -10, -22, -104, -10, -15, Blocks.DIRT.getDefaultState());
        structure.fillWithBlocks(world, start, -108, -10, -14, -108, -10, -8, Blocks.GRASS_BLOCK.getDefaultState().with(SnowyDirtBlock.SNOWY, false));
        structure.fillWithBlocks(world, start, -108, -10, 7, -108, -9, 7, Blocks.CAVE_AIR.getDefaultState());
        structure.fillWithBlocks(world, start, -108, -10, 15, -108, -10, 19, Blocks.GRASS_BLOCK.getDefaultState().with(SnowyDirtBlock.SNOWY, false));
        structure.fillWithBlocks(world, start, -108, -10, 20, -106, -10, 22, Blocks.DIRT.getDefaultState());
        structure.fillWithBlocks(world, start, -108, -10, 54, -108, -10, 61, Blocks.GRASS_BLOCK.getDefaultState().with(SnowyDirtBlock.SNOWY, false));
        structure.fillWithBlocks(world, start, -108, -10, 62, -105, -10, 79, Blocks.DIRT.getDefaultState());
        structure.fillWithBlocks(world, start, -108, -10, 80, -108, -10, 81, Blocks.GRASS_BLOCK.getDefaultState().with(SnowyDirtBlock.SNOWY, false));
        structure.fillWithBlocks(world, start, -108, -9, -62, -108, -9, -59, Blocks.GRASS_BLOCK.getDefaultState().with(SnowyDirtBlock.SNOWY, false));
        structure.fillWithBlocks(world, start, -108, -9, -58, -99, -9, -48, Blocks.DIRT.getDefaultState());
        structure.fillWithBlocks(world, start, -108, -9, -47, -108, -9, -44, Blocks.GRASS_BLOCK.getDefaultState().with(SnowyDirtBlock.SNOWY, false));
        structure.fillWithBlocks(world, start, -108, -9, -22, -108, -9, -15, Blocks.GRASS_BLOCK.getDefaultState().with(SnowyDirtBlock.SNOWY, false));
        structure.fillWithBlocks(world, start, -108, -9, 8, -108, -8, 11, Blocks.CAVE_AIR.getDefaultState());
        structure.fillWithBlocks(world, start, -108, -9, 13, -108, -8, 14, Blocks.CAVE_AIR.getDefaultState());
        structure.fillWithBlocks(world, start, -108, -9, 20, -108, -9, 24, Blocks.GRASS_BLOCK.getDefaultState().with(SnowyDirtBlock.SNOWY, false));
        structure.fillWithBlocks(world, start, -108, -9, 25, -106, -9, 49, Blocks.DIRT.getDefaultState());
        structure.fillWithBlocks(world, start, -108, -9, 50, -108, -9, 53, Blocks.GRASS_BLOCK.getDefaultState().with(SnowyDirtBlock.SNOWY, false));
        structure.fillWithBlocks(world, start, -108, -9, 62, -108, -9, 79, Blocks.GRASS_BLOCK.getDefaultState().with(SnowyDirtBlock.SNOWY, false));
        structure.fillWithBlocks(world, start, -108, -8, -58, -107, -8, -57, Blocks.GRASS_BLOCK.getDefaultState().with(SnowyDirtBlock.SNOWY, false));
        structure.fillWithBlocks(world, start, -108, -8, -56, -108, -8, -48, Blocks.GRASS_BLOCK.getDefaultState().with(SnowyDirtBlock.SNOWY, false));
        structure.fillWithBlocks(world, start, -108, -8, 6, -108, -8, 6, Blocks.CAVE_AIR.getDefaultState());
        structure.fillWithBlocks(world, start, -108, -8, 17, -108, -8, 18, Blocks.CAVE_AIR.getDefaultState());
        structure.fillWithBlocks(world, start, -108, -8, 25, -108, -8, 32, Blocks.GRASS_BLOCK.getDefaultState().with(SnowyDirtBlock.SNOWY, false));
        structure.fillWithBlocks(world, start, -108, -8, 33, -98, -8, 44, Blocks.DIRT.getDefaultState());
        structure.fillWithBlocks(world, start, -108, -8, 45, -108, -8, 49, Blocks.GRASS_BLOCK.getDefaultState().with(SnowyDirtBlock.SNOWY, false));
        structure.fillWithBlocks(world, start, -108, -7, 2, -108, -7, 4, Blocks.CAVE_AIR.getDefaultState());
        structure.fillWithBlocks(world, start, -108, -7, 15, -107, -7, 15, Blocks.CAVE_AIR.getDefaultState());
        structure.fillWithBlocks(world, start, -108, -7, 18, -108, -7, 19, Blocks.CAVE_AIR.getDefaultState());
        structure.fillWithBlocks(world, start, -108, -7, 21, -108, -6, 25, Blocks.CAVE_AIR.getDefaultState());
        structure.fillWithBlocks(world, start, -108, -7, 33, -108, -7, 44, Blocks.GRASS_BLOCK.getDefaultState().with(SnowyDirtBlock.SNOWY, false));
        structure.fillWithBlocks(world, start, -108, -6, 12, -106, -6, 12, Blocks.CAVE_AIR.getDefaultState());
        structure.fillWithBlocks(world, start, -108, -6, 19, -107, -6, 22, Blocks.CAVE_AIR.getDefaultState());
        structure.fillWithBlocks(world, start, -108, -5, 20, -108, -5, 20, Blocks.CAVE_AIR.getDefaultState());
        structure.fillWithBlocks(world, start, -108, -5, 22, -107, -5, 23, Blocks.CAVE_AIR.getDefaultState());
        structure.fillWithBlocks(world, start, -108, -5, 33, -108, -4, 35, Blocks.CAVE_AIR.getDefaultState());
        structure.fillWithBlocks(world, start, -108, -5, 37, -108, -4, 39, Blocks.CAVE_AIR.getDefaultState());
        structure.fillWithBlocks(world, start, -108, -5, 41, -108, -4, 41, Blocks.CAVE_AIR.getDefaultState());
        structure.fillWithBlocks(world, start, -108, -4, 36, -107, -4, 41, Blocks.CAVE_AIR.getDefaultState());
        structure.fillWithBlocks(world, start, -108, -3, 36, -108, -3, 36, Blocks.CAVE_AIR.getDefaultState());
        structure.fillWithBlocks(world, start, -108, -3, 40, -108, -3, 40, Blocks.CAVE_AIR.getDefaultState());
        structure.fillWithBlocks(world, start, -107, -11, -69, -107, -11, -68, Blocks.GRASS_BLOCK.getDefaultState().with(SnowyDirtBlock.SNOWY, false));
        structure.fillWithBlocks(world, start, -107, -11, -67, -103, -11, -59, Blocks.DIRT.getDefaultState());
        structure.fillWithBlocks(world, start, -107, -11, -40, -107, -11, -40, Blocks.DIRT.getDefaultState());
        structure.fillWithBlocks(world, start, -107, -11, -39, -107, -11, -38, Blocks.GRASS_BLOCK.getDefaultState().with(SnowyDirtBlock.SNOWY, false));
        structure.fillWithBlocks(world, start, -107, -11, -32, -107, -11, -30, Blocks.GRASS_BLOCK.getDefaultState().with(SnowyDirtBlock.SNOWY, false));
        structure.fillWithBlocks(world, start, -107, -11, -29, -105, -11, -17, Blocks.DIRT.getDefaultState());
        structure.fillWithBlocks(world, start, -107, -11, -7, -106, -11, 21, Blocks.DIRT.getDefaultState());
        structure.fillWithBlocks(world, start, -107, -11, 22, -107, -9, 22, Blocks.DIRT.getDefaultState());
        structure.fillWithBlocks(world, start, -107, -11, 23, -105, -11, 25, Blocks.STONE.getDefaultState());
        structure.fillWithBlocks(world, start, -107, -11, 26, -107, -8, 32, Blocks.DIRT.getDefaultState());
        structure.fillWithBlocks(world, start, -107, -11, 33, -106, -11, 34, Blocks.STONE.getDefaultState());
        structure.fillWithBlocks(world, start, -107, -11, 35, -107, -11, 84, Blocks.DIRT.getDefaultState());
        structure.fillWithBlocks(world, start, -107, -11, 85, -107, -11, 87, Blocks.GRASS_BLOCK.getDefaultState().with(SnowyDirtBlock.SNOWY, false));
        structure.fillWithBlocks(world, start, -107, -10, -67, -107, -10, -65, Blocks.GRASS_BLOCK.getDefaultState().with(SnowyDirtBlock.SNOWY, false));
        structure.fillWithBlocks(world, start, -107, -10, -64, -101, -10, -57, Blocks.DIRT.getDefaultState());
        structure.fillWithBlocks(world, start, -107, -10, -43, -106, -10, -42, Blocks.DIRT.getDefaultState());
        structure.fillWithBlocks(world, start, -107, -10, -41, -107, -10, -40, Blocks.GRASS_BLOCK.getDefaultState().with(SnowyDirtBlock.SNOWY, false));
        structure.fillWithBlocks(world, start, -107, -10, -29, -107, -10, -27, Blocks.GRASS_BLOCK.getDefaultState().with(SnowyDirtBlock.SNOWY, false));
        structure.fillWithBlocks(world, start, -107, -10, -26, -104, -10, -15, Blocks.DIRT.getDefaultState());
        structure.fillWithBlocks(world, start, -107, -10, -14, -105, -10, -5, Blocks.DIRT.getDefaultState());
        structure.fillWithBlocks(world, start, -107, -10, -4, -107, -10, 13, Blocks.GRASS_BLOCK.getDefaultState().with(SnowyDirtBlock.SNOWY, false));
        structure.fillWithBlocks(world, start, -107, -10, 14, -104, -10, 19, Blocks.DIRT.getDefaultState());
        structure.fillWithBlocks(world, start, -107, -10, 23, -107, -8, 50, Blocks.DIRT.getDefaultState());
        structure.fillWithBlocks(world, start, -107, -10, 51, -106, -10, 81, Blocks.DIRT.getDefaultState());
        structure.fillWithBlocks(world, start, -107, -10, 82, -107, -10, 84, Blocks.GRASS_BLOCK.getDefaultState().with(SnowyDirtBlock.SNOWY, false));
        structure.fillWithBlocks(world, start, -107, -9, -64, -107, -9, -62, Blocks.GRASS_BLOCK.getDefaultState().with(SnowyDirtBlock.SNOWY, false));
        structure.fillWithBlocks(world, start, -107, -9, -61, -99, -9, -44, Blocks.DIRT.getDefaultState());
        structure.fillWithBlocks(world, start, -107, -9, -43, -107, -9, -42, Blocks.GRASS_BLOCK.getDefaultState().with(SnowyDirtBlock.SNOWY, false));
        structure.fillWithBlocks(world, start, -107, -9, -26, -107, -9, -22, Blocks.GRASS_BLOCK.getDefaultState().with(SnowyDirtBlock.SNOWY, false));
        structure.fillWithBlocks(world, start, -107, -9, -21, -102, -9, -10, Blocks.DIRT.getDefaultState());
        structure.fillWithBlocks(world, start, -107, -9, -9, -107, -9, -5, Blocks.GRASS_BLOCK.getDefaultState().with(SnowyDirtBlock.SNOWY, false));
        structure.fillWithBlocks(world, start, -107, -9, 4, -107, -9, 7, Blocks.CAVE_AIR.getDefaultState());
        structure.fillWithBlocks(world, start, -107, -9, 14, -107, -9, 17, Blocks.GRASS_BLOCK.getDefaultState().with(SnowyDirtBlock.SNOWY, false));
        structure.fillWithBlocks(world, start, -107, -9, 18, -105, -9, 25, Blocks.DIRT.getDefaultState());
        structure.fillWithBlocks(world, start, -107, -9, 51, -105, -9, 78, Blocks.DIRT.getDefaultState());
        structure.fillWithBlocks(world, start, -107, -9, 79, -107, -9, 81, Blocks.GRASS_BLOCK.getDefaultState().with(SnowyDirtBlock.SNOWY, false));
        structure.fillWithBlocks(world, start, -107, -8, -61, -107, -8, -57, Blocks.GRASS_BLOCK.getDefaultState().with(SnowyDirtBlock.SNOWY, false));
        structure.fillWithBlocks(world, start, -107, -8, -56, -100, -8, -49, Blocks.DIRT.getDefaultState());
        structure.fillWithBlocks(world, start, -107, -8, -48, -107, -8, -44, Blocks.GRASS_BLOCK.getDefaultState().with(SnowyDirtBlock.SNOWY, false));
        structure.fillWithBlocks(world, start, -107, -8, -21, -107, -8, -10, Blocks.GRASS_BLOCK.getDefaultState().with(SnowyDirtBlock.SNOWY, false));
        structure.fillWithBlocks(world, start, -107, -8, 6, -107, -8, 11, Blocks.CAVE_AIR.getDefaultState());
        structure.fillWithBlocks(world, start, -107, -8, 13, -107, -7, 13, Blocks.CAVE_AIR.getDefaultState());
        structure.fillWithBlocks(world, start, -107, -8, 18, -107, -8, 22, Blocks.GRASS_BLOCK.getDefaultState().with(SnowyDirtBlock.SNOWY, false));
        structure.fillWithBlocks(world, start, -107, -8, 51, -107, -8, 78, Blocks.GRASS_BLOCK.getDefaultState().with(SnowyDirtBlock.SNOWY, false));
        structure.fillWithBlocks(world, start, -107, -7, -56, -106, -7, -49, Blocks.GRASS_BLOCK.getDefaultState().with(SnowyDirtBlock.SNOWY, false));
        structure.fillWithBlocks(world, start, -107, -7, 8, -107, -7, 15, Blocks.CAVE_AIR.getDefaultState());
        structure.fillWithBlocks(world, start, -107, -7, 23, -107, -7, 32, Blocks.GRASS_BLOCK.getDefaultState().with(SnowyDirtBlock.SNOWY, false));
        structure.fillWithBlocks(world, start, -107, -7, 33, -97, -7, 43, Blocks.DIRT.getDefaultState());
        structure.fillWithBlocks(world, start, -107, -7, 44, -107, -7, 50, Blocks.GRASS_BLOCK.getDefaultState().with(SnowyDirtBlock.SNOWY, false));
        structure.fillWithBlocks(world, start, -107, -6, 14, -107, -6, 15, Blocks.CAVE_AIR.getDefaultState());
        structure.fillWithBlocks(world, start, -107, -6, 18, -107, -5, 22, Blocks.CAVE_AIR.getDefaultState());
        structure.fillWithBlocks(world, start, -107, -6, 33, -106, -6, 43, Blocks.GRASS_BLOCK.getDefaultState().with(SnowyDirtBlock.SNOWY, false));
        structure.fillWithBlocks(world, start, -107, -5, 12, -107, -5, 12, Blocks.CAVE_AIR.getDefaultState());
        structure.fillWithBlocks(world, start, -107, -5, 24, -107, -4, 25, Blocks.CAVE_AIR.getDefaultState());
        structure.fillWithBlocks(world, start, -107, -4, 21, -105, -4, 25, Blocks.CAVE_AIR.getDefaultState());
        structure.fillWithBlocks(world, start, -107, -4, 34, -106, -4, 36, Blocks.CAVE_AIR.getDefaultState());
        structure.fillWithBlocks(world, start, -107, -3, 23, -107, -3, 23, Blocks.CAVE_AIR.getDefaultState());
        structure.fillWithBlocks(world, start, -107, -3, 34, -105, -3, 36, Blocks.CAVE_AIR.getDefaultState());
        structure.fillWithBlocks(world, start, -107, -3, 37, -107, -3, 41, Blocks.CAVE_AIR.getDefaultState());
        structure.fillWithBlocks(world, start, -106, -11, -71, -105, -11, -70, Blocks.GRASS_BLOCK.getDefaultState().with(SnowyDirtBlock.SNOWY, false));
        structure.fillWithBlocks(world, start, -106, -11, -68, -103, -11, -59, Blocks.DIRT.getDefaultState());
        structure.fillWithBlocks(world, start, -106, -11, -46, -106, -9, -42, Blocks.DIRT.getDefaultState());
        structure.fillWithBlocks(world, start, -106, -11, -40, -104, -11, -38, Blocks.DIRT.getDefaultState());
        structure.fillWithBlocks(world, start, -106, -11, -37, -106, -11, -33, Blocks.GRASS_BLOCK.getDefaultState().with(SnowyDirtBlock.SNOWY, false));
        structure.fillWithBlocks(world, start, -106, -11, -32, -104, -11, -27, Blocks.DIRT.getDefaultState());
        structure.fillWithBlocks(world, start, -106, -11, 22, -93, -11, 35, Blocks.STONE.getDefaultState());
        structure.fillWithBlocks(world, start, -106, -11, 36, -106, -7, 45, Blocks.DIRT.getDefaultState());
        structure.fillWithBlocks(world, start, -106, -11, 46, -95, -11, 57, Blocks.STONE.getDefaultState());
        structure.fillWithBlocks(world, start, -106, -11, 58, -106, -8, 76, Blocks.DIRT.getDefaultState());
        structure.fillWithBlocks(world, start, -106, -11, 80, -104, -11, 86, Blocks.DIRT.getDefaultState());
        structure.fillWithBlocks(world, start, -106, -11, 87, -106, -11, 88, Blocks.GRASS_BLOCK.getDefaultState().with(SnowyDirtBlock.SNOWY, false));
        structure.fillWithBlocks(world, start, -106, -10, -68, -106, -10, -67, Blocks.GRASS_BLOCK.getDefaultState().with(SnowyDirtBlock.SNOWY, false));
        structure.fillWithBlocks(world, start, -106, -10, -66, -101, -10, -57, Blocks.DIRT.getDefaultState());
        structure.fillWithBlocks(world, start, -106, -10, -41, -105, -10, -40, Blocks.DIRT.getDefaultState());
        structure.fillWithBlocks(world, start, -106, -10, -39, -106, -10, -38, Blocks.GRASS_BLOCK.getDefaultState().with(SnowyDirtBlock.SNOWY, false));
        structure.fillWithBlocks(world, start, -106, -10, -32, -106, -10, -30, Blocks.GRASS_BLOCK.getDefaultState().with(SnowyDirtBlock.SNOWY, false));
        structure.fillWithBlocks(world, start, -106, -10, -29, -103, -10, -25, Blocks.DIRT.getDefaultState());
        structure.fillWithBlocks(world, start, -106, -10, -4, -104, -10, 19, Blocks.DIRT.getDefaultState());
        structure.fillWithBlocks(world, start, -106, -10, 23, -101, -10, 28, Blocks.STONE.getDefaultState());
        structure.fillWithBlocks(world, start, -106, -10, 29, -106, -7, 51, Blocks.DIRT.getDefaultState());
        structure.fillWithBlocks(world, start, -106, -10, 82, -105, -10, 83, Blocks.DIRT.getDefaultState());
        structure.fillWithBlocks(world, start, -106, -10, 84, -106, -10, 86, Blocks.GRASS_BLOCK.getDefaultState().with(SnowyDirtBlock.SNOWY, false));
        structure.fillWithBlocks(world, start, -106, -9, -66, -106, -9, -64, Blocks.GRASS_BLOCK.getDefaultState().with(SnowyDirtBlock.SNOWY, false));
        structure.fillWithBlocks(world, start, -106, -9, -63, -99, -9, -42, Blocks.DIRT.getDefaultState());
        structure.fillWithBlocks(world, start, -106, -9, -41, -106, -9, -40, Blocks.GRASS_BLOCK.getDefaultState().with(SnowyDirtBlock.SNOWY, false));
        structure.fillWithBlocks(world, start, -106, -9, -29, -106, -9, -27, Blocks.GRASS_BLOCK.getDefaultState().with(SnowyDirtBlock.SNOWY, false));
        structure.fillWithBlocks(world, start, -106, -9, -26, -102, -9, -3, Blocks.DIRT.getDefaultState());
        structure.fillWithBlocks(world, start, -106, -9, -2, -106, -9, 4, Blocks.GRASS_BLOCK.getDefaultState().with(SnowyDirtBlock.SNOWY, false));
        structure.fillWithBlocks(world, start, -106, -9, 5, -101, -9, 15, Blocks.DIRT.getDefaultState());
        structure.fillWithBlocks(world, start, -106, -9, 16, -104, -9, 19, Blocks.DIRT.getDefaultState());
        structure.fillWithBlocks(world, start, -106, -9, 79, -104, -9, 81, Blocks.DIRT.getDefaultState());
        structure.fillWithBlocks(world, start, -106, -9, 82, -106, -9, 83, Blocks.GRASS_BLOCK.getDefaultState().with(SnowyDirtBlock.SNOWY, false));
        structure.fillWithBlocks(world, start, -106, -8, -71, -105, -8, -71, Blocks.CAVE_AIR.getDefaultState());
        structure.fillWithBlocks(world, start, -106, -8, -63, -106, -8, -61, Blocks.GRASS_BLOCK.getDefaultState().with(SnowyDirtBlock.SNOWY, false));
        structure.fillWithBlocks(world, start, -106, -8, -60, -91, -8, -45, Blocks.DIRT.getDefaultState());
        structure.fillWithBlocks(world, start, -106, -8, -44, -106, -8, -42, Blocks.GRASS_BLOCK.getDefaultState().with(SnowyDirtBlock.SNOWY, false));
        structure.fillWithBlocks(world, start, -106, -8, -26, -106, -8, -21, Blocks.GRASS_BLOCK.getDefaultState().with(SnowyDirtBlock.SNOWY, false));
        structure.fillWithBlocks(world, start, -106, -8, -20, -94, -8, -8, Blocks.DIRT.getDefaultState());
        structure.fillWithBlocks(world, start, -106, -8, -7, -106, -8, -3, Blocks.GRASS_BLOCK.getDefaultState().with(SnowyDirtBlock.SNOWY, false));
        structure.fillWithBlocks(world, start, -106, -8, 5, -105, -8, 6, Blocks.GRASS_BLOCK.getDefaultState().with(SnowyDirtBlock.SNOWY, false));
        structure.fillWithBlocks(world, start, -106, -8, 7, -106, -8, 17, Blocks.GRASS_BLOCK.getDefaultState().with(SnowyDirtBlock.SNOWY, false));
        structure.fillWithBlocks(world, start, -106, -8, 18, -103, -8, 27, Blocks.DIRT.getDefaultState());
        structure.fillWithBlocks(world, start, -106, -8, 28, -104, -8, 76, Blocks.DIRT.getDefaultState());
        structure.fillWithBlocks(world, start, -106, -8, 77, -106, -8, 81, Blocks.GRASS_BLOCK.getDefaultState().with(SnowyDirtBlock.SNOWY, false));
        structure.fillWithBlocks(world, start, -106, -7, -70, -106, -6, -69, Blocks.CAVE_AIR.getDefaultState());
        structure.fillWithBlocks(world, start, -106, -7, -68, -106, -7, -68, Blocks.CAVE_AIR.getDefaultState());
        structure.fillWithBlocks(world, start, -106, -7, -60, -105, -7, -59, Blocks.GRASS_BLOCK.getDefaultState().with(SnowyDirtBlock.SNOWY, false));
        structure.fillWithBlocks(world, start, -106, -7, -58, -106, -7, -45, Blocks.GRASS_BLOCK.getDefaultState().with(SnowyDirtBlock.SNOWY, false));
        structure.fillWithBlocks(world, start, -106, -7, -20, -106, -7, -8, Blocks.GRASS_BLOCK.getDefaultState().with(SnowyDirtBlock.SNOWY, false));
        structure.fillWithBlocks(world, start, -106, -7, 7, -106, -6, 7, Blocks.CAVE_AIR.getDefaultState());
        structure.fillWithBlocks(world, start, -106, -7, 9, -106, -6, 10, Blocks.CAVE_AIR.getDefaultState());
        structure.fillWithBlocks(world, start, -106, -7, 18, -106, -7, 22, Blocks.GRASS_BLOCK.getDefaultState().with(SnowyDirtBlock.SNOWY, false));
        structure.fillWithBlocks(world, start, -106, -7, 23, -78, -7, 51, Blocks.DIRT.getDefaultState());
        structure.fillWithBlocks(world, start, -106, -7, 52, -106, -7, 76, Blocks.GRASS_BLOCK.getDefaultState().with(SnowyDirtBlock.SNOWY, false));
        structure.fillWithBlocks(world, start, -106, -6, 8, -106, -6, 13, Blocks.CAVE_AIR.getDefaultState());
        structure.fillWithBlocks(world, start, -106, -6, 23, -105, -6, 25, Blocks.GRASS_BLOCK.getDefaultState().with(SnowyDirtBlock.SNOWY, false));
        structure.fillWithBlocks(world, start, -106, -6, 26, -106, -6, 51, Blocks.GRASS_BLOCK.getDefaultState().with(SnowyDirtBlock.SNOWY, false));
        structure.fillWithBlocks(world, start, -106, -5, 11, -105, -5, 13, Blocks.CAVE_AIR.getDefaultState());
        structure.fillWithBlocks(world, start, -106, -5, 19, -106, -4, 22, Blocks.CAVE_AIR.getDefaultState());
        structure.fillWithBlocks(world, start, -106, -4, 31, -106, -3, 36, Blocks.CAVE_AIR.getDefaultState());
        structure.fillWithBlocks(world, start, -106, -4, 39, -106, -3, 41, Blocks.CAVE_AIR.getDefaultState());
        structure.fillWithBlocks(world, start, -106, -3, 21, -104, -3, 24, Blocks.CAVE_AIR.getDefaultState());
        structure.fillWithBlocks(world, start, -106, -2, 23, -104, -2, 23, Blocks.CAVE_AIR.getDefaultState());
        structure.fillWithBlocks(world, start, -105, -11, -72, -105, -11, -70, Blocks.GRASS_BLOCK.getDefaultState().with(SnowyDirtBlock.SNOWY, false));
        structure.fillWithBlocks(world, start, -105, -11, -69, -102, -11, -65, Blocks.DIRT.getDefaultState());
        structure.fillWithBlocks(world, start, -105, -11, -51, -99, -11, -45, Blocks.STONE.getDefaultState());
        structure.fillWithBlocks(world, start, -105, -11, -44, -105, -11, -17, Blocks.DIRT.getDefaultState());
        structure.fillWithBlocks(world, start, -105, -11, -16, -96, -11, -7, Blocks.STONE.getDefaultState());
        structure.fillWithBlocks(world, start, -105, -11, -6, -105, -8, -1, Blocks.DIRT.getDefaultState());
        structure.fillWithBlocks(world, start, -105, -11, 0, -103, -11, 6, Blocks.DIRT.getDefaultState());
        structure.fillWithBlocks(world, start, -105, -11, 7, -104, -11, 10, Blocks.DIRT.getDefaultState());
        structure.fillWithBlocks(world, start, -105, -11, 11, -105, -8, 17, Blocks.DIRT.getDefaultState());
        structure.fillWithBlocks(world, start, -105, -11, 18, -57, -11, 66, Blocks.STONE.getDefaultState());
        structure.fillWithBlocks(world, start, -105, -11, 76, -104, -11, 77, Blocks.DIRT.getDefaultState());
        structure.fillWithBlocks(world, start, -105, -11, 78, -105, -11, 87, Blocks.DIRT.getDefaultState());
        structure.fillWithBlocks(world, start, -105, -11, 88, -105, -11, 90, Blocks.GRASS_BLOCK.getDefaultState().with(SnowyDirtBlock.SNOWY, false));
        structure.fillWithBlocks(world, start, -105, -10, -69, -105, -10, -68, Blocks.GRASS_BLOCK.getDefaultState().with(SnowyDirtBlock.SNOWY, false));
        structure.fillWithBlocks(world, start, -105, -10, -67, -101, -10, -57, Blocks.DIRT.getDefaultState());
        structure.fillWithBlocks(world, start, -105, -10, -50, -105, -7, -45, Blocks.DIRT.getDefaultState());
        structure.fillWithBlocks(world, start, -105, -10, -44, -102, -10, -36, Blocks.DIRT.getDefaultState());
        structure.fillWithBlocks(world, start, -105, -10, -34, -103, -10, -25, Blocks.DIRT.getDefaultState());
        structure.fillWithBlocks(world, start, -105, -10, 20, -105, -7, 20, Blocks.DIRT.getDefaultState());
        structure.fillWithBlocks(world, start, -105, -10, 21, -90, -10, 36, Blocks.STONE.getDefaultState());
        structure.fillWithBlocks(world, start, -105, -10, 37, -104, -10, 47, Blocks.DIRT.getDefaultState());
        structure.fillWithBlocks(world, start, -105, -10, 48, -105, -10, 48, Blocks.STONE.getDefaultState());
        structure.fillWithBlocks(world, start, -105, -10, 49, -105, -7, 52, Blocks.DIRT.getDefaultState());
        structure.fillWithBlocks(world, start, -105, -10, 53, -100, -10, 58, Blocks.STONE.getDefaultState());
        structure.fillWithBlocks(world, start, -105, -10, 59, -105, -7, 73, Blocks.DIRT.getDefaultState());
        structure.fillWithBlocks(world, start, -105, -10, 80, -101, -10, 85, Blocks.DIRT.getDefaultState());
        structure.fillWithBlocks(world, start, -105, -10, 86, -105, -10, 87, Blocks.GRASS_BLOCK.getDefaultState().with(SnowyDirtBlock.SNOWY, false));
        structure.fillWithBlocks(world, start, -105, -9, -67, -105, -9, -66, Blocks.GRASS_BLOCK.getDefaultState().with(SnowyDirtBlock.SNOWY, false));
        structure.fillWithBlocks(world, start, -105, -9, -65, -99, -9, -39, Blocks.DIRT.getDefaultState());
        structure.fillWithBlocks(world, start, -105, -9, -38, -105, -9, -36, Blocks.GRASS_BLOCK.getDefaultState().with(SnowyDirtBlock.SNOWY, false));
        structure.fillWithBlocks(world, start, -105, -9, -34, -105, -9, -32, Blocks.GRASS_BLOCK.getDefaultState().with(SnowyDirtBlock.SNOWY, false));
        structure.fillWithBlocks(world, start, -105, -9, -31, -101, -9, -23, Blocks.DIRT.getDefaultState());
        structure.fillWithBlocks(world, start, -105, -9, 0, -100, -9, 10, Blocks.DIRT.getDefaultState());
        structure.fillWithBlocks(world, start, -105, -9, 26, -100, -9, 31, Blocks.STONE.getDefaultState());
        structure.fillWithBlocks(world, start, -105, -9, 32, -104, -9, 53, Blocks.DIRT.getDefaultState());
        structure.fillWithBlocks(world, start, -105, -9, 82, -104, -9, 83, Blocks.DIRT.getDefaultState());
        structure.fillWithBlocks(world, start, -105, -9, 84, -105, -9, 85, Blocks.GRASS_BLOCK.getDefaultState().with(SnowyDirtBlock.SNOWY, false));
        structure.fillWithBlocks(world, start, -105, -8, -65, -105, -8, -63, Blocks.GRASS_BLOCK.getDefaultState().with(SnowyDirtBlock.SNOWY, false));
        structure.fillWithBlocks(world, start, -105, -8, -62, -91, -8, -41, Blocks.DIRT.getDefaultState());
        structure.fillWithBlocks(world, start, -105, -8, -40, -105, -8, -39, Blocks.GRASS_BLOCK.getDefaultState().with(SnowyDirtBlock.SNOWY, false));
        structure.fillWithBlocks(world, start, -105, -8, -31, -105, -8, -27, Blocks.GRASS_BLOCK.getDefaultState().with(SnowyDirtBlock.SNOWY, false));
        structure.fillWithBlocks(world, start, -105, -8, -26, -92, -8, -12, Blocks.DIRT.getDefaultState());
        structure.fillWithBlocks(world, start, -105, -8, -7, -99, -8, -1, Blocks.DIRT.getDefaultState());
        structure.fillWithBlocks(world, start, -105, -8, 0, -105, -8, 6, Blocks.GRASS_BLOCK.getDefaultState().with(SnowyDirtBlock.SNOWY, false));
        structure.fillWithBlocks(world, start, -105, -8, 7, -100, -8, 12, Blocks.DIRT.getDefaultState());
        structure.fillWithBlocks(world, start, -105, -8, 77, -102, -8, 80, Blocks.DIRT.getDefaultState());
        structure.fillWithBlocks(world, start, -105, -8, 81, -105, -8, 83, Blocks.GRASS_BLOCK.getDefaultState().with(SnowyDirtBlock.SNOWY, false));
        structure.fillWithBlocks(world, start, -105, -7, -71, -105, -7, -70, Blocks.CAVE_AIR.getDefaultState());
        structure.fillWithBlocks(world, start, -105, -7, -68, -105, -6, -66, Blocks.CAVE_AIR.getDefaultState());
        structure.fillWithBlocks(world, start, -105, -7, -62, -105, -7, -59, Blocks.GRASS_BLOCK.getDefaultState().with(SnowyDirtBlock.SNOWY, false));
        structure.fillWithBlocks(world, start, -105, -7, -58, -92, -7, -45, Blocks.DIRT.getDefaultState());
        structure.fillWithBlocks(world, start, -105, -7, -44, -105, -7, -41, Blocks.GRASS_BLOCK.getDefaultState().with(SnowyDirtBlock.SNOWY, false));
        structure.fillWithBlocks(world, start, -105, -7, -26, -105, -7, -20, Blocks.GRASS_BLOCK.getDefaultState().with(SnowyDirtBlock.SNOWY, false));
        structure.fillWithBlocks(world, start, -105, -7, -19, -93, -7, -7, Blocks.DIRT.getDefaultState());
        structure.fillWithBlocks(world, start, -105, -7, -6, -105, -7, -1, Blocks.GRASS_BLOCK.getDefaultState().with(SnowyDirtBlock.SNOWY, false));
        structure.fillWithBlocks(world, start, -105, -7, 7, -104, -7, 10, Blocks.GRASS_BLOCK.getDefaultState().with(SnowyDirtBlock.SNOWY, false));
