package mod.arcalitegames.odyssey.world.structure.town.boromirtown;

import mod.arcalitegames.buildersaddition.Index;
import mod.arcalitegames.buildersaddition.blocks.Shelf;
import mod.arcalitegames.odyssey.world.structure.StructureBase;
import net.minecraft.block.BarrelBlock;
import net.minecraft.block.Blocks;
import net.minecraft.block.ChainBlock;
import net.minecraft.block.CropsBlock;
import net.minecraft.block.FarmlandBlock;
import net.minecraft.block.FourWayBlock;
import net.minecraft.block.HorizontalBlock;
import net.minecraft.block.LeavesBlock;
import net.minecraft.block.SlabBlock;
import net.minecraft.block.SnowyDirtBlock;
import net.minecraft.block.StairsBlock;
import net.minecraft.block.TrapDoorBlock;
import net.minecraft.block.WallBlock;
import net.minecraft.block.WallHeight;
import net.minecraft.block.WallTorchBlock;
import net.minecraft.state.properties.Half;
import net.minecraft.state.properties.SlabType;
import net.minecraft.state.properties.StairsShape;
import net.minecraft.util.Direction;
import net.minecraft.util.math.BlockPos;
import net.minecraft.world.World;

public class BoromirComponent3
{
	public static BlockPos start;
    public static World world;
    public static StructureBase structure;

    public static void init(World worldIn, BlockPos blockPos, StructureBase structureIn)
    {
        world = worldIn; start = blockPos; structure = structureIn;
    }
    
    public static void generatePart31()
    {
        structure.fillWithBlocks(world, start, 13, 3, 6, 14, 3, 6, Index.SHELF_SPRUCE.getDefaultState().with(Shelf.FACING, Direction.NORTH));
        structure.fillWithBlocks(world, start, 13, 3, 24, 13, 3, 25, Blocks.COBBLESTONE.getDefaultState());
        structure.fillWithBlocks(world, start, 13, 4, -43, 13, 6, -43, Blocks.OAK_LEAVES.getDefaultState().with(LeavesBlock.PERSISTENT, false).with(LeavesBlock.DISTANCE, 2));
        structure.fillWithBlocks(world, start, 13, 4, -37, 13, 7, -37, Blocks.OAK_LEAVES.getDefaultState().with(LeavesBlock.PERSISTENT, false).with(LeavesBlock.DISTANCE, 2));
        structure.fillWithBlocks(world, start, 13, 4, -36, 13, 5, -36, Blocks.OAK_LEAVES.getDefaultState().with(LeavesBlock.PERSISTENT, false).with(LeavesBlock.DISTANCE, 3));
        structure.fillWithBlocks(world, start, 13, 4, -35, 13, 5, -35, Blocks.OAK_LEAVES.getDefaultState().with(LeavesBlock.PERSISTENT, false).with(LeavesBlock.DISTANCE, 4));
        structure.fillWithBlocks(world, start, 13, 4, -34, 13, 5, -34, Blocks.OAK_LEAVES.getDefaultState().with(LeavesBlock.PERSISTENT, false).with(LeavesBlock.DISTANCE, 5));
        structure.fillWithBlocks(world, start, 13, 4, -30, 13, 5, -30, Blocks.OAK_LEAVES.getDefaultState().with(LeavesBlock.PERSISTENT, false).with(LeavesBlock.DISTANCE, 3));
        structure.fillWithBlocks(world, start, 13, 4, -29, 13, 6, -29, Blocks.OAK_LEAVES.getDefaultState().with(LeavesBlock.PERSISTENT, false).with(LeavesBlock.DISTANCE, 2));
        structure.fillWithBlocks(world, start, 13, 4, -28, 13, 6, -28, Blocks.OAK_LEAVES.getDefaultState().with(LeavesBlock.PERSISTENT, false).with(LeavesBlock.DISTANCE, 1));
        structure.fillWithBlocks(world, start, 13, 4, -27, 13, 4, -26, Blocks.OAK_LEAVES.getDefaultState().with(LeavesBlock.PERSISTENT, false).with(LeavesBlock.DISTANCE, 2));
        structure.fillWithBlocks(world, start, 13, 4, -25, 13, 4, -24, Blocks.OAK_LEAVES.getDefaultState().with(LeavesBlock.PERSISTENT, false).with(LeavesBlock.DISTANCE, 1));
        structure.fillWithBlocks(world, start, 13, 4, -10, 14, 4, -8, Blocks.SPRUCE_PLANKS.getDefaultState());
        structure.fillWithBlocks(world, start, 13, 4, 15, 15, 4, 22, Blocks.SPRUCE_PLANKS.getDefaultState());
        structure.fillWithBlocks(world, start, 13, 4, 25, 13, 5, 25, Blocks.OAK_STAIRS.getDefaultState().with(StairsBlock.FACING, Direction.EAST).with(StairsBlock.WATERLOGGED, false).with(StairsBlock.SHAPE, StairsShape.STRAIGHT).with(StairsBlock.HALF, Half.BOTTOM));
        structure.fillWithBlocks(world, start, 13, 5, -45, 14, 5, -45, Blocks.OAK_LEAVES.getDefaultState().with(LeavesBlock.PERSISTENT, false).with(LeavesBlock.DISTANCE, 3));
        structure.fillWithBlocks(world, start, 13, 5, -44, 13, 6, -43, Blocks.OAK_LEAVES.getDefaultState().with(LeavesBlock.PERSISTENT, false).with(LeavesBlock.DISTANCE, 2));
        structure.fillWithBlocks(world, start, 13, 5, -42, 13, 5, -42, Blocks.OAK_LEAVES.getDefaultState().with(LeavesBlock.PERSISTENT, false).with(LeavesBlock.DISTANCE, 1));
        structure.fillWithBlocks(world, start, 13, 5, -40, 13, 5, -40, Blocks.OAK_LEAVES.getDefaultState().with(LeavesBlock.PERSISTENT, false).with(LeavesBlock.DISTANCE, 1));
        structure.fillWithBlocks(world, start, 13, 5, -38, 13, 5, -37, Blocks.OAK_LEAVES.getDefaultState().with(LeavesBlock.PERSISTENT, false).with(LeavesBlock.DISTANCE, 2));
        structure.fillWithBlocks(world, start, 13, 5, -27, 13, 5, -27, Blocks.OAK_LEAVES.getDefaultState().with(LeavesBlock.PERSISTENT, false).with(LeavesBlock.DISTANCE, 2));
        structure.fillWithBlocks(world, start, 13, 5, -26, 13, 6, -26, Blocks.OAK_LEAVES.getDefaultState().with(LeavesBlock.PERSISTENT, false).with(LeavesBlock.DISTANCE, 3));
        structure.fillWithBlocks(world, start, 13, 5, -25, 13, 7, -25, Blocks.OAK_LEAVES.getDefaultState().with(LeavesBlock.PERSISTENT, false).with(LeavesBlock.DISTANCE, 2));
        structure.fillWithBlocks(world, start, 13, 5, -22, 14, 5, -22, Blocks.OAK_LEAVES.getDefaultState().with(LeavesBlock.PERSISTENT, false).with(LeavesBlock.DISTANCE, 2));
        structure.fillWithBlocks(world, start, 13, 5, -10, 14, 5, -8, Blocks.SPRUCE_PLANKS.getDefaultState());
        structure.fillWithBlocks(world, start, 13, 5, 5, 13, 8, 5, Blocks.CHAIN.getDefaultState().with(ChainBlock.WATERLOGGED, false));
        structure.fillWithBlocks(world, start, 13, 6, -42, 13, 6, -42, Blocks.OAK_LEAVES.getDefaultState().with(LeavesBlock.PERSISTENT, false).with(LeavesBlock.DISTANCE, 2));
        structure.fillWithBlocks(world, start, 13, 6, -40, 13, 6, -40, Blocks.OAK_LEAVES.getDefaultState().with(LeavesBlock.PERSISTENT, false).with(LeavesBlock.DISTANCE, 2));
        structure.fillWithBlocks(world, start, 13, 6, -39, 13, 6, -38, Blocks.OAK_LEAVES.getDefaultState().with(LeavesBlock.PERSISTENT, false).with(LeavesBlock.DISTANCE, 3));
        structure.fillWithBlocks(world, start, 13, 6, -10, 14, 6, -8, Blocks.SPRUCE_PLANKS.getDefaultState());
        structure.fillWithBlocks(world, start, 13, 6, 17, 14, 6, 18, Blocks.COBBLESTONE_SLAB.getDefaultState().with(SlabBlock.TYPE, SlabType.BOTTOM).with(SlabBlock.WATERLOGGED, false));
        structure.fillWithBlocks(world, start, 13, 6, 31, 18, 6, 36, Blocks.COBBLESTONE.getDefaultState());
        structure.fillWithBlocks(world, start, 13, 6, 55, 14, 6, 57, Blocks.OAK_FENCE.getDefaultState().with(FourWayBlock.WATERLOGGED, false).with(FourWayBlock.NORTH, true).with(FourWayBlock.SOUTH, true).with(FourWayBlock.EAST, true).with(FourWayBlock.WEST, true));
        structure.fillWithBlocks(world, start, 13, 7, -44, 13, 7, -44, Blocks.OAK_LEAVES.getDefaultState().with(LeavesBlock.PERSISTENT, false).with(LeavesBlock.DISTANCE, 2));
        structure.fillWithBlocks(world, start, 13, 7, -43, 13, 7, -42, Blocks.OAK_LEAVES.getDefaultState().with(LeavesBlock.PERSISTENT, false).with(LeavesBlock.DISTANCE, 3));
        structure.fillWithBlocks(world, start, 13, 7, -40, 13, 7, -40, Blocks.OAK_LEAVES.getDefaultState().with(LeavesBlock.PERSISTENT, false).with(LeavesBlock.DISTANCE, 3));
        structure.fillWithBlocks(world, start, 13, 7, -36, 13, 7, -36, Blocks.OAK_LEAVES.getDefaultState().with(LeavesBlock.PERSISTENT, false).with(LeavesBlock.DISTANCE, 3));
        structure.fillWithBlocks(world, start, 13, 7, -35, 13, 7, -35, Blocks.OAK_LEAVES.getDefaultState().with(LeavesBlock.PERSISTENT, false).with(LeavesBlock.DISTANCE, 4));
        structure.fillWithBlocks(world, start, 13, 7, -28, 13, 7, -28, Blocks.OAK_LEAVES.getDefaultState().with(LeavesBlock.PERSISTENT, false).with(LeavesBlock.DISTANCE, 2));
        structure.fillWithBlocks(world, start, 13, 7, -10, 14, 7, -8, Blocks.SPRUCE_PLANKS.getDefaultState());
        structure.fillWithBlocks(world, start, 13, 7, 55, 14, 7, 57, Blocks.OAK_FENCE.getDefaultState().with(FourWayBlock.WATERLOGGED, false).with(FourWayBlock.NORTH, true).with(FourWayBlock.SOUTH, true).with(FourWayBlock.EAST, true).with(FourWayBlock.WEST, true));
        structure.fillWithBlocks(world, start, 13, 8, -44, 13, 8, -44, Blocks.OAK_LEAVES.getDefaultState().with(LeavesBlock.PERSISTENT, false).with(LeavesBlock.DISTANCE, 3));
        structure.fillWithBlocks(world, start, 13, 8, -43, 13, 8, -42, Blocks.OAK_LEAVES.getDefaultState().with(LeavesBlock.PERSISTENT, false).with(LeavesBlock.DISTANCE, 4));
        structure.fillWithBlocks(world, start, 13, 8, -40, 13, 8, -40, Blocks.OAK_LEAVES.getDefaultState().with(LeavesBlock.PERSISTENT, false).with(LeavesBlock.DISTANCE, 4));
        structure.fillWithBlocks(world, start, 13, 8, -37, 13, 8, -37, Blocks.OAK_LEAVES.getDefaultState().with(LeavesBlock.PERSISTENT, false).with(LeavesBlock.DISTANCE, 3));
        structure.fillWithBlocks(world, start, 13, 8, -36, 13, 8, -36, Blocks.OAK_LEAVES.getDefaultState().with(LeavesBlock.PERSISTENT, false).with(LeavesBlock.DISTANCE, 4));
        structure.fillWithBlocks(world, start, 13, 8, -35, 13, 8, -35, Blocks.OAK_LEAVES.getDefaultState().with(LeavesBlock.PERSISTENT, false).with(LeavesBlock.DISTANCE, 5));
        structure.fillWithBlocks(world, start, 13, 8, -24, 13, 8, -24, Blocks.OAK_LEAVES.getDefaultState().with(LeavesBlock.PERSISTENT, false).with(LeavesBlock.DISTANCE, 2));
        structure.fillWithBlocks(world, start, 13, 8, -10, 14, 8, -8, Blocks.SPRUCE_PLANKS.getDefaultState());
        structure.fillWithBlocks(world, start, 13, 8, -2, 15, 8, -2, Blocks.SPRUCE_PLANKS.getDefaultState());
        structure.fillWithBlocks(world, start, 13, 8, 4, 13, 8, 4, Blocks.GLOWSTONE.getDefaultState());
        structure.fillWithBlocks(world, start, 13, 9, -37, 13, 9, -37, Blocks.OAK_LEAVES.getDefaultState().with(LeavesBlock.PERSISTENT, false).with(LeavesBlock.DISTANCE, 4));
        structure.fillWithBlocks(world, start, 13, 9, -36, 13, 9, -36, Blocks.OAK_LEAVES.getDefaultState().with(LeavesBlock.PERSISTENT, false).with(LeavesBlock.DISTANCE, 5));
        structure.fillWithBlocks(world, start, 13, 9, -10, 14, 9, -8, Blocks.SPRUCE_PLANKS.getDefaultState());
        structure.fillWithBlocks(world, start, 14, -11, 92, 14, -11, 92, Blocks.DIRT.getDefaultState());
        structure.fillWithBlocks(world, start, 14, -10, -72, 36, -10, 88, Blocks.STONE.getDefaultState());
        structure.fillWithBlocks(world, start, 14, -10, 89, 16, -10, 98, Blocks.DIRT.getDefaultState());
        structure.fillWithBlocks(world, start, 14, -9, -72, 17, -7, -72, Blocks.DIRT.getDefaultState());
        structure.fillWithBlocks(world, start, 14, -9, -71, 14, -9, -71, Blocks.STONE.getDefaultState());
        structure.fillWithBlocks(world, start, 14, -9, -70, 14, -6, -70, Blocks.DIRT.getDefaultState());
        structure.fillWithBlocks(world, start, 14, -9, -65, 15, -9, -64, Blocks.STONE.getDefaultState());
        structure.fillWithBlocks(world, start, 14, -9, -63, 14, -9, -56, Blocks.DIRT.getDefaultState());
        structure.fillWithBlocks(world, start, 14, -9, -40, 15, -9, -39, Blocks.STONE.getDefaultState());
        structure.fillWithBlocks(world, start, 14, -9, -38, 14, -9, -26, Blocks.DIRT.getDefaultState());
        structure.fillWithBlocks(world, start, 14, -9, -1, 17, -9, 2, Blocks.DIRT.getDefaultState());
        structure.fillWithBlocks(world, start, 14, -9, 3, 16, -7, 3, Blocks.DIRT.getDefaultState());
        structure.fillWithBlocks(world, start, 14, -9, 15, 24, -9, 47, Blocks.STONE.getDefaultState());
        structure.fillWithBlocks(world, start, 14, -9, 48, 15, -9, 49, Blocks.STONE.getDefaultState());
        structure.fillWithBlocks(world, start, 14, -9, 101, 16, -9, 103, Blocks.CAVE_AIR.getDefaultState());
        structure.fillWithBlocks(world, start, 14, -8, -8, 40, -8, 22, Blocks.DIRT.getDefaultState());
        structure.fillWithBlocks(world, start, 14, -5, 96, 15, -5, 98, Blocks.CAVE_AIR.getDefaultState());
        structure.fillWithBlocks(world, start, 14, -4, -69, 19, -4, -63, Blocks.GRASS_BLOCK.getDefaultState().with(SnowyDirtBlock.SNOWY, false));
        structure.fillWithBlocks(world, start, 14, -4, -53, 15, -3, -53, Blocks.STONE.getDefaultState());
        structure.fillWithBlocks(world, start, 14, -4, -52, 17, -4, -49, Blocks.GRAVEL.getDefaultState());
        structure.fillWithBlocks(world, start, 14, -4, -48, 15, -3, -48, Blocks.GRAVEL.getDefaultState());
        structure.fillWithBlocks(world, start, 14, -4, -47, 25, -4, -36, Blocks.STONE.getDefaultState());
        structure.fillWithBlocks(world, start, 14, -4, -16, 14, -3, -15, Blocks.DIRT.getDefaultState());
        structure.fillWithBlocks(world, start, 14, -4, -14, 17, -4, -11, Blocks.STONE.getDefaultState());
        structure.fillWithBlocks(world, start, 14, -4, -10, 15, -3, -10, Blocks.DIRT.getDefaultState());
        structure.fillWithBlocks(world, start, 14, -4, -9, 15, -4, -6, Blocks.STONE.getDefaultState());
        structure.fillWithBlocks(world, start, 14, -4, -5, 14, -2, -5, Blocks.DIRT.getDefaultState());
        structure.fillWithBlocks(world, start, 14, -4, -4, 20, -4, 2, Blocks.STONE.getDefaultState());
        structure.fillWithBlocks(world, start, 14, -4, 3, 14, -3, 4, Blocks.DIRT.getDefaultState());
        structure.fillWithBlocks(world, start, 14, -4, 5, 18, -4, 9, Blocks.STONE.getDefaultState());
        structure.fillWithBlocks(world, start, 14, -4, 54, 15, -4, 55, Blocks.DIRT.getDefaultState());
        structure.fillWithBlocks(world, start, 14, -4, 56, 14, -4, 72, Blocks.STONE.getDefaultState());
        structure.fillWithBlocks(world, start, 14, -4, 73, 14, -2, 73, Blocks.DIRT.getDefaultState());
        structure.fillWithBlocks(world, start, 14, -4, 74, 15, -4, 75, Blocks.STONE.getDefaultState());
        structure.fillWithBlocks(world, start, 14, -4, 76, 15, -4, 79, Blocks.DIRT.getDefaultState());
        structure.fillWithBlocks(world, start, 14, -4, 93, 16, -4, 97, Blocks.CAVE_AIR.getDefaultState());
        structure.fillWithBlocks(world, start, 14, -3, -62, 15, -3, -61, Blocks.GRASS_BLOCK.getDefaultState().with(SnowyDirtBlock.SNOWY, false));
        structure.fillWithBlocks(world, start, 14, -3, -55, 15, -3, -53, Blocks.STONE.getDefaultState());
        structure.fillWithBlocks(world, start, 14, -3, -52, 16, -3, -50, Blocks.GRAVEL.getDefaultState());
        structure.fillWithBlocks(world, start, 14, -3, 6, 15, -3, 8, Blocks.STONE.getDefaultState());
        structure.fillWithBlocks(world, start, 14, -3, 10, 15, -3, 55, Blocks.DIRT.getDefaultState());
        structure.fillWithBlocks(world, start, 14, -3, 56, 14, -1, 62, Blocks.DIRT.getDefaultState());
        structure.fillWithBlocks(world, start, 14, -3, 63, 14, -3, 63, Blocks.STONE.getDefaultState());
        structure.fillWithBlocks(world, start, 14, -3, 64, 14, -1, 64, Blocks.DIRT.getDefaultState());
        structure.fillWithBlocks(world, start, 14, -3, 65, 17, -3, 69, Blocks.STONE.getDefaultState());
        structure.fillWithBlocks(world, start, 14, -3, 71, 14, -2, 77, Blocks.DIRT.getDefaultState());
        structure.fillWithBlocks(world, start, 14, -3, 93, 15, -3, 97, Blocks.CAVE_AIR.getDefaultState());
        structure.fillWithBlocks(world, start, 14, -2, -60, 15, -2, -59, Blocks.GRASS_BLOCK.getDefaultState().with(SnowyDirtBlock.SNOWY, false));
        structure.fillWithBlocks(world, start, 14, -2, -18, 29, -1, -18, Blocks.DIRT.getDefaultState());
        structure.fillWithBlocks(world, start, 14, -2, -17, 16, 0, -17, Blocks.GRAVEL.getDefaultState());
        structure.fillWithBlocks(world, start, 14, -2, -16, 31, -2, 6, Blocks.DIRT.getDefaultState());
        structure.fillWithBlocks(world, start, 14, -2, 9, 14, 0, 9, Blocks.GRAVEL.getDefaultState());
        structure.fillWithBlocks(world, start, 14, -2, 10, 15, -2, 24, Blocks.DIRT.getDefaultState());
        structure.fillWithBlocks(world, start, 14, -2, 25, 14, -1, 25, Blocks.NETHERRACK.getDefaultState());
        structure.fillWithBlocks(world, start, 14, -2, 26, 22, -2, 39, Blocks.DIRT.getDefaultState());
        structure.fillWithBlocks(world, start, 14, -2, 42, 14, -1, 45, Blocks.DIRT.getDefaultState());
        structure.fillWithBlocks(world, start, 14, -2, 46, 14, 0, 46, Blocks.GRAVEL.getDefaultState());
        structure.fillWithBlocks(world, start, 14, -2, 47, 18, -2, 51, Blocks.DIRT.getDefaultState());
        structure.fillWithBlocks(world, start, 14, -2, 52, 14, -1, 54, Blocks.DIRT.getDefaultState());
        structure.fillWithBlocks(world, start, 14, -2, 55, 14, 0, 55, Blocks.GRAVEL.getDefaultState());
        structure.fillWithBlocks(world, start, 14, -2, 63, 14, 0, 63, Blocks.GRAVEL.getDefaultState());
        structure.fillWithBlocks(world, start, 14, -2, 65, 14, 0, 65, Blocks.GRAVEL.getDefaultState());
        structure.fillWithBlocks(world, start, 14, -2, 68, 14, -1, 68, Blocks.STONE.getDefaultState());
        structure.fillWithBlocks(world, start, 14, -2, 69, 14, -2, 69, Blocks.GRAVEL.getDefaultState());
        structure.fillWithBlocks(world, start, 14, -2, 70, 14, -1, 70, Blocks.STONE.getDefaultState());
        structure.fillWithBlocks(world, start, 14, -2, 95, 15, -2, 95, Blocks.CAVE_AIR.getDefaultState());
        structure.fillWithBlocks(world, start, 14, -1, -16, 18, -1, -12, Blocks.DIRT.getDefaultState());
        structure.fillWithBlocks(world, start, 14, -1, -10, 15, -1, -10, Blocks.HAY_BLOCK.getDefaultState());
        structure.fillWithBlocks(world, start, 14, -1, -9, 15, -1, -6, Blocks.DIRT.getDefaultState());
        structure.fillWithBlocks(world, start, 14, -1, -4, 17, -1, 1, Blocks.DIRT.getDefaultState());
        structure.fillWithBlocks(world, start, 14, -1, 3, 14, -1, 4, Blocks.HAY_BLOCK.getDefaultState());
        structure.fillWithBlocks(world, start, 14, -1, 6, 15, -1, 6, Blocks.RED_TERRACOTTA.getDefaultState());
        structure.fillWithBlocks(world, start, 14, -1, 7, 15, -1, 8, Blocks.DIRT.getDefaultState());
        structure.fillWithBlocks(world, start, 14, -1, 10, 15, -1, 24, Blocks.DIRT.getDefaultState());
        structure.fillWithBlocks(world, start, 14, -1, 26, 22, -1, 36, Blocks.DIRT.getDefaultState());
        structure.fillWithBlocks(world, start, 14, -1, 40, 14, -1, 45, Blocks.DIRT.getDefaultState());
        structure.fillWithBlocks(world, start, 14, -1, 47, 18, -1, 51, Blocks.DIRT.getDefaultState());
        structure.fillWithBlocks(world, start, 14, -1, 69, 14, -1, 69, Blocks.GRAVEL.getDefaultState());
        structure.fillWithBlocks(world, start, 14, -1, 71, 14, -1, 72, Blocks.DIRT.getDefaultState());
        structure.fillWithBlocks(world, start, 14, -1, 74, 15, -1, 76, Blocks.DIRT.getDefaultState());
        structure.fillWithBlocks(world, start, 14, 0, -57, 15, 0, -56, Blocks.GRASS_BLOCK.getDefaultState().with(SnowyDirtBlock.SNOWY, false));
        structure.fillWithBlocks(world, start, 14, 0, -53, 17, 0, -50, Blocks.DIRT.getDefaultState());
        structure.fillWithBlocks(world, start, 14, 0, -48, 14, 0, -48, Blocks.GRASS_BLOCK.getDefaultState().with(SnowyDirtBlock.SNOWY, false));
        structure.fillWithBlocks(world, start, 14, 0, -47, 14, 0, -47, Blocks.FARMLAND.getDefaultState().with(FarmlandBlock.MOISTURE, 7));
        structure.fillWithBlocks(world, start, 14, 0, -46, 14, 0, -46, Blocks.GRASS_BLOCK.getDefaultState().with(SnowyDirtBlock.SNOWY, false));
        structure.fillWithBlocks(world, start, 14, 0, -45, 14, 0, -45, Blocks.FARMLAND.getDefaultState().with(FarmlandBlock.MOISTURE, 7));
        structure.fillWithBlocks(world, start, 14, 0, -43, 14, 0, -43, Blocks.FARMLAND.getDefaultState().with(FarmlandBlock.MOISTURE, 7));
        structure.fillWithBlocks(world, start, 14, 0, -42, 14, 0, -42, Blocks.GRASS_BLOCK.getDefaultState().with(SnowyDirtBlock.SNOWY, false));
        structure.fillWithBlocks(world, start, 14, 0, -41, 14, 0, -41, Blocks.FARMLAND.getDefaultState().with(FarmlandBlock.MOISTURE, 7));
        structure.fillWithBlocks(world, start, 14, 0, -40, 14, 0, -40, Blocks.GRASS_BLOCK.getDefaultState().with(SnowyDirtBlock.SNOWY, false));
        structure.fillWithBlocks(world, start, 14, 0, -39, 14, 0, -39, Blocks.FARMLAND.getDefaultState().with(FarmlandBlock.MOISTURE, 7));
        structure.fillWithBlocks(world, start, 14, 0, -37, 14, 0, -37, Blocks.FARMLAND.getDefaultState().with(FarmlandBlock.MOISTURE, 7));
        structure.fillWithBlocks(world, start, 14, 0, -36, 14, 0, -36, Blocks.GRASS_BLOCK.getDefaultState().with(SnowyDirtBlock.SNOWY, false));
        structure.fillWithBlocks(world, start, 14, 0, -35, 14, 0, -35, Blocks.FARMLAND.getDefaultState().with(FarmlandBlock.MOISTURE, 7));
        structure.fillWithBlocks(world, start, 14, 0, -34, 14, 0, -34, Blocks.GRASS_BLOCK.getDefaultState().with(SnowyDirtBlock.SNOWY, false));
        structure.fillWithBlocks(world, start, 14, 0, -33, 14, 0, -33, Blocks.FARMLAND.getDefaultState().with(FarmlandBlock.MOISTURE, 7));
        structure.fillWithBlocks(world, start, 14, 0, -32, 14, 0, -32, Blocks.GRASS_BLOCK.getDefaultState().with(SnowyDirtBlock.SNOWY, false));
        structure.fillWithBlocks(world, start, 14, 0, -31, 14, 0, -31, Blocks.FARMLAND.getDefaultState().with(FarmlandBlock.MOISTURE, 7));
        structure.fillWithBlocks(world, start, 14, 0, -30, 14, 0, -30, Blocks.GRASS_BLOCK.getDefaultState().with(SnowyDirtBlock.SNOWY, false));
        structure.fillWithBlocks(world, start, 14, 0, -29, 14, 0, -29, Blocks.FARMLAND.getDefaultState().with(FarmlandBlock.MOISTURE, 7));
        structure.fillWithBlocks(world, start, 14, 0, -18, 18, 0, -18, Blocks.STONE_BRICKS.getDefaultState());
        structure.fillWithBlocks(world, start, 14, 0, -16, 18, 0, -16, Blocks.STONE_BRICKS.getDefaultState());
        structure.fillWithBlocks(world, start, 14, 0, -11, 14, 3, -11, Blocks.OAK_LOG.getDefaultState());
        structure.fillWithBlocks(world, start, 14, 0, 7, 16, 0, 7, Blocks.DIRT.getDefaultState());
        structure.fillWithBlocks(world, start, 14, 0, 14, 14, 0, 23, Blocks.SPRUCE_PLANKS.getDefaultState());
        structure.fillWithBlocks(world, start, 14, 0, 24, 14, 0, 25, Blocks.COBBLESTONE.getDefaultState());
        structure.fillWithBlocks(world, start, 14, 0, 27, 14, 0, 28, Blocks.GRASS_BLOCK.getDefaultState().with(SnowyDirtBlock.SNOWY, false));
        structure.fillWithBlocks(world, start, 14, 0, 30, 20, 0, 36, Blocks.OAK_PLANKS.getDefaultState());
        structure.fillWithBlocks(world, start, 14, 0, 37, 14, 0, 37, Blocks.DIRT.getDefaultState());
        structure.fillWithBlocks(world, start, 14, 0, 38, 14, 0, 39, Blocks.GRASS_BLOCK.getDefaultState().with(SnowyDirtBlock.SNOWY, false));
        structure.fillWithBlocks(world, start, 14, 0, 42, 14, 0, 45, Blocks.STONE_BRICKS.getDefaultState());
        structure.fillWithBlocks(world, start, 14, 0, 48, 16, 0, 50, Blocks.GRASS_BLOCK.getDefaultState().with(SnowyDirtBlock.SNOWY, false));
        structure.fillWithBlocks(world, start, 14, 0, 51, 14, 0, 54, Blocks.STONE_BRICKS.getDefaultState());
        structure.fillWithBlocks(world, start, 14, 0, 56, 14, 0, 62, Blocks.STONE_BRICKS.getDefaultState());
        structure.fillWithBlocks(world, start, 14, 0, 64, 14, 0, 64, Blocks.STONE_BRICKS.getDefaultState());
        structure.fillWithBlocks(world, start, 14, 0, 66, 14, 0, 66, Blocks.STONE_BRICKS.getDefaultState());
        structure.fillWithBlocks(world, start, 14, 0, 69, 14, 0, 69, Blocks.GRAVEL.getDefaultState());
        structure.fillWithBlocks(world, start, 14, 0, 70, 14, 0, 72, Blocks.STONE_BRICKS.getDefaultState());
        structure.fillWithBlocks(world, start, 14, 0, 73, 15, 0, 73, Blocks.GRAVEL.getDefaultState());
        structure.fillWithBlocks(world, start, 14, 0, 74, 15, 0, 75, Blocks.STONE_BRICKS.getDefaultState());
        structure.fillWithBlocks(world, start, 14, 1, -55, 15, 2, -55, Blocks.OAK_LOG.getDefaultState());
        structure.fillWithBlocks(world, start, 14, 1, -51, 15, 2, -51, Blocks.OAK_LOG.getDefaultState());
        structure.fillWithBlocks(world, start, 14, 1, -45, 14, 1, -45, Blocks.CARROTS.getDefaultState().with(CropsBlock.AGE, 7));
        structure.fillWithBlocks(world, start, 14, 1, -43, 14, 1, -43, Blocks.CARROTS.getDefaultState().with(CropsBlock.AGE, 7));
        structure.fillWithBlocks(world, start, 14, 1, -41, 14, 1, -41, Blocks.CARROTS.getDefaultState().with(CropsBlock.AGE, 7));
        structure.fillWithBlocks(world, start, 14, 1, -39, 14, 1, -39, Blocks.CARROTS.getDefaultState().with(CropsBlock.AGE, 7));
        structure.fillWithBlocks(world, start, 14, 1, -37, 14, 1, -37, Blocks.CARROTS.getDefaultState().with(CropsBlock.AGE, 7));
        structure.fillWithBlocks(world, start, 14, 1, -35, 14, 1, -35, Blocks.CARROTS.getDefaultState().with(CropsBlock.AGE, 7));
        structure.fillWithBlocks(world, start, 14, 1, -33, 14, 1, -33, Blocks.CARROTS.getDefaultState().with(CropsBlock.AGE, 7));
        structure.fillWithBlocks(world, start, 14, 1, -31, 14, 1, -31, Blocks.CARROTS.getDefaultState().with(CropsBlock.AGE, 7));
        structure.fillWithBlocks(world, start, 14, 1, -29, 14, 1, -29, Blocks.CARROTS.getDefaultState().with(CropsBlock.AGE, 7));
        structure.fillWithBlocks(world, start, 14, 1, -28, 14, 6, -28, Blocks.OAK_LOG.getDefaultState());
        structure.fillWithBlocks(world, start, 14, 1, -25, 15, 1, -24, Blocks.DIRT.getDefaultState());
        structure.fillWithBlocks(world, start, 14, 1, -22, 16, 1, -20, Blocks.GRASS.getDefaultState());
        structure.fillWithBlocks(world, start, 14, 1, -12, 14, 2, -12, Blocks.OAK_FENCE.getDefaultState().with(FourWayBlock.WATERLOGGED, false).with(FourWayBlock.NORTH, false).with(FourWayBlock.SOUTH, true).with(FourWayBlock.EAST, false).with(FourWayBlock.WEST, false));
        structure.fillWithBlocks(world, start, 14, 1, 26, 14, 7, 26, Blocks.COBBLESTONE.getDefaultState());
        structure.fillWithBlocks(world, start, 14, 1, 29, 14, 6, 29, Blocks.COBBLESTONE.getDefaultState());
        structure.fillWithBlocks(world, start, 14, 1, 37, 14, 6, 37, Blocks.COBBLESTONE.getDefaultState());
        structure.fillWithBlocks(world, start, 14, 2, -25, 14, 2, -25, Blocks.GRASS_BLOCK.getDefaultState().with(SnowyDirtBlock.SNOWY, false));
        structure.fillWithBlocks(world, start, 14, 2, -16, 14, 3, -16, Blocks.OAK_LEAVES.getDefaultState().with(LeavesBlock.PERSISTENT, false).with(LeavesBlock.DISTANCE, 3));
        structure.fillWithBlocks(world, start, 14, 2, -15, 14, 3, -15, Blocks.OAK_LEAVES.getDefaultState().with(LeavesBlock.PERSISTENT, false).with(LeavesBlock.DISTANCE, 2));
        structure.fillWithBlocks(world, start, 14, 2, -14, 14, 3, -14, Blocks.OAK_LEAVES.getDefaultState().with(LeavesBlock.PERSISTENT, false).with(LeavesBlock.DISTANCE, 3));
        structure.fillWithBlocks(world, start, 14, 3, -55, 15, 4, -55, Blocks.OAK_LOG.getDefaultState());
        structure.fillWithBlocks(world, start, 14, 3, -51, 15, 4, -51, Blocks.OAK_LOG.getDefaultState());
        structure.fillWithBlocks(world, start, 14, 3, -44, 14, 6, -44, Blocks.OAK_LEAVES.getDefaultState().with(LeavesBlock.PERSISTENT, false).with(LeavesBlock.DISTANCE, 2));
        structure.fillWithBlocks(world, start, 14, 3, -24, 14, 7, -24, Blocks.OAK_LOG.getDefaultState());
        structure.fillWithBlocks(world, start, 14, 3, -23, 14, 7, -23, Blocks.OAK_LEAVES.getDefaultState().with(LeavesBlock.PERSISTENT, false).with(LeavesBlock.DISTANCE, 1));
        structure.fillWithBlocks(world, start, 14, 3, -22, 14, 6, -22, Blocks.OAK_LEAVES.getDefaultState().with(LeavesBlock.PERSISTENT, false).with(LeavesBlock.DISTANCE, 2));
        structure.fillWithBlocks(world, start, 14, 3, -21, 14, 4, -21, Blocks.OAK_LEAVES.getDefaultState().with(LeavesBlock.PERSISTENT, false).with(LeavesBlock.DISTANCE, 3));
        structure.fillWithBlocks(world, start, 14, 4, -46, 14, 5, -46, Blocks.OAK_LEAVES.getDefaultState().with(LeavesBlock.PERSISTENT, false).with(LeavesBlock.DISTANCE, 4));
        structure.fillWithBlocks(world, start, 14, 4, -45, 14, 5, -45, Blocks.OAK_LEAVES.getDefaultState().with(LeavesBlock.PERSISTENT, false).with(LeavesBlock.DISTANCE, 3));
        structure.fillWithBlocks(world, start, 14, 4, -43, 14, 6, -43, Blocks.OAK_LEAVES.getDefaultState().with(LeavesBlock.PERSISTENT, false).with(LeavesBlock.DISTANCE, 1));
        structure.fillWithBlocks(world, start, 14, 4, -37, 14, 7, -37, Blocks.OAK_LEAVES.getDefaultState().with(LeavesBlock.PERSISTENT, false).with(LeavesBlock.DISTANCE, 1));
        structure.fillWithBlocks(world, start, 14, 4, -36, 14, 5, -36, Blocks.OAK_LEAVES.getDefaultState().with(LeavesBlock.PERSISTENT, false).with(LeavesBlock.DISTANCE, 2));
        structure.fillWithBlocks(world, start, 14, 4, -35, 14, 5, -35, Blocks.OAK_LEAVES.getDefaultState().with(LeavesBlock.PERSISTENT, false).with(LeavesBlock.DISTANCE, 3));
        structure.fillWithBlocks(world, start, 14, 4, -34, 14, 5, -34, Blocks.OAK_LEAVES.getDefaultState().with(LeavesBlock.PERSISTENT, false).with(LeavesBlock.DISTANCE, 4));
        structure.fillWithBlocks(world, start, 14, 4, -30, 14, 5, -30, Blocks.OAK_LEAVES.getDefaultState().with(LeavesBlock.PERSISTENT, false).with(LeavesBlock.DISTANCE, 2));
        structure.fillWithBlocks(world, start, 14, 4, -29, 14, 6, -29, Blocks.OAK_LEAVES.getDefaultState().with(LeavesBlock.PERSISTENT, false).with(LeavesBlock.DISTANCE, 1));
        structure.fillWithBlocks(world, start, 14, 4, -27, 14, 6, -27, Blocks.OAK_LEAVES.getDefaultState().with(LeavesBlock.PERSISTENT, false).with(LeavesBlock.DISTANCE, 1));
        structure.fillWithBlocks(world, start, 14, 4, -26, 14, 6, -26, Blocks.OAK_LEAVES.getDefaultState().with(LeavesBlock.PERSISTENT, false).with(LeavesBlock.DISTANCE, 2));
        structure.fillWithBlocks(world, start, 14, 4, -25, 14, 7, -25, Blocks.OAK_LEAVES.getDefaultState().with(LeavesBlock.PERSISTENT, false).with(LeavesBlock.DISTANCE, 1));
        structure.fillWithBlocks(world, start, 14, 4, -7, 15, 4, -6, Blocks.SPRUCE_STAIRS.getDefaultState().with(StairsBlock.FACING, Direction.SOUTH).with(StairsBlock.WATERLOGGED, false).with(StairsBlock.SHAPE, StairsShape.STRAIGHT).with(StairsBlock.HALF, Half.BOTTOM));
        structure.fillWithBlocks(world, start, 14, 4, -5, 15, 4, 1, Blocks.SPRUCE_PLANKS.getDefaultState());
        structure.fillWithBlocks(world, start, 14, 4, 13, 14, 4, 14, Blocks.COBBLESTONE_STAIRS.getDefaultState().with(StairsBlock.FACING, Direction.SOUTH).with(StairsBlock.WATERLOGGED, false).with(StairsBlock.SHAPE, StairsShape.STRAIGHT).with(StairsBlock.HALF, Half.BOTTOM));
        structure.fillWithBlocks(world, start, 14, 4, 25, 14, 4, 26, Blocks.COBBLESTONE.getDefaultState());
        structure.fillWithBlocks(world, start, 14, 5, -55, 15, 6, -55, Blocks.OAK_LOG.getDefaultState());
        structure.fillWithBlocks(world, start, 14, 5, -51, 15, 6, -51, Blocks.OAK_LOG.getDefaultState());
        structure.fillWithBlocks(world, start, 14, 5, -42, 14, 5, -41, Blocks.OAK_LEAVES.getDefaultState().with(LeavesBlock.PERSISTENT, false).with(LeavesBlock.DISTANCE, 1));
        structure.fillWithBlocks(world, start, 14, 5, -39, 14, 5, -37, Blocks.OAK_LEAVES.getDefaultState().with(LeavesBlock.PERSISTENT, false).with(LeavesBlock.DISTANCE, 1));
        structure.fillWithBlocks(world, start, 14, 5, 24, 14, 5, 25, Blocks.OAK_STAIRS.getDefaultState().with(StairsBlock.FACING, Direction.WEST).with(StairsBlock.WATERLOGGED, false).with(StairsBlock.SHAPE, StairsShape.STRAIGHT).with(StairsBlock.HALF, Half.BOTTOM));
        structure.fillWithBlocks(world, start, 14, 6, -54, 16, 6, -52, Blocks.OAK_PLANKS.getDefaultState());
        structure.fillWithBlocks(world, start, 14, 6, -42, 14, 6, -41, Blocks.OAK_LEAVES.getDefaultState().with(LeavesBlock.PERSISTENT, false).with(LeavesBlock.DISTANCE, 2));
        structure.fillWithBlocks(world, start, 14, 6, -39, 14, 6, -38, Blocks.OAK_LEAVES.getDefaultState().with(LeavesBlock.PERSISTENT, false).with(LeavesBlock.DISTANCE, 2));
        structure.fillWithBlocks(world, start, 14, 6, -36, 14, 6, -36, Blocks.OAK_LEAVES.getDefaultState().with(LeavesBlock.PERSISTENT, false).with(LeavesBlock.DISTANCE, 1));
        structure.fillWithBlocks(world, start, 14, 6, 15, 14, 6, 22, Blocks.COBBLESTONE_SLAB.getDefaultState().with(SlabBlock.TYPE, SlabType.BOTTOM).with(SlabBlock.WATERLOGGED, false));
        structure.fillWithBlocks(world, start, 14, 6, 30, 21, 6, 37, Blocks.COBBLESTONE.getDefaultState());
        structure.fillWithBlocks(world, start, 14, 7, -55, 15, 7, -55, Blocks.OAK_LOG.getDefaultState());
        structure.fillWithBlocks(world, start, 14, 7, -51, 15, 7, -51, Blocks.OAK_LOG.getDefaultState());
        structure.fillWithBlocks(world, start, 14, 7, -43, 14, 7, -43, Blocks.OAK_LEAVES.getDefaultState().with(LeavesBlock.PERSISTENT, false).with(LeavesBlock.DISTANCE, 2));
        structure.fillWithBlocks(world, start, 14, 7, -42, 14, 7, -41, Blocks.OAK_LEAVES.getDefaultState().with(LeavesBlock.PERSISTENT, false).with(LeavesBlock.DISTANCE, 3));
        structure.fillWithBlocks(world, start, 14, 7, -36, 14, 7, -36, Blocks.OAK_LEAVES.getDefaultState().with(LeavesBlock.PERSISTENT, false).with(LeavesBlock.DISTANCE, 2));
        structure.fillWithBlocks(world, start, 14, 7, -35, 14, 7, -35, Blocks.OAK_LEAVES.getDefaultState().with(LeavesBlock.PERSISTENT, false).with(LeavesBlock.DISTANCE, 3));
        structure.fillWithBlocks(world, start, 14, 7, -29, 14, 7, -29, Blocks.OAK_LEAVES.getDefaultState().with(LeavesBlock.PERSISTENT, false).with(LeavesBlock.DISTANCE, 2));
        structure.fillWithBlocks(world, start, 14, 7, 8, 15, 7, 9, Blocks.SPRUCE_PLANKS.getDefaultState());
        structure.fillWithBlocks(world, start, 14, 8, -43, 14, 8, -43, Blocks.OAK_LEAVES.getDefaultState().with(LeavesBlock.PERSISTENT, false).with(LeavesBlock.DISTANCE, 3));
        structure.fillWithBlocks(world, start, 14, 8, -42, 14, 8, -41, Blocks.OAK_LEAVES.getDefaultState().with(LeavesBlock.PERSISTENT, false).with(LeavesBlock.DISTANCE, 4));
        structure.fillWithBlocks(world, start, 14, 8, -37, 14, 8, -37, Blocks.OAK_LEAVES.getDefaultState().with(LeavesBlock.PERSISTENT, false).with(LeavesBlock.DISTANCE, 2));
        structure.fillWithBlocks(world, start, 14, 8, -36, 14, 8, -36, Blocks.OAK_LEAVES.getDefaultState().with(LeavesBlock.PERSISTENT, false).with(LeavesBlock.DISTANCE, 3));
        structure.fillWithBlocks(world, start, 14, 8, -35, 14, 8, -35, Blocks.OAK_LEAVES.getDefaultState().with(LeavesBlock.PERSISTENT, false).with(LeavesBlock.DISTANCE, 4));
        structure.fillWithBlocks(world, start, 14, 8, -25, 14, 8, -25, Blocks.OAK_LEAVES.getDefaultState().with(LeavesBlock.PERSISTENT, false).with(LeavesBlock.DISTANCE, 2));
        structure.fillWithBlocks(world, start, 14, 8, 4, 15, 8, 5, Blocks.GLOWSTONE.getDefaultState());
        structure.fillWithBlocks(world, start, 14, 8, 55, 15, 8, 57, Blocks.OAK_PLANKS.getDefaultState());
        structure.fillWithBlocks(world, start, 14, 9, -43, 14, 9, -43, Blocks.OAK_LEAVES.getDefaultState().with(LeavesBlock.PERSISTENT, false).with(LeavesBlock.DISTANCE, 4));
        structure.fillWithBlocks(world, start, 14, 9, -37, 14, 9, -37, Blocks.OAK_LEAVES.getDefaultState().with(LeavesBlock.PERSISTENT, false).with(LeavesBlock.DISTANCE, 3));
        structure.fillWithBlocks(world, start, 14, 9, -36, 14, 9, -36, Blocks.OAK_LEAVES.getDefaultState().with(LeavesBlock.PERSISTENT, false).with(LeavesBlock.DISTANCE, 4));
        structure.fillWithBlocks(world, start, 14, 9, 4, 15, 9, 6, Blocks.SPRUCE_PLANKS.getDefaultState());
        structure.fillWithBlocks(world, start, 14, 10, -37, 14, 10, -37, Blocks.OAK_LEAVES.getDefaultState().with(LeavesBlock.PERSISTENT, false).with(LeavesBlock.DISTANCE, 4));
        structure.fillWithBlocks(world, start, 14, 12, 31, 14, 12, 35, Blocks.COBBLESTONE_STAIRS.getDefaultState().with(StairsBlock.FACING, Direction.EAST).with(StairsBlock.WATERLOGGED, false).with(StairsBlock.SHAPE, StairsShape.STRAIGHT).with(StairsBlock.HALF, Half.BOTTOM));
        structure.fillWithBlocks(world, start, 14, 12, 54, 15, 12, 58, Blocks.OAK_PLANKS.getDefaultState());
        structure.fillWithBlocks(world, start, 14, 13, 55, 16, 13, 57, Blocks.OAK_PLANKS.getDefaultState());
        structure.fillWithBlocks(world, start, 15, -11, -76, 17, -11, -74, Blocks.DIRT.getDefaultState());
        structure.fillWithBlocks(world, start, 15, -11, 92, 18, -11, 100, Blocks.DIRT.getDefaultState());
        structure.fillWithBlocks(world, start, 15, -10, 100, 25, -10, 100, Blocks.GRASS_BLOCK.getDefaultState().with(SnowyDirtBlock.SNOWY, false));
        structure.fillWithBlocks(world, start, 15, -9, -71, 23, -9, -63, Blocks.STONE.getDefaultState());
        structure.fillWithBlocks(world, start, 15, -9, -62, 15, -9, -55, Blocks.DIRT.getDefaultState());
        structure.fillWithBlocks(world, start, 15, -9, -54, 15, -9, -38, Blocks.STONE.getDefaultState());
        structure.fillWithBlocks(world, start, 15, -9, -37, 15, -5, -27, Blocks.DIRT.getDefaultState());
        structure.fillWithBlocks(world, start, 15, -9, -26, 18, -9, -2, Blocks.STONE.getDefaultState());
        structure.fillWithBlocks(world, start, 15, -9, 50, 20, -9, 50, Blocks.STONE.getDefaultState());
        structure.fillWithBlocks(world, start, 15, -9, 51, 19, -9, 56, Blocks.DIRT.getDefaultState());
        structure.fillWithBlocks(world, start, 15, -9, 57, 16, -9, 59, Blocks.DIRT.getDefaultState());
        structure.fillWithBlocks(world, start, 15, -9, 60, 30, -9, 84, Blocks.STONE.getDefaultState());
        structure.fillWithBlocks(world, start, 15, -8, -71, 15, -6, -20, Blocks.DIRT.getDefaultState());
        structure.fillWithBlocks(world, start, 15, -7, 99, 16, -7, 100, Blocks.CAVE_AIR.getDefaultState());
        structure.fillWithBlocks(world, start, 15, -7, 101, 15, -7, 103, Blocks.CAVE_AIR.getDefaultState());
        structure.fillWithBlocks(world, start, 15, -5, -71, 15, -5, -70, Blocks.GRASS_BLOCK.getDefaultState().with(SnowyDirtBlock.SNOWY, false));
        structure.fillWithBlocks(world, start, 15, -4, -18, 15, -3, -17, Blocks.DIRT.getDefaultState());
        structure.fillWithBlocks(world, start, 15, -4, -16, 20, -4, -11, Blocks.STONE.getDefaultState());
        structure.fillWithBlocks(world, start, 15, -4, -5, 23, -4, 3, Blocks.STONE.getDefaultState());
        structure.fillWithBlocks(world, start, 15, -4, 4, 20, -4, 9, Blocks.STONE.getDefaultState());
        structure.fillWithBlocks(world, start, 15, -4, 10, 16, -4, 54, Blocks.DIRT.getDefaultState());
        structure.fillWithBlocks(world, start, 15, -4, 56, 15, -4, 56, Blocks.GRAVEL.getDefaultState());
        structure.fillWithBlocks(world, start, 15, -4, 57, 15, -4, 75, Blocks.STONE.getDefaultState());
        structure.fillWithBlocks(world, start, 15, -3, 2, 16, -3, 3, Blocks.DIRT.getDefaultState());
        structure.fillWithBlocks(world, start, 15, -3, 4, 18, -3, 7, Blocks.STONE.getDefaultState());
        structure.fillWithBlocks(world, start, 15, -3, 9, 15, -3, 55, Blocks.DIRT.getDefaultState());
        structure.fillWithBlocks(world, start, 15, -3, 56, 16, -3, 57, Blocks.GRAVEL.getDefaultState());
        structure.fillWithBlocks(world, start, 15, -3, 58, 15, -3, 61, Blocks.STONE.getDefaultState());
        structure.fillWithBlocks(world, start, 15, -3, 62, 15, -2, 63, Blocks.DIRT.getDefaultState());
        structure.fillWithBlocks(world, start, 15, -3, 64, 17, -3, 69, Blocks.STONE.getDefaultState());
        structure.fillWithBlocks(world, start, 15, -3, 71, 16, -3, 71, Blocks.STONE.getDefaultState());
        structure.fillWithBlocks(world, start, 15, -3, 72, 15, -2, 73, Blocks.GRAVEL.getDefaultState());
        structure.fillWithBlocks(world, start, 15, -3, 74, 16, -3, 75, Blocks.DIRT.getDefaultState());
        structure.fillWithBlocks(world, start, 15, -3, 76, 15, -2, 77, Blocks.DIRT.getDefaultState());
        structure.fillWithBlocks(world, start, 15, -2, -26, 16, -2, -24, Blocks.STONE.getDefaultState());
        structure.fillWithBlocks(world, start, 15, -2, 9, 15, -2, 40, Blocks.DIRT.getDefaultState());
        structure.fillWithBlocks(world, start, 15, -2, 41, 15, 0, 41, Blocks.GRAVEL.getDefaultState());
        structure.fillWithBlocks(world, start, 15, -2, 42, 15, -1, 42, Blocks.DIRT.getDefaultState());
        structure.fillWithBlocks(world, start, 15, -2, 43, 15, -2, 43, Blocks.GRAVEL.getDefaultState());
        structure.fillWithBlocks(world, start, 15, -2, 44, 15, -1, 44, Blocks.DIRT.getDefaultState());
        structure.fillWithBlocks(world, start, 15, -2, 45, 15, 0, 45, Blocks.GRAVEL.getDefaultState());
        structure.fillWithBlocks(world, start, 15, -2, 46, 15, -2, 52, Blocks.DIRT.getDefaultState());
        structure.fillWithBlocks(world, start, 15, -2, 53, 15, -1, 54, Blocks.GRAVEL.getDefaultState());
        structure.fillWithBlocks(world, start, 15, -2, 55, 15, -2, 55, Blocks.DIRT.getDefaultState());
        structure.fillWithBlocks(world, start, 15, -2, 56, 15, 0, 61, Blocks.GRAVEL.getDefaultState());
        structure.fillWithBlocks(world, start, 15, -2, 64, 17, -2, 66, Blocks.DIRT.getDefaultState());
        structure.fillWithBlocks(world, start, 15, -2, 67, 15, -1, 67, Blocks.STONE.getDefaultState());
        structure.fillWithBlocks(world, start, 15, -2, 68, 15, 0, 73, Blocks.GRAVEL.getDefaultState());
        structure.fillWithBlocks(world, start, 15, -2, 74, 16, -2, 75, Blocks.DIRT.getDefaultState());
        structure.fillWithBlocks(world, start, 15, -1, -11, 17, 1, -11, Blocks.RED_TERRACOTTA.getDefaultState());
        structure.fillWithBlocks(world, start, 15, -1, -5, 17, -1, 1, Blocks.DIRT.getDefaultState());
        structure.fillWithBlocks(world, start, 15, -1, 2, 15, -1, 6, Blocks.RED_TERRACOTTA.getDefaultState());
        structure.fillWithBlocks(world, start, 15, -1, 9, 15, -1, 40, Blocks.DIRT.getDefaultState());
        structure.fillWithBlocks(world, start, 15, -1, 43, 15, -1, 43, Blocks.GRAVEL.getDefaultState());
        structure.fillWithBlocks(world, start, 15, -1, 46, 15, -1, 52, Blocks.DIRT.getDefaultState());
        structure.fillWithBlocks(world, start, 15, -1, 55, 15, -1, 55, Blocks.DIRT.getDefaultState());
        structure.fillWithBlocks(world, start, 15, -1, 62, 19, -1, 66, Blocks.DIRT.getDefaultState());
        structure.fillWithBlocks(world, start, 15, 0, -48, 15, 0, -48, Blocks.FARMLAND.getDefaultState().with(FarmlandBlock.MOISTURE, 7));
        structure.fillWithBlocks(world, start, 15, 0, -47, 15, 0, -47, Blocks.GRASS_BLOCK.getDefaultState().with(SnowyDirtBlock.SNOWY, false));
        structure.fillWithBlocks(world, start, 15, 0, -46, 15, 0, -46, Blocks.FARMLAND.getDefaultState().with(FarmlandBlock.MOISTURE, 7));
        structure.fillWithBlocks(world, start, 15, 0, -45, 15, 0, -45, Blocks.GRASS_BLOCK.getDefaultState().with(SnowyDirtBlock.SNOWY, false));
        structure.fillWithBlocks(world, start, 15, 0, -44, 15, 0, -44, Blocks.FARMLAND.getDefaultState().with(FarmlandBlock.MOISTURE, 7));
        structure.fillWithBlocks(world, start, 15, 0, -42, 15, 0, -42, Blocks.FARMLAND.getDefaultState().with(FarmlandBlock.MOISTURE, 7));
        structure.fillWithBlocks(world, start, 15, 0, -41, 15, 0, -41, Blocks.GRASS_BLOCK.getDefaultState().with(SnowyDirtBlock.SNOWY, false));
        structure.fillWithBlocks(world, start, 15, 0, -40, 15, 0, -40, Blocks.FARMLAND.getDefaultState().with(FarmlandBlock.MOISTURE, 7));
        structure.fillWithBlocks(world, start, 15, 0, -39, 15, 0, -39, Blocks.GRASS_BLOCK.getDefaultState().with(SnowyDirtBlock.SNOWY, false));
        structure.fillWithBlocks(world, start, 15, 0, -38, 15, 0, -38, Blocks.FARMLAND.getDefaultState().with(FarmlandBlock.MOISTURE, 7));
        structure.fillWithBlocks(world, start, 15, 0, -36, 15, 0, -36, Blocks.FARMLAND.getDefaultState().with(FarmlandBlock.MOISTURE, 7));
        structure.fillWithBlocks(world, start, 15, 0, -35, 15, 0, -35, Blocks.GRASS_BLOCK.getDefaultState().with(SnowyDirtBlock.SNOWY, false));
        structure.fillWithBlocks(world, start, 15, 0, -34, 15, 0, -34, Blocks.FARMLAND.getDefaultState().with(FarmlandBlock.MOISTURE, 7));
        structure.fillWithBlocks(world, start, 15, 0, -33, 15, 0, -33, Blocks.GRASS_BLOCK.getDefaultState().with(SnowyDirtBlock.SNOWY, false));
        structure.fillWithBlocks(world, start, 15, 0, -32, 15, 0, -32, Blocks.FARMLAND.getDefaultState().with(FarmlandBlock.MOISTURE, 7));
        structure.fillWithBlocks(world, start, 15, 0, -31, 15, 0, -31, Blocks.GRASS_BLOCK.getDefaultState().with(SnowyDirtBlock.SNOWY, false));
        structure.fillWithBlocks(world, start, 15, 0, -30, 15, 0, -30, Blocks.FARMLAND.getDefaultState().with(FarmlandBlock.MOISTURE, 7));
        structure.fillWithBlocks(world, start, 15, 0, -29, 15, 0, -29, Blocks.GRASS_BLOCK.getDefaultState().with(SnowyDirtBlock.SNOWY, false));
        structure.fillWithBlocks(world, start, 15, 0, -15, 15, 0, -12, Blocks.GRASS_BLOCK.getDefaultState().with(SnowyDirtBlock.SNOWY, false));
        structure.fillWithBlocks(world, start, 15, 0, 24, 15, 0, 25, Blocks.DIRT.getDefaultState());
        structure.fillWithBlocks(world, start, 15, 0, 26, 16, 0, 27, Blocks.GRASS_BLOCK.getDefaultState().with(SnowyDirtBlock.SNOWY, false));
        structure.fillWithBlocks(world, start, 15, 0, 28, 21, 0, 28, Blocks.DIRT.getDefaultState());
        structure.fillWithBlocks(world, start, 15, 0, 29, 20, 0, 37, Blocks.OAK_PLANKS.getDefaultState());
        structure.fillWithBlocks(world, start, 15, 0, 38, 18, 0, 38, Blocks.DIRT.getDefaultState());
        structure.fillWithBlocks(world, start, 15, 0, 39, 22, 0, 39, Blocks.GRASS_BLOCK.getDefaultState().with(SnowyDirtBlock.SNOWY, false));
        structure.fillWithBlocks(world, start, 15, 0, 40, 15, 0, 40, Blocks.STONE_BRICKS.getDefaultState());
        structure.fillWithBlocks(world, start, 15, 0, 43, 15, 0, 43, Blocks.GRAVEL.getDefaultState());
        structure.fillWithBlocks(world, start, 15, 0, 44, 15, 0, 44, Blocks.STONE_BRICKS.getDefaultState());
        structure.fillWithBlocks(world, start, 15, 0, 47, 19, 0, 51, Blocks.GRASS_BLOCK.getDefaultState().with(SnowyDirtBlock.SNOWY, false));
        structure.fillWithBlocks(world, start, 15, 0, 52, 15, 0, 52, Blocks.STONE_BRICKS.getDefaultState());
        structure.fillWithBlocks(world, start, 15, 0, 53, 15, 0, 54, Blocks.GRAVEL.getDefaultState());
        structure.fillWithBlocks(world, start, 15, 0, 62, 15, 0, 67, Blocks.STONE_BRICKS.getDefaultState());
        structure.fillWithBlocks(world, start, 15, 1, -48, 15, 1, -48, Blocks.CARROTS.getDefaultState().with(CropsBlock.AGE, 7));
        structure.fillWithBlocks(world, start, 15, 1, -44, 15, 1, -44, Blocks.CARROTS.getDefaultState().with(CropsBlock.AGE, 7));
        structure.fillWithBlocks(world, start, 15, 1, -43, 15, 6, -43, Blocks.OAK_LOG.getDefaultState());
        structure.fillWithBlocks(world, start, 15, 1, -42, 15, 1, -42, Blocks.CARROTS.getDefaultState().with(CropsBlock.AGE, 7));
        structure.fillWithBlocks(world, start, 15, 1, -40, 15, 1, -40, Blocks.CARROTS.getDefaultState().with(CropsBlock.AGE, 7));
        structure.fillWithBlocks(world, start, 15, 1, -38, 15, 1, -38, Blocks.CARROTS.getDefaultState().with(CropsBlock.AGE, 7));
        structure.fillWithBlocks(world, start, 15, 1, -37, 15, 7, -37, Blocks.OAK_LOG.getDefaultState());
        structure.fillWithBlocks(world, start, 15, 1, -36, 15, 1, -36, Blocks.CARROTS.getDefaultState().with(CropsBlock.AGE, 7));
        structure.fillWithBlocks(world, start, 15, 1, -34, 15, 1, -34, Blocks.CARROTS.getDefaultState().with(CropsBlock.AGE, 7));
        structure.fillWithBlocks(world, start, 15, 1, -32, 15, 1, -32, Blocks.CARROTS.getDefaultState().with(CropsBlock.AGE, 7));
        structure.fillWithBlocks(world, start, 15, 1, -30, 15, 1, -30, Blocks.CARROTS.getDefaultState().with(CropsBlock.AGE, 7));
        structure.fillWithBlocks(world, start, 15, 1, 14, 15, 2, 14, Blocks.SPRUCE_PLANKS.getDefaultState());
        structure.fillWithBlocks(world, start, 15, 1, 16, 15, 1, 18, Blocks.OAK_SLAB.getDefaultState().with(SlabBlock.TYPE, SlabType.TOP).with(SlabBlock.WATERLOGGED, false));
        structure.fillWithBlocks(world, start, 15, 1, 24, 15, 1, 25, Blocks.COBBLESTONE.getDefaultState());
        structure.fillWithBlocks(world, start, 15, 1, 28, 17, 3, 28, Blocks.COBBLESTONE.getDefaultState());
        structure.fillWithBlocks(world, start, 15, 1, 38, 17, 3, 38, Blocks.COBBLESTONE.getDefaultState());
        structure.fillWithBlocks(world, start, 15, 2, -25, 16, 2, -24, Blocks.GRASS_BLOCK.getDefaultState().with(SnowyDirtBlock.SNOWY, false));
        structure.fillWithBlocks(world, start, 15, 2, -17, 15, 3, -17, Blocks.OAK_LEAVES.getDefaultState().with(LeavesBlock.PERSISTENT, false).with(LeavesBlock.DISTANCE, 3));
        structure.fillWithBlocks(world, start, 15, 2, -16, 15, 4, -16, Blocks.OAK_LEAVES.getDefaultState().with(LeavesBlock.PERSISTENT, false).with(LeavesBlock.DISTANCE, 2));
        structure.fillWithBlocks(world, start, 15, 2, -15, 15, 4, -15, Blocks.OAK_LEAVES.getDefaultState().with(LeavesBlock.PERSISTENT, false).with(LeavesBlock.DISTANCE, 1));
        structure.fillWithBlocks(world, start, 15, 2, -14, 15, 3, -14, Blocks.OAK_LEAVES.getDefaultState().with(LeavesBlock.PERSISTENT, false).with(LeavesBlock.DISTANCE, 2));
        structure.fillWithBlocks(world, start, 15, 2, -13, 15, 3, -13, Blocks.OAK_LEAVES.getDefaultState().with(LeavesBlock.PERSISTENT, false).with(LeavesBlock.DISTANCE, 3));
        structure.fillWithBlocks(world, start, 15, 2, -11, 16, 2, -11, Blocks.OAK_PLANKS.getDefaultState());
        structure.fillWithBlocks(world, start, 15, 2, 25, 15, 3, 25, Blocks.COBBLESTONE.getDefaultState());
        structure.fillWithBlocks(world, start, 15, 3, -45, 15, 6, -45, Blocks.OAK_LEAVES.getDefaultState().with(LeavesBlock.PERSISTENT, false).with(LeavesBlock.DISTANCE, 2));
        structure.fillWithBlocks(world, start, 15, 3, -44, 15, 6, -44, Blocks.OAK_LEAVES.getDefaultState().with(LeavesBlock.PERSISTENT, false).with(LeavesBlock.DISTANCE, 1));
        structure.fillWithBlocks(world, start, 15, 3, 4, 15, 3, 5, Index.SHELF_SPRUCE.getDefaultState().with(Shelf.FACING, Direction.WEST));
        structure.fillWithBlocks(world, start, 15, 3, 13, 16, 3, 13, Blocks.OAK_PLANKS.getDefaultState());
        structure.fillWithBlocks(world, start, 15, 3, 24, 15, 3, 25, Blocks.COBBLESTONE.getDefaultState());
        structure.fillWithBlocks(world, start, 15, 4, -46, 15, 5, -46, Blocks.OAK_LEAVES.getDefaultState().with(LeavesBlock.PERSISTENT, false).with(LeavesBlock.DISTANCE, 3));
        structure.fillWithBlocks(world, start, 15, 4, -42, 15, 6, -42, Blocks.OAK_LEAVES.getDefaultState().with(LeavesBlock.PERSISTENT, false).with(LeavesBlock.DISTANCE, 1));
        structure.fillWithBlocks(world, start, 15, 4, -36, 15, 5, -36, Blocks.OAK_LEAVES.getDefaultState().with(LeavesBlock.PERSISTENT, false).with(LeavesBlock.DISTANCE, 1));
        structure.fillWithBlocks(world, start, 15, 4, -35, 15, 5, -35, Blocks.OAK_LEAVES.getDefaultState().with(LeavesBlock.PERSISTENT, false).with(LeavesBlock.DISTANCE, 2));
        structure.fillWithBlocks(world, start, 15, 4, -30, 15, 5, -30, Blocks.OAK_LEAVES.getDefaultState().with(LeavesBlock.PERSISTENT, false).with(LeavesBlock.DISTANCE, 3));
        structure.fillWithBlocks(world, start, 15, 4, -29, 15, 6, -29, Blocks.OAK_LEAVES.getDefaultState().with(LeavesBlock.PERSISTENT, false).with(LeavesBlock.DISTANCE, 2));
        structure.fillWithBlocks(world, start, 15, 4, -28, 15, 6, -28, Blocks.OAK_LEAVES.getDefaultState().with(LeavesBlock.PERSISTENT, false).with(LeavesBlock.DISTANCE, 1));
        structure.fillWithBlocks(world, start, 15, 4, -27, 15, 5, -27, Blocks.OAK_LEAVES.getDefaultState().with(LeavesBlock.PERSISTENT, false).with(LeavesBlock.DISTANCE, 2));
        structure.fillWithBlocks(world, start, 15, 4, -26, 15, 6, -26, Blocks.OAK_LEAVES.getDefaultState().with(LeavesBlock.PERSISTENT, false).with(LeavesBlock.DISTANCE, 3));
        structure.fillWithBlocks(world, start, 15, 4, -10, 17, 4, -8, Blocks.SPRUCE_SLAB.getDefaultState().with(SlabBlock.TYPE, SlabType.BOTTOM).with(SlabBlock.WATERLOGGED, false));
        structure.fillWithBlocks(world, start, 15, 4, 6, 16, 4, 7, Blocks.SPRUCE_PLANKS.getDefaultState());
        structure.fillWithBlocks(world, start, 15, 4, 14, 15, 4, 23, Blocks.SPRUCE_PLANKS.getDefaultState());
        structure.fillWithBlocks(world, start, 15, 4, 28, 17, 6, 28, Blocks.COBBLESTONE.getDefaultState());
        structure.fillWithBlocks(world, start, 15, 4, 38, 17, 6, 38, Blocks.COBBLESTONE.getDefaultState());
        structure.fillWithBlocks(world, start, 15, 5, -41, 15, 5, -41, Blocks.OAK_LEAVES.getDefaultState().with(LeavesBlock.PERSISTENT, false).with(LeavesBlock.DISTANCE, 2));
        structure.fillWithBlocks(world, start, 15, 5, -40, 15, 5, -40, Blocks.OAK_LEAVES.getDefaultState().with(LeavesBlock.PERSISTENT, false).with(LeavesBlock.DISTANCE, 1));
        structure.fillWithBlocks(world, start, 15, 5, -39, 15, 5, -38, Blocks.OAK_LOG.getDefaultState());
        structure.fillWithBlocks(world, start, 15, 5, -25, 15, 6, -25, Blocks.OAK_LEAVES.getDefaultState().with(LeavesBlock.PERSISTENT, false).with(LeavesBlock.DISTANCE, 2));
        structure.fillWithBlocks(world, start, 15, 5, -24, 15, 7, -24, Blocks.OAK_LEAVES.getDefaultState().with(LeavesBlock.PERSISTENT, false).with(LeavesBlock.DISTANCE, 1));
        structure.fillWithBlocks(world, start, 15, 5, -23, 15, 7, -23, Blocks.OAK_LEAVES.getDefaultState().with(LeavesBlock.PERSISTENT, false).with(LeavesBlock.DISTANCE, 2));
        structure.fillWithBlocks(world, start, 15, 5, -22, 15, 6, -22, Blocks.OAK_LEAVES.getDefaultState().with(LeavesBlock.PERSISTENT, false).with(LeavesBlock.DISTANCE, 3));
        structure.fillWithBlocks(world, start, 15, 5, -15, 15, 5, -15, Blocks.OAK_LEAVES.getDefaultState().with(LeavesBlock.PERSISTENT, false).with(LeavesBlock.DISTANCE, 2));
        structure.fillWithBlocks(world, start, 15, 5, 6, 16, 5, 7, Blocks.SPRUCE_PLANKS.getDefaultState());
        structure.fillWithBlocks(world, start, 15, 5, 19, 15, 5, 20, Blocks.OAK_STAIRS.getDefaultState().with(StairsBlock.FACING, Direction.WEST).with(StairsBlock.WATERLOGGED, false).with(StairsBlock.SHAPE, StairsShape.STRAIGHT).with(StairsBlock.HALF, Half.BOTTOM));
        structure.fillWithBlocks(world, start, 15, 5, 22, 16, 5, 22, Blocks.OAK_PLANKS.getDefaultState());
        structure.fillWithBlocks(world, start, 15, 5, 23, 16, 5, 23, Blocks.OAK_STAIRS.getDefaultState().with(StairsBlock.FACING, Direction.NORTH).with(StairsBlock.WATERLOGGED, false).with(StairsBlock.SHAPE, StairsShape.STRAIGHT).with(StairsBlock.HALF, Half.BOTTOM));
        structure.fillWithBlocks(world, start, 15, 6, -41, 15, 6, -40, Blocks.OAK_LEAVES.getDefaultState().with(LeavesBlock.PERSISTENT, false).with(LeavesBlock.DISTANCE, 2));
        structure.fillWithBlocks(world, start, 15, 6, -39, 15, 6, -38, Blocks.OAK_LEAVES.getDefaultState().with(LeavesBlock.PERSISTENT, false).with(LeavesBlock.DISTANCE, 1));
        structure.fillWithBlocks(world, start, 15, 6, 6, 16, 6, 7, Blocks.SPRUCE_PLANKS.getDefaultState());
        structure.fillWithBlocks(world, start, 15, 6, 22, 16, 6, 22, Blocks.COBBLESTONE_SLAB.getDefaultState().with(SlabBlock.TYPE, SlabType.BOTTOM).with(SlabBlock.WATERLOGGED, false));
        structure.fillWithBlocks(world, start, 15, 6, 29, 21, 6, 37, Blocks.COBBLESTONE.getDefaultState());
        structure.fillWithBlocks(world, start, 15, 6, 55, 15, 7, 57, Blocks.OAK_FENCE.getDefaultState().with(FourWayBlock.WATERLOGGED, false).with(FourWayBlock.NORTH, true).with(FourWayBlock.SOUTH, true).with(FourWayBlock.EAST, false).with(FourWayBlock.WEST, true));
        structure.fillWithBlocks(world, start, 15, 7, -45, 15, 7, -45, Blocks.OAK_LEAVES.getDefaultState().with(LeavesBlock.PERSISTENT, false).with(LeavesBlock.DISTANCE, 3));
        structure.fillWithBlocks(world, start, 15, 7, -44, 15, 7, -44, Blocks.OAK_LEAVES.getDefaultState().with(LeavesBlock.PERSISTENT, false).with(LeavesBlock.DISTANCE, 2));
        structure.fillWithBlocks(world, start, 15, 7, -41, 15, 7, -40, Blocks.OAK_LEAVES.getDefaultState().with(LeavesBlock.PERSISTENT, false).with(LeavesBlock.DISTANCE, 3));
        structure.fillWithBlocks(world, start, 15, 7, -39, 15, 7, -39, Blocks.OAK_LEAVES.getDefaultState().with(LeavesBlock.PERSISTENT, false).with(LeavesBlock.DISTANCE, 2));
        structure.fillWithBlocks(world, start, 15, 7, -38, 15, 7, -38, Blocks.OAK_LEAVES.getDefaultState().with(LeavesBlock.PERSISTENT, false).with(LeavesBlock.DISTANCE, 1));
        structure.fillWithBlocks(world, start, 15, 7, 6, 16, 7, 7, Blocks.SPRUCE_PLANKS.getDefaultState());
        structure.fillWithBlocks(world, start, 15, 7, 31, 15, 12, 31, Blocks.OAK_LOG.getDefaultState());
        structure.fillWithBlocks(world, start, 15, 7, 32, 15, 7, 34, Blocks.COBBLESTONE.getDefaultState());
        structure.fillWithBlocks(world, start, 15, 7, 35, 15, 12, 35, Blocks.OAK_LOG.getDefaultState());
        structure.fillWithBlocks(world, start, 15, 8, -45, 16, 8, -45, Blocks.OAK_LEAVES.getDefaultState().with(LeavesBlock.PERSISTENT, false).with(LeavesBlock.DISTANCE, 4));
        structure.fillWithBlocks(world, start, 15, 8, -44, 15, 8, -44, Blocks.OAK_LEAVES.getDefaultState().with(LeavesBlock.PERSISTENT, false).with(LeavesBlock.DISTANCE, 3));
        structure.fillWithBlocks(world, start, 15, 8, -41, 15, 8, -40, Blocks.OAK_LEAVES.getDefaultState().with(LeavesBlock.PERSISTENT, false).with(LeavesBlock.DISTANCE, 4));
        structure.fillWithBlocks(world, start, 15, 8, -39, 15, 8, -39, Blocks.OAK_LEAVES.getDefaultState().with(LeavesBlock.PERSISTENT, false).with(LeavesBlock.DISTANCE, 3));
        structure.fillWithBlocks(world, start, 15, 8, -38, 15, 8, -38, Blocks.OAK_LEAVES.getDefaultState().with(LeavesBlock.PERSISTENT, false).with(LeavesBlock.DISTANCE, 2));
        structure.fillWithBlocks(world, start, 15, 8, 6, 16, 8, 7, Blocks.SPRUCE_PLANKS.getDefaultState());
        structure.fillWithBlocks(world, start, 15, 8, 34, 15, 8, 34, Blocks.COBBLESTONE.getDefaultState());
        structure.fillWithBlocks(world, start, 15, 9, -44, 15, 9, -44, Blocks.OAK_LEAVES.getDefaultState().with(LeavesBlock.PERSISTENT, false).with(LeavesBlock.DISTANCE, 4));
        structure.fillWithBlocks(world, start, 15, 9, -39, 15, 9, -39, Blocks.OAK_LEAVES.getDefaultState().with(LeavesBlock.PERSISTENT, false).with(LeavesBlock.DISTANCE, 4));
        structure.fillWithBlocks(world, start, 15, 9, -38, 15, 9, -38, Blocks.OAK_LEAVES.getDefaultState().with(LeavesBlock.PERSISTENT, false).with(LeavesBlock.DISTANCE, 3));
        structure.fillWithBlocks(world, start, 15, 10, -38, 15, 10, -38, Blocks.OAK_LEAVES.getDefaultState().with(LeavesBlock.PERSISTENT, false).with(LeavesBlock.DISTANCE, 4));
        structure.fillWithBlocks(world, start, 15, 10, 32, 15, 12, 32, Blocks.COBBLESTONE.getDefaultState());
        structure.fillWithBlocks(world, start, 15, 10, 34, 15, 12, 34, Blocks.COBBLESTONE.getDefaultState());
        structure.fillWithBlocks(world, start, 15, 11, 33, 15, 12, 34, Blocks.COBBLESTONE.getDefaultState());
        structure.fillWithBlocks(world, start, 15, 12, 30, 18, 12, 30, Blocks.COBBLESTONE_STAIRS.getDefaultState().with(StairsBlock.FACING, Direction.SOUTH).with(StairsBlock.WATERLOGGED, false).with(StairsBlock.SHAPE, StairsShape.STRAIGHT).with(StairsBlock.HALF, Half.BOTTOM));
        structure.fillWithBlocks(world, start, 15, 12, 36, 18, 12, 36, Blocks.COBBLESTONE_STAIRS.getDefaultState().with(StairsBlock.FACING, Direction.NORTH).with(StairsBlock.WATERLOGGED, false).with(StairsBlock.SHAPE, StairsShape.STRAIGHT).with(StairsBlock.HALF, Half.BOTTOM));
        structure.fillWithBlocks(world, start, 15, 13, 32, 15, 13, 34, Blocks.COBBLESTONE_STAIRS.getDefaultState().with(StairsBlock.FACING, Direction.EAST).with(StairsBlock.WATERLOGGED, false).with(StairsBlock.SHAPE, StairsShape.STRAIGHT).with(StairsBlock.HALF, Half.BOTTOM));
        structure.fillWithBlocks(world, start, 16, -10, -75, 17, -10, -73, Blocks.DIRT.getDefaultState());
        structure.fillWithBlocks(world, start, 16, -10, 102, 16, -9, 103, Blocks.CAVE_AIR.getDefaultState());
        structure.fillWithBlocks(world, start, 16, -9, -62, 16, -9, -62, Blocks.STONE.getDefaultState());
        structure.fillWithBlocks(world, start, 16, -9, -61, 16, -9, -54, Blocks.DIRT.getDefaultState());
        structure.fillWithBlocks(world, start, 16, -9, -53, 16, -9, -34, Blocks.STONE.getDefaultState());
        structure.fillWithBlocks(world, start, 16, -9, -33, 16, -5, -27, Blocks.DIRT.getDefaultState());
        structure.fillWithBlocks(world, start, 16, -9, 48, 18, -9, 50, Blocks.STONE.getDefaultState());
        structure.fillWithBlocks(world, start, 16, -9, 85, 18, -9, 87, Blocks.STONE.getDefaultState());
        structure.fillWithBlocks(world, start, 16, -8, -71, 22, -6, -71, Blocks.DIRT.getDefaultState());
        structure.fillWithBlocks(world, start, 16, -8, -70, 17, -8, -69, Blocks.STONE.getDefaultState());
        structure.fillWithBlocks(world, start, 16, -8, -68, 16, -5, -20, Blocks.DIRT.getDefaultState());
        structure.fillWithBlocks(world, start, 16, -7, 98, 18, -7, 100, Blocks.CAVE_AIR.getDefaultState());
        structure.fillWithBlocks(world, start, 16, -5, -71, 22, -5, -71, Blocks.GRASS_BLOCK.getDefaultState().with(SnowyDirtBlock.SNOWY, false));
        structure.fillWithBlocks(world, start, 16, -5, -70, 38, -5, 87, Blocks.DIRT.getDefaultState());
        structure.fillWithBlocks(world, start, 16, -5, 94, 16, -4, 94, Blocks.CAVE_AIR.getDefaultState());
        structure.fillWithBlocks(world, start, 16, -5, 96, 16, -4, 97, Blocks.CAVE_AIR.getDefaultState());
        structure.fillWithBlocks(world, start, 16, -4, -70, 22, -4, -64, Blocks.GRASS_BLOCK.getDefaultState().with(SnowyDirtBlock.SNOWY, false));
        structure.fillWithBlocks(world, start, 16, -4, -62, 19, -4, -59, Blocks.DIRT.getDefaultState());
        structure.fillWithBlocks(world, start, 16, -4, -53, 18, -4, -50, Blocks.GRAVEL.getDefaultState());
        structure.fillWithBlocks(world, start, 16, -4, -48, 28, -4, -36, Blocks.STONE.getDefaultState());
        structure.fillWithBlocks(world, start, 16, -4, -34, 17, -4, -34, Blocks.STONE.getDefaultState());
        structure.fillWithBlocks(world, start, 16, -4, -33, 17, -4, -32, Blocks.DIRT.getDefaultState());
        structure.fillWithBlocks(world, start, 16, -4, -31, 18, -4, -22, Blocks.STONE.getDefaultState());
        structure.fillWithBlocks(world, start, 16, -4, -19, 17, -4, -18, Blocks.DIRT.getDefaultState());
        structure.fillWithBlocks(world, start, 16, -4, -17, 16, -4, -9, Blocks.STONE.getDefaultState());
        structure.fillWithBlocks(world, start, 16, -4, -8, 16, -2, -8, Blocks.DIRT.getDefaultState());
        structure.fillWithBlocks(world, start, 16, -4, -7, 26, -4, 3, Blocks.STONE.getDefaultState());
        structure.fillWithBlocks(world, start, 16, -4, 55, 18, -4, 57, Blocks.GRAVEL.getDefaultState());
        structure.fillWithBlocks(world, start, 16, -4, 58, 16, -4, 75, Blocks.STONE.getDefaultState());
        structure.fillWithBlocks(world, start, 16, -4, 76, 16, -4, 76, Blocks.DIRT.getDefaultState());
        structure.fillWithBlocks(world, start, 16, -4, 77, 16, -4, 87, Blocks.GRASS_BLOCK.getDefaultState().with(SnowyDirtBlock.SNOWY, false));
        structure.fillWithBlocks(world, start, 16, -3, -62, 17, -3, -61, Blocks.GRASS_BLOCK.getDefaultState().with(SnowyDirtBlock.SNOWY, false));
        structure.fillWithBlocks(world, start, 16, -3, -60, 20, -3, -56, Blocks.DIRT.getDefaultState());
        structure.fillWithBlocks(world, start, 16, -3, -55, 17, -3, -54, Blocks.STONE.getDefaultState());
        structure.fillWithBlocks(world, start, 16, -3, -53, 18, -3, -51, Blocks.GRAVEL.getDefaultState());
        structure.fillWithBlocks(world, start, 16, -3, -48, 16, -3, -28, Blocks.STONE.getDefaultState());
        structure.fillWithBlocks(world, start, 16, -3, -27, 23, -1, -27, Blocks.DIRT.getDefaultState());
        structure.fillWithBlocks(world, start, 16, -3, -26, 17, -3, -24, Blocks.STONE.getDefaultState());
        structure.fillWithBlocks(world, start, 16, -3, 8, 21, -1, 8, Blocks.DIRT.getDefaultState());
        structure.fillWithBlocks(world, start, 16, -3, 9, 16, -3, 9, Blocks.STONE.getDefaultState());
        structure.fillWithBlocks(world, start, 16, -3, 10, 16, -2, 11, Blocks.DIRT.getDefaultState());
        structure.fillWithBlocks(world, start, 16, -3, 12, 20, -3, 12, Blocks.COBBLESTONE.getDefaultState());
        structure.fillWithBlocks(world, start, 16, -3, 54, 16, -2, 55, Blocks.DIRT.getDefaultState());
        structure.fillWithBlocks(world, start, 16, -3, 58, 16, -1, 58, Blocks.DIRT.getDefaultState());
        structure.fillWithBlocks(world, start, 16, -3, 59, 16, -3, 61, Blocks.STONE.getDefaultState());
        structure.fillWithBlocks(world, start, 16, -3, 62, 16, -1, 62, Blocks.DIRT.getDefaultState());
        structure.fillWithBlocks(world, start, 16, -3, 63, 17, -3, 69, Blocks.STONE.getDefaultState());
        structure.fillWithBlocks(world, start, 16, -3, 72, 18, -3, 74, Blocks.DIRT.getDefaultState());
        structure.fillWithBlocks(world, start, 16, -3, 76, 16, -3, 76, Blocks.GRASS_BLOCK.getDefaultState().with(SnowyDirtBlock.SNOWY, false));
        structure.fillWithBlocks(world, start, 16, -2, -60, 17, -2, -59, Blocks.GRASS_BLOCK.getDefaultState().with(SnowyDirtBlock.SNOWY, false));
        structure.fillWithBlocks(world, start, 16, -2, -58, 27, -2, -31, Blocks.DIRT.getDefaultState());
        structure.fillWithBlocks(world, start, 16, -2, -30, 17, -2, -27, Blocks.DIRT.getDefaultState());
        structure.fillWithBlocks(world, start, 16, -2, -23, 17, -2, -18, Blocks.DIRT.getDefaultState());
        structure.fillWithBlocks(world, start, 16, -2, 7, 17, -2, 8, Blocks.DIRT.getDefaultState());
        structure.fillWithBlocks(world, start, 16, -2, 9, 19, 0, 9, Blocks.GRAVEL.getDefaultState());
        structure.fillWithBlocks(world, start, 16, -2, 12, 16, -1, 12, Blocks.COBBLESTONE.getDefaultState());
        structure.fillWithBlocks(world, start, 16, -2, 25, 22, -2, 39, Blocks.DIRT.getDefaultState());
        structure.fillWithBlocks(world, start, 16, -2, 40, 16, -1, 41, Blocks.DIRT.getDefaultState());
        structure.fillWithBlocks(world, start, 16, -2, 42, 17, -2, 43, Blocks.GRAVEL.getDefaultState());
        structure.fillWithBlocks(world, start, 16, -2, 44, 16, 0, 44, Blocks.GRAVEL.getDefaultState());
        structure.fillWithBlocks(world, start, 16, -2, 45, 16, -1, 45, Blocks.DIRT.getDefaultState());
        structure.fillWithBlocks(world, start, 16, -2, 46, 16, 0, 46, Blocks.GRAVEL.getDefaultState());
        structure.fillWithBlocks(world, start, 16, -2, 52, 16, 0, 52, Blocks.GRAVEL.getDefaultState());
        structure.fillWithBlocks(world, start, 16, -2, 53, 16, -2, 58, Blocks.DIRT.getDefaultState());
        structure.fillWithBlocks(world, start, 16, -2, 59, 16, 0, 61, Blocks.GRAVEL.getDefaultState());
        structure.fillWithBlocks(world, start, 16, -2, 63, 22, -2, 70, Blocks.DIRT.getDefaultState());
        structure.fillWithBlocks(world, start, 16, -2, 71, 17, -2, 72, Blocks.DIRT.getDefaultState());
        structure.fillWithBlocks(world, start, 16, -2, 73, 16, -2, 75, Blocks.DIRT.getDefaultState());
        structure.fillWithBlocks(world, start, 16, -1, -30, 17, -1, -26, Blocks.DIRT.getDefaultState());
        structure.fillWithBlocks(world, start, 16, -1, -10, 16, -1, -9, Blocks.DIRT.getDefaultState());
        structure.fillWithBlocks(world, start, 16, -1, -7, 17, -1, 1, Blocks.DIRT.getDefaultState());
        structure.fillWithBlocks(world, start, 16, -1, 2, 17, 0, 2, Blocks.RED_TERRACOTTA.getDefaultState());
        structure.fillWithBlocks(world, start, 16, -1, 3, 21, -1, 8, Blocks.DIRT.getDefaultState());
        structure.fillWithBlocks(world, start, 16, -1, 10, 17, -1, 11, Blocks.DIRT.getDefaultState());
        structure.fillWithBlocks(world, start, 16, -1, 13, 17, -1, 14, Blocks.DIRT.getDefaultState());
        structure.fillWithBlocks(world, start, 16, -1, 15, 16, 0, 19, Blocks.RED_TERRACOTTA.getDefaultState());
        structure.fillWithBlocks(world, start, 16, -1, 20, 16, -1, 41, Blocks.DIRT.getDefaultState());
        structure.fillWithBlocks(world, start, 16, -1, 42, 17, -1, 43, Blocks.GRAVEL.getDefaultState());
        structure.fillWithBlocks(world, start, 16, -1, 53, 16, -1, 58, Blocks.DIRT.getDefaultState());
        structure.fillWithBlocks(world, start, 16, -1, 67, 18, -1, 69, Blocks.DIRT.getDefaultState());
        structure.fillWithBlocks(world, start, 16, -1, 70, 16, -1, 71, Blocks.DIRT.getDefaultState());
        structure.fillWithBlocks(world, start, 16, -1, 72, 16, -1, 75, Blocks.GRASS_BLOCK.getDefaultState().with(SnowyDirtBlock.SNOWY, false));
        structure.fillWithBlocks(world, start, 16, 0, -57, 17, 0, -56, Blocks.GRASS_BLOCK.getDefaultState().with(SnowyDirtBlock.SNOWY, false));
        structure.fillWithBlocks(world, start, 16, 0, -26, 16, 0, -23, Blocks.DIRT.getDefaultState());
        structure.fillWithBlocks(world, start, 16, 0, -14, 18, 0, -12, Blocks.GRASS_BLOCK.getDefaultState().with(SnowyDirtBlock.SNOWY, false));
        structure.fillWithBlocks(world, start, 16, 0, 3, 16, 0, 7, Blocks.DIRT.getDefaultState());
        structure.fillWithBlocks(world, start, 16, 0, 8, 21, 0, 8, Blocks.STONE_BRICKS.getDefaultState());
        structure.fillWithBlocks(world, start, 16, 0, 10, 16, 1, 10, Blocks.OAK_LOG.getDefaultState());
        structure.fillWithBlocks(world, start, 16, 0, 11, 16, 0, 13, Blocks.OAK_LOG.getDefaultState());
        structure.fillWithBlocks(world, start, 16, 0, 21, 17, 0, 23, Blocks.SPRUCE_PLANKS.getDefaultState());
        structure.fillWithBlocks(world, start, 16, 0, 24, 16, 2, 24, Blocks.OAK_LOG.getDefaultState());
        structure.fillWithBlocks(world, start, 16, 0, 25, 18, 0, 27, Blocks.GRASS_BLOCK.getDefaultState().with(SnowyDirtBlock.SNOWY, false));
        structure.fillWithBlocks(world, start, 16, 0, 40, 16, 0, 41, Blocks.STONE_BRICKS.getDefaultState());
        structure.fillWithBlocks(world, start, 16, 0, 42, 17, 0, 43, Blocks.GRAVEL.getDefaultState());
        structure.fillWithBlocks(world, start, 16, 0, 45, 16, 0, 45, Blocks.STONE_BRICKS.getDefaultState());
        structure.fillWithBlocks(world, start, 16, 0, 53, 16, 0, 53, Blocks.STONE_BRICKS.getDefaultState());
        structure.fillWithBlocks(world, start, 16, 0, 54, 16, 0, 57, Blocks.DIRT.getDefaultState());
        structure.fillWithBlocks(world, start, 16, 0, 58, 16, 12, 58, Blocks.OAK_LOG.getDefaultState());
        structure.fillWithBlocks(world, start, 16, 0, 63, 17, 0, 69, Blocks.GRASS_BLOCK.getDefaultState().with(SnowyDirtBlock.SNOWY, false));
        structure.fillWithBlocks(world, start, 16, 0, 70, 16, 0, 71, Blocks.GRASS_BLOCK.getDefaultState().with(SnowyDirtBlock.SNOWY, false));
        structure.fillWithBlocks(world, start, 16, 1, -55, 18, 1, -55, Blocks.STONE_BRICK_STAIRS.getDefaultState().with(StairsBlock.FACING, Direction.SOUTH).with(StairsBlock.WATERLOGGED, false).with(StairsBlock.SHAPE, StairsShape.STRAIGHT).with(StairsBlock.HALF, Half.BOTTOM));
        structure.fillWithBlocks(world, start, 16, 1, -54, 18, 3, -54, Blocks.STONE_BRICKS.getDefaultState());
        structure.fillWithBlocks(world, start, 16, 1, -52, 18, 3, -52, Blocks.STONE_BRICKS.getDefaultState());
        structure.fillWithBlocks(world, start, 16, 1, -51, 18, 1, -51, Blocks.STONE_BRICK_STAIRS.getDefaultState().with(StairsBlock.FACING, Direction.NORTH).with(StairsBlock.WATERLOGGED, false).with(StairsBlock.SHAPE, StairsShape.STRAIGHT).with(StairsBlock.HALF, Half.BOTTOM));
        structure.fillWithBlocks(world, start, 16, 1, -25, 16, 1, -24, Blocks.DIRT.getDefaultState());
        structure.fillWithBlocks(world, start, 16, 1, -15, 16, 4, -15, Blocks.OAK_LOG.getDefaultState());
        structure.fillWithBlocks(world, start, 16, 1, -4, 17, 1, -4, Blocks.OAK_STAIRS.getDefaultState().with(StairsBlock.FACING, Direction.SOUTH).with(StairsBlock.WATERLOGGED, false).with(StairsBlock.SHAPE, StairsShape.STRAIGHT).with(StairsBlock.HALF, Half.BOTTOM));
        structure.fillWithBlocks(world, start, 16, 1, -3, 17, 1, 1, Blocks.OAK_PLANKS.getDefaultState());
        structure.fillWithBlocks(world, start, 16, 1, 2, 16, 1, 7, Blocks.RED_TERRACOTTA.getDefaultState());
        structure.fillWithBlocks(world, start, 16, 1, 11, 16, 1, 12, Blocks.OAK_FENCE.getDefaultState().with(FourWayBlock.WATERLOGGED, false).with(FourWayBlock.NORTH, true).with(FourWayBlock.SOUTH, true).with(FourWayBlock.EAST, false).with(FourWayBlock.WEST, false));
        structure.fillWithBlocks(world, start, 16, 1, 13, 16, 2, 13, Blocks.OAK_FENCE.getDefaultState().with(FourWayBlock.WATERLOGGED, false).with(FourWayBlock.NORTH, true).with(FourWayBlock.SOUTH, false).with(FourWayBlock.EAST, false).with(FourWayBlock.WEST, false));
        structure.fillWithBlocks(world, start, 16, 1, 20, 16, 3, 20, Blocks.OAK_LOG.getDefaultState());
        structure.fillWithBlocks(world, start, 16, 1, 25, 16, 2, 25, Blocks.OAK_FENCE.getDefaultState().with(FourWayBlock.WATERLOGGED, false).with(FourWayBlock.NORTH, true).with(FourWayBlock.SOUTH, false).with(FourWayBlock.EAST, false).with(FourWayBlock.WEST, true));
        structure.fillWithBlocks(world, start, 16, 1, 54, 16, 12, 54, Blocks.OAK_LOG.getDefaultState());
        structure.fillWithBlocks(world, start, 16, 1, 55, 16, 1, 57, Blocks.STONE_BRICK_STAIRS.getDefaultState().with(StairsBlock.FACING, Direction.EAST).with(StairsBlock.WATERLOGGED, false).with(StairsBlock.SHAPE, StairsShape.STRAIGHT).with(StairsBlock.HALF, Half.BOTTOM));
        structure.fillWithBlocks(world, start, 16, 2, -17, 16, 3, -17, Blocks.OAK_LEAVES.getDefaultState().with(LeavesBlock.PERSISTENT, false).with(LeavesBlock.DISTANCE, 2));
        structure.fillWithBlocks(world, start, 16, 2, -16, 16, 4, -16, Blocks.OAK_LEAVES.getDefaultState().with(LeavesBlock.PERSISTENT, false).with(LeavesBlock.DISTANCE, 1));
        structure.fillWithBlocks(world, start, 16, 2, -14, 16, 4, -14, Blocks.OAK_LEAVES.getDefaultState().with(LeavesBlock.PERSISTENT, false).with(LeavesBlock.DISTANCE, 1));
        structure.fillWithBlocks(world, start, 16, 2, -13, 16, 3, -13, Blocks.OAK_LEAVES.getDefaultState().with(LeavesBlock.PERSISTENT, false).with(LeavesBlock.DISTANCE, 2));
        structure.fillWithBlocks(world, start, 16, 2, -3, 17, 2, -3, Blocks.OAK_STAIRS.getDefaultState().with(StairsBlock.FACING, Direction.SOUTH).with(StairsBlock.WATERLOGGED, false).with(StairsBlock.SHAPE, StairsShape.STRAIGHT).with(StairsBlock.HALF, Half.BOTTOM));
        structure.fillWithBlocks(world, start, 16, 2, -2, 18, 2, 1, Blocks.OAK_PLANKS.getDefaultState());
        structure.fillWithBlocks(world, start, 16, 2, 2, 17, 2, 2, Blocks.SPRUCE_PLANKS.getDefaultState());
        structure.fillWithBlocks(world, start, 16, 2, 3, 16, 3, 4, Blocks.OAK_PLANKS.getDefaultState());
        structure.fillWithBlocks(world, start, 16, 2, 5, 16, 2, 7, Blocks.OAK_PLANKS.getDefaultState());
        structure.fillWithBlocks(world, start, 16, 3, -44, 16, 6, -44, Blocks.OAK_LEAVES.getDefaultState().with(LeavesBlock.PERSISTENT, false).with(LeavesBlock.DISTANCE, 2));
        structure.fillWithBlocks(world, start, 16, 3, -11, 17, 3, -11, Blocks.OAK_PLANKS.getDefaultState());
        structure.fillWithBlocks(world, start, 16, 3, -2, 17, 3, -2, Blocks.OAK_STAIRS.getDefaultState().with(StairsBlock.FACING, Direction.SOUTH).with(StairsBlock.WATERLOGGED, false).with(StairsBlock.SHAPE, StairsShape.STRAIGHT).with(StairsBlock.HALF, Half.BOTTOM));
        structure.fillWithBlocks(world, start, 16, 3, -1, 17, 3, 2, Blocks.OAK_PLANKS.getDefaultState());
        structure.fillWithBlocks(world, start, 16, 3, 5, 16, 8, 5, Blocks.SPRUCE_PLANKS.getDefaultState());
        structure.fillWithBlocks(world, start, 16, 3, 6, 16, 3, 7, Blocks.OAK_PLANKS.getDefaultState());
        structure.fillWithBlocks(world, start, 16, 3, 21, 16, 3, 23, Blocks.OAK_LOG.getDefaultState());
        structure.fillWithBlocks(world, start, 16, 4, -54, 18, 5, -54, Blocks.STONE_BRICKS.getDefaultState());
        structure.fillWithBlocks(world, start, 16, 4, -52, 18, 5, -52, Blocks.STONE_BRICKS.getDefaultState());
        structure.fillWithBlocks(world, start, 16, 4, -46, 16, 5, -46, Blocks.OAK_LEAVES.getDefaultState().with(LeavesBlock.PERSISTENT, false).with(LeavesBlock.DISTANCE, 4));
        structure.fillWithBlocks(world, start, 16, 4, -45, 17, 4, -45, Blocks.OAK_LEAVES.getDefaultState().with(LeavesBlock.PERSISTENT, false).with(LeavesBlock.DISTANCE, 3));
        structure.fillWithBlocks(world, start, 16, 4, -43, 17, 4, -43, Blocks.OAK_LEAVES.getDefaultState().with(LeavesBlock.PERSISTENT, false).with(LeavesBlock.DISTANCE, 1));
        structure.fillWithBlocks(world, start, 16, 4, -42, 17, 4, -42, Blocks.OAK_LOG.getDefaultState());
        structure.fillWithBlocks(world, start, 16, 4, -37, 17, 4, -37, Blocks.OAK_LOG.getDefaultState());
        structure.fillWithBlocks(world, start, 16, 4, -29, 16, 5, -29, Blocks.OAK_LEAVES.getDefaultState().with(LeavesBlock.PERSISTENT, false).with(LeavesBlock.DISTANCE, 3));
        structure.fillWithBlocks(world, start, 16, 4, -28, 16, 5, -28, Blocks.OAK_LEAVES.getDefaultState().with(LeavesBlock.PERSISTENT, false).with(LeavesBlock.DISTANCE, 2));
        structure.fillWithBlocks(world, start, 16, 4, -27, 16, 5, -27, Blocks.OAK_LEAVES.getDefaultState().with(LeavesBlock.PERSISTENT, false).with(LeavesBlock.DISTANCE, 3));
        structure.fillWithBlocks(world, start, 16, 4, -7, 19, 4, -7, Blocks.SPRUCE_STAIRS.getDefaultState().with(StairsBlock.FACING, Direction.SOUTH).with(StairsBlock.WATERLOGGED, false).with(StairsBlock.SHAPE, StairsShape.STRAIGHT).with(StairsBlock.HALF, Half.BOTTOM));
        structure.fillWithBlocks(world, start, 16, 4, -6, 17, 4, -6, Blocks.SPRUCE_STAIRS.getDefaultState().with(StairsBlock.FACING, Direction.NORTH).with(StairsBlock.WATERLOGGED, false).with(StairsBlock.SHAPE, StairsShape.STRAIGHT).with(StairsBlock.HALF, Half.TOP));
        structure.fillWithBlocks(world, start, 16, 4, -1, 17, 4, -1, Blocks.OAK_STAIRS.getDefaultState().with(StairsBlock.FACING, Direction.SOUTH).with(StairsBlock.WATERLOGGED, false).with(StairsBlock.SHAPE, StairsShape.STRAIGHT).with(StairsBlock.HALF, Half.BOTTOM));
        structure.fillWithBlocks(world, start, 16, 4, 0, 17, 4, 1, Blocks.SPRUCE_PLANKS.getDefaultState());
        structure.fillWithBlocks(world, start, 16, 4, 3, 16, 8, 7, Blocks.SPRUCE_PLANKS.getDefaultState());
        structure.fillWithBlocks(world, start, 16, 4, 21, 16, 4, 23, Blocks.SPRUCE_PLANKS.getDefaultState());
        structure.fillWithBlocks(world, start, 16, 4, 55, 16, 4, 57, Blocks.WALL_TORCH.getDefaultState().with(WallTorchBlock.HORIZONTAL_FACING, Direction.WEST));
        structure.fillWithBlocks(world, start, 16, 5, -55, 18, 5, -55, Blocks.STONE_BRICK_STAIRS.getDefaultState().with(StairsBlock.FACING, Direction.SOUTH).with(StairsBlock.WATERLOGGED, false).with(StairsBlock.SHAPE, StairsShape.STRAIGHT).with(StairsBlock.HALF, Half.TOP));
        structure.fillWithBlocks(world, start, 16, 5, -51, 18, 5, -51, Blocks.STONE_BRICK_STAIRS.getDefaultState().with(StairsBlock.FACING, Direction.NORTH).with(StairsBlock.WATERLOGGED, false).with(StairsBlock.SHAPE, StairsShape.STRAIGHT).with(StairsBlock.HALF, Half.TOP));
        structure.fillWithBlocks(world, start, 16, 5, -45, 16, 5, -45, Blocks.OAK_LEAVES.getDefaultState().with(LeavesBlock.PERSISTENT, false).with(LeavesBlock.DISTANCE, 3));
        structure.fillWithBlocks(world, start, 16, 5, -43, 16, 5, -42, Blocks.OAK_LEAVES.getDefaultState().with(LeavesBlock.PERSISTENT, false).with(LeavesBlock.DISTANCE, 1));
        structure.fillWithBlocks(world, start, 16, 5, -41, 16, 5, -40, Blocks.OAK_LEAVES.getDefaultState().with(LeavesBlock.PERSISTENT, false).with(LeavesBlock.DISTANCE, 2));
        structure.fillWithBlocks(world, start, 16, 5, -39, 16, 5, -37, Blocks.OAK_LEAVES.getDefaultState().with(LeavesBlock.PERSISTENT, false).with(LeavesBlock.DISTANCE, 1));
        structure.fillWithBlocks(world, start, 16, 5, -36, 16, 5, -36, Blocks.OAK_LEAVES.getDefaultState().with(LeavesBlock.PERSISTENT, false).with(LeavesBlock.DISTANCE, 2));
        structure.fillWithBlocks(world, start, 16, 5, -35, 16, 5, -35, Blocks.OAK_LEAVES.getDefaultState().with(LeavesBlock.PERSISTENT, false).with(LeavesBlock.DISTANCE, 3));
        structure.fillWithBlocks(world, start, 16, 5, -26, 16, 6, -26, Blocks.OAK_LEAVES.getDefaultState().with(LeavesBlock.PERSISTENT, false).with(LeavesBlock.DISTANCE, 4));
        structure.fillWithBlocks(world, start, 16, 5, -25, 16, 6, -25, Blocks.OAK_LEAVES.getDefaultState().with(LeavesBlock.PERSISTENT, false).with(LeavesBlock.DISTANCE, 3));
        structure.fillWithBlocks(world, start, 16, 5, -24, 16, 6, -24, Blocks.OAK_LEAVES.getDefaultState().with(LeavesBlock.PERSISTENT, false).with(LeavesBlock.DISTANCE, 2));
        structure.fillWithBlocks(world, start, 16, 5, -23, 16, 6, -23, Blocks.OAK_LEAVES.getDefaultState().with(LeavesBlock.PERSISTENT, false).with(LeavesBlock.DISTANCE, 3));
        structure.fillWithBlocks(world, start, 16, 5, -22, 16, 6, -22, Blocks.OAK_LEAVES.getDefaultState().with(LeavesBlock.PERSISTENT, false).with(LeavesBlock.DISTANCE, 4));
        structure.fillWithBlocks(world, start, 16, 5, -16, 16, 5, -16, Blocks.OAK_LEAVES.getDefaultState().with(LeavesBlock.PERSISTENT, false).with(LeavesBlock.DISTANCE, 2));
        structure.fillWithBlocks(world, start, 16, 5, -5, 17, 5, -5, Blocks.SPRUCE_STAIRS.getDefaultState().with(StairsBlock.FACING, Direction.NORTH).with(StairsBlock.WATERLOGGED, false).with(StairsBlock.SHAPE, StairsShape.STRAIGHT).with(StairsBlock.HALF, Half.TOP));
        structure.fillWithBlocks(world, start, 16, 6, -42, 17, 6, -42, Blocks.OAK_LEAVES.getDefaultState().with(LeavesBlock.PERSISTENT, false).with(LeavesBlock.DISTANCE, 2));
        structure.fillWithBlocks(world, start, 16, 6, -41, 16, 6, -40, Blocks.OAK_LEAVES.getDefaultState().with(LeavesBlock.PERSISTENT, false).with(LeavesBlock.DISTANCE, 3));
        structure.fillWithBlocks(world, start, 16, 6, -39, 16, 6, -38, Blocks.OAK_LEAVES.getDefaultState().with(LeavesBlock.PERSISTENT, false).with(LeavesBlock.DISTANCE, 2));
        structure.fillWithBlocks(world, start, 16, 6, -37, 16, 6, -36, Blocks.OAK_LEAVES.getDefaultState().with(LeavesBlock.PERSISTENT, false).with(LeavesBlock.DISTANCE, 1));
        structure.fillWithBlocks(world, start, 16, 6, -35, 17, 6, -35, Blocks.OAK_LEAVES.getDefaultState().with(LeavesBlock.PERSISTENT, false).with(LeavesBlock.DISTANCE, 2));
        structure.fillWithBlocks(world, start, 16, 6, -4, 17, 6, -4, Blocks.SPRUCE_STAIRS.getDefaultState().with(StairsBlock.FACING, Direction.NORTH).with(StairsBlock.WATERLOGGED, false).with(StairsBlock.SHAPE, StairsShape.STRAIGHT).with(StairsBlock.HALF, Half.TOP));
        structure.fillWithBlocks(world, start, 16, 7, -45, 16, 8, -45, Blocks.OAK_LEAVES.getDefaultState().with(LeavesBlock.PERSISTENT, false).with(LeavesBlock.DISTANCE, 4));
        structure.fillWithBlocks(world, start, 16, 7, -44, 16, 7, -44, Blocks.OAK_LEAVES.getDefaultState().with(LeavesBlock.PERSISTENT, false).with(LeavesBlock.DISTANCE, 3));
        structure.fillWithBlocks(world, start, 16, 7, -42, 16, 7, -41, Blocks.OAK_LEAVES.getDefaultState().with(LeavesBlock.PERSISTENT, false).with(LeavesBlock.DISTANCE, 3));
        structure.fillWithBlocks(world, start, 16, 7, -40, 16, 7, -40, Blocks.OAK_LEAVES.getDefaultState().with(LeavesBlock.PERSISTENT, false).with(LeavesBlock.DISTANCE, 4));
        structure.fillWithBlocks(world, start, 16, 7, -39, 16, 7, -39, Blocks.OAK_LEAVES.getDefaultState().with(LeavesBlock.PERSISTENT, false).with(LeavesBlock.DISTANCE, 3));
        structure.fillWithBlocks(world, start, 16, 7, -38, 16, 7, -38, Blocks.OAK_LEAVES.getDefaultState().with(LeavesBlock.PERSISTENT, false).with(LeavesBlock.DISTANCE, 2));
        structure.fillWithBlocks(world, start, 16, 7, -35, 17, 7, -35, Blocks.OAK_LEAVES.getDefaultState().with(LeavesBlock.PERSISTENT, false).with(LeavesBlock.DISTANCE, 3));
        structure.fillWithBlocks(world, start, 16, 7, 28, 20, 7, 28, Blocks.OAK_FENCE.getDefaultState().with(FourWayBlock.WATERLOGGED, false).with(FourWayBlock.NORTH, false).with(FourWayBlock.SOUTH, false).with(FourWayBlock.EAST, true).with(FourWayBlock.WEST, true));
        structure.fillWithBlocks(world, start, 16, 7, 31, 17, 8, 31, Blocks.COBBLESTONE.getDefaultState());
        structure.fillWithBlocks(world, start, 16, 7, 35, 17, 8, 35, Blocks.COBBLESTONE.getDefaultState());
        structure.fillWithBlocks(world, start, 16, 7, 38, 20, 7, 38, Blocks.OAK_FENCE.getDefaultState().with(FourWayBlock.WATERLOGGED, false).with(FourWayBlock.NORTH, false).with(FourWayBlock.SOUTH, false).with(FourWayBlock.EAST, true).with(FourWayBlock.WEST, true));
        structure.fillWithBlocks(world, start, 16, 7, 55, 16, 7, 57, Blocks.STONE_BRICK_STAIRS.getDefaultState().with(StairsBlock.FACING, Direction.EAST).with(StairsBlock.WATERLOGGED, false).with(StairsBlock.SHAPE, StairsShape.STRAIGHT).with(StairsBlock.HALF, Half.TOP));
        structure.fillWithBlocks(world, start, 16, 8, -44, 16, 8, -43, Blocks.OAK_LEAVES.getDefaultState().with(LeavesBlock.PERSISTENT, false).with(LeavesBlock.DISTANCE, 3));
        structure.fillWithBlocks(world, start, 16, 8, -42, 16, 8, -41, Blocks.OAK_LEAVES.getDefaultState().with(LeavesBlock.PERSISTENT, false).with(LeavesBlock.DISTANCE, 4));
        structure.fillWithBlocks(world, start, 16, 8, -39, 16, 8, -39, Blocks.OAK_LEAVES.getDefaultState().with(LeavesBlock.PERSISTENT, false).with(LeavesBlock.DISTANCE, 4));
        structure.fillWithBlocks(world, start, 16, 8, -38, 16, 8, -38, Blocks.OAK_LEAVES.getDefaultState().with(LeavesBlock.PERSISTENT, false).with(LeavesBlock.DISTANCE, 3));
        structure.fillWithBlocks(world, start, 16, 8, -35, 17, 8, -35, Blocks.OAK_LEAVES.getDefaultState().with(LeavesBlock.PERSISTENT, false).with(LeavesBlock.DISTANCE, 4));
        structure.fillWithBlocks(world, start, 16, 8, -2, 17, 8, -2, Blocks.SPRUCE_SLAB.getDefaultState().with(SlabBlock.TYPE, SlabType.TOP).with(SlabBlock.WATERLOGGED, false));
        structure.fillWithBlocks(world, start, 16, 8, 55, 16, 8, 57, Blocks.OAK_SLAB.getDefaultState().with(SlabBlock.TYPE, SlabType.DOUBLE).with(SlabBlock.WATERLOGGED, false));
        structure.fillWithBlocks(world, start, 16, 9, -43, 17, 9, -43, Blocks.OAK_LEAVES.getDefaultState().with(LeavesBlock.PERSISTENT, false).with(LeavesBlock.DISTANCE, 4));
        structure.fillWithBlocks(world, start, 16, 9, -38, 16, 9, -38, Blocks.OAK_LEAVES.getDefaultState().with(LeavesBlock.PERSISTENT, false).with(LeavesBlock.DISTANCE, 4));
        structure.fillWithBlocks(world, start, 16, 9, 4, 16, 9, 6, Blocks.SPRUCE_STAIRS.getDefaultState().with(StairsBlock.FACING, Direction.WEST).with(StairsBlock.WATERLOGGED, false).with(StairsBlock.SHAPE, StairsShape.STRAIGHT).with(StairsBlock.HALF, Half.BOTTOM));
        structure.fillWithBlocks(world, start, 16, 9, 31, 17, 10, 31, Blocks.COBBLESTONE.getDefaultState());
        structure.fillWithBlocks(world, start, 16, 9, 35, 17, 10, 35, Blocks.COBBLESTONE.getDefaultState());
        structure.fillWithBlocks(world, start, 16, 11, 31, 17, 12, 31, Blocks.COBBLESTONE.getDefaultState());
        structure.fillWithBlocks(world, start, 16, 11, 35, 17, 12, 35, Blocks.COBBLESTONE.getDefaultState());
        structure.fillWithBlocks(world, start, 16, 12, 55, 16, 13, 57, Blocks.OAK_PLANKS.getDefaultState());
        structure.fillWithBlocks(world, start, 16, 13, 31, 17, 13, 31, Blocks.COBBLESTONE_STAIRS.getDefaultState().with(StairsBlock.FACING, Direction.SOUTH).with(StairsBlock.WATERLOGGED, false).with(StairsBlock.SHAPE, StairsShape.STRAIGHT).with(StairsBlock.HALF, Half.BOTTOM));
        structure.fillWithBlocks(world, start, 16, 13, 32, 16, 13, 34, Blocks.COBBLESTONE_SLAB.getDefaultState().with(SlabBlock.TYPE, SlabType.DOUBLE).with(SlabBlock.WATERLOGGED, false));
        structure.fillWithBlocks(world, start, 16, 13, 35, 17, 13, 35, Blocks.COBBLESTONE_STAIRS.getDefaultState().with(StairsBlock.FACING, Direction.NORTH).with(StairsBlock.WATERLOGGED, false).with(StairsBlock.SHAPE, StairsShape.STRAIGHT).with(StairsBlock.HALF, Half.BOTTOM));
        structure.fillWithBlocks(world, start, 16, 14, 32, 17, 14, 34, Blocks.COBBLESTONE_SLAB.getDefaultState().with(SlabBlock.TYPE, SlabType.BOTTOM).with(SlabBlock.WATERLOGGED, false));
        structure.fillWithBlocks(world, start, 17, -11, 102, 17, -11, 103, Blocks.CAVE_AIR.getDefaultState());
        structure.fillWithBlocks(world, start, 17, -10, 89, 38, -10, 89, Blocks.STONE.getDefaultState());
        structure.fillWithBlocks(world, start, 17, -10, 90, 18, -10, 98, Blocks.DIRT.getDefaultState());
        structure.fillWithBlocks(world, start, 17, -9, -62, 18, -9, -61, Blocks.STONE.getDefaultState());
        structure.fillWithBlocks(world, start, 17, -9, -60, 18, -9, -53, Blocks.DIRT.getDefaultState());
        structure.fillWithBlocks(world, start, 17, -9, -52, 37, -9, -32, Blocks.STONE.getDefaultState());
        structure.fillWithBlocks(world, start, 17, -9, -31, 17, -5, -27, Blocks.DIRT.getDefaultState());
        structure.fillWithBlocks(world, start, 17, -9, 3, 22, -9, 48, Blocks.STONE.getDefaultState());
        structure.fillWithBlocks(world, start, 17, -9, 57, 17, -8, 58, Blocks.DIRT.getDefaultState());
        structure.fillWithBlocks(world, start, 17, -9, 59, 30, -9, 84, Blocks.STONE.getDefaultState());
        structure.fillWithBlocks(world, start, 17, -9, 88, 27, -9, 88, Blocks.STONE.getDefaultState());
        structure.fillWithBlocks(world, start, 17, -9, 89, 20, -9, 97, Blocks.DIRT.getDefaultState());
        structure.fillWithBlocks(world, start, 17, -8, -68, 18, -8, -67, Blocks.STONE.getDefaultState());
        structure.fillWithBlocks(world, start, 17, -8, -66, 17, -8, -19, Blocks.DIRT.getDefaultState());
        structure.fillWithBlocks(world, start, 17, -8, 70, 18, -8, 74, Blocks.DIRT.getDefaultState());
        structure.fillWithBlocks(world, start, 17, -8, 75, 17, -5, 88, Blocks.DIRT.getDefaultState());
        structure.fillWithBlocks(world, start, 17, -8, 99, 18, -8, 100, Blocks.CAVE_AIR.getDefaultState());
        structure.fillWithBlocks(world, start, 17, -6, 96, 17, -6, 98, Blocks.CAVE_AIR.getDefaultState());
        structure.fillWithBlocks(world, start, 17, -5, 89, 19, -5, 91, Blocks.GRASS_BLOCK.getDefaultState().with(SnowyDirtBlock.SNOWY, false));
        structure.fillWithBlocks(world, start, 17, -5, 95, 17, -5, 96, Blocks.CAVE_AIR.getDefaultState());
        structure.fillWithBlocks(world, start, 17, -4, -58, 19, -4, -54, Blocks.STONE.getDefaultState());
        structure.fillWithBlocks(world, start, 17, -4, -17, 17, -1, -17, Blocks.DIRT.getDefaultState());
        structure.fillWithBlocks(world, start, 17, -4, -10, 17, -4, -10, Blocks.STONE.getDefaultState());
        structure.fillWithBlocks(world, start, 17, -4, -9, 17, -2, -9, Blocks.DIRT.getDefaultState());
        structure.fillWithBlocks(world, start, 17, -4, -8, 28, -4, 3, Blocks.STONE.getDefaultState());
        structure.fillWithBlocks(world, start, 17, -4, 10, 17, -4, 11, Blocks.DIRT.getDefaultState());
        structure.fillWithBlocks(world, start, 17, -4, 12, 36, -4, 12, Blocks.STONE.getDefaultState());
        structure.fillWithBlocks(world, start, 17, -4, 54, 17, -1, 54, Blocks.DIRT.getDefaultState());
        structure.fillWithBlocks(world, start, 17, -4, 58, 17, -4, 58, Blocks.GRAVEL.getDefaultState());
        structure.fillWithBlocks(world, start, 17, -4, 60, 22, -4, 65, Blocks.STONE.getDefaultState());
        structure.fillWithBlocks(world, start, 17, -4, 66, 18, -4, 67, Blocks.COAL_ORE.getDefaultState());
        structure.fillWithBlocks(world, start, 17, -4, 68, 17, -4, 72, Blocks.STONE.getDefaultState());
        structure.fillWithBlocks(world, start, 17, -4, 73, 20, -4, 76, Blocks.DIRT.getDefaultState());
        structure.fillWithBlocks(world, start, 17, -4, 77, 18, -4, 77, Blocks.DIRT.getDefaultState());
        structure.fillWithBlocks(world, start, 17, -4, 78, 27, -4, 88, Blocks.GRASS_BLOCK.getDefaultState().with(SnowyDirtBlock.SNOWY, false));
        structure.fillWithBlocks(world, start, 17, -3, -50, 17, -3, -27, Blocks.DIRT.getDefaultState());
        structure.fillWithBlocks(world, start, 17, -3, -23, 24, -3, -4, Blocks.DIRT.getDefaultState());
        structure.fillWithBlocks(world, start, 17, -3, 2, 18, -3, 3, Blocks.DIRT.getDefaultState());
        structure.fillWithBlocks(world, start, 17, -3, 9, 19, -3, 11, Blocks.STONE.getDefaultState());
        structure.fillWithBlocks(world, start, 17, -3, 55, 17, -3, 58, Blocks.GRAVEL.getDefaultState());
        structure.fillWithBlocks(world, start, 17, -3, 59, 17, -1, 61, Blocks.DIRT.getDefaultState());
        structure.fillWithBlocks(world, start, 17, -3, 62, 18, -3, 64, Blocks.STONE.getDefaultState());
        structure.fillWithBlocks(world, start, 17, -3, 70, 20, -3, 73, Blocks.DIRT.getDefaultState());
        structure.fillWithBlocks(world, start, 17, -3, 75, 18, -3, 77, Blocks.GRASS_BLOCK.getDefaultState().with(SnowyDirtBlock.SNOWY, false));
        structure.fillWithBlocks(world, start, 17, -2, -26, 18, -1, -26, Blocks.DIRT.getDefaultState());
        structure.fillWithBlocks(world, start, 17, -2, -25, 18, -1, -25, Blocks.STONE.getDefaultState());
        structure.fillWithBlocks(world, start, 17, -2, -24, 19, -2, -22, Blocks.DIRT.getDefaultState());
        structure.fillWithBlocks(world, start, 17, -2, 10, 20, -2, 39, Blocks.DIRT.getDefaultState());
        structure.fillWithBlocks(world, start, 17, -2, 40, 18, -2, 41, Blocks.GRAVEL.getDefaultState());
        structure.fillWithBlocks(world, start, 17, -2, 44, 17, -1, 44, Blocks.DIRT.getDefaultState());
        structure.fillWithBlocks(world, start, 17, -2, 45, 17, 0, 45, Blocks.GRAVEL.getDefaultState());
        structure.fillWithBlocks(world, start, 17, -2, 46, 17, -2, 52, Blocks.DIRT.getDefaultState());
        structure.fillWithBlocks(world, start, 17, -2, 53, 17, 0, 53, Blocks.GRAVEL.getDefaultState());
        structure.fillWithBlocks(world, start, 17, -2, 55, 17, 0, 57, Blocks.DIRT.getDefaultState());
        structure.fillWithBlocks(world, start, 17, -2, 58, 18, -1, 58, Blocks.GRAVEL.getDefaultState());
        structure.fillWithBlocks(world, start, 17, -2, 62, 24, -2, 69, Blocks.DIRT.getDefaultState());
        structure.fillWithBlocks(world, start, 17, -2, 73, 18, -2, 74, Blocks.GRASS_BLOCK.getDefaultState().with(SnowyDirtBlock.SNOWY, false));
        structure.fillWithBlocks(world, start, 17, -1, -24, 19, -1, -22, Blocks.DIRT.getDefaultState());
        structure.fillWithBlocks(world, start, 17, -1, -21, 17, -1, -12, Blocks.DIRT.getDefaultState());
        structure.fillWithBlocks(world, start, 17, -1, -8, 17, -1, 1, Blocks.DIRT.getDefaultState());
        structure.fillWithBlocks(world, start, 17, -1, 12, 22, -1, 19, Blocks.DIRT.getDefaultState());
        structure.fillWithBlocks(world, start, 17, -1, 20, 17, 1, 20, Blocks.RED_TERRACOTTA.getDefaultState());
        structure.fillWithBlocks(world, start, 17, -1, 21, 17, -1, 23, Blocks.DIRT.getDefaultState());
        structure.fillWithBlocks(world, start, 17, -1, 24, 17, 1, 24, Blocks.RED_TERRACOTTA.getDefaultState());
        structure.fillWithBlocks(world, start, 17, -1, 25, 22, -1, 36, Blocks.DIRT.getDefaultState());
        structure.fillWithBlocks(world, start, 17, -1, 40, 18, -1, 41, Blocks.GRAVEL.getDefaultState());
        structure.fillWithBlocks(world, start, 17, -1, 46, 17, -1, 52, Blocks.DIRT.getDefaultState());
        structure.fillWithBlocks(world, start, 17, -1, 70, 18, -1, 71, Blocks.GRASS_BLOCK.getDefaultState().with(SnowyDirtBlock.SNOWY, false));
        structure.fillWithBlocks(world, start, 17, 0, -48, 18, 0, -27, Blocks.OAK_PLANKS.getDefaultState());
        structure.fillWithBlocks(world, start, 17, 0, -26, 25, 0, -26, Blocks.DIRT.getDefaultState());
        structure.fillWithBlocks(world, start, 17, 0, -25, 18, 0, -24, Blocks.STONE.getDefaultState());
        structure.fillWithBlocks(world, start, 17, 0, -23, 18, 0, -22, Blocks.DIRT.getDefaultState());
        structure.fillWithBlocks(world, start, 17, 0, -21, 17, 0, -16, Blocks.STONE_BRICKS.getDefaultState());
        structure.fillWithBlocks(world, start, 17, 0, -15, 20, 0, -12, Blocks.GRASS_BLOCK.getDefaultState().with(SnowyDirtBlock.SNOWY, false));
        structure.fillWithBlocks(world, start, 17, 0, 3, 19, 0, 5, Blocks.GRASS_BLOCK.getDefaultState().with(SnowyDirtBlock.SNOWY, false));
        structure.fillWithBlocks(world, start, 17, 0, 6, 18, 0, 7, Blocks.GRASS_BLOCK.getDefaultState().with(SnowyDirtBlock.SNOWY, false));
        structure.fillWithBlocks(world, start, 17, 0, 10, 19, 0, 13, Blocks.GRASS_BLOCK.getDefaultState().with(SnowyDirtBlock.SNOWY, false));
        structure.fillWithBlocks(world, start, 17, 0, 14, 17, 0, 19, Blocks.DIRT.getDefaultState());
        structure.fillWithBlocks(world, start, 17, 0, 40, 18, 0, 41, Blocks.GRAVEL.getDefaultState());
        structure.fillWithBlocks(world, start, 17, 0, 44, 17, 0, 44, Blocks.STONE_BRICKS.getDefaultState());
        structure.fillWithBlocks(world, start, 17, 0, 52, 17, 0, 52, Blocks.GRASS_BLOCK.getDefaultState().with(SnowyDirtBlock.SNOWY, false));
        structure.fillWithBlocks(world, start, 17, 0, 58, 18, 0, 58, Blocks.GRAVEL.getDefaultState());
        structure.fillWithBlocks(world, start, 17, 0, 59, 17, 0, 61, Blocks.STONE_BRICKS.getDefaultState());
        structure.fillWithBlocks(world, start, 17, 0, 62, 17, 0, 69, Blocks.GRASS_BLOCK.getDefaultState().with(SnowyDirtBlock.SNOWY, false));
        structure.fillWithBlocks(world, start, 17, 1, -26, 18, 1, -26, Blocks.OAK_STAIRS.getDefaultState().with(StairsBlock.FACING, Direction.SOUTH).with(StairsBlock.WATERLOGGED, false).with(StairsBlock.SHAPE, StairsShape.STRAIGHT).with(StairsBlock.HALF, Half.BOTTOM));
        structure.fillWithBlocks(world, start, 17, 1, -25, 18, 1, -24, Blocks.STONE.getDefaultState());
        structure.fillWithBlocks(world, start, 17, 1, -23, 18, 1, -23, Blocks.DIRT.getDefaultState());
        structure.fillWithBlocks(world, start, 17, 1, -22, 18, 1, -22, Blocks.STONE_BRICK_STAIRS.getDefaultState().with(StairsBlock.FACING, Direction.NORTH).with(StairsBlock.WATERLOGGED, false).with(StairsBlock.SHAPE, StairsShape.STRAIGHT).with(StairsBlock.HALF, Half.BOTTOM));
        structure.fillWithBlocks(world, start, 17, 1, 3, 17, 1, 4, Blocks.GRASS.getDefaultState());
        structure.fillWithBlocks(world, start, 17, 1, 14, 17, 2, 14, Blocks.OAK_LOG.getDefaultState());
        structure.fillWithBlocks(world, start, 17, 1, 15, 17, 1, 20, Blocks.RED_TERRACOTTA.getDefaultState());
        structure.fillWithBlocks(world, start, 17, 1, 54, 19, 1, 54, Blocks.STONE_BRICK_STAIRS.getDefaultState().with(StairsBlock.FACING, Direction.SOUTH).with(StairsBlock.WATERLOGGED, false).with(StairsBlock.SHAPE, StairsShape.STRAIGHT).with(StairsBlock.HALF, Half.BOTTOM));
        structure.fillWithBlocks(world, start, 17, 1, 55, 17, 3, 57, Blocks.STONE_BRICKS.getDefaultState());
        structure.fillWithBlocks(world, start, 17, 1, 58, 19, 1, 58, Blocks.STONE_BRICK_STAIRS.getDefaultState().with(StairsBlock.FACING, Direction.NORTH).with(StairsBlock.WATERLOGGED, false).with(StairsBlock.SHAPE, StairsShape.STRAIGHT).with(StairsBlock.HALF, Half.BOTTOM));
        structure.fillWithBlocks(world, start, 17, 2, -25, 18, 2, -25, Blocks.OAK_STAIRS.getDefaultState().with(StairsBlock.FACING, Direction.SOUTH).with(StairsBlock.WATERLOGGED, false).with(StairsBlock.SHAPE, StairsShape.STRAIGHT).with(StairsBlock.HALF, Half.BOTTOM));
        structure.fillWithBlocks(world, start, 17, 2, -24, 18, 2, -24, Blocks.STONE.getDefaultState());
