package mod.arcalitegames.odyssey.world.structure.town.boromirtown;

import mod.arcalitegames.buildersaddition.Index;
import mod.arcalitegames.buildersaddition.blocks.Cabinet;
import mod.arcalitegames.buildersaddition.blocks.Cupboard;
import mod.arcalitegames.buildersaddition.blocks.Pillar;
import mod.arcalitegames.buildersaddition.blocks.Shelf;
import mod.arcalitegames.buildersaddition.blocks.Stool;
import mod.arcalitegames.buildersaddition.state.PillarState;
import mod.arcalitegames.buildersaddition.state.StoolState;
import mod.arcalitegames.odyssey.world.structure.StructureBase;
import net.minecraft.block.AbstractFurnaceBlock;
import net.minecraft.block.BarrelBlock;
import net.minecraft.block.BedBlock;
import net.minecraft.block.Blocks;
import net.minecraft.block.CampfireBlock;
import net.minecraft.block.CarvedPumpkinBlock;
import net.minecraft.block.ChainBlock;
import net.minecraft.block.CropsBlock;
import net.minecraft.block.DirectionalBlock;
import net.minecraft.block.FarmlandBlock;
import net.minecraft.block.FourWayBlock;
import net.minecraft.block.HorizontalBlock;
import net.minecraft.block.LanternBlock;
import net.minecraft.block.LeavesBlock;
import net.minecraft.block.PistonBlock;
import net.minecraft.block.SlabBlock;
import net.minecraft.block.SnowyDirtBlock;
import net.minecraft.block.StairsBlock;
import net.minecraft.block.TrapDoorBlock;
import net.minecraft.block.WallBlock;
import net.minecraft.block.WallHeight;
import net.minecraft.block.WallTorchBlock;
import net.minecraft.state.properties.BedPart;
import net.minecraft.state.properties.DoubleBlockHalf;
import net.minecraft.state.properties.Half;
import net.minecraft.state.properties.SlabType;
import net.minecraft.state.properties.StairsShape;
import net.minecraft.util.Direction;
import net.minecraft.util.math.BlockPos;
import net.minecraft.world.World;

public class BoromirComponent2
{
	public static BlockPos start;
    public static World world;
    public static StructureBase structure;

    public static void init(World worldIn, BlockPos blockPos, StructureBase structureIn)
    {
        world = worldIn; start = blockPos; structure = structureIn;
    }
    
    public static void generatePart21()
    {
        structure.fillWithBlocks(world, start, -38, 7, 2, -34, 7, 9, Blocks.COBBLESTONE.getDefaultState());
        structure.fillWithBlocks(world, start, -38, 7, 17, -38, 7, 17, Blocks.OAK_LEAVES.getDefaultState().with(LeavesBlock.PERSISTENT, false).with(LeavesBlock.DISTANCE, 1));
        structure.fillWithBlocks(world, start, -38, 7, 19, -38, 7, 19, Blocks.OAK_LEAVES.getDefaultState().with(LeavesBlock.PERSISTENT, false).with(LeavesBlock.DISTANCE, 1));
        structure.fillWithBlocks(world, start, -38, 7, 32, -38, 7, 33, Blocks.OAK_LEAVES.getDefaultState().with(LeavesBlock.PERSISTENT, false).with(LeavesBlock.DISTANCE, 2));
        structure.fillWithBlocks(world, start, -38, 7, 35, -38, 7, 36, Blocks.OAK_LEAVES.getDefaultState().with(LeavesBlock.PERSISTENT, false).with(LeavesBlock.DISTANCE, 1));
        structure.fillWithBlocks(world, start, -38, 7, 37, -38, 7, 37, Blocks.OAK_LEAVES.getDefaultState().with(LeavesBlock.PERSISTENT, false).with(LeavesBlock.DISTANCE, 2));
        structure.fillWithBlocks(world, start, -38, 8, -4, -37, 8, -3, Blocks.OAK_PLANKS.getDefaultState());
        structure.fillWithBlocks(world, start, -38, 8, 1, -37, 8, 2, Blocks.HAY_BLOCK.getDefaultState());
        structure.fillWithBlocks(world, start, -38, 8, 4, -34, 8, 4, Blocks.HAY_BLOCK.getDefaultState());
        structure.fillWithBlocks(world, start, -38, 8, 5, -38, 8, 6, Blocks.HAY_BLOCK.getDefaultState());
        structure.fillWithBlocks(world, start, -38, 8, 7, -38, 8, 9, Blocks.HAY_BLOCK.getDefaultState());
        structure.fillWithBlocks(world, start, -38, 8, 11, -33, 8, 11, Blocks.DARK_OAK_SLAB.getDefaultState().with(SlabBlock.TYPE, SlabType.TOP).with(SlabBlock.WATERLOGGED, false));
        structure.fillWithBlocks(world, start, -38, 8, 12, -32, 8, 12, Blocks.OAK_PLANKS.getDefaultState());
        structure.fillWithBlocks(world, start, -38, 8, 17, -38, 8, 17, Blocks.OAK_LEAVES.getDefaultState().with(LeavesBlock.PERSISTENT, false).with(LeavesBlock.DISTANCE, 2));
        structure.fillWithBlocks(world, start, -38, 8, 19, -38, 8, 19, Blocks.OAK_LEAVES.getDefaultState().with(LeavesBlock.PERSISTENT, false).with(LeavesBlock.DISTANCE, 2));
        structure.fillWithBlocks(world, start, -38, 8, 35, -38, 8, 35, Blocks.OAK_LEAVES.getDefaultState().with(LeavesBlock.PERSISTENT, false).with(LeavesBlock.DISTANCE, 1));
        structure.fillWithBlocks(world, start, -38, 8, 36, -38, 8, 36, Blocks.OAK_LEAVES.getDefaultState().with(LeavesBlock.PERSISTENT, false).with(LeavesBlock.DISTANCE, 2));
        structure.fillWithBlocks(world, start, -38, 8, 37, -38, 8, 37, Blocks.OAK_LEAVES.getDefaultState().with(LeavesBlock.PERSISTENT, false).with(LeavesBlock.DISTANCE, 3));
        structure.fillWithBlocks(world, start, -38, 8, 44, -38, 8, 44, Blocks.OAK_LEAVES.getDefaultState().with(LeavesBlock.PERSISTENT, false).with(LeavesBlock.DISTANCE, 2));
        structure.fillWithBlocks(world, start, -38, 9, -20, -32, 9, -20, Blocks.COBBLESTONE.getDefaultState());
        structure.fillWithBlocks(world, start, -38, 9, -18, -38, 9, -12, Blocks.OAK_STAIRS.getDefaultState().with(StairsBlock.FACING, Direction.WEST).with(StairsBlock.WATERLOGGED, false).with(StairsBlock.SHAPE, StairsShape.STRAIGHT).with(StairsBlock.HALF, Half.BOTTOM));
        structure.fillWithBlocks(world, start, -38, 9, 8, -36, 9, 8, Blocks.HAY_BLOCK.getDefaultState());
        structure.fillWithBlocks(world, start, -38, 9, 31, -38, 9, 31, Blocks.OAK_LEAVES.getDefaultState().with(LeavesBlock.PERSISTENT, false).with(LeavesBlock.DISTANCE, 1));
        structure.fillWithBlocks(world, start, -38, 9, 34, -38, 10, 34, Blocks.OAK_LEAVES.getDefaultState().with(LeavesBlock.PERSISTENT, false).with(LeavesBlock.DISTANCE, 1));
        structure.fillWithBlocks(world, start, -38, 9, 35, -38, 10, 35, Blocks.OAK_LEAVES.getDefaultState().with(LeavesBlock.PERSISTENT, false).with(LeavesBlock.DISTANCE, 2));
        structure.fillWithBlocks(world, start, -38, 9, 36, -38, 10, 36, Blocks.OAK_LEAVES.getDefaultState().with(LeavesBlock.PERSISTENT, false).with(LeavesBlock.DISTANCE, 3));
        structure.fillWithBlocks(world, start, -38, 9, 37, -38, 9, 37, Blocks.OAK_LEAVES.getDefaultState().with(LeavesBlock.PERSISTENT, false).with(LeavesBlock.DISTANCE, 4));
        structure.fillWithBlocks(world, start, -38, 10, 31, -38, 10, 31, Blocks.OAK_LEAVES.getDefaultState().with(LeavesBlock.PERSISTENT, false).with(LeavesBlock.DISTANCE, 2));
        structure.fillWithBlocks(world, start, -38, 11, -2, -33, 12, -2, Blocks.OAK_PLANKS.getDefaultState());
        structure.fillWithBlocks(world, start, -38, 11, 10, -37, 11, 11, Blocks.OAK_PLANKS.getDefaultState());
        structure.fillWithBlocks(world, start, -38, 11, 31, -38, 11, 31, Blocks.OAK_LEAVES.getDefaultState().with(LeavesBlock.PERSISTENT, false).with(LeavesBlock.DISTANCE, 3));
        structure.fillWithBlocks(world, start, -38, 11, 34, -38, 11, 34, Blocks.OAK_LEAVES.getDefaultState().with(LeavesBlock.PERSISTENT, false).with(LeavesBlock.DISTANCE, 2));
        structure.fillWithBlocks(world, start, -38, 12, -1, -38, 13, 9, Blocks.OAK_PLANKS.getDefaultState());
        structure.fillWithBlocks(world, start, -38, 12, 10, -33, 12, 10, Blocks.OAK_PLANKS.getDefaultState());
        structure.fillWithBlocks(world, start, -38, 12, 31, -38, 12, 31, Blocks.OAK_LEAVES.getDefaultState().with(LeavesBlock.PERSISTENT, false).with(LeavesBlock.DISTANCE, 4));
        structure.fillWithBlocks(world, start, -38, 12, 34, -38, 12, 34, Blocks.OAK_LEAVES.getDefaultState().with(LeavesBlock.PERSISTENT, false).with(LeavesBlock.DISTANCE, 3));
        structure.fillWithBlocks(world, start, -38, 12, 35, -38, 12, 35, Blocks.OAK_LEAVES.getDefaultState().with(LeavesBlock.PERSISTENT, false).with(LeavesBlock.DISTANCE, 4));
        structure.fillWithBlocks(world, start, -38, 13, -2, -34, 13, -2, Blocks.OAK_STAIRS.getDefaultState().with(StairsBlock.FACING, Direction.SOUTH).with(StairsBlock.WATERLOGGED, false).with(StairsBlock.SHAPE, StairsShape.STRAIGHT).with(StairsBlock.HALF, Half.BOTTOM));
        structure.fillWithBlocks(world, start, -38, 13, 10, -34, 13, 10, Blocks.OAK_STAIRS.getDefaultState().with(StairsBlock.FACING, Direction.NORTH).with(StairsBlock.WATERLOGGED, false).with(StairsBlock.SHAPE, StairsShape.STRAIGHT).with(StairsBlock.HALF, Half.BOTTOM));
        structure.fillWithBlocks(world, start, -38, 13, 34, -38, 13, 34, Blocks.OAK_LEAVES.getDefaultState().with(LeavesBlock.PERSISTENT, false).with(LeavesBlock.DISTANCE, 4));
        structure.fillWithBlocks(world, start, -38, 14, 0, -38, 14, 8, Blocks.OAK_STAIRS.getDefaultState().with(StairsBlock.FACING, Direction.EAST).with(StairsBlock.WATERLOGGED, false).with(StairsBlock.SHAPE, StairsShape.STRAIGHT).with(StairsBlock.HALF, Half.BOTTOM));
        structure.fillWithBlocks(world, start, -37, -11, -80, -12, -11, -80, Blocks.GRASS_BLOCK.getDefaultState().with(SnowyDirtBlock.SNOWY, false));
        structure.fillWithBlocks(world, start, -37, -11, -79, -33, -11, -75, Blocks.DIRT.getDefaultState());
        structure.fillWithBlocks(world, start, -37, -11, -74, -33, -11, 92, Blocks.STONE.getDefaultState());
        structure.fillWithBlocks(world, start, -37, -11, 103, -36, -11, 105, Blocks.CAVE_AIR.getDefaultState());
        structure.fillWithBlocks(world, start, -37, -10, -79, -33, -10, -79, Blocks.GRASS_BLOCK.getDefaultState().with(SnowyDirtBlock.SNOWY, false));
        structure.fillWithBlocks(world, start, -37, -10, -78, -34, -10, -73, Blocks.DIRT.getDefaultState());
        structure.fillWithBlocks(world, start, -37, -10, -72, -37, -10, -72, Blocks.STONE.getDefaultState());
        structure.fillWithBlocks(world, start, -37, -10, -71, -37, -9, -70, Blocks.DIRT.getDefaultState());
        structure.fillWithBlocks(world, start, -37, -10, 87, -33, -10, 91, Blocks.STONE.getDefaultState());
        structure.fillWithBlocks(world, start, -37, -10, 92, -37, -10, 96, Blocks.DIRT.getDefaultState());
        structure.fillWithBlocks(world, start, -37, -9, -64, -14, -9, -41, Blocks.STONE.getDefaultState());
        structure.fillWithBlocks(world, start, -37, -9, -35, -35, -9, -33, Blocks.STONE.getDefaultState());
        structure.fillWithBlocks(world, start, -37, -9, -25, -25, -9, -13, Blocks.STONE.getDefaultState());
        structure.fillWithBlocks(world, start, -37, -9, -9, -28, -9, -9, Blocks.STONE.getDefaultState());
        structure.fillWithBlocks(world, start, -37, -9, -8, -32, -9, -2, Blocks.DIRT.getDefaultState());
        structure.fillWithBlocks(world, start, -37, -9, -1, -34, -6, -1, Blocks.DIRT.getDefaultState());
        structure.fillWithBlocks(world, start, -37, -9, 69, -34, -9, 72, Blocks.DIRT.getDefaultState());
        structure.fillWithBlocks(world, start, -37, -9, 73, -36, -8, 73, Blocks.DIRT.getDefaultState());
        structure.fillWithBlocks(world, start, -37, -9, 74, -21, -9, 90, Blocks.STONE.getDefaultState());
        structure.fillWithBlocks(world, start, -37, -9, 91, -33, -9, 95, Blocks.DIRT.getDefaultState());
        structure.fillWithBlocks(world, start, -37, -8, -75, -29, -8, -53, Blocks.DIRT.getDefaultState());
        structure.fillWithBlocks(world, start, -37, -8, -40, -37, -8, -40, Blocks.STONE.getDefaultState());
        structure.fillWithBlocks(world, start, -37, -8, -39, -37, -8, -20, Blocks.DIRT.getDefaultState());
        structure.fillWithBlocks(world, start, -37, -8, -19, -32, -8, -14, Blocks.STONE.getDefaultState());
        structure.fillWithBlocks(world, start, -37, -8, 6, -36, -8, 8, Blocks.STONE.getDefaultState());
        structure.fillWithBlocks(world, start, -37, -8, 10, -22, -8, 46, Blocks.DIRT.getDefaultState());
        structure.fillWithBlocks(world, start, -37, -8, 62, -23, -8, 76, Blocks.DIRT.getDefaultState());
        structure.fillWithBlocks(world, start, -37, -8, 83, -33, -8, 87, Blocks.STONE.getDefaultState());
        structure.fillWithBlocks(world, start, -37, -7, -75, -29, -7, -75, Blocks.GRASS_BLOCK.getDefaultState().with(SnowyDirtBlock.SNOWY, false));
        structure.fillWithBlocks(world, start, -37, -6, -74, -36, -6, -73, Blocks.GRASS_BLOCK.getDefaultState().with(SnowyDirtBlock.SNOWY, false));
        structure.fillWithBlocks(world, start, -37, -5, -72, -35, -5, -70, Blocks.GRASS_BLOCK.getDefaultState().with(SnowyDirtBlock.SNOWY, false));
        structure.fillWithBlocks(world, start, -37, -5, 88, -35, -5, 90, Blocks.GRASS_BLOCK.getDefaultState().with(SnowyDirtBlock.SNOWY, false));
        structure.fillWithBlocks(world, start, -37, -4, -26, -35, -4, -23, Blocks.STONE.getDefaultState());
        structure.fillWithBlocks(world, start, -37, -4, -14, -34, -4, -11, Blocks.DIRT.getDefaultState());
        structure.fillWithBlocks(world, start, -37, -4, 8, -36, -4, 10, Blocks.GRAVEL.getDefaultState());
        structure.fillWithBlocks(world, start, -37, -4, 11, -37, -4, 53, Blocks.STONE.getDefaultState());
        structure.fillWithBlocks(world, start, -37, -3, -51, -34, -3, -48, Blocks.STONE.getDefaultState());
        structure.fillWithBlocks(world, start, -37, -3, -47, -37, -3, -33, Blocks.DIRT.getDefaultState());
        structure.fillWithBlocks(world, start, -37, -3, -26, -36, -3, -26, Blocks.IRON_ORE.getDefaultState());
        structure.fillWithBlocks(world, start, -37, -3, -25, -35, -3, -23, Blocks.STONE.getDefaultState());
        structure.fillWithBlocks(world, start, -37, -2, -14, -37, 1, -11, Blocks.DIRT.getDefaultState());
        structure.fillWithBlocks(world, start, -37, -2, 46, -27, -2, 56, Blocks.DIRT.getDefaultState());
        structure.fillWithBlocks(world, start, -37, -1, -60, -34, -1, -57, Blocks.GRASS_BLOCK.getDefaultState().with(SnowyDirtBlock.SNOWY, false));
        structure.fillWithBlocks(world, start, -37, -1, -27, -34, -1, -24, Blocks.DIRT.getDefaultState());
        structure.fillWithBlocks(world, start, -37, -1, -10, -36, -1, -9, Blocks.STONE.getDefaultState());
        structure.fillWithBlocks(world, start, -37, -1, -8, -37, -1, -8, Blocks.DIRT.getDefaultState());
        structure.fillWithBlocks(world, start, -37, -1, -7, -37, -1, -7, Blocks.STONE.getDefaultState());
        structure.fillWithBlocks(world, start, -37, -1, -6, -37, 0, -5, Blocks.DIRT.getDefaultState());
        structure.fillWithBlocks(world, start, -37, -1, -3, -35, 1, -3, Blocks.DIRT.getDefaultState());
        structure.fillWithBlocks(world, start, -37, -1, -2, -33, -1, 2, Blocks.STONE.getDefaultState());
        structure.fillWithBlocks(world, start, -37, -1, 3, -36, -1, 11, Blocks.STONE.getDefaultState());
        structure.fillWithBlocks(world, start, -37, -1, 12, -37, 1, 12, Blocks.DIRT.getDefaultState());
        structure.fillWithBlocks(world, start, -37, -1, 16, -37, -1, 17, Blocks.STONE.getDefaultState());
        structure.fillWithBlocks(world, start, -37, -1, 23, -36, -1, 25, Blocks.DIRT.getDefaultState());
        structure.fillWithBlocks(world, start, -37, -1, 26, -37, -1, 32, Blocks.STONE.getDefaultState());
        structure.fillWithBlocks(world, start, -37, -1, 33, -34, -1, 53, Blocks.DIRT.getDefaultState());
        structure.fillWithBlocks(world, start, -37, 0, -48, -37, 0, -48, Blocks.GRASS_BLOCK.getDefaultState().with(SnowyDirtBlock.SNOWY, false));
        structure.fillWithBlocks(world, start, -37, 0, -47, -37, 0, -33, Blocks.WATER.getDefaultState());
        structure.fillWithBlocks(world, start, -37, 0, -29, -37, 0, -28, Blocks.GRASS_BLOCK.getDefaultState().with(SnowyDirtBlock.SNOWY, false));
        structure.fillWithBlocks(world, start, -37, 0, -26, -35, 0, -24, Blocks.DIRT.getDefaultState());
        structure.fillWithBlocks(world, start, -37, 0, -10, -35, 0, -8, Blocks.DIRT.getDefaultState());
        structure.fillWithBlocks(world, start, -37, 0, -7, -37, 2, -7, Blocks.GRAVEL.getDefaultState());
        structure.fillWithBlocks(world, start, -37, 0, -2, -35, 0, 9, Blocks.DIRT.getDefaultState());
        structure.fillWithBlocks(world, start, -37, 0, 13, -37, 2, 13, Blocks.GRAVEL.getDefaultState());
        structure.fillWithBlocks(world, start, -37, 0, 16, -37, 2, 18, Blocks.GRAVEL.getDefaultState());
        structure.fillWithBlocks(world, start, -37, 0, 19, -37, 1, 21, Blocks.DIRT.getDefaultState());
        structure.fillWithBlocks(world, start, -37, 0, 22, -37, 2, 22, Blocks.GRAVEL.getDefaultState());
        structure.fillWithBlocks(world, start, -37, 0, 23, -37, 0, 49, Blocks.DIRT.getDefaultState());
        structure.fillWithBlocks(world, start, -37, 0, 50, -36, 0, 52, Blocks.GRASS_BLOCK.getDefaultState().with(SnowyDirtBlock.SNOWY, false));
        structure.fillWithBlocks(world, start, -37, 1, -50, -37, 1, -48, Blocks.GRASS.getDefaultState());
        structure.fillWithBlocks(world, start, -37, 1, -26, -35, 1, -24, Blocks.DIRT.getDefaultState());
        structure.fillWithBlocks(world, start, -37, 1, -10, -35, 1, -8, Blocks.DIRT.getDefaultState());
        structure.fillWithBlocks(world, start, -37, 1, -6, -37, 1, 12, Blocks.DIRT.getDefaultState());
        structure.fillWithBlocks(world, start, -37, 1, 23, -37, 1, 26, Blocks.DIRT.getDefaultState());
        structure.fillWithBlocks(world, start, -37, 1, 27, -37, 3, 27, Blocks.GRAVEL.getDefaultState());
        structure.fillWithBlocks(world, start, -37, 1, 28, -37, 2, 32, Blocks.DIRT.getDefaultState());
        structure.fillWithBlocks(world, start, -37, 1, 33, -37, 1, 33, Blocks.GRASS_BLOCK.getDefaultState().with(SnowyDirtBlock.SNOWY, false));
        structure.fillWithBlocks(world, start, -37, 1, 35, -36, 1, 48, Blocks.GRASS_BLOCK.getDefaultState().with(SnowyDirtBlock.SNOWY, false));
        structure.fillWithBlocks(world, start, -37, 1, 49, -36, 2, 49, Blocks.OAK_LOG.getDefaultState());
        structure.fillWithBlocks(world, start, -37, 1, 53, -36, 2, 53, Blocks.OAK_LOG.getDefaultState());
        structure.fillWithBlocks(world, start, -37, 2, -29, -37, 2, -28, Blocks.STONE_BRICKS.getDefaultState());
        structure.fillWithBlocks(world, start, -37, 2, -10, -36, 2, -9, Blocks.GRASS_BLOCK.getDefaultState().with(SnowyDirtBlock.SNOWY, false));
        structure.fillWithBlocks(world, start, -37, 2, -8, -37, 2, -8, Blocks.STONE_BRICKS.getDefaultState());
        structure.fillWithBlocks(world, start, -37, 2, -3, -35, 2, -3, Blocks.COBBLESTONE.getDefaultState());
        structure.fillWithBlocks(world, start, -37, 2, 11, -34, 2, 11, Blocks.DIRT.getDefaultState());
        structure.fillWithBlocks(world, start, -37, 2, 12, -37, 2, 12, Blocks.COBBLESTONE.getDefaultState());
        structure.fillWithBlocks(world, start, -37, 2, 14, -36, 2, 15, Blocks.COBBLESTONE.getDefaultState());
        structure.fillWithBlocks(world, start, -37, 2, 19, -37, 2, 21, Blocks.COBBLESTONE.getDefaultState());
        structure.fillWithBlocks(world, start, -37, 2, 23, -37, 2, 25, Blocks.COBBLESTONE.getDefaultState());
        structure.fillWithBlocks(world, start, -37, 2, 26, -37, 2, 26, Blocks.DIRT.getDefaultState());
        structure.fillWithBlocks(world, start, -37, 2, 34, -37, 10, 34, Blocks.OAK_LOG.getDefaultState());
        structure.fillWithBlocks(world, start, -37, 2, 35, -36, 2, 36, Blocks.GRASS.getDefaultState());
        structure.fillWithBlocks(world, start, -37, 2, 38, -37, 2, 45, Blocks.GRASS.getDefaultState());
        structure.fillWithBlocks(world, start, -37, 3, -26, -37, 3, -26, Blocks.GRASS.getDefaultState());
        structure.fillWithBlocks(world, start, -37, 3, -11, -37, 5, -11, Blocks.OAK_PLANKS.getDefaultState());
        structure.fillWithBlocks(world, start, -37, 3, -5, -36, 3, -4, Blocks.GRASS.getDefaultState());
        structure.fillWithBlocks(world, start, -37, 3, -2, -35, 4, -2, Blocks.COBBLESTONE.getDefaultState());
        structure.fillWithBlocks(world, start, -37, 3, -1, -35, 3, 9, Blocks.OAK_PLANKS.getDefaultState());
        structure.fillWithBlocks(world, start, -37, 3, 11, -35, 3, 11, Blocks.OAK_PLANKS.getDefaultState());
        structure.fillWithBlocks(world, start, -37, 3, 12, -35, 3, 12, Blocks.OAK_STAIRS.getDefaultState().with(StairsBlock.FACING, Direction.NORTH).with(StairsBlock.WATERLOGGED, false).with(StairsBlock.SHAPE, StairsShape.STRAIGHT).with(StairsBlock.HALF, Half.BOTTOM));
        structure.fillWithBlocks(world, start, -37, 3, 26, -36, 3, 26, Blocks.COBBLESTONE_SLAB.getDefaultState().with(SlabBlock.TYPE, SlabType.BOTTOM).with(SlabBlock.WATERLOGGED, false));
        structure.fillWithBlocks(world, start, -37, 3, 28, -37, 3, 31, Blocks.COBBLESTONE.getDefaultState());
        structure.fillWithBlocks(world, start, -37, 3, 49, -36, 4, 49, Blocks.OAK_LOG.getDefaultState());
        structure.fillWithBlocks(world, start, -37, 3, 53, -36, 4, 53, Blocks.OAK_LOG.getDefaultState());
        structure.fillWithBlocks(world, start, -37, 4, -23, -37, 5, -23, Blocks.OAK_PLANKS.getDefaultState());
        structure.fillWithBlocks(world, start, -37, 4, 20, -37, 7, 20, Blocks.OAK_LEAVES.getDefaultState().with(LeavesBlock.PERSISTENT, false).with(LeavesBlock.DISTANCE, 1));
        structure.fillWithBlocks(world, start, -37, 4, 21, -37, 4, 22, Blocks.OAK_LEAVES.getDefaultState().with(LeavesBlock.PERSISTENT, false).with(LeavesBlock.DISTANCE, 2));
        structure.fillWithBlocks(world, start, -37, 5, -2, -35, 5, -2, Blocks.OAK_PLANKS.getDefaultState());
        structure.fillWithBlocks(world, start, -37, 5, 16, -37, 6, 16, Blocks.OAK_LEAVES.getDefaultState().with(LeavesBlock.PERSISTENT, false).with(LeavesBlock.DISTANCE, 4));
        structure.fillWithBlocks(world, start, -37, 5, 17, -37, 6, 17, Blocks.OAK_LEAVES.getDefaultState().with(LeavesBlock.PERSISTENT, false).with(LeavesBlock.DISTANCE, 3));
        structure.fillWithBlocks(world, start, -37, 5, 18, -37, 6, 19, Blocks.OAK_LEAVES.getDefaultState().with(LeavesBlock.PERSISTENT, false).with(LeavesBlock.DISTANCE, 2));
        structure.fillWithBlocks(world, start, -37, 5, 21, -37, 6, 21, Blocks.OAK_LEAVES.getDefaultState().with(LeavesBlock.PERSISTENT, false).with(LeavesBlock.DISTANCE, 2));
        structure.fillWithBlocks(world, start, -37, 5, 22, -37, 6, 22, Blocks.OAK_LEAVES.getDefaultState().with(LeavesBlock.PERSISTENT, false).with(LeavesBlock.DISTANCE, 3));
        structure.fillWithBlocks(world, start, -37, 5, 33, -37, 5, 33, Blocks.OAK_LEAVES.getDefaultState().with(LeavesBlock.PERSISTENT, false).with(LeavesBlock.DISTANCE, 1));
        structure.fillWithBlocks(world, start, -37, 5, 43, -37, 6, 43, Blocks.OAK_LEAVES.getDefaultState().with(LeavesBlock.PERSISTENT, false).with(LeavesBlock.DISTANCE, 3));
        structure.fillWithBlocks(world, start, -37, 5, 44, -37, 7, 44, Blocks.OAK_LEAVES.getDefaultState().with(LeavesBlock.PERSISTENT, false).with(LeavesBlock.DISTANCE, 2));
        structure.fillWithBlocks(world, start, -37, 5, 45, -37, 7, 45, Blocks.OAK_LEAVES.getDefaultState().with(LeavesBlock.PERSISTENT, false).with(LeavesBlock.DISTANCE, 1));
        structure.fillWithBlocks(world, start, -37, 5, 46, -37, 6, 46, Blocks.OAK_LEAVES.getDefaultState().with(LeavesBlock.PERSISTENT, false).with(LeavesBlock.DISTANCE, 2));
        structure.fillWithBlocks(world, start, -37, 5, 47, -37, 6, 47, Blocks.OAK_LEAVES.getDefaultState().with(LeavesBlock.PERSISTENT, false).with(LeavesBlock.DISTANCE, 3));
        structure.fillWithBlocks(world, start, -37, 5, 49, -36, 6, 49, Blocks.OAK_LOG.getDefaultState());
        structure.fillWithBlocks(world, start, -37, 5, 53, -36, 6, 53, Blocks.OAK_LOG.getDefaultState());
        structure.fillWithBlocks(world, start, -37, 6, -54, -35, 6, -52, Blocks.OAK_PLANKS.getDefaultState());
        structure.fillWithBlocks(world, start, -37, 6, -33, -37, 7, -33, Blocks.OAK_LEAVES.getDefaultState().with(LeavesBlock.PERSISTENT, false).with(LeavesBlock.DISTANCE, 3));
        structure.fillWithBlocks(world, start, -37, 6, -32, -37, 8, -32, Blocks.OAK_LEAVES.getDefaultState().with(LeavesBlock.PERSISTENT, false).with(LeavesBlock.DISTANCE, 2));
        structure.fillWithBlocks(world, start, -37, 6, -31, -37, 8, -31, Blocks.OAK_LEAVES.getDefaultState().with(LeavesBlock.PERSISTENT, false).with(LeavesBlock.DISTANCE, 1));
        structure.fillWithBlocks(world, start, -37, 6, -30, -37, 7, -30, Blocks.OAK_LEAVES.getDefaultState().with(LeavesBlock.PERSISTENT, false).with(LeavesBlock.DISTANCE, 2));
        structure.fillWithBlocks(world, start, -37, 6, -29, -37, 7, -29, Blocks.OAK_LEAVES.getDefaultState().with(LeavesBlock.PERSISTENT, false).with(LeavesBlock.DISTANCE, 3));
        structure.fillWithBlocks(world, start, -37, 6, -11, -36, 6, -11, Blocks.COBBLESTONE.getDefaultState());
        structure.fillWithBlocks(world, start, -37, 6, -3, -35, 6, -3, Blocks.DARK_OAK_SLAB.getDefaultState().with(SlabBlock.TYPE, SlabType.TOP).with(SlabBlock.WATERLOGGED, false));
        structure.fillWithBlocks(world, start, -37, 6, -2, -35, 6, -2, Blocks.OAK_LOG.getDefaultState());
        structure.fillWithBlocks(world, start, -37, 6, 11, -35, 6, 11, Blocks.DARK_OAK_SLAB.getDefaultState().with(SlabBlock.TYPE, SlabType.TOP).with(SlabBlock.WATERLOGGED, false));
        structure.fillWithBlocks(world, start, -37, 6, 33, -37, 7, 33, Blocks.OAK_LEAVES.getDefaultState().with(LeavesBlock.PERSISTENT, false).with(LeavesBlock.DISTANCE, 1));
        structure.fillWithBlocks(world, start, -37, 6, 35, -37, 6, 36, Blocks.OAK_LEAVES.getDefaultState().with(LeavesBlock.PERSISTENT, false).with(LeavesBlock.DISTANCE, 1));
        structure.fillWithBlocks(world, start, -37, 7, -2, -35, 7, 10, Blocks.COBBLESTONE.getDefaultState());
        structure.fillWithBlocks(world, start, -37, 7, 31, -36, 7, 31, Blocks.OAK_LEAVES.getDefaultState().with(LeavesBlock.PERSISTENT, false).with(LeavesBlock.DISTANCE, 2));
        structure.fillWithBlocks(world, start, -37, 7, 32, -36, 7, 33, Blocks.OAK_LEAVES.getDefaultState().with(LeavesBlock.PERSISTENT, false).with(LeavesBlock.DISTANCE, 1));
        structure.fillWithBlocks(world, start, -37, 7, 35, -37, 7, 36, Blocks.OAK_LOG.getDefaultState());
        structure.fillWithBlocks(world, start, -37, 7, 49, -36, 7, 49, Blocks.OAK_LOG.getDefaultState());
        structure.fillWithBlocks(world, start, -37, 7, 53, -36, 7, 53, Blocks.OAK_LOG.getDefaultState());
        structure.fillWithBlocks(world, start, -37, 8, -17, -37, 8, -12, Blocks.OAK_STAIRS.getDefaultState().with(StairsBlock.FACING, Direction.WEST).with(StairsBlock.WATERLOGGED, false).with(StairsBlock.SHAPE, StairsShape.STRAIGHT).with(StairsBlock.HALF, Half.BOTTOM));
        structure.fillWithBlocks(world, start, -37, 8, -2, -35, 8, -2, Blocks.COBBLESTONE.getDefaultState());
        structure.fillWithBlocks(world, start, -37, 8, 3, -36, 8, 4, Blocks.HAY_BLOCK.getDefaultState());
        structure.fillWithBlocks(world, start, -37, 8, 5, -37, 9, 5, Blocks.CARVED_PUMPKIN.getDefaultState().with(CarvedPumpkinBlock.FACING, Direction.WEST));
        structure.fillWithBlocks(world, start, -37, 8, 6, -37, 8, 6, Blocks.HAY_BLOCK.getDefaultState());
        structure.fillWithBlocks(world, start, -37, 8, 8, -36, 8, 9, Blocks.HAY_BLOCK.getDefaultState());
        structure.fillWithBlocks(world, start, -37, 8, 10, -35, 8, 10, Blocks.COBBLESTONE.getDefaultState());
        structure.fillWithBlocks(world, start, -37, 8, 31, -37, 8, 31, Blocks.OAK_LEAVES.getDefaultState().with(LeavesBlock.PERSISTENT, false).with(LeavesBlock.DISTANCE, 1));
        structure.fillWithBlocks(world, start, -37, 8, 32, -37, 8, 33, Blocks.OAK_LOG.getDefaultState());
        structure.fillWithBlocks(world, start, -37, 8, 35, -37, 8, 36, Blocks.OAK_LEAVES.getDefaultState().with(LeavesBlock.PERSISTENT, false).with(LeavesBlock.DISTANCE, 1));
        structure.fillWithBlocks(world, start, -37, 8, 37, -36, 8, 37, Blocks.OAK_LEAVES.getDefaultState().with(LeavesBlock.PERSISTENT, false).with(LeavesBlock.DISTANCE, 2));
        structure.fillWithBlocks(world, start, -37, 8, 38, -36, 8, 38, Blocks.OAK_LEAVES.getDefaultState().with(LeavesBlock.PERSISTENT, false).with(LeavesBlock.DISTANCE, 3));
        structure.fillWithBlocks(world, start, -37, 9, -31, -37, 9, -31, Blocks.OAK_LEAVES.getDefaultState().with(LeavesBlock.PERSISTENT, false).with(LeavesBlock.DISTANCE, 2));
        structure.fillWithBlocks(world, start, -37, 9, -21, -33, 9, -21, Blocks.OAK_STAIRS.getDefaultState().with(StairsBlock.FACING, Direction.SOUTH).with(StairsBlock.WATERLOGGED, false).with(StairsBlock.SHAPE, StairsShape.STRAIGHT).with(StairsBlock.HALF, Half.BOTTOM));
        structure.fillWithBlocks(world, start, -37, 9, -19, -33, 9, -19, Blocks.OAK_STAIRS.getDefaultState().with(StairsBlock.FACING, Direction.NORTH).with(StairsBlock.WATERLOGGED, false).with(StairsBlock.SHAPE, StairsShape.STRAIGHT).with(StairsBlock.HALF, Half.BOTTOM));
        structure.fillWithBlocks(world, start, -37, 9, 4, -37, 9, 4, Blocks.HAY_BLOCK.getDefaultState());
        structure.fillWithBlocks(world, start, -37, 9, 6, -37, 9, 6, Blocks.HAY_BLOCK.getDefaultState());
        structure.fillWithBlocks(world, start, -37, 9, 30, -37, 9, 30, Blocks.OAK_LEAVES.getDefaultState().with(LeavesBlock.PERSISTENT, false).with(LeavesBlock.DISTANCE, 1));
        structure.fillWithBlocks(world, start, -37, 9, 32, -37, 9, 33, Blocks.OAK_LEAVES.getDefaultState().with(LeavesBlock.PERSISTENT, false).with(LeavesBlock.DISTANCE, 1));
        structure.fillWithBlocks(world, start, -37, 9, 35, -36, 9, 35, Blocks.OAK_LEAVES.getDefaultState().with(LeavesBlock.PERSISTENT, false).with(LeavesBlock.DISTANCE, 1));
        structure.fillWithBlocks(world, start, -37, 9, 36, -36, 9, 36, Blocks.OAK_LEAVES.getDefaultState().with(LeavesBlock.PERSISTENT, false).with(LeavesBlock.DISTANCE, 2));
        structure.fillWithBlocks(world, start, -37, 9, 37, -36, 9, 37, Blocks.OAK_LEAVES.getDefaultState().with(LeavesBlock.PERSISTENT, false).with(LeavesBlock.DISTANCE, 3));
        structure.fillWithBlocks(world, start, -37, 9, 38, -36, 9, 38, Blocks.OAK_LEAVES.getDefaultState().with(LeavesBlock.PERSISTENT, false).with(LeavesBlock.DISTANCE, 4));
        structure.fillWithBlocks(world, start, -37, 10, -2, -33, 10, -2, Blocks.OAK_LOG.getDefaultState());
        structure.fillWithBlocks(world, start, -37, 10, 10, -33, 10, 10, Blocks.OAK_LOG.getDefaultState());
        structure.fillWithBlocks(world, start, -37, 10, 29, -37, 10, 29, Blocks.OAK_LEAVES.getDefaultState().with(LeavesBlock.PERSISTENT, false).with(LeavesBlock.DISTANCE, 3));
        structure.fillWithBlocks(world, start, -37, 10, 30, -37, 10, 30, Blocks.OAK_LEAVES.getDefaultState().with(LeavesBlock.PERSISTENT, false).with(LeavesBlock.DISTANCE, 2));
        structure.fillWithBlocks(world, start, -37, 10, 32, -37, 10, 32, Blocks.OAK_LEAVES.getDefaultState().with(LeavesBlock.PERSISTENT, false).with(LeavesBlock.DISTANCE, 2));
        structure.fillWithBlocks(world, start, -37, 10, 33, -37, 10, 33, Blocks.OAK_LEAVES.getDefaultState().with(LeavesBlock.PERSISTENT, false).with(LeavesBlock.DISTANCE, 1));
        structure.fillWithBlocks(world, start, -37, 11, 29, -37, 11, 29, Blocks.OAK_LEAVES.getDefaultState().with(LeavesBlock.PERSISTENT, false).with(LeavesBlock.DISTANCE, 4));
        structure.fillWithBlocks(world, start, -37, 11, 30, -37, 11, 30, Blocks.OAK_LEAVES.getDefaultState().with(LeavesBlock.PERSISTENT, false).with(LeavesBlock.DISTANCE, 3));
        structure.fillWithBlocks(world, start, -37, 11, 32, -37, 11, 32, Blocks.OAK_LEAVES.getDefaultState().with(LeavesBlock.PERSISTENT, false).with(LeavesBlock.DISTANCE, 3));
        structure.fillWithBlocks(world, start, -37, 11, 33, -37, 11, 33, Blocks.OAK_LEAVES.getDefaultState().with(LeavesBlock.PERSISTENT, false).with(LeavesBlock.DISTANCE, 2));
        structure.fillWithBlocks(world, start, -37, 12, -1, -34, 13, -1, Blocks.OAK_PLANKS.getDefaultState());
        structure.fillWithBlocks(world, start, -37, 12, 9, -36, 12, 10, Blocks.OAK_PLANKS.getDefaultState());
        structure.fillWithBlocks(world, start, -37, 12, 30, -37, 12, 30, Blocks.OAK_LEAVES.getDefaultState().with(LeavesBlock.PERSISTENT, false).with(LeavesBlock.DISTANCE, 4));
        structure.fillWithBlocks(world, start, -37, 12, 32, -37, 12, 32, Blocks.OAK_LEAVES.getDefaultState().with(LeavesBlock.PERSISTENT, false).with(LeavesBlock.DISTANCE, 4));
        structure.fillWithBlocks(world, start, -37, 12, 33, -37, 12, 33, Blocks.OAK_LEAVES.getDefaultState().with(LeavesBlock.PERSISTENT, false).with(LeavesBlock.DISTANCE, 3));
        structure.fillWithBlocks(world, start, -37, 13, 0, -37, 14, 8, Blocks.OAK_PLANKS.getDefaultState());
        structure.fillWithBlocks(world, start, -37, 13, 9, -34, 13, 9, Blocks.OAK_PLANKS.getDefaultState());
        structure.fillWithBlocks(world, start, -37, 13, 33, -37, 13, 33, Blocks.OAK_LEAVES.getDefaultState().with(LeavesBlock.PERSISTENT, false).with(LeavesBlock.DISTANCE, 4));
        structure.fillWithBlocks(world, start, -37, 14, -1, -35, 14, -1, Blocks.OAK_STAIRS.getDefaultState().with(StairsBlock.FACING, Direction.SOUTH).with(StairsBlock.WATERLOGGED, false).with(StairsBlock.SHAPE, StairsShape.STRAIGHT).with(StairsBlock.HALF, Half.BOTTOM));
        structure.fillWithBlocks(world, start, -37, 14, 9, -35, 14, 9, Blocks.OAK_STAIRS.getDefaultState().with(StairsBlock.FACING, Direction.NORTH).with(StairsBlock.WATERLOGGED, false).with(StairsBlock.SHAPE, StairsShape.STRAIGHT).with(StairsBlock.HALF, Half.BOTTOM));
        structure.fillWithBlocks(world, start, -36, -10, -72, -33, -10, 92, Blocks.STONE.getDefaultState());
        structure.fillWithBlocks(world, start, -36, -10, 93, -33, -10, 96, Blocks.DIRT.getDefaultState());
        structure.fillWithBlocks(world, start, -36, -9, -69, -36, -9, -32, Blocks.STONE.getDefaultState());
        structure.fillWithBlocks(world, start, -36, -9, -31, -36, -9, -26, Blocks.DIRT.getDefaultState());
        structure.fillWithBlocks(world, start, -36, -9, 16, -35, -9, 16, Blocks.STONE.getDefaultState());
        structure.fillWithBlocks(world, start, -36, -9, 17, -30, -9, 32, Blocks.DIRT.getDefaultState());
        structure.fillWithBlocks(world, start, -36, -8, -40, -35, -8, -39, Blocks.STONE.getDefaultState());
        structure.fillWithBlocks(world, start, -36, -8, -38, -36, -8, -20, Blocks.DIRT.getDefaultState());
        structure.fillWithBlocks(world, start, -36, -8, 9, -22, -8, 46, Blocks.DIRT.getDefaultState());
        structure.fillWithBlocks(world, start, -36, -8, 61, -21, -8, 76, Blocks.DIRT.getDefaultState());
        structure.fillWithBlocks(world, start, -36, -8, 77, -35, -8, 79, Blocks.DIRT.getDefaultState());
        structure.fillWithBlocks(world, start, -36, -8, 80, -36, -5, 80, Blocks.DIRT.getDefaultState());
        structure.fillWithBlocks(world, start, -36, -8, 81, -30, -8, 87, Blocks.STONE.getDefaultState());
        structure.fillWithBlocks(world, start, -36, -6, 91, -35, -6, 92, Blocks.GRASS_BLOCK.getDefaultState().with(SnowyDirtBlock.SNOWY, false));
        structure.fillWithBlocks(world, start, -36, -4, -61, -34, -4, -61, Blocks.GRASS_BLOCK.getDefaultState().with(SnowyDirtBlock.SNOWY, false));
        structure.fillWithBlocks(world, start, -36, -4, -22, -34, -4, -19, Blocks.DIRT.getDefaultState());
        structure.fillWithBlocks(world, start, -36, -4, -18, -36, -4, -15, Blocks.STONE.getDefaultState());
        structure.fillWithBlocks(world, start, -36, -4, -10, -34, -4, -8, Blocks.STONE.getDefaultState());
        structure.fillWithBlocks(world, start, -36, -4, -7, -35, -4, -6, Blocks.IRON_ORE.getDefaultState());
        structure.fillWithBlocks(world, start, -36, -4, -5, -24, -4, 7, Blocks.STONE.getDefaultState());
        structure.fillWithBlocks(world, start, -36, -4, 11, -36, -4, 11, Blocks.GRAVEL.getDefaultState());
        structure.fillWithBlocks(world, start, -36, -4, 12, -36, -4, 53, Blocks.STONE.getDefaultState());
        structure.fillWithBlocks(world, start, -36, -3, -55, -32, -3, -51, Blocks.STONE.getDefaultState());
        structure.fillWithBlocks(world, start, -36, -3, -47, 9, -3, -47, Blocks.STONE.getDefaultState());
        structure.fillWithBlocks(world, start, -36, -3, -34, -36, -2, -33, Blocks.DIRT.getDefaultState());
        structure.fillWithBlocks(world, start, -36, -3, -27, -36, -3, -26, Blocks.IRON_ORE.getDefaultState());
        structure.fillWithBlocks(world, start, -36, -3, -15, -33, -3, -12, Blocks.SMOOTH_STONE_SLAB.getDefaultState().with(SlabBlock.TYPE, SlabType.DOUBLE).with(SlabBlock.WATERLOGGED, false));
        structure.fillWithBlocks(world, start, -36, -3, -10, -34, -3, -8, Blocks.STONE.getDefaultState());
        structure.fillWithBlocks(world, start, -36, -3, -7, -35, -3, -6, Blocks.IRON_ORE.getDefaultState());
        structure.fillWithBlocks(world, start, -36, -3, -5, -22, -3, 13, Blocks.STONE.getDefaultState());
        structure.fillWithBlocks(world, start, -36, -3, 35, -34, -3, 37, Blocks.STONE.getDefaultState());
        structure.fillWithBlocks(world, start, -36, -3, 38, -35, -3, 47, Blocks.STONE.getDefaultState());
        structure.fillWithBlocks(world, start, -36, -2, -20, -36, -2, -19, Blocks.IRON_TRAPDOOR.getDefaultState().with(HorizontalBlock.HORIZONTAL_FACING, Direction.WEST).with(TrapDoorBlock.HALF, Half.TOP).with(TrapDoorBlock.WATERLOGGED, false).with(TrapDoorBlock.POWERED, false).with(TrapDoorBlock.OPEN, false));
        structure.fillWithBlocks(world, start, -36, -2, -14, -36, 0, -12, Blocks.COBBLESTONE.getDefaultState());
        structure.fillWithBlocks(world, start, -36, -2, -11, -31, -2, 18, Blocks.STONE.getDefaultState());
        structure.fillWithBlocks(world, start, -36, -2, 44, -36, 0, 49, Blocks.DIRT.getDefaultState());
        structure.fillWithBlocks(world, start, -36, -2, 57, -34, -2, 59, Blocks.GRASS_BLOCK.getDefaultState().with(SnowyDirtBlock.SNOWY, false));
        structure.fillWithBlocks(world, start, -36, -1, -11, -34, -1, -9, Blocks.STONE.getDefaultState());
        structure.fillWithBlocks(world, start, -36, -1, -8, -35, -1, -7, Blocks.DIRT.getDefaultState());
        structure.fillWithBlocks(world, start, -36, -1, -6, -36, -1, -5, Blocks.STONE.getDefaultState());
        structure.fillWithBlocks(world, start, -36, -1, -4, -36, -1, -3, Blocks.DIRT.getDefaultState());
        structure.fillWithBlocks(world, start, -36, -1, 12, -29, -1, 12, Blocks.STONE.getDefaultState());
        structure.fillWithBlocks(world, start, -36, -1, 13, -36, 1, 17, Blocks.DIRT.getDefaultState());
        structure.fillWithBlocks(world, start, -36, -1, 26, -36, -1, 26, Blocks.DIRT.getDefaultState());
        structure.fillWithBlocks(world, start, -36, -1, 27, -36, -1, 32, Blocks.STONE.getDefaultState());
        structure.fillWithBlocks(world, start, -36, -1, 54, -34, -1, 56, Blocks.GRASS_BLOCK.getDefaultState().with(SnowyDirtBlock.SNOWY, false));
        structure.fillWithBlocks(world, start, -36, 0, -52, -36, 0, -51, Blocks.DIRT.getDefaultState());
        structure.fillWithBlocks(world, start, -36, 0, -50, -33, 0, -47, Blocks.GRASS_BLOCK.getDefaultState().with(SnowyDirtBlock.SNOWY, false));
        structure.fillWithBlocks(world, start, -36, 0, -46, -32, 0, -42, Blocks.WATER.getDefaultState());
        structure.fillWithBlocks(world, start, -36, 0, -41, -34, 0, -36, Blocks.WATER.getDefaultState());
        structure.fillWithBlocks(world, start, -36, 0, -35, -36, 0, -33, Blocks.WATER.getDefaultState());
        structure.fillWithBlocks(world, start, -36, 0, -32, -35, 0, -31, Blocks.DIRT.getDefaultState());
        structure.fillWithBlocks(world, start, -36, 0, -30, -36, 0, -30, Blocks.GRASS_BLOCK.getDefaultState().with(SnowyDirtBlock.SNOWY, false));
        structure.fillWithBlocks(world, start, -36, 0, -29, -36, 0, -28, Blocks.GRAVEL.getDefaultState());
        structure.fillWithBlocks(world, start, -36, 0, -27, -35, 0, -27, Blocks.GRASS_BLOCK.getDefaultState().with(SnowyDirtBlock.SNOWY, false));
        structure.fillWithBlocks(world, start, -36, 0, -11, -33, 0, -8, Blocks.DIRT.getDefaultState());
        structure.fillWithBlocks(world, start, -36, 0, -7, -36, 0, -7, Blocks.DIRT.getDefaultState());
        structure.fillWithBlocks(world, start, -36, 0, -6, -36, 2, -6, Blocks.GRAVEL.getDefaultState());
        structure.fillWithBlocks(world, start, -36, 0, -5, -31, 0, 0, Blocks.DIRT.getDefaultState());
        structure.fillWithBlocks(world, start, -36, 0, 10, -36, 0, 11, Blocks.DIRT.getDefaultState());
        structure.fillWithBlocks(world, start, -36, 0, 12, -35, 1, 12, Blocks.GRAVEL.getDefaultState());
        structure.fillWithBlocks(world, start, -36, 0, 18, -35, 1, 18, Blocks.GRAVEL.getDefaultState());
        structure.fillWithBlocks(world, start, -36, 0, 19, -36, 0, 19, Blocks.DIRT.getDefaultState());
        structure.fillWithBlocks(world, start, -36, 0, 20, -36, 2, 20, Blocks.GRAVEL.getDefaultState());
        structure.fillWithBlocks(world, start, -36, 0, 21, -36, 1, 22, Blocks.DIRT.getDefaultState());
        structure.fillWithBlocks(world, start, -36, 0, 23, -35, 1, 23, Blocks.GRAVEL.getDefaultState());
        structure.fillWithBlocks(world, start, -36, 0, 24, -36, 1, 25, Blocks.DIRT.getDefaultState());
        structure.fillWithBlocks(world, start, -36, 0, 26, -36, 2, 26, Blocks.GRAVEL.getDefaultState());
        structure.fillWithBlocks(world, start, -36, 0, 27, -35, 0, 28, Blocks.DIRT.getDefaultState());
        structure.fillWithBlocks(world, start, -36, 0, 29, -36, 0, 30, Blocks.STONE.getDefaultState());
        structure.fillWithBlocks(world, start, -36, 0, 31, -36, 0, 31, Blocks.DIRT.getDefaultState());
        structure.fillWithBlocks(world, start, -36, 0, 33, -34, 0, 49, Blocks.DIRT.getDefaultState());
        structure.fillWithBlocks(world, start, -36, 1, -50, -35, 1, -50, Blocks.GRASS.getDefaultState());
        structure.fillWithBlocks(world, start, -36, 1, -49, -35, 1, -49, Blocks.TALL_GRASS.getDefaultState());
        structure.fillWithBlocks(world, start, -36, 1, -48, -35, 1, -47, Blocks.GRASS.getDefaultState());
        structure.fillWithBlocks(world, start, -36, 1, -32, -35, 1, -31, Blocks.DIRT.getDefaultState());
        structure.fillWithBlocks(world, start, -36, 1, -29, -36, 1, -28, Blocks.GRAVEL.getDefaultState());
        structure.fillWithBlocks(world, start, -36, 1, -14, -36, 1, -12, Blocks.COBBLESTONE.getDefaultState());
        structure.fillWithBlocks(world, start, -36, 1, -11, -33, 1, -8, Blocks.DIRT.getDefaultState());
        structure.fillWithBlocks(world, start, -36, 1, -7, -36, 1, -7, Blocks.DIRT.getDefaultState());
        structure.fillWithBlocks(world, start, -36, 1, 19, -36, 1, 19, Blocks.DIRT.getDefaultState());
        structure.fillWithBlocks(world, start, -36, 1, 27, -36, 1, 27, Blocks.DIRT.getDefaultState());
        structure.fillWithBlocks(world, start, -36, 1, 28, -36, 3, 30, Blocks.GRAVEL.getDefaultState());
        structure.fillWithBlocks(world, start, -36, 1, 31, -35, 1, 32, Blocks.DIRT.getDefaultState());
        structure.fillWithBlocks(world, start, -36, 1, 33, -34, 1, 36, Blocks.GRASS_BLOCK.getDefaultState().with(SnowyDirtBlock.SNOWY, false));
        structure.fillWithBlocks(world, start, -36, 2, -32, -36, 2, -32, Blocks.GRASS_BLOCK.getDefaultState().with(SnowyDirtBlock.SNOWY, false));
        structure.fillWithBlocks(world, start, -36, 2, -30, -36, 2, -30, Blocks.STONE_BRICKS.getDefaultState());
        structure.fillWithBlocks(world, start, -36, 2, -29, -36, 2, -28, Blocks.GRAVEL.getDefaultState());
        structure.fillWithBlocks(world, start, -36, 2, -27, -35, 2, -27, Blocks.STONE_BRICKS.getDefaultState());
        structure.fillWithBlocks(world, start, -36, 2, -26, -34, 2, -24, Blocks.GRASS_BLOCK.getDefaultState().with(SnowyDirtBlock.SNOWY, false));
        structure.fillWithBlocks(world, start, -36, 2, -22, -32, 2, -18, Blocks.SMOOTH_STONE_SLAB.getDefaultState().with(SlabBlock.TYPE, SlabType.DOUBLE).with(SlabBlock.WATERLOGGED, false));
        structure.fillWithBlocks(world, start, -36, 2, -8, -35, 2, -7, Blocks.STONE_BRICKS.getDefaultState());
        structure.fillWithBlocks(world, start, -36, 2, -5, -35, 2, -4, Blocks.GRASS_BLOCK.getDefaultState().with(SnowyDirtBlock.SNOWY, false));
        structure.fillWithBlocks(world, start, -36, 2, 12, -35, 2, 12, Blocks.GRAVEL.getDefaultState());
        structure.fillWithBlocks(world, start, -36, 2, 13, -36, 2, 17, Blocks.COBBLESTONE.getDefaultState());
        structure.fillWithBlocks(world, start, -36, 2, 18, -35, 2, 18, Blocks.GRAVEL.getDefaultState());
        structure.fillWithBlocks(world, start, -36, 2, 19, -36, 2, 19, Blocks.COBBLESTONE.getDefaultState());
        structure.fillWithBlocks(world, start, -36, 2, 21, -36, 2, 22, Blocks.COBBLESTONE.getDefaultState());
        structure.fillWithBlocks(world, start, -36, 2, 24, -35, 2, 25, Blocks.COBBLESTONE.getDefaultState());
        structure.fillWithBlocks(world, start, -36, 2, 31, -36, 2, 32, Blocks.DIRT.getDefaultState());
        structure.fillWithBlocks(world, start, -36, 2, 42, -36, 2, 47, Blocks.GRASS.getDefaultState());
        structure.fillWithBlocks(world, start, -36, 3, -31, -36, 8, -31, Blocks.OAK_LOG.getDefaultState());
        structure.fillWithBlocks(world, start, -36, 3, -26, -35, 3, -25, Blocks.GRASS.getDefaultState());
        structure.fillWithBlocks(world, start, -36, 3, -21, -36, 3, -19, Index.STOOL_OAK.getDefaultState().with(Stool.PILLOW, StoolState.NONE));
        structure.fillWithBlocks(world, start, -36, 3, -17, -36, 3, -11, Blocks.COBBLESTONE.getDefaultState());
        structure.fillWithBlocks(world, start, -36, 3, 10, -36, 3, 11, Blocks.OAK_PLANKS.getDefaultState());
        structure.fillWithBlocks(world, start, -36, 3, 27, -36, 3, 27, Blocks.COBBLESTONE.getDefaultState());
        structure.fillWithBlocks(world, start, -36, 3, 31, -35, 3, 31, Blocks.COBBLESTONE.getDefaultState());
        structure.fillWithBlocks(world, start, -36, 4, -23, -36, 6, -23, Blocks.COBBLESTONE.getDefaultState());
        structure.fillWithBlocks(world, start, -36, 4, -17, -36, 6, -17, Blocks.COBBLESTONE.getDefaultState());
        structure.fillWithBlocks(world, start, -36, 4, -16, -36, 5, -16, Blocks.OAK_PLANKS.getDefaultState());
        structure.fillWithBlocks(world, start, -36, 4, -15, -36, 5, -13, Blocks.GLASS.getDefaultState());
        structure.fillWithBlocks(world, start, -36, 4, -12, -36, 5, -12, Blocks.OAK_PLANKS.getDefaultState());
        structure.fillWithBlocks(world, start, -36, 4, -11, -36, 6, -11, Blocks.COBBLESTONE.getDefaultState());
        structure.fillWithBlocks(world, start, -36, 5, 17, -36, 6, 17, Blocks.OAK_LEAVES.getDefaultState().with(LeavesBlock.PERSISTENT, false).with(LeavesBlock.DISTANCE, 4));
        structure.fillWithBlocks(world, start, -36, 5, 18, -36, 6, 19, Blocks.OAK_LEAVES.getDefaultState().with(LeavesBlock.PERSISTENT, false).with(LeavesBlock.DISTANCE, 3));
        structure.fillWithBlocks(world, start, -36, 5, 20, -36, 6, 20, Blocks.OAK_LEAVES.getDefaultState().with(LeavesBlock.PERSISTENT, false).with(LeavesBlock.DISTANCE, 2));
        structure.fillWithBlocks(world, start, -36, 5, 21, -36, 6, 21, Blocks.OAK_LEAVES.getDefaultState().with(LeavesBlock.PERSISTENT, false).with(LeavesBlock.DISTANCE, 3));
        structure.fillWithBlocks(world, start, -36, 5, 32, -36, 5, 32, Blocks.OAK_LEAVES.getDefaultState().with(LeavesBlock.PERSISTENT, false).with(LeavesBlock.DISTANCE, 2));
        structure.fillWithBlocks(world, start, -36, 5, 33, -36, 5, 34, Blocks.OAK_LEAVES.getDefaultState().with(LeavesBlock.PERSISTENT, false).with(LeavesBlock.DISTANCE, 1));
        structure.fillWithBlocks(world, start, -36, 5, 37, -36, 5, 45, Blocks.OAK_STAIRS.getDefaultState().with(StairsBlock.FACING, Direction.EAST).with(StairsBlock.WATERLOGGED, false).with(StairsBlock.SHAPE, StairsShape.STRAIGHT).with(StairsBlock.HALF, Half.BOTTOM));
        structure.fillWithBlocks(world, start, -36, 6, -33, -36, 7, -33, Blocks.OAK_LEAVES.getDefaultState().with(LeavesBlock.PERSISTENT, false).with(LeavesBlock.DISTANCE, 2));
        structure.fillWithBlocks(world, start, -36, 6, -32, -36, 8, -32, Blocks.OAK_LEAVES.getDefaultState().with(LeavesBlock.PERSISTENT, false).with(LeavesBlock.DISTANCE, 1));
        structure.fillWithBlocks(world, start, -36, 6, -30, -36, 8, -30, Blocks.OAK_LEAVES.getDefaultState().with(LeavesBlock.PERSISTENT, false).with(LeavesBlock.DISTANCE, 1));
        structure.fillWithBlocks(world, start, -36, 6, -29, -36, 7, -29, Blocks.OAK_LEAVES.getDefaultState().with(LeavesBlock.PERSISTENT, false).with(LeavesBlock.DISTANCE, 2));
        structure.fillWithBlocks(world, start, -36, 6, -16, -36, 6, -11, Blocks.COBBLESTONE.getDefaultState());
        structure.fillWithBlocks(world, start, -36, 6, 31, -35, 6, 31, Blocks.OAK_LEAVES.getDefaultState().with(LeavesBlock.PERSISTENT, false).with(LeavesBlock.DISTANCE, 2));
        structure.fillWithBlocks(world, start, -36, 6, 32, -36, 6, 32, Blocks.OAK_LEAVES.getDefaultState().with(LeavesBlock.PERSISTENT, false).with(LeavesBlock.DISTANCE, 1));
        structure.fillWithBlocks(world, start, -36, 6, 33, -36, 6, 34, Blocks.OAK_LOG.getDefaultState());
        structure.fillWithBlocks(world, start, -36, 6, 35, -35, 6, 35, Blocks.OAK_LEAVES.getDefaultState().with(LeavesBlock.PERSISTENT, false).with(LeavesBlock.DISTANCE, 1));
        structure.fillWithBlocks(world, start, -36, 6, 50, -34, 6, 52, Blocks.OAK_PLANKS.getDefaultState());
        structure.fillWithBlocks(world, start, -36, 7, -22, -36, 7, -18, Blocks.OAK_PLANKS.getDefaultState());
        structure.fillWithBlocks(world, start, -36, 7, -16, -36, 7, -12, Blocks.OAK_STAIRS.getDefaultState().with(StairsBlock.FACING, Direction.WEST).with(StairsBlock.WATERLOGGED, false).with(StairsBlock.SHAPE, StairsShape.STRAIGHT).with(StairsBlock.HALF, Half.BOTTOM));
        structure.fillWithBlocks(world, start, -36, 7, 34, -36, 7, 36, Blocks.OAK_LEAVES.getDefaultState().with(LeavesBlock.PERSISTENT, false).with(LeavesBlock.DISTANCE, 1));
        structure.fillWithBlocks(world, start, -36, 7, 37, -36, 8, 37, Blocks.OAK_LEAVES.getDefaultState().with(LeavesBlock.PERSISTENT, false).with(LeavesBlock.DISTANCE, 2));
        structure.fillWithBlocks(world, start, -36, 8, -22, -33, 8, -22, Blocks.OAK_STAIRS.getDefaultState().with(StairsBlock.FACING, Direction.SOUTH).with(StairsBlock.WATERLOGGED, false).with(StairsBlock.SHAPE, StairsShape.STRAIGHT).with(StairsBlock.HALF, Half.BOTTOM));
        structure.fillWithBlocks(world, start, -36, 8, -21, -36, 8, -19, Blocks.COBBLESTONE.getDefaultState());
        structure.fillWithBlocks(world, start, -36, 8, -18, -33, 8, -18, Blocks.OAK_STAIRS.getDefaultState().with(StairsBlock.FACING, Direction.NORTH).with(StairsBlock.WATERLOGGED, false).with(StairsBlock.SHAPE, StairsShape.STRAIGHT).with(StairsBlock.HALF, Half.BOTTOM));
        structure.fillWithBlocks(world, start, -36, 8, -4, -35, 8, -3, Blocks.OAK_PLANKS.getDefaultState());
        structure.fillWithBlocks(world, start, -36, 8, 2, -35, 8, 4, Blocks.HAY_BLOCK.getDefaultState());
        structure.fillWithBlocks(world, start, -36, 8, 5, -35, 8, 7, Blocks.HAY_BLOCK.getDefaultState());
        structure.fillWithBlocks(world, start, -36, 8, 30, -35, 8, 30, Blocks.OAK_LEAVES.getDefaultState().with(LeavesBlock.PERSISTENT, false).with(LeavesBlock.DISTANCE, 3));
        structure.fillWithBlocks(world, start, -36, 8, 31, -35, 8, 31, Blocks.OAK_LEAVES.getDefaultState().with(LeavesBlock.PERSISTENT, false).with(LeavesBlock.DISTANCE, 2));
        structure.fillWithBlocks(world, start, -36, 8, 32, -36, 8, 33, Blocks.OAK_LEAVES.getDefaultState().with(LeavesBlock.PERSISTENT, false).with(LeavesBlock.DISTANCE, 1));
        structure.fillWithBlocks(world, start, -36, 8, 34, -36, 8, 35, Blocks.OAK_LOG.getDefaultState());
        structure.fillWithBlocks(world, start, -36, 9, -32, -36, 9, -32, Blocks.OAK_LEAVES.getDefaultState().with(LeavesBlock.PERSISTENT, false).with(LeavesBlock.DISTANCE, 2));
        structure.fillWithBlocks(world, start, -36, 9, 3, -36, 9, 9, Blocks.HAY_BLOCK.getDefaultState());
        structure.fillWithBlocks(world, start, -36, 9, 30, -36, 9, 30, Blocks.OAK_LEAVES.getDefaultState().with(LeavesBlock.PERSISTENT, false).with(LeavesBlock.DISTANCE, 2));
        structure.fillWithBlocks(world, start, -36, 9, 32, -36, 9, 33, Blocks.OAK_LEAVES.getDefaultState().with(LeavesBlock.PERSISTENT, false).with(LeavesBlock.DISTANCE, 2));
        structure.fillWithBlocks(world, start, -36, 9, 34, -36, 9, 35, Blocks.OAK_LEAVES.getDefaultState().with(LeavesBlock.PERSISTENT, false).with(LeavesBlock.DISTANCE, 1));
        structure.fillWithBlocks(world, start, -36, 10, 29, -36, 10, 29, Blocks.OAK_LEAVES.getDefaultState().with(LeavesBlock.PERSISTENT, false).with(LeavesBlock.DISTANCE, 4));
        structure.fillWithBlocks(world, start, -36, 10, 30, -36, 10, 30, Blocks.OAK_LEAVES.getDefaultState().with(LeavesBlock.PERSISTENT, false).with(LeavesBlock.DISTANCE, 3));
        structure.fillWithBlocks(world, start, -36, 10, 32, -35, 10, 32, Blocks.OAK_LEAVES.getDefaultState().with(LeavesBlock.PERSISTENT, false).with(LeavesBlock.DISTANCE, 3));
        structure.fillWithBlocks(world, start, -36, 10, 33, -36, 10, 33, Blocks.OAK_LEAVES.getDefaultState().with(LeavesBlock.PERSISTENT, false).with(LeavesBlock.DISTANCE, 2));
        structure.fillWithBlocks(world, start, -36, 11, 10, -35, 11, 11, Blocks.OAK_PLANKS.getDefaultState());
        structure.fillWithBlocks(world, start, -36, 11, 29, -36, 11, 29, Blocks.OAK_LEAVES.getDefaultState().with(LeavesBlock.PERSISTENT, false).with(LeavesBlock.DISTANCE, 5));
        structure.fillWithBlocks(world, start, -36, 11, 30, -36, 11, 30, Blocks.OAK_LEAVES.getDefaultState().with(LeavesBlock.PERSISTENT, false).with(LeavesBlock.DISTANCE, 4));
        structure.fillWithBlocks(world, start, -36, 11, 32, -35, 11, 32, Blocks.OAK_LEAVES.getDefaultState().with(LeavesBlock.PERSISTENT, false).with(LeavesBlock.DISTANCE, 4));
        structure.fillWithBlocks(world, start, -36, 11, 33, -36, 11, 33, Blocks.OAK_LEAVES.getDefaultState().with(LeavesBlock.PERSISTENT, false).with(LeavesBlock.DISTANCE, 3));
        structure.fillWithBlocks(world, start, -36, 12, 33, -36, 12, 33, Blocks.OAK_LEAVES.getDefaultState().with(LeavesBlock.PERSISTENT, false).with(LeavesBlock.DISTANCE, 4));
        structure.fillWithBlocks(world, start, -36, 13, 0, -36, 13, 0, Blocks.OAK_PLANKS.getDefaultState());
        structure.fillWithBlocks(world, start, -36, 13, 8, -35, 13, 9, Blocks.OAK_PLANKS.getDefaultState());
        structure.fillWithBlocks(world, start, -36, 14, 0, -35, 14, 8, Blocks.OAK_PLANKS.getDefaultState());
        structure.fillWithBlocks(world, start, -35, -11, 93, -35, -11, 93, Blocks.STONE.getDefaultState());
        structure.fillWithBlocks(world, start, -35, -11, 94, -35, -11, 97, Blocks.DIRT.getDefaultState());
        structure.fillWithBlocks(world, start, -35, -9, -69, -18, -6, -69, Blocks.DIRT.getDefaultState());
        structure.fillWithBlocks(world, start, -35, -9, -68, -32, -9, -31, Blocks.STONE.getDefaultState());
        structure.fillWithBlocks(world, start, -35, -9, -30, -35, -5, -26, Blocks.DIRT.getDefaultState());
        structure.fillWithBlocks(world, start, -35, -9, 33, -33, -9, 65, Blocks.STONE.getDefaultState());
        structure.fillWithBlocks(world, start, -35, -9, 68, -31, -9, 72, Blocks.DIRT.getDefaultState());
        structure.fillWithBlocks(world, start, -35, -9, 73, -18, -9, 90, Blocks.STONE.getDefaultState());
        structure.fillWithBlocks(world, start, -35, -8, -76, -13, -8, -76, Blocks.GRASS_BLOCK.getDefaultState().with(SnowyDirtBlock.SNOWY, false));
        structure.fillWithBlocks(world, start, -35, -8, -38, -35, -8, -38, Blocks.STONE.getDefaultState());
        structure.fillWithBlocks(world, start, -35, -8, -37, -35, -8, -20, Blocks.DIRT.getDefaultState());
        structure.fillWithBlocks(world, start, -35, -8, 6, -19, -8, 22, Blocks.DIRT.getDefaultState());
        structure.fillWithBlocks(world, start, -35, -8, 47, -35, -8, 47, Blocks.DIRT.getDefaultState());
        structure.fillWithBlocks(world, start, -35, -8, 60, -19, -8, 76, Blocks.DIRT.getDefaultState());
        structure.fillWithBlocks(world, start, -35, -8, 80, -28, -8, 87, Blocks.STONE.getDefaultState());
        structure.fillWithBlocks(world, start, -35, -6, -74, -34, -6, -73, Blocks.GRASS_BLOCK.getDefaultState().with(SnowyDirtBlock.SNOWY, false));
        structure.fillWithBlocks(world, start, -35, -5, -69, 0, -5, -69, Blocks.GRASS_BLOCK.getDefaultState().with(SnowyDirtBlock.SNOWY, false));
        structure.fillWithBlocks(world, start, -35, -5, 86, -34, -5, 87, Blocks.DIRT.getDefaultState());
        structure.fillWithBlocks(world, start, -35, -4, -68, -32, -4, -64, Blocks.GRASS_BLOCK.getDefaultState().with(SnowyDirtBlock.SNOWY, false));
        structure.fillWithBlocks(world, start, -35, -4, -63, -34, -4, -61, Blocks.GRASS_BLOCK.getDefaultState().with(SnowyDirtBlock.SNOWY, false));
        structure.fillWithBlocks(world, start, -35, -4, -18, -34, -4, -18, Blocks.DIRT.getDefaultState());
        structure.fillWithBlocks(world, start, -35, -4, -17, -33, -4, -15, Blocks.STONE.getDefaultState());
        structure.fillWithBlocks(world, start, -35, -4, 8, -30, -1, 8, Blocks.STONE.getDefaultState());
        structure.fillWithBlocks(world, start, -35, -4, 9, -34, -4, 12, Blocks.GRAVEL.getDefaultState());
        structure.fillWithBlocks(world, start, -35, -3, -34, -29, -3, -28, Blocks.STONE.getDefaultState());
        structure.fillWithBlocks(world, start, -35, -3, -27, -32, -3, -24, Blocks.STONE.getDefaultState());
        structure.fillWithBlocks(world, start, -35, -3, -11, -32, -3, -8, Blocks.STONE.getDefaultState());
        structure.fillWithBlocks(world, start, -35, -3, 48, -25, -3, 58, Blocks.DIRT.getDefaultState());
        structure.fillWithBlocks(world, start, -35, -2, -22, -35, 1, -16, Blocks.COBBLESTONE.getDefaultState());
        structure.fillWithBlocks(world, start, -35, -2, -15, -32, -2, 21, Blocks.STONE.getDefaultState());
        structure.fillWithBlocks(world, start, -35, -2, 22, -34, -2, 23, Blocks.STONE.getDefaultState());
        structure.fillWithBlocks(world, start, -35, -2, 24, -35, -1, 25, Blocks.DIRT.getDefaultState());
        structure.fillWithBlocks(world, start, -35, -2, 26, -32, -2, 32, Blocks.STONE.getDefaultState());
        structure.fillWithBlocks(world, start, -35, -2, 38, -35, -2, 45, Blocks.COBBLESTONE.getDefaultState());
        structure.fillWithBlocks(world, start, -35, -1, -14, -35, 0, -13, Blocks.DIRT.getDefaultState());
        structure.fillWithBlocks(world, start, -35, -1, -12, -32, -1, -9, Blocks.STONE.getDefaultState());
        structure.fillWithBlocks(world, start, -35, -1, -6, -35, 1, -6, Blocks.DIRT.getDefaultState());
        structure.fillWithBlocks(world, start, -35, -1, -5, -34, -1, -4, Blocks.STONE.getDefaultState());
        structure.fillWithBlocks(world, start, -35, -1, 3, -35, 1, 3, Blocks.DIRT.getDefaultState());
        structure.fillWithBlocks(world, start, -35, -1, 4, -29, -1, 12, Blocks.STONE.getDefaultState());
        structure.fillWithBlocks(world, start, -35, -1, 13, -35, 1, 13, Blocks.DIRT.getDefaultState());
        structure.fillWithBlocks(world, start, -35, -1, 14, -35, -1, 14, Blocks.STONE.getDefaultState());
        structure.fillWithBlocks(world, start, -35, -1, 16, -33, -1, 16, Blocks.STONE.getDefaultState());
        structure.fillWithBlocks(world, start, -35, -1, 17, -34, -1, 22, Blocks.DIRT.getDefaultState());
        structure.fillWithBlocks(world, start, -35, -1, 23, -35, 1, 23, Blocks.GRAVEL.getDefaultState());
        structure.fillWithBlocks(world, start, -35, -1, 26, -34, -1, 27, Blocks.DIRT.getDefaultState());
        structure.fillWithBlocks(world, start, -35, -1, 28, -35, 1, 31, Blocks.DIRT.getDefaultState());
        structure.fillWithBlocks(world, start, -35, -1, 32, -34, -1, 32, Blocks.STONE.getDefaultState());
        structure.fillWithBlocks(world, start, -35, 0, -54, -35, 0, -52, Blocks.GRASS_BLOCK.getDefaultState().with(SnowyDirtBlock.SNOWY, false));
        structure.fillWithBlocks(world, start, -35, 0, -35, -31, 0, -31, Blocks.DIRT.getDefaultState());
        structure.fillWithBlocks(world, start, -35, 0, -30, -34, 0, -29, Blocks.GRASS_BLOCK.getDefaultState().with(SnowyDirtBlock.SNOWY, false));
        structure.fillWithBlocks(world, start, -35, 0, -28, -35, 2, -28, Blocks.GRAVEL.getDefaultState());
        structure.fillWithBlocks(world, start, -35, 0, -15, -29, 0, -9, Blocks.DIRT.getDefaultState());
        structure.fillWithBlocks(world, start, -35, 0, -7, -35, 1, 9, Blocks.DIRT.getDefaultState());
        structure.fillWithBlocks(world, start, -35, 0, 10, -34, 0, 10, Blocks.STONE.getDefaultState());
        structure.fillWithBlocks(world, start, -35, 0, 11, -35, 0, 11, Blocks.DIRT.getDefaultState());
        structure.fillWithBlocks(world, start, -35, 0, 14, -35, 2, 14, Blocks.GRAVEL.getDefaultState());
        structure.fillWithBlocks(world, start, -35, 0, 16, -35, 2, 16, Blocks.GRAVEL.getDefaultState());
        structure.fillWithBlocks(world, start, -35, 0, 17, -35, 0, 17, Blocks.DIRT.getDefaultState());
        structure.fillWithBlocks(world, start, -35, 0, 19, -33, 0, 21, Blocks.DIRT.getDefaultState());
        structure.fillWithBlocks(world, start, -35, 0, 22, -35, 1, 23, Blocks.GRAVEL.getDefaultState());
        structure.fillWithBlocks(world, start, -35, 0, 24, -35, 0, 25, Blocks.GRASS_BLOCK.getDefaultState().with(SnowyDirtBlock.SNOWY, false));
        structure.fillWithBlocks(world, start, -35, 0, 26, -32, 0, 29, Blocks.DIRT.getDefaultState());
        structure.fillWithBlocks(world, start, -35, 0, 32, -35, 0, 50, Blocks.DIRT.getDefaultState());
        structure.fillWithBlocks(world, start, -35, 0, 52, -34, 0, 53, Blocks.DIRT.getDefaultState());
        structure.fillWithBlocks(world, start, -35, 1, -55, -35, 7, -55, Blocks.OAK_LOG.getDefaultState());
        structure.fillWithBlocks(world, start, -35, 1, -51, -35, 7, -51, Blocks.OAK_LOG.getDefaultState());
        structure.fillWithBlocks(world, start, -35, 1, -35, -31, 1, -31, Blocks.DIRT.getDefaultState());
        structure.fillWithBlocks(world, start, -35, 1, -30, -35, 1, -29, Blocks.GRASS.getDefaultState());
        structure.fillWithBlocks(world, start, -35, 1, -15, -29, 1, -9, Blocks.DIRT.getDefaultState());
        structure.fillWithBlocks(world, start, -35, 1, 17, -35, 1, 17, Blocks.DIRT.getDefaultState());
        structure.fillWithBlocks(world, start, -35, 1, 19, -33, 1, 21, Blocks.DIRT.getDefaultState());
        structure.fillWithBlocks(world, start, -35, 1, 26, -33, 1, 28, Blocks.DIRT.getDefaultState());
        structure.fillWithBlocks(world, start, -35, 1, 37, -35, 1, 45, Blocks.DIRT.getDefaultState());
        structure.fillWithBlocks(world, start, -35, 1, 46, -33, 1, 48, Blocks.GRASS_BLOCK.getDefaultState().with(SnowyDirtBlock.SNOWY, false));
        structure.fillWithBlocks(world, start, -35, 1, 49, -33, 1, 49, Blocks.STONE_BRICK_STAIRS.getDefaultState().with(StairsBlock.FACING, Direction.SOUTH).with(StairsBlock.WATERLOGGED, false).with(StairsBlock.SHAPE, StairsShape.STRAIGHT).with(StairsBlock.HALF, Half.BOTTOM));
        structure.fillWithBlocks(world, start, -35, 1, 50, -33, 3, 50, Blocks.STONE_BRICKS.getDefaultState());
        structure.fillWithBlocks(world, start, -35, 1, 52, -33, 3, 52, Blocks.STONE_BRICKS.getDefaultState());
        structure.fillWithBlocks(world, start, -35, 1, 53, -33, 1, 53, Blocks.STONE_BRICK_STAIRS.getDefaultState().with(StairsBlock.FACING, Direction.NORTH).with(StairsBlock.WATERLOGGED, false).with(StairsBlock.SHAPE, StairsShape.STRAIGHT).with(StairsBlock.HALF, Half.BOTTOM));
        structure.fillWithBlocks(world, start, -35, 2, -35, -33, 2, -33, Blocks.GRASS_BLOCK.getDefaultState().with(SnowyDirtBlock.SNOWY, false));
        structure.fillWithBlocks(world, start, -35, 2, -32, -35, 2, -31, Blocks.GRASS_BLOCK.getDefaultState().with(SnowyDirtBlock.SNOWY, false));
        structure.fillWithBlocks(world, start, -35, 2, -30, -34, 2, -29, Blocks.STONE_BRICKS.getDefaultState());
        structure.fillWithBlocks(world, start, -35, 2, -23, -33, 2, -17, Blocks.SMOOTH_STONE_SLAB.getDefaultState().with(SlabBlock.TYPE, SlabType.DOUBLE).with(SlabBlock.WATERLOGGED, false));
        structure.fillWithBlocks(world, start, -35, 2, -16, -32, 2, -13, Blocks.GRASS_BLOCK.getDefaultState().with(SnowyDirtBlock.SNOWY, false));
        structure.fillWithBlocks(world, start, -35, 2, -12, -33, 2, -9, Blocks.GRASS_BLOCK.getDefaultState().with(SnowyDirtBlock.SNOWY, false));
        structure.fillWithBlocks(world, start, -35, 2, -2, -31, 2, 2, Blocks.DIRT.getDefaultState());
        structure.fillWithBlocks(world, start, -35, 2, 4, -30, 2, 10, Blocks.DIRT.getDefaultState());
        structure.fillWithBlocks(world, start, -35, 2, 19, -35, 2, 21, Blocks.COBBLESTONE.getDefaultState());
        structure.fillWithBlocks(world, start, -35, 2, 23, -35, 2, 29, Blocks.COBBLESTONE.getDefaultState());
        structure.fillWithBlocks(world, start, -35, 2, 31, -35, 3, 31, Blocks.COBBLESTONE.getDefaultState());
        structure.fillWithBlocks(world, start, -35, 2, 35, -35, 2, 36, Blocks.GRASS.getDefaultState());
        structure.fillWithBlocks(world, start, -35, 2, 37, -35, 5, 45, Blocks.COBBLESTONE.getDefaultState());
        structure.fillWithBlocks(world, start, -35, 3, -34, -35, 3, -33, Blocks.TALL_GRASS.getDefaultState());
        structure.fillWithBlocks(world, start, -35, 3, -32, -35, 3, -31, Blocks.GRASS.getDefaultState());
        structure.fillWithBlocks(world, start, -35, 3, -17, -32, 3, -17, Blocks.COBBLESTONE.getDefaultState());
        structure.fillWithBlocks(world, start, -35, 3, -5, -28, 3, -5, Blocks.GRASS.getDefaultState());
        structure.fillWithBlocks(world, start, -35, 3, 10, -34, 3, 10, Blocks.DIRT.getDefaultState());
        structure.fillWithBlocks(world, start, -35, 3, 27, -35, 3, 31, Blocks.COBBLESTONE.getDefaultState());
        structure.fillWithBlocks(world, start, -35, 4, -34, -35, 4, -33, Blocks.TALL_GRASS.getDefaultState());
        structure.fillWithBlocks(world, start, -35, 4, -23, -35, 5, -23, Blocks.OAK_PLANKS.getDefaultState());
        structure.fillWithBlocks(world, start, -35, 4, -17, -35, 5, -17, Blocks.OAK_PLANKS.getDefaultState());
        structure.fillWithBlocks(world, start, -35, 4, 50, -33, 5, 50, Blocks.STONE_BRICKS.getDefaultState());
        structure.fillWithBlocks(world, start, -35, 4, 52, -33, 5, 52, Blocks.STONE_BRICKS.getDefaultState());
        structure.fillWithBlocks(world, start, -35, 5, -52, -35, 6, -52, Blocks.OAK_PLANKS.getDefaultState());
        structure.fillWithBlocks(world, start, -35, 5, 36, -29, 5, 36, Blocks.OAK_STAIRS.getDefaultState().with(StairsBlock.FACING, Direction.SOUTH).with(StairsBlock.WATERLOGGED, false).with(StairsBlock.SHAPE, StairsShape.STRAIGHT).with(StairsBlock.HALF, Half.BOTTOM));
        structure.fillWithBlocks(world, start, -35, 5, 46, -24, 5, 46, Blocks.OAK_STAIRS.getDefaultState().with(StairsBlock.FACING, Direction.NORTH).with(StairsBlock.WATERLOGGED, false).with(StairsBlock.SHAPE, StairsShape.STRAIGHT).with(StairsBlock.HALF, Half.BOTTOM));
        structure.fillWithBlocks(world, start, -35, 5, 49, -33, 5, 49, Blocks.STONE_BRICK_STAIRS.getDefaultState().with(StairsBlock.FACING, Direction.SOUTH).with(StairsBlock.WATERLOGGED, false).with(StairsBlock.SHAPE, StairsShape.STRAIGHT).with(StairsBlock.HALF, Half.TOP));
        structure.fillWithBlocks(world, start, -35, 5, 53, -33, 5, 53, Blocks.STONE_BRICK_STAIRS.getDefaultState().with(StairsBlock.FACING, Direction.NORTH).with(StairsBlock.WATERLOGGED, false).with(StairsBlock.SHAPE, StairsShape.STRAIGHT).with(StairsBlock.HALF, Half.TOP));
        structure.fillWithBlocks(world, start, -35, 6, -33, -35, 7, -33, Blocks.OAK_LEAVES.getDefaultState().with(LeavesBlock.PERSISTENT, false).with(LeavesBlock.DISTANCE, 3));
        structure.fillWithBlocks(world, start, -35, 6, -32, -35, 7, -32, Blocks.OAK_LEAVES.getDefaultState().with(LeavesBlock.PERSISTENT, false).with(LeavesBlock.DISTANCE, 2));
        structure.fillWithBlocks(world, start, -35, 6, -31, -35, 8, -31, Blocks.OAK_LEAVES.getDefaultState().with(LeavesBlock.PERSISTENT, false).with(LeavesBlock.DISTANCE, 1));
        structure.fillWithBlocks(world, start, -35, 6, -30, -35, 7, -30, Blocks.OAK_LEAVES.getDefaultState().with(LeavesBlock.PERSISTENT, false).with(LeavesBlock.DISTANCE, 2));
        structure.fillWithBlocks(world, start, -35, 6, -29, -35, 7, -29, Blocks.OAK_LEAVES.getDefaultState().with(LeavesBlock.PERSISTENT, false).with(LeavesBlock.DISTANCE, 3));
        structure.fillWithBlocks(world, start, -35, 6, 32, -35, 6, 33, Blocks.OAK_LEAVES.getDefaultState().with(LeavesBlock.PERSISTENT, false).with(LeavesBlock.DISTANCE, 1));
        structure.fillWithBlocks(world, start, -35, 6, 38, -35, 6, 44, Blocks.OAK_STAIRS.getDefaultState().with(StairsBlock.FACING, Direction.EAST).with(StairsBlock.WATERLOGGED, false).with(StairsBlock.SHAPE, StairsShape.STRAIGHT).with(StairsBlock.HALF, Half.BOTTOM));
        structure.fillWithBlocks(world, start, -35, 7, -23, -33, 7, -23, Blocks.OAK_STAIRS.getDefaultState().with(StairsBlock.FACING, Direction.SOUTH).with(StairsBlock.WATERLOGGED, false).with(StairsBlock.SHAPE, StairsShape.STRAIGHT).with(StairsBlock.HALF, Half.BOTTOM));
        structure.fillWithBlocks(world, start, -35, 7, -17, -33, 7, -17, Blocks.OAK_STAIRS.getDefaultState().with(StairsBlock.FACING, Direction.NORTH).with(StairsBlock.WATERLOGGED, false).with(StairsBlock.SHAPE, StairsShape.STRAIGHT).with(StairsBlock.HALF, Half.BOTTOM));
        structure.fillWithBlocks(world, start, -35, 7, 31, -35, 7, 31, Blocks.OAK_LEAVES.getDefaultState().with(LeavesBlock.PERSISTENT, false).with(LeavesBlock.DISTANCE, 1));
        structure.fillWithBlocks(world, start, -35, 7, 33, -35, 7, 34, Blocks.OAK_LEAVES.getDefaultState().with(LeavesBlock.PERSISTENT, false).with(LeavesBlock.DISTANCE, 1));
        structure.fillWithBlocks(world, start, -35, 7, 35, -35, 7, 36, Blocks.OAK_LEAVES.getDefaultState().with(LeavesBlock.PERSISTENT, false).with(LeavesBlock.DISTANCE, 2));
        structure.fillWithBlocks(world, start, -35, 8, -21, -35, 8, -19, Blocks.OAK_PLANKS.getDefaultState());
        structure.fillWithBlocks(world, start, -35, 8, 1, -35, 8, 4, Blocks.HAY_BLOCK.getDefaultState());
        structure.fillWithBlocks(world, start, -35, 8, 8, -34, 8, 9, Blocks.HAY_BLOCK.getDefaultState());
        structure.fillWithBlocks(world, start, -35, 8, 32, -35, 8, 32, Blocks.OAK_LEAVES.getDefaultState().with(LeavesBlock.PERSISTENT, false).with(LeavesBlock.DISTANCE, 1));
        structure.fillWithBlocks(world, start, -35, 8, 34, -35, 8, 35, Blocks.OAK_LEAVES.getDefaultState().with(LeavesBlock.PERSISTENT, false).with(LeavesBlock.DISTANCE, 1));
        structure.fillWithBlocks(world, start, -35, 9, 30, -35, 9, 30, Blocks.OAK_LEAVES.getDefaultState().with(LeavesBlock.PERSISTENT, false).with(LeavesBlock.DISTANCE, 3));
        structure.fillWithBlocks(world, start, -35, 9, 31, -35, 9, 32, Blocks.OAK_LEAVES.getDefaultState().with(LeavesBlock.PERSISTENT, false).with(LeavesBlock.DISTANCE, 2));
        structure.fillWithBlocks(world, start, -35, 9, 34, -35, 9, 35, Blocks.OAK_LEAVES.getDefaultState().with(LeavesBlock.PERSISTENT, false).with(LeavesBlock.DISTANCE, 2));
        structure.fillWithBlocks(world, start, -35, 10, 30, -35, 10, 30, Blocks.OAK_LEAVES.getDefaultState().with(LeavesBlock.PERSISTENT, false).with(LeavesBlock.DISTANCE, 4));
        structure.fillWithBlocks(world, start, -35, 10, 31, -35, 10, 32, Blocks.OAK_LEAVES.getDefaultState().with(LeavesBlock.PERSISTENT, false).with(LeavesBlock.DISTANCE, 3));
        structure.fillWithBlocks(world, start, -35, 10, 33, -35, 10, 34, Blocks.OAK_LEAVES.getDefaultState().with(LeavesBlock.PERSISTENT, false).with(LeavesBlock.DISTANCE, 2));
        structure.fillWithBlocks(world, start, -35, 11, 31, -35, 11, 32, Blocks.OAK_LEAVES.getDefaultState().with(LeavesBlock.PERSISTENT, false).with(LeavesBlock.DISTANCE, 4));
        structure.fillWithBlocks(world, start, -35, 11, 33, -35, 11, 34, Blocks.OAK_LEAVES.getDefaultState().with(LeavesBlock.PERSISTENT, false).with(LeavesBlock.DISTANCE, 3));
        structure.fillWithBlocks(world, start, -35, 12, 9, -34, 12, 10, Blocks.OAK_PLANKS.getDefaultState());
        structure.fillWithBlocks(world, start, -35, 12, 33, -35, 12, 34, Blocks.OAK_LEAVES.getDefaultState().with(LeavesBlock.PERSISTENT, false).with(LeavesBlock.DISTANCE, 4));
        structure.fillWithBlocks(world, start, -35, 13, 0, -34, 13, 9, Blocks.OAK_PLANKS.getDefaultState());
        structure.fillWithBlocks(world, start, -34, -11, 93, -33, -11, 94, Blocks.STONE.getDefaultState());
        structure.fillWithBlocks(world, start, -34, -11, 95, -32, -11, 97, Blocks.DIRT.getDefaultState());
        structure.fillWithBlocks(world, start, -34, -10, 103, -33, -10, 103, Blocks.CAVE_AIR.getDefaultState());
        structure.fillWithBlocks(world, start, -34, -9, -77, -10, -9, -77, Blocks.GRASS_BLOCK.getDefaultState().with(SnowyDirtBlock.SNOWY, false));
        structure.fillWithBlocks(world, start, -34, -9, -76, -27, -9, -69, Blocks.DIRT.getDefaultState());
        structure.fillWithBlocks(world, start, -34, -9, -30, -21, -9, -17, Blocks.STONE.getDefaultState());
        structure.fillWithBlocks(world, start, -34, -9, 16, -31, -9, 32, Blocks.DIRT.getDefaultState());
        structure.fillWithBlocks(world, start, -34, -9, 67, -29, -9, 72, Blocks.DIRT.getDefaultState());
        structure.fillWithBlocks(world, start, -34, -8, -40, -31, -8, -37, Blocks.STONE.getDefaultState());
        structure.fillWithBlocks(world, start, -34, -8, -36, -34, -8, -20, Blocks.DIRT.getDefaultState());
        structure.fillWithBlocks(world, start, -34, -8, 47, -33, -8, 48, Blocks.DIRT.getDefaultState());
        structure.fillWithBlocks(world, start, -34, -8, 49, -34, -8, 58, Blocks.STONE.getDefaultState());
        structure.fillWithBlocks(world, start, -34, -8, 59, -17, -8, 76, Blocks.DIRT.getDefaultState());
        structure.fillWithBlocks(world, start, -34, -8, 77, -34, -7, 78, Blocks.DIRT.getDefaultState());
        structure.fillWithBlocks(world, start, -34, -8, 79, -26, -8, 87, Blocks.STONE.getDefaultState());
        structure.fillWithBlocks(world, start, -34, -6, 91, -33, -6, 92, Blocks.GRASS_BLOCK.getDefaultState().with(SnowyDirtBlock.SNOWY, false));
        structure.fillWithBlocks(world, start, -34, -5, -72, -33, -5, -69, Blocks.GRASS_BLOCK.getDefaultState().with(SnowyDirtBlock.SNOWY, false));
        structure.fillWithBlocks(world, start, -34, -5, 88, -33, -5, 90, Blocks.GRASS_BLOCK.getDefaultState().with(SnowyDirtBlock.SNOWY, false));
        structure.fillWithBlocks(world, start, -34, -4, -26, -34, -3, -25, Blocks.STONE.getDefaultState());
        structure.fillWithBlocks(world, start, -34, -4, -24, -34, -4, -18, Blocks.DIRT.getDefaultState());
        structure.fillWithBlocks(world, start, -34, -4, -7, -21, -4, 7, Blocks.STONE.getDefaultState());
        structure.fillWithBlocks(world, start, -34, -3, -60, -30, -3, -56, Blocks.DIRT.getDefaultState());
        structure.fillWithBlocks(world, start, -34, -3, -35, -28, -3, -29, Blocks.STONE.getDefaultState());
        structure.fillWithBlocks(world, start, -34, -3, -22, -33, -3, -12, Blocks.SMOOTH_STONE_SLAB.getDefaultState().with(SlabBlock.TYPE, SlabType.DOUBLE).with(SlabBlock.WATERLOGGED, false));
        structure.fillWithBlocks(world, start, -34, -3, -7, -22, -3, 13, Blocks.STONE.getDefaultState());
        structure.fillWithBlocks(world, start, -34, -3, 38, -30, -3, 44, Blocks.COBBLESTONE.getDefaultState());
        structure.fillWithBlocks(world, start, -34, -3, 45, -32, -3, 47, Blocks.STONE.getDefaultState());
        structure.fillWithBlocks(world, start, -34, -2, -22, -32, -2, -18, Blocks.DIRT.getDefaultState());
        structure.fillWithBlocks(world, start, -34, -2, -17, -33, -1, -17, Blocks.COBBLESTONE.getDefaultState());
        structure.fillWithBlocks(world, start, -34, -2, -16, -32, -2, 21, Blocks.STONE.getDefaultState());
        structure.fillWithBlocks(world, start, -34, -2, 24, -31, -2, 27, Blocks.STONE.getDefaultState());
        structure.fillWithBlocks(world, start, -34, -2, 33, -33, -2, 35, Blocks.STONE.getDefaultState());
        structure.fillWithBlocks(world, start, -34, -2, 37, -30, -2, 37, Blocks.COBBLESTONE.getDefaultState());
        structure.fillWithBlocks(world, start, -34, -2, 38, -30, -2, 44, Blocks.DIRT.getDefaultState());
        structure.fillWithBlocks(world, start, -34, -2, 45, -25, -2, 45, Blocks.COBBLESTONE.getDefaultState());
        structure.fillWithBlocks(world, start, -34, -1, -22, -30, -1, -18, Blocks.DIRT.getDefaultState());
        structure.fillWithBlocks(world, start, -34, -1, -16, -34, 1, -14, Blocks.DIRT.getDefaultState());
        structure.fillWithBlocks(world, start, -34, -1, -13, -33, -1, -9, Blocks.STONE.getDefaultState());
        structure.fillWithBlocks(world, start, -34, -1, -8, -34, -1, -8, Blocks.DIRT.getDefaultState());
        structure.fillWithBlocks(world, start, -34, -1, -7, -34, -1, 16, Blocks.STONE.getDefaultState());
        structure.fillWithBlocks(world, start, -34, -1, 23, -30, -1, 27, Blocks.DIRT.getDefaultState());
        structure.fillWithBlocks(world, start, -34, -1, 28, -34, -1, 32, Blocks.STONE.getDefaultState());
        structure.fillWithBlocks(world, start, -34, 0, -54, -32, 0, -54, Blocks.DIRT.getDefaultState());
        structure.fillWithBlocks(world, start, -34, 0, -52, -33, 0, -51, Blocks.DIRT.getDefaultState());
        structure.fillWithBlocks(world, start, -34, 0, -28, -34, 0, -28, Blocks.GRASS_BLOCK.getDefaultState().with(SnowyDirtBlock.SNOWY, false));
        structure.fillWithBlocks(world, start, -34, 0, -27, -34, 2, -27, Blocks.GRAVEL.getDefaultState());
        structure.fillWithBlocks(world, start, -34, 0, -26, -32, 0, -24, Blocks.DIRT.getDefaultState());
        structure.fillWithBlocks(world, start, -34, 0, -22, -30, 0, -18, Blocks.DIRT.getDefaultState());
        structure.fillWithBlocks(world, start, -34, 0, -17, -33, 1, -17, Blocks.COBBLESTONE.getDefaultState());
        structure.fillWithBlocks(world, start, -34, 0, -7, -34, 0, -6, Blocks.GRAVEL.getDefaultState());
        structure.fillWithBlocks(world, start, -34, 0, 1, -34, 0, 3, Blocks.STONE.getDefaultState());
        structure.fillWithBlocks(world, start, -34, 0, 4, -32, 0, 6, Blocks.DIRT.getDefaultState());
        structure.fillWithBlocks(world, start, -34, 0, 8, -34, 0, 8, Blocks.DIRT.getDefaultState());
        structure.fillWithBlocks(world, start, -34, 0, 9, -34, 0, 10, Blocks.STONE.getDefaultState());
        structure.fillWithBlocks(world, start, -34, 0, 11, -31, 0, 14, Blocks.DIRT.getDefaultState());
        structure.fillWithBlocks(world, start, -34, 0, 15, -32, 0, 29, Blocks.DIRT.getDefaultState());
        structure.fillWithBlocks(world, start, -34, 0, 30, -33, 0, 31, Blocks.DIRT.getDefaultState());
        structure.fillWithBlocks(world, start, -34, 0, 32, -34, 0, 32, Blocks.GRAVEL.getDefaultState());
        structure.fillWithBlocks(world, start, -34, 0, 50, -33, 0, 50, Blocks.DIRT.getDefaultState());
        structure.fillWithBlocks(world, start, -34, 1, -55, -32, 1, -55, Blocks.STONE_BRICK_STAIRS.getDefaultState().with(StairsBlock.FACING, Direction.SOUTH).with(StairsBlock.WATERLOGGED, false).with(StairsBlock.SHAPE, StairsShape.STRAIGHT).with(StairsBlock.HALF, Half.BOTTOM));
        structure.fillWithBlocks(world, start, -34, 1, -54, -32, 3, -54, Blocks.STONE_BRICKS.getDefaultState());
        structure.fillWithBlocks(world, start, -34, 1, -52, -32, 3, -52, Blocks.STONE_BRICKS.getDefaultState());
        structure.fillWithBlocks(world, start, -34, 1, -51, -32, 1, -51, Blocks.STONE_BRICK_STAIRS.getDefaultState().with(StairsBlock.FACING, Direction.NORTH).with(StairsBlock.WATERLOGGED, false).with(StairsBlock.SHAPE, StairsShape.STRAIGHT).with(StairsBlock.HALF, Half.BOTTOM));
        structure.fillWithBlocks(world, start, -34, 1, -49, -33, 1, -48, Blocks.GRASS.getDefaultState());
        structure.fillWithBlocks(world, start, -34, 1, -26, -32, 1, -24, Blocks.DIRT.getDefaultState());
        structure.fillWithBlocks(world, start, -34, 1, -22, -30, 1, -18, Blocks.DIRT.getDefaultState());
        structure.fillWithBlocks(world, start, -34, 1, -7, -34, 1, -6, Blocks.GRAVEL.getDefaultState());
        structure.fillWithBlocks(world, start, -34, 1, 12, -32, 1, 21, Blocks.DIRT.getDefaultState());
        structure.fillWithBlocks(world, start, -34, 1, 22, -33, 1, 28, Blocks.DIRT.getDefaultState());
        structure.fillWithBlocks(world, start, -34, 1, 29, -34, 3, 31, Blocks.GRAVEL.getDefaultState());
        structure.fillWithBlocks(world, start, -34, 1, 32, -34, 1, 32, Blocks.GRAVEL.getDefaultState());
        structure.fillWithBlocks(world, start, -34, 1, 37, -33, 1, 37, Blocks.DIRT.getDefaultState());
        structure.fillWithBlocks(world, start, -34, 1, 38, -30, 1, 44, Blocks.OAK_PLANKS.getDefaultState());
        structure.fillWithBlocks(world, start, -34, 1, 45, -26, 1, 45, Blocks.DIRT.getDefaultState());
        structure.fillWithBlocks(world, start, -34, 2, -31, -29, 2, -31, Blocks.GRASS_BLOCK.getDefaultState().with(SnowyDirtBlock.SNOWY, false));
        structure.fillWithBlocks(world, start, -34, 2, -28, -34, 2, -28, Blocks.STONE_BRICKS.getDefaultState());
        structure.fillWithBlocks(world, start, -34, 2, -8, -34, 2, -8, Blocks.STONE_BRICKS.getDefaultState());
        structure.fillWithBlocks(world, start, -34, 2, -7, -34, 2, -6, Blocks.GRAVEL.getDefaultState());
        structure.fillWithBlocks(world, start, -34, 2, -5, -33, 2, -4, Blocks.GRASS_BLOCK.getDefaultState().with(SnowyDirtBlock.SNOWY, false));
        structure.fillWithBlocks(world, start, -34, 2, -3, -34, 2, 12, Blocks.DIRT.getDefaultState());
        structure.fillWithBlocks(world, start, -34, 2, 13, -34, 2, 27, Blocks.GRASS_BLOCK.getDefaultState().with(SnowyDirtBlock.SNOWY, false));
        structure.fillWithBlocks(world, start, -34, 2, 32, -33, 2, 32, Blocks.GRAVEL.getDefaultState());
        structure.fillWithBlocks(world, start, -34, 2, 37, -33, 3, 37, Blocks.COBBLESTONE.getDefaultState());
        structure.fillWithBlocks(world, start, -34, 2, 38, -34, 2, 39, Blocks.BARREL.getDefaultState().with(BarrelBlock.PROPERTY_FACING, Direction.EAST).with(BarrelBlock.PROPERTY_OPEN, false));
        structure.fillWithBlocks(world, start, -34, 2, 45, -24, 5, 45, Blocks.COBBLESTONE.getDefaultState());
        structure.fillWithBlocks(world, start, -34, 2, 47, -34, 2, 47, Blocks.GRASS.getDefaultState());
        structure.fillWithBlocks(world, start, -34, 3, -35, -34, 3, -33, Blocks.GRASS.getDefaultState());
        structure.fillWithBlocks(world, start, -34, 3, -4, -33, 3, -4, Blocks.DANDELION.getDefaultState());
        structure.fillWithBlocks(world, start, -34, 3, -3, -34, 6, -3, Blocks.OAK_PLANKS.getDefaultState());
        structure.fillWithBlocks(world, start, -34, 3, -2, -34, 3, -1, Blocks.DIRT.getDefaultState());
        structure.fillWithBlocks(world, start, -34, 3, 1, -34, 3, 3, Blocks.DIRT.getDefaultState());
        structure.fillWithBlocks(world, start, -34, 3, 5, -34, 3, 7, Blocks.DIRT.getDefaultState());
        structure.fillWithBlocks(world, start, -34, 3, 9, -34, 3, 10, Blocks.DIRT.getDefaultState());
        structure.fillWithBlocks(world, start, -34, 3, 17, -34, 3, 18, Blocks.GRASS.getDefaultState());
        structure.fillWithBlocks(world, start, -34, 3, 22, -34, 3, 23, Blocks.GRASS.getDefaultState());
        structure.fillWithBlocks(world, start, -34, 3, 26, -33, 3, 27, Blocks.GRASS.getDefaultState());
        structure.fillWithBlocks(world, start, -34, 4, -54, -32, 5, -54, Blocks.STONE_BRICKS.getDefaultState());
        structure.fillWithBlocks(world, start, -34, 4, -52, -32, 5, -52, Blocks.STONE_BRICKS.getDefaultState());
        structure.fillWithBlocks(world, start, -34, 4, -23, -34, 5, -23, Blocks.GLASS.getDefaultState());
        structure.fillWithBlocks(world, start, -34, 4, -17, -34, 5, -17, Blocks.GLASS.getDefaultState());
        structure.fillWithBlocks(world, start, -34, 4, -13, -34, 5, -13, Blocks.OAK_LEAVES.getDefaultState().with(LeavesBlock.PERSISTENT, false).with(LeavesBlock.DISTANCE, 3));
        structure.fillWithBlocks(world, start, -34, 4, -12, -34, 5, -12, Blocks.OAK_LEAVES.getDefaultState().with(LeavesBlock.PERSISTENT, false).with(LeavesBlock.DISTANCE, 2));
        structure.fillWithBlocks(world, start, -34, 4, -11, -34, 5, -11, Blocks.OAK_LEAVES.getDefaultState().with(LeavesBlock.PERSISTENT, false).with(LeavesBlock.DISTANCE, 3));
        structure.fillWithBlocks(world, start, -34, 4, -2, -34, 10, -2, Blocks.OAK_LOG.getDefaultState());
        structure.fillWithBlocks(world, start, -34, 4, 2, -34, 6, 2, Blocks.OAK_LOG.getDefaultState());
        structure.fillWithBlocks(world, start, -34, 4, 6, -34, 6, 6, Blocks.OAK_LOG.getDefaultState());
        structure.fillWithBlocks(world, start, -34, 4, 10, -34, 10, 10, Blocks.OAK_LOG.getDefaultState());
        structure.fillWithBlocks(world, start, -34, 4, 37, -29, 5, 37, Blocks.COBBLESTONE.getDefaultState());
        structure.fillWithBlocks(world, start, -34, 5, -55, -32, 5, -55, Blocks.STONE_BRICK_STAIRS.getDefaultState().with(StairsBlock.FACING, Direction.SOUTH).with(StairsBlock.WATERLOGGED, false).with(StairsBlock.SHAPE, StairsShape.STRAIGHT).with(StairsBlock.HALF, Half.TOP));
        structure.fillWithBlocks(world, start, -34, 5, -51, -32, 5, -51, Blocks.STONE_BRICK_STAIRS.getDefaultState().with(StairsBlock.FACING, Direction.NORTH).with(StairsBlock.WATERLOGGED, false).with(StairsBlock.SHAPE, StairsShape.STRAIGHT).with(StairsBlock.HALF, Half.TOP));
        structure.fillWithBlocks(world, start, -34, 5, 38, -29, 5, 45, Blocks.COBBLESTONE.getDefaultState());
        structure.fillWithBlocks(world, start, -34, 6, -54, -32, 6, -52, Blocks.OAK_PLANKS.getDefaultState());
        structure.fillWithBlocks(world, start, -34, 6, -32, -34, 7, -32, Blocks.OAK_LEAVES.getDefaultState().with(LeavesBlock.PERSISTENT, false).with(LeavesBlock.DISTANCE, 3));
        structure.fillWithBlocks(world, start, -34, 6, -31, -34, 7, -31, Blocks.OAK_LEAVES.getDefaultState().with(LeavesBlock.PERSISTENT, false).with(LeavesBlock.DISTANCE, 2));
        structure.fillWithBlocks(world, start, -34, 6, -30, -34, 7, -30, Blocks.OAK_LEAVES.getDefaultState().with(LeavesBlock.PERSISTENT, false).with(LeavesBlock.DISTANCE, 3));
        structure.fillWithBlocks(world, start, -34, 6, -23, -32, 6, -17, Blocks.COBBLESTONE.getDefaultState());
        structure.fillWithBlocks(world, start, -34, 6, -1, -34, 6, 1, Blocks.OAK_PLANKS.getDefaultState());
        structure.fillWithBlocks(world, start, -34, 6, 3, -34, 6, 5, Blocks.OAK_PLANKS.getDefaultState());
        structure.fillWithBlocks(world, start, -34, 6, 7, -34, 6, 9, Blocks.OAK_PLANKS.getDefaultState());
        structure.fillWithBlocks(world, start, -34, 6, 32, -34, 6, 33, Blocks.OAK_LEAVES.getDefaultState().with(LeavesBlock.PERSISTENT, false).with(LeavesBlock.DISTANCE, 2));
        structure.fillWithBlocks(world, start, -34, 6, 37, -30, 6, 37, Blocks.OAK_STAIRS.getDefaultState().with(StairsBlock.FACING, Direction.SOUTH).with(StairsBlock.WATERLOGGED, false).with(StairsBlock.SHAPE, StairsShape.STRAIGHT).with(StairsBlock.HALF, Half.BOTTOM));
        structure.fillWithBlocks(world, start, -34, 6, 38, -34, 6, 44, Blocks.COBBLESTONE.getDefaultState());
        structure.fillWithBlocks(world, start, -34, 6, 45, -25, 6, 45, Blocks.OAK_STAIRS.getDefaultState().with(StairsBlock.FACING, Direction.NORTH).with(StairsBlock.WATERLOGGED, false).with(StairsBlock.SHAPE, StairsShape.STRAIGHT).with(StairsBlock.HALF, Half.BOTTOM));
        structure.fillWithBlocks(world, start, -34, 7, -1, -33, 7, 1, Blocks.COBBLESTONE.getDefaultState());
        structure.fillWithBlocks(world, start, -34, 7, 33, -34, 7, 34, Blocks.OAK_LEAVES.getDefaultState().with(LeavesBlock.PERSISTENT, false).with(LeavesBlock.DISTANCE, 2));
        structure.fillWithBlocks(world, start, -34, 7, 35, -34, 7, 36, Blocks.OAK_LEAVES.getDefaultState().with(LeavesBlock.PERSISTENT, false).with(LeavesBlock.DISTANCE, 3));
        structure.fillWithBlocks(world, start, -34, 7, 39, -34, 7, 43, Blocks.OAK_STAIRS.getDefaultState().with(StairsBlock.FACING, Direction.EAST).with(StairsBlock.WATERLOGGED, false).with(StairsBlock.SHAPE, StairsShape.STRAIGHT).with(StairsBlock.HALF, Half.BOTTOM));
        structure.fillWithBlocks(world, start, -34, 8, -4, -33, 8, -3, Blocks.OAK_PLANKS.getDefaultState());
        structure.fillWithBlocks(world, start, -34, 8, -1, -34, 8, 1, Blocks.HAY_BLOCK.getDefaultState());
        structure.fillWithBlocks(world, start, -34, 8, 5, -34, 8, 6, Blocks.HAY_BLOCK.getDefaultState());
        structure.fillWithBlocks(world, start, -34, 8, 30, -34, 9, 30, Blocks.OAK_LEAVES.getDefaultState().with(LeavesBlock.PERSISTENT, false).with(LeavesBlock.DISTANCE, 4));
        structure.fillWithBlocks(world, start, -34, 8, 31, -34, 9, 31, Blocks.OAK_LEAVES.getDefaultState().with(LeavesBlock.PERSISTENT, false).with(LeavesBlock.DISTANCE, 3));
        structure.fillWithBlocks(world, start, -34, 8, 32, -34, 8, 32, Blocks.OAK_LEAVES.getDefaultState().with(LeavesBlock.PERSISTENT, false).with(LeavesBlock.DISTANCE, 2));
        structure.fillWithBlocks(world, start, -34, 8, 34, -34, 8, 35, Blocks.OAK_LEAVES.getDefaultState().with(LeavesBlock.PERSISTENT, false).with(LeavesBlock.DISTANCE, 2));
        structure.fillWithBlocks(world, start, -34, 9, 8, -34, 9, 9, Blocks.HAY_BLOCK.getDefaultState());
        structure.fillWithBlocks(world, start, -34, 9, 32, -34, 9, 32, Blocks.OAK_LEAVES.getDefaultState().with(LeavesBlock.PERSISTENT, false).with(LeavesBlock.DISTANCE, 3));
        structure.fillWithBlocks(world, start, -34, 9, 34, -34, 9, 35, Blocks.OAK_LEAVES.getDefaultState().with(LeavesBlock.PERSISTENT, false).with(LeavesBlock.DISTANCE, 3));
        structure.fillWithBlocks(world, start, -34, 10, 31, -34, 10, 32, Blocks.OAK_LEAVES.getDefaultState().with(LeavesBlock.PERSISTENT, false).with(LeavesBlock.DISTANCE, 4));
        structure.fillWithBlocks(world, start, -34, 10, 33, -34, 10, 34, Blocks.OAK_LEAVES.getDefaultState().with(LeavesBlock.PERSISTENT, false).with(LeavesBlock.DISTANCE, 3));
        structure.fillWithBlocks(world, start, -34, 11, 10, -33, 11, 11, Blocks.OAK_PLANKS.getDefaultState());
        structure.fillWithBlocks(world, start, -34, 12, 0, -33, 12, 10, Blocks.OAK_PLANKS.getDefaultState());
        structure.fillWithBlocks(world, start, -34, 14, 0, -34, 14, 8, Blocks.OAK_STAIRS.getDefaultState().with(StairsBlock.FACING, Direction.WEST).with(StairsBlock.WATERLOGGED, false).with(StairsBlock.SHAPE, StairsShape.STRAIGHT).with(StairsBlock.HALF, Half.BOTTOM));
        structure.fillWithBlocks(world, start, -33, -10, -78, -8, -10, -78, Blocks.GRASS_BLOCK.getDefaultState().with(SnowyDirtBlock.SNOWY, false));
        structure.fillWithBlocks(world, start, -33, -10, -77, -29, -10, -73, Blocks.DIRT.getDefaultState());
        structure.fillWithBlocks(world, start, -33, -9, -1, -18, -9, 15, Blocks.STONE.getDefaultState());
        structure.fillWithBlocks(world, start, -33, -9, 66, -27, -9, 72, Blocks.DIRT.getDefaultState());
        structure.fillWithBlocks(world, start, -33, -9, 103, -33, -9, 104, Blocks.CAVE_AIR.getDefaultState());
        structure.fillWithBlocks(world, start, -33, -8, -50, -33, -5, -50, Blocks.DIRT.getDefaultState());
        structure.fillWithBlocks(world, start, -33, -8, -36, -33, -8, -36, Blocks.STONE.getDefaultState());
        structure.fillWithBlocks(world, start, -33, -8, -35, -33, -8, -21, Blocks.DIRT.getDefaultState());
        structure.fillWithBlocks(world, start, -33, -8, -20, -29, -8, -16, Blocks.STONE.getDefaultState());
        structure.fillWithBlocks(world, start, -33, -8, 49, -33, -8, 49, Blocks.DIRT.getDefaultState());
        structure.fillWithBlocks(world, start, -33, -8, 50, -33, -8, 57, Blocks.STONE.getDefaultState());
        structure.fillWithBlocks(world, start, -33, -8, 58, -15, -8, 76, Blocks.DIRT.getDefaultState());
        structure.fillWithBlocks(world, start, -33, -8, 77, -33, -5, 77, Blocks.DIRT.getDefaultState());
        structure.fillWithBlocks(world, start, -33, -8, 78, -24, -8, 87, Blocks.STONE.getDefaultState());
        structure.fillWithBlocks(world, start, -33, -6, -74, -33, -6, -73, Blocks.GRASS_BLOCK.getDefaultState().with(SnowyDirtBlock.SNOWY, false));
        structure.fillWithBlocks(world, start, -33, -5, 86, -32, -5, 87, Blocks.DIRT.getDefaultState());
        structure.fillWithBlocks(world, start, -33, -4, -63, -33, -4, -58, Blocks.DIRT.getDefaultState());
        structure.fillWithBlocks(world, start, -33, -4, -57, -33, -4, -27, Blocks.STONE.getDefaultState());
        structure.fillWithBlocks(world, start, -33, -4, -26, -32, -4, -24, Blocks.DIRT.getDefaultState());
        structure.fillWithBlocks(world, start, -33, -4, -23, -33, -3, -23, Blocks.STONE.getDefaultState());
        structure.fillWithBlocks(world, start, -33, -4, -22, -33, -4, -20, Blocks.DIRT.getDefaultState());
        structure.fillWithBlocks(world, start, -33, -4, -19, -28, -4, -14, Blocks.STONE.getDefaultState());
        structure.fillWithBlocks(world, start, -33, -4, -13, -32, -4, -12, Blocks.DIRT.getDefaultState());
        structure.fillWithBlocks(world, start, -33, -4, -11, -18, -4, 5, Blocks.STONE.getDefaultState());
        structure.fillWithBlocks(world, start, -33, -4, 9, -33, -4, 9, Blocks.STONE.getDefaultState());
        structure.fillWithBlocks(world, start, -33, -4, 10, -33, -4, 13, Blocks.GRAVEL.getDefaultState());
        structure.fillWithBlocks(world, start, -33, -4, 14, -24, -4, 23, Blocks.STONE.getDefaultState());
        structure.fillWithBlocks(world, start, -33, -4, 37, -33, -4, 53, Blocks.STONE.getDefaultState());
        structure.fillWithBlocks(world, start, -33, -4, 54, -27, -4, 60, Blocks.DIRT.getDefaultState());
        structure.fillWithBlocks(world, start, -33, -3, -63, -33, -3, -61, Blocks.GRASS_BLOCK.getDefaultState().with(SnowyDirtBlock.SNOWY, false));
        structure.fillWithBlocks(world, start, -33, -3, -50, -33, -3, -47, Blocks.STONE.getDefaultState());
        structure.fillWithBlocks(world, start, -33, -3, -36, -27, -3, -30, Blocks.STONE.getDefaultState());
        structure.fillWithBlocks(world, start, -33, -3, 35, -33, -3, 37, Blocks.STONE.getDefaultState());
        structure.fillWithBlocks(world, start, -33, -2, -60, -32, -2, -59, Blocks.GRASS_BLOCK.getDefaultState().with(SnowyDirtBlock.SNOWY, false));
        structure.fillWithBlocks(world, start, -33, -2, -58, -25, -2, -50, Blocks.DIRT.getDefaultState());
        structure.fillWithBlocks(world, start, -33, -2, -49, -31, -2, -42, Blocks.DIRT.getDefaultState());
        structure.fillWithBlocks(world, start, -33, -2, -24, -33, 1, -24, Blocks.DIRT.getDefaultState());
        structure.fillWithBlocks(world, start, -33, -2, 22, -33, -2, 35, Blocks.STONE.getDefaultState());
        structure.fillWithBlocks(world, start, -33, -2, 36, -29, -2, 36, Blocks.DIRT.getDefaultState());
        structure.fillWithBlocks(world, start, -33, -2, 57, -32, -2, 58, Blocks.GRASS_BLOCK.getDefaultState().with(SnowyDirtBlock.SNOWY, false));
        structure.fillWithBlocks(world, start, -33, -1, -27, -30, -1, -24, Blocks.DIRT.getDefaultState());
        structure.fillWithBlocks(world, start, -33, -1, -16, -33, -1, -15, Blocks.STONE.getDefaultState());
        structure.fillWithBlocks(world, start, -33, -1, -14, -33, -1, -14, Blocks.DIRT.getDefaultState());
        structure.fillWithBlocks(world, start, -33, -1, -8, -33, 0, -7, Blocks.DIRT.getDefaultState());
        structure.fillWithBlocks(world, start, -33, -1, -6, -33, -1, 17, Blocks.STONE.getDefaultState());
        structure.fillWithBlocks(world, start, -33, -1, 18, -33, -1, 29, Blocks.DIRT.getDefaultState());
        structure.fillWithBlocks(world, start, -33, -1, 30, -33, -1, 31, Blocks.STONE.getDefaultState());
        structure.fillWithBlocks(world, start, -33, -1, 32, -33, -1, 32, Blocks.DIRT.getDefaultState());
        structure.fillWithBlocks(world, start, -33, -1, 33, -33, 1, 35, Blocks.GRAVEL.getDefaultState());
        structure.fillWithBlocks(world, start, -33, -1, 36, -33, 0, 50, Blocks.DIRT.getDefaultState());
        structure.fillWithBlocks(world, start, -33, -1, 54, -31, -1, 56, Blocks.GRASS_BLOCK.getDefaultState().with(SnowyDirtBlock.SNOWY, false));
        structure.fillWithBlocks(world, start, -33, 0, -41, -29, 0, -31, Blocks.DIRT.getDefaultState());
        structure.fillWithBlocks(world, start, -33, 0, -30, -33, 0, -29, Blocks.GRAVEL.getDefaultState());
        structure.fillWithBlocks(world, start, -33, 0, -28, -33, 0, -27, Blocks.GRASS_BLOCK.getDefaultState().with(SnowyDirtBlock.SNOWY, false));
        structure.fillWithBlocks(world, start, -33, 0, -16, -29, 0, -9, Blocks.DIRT.getDefaultState());
        structure.fillWithBlocks(world, start, -33, 0, -6, -33, 2, -6, Blocks.GRAVEL.getDefaultState());
        structure.fillWithBlocks(world, start, -33, 0, 1, -20, 0, 14, Blocks.DIRT.getDefaultState());
        structure.fillWithBlocks(world, start, -33, 0, 32, -33, 1, 35, Blocks.GRAVEL.getDefaultState());
        structure.fillWithBlocks(world, start, -33, 0, 52, -33, 0, 53, Blocks.DIRT.getDefaultState());
        structure.fillWithBlocks(world, start, -33, 1, -50, -32, 1, -49, Blocks.GRASS.getDefaultState());
        structure.fillWithBlocks(world, start, -33, 1, -47, -32, 1, -47, Blocks.GRASS.getDefaultState());
        structure.fillWithBlocks(world, start, -33, 1, -41, -29, 1, -31, Blocks.DIRT.getDefaultState());
        structure.fillWithBlocks(world, start, -33, 1, -30, -33, 1, -29, Blocks.GRAVEL.getDefaultState());
        structure.fillWithBlocks(world, start, -33, 1, -16, -29, 1, -9, Blocks.DIRT.getDefaultState());
        structure.fillWithBlocks(world, start, -33, 1, -7, -33, 1, -7, Blocks.DIRT.getDefaultState());
        structure.fillWithBlocks(world, start, -33, 1, 29, -33, 1, 31, Blocks.DIRT.getDefaultState());
        structure.fillWithBlocks(world, start, -33, 2, -41, -29, 2, -36, Blocks.GRASS_BLOCK.getDefaultState().with(SnowyDirtBlock.SNOWY, false));
        structure.fillWithBlocks(world, start, -33, 2, -32, -32, 2, -31, Blocks.GRASS_BLOCK.getDefaultState().with(SnowyDirtBlock.SNOWY, false));
        structure.fillWithBlocks(world, start, -33, 2, -30, -33, 2, -29, Blocks.GRAVEL.getDefaultState());
        structure.fillWithBlocks(world, start, -33, 2, -28, -33, 2, -27, Blocks.STONE_BRICKS.getDefaultState());
        structure.fillWithBlocks(world, start, -33, 2, -26, -31, 2, -24, Blocks.GRASS_BLOCK.getDefaultState().with(SnowyDirtBlock.SNOWY, false));
        structure.fillWithBlocks(world, start, -33, 2, -8, -33, 2, -7, Blocks.STONE_BRICKS.getDefaultState());
        structure.fillWithBlocks(world, start, -33, 2, -3, -24, 2, -3, Blocks.GRASS_BLOCK.getDefaultState().with(SnowyDirtBlock.SNOWY, false));
        structure.fillWithBlocks(world, start, -33, 2, 3, -30, 2, 10, Blocks.DIRT.getDefaultState());
        structure.fillWithBlocks(world, start, -33, 2, 11, -31, 2, 13, Blocks.GRASS_BLOCK.getDefaultState().with(SnowyDirtBlock.SNOWY, false));
        structure.fillWithBlocks(world, start, -33, 2, 14, -33, 2, 25, Blocks.DIRT.getDefaultState());
        structure.fillWithBlocks(world, start, -33, 2, 26, -31, 2, 28, Blocks.GRASS_BLOCK.getDefaultState().with(SnowyDirtBlock.SNOWY, false));
        structure.fillWithBlocks(world, start, -33, 2, 29, -32, 2, 29, Blocks.COBBLESTONE.getDefaultState());
        structure.fillWithBlocks(world, start, -33, 2, 30, -33, 2, 31, Blocks.DIRT.getDefaultState());
        structure.fillWithBlocks(world, start, -33, 2, 46, -32, 2, 48, Blocks.GRASS.getDefaultState());
        structure.fillWithBlocks(world, start, -33, 3, -38, -33, 3, -38, Blocks.GRASS.getDefaultState());
        structure.fillWithBlocks(world, start, -33, 3, -36, -33, 3, -36, Blocks.GRASS.getDefaultState());
        structure.fillWithBlocks(world, start, -33, 3, -34, -30, 3, -34, Blocks.GRASS.getDefaultState());
        structure.fillWithBlocks(world, start, -33, 3, -3, -31, 3, -3, Blocks.GRASS.getDefaultState());
        structure.fillWithBlocks(world, start, -33, 3, -2, -31, 3, -2, Blocks.OAK_LOG.getDefaultState());
