package mod.arcalitegames.odyssey.world.structure.structures.ruins.cathedral;

import mod.arcalitegames.buildersaddition.Index;
import mod.arcalitegames.buildersaddition.blocks.Stool;
import mod.arcalitegames.buildersaddition.state.StoolState;
import mod.arcalitegames.odyssey.world.structure.StructureBase;
import net.minecraft.block.BarrelBlock;
import net.minecraft.block.Blocks;
import net.minecraft.block.CampfireBlock;
import net.minecraft.block.ChestBlock;
import net.minecraft.block.ComposterBlock;
import net.minecraft.block.FourWayBlock;
import net.minecraft.block.LeavesBlock;
import net.minecraft.block.NetherWartBlock;
import net.minecraft.block.SlabBlock;
import net.minecraft.block.SnowyDirtBlock;
import net.minecraft.block.StairsBlock;
import net.minecraft.block.VineBlock;
import net.minecraft.state.properties.ChestType;
import net.minecraft.state.properties.Half;
import net.minecraft.state.properties.SlabType;
import net.minecraft.state.properties.StairsShape;
import net.minecraft.util.Direction;
import net.minecraft.util.math.BlockPos;
import net.minecraft.world.World;

public class CathedralComponents
{

	public static BlockPos start;
    public static World world;
    public static StructureBase structure;

    public static void init(World worldIn, BlockPos blockPos, StructureBase structureIn)
    {
        world = worldIn; start = blockPos; structure = structureIn;
    }
    
    public static void generatePart1()
    {
        structure.setBlockState(world, Blocks.GRASS_BLOCK.getDefaultState().with(SnowyDirtBlock.SNOWY, false), 0, 0, 0, start);
        structure.setBlockState(world, Blocks.GRASS_BLOCK.getDefaultState().with(SnowyDirtBlock.SNOWY, false), 4, 2, 20, start);
        structure.setBlockState(world, Blocks.GRASS_BLOCK.getDefaultState().with(SnowyDirtBlock.SNOWY, false), 5, 1, 15, start);
        structure.setBlockState(world, Blocks.GRASS_BLOCK.getDefaultState().with(SnowyDirtBlock.SNOWY, false), 5, 3, 18, start);
        structure.setBlockState(world, Blocks.GRASS_BLOCK.getDefaultState().with(SnowyDirtBlock.SNOWY, false), 6, 2, 14, start);
        structure.setBlockState(world, Blocks.GRASS_BLOCK.getDefaultState().with(SnowyDirtBlock.SNOWY, false), 6, 3, 15, start);
        structure.setBlockState(world, Blocks.GRASS.getDefaultState(), 6, 7, 31, start);
        structure.setBlockState(world, Blocks.GRASS_BLOCK.getDefaultState().with(SnowyDirtBlock.SNOWY, false), 7, 1, 11, start);
        structure.setBlockState(world, Blocks.GRASS_BLOCK.getDefaultState().with(SnowyDirtBlock.SNOWY, false), 7, 2, 12, start);
        structure.setBlockState(world, Blocks.GRASS_BLOCK.getDefaultState().with(SnowyDirtBlock.SNOWY, false), 7, 3, 13, start);
        structure.setBlockState(world, Blocks.GRASS_BLOCK.getDefaultState().with(SnowyDirtBlock.SNOWY, false), 7, 4, 14, start);
        structure.setBlockState(world, Blocks.GRASS.getDefaultState(), 7, 7, 21, start);
        structure.setBlockState(world, Blocks.GRASS_BLOCK.getDefaultState().with(SnowyDirtBlock.SNOWY, false), 8, 0, 8, start);
        structure.setBlockState(world, Blocks.GRASS_BLOCK.getDefaultState().with(SnowyDirtBlock.SNOWY, false), 8, 1, 9, start);
        structure.setBlockState(world, Blocks.STONE.getDefaultState(), 8, 1, 41, start);
        structure.setBlockState(world, Blocks.GRASS_BLOCK.getDefaultState().with(SnowyDirtBlock.SNOWY, false), 8, 2, 10, start);
        structure.setBlockState(world, Blocks.GRASS_BLOCK.getDefaultState().with(SnowyDirtBlock.SNOWY, false), 8, 2, 56, start);
        structure.setBlockState(world, Blocks.GRASS_BLOCK.getDefaultState().with(SnowyDirtBlock.SNOWY, false), 8, 3, 11, start);
        structure.setBlockState(world, Blocks.GRASS_BLOCK.getDefaultState().with(SnowyDirtBlock.SNOWY, false), 8, 4, 12, start);
        structure.setBlockState(world, Blocks.GRASS_BLOCK.getDefaultState().with(SnowyDirtBlock.SNOWY, false), 8, 5, 15, start);
        structure.setBlockState(world, Blocks.GRASS.getDefaultState(), 8, 7, 30, start);
        structure.setBlockState(world, Blocks.GRASS.getDefaultState(), 8, 7, 37, start);
        structure.setBlockState(world, Blocks.GRASS_BLOCK.getDefaultState().with(SnowyDirtBlock.SNOWY, false), 9, 1, 8, start);
        structure.setBlockState(world, Blocks.GRASS_BLOCK.getDefaultState().with(SnowyDirtBlock.SNOWY, false), 9, 2, 9, start);
        structure.setBlockState(world, Blocks.GRASS_BLOCK.getDefaultState().with(SnowyDirtBlock.SNOWY, false), 9, 3, 10, start);
        structure.setBlockState(world, Blocks.GRASS_BLOCK.getDefaultState().with(SnowyDirtBlock.SNOWY, false), 9, 4, 11, start);
        structure.setBlockState(world, Blocks.GRASS.getDefaultState(), 9, 7, 21, start);
        structure.setBlockState(world, Blocks.DANDELION.getDefaultState(), 9, 7, 32, start);
        structure.setBlockState(world, Blocks.GRASS.getDefaultState(), 9, 7, 34, start);
        structure.setBlockState(world, Blocks.GRASS.getDefaultState(), 9, 7, 42, start);
        structure.setBlockState(world, Blocks.STONE.getDefaultState(), 10, 1, 30, start);
        structure.setBlockState(world, Blocks.GRASS_BLOCK.getDefaultState().with(SnowyDirtBlock.SNOWY, false), 10, 2, 8, start);
        structure.setBlockState(world, Blocks.GRASS_BLOCK.getDefaultState().with(SnowyDirtBlock.SNOWY, false), 10, 2, 59, start);
        structure.setBlockState(world, Blocks.GRASS_BLOCK.getDefaultState().with(SnowyDirtBlock.SNOWY, false), 10, 3, 9, start);
        structure.setBlockState(world, Blocks.GRASS_BLOCK.getDefaultState().with(SnowyDirtBlock.SNOWY, false), 10, 4, 10, start);
        structure.setBlockState(world, Blocks.GRASS.getDefaultState(), 10, 7, 36, start);
        structure.setBlockState(world, Blocks.GRASS.getDefaultState(), 10, 7, 39, start);
        structure.setBlockState(world, Blocks.GRASS.getDefaultState(), 10, 7, 45, start);
        structure.setBlockState(world, Blocks.GRASS_BLOCK.getDefaultState().with(SnowyDirtBlock.SNOWY, false), 11, 1, 7, start);
        structure.setBlockState(world, Blocks.GRASS_BLOCK.getDefaultState().with(SnowyDirtBlock.SNOWY, false), 11, 3, 8, start);
        structure.setBlockState(world, Blocks.GRASS_BLOCK.getDefaultState().with(SnowyDirtBlock.SNOWY, false), 11, 4, 9, start);
        structure.setBlockState(world, Blocks.GRASS.getDefaultState(), 11, 7, 15, start);
        structure.setBlockState(world, Blocks.GRASS.getDefaultState(), 11, 7, 21, start);
        structure.setBlockState(world, Blocks.POPPY.getDefaultState(), 11, 7, 34, start);
        structure.setBlockState(world, Blocks.GRASS.getDefaultState(), 11, 7, 35, start);
        structure.setBlockState(world, Blocks.GRASS.getDefaultState(), 11, 7, 48, start);
        structure.setBlockState(world, Blocks.GRASS_BLOCK.getDefaultState().with(SnowyDirtBlock.SNOWY, false), 12, 1, 61, start);
        structure.setBlockState(world, Blocks.GRASS_BLOCK.getDefaultState().with(SnowyDirtBlock.SNOWY, false), 12, 2, 7, start);
        structure.setBlockState(world, Blocks.GRASS.getDefaultState(), 12, 7, 18, start);
        structure.setBlockState(world, Blocks.GRASS.getDefaultState(), 12, 7, 32, start);
        structure.setBlockState(world, Blocks.GRASS.getDefaultState(), 12, 7, 34, start);
        structure.setBlockState(world, Blocks.GRASS.getDefaultState(), 12, 7, 43, start);
        structure.setBlockState(world, Blocks.GRASS.getDefaultState(), 12, 7, 51, start);
        structure.setBlockState(world, Blocks.GRASS_BLOCK.getDefaultState().with(SnowyDirtBlock.SNOWY, false), 13, 1, 6, start);
        structure.setBlockState(world, Blocks.GRASS_BLOCK.getDefaultState().with(SnowyDirtBlock.SNOWY, false), 13, 3, 7, start);
        structure.setBlockState(world, Blocks.GRASS.getDefaultState(), 13, 7, 14, start);
        structure.setBlockState(world, Blocks.GRASS.getDefaultState(), 13, 7, 23, start);
        structure.setBlockState(world, Blocks.GRASS.getDefaultState(), 13, 7, 26, start);
        structure.setBlockState(world, Blocks.GRASS.getDefaultState(), 13, 7, 29, start);
        structure.setBlockState(world, Blocks.GRASS.getDefaultState(), 13, 7, 38, start);
        structure.setBlockState(world, Blocks.GRASS.getDefaultState(), 13, 7, 47, start);
        structure.setBlockState(world, Blocks.GRASS_BLOCK.getDefaultState().with(SnowyDirtBlock.SNOWY, false), 14, 5, 10, start);
        structure.setBlockState(world, Blocks.GRASS.getDefaultState(), 14, 7, 22, start);
        structure.setBlockState(world, Blocks.GRASS.getDefaultState(), 14, 7, 35, start);
        structure.setBlockState(world, Blocks.GRASS.getDefaultState(), 14, 7, 55, start);
        structure.setBlockState(world, Blocks.GRASS.getDefaultState(), 15, 7, 11, start);
        structure.setBlockState(world, Blocks.GRASS.getDefaultState(), 15, 7, 13, start);
        structure.setBlockState(world, Blocks.GRASS.getDefaultState(), 15, 7, 20, start);
        structure.setBlockState(world, Blocks.GRASS.getDefaultState(), 15, 7, 27, start);
        structure.setBlockState(world, Blocks.GRASS.getDefaultState(), 15, 7, 33, start);
        structure.setBlockState(world, Blocks.GRASS.getDefaultState(), 15, 7, 53, start);
        structure.setBlockState(world, Blocks.GRASS.getDefaultState(), 16, 7, 31, start);
        structure.setBlockState(world, Blocks.POPPY.getDefaultState(), 16, 7, 33, start);
        structure.setBlockState(world, Blocks.GRASS.getDefaultState(), 16, 7, 38, start);
        structure.setBlockState(world, Blocks.GRASS.getDefaultState(), 16, 7, 52, start);
        structure.setBlockState(world, Blocks.GRASS.getDefaultState(), 16, 7, 55, start);
        structure.setBlockState(world, Blocks.STONE.getDefaultState(), 17, 1, 27, start);
        structure.setBlockState(world, Blocks.GRASS.getDefaultState(), 17, 7, 15, start);
        structure.setBlockState(world, Blocks.GRASS.getDefaultState(), 17, 7, 17, start);
        structure.setBlockState(world, Blocks.POPPY.getDefaultState(), 17, 7, 29, start);
        structure.setBlockState(world, Blocks.GRASS.getDefaultState(), 17, 7, 33, start);
        structure.setBlockState(world, Blocks.GRASS_BLOCK.getDefaultState().with(SnowyDirtBlock.SNOWY, false), 18, 4, 16, start);
        structure.setBlockState(world, Blocks.DANDELION.getDefaultState(), 18, 7, 14, start);
        structure.setBlockState(world, Blocks.GRASS.getDefaultState(), 18, 7, 32, start);
        structure.setBlockState(world, Blocks.POPPY.getDefaultState(), 18, 7, 35, start);
        structure.setBlockState(world, Blocks.GRASS.getDefaultState(), 18, 7, 37, start);
        structure.setBlockState(world, Blocks.GRASS.getDefaultState(), 18, 7, 46, start);
        structure.setBlockState(world, Blocks.GRASS.getDefaultState(), 18, 7, 51, start);
        structure.setBlockState(world, Blocks.GRASS.getDefaultState(), 19, 7, 10, start);
        structure.setBlockState(world, Blocks.GRASS.getDefaultState(), 19, 7, 13, start);
        structure.setBlockState(world, Blocks.GRASS.getDefaultState(), 19, 7, 20, start);
        structure.setBlockState(world, Blocks.GRASS.getDefaultState(), 19, 7, 35, start);
        structure.setBlockState(world, Blocks.GRASS.getDefaultState(), 19, 7, 54, start);
        structure.setBlockState(world, Blocks.GRASS.getDefaultState(), 19, 7, 56, start);
        structure.setBlockState(world, Blocks.STONE.getDefaultState(), 20, 1, 25, start);
        structure.setBlockState(world, Blocks.GRASS_BLOCK.getDefaultState().with(SnowyDirtBlock.SNOWY, false), 20, 4, 17, start);
        structure.setBlockState(world, Blocks.GRASS.getDefaultState(), 20, 5, 17, start);
        structure.setBlockState(world, Blocks.DIRT.getDefaultState(), 20, 5, 43, start);
        structure.setBlockState(world, Blocks.GRASS.getDefaultState(), 20, 7, 34, start);
        structure.setBlockState(world, Blocks.DANDELION.getDefaultState(), 20, 7, 49, start);
        structure.setBlockState(world, Blocks.TALL_GRASS.getDefaultState(), 20, 8, 39, start);
        structure.setBlockState(world, Blocks.POPPY.getDefaultState(), 21, 7, 39, start);
        structure.setBlockState(world, Blocks.AZURE_BLUET.getDefaultState(), 21, 7, 46, start);
        structure.setBlockState(world, Blocks.TALL_GRASS.getDefaultState(), 21, 7, 48, start);
        structure.setBlockState(world, Blocks.GRASS.getDefaultState(), 21, 7, 56, start);
        structure.setBlockState(world, Blocks.TALL_GRASS.getDefaultState(), 21, 8, 48, start);
        structure.setBlockState(world, Blocks.GRASS.getDefaultState(), 22, 7, 15, start);
        structure.setBlockState(world, Blocks.GRASS.getDefaultState(), 22, 7, 18, start);
        structure.setBlockState(world, Blocks.AIR.getDefaultState(), 22, 7, 25, start);
        structure.setBlockState(world, Blocks.AIR.getDefaultState(), 22, 7, 33, start);
        structure.setBlockState(world, Blocks.POPPY.getDefaultState(), 22, 7, 37, start);
        structure.setBlockState(world, Blocks.OXEYE_DAISY.getDefaultState(), 22, 7, 38, start);
        structure.setBlockState(world, Blocks.GRASS.getDefaultState(), 22, 7, 44, start);
        structure.setBlockState(world, Blocks.GRASS_BLOCK.getDefaultState().with(SnowyDirtBlock.SNOWY, false), 23, 5, 20, start);
        structure.setBlockState(world, Blocks.STONE.getDefaultState(), 23, 5, 44, start);
        structure.setBlockState(world, Blocks.VINE.getDefaultState().with(VineBlock.UP, false).with(VineBlock.NORTH, false).with(VineBlock.SOUTH, false).with(VineBlock.EAST, true).with(VineBlock.WEST, true), 23, 6, 20, start);
        structure.setBlockState(world, Blocks.GRASS.getDefaultState(), 23, 7, 13, start);
        structure.setBlockState(world, Blocks.DANDELION.getDefaultState(), 23, 7, 18, start);
        structure.setBlockState(world, Blocks.GRASS.getDefaultState(), 23, 7, 38, start);
        structure.setBlockState(world, Blocks.POPPY.getDefaultState(), 23, 7, 42, start);
        structure.setBlockState(world, Blocks.VINE.getDefaultState().with(VineBlock.UP, false).with(VineBlock.NORTH, false).with(VineBlock.SOUTH, false).with(VineBlock.EAST, true).with(VineBlock.WEST, false), 23, 7, 46, start);
        structure.setBlockState(world, Blocks.GRASS.getDefaultState(), 23, 7, 48, start);
        structure.setBlockState(world, Blocks.GRASS.getDefaultState(), 23, 7, 55, start);
        structure.setBlockState(world, Blocks.GRASS.getDefaultState(), 23, 7, 57, start);
        structure.setBlockState(world, Blocks.VINE.getDefaultState().with(VineBlock.UP, false).with(VineBlock.NORTH, false).with(VineBlock.SOUTH, false).with(VineBlock.EAST, true).with(VineBlock.WEST, false), 23, 9, 46, start);
        structure.setBlockState(world, Blocks.VINE.getDefaultState().with(VineBlock.UP, false).with(VineBlock.NORTH, false).with(VineBlock.SOUTH, false).with(VineBlock.EAST, true).with(VineBlock.WEST, false), 23, 11, 46, start);
        structure.setBlockState(world, Blocks.VINE.getDefaultState().with(VineBlock.UP, false).with(VineBlock.NORTH, false).with(VineBlock.SOUTH, false).with(VineBlock.EAST, true).with(VineBlock.WEST, false), 23, 17, 47, start);
        structure.setBlockState(world, Blocks.GRASS_BLOCK.getDefaultState().with(SnowyDirtBlock.SNOWY, false), 24, 6, 20, start);
        structure.setBlockState(world, Blocks.GRASS.getDefaultState(), 24, 7, 11, start);
        structure.setBlockState(world, Blocks.TALL_GRASS.getDefaultState(), 24, 7, 28, start);
        structure.setBlockState(world, Blocks.GRASS.getDefaultState(), 24, 7, 29, start);
        structure.setBlockState(world, Blocks.TALL_GRASS.getDefaultState(), 24, 7, 30, start);
        structure.setBlockState(world, Blocks.TALL_GRASS.getDefaultState(), 24, 7, 36, start);
        structure.setBlockState(world, Blocks.DANDELION.getDefaultState(), 24, 7, 40, start);
        structure.setBlockState(world, Blocks.GRASS.getDefaultState(), 24, 7, 44, start);
        structure.setBlockState(world, Blocks.DANDELION.getDefaultState(), 24, 7, 57, start);
        structure.setBlockState(world, Blocks.TALL_GRASS.getDefaultState(), 24, 8, 28, start);
        structure.setBlockState(world, Blocks.TALL_GRASS.getDefaultState(), 24, 8, 30, start);
        structure.setBlockState(world, Blocks.TALL_GRASS.getDefaultState(), 24, 8, 36, start);
        structure.setBlockState(world, Blocks.MOSSY_STONE_BRICKS.getDefaultState(), 24, 8, 38, start);
        structure.setBlockState(world, Blocks.MOSSY_STONE_BRICKS.getDefaultState(), 24, 8, 49, start);
        structure.setBlockState(world, Blocks.OAK_LEAVES.getDefaultState().with(LeavesBlock.PERSISTENT, true).with(LeavesBlock.DISTANCE, 7), 24, 9, 37, start);
        structure.setBlockState(world, Blocks.STONE_BRICKS.getDefaultState(), 24, 9, 38, start);
        structure.setBlockState(world, Blocks.MOSSY_STONE_BRICKS.getDefaultState(), 24, 9, 46, start);
        structure.setBlockState(world, Blocks.OAK_LEAVES.getDefaultState().with(LeavesBlock.PERSISTENT, true).with(LeavesBlock.DISTANCE, 7), 24, 10, 38, start);
        structure.setBlockState(world, Blocks.MOSSY_COBBLESTONE.getDefaultState(), 24, 10, 47, start);
        structure.setBlockState(world, Blocks.STONE_BRICKS.getDefaultState(), 24, 11, 47, start);
        structure.setBlockState(world, Blocks.OAK_LEAVES.getDefaultState().with(LeavesBlock.PERSISTENT, true).with(LeavesBlock.DISTANCE, 7), 24, 11, 49, start);
        structure.setBlockState(world, Blocks.STONE_BRICK_STAIRS.getDefaultState().with(StairsBlock.FACING, Direction.EAST).with(StairsBlock.WATERLOGGED, false).with(StairsBlock.SHAPE, StairsShape.STRAIGHT).with(StairsBlock.HALF, Half.TOP), 24, 12, 20, start);
        structure.setBlockState(world, Blocks.OAK_LEAVES.getDefaultState().with(LeavesBlock.PERSISTENT, true).with(LeavesBlock.DISTANCE, 7), 24, 12, 21, start);
        structure.setBlockState(world, Blocks.STONE_BRICK_STAIRS.getDefaultState().with(StairsBlock.FACING, Direction.EAST).with(StairsBlock.WATERLOGGED, false).with(StairsBlock.SHAPE, StairsShape.STRAIGHT).with(StairsBlock.HALF, Half.TOP), 24, 12, 39, start);
        structure.setBlockState(world, Blocks.OAK_LEAVES.getDefaultState().with(LeavesBlock.PERSISTENT, true).with(LeavesBlock.DISTANCE, 7), 24, 12, 47, start);
        structure.setBlockState(world, Blocks.MOSSY_STONE_BRICKS.getDefaultState(), 24, 12, 49, start);
        structure.setBlockState(world, Blocks.MOSSY_COBBLESTONE.getDefaultState(), 24, 13, 20, start);
        structure.setBlockState(world, Blocks.MOSSY_COBBLESTONE.getDefaultState(), 24, 13, 49, start);
        structure.setBlockState(world, Blocks.VINE.getDefaultState().with(VineBlock.UP, false).with(VineBlock.NORTH, true).with(VineBlock.SOUTH, false).with(VineBlock.EAST, false).with(VineBlock.WEST, false), 24, 14, 22, start);
        structure.setBlockState(world, Blocks.MOSSY_STONE_BRICKS.getDefaultState(), 24, 14, 39, start);
        structure.setBlockState(world, Blocks.VINE.getDefaultState().with(VineBlock.UP, false).with(VineBlock.NORTH, true).with(VineBlock.SOUTH, false).with(VineBlock.EAST, true).with(VineBlock.WEST, false), 24, 14, 42, start);
        structure.setBlockState(world, Blocks.MOSSY_STONE_BRICKS.getDefaultState(), 24, 15, 21, start);
        structure.setBlockState(world, Blocks.VINE.getDefaultState().with(VineBlock.UP, false).with(VineBlock.NORTH, true).with(VineBlock.SOUTH, false).with(VineBlock.EAST, false).with(VineBlock.WEST, false), 24, 15, 42, start);
        structure.setBlockState(world, Blocks.VINE.getDefaultState().with(VineBlock.UP, false).with(VineBlock.NORTH, false).with(VineBlock.SOUTH, true).with(VineBlock.EAST, false).with(VineBlock.WEST, false), 24, 15, 45, start);
        structure.setBlockState(world, Blocks.OAK_LEAVES.getDefaultState().with(LeavesBlock.PERSISTENT, true).with(LeavesBlock.DISTANCE, 7), 24, 16, 20, start);
        structure.setBlockState(world, Blocks.STONE_BRICKS.getDefaultState(), 24, 16, 21, start);
        structure.setBlockState(world, Blocks.VINE.getDefaultState().with(VineBlock.UP, false).with(VineBlock.NORTH, false).with(VineBlock.SOUTH, false).with(VineBlock.EAST, true).with(VineBlock.WEST, false), 24, 16, 39, start);
        structure.setBlockState(world, Blocks.MOSSY_COBBLESTONE.getDefaultState(), 24, 17, 47, start);
        structure.setBlockState(world, Blocks.COBBLESTONE_STAIRS.getDefaultState().with(StairsBlock.FACING, Direction.NORTH).with(StairsBlock.WATERLOGGED, false).with(StairsBlock.SHAPE, StairsShape.STRAIGHT).with(StairsBlock.HALF, Half.BOTTOM), 24, 17, 48, start);
        structure.setBlockState(world, Blocks.MOSSY_COBBLESTONE.getDefaultState(), 24, 18, 38, start);
        structure.setBlockState(world, Blocks.VINE.getDefaultState().with(VineBlock.UP, false).with(VineBlock.NORTH, false).with(VineBlock.SOUTH, false).with(VineBlock.EAST, true).with(VineBlock.WEST, false), 24, 19, 41, start);
        structure.setBlockState(world, Blocks.OAK_LEAVES.getDefaultState().with(LeavesBlock.PERSISTENT, true).with(LeavesBlock.DISTANCE, 7), 24, 20, 20, start);
        structure.setBlockState(world, Blocks.MOSSY_STONE_BRICKS.getDefaultState(), 24, 20, 21, start);
        structure.setBlockState(world, Blocks.MOSSY_COBBLESTONE.getDefaultState(), 24, 23, 20, start);
        structure.setBlockState(world, Blocks.VINE.getDefaultState().with(VineBlock.UP, false).with(VineBlock.NORTH, false).with(VineBlock.SOUTH, false).with(VineBlock.EAST, true).with(VineBlock.WEST, false), 24, 23, 23, start);
        structure.setBlockState(world, Blocks.MOSSY_COBBLESTONE.getDefaultState(), 24, 24, 21, start);
        structure.setBlockState(world, Blocks.OAK_LEAVES.getDefaultState().with(LeavesBlock.PERSISTENT, true).with(LeavesBlock.DISTANCE, 7), 24, 25, 20, start);
        structure.setBlockState(world, Blocks.VINE.getDefaultState().with(VineBlock.UP, true).with(VineBlock.NORTH, true).with(VineBlock.SOUTH, false).with(VineBlock.EAST, true).with(VineBlock.WEST, false), 24, 26, 37, start);
        structure.setBlockState(world, Blocks.VINE.getDefaultState().with(VineBlock.UP, false).with(VineBlock.NORTH, true).with(VineBlock.SOUTH, false).with(VineBlock.EAST, true).with(VineBlock.WEST, false), 24, 26, 40, start);
        structure.setBlockState(world, Blocks.OAK_LEAVES.getDefaultState().with(LeavesBlock.PERSISTENT, true).with(LeavesBlock.DISTANCE, 7), 24, 27, 20, start);
        structure.setBlockState(world, Blocks.MOSSY_COBBLESTONE.getDefaultState(), 24, 27, 24, start);
        structure.setBlockState(world, Blocks.STONE_BRICK_STAIRS.getDefaultState().with(StairsBlock.FACING, Direction.NORTH).with(StairsBlock.WATERLOGGED, false).with(StairsBlock.SHAPE, StairsShape.STRAIGHT).with(StairsBlock.HALF, Half.TOP), 24, 27, 25, start);
        structure.setBlockState(world, Blocks.STONE_BRICK_STAIRS.getDefaultState().with(StairsBlock.FACING, Direction.SOUTH).with(StairsBlock.WATERLOGGED, false).with(StairsBlock.SHAPE, StairsShape.STRAIGHT).with(StairsBlock.HALF, Half.TOP), 24, 27, 33, start);
        structure.setBlockState(world, Blocks.MOSSY_COBBLESTONE.getDefaultState(), 24, 27, 35, start);
        structure.setBlockState(world, Blocks.MOSSY_STONE_BRICKS.getDefaultState(), 24, 27, 36, start);
        structure.setBlockState(world, Blocks.VINE.getDefaultState().with(VineBlock.UP, true).with(VineBlock.NORTH, false).with(VineBlock.SOUTH, false).with(VineBlock.EAST, true).with(VineBlock.WEST, false), 24, 27, 38, start);
        structure.setBlockState(world, Blocks.MOSSY_STONE_BRICKS.getDefaultState(), 24, 27, 39, start);
        structure.setBlockState(world, Blocks.MOSSY_COBBLESTONE.getDefaultState(), 24, 28, 20, start);
        structure.setBlockState(world, Blocks.MOSSY_STONE_BRICKS.getDefaultState(), 24, 28, 21, start);
        structure.setBlockState(world, Blocks.VINE.getDefaultState().with(VineBlock.UP, false).with(VineBlock.NORTH, true).with(VineBlock.SOUTH, false).with(VineBlock.EAST, true).with(VineBlock.WEST, false), 24, 28, 22, start);
        structure.setBlockState(world, Blocks.COBBLESTONE_STAIRS.getDefaultState().with(StairsBlock.FACING, Direction.SOUTH).with(StairsBlock.WATERLOGGED, false).with(StairsBlock.SHAPE, StairsShape.STRAIGHT).with(StairsBlock.HALF, Half.BOTTOM), 24, 28, 25, start);
        structure.setBlockState(world, Blocks.STONE_BRICK_STAIRS.getDefaultState().with(StairsBlock.FACING, Direction.NORTH).with(StairsBlock.WATERLOGGED, false).with(StairsBlock.SHAPE, StairsShape.STRAIGHT).with(StairsBlock.HALF, Half.TOP), 24, 28, 26, start);
        structure.setBlockState(world, Blocks.STONE_BRICK_STAIRS.getDefaultState().with(StairsBlock.FACING, Direction.SOUTH).with(StairsBlock.WATERLOGGED, false).with(StairsBlock.SHAPE, StairsShape.STRAIGHT).with(StairsBlock.HALF, Half.TOP), 24, 28, 32, start);
        structure.setBlockState(world, Blocks.MOSSY_COBBLESTONE.getDefaultState(), 24, 28, 33, start);
        structure.setBlockState(world, Blocks.MOSSY_COBBLESTONE.getDefaultState(), 24, 28, 38, start);
        structure.setBlockState(world, Blocks.COBBLESTONE_STAIRS.getDefaultState().with(StairsBlock.FACING, Direction.EAST).with(StairsBlock.WATERLOGGED, false).with(StairsBlock.SHAPE, StairsShape.STRAIGHT).with(StairsBlock.HALF, Half.BOTTOM), 24, 29, 20, start);
        structure.setBlockState(world, Blocks.STONE_BRICK_STAIRS.getDefaultState().with(StairsBlock.FACING, Direction.EAST).with(StairsBlock.WATERLOGGED, false).with(StairsBlock.SHAPE, StairsShape.STRAIGHT).with(StairsBlock.HALF, Half.TOP), 24, 29, 21, start);
        structure.setBlockState(world, Blocks.STONE_BRICK_STAIRS.getDefaultState().with(StairsBlock.FACING, Direction.NORTH).with(StairsBlock.WATERLOGGED, false).with(StairsBlock.SHAPE, StairsShape.STRAIGHT).with(StairsBlock.HALF, Half.TOP), 24, 29, 27, start);
        structure.setBlockState(world, Blocks.STONE_BRICKS.getDefaultState(), 24, 29, 38, start);
        structure.setBlockState(world, Blocks.MOSSY_STONE_BRICKS.getDefaultState(), 24, 29, 39, start);
        structure.setBlockState(world, Blocks.OAK_LEAVES.getDefaultState().with(LeavesBlock.PERSISTENT, true).with(LeavesBlock.DISTANCE, 7), 24, 29, 40, start);
        structure.setBlockState(world, Blocks.STONE_BRICKS.getDefaultState(), 24, 30, 27, start);
        structure.setBlockState(world, Blocks.MOSSY_COBBLESTONE.getDefaultState(), 24, 30, 38, start);
        structure.setBlockState(world, Blocks.STONE_BRICK_STAIRS.getDefaultState().with(StairsBlock.FACING, Direction.SOUTH).with(StairsBlock.WATERLOGGED, false).with(StairsBlock.SHAPE, StairsShape.STRAIGHT).with(StairsBlock.HALF, Half.BOTTOM), 24, 31, 27, start);
        structure.setBlockState(world, Blocks.OAK_LEAVES.getDefaultState().with(LeavesBlock.PERSISTENT, true).with(LeavesBlock.DISTANCE, 7), 24, 31, 39, start);
        structure.setBlockState(world, Blocks.STONE_BRICKS.getDefaultState(), 24, 32, 38, start);
        structure.setBlockState(world, Blocks.COARSE_DIRT.getDefaultState(), 25, 6, 34, start);
        structure.setBlockState(world, Blocks.GRASS_BLOCK.getDefaultState().with(SnowyDirtBlock.SNOWY, false), 25, 6, 48, start);
        structure.setBlockState(world, Blocks.TALL_GRASS.getDefaultState(), 25, 7, 26, start);
        structure.setBlockState(world, Blocks.MOSSY_STONE_BRICKS.getDefaultState(), 25, 7, 38, start);
        structure.setBlockState(world, Blocks.STONE_BRICKS.getDefaultState(), 25, 7, 39, start);
        structure.setBlockState(world, Blocks.GRASS.getDefaultState(), 25, 7, 53, start);
        structure.setBlockState(world, Blocks.GRASS.getDefaultState(), 25, 7, 57, start);
        structure.setBlockState(world, Blocks.TALL_GRASS.getDefaultState(), 25, 8, 26, start);
        structure.setBlockState(world, Blocks.TALL_GRASS.getDefaultState(), 25, 8, 33, start);
        structure.setBlockState(world, Blocks.TALL_GRASS.getDefaultState(), 25, 8, 40, start);
        structure.setBlockState(world, Blocks.STONE_BRICKS.getDefaultState(), 25, 8, 46, start);
        structure.setBlockState(world, Blocks.MOSSY_COBBLESTONE.getDefaultState(), 25, 9, 22, start);
        structure.setBlockState(world, Blocks.MOSSY_STONE_BRICKS.getDefaultState(), 25, 9, 49, start);
        structure.setBlockState(world, Blocks.STONE_BRICKS.getDefaultState(), 25, 9, 50, start);
        structure.setBlockState(world, Blocks.OAK_LEAVES.getDefaultState().with(LeavesBlock.PERSISTENT, true).with(LeavesBlock.DISTANCE, 7), 25, 10, 37, start);
        structure.setBlockState(world, Blocks.MOSSY_COBBLESTONE.getDefaultState(), 25, 10, 46, start);
        structure.setBlockState(world, Blocks.OAK_LEAVES.getDefaultState().with(LeavesBlock.PERSISTENT, true).with(LeavesBlock.DISTANCE, 7), 25, 10, 50, start);
        structure.setBlockState(world, Blocks.MOSSY_COBBLESTONE.getDefaultState(), 25, 11, 25, start);
        structure.setBlockState(world, Blocks.MOSSY_COBBLESTONE.getDefaultState(), 25, 11, 31, start);
        structure.setBlockState(world, Blocks.MOSSY_COBBLESTONE.getDefaultState(), 25, 11, 47, start);
        structure.setBlockState(world, Blocks.MOSSY_COBBLESTONE.getDefaultState(), 25, 11, 50, start);
        structure.setBlockState(world, Blocks.STONE_BRICKS.getDefaultState(), 25, 12, 20, start);
        structure.setBlockState(world, Blocks.STONE_BRICKS.getDefaultState(), 25, 12, 22, start);
        structure.setBlockState(world, Blocks.STONE_BRICKS.getDefaultState(), 25, 12, 28, start);
        structure.setBlockState(world, Blocks.STONE_BRICKS.getDefaultState(), 25, 12, 31, start);
        structure.setBlockState(world, Blocks.MOSSY_COBBLESTONE.getDefaultState(), 25, 12, 34, start);
        structure.setBlockState(world, Blocks.STONE_BRICK_STAIRS.getDefaultState().with(StairsBlock.FACING, Direction.NORTH).with(StairsBlock.WATERLOGGED, false).with(StairsBlock.SHAPE, StairsShape.STRAIGHT).with(StairsBlock.HALF, Half.TOP), 25, 12, 40, start);
        structure.setBlockState(world, Blocks.STONE_BRICK_STAIRS.getDefaultState().with(StairsBlock.FACING, Direction.SOUTH).with(StairsBlock.WATERLOGGED, false).with(StairsBlock.SHAPE, StairsShape.STRAIGHT).with(StairsBlock.HALF, Half.TOP), 25, 12, 44, start);
        structure.setBlockState(world, Blocks.MOSSY_STONE_BRICKS.getDefaultState(), 25, 13, 22, start);
        structure.setBlockState(world, Blocks.MOSSY_STONE_BRICKS.getDefaultState(), 25, 13, 28, start);
        structure.setBlockState(world, Blocks.MOSSY_STONE_BRICKS.getDefaultState(), 25, 13, 31, start);
        structure.setBlockState(world, Blocks.STONE_BRICKS.getDefaultState(), 25, 13, 34, start);
        structure.setBlockState(world, Blocks.MOSSY_COBBLESTONE.getDefaultState(), 25, 13, 37, start);
        structure.setBlockState(world, Blocks.STONE_BRICK_STAIRS.getDefaultState().with(StairsBlock.FACING, Direction.NORTH).with(StairsBlock.WATERLOGGED, false).with(StairsBlock.SHAPE, StairsShape.STRAIGHT).with(StairsBlock.HALF, Half.TOP), 25, 13, 41, start);
        structure.setBlockState(world, Blocks.STONE_BRICK_STAIRS.getDefaultState().with(StairsBlock.FACING, Direction.SOUTH).with(StairsBlock.WATERLOGGED, false).with(StairsBlock.SHAPE, StairsShape.STRAIGHT).with(StairsBlock.HALF, Half.TOP), 25, 13, 43, start);
        structure.setBlockState(world, Blocks.MOSSY_STONE_BRICKS.getDefaultState(), 25, 13, 46, start);
        structure.setBlockState(world, Blocks.MOSSY_STONE_BRICKS.getDefaultState(), 25, 13, 50, start);
        structure.setBlockState(world, Blocks.MOSSY_STONE_BRICKS.getDefaultState(), 25, 14, 20, start);
        structure.setBlockState(world, Blocks.STONE_BRICK_STAIRS.getDefaultState().with(StairsBlock.FACING, Direction.SOUTH).with(StairsBlock.WATERLOGGED, false).with(StairsBlock.SHAPE, StairsShape.STRAIGHT).with(StairsBlock.HALF, Half.TOP), 25, 14, 24, start);
        structure.setBlockState(world, Blocks.STONE_BRICKS.getDefaultState(), 25, 14, 25, start);
        structure.setBlockState(world, Blocks.STONE_BRICK_STAIRS.getDefaultState().with(StairsBlock.FACING, Direction.NORTH).with(StairsBlock.WATERLOGGED, false).with(StairsBlock.SHAPE, StairsShape.STRAIGHT).with(StairsBlock.HALF, Half.TOP), 25, 14, 26, start);
        structure.setBlockState(world, Blocks.STONE_BRICK_STAIRS.getDefaultState().with(StairsBlock.FACING, Direction.SOUTH).with(StairsBlock.WATERLOGGED, false).with(StairsBlock.SHAPE, StairsShape.STRAIGHT).with(StairsBlock.HALF, Half.TOP), 25, 14, 27, start);
        structure.setBlockState(world, Blocks.STONE_BRICK_STAIRS.getDefaultState().with(StairsBlock.FACING, Direction.NORTH).with(StairsBlock.WATERLOGGED, false).with(StairsBlock.SHAPE, StairsShape.STRAIGHT).with(StairsBlock.HALF, Half.TOP), 25, 14, 29, start);
        structure.setBlockState(world, Blocks.STONE_BRICK_STAIRS.getDefaultState().with(StairsBlock.FACING, Direction.SOUTH).with(StairsBlock.WATERLOGGED, false).with(StairsBlock.SHAPE, StairsShape.STRAIGHT).with(StairsBlock.HALF, Half.TOP), 25, 14, 30, start);
        structure.setBlockState(world, Blocks.STONE_BRICK_STAIRS.getDefaultState().with(StairsBlock.FACING, Direction.NORTH).with(StairsBlock.WATERLOGGED, false).with(StairsBlock.SHAPE, StairsShape.STRAIGHT).with(StairsBlock.HALF, Half.TOP), 25, 14, 32, start);
        structure.setBlockState(world, Blocks.STONE_BRICK_STAIRS.getDefaultState().with(StairsBlock.FACING, Direction.SOUTH).with(StairsBlock.WATERLOGGED, false).with(StairsBlock.SHAPE, StairsShape.STRAIGHT).with(StairsBlock.HALF, Half.TOP), 25, 14, 33, start);
        structure.setBlockState(world, Blocks.MOSSY_STONE_BRICKS.getDefaultState(), 25, 14, 34, start);
        structure.setBlockState(world, Blocks.STONE_BRICK_STAIRS.getDefaultState().with(StairsBlock.FACING, Direction.NORTH).with(StairsBlock.WATERLOGGED, false).with(StairsBlock.SHAPE, StairsShape.STRAIGHT).with(StairsBlock.HALF, Half.TOP), 25, 14, 35, start);
        structure.setBlockState(world, Blocks.STONE_BRICK_STAIRS.getDefaultState().with(StairsBlock.FACING, Direction.SOUTH).with(StairsBlock.WATERLOGGED, false).with(StairsBlock.SHAPE, StairsShape.STRAIGHT).with(StairsBlock.HALF, Half.TOP), 25, 14, 36, start);
        structure.setBlockState(world, Blocks.STONE_BRICKS.getDefaultState(), 25, 14, 38, start);
        structure.setBlockState(world, Blocks.MOSSY_STONE_BRICKS.getDefaultState(), 25, 14, 41, start);
        structure.setBlockState(world, Blocks.MOSSY_STONE_BRICKS.getDefaultState(), 25, 14, 49, start);
        structure.setBlockState(world, Blocks.STONE_BRICK_STAIRS.getDefaultState().with(StairsBlock.FACING, Direction.NORTH).with(StairsBlock.WATERLOGGED, false).with(StairsBlock.SHAPE, StairsShape.STRAIGHT).with(StairsBlock.HALF, Half.BOTTOM), 25, 14, 50, start);
        structure.setBlockState(world, Blocks.MOSSY_STONE_BRICKS.getDefaultState(), 25, 15, 24, start);
        structure.setBlockState(world, Blocks.MOSSY_COBBLESTONE.getDefaultState(), 25, 15, 25, start);
        structure.setBlockState(world, Blocks.STONE_BRICKS.getDefaultState(), 25, 15, 29, start);
        structure.setBlockState(world, Blocks.MOSSY_COBBLESTONE.getDefaultState(), 25, 15, 34, start);
        structure.setBlockState(world, Blocks.MOSSY_STONE_BRICKS.getDefaultState(), 25, 15, 35, start);
        structure.setBlockState(world, Blocks.STONE_BRICKS.getDefaultState(), 25, 15, 36, start);
        structure.setBlockState(world, Blocks.COBBLESTONE_STAIRS.getDefaultState().with(StairsBlock.FACING, Direction.EAST).with(StairsBlock.WATERLOGGED, false).with(StairsBlock.SHAPE, StairsShape.STRAIGHT).with(StairsBlock.HALF, Half.BOTTOM), 25, 15, 42, start);
        structure.setBlockState(world, Blocks.STONE_BRICK_STAIRS.getDefaultState().with(StairsBlock.FACING, Direction.EAST).with(StairsBlock.WATERLOGGED, false).with(StairsBlock.SHAPE, StairsShape.STRAIGHT).with(StairsBlock.HALF, Half.BOTTOM), 25, 15, 43, start);
        structure.setBlockState(world, Blocks.MOSSY_COBBLESTONE.getDefaultState(), 25, 15, 49, start);
        structure.setBlockState(world, Blocks.COBBLESTONE_STAIRS.getDefaultState().with(StairsBlock.FACING, Direction.NORTH).with(StairsBlock.WATERLOGGED, false).with(StairsBlock.SHAPE, StairsShape.STRAIGHT).with(StairsBlock.HALF, Half.TOP), 25, 15, 50, start);
        structure.setBlockState(world, Blocks.STONE_BRICKS.getDefaultState(), 25, 16, 27, start);
        structure.setBlockState(world, Blocks.MOSSY_STONE_BRICKS.getDefaultState(), 25, 16, 29, start);
        structure.setBlockState(world, Blocks.STONE_BRICK_SLAB.getDefaultState().with(SlabBlock.TYPE, SlabType.BOTTOM).with(SlabBlock.WATERLOGGED, false), 25, 16, 30, start);
        structure.setBlockState(world, Blocks.MOSSY_STONE_BRICKS.getDefaultState(), 25, 16, 32, start);
        structure.setBlockState(world, Blocks.VINE.getDefaultState().with(VineBlock.UP, false).with(VineBlock.NORTH, true).with(VineBlock.SOUTH, true).with(VineBlock.EAST, false).with(VineBlock.WEST, false), 25, 16, 33, start);
        structure.setBlockState(world, Blocks.STONE_BRICKS.getDefaultState(), 25, 16, 34, start);
        structure.setBlockState(world, Blocks.VINE.getDefaultState().with(VineBlock.UP, false).with(VineBlock.NORTH, false).with(VineBlock.SOUTH, true).with(VineBlock.EAST, false).with(VineBlock.WEST, false), 25, 16, 45, start);
        structure.setBlockState(world, Blocks.MOSSY_STONE_BRICKS.getDefaultState(), 25, 16, 46, start);
        structure.setBlockState(world, Blocks.MOSSY_STONE_BRICKS.getDefaultState(), 25, 16, 49, start);
        structure.setBlockState(world, Blocks.MOSSY_STONE_BRICKS.getDefaultState(), 25, 17, 27, start);
        structure.setBlockState(world, Blocks.OAK_LEAVES.getDefaultState().with(LeavesBlock.PERSISTENT, true).with(LeavesBlock.DISTANCE, 7), 25, 17, 32, start);
        structure.setBlockState(world, Blocks.STONE_BRICKS.getDefaultState(), 25, 17, 39, start);
        structure.setBlockState(world, Blocks.STONE_BRICK_STAIRS.getDefaultState().with(StairsBlock.FACING, Direction.NORTH).with(StairsBlock.WATERLOGGED, false).with(StairsBlock.SHAPE, StairsShape.STRAIGHT).with(StairsBlock.HALF, Half.TOP), 25, 17, 40, start);
        structure.setBlockState(world, Blocks.STONE_BRICK_STAIRS.getDefaultState().with(StairsBlock.FACING, Direction.SOUTH).with(StairsBlock.WATERLOGGED, false).with(StairsBlock.SHAPE, StairsShape.STRAIGHT).with(StairsBlock.HALF, Half.TOP), 25, 17, 45, start);
        structure.setBlockState(world, Blocks.MOSSY_COBBLESTONE.getDefaultState(), 25, 17, 46, start);
        structure.setBlockState(world, Blocks.MOSSY_STONE_BRICKS.getDefaultState(), 25, 17, 47, start);
        structure.setBlockState(world, Blocks.STONE_BRICKS.getDefaultState(), 25, 18, 20, start);
        structure.setBlockState(world, Blocks.STONE_BRICKS.getDefaultState(), 25, 18, 22, start);
        structure.setBlockState(world, Blocks.STONE_BRICKS.getDefaultState(), 25, 18, 40, start);
        structure.setBlockState(world, Blocks.STONE_BRICK_STAIRS.getDefaultState().with(StairsBlock.FACING, Direction.NORTH).with(StairsBlock.WATERLOGGED, false).with(StairsBlock.SHAPE, StairsShape.STRAIGHT).with(StairsBlock.HALF, Half.TOP), 25, 18, 41, start);
        structure.setBlockState(world, Blocks.STONE_BRICK_STAIRS.getDefaultState().with(StairsBlock.FACING, Direction.SOUTH).with(StairsBlock.WATERLOGGED, false).with(StairsBlock.SHAPE, StairsShape.STRAIGHT).with(StairsBlock.HALF, Half.TOP), 25, 18, 44, start);
        structure.setBlockState(world, Blocks.STONE_BRICKS.getDefaultState(), 25, 18, 45, start);
        structure.setBlockState(world, Blocks.MOSSY_STONE_BRICKS.getDefaultState(), 25, 18, 50, start);
        structure.setBlockState(world, Blocks.OAK_LEAVES.getDefaultState().with(LeavesBlock.PERSISTENT, true).with(LeavesBlock.DISTANCE, 7), 25, 19, 22, start);
        structure.setBlockState(world, Blocks.MOSSY_COBBLESTONE.getDefaultState(), 25, 19, 39, start);
        structure.setBlockState(world, Blocks.STONE_BRICKS.getDefaultState(), 25, 19, 42, start);
        structure.setBlockState(world, Blocks.MOSSY_COBBLESTONE.getDefaultState(), 25, 19, 43, start);
        structure.setBlockState(world, Blocks.STONE_BRICK_STAIRS.getDefaultState().with(StairsBlock.FACING, Direction.NORTH).with(StairsBlock.WATERLOGGED, false).with(StairsBlock.SHAPE, StairsShape.STRAIGHT).with(StairsBlock.HALF, Half.BOTTOM), 25, 19, 44, start);
        structure.setBlockState(world, Blocks.COBBLESTONE_STAIRS.getDefaultState().with(StairsBlock.FACING, Direction.NORTH).with(StairsBlock.WATERLOGGED, false).with(StairsBlock.SHAPE, StairsShape.STRAIGHT).with(StairsBlock.HALF, Half.TOP), 25, 19, 50, start);
        structure.setBlockState(world, Blocks.MOSSY_STONE_BRICKS.getDefaultState(), 25, 20, 19, start);
        structure.setBlockState(world, Blocks.MOSSY_COBBLESTONE.getDefaultState(), 25, 20, 21, start);
        structure.setBlockState(world, Blocks.MOSSY_STONE_BRICKS.getDefaultState(), 25, 20, 37, start);
        structure.setBlockState(world, Blocks.OAK_LEAVES.getDefaultState().with(LeavesBlock.PERSISTENT, true).with(LeavesBlock.DISTANCE, 7), 25, 20, 40, start);
        structure.setBlockState(world, Blocks.MOSSY_COBBLESTONE.getDefaultState(), 25, 20, 50, start);
        structure.setBlockState(world, Blocks.MOSSY_STONE_BRICKS.getDefaultState(), 25, 21, 21, start);
        structure.setBlockState(world, Blocks.STONE_BRICK_STAIRS.getDefaultState().with(StairsBlock.FACING, Direction.NORTH).with(StairsBlock.WATERLOGGED, false).with(StairsBlock.SHAPE, StairsShape.STRAIGHT).with(StairsBlock.HALF, Half.TOP), 25, 22, 23, start);
        structure.setBlockState(world, Blocks.MOSSY_COBBLESTONE.getDefaultState(), 25, 22, 27, start);
        structure.setBlockState(world, Blocks.STONE_BRICK_STAIRS.getDefaultState().with(StairsBlock.FACING, Direction.NORTH).with(StairsBlock.WATERLOGGED, false).with(StairsBlock.SHAPE, StairsShape.STRAIGHT).with(StairsBlock.HALF, Half.TOP), 25, 22, 33, start);
        structure.setBlockState(world, Blocks.STONE_BRICK_STAIRS.getDefaultState().with(StairsBlock.FACING, Direction.SOUTH).with(StairsBlock.WATERLOGGED, false).with(StairsBlock.SHAPE, StairsShape.STRAIGHT).with(StairsBlock.HALF, Half.TOP), 25, 22, 36, start);
        structure.setBlockState(world, Blocks.MOSSY_COBBLESTONE.getDefaultState(), 25, 22, 39, start);
        structure.setBlockState(world, Blocks.STONE_BRICKS.getDefaultState(), 25, 23, 26, start);
        structure.setBlockState(world, Blocks.STONE_BRICK_STAIRS.getDefaultState().with(StairsBlock.FACING, Direction.NORTH).with(StairsBlock.WATERLOGGED, false).with(StairsBlock.SHAPE, StairsShape.STRAIGHT).with(StairsBlock.HALF, Half.BOTTOM), 25, 23, 27, start);
        structure.setBlockState(world, Blocks.OAK_LEAVES.getDefaultState().with(LeavesBlock.PERSISTENT, true).with(LeavesBlock.DISTANCE, 7), 25, 23, 33, start);
        structure.setBlockState(world, Blocks.MOSSY_STONE_BRICKS.getDefaultState(), 25, 23, 39, start);
        structure.setBlockState(world, Blocks.MOSSY_COBBLESTONE.getDefaultState(), 25, 23, 40, start);
        structure.setBlockState(world, Blocks.OAK_LEAVES.getDefaultState().with(LeavesBlock.PERSISTENT, true).with(LeavesBlock.DISTANCE, 7), 25, 24, 22, start);
        structure.setBlockState(world, Blocks.MOSSY_STONE_BRICKS.getDefaultState(), 25, 24, 23, start);
        structure.setBlockState(world, Blocks.STONE_BRICK_STAIRS.getDefaultState().with(StairsBlock.FACING, Direction.NORTH).with(StairsBlock.WATERLOGGED, false).with(StairsBlock.SHAPE, StairsShape.STRAIGHT).with(StairsBlock.HALF, Half.TOP), 25, 24, 24, start);
        structure.setBlockState(world, Blocks.STONE_BRICK_STAIRS.getDefaultState().with(StairsBlock.FACING, Direction.SOUTH).with(StairsBlock.WATERLOGGED, false).with(StairsBlock.SHAPE, StairsShape.STRAIGHT).with(StairsBlock.HALF, Half.TOP), 25, 24, 25, start);
        structure.setBlockState(world, Blocks.STONE_BRICK_STAIRS.getDefaultState().with(StairsBlock.FACING, Direction.NORTH).with(StairsBlock.WATERLOGGED, false).with(StairsBlock.SHAPE, StairsShape.STRAIGHT).with(StairsBlock.HALF, Half.TOP), 25, 24, 27, start);
        structure.setBlockState(world, Blocks.STONE_BRICKS.getDefaultState(), 25, 24, 33, start);
        structure.setBlockState(world, Blocks.STONE_BRICK_STAIRS.getDefaultState().with(StairsBlock.FACING, Direction.NORTH).with(StairsBlock.WATERLOGGED, false).with(StairsBlock.SHAPE, StairsShape.STRAIGHT).with(StairsBlock.HALF, Half.TOP), 25, 24, 34, start);
        structure.setBlockState(world, Blocks.STONE_BRICK_STAIRS.getDefaultState().with(StairsBlock.FACING, Direction.SOUTH).with(StairsBlock.WATERLOGGED, false).with(StairsBlock.SHAPE, StairsShape.STRAIGHT).with(StairsBlock.HALF, Half.TOP), 25, 24, 35, start);
        structure.setBlockState(world, Blocks.MOSSY_STONE_BRICKS.getDefaultState(), 25, 24, 36, start);
        structure.setBlockState(world, Blocks.MOSSY_STONE_BRICKS.getDefaultState(), 25, 24, 40, start);
        structure.setBlockState(world, Blocks.OAK_LEAVES.getDefaultState().with(LeavesBlock.PERSISTENT, true).with(LeavesBlock.DISTANCE, 7), 25, 25, 19, start);
        structure.setBlockState(world, Blocks.STONE_BRICKS.getDefaultState(), 25, 25, 22, start);
        structure.setBlockState(world, Blocks.VINE.getDefaultState().with(VineBlock.UP, true).with(VineBlock.NORTH, true).with(VineBlock.SOUTH, false).with(VineBlock.EAST, false).with(VineBlock.WEST, false), 25, 25, 23, start);
        structure.setBlockState(world, Blocks.MOSSY_COBBLESTONE.getDefaultState(), 25, 25, 24, start);
        structure.setBlockState(world, Blocks.STONE_BRICKS.getDefaultState(), 25, 25, 27, start);
        structure.setBlockState(world, Blocks.STONE_BRICKS.getDefaultState(), 25, 25, 36, start);
        structure.setBlockState(world, Blocks.MOSSY_COBBLESTONE.getDefaultState(), 25, 25, 37, start);
        structure.setBlockState(world, Blocks.MOSSY_STONE_BRICKS.getDefaultState(), 25, 25, 39, start);
        structure.setBlockState(world, Blocks.MOSSY_COBBLESTONE.getDefaultState(), 25, 26, 25, start);
        structure.setBlockState(world, Blocks.MOSSY_STONE_BRICKS.getDefaultState(), 25, 27, 20, start);
        structure.setBlockState(world, Blocks.GRASS_BLOCK.getDefaultState().with(SnowyDirtBlock.SNOWY, false), 25, 27, 25, start);
        structure.setBlockState(world, Blocks.STONE_BRICK_STAIRS.getDefaultState().with(StairsBlock.FACING, Direction.NORTH).with(StairsBlock.WATERLOGGED, false).with(StairsBlock.SHAPE, StairsShape.STRAIGHT).with(StairsBlock.HALF, Half.TOP), 25, 27, 28, start);
        structure.setBlockState(world, Blocks.STONE_BRICK_STAIRS.getDefaultState().with(StairsBlock.FACING, Direction.SOUTH).with(StairsBlock.WATERLOGGED, false).with(StairsBlock.SHAPE, StairsShape.STRAIGHT).with(StairsBlock.HALF, Half.TOP), 25, 27, 31, start);
        structure.setBlockState(world, Blocks.MOSSY_STONE_BRICKS.getDefaultState(), 25, 27, 33, start);
        structure.setBlockState(world, Blocks.VINE.getDefaultState().with(VineBlock.UP, false).with(VineBlock.NORTH, true).with(VineBlock.SOUTH, false).with(VineBlock.EAST, false).with(VineBlock.WEST, false), 25, 28, 23, start);
        structure.setBlockState(world, Blocks.DANDELION.getDefaultState(), 25, 28, 25, start);
        structure.setBlockState(world, Blocks.MOSSY_STONE_BRICKS.getDefaultState(), 25, 28, 26, start);
        structure.setBlockState(world, Blocks.MOSSY_COBBLESTONE.getDefaultState(), 25, 28, 27, start);
        structure.setBlockState(world, Blocks.STONE_BRICKS.getDefaultState(), 25, 28, 28, start);
        structure.setBlockState(world, Blocks.COBBLESTONE_STAIRS.getDefaultState().with(StairsBlock.FACING, Direction.SOUTH).with(StairsBlock.WATERLOGGED, false).with(StairsBlock.SHAPE, StairsShape.STRAIGHT).with(StairsBlock.HALF, Half.BOTTOM), 25, 28, 31, start);
        structure.setBlockState(world, Blocks.STONE_BRICKS.getDefaultState(), 25, 28, 33, start);
        structure.setBlockState(world, Blocks.STONE_BRICKS.getDefaultState(), 25, 28, 37, start);
        structure.setBlockState(world, Blocks.MOSSY_STONE_BRICKS.getDefaultState(), 25, 28, 40, start);
        structure.setBlockState(world, Blocks.MOSSY_COBBLESTONE.getDefaultState(), 25, 29, 19, start);
        structure.setBlockState(world, Blocks.STONE_BRICKS.getDefaultState(), 25, 29, 22, start);
        structure.setBlockState(world, Blocks.STONE_BRICKS.getDefaultState(), 25, 29, 27, start);
        structure.setBlockState(world, Blocks.COBBLESTONE_STAIRS.getDefaultState().with(StairsBlock.FACING, Direction.SOUTH).with(StairsBlock.WATERLOGGED, false).with(StairsBlock.SHAPE, StairsShape.STRAIGHT).with(StairsBlock.HALF, Half.TOP), 25, 29, 31, start);
        structure.setBlockState(world, Blocks.STONE_BRICKS.getDefaultState(), 25, 30, 19, start);
        structure.setBlockState(world, Blocks.OAK_LEAVES.getDefaultState().with(LeavesBlock.PERSISTENT, true).with(LeavesBlock.DISTANCE, 7), 25, 30, 40, start);
        structure.setBlockState(world, Blocks.MOSSY_STONE_BRICKS.getDefaultState(), 25, 31, 40, start);
        structure.setBlockState(world, Blocks.COBBLESTONE_SLAB.getDefaultState().with(SlabBlock.TYPE, SlabType.BOTTOM).with(SlabBlock.WATERLOGGED, false), 25, 32, 40, start);
        structure.setBlockState(world, Blocks.MOSSY_COBBLESTONE.getDefaultState(), 25, 33, 39, start);
        structure.setBlockState(world, Blocks.MOSSY_COBBLESTONE.getDefaultState(), 25, 34, 37, start);
        structure.setBlockState(world, Blocks.COBBLESTONE_SLAB.getDefaultState().with(SlabBlock.TYPE, SlabType.BOTTOM).with(SlabBlock.WATERLOGGED, false), 25, 34, 39, start);
        structure.setBlockState(world, Blocks.COBBLESTONE_STAIRS.getDefaultState().with(StairsBlock.FACING, Direction.SOUTH).with(StairsBlock.WATERLOGGED, false).with(StairsBlock.SHAPE, StairsShape.STRAIGHT).with(StairsBlock.HALF, Half.BOTTOM), 25, 35, 37, start);
        structure.setBlockState(world, Blocks.MOSSY_COBBLESTONE.getDefaultState(), 25, 35, 38, start);
        structure.setBlockState(world, Blocks.MOSSY_COBBLESTONE.getDefaultState(), 25, 36, 37, start);
        structure.setBlockState(world, Blocks.MOSSY_STONE_BRICKS.getDefaultState(), 25, 37, 37, start);
        structure.setBlockState(world, Blocks.COARSE_DIRT.getDefaultState(), 26, 6, 21, start);
        structure.setBlockState(world, Blocks.GRASS_BLOCK.getDefaultState().with(SnowyDirtBlock.SNOWY, false), 26, 6, 25, start);
        structure.setBlockState(world, Blocks.COARSE_DIRT.getDefaultState(), 26, 6, 38, start);
        structure.setBlockState(world, Blocks.GRASS.getDefaultState(), 26, 7, 15, start);
        structure.setBlockState(world, Blocks.POPPY.getDefaultState(), 26, 7, 16, start);
        structure.setBlockState(world, Blocks.GRASS.getDefaultState(), 26, 7, 19, start);
        structure.setBlockState(world, Blocks.MOSSY_COBBLESTONE.getDefaultState(), 26, 7, 21, start);
        structure.setBlockState(world, Blocks.GRASS.getDefaultState(), 26, 7, 25, start);
        structure.setBlockState(world, Blocks.GRASS.getDefaultState(), 26, 7, 33, start);
        structure.setBlockState(world, Blocks.AZURE_BLUET.getDefaultState(), 26, 7, 36, start);
        structure.setBlockState(world, Blocks.DANDELION.getDefaultState(), 26, 7, 42, start);
        structure.setBlockState(world, Blocks.TALL_GRASS.getDefaultState(), 26, 7, 44, start);
        structure.setBlockState(world, Blocks.MOSSY_COBBLESTONE.getDefaultState(), 26, 7, 47, start);
        structure.setBlockState(world, Blocks.TALL_GRASS.getDefaultState(), 26, 8, 44, start);
        structure.setBlockState(world, Blocks.MOSSY_STONE_BRICKS.getDefaultState(), 26, 8, 47, start);
        structure.setBlockState(world, Blocks.STONE_BRICKS.getDefaultState(), 26, 10, 38, start);
        structure.setBlockState(world, Blocks.OAK_LEAVES.getDefaultState().with(LeavesBlock.PERSISTENT, true).with(LeavesBlock.DISTANCE, 7), 26, 11, 21, start);
        structure.setBlockState(world, Blocks.STONE_BRICK_STAIRS.getDefaultState().with(StairsBlock.FACING, Direction.WEST).with(StairsBlock.WATERLOGGED, false).with(StairsBlock.SHAPE, StairsShape.STRAIGHT).with(StairsBlock.HALF, Half.TOP), 26, 12, 20, start);
        structure.setBlockState(world, Blocks.STONE_BRICK_STAIRS.getDefaultState().with(StairsBlock.FACING, Direction.WEST).with(StairsBlock.WATERLOGGED, false).with(StairsBlock.SHAPE, StairsShape.STRAIGHT).with(StairsBlock.HALF, Half.TOP), 26, 12, 39, start);
        structure.setBlockState(world, Blocks.MOSSY_COBBLESTONE.getDefaultState(), 26, 12, 49, start);
        structure.setBlockState(world, Blocks.MOSSY_COBBLESTONE.getDefaultState(), 26, 13, 39, start);
        structure.setBlockState(world, Blocks.STONE_BRICK_SLAB.getDefaultState().with(SlabBlock.TYPE, SlabType.TOP).with(SlabBlock.WATERLOGGED, false), 26, 13, 44, start);
        structure.setBlockState(world, Blocks.STONE_BRICKS.getDefaultState(), 26, 13, 49, start);
        structure.setBlockState(world, Blocks.MOSSY_COBBLESTONE.getDefaultState(), 26, 14, 20, start);
        structure.setBlockState(world, Blocks.MOSSY_COBBLESTONE.getDefaultState(), 26, 14, 38, start);
        structure.setBlockState(world, Blocks.MOSSY_STONE_BRICKS.getDefaultState(), 26, 14, 39, start);
        structure.setBlockState(world, Blocks.MOSSY_COBBLESTONE.getDefaultState(), 26, 14, 40, start);
        structure.setBlockState(world, Blocks.STONE_BRICKS.getDefaultState(), 26, 15, 20, start);
        structure.setBlockState(world, Blocks.OAK_LEAVES.getDefaultState().with(LeavesBlock.PERSISTENT, true).with(LeavesBlock.DISTANCE, 7), 26, 15, 31, start);
        structure.setBlockState(world, Blocks.MOSSY_STONE_BRICKS.getDefaultState(), 26, 15, 41, start);
        structure.setBlockState(world, Blocks.OAK_LEAVES.getDefaultState().with(LeavesBlock.PERSISTENT, true).with(LeavesBlock.DISTANCE, 7), 26, 15, 42, start);
        structure.setBlockState(world, Blocks.MOSSY_STONE_BRICKS.getDefaultState(), 26, 15, 49, start);
        structure.setBlockState(world, Blocks.MOSSY_STONE_BRICKS.getDefaultState(), 26, 16, 21, start);
        structure.setBlockState(world, Blocks.ANDESITE.getDefaultState(), 26, 16, 38, start);
        structure.setBlockState(world, Blocks.VINE.getDefaultState().with(VineBlock.UP, false).with(VineBlock.NORTH, false).with(VineBlock.SOUTH, false).with(VineBlock.EAST, false).with(VineBlock.WEST, true), 26, 16, 39, start);
        structure.setBlockState(world, Blocks.OAK_LEAVES.getDefaultState().with(LeavesBlock.PERSISTENT, true).with(LeavesBlock.DISTANCE, 7), 26, 16, 46, start);
        structure.setBlockState(world, Blocks.MOSSY_COBBLESTONE.getDefaultState(), 26, 16, 47, start);
        structure.setBlockState(world, Blocks.MOSSY_COBBLESTONE.getDefaultState(), 26, 17, 21, start);
        structure.setBlockState(world, Blocks.STONE_BRICKS.getDefaultState(), 26, 17, 38, start);
        structure.setBlockState(world, Blocks.MOSSY_STONE_BRICKS.getDefaultState(), 26, 17, 46, start);
        structure.setBlockState(world, Blocks.STONE_BRICKS.getDefaultState(), 26, 17, 47, start);
        structure.setBlockState(world, Blocks.MOSSY_STONE_BRICKS.getDefaultState(), 26, 18, 21, start);
        structure.setBlockState(world, Blocks.MOSSY_COBBLESTONE.getDefaultState(), 26, 18, 38, start);
        structure.setBlockState(world, Blocks.OAK_LEAVES.getDefaultState().with(LeavesBlock.PERSISTENT, true).with(LeavesBlock.DISTANCE, 7), 26, 19, 21, start);
        structure.setBlockState(world, Blocks.STONE_BRICKS.getDefaultState(), 26, 19, 38, start);
        structure.setBlockState(world, Blocks.OAK_LEAVES.getDefaultState().with(LeavesBlock.PERSISTENT, true).with(LeavesBlock.DISTANCE, 7), 26, 19, 39, start);
        structure.setBlockState(world, Blocks.ANDESITE.getDefaultState(), 26, 19, 40, start);
        structure.setBlockState(world, Blocks.STONE_BRICKS.getDefaultState(), 26, 20, 21, start);
        structure.setBlockState(world, Blocks.ANDESITE.getDefaultState(), 26, 20, 39, start);
        structure.setBlockState(world, Blocks.STONE_BRICK_STAIRS.getDefaultState().with(StairsBlock.FACING, Direction.NORTH).with(StairsBlock.WATERLOGGED, false).with(StairsBlock.SHAPE, StairsShape.STRAIGHT).with(StairsBlock.HALF, Half.BOTTOM), 26, 20, 42, start);
        structure.setBlockState(world, Blocks.STONE_BRICK_STAIRS.getDefaultState().with(StairsBlock.FACING, Direction.SOUTH).with(StairsBlock.WATERLOGGED, false).with(StairsBlock.SHAPE, StairsShape.STRAIGHT).with(StairsBlock.HALF, Half.BOTTOM), 26, 21, 19, start);
        structure.setBlockState(world, Blocks.MOSSY_COBBLESTONE.getDefaultState(), 26, 21, 21, start);
        structure.setBlockState(world, Blocks.OAK_LEAVES.getDefaultState().with(LeavesBlock.PERSISTENT, true).with(LeavesBlock.DISTANCE, 7), 26, 22, 38, start);
        structure.setBlockState(world, Blocks.STONE_BRICKS.getDefaultState(), 26, 22, 39, start);
        structure.setBlockState(world, Blocks.VINE.getDefaultState().with(VineBlock.UP, false).with(VineBlock.NORTH, true).with(VineBlock.SOUTH, false).with(VineBlock.EAST, false).with(VineBlock.WEST, true), 26, 22, 40, start);
        structure.setBlockState(world, Blocks.MOSSY_STONE_BRICKS.getDefaultState(), 26, 23, 20, start);
        structure.setBlockState(world, Blocks.STONE_BRICKS.getDefaultState(), 26, 23, 21, start);
        structure.setBlockState(world, Blocks.MOSSY_COBBLESTONE.getDefaultState(), 26, 23, 39, start);
        structure.setBlockState(world, Blocks.MOSSY_COBBLESTONE.getDefaultState(), 26, 24, 21, start);
        structure.setBlockState(world, Blocks.MOSSY_COBBLESTONE.getDefaultState(), 26, 25, 39, start);
        structure.setBlockState(world, Blocks.OAK_LEAVES.getDefaultState().with(LeavesBlock.PERSISTENT, true).with(LeavesBlock.DISTANCE, 7), 26, 26, 37, start);
        structure.setBlockState(world, Blocks.MOSSY_STONE_BRICKS.getDefaultState(), 26, 26, 38, start);
        structure.setBlockState(world, Blocks.OAK_LEAVES.getDefaultState().with(LeavesBlock.PERSISTENT, true).with(LeavesBlock.DISTANCE, 7), 26, 26, 39, start);
        structure.setBlockState(world, Blocks.MOSSY_STONE_BRICKS.getDefaultState(), 26, 27, 22, start);
        structure.setBlockState(world, Blocks.GRASS_BLOCK.getDefaultState().with(SnowyDirtBlock.SNOWY, false), 26, 27, 23, start);
        structure.setBlockState(world, Blocks.GRASS_BLOCK.getDefaultState().with(SnowyDirtBlock.SNOWY, false), 26, 27, 36, start);
        structure.setBlockState(world, Blocks.MOSSY_COBBLESTONE.getDefaultState(), 26, 27, 37, start);
        structure.setBlockState(world, Blocks.STONE_BRICKS.getDefaultState(), 26, 27, 38, start);
        structure.setBlockState(world, Blocks.MOSSY_STONE_BRICKS.getDefaultState(), 26, 27, 39, start);
        structure.setBlockState(world, Blocks.TALL_GRASS.getDefaultState(), 26, 28, 23, start);
        structure.setBlockState(world, Blocks.MOSSY_COBBLESTONE.getDefaultState(), 26, 28, 33, start);
        structure.setBlockState(world, Blocks.TALL_GRASS.getDefaultState(), 26, 28, 36, start);
        structure.setBlockState(world, Blocks.CHEST.getDefaultState().with(ChestBlock.FACING, Direction.NORTH).with(ChestBlock.WATERLOGGED, false).with(ChestBlock.TYPE, ChestType.SINGLE), 26, 28, 37, start);
        structure.setBlockState(world, Blocks.TALL_GRASS.getDefaultState(), 26, 29, 23, start);
        structure.setBlockState(world, Blocks.STONE_BRICKS.getDefaultState(), 26, 29, 32, start);
        structure.setBlockState(world, Blocks.TALL_GRASS.getDefaultState(), 26, 29, 36, start);
        structure.setBlockState(world, Blocks.OAK_LEAVES.getDefaultState().with(LeavesBlock.PERSISTENT, true).with(LeavesBlock.DISTANCE, 7), 26, 29, 39, start);
        structure.setBlockState(world, Blocks.MOSSY_COBBLESTONE.getDefaultState(), 26, 30, 20, start);
        structure.setBlockState(world, Blocks.MOSSY_STONE_BRICKS.getDefaultState(), 26, 30, 21, start);
        structure.setBlockState(world, Blocks.COBBLESTONE_STAIRS.getDefaultState().with(StairsBlock.FACING, Direction.WEST).with(StairsBlock.WATERLOGGED, false).with(StairsBlock.SHAPE, StairsShape.STRAIGHT).with(StairsBlock.HALF, Half.BOTTOM), 26, 31, 20, start);
        structure.setBlockState(world, Blocks.MOSSY_COBBLESTONE.getDefaultState(), 26, 31, 21, start);
        structure.setBlockState(world, Blocks.COBBLESTONE_SLAB.getDefaultState().with(SlabBlock.TYPE, SlabType.BOTTOM).with(SlabBlock.WATERLOGGED, false), 26, 32, 39, start);
        structure.setBlockState(world, Blocks.COBBLESTONE_SLAB.getDefaultState().with(SlabBlock.TYPE, SlabType.BOTTOM).with(SlabBlock.WATERLOGGED, false), 26, 33, 38, start);
        structure.setBlockState(world, Blocks.GRASS.getDefaultState(), 27, 7, 18, start);
        structure.setBlockState(world, Blocks.AZURE_BLUET.getDefaultState(), 27, 7, 24, start);
        structure.setBlockState(world, Blocks.DANDELION.getDefaultState(), 27, 7, 41, start);
        structure.setBlockState(world, Blocks.TALL_GRASS.getDefaultState(), 27, 7, 43, start);
        structure.setBlockState(world, Blocks.MOSSY_STONE_BRICKS.getDefaultState(), 27, 7, 48, start);
        structure.setBlockState(world, Blocks.TALL_GRASS.getDefaultState(), 27, 8, 43, start);
        structure.setBlockState(world, Blocks.MOSSY_COBBLESTONE.getDefaultState(), 27, 8, 47, start);
        structure.setBlockState(world, Blocks.OAK_LEAVES.getDefaultState().with(LeavesBlock.PERSISTENT, true).with(LeavesBlock.DISTANCE, 7), 27, 9, 47, start);
        structure.setBlockState(world, Blocks.MOSSY_COBBLESTONE.getDefaultState(), 27, 11, 48, start);
        structure.setBlockState(world, Blocks.STONE_BRICK_STAIRS.getDefaultState().with(StairsBlock.FACING, Direction.WEST).with(StairsBlock.WATERLOGGED, false).with(StairsBlock.SHAPE, StairsShape.STRAIGHT).with(StairsBlock.HALF, Half.TOP), 27, 12, 38, start);
        structure.setBlockState(world, Blocks.STONE_BRICK_STAIRS.getDefaultState().with(StairsBlock.FACING, Direction.WEST).with(StairsBlock.WATERLOGGED, false).with(StairsBlock.SHAPE, StairsShape.STRAIGHT).with(StairsBlock.HALF, Half.TOP), 27, 12, 46, start);
        structure.setBlockState(world, Blocks.STONE_BRICK_STAIRS.getDefaultState().with(StairsBlock.FACING, Direction.WEST).with(StairsBlock.WATERLOGGED, false).with(StairsBlock.SHAPE, StairsShape.STRAIGHT).with(StairsBlock.HALF, Half.TOP), 27, 13, 20, start);
        structure.setBlockState(world, Blocks.STONE_BRICK_STAIRS.getDefaultState().with(StairsBlock.FACING, Direction.WEST).with(StairsBlock.WATERLOGGED, false).with(StairsBlock.SHAPE, StairsShape.STRAIGHT).with(StairsBlock.HALF, Half.TOP), 27, 13, 39, start);
        structure.setBlockState(world, Blocks.STONE_BRICK_STAIRS.getDefaultState().with(StairsBlock.FACING, Direction.WEST).with(StairsBlock.WATERLOGGED, false).with(StairsBlock.SHAPE, StairsShape.STRAIGHT).with(StairsBlock.HALF, Half.TOP), 27, 13, 45, start);
        structure.setBlockState(world, Blocks.MOSSY_STONE_BRICKS.getDefaultState(), 27, 13, 46, start);
        structure.setBlockState(world, Blocks.STONE_BRICK_STAIRS.getDefaultState().with(StairsBlock.FACING, Direction.SOUTH).with(StairsBlock.WATERLOGGED, false).with(StairsBlock.SHAPE, StairsShape.STRAIGHT).with(StairsBlock.HALF, Half.TOP), 27, 14, 44, start);
        structure.setBlockState(world, Blocks.OAK_LEAVES.getDefaultState().with(LeavesBlock.PERSISTENT, true).with(LeavesBlock.DISTANCE, 7), 27, 14, 48, start);
        structure.setBlockState(world, Blocks.STONE_BRICKS.getDefaultState(), 27, 15, 44, start);
        structure.setBlockState(world, Blocks.MOSSY_STONE_BRICKS.getDefaultState(), 27, 15, 48, start);
        structure.setBlockState(world, Blocks.STONE_BRICK_STAIRS.getDefaultState().with(StairsBlock.FACING, Direction.WEST).with(StairsBlock.WATERLOGGED, false).with(StairsBlock.SHAPE, StairsShape.STRAIGHT).with(StairsBlock.HALF, Half.TOP), 27, 20, 21, start);
        structure.setBlockState(world, Blocks.STONE_BRICK_STAIRS.getDefaultState().with(StairsBlock.FACING, Direction.WEST).with(StairsBlock.WATERLOGGED, false).with(StairsBlock.SHAPE, StairsShape.STRAIGHT).with(StairsBlock.HALF, Half.TOP), 27, 20, 38, start);
        structure.setBlockState(world, Blocks.COBBLESTONE_STAIRS.getDefaultState().with(StairsBlock.FACING, Direction.SOUTH).with(StairsBlock.WATERLOGGED, false).with(StairsBlock.SHAPE, StairsShape.STRAIGHT).with(StairsBlock.HALF, Half.BOTTOM), 27, 21, 19, start);
        structure.setBlockState(world, Blocks.STONE_BRICKS.getDefaultState(), 27, 21, 39, start);
        structure.setBlockState(world, Blocks.GREEN_STAINED_GLASS.getDefaultState(), 27, 22, 20, start);
        structure.setBlockState(world, Blocks.LIGHT_BLUE_STAINED_GLASS_PANE.getDefaultState().with(FourWayBlock.WATERLOGGED, false).with(FourWayBlock.NORTH, true).with(FourWayBlock.SOUTH, false).with(FourWayBlock.EAST, true).with(FourWayBlock.WEST, true), 27, 22, 21, start);
        structure.setBlockState(world, Blocks.LIGHT_BLUE_STAINED_GLASS_PANE.getDefaultState().with(FourWayBlock.WATERLOGGED, false).with(FourWayBlock.NORTH, false).with(FourWayBlock.SOUTH, true).with(FourWayBlock.EAST, true).with(FourWayBlock.WEST, false), 27, 22, 38, start);
        structure.setBlockState(world, Blocks.GREEN_STAINED_GLASS.getDefaultState(), 27, 22, 39, start);
        structure.setBlockState(world, Blocks.GREEN_STAINED_GLASS_PANE.getDefaultState().with(FourWayBlock.WATERLOGGED, false).with(FourWayBlock.NORTH, false).with(FourWayBlock.SOUTH, true).with(FourWayBlock.EAST, true).with(FourWayBlock.WEST, true), 27, 23, 20, start);
        structure.setBlockState(world, Blocks.PURPLE_STAINED_GLASS_PANE.getDefaultState().with(FourWayBlock.WATERLOGGED, false).with(FourWayBlock.NORTH, true).with(FourWayBlock.SOUTH, false).with(FourWayBlock.EAST, true).with(FourWayBlock.WEST, true), 27, 23, 21, start);
        structure.setBlockState(world, Blocks.PURPLE_STAINED_GLASS_PANE.getDefaultState().with(FourWayBlock.WATERLOGGED, false).with(FourWayBlock.NORTH, false).with(FourWayBlock.SOUTH, true).with(FourWayBlock.EAST, true).with(FourWayBlock.WEST, true), 27, 23, 38, start);
        structure.setBlockState(world, Blocks.GREEN_STAINED_GLASS_PANE.getDefaultState().with(FourWayBlock.WATERLOGGED, false).with(FourWayBlock.NORTH, true).with(FourWayBlock.SOUTH, false).with(FourWayBlock.EAST, true).with(FourWayBlock.WEST, true), 27, 23, 39, start);
        structure.setBlockState(world, Blocks.GRAY_STAINED_GLASS.getDefaultState(), 27, 24, 20, start);
        structure.setBlockState(world, Blocks.MAGENTA_STAINED_GLASS_PANE.getDefaultState().with(FourWayBlock.WATERLOGGED, false).with(FourWayBlock.NORTH, false).with(FourWayBlock.SOUTH, false).with(FourWayBlock.EAST, false).with(FourWayBlock.WEST, true), 27, 24, 38, start);
        structure.setBlockState(world, Blocks.GREEN_STAINED_GLASS.getDefaultState(), 27, 25, 20, start);
        structure.setBlockState(world, Blocks.LIGHT_BLUE_STAINED_GLASS_PANE.getDefaultState().with(FourWayBlock.WATERLOGGED, false).with(FourWayBlock.NORTH, true).with(FourWayBlock.SOUTH, false).with(FourWayBlock.EAST, true).with(FourWayBlock.WEST, true), 27, 25, 21, start);
        structure.setBlockState(world, Blocks.LIGHT_BLUE_STAINED_GLASS_PANE.getDefaultState().with(FourWayBlock.WATERLOGGED, false).with(FourWayBlock.NORTH, false).with(FourWayBlock.SOUTH, true).with(FourWayBlock.EAST, true).with(FourWayBlock.WEST, true), 27, 25, 38, start);
        structure.setBlockState(world, Blocks.GREEN_STAINED_GLASS.getDefaultState(), 27, 25, 39, start);
        structure.setBlockState(world, Blocks.OAK_LEAVES.getDefaultState().with(LeavesBlock.PERSISTENT, true).with(LeavesBlock.DISTANCE, 7), 27, 26, 20, start);
        structure.setBlockState(world, Blocks.CYAN_STAINED_GLASS_PANE.getDefaultState().with(FourWayBlock.WATERLOGGED, false).with(FourWayBlock.NORTH, false).with(FourWayBlock.SOUTH, false).with(FourWayBlock.EAST, true).with(FourWayBlock.WEST, true), 27, 26, 21, start);
        structure.setBlockState(world, Blocks.MOSSY_STONE_BRICKS.getDefaultState(), 27, 26, 23, start);
        structure.setBlockState(world, Blocks.CYAN_STAINED_GLASS_PANE.getDefaultState().with(FourWayBlock.WATERLOGGED, false).with(FourWayBlock.NORTH, false).with(FourWayBlock.SOUTH, true).with(FourWayBlock.EAST, true).with(FourWayBlock.WEST, true), 27, 26, 38, start);
        structure.setBlockState(world, Blocks.BROWN_STAINED_GLASS.getDefaultState(), 27, 26, 39, start);
        structure.setBlockState(world, Blocks.MOSSY_STONE_BRICKS.getDefaultState(), 27, 28, 20, start);
        structure.setBlockState(world, Blocks.STONE_BRICKS.getDefaultState(), 27, 28, 33, start);
        structure.setBlockState(world, Blocks.AIR.getDefaultState(), 27, 28, 37, start);
        structure.setBlockState(world, Blocks.MOSSY_STONE_BRICKS.getDefaultState(), 27, 28, 39, start);
        structure.setBlockState(world, Blocks.STONE_BRICK_STAIRS.getDefaultState().with(StairsBlock.FACING, Direction.NORTH).with(StairsBlock.WATERLOGGED, false).with(StairsBlock.SHAPE, StairsShape.STRAIGHT).with(StairsBlock.HALF, Half.BOTTOM), 27, 29, 33, start);
        structure.setBlockState(world, Blocks.VINE.getDefaultState().with(VineBlock.UP, false).with(VineBlock.NORTH, false).with(VineBlock.SOUTH, false).with(VineBlock.EAST, false).with(VineBlock.WEST, true), 27, 31, 39, start);
        structure.setBlockState(world, Blocks.GRASS.getDefaultState(), 28, 7, 10, start);
        structure.setBlockState(world, Blocks.OXEYE_DAISY.getDefaultState(), 28, 7, 19, start);
        structure.setBlockState(world, Blocks.GRASS.getDefaultState(), 28, 7, 20, start);
        structure.setBlockState(world, Blocks.GRASS.getDefaultState(), 28, 7, 22, start);
        structure.setBlockState(world, Blocks.TALL_GRASS.getDefaultState(), 28, 7, 23, start);
        structure.setBlockState(world, Blocks.GRASS.getDefaultState(), 28, 7, 24, start);
        structure.setBlockState(world, Blocks.POPPY.getDefaultState(), 28, 7, 35, start);
        structure.setBlockState(world, Blocks.GRASS.getDefaultState(), 28, 7, 51, start);
        structure.setBlockState(world, Blocks.GRASS.getDefaultState(), 28, 7, 53, start);
        structure.setBlockState(world, Blocks.VINE.getDefaultState().with(VineBlock.UP, true).with(VineBlock.NORTH, false).with(VineBlock.SOUTH, false).with(VineBlock.EAST, true).with(VineBlock.WEST, false), 28, 8, 46, start);
        structure.setBlockState(world, Blocks.OAK_LEAVES.getDefaultState().with(LeavesBlock.PERSISTENT, true).with(LeavesBlock.DISTANCE, 7), 28, 8, 47, start);
        structure.setBlockState(world, Blocks.MOSSY_STONE_BRICKS.getDefaultState(), 28, 10, 47, start);
        structure.setBlockState(world, Blocks.STONE_BRICK_STAIRS.getDefaultState().with(StairsBlock.FACING, Direction.EAST).with(StairsBlock.WATERLOGGED, false).with(StairsBlock.SHAPE, StairsShape.STRAIGHT).with(StairsBlock.HALF, Half.TOP), 28, 12, 21, start);
        structure.setBlockState(world, Blocks.STONE_BRICK_STAIRS.getDefaultState().with(StairsBlock.FACING, Direction.EAST).with(StairsBlock.WATERLOGGED, false).with(StairsBlock.SHAPE, StairsShape.STRAIGHT).with(StairsBlock.HALF, Half.TOP), 28, 12, 38, start);
        structure.setBlockState(world, Blocks.STONE_BRICK_STAIRS.getDefaultState().with(StairsBlock.FACING, Direction.EAST).with(StairsBlock.WATERLOGGED, false).with(StairsBlock.SHAPE, StairsShape.STRAIGHT).with(StairsBlock.HALF, Half.TOP), 28, 12, 46, start);
        structure.setBlockState(world, Blocks.STONE_BRICK_STAIRS.getDefaultState().with(StairsBlock.FACING, Direction.EAST).with(StairsBlock.WATERLOGGED, false).with(StairsBlock.SHAPE, StairsShape.STRAIGHT).with(StairsBlock.HALF, Half.TOP), 28, 13, 20, start);
        structure.setBlockState(world, Blocks.OAK_LEAVES.getDefaultState().with(LeavesBlock.PERSISTENT, true).with(LeavesBlock.DISTANCE, 7), 28, 13, 38, start);
        structure.setBlockState(world, Blocks.STONE_BRICK_STAIRS.getDefaultState().with(StairsBlock.FACING, Direction.EAST).with(StairsBlock.WATERLOGGED, false).with(StairsBlock.SHAPE, StairsShape.STRAIGHT).with(StairsBlock.HALF, Half.TOP), 28, 13, 39, start);
        structure.setBlockState(world, Blocks.STONE_BRICK_STAIRS.getDefaultState().with(StairsBlock.FACING, Direction.EAST).with(StairsBlock.WATERLOGGED, false).with(StairsBlock.SHAPE, StairsShape.STRAIGHT).with(StairsBlock.HALF, Half.TOP), 28, 13, 45, start);
        structure.setBlockState(world, Blocks.MOSSY_COBBLESTONE.getDefaultState(), 28, 13, 46, start);
        structure.setBlockState(world, Blocks.MOSSY_STONE_BRICKS.getDefaultState(), 28, 14, 20, start);
        structure.setBlockState(world, Blocks.STONE_BRICKS.getDefaultState(), 28, 14, 38, start);
        structure.setBlockState(world, Blocks.MOSSY_COBBLESTONE.getDefaultState(), 28, 14, 39, start);
        structure.setBlockState(world, Blocks.STONE_BRICK_STAIRS.getDefaultState().with(StairsBlock.FACING, Direction.NORTH).with(StairsBlock.WATERLOGGED, false).with(StairsBlock.SHAPE, StairsShape.STRAIGHT).with(StairsBlock.HALF, Half.TOP), 28, 14, 40, start);
        structure.setBlockState(world, Blocks.MOSSY_STONE_BRICKS.getDefaultState(), 28, 14, 48, start);
        structure.setBlockState(world, Blocks.STONE_BRICKS.getDefaultState(), 28, 15, 20, start);
        structure.setBlockState(world, Blocks.MOSSY_STONE_BRICKS.getDefaultState(), 28, 15, 39, start);
        structure.setBlockState(world, Blocks.STONE_BRICKS.getDefaultState(), 28, 20, 40, start);
        structure.setBlockState(world, Blocks.STONE_BRICK_STAIRS.getDefaultState().with(StairsBlock.FACING, Direction.SOUTH).with(StairsBlock.WATERLOGGED, false).with(StairsBlock.SHAPE, StairsShape.STRAIGHT).with(StairsBlock.HALF, Half.BOTTOM), 28, 21, 19, start);
        structure.setBlockState(world, Blocks.STONE_BRICKS.getDefaultState(), 28, 21, 20, start);
        structure.setBlockState(world, Blocks.COBBLESTONE_STAIRS.getDefaultState().with(StairsBlock.FACING, Direction.NORTH).with(StairsBlock.WATERLOGGED, false).with(StairsBlock.SHAPE, StairsShape.STRAIGHT).with(StairsBlock.HALF, Half.BOTTOM), 28, 21, 40, start);
        structure.setBlockState(world, Blocks.CYAN_STAINED_GLASS_PANE.getDefaultState().with(FourWayBlock.WATERLOGGED, false).with(FourWayBlock.NORTH, false).with(FourWayBlock.SOUTH, false).with(FourWayBlock.EAST, true).with(FourWayBlock.WEST, true), 28, 22, 21, start);
        structure.setBlockState(world, Blocks.CYAN_STAINED_GLASS_PANE.getDefaultState().with(FourWayBlock.WATERLOGGED, false).with(FourWayBlock.NORTH, false).with(FourWayBlock.SOUTH, true).with(FourWayBlock.EAST, true).with(FourWayBlock.WEST, true), 28, 22, 38, start);
        structure.setBlockState(world, Blocks.BROWN_STAINED_GLASS.getDefaultState(), 28, 22, 39, start);
        structure.setBlockState(world, Blocks.GRAY_STAINED_GLASS.getDefaultState(), 28, 23, 20, start);
        structure.setBlockState(world, Blocks.MAGENTA_STAINED_GLASS_PANE.getDefaultState().with(FourWayBlock.WATERLOGGED, false).with(FourWayBlock.NORTH, true).with(FourWayBlock.SOUTH, false).with(FourWayBlock.EAST, true).with(FourWayBlock.WEST, true), 28, 23, 21, start);
        structure.setBlockState(world, Blocks.MAGENTA_STAINED_GLASS_PANE.getDefaultState().with(FourWayBlock.WATERLOGGED, false).with(FourWayBlock.NORTH, false).with(FourWayBlock.SOUTH, true).with(FourWayBlock.EAST, true).with(FourWayBlock.WEST, true), 28, 23, 38, start);
        structure.setBlockState(world, Blocks.GRAY_STAINED_GLASS.getDefaultState(), 28, 23, 39, start);
        structure.setBlockState(world, Blocks.GREEN_STAINED_GLASS_PANE.getDefaultState().with(FourWayBlock.WATERLOGGED, false).with(FourWayBlock.NORTH, false).with(FourWayBlock.SOUTH, true).with(FourWayBlock.EAST, true).with(FourWayBlock.WEST, true), 28, 24, 20, start);
        structure.setBlockState(world, Blocks.PURPLE_STAINED_GLASS_PANE.getDefaultState().with(FourWayBlock.WATERLOGGED, false).with(FourWayBlock.NORTH, true).with(FourWayBlock.SOUTH, false).with(FourWayBlock.EAST, true).with(FourWayBlock.WEST, false), 28, 24, 21, start);
        structure.setBlockState(world, Blocks.GREEN_STAINED_GLASS_PANE.getDefaultState().with(FourWayBlock.WATERLOGGED, false).with(FourWayBlock.NORTH, false).with(FourWayBlock.SOUTH, false).with(FourWayBlock.EAST, true).with(FourWayBlock.WEST, false), 28, 24, 39, start);
        structure.setBlockState(world, Blocks.BROWN_STAINED_GLASS_PANE.getDefaultState().with(FourWayBlock.WATERLOGGED, false).with(FourWayBlock.NORTH, false).with(FourWayBlock.SOUTH, true).with(FourWayBlock.EAST, true).with(FourWayBlock.WEST, true), 28, 25, 20, start);
        structure.setBlockState(world, Blocks.BLUE_STAINED_GLASS_PANE.getDefaultState().with(FourWayBlock.WATERLOGGED, false).with(FourWayBlock.NORTH, true).with(FourWayBlock.SOUTH, false).with(FourWayBlock.EAST, true).with(FourWayBlock.WEST, true), 28, 25, 21, start);
        structure.setBlockState(world, Blocks.BLUE_STAINED_GLASS_PANE.getDefaultState().with(FourWayBlock.WATERLOGGED, false).with(FourWayBlock.NORTH, false).with(FourWayBlock.SOUTH, false).with(FourWayBlock.EAST, true).with(FourWayBlock.WEST, true), 28, 25, 38, start);
        structure.setBlockState(world, Blocks.GRAY_STAINED_GLASS.getDefaultState(), 28, 26, 20, start);
        structure.setBlockState(world, Blocks.MAGENTA_STAINED_GLASS_PANE.getDefaultState().with(FourWayBlock.WATERLOGGED, false).with(FourWayBlock.NORTH, true).with(FourWayBlock.SOUTH, false).with(FourWayBlock.EAST, true).with(FourWayBlock.WEST, true), 28, 26, 21, start);
        structure.setBlockState(world, Blocks.MAGENTA_STAINED_GLASS_PANE.getDefaultState().with(FourWayBlock.WATERLOGGED, false).with(FourWayBlock.NORTH, false).with(FourWayBlock.SOUTH, true).with(FourWayBlock.EAST, true).with(FourWayBlock.WEST, true), 28, 26, 38, start);
        structure.setBlockState(world, Blocks.GRAY_STAINED_GLASS.getDefaultState(), 28, 26, 39, start);
        structure.setBlockState(world, Blocks.MOSSY_COBBLESTONE.getDefaultState(), 28, 27, 20, start);
        structure.setBlockState(world, Blocks.MOSSY_COBBLESTONE.getDefaultState(), 28, 27, 22, start);
        structure.setBlockState(world, Blocks.MOSSY_STONE_BRICKS.getDefaultState(), 28, 27, 24, start);
        structure.setBlockState(world, Blocks.STONE_BRICKS.getDefaultState(), 28, 27, 39, start);
        structure.setBlockState(world, Blocks.MOSSY_COBBLESTONE.getDefaultState(), 28, 28, 33, start);
        structure.setBlockState(world, Blocks.AIR.getDefaultState(), 28, 28, 35, start);
        structure.setBlockState(world, Blocks.TALL_GRASS.getDefaultState(), 28, 29, 25, start);
        structure.setBlockState(world, Blocks.TALL_GRASS.getDefaultState(), 28, 30, 25, start);
        structure.setBlockState(world, Blocks.DIRT.getDefaultState(), 29, 6, 33, start);
        structure.setBlockState(world, Blocks.TALL_GRASS.getDefaultState(), 29, 7, 19, start);
        structure.setBlockState(world, Blocks.STONE_BRICK_SLAB.getDefaultState().with(SlabBlock.TYPE, SlabType.BOTTOM).with(SlabBlock.WATERLOGGED, false), 29, 7, 33, start);
        structure.setBlockState(world, Blocks.STONE_BRICKS.getDefaultState(), 29, 7, 38, start);
        structure.setBlockState(world, Blocks.TALL_GRASS.getDefaultState(), 29, 7, 41, start);
        structure.setBlockState(world, Blocks.GRASS.getDefaultState(), 29, 7, 55, start);
        structure.setBlockState(world, Blocks.TALL_GRASS.getDefaultState(), 29, 8, 19, start);
        structure.setBlockState(world, Blocks.OAK_LEAVES.getDefaultState().with(LeavesBlock.PERSISTENT, true).with(LeavesBlock.DISTANCE, 7), 29, 8, 20, start);
        structure.setBlockState(world, Blocks.TALL_GRASS.getDefaultState(), 29, 8, 22, start);
        structure.setBlockState(world, Blocks.OAK_LEAVES.getDefaultState().with(LeavesBlock.PERSISTENT, true).with(LeavesBlock.DISTANCE, 7), 29, 8, 37, start);
        structure.setBlockState(world, Blocks.TALL_GRASS.getDefaultState(), 29, 8, 41, start);
        structure.setBlockState(world, Blocks.MOSSY_COBBLESTONE.getDefaultState(), 29, 8, 49, start);
        structure.setBlockState(world, Blocks.MOSSY_COBBLESTONE.getDefaultState(), 29, 9, 21, start);
        structure.setBlockState(world, Blocks.MOSSY_COBBLESTONE.getDefaultState(), 29, 10, 38, start);
        structure.setBlockState(world, Blocks.OAK_LEAVES.getDefaultState().with(LeavesBlock.PERSISTENT, true).with(LeavesBlock.DISTANCE, 7), 29, 10, 46, start);
        structure.setBlockState(world, Blocks.STONE_BRICKS.getDefaultState(), 29, 11, 38, start);
        structure.setBlockState(world, Blocks.STONE_BRICK_STAIRS.getDefaultState().with(StairsBlock.FACING, Direction.EAST).with(StairsBlock.WATERLOGGED, false).with(StairsBlock.SHAPE, StairsShape.STRAIGHT).with(StairsBlock.HALF, Half.TOP), 29, 12, 45, start);
        structure.setBlockState(world, Blocks.OAK_LEAVES.getDefaultState().with(LeavesBlock.PERSISTENT, true).with(LeavesBlock.DISTANCE, 7), 29, 12, 49, start);
        structure.setBlockState(world, Blocks.STONE_BRICKS.getDefaultState(), 29, 13, 38, start);
        structure.setBlockState(world, Blocks.STONE_BRICK_SLAB.getDefaultState().with(SlabBlock.TYPE, SlabType.TOP).with(SlabBlock.WATERLOGGED, false), 29, 13, 40, start);
        structure.setBlockState(world, Blocks.STONE_BRICK_SLAB.getDefaultState().with(SlabBlock.TYPE, SlabType.TOP).with(SlabBlock.WATERLOGGED, false), 29, 13, 44, start);
        structure.setBlockState(world, Blocks.OAK_LEAVES.getDefaultState().with(LeavesBlock.PERSISTENT, true).with(LeavesBlock.DISTANCE, 7), 29, 13, 45, start);
        structure.setBlockState(world, Blocks.STONE_BRICK_STAIRS.getDefaultState().with(StairsBlock.FACING, Direction.EAST).with(StairsBlock.WATERLOGGED, false).with(StairsBlock.SHAPE, StairsShape.STRAIGHT).with(StairsBlock.HALF, Half.TOP), 29, 14, 42, start);
        structure.setBlockState(world, Blocks.COBBLESTONE_STAIRS.getDefaultState().with(StairsBlock.FACING, Direction.EAST).with(StairsBlock.WATERLOGGED, false).with(StairsBlock.SHAPE, StairsShape.STRAIGHT).with(StairsBlock.HALF, Half.TOP), 29, 14, 43, start);
        structure.setBlockState(world, Blocks.STONE_BRICKS.getDefaultState(), 29, 14, 44, start);
        structure.setBlockState(world, Blocks.GRASS_BLOCK.getDefaultState().with(SnowyDirtBlock.SNOWY, false), 29, 15, 39, start);
        structure.setBlockState(world, Blocks.MOSSY_STONE_BRICKS.getDefaultState(), 29, 15, 46, start);
        structure.setBlockState(world, Blocks.MOSSY_COBBLESTONE.getDefaultState(), 29, 15, 49, start);
        structure.setBlockState(world, Blocks.STONE_BRICKS.getDefaultState(), 29, 16, 38, start);
        structure.setBlockState(world, Blocks.TALL_GRASS.getDefaultState(), 29, 16, 39, start);
        structure.setBlockState(world, Blocks.GRASS_BLOCK.getDefaultState().with(SnowyDirtBlock.SNOWY, false), 29, 16, 47, start);
        structure.setBlockState(world, Blocks.TALL_GRASS.getDefaultState(), 29, 17, 39, start);
        structure.setBlockState(world, Blocks.MOSSY_STONE_BRICKS.getDefaultState(), 29, 19, 38, start);
        structure.setBlockState(world, Blocks.MOSSY_COBBLESTONE.getDefaultState(), 29, 20, 40, start);
        structure.setBlockState(world, Blocks.OAK_LEAVES.getDefaultState().with(LeavesBlock.PERSISTENT, true).with(LeavesBlock.DISTANCE, 7), 29, 21, 19, start);
        structure.setBlockState(world, Blocks.STONE_BRICK_STAIRS.getDefaultState().with(StairsBlock.FACING, Direction.NORTH).with(StairsBlock.WATERLOGGED, false).with(StairsBlock.SHAPE, StairsShape.STRAIGHT).with(StairsBlock.HALF, Half.BOTTOM), 29, 21, 40, start);
        structure.setBlockState(world, Blocks.MOSSY_COBBLESTONE.getDefaultState(), 29, 22, 39, start);
        structure.setBlockState(world, Blocks.MOSSY_STONE_BRICKS.getDefaultState(), 29, 23, 39, start);
        structure.setBlockState(world, Blocks.OAK_LEAVES.getDefaultState().with(LeavesBlock.PERSISTENT, true).with(LeavesBlock.DISTANCE, 7), 29, 25, 40, start);
        structure.setBlockState(world, Blocks.OAK_LEAVES.getDefaultState().with(LeavesBlock.PERSISTENT, true).with(LeavesBlock.DISTANCE, 7), 29, 26, 37, start);
        structure.setBlockState(world, Blocks.MOSSY_STONE_BRICKS.getDefaultState(), 29, 26, 38, start);
        structure.setBlockState(world, Blocks.OAK_LEAVES.getDefaultState().with(LeavesBlock.PERSISTENT, true).with(LeavesBlock.DISTANCE, 7), 29, 26, 39, start);
        structure.setBlockState(world, Blocks.VINE.getDefaultState().with(VineBlock.UP, false).with(VineBlock.NORTH, true).with(VineBlock.SOUTH, false).with(VineBlock.EAST, true).with(VineBlock.WEST, false), 29, 26, 40, start);
        structure.setBlockState(world, Blocks.MOSSY_COBBLESTONE.getDefaultState(), 29, 27, 24, start);
        structure.setBlockState(world, Blocks.MOSSY_COBBLESTONE.getDefaultState(), 29, 28, 21, start);
        structure.setBlockState(world, Blocks.STONE_BRICKS.getDefaultState(), 29, 28, 33, start);
        structure.setBlockState(world, Blocks.MOSSY_COBBLESTONE.getDefaultState(), 29, 28, 39, start);
        structure.setBlockState(world, Blocks.OAK_LEAVES.getDefaultState().with(LeavesBlock.PERSISTENT, true).with(LeavesBlock.DISTANCE, 7), 29, 28, 40, start);
        structure.setBlockState(world, Blocks.MOSSY_STONE_BRICKS.getDefaultState(), 29, 29, 21, start);
        structure.setBlockState(world, Blocks.DANDELION.getDefaultState(), 29, 29, 25, start);
        structure.setBlockState(world, Blocks.STONE_BRICK_STAIRS.getDefaultState().with(StairsBlock.FACING, Direction.NORTH).with(StairsBlock.WATERLOGGED, false).with(StairsBlock.SHAPE, StairsShape.STRAIGHT).with(StairsBlock.HALF, Half.TOP), 29, 29, 27, start);
        structure.setBlockState(world, Blocks.OAK_LEAVES.getDefaultState().with(LeavesBlock.PERSISTENT, true).with(LeavesBlock.DISTANCE, 7), 29, 29, 39, start);
        structure.setBlockState(world, Blocks.MOSSY_COBBLESTONE.getDefaultState(), 29, 32, 38, start);
        structure.setBlockState(world, Blocks.STONE_BRICKS.getDefaultState(), 29, 33, 38, start);
        structure.setBlockState(world, Blocks.GRASS.getDefaultState(), 30, 7, 13, start);
        structure.setBlockState(world, Blocks.GRASS.getDefaultState(), 30, 7, 19, start);
        structure.setBlockState(world, Blocks.STONE_BRICK_STAIRS.getDefaultState().with(StairsBlock.FACING, Direction.WEST).with(StairsBlock.WATERLOGGED, false).with(StairsBlock.SHAPE, StairsShape.STRAIGHT).with(StairsBlock.HALF, Half.BOTTOM), 30, 7, 28, start);
        structure.setBlockState(world, Blocks.AIR.getDefaultState(), 30, 7, 36, start);
        structure.setBlockState(world, Blocks.MOSSY_STONE_BRICKS.getDefaultState(), 30, 7, 48, start);
        structure.setBlockState(world, Blocks.GRASS.getDefaultState(), 30, 7, 57, start);
        structure.setBlockState(world, Blocks.MOSSY_STONE_BRICKS.getDefaultState(), 30, 8, 45, start);
        structure.setBlockState(world, Blocks.STONE_BRICKS.getDefaultState(), 30, 8, 46, start);
        structure.setBlockState(world, Blocks.OAK_LEAVES.getDefaultState().with(LeavesBlock.PERSISTENT, true).with(LeavesBlock.DISTANCE, 7), 30, 9, 20, start);
        structure.setBlockState(world, Blocks.MOSSY_COBBLESTONE.getDefaultState(), 30, 9, 37, start);
        structure.setBlockState(world, Blocks.STONE_BRICKS.getDefaultState(), 30, 9, 38, start);
        structure.setBlockState(world, Blocks.STONE_BRICKS.getDefaultState(), 30, 9, 45, start);
        structure.setBlockState(world, Blocks.MOSSY_COBBLESTONE.getDefaultState(), 30, 10, 20, start);
        structure.setBlockState(world, Blocks.STONE_BRICKS.getDefaultState(), 30, 10, 37, start);
        structure.setBlockState(world, Blocks.STONE_BRICKS.getDefaultState(), 30, 10, 39, start);
        structure.setBlockState(world, Blocks.OAK_LEAVES.getDefaultState().with(LeavesBlock.PERSISTENT, true).with(LeavesBlock.DISTANCE, 7), 30, 11, 22, start);
        structure.setBlockState(world, Blocks.OAK_LEAVES.getDefaultState().with(LeavesBlock.PERSISTENT, true).with(LeavesBlock.DISTANCE, 7), 30, 11, 37, start);
        structure.setBlockState(world, Blocks.OAK_LEAVES.getDefaultState().with(LeavesBlock.PERSISTENT, true).with(LeavesBlock.DISTANCE, 7), 30, 11, 39, start);
        structure.setBlockState(world, Blocks.STONE_BRICKS.getDefaultState(), 30, 11, 49, start);
        structure.setBlockState(world, Blocks.STONE_BRICKS.getDefaultState(), 30, 12, 20, start);
        structure.setBlockState(world, Blocks.STONE_BRICKS.getDefaultState(), 30, 12, 39, start);
        structure.setBlockState(world, Blocks.STONE_BRICK_STAIRS.getDefaultState().with(StairsBlock.FACING, Direction.NORTH).with(StairsBlock.WATERLOGGED, false).with(StairsBlock.SHAPE, StairsShape.STRAIGHT).with(StairsBlock.HALF, Half.TOP), 30, 12, 40, start);
        structure.setBlockState(world, Blocks.STONE_BRICK_STAIRS.getDefaultState().with(StairsBlock.FACING, Direction.SOUTH).with(StairsBlock.WATERLOGGED, false).with(StairsBlock.SHAPE, StairsShape.STRAIGHT).with(StairsBlock.HALF, Half.TOP), 30, 12, 44, start);
        structure.setBlockState(world, Blocks.STONE_BRICK_STAIRS.getDefaultState().with(StairsBlock.FACING, Direction.NORTH).with(StairsBlock.WATERLOGGED, false).with(StairsBlock.SHAPE, StairsShape.STRAIGHT).with(StairsBlock.HALF, Half.TOP), 30, 13, 41, start);
        structure.setBlockState(world, Blocks.STONE_BRICK_STAIRS.getDefaultState().with(StairsBlock.FACING, Direction.SOUTH).with(StairsBlock.WATERLOGGED, false).with(StairsBlock.SHAPE, StairsShape.STRAIGHT).with(StairsBlock.HALF, Half.TOP), 30, 13, 43, start);
        structure.setBlockState(world, Blocks.STONE_BRICKS.getDefaultState(), 30, 13, 44, start);
        structure.setBlockState(world, Blocks.MOSSY_STONE_BRICKS.getDefaultState(), 30, 13, 50, start);
        structure.setBlockState(world, Blocks.OAK_LEAVES.getDefaultState().with(LeavesBlock.PERSISTENT, true).with(LeavesBlock.DISTANCE, 7), 30, 14, 20, start);
        structure.setBlockState(world, Blocks.MOSSY_COBBLESTONE.getDefaultState(), 30, 14, 22, start);
        structure.setBlockState(world, Blocks.STONE_BRICKS.getDefaultState(), 30, 14, 37, start);
        structure.setBlockState(world, Blocks.MOSSY_COBBLESTONE.getDefaultState(), 30, 14, 42, start);
        structure.setBlockState(world, Blocks.STONE_BRICKS.getDefaultState(), 30, 14, 43, start);
        structure.setBlockState(world, Blocks.MOSSY_STONE_BRICKS.getDefaultState(), 30, 15, 37, start);
        structure.setBlockState(world, Blocks.MOSSY_STONE_BRICKS.getDefaultState(), 30, 15, 41, start);
        structure.setBlockState(world, Blocks.MOSSY_COBBLESTONE.getDefaultState(), 30, 15, 45, start);
        structure.setBlockState(world, Blocks.MOSSY_STONE_BRICKS.getDefaultState(), 30, 16, 22, start);
        structure.setBlockState(world, Blocks.OAK_LEAVES.getDefaultState().with(LeavesBlock.PERSISTENT, true).with(LeavesBlock.DISTANCE, 7), 30, 16, 39, start);
        structure.setBlockState(world, Blocks.TALL_GRASS.getDefaultState(), 30, 16, 42, start);
        structure.setBlockState(world, Blocks.GRASS.getDefaultState(), 30, 16, 43, start);
        structure.setBlockState(world, Blocks.OAK_LEAVES.getDefaultState().with(LeavesBlock.PERSISTENT, true).with(LeavesBlock.DISTANCE, 7), 30, 16, 47, start);
        structure.setBlockState(world, Blocks.STONE_BRICK_STAIRS.getDefaultState().with(StairsBlock.FACING, Direction.NORTH).with(StairsBlock.WATERLOGGED, false).with(StairsBlock.SHAPE, StairsShape.STRAIGHT).with(StairsBlock.HALF, Half.TOP), 30, 16, 50, start);
        structure.setBlockState(world, Blocks.MOSSY_COBBLESTONE.getDefaultState(), 30, 17, 37, start);
        structure.setBlockState(world, Blocks.STONE_BRICKS.getDefaultState(), 30, 17, 39, start);
        structure.setBlockState(world, Blocks.TALL_GRASS.getDefaultState(), 30, 17, 42, start);
        structure.setBlockState(world, Blocks.OAK_LEAVES.getDefaultState().with(LeavesBlock.PERSISTENT, true).with(LeavesBlock.DISTANCE, 7), 30, 17, 48, start);
        structure.setBlockState(world, Blocks.COBBLESTONE_STAIRS.getDefaultState().with(StairsBlock.FACING, Direction.NORTH).with(StairsBlock.WATERLOGGED, false).with(StairsBlock.SHAPE, StairsShape.STRAIGHT).with(StairsBlock.HALF, Half.BOTTOM), 30, 17, 50, start);
        structure.setBlockState(world, Blocks.COBBLESTONE_STAIRS.getDefaultState().with(StairsBlock.FACING, Direction.NORTH).with(StairsBlock.WATERLOGGED, false).with(StairsBlock.SHAPE, StairsShape.STRAIGHT).with(StairsBlock.HALF, Half.BOTTOM), 30, 18, 46, start);
        structure.setBlockState(world, Blocks.MOSSY_STONE_BRICKS.getDefaultState(), 30, 20, 19, start);
        structure.setBlockState(world, Blocks.OAK_LEAVES.getDefaultState().with(LeavesBlock.PERSISTENT, true).with(LeavesBlock.DISTANCE, 7), 30, 20, 20, start);
        structure.setBlockState(world, Blocks.STONE_BRICKS.getDefaultState(), 30, 20, 21, start);
        structure.setBlockState(world, Blocks.OAK_LEAVES.getDefaultState().with(LeavesBlock.PERSISTENT, true).with(LeavesBlock.DISTANCE, 7), 30, 20, 37, start);
        structure.setBlockState(world, Blocks.VINE.getDefaultState().with(VineBlock.UP, false).with(VineBlock.NORTH, true).with(VineBlock.SOUTH, false).with(VineBlock.EAST, true).with(VineBlock.WEST, false), 30, 20, 41, start);
        structure.setBlockState(world, Blocks.MOSSY_COBBLESTONE.getDefaultState(), 30, 21, 37, start);
        structure.setBlockState(world, Blocks.STONE_BRICKS.getDefaultState(), 30, 22, 19, start);
        structure.setBlockState(world, Blocks.MOSSY_STONE_BRICKS.getDefaultState(), 30, 22, 40, start);
        structure.setBlockState(world, Blocks.OAK_LEAVES.getDefaultState().with(LeavesBlock.PERSISTENT, true).with(LeavesBlock.DISTANCE, 7), 30, 23, 19, start);
        structure.setBlockState(world, Blocks.STONE_BRICKS.getDefaultState(), 30, 23, 20, start);
        structure.setBlockState(world, Blocks.MOSSY_STONE_BRICKS.getDefaultState(), 30, 23, 21, start);
        structure.setBlockState(world, Blocks.STONE_BRICKS.getDefaultState(), 30, 23, 22, start);
        structure.setBlockState(world, Blocks.OAK_LEAVES.getDefaultState().with(LeavesBlock.PERSISTENT, true).with(LeavesBlock.DISTANCE, 7), 30, 24, 40, start);
        structure.setBlockState(world, Blocks.MOSSY_COBBLESTONE.getDefaultState(), 30, 25, 40, start);
        structure.setBlockState(world, Blocks.MOSSY_STONE_BRICKS.getDefaultState(), 30, 26, 36, start);
        structure.setBlockState(world, Blocks.STONE_BRICKS.getDefaultState(), 30, 26, 39, start);
        structure.setBlockState(world, Blocks.MOSSY_STONE_BRICKS.getDefaultState(), 30, 26, 40, start);
        structure.setBlockState(world, Blocks.COBBLESTONE_STAIRS.getDefaultState().with(StairsBlock.FACING, Direction.SOUTH).with(StairsBlock.WATERLOGGED, false).with(StairsBlock.SHAPE, StairsShape.STRAIGHT).with(StairsBlock.HALF, Half.TOP), 30, 27, 34, start);
        structure.setBlockState(world, Blocks.OAK_LEAVES.getDefaultState().with(LeavesBlock.PERSISTENT, true).with(LeavesBlock.DISTANCE, 7), 30, 27, 40, start);
        structure.setBlockState(world, Blocks.MOSSY_COBBLESTONE.getDefaultState(), 30, 28, 33, start);
        structure.setBlockState(world, Blocks.COBBLESTONE_STAIRS.getDefaultState().with(StairsBlock.FACING, Direction.NORTH).with(StairsBlock.WATERLOGGED, false).with(StairsBlock.SHAPE, StairsShape.STRAIGHT).with(StairsBlock.HALF, Half.BOTTOM), 30, 28, 34, start);
        structure.setBlockState(world, Blocks.MOSSY_STONE_BRICKS.getDefaultState(), 30, 28, 37, start);
        structure.setBlockState(world, Blocks.MOSSY_COBBLESTONE.getDefaultState(), 30, 29, 20, start);
        structure.setBlockState(world, Blocks.TALL_GRASS.getDefaultState(), 30, 29, 25, start);
        structure.setBlockState(world, Blocks.STONE_BRICK_STAIRS.getDefaultState().with(StairsBlock.FACING, Direction.SOUTH).with(StairsBlock.WATERLOGGED, false).with(StairsBlock.SHAPE, StairsShape.STRAIGHT).with(StairsBlock.HALF, Half.BOTTOM), 30, 29, 26, start);
        structure.setBlockState(world, Blocks.MOSSY_STONE_BRICKS.getDefaultState(), 30, 29, 38, start);
        structure.setBlockState(world, Blocks.MOSSY_COBBLESTONE.getDefaultState(), 30, 29, 40, start);
        structure.setBlockState(world, Blocks.MOSSY_COBBLESTONE.getDefaultState(), 30, 30, 19, start);
        structure.setBlockState(world, Blocks.TALL_GRASS.getDefaultState(), 30, 30, 25, start);
        structure.setBlockState(world, Blocks.COBBLESTONE_STAIRS.getDefaultState().with(StairsBlock.FACING, Direction.NORTH).with(StairsBlock.WATERLOGGED, false).with(StairsBlock.SHAPE, StairsShape.STRAIGHT).with(StairsBlock.HALF, Half.BOTTOM), 30, 30, 40, start);
        structure.setBlockState(world, Blocks.MOSSY_STONE_BRICKS.getDefaultState(), 30, 31, 21, start);
        structure.setBlockState(world, Blocks.STONE_BRICK_STAIRS.getDefaultState().with(StairsBlock.FACING, Direction.SOUTH).with(StairsBlock.WATERLOGGED, false).with(StairsBlock.SHAPE, StairsShape.STRAIGHT).with(StairsBlock.HALF, Half.TOP), 30, 31, 38, start);
        structure.setBlockState(world, Blocks.MOSSY_STONE_BRICKS.getDefaultState(), 30, 31, 39, start);
        structure.setBlockState(world, Blocks.MOSSY_COBBLESTONE.getDefaultState(), 30, 32, 20, start);
        structure.setBlockState(world, Blocks.STONE_BRICK_STAIRS.getDefaultState().with(StairsBlock.FACING, Direction.EAST).with(StairsBlock.WATERLOGGED, false).with(StairsBlock.SHAPE, StairsShape.STRAIGHT).with(StairsBlock.HALF, Half.TOP), 30, 32, 21, start);
        structure.setBlockState(world, Blocks.COBBLESTONE_STAIRS.getDefaultState().with(StairsBlock.FACING, Direction.SOUTH).with(StairsBlock.WATERLOGGED, false).with(StairsBlock.SHAPE, StairsShape.STRAIGHT).with(StairsBlock.HALF, Half.BOTTOM), 30, 33, 20, start);
        structure.setBlockState(world, Blocks.COBBLESTONE_STAIRS.getDefaultState().with(StairsBlock.FACING, Direction.NORTH).with(StairsBlock.WATERLOGGED, false).with(StairsBlock.SHAPE, StairsShape.STRAIGHT).with(StairsBlock.HALF, Half.BOTTOM), 30, 35, 38, start);
        structure.setBlockState(world, Blocks.COARSE_DIRT.getDefaultState(), 31, 6, 21, start);
        structure.setBlockState(world, Blocks.GRASS.getDefaultState(), 31, 7, 17, start);
        structure.setBlockState(world, Blocks.AZURE_BLUET.getDefaultState(), 31, 7, 22, start);
        structure.setBlockState(world, Blocks.GRASS.getDefaultState(), 31, 7, 24, start);
        structure.setBlockState(world, Blocks.DANDELION.getDefaultState(), 31, 7, 39, start);
        structure.setBlockState(world, Blocks.GRASS.getDefaultState(), 31, 7, 50, start);
        structure.setBlockState(world, Blocks.GRASS.getDefaultState(), 31, 7, 55, start);
        structure.setBlockState(world, Blocks.TALL_GRASS.getDefaultState(), 31, 8, 20, start);
        structure.setBlockState(world, Blocks.STONE_BRICKS.getDefaultState(), 31, 8, 38, start);
        structure.setBlockState(world, Blocks.ANDESITE.getDefaultState(), 31, 10, 46, start);
        structure.setBlockState(world, Blocks.STONE_BRICKS.getDefaultState(), 31, 11, 21, start);
        structure.setBlockState(world, Blocks.OAK_LEAVES.getDefaultState().with(LeavesBlock.PERSISTENT, true).with(LeavesBlock.DISTANCE, 7), 31, 12, 21, start);
        structure.setBlockState(world, Blocks.STONE_BRICK_STAIRS.getDefaultState().with(StairsBlock.FACING, Direction.WEST).with(StairsBlock.WATERLOGGED, false).with(StairsBlock.SHAPE, StairsShape.STRAIGHT).with(StairsBlock.HALF, Half.TOP), 31, 12, 39, start);
        structure.setBlockState(world, Blocks.MOSSY_STONE_BRICKS.getDefaultState(), 31, 12, 48, start);
        structure.setBlockState(world, Blocks.MOSSY_COBBLESTONE.getDefaultState(), 31, 12, 49, start);
        structure.setBlockState(world, Blocks.MOSSY_STONE_BRICKS.getDefaultState(), 31, 13, 21, start);
        structure.setBlockState(world, Blocks.STONE_BRICK_SLAB.getDefaultState().with(SlabBlock.TYPE, SlabType.TOP).with(SlabBlock.WATERLOGGED, false), 31, 13, 40, start);
        structure.setBlockState(world, Blocks.MOSSY_STONE_BRICKS.getDefaultState(), 31, 13, 47, start);
        structure.setBlockState(world, Blocks.MOSSY_STONE_BRICKS.getDefaultState(), 31, 13, 49, start);
        structure.setBlockState(world, Blocks.MOSSY_COBBLESTONE.getDefaultState(), 31, 14, 38, start);
        structure.setBlockState(world, Blocks.STONE_BRICK_STAIRS.getDefaultState().with(StairsBlock.FACING, Direction.WEST).with(StairsBlock.WATERLOGGED, false).with(StairsBlock.SHAPE, StairsShape.STRAIGHT).with(StairsBlock.HALF, Half.TOP), 31, 14, 41, start);
