package mod.arcalitegames.odyssey.world.structure.structures.statues.statue_swordpointing;

import mod.arcalitegames.odyssey.world.structure.StructureBase;
import net.minecraft.block.AbstractButtonBlock;
import net.minecraft.block.AbstractFurnaceBlock;
import net.minecraft.block.Blocks;
import net.minecraft.block.ChestBlock;
import net.minecraft.block.HorizontalBlock;
import net.minecraft.block.HorizontalFaceBlock;
import net.minecraft.block.LanternBlock;
import net.minecraft.block.LecternBlock;
import net.minecraft.block.SlabBlock;
import net.minecraft.block.SnowyDirtBlock;
import net.minecraft.block.StairsBlock;
import net.minecraft.block.WallBlock;
import net.minecraft.block.WallHeight;
import net.minecraft.block.WallTorchBlock;
import net.minecraft.state.properties.AttachFace;
import net.minecraft.state.properties.ChestType;
import net.minecraft.state.properties.Half;
import net.minecraft.state.properties.SlabType;
import net.minecraft.state.properties.StairsShape;
import net.minecraft.util.Direction;
import net.minecraft.util.math.BlockPos;
import net.minecraft.world.World;

public class SwordPointingComponents
{

	public static BlockPos start;
    public static World world;
    public static StructureBase structure;

    public static void init(World worldIn, BlockPos blockPos, StructureBase structureIn)
    {
        world = worldIn; start = blockPos; structure = structureIn;
    }
    
    public static void generatePart1()
    {
        structure.setBlockState(world, Blocks.GRASS_BLOCK.getDefaultState().with(SnowyDirtBlock.SNOWY, false), 0, 0, 0, start);
        structure.setBlockState(world, Blocks.GRASS_BLOCK.getDefaultState().with(SnowyDirtBlock.SNOWY, false), 3, 0, 7, start);
        structure.setBlockState(world, Blocks.GRASS_BLOCK.getDefaultState().with(SnowyDirtBlock.SNOWY, false), 3, 1, 8, start);
        structure.setBlockState(world, Blocks.GRASS_BLOCK.getDefaultState().with(SnowyDirtBlock.SNOWY, false), 4, 0, 6, start);
        structure.setBlockState(world, Blocks.GRASS_BLOCK.getDefaultState().with(SnowyDirtBlock.SNOWY, false), 4, 1, 7, start);
        structure.setBlockState(world, Blocks.GRASS_BLOCK.getDefaultState().with(SnowyDirtBlock.SNOWY, false), 4, 2, 28, start);
        structure.setBlockState(world, Blocks.GRASS_BLOCK.getDefaultState().with(SnowyDirtBlock.SNOWY, false), 4, 4, 10, start);
        structure.setBlockState(world, Blocks.GRASS_BLOCK.getDefaultState().with(SnowyDirtBlock.SNOWY, false), 5, 0, 5, start);
        structure.setBlockState(world, Blocks.GRASS_BLOCK.getDefaultState().with(SnowyDirtBlock.SNOWY, false), 5, 0, 36, start);
        structure.setBlockState(world, Blocks.GRASS_BLOCK.getDefaultState().with(SnowyDirtBlock.SNOWY, false), 5, 2, 6, start);
        structure.setBlockState(world, Blocks.GRASS_BLOCK.getDefaultState().with(SnowyDirtBlock.SNOWY, false), 5, 3, 7, start);
        structure.setBlockState(world, Blocks.GRASS_BLOCK.getDefaultState().with(SnowyDirtBlock.SNOWY, false), 5, 4, 8, start);
        structure.setBlockState(world, Blocks.GRASS_BLOCK.getDefaultState().with(SnowyDirtBlock.SNOWY, false), 6, 0, 4, start);
        structure.setBlockState(world, Blocks.GRASS_BLOCK.getDefaultState().with(SnowyDirtBlock.SNOWY, false), 6, 2, 5, start);
        structure.setBlockState(world, Blocks.GRASS_BLOCK.getDefaultState().with(SnowyDirtBlock.SNOWY, false), 6, 2, 36, start);
        structure.setBlockState(world, Blocks.GRASS_BLOCK.getDefaultState().with(SnowyDirtBlock.SNOWY, false), 6, 3, 6, start);
        structure.setBlockState(world, Blocks.GRASS_BLOCK.getDefaultState().with(SnowyDirtBlock.SNOWY, false), 6, 4, 7, start);
        structure.setBlockState(world, Blocks.GRASS_BLOCK.getDefaultState().with(SnowyDirtBlock.SNOWY, false), 7, 0, 3, start);
        structure.setBlockState(world, Blocks.GRASS_BLOCK.getDefaultState().with(SnowyDirtBlock.SNOWY, false), 7, 2, 4, start);
        structure.setBlockState(world, Blocks.GRASS_BLOCK.getDefaultState().with(SnowyDirtBlock.SNOWY, false), 7, 3, 5, start);
        structure.setBlockState(world, Blocks.GRASS_BLOCK.getDefaultState().with(SnowyDirtBlock.SNOWY, false), 7, 4, 6, start);
        structure.setBlockState(world, Blocks.STONE_STAIRS.getDefaultState().with(StairsBlock.FACING, Direction.EAST).with(StairsBlock.WATERLOGGED, false).with(StairsBlock.SHAPE, StairsShape.STRAIGHT).with(StairsBlock.HALF, Half.TOP), 7, 48, 17, start);
        structure.setBlockState(world, Blocks.STONE.getDefaultState(), 7, 48, 18, start);
        structure.setBlockState(world, Blocks.ANDESITE_STAIRS.getDefaultState().with(StairsBlock.FACING, Direction.EAST).with(StairsBlock.WATERLOGGED, false).with(StairsBlock.SHAPE, StairsShape.STRAIGHT).with(StairsBlock.HALF, Half.BOTTOM), 7, 49, 17, start);
        structure.setBlockState(world, Blocks.STONE_STAIRS.getDefaultState().with(StairsBlock.FACING, Direction.EAST).with(StairsBlock.WATERLOGGED, false).with(StairsBlock.SHAPE, StairsShape.STRAIGHT).with(StairsBlock.HALF, Half.BOTTOM), 7, 49, 18, start);
        structure.setBlockState(world, Blocks.ANDESITE_STAIRS.getDefaultState().with(StairsBlock.FACING, Direction.EAST).with(StairsBlock.WATERLOGGED, false).with(StairsBlock.SHAPE, StairsShape.STRAIGHT).with(StairsBlock.HALF, Half.BOTTOM), 7, 49, 19, start);
        structure.setBlockState(world, Blocks.GRASS_BLOCK.getDefaultState().with(SnowyDirtBlock.SNOWY, false), 8, 0, 40, start);
        structure.setBlockState(world, Blocks.GRASS_BLOCK.getDefaultState().with(SnowyDirtBlock.SNOWY, false), 8, 1, 3, start);
        structure.setBlockState(world, Blocks.GRASS_BLOCK.getDefaultState().with(SnowyDirtBlock.SNOWY, false), 8, 3, 4, start);
        structure.setBlockState(world, Blocks.GRASS_BLOCK.getDefaultState().with(SnowyDirtBlock.SNOWY, false), 8, 4, 5, start);
        structure.setBlockState(world, Blocks.STONE_SLAB.getDefaultState().with(SlabBlock.TYPE, SlabType.TOP).with(SlabBlock.WATERLOGGED, false), 8, 46, 19, start);
        structure.setBlockState(world, Blocks.STONE_STAIRS.getDefaultState().with(StairsBlock.FACING, Direction.SOUTH).with(StairsBlock.WATERLOGGED, false).with(StairsBlock.SHAPE, StairsShape.STRAIGHT).with(StairsBlock.HALF, Half.TOP), 8, 47, 17, start);
        structure.setBlockState(world, Blocks.STONE.getDefaultState(), 8, 47, 19, start);
        structure.setBlockState(world, Blocks.STONE.getDefaultState(), 8, 48, 17, start);
        structure.setBlockState(world, Blocks.ANDESITE.getDefaultState(), 8, 50, 18, start);
        structure.setBlockState(world, Blocks.STONE.getDefaultState(), 8, 50, 19, start);
        structure.setBlockState(world, Blocks.ANDESITE_STAIRS.getDefaultState().with(StairsBlock.FACING, Direction.SOUTH).with(StairsBlock.WATERLOGGED, false).with(StairsBlock.SHAPE, StairsShape.OUTER_LEFT).with(StairsBlock.HALF, Half.BOTTOM), 8, 51, 17, start);
        structure.setBlockState(world, Blocks.GRASS_BLOCK.getDefaultState().with(SnowyDirtBlock.SNOWY, false), 9, 1, 40, start);
        structure.setBlockState(world, Blocks.GRASS_BLOCK.getDefaultState().with(SnowyDirtBlock.SNOWY, false), 9, 3, 39, start);
        structure.setBlockState(world, Blocks.ANDESITE_SLAB.getDefaultState().with(SlabBlock.TYPE, SlabType.TOP).with(SlabBlock.WATERLOGGED, false), 9, 45, 19, start);
        structure.setBlockState(world, Blocks.ANDESITE_SLAB.getDefaultState().with(SlabBlock.TYPE, SlabType.TOP).with(SlabBlock.WATERLOGGED, false), 9, 46, 18, start);
        structure.setBlockState(world, Blocks.STONE.getDefaultState(), 9, 46, 19, start);
        structure.setBlockState(world, Blocks.ANDESITE_STAIRS.getDefaultState().with(StairsBlock.FACING, Direction.EAST).with(StairsBlock.WATERLOGGED, false).with(StairsBlock.SHAPE, StairsShape.STRAIGHT).with(StairsBlock.HALF, Half.TOP), 9, 46, 20, start);
        structure.setBlockState(world, Blocks.STONE_STAIRS.getDefaultState().with(StairsBlock.FACING, Direction.EAST).with(StairsBlock.WATERLOGGED, false).with(StairsBlock.SHAPE, StairsShape.STRAIGHT).with(StairsBlock.HALF, Half.TOP), 9, 46, 21, start);
        structure.setBlockState(world, Blocks.ANDESITE.getDefaultState(), 9, 47, 20, start);
        structure.setBlockState(world, Blocks.STONE_STAIRS.getDefaultState().with(StairsBlock.FACING, Direction.EAST).with(StairsBlock.WATERLOGGED, false).with(StairsBlock.SHAPE, StairsShape.STRAIGHT).with(StairsBlock.HALF, Half.BOTTOM), 9, 47, 21, start);
        structure.setBlockState(world, Blocks.STONE_STAIRS.getDefaultState().with(StairsBlock.FACING, Direction.SOUTH).with(StairsBlock.WATERLOGGED, false).with(StairsBlock.SHAPE, StairsShape.STRAIGHT).with(StairsBlock.HALF, Half.TOP), 9, 48, 17, start);
        structure.setBlockState(world, Blocks.ANDESITE.getDefaultState(), 9, 48, 18, start);
        structure.setBlockState(world, Blocks.ANDESITE_STAIRS.getDefaultState().with(StairsBlock.FACING, Direction.NORTH).with(StairsBlock.WATERLOGGED, false).with(StairsBlock.SHAPE, StairsShape.STRAIGHT).with(StairsBlock.HALF, Half.BOTTOM), 9, 48, 20, start);
        structure.setBlockState(world, Blocks.STONE.getDefaultState(), 9, 49, 17, start);
        structure.setBlockState(world, Blocks.ANDESITE_STAIRS.getDefaultState().with(StairsBlock.FACING, Direction.SOUTH).with(StairsBlock.WATERLOGGED, false).with(StairsBlock.SHAPE, StairsShape.STRAIGHT).with(StairsBlock.HALF, Half.TOP), 9, 50, 16, start);
        structure.setBlockState(world, Blocks.STONE_STAIRS.getDefaultState().with(StairsBlock.FACING, Direction.NORTH).with(StairsBlock.WATERLOGGED, false).with(StairsBlock.SHAPE, StairsShape.STRAIGHT).with(StairsBlock.HALF, Half.TOP), 9, 50, 20, start);
        structure.setBlockState(world, Blocks.STONE_STAIRS.getDefaultState().with(StairsBlock.FACING, Direction.SOUTH).with(StairsBlock.WATERLOGGED, false).with(StairsBlock.SHAPE, StairsShape.STRAIGHT).with(StairsBlock.HALF, Half.BOTTOM), 9, 51, 16, start);
        structure.setBlockState(world, Blocks.STONE.getDefaultState(), 9, 51, 17, start);
        structure.setBlockState(world, Blocks.STONE.getDefaultState(), 9, 51, 20, start);
        structure.setBlockState(world, Blocks.ANDESITE_STAIRS.getDefaultState().with(StairsBlock.FACING, Direction.EAST).with(StairsBlock.WATERLOGGED, false).with(StairsBlock.SHAPE, StairsShape.STRAIGHT).with(StairsBlock.HALF, Half.BOTTOM), 9, 52, 17, start);
        structure.setBlockState(world, Blocks.STONE_STAIRS.getDefaultState().with(StairsBlock.FACING, Direction.EAST).with(StairsBlock.WATERLOGGED, false).with(StairsBlock.SHAPE, StairsShape.STRAIGHT).with(StairsBlock.HALF, Half.BOTTOM), 9, 52, 20, start);
        structure.setBlockState(world, Blocks.STONE_STAIRS.getDefaultState().with(StairsBlock.FACING, Direction.EAST).with(StairsBlock.WATERLOGGED, false).with(StairsBlock.SHAPE, StairsShape.STRAIGHT).with(StairsBlock.HALF, Half.BOTTOM), 9, 53, 18, start);
        structure.setBlockState(world, Blocks.ANDESITE_STAIRS.getDefaultState().with(StairsBlock.FACING, Direction.EAST).with(StairsBlock.WATERLOGGED, false).with(StairsBlock.SHAPE, StairsShape.STRAIGHT).with(StairsBlock.HALF, Half.BOTTOM), 9, 53, 19, start);
        structure.setBlockState(world, Blocks.GRASS_BLOCK.getDefaultState().with(SnowyDirtBlock.SNOWY, false), 10, 0, 41, start);
        structure.setBlockState(world, Blocks.GRASS_BLOCK.getDefaultState().with(SnowyDirtBlock.SNOWY, false), 10, 2, 40, start);
        structure.setBlockState(world, Blocks.STONE_SLAB.getDefaultState().with(SlabBlock.TYPE, SlabType.TOP).with(SlabBlock.WATERLOGGED, false), 10, 46, 19, start);
        structure.setBlockState(world, Blocks.ANDESITE_STAIRS.getDefaultState().with(StairsBlock.FACING, Direction.EAST).with(StairsBlock.WATERLOGGED, false).with(StairsBlock.SHAPE, StairsShape.STRAIGHT).with(StairsBlock.HALF, Half.BOTTOM), 10, 47, 22, start);
        structure.setBlockState(world, Blocks.STONE.getDefaultState(), 10, 48, 20, start);
        structure.setBlockState(world, Blocks.STONE_STAIRS.getDefaultState().with(StairsBlock.FACING, Direction.WEST).with(StairsBlock.WATERLOGGED, false).with(StairsBlock.SHAPE, StairsShape.STRAIGHT).with(StairsBlock.HALF, Half.TOP), 10, 49, 18, start);
        structure.setBlockState(world, Blocks.ANDESITE_STAIRS.getDefaultState().with(StairsBlock.FACING, Direction.WEST).with(StairsBlock.WATERLOGGED, false).with(StairsBlock.SHAPE, StairsShape.STRAIGHT).with(StairsBlock.HALF, Half.BOTTOM), 10, 49, 19, start);
        structure.setBlockState(world, Blocks.STONE_STAIRS.getDefaultState().with(StairsBlock.FACING, Direction.WEST).with(StairsBlock.WATERLOGGED, false).with(StairsBlock.SHAPE, StairsShape.STRAIGHT).with(StairsBlock.HALF, Half.TOP), 10, 50, 17, start);
        structure.setBlockState(world, Blocks.STONE.getDefaultState(), 10, 50, 18, start);
        structure.setBlockState(world, Blocks.ANDESITE_STAIRS.getDefaultState().with(StairsBlock.FACING, Direction.WEST).with(StairsBlock.WATERLOGGED, false).with(StairsBlock.SHAPE, StairsShape.STRAIGHT).with(StairsBlock.HALF, Half.TOP), 10, 50, 19, start);
        structure.setBlockState(world, Blocks.STONE_STAIRS.getDefaultState().with(StairsBlock.FACING, Direction.SOUTH).with(StairsBlock.WATERLOGGED, false).with(StairsBlock.SHAPE, StairsShape.STRAIGHT).with(StairsBlock.HALF, Half.TOP), 10, 51, 16, start);
        structure.setBlockState(world, Blocks.STONE_STAIRS.getDefaultState().with(StairsBlock.FACING, Direction.WEST).with(StairsBlock.WATERLOGGED, false).with(StairsBlock.SHAPE, StairsShape.INNER_RIGHT).with(StairsBlock.HALF, Half.TOP), 10, 51, 20, start);
        structure.setBlockState(world, Blocks.ANDESITE_STAIRS.getDefaultState().with(StairsBlock.FACING, Direction.SOUTH).with(StairsBlock.WATERLOGGED, false).with(StairsBlock.SHAPE, StairsShape.STRAIGHT).with(StairsBlock.HALF, Half.BOTTOM), 10, 52, 16, start);
        structure.setBlockState(world, Blocks.STONE.getDefaultState(), 10, 52, 20, start);
        structure.setBlockState(world, Blocks.STONE_STAIRS.getDefaultState().with(StairsBlock.FACING, Direction.EAST).with(StairsBlock.WATERLOGGED, false).with(StairsBlock.SHAPE, StairsShape.STRAIGHT).with(StairsBlock.HALF, Half.BOTTOM), 10, 53, 17, start);
        structure.setBlockState(world, Blocks.ANDESITE.getDefaultState(), 10, 53, 20, start);
        structure.setBlockState(world, Blocks.STONE.getDefaultState(), 10, 54, 19, start);
        structure.setBlockState(world, Blocks.ANDESITE_STAIRS.getDefaultState().with(StairsBlock.FACING, Direction.EAST).with(StairsBlock.WATERLOGGED, false).with(StairsBlock.SHAPE, StairsShape.STRAIGHT).with(StairsBlock.HALF, Half.BOTTOM), 10, 54, 20, start);
        structure.setBlockState(world, Blocks.STONE_STAIRS.getDefaultState().with(StairsBlock.FACING, Direction.EAST).with(StairsBlock.WATERLOGGED, false).with(StairsBlock.SHAPE, StairsShape.STRAIGHT).with(StairsBlock.HALF, Half.BOTTOM), 10, 55, 18, start);
        structure.setBlockState(world, Blocks.ANDESITE_STAIRS.getDefaultState().with(StairsBlock.FACING, Direction.EAST).with(StairsBlock.WATERLOGGED, false).with(StairsBlock.SHAPE, StairsShape.STRAIGHT).with(StairsBlock.HALF, Half.BOTTOM), 10, 55, 19, start);
        structure.setBlockState(world, Blocks.GRASS_BLOCK.getDefaultState().with(SnowyDirtBlock.SNOWY, false), 11, 1, 41, start);
        structure.setBlockState(world, Blocks.GRASS_BLOCK.getDefaultState().with(SnowyDirtBlock.SNOWY, false), 11, 3, 40, start);
        structure.setBlockState(world, Blocks.ANDESITE_SLAB.getDefaultState().with(SlabBlock.TYPE, SlabType.TOP).with(SlabBlock.WATERLOGGED, false), 11, 45, 21, start);
        structure.setBlockState(world, Blocks.STONE_STAIRS.getDefaultState().with(StairsBlock.FACING, Direction.SOUTH).with(StairsBlock.WATERLOGGED, false).with(StairsBlock.SHAPE, StairsShape.STRAIGHT).with(StairsBlock.HALF, Half.TOP), 11, 46, 20, start);
        structure.setBlockState(world, Blocks.ANDESITE_STAIRS.getDefaultState().with(StairsBlock.FACING, Direction.EAST).with(StairsBlock.WATERLOGGED, false).with(StairsBlock.SHAPE, StairsShape.STRAIGHT).with(StairsBlock.HALF, Half.TOP), 11, 46, 23, start);
        structure.setBlockState(world, Blocks.ANDESITE.getDefaultState(), 11, 47, 20, start);
        structure.setBlockState(world, Blocks.STONE_STAIRS.getDefaultState().with(StairsBlock.FACING, Direction.EAST).with(StairsBlock.WATERLOGGED, false).with(StairsBlock.SHAPE, StairsShape.STRAIGHT).with(StairsBlock.HALF, Half.BOTTOM), 11, 47, 23, start);
        structure.setBlockState(world, Blocks.ANDESITE_STAIRS.getDefaultState().with(StairsBlock.FACING, Direction.WEST).with(StairsBlock.WATERLOGGED, false).with(StairsBlock.SHAPE, StairsShape.STRAIGHT).with(StairsBlock.HALF, Half.BOTTOM), 11, 48, 20, start);
        structure.setBlockState(world, Blocks.STONE_SLAB.getDefaultState().with(SlabBlock.TYPE, SlabType.BOTTOM).with(SlabBlock.WATERLOGGED, false), 11, 48, 21, start);
        structure.setBlockState(world, Blocks.ANDESITE_SLAB.getDefaultState().with(SlabBlock.TYPE, SlabType.BOTTOM).with(SlabBlock.WATERLOGGED, false), 11, 48, 22, start);
        structure.setBlockState(world, Blocks.CRACKED_STONE_BRICKS.getDefaultState(), 11, 48, 24, start);
        structure.setBlockState(world, Blocks.ANDESITE_STAIRS.getDefaultState().with(StairsBlock.FACING, Direction.WEST).with(StairsBlock.WATERLOGGED, false).with(StairsBlock.SHAPE, StairsShape.STRAIGHT).with(StairsBlock.HALF, Half.TOP), 11, 50, 18, start);
        structure.setBlockState(world, Blocks.ANDESITE.getDefaultState(), 11, 51, 17, start);
        structure.setBlockState(world, Blocks.STONE.getDefaultState(), 11, 51, 19, start);
        structure.setBlockState(world, Blocks.STONE_STAIRS.getDefaultState().with(StairsBlock.FACING, Direction.NORTH).with(StairsBlock.WATERLOGGED, false).with(StairsBlock.SHAPE, StairsShape.STRAIGHT).with(StairsBlock.HALF, Half.TOP), 11, 51, 20, start);
        structure.setBlockState(world, Blocks.STONE.getDefaultState(), 11, 52, 17, start);
        structure.setBlockState(world, Blocks.ANDESITE.getDefaultState(), 11, 52, 20, start);
        structure.setBlockState(world, Blocks.ANDESITE_STAIRS.getDefaultState().with(StairsBlock.FACING, Direction.SOUTH).with(StairsBlock.WATERLOGGED, false).with(StairsBlock.SHAPE, StairsShape.STRAIGHT).with(StairsBlock.HALF, Half.TOP), 11, 53, 16, start);
        structure.setBlockState(world, Blocks.STONE_STAIRS.getDefaultState().with(StairsBlock.FACING, Direction.SOUTH).with(StairsBlock.WATERLOGGED, false).with(StairsBlock.SHAPE, StairsShape.STRAIGHT).with(StairsBlock.HALF, Half.BOTTOM), 11, 54, 16, start);
        structure.setBlockState(world, Blocks.STONE.getDefaultState(), 11, 54, 17, start);
        structure.setBlockState(world, Blocks.ANDESITE_STAIRS.getDefaultState().with(StairsBlock.FACING, Direction.EAST).with(StairsBlock.WATERLOGGED, false).with(StairsBlock.SHAPE, StairsShape.STRAIGHT).with(StairsBlock.HALF, Half.BOTTOM), 11, 55, 17, start);
        structure.setBlockState(world, Blocks.STONE_STAIRS.getDefaultState().with(StairsBlock.FACING, Direction.NORTH).with(StairsBlock.WATERLOGGED, false).with(StairsBlock.SHAPE, StairsShape.STRAIGHT).with(StairsBlock.HALF, Half.BOTTOM), 11, 55, 20, start);
        structure.setBlockState(world, Blocks.STONE_SLAB.getDefaultState().with(SlabBlock.TYPE, SlabType.BOTTOM).with(SlabBlock.WATERLOGGED, false), 11, 56, 18, start);
        structure.setBlockState(world, Blocks.STONE_BRICK_STAIRS.getDefaultState().with(StairsBlock.FACING, Direction.SOUTH).with(StairsBlock.WATERLOGGED, false).with(StairsBlock.SHAPE, StairsShape.OUTER_LEFT).with(StairsBlock.HALF, Half.BOTTOM), 11, 57, 15, start);
        structure.setBlockState(world, Blocks.STONE_BRICK_STAIRS.getDefaultState().with(StairsBlock.FACING, Direction.EAST).with(StairsBlock.WATERLOGGED, false).with(StairsBlock.SHAPE, StairsShape.STRAIGHT).with(StairsBlock.HALF, Half.BOTTOM), 11, 57, 16, start);
        structure.setBlockState(world, Blocks.STONE_BRICK_STAIRS.getDefaultState().with(StairsBlock.FACING, Direction.EAST).with(StairsBlock.WATERLOGGED, false).with(StairsBlock.SHAPE, StairsShape.STRAIGHT).with(StairsBlock.HALF, Half.BOTTOM), 11, 57, 19, start);
        structure.setBlockState(world, Blocks.STONE_BRICK_STAIRS.getDefaultState().with(StairsBlock.FACING, Direction.NORTH).with(StairsBlock.WATERLOGGED, false).with(StairsBlock.SHAPE, StairsShape.OUTER_RIGHT).with(StairsBlock.HALF, Half.BOTTOM), 11, 57, 20, start);
        structure.setBlockState(world, Blocks.GRASS_BLOCK.getDefaultState().with(SnowyDirtBlock.SNOWY, false), 12, 2, 41, start);
        structure.setBlockState(world, Blocks.STONE_BRICK_SLAB.getDefaultState().with(SlabBlock.TYPE, SlabType.TOP).with(SlabBlock.WATERLOGGED, false), 12, 45, 23, start);
        structure.setBlockState(world, Blocks.ANDESITE_STAIRS.getDefaultState().with(StairsBlock.FACING, Direction.WEST).with(StairsBlock.WATERLOGGED, false).with(StairsBlock.SHAPE, StairsShape.STRAIGHT).with(StairsBlock.HALF, Half.TOP), 12, 46, 21, start);
        structure.setBlockState(world, Blocks.STONE_STAIRS.getDefaultState().with(StairsBlock.FACING, Direction.EAST).with(StairsBlock.WATERLOGGED, false).with(StairsBlock.SHAPE, StairsShape.STRAIGHT).with(StairsBlock.HALF, Half.TOP), 12, 46, 24, start);
        structure.setBlockState(world, Blocks.CRACKED_STONE_BRICKS.getDefaultState(), 12, 46, 25, start);
        structure.setBlockState(world, Blocks.STONE_STAIRS.getDefaultState().with(StairsBlock.FACING, Direction.WEST).with(StairsBlock.WATERLOGGED, false).with(StairsBlock.SHAPE, StairsShape.STRAIGHT).with(StairsBlock.HALF, Half.BOTTOM), 12, 47, 21, start);
        structure.setBlockState(world, Blocks.ANDESITE_STAIRS.getDefaultState().with(StairsBlock.FACING, Direction.EAST).with(StairsBlock.WATERLOGGED, false).with(StairsBlock.SHAPE, StairsShape.STRAIGHT).with(StairsBlock.HALF, Half.BOTTOM), 12, 47, 24, start);
        structure.setBlockState(world, Blocks.STONE_BRICK_SLAB.getDefaultState().with(SlabBlock.TYPE, SlabType.BOTTOM).with(SlabBlock.WATERLOGGED, false), 12, 48, 23, start);
        structure.setBlockState(world, Blocks.ANDESITE.getDefaultState(), 12, 52, 17, start);
        structure.setBlockState(world, Blocks.ANDESITE_STAIRS.getDefaultState().with(StairsBlock.FACING, Direction.NORTH).with(StairsBlock.WATERLOGGED, false).with(StairsBlock.SHAPE, StairsShape.STRAIGHT).with(StairsBlock.HALF, Half.TOP), 12, 52, 20, start);
        structure.setBlockState(world, Blocks.STONE.getDefaultState(), 12, 53, 17, start);
        structure.setBlockState(world, Blocks.ANDESITE_STAIRS.getDefaultState().with(StairsBlock.FACING, Direction.SOUTH).with(StairsBlock.WATERLOGGED, false).with(StairsBlock.SHAPE, StairsShape.STRAIGHT).with(StairsBlock.HALF, Half.TOP), 12, 54, 16, start);
        structure.setBlockState(world, Blocks.STONE_STAIRS.getDefaultState().with(StairsBlock.FACING, Direction.SOUTH).with(StairsBlock.WATERLOGGED, false).with(StairsBlock.SHAPE, StairsShape.STRAIGHT).with(StairsBlock.HALF, Half.BOTTOM), 12, 55, 16, start);
        structure.setBlockState(world, Blocks.ANDESITE_STAIRS.getDefaultState().with(StairsBlock.FACING, Direction.NORTH).with(StairsBlock.WATERLOGGED, false).with(StairsBlock.SHAPE, StairsShape.STRAIGHT).with(StairsBlock.HALF, Half.BOTTOM), 12, 55, 20, start);
        structure.setBlockState(world, Blocks.STONE_SLAB.getDefaultState().with(SlabBlock.TYPE, SlabType.BOTTOM).with(SlabBlock.WATERLOGGED, false), 12, 56, 17, start);
        structure.setBlockState(world, Blocks.STONE_STAIRS.getDefaultState().with(StairsBlock.FACING, Direction.EAST).with(StairsBlock.WATERLOGGED, false).with(StairsBlock.SHAPE, StairsShape.STRAIGHT).with(StairsBlock.HALF, Half.BOTTOM), 12, 56, 19, start);
        structure.setBlockState(world, Blocks.GRASS_BLOCK.getDefaultState().with(SnowyDirtBlock.SNOWY, false), 13, 6, 16, start);
        structure.setBlockState(world, Blocks.GRASS_BLOCK.getDefaultState().with(SnowyDirtBlock.SNOWY, false), 13, 6, 21, start);
        structure.setBlockState(world, Blocks.POLISHED_ANDESITE.getDefaultState(), 13, 7, 15, start);
        structure.setBlockState(world, Blocks.STONE_BRICK_WALL.getDefaultState().with(WallBlock.WATERLOGGED, false).with(WallBlock.UP, true).with(WallBlock.WALL_HEIGHT_NORTH, WallHeight.LOW).with(WallBlock.WALL_HEIGHT_SOUTH, WallHeight.LOW).with(WallBlock.WALL_HEIGHT_EAST, WallHeight.LOW).with(WallBlock.WALL_HEIGHT_WEST, WallHeight.LOW), 13, 7, 16, start);
        structure.setBlockState(world, Blocks.POLISHED_ANDESITE.getDefaultState(), 13, 7, 17, start);
        structure.setBlockState(world, Blocks.POLISHED_ANDESITE.getDefaultState(), 13, 7, 20, start);
        structure.setBlockState(world, Blocks.STONE_BRICK_WALL.getDefaultState().with(WallBlock.WATERLOGGED, false).with(WallBlock.UP, true).with(WallBlock.WALL_HEIGHT_NORTH, WallHeight.LOW).with(WallBlock.WALL_HEIGHT_SOUTH, WallHeight.LOW).with(WallBlock.WALL_HEIGHT_EAST, WallHeight.LOW).with(WallBlock.WALL_HEIGHT_WEST, WallHeight.LOW), 13, 7, 21, start);
        structure.setBlockState(world, Blocks.POLISHED_ANDESITE.getDefaultState(), 13, 7, 22, start);
        structure.setBlockState(world, Blocks.STONE_BRICK_STAIRS.getDefaultState().with(StairsBlock.FACING, Direction.EAST).with(StairsBlock.WATERLOGGED, false).with(StairsBlock.SHAPE, StairsShape.STRAIGHT).with(StairsBlock.HALF, Half.BOTTOM), 13, 8, 15, start);
        structure.setBlockState(world, Blocks.STONE_BRICK_SLAB.getDefaultState().with(SlabBlock.TYPE, SlabType.BOTTOM).with(SlabBlock.WATERLOGGED, false), 13, 8, 16, start);
        structure.setBlockState(world, Blocks.STONE_BRICK_STAIRS.getDefaultState().with(StairsBlock.FACING, Direction.EAST).with(StairsBlock.WATERLOGGED, false).with(StairsBlock.SHAPE, StairsShape.STRAIGHT).with(StairsBlock.HALF, Half.BOTTOM), 13, 8, 17, start);
        structure.setBlockState(world, Blocks.STONE_BRICK_STAIRS.getDefaultState().with(StairsBlock.FACING, Direction.EAST).with(StairsBlock.WATERLOGGED, false).with(StairsBlock.SHAPE, StairsShape.STRAIGHT).with(StairsBlock.HALF, Half.BOTTOM), 13, 8, 20, start);
        structure.setBlockState(world, Blocks.STONE_BRICK_SLAB.getDefaultState().with(SlabBlock.TYPE, SlabType.BOTTOM).with(SlabBlock.WATERLOGGED, false), 13, 8, 21, start);
        structure.setBlockState(world, Blocks.STONE_BRICK_STAIRS.getDefaultState().with(StairsBlock.FACING, Direction.EAST).with(StairsBlock.WATERLOGGED, false).with(StairsBlock.SHAPE, StairsShape.STRAIGHT).with(StairsBlock.HALF, Half.BOTTOM), 13, 8, 22, start);
        structure.setBlockState(world, Blocks.STONE_BRICK_STAIRS.getDefaultState().with(StairsBlock.FACING, Direction.EAST).with(StairsBlock.WATERLOGGED, false).with(StairsBlock.SHAPE, StairsShape.STRAIGHT).with(StairsBlock.HALF, Half.TOP), 13, 9, 15, start);
        structure.setBlockState(world, Blocks.STONE_BRICK_STAIRS.getDefaultState().with(StairsBlock.FACING, Direction.EAST).with(StairsBlock.WATERLOGGED, false).with(StairsBlock.SHAPE, StairsShape.STRAIGHT).with(StairsBlock.HALF, Half.TOP), 13, 9, 17, start);
        structure.setBlockState(world, Blocks.STONE_BRICK_STAIRS.getDefaultState().with(StairsBlock.FACING, Direction.EAST).with(StairsBlock.WATERLOGGED, false).with(StairsBlock.SHAPE, StairsShape.STRAIGHT).with(StairsBlock.HALF, Half.TOP), 13, 9, 20, start);
        structure.setBlockState(world, Blocks.STONE_BRICK_STAIRS.getDefaultState().with(StairsBlock.FACING, Direction.EAST).with(StairsBlock.WATERLOGGED, false).with(StairsBlock.SHAPE, StairsShape.STRAIGHT).with(StairsBlock.HALF, Half.TOP), 13, 9, 22, start);
        structure.setBlockState(world, Blocks.STONE_BRICK_STAIRS.getDefaultState().with(StairsBlock.FACING, Direction.EAST).with(StairsBlock.WATERLOGGED, false).with(StairsBlock.SHAPE, StairsShape.STRAIGHT).with(StairsBlock.HALF, Half.BOTTOM), 13, 10, 15, start);
        structure.setBlockState(world, Blocks.STONE_BRICK_STAIRS.getDefaultState().with(StairsBlock.FACING, Direction.EAST).with(StairsBlock.WATERLOGGED, false).with(StairsBlock.SHAPE, StairsShape.STRAIGHT).with(StairsBlock.HALF, Half.BOTTOM), 13, 10, 17, start);
        structure.setBlockState(world, Blocks.STONE_BRICK_STAIRS.getDefaultState().with(StairsBlock.FACING, Direction.EAST).with(StairsBlock.WATERLOGGED, false).with(StairsBlock.SHAPE, StairsShape.STRAIGHT).with(StairsBlock.HALF, Half.BOTTOM), 13, 10, 20, start);
        structure.setBlockState(world, Blocks.STONE_BRICK_STAIRS.getDefaultState().with(StairsBlock.FACING, Direction.EAST).with(StairsBlock.WATERLOGGED, false).with(StairsBlock.SHAPE, StairsShape.STRAIGHT).with(StairsBlock.HALF, Half.BOTTOM), 13, 10, 22, start);
        structure.setBlockState(world, Blocks.STONE_BUTTON.getDefaultState().with(HorizontalBlock.HORIZONTAL_FACING, Direction.WEST).with(HorizontalFaceBlock.FACE, AttachFace.WALL).with(AbstractButtonBlock.POWERED, false), 13, 19, 15, start);
        structure.setBlockState(world, Blocks.STONE_BUTTON.getDefaultState().with(HorizontalBlock.HORIZONTAL_FACING, Direction.WEST).with(HorizontalFaceBlock.FACE, AttachFace.WALL).with(AbstractButtonBlock.POWERED, false), 13, 19, 17, start);
        structure.setBlockState(world, Blocks.STONE_BUTTON.getDefaultState().with(HorizontalBlock.HORIZONTAL_FACING, Direction.WEST).with(HorizontalFaceBlock.FACE, AttachFace.WALL).with(AbstractButtonBlock.POWERED, false), 13, 19, 20, start);
        structure.setBlockState(world, Blocks.STONE_BUTTON.getDefaultState().with(HorizontalBlock.HORIZONTAL_FACING, Direction.WEST).with(HorizontalFaceBlock.FACE, AttachFace.WALL).with(AbstractButtonBlock.POWERED, false), 13, 19, 22, start);
        structure.setBlockState(world, Blocks.ANDESITE_SLAB.getDefaultState().with(SlabBlock.TYPE, SlabType.TOP).with(SlabBlock.WATERLOGGED, false), 13, 45, 23, start);
        structure.setBlockState(world, Blocks.COBBLESTONE.getDefaultState(), 13, 46, 23, start);
        structure.setBlockState(world, Blocks.ANDESITE_STAIRS.getDefaultState().with(StairsBlock.FACING, Direction.EAST).with(StairsBlock.WATERLOGGED, false).with(StairsBlock.SHAPE, StairsShape.STRAIGHT).with(StairsBlock.HALF, Half.TOP), 13, 46, 25, start);
        structure.setBlockState(world, Blocks.COBBLESTONE.getDefaultState(), 13, 47, 24, start);
        structure.setBlockState(world, Blocks.STONE_STAIRS.getDefaultState().with(StairsBlock.FACING, Direction.EAST).with(StairsBlock.WATERLOGGED, false).with(StairsBlock.SHAPE, StairsShape.STRAIGHT).with(StairsBlock.HALF, Half.BOTTOM), 13, 47, 25, start);
        structure.setBlockState(world, Blocks.ANDESITE_SLAB.getDefaultState().with(SlabBlock.TYPE, SlabType.BOTTOM).with(SlabBlock.WATERLOGGED, false), 13, 48, 24, start);
        structure.setBlockState(world, Blocks.ANDESITE_STAIRS.getDefaultState().with(StairsBlock.FACING, Direction.WEST).with(StairsBlock.WATERLOGGED, false).with(StairsBlock.SHAPE, StairsShape.STRAIGHT).with(StairsBlock.HALF, Half.TOP), 13, 52, 18, start);
        structure.setBlockState(world, Blocks.STONE_STAIRS.getDefaultState().with(StairsBlock.FACING, Direction.WEST).with(StairsBlock.WATERLOGGED, false).with(StairsBlock.SHAPE, StairsShape.STRAIGHT).with(StairsBlock.HALF, Half.TOP), 13, 52, 19, start);
        structure.setBlockState(world, Blocks.STONE.getDefaultState(), 13, 53, 19, start);
        structure.setBlockState(world, Blocks.STONE_STAIRS.getDefaultState().with(StairsBlock.FACING, Direction.NORTH).with(StairsBlock.WATERLOGGED, false).with(StairsBlock.SHAPE, StairsShape.STRAIGHT).with(StairsBlock.HALF, Half.TOP), 13, 54, 20, start);
        structure.setBlockState(world, Blocks.ANDESITE_STAIRS.getDefaultState().with(StairsBlock.FACING, Direction.SOUTH).with(StairsBlock.WATERLOGGED, false).with(StairsBlock.SHAPE, StairsShape.STRAIGHT).with(StairsBlock.HALF, Half.TOP), 13, 55, 16, start);
        structure.setBlockState(world, Blocks.ANDESITE.getDefaultState(), 13, 55, 20, start);
        structure.setBlockState(world, Blocks.STONE_SLAB.getDefaultState().with(SlabBlock.TYPE, SlabType.BOTTOM).with(SlabBlock.WATERLOGGED, false), 13, 56, 16, start);
        structure.setBlockState(world, Blocks.ANDESITE_STAIRS.getDefaultState().with(StairsBlock.FACING, Direction.EAST).with(StairsBlock.WATERLOGGED, false).with(StairsBlock.SHAPE, StairsShape.STRAIGHT).with(StairsBlock.HALF, Half.BOTTOM), 13, 56, 17, start);
        structure.setBlockState(world, Blocks.STONE_STAIRS.getDefaultState().with(StairsBlock.FACING, Direction.NORTH).with(StairsBlock.WATERLOGGED, false).with(StairsBlock.SHAPE, StairsShape.STRAIGHT).with(StairsBlock.HALF, Half.BOTTOM), 13, 56, 20, start);
        structure.setBlockState(world, Blocks.ANDESITE_STAIRS.getDefaultState().with(StairsBlock.FACING, Direction.EAST).with(StairsBlock.WATERLOGGED, false).with(StairsBlock.SHAPE, StairsShape.STRAIGHT).with(StairsBlock.HALF, Half.BOTTOM), 13, 57, 18, start);
        structure.setBlockState(world, Blocks.ANDESITE.getDefaultState(), 13, 57, 19, start);
        structure.setBlockState(world, Blocks.STONE_BRICK_WALL.getDefaultState().with(WallBlock.WATERLOGGED, false).with(WallBlock.UP, true).with(WallBlock.WALL_HEIGHT_NORTH, WallHeight.LOW).with(WallBlock.WALL_HEIGHT_SOUTH, WallHeight.LOW).with(WallBlock.WALL_HEIGHT_EAST, WallHeight.LOW).with(WallBlock.WALL_HEIGHT_WEST, WallHeight.LOW), 14, 7, 14, start);
        structure.setBlockState(world, Blocks.MOSSY_STONE_BRICKS.getDefaultState(), 14, 7, 18, start);
        structure.setBlockState(world, Blocks.MOSSY_STONE_BRICKS.getDefaultState(), 14, 7, 22, start);
        structure.setBlockState(world, Blocks.STONE_BRICK_WALL.getDefaultState().with(WallBlock.WATERLOGGED, false).with(WallBlock.UP, true).with(WallBlock.WALL_HEIGHT_NORTH, WallHeight.LOW).with(WallBlock.WALL_HEIGHT_SOUTH, WallHeight.LOW).with(WallBlock.WALL_HEIGHT_EAST, WallHeight.LOW).with(WallBlock.WALL_HEIGHT_WEST, WallHeight.LOW), 14, 7, 23, start);
        structure.setBlockState(world, Blocks.STONE_BRICK_SLAB.getDefaultState().with(SlabBlock.TYPE, SlabType.BOTTOM).with(SlabBlock.WATERLOGGED, false), 14, 8, 14, start);
        structure.setBlockState(world, Blocks.MOSSY_STONE_BRICKS.getDefaultState(), 14, 8, 16, start);
        structure.setBlockState(world, Blocks.CRACKED_STONE_BRICKS.getDefaultState(), 14, 8, 18, start);
        structure.setBlockState(world, Blocks.MOSSY_STONE_BRICKS.getDefaultState(), 14, 8, 19, start);
        structure.setBlockState(world, Blocks.CRACKED_STONE_BRICKS.getDefaultState(), 14, 8, 22, start);
        structure.setBlockState(world, Blocks.STONE_BRICK_SLAB.getDefaultState().with(SlabBlock.TYPE, SlabType.BOTTOM).with(SlabBlock.WATERLOGGED, false), 14, 8, 23, start);
        structure.setBlockState(world, Blocks.STONE_BRICK_STAIRS.getDefaultState().with(StairsBlock.FACING, Direction.EAST).with(StairsBlock.WATERLOGGED, false).with(StairsBlock.SHAPE, StairsShape.STRAIGHT).with(StairsBlock.HALF, Half.BOTTOM), 14, 9, 16, start);
        structure.setBlockState(world, Blocks.STONE_BRICK_STAIRS.getDefaultState().with(StairsBlock.FACING, Direction.EAST).with(StairsBlock.WATERLOGGED, false).with(StairsBlock.SHAPE, StairsShape.STRAIGHT).with(StairsBlock.HALF, Half.BOTTOM), 14, 9, 21, start);
        structure.setBlockState(world, Blocks.STONE_BRICK_STAIRS.getDefaultState().with(StairsBlock.FACING, Direction.EAST).with(StairsBlock.WATERLOGGED, false).with(StairsBlock.SHAPE, StairsShape.STRAIGHT).with(StairsBlock.HALF, Half.TOP), 14, 10, 16, start);
        structure.setBlockState(world, Blocks.STONE_BRICK_STAIRS.getDefaultState().with(StairsBlock.FACING, Direction.EAST).with(StairsBlock.WATERLOGGED, false).with(StairsBlock.SHAPE, StairsShape.STRAIGHT).with(StairsBlock.HALF, Half.TOP), 14, 10, 21, start);
        structure.setBlockState(world, Blocks.STONE_BRICK_STAIRS.getDefaultState().with(StairsBlock.FACING, Direction.EAST).with(StairsBlock.WATERLOGGED, false).with(StairsBlock.SHAPE, StairsShape.STRAIGHT).with(StairsBlock.HALF, Half.BOTTOM), 14, 11, 17, start);
        structure.setBlockState(world, Blocks.STONE_BRICK_STAIRS.getDefaultState().with(StairsBlock.FACING, Direction.EAST).with(StairsBlock.WATERLOGGED, false).with(StairsBlock.SHAPE, StairsShape.STRAIGHT).with(StairsBlock.HALF, Half.BOTTOM), 14, 11, 22, start);
        structure.setBlockState(world, Blocks.STONE_BRICK_STAIRS.getDefaultState().with(StairsBlock.FACING, Direction.EAST).with(StairsBlock.WATERLOGGED, false).with(StairsBlock.SHAPE, StairsShape.STRAIGHT).with(StairsBlock.HALF, Half.TOP), 14, 17, 22, start);
        structure.setBlockState(world, Blocks.STONE_BRICK_STAIRS.getDefaultState().with(StairsBlock.FACING, Direction.EAST).with(StairsBlock.WATERLOGGED, false).with(StairsBlock.SHAPE, StairsShape.STRAIGHT).with(StairsBlock.HALF, Half.BOTTOM), 14, 18, 15, start);
        structure.setBlockState(world, Blocks.STONE_BRICK_STAIRS.getDefaultState().with(StairsBlock.FACING, Direction.EAST).with(StairsBlock.WATERLOGGED, false).with(StairsBlock.SHAPE, StairsShape.STRAIGHT).with(StairsBlock.HALF, Half.BOTTOM), 14, 18, 17, start);
        structure.setBlockState(world, Blocks.STONE_BRICK_STAIRS.getDefaultState().with(StairsBlock.FACING, Direction.EAST).with(StairsBlock.WATERLOGGED, false).with(StairsBlock.SHAPE, StairsShape.STRAIGHT).with(StairsBlock.HALF, Half.BOTTOM), 14, 18, 20, start);
        structure.setBlockState(world, Blocks.STONE_BRICK_STAIRS.getDefaultState().with(StairsBlock.FACING, Direction.EAST).with(StairsBlock.WATERLOGGED, false).with(StairsBlock.SHAPE, StairsShape.STRAIGHT).with(StairsBlock.HALF, Half.BOTTOM), 14, 18, 22, start);
        structure.setBlockState(world, Blocks.CHISELED_STONE_BRICKS.getDefaultState(), 14, 19, 15, start);
        structure.setBlockState(world, Blocks.CHISELED_STONE_BRICKS.getDefaultState(), 14, 19, 17, start);
        structure.setBlockState(world, Blocks.CHISELED_STONE_BRICKS.getDefaultState(), 14, 19, 20, start);
        structure.setBlockState(world, Blocks.CHISELED_STONE_BRICKS.getDefaultState(), 14, 19, 22, start);
        structure.setBlockState(world, Blocks.STONE_BRICK_SLAB.getDefaultState().with(SlabBlock.TYPE, SlabType.BOTTOM).with(SlabBlock.WATERLOGGED, false), 14, 20, 15, start);
        structure.setBlockState(world, Blocks.STONE_BRICK_SLAB.getDefaultState().with(SlabBlock.TYPE, SlabType.BOTTOM).with(SlabBlock.WATERLOGGED, false), 14, 20, 17, start);
        structure.setBlockState(world, Blocks.STONE_BRICK_SLAB.getDefaultState().with(SlabBlock.TYPE, SlabType.BOTTOM).with(SlabBlock.WATERLOGGED, false), 14, 20, 20, start);
        structure.setBlockState(world, Blocks.STONE_BRICK_SLAB.getDefaultState().with(SlabBlock.TYPE, SlabType.BOTTOM).with(SlabBlock.WATERLOGGED, false), 14, 20, 22, start);
        structure.setBlockState(world, Blocks.STONE_STAIRS.getDefaultState().with(StairsBlock.FACING, Direction.WEST).with(StairsBlock.WATERLOGGED, false).with(StairsBlock.SHAPE, StairsShape.STRAIGHT).with(StairsBlock.HALF, Half.TOP), 14, 46, 23, start);
        structure.setBlockState(world, Blocks.STONE.getDefaultState(), 14, 46, 25, start);
        structure.setBlockState(world, Blocks.STONE.getDefaultState(), 14, 47, 24, start);
        structure.setBlockState(world, Blocks.STONE_BRICK_STAIRS.getDefaultState().with(StairsBlock.FACING, Direction.EAST).with(StairsBlock.WATERLOGGED, false).with(StairsBlock.SHAPE, StairsShape.STRAIGHT).with(StairsBlock.HALF, Half.TOP), 14, 51, 25, start);
        structure.setBlockState(world, Blocks.STONE.getDefaultState(), 14, 54, 17, start);
        structure.setBlockState(world, Blocks.ANDESITE.getDefaultState(), 14, 54, 18, start);
        structure.setBlockState(world, Blocks.STONE.getDefaultState(), 14, 55, 16, start);
        structure.setBlockState(world, Blocks.STONE_STAIRS.getDefaultState().with(StairsBlock.FACING, Direction.NORTH).with(StairsBlock.WATERLOGGED, false).with(StairsBlock.SHAPE, StairsShape.STRAIGHT).with(StairsBlock.HALF, Half.TOP), 14, 55, 20, start);
        structure.setBlockState(world, Blocks.ANDESITE.getDefaultState(), 14, 56, 16, start);
        structure.setBlockState(world, Blocks.ANDESITE_STAIRS.getDefaultState().with(StairsBlock.FACING, Direction.NORTH).with(StairsBlock.WATERLOGGED, false).with(StairsBlock.SHAPE, StairsShape.STRAIGHT).with(StairsBlock.HALF, Half.BOTTOM), 14, 56, 20, start);
        structure.setBlockState(world, Blocks.STONE.getDefaultState(), 14, 57, 17, start);
        structure.setBlockState(world, Blocks.STONE_BRICK_STAIRS.getDefaultState().with(StairsBlock.FACING, Direction.EAST).with(StairsBlock.WATERLOGGED, false).with(StairsBlock.SHAPE, StairsShape.OUTER_RIGHT).with(StairsBlock.HALF, Half.BOTTOM), 14, 59, 17, start);
        structure.setBlockState(world, Blocks.STONE_BRICK_STAIRS.getDefaultState().with(StairsBlock.FACING, Direction.EAST).with(StairsBlock.WATERLOGGED, false).with(StairsBlock.SHAPE, StairsShape.OUTER_LEFT).with(StairsBlock.HALF, Half.BOTTOM), 14, 59, 18, start);
        structure.setBlockState(world, Blocks.STONE.getDefaultState(), 15, 0, 40, start);
        structure.setBlockState(world, Blocks.POLISHED_ANDESITE.getDefaultState(), 15, 7, 13, start);
        structure.setBlockState(world, Blocks.MOSSY_STONE_BRICKS.getDefaultState(), 15, 7, 14, start);
        structure.setBlockState(world, Blocks.POLISHED_ANDESITE.getDefaultState(), 15, 7, 24, start);
        structure.setBlockState(world, Blocks.STONE_BRICK_STAIRS.getDefaultState().with(StairsBlock.FACING, Direction.EAST).with(StairsBlock.WATERLOGGED, false).with(StairsBlock.SHAPE, StairsShape.STRAIGHT).with(StairsBlock.HALF, Half.BOTTOM), 15, 8, 13, start);
        structure.setBlockState(world, Blocks.STONE_BRICK_STAIRS.getDefaultState().with(StairsBlock.FACING, Direction.EAST).with(StairsBlock.WATERLOGGED, false).with(StairsBlock.SHAPE, StairsShape.STRAIGHT).with(StairsBlock.HALF, Half.BOTTOM), 15, 8, 24, start);
        structure.setBlockState(world, Blocks.STONE_BRICK_STAIRS.getDefaultState().with(StairsBlock.FACING, Direction.EAST).with(StairsBlock.WATERLOGGED, false).with(StairsBlock.SHAPE, StairsShape.STRAIGHT).with(StairsBlock.HALF, Half.TOP), 15, 9, 13, start);
        structure.setBlockState(world, Blocks.CRACKED_STONE_BRICKS.getDefaultState(), 15, 9, 23, start);
        structure.setBlockState(world, Blocks.STONE_BRICK_STAIRS.getDefaultState().with(StairsBlock.FACING, Direction.EAST).with(StairsBlock.WATERLOGGED, false).with(StairsBlock.SHAPE, StairsShape.STRAIGHT).with(StairsBlock.HALF, Half.TOP), 15, 9, 24, start);
        structure.setBlockState(world, Blocks.STONE_BRICK_STAIRS.getDefaultState().with(StairsBlock.FACING, Direction.EAST).with(StairsBlock.WATERLOGGED, false).with(StairsBlock.SHAPE, StairsShape.STRAIGHT).with(StairsBlock.HALF, Half.BOTTOM), 15, 10, 13, start);
        structure.setBlockState(world, Blocks.STONE_BRICK_STAIRS.getDefaultState().with(StairsBlock.FACING, Direction.EAST).with(StairsBlock.WATERLOGGED, false).with(StairsBlock.SHAPE, StairsShape.STRAIGHT).with(StairsBlock.HALF, Half.BOTTOM), 15, 10, 24, start);
        structure.setBlockState(world, Blocks.STONE_BRICK_STAIRS.getDefaultState().with(StairsBlock.FACING, Direction.SOUTH).with(StairsBlock.WATERLOGGED, false).with(StairsBlock.SHAPE, StairsShape.STRAIGHT).with(StairsBlock.HALF, Half.BOTTOM), 15, 11, 14, start);
        structure.setBlockState(world, Blocks.STONE_BRICK_STAIRS.getDefaultState().with(StairsBlock.FACING, Direction.EAST).with(StairsBlock.WATERLOGGED, false).with(StairsBlock.SHAPE, StairsShape.STRAIGHT).with(StairsBlock.HALF, Half.BOTTOM), 15, 11, 16, start);
        structure.setBlockState(world, Blocks.STONE_BRICK_STAIRS.getDefaultState().with(StairsBlock.FACING, Direction.EAST).with(StairsBlock.WATERLOGGED, false).with(StairsBlock.SHAPE, StairsShape.STRAIGHT).with(StairsBlock.HALF, Half.BOTTOM), 15, 11, 21, start);
        structure.setBlockState(world, Blocks.STONE_BRICK_STAIRS.getDefaultState().with(StairsBlock.FACING, Direction.NORTH).with(StairsBlock.WATERLOGGED, false).with(StairsBlock.SHAPE, StairsShape.STRAIGHT).with(StairsBlock.HALF, Half.BOTTOM), 15, 11, 23, start);
        structure.setBlockState(world, Blocks.STONE_BRICK_STAIRS.getDefaultState().with(StairsBlock.FACING, Direction.SOUTH).with(StairsBlock.WATERLOGGED, false).with(StairsBlock.SHAPE, StairsShape.STRAIGHT).with(StairsBlock.HALF, Half.TOP), 15, 17, 14, start);
        structure.setBlockState(world, Blocks.STONE_BRICK_STAIRS.getDefaultState().with(StairsBlock.FACING, Direction.NORTH).with(StairsBlock.WATERLOGGED, false).with(StairsBlock.SHAPE, StairsShape.STRAIGHT).with(StairsBlock.HALF, Half.TOP), 15, 17, 23, start);
        structure.setBlockState(world, Blocks.STONE_BRICK_STAIRS.getDefaultState().with(StairsBlock.FACING, Direction.SOUTH).with(StairsBlock.WATERLOGGED, false).with(StairsBlock.SHAPE, StairsShape.STRAIGHT).with(StairsBlock.HALF, Half.BOTTOM), 15, 18, 14, start);
        structure.setBlockState(world, Blocks.MOSSY_STONE_BRICKS.getDefaultState(), 15, 18, 22, start);
        structure.setBlockState(world, Blocks.STONE_BRICK_STAIRS.getDefaultState().with(StairsBlock.FACING, Direction.NORTH).with(StairsBlock.WATERLOGGED, false).with(StairsBlock.SHAPE, StairsShape.STRAIGHT).with(StairsBlock.HALF, Half.BOTTOM), 15, 18, 23, start);
        structure.setBlockState(world, Blocks.STONE_BUTTON.getDefaultState().with(HorizontalBlock.HORIZONTAL_FACING, Direction.WEST).with(HorizontalFaceBlock.FACE, AttachFace.WALL).with(AbstractButtonBlock.POWERED, false), 15, 19, 13, start);
        structure.setBlockState(world, Blocks.SMOOTH_STONE_SLAB.getDefaultState().with(SlabBlock.TYPE, SlabType.BOTTOM).with(SlabBlock.WATERLOGGED, false), 15, 19, 19, start);
        structure.setBlockState(world, Blocks.STONE_BUTTON.getDefaultState().with(HorizontalBlock.HORIZONTAL_FACING, Direction.WEST).with(HorizontalFaceBlock.FACE, AttachFace.WALL).with(AbstractButtonBlock.POWERED, false), 15, 19, 24, start);
        structure.setBlockState(world, Blocks.ANDESITE_SLAB.getDefaultState().with(SlabBlock.TYPE, SlabType.TOP).with(SlabBlock.WATERLOGGED, false), 15, 45, 25, start);
        structure.setBlockState(world, Blocks.ANDESITE_STAIRS.getDefaultState().with(StairsBlock.FACING, Direction.WEST).with(StairsBlock.WATERLOGGED, false).with(StairsBlock.SHAPE, StairsShape.STRAIGHT).with(StairsBlock.HALF, Half.TOP), 15, 46, 24, start);
        structure.setBlockState(world, Blocks.ANDESITE_WALL.getDefaultState().with(WallBlock.WATERLOGGED, false).with(WallBlock.UP, true).with(WallBlock.WALL_HEIGHT_NORTH, WallHeight.LOW).with(WallBlock.WALL_HEIGHT_SOUTH, WallHeight.LOW).with(WallBlock.WALL_HEIGHT_EAST, WallHeight.LOW).with(WallBlock.WALL_HEIGHT_WEST, WallHeight.LOW), 15, 46, 26, start);
        structure.setBlockState(world, Blocks.STONE_STAIRS.getDefaultState().with(StairsBlock.FACING, Direction.WEST).with(StairsBlock.WATERLOGGED, false).with(StairsBlock.SHAPE, StairsShape.STRAIGHT).with(StairsBlock.HALF, Half.BOTTOM), 15, 47, 24, start);
        structure.setBlockState(world, Blocks.ANDESITE_WALL.getDefaultState().with(WallBlock.WATERLOGGED, false).with(WallBlock.UP, true).with(WallBlock.WALL_HEIGHT_NORTH, WallHeight.LOW).with(WallBlock.WALL_HEIGHT_SOUTH, WallHeight.LOW).with(WallBlock.WALL_HEIGHT_EAST, WallHeight.LOW).with(WallBlock.WALL_HEIGHT_WEST, WallHeight.LOW), 15, 47, 26, start);
        structure.setBlockState(world, Blocks.STONE_BRICKS.getDefaultState(), 15, 51, 25, start);
        structure.setBlockState(world, Blocks.STONE_BRICK_STAIRS.getDefaultState().with(StairsBlock.FACING, Direction.SOUTH).with(StairsBlock.WATERLOGGED, false).with(StairsBlock.SHAPE, StairsShape.STRAIGHT).with(StairsBlock.HALF, Half.TOP), 15, 54, 16, start);
        structure.setBlockState(world, Blocks.STONE_BRICKS.getDefaultState(), 15, 54, 17, start);
        structure.setBlockState(world, Blocks.STONE_BRICK_STAIRS.getDefaultState().with(StairsBlock.FACING, Direction.NORTH).with(StairsBlock.WATERLOGGED, false).with(StairsBlock.SHAPE, StairsShape.STRAIGHT).with(StairsBlock.HALF, Half.TOP), 15, 54, 18, start);
        structure.setBlockState(world, Blocks.STONE_BRICK_STAIRS.getDefaultState().with(StairsBlock.FACING, Direction.SOUTH).with(StairsBlock.WATERLOGGED, false).with(StairsBlock.SHAPE, StairsShape.STRAIGHT).with(StairsBlock.HALF, Half.TOP), 15, 55, 15, start);
        structure.setBlockState(world, Blocks.STONE.getDefaultState(), 15, 55, 18, start);
        structure.setBlockState(world, Blocks.STONE_BRICK_STAIRS.getDefaultState().with(StairsBlock.FACING, Direction.NORTH).with(StairsBlock.WATERLOGGED, false).with(StairsBlock.SHAPE, StairsShape.STRAIGHT).with(StairsBlock.HALF, Half.TOP), 15, 55, 19, start);
        structure.setBlockState(world, Blocks.STONE_BRICK_STAIRS.getDefaultState().with(StairsBlock.FACING, Direction.SOUTH).with(StairsBlock.WATERLOGGED, false).with(StairsBlock.SHAPE, StairsShape.STRAIGHT).with(StairsBlock.HALF, Half.BOTTOM), 15, 57, 14, start);
        structure.setBlockState(world, Blocks.STONE.getDefaultState(), 15, 57, 16, start);
        structure.setBlockState(world, Blocks.STONE_BRICK_STAIRS.getDefaultState().with(StairsBlock.FACING, Direction.SOUTH).with(StairsBlock.WATERLOGGED, false).with(StairsBlock.SHAPE, StairsShape.STRAIGHT).with(StairsBlock.HALF, Half.BOTTOM), 15, 58, 15, start);
        structure.setBlockState(world, Blocks.STONE_BRICKS.getDefaultState(), 15, 58, 16, start);
        structure.setBlockState(world, Blocks.STONE_BRICKS.getDefaultState(), 15, 58, 19, start);
        structure.setBlockState(world, Blocks.STONE_BRICK_STAIRS.getDefaultState().with(StairsBlock.FACING, Direction.SOUTH).with(StairsBlock.WATERLOGGED, false).with(StairsBlock.SHAPE, StairsShape.STRAIGHT).with(StairsBlock.HALF, Half.BOTTOM), 15, 59, 17, start);
        structure.setBlockState(world, Blocks.STONE_BRICK_STAIRS.getDefaultState().with(StairsBlock.FACING, Direction.NORTH).with(StairsBlock.WATERLOGGED, false).with(StairsBlock.SHAPE, StairsShape.STRAIGHT).with(StairsBlock.HALF, Half.BOTTOM), 15, 59, 18, start);
        structure.setBlockState(world, Blocks.STONE_BRICK_WALL.getDefaultState().with(WallBlock.WATERLOGGED, false).with(WallBlock.UP, true).with(WallBlock.WALL_HEIGHT_NORTH, WallHeight.LOW).with(WallBlock.WALL_HEIGHT_SOUTH, WallHeight.LOW).with(WallBlock.WALL_HEIGHT_EAST, WallHeight.LOW).with(WallBlock.WALL_HEIGHT_WEST, WallHeight.LOW), 16, 7, 12, start);
        structure.setBlockState(world, Blocks.STONE_BRICK_WALL.getDefaultState().with(WallBlock.WATERLOGGED, false).with(WallBlock.UP, true).with(WallBlock.WALL_HEIGHT_NORTH, WallHeight.LOW).with(WallBlock.WALL_HEIGHT_SOUTH, WallHeight.LOW).with(WallBlock.WALL_HEIGHT_EAST, WallHeight.LOW).with(WallBlock.WALL_HEIGHT_WEST, WallHeight.LOW), 16, 7, 25, start);
        structure.setBlockState(world, Blocks.STONE_BRICK_SLAB.getDefaultState().with(SlabBlock.TYPE, SlabType.BOTTOM).with(SlabBlock.WATERLOGGED, false), 16, 8, 12, start);
        structure.setBlockState(world, Blocks.CRACKED_STONE_BRICKS.getDefaultState(), 16, 8, 24, start);
        structure.setBlockState(world, Blocks.STONE_BRICK_SLAB.getDefaultState().with(SlabBlock.TYPE, SlabType.BOTTOM).with(SlabBlock.WATERLOGGED, false), 16, 8, 25, start);
        structure.setBlockState(world, Blocks.MOSSY_STONE_BRICKS.getDefaultState(), 16, 9, 13, start);
        structure.setBlockState(world, Blocks.CRACKED_STONE_BRICKS.getDefaultState(), 16, 10, 13, start);
        structure.setBlockState(world, Blocks.STONE_BRICK_STAIRS.getDefaultState().with(StairsBlock.FACING, Direction.EAST).with(StairsBlock.WATERLOGGED, false).with(StairsBlock.SHAPE, StairsShape.STRAIGHT).with(StairsBlock.HALF, Half.BOTTOM), 16, 11, 13, start);
        structure.setBlockState(world, Blocks.STONE_BRICK_SLAB.getDefaultState().with(SlabBlock.TYPE, SlabType.BOTTOM).with(SlabBlock.WATERLOGGED, false), 16, 11, 14, start);
        structure.setBlockState(world, Blocks.STONE_BRICK_SLAB.getDefaultState().with(SlabBlock.TYPE, SlabType.BOTTOM).with(SlabBlock.WATERLOGGED, false), 16, 11, 23, start);
        structure.setBlockState(world, Blocks.STONE_BRICK_STAIRS.getDefaultState().with(StairsBlock.FACING, Direction.EAST).with(StairsBlock.WATERLOGGED, false).with(StairsBlock.SHAPE, StairsShape.STRAIGHT).with(StairsBlock.HALF, Half.BOTTOM), 16, 11, 24, start);
        structure.setBlockState(world, Blocks.MOSSY_STONE_BRICKS.getDefaultState(), 16, 12, 21, start);
        structure.setBlockState(world, Blocks.STONE_BRICK_STAIRS.getDefaultState().with(StairsBlock.FACING, Direction.EAST).with(StairsBlock.WATERLOGGED, false).with(StairsBlock.SHAPE, StairsShape.STRAIGHT).with(StairsBlock.HALF, Half.BOTTOM), 16, 13, 16, start);
        structure.setBlockState(world, Blocks.STONE_BRICK_STAIRS.getDefaultState().with(StairsBlock.FACING, Direction.EAST).with(StairsBlock.WATERLOGGED, false).with(StairsBlock.SHAPE, StairsShape.STRAIGHT).with(StairsBlock.HALF, Half.BOTTOM), 16, 13, 21, start);
        structure.setBlockState(world, Blocks.STONE_BRICK_STAIRS.getDefaultState().with(StairsBlock.FACING, Direction.EAST).with(StairsBlock.WATERLOGGED, false).with(StairsBlock.SHAPE, StairsShape.STRAIGHT).with(StairsBlock.HALF, Half.TOP), 16, 15, 16, start);
        structure.setBlockState(world, Blocks.STONE_BRICK_STAIRS.getDefaultState().with(StairsBlock.FACING, Direction.EAST).with(StairsBlock.WATERLOGGED, false).with(StairsBlock.SHAPE, StairsShape.STRAIGHT).with(StairsBlock.HALF, Half.TOP), 16, 15, 21, start);
        structure.setBlockState(world, Blocks.STONE_BRICK_STAIRS.getDefaultState().with(StairsBlock.FACING, Direction.EAST).with(StairsBlock.WATERLOGGED, false).with(StairsBlock.SHAPE, StairsShape.STRAIGHT).with(StairsBlock.HALF, Half.TOP), 16, 17, 13, start);
        structure.setBlockState(world, Blocks.STONE_BRICK_SLAB.getDefaultState().with(SlabBlock.TYPE, SlabType.TOP).with(SlabBlock.WATERLOGGED, false), 16, 17, 14, start);
        structure.setBlockState(world, Blocks.STONE_BRICK_SLAB.getDefaultState().with(SlabBlock.TYPE, SlabType.TOP).with(SlabBlock.WATERLOGGED, false), 16, 17, 23, start);
        structure.setBlockState(world, Blocks.STONE_BRICK_STAIRS.getDefaultState().with(StairsBlock.FACING, Direction.EAST).with(StairsBlock.WATERLOGGED, false).with(StairsBlock.SHAPE, StairsShape.STRAIGHT).with(StairsBlock.HALF, Half.TOP), 16, 17, 24, start);
        structure.setBlockState(world, Blocks.STONE_BRICK_STAIRS.getDefaultState().with(StairsBlock.FACING, Direction.EAST).with(StairsBlock.WATERLOGGED, false).with(StairsBlock.SHAPE, StairsShape.STRAIGHT).with(StairsBlock.HALF, Half.BOTTOM), 16, 18, 13, start);
        structure.setBlockState(world, Blocks.MOSSY_STONE_BRICKS.getDefaultState(), 16, 18, 14, start);
        structure.setBlockState(world, Blocks.STONE_BRICK_STAIRS.getDefaultState().with(StairsBlock.FACING, Direction.EAST).with(StairsBlock.WATERLOGGED, false).with(StairsBlock.SHAPE, StairsShape.STRAIGHT).with(StairsBlock.HALF, Half.BOTTOM), 16, 18, 24, start);
        structure.setBlockState(world, Blocks.CHISELED_STONE_BRICKS.getDefaultState(), 16, 19, 13, start);
        structure.setBlockState(world, Blocks.STONE_BRICK_SLAB.getDefaultState().with(SlabBlock.TYPE, SlabType.BOTTOM).with(SlabBlock.WATERLOGGED, false), 16, 20, 13, start);
        structure.setBlockState(world, Blocks.STONE_BRICK_WALL.getDefaultState().with(WallBlock.WATERLOGGED, false).with(WallBlock.UP, true).with(WallBlock.WALL_HEIGHT_NORTH, WallHeight.LOW).with(WallBlock.WALL_HEIGHT_SOUTH, WallHeight.LOW).with(WallBlock.WALL_HEIGHT_EAST, WallHeight.LOW).with(WallBlock.WALL_HEIGHT_WEST, WallHeight.LOW), 16, 35, 17, start);
        structure.setBlockState(world, Blocks.STONE_BRICK_WALL.getDefaultState().with(WallBlock.WATERLOGGED, false).with(WallBlock.UP, true).with(WallBlock.WALL_HEIGHT_NORTH, WallHeight.LOW).with(WallBlock.WALL_HEIGHT_SOUTH, WallHeight.LOW).with(WallBlock.WALL_HEIGHT_EAST, WallHeight.LOW).with(WallBlock.WALL_HEIGHT_WEST, WallHeight.LOW), 16, 36, 16, start);
        structure.setBlockState(world, Blocks.STONE_BRICK_STAIRS.getDefaultState().with(StairsBlock.FACING, Direction.EAST).with(StairsBlock.WATERLOGGED, false).with(StairsBlock.SHAPE, StairsShape.STRAIGHT).with(StairsBlock.HALF, Half.BOTTOM), 16, 40, 16, start);
        structure.setBlockState(world, Blocks.STONE_BRICK_STAIRS.getDefaultState().with(StairsBlock.FACING, Direction.EAST).with(StairsBlock.WATERLOGGED, false).with(StairsBlock.SHAPE, StairsShape.STRAIGHT).with(StairsBlock.HALF, Half.BOTTOM), 16, 42, 25, start);
        structure.setBlockState(world, Blocks.STONE_BRICKS.getDefaultState(), 16, 43, 16, start);
        structure.setBlockState(world, Blocks.STONE_BRICK_STAIRS.getDefaultState().with(StairsBlock.FACING, Direction.EAST).with(StairsBlock.WATERLOGGED, false).with(StairsBlock.SHAPE, StairsShape.STRAIGHT).with(StairsBlock.HALF, Half.TOP), 16, 43, 25, start);
        structure.setBlockState(world, Blocks.ANDESITE_STAIRS.getDefaultState().with(StairsBlock.FACING, Direction.EAST).with(StairsBlock.WATERLOGGED, false).with(StairsBlock.SHAPE, StairsShape.STRAIGHT).with(StairsBlock.HALF, Half.TOP), 16, 45, 26, start);
        structure.setBlockState(world, Blocks.STONE.getDefaultState(), 16, 46, 26, start);
        structure.setBlockState(world, Blocks.ANDESITE.getDefaultState(), 16, 47, 26, start);
        structure.setBlockState(world, Blocks.STONE_STAIRS.getDefaultState().with(StairsBlock.FACING, Direction.EAST).with(StairsBlock.WATERLOGGED, false).with(StairsBlock.SHAPE, StairsShape.STRAIGHT).with(StairsBlock.HALF, Half.BOTTOM), 16, 48, 26, start);
        structure.setBlockState(world, Blocks.ANDESITE_WALL.getDefaultState().with(WallBlock.WATERLOGGED, false).with(WallBlock.UP, true).with(WallBlock.WALL_HEIGHT_NORTH, WallHeight.LOW).with(WallBlock.WALL_HEIGHT_SOUTH, WallHeight.LOW).with(WallBlock.WALL_HEIGHT_EAST, WallHeight.LOW).with(WallBlock.WALL_HEIGHT_WEST, WallHeight.LOW), 16, 49, 24, start);
        structure.setBlockState(world, Blocks.ANDESITE_WALL.getDefaultState().with(WallBlock.WATERLOGGED, false).with(WallBlock.UP, true).with(WallBlock.WALL_HEIGHT_NORTH, WallHeight.LOW).with(WallBlock.WALL_HEIGHT_SOUTH, WallHeight.LOW).with(WallBlock.WALL_HEIGHT_EAST, WallHeight.LOW).with(WallBlock.WALL_HEIGHT_WEST, WallHeight.LOW), 16, 49, 25, start);
        structure.setBlockState(world, Blocks.STONE_BRICK_STAIRS.getDefaultState().with(StairsBlock.FACING, Direction.EAST).with(StairsBlock.WATERLOGGED, false).with(StairsBlock.SHAPE, StairsShape.STRAIGHT).with(StairsBlock.HALF, Half.TOP), 16, 50, 25, start);
        structure.setBlockState(world, Blocks.CRACKED_STONE_BRICKS.getDefaultState(), 16, 51, 25, start);
        structure.setBlockState(world, Blocks.STONE_STAIRS.getDefaultState().with(StairsBlock.FACING, Direction.SOUTH).with(StairsBlock.WATERLOGGED, false).with(StairsBlock.SHAPE, StairsShape.STRAIGHT).with(StairsBlock.HALF, Half.TOP), 16, 55, 15, start);
        structure.setBlockState(world, Blocks.STONE.getDefaultState(), 16, 55, 16, start);
        structure.setBlockState(world, Blocks.ANDESITE.getDefaultState(), 16, 55, 17, start);
        structure.setBlockState(world, Blocks.STONE_SLAB.getDefaultState().with(SlabBlock.TYPE, SlabType.TOP).with(SlabBlock.WATERLOGGED, false), 16, 55, 18, start);
        structure.setBlockState(world, Blocks.STONE.getDefaultState(), 16, 56, 15, start);
        structure.setBlockState(world, Blocks.ANDESITE.getDefaultState(), 16, 57, 15, start);
        structure.setBlockState(world, Blocks.STONE.getDefaultState(), 16, 57, 19, start);
        structure.setBlockState(world, Blocks.STONE_STAIRS.getDefaultState().with(StairsBlock.FACING, Direction.EAST).with(StairsBlock.WATERLOGGED, false).with(StairsBlock.SHAPE, StairsShape.INNER_RIGHT).with(StairsBlock.HALF, Half.BOTTOM), 16, 58, 15, start);
        structure.setBlockState(world, Blocks.STONE.getDefaultState(), 16, 58, 16, start);
        structure.setBlockState(world, Blocks.ANDESITE.getDefaultState(), 16, 58, 18, start);
        structure.setBlockState(world, Blocks.STONE_SLAB.getDefaultState().with(SlabBlock.TYPE, SlabType.BOTTOM).with(SlabBlock.WATERLOGGED, false), 16, 59, 17, start);
        structure.setBlockState(world, Blocks.POLISHED_DIORITE_STAIRS.getDefaultState().with(StairsBlock.FACING, Direction.EAST).with(StairsBlock.WATERLOGGED, false).with(StairsBlock.SHAPE, StairsShape.STRAIGHT).with(StairsBlock.HALF, Half.BOTTOM), 16, 62, 25, start);
        structure.setBlockState(world, Blocks.GRASS_BLOCK.getDefaultState().with(SnowyDirtBlock.SNOWY, false), 17, 6, 38, start);
        structure.setBlockState(world, Blocks.POLISHED_ANDESITE.getDefaultState(), 17, 7, 11, start);
        structure.setBlockState(world, Blocks.ANDESITE.getDefaultState(), 17, 7, 18, start);
        structure.setBlockState(world, Blocks.ANDESITE.getDefaultState(), 17, 7, 21, start);
        structure.setBlockState(world, Blocks.POLISHED_ANDESITE.getDefaultState(), 17, 7, 26, start);
        structure.setBlockState(world, Blocks.STONE_BRICK_STAIRS.getDefaultState().with(StairsBlock.FACING, Direction.SOUTH).with(StairsBlock.WATERLOGGED, false).with(StairsBlock.SHAPE, StairsShape.STRAIGHT).with(StairsBlock.HALF, Half.BOTTOM), 17, 8, 11, start);
        structure.setBlockState(world, Blocks.MOSSY_STONE_BRICKS.getDefaultState(), 17, 8, 12, start);
        structure.setBlockState(world, Blocks.STONE_BRICK_STAIRS.getDefaultState().with(StairsBlock.FACING, Direction.NORTH).with(StairsBlock.WATERLOGGED, false).with(StairsBlock.SHAPE, StairsShape.STRAIGHT).with(StairsBlock.HALF, Half.BOTTOM), 17, 8, 26, start);
        structure.setBlockState(world, Blocks.STONE_BRICK_STAIRS.getDefaultState().with(StairsBlock.FACING, Direction.SOUTH).with(StairsBlock.WATERLOGGED, false).with(StairsBlock.SHAPE, StairsShape.STRAIGHT).with(StairsBlock.HALF, Half.TOP), 17, 9, 11, start);
        structure.setBlockState(world, Blocks.CRACKED_STONE_BRICKS.getDefaultState(), 17, 9, 12, start);
        structure.setBlockState(world, Blocks.STONE_BRICK_STAIRS.getDefaultState().with(StairsBlock.FACING, Direction.NORTH).with(StairsBlock.WATERLOGGED, false).with(StairsBlock.SHAPE, StairsShape.STRAIGHT).with(StairsBlock.HALF, Half.TOP), 17, 9, 26, start);
        structure.setBlockState(world, Blocks.STONE_BRICK_STAIRS.getDefaultState().with(StairsBlock.FACING, Direction.SOUTH).with(StairsBlock.WATERLOGGED, false).with(StairsBlock.SHAPE, StairsShape.STRAIGHT).with(StairsBlock.HALF, Half.BOTTOM), 17, 10, 11, start);
        structure.setBlockState(world, Blocks.STONE_BRICK_STAIRS.getDefaultState().with(StairsBlock.FACING, Direction.NORTH).with(StairsBlock.WATERLOGGED, false).with(StairsBlock.SHAPE, StairsShape.STRAIGHT).with(StairsBlock.HALF, Half.BOTTOM), 17, 10, 26, start);
        structure.setBlockState(world, Blocks.STONE_BRICK_STAIRS.getDefaultState().with(StairsBlock.FACING, Direction.SOUTH).with(StairsBlock.WATERLOGGED, false).with(StairsBlock.SHAPE, StairsShape.STRAIGHT).with(StairsBlock.HALF, Half.BOTTOM), 17, 11, 12, start);
        structure.setBlockState(world, Blocks.STONE_BRICK_STAIRS.getDefaultState().with(StairsBlock.FACING, Direction.NORTH).with(StairsBlock.WATERLOGGED, false).with(StairsBlock.SHAPE, StairsShape.STRAIGHT).with(StairsBlock.HALF, Half.BOTTOM), 17, 11, 25, start);
        structure.setBlockState(world, Blocks.MOSSY_STONE_BRICKS.getDefaultState(), 17, 12, 14, start);
        structure.setBlockState(world, Blocks.CRACKED_STONE_BRICKS.getDefaultState(), 17, 13, 18, start);
        structure.setBlockState(world, Blocks.CRACKED_STONE_BRICKS.getDefaultState(), 17, 14, 19, start);
        structure.setBlockState(world, Blocks.CRACKED_STONE_BRICKS.getDefaultState(), 17, 15, 14, start);
        structure.setBlockState(world, Blocks.CRACKED_STONE_BRICKS.getDefaultState(), 17, 16, 23, start);
        structure.setBlockState(world, Blocks.STONE_BRICK_STAIRS.getDefaultState().with(StairsBlock.FACING, Direction.SOUTH).with(StairsBlock.WATERLOGGED, false).with(StairsBlock.SHAPE, StairsShape.STRAIGHT).with(StairsBlock.HALF, Half.TOP), 17, 17, 12, start);
        structure.setBlockState(world, Blocks.STONE_BRICK_STAIRS.getDefaultState().with(StairsBlock.FACING, Direction.NORTH).with(StairsBlock.WATERLOGGED, false).with(StairsBlock.SHAPE, StairsShape.STRAIGHT).with(StairsBlock.HALF, Half.TOP), 17, 17, 25, start);
        structure.setBlockState(world, Blocks.STONE_BRICK_STAIRS.getDefaultState().with(StairsBlock.FACING, Direction.SOUTH).with(StairsBlock.WATERLOGGED, false).with(StairsBlock.SHAPE, StairsShape.STRAIGHT).with(StairsBlock.HALF, Half.BOTTOM), 17, 18, 12, start);
        structure.setBlockState(world, Blocks.MOSSY_STONE_BRICKS.getDefaultState(), 17, 18, 24, start);
        structure.setBlockState(world, Blocks.STONE_BRICK_STAIRS.getDefaultState().with(StairsBlock.FACING, Direction.NORTH).with(StairsBlock.WATERLOGGED, false).with(StairsBlock.SHAPE, StairsShape.STRAIGHT).with(StairsBlock.HALF, Half.BOTTOM), 17, 18, 25, start);
        structure.setBlockState(world, Blocks.STONE_BUTTON.getDefaultState().with(HorizontalBlock.HORIZONTAL_FACING, Direction.NORTH).with(HorizontalFaceBlock.FACE, AttachFace.WALL).with(AbstractButtonBlock.POWERED, false), 17, 19, 11, start);
        structure.setBlockState(world, Blocks.CHISELED_STONE_BRICKS.getDefaultState(), 17, 19, 12, start);
        structure.setBlockState(world, Blocks.CHISELED_STONE_BRICKS.getDefaultState(), 17, 19, 25, start);
        structure.setBlockState(world, Blocks.STONE_BUTTON.getDefaultState().with(HorizontalBlock.HORIZONTAL_FACING, Direction.SOUTH).with(HorizontalFaceBlock.FACE, AttachFace.WALL).with(AbstractButtonBlock.POWERED, false), 17, 19, 26, start);
        structure.setBlockState(world, Blocks.STONE_BRICK_SLAB.getDefaultState().with(SlabBlock.TYPE, SlabType.BOTTOM).with(SlabBlock.WATERLOGGED, false), 17, 20, 12, start);
        structure.setBlockState(world, Blocks.STONE_BRICK_SLAB.getDefaultState().with(SlabBlock.TYPE, SlabType.BOTTOM).with(SlabBlock.WATERLOGGED, false), 17, 20, 25, start);
        structure.setBlockState(world, Blocks.STONE_BRICK_STAIRS.getDefaultState().with(StairsBlock.FACING, Direction.EAST).with(StairsBlock.WATERLOGGED, false).with(StairsBlock.SHAPE, StairsShape.STRAIGHT).with(StairsBlock.HALF, Half.TOP), 17, 28, 17, start);
        structure.setBlockState(world, Blocks.STONE_BRICK_WALL.getDefaultState().with(WallBlock.WATERLOGGED, false).with(WallBlock.UP, true).with(WallBlock.WALL_HEIGHT_NORTH, WallHeight.LOW).with(WallBlock.WALL_HEIGHT_SOUTH, WallHeight.LOW).with(WallBlock.WALL_HEIGHT_EAST, WallHeight.LOW).with(WallBlock.WALL_HEIGHT_WEST, WallHeight.LOW), 17, 29, 14, start);
        structure.setBlockState(world, Blocks.STONE_BRICK_WALL.getDefaultState().with(WallBlock.WATERLOGGED, false).with(WallBlock.UP, true).with(WallBlock.WALL_HEIGHT_NORTH, WallHeight.LOW).with(WallBlock.WALL_HEIGHT_SOUTH, WallHeight.LOW).with(WallBlock.WALL_HEIGHT_EAST, WallHeight.LOW).with(WallBlock.WALL_HEIGHT_WEST, WallHeight.LOW), 17, 29, 15, start);
        structure.setBlockState(world, Blocks.STONE_BRICKS.getDefaultState(), 17, 29, 16, start);
        structure.setBlockState(world, Blocks.CRACKED_STONE_BRICKS.getDefaultState(), 17, 29, 17, start);
        structure.setBlockState(world, Blocks.STONE_BRICK_STAIRS.getDefaultState().with(StairsBlock.FACING, Direction.EAST).with(StairsBlock.WATERLOGGED, false).with(StairsBlock.SHAPE, StairsShape.STRAIGHT).with(StairsBlock.HALF, Half.BOTTOM), 17, 30, 17, start);
        structure.setBlockState(world, Blocks.STONE_BRICK_SLAB.getDefaultState().with(SlabBlock.TYPE, SlabType.TOP).with(SlabBlock.WATERLOGGED, false), 17, 35, 15, start);
        structure.setBlockState(world, Blocks.STONE_BRICK_SLAB.getDefaultState().with(SlabBlock.TYPE, SlabType.TOP).with(SlabBlock.WATERLOGGED, false), 17, 35, 18, start);
        structure.setBlockState(world, Blocks.STONE_STAIRS.getDefaultState().with(StairsBlock.FACING, Direction.EAST).with(StairsBlock.WATERLOGGED, false).with(StairsBlock.SHAPE, StairsShape.STRAIGHT).with(StairsBlock.HALF, Half.TOP), 17, 37, 16, start);
        structure.setBlockState(world, Blocks.STONE_BRICKS.getDefaultState(), 17, 40, 15, start);
        structure.setBlockState(world, Blocks.STONE_BRICK_STAIRS.getDefaultState().with(StairsBlock.FACING, Direction.SOUTH).with(StairsBlock.WATERLOGGED, false).with(StairsBlock.SHAPE, StairsShape.STRAIGHT).with(StairsBlock.HALF, Half.TOP), 17, 41, 14, start);
        structure.setBlockState(world, Blocks.CRACKED_STONE_BRICKS.getDefaultState(), 17, 41, 15, start);
        structure.setBlockState(world, Blocks.STONE_BRICK_STAIRS.getDefaultState().with(StairsBlock.FACING, Direction.EAST).with(StairsBlock.WATERLOGGED, false).with(StairsBlock.SHAPE, StairsShape.STRAIGHT).with(StairsBlock.HALF, Half.TOP), 17, 41, 25, start);
        structure.setBlockState(world, Blocks.STONE_BRICK_STAIRS.getDefaultState().with(StairsBlock.FACING, Direction.SOUTH).with(StairsBlock.WATERLOGGED, false).with(StairsBlock.SHAPE, StairsShape.STRAIGHT).with(StairsBlock.HALF, Half.BOTTOM), 17, 42, 14, start);
        structure.setBlockState(world, Blocks.COBBLESTONE_STAIRS.getDefaultState().with(StairsBlock.FACING, Direction.EAST).with(StairsBlock.WATERLOGGED, false).with(StairsBlock.SHAPE, StairsShape.STRAIGHT).with(StairsBlock.HALF, Half.BOTTOM), 17, 43, 16, start);
        structure.setBlockState(world, Blocks.CRACKED_STONE_BRICKS.getDefaultState(), 17, 43, 17, start);
        structure.setBlockState(world, Blocks.STONE_BRICK_STAIRS.getDefaultState().with(StairsBlock.FACING, Direction.EAST).with(StairsBlock.WATERLOGGED, false).with(StairsBlock.SHAPE, StairsShape.STRAIGHT).with(StairsBlock.HALF, Half.BOTTOM), 17, 44, 14, start);
        structure.setBlockState(world, Blocks.STONE_BRICKS.getDefaultState(), 17, 44, 16, start);
        structure.setBlockState(world, Blocks.STONE_BRICK_STAIRS.getDefaultState().with(StairsBlock.FACING, Direction.EAST).with(StairsBlock.WATERLOGGED, false).with(StairsBlock.SHAPE, StairsShape.STRAIGHT).with(StairsBlock.HALF, Half.BOTTOM), 17, 44, 17, start);
        structure.setBlockState(world, Blocks.STONE.getDefaultState(), 17, 45, 26, start);
        structure.setBlockState(world, Blocks.STONE_BRICKS.getDefaultState(), 17, 46, 25, start);
        structure.setBlockState(world, Blocks.ANDESITE.getDefaultState(), 17, 46, 26, start);
        structure.setBlockState(world, Blocks.CRACKED_STONE_BRICKS.getDefaultState(), 17, 47, 25, start);
        structure.setBlockState(world, Blocks.ANDESITE_WALL.getDefaultState().with(WallBlock.WATERLOGGED, false).with(WallBlock.UP, true).with(WallBlock.WALL_HEIGHT_NORTH, WallHeight.LOW).with(WallBlock.WALL_HEIGHT_SOUTH, WallHeight.LOW).with(WallBlock.WALL_HEIGHT_EAST, WallHeight.LOW).with(WallBlock.WALL_HEIGHT_WEST, WallHeight.LOW), 17, 49, 24, start);
        structure.setBlockState(world, Blocks.CRACKED_STONE_BRICKS.getDefaultState(), 17, 50, 25, start);
        structure.setBlockState(world, Blocks.STONE_BRICKS.getDefaultState(), 17, 54, 15, start);
        structure.setBlockState(world, Blocks.STONE.getDefaultState(), 17, 55, 18, start);
        structure.setBlockState(world, Blocks.STONE_STAIRS.getDefaultState().with(StairsBlock.FACING, Direction.EAST).with(StairsBlock.WATERLOGGED, false).with(StairsBlock.SHAPE, StairsShape.STRAIGHT).with(StairsBlock.HALF, Half.TOP), 17, 55, 19, start);
        structure.setBlockState(world, Blocks.ANDESITE_STAIRS.getDefaultState().with(StairsBlock.FACING, Direction.SOUTH).with(StairsBlock.WATERLOGGED, false).with(StairsBlock.SHAPE, StairsShape.STRAIGHT).with(StairsBlock.HALF, Half.TOP), 17, 56, 14, start);
        structure.setBlockState(world, Blocks.STONE_STAIRS.getDefaultState().with(StairsBlock.FACING, Direction.SOUTH).with(StairsBlock.WATERLOGGED, false).with(StairsBlock.SHAPE, StairsShape.STRAIGHT).with(StairsBlock.HALF, Half.BOTTOM), 17, 57, 14, start);
        structure.setBlockState(world, Blocks.ANDESITE.getDefaultState(), 17, 57, 19, start);
        structure.setBlockState(world, Blocks.STONE.getDefaultState(), 17, 58, 15, start);
        structure.setBlockState(world, Blocks.STONE.getDefaultState(), 17, 58, 18, start);
        structure.setBlockState(world, Blocks.STONE_SLAB.getDefaultState().with(SlabBlock.TYPE, SlabType.BOTTOM).with(SlabBlock.WATERLOGGED, false), 17, 58, 19, start);
        structure.setBlockState(world, Blocks.ANDESITE_STAIRS.getDefaultState().with(StairsBlock.FACING, Direction.EAST).with(StairsBlock.WATERLOGGED, false).with(StairsBlock.SHAPE, StairsShape.STRAIGHT).with(StairsBlock.HALF, Half.BOTTOM), 17, 59, 16, start);
        structure.setBlockState(world, Blocks.STONE.getDefaultState(), 17, 59, 17, start);
        structure.setBlockState(world, Blocks.STONE_STAIRS.getDefaultState().with(StairsBlock.FACING, Direction.EAST).with(StairsBlock.WATERLOGGED, false).with(StairsBlock.SHAPE, StairsShape.STRAIGHT).with(StairsBlock.HALF, Half.BOTTOM), 17, 59, 18, start);
        structure.setBlockState(world, Blocks.POLISHED_DIORITE_STAIRS.getDefaultState().with(StairsBlock.FACING, Direction.EAST).with(StairsBlock.WATERLOGGED, false).with(StairsBlock.SHAPE, StairsShape.STRAIGHT).with(StairsBlock.HALF, Half.BOTTOM), 17, 69, 25, start);
        structure.setBlockState(world, Blocks.STONE_BRICK_WALL.getDefaultState().with(WallBlock.WATERLOGGED, false).with(WallBlock.UP, true).with(WallBlock.WALL_HEIGHT_NORTH, WallHeight.LOW).with(WallBlock.WALL_HEIGHT_SOUTH, WallHeight.LOW).with(WallBlock.WALL_HEIGHT_EAST, WallHeight.LOW).with(WallBlock.WALL_HEIGHT_WEST, WallHeight.LOW), 18, 7, 10, start);
        structure.setBlockState(world, Blocks.MOSSY_STONE_BRICKS.getDefaultState(), 18, 7, 11, start);
        structure.setBlockState(world, Blocks.STONE.getDefaultState(), 18, 7, 14, start);
        structure.setBlockState(world, Blocks.STONE_BRICK_WALL.getDefaultState().with(WallBlock.WATERLOGGED, false).with(WallBlock.UP, true).with(WallBlock.WALL_HEIGHT_NORTH, WallHeight.LOW).with(WallBlock.WALL_HEIGHT_SOUTH, WallHeight.LOW).with(WallBlock.WALL_HEIGHT_EAST, WallHeight.LOW).with(WallBlock.WALL_HEIGHT_WEST, WallHeight.LOW), 18, 7, 27, start);
        structure.setBlockState(world, Blocks.STONE_BRICK_SLAB.getDefaultState().with(SlabBlock.TYPE, SlabType.BOTTOM).with(SlabBlock.WATERLOGGED, false), 18, 8, 10, start);
        structure.setBlockState(world, Blocks.STONE_BRICK_SLAB.getDefaultState().with(SlabBlock.TYPE, SlabType.BOTTOM).with(SlabBlock.WATERLOGGED, false), 18, 8, 27, start);
        structure.setBlockState(world, Blocks.ANDESITE.getDefaultState(), 18, 9, 23, start);
        structure.setBlockState(world, Blocks.STONE_BRICK_STAIRS.getDefaultState().with(StairsBlock.FACING, Direction.EAST).with(StairsBlock.WATERLOGGED, false).with(StairsBlock.SHAPE, StairsShape.STRAIGHT).with(StairsBlock.HALF, Half.BOTTOM), 18, 11, 11, start);
        structure.setBlockState(world, Blocks.STONE_BRICK_SLAB.getDefaultState().with(SlabBlock.TYPE, SlabType.BOTTOM).with(SlabBlock.WATERLOGGED, false), 18, 11, 12, start);
        structure.setBlockState(world, Blocks.STONE_BRICK_SLAB.getDefaultState().with(SlabBlock.TYPE, SlabType.BOTTOM).with(SlabBlock.WATERLOGGED, false), 18, 11, 25, start);
        structure.setBlockState(world, Blocks.STONE_BRICK_STAIRS.getDefaultState().with(StairsBlock.FACING, Direction.EAST).with(StairsBlock.WATERLOGGED, false).with(StairsBlock.SHAPE, StairsShape.STRAIGHT).with(StairsBlock.HALF, Half.BOTTOM), 18, 11, 26, start);
        structure.setBlockState(world, Blocks.STONE_BRICKS.getDefaultState(), 18, 12, 24, start);
        structure.setBlockState(world, Blocks.CRACKED_STONE_BRICKS.getDefaultState(), 18, 13, 24, start);
        structure.setBlockState(world, Blocks.CRACKED_STONE_BRICKS.getDefaultState(), 18, 14, 13, start);
        structure.setBlockState(world, Blocks.CRACKED_STONE_BRICKS.getDefaultState(), 18, 14, 18, start);
        structure.setBlockState(world, Blocks.STONE_BRICK_STAIRS.getDefaultState().with(StairsBlock.FACING, Direction.EAST).with(StairsBlock.WATERLOGGED, false).with(StairsBlock.SHAPE, StairsShape.STRAIGHT).with(StairsBlock.HALF, Half.TOP), 18, 17, 11, start);
        structure.setBlockState(world, Blocks.STONE_BRICK_SLAB.getDefaultState().with(SlabBlock.TYPE, SlabType.TOP).with(SlabBlock.WATERLOGGED, false), 18, 17, 12, start);
        structure.setBlockState(world, Blocks.STONE_BRICK_SLAB.getDefaultState().with(SlabBlock.TYPE, SlabType.TOP).with(SlabBlock.WATERLOGGED, false), 18, 17, 25, start);
        structure.setBlockState(world, Blocks.STONE_BRICK_STAIRS.getDefaultState().with(StairsBlock.FACING, Direction.EAST).with(StairsBlock.WATERLOGGED, false).with(StairsBlock.SHAPE, StairsShape.STRAIGHT).with(StairsBlock.HALF, Half.TOP), 18, 17, 26, start);
        structure.setBlockState(world, Blocks.STONE_BRICK_STAIRS.getDefaultState().with(StairsBlock.FACING, Direction.EAST).with(StairsBlock.WATERLOGGED, false).with(StairsBlock.SHAPE, StairsShape.STRAIGHT).with(StairsBlock.HALF, Half.BOTTOM), 18, 18, 11, start);
        structure.setBlockState(world, Blocks.MOSSY_STONE_BRICKS.getDefaultState(), 18, 18, 12, start);
        structure.setBlockState(world, Blocks.STONE_BRICK_STAIRS.getDefaultState().with(StairsBlock.FACING, Direction.EAST).with(StairsBlock.WATERLOGGED, false).with(StairsBlock.SHAPE, StairsShape.STRAIGHT).with(StairsBlock.HALF, Half.BOTTOM), 18, 18, 26, start);
        structure.setBlockState(world, Blocks.STONE_BRICK_STAIRS.getDefaultState().with(StairsBlock.FACING, Direction.EAST).with(StairsBlock.WATERLOGGED, false).with(StairsBlock.SHAPE, StairsShape.STRAIGHT).with(StairsBlock.HALF, Half.TOP), 18, 20, 15, start);
        structure.setBlockState(world, Blocks.STONE_BRICK_SLAB.getDefaultState().with(SlabBlock.TYPE, SlabType.TOP).with(SlabBlock.WATERLOGGED, false), 18, 20, 16, start);
        structure.setBlockState(world, Blocks.STONE_BRICK_STAIRS.getDefaultState().with(StairsBlock.FACING, Direction.EAST).with(StairsBlock.WATERLOGGED, false).with(StairsBlock.SHAPE, StairsShape.STRAIGHT).with(StairsBlock.HALF, Half.TOP), 18, 20, 17, start);
        structure.setBlockState(world, Blocks.STONE_BRICK_STAIRS.getDefaultState().with(StairsBlock.FACING, Direction.EAST).with(StairsBlock.WATERLOGGED, false).with(StairsBlock.SHAPE, StairsShape.OUTER_LEFT).with(StairsBlock.HALF, Half.BOTTOM), 18, 20, 21, start);
        structure.setBlockState(world, Blocks.ANDESITE_STAIRS.getDefaultState().with(StairsBlock.FACING, Direction.EAST).with(StairsBlock.WATERLOGGED, false).with(StairsBlock.SHAPE, StairsShape.STRAIGHT).with(StairsBlock.HALF, Half.BOTTOM), 18, 21, 15, start);
        structure.setBlockState(world, Blocks.STONE.getDefaultState(), 18, 21, 16, start);
        structure.setBlockState(world, Blocks.ANDESITE_STAIRS.getDefaultState().with(StairsBlock.FACING, Direction.EAST).with(StairsBlock.WATERLOGGED, false).with(StairsBlock.SHAPE, StairsShape.STRAIGHT).with(StairsBlock.HALF, Half.BOTTOM), 18, 21, 17, start);
        structure.setBlockState(world, Blocks.STONE_SLAB.getDefaultState().with(SlabBlock.TYPE, SlabType.BOTTOM).with(SlabBlock.WATERLOGGED, false), 18, 21, 19, start);
        structure.setBlockState(world, Blocks.ANDESITE_STAIRS.getDefaultState().with(StairsBlock.FACING, Direction.EAST).with(StairsBlock.WATERLOGGED, false).with(StairsBlock.SHAPE, StairsShape.STRAIGHT).with(StairsBlock.HALF, Half.BOTTOM), 18, 22, 16, start);
        structure.setBlockState(world, Blocks.STONE_STAIRS.getDefaultState().with(StairsBlock.FACING, Direction.EAST).with(StairsBlock.WATERLOGGED, false).with(StairsBlock.SHAPE, StairsShape.STRAIGHT).with(StairsBlock.HALF, Half.TOP), 18, 23, 16, start);
        structure.setBlockState(world, Blocks.STONE.getDefaultState(), 18, 24, 16, start);
        structure.setBlockState(world, Blocks.STONE_BRICK_STAIRS.getDefaultState().with(StairsBlock.FACING, Direction.EAST).with(StairsBlock.WATERLOGGED, false).with(StairsBlock.SHAPE, StairsShape.STRAIGHT).with(StairsBlock.HALF, Half.TOP), 18, 24, 17, start);
        structure.setBlockState(world, Blocks.STONE_STAIRS.getDefaultState().with(StairsBlock.FACING, Direction.SOUTH).with(StairsBlock.WATERLOGGED, false).with(StairsBlock.SHAPE, StairsShape.STRAIGHT).with(StairsBlock.HALF, Half.TOP), 18, 25, 15, start);
        structure.setBlockState(world, Blocks.ANDESITE.getDefaultState(), 18, 25, 16, start);
        structure.setBlockState(world, Blocks.STONE.getDefaultState(), 18, 26, 16, start);
        structure.setBlockState(world, Blocks.STONE.getDefaultState(), 18, 28, 17, start);
        structure.setBlockState(world, Blocks.STONE_BRICK_STAIRS.getDefaultState().with(StairsBlock.FACING, Direction.NORTH).with(StairsBlock.WATERLOGGED, false).with(StairsBlock.SHAPE, StairsShape.STRAIGHT).with(StairsBlock.HALF, Half.TOP), 18, 28, 18, start);
        structure.setBlockState(world, Blocks.STONE_BRICK_WALL.getDefaultState().with(WallBlock.WATERLOGGED, false).with(WallBlock.UP, true).with(WallBlock.WALL_HEIGHT_NORTH, WallHeight.LOW).with(WallBlock.WALL_HEIGHT_SOUTH, WallHeight.LOW).with(WallBlock.WALL_HEIGHT_EAST, WallHeight.LOW).with(WallBlock.WALL_HEIGHT_WEST, WallHeight.LOW), 18, 29, 13, start);
        structure.setBlockState(world, Blocks.STONE_BRICKS.getDefaultState(), 18, 29, 14, start);
        structure.setBlockState(world, Blocks.STONE.getDefaultState(), 18, 30, 14, start);
        structure.setBlockState(world, Blocks.ANDESITE.getDefaultState(), 18, 30, 15, start);
        structure.setBlockState(world, Blocks.STONE.getDefaultState(), 18, 30, 16, start);
        structure.setBlockState(world, Blocks.STONE_STAIRS.getDefaultState().with(StairsBlock.FACING, Direction.SOUTH).with(StairsBlock.WATERLOGGED, false).with(StairsBlock.SHAPE, StairsShape.STRAIGHT).with(StairsBlock.HALF, Half.BOTTOM), 18, 31, 14, start);
        structure.setBlockState(world, Blocks.STONE.getDefaultState(), 18, 31, 15, start);
        structure.setBlockState(world, Blocks.STONE_BRICK_STAIRS.getDefaultState().with(StairsBlock.FACING, Direction.NORTH).with(StairsBlock.WATERLOGGED, false).with(StairsBlock.SHAPE, StairsShape.STRAIGHT).with(StairsBlock.HALF, Half.BOTTOM), 18, 31, 18, start);
        structure.setBlockState(world, Blocks.ANDESITE_STAIRS.getDefaultState().with(StairsBlock.FACING, Direction.SOUTH).with(StairsBlock.WATERLOGGED, false).with(StairsBlock.SHAPE, StairsShape.STRAIGHT).with(StairsBlock.HALF, Half.BOTTOM), 18, 32, 15, start);
        structure.setBlockState(world, Blocks.ANDESITE.getDefaultState(), 18, 32, 16, start);
        structure.setBlockState(world, Blocks.STONE.getDefaultState(), 18, 33, 16, start);
        structure.setBlockState(world, Blocks.STONE_STAIRS.getDefaultState().with(StairsBlock.FACING, Direction.EAST).with(StairsBlock.WATERLOGGED, false).with(StairsBlock.SHAPE, StairsShape.STRAIGHT).with(StairsBlock.HALF, Half.BOTTOM), 18, 33, 17, start);
        structure.setBlockState(world, Blocks.STONE_STAIRS.getDefaultState().with(StairsBlock.FACING, Direction.EAST).with(StairsBlock.WATERLOGGED, false).with(StairsBlock.SHAPE, StairsShape.STRAIGHT).with(StairsBlock.HALF, Half.TOP), 18, 34, 17, start);
        structure.setBlockState(world, Blocks.STONE_BRICK_WALL.getDefaultState().with(WallBlock.WATERLOGGED, false).with(WallBlock.UP, true).with(WallBlock.WALL_HEIGHT_NORTH, WallHeight.LOW).with(WallBlock.WALL_HEIGHT_SOUTH, WallHeight.LOW).with(WallBlock.WALL_HEIGHT_EAST, WallHeight.LOW).with(WallBlock.WALL_HEIGHT_WEST, WallHeight.LOW), 18, 35, 14, start);
        structure.setBlockState(world, Blocks.ANDESITE_STAIRS.getDefaultState().with(StairsBlock.FACING, Direction.EAST).with(StairsBlock.WATERLOGGED, false).with(StairsBlock.SHAPE, StairsShape.STRAIGHT).with(StairsBlock.HALF, Half.TOP), 18, 36, 15, start);
        structure.setBlockState(world, Blocks.STONE_BRICK_STAIRS.getDefaultState().with(StairsBlock.FACING, Direction.WEST).with(StairsBlock.WATERLOGGED, false).with(StairsBlock.SHAPE, StairsShape.STRAIGHT).with(StairsBlock.HALF, Half.TOP), 18, 41, 25, start);
        structure.setBlockState(world, Blocks.STONE_BRICK_STAIRS.getDefaultState().with(StairsBlock.FACING, Direction.EAST).with(StairsBlock.WATERLOGGED, false).with(StairsBlock.SHAPE, StairsShape.STRAIGHT).with(StairsBlock.HALF, Half.BOTTOM), 18, 45, 14, start);
        structure.setBlockState(world, Blocks.STONE_BRICK_STAIRS.getDefaultState().with(StairsBlock.FACING, Direction.EAST).with(StairsBlock.WATERLOGGED, false).with(StairsBlock.SHAPE, StairsShape.STRAIGHT).with(StairsBlock.HALF, Half.BOTTOM), 18, 45, 17, start);
        structure.setBlockState(world, Blocks.CRACKED_STONE_BRICKS.getDefaultState(), 18, 46, 25, start);
        structure.setBlockState(world, Blocks.ANDESITE_WALL.getDefaultState().with(WallBlock.WATERLOGGED, false).with(WallBlock.UP, true).with(WallBlock.WALL_HEIGHT_NORTH, WallHeight.LOW).with(WallBlock.WALL_HEIGHT_SOUTH, WallHeight.LOW).with(WallBlock.WALL_HEIGHT_EAST, WallHeight.LOW).with(WallBlock.WALL_HEIGHT_WEST, WallHeight.LOW), 18, 48, 26, start);
        structure.setBlockState(world, Blocks.ANDESITE_WALL.getDefaultState().with(WallBlock.WATERLOGGED, false).with(WallBlock.UP, true).with(WallBlock.WALL_HEIGHT_NORTH, WallHeight.LOW).with(WallBlock.WALL_HEIGHT_SOUTH, WallHeight.LOW).with(WallBlock.WALL_HEIGHT_EAST, WallHeight.LOW).with(WallBlock.WALL_HEIGHT_WEST, WallHeight.LOW), 18, 49, 24, start);
        structure.setBlockState(world, Blocks.STONE_BRICKS.getDefaultState(), 18, 53, 19, start);
        structure.setBlockState(world, Blocks.STONE.getDefaultState(), 18, 54, 18, start);
        structure.setBlockState(world, Blocks.ANDESITE.getDefaultState(), 18, 54, 19, start);
        structure.setBlockState(world, Blocks.STONE_BRICK_STAIRS.getDefaultState().with(StairsBlock.FACING, Direction.NORTH).with(StairsBlock.WATERLOGGED, false).with(StairsBlock.SHAPE, StairsShape.STRAIGHT).with(StairsBlock.HALF, Half.TOP), 18, 54, 20, start);
        structure.setBlockState(world, Blocks.STONE.getDefaultState(), 18, 55, 15, start);
        structure.setBlockState(world, Blocks.POLISHED_ANDESITE.getDefaultState(), 18, 55, 20, start);
        structure.setBlockState(world, Blocks.STONE.getDefaultState(), 18, 56, 14, start);
        structure.setBlockState(world, Blocks.ANDESITE_STAIRS.getDefaultState().with(StairsBlock.FACING, Direction.EAST).with(StairsBlock.WATERLOGGED, false).with(StairsBlock.SHAPE, StairsShape.INNER_RIGHT).with(StairsBlock.HALF, Half.BOTTOM), 18, 57, 14, start);
        structure.setBlockState(world, Blocks.COBBLESTONE.getDefaultState(), 18, 57, 19, start);
        structure.setBlockState(world, Blocks.STONE_BRICK_STAIRS.getDefaultState().with(StairsBlock.FACING, Direction.NORTH).with(StairsBlock.WATERLOGGED, false).with(StairsBlock.SHAPE, StairsShape.STRAIGHT).with(StairsBlock.HALF, Half.BOTTOM), 18, 57, 20, start);
        structure.setBlockState(world, Blocks.STONE_BRICKS.getDefaultState(), 18, 58, 14, start);
        structure.setBlockState(world, Blocks.STONE_BRICK_STAIRS.getDefaultState().with(StairsBlock.FACING, Direction.NORTH).with(StairsBlock.WATERLOGGED, false).with(StairsBlock.SHAPE, StairsShape.STRAIGHT).with(StairsBlock.HALF, Half.BOTTOM), 18, 58, 19, start);
        structure.setBlockState(world, Blocks.STONE_BRICKS.getDefaultState(), 18, 59, 15, start);
        structure.setBlockState(world, Blocks.POLISHED_DIORITE_STAIRS.getDefaultState().with(StairsBlock.FACING, Direction.WEST).with(StairsBlock.WATERLOGGED, false).with(StairsBlock.SHAPE, StairsShape.STRAIGHT).with(StairsBlock.HALF, Half.BOTTOM), 18, 69, 25, start);
        structure.setBlockState(world, Blocks.POLISHED_ANDESITE.getDefaultState(), 19, 7, 9, start);
        structure.setBlockState(world, Blocks.STONE.getDefaultState(), 19, 7, 13, start);
        structure.setBlockState(world, Blocks.POLISHED_ANDESITE.getDefaultState(), 19, 7, 28, start);
        structure.setBlockState(world, Blocks.STONE_BRICK_STAIRS.getDefaultState().with(StairsBlock.FACING, Direction.SOUTH).with(StairsBlock.WATERLOGGED, false).with(StairsBlock.SHAPE, StairsShape.STRAIGHT).with(StairsBlock.HALF, Half.BOTTOM), 19, 8, 9, start);
        structure.setBlockState(world, Blocks.MOSSY_STONE_BRICKS.getDefaultState(), 19, 8, 27, start);
        structure.setBlockState(world, Blocks.STONE_BRICK_STAIRS.getDefaultState().with(StairsBlock.FACING, Direction.NORTH).with(StairsBlock.WATERLOGGED, false).with(StairsBlock.SHAPE, StairsShape.STRAIGHT).with(StairsBlock.HALF, Half.BOTTOM), 19, 8, 28, start);
        structure.setBlockState(world, Blocks.STONE_BRICK_STAIRS.getDefaultState().with(StairsBlock.FACING, Direction.SOUTH).with(StairsBlock.WATERLOGGED, false).with(StairsBlock.SHAPE, StairsShape.STRAIGHT).with(StairsBlock.HALF, Half.TOP), 19, 9, 9, start);
        structure.setBlockState(world, Blocks.STONE_BRICK_STAIRS.getDefaultState().with(StairsBlock.FACING, Direction.NORTH).with(StairsBlock.WATERLOGGED, false).with(StairsBlock.SHAPE, StairsShape.STRAIGHT).with(StairsBlock.HALF, Half.TOP), 19, 9, 28, start);
        structure.setBlockState(world, Blocks.STONE_BRICK_STAIRS.getDefaultState().with(StairsBlock.FACING, Direction.SOUTH).with(StairsBlock.WATERLOGGED, false).with(StairsBlock.SHAPE, StairsShape.STRAIGHT).with(StairsBlock.HALF, Half.BOTTOM), 19, 10, 9, start);
        structure.setBlockState(world, Blocks.STONE_BRICK_STAIRS.getDefaultState().with(StairsBlock.FACING, Direction.NORTH).with(StairsBlock.WATERLOGGED, false).with(StairsBlock.SHAPE, StairsShape.STRAIGHT).with(StairsBlock.HALF, Half.BOTTOM), 19, 10, 28, start);
        structure.setBlockState(world, Blocks.STONE_BRICK_STAIRS.getDefaultState().with(StairsBlock.FACING, Direction.NORTH).with(StairsBlock.WATERLOGGED, false).with(StairsBlock.SHAPE, StairsShape.STRAIGHT).with(StairsBlock.HALF, Half.BOTTOM), 19, 11, 27, start);
        structure.setBlockState(world, Blocks.STONE_BRICK_STAIRS.getDefaultState().with(StairsBlock.FACING, Direction.WEST).with(StairsBlock.WATERLOGGED, false).with(StairsBlock.SHAPE, StairsShape.STRAIGHT).with(StairsBlock.HALF, Half.BOTTOM), 19, 12, 16, start);
        structure.setBlockState(world, Blocks.STONE_BRICK_STAIRS.getDefaultState().with(StairsBlock.FACING, Direction.WEST).with(StairsBlock.WATERLOGGED, false).with(StairsBlock.SHAPE, StairsShape.STRAIGHT).with(StairsBlock.HALF, Half.BOTTOM), 19, 12, 21, start);
        structure.setBlockState(world, Blocks.CRACKED_STONE_BRICKS.getDefaultState(), 19, 12, 25, start);
        structure.setBlockState(world, Blocks.CRACKED_STONE_BRICKS.getDefaultState(), 19, 15, 12, start);
        structure.setBlockState(world, Blocks.STONE_BRICK_STAIRS.getDefaultState().with(StairsBlock.FACING, Direction.WEST).with(StairsBlock.WATERLOGGED, false).with(StairsBlock.SHAPE, StairsShape.STRAIGHT).with(StairsBlock.HALF, Half.TOP), 19, 15, 16, start);
        structure.setBlockState(world, Blocks.STONE_BRICK_STAIRS.getDefaultState().with(StairsBlock.FACING, Direction.WEST).with(StairsBlock.WATERLOGGED, false).with(StairsBlock.SHAPE, StairsShape.STRAIGHT).with(StairsBlock.HALF, Half.TOP), 19, 15, 21, start);
        structure.setBlockState(world, Blocks.COBBLESTONE.getDefaultState(), 19, 16, 20, start);
        structure.setBlockState(world, Blocks.STONE_BRICK_STAIRS.getDefaultState().with(StairsBlock.FACING, Direction.NORTH).with(StairsBlock.WATERLOGGED, false).with(StairsBlock.SHAPE, StairsShape.STRAIGHT).with(StairsBlock.HALF, Half.TOP), 19, 17, 27, start);
        structure.setBlockState(world, Blocks.STONE_BRICK_STAIRS.getDefaultState().with(StairsBlock.FACING, Direction.SOUTH).with(StairsBlock.WATERLOGGED, false).with(StairsBlock.SHAPE, StairsShape.STRAIGHT).with(StairsBlock.HALF, Half.BOTTOM), 19, 18, 10, start);
        structure.setBlockState(world, Blocks.STONE_BRICKS.getDefaultState(), 19, 18, 26, start);
        structure.setBlockState(world, Blocks.STONE_BRICK_STAIRS.getDefaultState().with(StairsBlock.FACING, Direction.NORTH).with(StairsBlock.WATERLOGGED, false).with(StairsBlock.SHAPE, StairsShape.STRAIGHT).with(StairsBlock.HALF, Half.BOTTOM), 19, 18, 27, start);
        structure.setBlockState(world, Blocks.STONE_BUTTON.getDefaultState().with(HorizontalBlock.HORIZONTAL_FACING, Direction.NORTH).with(HorizontalFaceBlock.FACE, AttachFace.WALL).with(AbstractButtonBlock.POWERED, false), 19, 19, 9, start);
        structure.setBlockState(world, Blocks.CHISELED_STONE_BRICKS.getDefaultState(), 19, 19, 10, start);
        structure.setBlockState(world, Blocks.SMOOTH_STONE_SLAB.getDefaultState().with(SlabBlock.TYPE, SlabType.BOTTOM).with(SlabBlock.WATERLOGGED, false), 19, 19, 11, start);
        structure.setBlockState(world, Blocks.GRAVEL.getDefaultState(), 19, 19, 21, start);
        structure.setBlockState(world, Blocks.CHISELED_STONE_BRICKS.getDefaultState(), 19, 19, 27, start);
        structure.setBlockState(world, Blocks.STONE_BUTTON.getDefaultState().with(HorizontalBlock.HORIZONTAL_FACING, Direction.SOUTH).with(HorizontalFaceBlock.FACE, AttachFace.WALL).with(AbstractButtonBlock.POWERED, false), 19, 19, 28, start);
        structure.setBlockState(world, Blocks.STONE_BRICK_SLAB.getDefaultState().with(SlabBlock.TYPE, SlabType.BOTTOM).with(SlabBlock.WATERLOGGED, false), 19, 20, 10, start);
        structure.setBlockState(world, Blocks.STONE_BRICK_STAIRS.getDefaultState().with(StairsBlock.FACING, Direction.SOUTH).with(StairsBlock.WATERLOGGED, false).with(StairsBlock.SHAPE, StairsShape.STRAIGHT).with(StairsBlock.HALF, Half.TOP), 19, 20, 14, start);
        structure.setBlockState(world, Blocks.COBBLESTONE.getDefaultState(), 19, 20, 15, start);
        structure.setBlockState(world, Blocks.STONE_BRICKS.getDefaultState(), 19, 20, 16, start);
        structure.setBlockState(world, Blocks.COBBLESTONE.getDefaultState(), 19, 20, 20, start);
        structure.setBlockState(world, Blocks.STONE_BRICK_STAIRS.getDefaultState().with(StairsBlock.FACING, Direction.NORTH).with(StairsBlock.WATERLOGGED, false).with(StairsBlock.SHAPE, StairsShape.STRAIGHT).with(StairsBlock.HALF, Half.BOTTOM), 19, 20, 21, start);
        structure.setBlockState(world, Blocks.STONE_BRICK_SLAB.getDefaultState().with(SlabBlock.TYPE, SlabType.BOTTOM).with(SlabBlock.WATERLOGGED, false), 19, 20, 27, start);
        structure.setBlockState(world, Blocks.STONE_STAIRS.getDefaultState().with(StairsBlock.FACING, Direction.SOUTH).with(StairsBlock.WATERLOGGED, false).with(StairsBlock.SHAPE, StairsShape.STRAIGHT).with(StairsBlock.HALF, Half.BOTTOM), 19, 21, 14, start);
        structure.setBlockState(world, Blocks.MOSSY_COBBLESTONE.getDefaultState(), 19, 21, 15, start);
        structure.setBlockState(world, Blocks.ANDESITE_STAIRS.getDefaultState().with(StairsBlock.FACING, Direction.NORTH).with(StairsBlock.WATERLOGGED, false).with(StairsBlock.SHAPE, StairsShape.STRAIGHT).with(StairsBlock.HALF, Half.BOTTOM), 19, 21, 18, start);
        structure.setBlockState(world, Blocks.STONE_BRICK_SLAB.getDefaultState().with(SlabBlock.TYPE, SlabType.BOTTOM).with(SlabBlock.WATERLOGGED, false), 19, 21, 19, start);
        structure.setBlockState(world, Blocks.ANDESITE_SLAB.getDefaultState().with(SlabBlock.TYPE, SlabType.BOTTOM).with(SlabBlock.WATERLOGGED, false), 19, 21, 20, start);
        structure.setBlockState(world, Blocks.STONE_STAIRS.getDefaultState().with(StairsBlock.FACING, Direction.SOUTH).with(StairsBlock.WATERLOGGED, false).with(StairsBlock.SHAPE, StairsShape.STRAIGHT).with(StairsBlock.HALF, Half.BOTTOM), 19, 22, 15, start);
        structure.setBlockState(world, Blocks.STONE.getDefaultState(), 19, 22, 17, start);
        structure.setBlockState(world, Blocks.STONE_STAIRS.getDefaultState().with(StairsBlock.FACING, Direction.SOUTH).with(StairsBlock.WATERLOGGED, false).with(StairsBlock.SHAPE, StairsShape.STRAIGHT).with(StairsBlock.HALF, Half.TOP), 19, 23, 15, start);
        structure.setBlockState(world, Blocks.ANDESITE.getDefaultState(), 19, 23, 17, start);
        structure.setBlockState(world, Blocks.STONE_BRICK_STAIRS.getDefaultState().with(StairsBlock.FACING, Direction.NORTH).with(StairsBlock.WATERLOGGED, false).with(StairsBlock.SHAPE, StairsShape.STRAIGHT).with(StairsBlock.HALF, Half.TOP), 19, 24, 18, start);
        structure.setBlockState(world, Blocks.STONE_BRICK_STAIRS.getDefaultState().with(StairsBlock.FACING, Direction.NORTH).with(StairsBlock.WATERLOGGED, false).with(StairsBlock.SHAPE, StairsShape.STRAIGHT).with(StairsBlock.HALF, Half.BOTTOM), 19, 25, 18, start);
        structure.setBlockState(world, Blocks.STONE_BRICK_STAIRS.getDefaultState().with(StairsBlock.FACING, Direction.NORTH).with(StairsBlock.WATERLOGGED, false).with(StairsBlock.SHAPE, StairsShape.STRAIGHT).with(StairsBlock.HALF, Half.TOP), 19, 26, 18, start);
        structure.setBlockState(world, Blocks.ANDESITE_STAIRS.getDefaultState().with(StairsBlock.FACING, Direction.SOUTH).with(StairsBlock.WATERLOGGED, false).with(StairsBlock.SHAPE, StairsShape.STRAIGHT).with(StairsBlock.HALF, Half.TOP), 19, 27, 14, start);
        structure.setBlockState(world, Blocks.STONE_BRICK_WALL.getDefaultState().with(WallBlock.WATERLOGGED, false).with(WallBlock.UP, true).with(WallBlock.WALL_HEIGHT_NORTH, WallHeight.LOW).with(WallBlock.WALL_HEIGHT_SOUTH, WallHeight.LOW).with(WallBlock.WALL_HEIGHT_EAST, WallHeight.LOW).with(WallBlock.WALL_HEIGHT_WEST, WallHeight.LOW), 19, 29, 13, start);
        structure.setBlockState(world, Blocks.STONE.getDefaultState(), 19, 31, 14, start);
        structure.setBlockState(world, Blocks.STONE_BRICK_STAIRS.getDefaultState().with(StairsBlock.FACING, Direction.NORTH).with(StairsBlock.WATERLOGGED, false).with(StairsBlock.SHAPE, StairsShape.STRAIGHT).with(StairsBlock.HALF, Half.TOP), 19, 31, 19, start);
        structure.setBlockState(world, Blocks.STONE_BRICK_SLAB.getDefaultState().with(SlabBlock.TYPE, SlabType.BOTTOM).with(SlabBlock.WATERLOGGED, false), 19, 32, 18, start);
        structure.setBlockState(world, Blocks.STONE_STAIRS.getDefaultState().with(StairsBlock.FACING, Direction.SOUTH).with(StairsBlock.WATERLOGGED, false).with(StairsBlock.SHAPE, StairsShape.STRAIGHT).with(StairsBlock.HALF, Half.BOTTOM), 19, 33, 15, start);
        structure.setBlockState(world, Blocks.STONE_STAIRS.getDefaultState().with(StairsBlock.FACING, Direction.NORTH).with(StairsBlock.WATERLOGGED, false).with(StairsBlock.SHAPE, StairsShape.STRAIGHT).with(StairsBlock.HALF, Half.TOP), 19, 33, 18, start);
        structure.setBlockState(world, Blocks.STONE_STAIRS.getDefaultState().with(StairsBlock.FACING, Direction.SOUTH).with(StairsBlock.WATERLOGGED, false).with(StairsBlock.SHAPE, StairsShape.STRAIGHT).with(StairsBlock.HALF, Half.TOP), 19, 34, 15, start);
        structure.setBlockState(world, Blocks.STONE_STAIRS.getDefaultState().with(StairsBlock.FACING, Direction.NORTH).with(StairsBlock.WATERLOGGED, false).with(StairsBlock.SHAPE, StairsShape.STRAIGHT).with(StairsBlock.HALF, Half.BOTTOM), 19, 34, 18, start);
        structure.setBlockState(world, Blocks.STONE_BRICK_SLAB.getDefaultState().with(SlabBlock.TYPE, SlabType.TOP).with(SlabBlock.WATERLOGGED, false), 19, 35, 14, start);
        structure.setBlockState(world, Blocks.STONE_BRICK_SLAB.getDefaultState().with(SlabBlock.TYPE, SlabType.TOP).with(SlabBlock.WATERLOGGED, false), 19, 35, 19, start);
        structure.setBlockState(world, Blocks.STONE_STAIRS.getDefaultState().with(StairsBlock.FACING, Direction.NORTH).with(StairsBlock.WATERLOGGED, false).with(StairsBlock.SHAPE, StairsShape.STRAIGHT).with(StairsBlock.HALF, Half.TOP), 19, 36, 18, start);
        structure.setBlockState(world, Blocks.STONE_BRICK_STAIRS.getDefaultState().with(StairsBlock.FACING, Direction.NORTH).with(StairsBlock.WATERLOGGED, false).with(StairsBlock.SHAPE, StairsShape.STRAIGHT).with(StairsBlock.HALF, Half.TOP), 19, 37, 19, start);
        structure.setBlockState(world, Blocks.STONE_BRICKS.getDefaultState(), 19, 38, 19, start);
        structure.setBlockState(world, Blocks.CRACKED_STONE_BRICKS.getDefaultState(), 19, 42, 13, start);
        structure.setBlockState(world, Blocks.ANDESITE_STAIRS.getDefaultState().with(StairsBlock.FACING, Direction.SOUTH).with(StairsBlock.WATERLOGGED, false).with(StairsBlock.SHAPE, StairsShape.STRAIGHT).with(StairsBlock.HALF, Half.TOP), 19, 42, 14, start);
        structure.setBlockState(world, Blocks.STONE_BRICK_STAIRS.getDefaultState().with(StairsBlock.FACING, Direction.WEST).with(StairsBlock.WATERLOGGED, false).with(StairsBlock.SHAPE, StairsShape.STRAIGHT).with(StairsBlock.HALF, Half.BOTTOM), 19, 42, 25, start);
