package mod.arcalitegames.odyssey.world.structure.town.saxontown;

import mod.arcalitegames.buildersaddition.Index;
import mod.arcalitegames.buildersaddition.blocks.BedsideTable;
import mod.arcalitegames.buildersaddition.blocks.Bookshelf;
import mod.arcalitegames.buildersaddition.blocks.Candle;
import mod.arcalitegames.buildersaddition.blocks.Counter;
import mod.arcalitegames.buildersaddition.blocks.Cupboard;
import mod.arcalitegames.buildersaddition.blocks.Hedge;
import mod.arcalitegames.buildersaddition.blocks.IronFence;
import mod.arcalitegames.buildersaddition.blocks.Pillar;
import mod.arcalitegames.buildersaddition.blocks.Sofa;
import mod.arcalitegames.buildersaddition.blocks.Stool;
import mod.arcalitegames.buildersaddition.blocks.SupportBracket;
import mod.arcalitegames.buildersaddition.blocks.Table;
import mod.arcalitegames.buildersaddition.state.HedgeState;
import mod.arcalitegames.buildersaddition.state.MountState;
import mod.arcalitegames.buildersaddition.state.PillarState;
import mod.arcalitegames.buildersaddition.state.SofaState;
import mod.arcalitegames.buildersaddition.state.StoolState;
import mod.arcalitegames.odyssey.blocks.ChairBlock;
import mod.arcalitegames.odyssey.blocks.ModBlocks;
import mod.arcalitegames.odyssey.blocks.ShopSignBlock;
import mod.arcalitegames.odyssey.world.structure.StructureBase;
import net.minecraft.block.AbstractFurnaceBlock;
import net.minecraft.block.AnvilBlock;
import net.minecraft.block.BarrelBlock;
import net.minecraft.block.BedBlock;
import net.minecraft.block.BeetrootBlock;
import net.minecraft.block.BellBlock;
import net.minecraft.block.Blocks;
import net.minecraft.block.CampfireBlock;
import net.minecraft.block.CauldronBlock;
import net.minecraft.block.ChainBlock;
import net.minecraft.block.ComposterBlock;
import net.minecraft.block.CropsBlock;
import net.minecraft.block.DoorBlock;
import net.minecraft.block.FarmlandBlock;
import net.minecraft.block.FenceGateBlock;
import net.minecraft.block.FourWayBlock;
import net.minecraft.block.HopperBlock;
import net.minecraft.block.HorizontalBlock;
import net.minecraft.block.LanternBlock;
import net.minecraft.block.RedstoneTorchBlock;
import net.minecraft.block.SaplingBlock;
import net.minecraft.block.SkullBlock;
import net.minecraft.block.SlabBlock;
import net.minecraft.block.SnowyDirtBlock;
import net.minecraft.block.StairsBlock;
import net.minecraft.block.StandingSignBlock;
import net.minecraft.block.StemBlock;
import net.minecraft.block.SweetBerryBushBlock;
import net.minecraft.block.TrapDoorBlock;
import net.minecraft.block.WallBannerBlock;
import net.minecraft.block.WallBlock;
import net.minecraft.block.WallHeight;
import net.minecraft.block.WallSignBlock;
import net.minecraft.state.properties.BedPart;
import net.minecraft.state.properties.BellAttachment;
import net.minecraft.state.properties.DoorHingeSide;
import net.minecraft.state.properties.DoubleBlockHalf;
import net.minecraft.state.properties.Half;
import net.minecraft.state.properties.SlabType;
import net.minecraft.state.properties.StairsShape;
import net.minecraft.util.Direction;
import net.minecraft.util.math.BlockPos;
import net.minecraft.world.World;

public class SaxonTownComponent0
{

	public static BlockPos start;
    public static World world;
    public static StructureBase structure;

    public static void init(World worldIn, BlockPos blockPos, StructureBase structureIn)
    {
        world = worldIn; start = blockPos; structure = structureIn;
    }
    
    public static void generatePart1()
    {
        structure.setBlockState(world, Blocks.DIORITE.getDefaultState(), -74, -7, 24, start);
        structure.setBlockState(world, Blocks.STONE.getDefaultState(), -72, -6, 35, start);
        structure.setBlockState(world, Blocks.GRASS_BLOCK.getDefaultState().with(SnowyDirtBlock.SNOWY, false), -72, -2, 43, start);
        structure.setBlockState(world, Blocks.COAL_ORE.getDefaultState(), -70, -6, -33, start);
        structure.setBlockState(world, Blocks.STONE.getDefaultState(), -70, -5, 44, start);
        structure.setBlockState(world, Blocks.IRON_ORE.getDefaultState(), -69, -7, -58, start);
        structure.setBlockState(world, Blocks.IRON_ORE.getDefaultState(), -69, -7, -25, start);
        structure.setBlockState(world, Blocks.GRAVEL.getDefaultState(), -69, -7, 15, start);
        structure.setBlockState(world, Blocks.COAL_ORE.getDefaultState(), -69, -7, 65, start);
        structure.setBlockState(world, Blocks.COAL_ORE.getDefaultState(), -69, -6, -25, start);
        structure.setBlockState(world, Blocks.STONE.getDefaultState(), -69, -6, 13, start);
        structure.setBlockState(world, Blocks.STONE.getDefaultState(), -69, -6, 18, start);
        structure.setBlockState(world, Blocks.STONE.getDefaultState(), -69, -6, 30, start);
        structure.setBlockState(world, Blocks.COAL_ORE.getDefaultState(), -69, -6, 31, start);
        structure.setBlockState(world, Blocks.IRON_ORE.getDefaultState(), -68, -7, -26, start);
        structure.setBlockState(world, Blocks.IRON_ORE.getDefaultState(), -68, -7, -13, start);
        structure.setBlockState(world, Blocks.GRASS_BLOCK.getDefaultState().with(SnowyDirtBlock.SNOWY, false), -68, -6, -69, start);
        structure.setBlockState(world, Blocks.COAL_ORE.getDefaultState(), -68, -6, 48, start);
        structure.setBlockState(world, Blocks.COAL_ORE.getDefaultState(), -67, -7, 24, start);
        structure.setBlockState(world, Blocks.GRASS_BLOCK.getDefaultState().with(SnowyDirtBlock.SNOWY, false), -67, -6, -70, start);
        structure.setBlockState(world, Blocks.STONE.getDefaultState(), -67, -6, -14, start);
        structure.setBlockState(world, Blocks.GRASS_BLOCK.getDefaultState().with(SnowyDirtBlock.SNOWY, false), -67, -5, -69, start);
        structure.setBlockState(world, Blocks.AZURE_BLUET.getDefaultState(), -67, 0, 43, start);
        structure.setBlockState(world, Blocks.GRASS_BLOCK.getDefaultState().with(SnowyDirtBlock.SNOWY, false), -66, -7, -72, start);
        structure.setBlockState(world, Blocks.COAL_ORE.getDefaultState(), -66, -7, -29, start);
        structure.setBlockState(world, Blocks.IRON_ORE.getDefaultState(), -66, -7, 57, start);
        structure.setBlockState(world, Blocks.WATER.getDefaultState(), -66, -6, -58, start);
        structure.setBlockState(world, Blocks.IRON_ORE.getDefaultState(), -66, -6, -18, start);
        structure.setBlockState(world, Blocks.GRANITE.getDefaultState(), -66, -6, 39, start);
        structure.setBlockState(world, Blocks.GRASS_BLOCK.getDefaultState().with(SnowyDirtBlock.SNOWY, false), -66, -4, -69, start);
        structure.setBlockState(world, Blocks.IRON_ORE.getDefaultState(), -65, -7, -58, start);
        structure.setBlockState(world, Blocks.GRANITE.getDefaultState(), -64, -7, 14, start);
        structure.setBlockState(world, Blocks.PINK_TULIP.getDefaultState(), -64, 0, 43, start);
        structure.setBlockState(world, Blocks.IRON_ORE.getDefaultState(), -63, -6, 61, start);
        structure.setBlockState(world, Blocks.STONE.getDefaultState(), -63, -5, -37, start);
        structure.setBlockState(world, Blocks.LILAC.getDefaultState(), -63, 0, -61, start);
        structure.setBlockState(world, Blocks.LILAC.getDefaultState(), -63, 0, -58, start);
        structure.setBlockState(world, Blocks.WHITE_TULIP.getDefaultState(), -63, 0, -10, start);
        structure.setBlockState(world, Blocks.SUNFLOWER.getDefaultState(), -63, 0, 44, start);
        structure.setBlockState(world, Blocks.LILAC.getDefaultState(), -63, 1, -61, start);
        structure.setBlockState(world, Blocks.LILAC.getDefaultState(), -63, 1, -58, start);
        structure.setBlockState(world, Blocks.SUNFLOWER.getDefaultState(), -63, 1, 44, start);
        structure.setBlockState(world, Blocks.GRANITE.getDefaultState(), -62, -6, -68, start);
        structure.setBlockState(world, Blocks.IRON_ORE.getDefaultState(), -62, -6, 60, start);
        structure.setBlockState(world, Blocks.COAL_ORE.getDefaultState(), -61, -7, -50, start);
        structure.setBlockState(world, Blocks.COAL_ORE.getDefaultState(), -61, -7, -17, start);
        structure.setBlockState(world, Blocks.COAL_ORE.getDefaultState(), -61, -7, 0, start);
        structure.setBlockState(world, Blocks.IRON_ORE.getDefaultState(), -61, -7, 20, start);
        structure.setBlockState(world, Blocks.GRANITE.getDefaultState(), -61, -6, -70, start);
        structure.setBlockState(world, Blocks.COAL_ORE.getDefaultState(), -61, -6, -49, start);
        structure.setBlockState(world, Blocks.STONE.getDefaultState(), -61, -6, -38, start);
        structure.setBlockState(world, Blocks.STONE.getDefaultState(), -61, -6, 26, start);
        structure.setBlockState(world, Blocks.LILAC.getDefaultState(), -61, 0, -62, start);
        structure.setBlockState(world, Blocks.PINK_TULIP.getDefaultState(), -61, 0, 8, start);
        structure.setBlockState(world, Blocks.LILAC.getDefaultState(), -61, 1, -62, start);
        structure.setBlockState(world, Blocks.STONE.getDefaultState(), -60, -7, -38, start);
        structure.setBlockState(world, Blocks.IRON_ORE.getDefaultState(), -60, -7, 19, start);
        structure.setBlockState(world, Blocks.STONE.getDefaultState(), -58, -5, -6, start);
        structure.setBlockState(world, Blocks.DIRT.getDefaultState(), -57, -7, 50, start);
        structure.setBlockState(world, Blocks.GRASS_BLOCK.getDefaultState().with(SnowyDirtBlock.SNOWY, false), -57, -4, 3, start);
        structure.setBlockState(world, Blocks.GRASS_BLOCK.getDefaultState().with(SnowyDirtBlock.SNOWY, false), -57, -4, 8, start);
        structure.setBlockState(world, Blocks.WATER.getDefaultState(), -57, -3, 1, start);
        structure.setBlockState(world, Blocks.WATER.getDefaultState(), -57, -3, 2, start);
        structure.setBlockState(world, Blocks.WATER.getDefaultState(), -57, -3, 3, start);
        structure.setBlockState(world, Blocks.WATER.getDefaultState(), -57, -3, 4, start);
        structure.setBlockState(world, Blocks.WATER.getDefaultState(), -57, -3, 9, start);
        structure.setBlockState(world, Blocks.STONE.getDefaultState(), -56, -7, 28, start);
        structure.setBlockState(world, Blocks.DIORITE.getDefaultState(), -56, -6, 25, start);
        structure.setBlockState(world, Blocks.GRASS_BLOCK.getDefaultState().with(SnowyDirtBlock.SNOWY, false), -56, -4, -2, start);
        structure.setBlockState(world, Blocks.WATER.getDefaultState(), -56, -3, -13, start);
        structure.setBlockState(world, Blocks.WATER.getDefaultState(), -56, -3, -12, start);
        structure.setBlockState(world, Blocks.WATER.getDefaultState(), -56, -3, -11, start);
        structure.setBlockState(world, Blocks.WATER.getDefaultState(), -56, -3, -10, start);
        structure.setBlockState(world, Blocks.WATER.getDefaultState(), -56, -3, -9, start);
        structure.setBlockState(world, Blocks.WATER.getDefaultState(), -56, -3, -8, start);
        structure.setBlockState(world, Blocks.WATER.getDefaultState(), -56, -3, -7, start);
        structure.setBlockState(world, Blocks.WATER.getDefaultState(), -56, -3, -6, start);
        structure.setBlockState(world, Blocks.WATER.getDefaultState(), -56, -3, -5, start);
        structure.setBlockState(world, Blocks.WATER.getDefaultState(), -56, -3, -4, start);
        structure.setBlockState(world, Blocks.WATER.getDefaultState(), -56, -3, -3, start);
        structure.setBlockState(world, Blocks.WATER.getDefaultState(), -56, -3, -2, start);
        structure.setBlockState(world, Blocks.WATER.getDefaultState(), -56, -3, -1, start);
        structure.setBlockState(world, Blocks.WATER.getDefaultState(), -56, -3, 0, start);
        structure.setBlockState(world, Blocks.WATER.getDefaultState(), -56, -3, 1, start);
        structure.setBlockState(world, Blocks.WATER.getDefaultState(), -56, -3, 2, start);
        structure.setBlockState(world, Blocks.WATER.getDefaultState(), -56, -3, 3, start);
        structure.setBlockState(world, Blocks.WATER.getDefaultState(), -56, -3, 4, start);
        structure.setBlockState(world, Blocks.WATER.getDefaultState(), -56, -3, 5, start);
        structure.setBlockState(world, Blocks.WATER.getDefaultState(), -56, -3, 6, start);
        structure.setBlockState(world, Blocks.WATER.getDefaultState(), -56, -3, 7, start);
        structure.setBlockState(world, Blocks.WATER.getDefaultState(), -56, -3, 9, start);
        structure.setBlockState(world, Blocks.WATER.getDefaultState(), -56, -3, 10, start);
        structure.setBlockState(world, Blocks.WATER.getDefaultState(), -56, -3, 11, start);
        structure.setBlockState(world, Blocks.WATER.getDefaultState(), -56, -3, 12, start);
        structure.setBlockState(world, Blocks.WATER.getDefaultState(), -56, -3, 18, start);
        structure.setBlockState(world, Blocks.COAL_ORE.getDefaultState(), -55, -7, -62, start);
        structure.setBlockState(world, Blocks.STONE.getDefaultState(), -55, -5, -52, start);
        structure.setBlockState(world, Blocks.STONE.getDefaultState(), -55, -5, -4, start);
        structure.setBlockState(world, Blocks.GRASS_BLOCK.getDefaultState().with(SnowyDirtBlock.SNOWY, false), -55, -4, 12, start);
        structure.setBlockState(world, Blocks.GRASS_BLOCK.getDefaultState().with(SnowyDirtBlock.SNOWY, false), -55, -4, 16, start);
        structure.setBlockState(world, Blocks.GRASS_BLOCK.getDefaultState().with(SnowyDirtBlock.SNOWY, false), -55, -4, 22, start);
        structure.setBlockState(world, Blocks.DIRT.getDefaultState(), -55, -3, -27, start);
        structure.setBlockState(world, Blocks.WATER.getDefaultState(), -55, -3, -12, start);
        structure.setBlockState(world, Blocks.WATER.getDefaultState(), -55, -3, -11, start);
        structure.setBlockState(world, Blocks.WATER.getDefaultState(), -55, -3, -10, start);
        structure.setBlockState(world, Blocks.WATER.getDefaultState(), -55, -3, -9, start);
        structure.setBlockState(world, Blocks.WATER.getDefaultState(), -55, -3, 9, start);
        structure.setBlockState(world, Blocks.WATER.getDefaultState(), -55, -3, 10, start);
        structure.setBlockState(world, Blocks.WATER.getDefaultState(), -55, -3, 11, start);
        structure.setBlockState(world, Blocks.WATER.getDefaultState(), -55, -3, 12, start);
        structure.setBlockState(world, Blocks.WATER.getDefaultState(), -55, -3, 13, start);
        structure.setBlockState(world, Blocks.WATER.getDefaultState(), -55, -3, 14, start);
        structure.setBlockState(world, Blocks.WATER.getDefaultState(), -55, -3, 15, start);
        structure.setBlockState(world, Blocks.WATER.getDefaultState(), -55, -3, 16, start);
        structure.setBlockState(world, Blocks.WATER.getDefaultState(), -55, -3, 17, start);
        structure.setBlockState(world, Blocks.WATER.getDefaultState(), -55, -3, 18, start);
        structure.setBlockState(world, Blocks.WATER.getDefaultState(), -55, -3, 19, start);
        structure.setBlockState(world, Blocks.WATER.getDefaultState(), -55, -3, 20, start);
        structure.setBlockState(world, Blocks.WATER.getDefaultState(), -55, -3, 26, start);
        structure.setBlockState(world, Blocks.DIRT.getDefaultState(), -55, -2, -40, start);
        structure.setBlockState(world, Blocks.GRASS_BLOCK.getDefaultState().with(SnowyDirtBlock.SNOWY, false), -55, -2, -27, start);
        structure.setBlockState(world, Blocks.GRASS_BLOCK.getDefaultState().with(SnowyDirtBlock.SNOWY, false), -55, -1, -40, start);
        structure.setBlockState(world, Blocks.DIRT.getDefaultState(), -54, -7, 46, start);
        structure.setBlockState(world, Blocks.STONE.getDefaultState(), -54, -6, -48, start);
        structure.setBlockState(world, Blocks.DIRT.getDefaultState(), -54, -4, -30, start);
        structure.setBlockState(world, Blocks.GRASS_BLOCK.getDefaultState().with(SnowyDirtBlock.SNOWY, false), -54, -4, 21, start);
        structure.setBlockState(world, Blocks.GRASS_BLOCK.getDefaultState().with(SnowyDirtBlock.SNOWY, false), -54, -4, 24, start);
        structure.setBlockState(world, Blocks.WATER.getDefaultState(), -54, -3, -30, start);
        structure.setBlockState(world, Blocks.WATER.getDefaultState(), -54, -3, -29, start);
        structure.setBlockState(world, Blocks.WATER.getDefaultState(), -54, -3, -26, start);
        structure.setBlockState(world, Blocks.WATER.getDefaultState(), -54, -3, -25, start);
        structure.setBlockState(world, Blocks.WATER.getDefaultState(), -54, -3, -24, start);
        structure.setBlockState(world, Blocks.WATER.getDefaultState(), -54, -3, -23, start);
        structure.setBlockState(world, Blocks.WATER.getDefaultState(), -54, -3, -22, start);
        structure.setBlockState(world, Blocks.WATER.getDefaultState(), -54, -3, -21, start);
        structure.setBlockState(world, Blocks.WATER.getDefaultState(), -54, -3, -20, start);
        structure.setBlockState(world, Blocks.WATER.getDefaultState(), -54, -3, -19, start);
        structure.setBlockState(world, Blocks.WATER.getDefaultState(), -54, -3, 19, start);
        structure.setBlockState(world, Blocks.WATER.getDefaultState(), -54, -3, 20, start);
        structure.setBlockState(world, Blocks.WATER.getDefaultState(), -54, -3, 23, start);
        structure.setBlockState(world, Blocks.WATER.getDefaultState(), -54, -3, 24, start);
        structure.setBlockState(world, Blocks.WATER.getDefaultState(), -54, -3, 25, start);
        structure.setBlockState(world, Blocks.WATER.getDefaultState(), -54, -3, 26, start);
        structure.setBlockState(world, Blocks.WATER.getDefaultState(), -54, -3, 27, start);
        structure.setBlockState(world, Blocks.WATER.getDefaultState(), -54, -3, 28, start);
        structure.setBlockState(world, Blocks.WATER.getDefaultState(), -54, -3, 29, start);
        structure.setBlockState(world, Blocks.WATER.getDefaultState(), -54, -3, 32, start);
        structure.setBlockState(world, Blocks.GRASS_BLOCK.getDefaultState().with(SnowyDirtBlock.SNOWY, false), -54, -2, -40, start);
        structure.setBlockState(world, Blocks.JUNGLE_FENCE_GATE.getDefaultState().with(FenceGateBlock.IN_WALL, false).with(FenceGateBlock.OPEN, false).with(FenceGateBlock.POWERED, false), -54, 0, -7, start);
        structure.setBlockState(world, Blocks.JUNGLE_FENCE_GATE.getDefaultState().with(FenceGateBlock.IN_WALL, false).with(FenceGateBlock.OPEN, false).with(FenceGateBlock.POWERED, false), -54, 0, -5, start);
        structure.setBlockState(world, Blocks.JUNGLE_FENCE_GATE.getDefaultState().with(FenceGateBlock.IN_WALL, false).with(FenceGateBlock.OPEN, false).with(FenceGateBlock.POWERED, false), -54, 0, -3, start);
        structure.setBlockState(world, Blocks.JUNGLE_FENCE_GATE.getDefaultState().with(FenceGateBlock.IN_WALL, false).with(FenceGateBlock.OPEN, false).with(FenceGateBlock.POWERED, false), -54, 0, -1, start);
        structure.setBlockState(world, Blocks.JUNGLE_FENCE_GATE.getDefaultState().with(FenceGateBlock.IN_WALL, false).with(FenceGateBlock.OPEN, false).with(FenceGateBlock.POWERED, false), -54, 0, 1, start);
        structure.setBlockState(world, Blocks.JUNGLE_FENCE_GATE.getDefaultState().with(FenceGateBlock.IN_WALL, false).with(FenceGateBlock.OPEN, false).with(FenceGateBlock.POWERED, false), -54, 0, 3, start);
        structure.setBlockState(world, Blocks.JUNGLE_FENCE_GATE.getDefaultState().with(FenceGateBlock.IN_WALL, false).with(FenceGateBlock.OPEN, false).with(FenceGateBlock.POWERED, false), -54, 0, 5, start);
        structure.setBlockState(world, Blocks.JUNGLE_FENCE_GATE.getDefaultState().with(FenceGateBlock.IN_WALL, false).with(FenceGateBlock.OPEN, false).with(FenceGateBlock.POWERED, false), -54, 0, 7, start);
        structure.setBlockState(world, Blocks.DIRT.getDefaultState(), -53, -7, 44, start);
        structure.setBlockState(world, Blocks.STONE.getDefaultState(), -53, -7, 74, start);
        structure.setBlockState(world, Blocks.STONE.getDefaultState(), -53, -6, -40, start);
        structure.setBlockState(world, Blocks.WATER.getDefaultState(), -53, -5, -4, start);
        structure.setBlockState(world, Blocks.DIRT.getDefaultState(), -53, -5, 74, start);
        structure.setBlockState(world, Blocks.GRASS_BLOCK.getDefaultState().with(SnowyDirtBlock.SNOWY, false), -53, -4, 29, start);
        structure.setBlockState(world, Blocks.DIRT.getDefaultState(), -53, -4, 35, start);
        structure.setBlockState(world, Blocks.GRASS_BLOCK.getDefaultState().with(SnowyDirtBlock.SNOWY, false), -53, -4, 74, start);
        structure.setBlockState(world, Blocks.DIRT.getDefaultState(), -53, -3, -41, start);
        structure.setBlockState(world, Blocks.GRASS_BLOCK.getDefaultState().with(SnowyDirtBlock.SNOWY, false), -53, -3, -40, start);
        structure.setBlockState(world, Blocks.WATER.getDefaultState(), -53, -3, -39, start);
        structure.setBlockState(world, Blocks.WATER.getDefaultState(), -53, -3, -38, start);
        structure.setBlockState(world, Blocks.WATER.getDefaultState(), -53, -3, -32, start);
        structure.setBlockState(world, Blocks.WATER.getDefaultState(), -53, -3, -31, start);
        structure.setBlockState(world, Blocks.WATER.getDefaultState(), -53, -3, -30, start);
        structure.setBlockState(world, Blocks.WATER.getDefaultState(), -53, -3, -29, start);
        structure.setBlockState(world, Blocks.WATER.getDefaultState(), -53, -3, -28, start);
        structure.setBlockState(world, Blocks.WATER.getDefaultState(), -53, -3, -27, start);
        structure.setBlockState(world, Blocks.WATER.getDefaultState(), -53, -3, -26, start);
        structure.setBlockState(world, Blocks.WATER.getDefaultState(), -53, -3, 27, start);
        structure.setBlockState(world, Blocks.WATER.getDefaultState(), -53, -3, 28, start);
        structure.setBlockState(world, Blocks.WATER.getDefaultState(), -53, -3, 31, start);
        structure.setBlockState(world, Blocks.WATER.getDefaultState(), -53, -3, 35, start);
        structure.setBlockState(world, Blocks.WATER.getDefaultState(), -53, -3, 36, start);
        structure.setBlockState(world, Blocks.GRASS_BLOCK.getDefaultState().with(SnowyDirtBlock.SNOWY, false), -53, -2, -41, start);
        structure.setBlockState(world, Blocks.JUNGLE_FENCE_GATE.getDefaultState().with(FenceGateBlock.IN_WALL, false).with(FenceGateBlock.OPEN, false).with(FenceGateBlock.POWERED, false), -53, 0, -17, start);
        structure.setBlockState(world, Blocks.JUNGLE_FENCE_GATE.getDefaultState().with(FenceGateBlock.IN_WALL, false).with(FenceGateBlock.OPEN, false).with(FenceGateBlock.POWERED, false), -53, 0, -15, start);
        structure.setBlockState(world, Blocks.JUNGLE_FENCE_GATE.getDefaultState().with(FenceGateBlock.IN_WALL, false).with(FenceGateBlock.OPEN, false).with(FenceGateBlock.POWERED, false), -53, 0, -13, start);
        structure.setBlockState(world, Blocks.JUNGLE_FENCE_GATE.getDefaultState().with(FenceGateBlock.IN_WALL, false).with(FenceGateBlock.OPEN, false).with(FenceGateBlock.POWERED, false), -53, 0, -11, start);
        structure.setBlockState(world, Blocks.JUNGLE_FENCE_GATE.getDefaultState().with(FenceGateBlock.IN_WALL, false).with(FenceGateBlock.OPEN, false).with(FenceGateBlock.POWERED, false), -53, 0, -9, start);
        structure.setBlockState(world, Blocks.JUNGLE_FENCE_GATE.getDefaultState().with(FenceGateBlock.IN_WALL, false).with(FenceGateBlock.OPEN, false).with(FenceGateBlock.POWERED, false), -53, 0, 9, start);
        structure.setBlockState(world, Blocks.JUNGLE_FENCE_GATE.getDefaultState().with(FenceGateBlock.IN_WALL, false).with(FenceGateBlock.OPEN, false).with(FenceGateBlock.POWERED, false), -53, 0, 11, start);
        structure.setBlockState(world, Blocks.JUNGLE_FENCE_GATE.getDefaultState().with(FenceGateBlock.IN_WALL, false).with(FenceGateBlock.OPEN, false).with(FenceGateBlock.POWERED, false), -53, 0, 13, start);
        structure.setBlockState(world, Blocks.JUNGLE_FENCE_GATE.getDefaultState().with(FenceGateBlock.IN_WALL, false).with(FenceGateBlock.OPEN, false).with(FenceGateBlock.POWERED, false), -53, 0, 15, start);
        structure.setBlockState(world, Blocks.JUNGLE_FENCE_GATE.getDefaultState().with(FenceGateBlock.IN_WALL, false).with(FenceGateBlock.OPEN, false).with(FenceGateBlock.POWERED, false), -53, 0, 17, start);
        structure.setBlockState(world, Blocks.JUNGLE_FENCE_GATE.getDefaultState().with(FenceGateBlock.IN_WALL, false).with(FenceGateBlock.OPEN, false).with(FenceGateBlock.POWERED, false), -53, 1, -8, start);
        structure.setBlockState(world, Blocks.JUNGLE_FENCE_GATE.getDefaultState().with(FenceGateBlock.IN_WALL, false).with(FenceGateBlock.OPEN, false).with(FenceGateBlock.POWERED, false), -53, 1, -6, start);
        structure.setBlockState(world, Blocks.JUNGLE_FENCE_GATE.getDefaultState().with(FenceGateBlock.IN_WALL, false).with(FenceGateBlock.OPEN, false).with(FenceGateBlock.POWERED, false), -53, 1, -4, start);
        structure.setBlockState(world, Blocks.JUNGLE_FENCE_GATE.getDefaultState().with(FenceGateBlock.IN_WALL, false).with(FenceGateBlock.OPEN, false).with(FenceGateBlock.POWERED, false), -53, 1, -2, start);
        structure.setBlockState(world, Blocks.JUNGLE_FENCE_GATE.getDefaultState().with(FenceGateBlock.IN_WALL, false).with(FenceGateBlock.OPEN, false).with(FenceGateBlock.POWERED, false), -53, 1, 0, start);
        structure.setBlockState(world, Blocks.JUNGLE_FENCE_GATE.getDefaultState().with(FenceGateBlock.IN_WALL, false).with(FenceGateBlock.OPEN, false).with(FenceGateBlock.POWERED, false), -53, 1, 2, start);
        structure.setBlockState(world, Blocks.JUNGLE_FENCE_GATE.getDefaultState().with(FenceGateBlock.IN_WALL, false).with(FenceGateBlock.OPEN, false).with(FenceGateBlock.POWERED, false), -53, 1, 4, start);
        structure.setBlockState(world, Blocks.JUNGLE_FENCE_GATE.getDefaultState().with(FenceGateBlock.IN_WALL, false).with(FenceGateBlock.OPEN, false).with(FenceGateBlock.POWERED, false), -53, 1, 6, start);
        structure.setBlockState(world, Blocks.JUNGLE_FENCE_GATE.getDefaultState().with(FenceGateBlock.IN_WALL, false).with(FenceGateBlock.OPEN, false).with(FenceGateBlock.POWERED, false), -53, 1, 8, start);
        structure.setBlockState(world, Blocks.COAL_ORE.getDefaultState(), -52, -7, 56, start);
        structure.setBlockState(world, Blocks.COAL_ORE.getDefaultState(), -52, -6, -30, start);
        structure.setBlockState(world, Blocks.WATER.getDefaultState(), -52, -6, 51, start);
        structure.setBlockState(world, Blocks.GRASS_BLOCK.getDefaultState().with(SnowyDirtBlock.SNOWY, false), -52, -4, 33, start);
        structure.setBlockState(world, Blocks.GRASS_BLOCK.getDefaultState().with(SnowyDirtBlock.SNOWY, false), -52, -3, -41, start);
        structure.setBlockState(world, Blocks.WATER.getDefaultState(), -52, -3, -39, start);
        structure.setBlockState(world, Blocks.WATER.getDefaultState(), -52, -3, -38, start);
        structure.setBlockState(world, Blocks.WATER.getDefaultState(), -52, -3, -37, start);
        structure.setBlockState(world, Blocks.WATER.getDefaultState(), -52, -3, -36, start);
        structure.setBlockState(world, Blocks.WATER.getDefaultState(), -52, -3, -35, start);
        structure.setBlockState(world, Blocks.WATER.getDefaultState(), -52, -3, -34, start);
        structure.setBlockState(world, Blocks.WATER.getDefaultState(), -52, -3, -33, start);
        structure.setBlockState(world, Blocks.WATER.getDefaultState(), -52, -3, 33, start);
        structure.setBlockState(world, Blocks.WATER.getDefaultState(), -52, -3, 34, start);
        structure.setBlockState(world, Blocks.WATER.getDefaultState(), -52, -3, 35, start);
        structure.setBlockState(world, Blocks.WATER.getDefaultState(), -52, -3, 36, start);
        structure.setBlockState(world, Blocks.WATER.getDefaultState(), -52, -3, 37, start);
        structure.setBlockState(world, Blocks.DIRT.getDefaultState(), -52, -2, -43, start);
        structure.setBlockState(world, Blocks.GRASS_BLOCK.getDefaultState().with(SnowyDirtBlock.SNOWY, false), -52, -2, -42, start);
        structure.setBlockState(world, Blocks.GRASS_BLOCK.getDefaultState().with(SnowyDirtBlock.SNOWY, false), -52, -1, -43, start);
        structure.setBlockState(world, Blocks.OAK_LOG.getDefaultState(), -52, -1, -7, start);
        structure.setBlockState(world, Blocks.JUNGLE_FENCE_GATE.getDefaultState().with(FenceGateBlock.IN_WALL, false).with(FenceGateBlock.OPEN, false).with(FenceGateBlock.POWERED, false), -52, 0, -25, start);
        structure.setBlockState(world, Blocks.JUNGLE_FENCE_GATE.getDefaultState().with(FenceGateBlock.IN_WALL, false).with(FenceGateBlock.OPEN, false).with(FenceGateBlock.POWERED, false), -52, 0, -23, start);
        structure.setBlockState(world, Blocks.JUNGLE_FENCE_GATE.getDefaultState().with(FenceGateBlock.IN_WALL, false).with(FenceGateBlock.OPEN, false).with(FenceGateBlock.POWERED, false), -52, 0, 19, start);
        structure.setBlockState(world, Blocks.JUNGLE_FENCE_GATE.getDefaultState().with(FenceGateBlock.IN_WALL, false).with(FenceGateBlock.OPEN, false).with(FenceGateBlock.POWERED, false), -52, 0, 21, start);
        structure.setBlockState(world, Blocks.JUNGLE_FENCE_GATE.getDefaultState().with(FenceGateBlock.IN_WALL, false).with(FenceGateBlock.OPEN, false).with(FenceGateBlock.POWERED, false), -52, 0, 23, start);
        structure.setBlockState(world, Blocks.JUNGLE_FENCE_GATE.getDefaultState().with(FenceGateBlock.IN_WALL, false).with(FenceGateBlock.OPEN, false).with(FenceGateBlock.POWERED, false), -52, 0, 25, start);
        structure.setBlockState(world, Blocks.JUNGLE_FENCE_GATE.getDefaultState().with(FenceGateBlock.IN_WALL, false).with(FenceGateBlock.OPEN, false).with(FenceGateBlock.POWERED, false), -52, 1, -18, start);
        structure.setBlockState(world, Blocks.JUNGLE_FENCE_GATE.getDefaultState().with(FenceGateBlock.IN_WALL, false).with(FenceGateBlock.OPEN, false).with(FenceGateBlock.POWERED, false), -52, 1, -16, start);
        structure.setBlockState(world, Blocks.JUNGLE_FENCE_GATE.getDefaultState().with(FenceGateBlock.IN_WALL, false).with(FenceGateBlock.OPEN, false).with(FenceGateBlock.POWERED, false), -52, 1, -14, start);
        structure.setBlockState(world, Blocks.JUNGLE_FENCE_GATE.getDefaultState().with(FenceGateBlock.IN_WALL, false).with(FenceGateBlock.OPEN, false).with(FenceGateBlock.POWERED, false), -52, 1, -12, start);
        structure.setBlockState(world, Blocks.JUNGLE_FENCE_GATE.getDefaultState().with(FenceGateBlock.IN_WALL, false).with(FenceGateBlock.OPEN, false).with(FenceGateBlock.POWERED, false), -52, 1, -10, start);
        structure.setBlockState(world, Blocks.JUNGLE_FENCE_GATE.getDefaultState().with(FenceGateBlock.IN_WALL, false).with(FenceGateBlock.OPEN, false).with(FenceGateBlock.POWERED, false), -52, 1, 10, start);
        structure.setBlockState(world, Blocks.JUNGLE_FENCE_GATE.getDefaultState().with(FenceGateBlock.IN_WALL, false).with(FenceGateBlock.OPEN, false).with(FenceGateBlock.POWERED, false), -52, 1, 12, start);
        structure.setBlockState(world, Blocks.JUNGLE_FENCE_GATE.getDefaultState().with(FenceGateBlock.IN_WALL, false).with(FenceGateBlock.OPEN, false).with(FenceGateBlock.POWERED, false), -52, 1, 14, start);
        structure.setBlockState(world, Blocks.JUNGLE_FENCE_GATE.getDefaultState().with(FenceGateBlock.IN_WALL, false).with(FenceGateBlock.OPEN, false).with(FenceGateBlock.POWERED, false), -52, 1, 16, start);
        structure.setBlockState(world, Blocks.JUNGLE_FENCE_GATE.getDefaultState().with(FenceGateBlock.IN_WALL, false).with(FenceGateBlock.OPEN, false).with(FenceGateBlock.POWERED, false), -52, 1, 18, start);
        structure.setBlockState(world, Blocks.SPRUCE_SLAB.getDefaultState().with(SlabBlock.TYPE, SlabType.BOTTOM).with(SlabBlock.WATERLOGGED, false), -52, 3, -8, start);
        structure.setBlockState(world, Blocks.SPRUCE_TRAPDOOR.getDefaultState().with(HorizontalBlock.HORIZONTAL_FACING, Direction.EAST).with(TrapDoorBlock.HALF, Half.BOTTOM).with(TrapDoorBlock.WATERLOGGED, false).with(TrapDoorBlock.POWERED, false).with(TrapDoorBlock.OPEN, false), -52, 3, -7, start);
        structure.setBlockState(world, Blocks.SPRUCE_SLAB.getDefaultState().with(SlabBlock.TYPE, SlabType.BOTTOM).with(SlabBlock.WATERLOGGED, false), -52, 3, -6, start);
        structure.setBlockState(world, Blocks.SPRUCE_TRAPDOOR.getDefaultState().with(HorizontalBlock.HORIZONTAL_FACING, Direction.EAST).with(TrapDoorBlock.HALF, Half.BOTTOM).with(TrapDoorBlock.WATERLOGGED, false).with(TrapDoorBlock.POWERED, false).with(TrapDoorBlock.OPEN, false), -52, 3, -5, start);
        structure.setBlockState(world, Blocks.SPRUCE_SLAB.getDefaultState().with(SlabBlock.TYPE, SlabType.BOTTOM).with(SlabBlock.WATERLOGGED, false), -52, 3, -4, start);
        structure.setBlockState(world, Blocks.SPRUCE_TRAPDOOR.getDefaultState().with(HorizontalBlock.HORIZONTAL_FACING, Direction.EAST).with(TrapDoorBlock.HALF, Half.BOTTOM).with(TrapDoorBlock.WATERLOGGED, false).with(TrapDoorBlock.POWERED, false).with(TrapDoorBlock.OPEN, false), -52, 3, -3, start);
        structure.setBlockState(world, Blocks.SPRUCE_SLAB.getDefaultState().with(SlabBlock.TYPE, SlabType.BOTTOM).with(SlabBlock.WATERLOGGED, false), -52, 3, -2, start);
        structure.setBlockState(world, Blocks.SPRUCE_TRAPDOOR.getDefaultState().with(HorizontalBlock.HORIZONTAL_FACING, Direction.EAST).with(TrapDoorBlock.HALF, Half.BOTTOM).with(TrapDoorBlock.WATERLOGGED, false).with(TrapDoorBlock.POWERED, false).with(TrapDoorBlock.OPEN, false), -52, 3, -1, start);
        structure.setBlockState(world, Blocks.SPRUCE_SLAB.getDefaultState().with(SlabBlock.TYPE, SlabType.BOTTOM).with(SlabBlock.WATERLOGGED, false), -52, 3, 0, start);
        structure.setBlockState(world, Blocks.SPRUCE_TRAPDOOR.getDefaultState().with(HorizontalBlock.HORIZONTAL_FACING, Direction.EAST).with(TrapDoorBlock.HALF, Half.BOTTOM).with(TrapDoorBlock.WATERLOGGED, false).with(TrapDoorBlock.POWERED, false).with(TrapDoorBlock.OPEN, false), -52, 3, 1, start);
        structure.setBlockState(world, Blocks.SPRUCE_SLAB.getDefaultState().with(SlabBlock.TYPE, SlabType.BOTTOM).with(SlabBlock.WATERLOGGED, false), -52, 3, 2, start);
        structure.setBlockState(world, Blocks.SPRUCE_TRAPDOOR.getDefaultState().with(HorizontalBlock.HORIZONTAL_FACING, Direction.EAST).with(TrapDoorBlock.HALF, Half.BOTTOM).with(TrapDoorBlock.WATERLOGGED, false).with(TrapDoorBlock.POWERED, false).with(TrapDoorBlock.OPEN, false), -52, 3, 3, start);
        structure.setBlockState(world, Blocks.SPRUCE_SLAB.getDefaultState().with(SlabBlock.TYPE, SlabType.BOTTOM).with(SlabBlock.WATERLOGGED, false), -52, 3, 4, start);
        structure.setBlockState(world, Blocks.SPRUCE_TRAPDOOR.getDefaultState().with(HorizontalBlock.HORIZONTAL_FACING, Direction.EAST).with(TrapDoorBlock.HALF, Half.BOTTOM).with(TrapDoorBlock.WATERLOGGED, false).with(TrapDoorBlock.POWERED, false).with(TrapDoorBlock.OPEN, false), -52, 3, 5, start);
        structure.setBlockState(world, Blocks.SPRUCE_SLAB.getDefaultState().with(SlabBlock.TYPE, SlabType.BOTTOM).with(SlabBlock.WATERLOGGED, false), -52, 3, 6, start);
        structure.setBlockState(world, Blocks.SPRUCE_TRAPDOOR.getDefaultState().with(HorizontalBlock.HORIZONTAL_FACING, Direction.EAST).with(TrapDoorBlock.HALF, Half.BOTTOM).with(TrapDoorBlock.WATERLOGGED, false).with(TrapDoorBlock.POWERED, false).with(TrapDoorBlock.OPEN, false), -52, 3, 7, start);
        structure.setBlockState(world, Blocks.SPRUCE_SLAB.getDefaultState().with(SlabBlock.TYPE, SlabType.BOTTOM).with(SlabBlock.WATERLOGGED, false), -52, 3, 8, start);
        structure.setBlockState(world, Blocks.GRANITE.getDefaultState(), -51, -7, -31, start);
        structure.setBlockState(world, Blocks.COAL_ORE.getDefaultState(), -51, -7, -30, start);
        structure.setBlockState(world, Blocks.DIRT.getDefaultState(), -51, -7, -12, start);
        structure.setBlockState(world, Blocks.DIORITE.getDefaultState(), -51, -6, -59, start);
        structure.setBlockState(world, Blocks.IRON_ORE.getDefaultState(), -51, -6, -58, start);
        structure.setBlockState(world, Blocks.ANDESITE.getDefaultState(), -51, -6, -42, start);
        structure.setBlockState(world, Blocks.GRASS_BLOCK.getDefaultState().with(SnowyDirtBlock.SNOWY, false), -51, -3, -42, start);
        structure.setBlockState(world, Blocks.WATER.getDefaultState(), -51, -3, -40, start);
        structure.setBlockState(world, Blocks.WATER.getDefaultState(), -51, -3, -39, start);
        structure.setBlockState(world, Blocks.WATER.getDefaultState(), -51, -3, 39, start);
        structure.setBlockState(world, Blocks.WATER.getDefaultState(), -51, -3, 40, start);
        structure.setBlockState(world, Blocks.GRASS_BLOCK.getDefaultState().with(SnowyDirtBlock.SNOWY, false), -51, -2, -43, start);
        structure.setBlockState(world, Blocks.JUNGLE_FENCE_GATE.getDefaultState().with(FenceGateBlock.IN_WALL, false).with(FenceGateBlock.OPEN, false).with(FenceGateBlock.POWERED, false), -51, 0, -32, start);
        structure.setBlockState(world, Blocks.JUNGLE_FENCE_GATE.getDefaultState().with(FenceGateBlock.IN_WALL, false).with(FenceGateBlock.OPEN, false).with(FenceGateBlock.POWERED, false), -51, 0, -30, start);
        structure.setBlockState(world, Blocks.JUNGLE_FENCE_GATE.getDefaultState().with(FenceGateBlock.IN_WALL, false).with(FenceGateBlock.OPEN, false).with(FenceGateBlock.POWERED, false), -51, 0, -28, start);
        structure.setBlockState(world, Blocks.JUNGLE_FENCE_GATE.getDefaultState().with(FenceGateBlock.IN_WALL, false).with(FenceGateBlock.OPEN, false).with(FenceGateBlock.POWERED, false), -51, 0, 27, start);
        structure.setBlockState(world, Blocks.JUNGLE_FENCE_GATE.getDefaultState().with(FenceGateBlock.IN_WALL, false).with(FenceGateBlock.OPEN, false).with(FenceGateBlock.POWERED, false), -51, 0, 29, start);
        structure.setBlockState(world, Blocks.JUNGLE_FENCE_GATE.getDefaultState().with(FenceGateBlock.IN_WALL, false).with(FenceGateBlock.OPEN, false).with(FenceGateBlock.POWERED, false), -51, 0, 31, start);
        structure.setBlockState(world, Blocks.JUNGLE_FENCE_GATE.getDefaultState().with(FenceGateBlock.IN_WALL, false).with(FenceGateBlock.OPEN, false).with(FenceGateBlock.POWERED, false), -51, 1, -26, start);
        structure.setBlockState(world, Blocks.JUNGLE_FENCE_GATE.getDefaultState().with(FenceGateBlock.IN_WALL, false).with(FenceGateBlock.OPEN, false).with(FenceGateBlock.POWERED, false), -51, 1, -24, start);
        structure.setBlockState(world, Blocks.JUNGLE_FENCE_GATE.getDefaultState().with(FenceGateBlock.IN_WALL, false).with(FenceGateBlock.OPEN, false).with(FenceGateBlock.POWERED, false), -51, 1, -22, start);
        structure.setBlockState(world, Blocks.JUNGLE_FENCE_GATE.getDefaultState().with(FenceGateBlock.IN_WALL, false).with(FenceGateBlock.OPEN, false).with(FenceGateBlock.POWERED, false), -51, 1, -20, start);
        structure.setBlockState(world, Blocks.JUNGLE_FENCE_GATE.getDefaultState().with(FenceGateBlock.IN_WALL, false).with(FenceGateBlock.OPEN, false).with(FenceGateBlock.POWERED, false), -51, 1, 20, start);
        structure.setBlockState(world, Blocks.JUNGLE_FENCE_GATE.getDefaultState().with(FenceGateBlock.IN_WALL, false).with(FenceGateBlock.OPEN, false).with(FenceGateBlock.POWERED, false), -51, 1, 22, start);
        structure.setBlockState(world, Blocks.JUNGLE_FENCE_GATE.getDefaultState().with(FenceGateBlock.IN_WALL, false).with(FenceGateBlock.OPEN, false).with(FenceGateBlock.POWERED, false), -51, 1, 24, start);
        structure.setBlockState(world, Blocks.JUNGLE_FENCE_GATE.getDefaultState().with(FenceGateBlock.IN_WALL, false).with(FenceGateBlock.OPEN, false).with(FenceGateBlock.POWERED, false), -51, 1, 26, start);
        structure.setBlockState(world, Blocks.SPRUCE_SLAB.getDefaultState().with(SlabBlock.TYPE, SlabType.BOTTOM).with(SlabBlock.WATERLOGGED, false), -51, 3, -18, start);
        structure.setBlockState(world, Blocks.SPRUCE_TRAPDOOR.getDefaultState().with(HorizontalBlock.HORIZONTAL_FACING, Direction.EAST).with(TrapDoorBlock.HALF, Half.BOTTOM).with(TrapDoorBlock.WATERLOGGED, false).with(TrapDoorBlock.POWERED, false).with(TrapDoorBlock.OPEN, false), -51, 3, -17, start);
        structure.setBlockState(world, Blocks.SPRUCE_SLAB.getDefaultState().with(SlabBlock.TYPE, SlabType.BOTTOM).with(SlabBlock.WATERLOGGED, false), -51, 3, -16, start);
        structure.setBlockState(world, Blocks.SPRUCE_TRAPDOOR.getDefaultState().with(HorizontalBlock.HORIZONTAL_FACING, Direction.EAST).with(TrapDoorBlock.HALF, Half.BOTTOM).with(TrapDoorBlock.WATERLOGGED, false).with(TrapDoorBlock.POWERED, false).with(TrapDoorBlock.OPEN, false), -51, 3, -15, start);
        structure.setBlockState(world, Blocks.SPRUCE_SLAB.getDefaultState().with(SlabBlock.TYPE, SlabType.BOTTOM).with(SlabBlock.WATERLOGGED, false), -51, 3, -14, start);
        structure.setBlockState(world, Blocks.SPRUCE_TRAPDOOR.getDefaultState().with(HorizontalBlock.HORIZONTAL_FACING, Direction.EAST).with(TrapDoorBlock.HALF, Half.BOTTOM).with(TrapDoorBlock.WATERLOGGED, false).with(TrapDoorBlock.POWERED, false).with(TrapDoorBlock.OPEN, false), -51, 3, -13, start);
        structure.setBlockState(world, Blocks.SPRUCE_SLAB.getDefaultState().with(SlabBlock.TYPE, SlabType.BOTTOM).with(SlabBlock.WATERLOGGED, false), -51, 3, -12, start);
        structure.setBlockState(world, Blocks.SPRUCE_TRAPDOOR.getDefaultState().with(HorizontalBlock.HORIZONTAL_FACING, Direction.EAST).with(TrapDoorBlock.HALF, Half.BOTTOM).with(TrapDoorBlock.WATERLOGGED, false).with(TrapDoorBlock.POWERED, false).with(TrapDoorBlock.OPEN, false), -51, 3, -11, start);
        structure.setBlockState(world, Blocks.SPRUCE_SLAB.getDefaultState().with(SlabBlock.TYPE, SlabType.BOTTOM).with(SlabBlock.WATERLOGGED, false), -51, 3, -10, start);
        structure.setBlockState(world, Blocks.SPRUCE_TRAPDOOR.getDefaultState().with(HorizontalBlock.HORIZONTAL_FACING, Direction.EAST).with(TrapDoorBlock.HALF, Half.BOTTOM).with(TrapDoorBlock.WATERLOGGED, false).with(TrapDoorBlock.POWERED, false).with(TrapDoorBlock.OPEN, false), -51, 3, -9, start);
        structure.setBlockState(world, Blocks.OAK_LOG.getDefaultState(), -51, 3, -8, start);
        structure.setBlockState(world, Blocks.OAK_LOG.getDefaultState(), -51, 3, 8, start);
        structure.setBlockState(world, Blocks.SPRUCE_TRAPDOOR.getDefaultState().with(HorizontalBlock.HORIZONTAL_FACING, Direction.EAST).with(TrapDoorBlock.HALF, Half.BOTTOM).with(TrapDoorBlock.WATERLOGGED, false).with(TrapDoorBlock.POWERED, false).with(TrapDoorBlock.OPEN, false), -51, 3, 9, start);
        structure.setBlockState(world, Blocks.SPRUCE_SLAB.getDefaultState().with(SlabBlock.TYPE, SlabType.BOTTOM).with(SlabBlock.WATERLOGGED, false), -51, 3, 10, start);
        structure.setBlockState(world, Blocks.SPRUCE_TRAPDOOR.getDefaultState().with(HorizontalBlock.HORIZONTAL_FACING, Direction.EAST).with(TrapDoorBlock.HALF, Half.BOTTOM).with(TrapDoorBlock.WATERLOGGED, false).with(TrapDoorBlock.POWERED, false).with(TrapDoorBlock.OPEN, false), -51, 3, 11, start);
        structure.setBlockState(world, Blocks.SPRUCE_SLAB.getDefaultState().with(SlabBlock.TYPE, SlabType.BOTTOM).with(SlabBlock.WATERLOGGED, false), -51, 3, 12, start);
        structure.setBlockState(world, Blocks.SPRUCE_TRAPDOOR.getDefaultState().with(HorizontalBlock.HORIZONTAL_FACING, Direction.EAST).with(TrapDoorBlock.HALF, Half.BOTTOM).with(TrapDoorBlock.WATERLOGGED, false).with(TrapDoorBlock.POWERED, false).with(TrapDoorBlock.OPEN, false), -51, 3, 13, start);
        structure.setBlockState(world, Blocks.SPRUCE_SLAB.getDefaultState().with(SlabBlock.TYPE, SlabType.BOTTOM).with(SlabBlock.WATERLOGGED, false), -51, 3, 14, start);
        structure.setBlockState(world, Blocks.SPRUCE_TRAPDOOR.getDefaultState().with(HorizontalBlock.HORIZONTAL_FACING, Direction.EAST).with(TrapDoorBlock.HALF, Half.BOTTOM).with(TrapDoorBlock.WATERLOGGED, false).with(TrapDoorBlock.POWERED, false).with(TrapDoorBlock.OPEN, false), -51, 3, 15, start);
        structure.setBlockState(world, Blocks.SPRUCE_SLAB.getDefaultState().with(SlabBlock.TYPE, SlabType.BOTTOM).with(SlabBlock.WATERLOGGED, false), -51, 3, 16, start);
        structure.setBlockState(world, Blocks.SPRUCE_TRAPDOOR.getDefaultState().with(HorizontalBlock.HORIZONTAL_FACING, Direction.EAST).with(TrapDoorBlock.HALF, Half.BOTTOM).with(TrapDoorBlock.WATERLOGGED, false).with(TrapDoorBlock.POWERED, false).with(TrapDoorBlock.OPEN, false), -51, 3, 17, start);
        structure.setBlockState(world, Blocks.SPRUCE_SLAB.getDefaultState().with(SlabBlock.TYPE, SlabType.BOTTOM).with(SlabBlock.WATERLOGGED, false), -51, 3, 18, start);
        structure.setBlockState(world, Blocks.SPRUCE_TRAPDOOR.getDefaultState().with(HorizontalBlock.HORIZONTAL_FACING, Direction.EAST).with(TrapDoorBlock.HALF, Half.BOTTOM).with(TrapDoorBlock.WATERLOGGED, false).with(TrapDoorBlock.POWERED, false).with(TrapDoorBlock.OPEN, false), -51, 4, -8, start);
        structure.setBlockState(world, Blocks.SPRUCE_SLAB.getDefaultState().with(SlabBlock.TYPE, SlabType.BOTTOM).with(SlabBlock.WATERLOGGED, false), -51, 4, -7, start);
        structure.setBlockState(world, Blocks.SPRUCE_TRAPDOOR.getDefaultState().with(HorizontalBlock.HORIZONTAL_FACING, Direction.EAST).with(TrapDoorBlock.HALF, Half.BOTTOM).with(TrapDoorBlock.WATERLOGGED, false).with(TrapDoorBlock.POWERED, false).with(TrapDoorBlock.OPEN, false), -51, 4, -6, start);
        structure.setBlockState(world, Blocks.SPRUCE_SLAB.getDefaultState().with(SlabBlock.TYPE, SlabType.BOTTOM).with(SlabBlock.WATERLOGGED, false), -51, 4, -5, start);
        structure.setBlockState(world, Blocks.SPRUCE_TRAPDOOR.getDefaultState().with(HorizontalBlock.HORIZONTAL_FACING, Direction.EAST).with(TrapDoorBlock.HALF, Half.BOTTOM).with(TrapDoorBlock.WATERLOGGED, false).with(TrapDoorBlock.POWERED, false).with(TrapDoorBlock.OPEN, false), -51, 4, -4, start);
        structure.setBlockState(world, Blocks.SPRUCE_SLAB.getDefaultState().with(SlabBlock.TYPE, SlabType.BOTTOM).with(SlabBlock.WATERLOGGED, false), -51, 4, -3, start);
        structure.setBlockState(world, Blocks.SPRUCE_TRAPDOOR.getDefaultState().with(HorizontalBlock.HORIZONTAL_FACING, Direction.EAST).with(TrapDoorBlock.HALF, Half.BOTTOM).with(TrapDoorBlock.WATERLOGGED, false).with(TrapDoorBlock.POWERED, false).with(TrapDoorBlock.OPEN, false), -51, 4, -2, start);
        structure.setBlockState(world, Blocks.SPRUCE_SLAB.getDefaultState().with(SlabBlock.TYPE, SlabType.BOTTOM).with(SlabBlock.WATERLOGGED, false), -51, 4, -1, start);
        structure.setBlockState(world, Blocks.SPRUCE_TRAPDOOR.getDefaultState().with(HorizontalBlock.HORIZONTAL_FACING, Direction.EAST).with(TrapDoorBlock.HALF, Half.BOTTOM).with(TrapDoorBlock.WATERLOGGED, false).with(TrapDoorBlock.POWERED, false).with(TrapDoorBlock.OPEN, false), -51, 4, 0, start);
        structure.setBlockState(world, Blocks.SPRUCE_SLAB.getDefaultState().with(SlabBlock.TYPE, SlabType.BOTTOM).with(SlabBlock.WATERLOGGED, false), -51, 4, 1, start);
        structure.setBlockState(world, Blocks.SPRUCE_TRAPDOOR.getDefaultState().with(HorizontalBlock.HORIZONTAL_FACING, Direction.EAST).with(TrapDoorBlock.HALF, Half.BOTTOM).with(TrapDoorBlock.WATERLOGGED, false).with(TrapDoorBlock.POWERED, false).with(TrapDoorBlock.OPEN, false), -51, 4, 2, start);
        structure.setBlockState(world, Blocks.SPRUCE_SLAB.getDefaultState().with(SlabBlock.TYPE, SlabType.BOTTOM).with(SlabBlock.WATERLOGGED, false), -51, 4, 3, start);
        structure.setBlockState(world, Blocks.SPRUCE_TRAPDOOR.getDefaultState().with(HorizontalBlock.HORIZONTAL_FACING, Direction.EAST).with(TrapDoorBlock.HALF, Half.BOTTOM).with(TrapDoorBlock.WATERLOGGED, false).with(TrapDoorBlock.POWERED, false).with(TrapDoorBlock.OPEN, false), -51, 4, 4, start);
        structure.setBlockState(world, Blocks.SPRUCE_SLAB.getDefaultState().with(SlabBlock.TYPE, SlabType.BOTTOM).with(SlabBlock.WATERLOGGED, false), -51, 4, 5, start);
        structure.setBlockState(world, Blocks.SPRUCE_TRAPDOOR.getDefaultState().with(HorizontalBlock.HORIZONTAL_FACING, Direction.EAST).with(TrapDoorBlock.HALF, Half.BOTTOM).with(TrapDoorBlock.WATERLOGGED, false).with(TrapDoorBlock.POWERED, false).with(TrapDoorBlock.OPEN, false), -51, 4, 6, start);
        structure.setBlockState(world, Blocks.SPRUCE_SLAB.getDefaultState().with(SlabBlock.TYPE, SlabType.BOTTOM).with(SlabBlock.WATERLOGGED, false), -51, 4, 7, start);
        structure.setBlockState(world, Blocks.SPRUCE_TRAPDOOR.getDefaultState().with(HorizontalBlock.HORIZONTAL_FACING, Direction.EAST).with(TrapDoorBlock.HALF, Half.BOTTOM).with(TrapDoorBlock.WATERLOGGED, false).with(TrapDoorBlock.POWERED, false).with(TrapDoorBlock.OPEN, false), -51, 4, 8, start);
        structure.setBlockState(world, Blocks.STONE.getDefaultState(), -50, -7, -52, start);
        structure.setBlockState(world, Blocks.ANDESITE.getDefaultState(), -50, -7, -41, start);
        structure.setBlockState(world, Blocks.DIRT.getDefaultState(), -50, -3, -44, start);
        structure.setBlockState(world, Blocks.GRASS_BLOCK.getDefaultState().with(SnowyDirtBlock.SNOWY, false), -50, -3, -43, start);
        structure.setBlockState(world, Blocks.WATER.getDefaultState(), -50, -3, -41, start);
        structure.setBlockState(world, Blocks.WATER.getDefaultState(), -50, -3, -40, start);
        structure.setBlockState(world, Blocks.WATER.getDefaultState(), -50, -3, 39, start);
        structure.setBlockState(world, Blocks.WATER.getDefaultState(), -50, -3, 40, start);
        structure.setBlockState(world, Blocks.WATER.getDefaultState(), -50, -3, 41, start);
        structure.setBlockState(world, Blocks.WATER.getDefaultState(), -50, -3, 42, start);
        structure.setBlockState(world, Blocks.WATER.getDefaultState(), -50, -3, 43, start);
        structure.setBlockState(world, Blocks.GRASS_BLOCK.getDefaultState().with(SnowyDirtBlock.SNOWY, false), -50, -2, -44, start);
        structure.setBlockState(world, Blocks.GRASS_BLOCK.getDefaultState().with(SnowyDirtBlock.SNOWY, false), -50, -2, -39, start);
        structure.setBlockState(world, Blocks.JUNGLE_FENCE_GATE.getDefaultState().with(FenceGateBlock.IN_WALL, false).with(FenceGateBlock.OPEN, false).with(FenceGateBlock.POWERED, false), -50, 0, -36, start);
        structure.setBlockState(world, Blocks.JUNGLE_FENCE_GATE.getDefaultState().with(FenceGateBlock.IN_WALL, false).with(FenceGateBlock.OPEN, false).with(FenceGateBlock.POWERED, false), -50, 0, -34, start);
        structure.setBlockState(world, Blocks.JUNGLE_FENCE_GATE.getDefaultState().with(FenceGateBlock.IN_WALL, false).with(FenceGateBlock.OPEN, false).with(FenceGateBlock.POWERED, false), -50, 0, 33, start);
        structure.setBlockState(world, Blocks.JUNGLE_FENCE_GATE.getDefaultState().with(FenceGateBlock.IN_WALL, false).with(FenceGateBlock.OPEN, false).with(FenceGateBlock.POWERED, false), -50, 0, 35, start);
        structure.setBlockState(world, Blocks.JUNGLE_FENCE_GATE.getDefaultState().with(FenceGateBlock.IN_WALL, false).with(FenceGateBlock.OPEN, false).with(FenceGateBlock.POWERED, false), -50, 1, -31, start);
        structure.setBlockState(world, Blocks.JUNGLE_FENCE_GATE.getDefaultState().with(FenceGateBlock.IN_WALL, false).with(FenceGateBlock.OPEN, false).with(FenceGateBlock.POWERED, false), -50, 1, -29, start);
        structure.setBlockState(world, Blocks.JUNGLE_FENCE_GATE.getDefaultState().with(FenceGateBlock.IN_WALL, false).with(FenceGateBlock.OPEN, false).with(FenceGateBlock.POWERED, false), -50, 1, -27, start);
        structure.setBlockState(world, Blocks.JUNGLE_FENCE_GATE.getDefaultState().with(FenceGateBlock.IN_WALL, false).with(FenceGateBlock.OPEN, false).with(FenceGateBlock.POWERED, false), -50, 1, 28, start);
        structure.setBlockState(world, Blocks.JUNGLE_FENCE_GATE.getDefaultState().with(FenceGateBlock.IN_WALL, false).with(FenceGateBlock.OPEN, false).with(FenceGateBlock.POWERED, false), -50, 1, 30, start);
        structure.setBlockState(world, Blocks.JUNGLE_FENCE_GATE.getDefaultState().with(FenceGateBlock.IN_WALL, false).with(FenceGateBlock.OPEN, false).with(FenceGateBlock.POWERED, false), -50, 1, 32, start);
        structure.setBlockState(world, Blocks.SPRUCE_SLAB.getDefaultState().with(SlabBlock.TYPE, SlabType.BOTTOM).with(SlabBlock.WATERLOGGED, false), -50, 3, -26, start);
        structure.setBlockState(world, Blocks.SPRUCE_TRAPDOOR.getDefaultState().with(HorizontalBlock.HORIZONTAL_FACING, Direction.EAST).with(TrapDoorBlock.HALF, Half.BOTTOM).with(TrapDoorBlock.WATERLOGGED, false).with(TrapDoorBlock.POWERED, false).with(TrapDoorBlock.OPEN, false), -50, 3, -25, start);
        structure.setBlockState(world, Blocks.SPRUCE_SLAB.getDefaultState().with(SlabBlock.TYPE, SlabType.BOTTOM).with(SlabBlock.WATERLOGGED, false), -50, 3, -24, start);
        structure.setBlockState(world, Blocks.SPRUCE_TRAPDOOR.getDefaultState().with(HorizontalBlock.HORIZONTAL_FACING, Direction.EAST).with(TrapDoorBlock.HALF, Half.BOTTOM).with(TrapDoorBlock.WATERLOGGED, false).with(TrapDoorBlock.POWERED, false).with(TrapDoorBlock.OPEN, false), -50, 3, -23, start);
        structure.setBlockState(world, Blocks.SPRUCE_SLAB.getDefaultState().with(SlabBlock.TYPE, SlabType.BOTTOM).with(SlabBlock.WATERLOGGED, false), -50, 3, -22, start);
        structure.setBlockState(world, Blocks.SPRUCE_TRAPDOOR.getDefaultState().with(HorizontalBlock.HORIZONTAL_FACING, Direction.EAST).with(TrapDoorBlock.HALF, Half.BOTTOM).with(TrapDoorBlock.WATERLOGGED, false).with(TrapDoorBlock.POWERED, false).with(TrapDoorBlock.OPEN, false), -50, 3, -21, start);
        structure.setBlockState(world, Blocks.SPRUCE_SLAB.getDefaultState().with(SlabBlock.TYPE, SlabType.BOTTOM).with(SlabBlock.WATERLOGGED, false), -50, 3, -20, start);
        structure.setBlockState(world, Blocks.SPRUCE_TRAPDOOR.getDefaultState().with(HorizontalBlock.HORIZONTAL_FACING, Direction.EAST).with(TrapDoorBlock.HALF, Half.BOTTOM).with(TrapDoorBlock.WATERLOGGED, false).with(TrapDoorBlock.POWERED, false).with(TrapDoorBlock.OPEN, false), -50, 3, -19, start);
        structure.setBlockState(world, Blocks.OAK_LOG.getDefaultState(), -50, 3, -18, start);
        structure.setBlockState(world, Blocks.OAK_LOG.getDefaultState(), -50, 3, 18, start);
        structure.setBlockState(world, Blocks.SPRUCE_TRAPDOOR.getDefaultState().with(HorizontalBlock.HORIZONTAL_FACING, Direction.EAST).with(TrapDoorBlock.HALF, Half.BOTTOM).with(TrapDoorBlock.WATERLOGGED, false).with(TrapDoorBlock.POWERED, false).with(TrapDoorBlock.OPEN, false), -50, 3, 19, start);
        structure.setBlockState(world, Blocks.SPRUCE_SLAB.getDefaultState().with(SlabBlock.TYPE, SlabType.BOTTOM).with(SlabBlock.WATERLOGGED, false), -50, 3, 20, start);
        structure.setBlockState(world, Blocks.SPRUCE_TRAPDOOR.getDefaultState().with(HorizontalBlock.HORIZONTAL_FACING, Direction.EAST).with(TrapDoorBlock.HALF, Half.BOTTOM).with(TrapDoorBlock.WATERLOGGED, false).with(TrapDoorBlock.POWERED, false).with(TrapDoorBlock.OPEN, false), -50, 3, 21, start);
        structure.setBlockState(world, Blocks.SPRUCE_SLAB.getDefaultState().with(SlabBlock.TYPE, SlabType.BOTTOM).with(SlabBlock.WATERLOGGED, false), -50, 3, 22, start);
        structure.setBlockState(world, Blocks.SPRUCE_TRAPDOOR.getDefaultState().with(HorizontalBlock.HORIZONTAL_FACING, Direction.EAST).with(TrapDoorBlock.HALF, Half.BOTTOM).with(TrapDoorBlock.WATERLOGGED, false).with(TrapDoorBlock.POWERED, false).with(TrapDoorBlock.OPEN, false), -50, 3, 23, start);
        structure.setBlockState(world, Blocks.SPRUCE_SLAB.getDefaultState().with(SlabBlock.TYPE, SlabType.BOTTOM).with(SlabBlock.WATERLOGGED, false), -50, 3, 24, start);
        structure.setBlockState(world, Blocks.SPRUCE_TRAPDOOR.getDefaultState().with(HorizontalBlock.HORIZONTAL_FACING, Direction.EAST).with(TrapDoorBlock.HALF, Half.BOTTOM).with(TrapDoorBlock.WATERLOGGED, false).with(TrapDoorBlock.POWERED, false).with(TrapDoorBlock.OPEN, false), -50, 3, 25, start);
        structure.setBlockState(world, Blocks.SPRUCE_SLAB.getDefaultState().with(SlabBlock.TYPE, SlabType.BOTTOM).with(SlabBlock.WATERLOGGED, false), -50, 3, 26, start);
        structure.setBlockState(world, Blocks.SPRUCE_TRAPDOOR.getDefaultState().with(HorizontalBlock.HORIZONTAL_FACING, Direction.EAST).with(TrapDoorBlock.HALF, Half.BOTTOM).with(TrapDoorBlock.WATERLOGGED, false).with(TrapDoorBlock.POWERED, false).with(TrapDoorBlock.OPEN, false), -50, 4, -18, start);
        structure.setBlockState(world, Blocks.SPRUCE_SLAB.getDefaultState().with(SlabBlock.TYPE, SlabType.BOTTOM).with(SlabBlock.WATERLOGGED, false), -50, 4, -17, start);
        structure.setBlockState(world, Blocks.SPRUCE_TRAPDOOR.getDefaultState().with(HorizontalBlock.HORIZONTAL_FACING, Direction.EAST).with(TrapDoorBlock.HALF, Half.BOTTOM).with(TrapDoorBlock.WATERLOGGED, false).with(TrapDoorBlock.POWERED, false).with(TrapDoorBlock.OPEN, false), -50, 4, -16, start);
        structure.setBlockState(world, Blocks.SPRUCE_SLAB.getDefaultState().with(SlabBlock.TYPE, SlabType.BOTTOM).with(SlabBlock.WATERLOGGED, false), -50, 4, -15, start);
        structure.setBlockState(world, Blocks.SPRUCE_TRAPDOOR.getDefaultState().with(HorizontalBlock.HORIZONTAL_FACING, Direction.EAST).with(TrapDoorBlock.HALF, Half.BOTTOM).with(TrapDoorBlock.WATERLOGGED, false).with(TrapDoorBlock.POWERED, false).with(TrapDoorBlock.OPEN, false), -50, 4, -14, start);
        structure.setBlockState(world, Blocks.SPRUCE_SLAB.getDefaultState().with(SlabBlock.TYPE, SlabType.BOTTOM).with(SlabBlock.WATERLOGGED, false), -50, 4, -13, start);
        structure.setBlockState(world, Blocks.SPRUCE_TRAPDOOR.getDefaultState().with(HorizontalBlock.HORIZONTAL_FACING, Direction.EAST).with(TrapDoorBlock.HALF, Half.BOTTOM).with(TrapDoorBlock.WATERLOGGED, false).with(TrapDoorBlock.POWERED, false).with(TrapDoorBlock.OPEN, false), -50, 4, -12, start);
        structure.setBlockState(world, Blocks.SPRUCE_SLAB.getDefaultState().with(SlabBlock.TYPE, SlabType.BOTTOM).with(SlabBlock.WATERLOGGED, false), -50, 4, -11, start);
        structure.setBlockState(world, Blocks.SPRUCE_TRAPDOOR.getDefaultState().with(HorizontalBlock.HORIZONTAL_FACING, Direction.EAST).with(TrapDoorBlock.HALF, Half.BOTTOM).with(TrapDoorBlock.WATERLOGGED, false).with(TrapDoorBlock.POWERED, false).with(TrapDoorBlock.OPEN, false), -50, 4, -10, start);
        structure.setBlockState(world, Blocks.SPRUCE_SLAB.getDefaultState().with(SlabBlock.TYPE, SlabType.BOTTOM).with(SlabBlock.WATERLOGGED, false), -50, 4, -9, start);
        structure.setBlockState(world, Blocks.SPRUCE_SLAB.getDefaultState().with(SlabBlock.TYPE, SlabType.BOTTOM).with(SlabBlock.WATERLOGGED, false), -50, 4, 9, start);
        structure.setBlockState(world, Blocks.SPRUCE_TRAPDOOR.getDefaultState().with(HorizontalBlock.HORIZONTAL_FACING, Direction.EAST).with(TrapDoorBlock.HALF, Half.BOTTOM).with(TrapDoorBlock.WATERLOGGED, false).with(TrapDoorBlock.POWERED, false).with(TrapDoorBlock.OPEN, false), -50, 4, 10, start);
        structure.setBlockState(world, Blocks.SPRUCE_SLAB.getDefaultState().with(SlabBlock.TYPE, SlabType.BOTTOM).with(SlabBlock.WATERLOGGED, false), -50, 4, 11, start);
        structure.setBlockState(world, Blocks.SPRUCE_TRAPDOOR.getDefaultState().with(HorizontalBlock.HORIZONTAL_FACING, Direction.EAST).with(TrapDoorBlock.HALF, Half.BOTTOM).with(TrapDoorBlock.WATERLOGGED, false).with(TrapDoorBlock.POWERED, false).with(TrapDoorBlock.OPEN, false), -50, 4, 12, start);
        structure.setBlockState(world, Blocks.SPRUCE_SLAB.getDefaultState().with(SlabBlock.TYPE, SlabType.BOTTOM).with(SlabBlock.WATERLOGGED, false), -50, 4, 13, start);
        structure.setBlockState(world, Blocks.SPRUCE_TRAPDOOR.getDefaultState().with(HorizontalBlock.HORIZONTAL_FACING, Direction.EAST).with(TrapDoorBlock.HALF, Half.BOTTOM).with(TrapDoorBlock.WATERLOGGED, false).with(TrapDoorBlock.POWERED, false).with(TrapDoorBlock.OPEN, false), -50, 4, 14, start);
        structure.setBlockState(world, Blocks.SPRUCE_SLAB.getDefaultState().with(SlabBlock.TYPE, SlabType.BOTTOM).with(SlabBlock.WATERLOGGED, false), -50, 4, 15, start);
        structure.setBlockState(world, Blocks.SPRUCE_TRAPDOOR.getDefaultState().with(HorizontalBlock.HORIZONTAL_FACING, Direction.EAST).with(TrapDoorBlock.HALF, Half.BOTTOM).with(TrapDoorBlock.WATERLOGGED, false).with(TrapDoorBlock.POWERED, false).with(TrapDoorBlock.OPEN, false), -50, 4, 16, start);
        structure.setBlockState(world, Blocks.SPRUCE_SLAB.getDefaultState().with(SlabBlock.TYPE, SlabType.BOTTOM).with(SlabBlock.WATERLOGGED, false), -50, 4, 17, start);
        structure.setBlockState(world, Blocks.SPRUCE_TRAPDOOR.getDefaultState().with(HorizontalBlock.HORIZONTAL_FACING, Direction.EAST).with(TrapDoorBlock.HALF, Half.BOTTOM).with(TrapDoorBlock.WATERLOGGED, false).with(TrapDoorBlock.POWERED, false).with(TrapDoorBlock.OPEN, false), -50, 4, 18, start);
        structure.setBlockState(world, Blocks.STONE.getDefaultState(), -49, -6, -54, start);
        structure.setBlockState(world, Blocks.IRON_ORE.getDefaultState(), -49, -6, 66, start);
        structure.setBlockState(world, Blocks.GRASS_BLOCK.getDefaultState().with(SnowyDirtBlock.SNOWY, false), -49, -3, -44, start);
        structure.setBlockState(world, Blocks.WATER.getDefaultState(), -49, -3, -41, start);
        structure.setBlockState(world, Blocks.WATER.getDefaultState(), -49, -3, 42, start);
        structure.setBlockState(world, Blocks.WATER.getDefaultState(), -49, -3, 44, start);
        structure.setBlockState(world, Blocks.GRASS_BLOCK.getDefaultState().with(SnowyDirtBlock.SNOWY, false), -49, -2, -45, start);
        structure.setBlockState(world, Blocks.GRASS_BLOCK.getDefaultState().with(SnowyDirtBlock.SNOWY, false), -49, -2, -40, start);
        structure.setBlockState(world, Blocks.JUNGLE_FENCE_GATE.getDefaultState().with(FenceGateBlock.IN_WALL, false).with(FenceGateBlock.OPEN, false).with(FenceGateBlock.POWERED, false), -49, 0, 37, start);
        structure.setBlockState(world, Blocks.JUNGLE_FENCE_GATE.getDefaultState().with(FenceGateBlock.IN_WALL, false).with(FenceGateBlock.OPEN, false).with(FenceGateBlock.POWERED, false), -49, 1, -35, start);
        structure.setBlockState(world, Blocks.JUNGLE_FENCE_GATE.getDefaultState().with(FenceGateBlock.IN_WALL, false).with(FenceGateBlock.OPEN, false).with(FenceGateBlock.POWERED, false), -49, 1, -33, start);
        structure.setBlockState(world, Blocks.JUNGLE_FENCE_GATE.getDefaultState().with(FenceGateBlock.IN_WALL, false).with(FenceGateBlock.OPEN, false).with(FenceGateBlock.POWERED, false), -49, 1, 34, start);
        structure.setBlockState(world, Blocks.JUNGLE_FENCE_GATE.getDefaultState().with(FenceGateBlock.IN_WALL, false).with(FenceGateBlock.OPEN, false).with(FenceGateBlock.POWERED, false), -49, 1, 36, start);
        structure.setBlockState(world, Blocks.DIRT.getDefaultState(), -49, 2, -8, start);
        structure.setBlockState(world, Blocks.DIRT.getDefaultState(), -49, 2, 8, start);
        structure.setBlockState(world, Blocks.SPRUCE_SLAB.getDefaultState().with(SlabBlock.TYPE, SlabType.BOTTOM).with(SlabBlock.WATERLOGGED, false), -49, 3, -32, start);
        structure.setBlockState(world, Blocks.SPRUCE_TRAPDOOR.getDefaultState().with(HorizontalBlock.HORIZONTAL_FACING, Direction.EAST).with(TrapDoorBlock.HALF, Half.BOTTOM).with(TrapDoorBlock.WATERLOGGED, false).with(TrapDoorBlock.POWERED, false).with(TrapDoorBlock.OPEN, false), -49, 3, -31, start);
        structure.setBlockState(world, Blocks.SPRUCE_SLAB.getDefaultState().with(SlabBlock.TYPE, SlabType.BOTTOM).with(SlabBlock.WATERLOGGED, false), -49, 3, -30, start);
        structure.setBlockState(world, Blocks.SPRUCE_TRAPDOOR.getDefaultState().with(HorizontalBlock.HORIZONTAL_FACING, Direction.EAST).with(TrapDoorBlock.HALF, Half.BOTTOM).with(TrapDoorBlock.WATERLOGGED, false).with(TrapDoorBlock.POWERED, false).with(TrapDoorBlock.OPEN, false), -49, 3, -29, start);
        structure.setBlockState(world, Blocks.SPRUCE_SLAB.getDefaultState().with(SlabBlock.TYPE, SlabType.BOTTOM).with(SlabBlock.WATERLOGGED, false), -49, 3, -28, start);
        structure.setBlockState(world, Blocks.SPRUCE_TRAPDOOR.getDefaultState().with(HorizontalBlock.HORIZONTAL_FACING, Direction.EAST).with(TrapDoorBlock.HALF, Half.BOTTOM).with(TrapDoorBlock.WATERLOGGED, false).with(TrapDoorBlock.POWERED, false).with(TrapDoorBlock.OPEN, false), -49, 3, -27, start);
        structure.setBlockState(world, Blocks.OAK_LOG.getDefaultState(), -49, 3, -26, start);
        structure.setBlockState(world, Blocks.AIR.getDefaultState(), -49, 3, 0, start);
        structure.setBlockState(world, Blocks.OAK_LOG.getDefaultState(), -49, 3, 26, start);
        structure.setBlockState(world, Blocks.SPRUCE_TRAPDOOR.getDefaultState().with(HorizontalBlock.HORIZONTAL_FACING, Direction.EAST).with(TrapDoorBlock.HALF, Half.BOTTOM).with(TrapDoorBlock.WATERLOGGED, false).with(TrapDoorBlock.POWERED, false).with(TrapDoorBlock.OPEN, false), -49, 3, 27, start);
        structure.setBlockState(world, Blocks.SPRUCE_SLAB.getDefaultState().with(SlabBlock.TYPE, SlabType.BOTTOM).with(SlabBlock.WATERLOGGED, false), -49, 3, 28, start);
        structure.setBlockState(world, Blocks.SPRUCE_TRAPDOOR.getDefaultState().with(HorizontalBlock.HORIZONTAL_FACING, Direction.EAST).with(TrapDoorBlock.HALF, Half.BOTTOM).with(TrapDoorBlock.WATERLOGGED, false).with(TrapDoorBlock.POWERED, false).with(TrapDoorBlock.OPEN, false), -49, 3, 29, start);
        structure.setBlockState(world, Blocks.SPRUCE_SLAB.getDefaultState().with(SlabBlock.TYPE, SlabType.BOTTOM).with(SlabBlock.WATERLOGGED, false), -49, 3, 30, start);
        structure.setBlockState(world, Blocks.SPRUCE_TRAPDOOR.getDefaultState().with(HorizontalBlock.HORIZONTAL_FACING, Direction.EAST).with(TrapDoorBlock.HALF, Half.BOTTOM).with(TrapDoorBlock.WATERLOGGED, false).with(TrapDoorBlock.POWERED, false).with(TrapDoorBlock.OPEN, false), -49, 3, 31, start);
        structure.setBlockState(world, Blocks.SPRUCE_SLAB.getDefaultState().with(SlabBlock.TYPE, SlabType.BOTTOM).with(SlabBlock.WATERLOGGED, false), -49, 3, 32, start);
        structure.setBlockState(world, Blocks.SPRUCE_TRAPDOOR.getDefaultState().with(HorizontalBlock.HORIZONTAL_FACING, Direction.EAST).with(TrapDoorBlock.HALF, Half.BOTTOM).with(TrapDoorBlock.WATERLOGGED, false).with(TrapDoorBlock.POWERED, false).with(TrapDoorBlock.OPEN, false), -49, 4, -26, start);
        structure.setBlockState(world, Blocks.SPRUCE_SLAB.getDefaultState().with(SlabBlock.TYPE, SlabType.BOTTOM).with(SlabBlock.WATERLOGGED, false), -49, 4, -25, start);
        structure.setBlockState(world, Blocks.SPRUCE_TRAPDOOR.getDefaultState().with(HorizontalBlock.HORIZONTAL_FACING, Direction.EAST).with(TrapDoorBlock.HALF, Half.BOTTOM).with(TrapDoorBlock.WATERLOGGED, false).with(TrapDoorBlock.POWERED, false).with(TrapDoorBlock.OPEN, false), -49, 4, -24, start);
        structure.setBlockState(world, Blocks.SPRUCE_SLAB.getDefaultState().with(SlabBlock.TYPE, SlabType.BOTTOM).with(SlabBlock.WATERLOGGED, false), -49, 4, -23, start);
        structure.setBlockState(world, Blocks.SPRUCE_TRAPDOOR.getDefaultState().with(HorizontalBlock.HORIZONTAL_FACING, Direction.EAST).with(TrapDoorBlock.HALF, Half.BOTTOM).with(TrapDoorBlock.WATERLOGGED, false).with(TrapDoorBlock.POWERED, false).with(TrapDoorBlock.OPEN, false), -49, 4, -22, start);
        structure.setBlockState(world, Blocks.SPRUCE_SLAB.getDefaultState().with(SlabBlock.TYPE, SlabType.BOTTOM).with(SlabBlock.WATERLOGGED, false), -49, 4, -21, start);
        structure.setBlockState(world, Blocks.SPRUCE_TRAPDOOR.getDefaultState().with(HorizontalBlock.HORIZONTAL_FACING, Direction.EAST).with(TrapDoorBlock.HALF, Half.BOTTOM).with(TrapDoorBlock.WATERLOGGED, false).with(TrapDoorBlock.POWERED, false).with(TrapDoorBlock.OPEN, false), -49, 4, -20, start);
        structure.setBlockState(world, Blocks.SPRUCE_SLAB.getDefaultState().with(SlabBlock.TYPE, SlabType.BOTTOM).with(SlabBlock.WATERLOGGED, false), -49, 4, -19, start);
        structure.setBlockState(world, Blocks.SPRUCE_SLAB.getDefaultState().with(SlabBlock.TYPE, SlabType.BOTTOM).with(SlabBlock.WATERLOGGED, false), -49, 4, 19, start);
        structure.setBlockState(world, Blocks.SPRUCE_TRAPDOOR.getDefaultState().with(HorizontalBlock.HORIZONTAL_FACING, Direction.EAST).with(TrapDoorBlock.HALF, Half.BOTTOM).with(TrapDoorBlock.WATERLOGGED, false).with(TrapDoorBlock.POWERED, false).with(TrapDoorBlock.OPEN, false), -49, 4, 20, start);
        structure.setBlockState(world, Blocks.SPRUCE_SLAB.getDefaultState().with(SlabBlock.TYPE, SlabType.BOTTOM).with(SlabBlock.WATERLOGGED, false), -49, 4, 21, start);
        structure.setBlockState(world, Blocks.SPRUCE_TRAPDOOR.getDefaultState().with(HorizontalBlock.HORIZONTAL_FACING, Direction.EAST).with(TrapDoorBlock.HALF, Half.BOTTOM).with(TrapDoorBlock.WATERLOGGED, false).with(TrapDoorBlock.POWERED, false).with(TrapDoorBlock.OPEN, false), -49, 4, 22, start);
        structure.setBlockState(world, Blocks.SPRUCE_SLAB.getDefaultState().with(SlabBlock.TYPE, SlabType.BOTTOM).with(SlabBlock.WATERLOGGED, false), -49, 4, 23, start);
        structure.setBlockState(world, Blocks.SPRUCE_TRAPDOOR.getDefaultState().with(HorizontalBlock.HORIZONTAL_FACING, Direction.EAST).with(TrapDoorBlock.HALF, Half.BOTTOM).with(TrapDoorBlock.WATERLOGGED, false).with(TrapDoorBlock.POWERED, false).with(TrapDoorBlock.OPEN, false), -49, 4, 24, start);
        structure.setBlockState(world, Blocks.SPRUCE_SLAB.getDefaultState().with(SlabBlock.TYPE, SlabType.BOTTOM).with(SlabBlock.WATERLOGGED, false), -49, 4, 25, start);
        structure.setBlockState(world, Blocks.SPRUCE_TRAPDOOR.getDefaultState().with(HorizontalBlock.HORIZONTAL_FACING, Direction.EAST).with(TrapDoorBlock.HALF, Half.BOTTOM).with(TrapDoorBlock.WATERLOGGED, false).with(TrapDoorBlock.POWERED, false).with(TrapDoorBlock.OPEN, false), -49, 4, 26, start);
        structure.setBlockState(world, Blocks.STONE.getDefaultState(), -48, -6, -58, start);
        structure.setBlockState(world, Blocks.DIRT.getDefaultState(), -48, -3, -46, start);
        structure.setBlockState(world, Blocks.WATER.getDefaultState(), -48, -3, 43, start);
        structure.setBlockState(world, Blocks.WATER.getDefaultState(), -48, -3, 44, start);
        structure.setBlockState(world, Blocks.WATER.getDefaultState(), -48, -3, 45, start);
        structure.setBlockState(world, Blocks.DIRT.getDefaultState(), -48, -2, -47, start);
        structure.setBlockState(world, Blocks.GRASS_BLOCK.getDefaultState().with(SnowyDirtBlock.SNOWY, false), -48, -2, -46, start);
        structure.setBlockState(world, Blocks.GRASS_BLOCK.getDefaultState().with(SnowyDirtBlock.SNOWY, false), -48, -1, -47, start);
        structure.setBlockState(world, Blocks.GRASS_BLOCK.getDefaultState().with(SnowyDirtBlock.SNOWY, false), -48, -1, -2, start);
        structure.setBlockState(world, Blocks.JUNGLE_FENCE_GATE.getDefaultState().with(FenceGateBlock.IN_WALL, false).with(FenceGateBlock.OPEN, false).with(FenceGateBlock.POWERED, false), -48, 0, -41, start);
        structure.setBlockState(world, Blocks.JUNGLE_FENCE_GATE.getDefaultState().with(FenceGateBlock.IN_WALL, false).with(FenceGateBlock.OPEN, false).with(FenceGateBlock.POWERED, false), -48, 0, -39, start);
        structure.setBlockState(world, Blocks.JUNGLE_FENCE_GATE.getDefaultState().with(FenceGateBlock.IN_WALL, false).with(FenceGateBlock.OPEN, false).with(FenceGateBlock.POWERED, false), -48, 0, 39, start);
        structure.setBlockState(world, Blocks.JUNGLE_FENCE_GATE.getDefaultState().with(FenceGateBlock.IN_WALL, false).with(FenceGateBlock.OPEN, false).with(FenceGateBlock.POWERED, false), -48, 0, 41, start);
        structure.setBlockState(world, Blocks.JUNGLE_FENCE_GATE.getDefaultState().with(FenceGateBlock.IN_WALL, false).with(FenceGateBlock.OPEN, false).with(FenceGateBlock.POWERED, false), -48, 1, -37, start);
        structure.setBlockState(world, Blocks.RED_WOOL.getDefaultState(), -48, 1, -2, start);
        structure.setBlockState(world, Blocks.JUNGLE_FENCE_GATE.getDefaultState().with(FenceGateBlock.IN_WALL, false).with(FenceGateBlock.OPEN, false).with(FenceGateBlock.POWERED, false), -48, 1, 38, start);
        structure.setBlockState(world, Blocks.SPRUCE_LOG.getDefaultState(), -48, 2, -2, start);
        structure.setBlockState(world, Blocks.DIRT.getDefaultState(), -48, 2, 18, start);
        structure.setBlockState(world, Blocks.SPRUCE_SLAB.getDefaultState().with(SlabBlock.TYPE, SlabType.BOTTOM).with(SlabBlock.WATERLOGGED, false), -48, 3, -36, start);
        structure.setBlockState(world, Blocks.SPRUCE_TRAPDOOR.getDefaultState().with(HorizontalBlock.HORIZONTAL_FACING, Direction.EAST).with(TrapDoorBlock.HALF, Half.BOTTOM).with(TrapDoorBlock.WATERLOGGED, false).with(TrapDoorBlock.POWERED, false).with(TrapDoorBlock.OPEN, false), -48, 3, -35, start);
        structure.setBlockState(world, Blocks.SPRUCE_SLAB.getDefaultState().with(SlabBlock.TYPE, SlabType.BOTTOM).with(SlabBlock.WATERLOGGED, false), -48, 3, -34, start);
        structure.setBlockState(world, Blocks.SPRUCE_TRAPDOOR.getDefaultState().with(HorizontalBlock.HORIZONTAL_FACING, Direction.EAST).with(TrapDoorBlock.HALF, Half.BOTTOM).with(TrapDoorBlock.WATERLOGGED, false).with(TrapDoorBlock.POWERED, false).with(TrapDoorBlock.OPEN, false), -48, 3, -33, start);
        structure.setBlockState(world, Blocks.OAK_LOG.getDefaultState(), -48, 3, -32, start);
        structure.setBlockState(world, Blocks.SPRUCE_SLAB.getDefaultState().with(SlabBlock.TYPE, SlabType.BOTTOM).with(SlabBlock.WATERLOGGED, false), -48, 3, -6, start);
        structure.setBlockState(world, Blocks.SPRUCE_TRAPDOOR.getDefaultState().with(HorizontalBlock.HORIZONTAL_FACING, Direction.WEST).with(TrapDoorBlock.HALF, Half.BOTTOM).with(TrapDoorBlock.WATERLOGGED, false).with(TrapDoorBlock.POWERED, false).with(TrapDoorBlock.OPEN, false), -48, 3, -5, start);
        structure.setBlockState(world, Blocks.SPRUCE_SLAB.getDefaultState().with(SlabBlock.TYPE, SlabType.BOTTOM).with(SlabBlock.WATERLOGGED, false), -48, 3, -4, start);
        structure.setBlockState(world, Blocks.SPRUCE_TRAPDOOR.getDefaultState().with(HorizontalBlock.HORIZONTAL_FACING, Direction.WEST).with(TrapDoorBlock.HALF, Half.BOTTOM).with(TrapDoorBlock.WATERLOGGED, false).with(TrapDoorBlock.POWERED, false).with(TrapDoorBlock.OPEN, false), -48, 3, -3, start);
        structure.setBlockState(world, Blocks.SPRUCE_SLAB.getDefaultState().with(SlabBlock.TYPE, SlabType.BOTTOM).with(SlabBlock.WATERLOGGED, false), -48, 3, -2, start);
        structure.setBlockState(world, Blocks.SPRUCE_TRAPDOOR.getDefaultState().with(HorizontalBlock.HORIZONTAL_FACING, Direction.WEST).with(TrapDoorBlock.HALF, Half.BOTTOM).with(TrapDoorBlock.WATERLOGGED, false).with(TrapDoorBlock.POWERED, false).with(TrapDoorBlock.OPEN, false), -48, 3, -1, start);
        structure.setBlockState(world, Blocks.SPRUCE_SLAB.getDefaultState().with(SlabBlock.TYPE, SlabType.BOTTOM).with(SlabBlock.WATERLOGGED, false), -48, 3, 0, start);
        structure.setBlockState(world, Blocks.SPRUCE_TRAPDOOR.getDefaultState().with(HorizontalBlock.HORIZONTAL_FACING, Direction.WEST).with(TrapDoorBlock.HALF, Half.BOTTOM).with(TrapDoorBlock.WATERLOGGED, false).with(TrapDoorBlock.POWERED, false).with(TrapDoorBlock.OPEN, false), -48, 3, 1, start);
        structure.setBlockState(world, Blocks.SPRUCE_SLAB.getDefaultState().with(SlabBlock.TYPE, SlabType.BOTTOM).with(SlabBlock.WATERLOGGED, false), -48, 3, 2, start);
        structure.setBlockState(world, Blocks.SPRUCE_TRAPDOOR.getDefaultState().with(HorizontalBlock.HORIZONTAL_FACING, Direction.WEST).with(TrapDoorBlock.HALF, Half.BOTTOM).with(TrapDoorBlock.WATERLOGGED, false).with(TrapDoorBlock.POWERED, false).with(TrapDoorBlock.OPEN, false), -48, 3, 3, start);
        structure.setBlockState(world, Blocks.SPRUCE_SLAB.getDefaultState().with(SlabBlock.TYPE, SlabType.BOTTOM).with(SlabBlock.WATERLOGGED, false), -48, 3, 4, start);
        structure.setBlockState(world, Blocks.SPRUCE_TRAPDOOR.getDefaultState().with(HorizontalBlock.HORIZONTAL_FACING, Direction.WEST).with(TrapDoorBlock.HALF, Half.BOTTOM).with(TrapDoorBlock.WATERLOGGED, false).with(TrapDoorBlock.POWERED, false).with(TrapDoorBlock.OPEN, false), -48, 3, 5, start);
        structure.setBlockState(world, Blocks.SPRUCE_SLAB.getDefaultState().with(SlabBlock.TYPE, SlabType.BOTTOM).with(SlabBlock.WATERLOGGED, false), -48, 3, 6, start);
        structure.setBlockState(world, Blocks.OAK_LOG.getDefaultState(), -48, 3, 32, start);
        structure.setBlockState(world, Blocks.SPRUCE_TRAPDOOR.getDefaultState().with(HorizontalBlock.HORIZONTAL_FACING, Direction.EAST).with(TrapDoorBlock.HALF, Half.BOTTOM).with(TrapDoorBlock.WATERLOGGED, false).with(TrapDoorBlock.POWERED, false).with(TrapDoorBlock.OPEN, false), -48, 3, 33, start);
        structure.setBlockState(world, Blocks.SPRUCE_SLAB.getDefaultState().with(SlabBlock.TYPE, SlabType.BOTTOM).with(SlabBlock.WATERLOGGED, false), -48, 3, 34, start);
        structure.setBlockState(world, Blocks.SPRUCE_TRAPDOOR.getDefaultState().with(HorizontalBlock.HORIZONTAL_FACING, Direction.EAST).with(TrapDoorBlock.HALF, Half.BOTTOM).with(TrapDoorBlock.WATERLOGGED, false).with(TrapDoorBlock.POWERED, false).with(TrapDoorBlock.OPEN, false), -48, 3, 35, start);
        structure.setBlockState(world, Blocks.SPRUCE_SLAB.getDefaultState().with(SlabBlock.TYPE, SlabType.BOTTOM).with(SlabBlock.WATERLOGGED, false), -48, 3, 36, start);
        structure.setBlockState(world, Blocks.SPRUCE_TRAPDOOR.getDefaultState().with(HorizontalBlock.HORIZONTAL_FACING, Direction.EAST).with(TrapDoorBlock.HALF, Half.BOTTOM).with(TrapDoorBlock.WATERLOGGED, false).with(TrapDoorBlock.POWERED, false).with(TrapDoorBlock.OPEN, false), -48, 4, -32, start);
        structure.setBlockState(world, Blocks.SPRUCE_SLAB.getDefaultState().with(SlabBlock.TYPE, SlabType.BOTTOM).with(SlabBlock.WATERLOGGED, false), -48, 4, -31, start);
        structure.setBlockState(world, Blocks.SPRUCE_TRAPDOOR.getDefaultState().with(HorizontalBlock.HORIZONTAL_FACING, Direction.EAST).with(TrapDoorBlock.HALF, Half.BOTTOM).with(TrapDoorBlock.WATERLOGGED, false).with(TrapDoorBlock.POWERED, false).with(TrapDoorBlock.OPEN, false), -48, 4, -30, start);
        structure.setBlockState(world, Blocks.SPRUCE_SLAB.getDefaultState().with(SlabBlock.TYPE, SlabType.BOTTOM).with(SlabBlock.WATERLOGGED, false), -48, 4, -29, start);
        structure.setBlockState(world, Blocks.SPRUCE_TRAPDOOR.getDefaultState().with(HorizontalBlock.HORIZONTAL_FACING, Direction.EAST).with(TrapDoorBlock.HALF, Half.BOTTOM).with(TrapDoorBlock.WATERLOGGED, false).with(TrapDoorBlock.POWERED, false).with(TrapDoorBlock.OPEN, false), -48, 4, -28, start);
        structure.setBlockState(world, Blocks.SPRUCE_SLAB.getDefaultState().with(SlabBlock.TYPE, SlabType.BOTTOM).with(SlabBlock.WATERLOGGED, false), -48, 4, -27, start);
        structure.setBlockState(world, Blocks.SPRUCE_SLAB.getDefaultState().with(SlabBlock.TYPE, SlabType.BOTTOM).with(SlabBlock.WATERLOGGED, false), -48, 4, 27, start);
        structure.setBlockState(world, Blocks.SPRUCE_TRAPDOOR.getDefaultState().with(HorizontalBlock.HORIZONTAL_FACING, Direction.EAST).with(TrapDoorBlock.HALF, Half.BOTTOM).with(TrapDoorBlock.WATERLOGGED, false).with(TrapDoorBlock.POWERED, false).with(TrapDoorBlock.OPEN, false), -48, 4, 28, start);
        structure.setBlockState(world, Blocks.SPRUCE_SLAB.getDefaultState().with(SlabBlock.TYPE, SlabType.BOTTOM).with(SlabBlock.WATERLOGGED, false), -48, 4, 29, start);
        structure.setBlockState(world, Blocks.SPRUCE_TRAPDOOR.getDefaultState().with(HorizontalBlock.HORIZONTAL_FACING, Direction.EAST).with(TrapDoorBlock.HALF, Half.BOTTOM).with(TrapDoorBlock.WATERLOGGED, false).with(TrapDoorBlock.POWERED, false).with(TrapDoorBlock.OPEN, false), -48, 4, 30, start);
        structure.setBlockState(world, Blocks.SPRUCE_SLAB.getDefaultState().with(SlabBlock.TYPE, SlabType.BOTTOM).with(SlabBlock.WATERLOGGED, false), -48, 4, 31, start);
        structure.setBlockState(world, Blocks.SPRUCE_TRAPDOOR.getDefaultState().with(HorizontalBlock.HORIZONTAL_FACING, Direction.EAST).with(TrapDoorBlock.HALF, Half.BOTTOM).with(TrapDoorBlock.WATERLOGGED, false).with(TrapDoorBlock.POWERED, false).with(TrapDoorBlock.OPEN, false), -48, 4, 32, start);
        structure.setBlockState(world, Blocks.COAL_ORE.getDefaultState(), -47, -6, -56, start);
        structure.setBlockState(world, Blocks.ANDESITE.getDefaultState(), -47, -6, -43, start);
        structure.setBlockState(world, Blocks.WATER.getDefaultState(), -47, -3, -44, start);
        structure.setBlockState(world, Blocks.GRASS_BLOCK.getDefaultState().with(SnowyDirtBlock.SNOWY, false), -47, -3, -43, start);
        structure.setBlockState(world, Blocks.WATER.getDefaultState(), -47, -3, 44, start);
        structure.setBlockState(world, Blocks.GRASS_BLOCK.getDefaultState().with(SnowyDirtBlock.SNOWY, false), -47, -2, -47, start);
        structure.setBlockState(world, Blocks.GRASS_BLOCK.getDefaultState().with(SnowyDirtBlock.SNOWY, false), -47, -1, -42, start);
        structure.setBlockState(world, Blocks.DIRT.getDefaultState(), -47, 0, -38, start);
        structure.setBlockState(world, Blocks.JUNGLE_FENCE_GATE.getDefaultState().with(FenceGateBlock.IN_WALL, false).with(FenceGateBlock.OPEN, false).with(FenceGateBlock.POWERED, false), -47, 1, -40, start);
        structure.setBlockState(world, Blocks.BIRCH_SIGN.getDefaultState().with(StandingSignBlock.ROTATION, 4), -47, 1, 36, start);
        structure.setBlockState(world, Blocks.JUNGLE_FENCE_GATE.getDefaultState().with(FenceGateBlock.IN_WALL, false).with(FenceGateBlock.OPEN, false).with(FenceGateBlock.POWERED, false), -47, 1, 40, start);
        structure.setBlockState(world, Blocks.OAK_LOG.getDefaultState(), -47, 2, 7, start);
        structure.setBlockState(world, Blocks.SPRUCE_LOG.getDefaultState(), -47, 2, 8, start);
        structure.setBlockState(world, Blocks.OAK_LOG.getDefaultState(), -47, 2, 9, start);
        structure.setBlockState(world, Blocks.SPRUCE_LOG.getDefaultState(), -47, 2, 10, start);
        structure.setBlockState(world, Blocks.OAK_LOG.getDefaultState(), -47, 2, 11, start);
        structure.setBlockState(world, Blocks.SPRUCE_LOG.getDefaultState(), -47, 2, 12, start);
        structure.setBlockState(world, Blocks.OAK_LOG.getDefaultState(), -47, 2, 13, start);
        structure.setBlockState(world, Blocks.SPRUCE_LOG.getDefaultState(), -47, 2, 14, start);
        structure.setBlockState(world, Blocks.OAK_LOG.getDefaultState(), -47, 2, 15, start);
        structure.setBlockState(world, Blocks.SPRUCE_LOG.getDefaultState(), -47, 2, 16, start);
        structure.setBlockState(world, Blocks.SPRUCE_SLAB.getDefaultState().with(SlabBlock.TYPE, SlabType.BOTTOM).with(SlabBlock.WATERLOGGED, false), -47, 3, -38, start);
        structure.setBlockState(world, Blocks.SPRUCE_TRAPDOOR.getDefaultState().with(HorizontalBlock.HORIZONTAL_FACING, Direction.EAST).with(TrapDoorBlock.HALF, Half.BOTTOM).with(TrapDoorBlock.WATERLOGGED, false).with(TrapDoorBlock.POWERED, false).with(TrapDoorBlock.OPEN, false), -47, 3, -37, start);
        structure.setBlockState(world, Blocks.OAK_LOG.getDefaultState(), -47, 3, -36, start);
        structure.setBlockState(world, Blocks.SPRUCE_SLAB.getDefaultState().with(SlabBlock.TYPE, SlabType.BOTTOM).with(SlabBlock.WATERLOGGED, false), -47, 3, -16, start);
        structure.setBlockState(world, Blocks.SPRUCE_TRAPDOOR.getDefaultState().with(HorizontalBlock.HORIZONTAL_FACING, Direction.WEST).with(TrapDoorBlock.HALF, Half.BOTTOM).with(TrapDoorBlock.WATERLOGGED, false).with(TrapDoorBlock.POWERED, false).with(TrapDoorBlock.OPEN, false), -47, 3, -15, start);
        structure.setBlockState(world, Blocks.SPRUCE_SLAB.getDefaultState().with(SlabBlock.TYPE, SlabType.BOTTOM).with(SlabBlock.WATERLOGGED, false), -47, 3, -14, start);
        structure.setBlockState(world, Blocks.SPRUCE_TRAPDOOR.getDefaultState().with(HorizontalBlock.HORIZONTAL_FACING, Direction.WEST).with(TrapDoorBlock.HALF, Half.BOTTOM).with(TrapDoorBlock.WATERLOGGED, false).with(TrapDoorBlock.POWERED, false).with(TrapDoorBlock.OPEN, false), -47, 3, -13, start);
        structure.setBlockState(world, Blocks.SPRUCE_SLAB.getDefaultState().with(SlabBlock.TYPE, SlabType.BOTTOM).with(SlabBlock.WATERLOGGED, false), -47, 3, -12, start);
        structure.setBlockState(world, Blocks.SPRUCE_TRAPDOOR.getDefaultState().with(HorizontalBlock.HORIZONTAL_FACING, Direction.WEST).with(TrapDoorBlock.HALF, Half.BOTTOM).with(TrapDoorBlock.WATERLOGGED, false).with(TrapDoorBlock.POWERED, false).with(TrapDoorBlock.OPEN, false), -47, 3, -11, start);
        structure.setBlockState(world, Blocks.SPRUCE_SLAB.getDefaultState().with(SlabBlock.TYPE, SlabType.BOTTOM).with(SlabBlock.WATERLOGGED, false), -47, 3, -10, start);
        structure.setBlockState(world, Blocks.SPRUCE_TRAPDOOR.getDefaultState().with(HorizontalBlock.HORIZONTAL_FACING, Direction.WEST).with(TrapDoorBlock.HALF, Half.BOTTOM).with(TrapDoorBlock.WATERLOGGED, false).with(TrapDoorBlock.POWERED, false).with(TrapDoorBlock.OPEN, false), -47, 3, -9, start);
        structure.setBlockState(world, Blocks.SPRUCE_SLAB.getDefaultState().with(SlabBlock.TYPE, SlabType.BOTTOM).with(SlabBlock.WATERLOGGED, false), -47, 3, -8, start);
        structure.setBlockState(world, Blocks.SPRUCE_TRAPDOOR.getDefaultState().with(HorizontalBlock.HORIZONTAL_FACING, Direction.WEST).with(TrapDoorBlock.HALF, Half.BOTTOM).with(TrapDoorBlock.WATERLOGGED, false).with(TrapDoorBlock.POWERED, false).with(TrapDoorBlock.OPEN, false), -47, 3, -7, start);
        structure.setBlockState(world, Blocks.SPRUCE_TRAPDOOR.getDefaultState().with(HorizontalBlock.HORIZONTAL_FACING, Direction.WEST).with(TrapDoorBlock.HALF, Half.BOTTOM).with(TrapDoorBlock.WATERLOGGED, false).with(TrapDoorBlock.POWERED, false).with(TrapDoorBlock.OPEN, false), -47, 3, 7, start);
        structure.setBlockState(world, Blocks.SPRUCE_SLAB.getDefaultState().with(SlabBlock.TYPE, SlabType.BOTTOM).with(SlabBlock.WATERLOGGED, false), -47, 3, 8, start);
        structure.setBlockState(world, Blocks.SPRUCE_TRAPDOOR.getDefaultState().with(HorizontalBlock.HORIZONTAL_FACING, Direction.WEST).with(TrapDoorBlock.HALF, Half.BOTTOM).with(TrapDoorBlock.WATERLOGGED, false).with(TrapDoorBlock.POWERED, false).with(TrapDoorBlock.OPEN, false), -47, 3, 9, start);
        structure.setBlockState(world, Blocks.SPRUCE_SLAB.getDefaultState().with(SlabBlock.TYPE, SlabType.BOTTOM).with(SlabBlock.WATERLOGGED, false), -47, 3, 10, start);
        structure.setBlockState(world, Blocks.SPRUCE_TRAPDOOR.getDefaultState().with(HorizontalBlock.HORIZONTAL_FACING, Direction.WEST).with(TrapDoorBlock.HALF, Half.BOTTOM).with(TrapDoorBlock.WATERLOGGED, false).with(TrapDoorBlock.POWERED, false).with(TrapDoorBlock.OPEN, false), -47, 3, 11, start);
        structure.setBlockState(world, Blocks.SPRUCE_SLAB.getDefaultState().with(SlabBlock.TYPE, SlabType.BOTTOM).with(SlabBlock.WATERLOGGED, false), -47, 3, 12, start);
        structure.setBlockState(world, Blocks.SPRUCE_TRAPDOOR.getDefaultState().with(HorizontalBlock.HORIZONTAL_FACING, Direction.WEST).with(TrapDoorBlock.HALF, Half.BOTTOM).with(TrapDoorBlock.WATERLOGGED, false).with(TrapDoorBlock.POWERED, false).with(TrapDoorBlock.OPEN, false), -47, 3, 13, start);
        structure.setBlockState(world, Blocks.SPRUCE_SLAB.getDefaultState().with(SlabBlock.TYPE, SlabType.BOTTOM).with(SlabBlock.WATERLOGGED, false), -47, 3, 14, start);
        structure.setBlockState(world, Blocks.SPRUCE_TRAPDOOR.getDefaultState().with(HorizontalBlock.HORIZONTAL_FACING, Direction.WEST).with(TrapDoorBlock.HALF, Half.BOTTOM).with(TrapDoorBlock.WATERLOGGED, false).with(TrapDoorBlock.POWERED, false).with(TrapDoorBlock.OPEN, false), -47, 3, 15, start);
        structure.setBlockState(world, Blocks.SPRUCE_SLAB.getDefaultState().with(SlabBlock.TYPE, SlabType.BOTTOM).with(SlabBlock.WATERLOGGED, false), -47, 3, 16, start);
        structure.setBlockState(world, Blocks.OAK_LOG.getDefaultState(), -47, 3, 36, start);
        structure.setBlockState(world, Blocks.SPRUCE_TRAPDOOR.getDefaultState().with(HorizontalBlock.HORIZONTAL_FACING, Direction.EAST).with(TrapDoorBlock.HALF, Half.BOTTOM).with(TrapDoorBlock.WATERLOGGED, false).with(TrapDoorBlock.POWERED, false).with(TrapDoorBlock.OPEN, false), -47, 3, 37, start);
        structure.setBlockState(world, Blocks.SPRUCE_SLAB.getDefaultState().with(SlabBlock.TYPE, SlabType.BOTTOM).with(SlabBlock.WATERLOGGED, false), -47, 3, 38, start);
        structure.setBlockState(world, Blocks.SPRUCE_TRAPDOOR.getDefaultState().with(HorizontalBlock.HORIZONTAL_FACING, Direction.EAST).with(TrapDoorBlock.HALF, Half.BOTTOM).with(TrapDoorBlock.WATERLOGGED, false).with(TrapDoorBlock.POWERED, false).with(TrapDoorBlock.OPEN, false), -47, 4, -36, start);
        structure.setBlockState(world, Blocks.SPRUCE_SLAB.getDefaultState().with(SlabBlock.TYPE, SlabType.BOTTOM).with(SlabBlock.WATERLOGGED, false), -47, 4, -35, start);
        structure.setBlockState(world, Blocks.SPRUCE_TRAPDOOR.getDefaultState().with(HorizontalBlock.HORIZONTAL_FACING, Direction.EAST).with(TrapDoorBlock.HALF, Half.BOTTOM).with(TrapDoorBlock.WATERLOGGED, false).with(TrapDoorBlock.POWERED, false).with(TrapDoorBlock.OPEN, false), -47, 4, -34, start);
        structure.setBlockState(world, Blocks.SPRUCE_SLAB.getDefaultState().with(SlabBlock.TYPE, SlabType.BOTTOM).with(SlabBlock.WATERLOGGED, false), -47, 4, -33, start);
        structure.setBlockState(world, Blocks.SPRUCE_SLAB.getDefaultState().with(SlabBlock.TYPE, SlabType.BOTTOM).with(SlabBlock.WATERLOGGED, false), -47, 4, 33, start);
        structure.setBlockState(world, Blocks.SPRUCE_TRAPDOOR.getDefaultState().with(HorizontalBlock.HORIZONTAL_FACING, Direction.EAST).with(TrapDoorBlock.HALF, Half.BOTTOM).with(TrapDoorBlock.WATERLOGGED, false).with(TrapDoorBlock.POWERED, false).with(TrapDoorBlock.OPEN, false), -47, 4, 34, start);
        structure.setBlockState(world, Blocks.SPRUCE_SLAB.getDefaultState().with(SlabBlock.TYPE, SlabType.BOTTOM).with(SlabBlock.WATERLOGGED, false), -47, 4, 35, start);
        structure.setBlockState(world, Blocks.SPRUCE_TRAPDOOR.getDefaultState().with(HorizontalBlock.HORIZONTAL_FACING, Direction.EAST).with(TrapDoorBlock.HALF, Half.BOTTOM).with(TrapDoorBlock.WATERLOGGED, false).with(TrapDoorBlock.POWERED, false).with(TrapDoorBlock.OPEN, false), -47, 4, 36, start);
        structure.setBlockState(world, Blocks.STONE.getDefaultState(), -46, -6, -61, start);
        structure.setBlockState(world, Blocks.ANDESITE.getDefaultState(), -46, -6, -44, start);
        structure.setBlockState(world, Blocks.WATER.getDefaultState(), -46, -3, -47, start);
        structure.setBlockState(world, Blocks.WATER.getDefaultState(), -46, -3, -46, start);
        structure.setBlockState(world, Blocks.WATER.getDefaultState(), -46, -3, -45, start);
        structure.setBlockState(world, Blocks.GRASS_BLOCK.getDefaultState().with(SnowyDirtBlock.SNOWY, false), -46, -3, -44, start);
        structure.setBlockState(world, Blocks.GRASS_BLOCK.getDefaultState().with(SnowyDirtBlock.SNOWY, false), -46, -2, -48, start);
        structure.setBlockState(world, Blocks.GRASS_BLOCK.getDefaultState().with(SnowyDirtBlock.SNOWY, false), -46, -1, -43, start);
        structure.setBlockState(world, Blocks.JUNGLE_FENCE_GATE.getDefaultState().with(FenceGateBlock.IN_WALL, false).with(FenceGateBlock.OPEN, false).with(FenceGateBlock.POWERED, false), -46, 0, -43, start);
        structure.setBlockState(world, Blocks.GRASS_BLOCK.getDefaultState().with(SnowyDirtBlock.SNOWY, false), -46, 0, -42, start);
        structure.setBlockState(world, Blocks.JUNGLE_FENCE_GATE.getDefaultState().with(FenceGateBlock.IN_WALL, false).with(FenceGateBlock.OPEN, false).with(FenceGateBlock.POWERED, false), -46, 1, -42, start);
        structure.setBlockState(world, Blocks.JUNGLE_FENCE_GATE.getDefaultState().with(FenceGateBlock.IN_WALL, false).with(FenceGateBlock.OPEN, false).with(FenceGateBlock.POWERED, false), -46, 1, 42, start);
        structure.setBlockState(world, Blocks.SPRUCE_TRAPDOOR.getDefaultState().with(HorizontalBlock.HORIZONTAL_FACING, Direction.WEST).with(TrapDoorBlock.HALF, Half.BOTTOM).with(TrapDoorBlock.WATERLOGGED, false).with(TrapDoorBlock.POWERED, false).with(TrapDoorBlock.OPEN, false), -46, 2, -5, start);
        structure.setBlockState(world, Blocks.SPRUCE_SLAB.getDefaultState().with(SlabBlock.TYPE, SlabType.BOTTOM).with(SlabBlock.WATERLOGGED, false), -46, 2, -4, start);
        structure.setBlockState(world, Blocks.SPRUCE_TRAPDOOR.getDefaultState().with(HorizontalBlock.HORIZONTAL_FACING, Direction.WEST).with(TrapDoorBlock.HALF, Half.BOTTOM).with(TrapDoorBlock.WATERLOGGED, false).with(TrapDoorBlock.POWERED, false).with(TrapDoorBlock.OPEN, false), -46, 2, -3, start);
        structure.setBlockState(world, Blocks.SPRUCE_SLAB.getDefaultState().with(SlabBlock.TYPE, SlabType.BOTTOM).with(SlabBlock.WATERLOGGED, false), -46, 2, -2, start);
        structure.setBlockState(world, Blocks.SPRUCE_SLAB.getDefaultState().with(SlabBlock.TYPE, SlabType.BOTTOM).with(SlabBlock.WATERLOGGED, false), -46, 2, 2, start);
        structure.setBlockState(world, Blocks.SPRUCE_TRAPDOOR.getDefaultState().with(HorizontalBlock.HORIZONTAL_FACING, Direction.WEST).with(TrapDoorBlock.HALF, Half.BOTTOM).with(TrapDoorBlock.WATERLOGGED, false).with(TrapDoorBlock.POWERED, false).with(TrapDoorBlock.OPEN, false), -46, 2, 3, start);
        structure.setBlockState(world, Blocks.SPRUCE_SLAB.getDefaultState().with(SlabBlock.TYPE, SlabType.BOTTOM).with(SlabBlock.WATERLOGGED, false), -46, 2, 4, start);
        structure.setBlockState(world, Blocks.SPRUCE_TRAPDOOR.getDefaultState().with(HorizontalBlock.HORIZONTAL_FACING, Direction.WEST).with(TrapDoorBlock.HALF, Half.BOTTOM).with(TrapDoorBlock.WATERLOGGED, false).with(TrapDoorBlock.POWERED, false).with(TrapDoorBlock.OPEN, false), -46, 2, 5, start);
        structure.setBlockState(world, Blocks.OAK_LOG.getDefaultState(), -46, 2, 17, start);
        structure.setBlockState(world, Blocks.SPRUCE_LOG.getDefaultState(), -46, 2, 18, start);
        structure.setBlockState(world, Blocks.OAK_LOG.getDefaultState(), -46, 2, 19, start);
        structure.setBlockState(world, Blocks.SPRUCE_LOG.getDefaultState(), -46, 2, 20, start);
        structure.setBlockState(world, Blocks.OAK_LOG.getDefaultState(), -46, 2, 21, start);
        structure.setBlockState(world, Blocks.SPRUCE_LOG.getDefaultState(), -46, 2, 22, start);
        structure.setBlockState(world, Blocks.OAK_LOG.getDefaultState(), -46, 2, 23, start);
        structure.setBlockState(world, Blocks.SPRUCE_LOG.getDefaultState(), -46, 2, 24, start);
        structure.setBlockState(world, Blocks.SPRUCE_TRAPDOOR.getDefaultState().with(HorizontalBlock.HORIZONTAL_FACING, Direction.WEST).with(TrapDoorBlock.HALF, Half.BOTTOM).with(TrapDoorBlock.WATERLOGGED, false).with(TrapDoorBlock.POWERED, false).with(TrapDoorBlock.OPEN, false), -46, 3, -41, start);
        structure.setBlockState(world, Blocks.SPRUCE_SLAB.getDefaultState().with(SlabBlock.TYPE, SlabType.BOTTOM).with(SlabBlock.WATERLOGGED, false), -46, 3, -40, start);
        structure.setBlockState(world, Blocks.SPRUCE_TRAPDOOR.getDefaultState().with(HorizontalBlock.HORIZONTAL_FACING, Direction.EAST).with(TrapDoorBlock.HALF, Half.BOTTOM).with(TrapDoorBlock.WATERLOGGED, false).with(TrapDoorBlock.POWERED, false).with(TrapDoorBlock.OPEN, false), -46, 3, -39, start);
        structure.setBlockState(world, Blocks.OAK_LOG.getDefaultState(), -46, 3, -38, start);
        structure.setBlockState(world, Blocks.SPRUCE_SLAB.getDefaultState().with(SlabBlock.TYPE, SlabType.BOTTOM).with(SlabBlock.WATERLOGGED, false), -46, 3, -24, start);
        structure.setBlockState(world, Blocks.SPRUCE_TRAPDOOR.getDefaultState().with(HorizontalBlock.HORIZONTAL_FACING, Direction.WEST).with(TrapDoorBlock.HALF, Half.BOTTOM).with(TrapDoorBlock.WATERLOGGED, false).with(TrapDoorBlock.POWERED, false).with(TrapDoorBlock.OPEN, false), -46, 3, -23, start);
        structure.setBlockState(world, Blocks.SPRUCE_SLAB.getDefaultState().with(SlabBlock.TYPE, SlabType.BOTTOM).with(SlabBlock.WATERLOGGED, false), -46, 3, -22, start);
        structure.setBlockState(world, Blocks.SPRUCE_TRAPDOOR.getDefaultState().with(HorizontalBlock.HORIZONTAL_FACING, Direction.WEST).with(TrapDoorBlock.HALF, Half.BOTTOM).with(TrapDoorBlock.WATERLOGGED, false).with(TrapDoorBlock.POWERED, false).with(TrapDoorBlock.OPEN, false), -46, 3, -21, start);
        structure.setBlockState(world, Blocks.SPRUCE_SLAB.getDefaultState().with(SlabBlock.TYPE, SlabType.BOTTOM).with(SlabBlock.WATERLOGGED, false), -46, 3, -20, start);
        structure.setBlockState(world, Blocks.SPRUCE_TRAPDOOR.getDefaultState().with(HorizontalBlock.HORIZONTAL_FACING, Direction.WEST).with(TrapDoorBlock.HALF, Half.BOTTOM).with(TrapDoorBlock.WATERLOGGED, false).with(TrapDoorBlock.POWERED, false).with(TrapDoorBlock.OPEN, false), -46, 3, -19, start);
        structure.setBlockState(world, Blocks.SPRUCE_SLAB.getDefaultState().with(SlabBlock.TYPE, SlabType.BOTTOM).with(SlabBlock.WATERLOGGED, false), -46, 3, -18, start);
        structure.setBlockState(world, Blocks.SPRUCE_TRAPDOOR.getDefaultState().with(HorizontalBlock.HORIZONTAL_FACING, Direction.WEST).with(TrapDoorBlock.HALF, Half.BOTTOM).with(TrapDoorBlock.WATERLOGGED, false).with(TrapDoorBlock.POWERED, false).with(TrapDoorBlock.OPEN, false), -46, 3, -17, start);
        structure.setBlockState(world, Blocks.SPRUCE_TRAPDOOR.getDefaultState().with(HorizontalBlock.HORIZONTAL_FACING, Direction.WEST).with(TrapDoorBlock.HALF, Half.BOTTOM).with(TrapDoorBlock.WATERLOGGED, false).with(TrapDoorBlock.POWERED, false).with(TrapDoorBlock.OPEN, false), -46, 3, 17, start);
        structure.setBlockState(world, Blocks.SPRUCE_SLAB.getDefaultState().with(SlabBlock.TYPE, SlabType.BOTTOM).with(SlabBlock.WATERLOGGED, false), -46, 3, 18, start);
        structure.setBlockState(world, Blocks.SPRUCE_TRAPDOOR.getDefaultState().with(HorizontalBlock.HORIZONTAL_FACING, Direction.WEST).with(TrapDoorBlock.HALF, Half.BOTTOM).with(TrapDoorBlock.WATERLOGGED, false).with(TrapDoorBlock.POWERED, false).with(TrapDoorBlock.OPEN, false), -46, 3, 19, start);
        structure.setBlockState(world, Blocks.SPRUCE_SLAB.getDefaultState().with(SlabBlock.TYPE, SlabType.BOTTOM).with(SlabBlock.WATERLOGGED, false), -46, 3, 20, start);
        structure.setBlockState(world, Blocks.SPRUCE_TRAPDOOR.getDefaultState().with(HorizontalBlock.HORIZONTAL_FACING, Direction.WEST).with(TrapDoorBlock.HALF, Half.BOTTOM).with(TrapDoorBlock.WATERLOGGED, false).with(TrapDoorBlock.POWERED, false).with(TrapDoorBlock.OPEN, false), -46, 3, 21, start);
        structure.setBlockState(world, Blocks.SPRUCE_SLAB.getDefaultState().with(SlabBlock.TYPE, SlabType.BOTTOM).with(SlabBlock.WATERLOGGED, false), -46, 3, 22, start);
        structure.setBlockState(world, Blocks.SPRUCE_TRAPDOOR.getDefaultState().with(HorizontalBlock.HORIZONTAL_FACING, Direction.WEST).with(TrapDoorBlock.HALF, Half.BOTTOM).with(TrapDoorBlock.WATERLOGGED, false).with(TrapDoorBlock.POWERED, false).with(TrapDoorBlock.OPEN, false), -46, 3, 23, start);
        structure.setBlockState(world, Blocks.SPRUCE_SLAB.getDefaultState().with(SlabBlock.TYPE, SlabType.BOTTOM).with(SlabBlock.WATERLOGGED, false), -46, 3, 24, start);
        structure.setBlockState(world, Blocks.OAK_LOG.getDefaultState(), -46, 3, 38, start);
        structure.setBlockState(world, Blocks.SPRUCE_TRAPDOOR.getDefaultState().with(HorizontalBlock.HORIZONTAL_FACING, Direction.EAST).with(TrapDoorBlock.HALF, Half.BOTTOM).with(TrapDoorBlock.WATERLOGGED, false).with(TrapDoorBlock.POWERED, false).with(TrapDoorBlock.OPEN, false), -46, 3, 39, start);
        structure.setBlockState(world, Blocks.SPRUCE_SLAB.getDefaultState().with(SlabBlock.TYPE, SlabType.BOTTOM).with(SlabBlock.WATERLOGGED, false), -46, 3, 40, start);
        structure.setBlockState(world, Blocks.SPRUCE_TRAPDOOR.getDefaultState().with(HorizontalBlock.HORIZONTAL_FACING, Direction.EAST).with(TrapDoorBlock.HALF, Half.BOTTOM).with(TrapDoorBlock.WATERLOGGED, false).with(TrapDoorBlock.POWERED, false).with(TrapDoorBlock.OPEN, false), -46, 3, 41, start);
