package mod.arcalitegames.odyssey.world.structure.town.saxontown;

import mod.arcalitegames.buildersaddition.Index;
import mod.arcalitegames.buildersaddition.blocks.Cabinet;
import mod.arcalitegames.buildersaddition.blocks.Cupboard;
import mod.arcalitegames.buildersaddition.blocks.IronFence;
import mod.arcalitegames.buildersaddition.blocks.Shelf;
import mod.arcalitegames.buildersaddition.blocks.Stool;
import mod.arcalitegames.buildersaddition.state.StoolState;
import mod.arcalitegames.odyssey.world.structure.StructureBase;
import net.minecraft.block.BarrelBlock;
import net.minecraft.block.BedBlock;
import net.minecraft.block.BeetrootBlock;
import net.minecraft.block.Blocks;
import net.minecraft.block.BrewingStandBlock;
import net.minecraft.block.CauldronBlock;
import net.minecraft.block.ChainBlock;
import net.minecraft.block.CropsBlock;
import net.minecraft.block.FarmlandBlock;
import net.minecraft.block.FenceGateBlock;
import net.minecraft.block.FourWayBlock;
import net.minecraft.block.HorizontalBlock;
import net.minecraft.block.NetherWartBlock;
import net.minecraft.block.RedstoneTorchBlock;
import net.minecraft.block.SlabBlock;
import net.minecraft.block.SnowyDirtBlock;
import net.minecraft.block.StairsBlock;
import net.minecraft.block.TrapDoorBlock;
import net.minecraft.block.WallBlock;
import net.minecraft.block.WallHeight;
import net.minecraft.state.properties.BedPart;
import net.minecraft.state.properties.DoubleBlockHalf;
import net.minecraft.state.properties.Half;
import net.minecraft.state.properties.SlabType;
import net.minecraft.state.properties.StairsShape;
import net.minecraft.util.Direction;
import net.minecraft.util.math.BlockPos;
import net.minecraft.world.World;

public class SaxonTownComponent2
{

	public static BlockPos start;
    public static World world;
    public static StructureBase structure;

    public static void init(World worldIn, BlockPos blockPos, StructureBase structureIn)
    {
        world = worldIn; start = blockPos; structure = structureIn;
    }
    
    public static void generatePart21()
    {
        structure.fillWithBlocks(world, start, 16, -1, -4, 18, -1, -2, Blocks.GRASS_BLOCK.getDefaultState().with(SnowyDirtBlock.SNOWY, false));
        structure.fillWithBlocks(world, start, 16, -1, 6, 17, -1, 8, Blocks.GRASS_BLOCK.getDefaultState().with(SnowyDirtBlock.SNOWY, false));
        structure.fillWithBlocks(world, start, 16, -1, 22, 17, -1, 25, Blocks.GRASS_BLOCK.getDefaultState().with(SnowyDirtBlock.SNOWY, false));
        structure.fillWithBlocks(world, start, 16, -1, 28, 17, -1, 29, Blocks.GRASS_BLOCK.getDefaultState().with(SnowyDirtBlock.SNOWY, false));
        structure.fillWithBlocks(world, start, 16, -1, 30, 16, -1, 31, Blocks.GRASS_BLOCK.getDefaultState().with(SnowyDirtBlock.SNOWY, false));
        structure.fillWithBlocks(world, start, 16, -1, 32, 17, -1, 32, Blocks.COARSE_DIRT.getDefaultState());
        structure.fillWithBlocks(world, start, 16, -1, 52, 18, -1, 54, Blocks.DIRT.getDefaultState());
        structure.fillWithBlocks(world, start, 16, 0, -51, 16, 2, -51, Blocks.OAK_LOG.getDefaultState());
        structure.fillWithBlocks(world, start, 16, 0, -50, 16, 3, -50, Blocks.SPRUCE_LOG.getDefaultState());
        structure.fillWithBlocks(world, start, 16, 0, -47, 16, 2, -47, Blocks.OAK_LOG.getDefaultState());
        structure.fillWithBlocks(world, start, 16, 0, -45, 25, 0, -45, Blocks.DIRT.getDefaultState());
        structure.fillWithBlocks(world, start, 16, 0, -44, 16, 1, -44, Blocks.OAK_LOG.getDefaultState());
        structure.fillWithBlocks(world, start, 16, 0, 9, 17, 0, 9, Blocks.DARK_OAK_PLANKS.getDefaultState());
        structure.fillWithBlocks(world, start, 16, 0, 19, 17, 0, 19, Blocks.DARK_OAK_PLANKS.getDefaultState());
        structure.fillWithBlocks(world, start, 16, 0, 47, 16, 1, 47, Blocks.SPRUCE_LOG.getDefaultState());
        structure.fillWithBlocks(world, start, 16, 0, 52, 16, 3, 52, Blocks.SPRUCE_LOG.getDefaultState());
        structure.fillWithBlocks(world, start, 16, 0, 53, 16, 2, 53, Blocks.OAK_LOG.getDefaultState());
        structure.fillWithBlocks(world, start, 16, 1, -45, 24, 1, -45, Blocks.GRASS_BLOCK.getDefaultState().with(SnowyDirtBlock.SNOWY, false));
        structure.fillWithBlocks(world, start, 16, 1, 9, 17, 2, 9, Blocks.OAK_PLANKS.getDefaultState());
        structure.fillWithBlocks(world, start, 16, 1, 19, 17, 2, 19, Blocks.OAK_PLANKS.getDefaultState());
        structure.fillWithBlocks(world, start, 16, 1, 49, 16, 2, 49, Blocks.SPRUCE_LOG.getDefaultState());
        structure.fillWithBlocks(world, start, 16, 2, -10, 17, 2, -10, Blocks.STONE_STAIRS.getDefaultState().with(StairsBlock.FACING, Direction.SOUTH).with(StairsBlock.WATERLOGGED, false).with(StairsBlock.SHAPE, StairsShape.STRAIGHT).with(StairsBlock.HALF, Half.BOTTOM));
        structure.fillWithBlocks(world, start, 16, 3, -39, 17, 3, -39, Blocks.DARK_OAK_SLAB.getDefaultState().with(SlabBlock.TYPE, SlabType.TOP).with(SlabBlock.WATERLOGGED, false));
        structure.fillWithBlocks(world, start, 16, 3, -37, 17, 3, -37, Blocks.DARK_OAK_SLAB.getDefaultState().with(SlabBlock.TYPE, SlabType.TOP).with(SlabBlock.WATERLOGGED, false));
        structure.fillWithBlocks(world, start, 16, 3, -9, 17, 3, -9, Blocks.STONE_STAIRS.getDefaultState().with(StairsBlock.FACING, Direction.SOUTH).with(StairsBlock.WATERLOGGED, false).with(StairsBlock.SHAPE, StairsShape.STRAIGHT).with(StairsBlock.HALF, Half.BOTTOM));
        structure.fillWithBlocks(world, start, 16, 3, -5, 17, 3, -5, Blocks.STONE_STAIRS.getDefaultState().with(StairsBlock.FACING, Direction.NORTH).with(StairsBlock.WATERLOGGED, false).with(StairsBlock.SHAPE, StairsShape.STRAIGHT).with(StairsBlock.HALF, Half.BOTTOM));
        structure.fillWithBlocks(world, start, 16, 4, -38, 17, 4, -38, Blocks.DARK_OAK_SLAB.getDefaultState().with(SlabBlock.TYPE, SlabType.TOP).with(SlabBlock.WATERLOGGED, false));
        structure.fillWithBlocks(world, start, 16, 4, -8, 16, 4, -8, Blocks.INFESTED_STONE_BRICKS.getDefaultState());
        structure.fillWithBlocks(world, start, 16, 4, -6, 17, 5, -6, Blocks.INFESTED_STONE_BRICKS.getDefaultState());
        structure.fillWithBlocks(world, start, 16, 4, 10, 17, 4, 11, Blocks.OAK_PLANKS.getDefaultState());
        structure.fillWithBlocks(world, start, 16, 4, 17, 17, 4, 18, Blocks.OAK_PLANKS.getDefaultState());
        structure.fillWithBlocks(world, start, 16, 5, -8, 16, 5, -8, Blocks.INFESTED_STONE_BRICKS.getDefaultState());
        structure.fillWithBlocks(world, start, 16, 6, -8, 16, 6, -8, Blocks.INFESTED_STONE_BRICKS.getDefaultState());
        structure.fillWithBlocks(world, start, 16, 6, -6, 17, 7, -6, Blocks.INFESTED_STONE_BRICKS.getDefaultState());
        structure.fillWithBlocks(world, start, 16, 6, 10, 17, 6, 10, Blocks.DARK_OAK_SLAB.getDefaultState().with(SlabBlock.TYPE, SlabType.TOP).with(SlabBlock.WATERLOGGED, false));
        structure.fillWithBlocks(world, start, 16, 6, 18, 30, 6, 18, Blocks.DARK_OAK_SLAB.getDefaultState().with(SlabBlock.TYPE, SlabType.TOP).with(SlabBlock.WATERLOGGED, false));
        structure.fillWithBlocks(world, start, 16, 7, -8, 16, 7, -8, Blocks.INFESTED_STONE_BRICKS.getDefaultState());
        structure.fillWithBlocks(world, start, 16, 8, 10, 24, 8, 10, Blocks.OAK_PLANKS.getDefaultState());
        structure.fillWithBlocks(world, start, 16, 8, 11, 17, 8, 11, Blocks.DARK_OAK_SLAB.getDefaultState().with(SlabBlock.TYPE, SlabType.TOP).with(SlabBlock.WATERLOGGED, false));
        structure.fillWithBlocks(world, start, 16, 8, 17, 17, 8, 17, Blocks.DARK_OAK_SLAB.getDefaultState().with(SlabBlock.TYPE, SlabType.TOP).with(SlabBlock.WATERLOGGED, false));
        structure.fillWithBlocks(world, start, 16, 8, 18, 24, 8, 18, Blocks.OAK_PLANKS.getDefaultState());
        structure.fillWithBlocks(world, start, 16, 9, 10, 24, 9, 10, Blocks.OAK_SLAB.getDefaultState().with(SlabBlock.TYPE, SlabType.BOTTOM).with(SlabBlock.WATERLOGGED, false));
        structure.fillWithBlocks(world, start, 16, 9, 11, 24, 9, 11, Blocks.OAK_PLANKS.getDefaultState());
        structure.fillWithBlocks(world, start, 16, 9, 12, 17, 9, 12, Blocks.DARK_OAK_SLAB.getDefaultState().with(SlabBlock.TYPE, SlabType.TOP).with(SlabBlock.WATERLOGGED, false));
        structure.fillWithBlocks(world, start, 16, 9, 16, 17, 9, 16, Blocks.DARK_OAK_SLAB.getDefaultState().with(SlabBlock.TYPE, SlabType.TOP).with(SlabBlock.WATERLOGGED, false));
        structure.fillWithBlocks(world, start, 16, 9, 17, 24, 9, 17, Blocks.OAK_PLANKS.getDefaultState());
        structure.fillWithBlocks(world, start, 16, 9, 18, 24, 9, 18, Blocks.OAK_SLAB.getDefaultState().with(SlabBlock.TYPE, SlabType.BOTTOM).with(SlabBlock.WATERLOGGED, false));
        structure.fillWithBlocks(world, start, 16, 10, 11, 24, 10, 11, Blocks.OAK_SLAB.getDefaultState().with(SlabBlock.TYPE, SlabType.BOTTOM).with(SlabBlock.WATERLOGGED, false));
        structure.fillWithBlocks(world, start, 16, 10, 12, 24, 10, 12, Blocks.OAK_PLANKS.getDefaultState());
        structure.fillWithBlocks(world, start, 16, 10, 13, 17, 10, 13, Blocks.DARK_OAK_SLAB.getDefaultState().with(SlabBlock.TYPE, SlabType.TOP).with(SlabBlock.WATERLOGGED, false));
        structure.fillWithBlocks(world, start, 16, 10, 15, 17, 10, 15, Blocks.DARK_OAK_SLAB.getDefaultState().with(SlabBlock.TYPE, SlabType.TOP).with(SlabBlock.WATERLOGGED, false));
        structure.fillWithBlocks(world, start, 16, 10, 16, 24, 10, 16, Blocks.OAK_PLANKS.getDefaultState());
        structure.fillWithBlocks(world, start, 16, 10, 17, 24, 10, 17, Blocks.OAK_SLAB.getDefaultState().with(SlabBlock.TYPE, SlabType.BOTTOM).with(SlabBlock.WATERLOGGED, false));
        structure.fillWithBlocks(world, start, 16, 11, 12, 24, 11, 12, Blocks.OAK_SLAB.getDefaultState().with(SlabBlock.TYPE, SlabType.BOTTOM).with(SlabBlock.WATERLOGGED, false));
        structure.fillWithBlocks(world, start, 16, 11, 13, 24, 11, 13, Blocks.OAK_PLANKS.getDefaultState());
        structure.fillWithBlocks(world, start, 16, 11, 15, 24, 11, 15, Blocks.OAK_PLANKS.getDefaultState());
        structure.fillWithBlocks(world, start, 16, 11, 16, 24, 11, 16, Blocks.OAK_SLAB.getDefaultState().with(SlabBlock.TYPE, SlabType.BOTTOM).with(SlabBlock.WATERLOGGED, false));
        structure.fillWithBlocks(world, start, 16, 12, 13, 24, 12, 13, Blocks.OAK_SLAB.getDefaultState().with(SlabBlock.TYPE, SlabType.BOTTOM).with(SlabBlock.WATERLOGGED, false));
        structure.fillWithBlocks(world, start, 16, 12, 15, 24, 12, 15, Blocks.OAK_SLAB.getDefaultState().with(SlabBlock.TYPE, SlabType.BOTTOM).with(SlabBlock.WATERLOGGED, false));
        structure.fillWithBlocks(world, start, 16, 13, 14, 24, 13, 14, Blocks.OAK_SLAB.getDefaultState().with(SlabBlock.TYPE, SlabType.BOTTOM).with(SlabBlock.WATERLOGGED, false));
        structure.fillWithBlocks(world, start, 17, -7, -49, 18, -7, -36, Blocks.STONE.getDefaultState());
        structure.fillWithBlocks(world, start, 17, -7, 25, 25, -7, 33, Blocks.STONE.getDefaultState());
        structure.fillWithBlocks(world, start, 17, -7, 49, 19, -7, 52, Blocks.STONE.getDefaultState());
        structure.fillWithBlocks(world, start, 17, -7, 53, 17, -7, 53, Blocks.IRON_ORE.getDefaultState());
        structure.fillWithBlocks(world, start, 17, -7, 54, 17, -7, 60, Blocks.STONE.getDefaultState());
        structure.fillWithBlocks(world, start, 17, -7, 73, 17, -7, 75, Blocks.DIRT.getDefaultState());
        structure.fillWithBlocks(world, start, 17, -6, -71, 50, -5, -71, Blocks.DIRT.getDefaultState());
        structure.fillWithBlocks(world, start, 17, -6, -70, 19, -6, -68, Blocks.STONE.getDefaultState());
        structure.fillWithBlocks(world, start, 17, -6, -66, 23, -6, -58, Blocks.DIRT.getDefaultState());
        structure.fillWithBlocks(world, start, 17, -6, -56, 18, -6, -55, Blocks.DIRT.getDefaultState());
        structure.fillWithBlocks(world, start, 17, -6, -31, 20, -6, -28, Blocks.DIRT.getDefaultState());
        structure.fillWithBlocks(world, start, 17, -6, 41, 17, -6, 41, Blocks.STONE.getDefaultState());
        structure.fillWithBlocks(world, start, 17, -6, 43, 21, -6, 48, Blocks.STONE.getDefaultState());
        structure.fillWithBlocks(world, start, 17, -6, 53, 17, -6, 53, Blocks.STONE.getDefaultState());
        structure.fillWithBlocks(world, start, 17, -6, 54, 17, -6, 64, Blocks.DIRT.getDefaultState());
        structure.fillWithBlocks(world, start, 17, -6, 65, 20, -6, 69, Blocks.GRANITE.getDefaultState());
        structure.fillWithBlocks(world, start, 17, -6, 71, 18, -6, 71, Blocks.COAL_ORE.getDefaultState());
        structure.fillWithBlocks(world, start, 17, -5, -48, 18, -5, -47, Blocks.STONE.getDefaultState());
        structure.fillWithBlocks(world, start, 17, -5, -19, 19, -5, -17, Blocks.STONE.getDefaultState());
        structure.fillWithBlocks(world, start, 17, -5, 0, 19, -5, 2, Blocks.STONE.getDefaultState());
        structure.fillWithBlocks(world, start, 17, -5, 3, 17, -5, 5, Blocks.STONE.getDefaultState());
        structure.fillWithBlocks(world, start, 17, -5, 6, 17, -5, 23, Blocks.DIRT.getDefaultState());
        structure.fillWithBlocks(world, start, 17, -5, 34, 19, -5, 34, Blocks.STONE.getDefaultState());
        structure.fillWithBlocks(world, start, 17, -5, 35, 28, -5, 46, Blocks.DIRT.getDefaultState());
        structure.fillWithBlocks(world, start, 17, -5, 73, 66, -5, 73, Blocks.DIRT.getDefaultState());
        structure.fillWithBlocks(world, start, 17, -4, -71, 50, -4, -71, Blocks.GRASS_BLOCK.getDefaultState().with(SnowyDirtBlock.SNOWY, false));
        structure.fillWithBlocks(world, start, 17, -4, -56, 17, -4, -55, Blocks.GRASS_BLOCK.getDefaultState().with(SnowyDirtBlock.SNOWY, false));
        structure.fillWithBlocks(world, start, 17, -4, -54, 33, -4, 16, Blocks.DIRT.getDefaultState());
        structure.fillWithBlocks(world, start, 17, -4, 72, 18, -4, 73, Blocks.GRASS_BLOCK.getDefaultState().with(SnowyDirtBlock.SNOWY, false));
        structure.fillWithBlocks(world, start, 17, -3, -56, 17, -3, -56, Blocks.WATER.getDefaultState());
        structure.fillWithBlocks(world, start, 17, -3, -8, 41, -3, 16, Blocks.DIRT.getDefaultState());
        structure.fillWithBlocks(world, start, 17, -3, 26, 17, -3, 26, Blocks.COARSE_DIRT.getDefaultState());
        structure.fillWithBlocks(world, start, 17, -3, 27, 17, -3, 29, Blocks.DIRT.getDefaultState());
        structure.fillWithBlocks(world, start, 17, -3, 30, 17, -1, 32, Blocks.COARSE_DIRT.getDefaultState());
        structure.fillWithBlocks(world, start, 17, -2, -14, 31, -2, 10, Blocks.DIRT.getDefaultState());
        structure.fillWithBlocks(world, start, 17, -2, 26, 17, -2, 26, Blocks.COARSE_DIRT.getDefaultState());
        structure.fillWithBlocks(world, start, 17, -2, 27, 17, -2, 29, Blocks.DIRT.getDefaultState());
        structure.fillWithBlocks(world, start, 17, -1, -52, 18, -1, -44, Blocks.DIRT.getDefaultState());
        structure.fillWithBlocks(world, start, 17, -1, -35, 17, -1, -29, Blocks.GRASS_PATH.getDefaultState());
        structure.fillWithBlocks(world, start, 17, -1, -27, 17, -1, -21, Blocks.GRASS_PATH.getDefaultState());
        structure.fillWithBlocks(world, start, 17, -1, -14, 20, -1, -10, Blocks.GRASS_BLOCK.getDefaultState().with(SnowyDirtBlock.SNOWY, false));
        structure.fillWithBlocks(world, start, 17, -1, -8, 17, -1, -5, Blocks.DIRT.getDefaultState());
        structure.fillWithBlocks(world, start, 17, -1, 2, 17, -1, 8, Blocks.GRASS_BLOCK.getDefaultState().with(SnowyDirtBlock.SNOWY, false));
        structure.fillWithBlocks(world, start, 17, -1, 20, 18, -1, 21, Blocks.GRASS_BLOCK.getDefaultState().with(SnowyDirtBlock.SNOWY, false));
        structure.fillWithBlocks(world, start, 17, -1, 26, 17, -1, 26, Blocks.COARSE_DIRT.getDefaultState());
        structure.fillWithBlocks(world, start, 17, -1, 27, 17, -1, 29, Blocks.GRASS_BLOCK.getDefaultState().with(SnowyDirtBlock.SNOWY, false));
        structure.fillWithBlocks(world, start, 17, 0, -51, 17, 2, -51, Blocks.SPRUCE_LOG.getDefaultState());
        structure.fillWithBlocks(world, start, 17, 0, -50, 17, 3, -50, Blocks.OAK_LOG.getDefaultState());
        structure.fillWithBlocks(world, start, 17, 0, -49, 18, 0, -47, Blocks.DIRT.getDefaultState());
        structure.fillWithBlocks(world, start, 17, 0, -44, 17, 1, -44, Blocks.SPRUCE_LOG.getDefaultState());
        structure.fillWithBlocks(world, start, 17, 0, -36, 17, 2, -36, Blocks.SPRUCE_LOG.getDefaultState());
        structure.fillWithBlocks(world, start, 17, 0, -16, 17, 0, -11, Blocks.COBBLESTONE_WALL.getDefaultState().with(WallBlock.WATERLOGGED, false).with(WallBlock.UP, false).with(WallBlock.WALL_HEIGHT_NORTH, WallHeight.LOW).with(WallBlock.WALL_HEIGHT_SOUTH, WallHeight.LOW).with(WallBlock.WALL_HEIGHT_EAST, WallHeight.LOW).with(WallBlock.WALL_HEIGHT_WEST, WallHeight.LOW));
        structure.fillWithBlocks(world, start, 17, 0, -9, 17, 2, -9, Blocks.SMOOTH_STONE.getDefaultState());
        structure.fillWithBlocks(world, start, 17, 0, -8, 17, 2, -6, Blocks.STONE_BRICKS.getDefaultState());
        structure.fillWithBlocks(world, start, 17, 0, -5, 17, 2, -5, Blocks.SMOOTH_STONE.getDefaultState());
        structure.fillWithBlocks(world, start, 17, 0, -2, 17, 1, -2, Blocks.SPRUCE_FENCE.getDefaultState().with(FourWayBlock.WATERLOGGED, false).with(FourWayBlock.NORTH, false).with(FourWayBlock.SOUTH, false).with(FourWayBlock.EAST, false).with(FourWayBlock.WEST, false));
        structure.fillWithBlocks(world, start, 17, 0, 47, 17, 1, 47, Blocks.OAK_LOG.getDefaultState());
        structure.fillWithBlocks(world, start, 17, 0, 52, 17, 3, 52, Blocks.OAK_LOG.getDefaultState());
        structure.fillWithBlocks(world, start, 17, 0, 53, 17, 2, 53, Blocks.SPRUCE_LOG.getDefaultState());
        structure.fillWithBlocks(world, start, 17, 1, -49, 18, 1, -47, Blocks.DIRT.getDefaultState());
        structure.fillWithBlocks(world, start, 17, 1, 49, 17, 2, 49, Blocks.OAK_LOG.getDefaultState());
        structure.fillWithBlocks(world, start, 17, 2, -47, 25, 2, -47, Blocks.GRASS_BLOCK.getDefaultState().with(SnowyDirtBlock.SNOWY, false));
        structure.fillWithBlocks(world, start, 17, 3, -41, 18, 3, -40, Blocks.OAK_PLANKS.getDefaultState());
        structure.fillWithBlocks(world, start, 17, 3, -35, 19, 3, -35, Blocks.OAK_PLANKS.getDefaultState());
        structure.fillWithBlocks(world, start, 17, 4, -40, 18, 4, -39, Blocks.OAK_PLANKS.getDefaultState());
        structure.fillWithBlocks(world, start, 17, 4, -36, 19, 4, -36, Blocks.OAK_PLANKS.getDefaultState());
        structure.fillWithBlocks(world, start, 17, 4, -8, 17, 6, -6, Blocks.INFESTED_STONE_BRICKS.getDefaultState());
        structure.fillWithBlocks(world, start, 17, 5, -39, 19, 5, -37, Blocks.OAK_PLANKS.getDefaultState());
        structure.fillWithBlocks(world, start, 17, 6, -38, 19, 6, -38, Blocks.OAK_PLANKS.getDefaultState());
        structure.fillWithBlocks(world, start, 17, 7, -8, 17, 7, -6, Blocks.INFESTED_STONE_BRICKS.getDefaultState());
        structure.fillWithBlocks(world, start, 18, -7, -73, 19, -7, -72, Blocks.DIRT.getDefaultState());
        structure.fillWithBlocks(world, start, 18, -7, -71, 27, -7, -57, Blocks.STONE.getDefaultState());
        structure.fillWithBlocks(world, start, 18, -7, -56, 18, -7, -55, Blocks.COAL_ORE.getDefaultState());
        structure.fillWithBlocks(world, start, 18, -7, -54, 20, -7, -52, Blocks.STONE.getDefaultState());
        structure.fillWithBlocks(world, start, 18, -7, -51, 18, -7, -36, Blocks.STONE.getDefaultState());
        structure.fillWithBlocks(world, start, 18, -7, -35, 19, -7, -34, Blocks.GRANITE.getDefaultState());
        structure.fillWithBlocks(world, start, 18, -7, -33, 18, -7, 52, Blocks.STONE.getDefaultState());
        structure.fillWithBlocks(world, start, 18, -7, 53, 18, -7, 54, Blocks.IRON_ORE.getDefaultState());
        structure.fillWithBlocks(world, start, 18, -7, 55, 22, -7, 59, Blocks.STONE.getDefaultState());
        structure.fillWithBlocks(world, start, 18, -7, 65, 20, -7, 69, Blocks.GRANITE.getDefaultState());
        structure.fillWithBlocks(world, start, 18, -7, 70, 18, -6, 71, Blocks.COAL_ORE.getDefaultState());
        structure.fillWithBlocks(world, start, 18, -7, 74, 20, -7, 76, Blocks.DIRT.getDefaultState());
        structure.fillWithBlocks(world, start, 18, -7, 77, 20, -7, 79, Blocks.GRASS_BLOCK.getDefaultState().with(SnowyDirtBlock.SNOWY, false));
        structure.fillWithBlocks(world, start, 18, -6, -67, 23, -6, -57, Blocks.DIRT.getDefaultState());
        structure.fillWithBlocks(world, start, 18, -6, -54, 18, -6, -51, Blocks.STONE.getDefaultState());
        structure.fillWithBlocks(world, start, 18, -6, -50, 19, -6, -49, Blocks.ANDESITE.getDefaultState());
        structure.fillWithBlocks(world, start, 18, -6, -48, 18, -5, -46, Blocks.STONE.getDefaultState());
        structure.fillWithBlocks(world, start, 18, -6, -37, 18, -6, -36, Blocks.STONE.getDefaultState());
        structure.fillWithBlocks(world, start, 18, -6, -35, 19, -6, -34, Blocks.GRANITE.getDefaultState());
        structure.fillWithBlocks(world, start, 18, -6, -32, 20, -6, -28, Blocks.DIRT.getDefaultState());
        structure.fillWithBlocks(world, start, 18, -6, -26, 26, -6, -9, Blocks.STONE.getDefaultState());
        structure.fillWithBlocks(world, start, 18, -6, 7, 19, -6, 8, Blocks.STONE.getDefaultState());
        structure.fillWithBlocks(world, start, 18, -6, 10, 19, -6, 11, Blocks.DIRT.getDefaultState());
        structure.fillWithBlocks(world, start, 18, -6, 12, 18, -6, 12, Blocks.STONE.getDefaultState());
        structure.fillWithBlocks(world, start, 18, -6, 13, 18, -6, 17, Blocks.DIRT.getDefaultState());
        structure.fillWithBlocks(world, start, 18, -6, 18, 27, -6, 33, Blocks.STONE.getDefaultState());
        structure.fillWithBlocks(world, start, 18, -6, 40, 21, -6, 48, Blocks.STONE.getDefaultState());
        structure.fillWithBlocks(world, start, 18, -6, 53, 19, -6, 54, Blocks.STONE.getDefaultState());
        structure.fillWithBlocks(world, start, 18, -6, 64, 21, -6, 67, Blocks.GRANITE.getDefaultState());
        structure.fillWithBlocks(world, start, 18, -6, 76, 28, -6, 76, Blocks.GRASS_BLOCK.getDefaultState().with(SnowyDirtBlock.SNOWY, false));
        structure.fillWithBlocks(world, start, 18, -5, -52, 26, -2, -52, Blocks.DIRT.getDefaultState());
        structure.fillWithBlocks(world, start, 18, -5, -51, 19, -5, -49, Blocks.ANDESITE.getDefaultState());
        structure.fillWithBlocks(world, start, 18, -5, -44, 19, -5, -21, Blocks.DIRT.getDefaultState());
        structure.fillWithBlocks(world, start, 18, -5, -20, 18, -2, -20, Blocks.DIRT.getDefaultState());
        structure.fillWithBlocks(world, start, 18, -5, -16, 21, -5, -16, Blocks.STONE.getDefaultState());
        structure.fillWithBlocks(world, start, 18, -5, -15, 19, -5, -3, Blocks.DIRT.getDefaultState());
        structure.fillWithBlocks(world, start, 18, -5, -2, 20, -5, 2, Blocks.STONE.getDefaultState());
        structure.fillWithBlocks(world, start, 18, -5, 4, 18, -5, 4, Blocks.COAL_ORE.getDefaultState());
        structure.fillWithBlocks(world, start, 18, -5, 5, 18, -5, 6, Blocks.STONE.getDefaultState());
        structure.fillWithBlocks(world, start, 18, -5, 7, 30, -5, 21, Blocks.DIRT.getDefaultState());
        structure.fillWithBlocks(world, start, 18, -5, 22, 19, -5, 23, Blocks.DIRT.getDefaultState());
        structure.fillWithBlocks(world, start, 18, -4, -56, 21, -4, 56, Blocks.DIRT.getDefaultState());
        structure.fillWithBlocks(world, start, 18, -4, 57, 18, -4, 57, Blocks.GRASS_BLOCK.getDefaultState().with(SnowyDirtBlock.SNOWY, false));
        structure.fillWithBlocks(world, start, 18, -4, 58, 18, -4, 71, Blocks.DIRT.getDefaultState());
        structure.fillWithBlocks(world, start, 18, -3, 26, 18, -2, 27, Blocks.COARSE_DIRT.getDefaultState());
        structure.fillWithBlocks(world, start, 18, -3, 28, 18, -2, 29, Blocks.DIRT.getDefaultState());
        structure.fillWithBlocks(world, start, 18, -3, 30, 20, -1, 30, Blocks.COARSE_DIRT.getDefaultState());
        structure.fillWithBlocks(world, start, 18, -3, 31, 19, -3, 56, Blocks.DIRT.getDefaultState());
        structure.fillWithBlocks(world, start, 18, -2, 31, 19, -2, 55, Blocks.DIRT.getDefaultState());
        structure.fillWithBlocks(world, start, 18, -1, -39, 20, -1, -37, Blocks.COBBLESTONE.getDefaultState());
        structure.fillWithBlocks(world, start, 18, -1, -35, 19, -1, -34, Blocks.GRASS_BLOCK.getDefaultState().with(SnowyDirtBlock.SNOWY, false));
        structure.fillWithBlocks(world, start, 18, -1, -32, 30, -1, -32, Blocks.GRASS_BLOCK.getDefaultState().with(SnowyDirtBlock.SNOWY, false));
        structure.fillWithBlocks(world, start, 18, -1, -31, 18, -1, -25, Blocks.DIRT.getDefaultState());
        structure.fillWithBlocks(world, start, 18, -1, -24, 18, -1, -24, Blocks.GRASS_BLOCK.getDefaultState().with(SnowyDirtBlock.SNOWY, false));
        structure.fillWithBlocks(world, start, 18, -1, -9, 20, -1, -2, Blocks.GRASS_BLOCK.getDefaultState().with(SnowyDirtBlock.SNOWY, false));
        structure.fillWithBlocks(world, start, 18, -1, -1, 21, -1, 3, Blocks.GRASS_PATH.getDefaultState());
        structure.fillWithBlocks(world, start, 18, -1, 4, 18, -1, 5, Blocks.GRASS_BLOCK.getDefaultState().with(SnowyDirtBlock.SNOWY, false));
        structure.fillWithBlocks(world, start, 18, -1, 7, 18, -1, 8, Blocks.GRASS_BLOCK.getDefaultState().with(SnowyDirtBlock.SNOWY, false));
        structure.fillWithBlocks(world, start, 18, -1, 23, 20, -1, 25, Blocks.GRASS_BLOCK.getDefaultState().with(SnowyDirtBlock.SNOWY, false));
        structure.fillWithBlocks(world, start, 18, -1, 26, 18, -1, 27, Blocks.COARSE_DIRT.getDefaultState());
        structure.fillWithBlocks(world, start, 18, -1, 28, 18, -1, 29, Blocks.GRASS_BLOCK.getDefaultState().with(SnowyDirtBlock.SNOWY, false));
        structure.fillWithBlocks(world, start, 18, -1, 31, 19, -1, 45, Blocks.GRASS_BLOCK.getDefaultState().with(SnowyDirtBlock.SNOWY, false));
        structure.fillWithBlocks(world, start, 18, 0, -51, 18, 2, -51, Blocks.OAK_LOG.getDefaultState());
        structure.fillWithBlocks(world, start, 18, 0, -50, 19, 1, -50, Blocks.SPRUCE_LOG.getDefaultState());
        structure.fillWithBlocks(world, start, 18, 0, -46, 18, 2, -46, Blocks.OAK_LOG.getDefaultState());
        structure.fillWithBlocks(world, start, 18, 0, -44, 18, 1, -44, Blocks.OAK_LOG.getDefaultState());
        structure.fillWithBlocks(world, start, 18, 0, -40, 18, 2, -40, Blocks.SPRUCE_LOG.getDefaultState());
        structure.fillWithBlocks(world, start, 18, 0, -31, 18, 2, -31, Blocks.SPRUCE_LOG.getDefaultState());
        structure.fillWithBlocks(world, start, 18, 0, -30, 18, 1, -29, Blocks.OAK_PLANKS.getDefaultState());
        structure.fillWithBlocks(world, start, 18, 0, -28, 18, 5, -28, Blocks.SPRUCE_LOG.getDefaultState());
        structure.fillWithBlocks(world, start, 18, 0, -27, 18, 1, -26, Blocks.OAK_PLANKS.getDefaultState());
        structure.fillWithBlocks(world, start, 18, 0, -25, 18, 2, -25, Blocks.SPRUCE_LOG.getDefaultState());
        structure.fillWithBlocks(world, start, 18, 0, 9, 19, 1, 9, Blocks.SPRUCE_LOG.getDefaultState());
        structure.fillWithBlocks(world, start, 18, 0, 19, 19, 1, 19, Blocks.SPRUCE_LOG.getDefaultState());
        structure.fillWithBlocks(world, start, 18, 0, 47, 18, 1, 47, Blocks.SPRUCE_LOG.getDefaultState());
        structure.fillWithBlocks(world, start, 18, 0, 52, 18, 3, 52, Blocks.SPRUCE_LOG.getDefaultState());
        structure.fillWithBlocks(world, start, 18, 0, 53, 18, 2, 53, Blocks.OAK_LOG.getDefaultState());
        structure.fillWithBlocks(world, start, 18, 1, 49, 18, 2, 49, Blocks.SPRUCE_LOG.getDefaultState());
        structure.fillWithBlocks(world, start, 18, 2, -50, 19, 2, -50, Blocks.SPRUCE_LOG.getDefaultState());
        structure.fillWithBlocks(world, start, 18, 2, -48, 26, 2, -48, Blocks.DIRT.getDefaultState());
        structure.fillWithBlocks(world, start, 18, 2, -32, 21, 2, -32, Blocks.OAK_PLANKS.getDefaultState());
        structure.fillWithBlocks(world, start, 18, 2, -30, 18, 2, -25, Blocks.SPRUCE_LOG.getDefaultState());
        structure.fillWithBlocks(world, start, 18, 2, -24, 21, 2, -24, Blocks.OAK_PLANKS.getDefaultState());
        structure.fillWithBlocks(world, start, 18, 2, 9, 19, 3, 9, Blocks.SPRUCE_LOG.getDefaultState());
        structure.fillWithBlocks(world, start, 18, 2, 19, 19, 3, 19, Blocks.SPRUCE_LOG.getDefaultState());
        structure.fillWithBlocks(world, start, 18, 3, -48, 26, 3, -48, Blocks.SPRUCE_SLAB.getDefaultState().with(SlabBlock.TYPE, SlabType.BOTTOM).with(SlabBlock.WATERLOGGED, false));
        structure.fillWithBlocks(world, start, 18, 3, -31, 18, 3, -29, Blocks.OAK_PLANKS.getDefaultState());
        structure.fillWithBlocks(world, start, 18, 3, -27, 18, 4, -26, Blocks.OAK_PLANKS.getDefaultState());
        structure.fillWithBlocks(world, start, 18, 3, -25, 28, 3, -25, Blocks.OAK_PLANKS.getDefaultState());
        structure.fillWithBlocks(world, start, 18, 3, 7, 18, 4, 8, Blocks.OAK_PLANKS.getDefaultState());
        structure.fillWithBlocks(world, start, 18, 4, -30, 18, 4, -29, Blocks.OAK_PLANKS.getDefaultState());
        structure.fillWithBlocks(world, start, 18, 4, 10, 19, 4, 11, Blocks.OAK_PLANKS.getDefaultState());
        structure.fillWithBlocks(world, start, 18, 4, 17, 19, 4, 18, Blocks.OAK_PLANKS.getDefaultState());
        structure.fillWithBlocks(world, start, 18, 5, -29, 28, 5, -29, Blocks.OAK_PLANKS.getDefaultState());
        structure.fillWithBlocks(world, start, 18, 5, -27, 28, 5, -27, Blocks.OAK_PLANKS.getDefaultState());
        structure.fillWithBlocks(world, start, 18, 6, -28, 28, 6, -28, Blocks.OAK_PLANKS.getDefaultState());
        structure.fillWithBlocks(world, start, 19, -7, -56, 23, -7, -52, Blocks.STONE.getDefaultState());
        structure.fillWithBlocks(world, start, 19, -7, -50, 22, -7, -47, Blocks.ANDESITE.getDefaultState());
        structure.fillWithBlocks(world, start, 19, -7, -46, 19, -7, -45, Blocks.IRON_ORE.getDefaultState());
        structure.fillWithBlocks(world, start, 19, -7, -44, 19, -6, -37, Blocks.STONE.getDefaultState());
        structure.fillWithBlocks(world, start, 19, -7, -36, 22, -7, -31, Blocks.GRANITE.getDefaultState());
        structure.fillWithBlocks(world, start, 19, -7, -30, 19, -7, 59, Blocks.STONE.getDefaultState());
        structure.fillWithBlocks(world, start, 19, -7, 60, 20, -7, 69, Blocks.GRANITE.getDefaultState());
        structure.fillWithBlocks(world, start, 19, -7, 70, 19, -7, 71, Blocks.GRANITE.getDefaultState());
        structure.fillWithBlocks(world, start, 19, -7, 72, 20, -7, 73, Blocks.STONE.getDefaultState());
        structure.fillWithBlocks(world, start, 19, -6, -56, 19, -6, -54, Blocks.DIRT.getDefaultState());
        structure.fillWithBlocks(world, start, 19, -6, -53, 19, -6, -52, Blocks.STONE.getDefaultState());
        structure.fillWithBlocks(world, start, 19, -6, -51, 22, -6, -47, Blocks.ANDESITE.getDefaultState());
        structure.fillWithBlocks(world, start, 19, -6, -46, 19, -5, -45, Blocks.STONE.getDefaultState());
        structure.fillWithBlocks(world, start, 19, -6, -36, 20, -6, -35, Blocks.GRANITE.getDefaultState());
        structure.fillWithBlocks(world, start, 19, -6, -33, 21, -6, -30, Blocks.DIRT.getDefaultState());
        structure.fillWithBlocks(world, start, 19, -6, 4, 20, -6, 5, Blocks.COAL_ORE.getDefaultState());
        structure.fillWithBlocks(world, start, 19, -6, 6, 20, -6, 7, Blocks.STONE.getDefaultState());
        structure.fillWithBlocks(world, start, 19, -6, 9, 21, -6, 11, Blocks.DIRT.getDefaultState());
        structure.fillWithBlocks(world, start, 19, -6, 12, 19, -6, 13, Blocks.STONE.getDefaultState());
        structure.fillWithBlocks(world, start, 19, -6, 14, 19, -6, 17, Blocks.DIRT.getDefaultState());
        structure.fillWithBlocks(world, start, 19, -6, 49, 19, -6, 49, Blocks.IRON_ORE.getDefaultState());
        structure.fillWithBlocks(world, start, 19, -6, 50, 19, -6, 55, Blocks.STONE.getDefaultState());
        structure.fillWithBlocks(world, start, 19, -6, 56, 19, -6, 62, Blocks.DIRT.getDefaultState());
        structure.fillWithBlocks(world, start, 19, -6, 63, 21, -6, 67, Blocks.GRANITE.getDefaultState());
        structure.fillWithBlocks(world, start, 19, -6, 72, 38, -6, 72, Blocks.STONE.getDefaultState());
        structure.fillWithBlocks(world, start, 19, -5, -48, 20, -5, -47, Blocks.ANDESITE.getDefaultState());
        structure.fillWithBlocks(world, start, 19, -5, -20, 22, -5, -17, Blocks.STONE.getDefaultState());
        structure.fillWithBlocks(world, start, 19, -5, 3, 19, -5, 5, Blocks.COAL_ORE.getDefaultState());
        structure.fillWithBlocks(world, start, 19, -5, 6, 30, -5, 21, Blocks.DIRT.getDefaultState());
        structure.fillWithBlocks(world, start, 19, -5, 24, 29, -2, 24, Blocks.DIRT.getDefaultState());
        structure.fillWithBlocks(world, start, 19, -5, 25, 20, -5, 33, Blocks.STONE.getDefaultState());
        structure.fillWithBlocks(world, start, 19, -4, 57, 20, -4, 58, Blocks.GRASS_BLOCK.getDefaultState().with(SnowyDirtBlock.SNOWY, false));
        structure.fillWithBlocks(world, start, 19, -4, 72, 65, -4, 72, Blocks.DIRT.getDefaultState());
        structure.fillWithBlocks(world, start, 19, -4, 73, 24, -4, 73, Blocks.GRASS_BLOCK.getDefaultState().with(SnowyDirtBlock.SNOWY, false));
        structure.fillWithBlocks(world, start, 19, -3, -53, 26, -3, 27, Blocks.DIRT.getDefaultState());
        structure.fillWithBlocks(world, start, 19, -3, 28, 20, -3, 30, Blocks.COARSE_DIRT.getDefaultState());
        structure.fillWithBlocks(world, start, 19, -3, 72, 27, -3, 72, Blocks.GRASS_BLOCK.getDefaultState().with(SnowyDirtBlock.SNOWY, false));
        structure.fillWithBlocks(world, start, 19, -2, -53, 26, -2, -53, Blocks.GRASS_BLOCK.getDefaultState().with(SnowyDirtBlock.SNOWY, false));
        structure.fillWithBlocks(world, start, 19, -2, -51, 32, -2, -30, Blocks.DIRT.getDefaultState());
        structure.fillWithBlocks(world, start, 19, -2, -29, 22, -2, -26, Blocks.DIRT.getDefaultState());
        structure.fillWithBlocks(world, start, 19, -2, 26, 20, -2, 27, Blocks.DIRT.getDefaultState());
        structure.fillWithBlocks(world, start, 19, -2, 28, 20, -2, 30, Blocks.COARSE_DIRT.getDefaultState());
        structure.fillWithBlocks(world, start, 19, -1, -52, 26, -1, -52, Blocks.GRASS_BLOCK.getDefaultState().with(SnowyDirtBlock.SNOWY, false));
        structure.fillWithBlocks(world, start, 19, -1, -51, 26, -1, -44, Blocks.DIRT.getDefaultState());
        structure.fillWithBlocks(world, start, 19, -1, -43, 21, -1, -41, Blocks.GRASS_BLOCK.getDefaultState().with(SnowyDirtBlock.SNOWY, false));
        structure.fillWithBlocks(world, start, 19, -1, -36, 22, -1, -36, Blocks.DIRT.getDefaultState());
        structure.fillWithBlocks(world, start, 19, -1, -33, 20, -1, -32, Blocks.GRASS_BLOCK.getDefaultState().with(SnowyDirtBlock.SNOWY, false));
        structure.fillWithBlocks(world, start, 19, -1, -31, 22, -1, -31, Blocks.DIRT.getDefaultState());
        structure.fillWithBlocks(world, start, 19, -1, -30, 23, -1, -26, Blocks.COBBLESTONE.getDefaultState());
        structure.fillWithBlocks(world, start, 19, -1, -25, 20, -1, -25, Blocks.DIRT.getDefaultState());
        structure.fillWithBlocks(world, start, 19, -1, -24, 20, -1, -23, Blocks.GRASS_BLOCK.getDefaultState().with(SnowyDirtBlock.SNOWY, false));
        structure.fillWithBlocks(world, start, 19, -1, -22, 19, -1, -21, Blocks.GRASS_PATH.getDefaultState());
        structure.fillWithBlocks(world, start, 19, -1, -20, 22, -1, -11, Blocks.GRASS_BLOCK.getDefaultState().with(SnowyDirtBlock.SNOWY, false));
        structure.fillWithBlocks(world, start, 19, -1, 4, 21, -1, 8, Blocks.GRASS_PATH.getDefaultState());
        structure.fillWithBlocks(world, start, 19, -1, 10, 27, -1, 18, Blocks.COBBLESTONE.getDefaultState());
        structure.fillWithBlocks(world, start, 19, -1, 20, 21, -1, 27, Blocks.GRASS_BLOCK.getDefaultState().with(SnowyDirtBlock.SNOWY, false));
        structure.fillWithBlocks(world, start, 19, -1, 28, 20, -1, 30, Blocks.COARSE_DIRT.getDefaultState());
        structure.fillWithBlocks(world, start, 19, -1, 46, 22, -1, 49, Blocks.DIRT.getDefaultState());
        structure.fillWithBlocks(world, start, 19, -1, 50, 21, 0, 50, Blocks.DIRT.getDefaultState());
        structure.fillWithBlocks(world, start, 19, -1, 52, 21, -1, 54, Blocks.DIRT.getDefaultState());
        structure.fillWithBlocks(world, start, 19, 0, -51, 26, 0, -51, Blocks.GRASS_BLOCK.getDefaultState().with(SnowyDirtBlock.SNOWY, false));
        structure.fillWithBlocks(world, start, 19, 0, -49, 19, 3, -49, Blocks.OAK_LOG.getDefaultState());
        structure.fillWithBlocks(world, start, 19, 0, -48, 20, 0, -47, Blocks.DIRT.getDefaultState());
        structure.fillWithBlocks(world, start, 19, 0, -46, 19, 2, -46, Blocks.SPRUCE_LOG.getDefaultState());
        structure.fillWithBlocks(world, start, 19, 0, -44, 19, 1, -44, Blocks.SPRUCE_LOG.getDefaultState());
        structure.fillWithBlocks(world, start, 19, 0, -40, 21, 1, -40, Blocks.OAK_PLANKS.getDefaultState());
        structure.fillWithBlocks(world, start, 19, 0, -36, 19, 2, -36, Blocks.SPRUCE_LOG.getDefaultState());
        structure.fillWithBlocks(world, start, 19, 0, -31, 21, 1, -31, Blocks.OAK_PLANKS.getDefaultState());
        structure.fillWithBlocks(world, start, 19, 0, -25, 21, 1, -25, Blocks.OAK_PLANKS.getDefaultState());
        structure.fillWithBlocks(world, start, 19, 0, 46, 19, 1, 46, Blocks.OAK_LOG.getDefaultState());
        structure.fillWithBlocks(world, start, 19, 0, 47, 19, 0, 48, Blocks.DIRT.getDefaultState());
        structure.fillWithBlocks(world, start, 19, 0, 49, 19, 2, 49, Blocks.OAK_LOG.getDefaultState());
        structure.fillWithBlocks(world, start, 19, 0, 52, 19, 3, 52, Blocks.OAK_LOG.getDefaultState());
        structure.fillWithBlocks(world, start, 19, 0, 53, 19, 2, 53, Blocks.SPRUCE_LOG.getDefaultState());
        structure.fillWithBlocks(world, start, 19, 1, -48, 20, 1, -47, Blocks.DIRT.getDefaultState());
        structure.fillWithBlocks(world, start, 19, 1, 47, 19, 1, 48, Blocks.GRASS_BLOCK.getDefaultState().with(SnowyDirtBlock.SNOWY, false));
        structure.fillWithBlocks(world, start, 19, 2, -31, 28, 2, -31, Blocks.SPRUCE_LOG.getDefaultState());
        structure.fillWithBlocks(world, start, 19, 2, -25, 28, 2, -25, Blocks.SPRUCE_LOG.getDefaultState());
        structure.fillWithBlocks(world, start, 19, 3, -41, 19, 3, -40, Blocks.OAK_PLANKS.getDefaultState());
        structure.fillWithBlocks(world, start, 19, 3, -39, 20, 3, -39, Blocks.DARK_OAK_SLAB.getDefaultState().with(SlabBlock.TYPE, SlabType.TOP).with(SlabBlock.WATERLOGGED, false));
        structure.fillWithBlocks(world, start, 19, 3, -37, 20, 3, -37, Blocks.DARK_OAK_SLAB.getDefaultState().with(SlabBlock.TYPE, SlabType.TOP).with(SlabBlock.WATERLOGGED, false));
        structure.fillWithBlocks(world, start, 19, 3, -31, 28, 3, -31, Blocks.OAK_PLANKS.getDefaultState());
        structure.fillWithBlocks(world, start, 19, 4, -40, 19, 4, -39, Blocks.OAK_PLANKS.getDefaultState());
        structure.fillWithBlocks(world, start, 19, 4, -38, 20, 4, -38, Blocks.DARK_OAK_SLAB.getDefaultState().with(SlabBlock.TYPE, SlabType.TOP).with(SlabBlock.WATERLOGGED, false));
        structure.fillWithBlocks(world, start, 19, 4, -30, 28, 4, -30, Blocks.OAK_PLANKS.getDefaultState());
        structure.fillWithBlocks(world, start, 19, 4, -26, 28, 4, -26, Blocks.OAK_PLANKS.getDefaultState());
        structure.fillWithBlocks(world, start, 19, 5, 7, 19, 6, 9, Blocks.OAK_PLANKS.getDefaultState());
        structure.fillWithBlocks(world, start, 19, 5, 20, 19, 5, 21, Blocks.OAK_PLANKS.getDefaultState());
        structure.fillWithBlocks(world, start, 19, 6, 10, 21, 6, 10, Blocks.DARK_OAK_SLAB.getDefaultState().with(SlabBlock.TYPE, SlabType.TOP).with(SlabBlock.WATERLOGGED, false));
        structure.fillWithBlocks(world, start, 19, 6, 20, 19, 6, 21, Blocks.OAK_STAIRS.getDefaultState().with(StairsBlock.FACING, Direction.EAST).with(StairsBlock.WATERLOGGED, false).with(StairsBlock.SHAPE, StairsShape.STRAIGHT).with(StairsBlock.HALF, Half.BOTTOM));
        structure.fillWithBlocks(world, start, 19, 8, 11, 21, 8, 11, Blocks.DARK_OAK_SLAB.getDefaultState().with(SlabBlock.TYPE, SlabType.TOP).with(SlabBlock.WATERLOGGED, false));
        structure.fillWithBlocks(world, start, 19, 8, 17, 21, 8, 17, Blocks.DARK_OAK_SLAB.getDefaultState().with(SlabBlock.TYPE, SlabType.TOP).with(SlabBlock.WATERLOGGED, false));
        structure.fillWithBlocks(world, start, 19, 9, 16, 21, 9, 16, Blocks.DARK_OAK_SLAB.getDefaultState().with(SlabBlock.TYPE, SlabType.TOP).with(SlabBlock.WATERLOGGED, false));
        structure.fillWithBlocks(world, start, 19, 11, 14, 19, 11, 15, Blocks.OAK_PLANKS.getDefaultState());
        structure.fillWithBlocks(world, start, 20, -7, -73, 21, -7, -72, Blocks.DIRT.getDefaultState());
        structure.fillWithBlocks(world, start, 20, -7, -51, 22, -7, -44, Blocks.ANDESITE.getDefaultState());
        structure.fillWithBlocks(world, start, 20, -7, -43, 21, -7, -43, Blocks.ANDESITE.getDefaultState());
        structure.fillWithBlocks(world, start, 20, -7, -42, 25, -7, -37, Blocks.STONE.getDefaultState());
        structure.fillWithBlocks(world, start, 20, -7, -30, 21, -7, -29, Blocks.GRANITE.getDefaultState());
        structure.fillWithBlocks(world, start, 20, -7, -9, 26, -7, -3, Blocks.STONE.getDefaultState());
        structure.fillWithBlocks(world, start, 20, -7, 24, 29, -7, 33, Blocks.STONE.getDefaultState());
        structure.fillWithBlocks(world, start, 20, -7, 49, 20, -6, 49, Blocks.IRON_ORE.getDefaultState());
        structure.fillWithBlocks(world, start, 20, -7, 50, 29, -7, 59, Blocks.STONE.getDefaultState());
        structure.fillWithBlocks(world, start, 20, -7, 70, 23, -7, 73, Blocks.STONE.getDefaultState());
        structure.fillWithBlocks(world, start, 20, -6, -70, 21, -6, -69, Blocks.STONE.getDefaultState());
        structure.fillWithBlocks(world, start, 20, -6, -68, 23, -6, -57, Blocks.DIRT.getDefaultState());
        structure.fillWithBlocks(world, start, 20, -6, -56, 21, -6, -56, Blocks.STONE.getDefaultState());
        structure.fillWithBlocks(world, start, 20, -6, -55, 21, -6, -54, Blocks.DIRT.getDefaultState());
        structure.fillWithBlocks(world, start, 20, -6, -53, 26, -6, -53, Blocks.STONE.getDefaultState());
        structure.fillWithBlocks(world, start, 20, -6, -52, 22, -6, -46, Blocks.ANDESITE.getDefaultState());
        structure.fillWithBlocks(world, start, 20, -6, -45, 21, -6, -45, Blocks.ANDESITE.getDefaultState());
        structure.fillWithBlocks(world, start, 20, -6, -44, 27, -6, -37, Blocks.STONE.getDefaultState());
        structure.fillWithBlocks(world, start, 20, -6, -34, 22, -6, -32, Blocks.DIRT.getDefaultState());
        structure.fillWithBlocks(world, start, 20, -6, -27, 29, -6, -18, Blocks.STONE.getDefaultState());
        structure.fillWithBlocks(world, start, 20, -6, 8, 23, -6, 11, Blocks.DIRT.getDefaultState());
        structure.fillWithBlocks(world, start, 20, -6, 12, 21, -6, 12, Blocks.WATER.getDefaultState());
        structure.fillWithBlocks(world, start, 20, -6, 13, 21, -6, 14, Blocks.STONE.getDefaultState());
        structure.fillWithBlocks(world, start, 20, -6, 15, 21, -6, 17, Blocks.DIRT.getDefaultState());
        structure.fillWithBlocks(world, start, 20, -6, 51, 24, -6, 55, Blocks.STONE.getDefaultState());
        structure.fillWithBlocks(world, start, 20, -6, 56, 21, -6, 56, Blocks.STONE.getDefaultState());
        structure.fillWithBlocks(world, start, 20, -6, 57, 24, -6, 61, Blocks.DIRT.getDefaultState());
        structure.fillWithBlocks(world, start, 20, -6, 62, 20, -2, 62, Blocks.DIRT.getDefaultState());
        structure.fillWithBlocks(world, start, 20, -6, 70, 22, -6, 72, Blocks.STONE.getDefaultState());
        structure.fillWithBlocks(world, start, 20, -5, -51, 20, -5, -51, Blocks.DIRT.getDefaultState());
        structure.fillWithBlocks(world, start, 20, -5, -50, 20, -5, -46, Blocks.ANDESITE.getDefaultState());
        structure.fillWithBlocks(world, start, 20, -5, -45, 21, -5, -44, Blocks.STONE.getDefaultState());
        structure.fillWithBlocks(world, start, 20, -5, -43, 36, -5, -21, Blocks.DIRT.getDefaultState());
        structure.fillWithBlocks(world, start, 20, -5, -14, 31, -5, -3, Blocks.DIRT.getDefaultState());
        structure.fillWithBlocks(world, start, 20, -5, 3, 21, -5, 3, Blocks.STONE.getDefaultState());
        structure.fillWithBlocks(world, start, 20, -5, 5, 30, -5, 21, Blocks.DIRT.getDefaultState());
        structure.fillWithBlocks(world, start, 20, -5, 22, 22, -5, 24, Blocks.DIRT.getDefaultState());
        structure.fillWithBlocks(world, start, 20, -5, 34, 32, -5, 46, Blocks.DIRT.getDefaultState());
        structure.fillWithBlocks(world, start, 20, -3, -56, 69, -3, -56, Blocks.DIRT.getDefaultState());
        structure.fillWithBlocks(world, start, 20, -3, 31, 20, -1, 31, Blocks.COARSE_DIRT.getDefaultState());
        structure.fillWithBlocks(world, start, 20, -3, 32, 20, -2, 55, Blocks.DIRT.getDefaultState());
        structure.fillWithBlocks(world, start, 20, -2, -57, 67, -2, -57, Blocks.DIRT.getDefaultState());
        structure.fillWithBlocks(world, start, 20, -2, -56, 27, -2, -56, Blocks.GRASS_BLOCK.getDefaultState().with(SnowyDirtBlock.SNOWY, false));
        structure.fillWithBlocks(world, start, 20, -2, 13, 20, -2, 13, Blocks.DIRT.getDefaultState());
        structure.fillWithBlocks(world, start, 20, -2, 14, 20, -2, 14, Blocks.REDSTONE_TORCH.getDefaultState().with(RedstoneTorchBlock.LIT, true));
        structure.fillWithBlocks(world, start, 20, -2, 60, 29, -2, 69, Blocks.DIRT.getDefaultState());
        structure.fillWithBlocks(world, start, 20, -1, -57, 67, -1, -57, Blocks.GRASS_BLOCK.getDefaultState().with(SnowyDirtBlock.SNOWY, false));
        structure.fillWithBlocks(world, start, 20, -1, -35, 21, -1, -34, Blocks.GRASS_BLOCK.getDefaultState().with(SnowyDirtBlock.SNOWY, false));
        structure.fillWithBlocks(world, start, 20, -1, -22, 22, -1, -22, Blocks.GRASS_PATH.getDefaultState());
        structure.fillWithBlocks(world, start, 20, -1, -21, 22, -1, -11, Blocks.GRASS_BLOCK.getDefaultState().with(SnowyDirtBlock.SNOWY, false));
        structure.fillWithBlocks(world, start, 20, -1, 9, 20, -1, 19, Blocks.COBBLESTONE.getDefaultState());
        structure.fillWithBlocks(world, start, 20, -1, 32, 20, -1, 45, Blocks.GRASS_BLOCK.getDefaultState().with(SnowyDirtBlock.SNOWY, false));
        structure.fillWithBlocks(world, start, 20, -1, 60, 29, -1, 69, Blocks.GRASS_BLOCK.getDefaultState().with(SnowyDirtBlock.SNOWY, false));
        structure.fillWithBlocks(world, start, 20, 0, -50, 20, 2, -50, Blocks.OAK_LOG.getDefaultState());
        structure.fillWithBlocks(world, start, 20, 0, -49, 20, 3, -49, Blocks.SPRUCE_LOG.getDefaultState());
        structure.fillWithBlocks(world, start, 20, 0, -46, 20, 2, -46, Blocks.OAK_LOG.getDefaultState());
        structure.fillWithBlocks(world, start, 20, 0, -44, 20, 1, -44, Blocks.OAK_LOG.getDefaultState());
        structure.fillWithBlocks(world, start, 20, 0, -39, 20, 0, -37, Blocks.OAK_SLAB.getDefaultState().with(SlabBlock.TYPE, SlabType.BOTTOM).with(SlabBlock.WATERLOGGED, false));
        structure.fillWithBlocks(world, start, 20, 0, -36, 21, 1, -36, Blocks.OAK_PLANKS.getDefaultState());
        structure.fillWithBlocks(world, start, 20, 0, 46, 20, 1, 46, Blocks.SPRUCE_LOG.getDefaultState());
        structure.fillWithBlocks(world, start, 20, 0, 47, 25, 0, 47, Blocks.DIRT.getDefaultState());
        structure.fillWithBlocks(world, start, 20, 0, 48, 25, 0, 48, Blocks.RED_WOOL.getDefaultState());
        structure.fillWithBlocks(world, start, 20, 0, 49, 21, 0, 50, Blocks.DIRT.getDefaultState());
        structure.fillWithBlocks(world, start, 20, 0, 52, 20, 3, 52, Blocks.SPRUCE_LOG.getDefaultState());
        structure.fillWithBlocks(world, start, 20, 0, 53, 20, 2, 53, Blocks.OAK_LOG.getDefaultState());
        structure.fillWithBlocks(world, start, 20, 1, 47, 25, 1, 47, Blocks.GRASS_BLOCK.getDefaultState().with(SnowyDirtBlock.SNOWY, false));
        structure.fillWithBlocks(world, start, 20, 1, 48, 20, 2, 48, Blocks.SPRUCE_LOG.getDefaultState());
        structure.fillWithBlocks(world, start, 20, 1, 49, 20, 1, 50, Blocks.DIRT.getDefaultState());
        structure.fillWithBlocks(world, start, 20, 2, -35, 22, 2, -35, Blocks.OAK_PLANKS.getDefaultState());
        structure.fillWithBlocks(world, start, 20, 2, 49, 20, 2, 50, Blocks.GRASS_BLOCK.getDefaultState().with(SnowyDirtBlock.SNOWY, false));
        structure.fillWithBlocks(world, start, 20, 4, 10, 21, 4, 11, Blocks.OAK_PLANKS.getDefaultState());
        structure.fillWithBlocks(world, start, 20, 4, 17, 21, 4, 18, Blocks.OAK_PLANKS.getDefaultState());
        structure.fillWithBlocks(world, start, 20, 5, 9, 20, 6, 9, Blocks.DARK_OAK_PLANKS.getDefaultState());
        structure.fillWithBlocks(world, start, 20, 7, 7, 20, 8, 10, Blocks.OAK_PLANKS.getDefaultState());
        structure.fillWithBlocks(world, start, 20, 7, 19, 20, 8, 21, Blocks.OAK_PLANKS.getDefaultState());
        structure.fillWithBlocks(world, start, 20, 10, 13, 21, 10, 13, Blocks.DARK_OAK_SLAB.getDefaultState().with(SlabBlock.TYPE, SlabType.TOP).with(SlabBlock.WATERLOGGED, false));
        structure.fillWithBlocks(world, start, 21, -7, 10, 22, -7, 11, Blocks.DIRT.getDefaultState());
        structure.fillWithBlocks(world, start, 21, -7, 12, 21, -7, 60, Blocks.STONE.getDefaultState());
        structure.fillWithBlocks(world, start, 21, -7, 61, 21, -7, 67, Blocks.GRANITE.getDefaultState());
        structure.fillWithBlocks(world, start, 21, -7, 68, 23, -7, 73, Blocks.STONE.getDefaultState());
        structure.fillWithBlocks(world, start, 21, -7, 74, 23, -7, 76, Blocks.DIRT.getDefaultState());
        structure.fillWithBlocks(world, start, 21, -7, 77, 23, -7, 79, Blocks.GRASS_BLOCK.getDefaultState().with(SnowyDirtBlock.SNOWY, false));
        structure.fillWithBlocks(world, start, 21, -6, -36, 22, -6, -36, Blocks.GRANITE.getDefaultState());
        structure.fillWithBlocks(world, start, 21, -6, -35, 23, -6, -33, Blocks.DIRT.getDefaultState());
        structure.fillWithBlocks(world, start, 21, -6, -29, 22, -6, -28, Blocks.GRANITE.getDefaultState());
        structure.fillWithBlocks(world, start, 21, -6, -2, 22, -6, -1, Blocks.IRON_ORE.getDefaultState());
        structure.fillWithBlocks(world, start, 21, -6, 0, 22, -6, 4, Blocks.STONE.getDefaultState());
        structure.fillWithBlocks(world, start, 21, -6, 6, 26, -6, 11, Blocks.DIRT.getDefaultState());
        structure.fillWithBlocks(world, start, 21, -6, 50, 26, -6, 55, Blocks.STONE.getDefaultState());
        structure.fillWithBlocks(world, start, 21, -6, 62, 22, -6, 65, Blocks.GRANITE.getDefaultState());
        structure.fillWithBlocks(world, start, 21, -6, 68, 25, -6, 72, Blocks.STONE.getDefaultState());
        structure.fillWithBlocks(world, start, 21, -5, -51, 22, -5, -50, Blocks.DIRT.getDefaultState());
        structure.fillWithBlocks(world, start, 21, -5, -49, 21, -5, -46, Blocks.ANDESITE.getDefaultState());
        structure.fillWithBlocks(world, start, 21, -5, -15, 33, -5, -3, Blocks.DIRT.getDefaultState());
        structure.fillWithBlocks(world, start, 21, -5, -2, 21, -5, -2, Blocks.IRON_ORE.getDefaultState());
        structure.fillWithBlocks(world, start, 21, -5, -1, 21, -5, 3, Blocks.STONE.getDefaultState());
        structure.fillWithBlocks(world, start, 21, -5, 4, 31, -5, 14, Blocks.DIRT.getDefaultState());
        structure.fillWithBlocks(world, start, 21, -5, 25, 21, -5, 25, Blocks.DIRT.getDefaultState());
        structure.fillWithBlocks(world, start, 21, -5, 26, 21, -5, 33, Blocks.STONE.getDefaultState());
        structure.fillWithBlocks(world, start, 21, -4, 58, 35, -4, 72, Blocks.DIRT.getDefaultState());
        structure.fillWithBlocks(world, start, 21, -3, -54, 22, -3, -54, Blocks.WATER.getDefaultState());
        structure.fillWithBlocks(world, start, 21, -3, 28, 25, -3, 32, Blocks.DIRT.getDefaultState());
        structure.fillWithBlocks(world, start, 21, -3, 33, 21, -3, 34, Blocks.COARSE_DIRT.getDefaultState());
        structure.fillWithBlocks(world, start, 21, -3, 35, 37, -3, 52, Blocks.DIRT.getDefaultState());
        structure.fillWithBlocks(world, start, 21, -3, 53, 23, -3, 55, Blocks.DIRT.getDefaultState());
        structure.fillWithBlocks(world, start, 21, -3, 71, 65, -3, 71, Blocks.DIRT.getDefaultState());
        structure.fillWithBlocks(world, start, 21, -2, -24, 36, -2, -9, Blocks.DIRT.getDefaultState());
        structure.fillWithBlocks(world, start, 21, -2, 13, 21, -2, 13, Blocks.REDSTONE_TORCH.getDefaultState().with(RedstoneTorchBlock.LIT, true));
        structure.fillWithBlocks(world, start, 21, -2, 14, 21, -2, 14, Blocks.DIRT.getDefaultState());
        structure.fillWithBlocks(world, start, 21, -2, 17, 21, -2, 17, Blocks.DIRT.getDefaultState());
        structure.fillWithBlocks(world, start, 21, -2, 19, 34, -2, 32, Blocks.DIRT.getDefaultState());
        structure.fillWithBlocks(world, start, 21, -2, 33, 21, -2, 34, Blocks.COARSE_DIRT.getDefaultState());
        structure.fillWithBlocks(world, start, 21, -2, 35, 37, -2, 51, Blocks.DIRT.getDefaultState());
        structure.fillWithBlocks(world, start, 21, -2, 52, 23, -2, 54, Blocks.DIRT.getDefaultState());
        structure.fillWithBlocks(world, start, 21, -2, 71, 49, -2, 71, Blocks.GRASS_BLOCK.getDefaultState().with(SnowyDirtBlock.SNOWY, false));
        structure.fillWithBlocks(world, start, 21, -1, -39, 21, -1, -37, Blocks.COBBLESTONE.getDefaultState());
        structure.fillWithBlocks(world, start, 21, -1, -24, 21, -1, -24, Blocks.GRASS_BLOCK.getDefaultState().with(SnowyDirtBlock.SNOWY, false));
        structure.fillWithBlocks(world, start, 21, -1, -10, 21, -1, -8, Blocks.DIRT.getDefaultState());
        structure.fillWithBlocks(world, start, 21, -1, -7, 21, -1, -7, Blocks.COBBLESTONE.getDefaultState());
        structure.fillWithBlocks(world, start, 21, -1, -6, 21, -1, -4, Blocks.DIRT.getDefaultState());
        structure.fillWithBlocks(world, start, 21, -1, -3, 21, -1, -2, Blocks.GRASS_BLOCK.getDefaultState().with(SnowyDirtBlock.SNOWY, false));
        structure.fillWithBlocks(world, start, 21, -1, 9, 31, -1, 9, Blocks.DIRT.getDefaultState());
        structure.fillWithBlocks(world, start, 21, -1, 19, 31, -1, 19, Blocks.DIRT.getDefaultState());
        structure.fillWithBlocks(world, start, 21, -1, 28, 25, -1, 32, Blocks.GRASS_BLOCK.getDefaultState().with(SnowyDirtBlock.SNOWY, false));
        structure.fillWithBlocks(world, start, 21, -1, 33, 21, -1, 34, Blocks.COARSE_DIRT.getDefaultState());
        structure.fillWithBlocks(world, start, 21, 0, -50, 21, 2, -50, Blocks.SPRUCE_LOG.getDefaultState());
        structure.fillWithBlocks(world, start, 21, 0, -49, 21, 3, -49, Blocks.OAK_LOG.getDefaultState());
        structure.fillWithBlocks(world, start, 21, 0, -48, 22, 0, -47, Blocks.DIRT.getDefaultState());
        structure.fillWithBlocks(world, start, 21, 0, -46, 21, 2, -46, Blocks.SPRUCE_LOG.getDefaultState());
        structure.fillWithBlocks(world, start, 21, 0, -44, 21, 1, -44, Blocks.SPRUCE_LOG.getDefaultState());
        structure.fillWithBlocks(world, start, 21, 0, -19, 21, 0, -12, Blocks.COBBLESTONE_WALL.getDefaultState().with(WallBlock.WATERLOGGED, false).with(WallBlock.UP, false).with(WallBlock.WALL_HEIGHT_NORTH, WallHeight.LOW).with(WallBlock.WALL_HEIGHT_SOUTH, WallHeight.LOW).with(WallBlock.WALL_HEIGHT_EAST, WallHeight.LOW).with(WallBlock.WALL_HEIGHT_WEST, WallHeight.LOW));
        structure.fillWithBlocks(world, start, 21, 0, -10, 21, 2, -10, Blocks.SPRUCE_LOG.getDefaultState());
        structure.fillWithBlocks(world, start, 21, 0, -9, 21, 1, -8, Blocks.OAK_PLANKS.getDefaultState());
        structure.fillWithBlocks(world, start, 21, 0, -6, 21, 1, -5, Blocks.OAK_PLANKS.getDefaultState());
        structure.fillWithBlocks(world, start, 21, 0, -4, 21, 2, -4, Blocks.SPRUCE_LOG.getDefaultState());
        structure.fillWithBlocks(world, start, 21, 0, -2, 21, 1, -2, Blocks.SPRUCE_FENCE.getDefaultState().with(FourWayBlock.WATERLOGGED, false).with(FourWayBlock.NORTH, false).with(FourWayBlock.SOUTH, false).with(FourWayBlock.EAST, false).with(FourWayBlock.WEST, false));
        structure.fillWithBlocks(world, start, 21, 0, 9, 22, 1, 9, Blocks.SPRUCE_LOG.getDefaultState());
        structure.fillWithBlocks(world, start, 21, 0, 19, 22, 1, 19, Blocks.SPRUCE_LOG.getDefaultState());
        structure.fillWithBlocks(world, start, 21, 0, 25, 22, 0, 25, Blocks.OAK_FENCE.getDefaultState().with(FourWayBlock.WATERLOGGED, false).with(FourWayBlock.NORTH, false).with(FourWayBlock.SOUTH, false).with(FourWayBlock.EAST, true).with(FourWayBlock.WEST, true));
        structure.fillWithBlocks(world, start, 21, 0, 46, 21, 1, 46, Blocks.OAK_LOG.getDefaultState());
        structure.fillWithBlocks(world, start, 21, 0, 52, 22, 1, 52, Blocks.OAK_LOG.getDefaultState());
        structure.fillWithBlocks(world, start, 21, 0, 53, 21, 2, 53, Blocks.SPRUCE_LOG.getDefaultState());
        structure.fillWithBlocks(world, start, 21, 1, -48, 22, 1, -47, Blocks.DIRT.getDefaultState());
        structure.fillWithBlocks(world, start, 21, 1, 48, 21, 2, 48, Blocks.OAK_LOG.getDefaultState());
        structure.fillWithBlocks(world, start, 21, 1, 49, 26, 1, 49, Blocks.DIRT.getDefaultState());
        structure.fillWithBlocks(world, start, 21, 2, -11, 22, 2, -11, Blocks.OAK_STAIRS.getDefaultState().with(StairsBlock.FACING, Direction.SOUTH).with(StairsBlock.WATERLOGGED, false).with(StairsBlock.SHAPE, StairsShape.STRAIGHT).with(StairsBlock.HALF, Half.BOTTOM));
        structure.fillWithBlocks(world, start, 21, 2, -9, 21, 2, -8, Blocks.SPRUCE_LOG.getDefaultState());
        structure.fillWithBlocks(world, start, 21, 2, -6, 21, 2, -4, Blocks.SPRUCE_LOG.getDefaultState());
        structure.fillWithBlocks(world, start, 21, 2, -3, 21, 2, -3, Blocks.OAK_SLAB.getDefaultState().with(SlabBlock.TYPE, SlabType.TOP).with(SlabBlock.WATERLOGGED, false));
        structure.fillWithBlocks(world, start, 21, 2, 9, 22, 3, 9, Blocks.SPRUCE_LOG.getDefaultState());
        structure.fillWithBlocks(world, start, 21, 2, 19, 22, 3, 19, Blocks.SPRUCE_LOG.getDefaultState());
        structure.fillWithBlocks(world, start, 21, 2, 49, 26, 2, 49, Blocks.GRASS_BLOCK.getDefaultState().with(SnowyDirtBlock.SNOWY, false));
        structure.fillWithBlocks(world, start, 21, 2, 52, 22, 2, 52, Blocks.OAK_LOG.getDefaultState());
        structure.fillWithBlocks(world, start, 21, 3, -32, 22, 3, -31, Blocks.OAK_PLANKS.getDefaultState());
        structure.fillWithBlocks(world, start, 21, 3, -24, 25, 3, -24, Blocks.OAK_PLANKS.getDefaultState());
        structure.fillWithBlocks(world, start, 21, 3, -10, 23, 3, -10, Blocks.OAK_STAIRS.getDefaultState().with(StairsBlock.FACING, Direction.SOUTH).with(StairsBlock.WATERLOGGED, false).with(StairsBlock.SHAPE, StairsShape.STRAIGHT).with(StairsBlock.HALF, Half.BOTTOM));
        structure.fillWithBlocks(world, start, 21, 3, -8, 21, 3, -6, Blocks.SPRUCE_LOG.getDefaultState());
        structure.fillWithBlocks(world, start, 21, 3, -4, 22, 3, -4, Blocks.OAK_STAIRS.getDefaultState().with(StairsBlock.FACING, Direction.NORTH).with(StairsBlock.WATERLOGGED, false).with(StairsBlock.SHAPE, StairsShape.STRAIGHT).with(StairsBlock.HALF, Half.BOTTOM));
        structure.fillWithBlocks(world, start, 21, 3, 50, 21, 3, 51, Blocks.SPRUCE_SLAB.getDefaultState().with(SlabBlock.TYPE, SlabType.BOTTOM).with(SlabBlock.WATERLOGGED, false));
        structure.fillWithBlocks(world, start, 21, 4, -31, 22, 4, -30, Blocks.OAK_PLANKS.getDefaultState());
        structure.fillWithBlocks(world, start, 21, 4, -25, 25, 4, -25, Blocks.OAK_PLANKS.getDefaultState());
        structure.fillWithBlocks(world, start, 21, 4, -9, 22, 4, -9, Blocks.OAK_STAIRS.getDefaultState().with(StairsBlock.FACING, Direction.SOUTH).with(StairsBlock.WATERLOGGED, false).with(StairsBlock.SHAPE, StairsShape.STRAIGHT).with(StairsBlock.HALF, Half.BOTTOM));
        structure.fillWithBlocks(world, start, 21, 4, -7, 21, 5, -7, Blocks.SPRUCE_LOG.getDefaultState());
        structure.fillWithBlocks(world, start, 21, 4, -5, 22, 4, -5, Blocks.OAK_STAIRS.getDefaultState().with(StairsBlock.FACING, Direction.NORTH).with(StairsBlock.WATERLOGGED, false).with(StairsBlock.SHAPE, StairsShape.STRAIGHT).with(StairsBlock.HALF, Half.BOTTOM));
        structure.fillWithBlocks(world, start, 21, 4, 9, 31, 4, 9, Blocks.DARK_OAK_PLANKS.getDefaultState());
        structure.fillWithBlocks(world, start, 21, 4, 19, 31, 4, 19, Blocks.DARK_OAK_PLANKS.getDefaultState());
        structure.fillWithBlocks(world, start, 21, 5, -30, 22, 5, -29, Blocks.OAK_PLANKS.getDefaultState());
        structure.fillWithBlocks(world, start, 21, 5, -26, 25, 5, -26, Blocks.OAK_PLANKS.getDefaultState());
        structure.fillWithBlocks(world, start, 21, 5, -8, 22, 5, -8, Blocks.OAK_STAIRS.getDefaultState().with(StairsBlock.FACING, Direction.SOUTH).with(StairsBlock.WATERLOGGED, false).with(StairsBlock.SHAPE, StairsShape.STRAIGHT).with(StairsBlock.HALF, Half.BOTTOM));
        structure.fillWithBlocks(world, start, 21, 5, -6, 22, 5, -6, Blocks.OAK_STAIRS.getDefaultState().with(StairsBlock.FACING, Direction.NORTH).with(StairsBlock.WATERLOGGED, false).with(StairsBlock.SHAPE, StairsShape.STRAIGHT).with(StairsBlock.HALF, Half.BOTTOM));
        structure.fillWithBlocks(world, start, 21, 5, 7, 21, 6, 9, Blocks.OAK_PLANKS.getDefaultState());
        structure.fillWithBlocks(world, start, 21, 5, 19, 21, 5, 21, Blocks.OAK_PLANKS.getDefaultState());
        structure.fillWithBlocks(world, start, 21, 6, -29, 23, 6, -27, Blocks.OAK_PLANKS.getDefaultState());
        structure.fillWithBlocks(world, start, 21, 6, -7, 23, 6, -7, Blocks.OAK_SLAB.getDefaultState().with(SlabBlock.TYPE, SlabType.BOTTOM).with(SlabBlock.WATERLOGGED, false));
        structure.fillWithBlocks(world, start, 21, 6, 20, 21, 6, 21, Blocks.OAK_STAIRS.getDefaultState().with(StairsBlock.FACING, Direction.WEST).with(StairsBlock.WATERLOGGED, false).with(StairsBlock.SHAPE, StairsShape.STRAIGHT).with(StairsBlock.HALF, Half.BOTTOM));
        structure.fillWithBlocks(world, start, 21, 7, -28, 25, 7, -28, Blocks.OAK_PLANKS.getDefaultState());
        structure.fillWithBlocks(world, start, 22, -7, -73, 23, -7, -72, Blocks.DIRT.getDefaultState());
        structure.fillWithBlocks(world, start, 22, -7, -43, 28, -7, -37, Blocks.STONE.getDefaultState());
        structure.fillWithBlocks(world, start, 22, -7, -30, 23, -7, -29, Blocks.GRANITE.getDefaultState());
        structure.fillWithBlocks(world, start, 22, -7, -28, 23, -7, -27, Blocks.STONE.getDefaultState());
        structure.fillWithBlocks(world, start, 22, -7, -25, 29, -7, -18, Blocks.STONE.getDefaultState());
        structure.fillWithBlocks(world, start, 22, -7, -17, 22, -7, -2, Blocks.STONE.getDefaultState());
        structure.fillWithBlocks(world, start, 22, -7, -1, 22, -5, -1, Blocks.IRON_ORE.getDefaultState());
        structure.fillWithBlocks(world, start, 22, -7, 0, 23, -7, 5, Blocks.STONE.getDefaultState());
        structure.fillWithBlocks(world, start, 22, -7, 6, 22, -7, 7, Blocks.STONE.getDefaultState());
        structure.fillWithBlocks(world, start, 22, -7, 8, 26, -7, 12, Blocks.DIRT.getDefaultState());
        structure.fillWithBlocks(world, start, 22, -7, 13, 24, -7, 33, Blocks.STONE.getDefaultState());
        structure.fillWithBlocks(world, start, 22, -7, 49, 31, -7, 60, Blocks.STONE.getDefaultState());
        structure.fillWithBlocks(world, start, 22, -7, 61, 22, -7, 61, Blocks.STONE.getDefaultState());
        structure.fillWithBlocks(world, start, 22, -7, 62, 22, -6, 64, Blocks.GRANITE.getDefaultState());
        structure.fillWithBlocks(world, start, 22, -7, 65, 25, -7, 68, Blocks.STONE.getDefaultState());
        structure.fillWithBlocks(world, start, 22, -6, -70, 22, -6, -70, Blocks.STONE.getDefaultState());
        structure.fillWithBlocks(world, start, 22, -6, -69, 22, -6, -54, Blocks.DIRT.getDefaultState());
        structure.fillWithBlocks(world, start, 22, -6, -45, 27, -6, -37, Blocks.STONE.getDefaultState());
        structure.fillWithBlocks(world, start, 22, -6, -31, 24, -6, -29, Blocks.GRANITE.getDefaultState());
        structure.fillWithBlocks(world, start, 22, -6, -8, 22, -6, -4, Blocks.STONE.getDefaultState());
        structure.fillWithBlocks(world, start, 22, -6, -3, 22, -6, -1, Blocks.IRON_ORE.getDefaultState());
        structure.fillWithBlocks(world, start, 22, -6, 5, 28, -6, 11, Blocks.DIRT.getDefaultState());
        structure.fillWithBlocks(world, start, 22, -6, 12, 23, -6, 33, Blocks.STONE.getDefaultState());
        structure.fillWithBlocks(world, start, 22, -6, 40, 22, -6, 42, Blocks.STONE.getDefaultState());
        structure.fillWithBlocks(world, start, 22, -6, 44, 23, -6, 55, Blocks.STONE.getDefaultState());
        structure.fillWithBlocks(world, start, 22, -6, 56, 27, -6, 61, Blocks.DIRT.getDefaultState());
        structure.fillWithBlocks(world, start, 22, -6, 66, 28, -6, 72, Blocks.STONE.getDefaultState());
        structure.fillWithBlocks(world, start, 22, -5, -49, 23, -5, -48, Blocks.DIRT.getDefaultState());
        structure.fillWithBlocks(world, start, 22, -5, -46, 23, -5, -44, Blocks.STONE.getDefaultState());
        structure.fillWithBlocks(world, start, 22, -5, -16, 36, -5, -2, Blocks.DIRT.getDefaultState());
        structure.fillWithBlocks(world, start, 22, -5, 0, 22, -5, 1, Blocks.STONE.getDefaultState());
        structure.fillWithBlocks(world, start, 22, -5, 2, 32, -5, 14, Blocks.DIRT.getDefaultState());
        structure.fillWithBlocks(world, start, 22, -5, 25, 23, -5, 26, Blocks.DIRT.getDefaultState());
        structure.fillWithBlocks(world, start, 22, -5, 27, 23, -5, 30, Blocks.STONE.getDefaultState());
        structure.fillWithBlocks(world, start, 22, -5, 31, 22, -5, 32, Blocks.STONE.getDefaultState());
        structure.fillWithBlocks(world, start, 22, -5, 33, 35, -5, 46, Blocks.DIRT.getDefaultState());
        structure.fillWithBlocks(world, start, 22, -4, -56, 22, -4, -56, Blocks.DIRT.getDefaultState());
        structure.fillWithBlocks(world, start, 22, -4, 56, 22, -4, 56, Blocks.GRASS_BLOCK.getDefaultState().with(SnowyDirtBlock.SNOWY, false));
        structure.fillWithBlocks(world, start, 22, -4, 57, 22, -4, 72, Blocks.DIRT.getDefaultState());
        structure.fillWithBlocks(world, start, 22, -3, -55, 22, -3, -54, Blocks.WATER.getDefaultState());
        structure.fillWithBlocks(world, start, 22, -3, 33, 22, -3, 33, Blocks.DIRT.getDefaultState());
        structure.fillWithBlocks(world, start, 22, -3, 34, 22, -1, 34, Blocks.COARSE_DIRT.getDefaultState());
        structure.fillWithBlocks(world, start, 22, -3, 56, 22, -3, 56, Blocks.WATER.getDefaultState());
        structure.fillWithBlocks(world, start, 22, -3, 58, 35, -3, 71, Blocks.DIRT.getDefaultState());
        structure.fillWithBlocks(world, start, 22, -2, -25, 38, -2, -9, Blocks.DIRT.getDefaultState());
        structure.fillWithBlocks(world, start, 22, -2, 13, 22, -2, 13, Blocks.DIRT.getDefaultState());
        structure.fillWithBlocks(world, start, 22, -2, 15, 27, -2, 33, Blocks.DIRT.getDefaultState());
        structure.fillWithBlocks(world, start, 22, -2, 55, 27, -2, 55, Blocks.GRASS_BLOCK.getDefaultState().with(SnowyDirtBlock.SNOWY, false));
        structure.fillWithBlocks(world, start, 22, -2, 58, 27, -2, 58, Blocks.GRASS_BLOCK.getDefaultState().with(SnowyDirtBlock.SNOWY, false));
        structure.fillWithBlocks(world, start, 22, -2, 59, 32, -2, 69, Blocks.DIRT.getDefaultState());
        structure.fillWithBlocks(world, start, 22, -1, -43, 23, -1, -41, Blocks.GRASS_BLOCK.getDefaultState().with(SnowyDirtBlock.SNOWY, false));
        structure.fillWithBlocks(world, start, 22, -1, -39, 22, -1, -36, Blocks.DIRT.getDefaultState());
        structure.fillWithBlocks(world, start, 22, -1, -35, 24, -1, -32, Blocks.GRASS_BLOCK.getDefaultState().with(SnowyDirtBlock.SNOWY, false));
        structure.fillWithBlocks(world, start, 22, -1, -24, 22, -1, -23, Blocks.GRASS_BLOCK.getDefaultState().with(SnowyDirtBlock.SNOWY, false));
        structure.fillWithBlocks(world, start, 22, -1, -10, 23, -1, -10, Blocks.DIRT.getDefaultState());
        structure.fillWithBlocks(world, start, 22, -1, -9, 26, -1, -5, Blocks.COBBLESTONE.getDefaultState());
        structure.fillWithBlocks(world, start, 22, -1, -4, 23, -1, -3, Blocks.COBBLESTONE.getDefaultState());
        structure.fillWithBlocks(world, start, 22, -1, -2, 24, -1, 1, Blocks.GRASS_PATH.getDefaultState());
        structure.fillWithBlocks(world, start, 22, -1, 3, 24, -1, 5, Blocks.GRASS_BLOCK.getDefaultState().with(SnowyDirtBlock.SNOWY, false));
        structure.fillWithBlocks(world, start, 22, -1, 7, 23, -1, 8, Blocks.GRASS_BLOCK.getDefaultState().with(SnowyDirtBlock.SNOWY, false));
        structure.fillWithBlocks(world, start, 22, -1, 20, 23, -1, 21, Blocks.GRASS_BLOCK.getDefaultState().with(SnowyDirtBlock.SNOWY, false));
        structure.fillWithBlocks(world, start, 22, -1, 23, 31, -1, 32, Blocks.GRASS_BLOCK.getDefaultState().with(SnowyDirtBlock.SNOWY, false));
        structure.fillWithBlocks(world, start, 22, -1, 33, 22, -1, 33, Blocks.GRASS_BLOCK.getDefaultState().with(SnowyDirtBlock.SNOWY, false));
        structure.fillWithBlocks(world, start, 22, -1, 50, 27, -1, 50, Blocks.GRASS_BLOCK.getDefaultState().with(SnowyDirtBlock.SNOWY, false));
        structure.fillWithBlocks(world, start, 22, -1, 51, 24, -1, 53, Blocks.DIRT.getDefaultState());
        structure.fillWithBlocks(world, start, 22, -1, 54, 27, -1, 54, Blocks.GRASS_BLOCK.getDefaultState().with(SnowyDirtBlock.SNOWY, false));
        structure.fillWithBlocks(world, start, 22, -1, 59, 32, -1, 69, Blocks.GRASS_BLOCK.getDefaultState().with(SnowyDirtBlock.SNOWY, false));
        structure.fillWithBlocks(world, start, 22, 0, -50, 22, 2, -50, Blocks.OAK_LOG.getDefaultState());
        structure.fillWithBlocks(world, start, 22, 0, -49, 22, 3, -49, Blocks.SPRUCE_LOG.getDefaultState());
        structure.fillWithBlocks(world, start, 22, 0, -46, 22, 2, -46, Blocks.OAK_LOG.getDefaultState());
        structure.fillWithBlocks(world, start, 22, 0, -44, 22, 1, -44, Blocks.OAK_LOG.getDefaultState());
        structure.fillWithBlocks(world, start, 22, 0, -40, 22, 2, -40, Blocks.SPRUCE_LOG.getDefaultState());
        structure.fillWithBlocks(world, start, 22, 0, -39, 22, 1, -39, Blocks.OAK_PLANKS.getDefaultState());
        structure.fillWithBlocks(world, start, 22, 0, -38, 22, 4, -38, Blocks.SPRUCE_LOG.getDefaultState());
        structure.fillWithBlocks(world, start, 22, 0, -37, 22, 1, -37, Blocks.OAK_PLANKS.getDefaultState());
        structure.fillWithBlocks(world, start, 22, 0, -36, 22, 2, -36, Blocks.SPRUCE_LOG.getDefaultState());
        structure.fillWithBlocks(world, start, 22, 0, -31, 22, 2, -31, Blocks.SPRUCE_LOG.getDefaultState());
        structure.fillWithBlocks(world, start, 22, 0, -25, 22, 2, -25, Blocks.SPRUCE_LOG.getDefaultState());
        structure.fillWithBlocks(world, start, 22, 0, -20, 26, 0, -20, Blocks.COBBLESTONE_WALL.getDefaultState().with(WallBlock.WATERLOGGED, false).with(WallBlock.UP, false).with(WallBlock.WALL_HEIGHT_NORTH, WallHeight.LOW).with(WallBlock.WALL_HEIGHT_SOUTH, WallHeight.LOW).with(WallBlock.WALL_HEIGHT_EAST, WallHeight.LOW).with(WallBlock.WALL_HEIGHT_WEST, WallHeight.LOW));
        structure.fillWithBlocks(world, start, 22, 0, -10, 24, 1, -10, Blocks.OAK_PLANKS.getDefaultState());
        structure.fillWithBlocks(world, start, 22, 0, 10, 22, 0, 13, Blocks.OAK_PLANKS.getDefaultState());
        structure.fillWithBlocks(world, start, 22, 0, 46, 22, 1, 46, Blocks.SPRUCE_LOG.getDefaultState());
        structure.fillWithBlocks(world, start, 22, 0, 49, 26, 1, 49, Blocks.DIRT.getDefaultState());
        structure.fillWithBlocks(world, start, 22, 0, 51, 22, 3, 51, Blocks.SPRUCE_LOG.getDefaultState());
        structure.fillWithBlocks(world, start, 22, 0, 53, 27, 0, 53, Blocks.GRASS_BLOCK.getDefaultState().with(SnowyDirtBlock.SNOWY, false));
        structure.fillWithBlocks(world, start, 22, 1, 48, 22, 2, 48, Blocks.SPRUCE_LOG.getDefaultState());
        structure.fillWithBlocks(world, start, 22, 2, -39, 22, 2, -36, Blocks.SPRUCE_LOG.getDefaultState());
        structure.fillWithBlocks(world, start, 22, 2, -10, 30, 2, -10, Blocks.SPRUCE_LOG.getDefaultState());
        structure.fillWithBlocks(world, start, 22, 2, -4, 30, 2, -4, Blocks.SPRUCE_LOG.getDefaultState());
        structure.fillWithBlocks(world, start, 22, 2, -2, 24, 2, -2, Blocks.OAK_SLAB.getDefaultState().with(SlabBlock.TYPE, SlabType.TOP).with(SlabBlock.WATERLOGGED, false));
        structure.fillWithBlocks(world, start, 22, 3, -39, 22, 4, -39, Blocks.OAK_PLANKS.getDefaultState());
        structure.fillWithBlocks(world, start, 22, 3, -37, 22, 3, -36, Blocks.OAK_PLANKS.getDefaultState());
        structure.fillWithBlocks(world, start, 22, 3, -3, 24, 3, -3, Blocks.OAK_SLAB.getDefaultState().with(SlabBlock.TYPE, SlabType.BOTTOM).with(SlabBlock.WATERLOGGED, false));
        structure.fillWithBlocks(world, start, 22, 3, 7, 22, 3, 8, Blocks.OAK_PLANKS.getDefaultState());
        structure.fillWithBlocks(world, start, 22, 3, 20, 22, 3, 21, Blocks.OAK_PLANKS.getDefaultState());
        structure.fillWithBlocks(world, start, 22, 3, 50, 27, 3, 50, Blocks.SPRUCE_SLAB.getDefaultState().with(SlabBlock.TYPE, SlabType.BOTTOM).with(SlabBlock.WATERLOGGED, false));
        structure.fillWithBlocks(world, start, 22, 4, -7, 22, 4, -7, Blocks.DARK_OAK_SLAB.getDefaultState().with(SlabBlock.TYPE, SlabType.TOP).with(SlabBlock.WATERLOGGED, false));
        structure.fillWithBlocks(world, start, 22, 4, 7, 22, 4, 8, Blocks.OAK_PLANKS.getDefaultState());
        structure.fillWithBlocks(world, start, 22, 4, 10, 23, 4, 11, Blocks.OAK_PLANKS.getDefaultState());
        structure.fillWithBlocks(world, start, 22, 4, 17, 23, 4, 18, Blocks.OAK_PLANKS.getDefaultState());
        structure.fillWithBlocks(world, start, 22, 5, 9, 31, 5, 9, Blocks.OAK_PLANKS.getDefaultState());
        structure.fillWithBlocks(world, start, 22, 5, 19, 31, 5, 19, Blocks.OAK_PLANKS.getDefaultState());
        structure.fillWithBlocks(world, start, 22, 6, 9, 30, 6, 9, Blocks.OAK_STAIRS.getDefaultState().with(StairsBlock.FACING, Direction.SOUTH).with(StairsBlock.WATERLOGGED, false).with(StairsBlock.SHAPE, StairsShape.STRAIGHT).with(StairsBlock.HALF, Half.BOTTOM));
        structure.fillWithBlocks(world, start, 22, 6, 19, 30, 6, 19, Blocks.OAK_STAIRS.getDefaultState().with(StairsBlock.FACING, Direction.NORTH).with(StairsBlock.WATERLOGGED, false).with(StairsBlock.SHAPE, StairsShape.STRAIGHT).with(StairsBlock.HALF, Half.BOTTOM));
        structure.fillWithBlocks(world, start, 23, -7, -51, 23, -7, -51, Blocks.STONE.getDefaultState());
        structure.fillWithBlocks(world, start, 23, -7, -50, 23, -6, -48, Blocks.ANDESITE.getDefaultState());
        structure.fillWithBlocks(world, start, 23, -7, -46, 31, -7, -38, Blocks.STONE.getDefaultState());
        structure.fillWithBlocks(world, start, 23, -7, -36, 30, -6, -36, Blocks.STONE.getDefaultState());
        structure.fillWithBlocks(world, start, 23, -7, -35, 24, -7, -30, Blocks.GRANITE.getDefaultState());
        structure.fillWithBlocks(world, start, 23, -7, -26, 31, -7, -18, Blocks.STONE.getDefaultState());
        structure.fillWithBlocks(world, start, 23, -7, -16, 29, -7, -9, Blocks.STONE.getDefaultState());
        structure.fillWithBlocks(world, start, 23, -7, -2, 24, -7, 1, Blocks.STONE.getDefaultState());
        structure.fillWithBlocks(world, start, 23, -7, 6, 29, -7, 12, Blocks.DIRT.getDefaultState());
        structure.fillWithBlocks(world, start, 23, -7, 34, 23, -7, 41, Blocks.ANDESITE.getDefaultState());
        structure.fillWithBlocks(world, start, 23, -7, 42, 23, -7, 73, Blocks.STONE.getDefaultState());
        structure.fillWithBlocks(world, start, 23, -6, -70, 24, -6, -69, Blocks.STONE.getDefaultState());
        structure.fillWithBlocks(world, start, 23, -6, -56, 24, -6, -54, Blocks.DIRT.getDefaultState());
        structure.fillWithBlocks(world, start, 23, -6, -52, 23, -6, -52, Blocks.STONE.getDefaultState());
        structure.fillWithBlocks(world, start, 23, -6, -51, 23, -6, -48, Blocks.ANDESITE.getDefaultState());
        structure.fillWithBlocks(world, start, 23, -6, -47, 27, -6, -36, Blocks.STONE.getDefaultState());
        structure.fillWithBlocks(world, start, 23, -6, -32, 24, -6, -29, Blocks.GRANITE.getDefaultState());
        structure.fillWithBlocks(world, start, 23, -6, -8, 24, -6, -8, Blocks.COAL_ORE.getDefaultState());
        structure.fillWithBlocks(world, start, 23, -6, -7, 24, -6, -6, Blocks.STONE.getDefaultState());
        structure.fillWithBlocks(world, start, 23, -6, -5, 23, -6, -2, Blocks.STONE.getDefaultState());
        structure.fillWithBlocks(world, start, 23, -6, 1, 29, -6, 11, Blocks.DIRT.getDefaultState());
        structure.fillWithBlocks(world, start, 23, -6, 34, 23, -6, 42, Blocks.ANDESITE.getDefaultState());
        structure.fillWithBlocks(world, start, 23, -6, 43, 23, -6, 55, Blocks.STONE.getDefaultState());
        structure.fillWithBlocks(world, start, 23, -6, 62, 23, -6, 63, Blocks.GRANITE.getDefaultState());
        structure.fillWithBlocks(world, start, 23, -6, 64, 28, -6, 72, Blocks.STONE.getDefaultState());
        structure.fillWithBlocks(world, start, 23, -6, 75, 62, -6, 75, Blocks.DIRT.getDefaultState());
        structure.fillWithBlocks(world, start, 23, -5, -51, 27, -5, -47, Blocks.DIRT.getDefaultState());
        structure.fillWithBlocks(world, start, 23, -5, -20, 51, -5, 8, Blocks.DIRT.getDefaultState());
        structure.fillWithBlocks(world, start, 23, -5, 22, 27, -5, 26, Blocks.DIRT.getDefaultState());
        structure.fillWithBlocks(world, start, 23, -5, 31, 33, -5, 46, Blocks.DIRT.getDefaultState());
        structure.fillWithBlocks(world, start, 23, -5, 75, 31, -5, 75, Blocks.GRASS_BLOCK.getDefaultState().with(SnowyDirtBlock.SNOWY, false));
        structure.fillWithBlocks(world, start, 23, -4, -56, 33, -4, 16, Blocks.DIRT.getDefaultState());
        structure.fillWithBlocks(world, start, 23, -4, 56, 24, -4, 57, Blocks.GRASS_BLOCK.getDefaultState().with(SnowyDirtBlock.SNOWY, false));
        structure.fillWithBlocks(world, start, 23, -3, 33, 40, -3, 51, Blocks.DIRT.getDefaultState());
        structure.fillWithBlocks(world, start, 23, -3, 56, 23, -3, 56, Blocks.WATER.getDefaultState());
        structure.fillWithBlocks(world, start, 23, -2, -29, 23, -2, 54, Blocks.DIRT.getDefaultState());
        structure.fillWithBlocks(world, start, 23, -1, -40, 24, -1, -32, Blocks.GRASS_BLOCK.getDefaultState().with(SnowyDirtBlock.SNOWY, false));
        structure.fillWithBlocks(world, start, 23, -1, -31, 23, -1, -25, Blocks.COBBLESTONE.getDefaultState());
        structure.fillWithBlocks(world, start, 23, -1, -24, 23, -1, -24, Blocks.GRASS_BLOCK.getDefaultState().with(SnowyDirtBlock.SNOWY, false));
        structure.fillWithBlocks(world, start, 23, -1, -23, 23, -1, -23, Blocks.GRASS_PATH.getDefaultState());
        structure.fillWithBlocks(world, start, 23, -1, -22, 23, -1, -19, Blocks.GRASS_BLOCK.getDefaultState().with(SnowyDirtBlock.SNOWY, false));
        structure.fillWithBlocks(world, start, 23, -1, -17, 26, -1, -11, Blocks.GRASS_BLOCK.getDefaultState().with(SnowyDirtBlock.SNOWY, false));
        structure.fillWithBlocks(world, start, 23, -1, 2, 26, -1, 5, Blocks.GRASS_BLOCK.getDefaultState().with(SnowyDirtBlock.SNOWY, false));
        structure.fillWithBlocks(world, start, 23, -1, 6, 24, -1, 8, Blocks.GRASS_BLOCK.getDefaultState().with(SnowyDirtBlock.SNOWY, false));
        structure.fillWithBlocks(world, start, 23, -1, 22, 24, -1, 45, Blocks.GRASS_BLOCK.getDefaultState().with(SnowyDirtBlock.SNOWY, false));
        structure.fillWithBlocks(world, start, 23, -1, 46, 26, -1, 49, Blocks.DIRT.getDefaultState());
        structure.fillWithBlocks(world, start, 23, 0, -50, 23, 2, -50, Blocks.SPRUCE_LOG.getDefaultState());
        structure.fillWithBlocks(world, start, 23, 0, -49, 23, 3, -49, Blocks.OAK_LOG.getDefaultState());
        structure.fillWithBlocks(world, start, 23, 0, -48, 24, 0, -47, Blocks.DIRT.getDefaultState());
        structure.fillWithBlocks(world, start, 23, 0, -46, 23, 2, -46, Blocks.SPRUCE_LOG.getDefaultState());
        structure.fillWithBlocks(world, start, 23, 0, -44, 23, 1, -44, Blocks.SPRUCE_LOG.getDefaultState());
        structure.fillWithBlocks(world, start, 23, 0, -29, 23, 0, -27, Blocks.YELLOW_CARPET.getDefaultState());
        structure.fillWithBlocks(world, start, 23, 0, 9, 24, 0, 9, Blocks.DARK_OAK_PLANKS.getDefaultState());
        structure.fillWithBlocks(world, start, 23, 0, 13, 28, 0, 13, Blocks.OAK_PLANKS.getDefaultState());
        structure.fillWithBlocks(world, start, 23, 0, 19, 24, 0, 19, Blocks.DARK_OAK_PLANKS.getDefaultState());
        structure.fillWithBlocks(world, start, 23, 0, 26, 23, 0, 29, Blocks.OAK_FENCE.getDefaultState().with(FourWayBlock.WATERLOGGED, false).with(FourWayBlock.NORTH, true).with(FourWayBlock.SOUTH, true).with(FourWayBlock.EAST, false).with(FourWayBlock.WEST, false));
        structure.fillWithBlocks(world, start, 23, 0, 31, 23, 0, 33, Blocks.OAK_FENCE.getDefaultState().with(FourWayBlock.WATERLOGGED, false).with(FourWayBlock.NORTH, true).with(FourWayBlock.SOUTH, true).with(FourWayBlock.EAST, false).with(FourWayBlock.WEST, false));
        structure.fillWithBlocks(world, start, 23, 0, 46, 23, 1, 46, Blocks.OAK_LOG.getDefaultState());
        structure.fillWithBlocks(world, start, 23, 0, 51, 23, 3, 51, Blocks.OAK_LOG.getDefaultState());
        structure.fillWithBlocks(world, start, 23, 0, 52, 23, 2, 52, Blocks.SPRUCE_LOG.getDefaultState());
        structure.fillWithBlocks(world, start, 23, 1, -48, 24, 1, -47, Blocks.DIRT.getDefaultState());
        structure.fillWithBlocks(world, start, 23, 1, 9, 24, 2, 9, Blocks.OAK_PLANKS.getDefaultState());
        structure.fillWithBlocks(world, start, 23, 1, 19, 24, 2, 19, Blocks.OAK_PLANKS.getDefaultState());
        structure.fillWithBlocks(world, start, 23, 1, 48, 23, 2, 48, Blocks.OAK_LOG.getDefaultState());
        structure.fillWithBlocks(world, start, 23, 2, 10, 28, 2, 10, Index.SHELF_SPRUCE.getDefaultState().with(Shelf.FACING, Direction.SOUTH));
        structure.fillWithBlocks(world, start, 23, 3, -32, 24, 3, -31, Blocks.OAK_PLANKS.getDefaultState());
        structure.fillWithBlocks(world, start, 23, 3, -9, 24, 3, -9, Blocks.DARK_OAK_SLAB.getDefaultState().with(SlabBlock.TYPE, SlabType.TOP).with(SlabBlock.WATERLOGGED, false));
        structure.fillWithBlocks(world, start, 23, 3, -5, 24, 3, -5, Blocks.DARK_OAK_SLAB.getDefaultState().with(SlabBlock.TYPE, SlabType.TOP).with(SlabBlock.WATERLOGGED, false));
        structure.fillWithBlocks(world, start, 23, 3, 8, 32, 3, 8, Blocks.OAK_PLANKS.getDefaultState());
        structure.fillWithBlocks(world, start, 23, 3, 20, 32, 3, 20, Blocks.OAK_PLANKS.getDefaultState());
        structure.fillWithBlocks(world, start, 23, 4, -31, 24, 4, -30, Blocks.OAK_PLANKS.getDefaultState());
        structure.fillWithBlocks(world, start, 23, 4, -8, 24, 4, -8, Blocks.DARK_OAK_SLAB.getDefaultState().with(SlabBlock.TYPE, SlabType.TOP).with(SlabBlock.WATERLOGGED, false));
        structure.fillWithBlocks(world, start, 23, 4, -6, 24, 4, -6, Blocks.DARK_OAK_SLAB.getDefaultState().with(SlabBlock.TYPE, SlabType.TOP).with(SlabBlock.WATERLOGGED, false));
        structure.fillWithBlocks(world, start, 23, 4, 8, 32, 4, 8, Blocks.OAK_STAIRS.getDefaultState().with(StairsBlock.FACING, Direction.SOUTH).with(StairsBlock.WATERLOGGED, false).with(StairsBlock.SHAPE, StairsShape.STRAIGHT).with(StairsBlock.HALF, Half.BOTTOM));
        structure.fillWithBlocks(world, start, 23, 4, 20, 31, 4, 20, Blocks.OAK_STAIRS.getDefaultState().with(StairsBlock.FACING, Direction.NORTH).with(StairsBlock.WATERLOGGED, false).with(StairsBlock.SHAPE, StairsShape.STRAIGHT).with(StairsBlock.HALF, Half.BOTTOM));
        structure.fillWithBlocks(world, start, 23, 5, -30, 24, 5, -29, Blocks.OAK_PLANKS.getDefaultState());
        structure.fillWithBlocks(world, start, 23, 6, 10, 24, 6, 10, Blocks.DARK_OAK_SLAB.getDefaultState().with(SlabBlock.TYPE, SlabType.TOP).with(SlabBlock.WATERLOGGED, false));
        structure.fillWithBlocks(world, start, 23, 8, 11, 24, 8, 11, Blocks.DARK_OAK_SLAB.getDefaultState().with(SlabBlock.TYPE, SlabType.TOP).with(SlabBlock.WATERLOGGED, false));
        structure.fillWithBlocks(world, start, 23, 8, 17, 24, 8, 17, Blocks.DARK_OAK_SLAB.getDefaultState().with(SlabBlock.TYPE, SlabType.TOP).with(SlabBlock.WATERLOGGED, false));
        structure.fillWithBlocks(world, start, 23, 9, 12, 24, 9, 12, Blocks.DARK_OAK_SLAB.getDefaultState().with(SlabBlock.TYPE, SlabType.TOP).with(SlabBlock.WATERLOGGED, false));
        structure.fillWithBlocks(world, start, 23, 9, 16, 24, 9, 16, Blocks.DARK_OAK_SLAB.getDefaultState().with(SlabBlock.TYPE, SlabType.TOP).with(SlabBlock.WATERLOGGED, false));
        structure.fillWithBlocks(world, start, 23, 10, 13, 24, 10, 13, Blocks.DARK_OAK_SLAB.getDefaultState().with(SlabBlock.TYPE, SlabType.TOP).with(SlabBlock.WATERLOGGED, false));
        structure.fillWithBlocks(world, start, 23, 10, 15, 24, 10, 15, Blocks.DARK_OAK_SLAB.getDefaultState().with(SlabBlock.TYPE, SlabType.TOP).with(SlabBlock.WATERLOGGED, false));
        structure.fillWithBlocks(world, start, 24, -7, -73, 25, -7, -72, Blocks.DIRT.getDefaultState());
        structure.fillWithBlocks(world, start, 24, -7, -56, 29, -7, -36, Blocks.STONE.getDefaultState());
        structure.fillWithBlocks(world, start, 24, -7, -29, 32, -7, -18, Blocks.STONE.getDefaultState());
        structure.fillWithBlocks(world, start, 24, -7, -17, 26, -7, -3, Blocks.STONE.getDefaultState());
        structure.fillWithBlocks(world, start, 24, -7, 2, 31, -7, 12, Blocks.DIRT.getDefaultState());
        structure.fillWithBlocks(world, start, 24, -7, 34, 24, -7, 34, Blocks.STONE.getDefaultState());
        structure.fillWithBlocks(world, start, 24, -7, 35, 24, -7, 43, Blocks.ANDESITE.getDefaultState());
        structure.fillWithBlocks(world, start, 24, -7, 44, 29, -7, 60, Blocks.STONE.getDefaultState());
        structure.fillWithBlocks(world, start, 24, -7, 61, 24, -7, 68, Blocks.STONE.getDefaultState());
        structure.fillWithBlocks(world, start, 24, -7, 70, 28, -7, 74, Blocks.STONE.getDefaultState());
        structure.fillWithBlocks(world, start, 24, -7, 75, 25, -7, 76, Blocks.DIRT.getDefaultState());
        structure.fillWithBlocks(world, start, 24, -7, 77, 26, -7, 80, Blocks.GRASS_BLOCK.getDefaultState().with(SnowyDirtBlock.SNOWY, false));
        structure.fillWithBlocks(world, start, 24, -6, -68, 28, -6, -63, Blocks.STONE.getDefaultState());
        structure.fillWithBlocks(world, start, 24, -6, -62, 24, -2, -57, Blocks.DIRT.getDefaultState());
        structure.fillWithBlocks(world, start, 24, -6, -52, 32, -6, -43, Blocks.STONE.getDefaultState());
        structure.fillWithBlocks(world, start, 24, -6, -35, 24, -5, -34, Blocks.DIRT.getDefaultState());
        structure.fillWithBlocks(world, start, 24, -6, -33, 25, -6, -31, Blocks.GRANITE.getDefaultState());
        structure.fillWithBlocks(world, start, 24, -6, -28, 34, -6, -18, Blocks.STONE.getDefaultState());
        structure.fillWithBlocks(world, start, 24, -6, -4, 26, -6, -2, Blocks.STONE.getDefaultState());
        structure.fillWithBlocks(world, start, 24, -6, 0, 29, -6, 12, Blocks.DIRT.getDefaultState());
        structure.fillWithBlocks(world, start, 24, -6, 13, 26, -6, 34, Blocks.STONE.getDefaultState());
        structure.fillWithBlocks(world, start, 24, -6, 35, 24, -6, 44, Blocks.ANDESITE.getDefaultState());
        structure.fillWithBlocks(world, start, 24, -6, 45, 25, -6, 55, Blocks.STONE.getDefaultState());
        structure.fillWithBlocks(world, start, 24, -6, 62, 25, -6, 72, Blocks.STONE.getDefaultState());
        structure.fillWithBlocks(world, start, 24, -5, -46, 24, -5, -46, Blocks.DIRT.getDefaultState());
        structure.fillWithBlocks(world, start, 24, -5, -45, 24, -5, -44, Blocks.STONE.getDefaultState());
        structure.fillWithBlocks(world, start, 24, -5, 27, 24, -5, 27, Blocks.DIRT.getDefaultState());
        structure.fillWithBlocks(world, start, 24, -5, 28, 24, -5, 29, Blocks.STONE.getDefaultState());
        structure.fillWithBlocks(world, start, 24, -5, 30, 31, -5, 46, Blocks.DIRT.getDefaultState());
        structure.fillWithBlocks(world, start, 24, -5, 74, 65, -5, 74, Blocks.DIRT.getDefaultState());
        structure.fillWithBlocks(world, start, 24, -4, -70, 41, -4, -53, Blocks.DIRT.getDefaultState());
        structure.fillWithBlocks(world, start, 24, -4, 74, 31, -4, 74, Blocks.GRASS_BLOCK.getDefaultState().with(SnowyDirtBlock.SNOWY, false));
        structure.fillWithBlocks(world, start, 24, -3, 53, 26, -3, 55, Blocks.DIRT.getDefaultState());
        structure.fillWithBlocks(world, start, 24, -3, 56, 24, -3, 57, Blocks.WATER.getDefaultState());
        structure.fillWithBlocks(world, start, 24, -2, -28, 43, -2, -9, Blocks.DIRT.getDefaultState());
        structure.fillWithBlocks(world, start, 24, -2, 13, 27, -2, 54, Blocks.DIRT.getDefaultState());
        structure.fillWithBlocks(world, start, 24, -1, -43, 45, -1, -43, Blocks.DIRT.getDefaultState());
        structure.fillWithBlocks(world, start, 24, -1, -42, 26, -1, -40, Blocks.GRASS_BLOCK.getDefaultState().with(SnowyDirtBlock.SNOWY, false));
        structure.fillWithBlocks(world, start, 24, -1, -31, 28, -1, -31, Blocks.DIRT.getDefaultState());
        structure.fillWithBlocks(world, start, 24, -1, -30, 27, -1, -26, Blocks.COBBLESTONE.getDefaultState());
        structure.fillWithBlocks(world, start, 24, -1, -25, 28, -1, -25, Blocks.DIRT.getDefaultState());
        structure.fillWithBlocks(world, start, 24, -1, -24, 24, -1, -23, Blocks.GRASS_BLOCK.getDefaultState().with(SnowyDirtBlock.SNOWY, false));
        structure.fillWithBlocks(world, start, 24, -1, -22, 24, -1, -22, Blocks.GRASS_PATH.getDefaultState());
        structure.fillWithBlocks(world, start, 24, -1, -21, 24, -1, -11, Blocks.GRASS_BLOCK.getDefaultState().with(SnowyDirtBlock.SNOWY, false));
        structure.fillWithBlocks(world, start, 24, -1, -10, 24, -1, -3, Blocks.COBBLESTONE.getDefaultState());
        structure.fillWithBlocks(world, start, 24, -1, 20, 25, -1, 21, Blocks.GRASS_BLOCK.getDefaultState().with(SnowyDirtBlock.SNOWY, false));
        structure.fillWithBlocks(world, start, 24, 0, -50, 24, 2, -50, Blocks.OAK_LOG.getDefaultState());
        structure.fillWithBlocks(world, start, 24, 0, -49, 24, 3, -49, Blocks.SPRUCE_LOG.getDefaultState());
        structure.fillWithBlocks(world, start, 24, 0, -46, 24, 2, -46, Blocks.OAK_LOG.getDefaultState());
        structure.fillWithBlocks(world, start, 24, 0, -44, 30, 0, -44, Blocks.DIRT.getDefaultState());
        structure.fillWithBlocks(world, start, 24, 0, -43, 24, 1, -43, Blocks.OAK_LOG.getDefaultState());
        structure.fillWithBlocks(world, start, 24, 0, -39, 24, 0, -35, Blocks.COBBLESTONE_WALL.getDefaultState().with(WallBlock.WATERLOGGED, false).with(WallBlock.UP, false).with(WallBlock.WALL_HEIGHT_NORTH, WallHeight.LOW).with(WallBlock.WALL_HEIGHT_SOUTH, WallHeight.LOW).with(WallBlock.WALL_HEIGHT_EAST, WallHeight.LOW).with(WallBlock.WALL_HEIGHT_WEST, WallHeight.LOW));
        structure.fillWithBlocks(world, start, 24, 0, -31, 24, 2, -31, Blocks.SPRUCE_LOG.getDefaultState());
        structure.fillWithBlocks(world, start, 24, 0, -25, 24, 2, -25, Blocks.SPRUCE_LOG.getDefaultState());
        structure.fillWithBlocks(world, start, 24, 0, 24, 25, 0, 24, Blocks.OAK_FENCE.getDefaultState().with(FourWayBlock.WATERLOGGED, false).with(FourWayBlock.NORTH, false).with(FourWayBlock.SOUTH, false).with(FourWayBlock.EAST, true).with(FourWayBlock.WEST, true));
        structure.fillWithBlocks(world, start, 24, 0, 35, 29, 0, 35, Blocks.OAK_FENCE.getDefaultState().with(FourWayBlock.WATERLOGGED, false).with(FourWayBlock.NORTH, false).with(FourWayBlock.SOUTH, false).with(FourWayBlock.EAST, true).with(FourWayBlock.WEST, true));
        structure.fillWithBlocks(world, start, 24, 0, 46, 24, 1, 46, Blocks.SPRUCE_LOG.getDefaultState());
        structure.fillWithBlocks(world, start, 24, 0, 51, 24, 3, 51, Blocks.SPRUCE_LOG.getDefaultState());
        structure.fillWithBlocks(world, start, 24, 0, 52, 24, 2, 52, Blocks.OAK_LOG.getDefaultState());
        structure.fillWithBlocks(world, start, 24, 1, -44, 30, 1, -44, Blocks.GRASS_BLOCK.getDefaultState().with(SnowyDirtBlock.SNOWY, false));
        structure.fillWithBlocks(world, start, 24, 1, 48, 24, 2, 48, Blocks.SPRUCE_LOG.getDefaultState());
        structure.fillWithBlocks(world, start, 24, 2, -11, 27, 2, -11, Blocks.OAK_PLANKS.getDefaultState());
        structure.fillWithBlocks(world, start, 24, 3, -10, 27, 3, -10, Blocks.OAK_PLANKS.getDefaultState());
        structure.fillWithBlocks(world, start, 24, 3, -4, 27, 3, -4, Blocks.OAK_PLANKS.getDefaultState());
        structure.fillWithBlocks(world, start, 24, 4, -9, 27, 4, -9, Blocks.OAK_PLANKS.getDefaultState());
        structure.fillWithBlocks(world, start, 24, 4, -5, 27, 4, -5, Blocks.OAK_PLANKS.getDefaultState());
        structure.fillWithBlocks(world, start, 24, 4, 10, 25, 4, 11, Blocks.OAK_PLANKS.getDefaultState());
        structure.fillWithBlocks(world, start, 24, 4, 17, 25, 4, 18, Blocks.OAK_PLANKS.getDefaultState());
        structure.fillWithBlocks(world, start, 24, 5, -8, 27, 5, -8, Blocks.OAK_PLANKS.getDefaultState());
        structure.fillWithBlocks(world, start, 24, 5, -6, 27, 5, -6, Blocks.OAK_PLANKS.getDefaultState());
        structure.fillWithBlocks(world, start, 24, 6, -29, 25, 6, -27, Blocks.OAK_PLANKS.getDefaultState());
        structure.fillWithBlocks(world, start, 24, 6, -7, 27, 6, -7, Blocks.OAK_PLANKS.getDefaultState());
        structure.fillWithBlocks(world, start, 25, -7, -35, 25, -7, -35, Blocks.STONE.getDefaultState());
        structure.fillWithBlocks(world, start, 25, -7, -34, 25, -6, -31, Blocks.GRANITE.getDefaultState());
        structure.fillWithBlocks(world, start, 25, -7, -30, 32, -7, -18, Blocks.STONE.getDefaultState());
        structure.fillWithBlocks(world, start, 25, -7, -2, 25, -6, -2, Blocks.STONE.getDefaultState());
        structure.fillWithBlocks(world, start, 25, -7, 0, 31, -7, 13, Blocks.DIRT.getDefaultState());
        structure.fillWithBlocks(world, start, 25, -7, 14, 26, -7, 35, Blocks.STONE.getDefaultState());
        structure.fillWithBlocks(world, start, 25, -7, 36, 25, -6, 40, Blocks.ANDESITE.getDefaultState());
        structure.fillWithBlocks(world, start, 25, -7, 41, 25, -6, 41, Blocks.COAL_ORE.getDefaultState());
        structure.fillWithBlocks(world, start, 25, -7, 42, 26, -7, 43, Blocks.ANDESITE.getDefaultState());
        structure.fillWithBlocks(world, start, 25, -7, 61, 26, -7, 61, Blocks.COAL_ORE.getDefaultState());
        structure.fillWithBlocks(world, start, 25, -7, 62, 37, -7, 74, Blocks.STONE.getDefaultState());
        structure.fillWithBlocks(world, start, 25, -6, -70, 28, -6, -56, Blocks.STONE.getDefaultState());
        structure.fillWithBlocks(world, start, 25, -6, -55, 26, -6, -54, Blocks.DIRT.getDefaultState());
        structure.fillWithBlocks(world, start, 25, -6, -35, 25, -6, -35, Blocks.STONE.getDefaultState());
        structure.fillWithBlocks(world, start, 25, -6, -30, 32, -6, -18, Blocks.STONE.getDefaultState());
        structure.fillWithBlocks(world, start, 25, -6, -8, 26, -6, -2, Blocks.STONE.getDefaultState());
        structure.fillWithBlocks(world, start, 25, -6, -1, 28, -6, 12, Blocks.DIRT.getDefaultState());
        structure.fillWithBlocks(world, start, 25, -6, 35, 25, -6, 35, Blocks.STONE.getDefaultState());
        structure.fillWithBlocks(world, start, 25, -6, 42, 27, -6, 44, Blocks.ANDESITE.getDefaultState());
        structure.fillWithBlocks(world, start, 25, -5, -46, 42, -5, -29, Blocks.DIRT.getDefaultState());
        structure.fillWithBlocks(world, start, 25, -5, 27, 28, -5, 46, Blocks.DIRT.getDefaultState());
        structure.fillWithBlocks(world, start, 25, -5, 47, 25, -5, 48, Blocks.STONE.getDefaultState());
        structure.fillWithBlocks(world, start, 25, -5, 49, 40, -5, 70, Blocks.DIRT.getDefaultState());
        structure.fillWithBlocks(world, start, 25, -5, 72, 27, -5, 74, Blocks.DIRT.getDefaultState());
        structure.fillWithBlocks(world, start, 25, -4, 56, 25, -4, 56, Blocks.GRASS_BLOCK.getDefaultState().with(SnowyDirtBlock.SNOWY, false));
        structure.fillWithBlocks(world, start, 25, -4, 57, 25, -4, 73, Blocks.DIRT.getDefaultState());
        structure.fillWithBlocks(world, start, 25, -3, 56, 25, -3, 56, Blocks.WATER.getDefaultState());
        structure.fillWithBlocks(world, start, 25, -3, 73, 51, -3, 73, Blocks.GRASS_BLOCK.getDefaultState().with(SnowyDirtBlock.SNOWY, false));
        structure.fillWithBlocks(world, start, 25, -2, -69, 37, -2, -57, Blocks.DIRT.getDefaultState());
        structure.fillWithBlocks(world, start, 25, -2, -29, 45, -2, -9, Blocks.DIRT.getDefaultState());
        structure.fillWithBlocks(world, start, 25, -1, -69, 37, -1, -57, Blocks.GRASS_BLOCK.getDefaultState().with(SnowyDirtBlock.SNOWY, false));
        structure.fillWithBlocks(world, start, 25, -1, -39, 25, -1, -35, Blocks.FARMLAND.getDefaultState().with(FarmlandBlock.MOISTURE, 7));
        structure.fillWithBlocks(world, start, 25, -1, -34, 25, -1, -34, Blocks.GRASS_BLOCK.getDefaultState().with(SnowyDirtBlock.SNOWY, false));
        structure.fillWithBlocks(world, start, 25, -1, -24, 25, -1, -24, Blocks.GRASS_BLOCK.getDefaultState().with(SnowyDirtBlock.SNOWY, false));
        structure.fillWithBlocks(world, start, 25, -1, -22, 25, -1, -22, Blocks.GRASS_BLOCK.getDefaultState().with(SnowyDirtBlock.SNOWY, false));
        structure.fillWithBlocks(world, start, 25, -1, -20, 26, -1, -11, Blocks.GRASS_BLOCK.getDefaultState().with(SnowyDirtBlock.SNOWY, false));
        structure.fillWithBlocks(world, start, 25, -1, -10, 30, -1, -10, Blocks.DIRT.getDefaultState());
        structure.fillWithBlocks(world, start, 25, -1, -4, 30, -1, -4, Blocks.DIRT.getDefaultState());
        structure.fillWithBlocks(world, start, 25, -1, -3, 26, -1, -2, Blocks.GRASS_BLOCK.getDefaultState().with(SnowyDirtBlock.SNOWY, false));
        structure.fillWithBlocks(world, start, 25, -1, -1, 27, -1, 1, Blocks.GRASS_PATH.getDefaultState());
        structure.fillWithBlocks(world, start, 25, -1, 7, 26, -1, 8, Blocks.GRASS_BLOCK.getDefaultState().with(SnowyDirtBlock.SNOWY, false));
        structure.fillWithBlocks(world, start, 25, -1, 33, 28, -1, 44, Blocks.GRASS_BLOCK.getDefaultState().with(SnowyDirtBlock.SNOWY, false));
        structure.fillWithBlocks(world, start, 25, -1, 45, 28, -1, 48, Blocks.DIRT.getDefaultState());
        structure.fillWithBlocks(world, start, 25, -1, 51, 27, -1, 53, Blocks.DIRT.getDefaultState());
        structure.fillWithBlocks(world, start, 25, 0, -50, 25, 2, -50, Blocks.SPRUCE_LOG.getDefaultState());
        structure.fillWithBlocks(world, start, 25, 0, -49, 25, 3, -49, Blocks.OAK_LOG.getDefaultState());
        structure.fillWithBlocks(world, start, 25, 0, -48, 26, 0, -46, Blocks.DIRT.getDefaultState());
        structure.fillWithBlocks(world, start, 25, 0, -43, 25, 1, -43, Blocks.SPRUCE_LOG.getDefaultState());
        structure.fillWithBlocks(world, start, 25, 0, -40, 34, 0, -40, Blocks.COBBLESTONE_WALL.getDefaultState().with(WallBlock.WATERLOGGED, false).with(WallBlock.UP, false).with(WallBlock.WALL_HEIGHT_NORTH, WallHeight.LOW).with(WallBlock.WALL_HEIGHT_SOUTH, WallHeight.LOW).with(WallBlock.WALL_HEIGHT_EAST, WallHeight.LOW).with(WallBlock.WALL_HEIGHT_WEST, WallHeight.LOW));
        structure.fillWithBlocks(world, start, 25, 0, -38, 26, 0, -38, Blocks.BEETROOTS.getDefaultState().with(BeetrootBlock.BEETROOT_AGE, 3));
        structure.fillWithBlocks(world, start, 25, 0, -36, 25, 0, -35, Blocks.BEETROOTS.getDefaultState().with(BeetrootBlock.BEETROOT_AGE, 3));
