package mod.arcalitegames.odyssey.world.structure.town.fortmesa;

import mod.arcalitegames.buildersaddition.Index;
import mod.arcalitegames.buildersaddition.blocks.Bookshelf;
import mod.arcalitegames.buildersaddition.blocks.Cabinet;
import mod.arcalitegames.buildersaddition.blocks.Counter;
import mod.arcalitegames.buildersaddition.blocks.Cupboard;
import mod.arcalitegames.buildersaddition.blocks.IronFence;
import mod.arcalitegames.buildersaddition.blocks.Shelf;
import mod.arcalitegames.buildersaddition.blocks.Stool;
import mod.arcalitegames.buildersaddition.blocks.VerticalSlab;
import mod.arcalitegames.buildersaddition.state.StoolState;
import mod.arcalitegames.buildersaddition.state.VerticalSlabState;
import mod.arcalitegames.odyssey.world.structure.StructureBase;
import net.minecraft.block.AbstractFurnaceBlock;
import net.minecraft.block.BarrelBlock;
import net.minecraft.block.BedBlock;
import net.minecraft.block.Blocks;
import net.minecraft.block.CakeBlock;
import net.minecraft.block.CauldronBlock;
import net.minecraft.block.ChainBlock;
import net.minecraft.block.FourWayBlock;
import net.minecraft.block.HorizontalBlock;
import net.minecraft.block.LadderBlock;
import net.minecraft.block.LeavesBlock;
import net.minecraft.block.SlabBlock;
import net.minecraft.block.StairsBlock;
import net.minecraft.block.TrapDoorBlock;
import net.minecraft.block.WallSignBlock;
import net.minecraft.state.properties.BedPart;
import net.minecraft.state.properties.DoubleBlockHalf;
import net.minecraft.state.properties.Half;
import net.minecraft.state.properties.SlabType;
import net.minecraft.state.properties.StairsShape;
import net.minecraft.util.Direction;
import net.minecraft.util.math.BlockPos;
import net.minecraft.world.World;

public class FortMesaComponent1
{

	public static BlockPos start;
    public static World world;
    public static StructureBase structure;

    public static void init(World worldIn, BlockPos blockPos, StructureBase structureIn)
    {
        world = worldIn; start = blockPos; structure = structureIn;
    }
    
    public static void generatePart11()
    {
        structure.fillWithBlocks(world, start, -19, 9, -58, -19, 10, -58, Blocks.OAK_LEAVES.getDefaultState().with(LeavesBlock.PERSISTENT, true).with(LeavesBlock.DISTANCE, 1));
        structure.fillWithBlocks(world, start, -19, 9, -57, -19, 10, -57, Blocks.OAK_LEAVES.getDefaultState().with(LeavesBlock.PERSISTENT, true).with(LeavesBlock.DISTANCE, 2));
        structure.fillWithBlocks(world, start, -19, 10, -67, -17, 10, -67, Blocks.OAK_LEAVES.getDefaultState().with(LeavesBlock.PERSISTENT, true).with(LeavesBlock.DISTANCE, 2));
        structure.fillWithBlocks(world, start, -19, 11, -68, -17, 11, -68, Blocks.OAK_LEAVES.getDefaultState().with(LeavesBlock.PERSISTENT, true).with(LeavesBlock.DISTANCE, 2));
        structure.fillWithBlocks(world, start, -19, 11, -67, -17, 11, -67, Blocks.OAK_LEAVES.getDefaultState().with(LeavesBlock.PERSISTENT, true).with(LeavesBlock.DISTANCE, 1));
        structure.fillWithBlocks(world, start, -19, 11, -62, -19, 11, -61, Blocks.OAK_LEAVES.getDefaultState().with(LeavesBlock.PERSISTENT, true).with(LeavesBlock.DISTANCE, 3));
        structure.fillWithBlocks(world, start, -19, 11, -60, -19, 11, -60, Blocks.OAK_LEAVES.getDefaultState().with(LeavesBlock.PERSISTENT, true).with(LeavesBlock.DISTANCE, 2));
        structure.fillWithBlocks(world, start, -19, 12, -67, -19, 12, -66, Blocks.OAK_LEAVES.getDefaultState().with(LeavesBlock.PERSISTENT, true).with(LeavesBlock.DISTANCE, 1));
        structure.fillWithBlocks(world, start, -19, 12, -63, -19, 12, -63, Blocks.OAK_LEAVES.getDefaultState().with(LeavesBlock.PERSISTENT, true).with(LeavesBlock.DISTANCE, 3));
        structure.fillWithBlocks(world, start, -19, 12, -61, -17, 12, -61, Blocks.OAK_LEAVES.getDefaultState().with(LeavesBlock.PERSISTENT, true).with(LeavesBlock.DISTANCE, 3));
        structure.fillWithBlocks(world, start, -19, 13, -67, -19, 13, -66, Blocks.OAK_LEAVES.getDefaultState().with(LeavesBlock.PERSISTENT, true).with(LeavesBlock.DISTANCE, 2));
        structure.fillWithBlocks(world, start, -18, -9, -75, -17, -9, -73, Blocks.TERRACOTTA.getDefaultState());
        structure.fillWithBlocks(world, start, -18, -9, -60, -17, -9, -53, Blocks.STONE.getDefaultState());
        structure.fillWithBlocks(world, start, -18, -9, -52, -18, -8, -51, Blocks.DIORITE.getDefaultState());
        structure.fillWithBlocks(world, start, -18, -9, -50, -10, -9, -42, Blocks.STONE.getDefaultState());
        structure.fillWithBlocks(world, start, -18, -9, 28, -18, -8, 28, Blocks.GOLD_ORE.getDefaultState());
        structure.fillWithBlocks(world, start, -18, -9, 29, -16, -9, 31, Blocks.ANDESITE.getDefaultState());
        structure.fillWithBlocks(world, start, -18, -8, -58, -13, -8, -53, Blocks.STONE.getDefaultState());
        structure.fillWithBlocks(world, start, -18, -8, -50, -9, -8, -41, Blocks.STONE.getDefaultState());
        structure.fillWithBlocks(world, start, -18, -8, -40, -17, -8, -32, Blocks.STONE.getDefaultState());
        structure.fillWithBlocks(world, start, -18, -8, -31, -18, -5, -31, Blocks.STONE.getDefaultState());
        structure.fillWithBlocks(world, start, -18, -8, -29, -17, -8, -28, Blocks.ANDESITE.getDefaultState());
        structure.fillWithBlocks(world, start, -18, -8, -27, -18, -7, -24, Blocks.STONE.getDefaultState());
        structure.fillWithBlocks(world, start, -18, -8, -23, -18, -8, -19, Blocks.GRAVEL.getDefaultState());
        structure.fillWithBlocks(world, start, -18, -8, -18, -17, -8, -8, Blocks.STONE.getDefaultState());
        structure.fillWithBlocks(world, start, -18, -8, 27, -18, -8, 27, Blocks.ANDESITE.getDefaultState());
        structure.fillWithBlocks(world, start, -18, -7, -54, -8, -7, -34, Blocks.STONE.getDefaultState());
        structure.fillWithBlocks(world, start, -18, -7, -29, -18, -6, -28, Blocks.STONE.getDefaultState());
        structure.fillWithBlocks(world, start, -18, -7, -23, -18, -7, -23, Blocks.STONE.getDefaultState());
        structure.fillWithBlocks(world, start, -18, -7, -22, -18, -7, -22, Blocks.GRAVEL.getDefaultState());
        structure.fillWithBlocks(world, start, -18, -7, -18, -18, -5, -12, Blocks.STONE.getDefaultState());
        structure.fillWithBlocks(world, start, -18, -7, -11, -17, -7, 26, Blocks.STONE.getDefaultState());
        structure.fillWithBlocks(world, start, -18, -7, 27, -15, -7, 30, Blocks.ANDESITE.getDefaultState());
        structure.fillWithBlocks(world, start, -18, -7, 32, -17, -7, 33, Blocks.STONE.getDefaultState());
        structure.fillWithBlocks(world, start, -18, -7, 36, -1, -7, 36, Blocks.RED_SAND.getDefaultState());
        structure.fillWithBlocks(world, start, -18, -6, -71, -16, -6, -69, Blocks.STONE.getDefaultState());
        structure.fillWithBlocks(world, start, -18, -6, -68, -18, -5, -68, Blocks.DIORITE.getDefaultState());
        structure.fillWithBlocks(world, start, -18, -6, -67, -5, -6, -47, Blocks.STONE.getDefaultState());
        structure.fillWithBlocks(world, start, -18, -6, -24, -18, -6, -22, Blocks.STONE.getDefaultState());
        structure.fillWithBlocks(world, start, -18, -6, -21, -16, -6, -19, Blocks.DIORITE.getDefaultState());
        structure.fillWithBlocks(world, start, -18, -6, 23, -15, -6, 26, Blocks.STONE.getDefaultState());
        structure.fillWithBlocks(world, start, -18, -5, -71, -17, -4, -71, Blocks.RED_SAND.getDefaultState());
        structure.fillWithBlocks(world, start, -18, -5, -69, -18, -5, -69, Blocks.STONE.getDefaultState());
        structure.fillWithBlocks(world, start, -18, -5, -67, -8, -5, -57, Blocks.STONE.getDefaultState());
        structure.fillWithBlocks(world, start, -18, -5, -47, -18, -5, -47, Blocks.RED_SAND.getDefaultState());
        structure.fillWithBlocks(world, start, -18, -5, -46, -18, -5, -44, Blocks.STONE.getDefaultState());
        structure.fillWithBlocks(world, start, -18, -5, -43, -17, -5, -42, Blocks.RED_SAND.getDefaultState());
        structure.fillWithBlocks(world, start, -18, -5, -41, -18, -5, -41, Blocks.ANDESITE.getDefaultState());
        structure.fillWithBlocks(world, start, -18, -5, -40, -18, -5, -39, Blocks.STONE.getDefaultState());
        structure.fillWithBlocks(world, start, -18, -5, -38, -18, -5, -36, Blocks.RED_SAND.getDefaultState());
        structure.fillWithBlocks(world, start, -18, -5, -34, -17, -5, -33, Blocks.RED_SAND.getDefaultState());
        structure.fillWithBlocks(world, start, -18, -5, -32, -18, -1, -32, Blocks.RED_SAND.getDefaultState());
        structure.fillWithBlocks(world, start, -18, -5, -7, -9, -5, 7, Blocks.STONE.getDefaultState());
        structure.fillWithBlocks(world, start, -18, -5, 22, -18, -5, 22, Blocks.STONE.getDefaultState());
        structure.fillWithBlocks(world, start, -18, -5, 24, -11, -5, 31, Blocks.STONE.getDefaultState());
        structure.fillWithBlocks(world, start, -18, -3, -71, 3, -3, -22, Blocks.RED_SAND.getDefaultState());
        structure.fillWithBlocks(world, start, -18, -3, -21, -17, -3, -20, Blocks.RED_SAND.getDefaultState());
        structure.fillWithBlocks(world, start, -18, -3, -19, -18, -1, -19, Blocks.COARSE_DIRT.getDefaultState());
        structure.fillWithBlocks(world, start, -18, -3, -18, -18, -1, 7, Blocks.RED_SAND.getDefaultState());
        structure.fillWithBlocks(world, start, -18, -2, -63, -7, -2, -22, Blocks.RED_SAND.getDefaultState());
        structure.fillWithBlocks(world, start, -18, -2, -21, -17, -2, -20, Blocks.RED_SAND.getDefaultState());
        structure.fillWithBlocks(world, start, -18, -2, 12, -16, -2, 12, Blocks.RED_SAND.getDefaultState());
        structure.fillWithBlocks(world, start, -18, -2, 13, -18, -2, 15, Blocks.STONE.getDefaultState());
        structure.fillWithBlocks(world, start, -18, -2, 16, -11, -2, 31, Blocks.RED_SAND.getDefaultState());
        structure.fillWithBlocks(world, start, -18, -1, -63, -7, -1, -22, Blocks.RED_SAND.getDefaultState());
        structure.fillWithBlocks(world, start, -18, -1, -21, -17, -1, -20, Blocks.RED_SAND.getDefaultState());
        structure.fillWithBlocks(world, start, -18, -1, 19, -17, -1, 20, Blocks.SPRUCE_PLANKS.getDefaultState());
        structure.fillWithBlocks(world, start, -18, -1, 21, -18, 7, 21, Blocks.STRIPPED_DARK_OAK_LOG.getDefaultState());
        structure.fillWithBlocks(world, start, -18, -1, 22, -11, -1, 29, Blocks.SPRUCE_PLANKS.getDefaultState());
        structure.fillWithBlocks(world, start, -18, -1, 30, -18, 7, 30, Blocks.STRIPPED_DARK_OAK_LOG.getDefaultState());
        structure.fillWithBlocks(world, start, -18, 0, -69, -15, 0, -43, Blocks.RED_SAND.getDefaultState());
        structure.fillWithBlocks(world, start, -18, 0, -22, -18, 0, -22, Blocks.SPRUCE_PLANKS.getDefaultState());
        structure.fillWithBlocks(world, start, -18, 0, 0, -18, 0, 3, Blocks.RED_SAND.getDefaultState());
        structure.fillWithBlocks(world, start, -18, 0, 22, -18, 0, 22, Blocks.OAK_PLANKS.getDefaultState());
        structure.fillWithBlocks(world, start, -18, 0, 24, -18, 0, 28, Blocks.OAK_PLANKS.getDefaultState());
        structure.fillWithBlocks(world, start, -18, 1, -12, -18, 2, -12, Blocks.BARREL.getDefaultState().with(BarrelBlock.PROPERTY_FACING, Direction.WEST).with(BarrelBlock.PROPERTY_OPEN, false));
        structure.fillWithBlocks(world, start, -18, 1, 19, -18, 2, 19, Blocks.DARK_OAK_FENCE.getDefaultState().with(FourWayBlock.WATERLOGGED, false).with(FourWayBlock.NORTH, false).with(FourWayBlock.SOUTH, false).with(FourWayBlock.EAST, false).with(FourWayBlock.WEST, false));
        structure.fillWithBlocks(world, start, -18, 1, 22, -17, 1, 23, Blocks.OAK_PLANKS.getDefaultState());
        structure.fillWithBlocks(world, start, -18, 1, 25, -18, 3, 29, Blocks.OAK_PLANKS.getDefaultState());
        structure.fillWithBlocks(world, start, -18, 2, -10, -18, 3, -10, Blocks.SPRUCE_PLANKS.getDefaultState());
        structure.fillWithBlocks(world, start, -18, 2, 22, -17, 2, 23, Blocks.OAK_PLANKS.getDefaultState());
        structure.fillWithBlocks(world, start, -18, 2, 24, -18, 4, 26, Blocks.OAK_PLANKS.getDefaultState());
        structure.fillWithBlocks(world, start, -18, 3, -38, -18, 3, -34, Blocks.DARK_OAK_SLAB.getDefaultState().with(SlabBlock.TYPE, SlabType.BOTTOM).with(SlabBlock.WATERLOGGED, false));
        structure.fillWithBlocks(world, start, -18, 3, 20, -9, 3, 20, Blocks.SPRUCE_SLAB.getDefaultState().with(SlabBlock.TYPE, SlabType.TOP).with(SlabBlock.WATERLOGGED, false));
        structure.fillWithBlocks(world, start, -18, 3, 22, -17, 3, 29, Blocks.OAK_PLANKS.getDefaultState());
        structure.fillWithBlocks(world, start, -18, 4, -32, -18, 4, -23, Blocks.SPRUCE_SLAB.getDefaultState().with(SlabBlock.TYPE, SlabType.TOP).with(SlabBlock.WATERLOGGED, false));
        structure.fillWithBlocks(world, start, -18, 4, 22, -18, 7, 22, Blocks.OAK_PLANKS.getDefaultState());
        structure.fillWithBlocks(world, start, -18, 4, 28, -18, 5, 29, Blocks.OAK_PLANKS.getDefaultState());
        structure.fillWithBlocks(world, start, -18, 5, -24, -18, 5, -24, Blocks.DARK_OAK_FENCE.getDefaultState().with(FourWayBlock.WATERLOGGED, false).with(FourWayBlock.NORTH, false).with(FourWayBlock.SOUTH, true).with(FourWayBlock.EAST, false).with(FourWayBlock.WEST, true));
        structure.fillWithBlocks(world, start, -18, 5, -23, -18, 5, -23, Blocks.DARK_OAK_FENCE.getDefaultState().with(FourWayBlock.WATERLOGGED, false).with(FourWayBlock.NORTH, true).with(FourWayBlock.SOUTH, false).with(FourWayBlock.EAST, true).with(FourWayBlock.WEST, false));
        structure.fillWithBlocks(world, start, -18, 5, 19, -18, 6, 19, Blocks.DARK_OAK_FENCE.getDefaultState().with(FourWayBlock.WATERLOGGED, false).with(FourWayBlock.NORTH, false).with(FourWayBlock.SOUTH, false).with(FourWayBlock.EAST, false).with(FourWayBlock.WEST, false));
        structure.fillWithBlocks(world, start, -18, 5, 23, -18, 6, 24, Blocks.OAK_PLANKS.getDefaultState());
        structure.fillWithBlocks(world, start, -18, 5, 25, -18, 5, 29, Blocks.OAK_PLANKS.getDefaultState());
        structure.fillWithBlocks(world, start, -18, 6, 26, -18, 7, 29, Blocks.OAK_PLANKS.getDefaultState());
        structure.fillWithBlocks(world, start, -18, 7, 19, -17, 7, 20, Blocks.SPRUCE_SLAB.getDefaultState().with(SlabBlock.TYPE, SlabType.BOTTOM).with(SlabBlock.WATERLOGGED, false));
        structure.fillWithBlocks(world, start, -18, 7, 23, -12, 7, 29, Blocks.OAK_PLANKS.getDefaultState());
        structure.fillWithBlocks(world, start, -18, 8, -23, -18, 8, -23, Blocks.SPRUCE_SLAB.getDefaultState().with(SlabBlock.TYPE, SlabType.BOTTOM).with(SlabBlock.WATERLOGGED, false));
        structure.fillWithBlocks(world, start, -18, 8, 22, -18, 8, 29, Blocks.SPRUCE_SLAB.getDefaultState().with(SlabBlock.TYPE, SlabType.BOTTOM).with(SlabBlock.WATERLOGGED, false));
        structure.fillWithBlocks(world, start, -18, 9, -60, -17, 9, -60, Blocks.OAK_LEAVES.getDefaultState().with(LeavesBlock.PERSISTENT, true).with(LeavesBlock.DISTANCE, 1));
        structure.fillWithBlocks(world, start, -18, 10, -61, -17, 10, -61, Blocks.OAK_LEAVES.getDefaultState().with(LeavesBlock.PERSISTENT, true).with(LeavesBlock.DISTANCE, 1));
        structure.fillWithBlocks(world, start, -18, 10, -60, -17, 10, -60, Blocks.OAK_WOOD.getDefaultState());
        structure.fillWithBlocks(world, start, -18, 11, -62, -18, 12, -62, Blocks.OAK_LEAVES.getDefaultState().with(LeavesBlock.PERSISTENT, true).with(LeavesBlock.DISTANCE, 3));
        structure.fillWithBlocks(world, start, -18, 11, -60, -17, 11, -60, Blocks.OAK_LEAVES.getDefaultState().with(LeavesBlock.PERSISTENT, true).with(LeavesBlock.DISTANCE, 1));
        structure.fillWithBlocks(world, start, -18, 11, -59, -17, 11, -59, Blocks.OAK_LEAVES.getDefaultState().with(LeavesBlock.PERSISTENT, true).with(LeavesBlock.DISTANCE, 2));
        structure.fillWithBlocks(world, start, -18, 12, -67, -17, 12, -67, Blocks.OAK_WOOD.getDefaultState());
        structure.fillWithBlocks(world, start, -18, 12, -65, -18, 12, -64, Blocks.OAK_LEAVES.getDefaultState().with(LeavesBlock.PERSISTENT, true).with(LeavesBlock.DISTANCE, 5));
        structure.fillWithBlocks(world, start, -18, 12, -63, -18, 12, -63, Blocks.OAK_LEAVES.getDefaultState().with(LeavesBlock.PERSISTENT, true).with(LeavesBlock.DISTANCE, 4));
        structure.fillWithBlocks(world, start, -17, -9, -76, -15, -9, -74, Blocks.TERRACOTTA.getDefaultState());
        structure.fillWithBlocks(world, start, -17, -9, -52, -15, -9, -42, Blocks.STONE.getDefaultState());
        structure.fillWithBlocks(world, start, -17, -9, -41, -17, -6, -41, Blocks.STONE.getDefaultState());
        structure.fillWithBlocks(world, start, -17, -9, -40, -16, -9, -39, Blocks.DIORITE.getDefaultState());
        structure.fillWithBlocks(world, start, -17, -9, -38, -17, -9, -32, Blocks.STONE.getDefaultState());
        structure.fillWithBlocks(world, start, -17, -9, -31, -14, -9, -28, Blocks.ANDESITE.getDefaultState());
        structure.fillWithBlocks(world, start, -17, -9, -27, -17, -9, -27, Blocks.ANDESITE.getDefaultState());
        structure.fillWithBlocks(world, start, -17, -9, -26, -17, -9, 26, Blocks.STONE.getDefaultState());
        structure.fillWithBlocks(world, start, -17, -9, 27, -15, -9, 29, Blocks.ANDESITE.getDefaultState());
        structure.fillWithBlocks(world, start, -17, -9, 33, -16, -9, 34, Blocks.STONE.getDefaultState());
        structure.fillWithBlocks(world, start, -17, -8, -74, -16, -8, -73, Blocks.RED_SAND.getDefaultState());
        structure.fillWithBlocks(world, start, -17, -8, -52, -8, -8, -41, Blocks.STONE.getDefaultState());
        structure.fillWithBlocks(world, start, -17, -8, -31, -14, -8, -28, Blocks.ANDESITE.getDefaultState());
        structure.fillWithBlocks(world, start, -17, -8, -27, -16, -8, -25, Blocks.ANDESITE.getDefaultState());
        structure.fillWithBlocks(world, start, -17, -8, -24, -15, -8, -22, Blocks.STONE.getDefaultState());
        structure.fillWithBlocks(world, start, -17, -8, -21, -17, -7, -20, Blocks.GRAVEL.getDefaultState());
        structure.fillWithBlocks(world, start, -17, -8, -19, -16, -8, -18, Blocks.STONE.getDefaultState());
        structure.fillWithBlocks(world, start, -17, -8, -7, -16, -8, 25, Blocks.STONE.getDefaultState());
        structure.fillWithBlocks(world, start, -17, -8, 27, -15, -8, 30, Blocks.ANDESITE.getDefaultState());
        structure.fillWithBlocks(world, start, -17, -8, 31, -17, -7, 31, Blocks.ANDESITE.getDefaultState());
        structure.fillWithBlocks(world, start, -17, -8, 32, -15, -8, 34, Blocks.STONE.getDefaultState());
        structure.fillWithBlocks(world, start, -17, -8, 37, -1, -8, 37, Blocks.RED_SAND.getDefaultState());
        structure.fillWithBlocks(world, start, -17, -7, -73, -17, -7, -72, Blocks.RED_SAND.getDefaultState());
        structure.fillWithBlocks(world, start, -17, -7, -31, -15, -7, -29, Blocks.ANDESITE.getDefaultState());
        structure.fillWithBlocks(world, start, -17, -7, -28, -16, -7, -27, Blocks.ANDESITE.getDefaultState());
        structure.fillWithBlocks(world, start, -17, -7, -26, -17, -6, -25, Blocks.ANDESITE.getDefaultState());
        structure.fillWithBlocks(world, start, -17, -7, -23, -16, -7, -22, Blocks.STONE.getDefaultState());
        structure.fillWithBlocks(world, start, -17, -7, -18, -15, -7, -13, Blocks.GRANITE.getDefaultState());
        structure.fillWithBlocks(world, start, -17, -7, -12, -17, -7, 26, Blocks.STONE.getDefaultState());
        structure.fillWithBlocks(world, start, -17, -7, 34, -15, -7, 36, Blocks.RED_SAND.getDefaultState());
        structure.fillWithBlocks(world, start, -17, -6, -68, -5, -6, -47, Blocks.STONE.getDefaultState());
        structure.fillWithBlocks(world, start, -17, -6, -31, -17, -6, -30, Blocks.STONE.getDefaultState());
        structure.fillWithBlocks(world, start, -17, -6, -29, -16, -6, -28, Blocks.ANDESITE.getDefaultState());
        structure.fillWithBlocks(world, start, -17, -6, -27, -17, -6, -24, Blocks.ANDESITE.getDefaultState());
        structure.fillWithBlocks(world, start, -17, -6, -23, -16, -5, -23, Blocks.STONE.getDefaultState());
        structure.fillWithBlocks(world, start, -17, -6, -22, -14, -6, -19, Blocks.DIORITE.getDefaultState());
        structure.fillWithBlocks(world, start, -17, -6, -18, -15, -6, -12, Blocks.GRANITE.getDefaultState());
        structure.fillWithBlocks(world, start, -17, -6, -11, -17, -5, 26, Blocks.STONE.getDefaultState());
        structure.fillWithBlocks(world, start, -17, -6, 27, -15, -6, 29, Blocks.ANDESITE.getDefaultState());
        structure.fillWithBlocks(world, start, -17, -6, 31, -16, -6, 32, Blocks.STONE.getDefaultState());
        structure.fillWithBlocks(world, start, -17, -5, -69, -7, -5, -58, Blocks.STONE.getDefaultState());
        structure.fillWithBlocks(world, start, -17, -5, -49, -10, -5, -42, Blocks.RED_SAND.getDefaultState());
        structure.fillWithBlocks(world, start, -17, -5, -41, -17, -5, -40, Blocks.ANDESITE.getDefaultState());
        structure.fillWithBlocks(world, start, -17, -5, -39, -17, -5, -39, Blocks.RED_SAND.getDefaultState());
        structure.fillWithBlocks(world, start, -17, -5, -38, -17, -5, -38, Blocks.STONE.getDefaultState());
        structure.fillWithBlocks(world, start, -17, -5, -37, -17, -5, -33, Blocks.RED_SAND.getDefaultState());
        structure.fillWithBlocks(world, start, -17, -5, -31, -17, -5, -31, Blocks.RED_SAND.getDefaultState());
        structure.fillWithBlocks(world, start, -17, -5, -30, -17, -5, -28, Blocks.STONE.getDefaultState());
        structure.fillWithBlocks(world, start, -17, -5, -27, -17, -1, -27, Blocks.RED_SAND.getDefaultState());
        structure.fillWithBlocks(world, start, -17, -5, -26, -17, -5, -24, Blocks.ANDESITE.getDefaultState());
        structure.fillWithBlocks(world, start, -17, -5, -22, -14, -5, -19, Blocks.DIORITE.getDefaultState());
        structure.fillWithBlocks(world, start, -17, -5, -17, -17, -5, -17, Blocks.GRANITE.getDefaultState());
        structure.fillWithBlocks(world, start, -17, -5, -15, -14, -5, -12, Blocks.GRANITE.getDefaultState());
        structure.fillWithBlocks(world, start, -17, -5, 32, -15, -5, 34, Blocks.RED_SAND.getDefaultState());
        structure.fillWithBlocks(world, start, -17, -3, -19, -17, -3, -18, Blocks.RED_SAND.getDefaultState());
        structure.fillWithBlocks(world, start, -17, -3, -17, -17, -1, -17, Blocks.COARSE_DIRT.getDefaultState());
        structure.fillWithBlocks(world, start, -17, -2, -19, -17, -2, -18, Blocks.RED_SAND.getDefaultState());
        structure.fillWithBlocks(world, start, -17, -2, 14, -17, -2, 31, Blocks.RED_SAND.getDefaultState());
        structure.fillWithBlocks(world, start, -17, -1, -19, -17, -1, -18, Blocks.RED_SAND.getDefaultState());
        structure.fillWithBlocks(world, start, -17, -1, 0, -16, -1, 0, Blocks.RED_SAND.getDefaultState());
        structure.fillWithBlocks(world, start, -17, -1, 6, -16, -1, 8, Blocks.RED_SAND.getDefaultState());
        structure.fillWithBlocks(world, start, -17, -1, 21, -9, -1, 29, Blocks.SPRUCE_PLANKS.getDefaultState());
        structure.fillWithBlocks(world, start, -17, -1, 30, -10, -1, 30, Blocks.SPRUCE_PLANKS.getDefaultState());
        structure.fillWithBlocks(world, start, -17, 0, -38, -17, 3, -38, Blocks.DARK_OAK_WOOD.getDefaultState());
        structure.fillWithBlocks(world, start, -17, 0, -37, -15, 0, -35, Blocks.DARK_OAK_PLANKS.getDefaultState());
        structure.fillWithBlocks(world, start, -17, 0, -34, -17, 3, -34, Blocks.DARK_OAK_WOOD.getDefaultState());
        structure.fillWithBlocks(world, start, -17, 0, -32, -17, 8, -32, Blocks.STRIPPED_DARK_OAK_LOG.getDefaultState());
        structure.fillWithBlocks(world, start, -17, 0, -31, -9, 0, -21, Blocks.SPRUCE_PLANKS.getDefaultState());
        structure.fillWithBlocks(world, start, -17, 0, -20, -16, 0, -20, Blocks.SPRUCE_STAIRS.getDefaultState().with(StairsBlock.FACING, Direction.NORTH).with(StairsBlock.WATERLOGGED, false).with(StairsBlock.SHAPE, StairsShape.STRAIGHT).with(StairsBlock.HALF, Half.BOTTOM));
        structure.fillWithBlocks(world, start, -17, 0, -16, -17, 3, -16, Blocks.DARK_OAK_WOOD.getDefaultState());
        structure.fillWithBlocks(world, start, -17, 0, -15, -17, 0, -15, Blocks.DARK_OAK_PLANKS.getDefaultState());
        structure.fillWithBlocks(world, start, -17, 0, -14, -17, 3, -14, Blocks.DARK_OAK_WOOD.getDefaultState());
        structure.fillWithBlocks(world, start, -17, 0, -13, -15, 0, -11, Blocks.DARK_OAK_PLANKS.getDefaultState());
        structure.fillWithBlocks(world, start, -17, 0, -10, -17, 3, -10, Blocks.DARK_OAK_WOOD.getDefaultState());
        structure.fillWithBlocks(world, start, -17, 0, -8, -7, 0, 7, Blocks.SPRUCE_PLANKS.getDefaultState());
        structure.fillWithBlocks(world, start, -17, 0, 19, -12, 0, 19, Blocks.DARK_OAK_FENCE.getDefaultState().with(FourWayBlock.WATERLOGGED, false).with(FourWayBlock.NORTH, false).with(FourWayBlock.SOUTH, false).with(FourWayBlock.EAST, true).with(FourWayBlock.WEST, true));
        structure.fillWithBlocks(world, start, -17, 0, 21, -17, 0, 23, Blocks.OAK_PLANKS.getDefaultState());
        structure.fillWithBlocks(world, start, -17, 0, 27, -17, 0, 28, Index.COUNTER_OAK_ANDESITE.getDefaultState().with(Counter.FACING, Direction.EAST).with(Counter.WATERLOGGED, false));
        structure.fillWithBlocks(world, start, -17, 0, 29, -17, 1, 30, Blocks.OAK_PLANKS.getDefaultState());
        structure.fillWithBlocks(world, start, -17, 1, -37, -17, 3, -37, Blocks.SPRUCE_PLANKS.getDefaultState());
        structure.fillWithBlocks(world, start, -17, 1, -35, -17, 3, -35, Blocks.SPRUCE_PLANKS.getDefaultState());
        structure.fillWithBlocks(world, start, -17, 1, -30, -17, 1, -26, Blocks.OAK_PLANKS.getDefaultState());
        structure.fillWithBlocks(world, start, -17, 1, -25, -17, 8, -25, Blocks.STRIPPED_DARK_OAK_LOG.getDefaultState());
        structure.fillWithBlocks(world, start, -17, 1, -15, -17, 3, -15, Blocks.SPRUCE_PLANKS.getDefaultState());
        structure.fillWithBlocks(world, start, -17, 1, -12, -17, 1, -11, Blocks.SPRUCE_PLANKS.getDefaultState());
        structure.fillWithBlocks(world, start, -17, 1, -8, -17, 6, -8, Blocks.SPRUCE_LOG.getDefaultState());
        structure.fillWithBlocks(world, start, -17, 1, -7, -17, 3, -5, Blocks.JUNGLE_PLANKS.getDefaultState());
        structure.fillWithBlocks(world, start, -17, 1, -4, -17, 1, -1, Blocks.JUNGLE_PLANKS.getDefaultState());
        structure.fillWithBlocks(world, start, -17, 1, 1, -17, 4, 4, Blocks.JUNGLE_PLANKS.getDefaultState());
        structure.fillWithBlocks(world, start, -17, 1, 5, -17, 1, 6, Blocks.JUNGLE_PLANKS.getDefaultState());
        structure.fillWithBlocks(world, start, -17, 1, 7, -17, 6, 7, Blocks.SPRUCE_LOG.getDefaultState());
        structure.fillWithBlocks(world, start, -17, 1, 21, -16, 1, 22, Blocks.OAK_PLANKS.getDefaultState());
        structure.fillWithBlocks(world, start, -17, 1, 26, -17, 2, 26, Index.IRON_FENCE_ROUGH.getDefaultState().with(IronFence.NORTH, false).with(IronFence.SOUTH, false).with(IronFence.EAST, false).with(IronFence.WEST, true).with(IronFence.WATERLOGGED, false));
        structure.fillWithBlocks(world, start, -17, 2, -31, -17, 3, -30, Blocks.OAK_PLANKS.getDefaultState());
        structure.fillWithBlocks(world, start, -17, 2, -29, -17, 3, -28, Blocks.LIGHT_GRAY_STAINED_GLASS_PANE.getDefaultState().with(FourWayBlock.WATERLOGGED, false).with(FourWayBlock.NORTH, true).with(FourWayBlock.SOUTH, true).with(FourWayBlock.EAST, false).with(FourWayBlock.WEST, false));
        structure.fillWithBlocks(world, start, -17, 2, -27, -17, 2, -26, Blocks.OAK_PLANKS.getDefaultState());
        structure.fillWithBlocks(world, start, -17, 2, -13, -17, 3, -12, Blocks.SPRUCE_PLANKS.getDefaultState());
        structure.fillWithBlocks(world, start, -17, 2, -3, -17, 4, 4, Blocks.JUNGLE_PLANKS.getDefaultState());
        structure.fillWithBlocks(world, start, -17, 2, 6, -17, 5, 6, Blocks.JUNGLE_PLANKS.getDefaultState());
        structure.fillWithBlocks(world, start, -17, 2, 21, -16, 2, 22, Blocks.OAK_PLANKS.getDefaultState());
        structure.fillWithBlocks(world, start, -17, 2, 24, -17, 2, 25, Index.CABINET_OAK.getDefaultState().with(Cabinet.FACING, Direction.EAST).with(Cabinet.WATERLOGGED, false));
        structure.fillWithBlocks(world, start, -17, 2, 27, -17, 2, 28, Index.CABINET_OAK.getDefaultState().with(Cabinet.FACING, Direction.EAST).with(Cabinet.WATERLOGGED, false));
        structure.fillWithBlocks(world, start, -17, 2, 29, -17, 2, 30, Blocks.OAK_PLANKS.getDefaultState());
        structure.fillWithBlocks(world, start, -17, 3, -36, -16, 3, -35, Blocks.SPRUCE_PLANKS.getDefaultState());
        structure.fillWithBlocks(world, start, -17, 3, -27, -17, 10, -27, Blocks.OAK_PLANKS.getDefaultState());
        structure.fillWithBlocks(world, start, -17, 3, -11, -17, 3, -11, Blocks.SPRUCE_PLANKS.getDefaultState());
        structure.fillWithBlocks(world, start, -17, 3, -4, -17, 5, -2, Blocks.JUNGLE_PLANKS.getDefaultState());
        structure.fillWithBlocks(world, start, -17, 3, 5, -17, 4, 6, Blocks.JUNGLE_PLANKS.getDefaultState());
        structure.fillWithBlocks(world, start, -17, 3, 19, -16, 3, 20, Blocks.SPRUCE_SLAB.getDefaultState().with(SlabBlock.TYPE, SlabType.TOP).with(SlabBlock.WATERLOGGED, false));
        structure.fillWithBlocks(world, start, -17, 3, 21, -17, 3, 30, Blocks.OAK_PLANKS.getDefaultState());
        structure.fillWithBlocks(world, start, -17, 4, -38, -14, 4, -38, Blocks.DARK_OAK_SLAB.getDefaultState().with(SlabBlock.TYPE, SlabType.BOTTOM).with(SlabBlock.WATERLOGGED, false));
        structure.fillWithBlocks(world, start, -17, 4, -37, -17, 4, -35, Blocks.SPRUCE_SLAB.getDefaultState().with(SlabBlock.TYPE, SlabType.DOUBLE).with(SlabBlock.WATERLOGGED, false));
        structure.fillWithBlocks(world, start, -17, 4, -34, -14, 4, -34, Blocks.DARK_OAK_SLAB.getDefaultState().with(SlabBlock.TYPE, SlabType.BOTTOM).with(SlabBlock.WATERLOGGED, false));
        structure.fillWithBlocks(world, start, -17, 4, -31, -17, 5, -30, Blocks.OAK_PLANKS.getDefaultState());
        structure.fillWithBlocks(world, start, -17, 4, -29, -17, 4, -26, Blocks.OAK_PLANKS.getDefaultState());
        structure.fillWithBlocks(world, start, -17, 4, -24, -17, 4, -22, Blocks.SPRUCE_SLAB.getDefaultState().with(SlabBlock.TYPE, SlabType.TOP).with(SlabBlock.WATERLOGGED, false));
        structure.fillWithBlocks(world, start, -17, 4, -15, -17, 4, -15, Blocks.DARK_OAK_SLAB.getDefaultState().with(SlabBlock.TYPE, SlabType.BOTTOM).with(SlabBlock.WATERLOGGED, false));
        structure.fillWithBlocks(world, start, -17, 4, -13, -15, 4, -11, Blocks.DARK_OAK_SLAB.getDefaultState().with(SlabBlock.TYPE, SlabType.BOTTOM).with(SlabBlock.WATERLOGGED, false));
        structure.fillWithBlocks(world, start, -17, 4, -7, -17, 6, -4, Blocks.JUNGLE_PLANKS.getDefaultState());
        structure.fillWithBlocks(world, start, -17, 4, 19, -11, 4, 19, Blocks.DARK_OAK_FENCE.getDefaultState().with(FourWayBlock.WATERLOGGED, false).with(FourWayBlock.NORTH, false).with(FourWayBlock.SOUTH, false).with(FourWayBlock.EAST, true).with(FourWayBlock.WEST, true));
        structure.fillWithBlocks(world, start, -17, 4, 21, -12, 4, 21, Blocks.OAK_PLANKS.getDefaultState());
        structure.fillWithBlocks(world, start, -17, 4, 28, -17, 4, 29, Blocks.OAK_SLAB.getDefaultState().with(SlabBlock.TYPE, SlabType.TOP).with(SlabBlock.WATERLOGGED, false));
        structure.fillWithBlocks(world, start, -17, 4, 30, -12, 4, 30, Blocks.OAK_PLANKS.getDefaultState());
        structure.fillWithBlocks(world, start, -17, 5, -26, -17, 9, -26, Blocks.OAK_PLANKS.getDefaultState());
        structure.fillWithBlocks(world, start, -17, 5, -23, -17, 5, -23, Blocks.DARK_OAK_FENCE.getDefaultState().with(FourWayBlock.WATERLOGGED, false).with(FourWayBlock.NORTH, false).with(FourWayBlock.SOUTH, true).with(FourWayBlock.EAST, false).with(FourWayBlock.WEST, true));
        structure.fillWithBlocks(world, start, -17, 5, -22, -17, 5, -22, Blocks.DARK_OAK_FENCE.getDefaultState().with(FourWayBlock.WATERLOGGED, false).with(FourWayBlock.NORTH, true).with(FourWayBlock.SOUTH, false).with(FourWayBlock.EAST, true).with(FourWayBlock.WEST, false));
        structure.fillWithBlocks(world, start, -17, 5, 0, -17, 6, 5, Blocks.JUNGLE_PLANKS.getDefaultState());
        structure.fillWithBlocks(world, start, -17, 5, 21, -17, 8, 21, Blocks.OAK_PLANKS.getDefaultState());
        structure.fillWithBlocks(world, start, -17, 5, 28, -17, 5, 29, Index.CUPBOARD_OAK.getDefaultState().with(Cupboard.FACING, Direction.EAST).with(Cupboard.HALF, DoubleBlockHalf.LOWER).with(Cupboard.MIRROR, false).with(Cupboard.WATERLOGGED, false));
        structure.fillWithBlocks(world, start, -17, 5, 30, -17, 7, 30, Blocks.OAK_PLANKS.getDefaultState());
        structure.fillWithBlocks(world, start, -17, 6, -31, -17, 7, -30, Blocks.OAK_PLANKS.getDefaultState());
        structure.fillWithBlocks(world, start, -17, 6, -2, -10, 6, 5, Blocks.JUNGLE_PLANKS.getDefaultState());
        structure.fillWithBlocks(world, start, -17, 6, 28, -17, 6, 29, Index.CUPBOARD_OAK.getDefaultState().with(Cupboard.FACING, Direction.EAST).with(Cupboard.HALF, DoubleBlockHalf.UPPER).with(Cupboard.MIRROR, false).with(Cupboard.WATERLOGGED, false));
        structure.fillWithBlocks(world, start, -17, 7, -29, -17, 9, -26, Blocks.OAK_PLANKS.getDefaultState());
        structure.fillWithBlocks(world, start, -17, 7, -7, -17, 7, 6, Blocks.DARK_OAK_SLAB.getDefaultState().with(SlabBlock.TYPE, SlabType.BOTTOM).with(SlabBlock.WATERLOGGED, false));
        structure.fillWithBlocks(world, start, -17, 7, 22, -10, 7, 29, Blocks.OAK_PLANKS.getDefaultState());
        structure.fillWithBlocks(world, start, -17, 8, -31, -12, 8, -26, Blocks.OAK_PLANKS.getDefaultState());
        structure.fillWithBlocks(world, start, -17, 8, -24, -17, 8, -22, Blocks.SPRUCE_SLAB.getDefaultState().with(SlabBlock.TYPE, SlabType.BOTTOM).with(SlabBlock.WATERLOGGED, false));
        structure.fillWithBlocks(world, start, -17, 8, 30, -10, 8, 30, Blocks.SPRUCE_SLAB.getDefaultState().with(SlabBlock.TYPE, SlabType.BOTTOM).with(SlabBlock.WATERLOGGED, false));
        structure.fillWithBlocks(world, start, -17, 9, -62, -17, 9, -62, Blocks.OAK_LEAVES.getDefaultState().with(LeavesBlock.PERSISTENT, true).with(LeavesBlock.DISTANCE, 3));
        structure.fillWithBlocks(world, start, -17, 9, -31, -17, 9, -26, Blocks.OAK_PLANKS.getDefaultState());
        structure.fillWithBlocks(world, start, -17, 10, -28, -17, 10, -27, Blocks.OAK_PLANKS.getDefaultState());
        structure.fillWithBlocks(world, start, -17, 11, -30, -17, 11, -27, Blocks.SPRUCE_SLAB.getDefaultState().with(SlabBlock.TYPE, SlabType.BOTTOM).with(SlabBlock.WATERLOGGED, false));
        structure.fillWithBlocks(world, start, -17, 12, -63, -17, 12, -63, Blocks.OAK_LEAVES.getDefaultState().with(LeavesBlock.PERSISTENT, true).with(LeavesBlock.DISTANCE, 5));
        structure.fillWithBlocks(world, start, -17, 12, -62, -17, 12, -62, Blocks.OAK_LEAVES.getDefaultState().with(LeavesBlock.PERSISTENT, true).with(LeavesBlock.DISTANCE, 4));
        structure.fillWithBlocks(world, start, -16, -9, -73, -15, -9, -72, Blocks.STONE.getDefaultState());
        structure.fillWithBlocks(world, start, -16, -9, -58, -13, -9, -55, Blocks.STONE.getDefaultState());
        structure.fillWithBlocks(world, start, -16, -9, -54, -16, -6, -42, Blocks.STONE.getDefaultState());
        structure.fillWithBlocks(world, start, -16, -9, -41, -14, -9, -38, Blocks.DIORITE.getDefaultState());
        structure.fillWithBlocks(world, start, -16, -9, -37, -14, -9, -35, Blocks.STONE.getDefaultState());
        structure.fillWithBlocks(world, start, -16, -9, -34, -16, -6, -34, Blocks.STONE.getDefaultState());
        structure.fillWithBlocks(world, start, -16, -9, -33, -14, -9, -28, Blocks.ANDESITE.getDefaultState());
        structure.fillWithBlocks(world, start, -16, -9, -27, -16, -8, -26, Blocks.ANDESITE.getDefaultState());
        structure.fillWithBlocks(world, start, -16, -9, -25, -12, -9, -21, Blocks.STONE.getDefaultState());
        structure.fillWithBlocks(world, start, -16, -9, -20, -15, -9, 26, Blocks.STONE.getDefaultState());
        structure.fillWithBlocks(world, start, -16, -9, 32, -14, -9, 34, Blocks.STONE.getDefaultState());
        structure.fillWithBlocks(world, start, -16, -9, 35, -13, -9, 38, Blocks.TERRACOTTA.getDefaultState());
        structure.fillWithBlocks(world, start, -16, -8, -40, -15, -8, -39, Blocks.DIORITE.getDefaultState());
        structure.fillWithBlocks(world, start, -16, -8, -33, -14, -8, -28, Blocks.ANDESITE.getDefaultState());
        structure.fillWithBlocks(world, start, -16, -8, -21, -15, -8, -18, Blocks.STONE.getDefaultState());
        structure.fillWithBlocks(world, start, -16, -8, -17, -16, -5, -17, Blocks.GRANITE.getDefaultState());
        structure.fillWithBlocks(world, start, -16, -8, -16, -7, -8, -16, Blocks.STONE.getDefaultState());
        structure.fillWithBlocks(world, start, -16, -8, -15, -15, -7, -15, Blocks.GRANITE.getDefaultState());
        structure.fillWithBlocks(world, start, -16, -8, -14, -9, -8, -7, Blocks.STONE.getDefaultState());
        structure.fillWithBlocks(world, start, -16, -8, 26, -13, -8, 29, Blocks.ANDESITE.getDefaultState());
        structure.fillWithBlocks(world, start, -16, -8, 31, -13, -8, 34, Blocks.STONE.getDefaultState());
        structure.fillWithBlocks(world, start, -16, -7, -73, -14, -6, -73, Blocks.RED_SAND.getDefaultState());
        structure.fillWithBlocks(world, start, -16, -7, -72, -12, -7, -68, Blocks.STONE.getDefaultState());
        structure.fillWithBlocks(world, start, -16, -7, -33, -14, -7, -29, Blocks.ANDESITE.getDefaultState());
        structure.fillWithBlocks(world, start, -16, -7, -26, -14, -7, -24, Blocks.DIRT.getDefaultState());
        structure.fillWithBlocks(world, start, -16, -7, -21, -15, -7, -19, Blocks.DIORITE.getDefaultState());
        structure.fillWithBlocks(world, start, -16, -7, -12, -15, -7, -11, Blocks.GRANITE.getDefaultState());
        structure.fillWithBlocks(world, start, -16, -7, -10, -13, -7, -7, Blocks.STONE.getDefaultState());
        structure.fillWithBlocks(world, start, -16, -7, -6, -16, -5, 25, Blocks.STONE.getDefaultState());
        structure.fillWithBlocks(world, start, -16, -7, 26, -13, -7, 29, Blocks.ANDESITE.getDefaultState());
        structure.fillWithBlocks(world, start, -16, -7, 31, -15, -7, 32, Blocks.STONE.getDefaultState());
        structure.fillWithBlocks(world, start, -16, -6, -72, -16, -4, -72, Blocks.RED_SAND.getDefaultState());
        structure.fillWithBlocks(world, start, -16, -6, -31, -15, -6, -29, Blocks.ANDESITE.getDefaultState());
        structure.fillWithBlocks(world, start, -16, -6, -27, -13, -6, -24, Blocks.DIRT.getDefaultState());
        structure.fillWithBlocks(world, start, -16, -6, -11, -15, -6, -10, Blocks.GRANITE.getDefaultState());
        structure.fillWithBlocks(world, start, -16, -6, -9, -14, -6, -7, Blocks.STONE.getDefaultState());
        structure.fillWithBlocks(world, start, -16, -5, -71, -5, -5, -59, Blocks.STONE.getDefaultState());
        structure.fillWithBlocks(world, start, -16, -5, -50, -4, -5, -38, Blocks.RED_SAND.getDefaultState());
        structure.fillWithBlocks(world, start, -16, -5, -36, -9, -5, -29, Blocks.RED_SAND.getDefaultState());
        structure.fillWithBlocks(world, start, -16, -5, -27, -16, -5, -25, Blocks.DIRT.getDefaultState());
        structure.fillWithBlocks(world, start, -16, -5, -18, -15, -5, -18, Blocks.DIORITE.getDefaultState());
        structure.fillWithBlocks(world, start, -16, -5, -16, -15, -5, -10, Blocks.GRANITE.getDefaultState());
        structure.fillWithBlocks(world, start, -16, -5, -9, -9, -5, 7, Blocks.STONE.getDefaultState());
        structure.fillWithBlocks(world, start, -16, -3, -21, -16, -1, -21, Blocks.RED_SAND.getDefaultState());
        structure.fillWithBlocks(world, start, -16, -3, -20, -16, -2, -19, Blocks.COARSE_DIRT.getDefaultState());
        structure.fillWithBlocks(world, start, -16, -3, -18, -16, -3, 32, Blocks.RED_SAND.getDefaultState());
        structure.fillWithBlocks(world, start, -16, -2, -71, -15, -2, -70, Blocks.RED_SAND.getDefaultState());
        structure.fillWithBlocks(world, start, -16, -2, -69, -15, -2, -67, Blocks.DIRT.getDefaultState());
        structure.fillWithBlocks(world, start, -16, -2, -66, -13, -2, -22, Blocks.RED_SAND.getDefaultState());
        structure.fillWithBlocks(world, start, -16, -2, -18, -16, -2, 14, Blocks.RED_SAND.getDefaultState());
        structure.fillWithBlocks(world, start, -16, -1, -69, -14, -1, -67, Blocks.DIRT.getDefaultState());
        structure.fillWithBlocks(world, start, -16, -1, -66, -13, -1, -22, Blocks.RED_SAND.getDefaultState());
        structure.fillWithBlocks(world, start, -16, -1, -20, -16, -1, -19, Blocks.COARSE_DIRT.getDefaultState());
        structure.fillWithBlocks(world, start, -16, -1, -18, -16, -1, 0, Blocks.RED_SAND.getDefaultState());
        structure.fillWithBlocks(world, start, -16, -1, 19, -9, -1, 29, Blocks.SPRUCE_PLANKS.getDefaultState());
        structure.fillWithBlocks(world, start, -16, 0, -70, -15, 0, -43, Blocks.RED_SAND.getDefaultState());
        structure.fillWithBlocks(world, start, -16, 0, -38, -14, 0, -34, Blocks.DARK_OAK_PLANKS.getDefaultState());
        structure.fillWithBlocks(world, start, -16, 0, -32, -9, 0, -21, Blocks.SPRUCE_PLANKS.getDefaultState());
        structure.fillWithBlocks(world, start, -16, 0, -16, -15, 0, -10, Blocks.DARK_OAK_PLANKS.getDefaultState());
        structure.fillWithBlocks(world, start, -16, 0, -9, -9, 0, -9, Blocks.CAVE_AIR.getDefaultState());
        structure.fillWithBlocks(world, start, -16, 0, 22, -15, 1, 22, Blocks.OAK_PLANKS.getDefaultState());
        structure.fillWithBlocks(world, start, -16, 1, -38, -14, 1, -38, Blocks.SPRUCE_PLANKS.getDefaultState());
        structure.fillWithBlocks(world, start, -16, 1, -34, -14, 1, -34, Blocks.SPRUCE_PLANKS.getDefaultState());
        structure.fillWithBlocks(world, start, -16, 1, -32, -15, 2, -32, Blocks.OAK_PLANKS.getDefaultState());
        structure.fillWithBlocks(world, start, -16, 1, -16, -15, 2, -16, Blocks.SPRUCE_PLANKS.getDefaultState());
        structure.fillWithBlocks(world, start, -16, 1, -11, -16, 1, -10, Blocks.SPRUCE_PLANKS.getDefaultState());
        structure.fillWithBlocks(world, start, -16, 1, 7, -10, 1, 7, Blocks.JUNGLE_PLANKS.getDefaultState());
        structure.fillWithBlocks(world, start, -16, 1, 30, -15, 2, 30, Blocks.OAK_PLANKS.getDefaultState());
        structure.fillWithBlocks(world, start, -16, 2, -34, -16, 3, -34, Blocks.SPRUCE_PLANKS.getDefaultState());
        structure.fillWithBlocks(world, start, -16, 2, -10, -15, 3, -10, Blocks.SPRUCE_PLANKS.getDefaultState());
        structure.fillWithBlocks(world, start, -16, 2, -8, -14, 4, -8, Blocks.JUNGLE_PLANKS.getDefaultState());
        structure.fillWithBlocks(world, start, -16, 2, 7, -16, 6, 7, Blocks.JUNGLE_PLANKS.getDefaultState());
        structure.fillWithBlocks(world, start, -16, 3, -38, -14, 3, -34, Blocks.SPRUCE_PLANKS.getDefaultState());
        structure.fillWithBlocks(world, start, -16, 3, -32, -13, 4, -32, Blocks.OAK_PLANKS.getDefaultState());
        structure.fillWithBlocks(world, start, -16, 3, -24, -16, 8, -24, Blocks.OAK_PLANKS.getDefaultState());
        structure.fillWithBlocks(world, start, -16, 3, -16, -15, 3, -16, Blocks.SPRUCE_PLANKS.getDefaultState());
        structure.fillWithBlocks(world, start, -16, 3, 21, -14, 4, 21, Blocks.OAK_PLANKS.getDefaultState());
        structure.fillWithBlocks(world, start, -16, 3, 23, -10, 3, 30, Blocks.OAK_PLANKS.getDefaultState());
        structure.fillWithBlocks(world, start, -16, 4, -23, -16, 4, -21, Blocks.SPRUCE_SLAB.getDefaultState().with(SlabBlock.TYPE, SlabType.TOP).with(SlabBlock.WATERLOGGED, false));
        structure.fillWithBlocks(world, start, -16, 4, -16, -12, 4, -10, Blocks.DARK_OAK_SLAB.getDefaultState().with(SlabBlock.TYPE, SlabType.BOTTOM).with(SlabBlock.WATERLOGGED, false));
        structure.fillWithBlocks(world, start, -16, 4, 23, -16, 4, 25, Blocks.LIGHT_GRAY_CARPET.getDefaultState());
        structure.fillWithBlocks(world, start, -16, 5, -32, -16, 8, -32, Blocks.OAK_PLANKS.getDefaultState());
        structure.fillWithBlocks(world, start, -16, 5, 21, -16, 6, 21, Blocks.LIGHT_GRAY_STAINED_GLASS_PANE.getDefaultState().with(FourWayBlock.WATERLOGGED, false).with(FourWayBlock.NORTH, false).with(FourWayBlock.SOUTH, false).with(FourWayBlock.EAST, true).with(FourWayBlock.WEST, true));
        structure.fillWithBlocks(world, start, -16, 6, -21, -16, 7, -21, Blocks.DARK_OAK_FENCE.getDefaultState().with(FourWayBlock.WATERLOGGED, false).with(FourWayBlock.NORTH, false).with(FourWayBlock.SOUTH, false).with(FourWayBlock.EAST, false).with(FourWayBlock.WEST, false));
        structure.fillWithBlocks(world, start, -16, 6, -8, -10, 6, 6, Blocks.JUNGLE_PLANKS.getDefaultState());
        structure.fillWithBlocks(world, start, -16, 6, 30, -14, 7, 30, Blocks.OAK_PLANKS.getDefaultState());
        structure.fillWithBlocks(world, start, -16, 7, -8, -9, 7, -8, Blocks.DARK_OAK_SLAB.getDefaultState().with(SlabBlock.TYPE, SlabType.BOTTOM).with(SlabBlock.WATERLOGGED, false));
        structure.fillWithBlocks(world, start, -16, 7, 7, -9, 7, 7, Blocks.DARK_OAK_SLAB.getDefaultState().with(SlabBlock.TYPE, SlabType.BOTTOM).with(SlabBlock.WATERLOGGED, false));
        structure.fillWithBlocks(world, start, -16, 7, 19, -15, 7, 20, Blocks.SPRUCE_SLAB.getDefaultState().with(SlabBlock.TYPE, SlabType.BOTTOM).with(SlabBlock.WATERLOGGED, false));
        structure.fillWithBlocks(world, start, -16, 7, 21, -12, 7, 29, Blocks.OAK_PLANKS.getDefaultState());
        structure.fillWithBlocks(world, start, -16, 8, -25, -15, 8, -24, Blocks.OAK_PLANKS.getDefaultState());
        structure.fillWithBlocks(world, start, -16, 8, -23, -16, 8, -21, Blocks.SPRUCE_SLAB.getDefaultState().with(SlabBlock.TYPE, SlabType.BOTTOM).with(SlabBlock.WATERLOGGED, false));
        structure.fillWithBlocks(world, start, -16, 8, 21, -14, 9, 21, Blocks.OAK_PLANKS.getDefaultState());
        structure.fillWithBlocks(world, start, -16, 9, -69, -16, 11, -69, Blocks.OAK_LEAVES.getDefaultState().with(LeavesBlock.PERSISTENT, true).with(LeavesBlock.DISTANCE, 7));
        structure.fillWithBlocks(world, start, -16, 9, -32, -9, 9, -32, Blocks.SPRUCE_SLAB.getDefaultState().with(SlabBlock.TYPE, SlabType.BOTTOM).with(SlabBlock.WATERLOGGED, false));
        structure.fillWithBlocks(world, start, -16, 10, 21, -13, 10, 21, Blocks.SPRUCE_SLAB.getDefaultState().with(SlabBlock.TYPE, SlabType.BOTTOM).with(SlabBlock.WATERLOGGED, false));
        structure.fillWithBlocks(world, start, -16, 12, -59, -16, 13, -59, Blocks.OAK_LEAVES.getDefaultState().with(LeavesBlock.PERSISTENT, true).with(LeavesBlock.DISTANCE, 7));
        structure.fillWithBlocks(world, start, -15, -9, -71, -15, -9, -69, Blocks.COAL_ORE.getDefaultState());
        structure.fillWithBlocks(world, start, -15, -9, -68, -8, -9, -61, Blocks.STONE.getDefaultState());
        structure.fillWithBlocks(world, start, -15, -9, -54, -14, -9, -53, Blocks.IRON_ORE.getDefaultState());
        structure.fillWithBlocks(world, start, -15, -9, -34, -15, -9, -27, Blocks.ANDESITE.getDefaultState());
        structure.fillWithBlocks(world, start, -15, -9, -26, -10, -9, -21, Blocks.STONE.getDefaultState());
        structure.fillWithBlocks(world, start, -15, -9, 30, -11, -9, 34, Blocks.STONE.getDefaultState());
        structure.fillWithBlocks(world, start, -15, -8, -75, -14, -8, -74, Blocks.RED_SAND.getDefaultState());
        structure.fillWithBlocks(world, start, -15, -8, -73, -15, -6, -73, Blocks.RED_SAND.getDefaultState());
        structure.fillWithBlocks(world, start, -15, -8, -72, -15, -8, -72, Blocks.STONE.getDefaultState());
        structure.fillWithBlocks(world, start, -15, -8, -71, -15, -8, -67, Blocks.COAL_ORE.getDefaultState());
        structure.fillWithBlocks(world, start, -15, -8, -66, -15, -8, -61, Blocks.STONE.getDefaultState());
        structure.fillWithBlocks(world, start, -15, -8, -59, -8, -8, -41, Blocks.STONE.getDefaultState());
        structure.fillWithBlocks(world, start, -15, -8, -38, -14, -8, -35, Blocks.STONE.getDefaultState());
        structure.fillWithBlocks(world, start, -15, -8, -34, -15, -8, -27, Blocks.ANDESITE.getDefaultState());
        structure.fillWithBlocks(world, start, -15, -8, -26, -14, -8, -25, Blocks.DIRT.getDefaultState());
        structure.fillWithBlocks(world, start, -15, -8, -17, -14, -8, -16, Blocks.STONE.getDefaultState());
        structure.fillWithBlocks(world, start, -15, -8, -6, -15, -6, -6, Blocks.GOLD_ORE.getDefaultState());
        structure.fillWithBlocks(world, start, -15, -7, -74, -14, -7, -73, Blocks.RED_SAND.getDefaultState());
        structure.fillWithBlocks(world, start, -15, -7, -67, -15, -7, -67, Blocks.COAL_ORE.getDefaultState());
        structure.fillWithBlocks(world, start, -15, -7, -66, -15, -7, -34, Blocks.STONE.getDefaultState());
        structure.fillWithBlocks(world, start, -15, -7, -28, -13, -7, -25, Blocks.DIRT.getDefaultState());
        structure.fillWithBlocks(world, start, -15, -7, -23, -15, -6, -23, Blocks.DIRT.getDefaultState());
        structure.fillWithBlocks(world, start, -15, -7, -22, -2, -7, -22, Blocks.STONE.getDefaultState());
        structure.fillWithBlocks(world, start, -15, -7, -5, -14, -6, -5, Blocks.GOLD_ORE.getDefaultState());
        structure.fillWithBlocks(world, start, -15, -7, -4, -13, -7, -2, Blocks.STONE.getDefaultState());
        structure.fillWithBlocks(world, start, -15, -7, 6, -10, -7, 25, Blocks.STONE.getDefaultState());
        structure.fillWithBlocks(world, start, -15, -7, 33, -15, -7, 36, Blocks.RED_SAND.getDefaultState());
        structure.fillWithBlocks(world, start, -15, -6, -72, -11, -6, -32, Blocks.STONE.getDefaultState());
        structure.fillWithBlocks(world, start, -15, -6, -28, -13, -6, -24, Blocks.DIRT.getDefaultState());
        structure.fillWithBlocks(world, start, -15, -6, -4, -12, -6, -1, Blocks.STONE.getDefaultState());
        structure.fillWithBlocks(world, start, -15, -6, 22, -11, -6, 26, Blocks.STONE.getDefaultState());
        structure.fillWithBlocks(world, start, -15, -6, 30, -13, -6, 32, Blocks.STONE.getDefaultState());
        structure.fillWithBlocks(world, start, -15, -5, -72, -14, -4, -72, Blocks.RED_SAND.getDefaultState());
        structure.fillWithBlocks(world, start, -15, -5, -51, 5, -5, -28, Blocks.RED_SAND.getDefaultState());
        structure.fillWithBlocks(world, start, -15, -5, -27, -14, -5, -26, Blocks.RED_SAND.getDefaultState());
        structure.fillWithBlocks(world, start, -15, -5, -25, -15, -5, -24, Blocks.DIRT.getDefaultState());
        structure.fillWithBlocks(world, start, -15, -5, -23, -14, -5, -23, Blocks.STONE.getDefaultState());
        structure.fillWithBlocks(world, start, -15, -5, -17, -15, -5, -10, Blocks.GRANITE.getDefaultState());
        structure.fillWithBlocks(world, start, -15, -5, 9, -10, -5, 14, Blocks.STONE.getDefaultState());
        structure.fillWithBlocks(world, start, -15, -5, 15, -14, -5, 31, Blocks.STONE.getDefaultState());
        structure.fillWithBlocks(world, start, -15, -3, -72, 3, -3, -22, Blocks.RED_SAND.getDefaultState());
        structure.fillWithBlocks(world, start, -15, -3, -21, -15, -1, -21, Blocks.STONE.getDefaultState());
        structure.fillWithBlocks(world, start, -15, -3, -20, -15, -2, -19, Blocks.RED_SAND.getDefaultState());
        structure.fillWithBlocks(world, start, -15, -3, -18, -15, -1, -18, Blocks.COARSE_DIRT.getDefaultState());
        structure.fillWithBlocks(world, start, -15, -3, -17, -15, -3, 32, Blocks.RED_SAND.getDefaultState());
        structure.fillWithBlocks(world, start, -15, -2, -17, -15, -2, 11, Blocks.RED_SAND.getDefaultState());
        structure.fillWithBlocks(world, start, -15, -2, 12, -15, -2, 13, Blocks.COARSE_DIRT.getDefaultState());
        structure.fillWithBlocks(world, start, -15, -2, 14, -15, -2, 31, Blocks.RED_SAND.getDefaultState());
        structure.fillWithBlocks(world, start, -15, -1, -71, -14, -1, -70, Blocks.RED_SAND.getDefaultState());
        structure.fillWithBlocks(world, start, -15, -1, -20, -15, -1, -19, Blocks.RED_SAND.getDefaultState());
        structure.fillWithBlocks(world, start, -15, -1, -17, -15, -1, -1, Blocks.RED_SAND.getDefaultState());
        structure.fillWithBlocks(world, start, -15, -1, 7, -14, -1, 8, Blocks.RED_SAND.getDefaultState());
        structure.fillWithBlocks(world, start, -15, 0, -42, -15, 0, -42, Blocks.RED_SAND.getDefaultState());
        structure.fillWithBlocks(world, start, -15, 0, 21, -14, 0, 22, Blocks.OAK_PLANKS.getDefaultState());
        structure.fillWithBlocks(world, start, -15, 0, 30, -13, 1, 30, Blocks.OAK_PLANKS.getDefaultState());
        structure.fillWithBlocks(world, start, -15, 1, -23, -15, 8, -23, Blocks.STRIPPED_DARK_OAK_LOG.getDefaultState());
        structure.fillWithBlocks(world, start, -15, 1, -10, -12, 1, -10, Blocks.SPRUCE_PLANKS.getDefaultState());
        structure.fillWithBlocks(world, start, -15, 1, -8, -12, 2, -8, Blocks.JUNGLE_PLANKS.getDefaultState());
        structure.fillWithBlocks(world, start, -15, 2, -38, -14, 3, -38, Blocks.SPRUCE_PLANKS.getDefaultState());
        structure.fillWithBlocks(world, start, -15, 2, 21, -14, 2, 21, Blocks.LIGHT_GRAY_STAINED_GLASS_PANE.getDefaultState().with(FourWayBlock.WATERLOGGED, false).with(FourWayBlock.NORTH, false).with(FourWayBlock.SOUTH, false).with(FourWayBlock.EAST, true).with(FourWayBlock.WEST, true));
        structure.fillWithBlocks(world, start, -15, 3, 7, -14, 4, 7, Blocks.JUNGLE_PLANKS.getDefaultState());
        structure.fillWithBlocks(world, start, -15, 3, 19, -14, 3, 20, Blocks.SPRUCE_SLAB.getDefaultState().with(SlabBlock.TYPE, SlabType.TOP).with(SlabBlock.WATERLOGGED, false));
        structure.fillWithBlocks(world, start, -15, 4, -22, -15, 4, -22, Blocks.SPRUCE_SLAB.getDefaultState().with(SlabBlock.TYPE, SlabType.TOP).with(SlabBlock.WATERLOGGED, false));
        structure.fillWithBlocks(world, start, -15, 4, 24, -15, 4, 25, Blocks.LIGHT_GRAY_CARPET.getDefaultState());
        structure.fillWithBlocks(world, start, -15, 5, -21, -9, 5, -21, Blocks.DARK_OAK_FENCE.getDefaultState().with(FourWayBlock.WATERLOGGED, false).with(FourWayBlock.NORTH, false).with(FourWayBlock.SOUTH, false).with(FourWayBlock.EAST, true).with(FourWayBlock.WEST, true));
        structure.fillWithBlocks(world, start, -15, 5, -8, -13, 6, -8, Blocks.JUNGLE_PLANKS.getDefaultState());
        structure.fillWithBlocks(world, start, -15, 5, 7, -12, 6, 7, Blocks.JUNGLE_PLANKS.getDefaultState());
        structure.fillWithBlocks(world, start, -15, 5, 21, -14, 6, 21, Blocks.OAK_PLANKS.getDefaultState());
        structure.fillWithBlocks(world, start, -15, 5, 30, -10, 6, 30, Blocks.OAK_PLANKS.getDefaultState());
        structure.fillWithBlocks(world, start, -15, 6, -32, -11, 7, -32, Blocks.OAK_PLANKS.getDefaultState());
        structure.fillWithBlocks(world, start, -15, 6, 29, -12, 6, 29, Index.CABINET_OAK.getDefaultState().with(Cabinet.FACING, Direction.NORTH).with(Cabinet.WATERLOGGED, false));
        structure.fillWithBlocks(world, start, -15, 8, -32, -14, 8, -24, Blocks.OAK_PLANKS.getDefaultState());
        structure.fillWithBlocks(world, start, -15, 8, -22, -14, 8, -21, Blocks.SPRUCE_SLAB.getDefaultState().with(SlabBlock.TYPE, SlabType.BOTTOM).with(SlabBlock.WATERLOGGED, false));
        structure.fillWithBlocks(world, start, -14, -9, -77, -12, -9, -75, Blocks.TERRACOTTA.getDefaultState());
        structure.fillWithBlocks(world, start, -14, -9, -73, -12, -9, -71, Blocks.STONE.getDefaultState());
        structure.fillWithBlocks(world, start, -14, -9, -70, -14, -8, -69, Blocks.COAL_ORE.getDefaultState());
        structure.fillWithBlocks(world, start, -14, -9, -60, -9, -9, -55, Blocks.STONE.getDefaultState());
        structure.fillWithBlocks(world, start, -14, -9, -51, -5, -9, -42, Blocks.STONE.getDefaultState());
        structure.fillWithBlocks(world, start, -14, -9, -34, -14, -9, -34, Blocks.STONE.getDefaultState());
        structure.fillWithBlocks(world, start, -14, -9, -27, -8, -9, -21, Blocks.STONE.getDefaultState());
        structure.fillWithBlocks(world, start, -14, -9, -20, -13, -9, -19, Blocks.GOLD_ORE.getDefaultState());
        structure.fillWithBlocks(world, start, -14, -9, -18, -9, -9, 2, Blocks.STONE.getDefaultState());
        structure.fillWithBlocks(world, start, -14, -9, 3, -13, -9, 4, Blocks.GOLD_ORE.getDefaultState());
        structure.fillWithBlocks(world, start, -14, -9, 5, -3, -9, 16, Blocks.STONE.getDefaultState());
        structure.fillWithBlocks(world, start, -14, -9, 27, -14, -7, 29, Blocks.ANDESITE.getDefaultState());
        structure.fillWithBlocks(world, start, -14, -8, -73, -12, -8, -71, Blocks.STONE.getDefaultState());
        structure.fillWithBlocks(world, start, -14, -8, -68, -14, -8, -66, Blocks.COAL_ORE.getDefaultState());
        structure.fillWithBlocks(world, start, -14, -8, -65, -5, -8, -56, Blocks.STONE.getDefaultState());
        structure.fillWithBlocks(world, start, -14, -8, -40, -14, -8, -39, Blocks.DIORITE.getDefaultState());
        structure.fillWithBlocks(world, start, -14, -8, -34, -14, -8, -34, Blocks.STONE.getDefaultState());
        structure.fillWithBlocks(world, start, -14, -8, -27, -14, -6, -25, Blocks.DIRT.getDefaultState());
        structure.fillWithBlocks(world, start, -14, -8, -24, -11, -8, -21, Blocks.STONE.getDefaultState());
        structure.fillWithBlocks(world, start, -14, -8, -20, -13, -8, -19, Blocks.GOLD_ORE.getDefaultState());
        structure.fillWithBlocks(world, start, -14, -8, -18, -8, -8, -2, Blocks.STONE.getDefaultState());
        structure.fillWithBlocks(world, start, -14, -8, -1, -14, -7, -1, Blocks.GOLD_ORE.getDefaultState());
        structure.fillWithBlocks(world, start, -14, -8, 0, -12, -8, 2, Blocks.STONE.getDefaultState());
        structure.fillWithBlocks(world, start, -14, -8, 4, -9, -8, 9, Blocks.STONE.getDefaultState());
        structure.fillWithBlocks(world, start, -14, -8, 10, -10, -8, 25, Blocks.STONE.getDefaultState());
        structure.fillWithBlocks(world, start, -14, -8, 30, -11, -8, 34, Blocks.STONE.getDefaultState());
        structure.fillWithBlocks(world, start, -14, -7, -67, -14, -7, -66, Blocks.COAL_ORE.getDefaultState());
        structure.fillWithBlocks(world, start, -14, -7, -65, -5, -7, -56, Blocks.STONE.getDefaultState());
        structure.fillWithBlocks(world, start, -14, -7, -55, -8, -7, -34, Blocks.STONE.getDefaultState());
        structure.fillWithBlocks(world, start, -14, -7, -23, -13, -7, -22, Blocks.STONE.getDefaultState());
        structure.fillWithBlocks(world, start, -14, -7, -21, -13, -7, -20, Blocks.DIORITE.getDefaultState());
        structure.fillWithBlocks(world, start, -14, -7, -19, -11, -7, -16, Blocks.STONE.getDefaultState());
        structure.fillWithBlocks(world, start, -14, -7, -15, -14, -5, -12, Blocks.GRANITE.getDefaultState());
        structure.fillWithBlocks(world, start, -14, -7, -11, -10, -7, -7, Blocks.STONE.getDefaultState());
        structure.fillWithBlocks(world, start, -14, -7, -6, -14, -6, -5, Blocks.GOLD_ORE.getDefaultState());
        structure.fillWithBlocks(world, start, -14, -7, 0, -13, -7, 0, Blocks.GOLD_ORE.getDefaultState());
        structure.fillWithBlocks(world, start, -14, -7, 1, -6, -7, 9, Blocks.STONE.getDefaultState());
        structure.fillWithBlocks(world, start, -14, -7, 30, -11, -7, 33, Blocks.STONE.getDefaultState());
        structure.fillWithBlocks(world, start, -14, -7, 34, -12, -7, 36, Blocks.RED_SAND.getDefaultState());
        structure.fillWithBlocks(world, start, -14, -6, -30, -12, -6, -26, Blocks.DIRT.getDefaultState());
        structure.fillWithBlocks(world, start, -14, -6, -23, -7, -6, -23, Blocks.STONE.getDefaultState());
        structure.fillWithBlocks(world, start, -14, -6, -18, -13, -6, -17, Blocks.STONE.getDefaultState());
        structure.fillWithBlocks(world, start, -14, -6, -16, -14, -6, -10, Blocks.GRANITE.getDefaultState());
        structure.fillWithBlocks(world, start, -14, -6, 27, -14, -6, 29, Blocks.ANDESITE.getDefaultState());
        structure.fillWithBlocks(world, start, -14, -5, -73, -14, -5, -72, Blocks.RED_SAND.getDefaultState());
        structure.fillWithBlocks(world, start, -14, -5, -54, -14, -5, -53, Blocks.ANDESITE.getDefaultState());
        structure.fillWithBlocks(world, start, -14, -5, -52, 4, -5, -28, Blocks.RED_SAND.getDefaultState());
        structure.fillWithBlocks(world, start, -14, -5, -25, -13, -5, -24, Blocks.RED_SAND.getDefaultState());
        structure.fillWithBlocks(world, start, -14, -5, -18, -12, -5, -16, Blocks.STONE.getDefaultState());
        structure.fillWithBlocks(world, start, -14, -5, -11, -14, -5, -10, Blocks.GRANITE.getDefaultState());
        structure.fillWithBlocks(world, start, -14, -5, 8, -8, -5, 14, Blocks.STONE.getDefaultState());
        structure.fillWithBlocks(world, start, -14, -5, 32, -12, -5, 34, Blocks.RED_SAND.getDefaultState());
        structure.fillWithBlocks(world, start, -14, -4, 33, -3, -4, 33, Blocks.RED_SAND.getDefaultState());
        structure.fillWithBlocks(world, start, -14, -3, -21, -14, -3, -20, Blocks.RED_SAND.getDefaultState());
        structure.fillWithBlocks(world, start, -14, -3, -19, -14, -1, -19, Blocks.COARSE_DIRT.getDefaultState());
        structure.fillWithBlocks(world, start, -14, -3, -18, -14, -1, -18, Blocks.RED_SAND.getDefaultState());
        structure.fillWithBlocks(world, start, -14, -3, -17, -14, -1, -17, Blocks.STONE.getDefaultState());
        structure.fillWithBlocks(world, start, -14, -2, -71, -12, -2, -69, Blocks.RED_SAND.getDefaultState());
        structure.fillWithBlocks(world, start, -14, -2, -68, -14, -2, -67, Blocks.DIRT.getDefaultState());
        structure.fillWithBlocks(world, start, -14, -2, -21, -14, -2, -20, Blocks.RED_SAND.getDefaultState());
        structure.fillWithBlocks(world, start, -14, -2, 12, -14, -2, 13, Blocks.RED_SAND.getDefaultState());
        structure.fillWithBlocks(world, start, -14, -2, 14, -14, -2, 14, Blocks.STONE.getDefaultState());
        structure.fillWithBlocks(world, start, -14, -2, 15, -14, -2, 31, Blocks.RED_SAND.getDefaultState());
        structure.fillWithBlocks(world, start, -14, -1, -21, -14, -1, -20, Blocks.RED_SAND.getDefaultState());
        structure.fillWithBlocks(world, start, -14, 0, -70, 33, 1, -70, Blocks.RED_SAND.getDefaultState());
        structure.fillWithBlocks(world, start, -14, 0, -69, -14, 0, -69, Blocks.DIRT.getDefaultState());
        structure.fillWithBlocks(world, start, -14, 0, -68, -14, 0, -41, Blocks.RED_SAND.getDefaultState());
        structure.fillWithBlocks(world, start, -14, 0, -16, -14, 0, -16, Blocks.DARK_OAK_PLANKS.getDefaultState());
        structure.fillWithBlocks(world, start, -14, 0, -15, -14, 3, -15, Blocks.DARK_OAK_WOOD.getDefaultState());
        structure.fillWithBlocks(world, start, -14, 0, -14, -12, 0, -12, Blocks.DARK_OAK_PLANKS.getDefaultState());
        structure.fillWithBlocks(world, start, -14, 0, -11, -14, 3, -11, Blocks.DARK_OAK_WOOD.getDefaultState());
        structure.fillWithBlocks(world, start, -14, 0, -10, -12, 0, -10, Blocks.DARK_OAK_PLANKS.getDefaultState());
        structure.fillWithBlocks(world, start, -14, 0, 25, -14, 0, 27, Blocks.OAK_STAIRS.getDefaultState().with(StairsBlock.FACING, Direction.WEST).with(StairsBlock.WATERLOGGED, false).with(StairsBlock.SHAPE, StairsShape.STRAIGHT).with(StairsBlock.HALF, Half.TOP));
        structure.fillWithBlocks(world, start, -14, 1, -69, -14, 1, -69, Blocks.RED_SAND.getDefaultState());
        structure.fillWithBlocks(world, start, -14, 1, -37, -14, 2, -36, Blocks.BARREL.getDefaultState().with(BarrelBlock.PROPERTY_FACING, Direction.WEST).with(BarrelBlock.PROPERTY_OPEN, false));
        structure.fillWithBlocks(world, start, -14, 1, -32, -11, 1, -32, Blocks.OAK_PLANKS.getDefaultState());
        structure.fillWithBlocks(world, start, -14, 1, -23, -13, 2, -23, Blocks.OAK_PLANKS.getDefaultState());
        structure.fillWithBlocks(world, start, -14, 1, -21, -9, 1, -21, Blocks.DARK_OAK_FENCE.getDefaultState().with(FourWayBlock.WATERLOGGED, false).with(FourWayBlock.NORTH, false).with(FourWayBlock.SOUTH, false).with(FourWayBlock.EAST, true).with(FourWayBlock.WEST, true));
        structure.fillWithBlocks(world, start, -14, 1, -16, -14, 1, -16, Blocks.SPRUCE_PLANKS.getDefaultState());
        structure.fillWithBlocks(world, start, -14, 1, -14, -14, 1, -13, Blocks.SPRUCE_PLANKS.getDefaultState());
        structure.fillWithBlocks(world, start, -14, 1, -9, -13, 1, -9, Blocks.CAVE_AIR.getDefaultState());
        structure.fillWithBlocks(world, start, -14, 1, -6, -12, 1, -6, Blocks.DARK_OAK_STAIRS.getDefaultState().with(StairsBlock.FACING, Direction.NORTH).with(StairsBlock.WATERLOGGED, false).with(StairsBlock.SHAPE, StairsShape.STRAIGHT).with(StairsBlock.HALF, Half.TOP));
        structure.fillWithBlocks(world, start, -14, 1, 4, -12, 1, 4, Index.STOOL_OAK.getDefaultState().with(Stool.PILLOW, StoolState.NONE));
        structure.fillWithBlocks(world, start, -14, 1, 6, -12, 1, 6, Index.STOOL_OAK.getDefaultState().with(Stool.PILLOW, StoolState.NONE));
        structure.fillWithBlocks(world, start, -14, 1, 21, -14, 2, 21, Blocks.LIGHT_GRAY_STAINED_GLASS_PANE.getDefaultState().with(FourWayBlock.WATERLOGGED, false).with(FourWayBlock.NORTH, false).with(FourWayBlock.SOUTH, false).with(FourWayBlock.EAST, true).with(FourWayBlock.WEST, true));
        structure.fillWithBlocks(world, start, -14, 2, -34, -14, 3, -34, Blocks.SPRUCE_PLANKS.getDefaultState());
        structure.fillWithBlocks(world, start, -14, 2, -16, -14, 3, -16, Blocks.LIGHT_GRAY_STAINED_GLASS_PANE.getDefaultState().with(FourWayBlock.WATERLOGGED, false).with(FourWayBlock.NORTH, false).with(FourWayBlock.SOUTH, true).with(FourWayBlock.EAST, true).with(FourWayBlock.WEST, true));
        structure.fillWithBlocks(world, start, -14, 2, -13, -14, 3, -12, Blocks.SPRUCE_PLANKS.getDefaultState());
        structure.fillWithBlocks(world, start, -14, 2, -10, -14, 3, -10, Blocks.LIGHT_GRAY_STAINED_GLASS_PANE.getDefaultState().with(FourWayBlock.WATERLOGGED, false).with(FourWayBlock.NORTH, true).with(FourWayBlock.SOUTH, false).with(FourWayBlock.EAST, true).with(FourWayBlock.WEST, true));
        structure.fillWithBlocks(world, start, -14, 2, 7, -11, 2, 7, Blocks.JUNGLE_PLANKS.getDefaultState());
        structure.fillWithBlocks(world, start, -14, 3, -31, -12, 3, -31, Blocks.SPRUCE_TRAPDOOR.getDefaultState().with(HorizontalBlock.HORIZONTAL_FACING, Direction.SOUTH).with(TrapDoorBlock.HALF, Half.TOP).with(TrapDoorBlock.WATERLOGGED, false).with(TrapDoorBlock.POWERED, false).with(TrapDoorBlock.OPEN, false));
        structure.fillWithBlocks(world, start, -14, 3, -23, -13, 3, -23, Blocks.OAK_PLANKS.getDefaultState());
        structure.fillWithBlocks(world, start, -14, 3, -14, -12, 3, -12, Blocks.SPRUCE_PLANKS.getDefaultState());
        structure.fillWithBlocks(world, start, -14, 4, -23, -14, 9, -23, Blocks.OAK_PLANKS.getDefaultState());
        structure.fillWithBlocks(world, start, -14, 4, -22, -13, 4, -21, Blocks.SPRUCE_SLAB.getDefaultState().with(SlabBlock.TYPE, SlabType.TOP).with(SlabBlock.WATERLOGGED, false));
        structure.fillWithBlocks(world, start, -14, 4, 24, -12, 4, 24, Blocks.LIGHT_GRAY_CARPET.getDefaultState());
        structure.fillWithBlocks(world, start, -14, 4, 25, -13, 4, 25, Blocks.OAK_SLAB.getDefaultState().with(SlabBlock.TYPE, SlabType.BOTTOM).with(SlabBlock.WATERLOGGED, false));
        structure.fillWithBlocks(world, start, -14, 4, 26, -14, 4, 27, Blocks.LIGHT_GRAY_CARPET.getDefaultState());
        structure.fillWithBlocks(world, start, -14, 4, 28, -13, 4, 28, Blocks.WHITE_BED.getDefaultState().with(HorizontalBlock.HORIZONTAL_FACING, Direction.SOUTH).with(BedBlock.PART, BedPart.FOOT));
        structure.fillWithBlocks(world, start, -14, 4, 29, -13, 4, 29, Blocks.WHITE_BED.getDefaultState().with(HorizontalBlock.HORIZONTAL_FACING, Direction.SOUTH).with(BedBlock.PART, BedPart.HEAD));
        structure.fillWithBlocks(world, start, -14, 5, -32, -11, 7, -32, Blocks.OAK_PLANKS.getDefaultState());
        structure.fillWithBlocks(world, start, -14, 5, -31, -12, 5, -31, Blocks.SPRUCE_TRAPDOOR.getDefaultState().with(HorizontalBlock.HORIZONTAL_FACING, Direction.SOUTH).with(TrapDoorBlock.HALF, Half.BOTTOM).with(TrapDoorBlock.WATERLOGGED, false).with(TrapDoorBlock.POWERED, false).with(TrapDoorBlock.OPEN, false));
        structure.fillWithBlocks(world, start, -14, 7, 19, -13, 7, 20, Blocks.SPRUCE_SLAB.getDefaultState().with(SlabBlock.TYPE, SlabType.BOTTOM).with(SlabBlock.WATERLOGGED, false));
        structure.fillWithBlocks(world, start, -13, -9, -74, -11, -9, -42, Blocks.STONE.getDefaultState());
        structure.fillWithBlocks(world, start, -13, -9, -41, -12, -9, -40, Blocks.DIORITE.getDefaultState());
        structure.fillWithBlocks(world, start, -13, -9, -39, -12, -9, -38, Blocks.GOLD_ORE.getDefaultState());
        structure.fillWithBlocks(world, start, -13, -9, -37, -11, -9, -21, Blocks.STONE.getDefaultState());
        structure.fillWithBlocks(world, start, -13, -9, 27, -11, -9, 34, Blocks.STONE.getDefaultState());
        structure.fillWithBlocks(world, start, -13, -8, -75, -12, -8, -74, Blocks.RED_SAND.getDefaultState());
        structure.fillWithBlocks(world, start, -13, -8, -70, -5, -8, -56, Blocks.STONE.getDefaultState());
        structure.fillWithBlocks(world, start, -13, -8, -40, -11, -8, -40, Blocks.DIORITE.getDefaultState());
        structure.fillWithBlocks(world, start, -13, -8, -39, -12, -8, -38, Blocks.GOLD_ORE.getDefaultState());
        structure.fillWithBlocks(world, start, -13, -8, -37, -9, -8, -33, Blocks.STONE.getDefaultState());
        structure.fillWithBlocks(world, start, -13, -8, -31, -13, -8, -31, Blocks.STONE.getDefaultState());
        structure.fillWithBlocks(world, start, -13, -8, -30, -13, -8, -29, Blocks.ANDESITE.getDefaultState());
        structure.fillWithBlocks(world, start, -13, -8, -28, -6, -8, -21, Blocks.STONE.getDefaultState());
        structure.fillWithBlocks(world, start, -13, -8, -1, -3, -8, 9, Blocks.STONE.getDefaultState());
        structure.fillWithBlocks(world, start, -13, -7, -74, -11, -6, -74, Blocks.RED_SAND.getDefaultState());
        structure.fillWithBlocks(world, start, -13, -7, -73, -7, -7, -56, Blocks.STONE.getDefaultState());
        structure.fillWithBlocks(world, start, -13, -7, -33, -11, -7, -31, Blocks.STONE.getDefaultState());
        structure.fillWithBlocks(world, start, -13, -7, -30, -12, -7, -29, Blocks.STONE.getDefaultState());
        structure.fillWithBlocks(world, start, -13, -7, -24, -11, -7, -22, Blocks.STONE.getDefaultState());
        structure.fillWithBlocks(world, start, -13, -7, -15, -8, -7, -4, Blocks.STONE.getDefaultState());
        structure.fillWithBlocks(world, start, -13, -7, -1, -13, -7, 0, Blocks.GOLD_ORE.getDefaultState());
        structure.fillWithBlocks(world, start, -13, -6, -73, -13, -4, -73, Blocks.RED_SAND.getDefaultState());
        structure.fillWithBlocks(world, start, -13, -6, -31, -12, -6, -26, Blocks.DIRT.getDefaultState());
        structure.fillWithBlocks(world, start, -13, -6, -22, -12, -6, -19, Blocks.DIORITE.getDefaultState());
        structure.fillWithBlocks(world, start, -13, -6, -16, -8, -6, -4, Blocks.STONE.getDefaultState());
        structure.fillWithBlocks(world, start, -13, -6, 1, -3, -6, 22, Blocks.STONE.getDefaultState());
        structure.fillWithBlocks(world, start, -13, -6, 27, -8, -6, 32, Blocks.STONE.getDefaultState());
        structure.fillWithBlocks(world, start, -13, -5, -72, -5, -5, -59, Blocks.STONE.getDefaultState());
        structure.fillWithBlocks(world, start, -13, -5, -53, 4, -5, -28, Blocks.RED_SAND.getDefaultState());
        structure.fillWithBlocks(world, start, -13, -5, -27, -12, -5, -26, Blocks.RED_SAND.getDefaultState());
        structure.fillWithBlocks(world, start, -13, -5, -23, -7, -1, -23, Blocks.RED_SAND.getDefaultState());
        structure.fillWithBlocks(world, start, -13, -5, -22, -11, -5, -20, Blocks.DIORITE.getDefaultState());
        structure.fillWithBlocks(world, start, -13, -5, -19, -12, -5, -19, Blocks.DIORITE.getDefaultState());
        structure.fillWithBlocks(world, start, -13, -5, -15, -4, -5, -3, Blocks.STONE.getDefaultState());
        structure.fillWithBlocks(world, start, -13, -5, 15, -12, -5, 16, Blocks.GOLD_ORE.getDefaultState());
        structure.fillWithBlocks(world, start, -13, -5, 17, -5, -5, 31, Blocks.STONE.getDefaultState());
        structure.fillWithBlocks(world, start, -13, -4, -72, 3, -4, -7, Blocks.RED_SAND.getDefaultState());
        structure.fillWithBlocks(world, start, -13, -3, -21, -13, -1, -21, Blocks.STONE.getDefaultState());
        structure.fillWithBlocks(world, start, -13, -3, -20, -13, -1, -20, Blocks.RED_SAND.getDefaultState());
        structure.fillWithBlocks(world, start, -13, -3, -19, -13, -3, -18, Blocks.STONE.getDefaultState());
        structure.fillWithBlocks(world, start, -13, -3, -17, -12, -3, 32, Blocks.RED_SAND.getDefaultState());
        structure.fillWithBlocks(world, start, -13, -2, -72, -9, -2, -68, Blocks.RED_SAND.getDefaultState());
        structure.fillWithBlocks(world, start, -13, -2, -67, -13, -2, -67, Blocks.DIRT.getDefaultState());
        structure.fillWithBlocks(world, start, -13, -2, -19, -13, -2, -18, Blocks.STONE.getDefaultState());
        structure.fillWithBlocks(world, start, -13, -2, -17, -12, -2, 11, Blocks.RED_SAND.getDefaultState());
        structure.fillWithBlocks(world, start, -13, -2, 12, -12, -2, 12, Blocks.STONE.getDefaultState());
        structure.fillWithBlocks(world, start, -13, -2, 13, -13, -2, 13, Blocks.RED_SAND.getDefaultState());
        structure.fillWithBlocks(world, start, -13, -2, 14, -13, -2, 15, Blocks.STONE.getDefaultState());
        structure.fillWithBlocks(world, start, -13, -1, -71, -12, -1, -70, Blocks.RED_SAND.getDefaultState());
        structure.fillWithBlocks(world, start, -13, -1, -69, -11, -1, -67, Blocks.DIRT.getDefaultState());
        structure.fillWithBlocks(world, start, -13, -1, -19, -13, -1, -18, Blocks.STONE.getDefaultState());
        structure.fillWithBlocks(world, start, -13, -1, -17, -12, -1, -1, Blocks.RED_SAND.getDefaultState());
        structure.fillWithBlocks(world, start, -13, -1, 7, -12, -1, 8, Blocks.RED_SAND.getDefaultState());
        structure.fillWithBlocks(world, start, -13, 0, -71, -12, 0, -70, Blocks.RED_SAND.getDefaultState());
        structure.fillWithBlocks(world, start, -13, 0, -69, -12, 0, -68, Blocks.DIRT.getDefaultState());
        structure.fillWithBlocks(world, start, -13, 0, -67, -12, 0, -44, Blocks.RED_SAND.getDefaultState());
        structure.fillWithBlocks(world, start, -13, 0, -43, -13, 0, -42, Blocks.RED_SAND.getDefaultState());
        structure.fillWithBlocks(world, start, -13, 0, -38, -13, 3, -38, Blocks.DARK_OAK_WOOD.getDefaultState());
        structure.fillWithBlocks(world, start, -13, 0, -37, -13, 0, -35, Blocks.DARK_OAK_PLANKS.getDefaultState());
        structure.fillWithBlocks(world, start, -13, 0, -34, -13, 3, -34, Blocks.DARK_OAK_WOOD.getDefaultState());
        structure.fillWithBlocks(world, start, -13, 0, -16, -12, 0, -10, Blocks.DARK_OAK_PLANKS.getDefaultState());
        structure.fillWithBlocks(world, start, -13, 0, 8, -10, 0, 8, Blocks.RED_SAND.getDefaultState());
        structure.fillWithBlocks(world, start, -13, 0, 21, -12, 1, 21, Blocks.OAK_PLANKS.getDefaultState());
        structure.fillWithBlocks(world, start, -13, 1, -69, -12, 1, -68, Blocks.RED_SAND.getDefaultState());
        structure.fillWithBlocks(world, start, -13, 1, -36, -13, 1, -35, Blocks.SPRUCE_PLANKS.getDefaultState());
        structure.fillWithBlocks(world, start, -13, 1, -16, -12, 1, -15, Blocks.SPRUCE_PLANKS.getDefaultState());
        structure.fillWithBlocks(world, start, -13, 1, -13, -13, 1, -12, Blocks.BARREL.getDefaultState().with(BarrelBlock.PROPERTY_FACING, Direction.EAST).with(BarrelBlock.PROPERTY_OPEN, false));
        structure.fillWithBlocks(world, start, -13, 1, -11, -12, 1, -10, Blocks.SPRUCE_PLANKS.getDefaultState());
        structure.fillWithBlocks(world, start, -13, 2, -37, -13, 3, -36, Blocks.SPRUCE_PLANKS.getDefaultState());
        structure.fillWithBlocks(world, start, -13, 2, -32, -9, 2, -32, Blocks.OAK_PLANKS.getDefaultState());
        structure.fillWithBlocks(world, start, -13, 2, -16, -13, 3, -15, Blocks.SPRUCE_PLANKS.getDefaultState());
        structure.fillWithBlocks(world, start, -13, 2, -11, -12, 2, -10, Blocks.SPRUCE_PLANKS.getDefaultState());
        structure.fillWithBlocks(world, start, -13, 2, 21, -12, 2, 21, Blocks.OAK_PLANKS.getDefaultState());
        structure.fillWithBlocks(world, start, -13, 2, 30, -10, 3, 30, Blocks.OAK_PLANKS.getDefaultState());
        structure.fillWithBlocks(world, start, -13, 3, -11, -12, 3, -10, Blocks.SPRUCE_PLANKS.getDefaultState());
        structure.fillWithBlocks(world, start, -13, 3, 19, -12, 3, 20, Blocks.SPRUCE_SLAB.getDefaultState().with(SlabBlock.TYPE, SlabType.TOP).with(SlabBlock.WATERLOGGED, false));
        structure.fillWithBlocks(world, start, -13, 4, -37, -13, 4, -35, Blocks.DARK_OAK_SLAB.getDefaultState().with(SlabBlock.TYPE, SlabType.BOTTOM).with(SlabBlock.WATERLOGGED, false));
        structure.fillWithBlocks(world, start, -13, 4, -8, -10, 4, -8, Blocks.JUNGLE_PLANKS.getDefaultState());
        structure.fillWithBlocks(world, start, -13, 4, 7, -10, 5, 7, Blocks.JUNGLE_PLANKS.getDefaultState());
        structure.fillWithBlocks(world, start, -13, 4, 26, -13, 4, 26, Blocks.LIGHT_GRAY_CARPET.getDefaultState());
        structure.fillWithBlocks(world, start, -13, 5, -23, -9, 5, -23, Blocks.OAK_PLANKS.getDefaultState());
        structure.fillWithBlocks(world, start, -13, 5, 21, -13, 6, 21, Blocks.LIGHT_GRAY_STAINED_GLASS_PANE.getDefaultState().with(FourWayBlock.WATERLOGGED, false).with(FourWayBlock.NORTH, false).with(FourWayBlock.SOUTH, false).with(FourWayBlock.EAST, true).with(FourWayBlock.WEST, true));
        structure.fillWithBlocks(world, start, -13, 6, -28, -13, 7, -28, Blocks.CHAIN.getDefaultState().with(ChainBlock.WATERLOGGED, false));
        structure.fillWithBlocks(world, start, -13, 6, -23, -13, 7, -23, Blocks.LIGHT_GRAY_STAINED_GLASS_PANE.getDefaultState().with(FourWayBlock.WATERLOGGED, false).with(FourWayBlock.NORTH, false).with(FourWayBlock.SOUTH, false).with(FourWayBlock.EAST, true).with(FourWayBlock.WEST, true));
        structure.fillWithBlocks(world, start, -13, 8, -25, -11, 8, -23, Blocks.OAK_PLANKS.getDefaultState());
        structure.fillWithBlocks(world, start, -13, 8, -22, -12, 8, -21, Blocks.SPRUCE_SLAB.getDefaultState().with(SlabBlock.TYPE, SlabType.BOTTOM).with(SlabBlock.WATERLOGGED, false));
        structure.fillWithBlocks(world, start, -13, 10, -23, -10, 10, -23, Blocks.OAK_PLANKS.getDefaultState());
        structure.fillWithBlocks(world, start, -13, 11, -23, -10, 11, -23, Blocks.SPRUCE_SLAB.getDefaultState().with(SlabBlock.TYPE, SlabType.BOTTOM).with(SlabBlock.WATERLOGGED, false));
        structure.fillWithBlocks(world, start, -12, -9, -20, -9, -9, 26, Blocks.STONE.getDefaultState());
        structure.fillWithBlocks(world, start, -12, -9, 35, -12, -9, 39, Blocks.TERRACOTTA.getDefaultState());
        structure.fillWithBlocks(world, start, -12, -8, -76, -11, -8, -75, Blocks.RED_SAND.getDefaultState());
        structure.fillWithBlocks(world, start, -12, -8, -32, -4, -8, -19, Blocks.STONE.getDefaultState());
        structure.fillWithBlocks(world, start, -12, -8, 26, -12, -8, 26, Blocks.STONE.getDefaultState());
        structure.fillWithBlocks(world, start, -12, -8, 27, -12, -7, 27, Blocks.ANDESITE.getDefaultState());
        structure.fillWithBlocks(world, start, -12, -8, 28, -8, -8, 32, Blocks.STONE.getDefaultState());
        structure.fillWithBlocks(world, start, -12, -7, -75, -11, -7, -74, Blocks.RED_SAND.getDefaultState());
        structure.fillWithBlocks(world, start, -12, -7, -28, -12, -7, -28, Blocks.STONE.getDefaultState());
        structure.fillWithBlocks(world, start, -12, -7, -27, -12, -6, -27, Blocks.DIRT.getDefaultState());
        structure.fillWithBlocks(world, start, -12, -7, -26, -5, -7, -13, Blocks.STONE.getDefaultState());
        structure.fillWithBlocks(world, start, -12, -7, -3, -10, -7, 26, Blocks.STONE.getDefaultState());
        structure.fillWithBlocks(world, start, -12, -7, 28, -7, -7, 33, Blocks.STONE.getDefaultState());
        structure.fillWithBlocks(world, start, -12, -6, -73, -12, -6, -32, Blocks.STONE.getDefaultState());
        structure.fillWithBlocks(world, start, -12, -6, -25, -10, -6, -23, Blocks.STONE.getDefaultState());
        structure.fillWithBlocks(world, start, -12, -6, -18, -10, -6, 32, Blocks.STONE.getDefaultState());
        structure.fillWithBlocks(world, start, -12, -5, -73, -11, -4, -73, Blocks.RED_SAND.getDefaultState());
        structure.fillWithBlocks(world, start, -12, -5, -54, 4, -5, -28, Blocks.RED_SAND.getDefaultState());
        structure.fillWithBlocks(world, start, -12, -5, -24, -11, -5, -23, Blocks.RED_SAND.getDefaultState());
        structure.fillWithBlocks(world, start, -12, -3, -73, 4, -3, -57, Blocks.RED_SAND.getDefaultState());
        structure.fillWithBlocks(world, start, -12, -3, -21, -12, -3, -21, Blocks.RED_SAND.getDefaultState());
        structure.fillWithBlocks(world, start, -12, -3, -20, -12, -1, -20, Blocks.STONE.getDefaultState());
        structure.fillWithBlocks(world, start, -12, -3, -19, -11, -2, -19, Blocks.RED_SAND.getDefaultState());
        structure.fillWithBlocks(world, start, -12, -3, -18, -12, -3, -18, Blocks.STONE.getDefaultState());
        structure.fillWithBlocks(world, start, -12, -2, -67, -12, -2, -66, Blocks.DIRT.getDefaultState());
        structure.fillWithBlocks(world, start, -12, -2, -65, -3, -2, -56, Blocks.RED_SAND.getDefaultState());
        structure.fillWithBlocks(world, start, -12, -2, -21, -12, -2, -21, Blocks.RED_SAND.getDefaultState());
        structure.fillWithBlocks(world, start, -12, -2, -18, -12, -2, -18, Blocks.STONE.getDefaultState());
        structure.fillWithBlocks(world, start, -12, -2, 13, -11, -2, 14, Blocks.RED_SAND.getDefaultState());
        structure.fillWithBlocks(world, start, -12, -1, -72, -10, -1, -70, Blocks.RED_SAND.getDefaultState());
        structure.fillWithBlocks(world, start, -12, -1, -66, -10, -1, -66, Blocks.DIRT.getDefaultState());
        structure.fillWithBlocks(world, start, -12, -1, -65, -3, -1, -56, Blocks.RED_SAND.getDefaultState());
        structure.fillWithBlocks(world, start, -12, -1, -21, -12, -1, -21, Blocks.RED_SAND.getDefaultState());
        structure.fillWithBlocks(world, start, -12, -1, -19, -11, -1, -19, Blocks.RED_SAND.getDefaultState());
        structure.fillWithBlocks(world, start, -12, -1, -18, -12, -1, -18, Blocks.STONE.getDefaultState());
        structure.fillWithBlocks(world, start, -12, -1, 9, -10, -1, 9, Blocks.RED_SAND.getDefaultState());
        structure.fillWithBlocks(world, start, -12, 0, 30, -10, 0, 30, Blocks.OAK_PLANKS.getDefaultState());
        structure.fillWithBlocks(world, start, -12, 1, -23, -11, 1, -23, Blocks.OAK_PLANKS.getDefaultState());
        structure.fillWithBlocks(world, start, -12, 1, -12, -11, 1, -12, Blocks.BARREL.getDefaultState().with(BarrelBlock.PROPERTY_FACING, Direction.UP).with(BarrelBlock.PROPERTY_OPEN, false));
        structure.fillWithBlocks(world, start, -12, 2, -23, -11, 3, -23, Blocks.LIGHT_GRAY_STAINED_GLASS_PANE.getDefaultState().with(FourWayBlock.WATERLOGGED, false).with(FourWayBlock.NORTH, false).with(FourWayBlock.SOUTH, false).with(FourWayBlock.EAST, true).with(FourWayBlock.WEST, true));
        structure.fillWithBlocks(world, start, -12, 2, -16, -12, 2, -16, Blocks.SPRUCE_PLANKS.getDefaultState());
        structure.fillWithBlocks(world, start, -12, 3, -15, -11, 3, -11, Blocks.SPRUCE_PLANKS.getDefaultState());
        structure.fillWithBlocks(world, start, -12, 3, -8, -10, 4, -8, Blocks.JUNGLE_PLANKS.getDefaultState());
        structure.fillWithBlocks(world, start, -12, 3, 7, -10, 5, 7, Blocks.JUNGLE_PLANKS.getDefaultState());
        structure.fillWithBlocks(world, start, -12, 3, 21, -12, 3, 30, Blocks.OAK_PLANKS.getDefaultState());
        structure.fillWithBlocks(world, start, -12, 4, -32, -9, 5, -32, Blocks.OAK_PLANKS.getDefaultState());
        structure.fillWithBlocks(world, start, -12, 4, -23, -9, 5, -23, Blocks.OAK_PLANKS.getDefaultState());
        structure.fillWithBlocks(world, start, -12, 4, -22, -11, 4, -21, Blocks.SPRUCE_SLAB.getDefaultState().with(SlabBlock.TYPE, SlabType.TOP).with(SlabBlock.WATERLOGGED, false));
        structure.fillWithBlocks(world, start, -12, 4, 25, -12, 4, 27, Blocks.LIGHT_GRAY_CARPET.getDefaultState());
        structure.fillWithBlocks(world, start, -12, 5, 21, -12, 8, 21, Blocks.OAK_PLANKS.getDefaultState());
        structure.fillWithBlocks(world, start, -12, 6, -23, -11, 7, -23, Blocks.OAK_PLANKS.getDefaultState());
        structure.fillWithBlocks(world, start, -12, 7, 19, -11, 7, 20, Blocks.SPRUCE_SLAB.getDefaultState().with(SlabBlock.TYPE, SlabType.BOTTOM).with(SlabBlock.WATERLOGGED, false));
        structure.fillWithBlocks(world, start, -12, 7, 30, -10, 7, 30, Blocks.OAK_PLANKS.getDefaultState());
        structure.fillWithBlocks(world, start, -12, 8, -32, -9, 8, -23, Blocks.OAK_PLANKS.getDefaultState());
        structure.fillWithBlocks(world, start, -12, 9, -23, -10, 10, -23, Blocks.OAK_PLANKS.getDefaultState());
        structure.fillWithBlocks(world, start, -11, -9, -78, -9, -9, -76, Blocks.TERRACOTTA.getDefaultState());
        structure.fillWithBlocks(world, start, -11, -9, -41, -11, -9, -38, Blocks.DIORITE.getDefaultState());
        structure.fillWithBlocks(world, start, -11, -9, 36, -9, -9, 39, Blocks.TERRACOTTA.getDefaultState());
        structure.fillWithBlocks(world, start, -11, -8, -74, -10, -8, -41, Blocks.STONE.getDefaultState());
        structure.fillWithBlocks(world, start, -11, -8, -38, -6, -8, -19, Blocks.STONE.getDefaultState());
        structure.fillWithBlocks(world, start, -11, -8, 26, -5, -8, 32, Blocks.STONE.getDefaultState());
        structure.fillWithBlocks(world, start, -11, -7, -30, -10, -7, -29, Blocks.IRON_ORE.getDefaultState());
        structure.fillWithBlocks(world, start, -11, -7, -28, -4, -7, -19, Blocks.STONE.getDefaultState());
        structure.fillWithBlocks(world, start, -11, -7, 27, -6, -7, 33, Blocks.STONE.getDefaultState());
        structure.fillWithBlocks(world, start, -11, -7, 34, -11, -7, 36, Blocks.RED_SAND.getDefaultState());
        structure.fillWithBlocks(world, start, -11, -6, -73, -11, -6, -73, Blocks.IRON_ORE.getDefaultState());
        structure.fillWithBlocks(world, start, -11, -6, -31, -9, -6, -31, Blocks.STONE.getDefaultState());
        structure.fillWithBlocks(world, start, -11, -6, -30, -11, -6, -29, Blocks.DIRT.getDefaultState());
        structure.fillWithBlocks(world, start, -11, -6, -28, -7, -6, -22, Blocks.STONE.getDefaultState());
        structure.fillWithBlocks(world, start, -11, -6, -21, -11, -5, -20, Blocks.DIORITE.getDefaultState());
        structure.fillWithBlocks(world, start, -11, -6, -19, -10, -6, 32, Blocks.STONE.getDefaultState());
        structure.fillWithBlocks(world, start, -11, -6, 35, -3, -6, 35, Blocks.RED_SAND.getDefaultState());
        structure.fillWithBlocks(world, start, -11, -5, -74, -11, -5, -73, Blocks.RED_SAND.getDefaultState());
        structure.fillWithBlocks(world, start, -11, -5, -55, 4, -5, -28, Blocks.RED_SAND.getDefaultState());
        structure.fillWithBlocks(world, start, -11, -5, -27, -9, -5, -25, Blocks.RED_SAND.getDefaultState());
        structure.fillWithBlocks(world, start, -11, -5, -19, -11, -5, 31, Blocks.STONE.getDefaultState());
        structure.fillWithBlocks(world, start, -11, -5, 32, -9, -5, 34, Blocks.RED_SAND.getDefaultState());
        structure.fillWithBlocks(world, start, -11, -3, -21, -10, -3, -20, Blocks.RED_SAND.getDefaultState());
        structure.fillWithBlocks(world, start, -11, -3, -18, -11, -2, -17, Blocks.STONE.getDefaultState());
        structure.fillWithBlocks(world, start, -11, -2, -67, 78, -2, -67, Blocks.RED_SAND.getDefaultState());
        structure.fillWithBlocks(world, start, -11, -2, -66, -10, -1, -66, Blocks.DIRT.getDefaultState());
        structure.fillWithBlocks(world, start, -11, -2, -21, -10, -2, -20, Blocks.RED_SAND.getDefaultState());
        structure.fillWithBlocks(world, start, -11, -2, 12, -10, -2, 13, Blocks.RED_SAND.getDefaultState());
        structure.fillWithBlocks(world, start, -11, -2, 15, -10, -2, 16, Blocks.RED_SAND.getDefaultState());
        structure.fillWithBlocks(world, start, -11, -1, -21, -10, -1, -20, Blocks.RED_SAND.getDefaultState());
        structure.fillWithBlocks(world, start, -11, -1, -18, -11, -1, -17, Blocks.STONE.getDefaultState());
        structure.fillWithBlocks(world, start, -11, -1, 0, -11, -1, 0, Blocks.RED_SAND.getDefaultState());
        structure.fillWithBlocks(world, start, -11, -1, 7, -10, -1, 9, Blocks.RED_SAND.getDefaultState());
        structure.fillWithBlocks(world, start, -11, 0, -71, -10, 0, -70, Blocks.RED_SAND.getDefaultState());
        structure.fillWithBlocks(world, start, -11, 0, -69, -11, 0, -67, Blocks.DIRT.getDefaultState());
        structure.fillWithBlocks(world, start, -11, 0, -66, -1, 0, -56, Blocks.RED_SAND.getDefaultState());
        structure.fillWithBlocks(world, start, -11, 0, -48, -6, 0, -42, Blocks.RED_SAND.getDefaultState());
        structure.fillWithBlocks(world, start, -11, 0, -16, -11, 3, -16, Blocks.DARK_OAK_WOOD.getDefaultState());
        structure.fillWithBlocks(world, start, -11, 0, -15, -11, 0, -11, Blocks.DARK_OAK_PLANKS.getDefaultState());
        structure.fillWithBlocks(world, start, -11, 0, -10, -11, 3, -10, Blocks.DARK_OAK_WOOD.getDefaultState());
        structure.fillWithBlocks(world, start, -11, 0, 21, -11, 7, 21, Blocks.STRIPPED_DARK_OAK_LOG.getDefaultState());
        structure.fillWithBlocks(world, start, -11, 1, -71, -7, 1, -67, Blocks.RED_SAND.getDefaultState());
        structure.fillWithBlocks(world, start, -11, 1, -29, -11, 1, -26, Index.STOOL_OAK.getDefaultState().with(Stool.PILLOW, StoolState.NONE));
        structure.fillWithBlocks(world, start, -11, 1, -15, -11, 3, -15, Blocks.SPRUCE_PLANKS.getDefaultState());
        structure.fillWithBlocks(world, start, -11, 1, -9, -9, 1, -9, Blocks.CAVE_AIR.getDefaultState());
        structure.fillWithBlocks(world, start, -11, 1, -8, -10, 1, -8, Blocks.JUNGLE_PLANKS.getDefaultState());
        structure.fillWithBlocks(world, start, -11, 1, 19, -11, 2, 19, Blocks.DARK_OAK_FENCE.getDefaultState().with(FourWayBlock.WATERLOGGED, false).with(FourWayBlock.NORTH, false).with(FourWayBlock.SOUTH, false).with(FourWayBlock.EAST, false).with(FourWayBlock.WEST, false));
        structure.fillWithBlocks(world, start, -11, 1, 30, -10, 2, 30, Blocks.OAK_PLANKS.getDefaultState());
        structure.fillWithBlocks(world, start, -11, 3, -32, -9, 5, -32, Blocks.OAK_PLANKS.getDefaultState());
        structure.fillWithBlocks(world, start, -11, 3, 22, -10, 3, 30, Blocks.OAK_PLANKS.getDefaultState());
        structure.fillWithBlocks(world, start, -11, 4, -15, -11, 4, -11, Blocks.DARK_OAK_SLAB.getDefaultState().with(SlabBlock.TYPE, SlabType.BOTTOM).with(SlabBlock.WATERLOGGED, false));
        structure.fillWithBlocks(world, start, -11, 4, 23, -11, 4, 23, Blocks.LIGHT_GRAY_CARPET.getDefaultState());
        structure.fillWithBlocks(world, start, -11, 5, -8, -10, 6, -8, Blocks.JUNGLE_PLANKS.getDefaultState());
        structure.fillWithBlocks(world, start, -11, 8, -22, -10, 8, -21, Blocks.SPRUCE_SLAB.getDefaultState().with(SlabBlock.TYPE, SlabType.BOTTOM).with(SlabBlock.WATERLOGGED, false));
        structure.fillWithBlocks(world, start, -10, -9, -75, -9, -9, -75, Blocks.COAL_ORE.getDefaultState());
        structure.fillWithBlocks(world, start, -10, -9, -74, -10, -7, -72, Blocks.STONE.getDefaultState());
        structure.fillWithBlocks(world, start, -10, -9, -71, -10, -9, -71, Blocks.DIRT.getDefaultState());
        structure.fillWithBlocks(world, start, -10, -9, -70, -10, -9, -41, Blocks.STONE.getDefaultState());
        structure.fillWithBlocks(world, start, -10, -9, -40, -9, -9, -39, Blocks.DIORITE.getDefaultState());
        structure.fillWithBlocks(world, start, -10, -9, -38, -9, -9, -37, Blocks.STONE.getDefaultState());
        structure.fillWithBlocks(world, start, -10, -9, -36, -9, -9, -35, Blocks.GOLD_ORE.getDefaultState());
        structure.fillWithBlocks(world, start, -10, -9, -34, -4, -9, -21, Blocks.STONE.getDefaultState());
        structure.fillWithBlocks(world, start, -10, -9, 27, -10, -5, 27, Blocks.STONE.getDefaultState());
        structure.fillWithBlocks(world, start, -10, -9, 28, -8, -9, 28, Blocks.DIRT.getDefaultState());
        structure.fillWithBlocks(world, start, -10, -9, 29, -7, -9, 32, Blocks.STONE.getDefaultState());
        structure.fillWithBlocks(world, start, -10, -9, 33, -10, -7, 33, Blocks.STONE.getDefaultState());
        structure.fillWithBlocks(world, start, -10, -9, 34, -9, -9, 35, Blocks.ANDESITE.getDefaultState());
        structure.fillWithBlocks(world, start, -10, -8, -76, -9, -8, -75, Blocks.RED_SAND.getDefaultState());
        structure.fillWithBlocks(world, start, -10, -8, -40, -5, -8, -35, Blocks.STONE.getDefaultState());
        structure.fillWithBlocks(world, start, -10, -8, 34, -8, -8, 34, Blocks.ANDESITE.getDefaultState());
        structure.fillWithBlocks(world, start, -10, -7, -75, -7, -6, -75, Blocks.RED_SAND.getDefaultState());
        structure.fillWithBlocks(world, start, -10, -7, -33, -8, -7, -31, Blocks.STONE.getDefaultState());
        structure.fillWithBlocks(world, start, -10, -6, -74, -9, -5, -74, Blocks.RED_SAND.getDefaultState());
        structure.fillWithBlocks(world, start, -10, -6, -73, -9, -6, -72, Blocks.IRON_ORE.getDefaultState());
        structure.fillWithBlocks(world, start, -10, -6, -71, -5, -6, -47, Blocks.STONE.getDefaultState());
        structure.fillWithBlocks(world, start, -10, -6, -46, -8, -6, -37, Blocks.STONE.getDefaultState());
        structure.fillWithBlocks(world, start, -10, -6, -36, -10, -6, -31, Blocks.STONE.getDefaultState());
        structure.fillWithBlocks(world, start, -10, -6, -30, -10, -6, -29, Blocks.IRON_ORE.getDefaultState());
        structure.fillWithBlocks(world, start, -10, -6, -21, -9, -6, -19, Blocks.STONE.getDefaultState());
        structure.fillWithBlocks(world, start, -10, -5, -24, -10, -5, -23, Blocks.RED_SAND.getDefaultState());
        structure.fillWithBlocks(world, start, -10, -5, -22, -10, -5, -19, Blocks.DIORITE.getDefaultState());
        structure.fillWithBlocks(world, start, -10, -5, -18, -10, -5, 31, Blocks.STONE.getDefaultState());
        structure.fillWithBlocks(world, start, -10, -4, -74, 6, -4, -58, Blocks.RED_SAND.getDefaultState());
        structure.fillWithBlocks(world, start, -10, -3, -19, -10, -1, -19, Blocks.STONE.getDefaultState());
        structure.fillWithBlocks(world, start, -10, -3, -18, -9, -3, 32, Blocks.RED_SAND.getDefaultState());
        structure.fillWithBlocks(world, start, -10, -2, -73, -4, -2, -67, Blocks.RED_SAND.getDefaultState());
        structure.fillWithBlocks(world, start, -10, -2, -18, -9, -2, 11, Blocks.RED_SAND.getDefaultState());
        structure.fillWithBlocks(world, start, -10, -2, 14, -7, -2, 14, Blocks.STONE.getDefaultState());
        structure.fillWithBlocks(world, start, -10, -2, 17, -9, -2, 17, Blocks.STONE.getDefaultState());
        structure.fillWithBlocks(world, start, -10, -2, 18, -8, -2, 31, Blocks.RED_SAND.getDefaultState());
        structure.fillWithBlocks(world, start, -10, -1, -69, -9, -1, -68, Blocks.RED_SAND.getDefaultState());
        structure.fillWithBlocks(world, start, -10, -1, -67, -10, -1, -66, Blocks.DIRT.getDefaultState());
        structure.fillWithBlocks(world, start, -10, -1, -18, -9, -1, 1, Blocks.RED_SAND.getDefaultState());
        structure.fillWithBlocks(world, start, -10, -1, 18, -9, -1, 18, Blocks.SPRUCE_STAIRS.getDefaultState().with(StairsBlock.FACING, Direction.SOUTH).with(StairsBlock.WATERLOGGED, false).with(StairsBlock.SHAPE, StairsShape.STRAIGHT).with(StairsBlock.HALF, Half.BOTTOM));
        structure.fillWithBlocks(world, start, -10, 0, -72, -6, 0, -68, Blocks.RED_SAND.getDefaultState());
        structure.fillWithBlocks(world, start, -10, 0, -16, -10, 0, -16, Blocks.DARK_OAK_PLANKS.getDefaultState());
        structure.fillWithBlocks(world, start, -10, 0, -15, -10, 3, -15, Blocks.DARK_OAK_WOOD.getDefaultState());
        structure.fillWithBlocks(world, start, -10, 0, -14, -8, 0, -12, Blocks.DARK_OAK_PLANKS.getDefaultState());
        structure.fillWithBlocks(world, start, -10, 0, -11, -10, 3, -11, Blocks.DARK_OAK_WOOD.getDefaultState());
        structure.fillWithBlocks(world, start, -10, 0, -10, -9, 0, -10, Blocks.DARK_OAK_PLANKS.getDefaultState());
        structure.fillWithBlocks(world, start, -10, 1, -29, -10, 1, -26, Blocks.OAK_STAIRS.getDefaultState().with(StairsBlock.FACING, Direction.EAST).with(StairsBlock.WATERLOGGED, false).with(StairsBlock.SHAPE, StairsShape.STRAIGHT).with(StairsBlock.HALF, Half.TOP));
        structure.fillWithBlocks(world, start, -10, 1, -14, -10, 3, -14, Blocks.SPRUCE_PLANKS.getDefaultState());
        structure.fillWithBlocks(world, start, -10, 1, -12, -10, 3, -12, Blocks.SPRUCE_PLANKS.getDefaultState());
        structure.fillWithBlocks(world, start, -10, 2, -23, -9, 3, -23, Blocks.OAK_PLANKS.getDefaultState());
        structure.fillWithBlocks(world, start, -10, 2, -8, -10, 6, -8, Blocks.JUNGLE_PLANKS.getDefaultState());
        structure.fillWithBlocks(world, start, -10, 2, 22, -10, 7, 22, Blocks.OAK_PLANKS.getDefaultState());
        structure.fillWithBlocks(world, start, -10, 3, -13, -10, 3, -12, Blocks.SPRUCE_PLANKS.getDefaultState());
        structure.fillWithBlocks(world, start, -10, 3, 19, -10, 3, 21, Blocks.SPRUCE_SLAB.getDefaultState().with(SlabBlock.TYPE, SlabType.TOP).with(SlabBlock.WATERLOGGED, false));
        structure.fillWithBlocks(world, start, -10, 4, -22, -9, 4, -21, Blocks.SPRUCE_SLAB.getDefaultState().with(SlabBlock.TYPE, SlabType.TOP).with(SlabBlock.WATERLOGGED, false));
        structure.fillWithBlocks(world, start, -10, 4, -14, -10, 4, -12, Blocks.SPRUCE_SLAB.getDefaultState().with(SlabBlock.TYPE, SlabType.DOUBLE).with(SlabBlock.WATERLOGGED, false));
        structure.fillWithBlocks(world, start, -10, 4, 19, -10, 4, 19, Blocks.DARK_OAK_FENCE.getDefaultState().with(FourWayBlock.WATERLOGGED, false).with(FourWayBlock.NORTH, false).with(FourWayBlock.SOUTH, true).with(FourWayBlock.EAST, false).with(FourWayBlock.WEST, true));
        structure.fillWithBlocks(world, start, -10, 4, 20, -10, 4, 20, Blocks.DARK_OAK_FENCE.getDefaultState().with(FourWayBlock.WATERLOGGED, false).with(FourWayBlock.NORTH, true).with(FourWayBlock.SOUTH, false).with(FourWayBlock.EAST, true).with(FourWayBlock.WEST, false));
        structure.fillWithBlocks(world, start, -10, 4, 30, -10, 7, 30, Blocks.OAK_PLANKS.getDefaultState());
        structure.fillWithBlocks(world, start, -10, 5, 19, -10, 6, 19, Blocks.DARK_OAK_FENCE.getDefaultState().with(FourWayBlock.WATERLOGGED, false).with(FourWayBlock.NORTH, false).with(FourWayBlock.SOUTH, false).with(FourWayBlock.EAST, false).with(FourWayBlock.WEST, false));
        structure.fillWithBlocks(world, start, -10, 6, -23, -10, 7, -23, Blocks.LIGHT_GRAY_STAINED_GLASS_PANE.getDefaultState().with(FourWayBlock.WATERLOGGED, false).with(FourWayBlock.NORTH, false).with(FourWayBlock.SOUTH, false).with(FourWayBlock.EAST, true).with(FourWayBlock.WEST, true));
        structure.fillWithBlocks(world, start, -10, 7, -32, -9, 8, -32, Blocks.OAK_PLANKS.getDefaultState());
        structure.fillWithBlocks(world, start, -10, 7, 19, -10, 7, 21, Blocks.SPRUCE_SLAB.getDefaultState().with(SlabBlock.TYPE, SlabType.BOTTOM).with(SlabBlock.WATERLOGGED, false));
