package mod.arcalitegames.odyssey.world.structure.town.saxon_snow;

import mod.arcalitegames.buildersaddition.Index;
import mod.arcalitegames.buildersaddition.blocks.BedsideTable;
import mod.arcalitegames.buildersaddition.blocks.Bookshelf;
import mod.arcalitegames.buildersaddition.blocks.Cabinet;
import mod.arcalitegames.buildersaddition.blocks.Candle;
import mod.arcalitegames.buildersaddition.blocks.Counter;
import mod.arcalitegames.buildersaddition.blocks.Cupboard;
import mod.arcalitegames.buildersaddition.blocks.Pillar;
import mod.arcalitegames.buildersaddition.blocks.Shelf;
import mod.arcalitegames.buildersaddition.blocks.Stool;
import mod.arcalitegames.buildersaddition.blocks.Table;
import mod.arcalitegames.buildersaddition.blocks.VerticalSlab;
import mod.arcalitegames.buildersaddition.state.PillarState;
import mod.arcalitegames.buildersaddition.state.StoolState;
import mod.arcalitegames.buildersaddition.state.VerticalSlabState;
import mod.arcalitegames.odyssey.world.structure.StructureBase;
import net.minecraft.block.AbstractFurnaceBlock;
import net.minecraft.block.BarrelBlock;
import net.minecraft.block.BedBlock;
import net.minecraft.block.BeetrootBlock;
import net.minecraft.block.Blocks;
import net.minecraft.block.ChainBlock;
import net.minecraft.block.ComposterBlock;
import net.minecraft.block.CropsBlock;
import net.minecraft.block.DoorBlock;
import net.minecraft.block.FarmlandBlock;
import net.minecraft.block.FenceGateBlock;
import net.minecraft.block.FourWayBlock;
import net.minecraft.block.HorizontalBlock;
import net.minecraft.block.LanternBlock;
import net.minecraft.block.RedstoneTorchBlock;
import net.minecraft.block.SlabBlock;
import net.minecraft.block.SnowBlock;
import net.minecraft.block.SnowyDirtBlock;
import net.minecraft.block.StairsBlock;
import net.minecraft.block.StemBlock;
import net.minecraft.block.TrapDoorBlock;
import net.minecraft.block.VineBlock;
import net.minecraft.block.WallBlock;
import net.minecraft.block.WallHeight;
import net.minecraft.block.WallSignBlock;
import net.minecraft.state.properties.BedPart;
import net.minecraft.state.properties.DoorHingeSide;
import net.minecraft.state.properties.DoubleBlockHalf;
import net.minecraft.state.properties.Half;
import net.minecraft.state.properties.SlabType;
import net.minecraft.state.properties.StairsShape;
import net.minecraft.util.Direction;
import net.minecraft.util.math.BlockPos;
import net.minecraft.world.World;

public class SaxonSnowComponent1
{

	public static BlockPos start;
    public static World world;
    public static StructureBase structure;

    public static void init(World worldIn, BlockPos blockPos, StructureBase structureIn)
    {
        world = worldIn; start = blockPos; structure = structureIn;
    }
    
    public static void generatePart11()
    {
        structure.setBlockState(world, Blocks.DARK_OAK_STAIRS.getDefaultState().with(StairsBlock.FACING, Direction.NORTH).with(StairsBlock.WATERLOGGED, false).with(StairsBlock.SHAPE, StairsShape.STRAIGHT).with(StairsBlock.HALF, Half.BOTTOM), 31, 0, 22, start);
        structure.setBlockState(world, Blocks.OAK_SLAB.getDefaultState().with(SlabBlock.TYPE, SlabType.BOTTOM).with(SlabBlock.WATERLOGGED, false), 31, 0, 34, start);
        structure.setBlockState(world, Blocks.SNOW.getDefaultState().with(SnowBlock.LAYERS, 1), 31, 0, 53, start);
        structure.setBlockState(world, Blocks.DARK_OAK_STAIRS.getDefaultState().with(StairsBlock.FACING, Direction.SOUTH).with(StairsBlock.WATERLOGGED, false).with(StairsBlock.SHAPE, StairsShape.STRAIGHT).with(StairsBlock.HALF, Half.BOTTOM), 31, 1, 7, start);
        structure.setBlockState(world, Blocks.DARK_OAK_STAIRS.getDefaultState().with(StairsBlock.FACING, Direction.NORTH).with(StairsBlock.WATERLOGGED, false).with(StairsBlock.SHAPE, StairsShape.STRAIGHT).with(StairsBlock.HALF, Half.TOP), 31, 1, 8, start);
        structure.setBlockState(world, Blocks.DARK_OAK_STAIRS.getDefaultState().with(StairsBlock.FACING, Direction.SOUTH).with(StairsBlock.WATERLOGGED, false).with(StairsBlock.SHAPE, StairsShape.STRAIGHT).with(StairsBlock.HALF, Half.TOP), 31, 1, 20, start);
        structure.setBlockState(world, Blocks.DARK_OAK_STAIRS.getDefaultState().with(StairsBlock.FACING, Direction.NORTH).with(StairsBlock.WATERLOGGED, false).with(StairsBlock.SHAPE, StairsShape.STRAIGHT).with(StairsBlock.HALF, Half.BOTTOM), 31, 1, 21, start);
        structure.setBlockState(world, Blocks.JUNGLE_FENCE_GATE.getDefaultState().with(FenceGateBlock.IN_WALL, false).with(FenceGateBlock.OPEN, false).with(FenceGateBlock.POWERED, false), 31, 1, 52, start);
        structure.setBlockState(world, Blocks.SPRUCE_SLAB.getDefaultState().with(SlabBlock.TYPE, SlabType.BOTTOM).with(SlabBlock.WATERLOGGED, false), 31, 2, -42, start);
        structure.setBlockState(world, Blocks.DARK_OAK_STAIRS.getDefaultState().with(StairsBlock.FACING, Direction.SOUTH).with(StairsBlock.WATERLOGGED, false).with(StairsBlock.SHAPE, StairsShape.STRAIGHT).with(StairsBlock.HALF, Half.BOTTOM), 31, 2, -11, start);
        structure.setBlockState(world, Blocks.OAK_STAIRS.getDefaultState().with(StairsBlock.FACING, Direction.SOUTH).with(StairsBlock.WATERLOGGED, false).with(StairsBlock.SHAPE, StairsShape.STRAIGHT).with(StairsBlock.HALF, Half.BOTTOM), 31, 2, -10, start);
        structure.setBlockState(world, Blocks.OAK_STAIRS.getDefaultState().with(StairsBlock.FACING, Direction.NORTH).with(StairsBlock.WATERLOGGED, false).with(StairsBlock.SHAPE, StairsShape.STRAIGHT).with(StairsBlock.HALF, Half.BOTTOM), 31, 2, -4, start);
        structure.setBlockState(world, Blocks.DARK_OAK_STAIRS.getDefaultState().with(StairsBlock.FACING, Direction.NORTH).with(StairsBlock.WATERLOGGED, false).with(StairsBlock.SHAPE, StairsShape.STRAIGHT).with(StairsBlock.HALF, Half.BOTTOM), 31, 2, -3, start);
        structure.setBlockState(world, Blocks.DARK_OAK_STAIRS.getDefaultState().with(StairsBlock.FACING, Direction.SOUTH).with(StairsBlock.WATERLOGGED, false).with(StairsBlock.SHAPE, StairsShape.STRAIGHT).with(StairsBlock.HALF, Half.BOTTOM), 31, 2, 8, start);
        structure.setBlockState(world, Blocks.DARK_OAK_STAIRS.getDefaultState().with(StairsBlock.FACING, Direction.NORTH).with(StairsBlock.WATERLOGGED, false).with(StairsBlock.SHAPE, StairsShape.STRAIGHT).with(StairsBlock.HALF, Half.BOTTOM), 31, 2, 20, start);
        structure.setBlockState(world, Blocks.SPRUCE_TRAPDOOR.getDefaultState().with(HorizontalBlock.HORIZONTAL_FACING, Direction.SOUTH).with(TrapDoorBlock.HALF, Half.BOTTOM).with(TrapDoorBlock.WATERLOGGED, false).with(TrapDoorBlock.POWERED, false).with(TrapDoorBlock.OPEN, false), 31, 2, 43, start);
        structure.setBlockState(world, Blocks.SPRUCE_SLAB.getDefaultState().with(SlabBlock.TYPE, SlabType.BOTTOM).with(SlabBlock.WATERLOGGED, false), 31, 3, -49, start);
        structure.setBlockState(world, Blocks.SPRUCE_SLAB.getDefaultState().with(SlabBlock.TYPE, SlabType.BOTTOM).with(SlabBlock.WATERLOGGED, false), 31, 3, -44, start);
        structure.setBlockState(world, Blocks.DARK_OAK_STAIRS.getDefaultState().with(StairsBlock.FACING, Direction.SOUTH).with(StairsBlock.WATERLOGGED, false).with(StairsBlock.SHAPE, StairsShape.STRAIGHT).with(StairsBlock.HALF, Half.BOTTOM), 31, 3, -10, start);
        structure.setBlockState(world, Blocks.OAK_STAIRS.getDefaultState().with(StairsBlock.FACING, Direction.SOUTH).with(StairsBlock.WATERLOGGED, false).with(StairsBlock.SHAPE, StairsShape.STRAIGHT).with(StairsBlock.HALF, Half.BOTTOM), 31, 3, -9, start);
        structure.setBlockState(world, Blocks.DARK_OAK_SLAB.getDefaultState().with(SlabBlock.TYPE, SlabType.TOP).with(SlabBlock.WATERLOGGED, false), 31, 3, -8, start);
        structure.setBlockState(world, Blocks.DARK_OAK_SLAB.getDefaultState().with(SlabBlock.TYPE, SlabType.TOP).with(SlabBlock.WATERLOGGED, false), 31, 3, -6, start);
        structure.setBlockState(world, Blocks.OAK_STAIRS.getDefaultState().with(StairsBlock.FACING, Direction.NORTH).with(StairsBlock.WATERLOGGED, false).with(StairsBlock.SHAPE, StairsShape.STRAIGHT).with(StairsBlock.HALF, Half.BOTTOM), 31, 3, -5, start);
        structure.setBlockState(world, Blocks.DARK_OAK_STAIRS.getDefaultState().with(StairsBlock.FACING, Direction.NORTH).with(StairsBlock.WATERLOGGED, false).with(StairsBlock.SHAPE, StairsShape.STRAIGHT).with(StairsBlock.HALF, Half.BOTTOM), 31, 3, -4, start);
        structure.setBlockState(world, Blocks.SPRUCE_TRAPDOOR.getDefaultState().with(HorizontalBlock.HORIZONTAL_FACING, Direction.SOUTH).with(TrapDoorBlock.HALF, Half.BOTTOM).with(TrapDoorBlock.WATERLOGGED, false).with(TrapDoorBlock.POWERED, false).with(TrapDoorBlock.OPEN, false), 31, 3, 46, start);
        structure.setBlockState(world, Blocks.OAK_LOG.getDefaultState(), 31, 3, 50, start);
        structure.setBlockState(world, Blocks.SPRUCE_SLAB.getDefaultState().with(SlabBlock.TYPE, SlabType.BOTTOM).with(SlabBlock.WATERLOGGED, false), 31, 3, 51, start);
        structure.setBlockState(world, Blocks.SPRUCE_TRAPDOOR.getDefaultState().with(HorizontalBlock.HORIZONTAL_FACING, Direction.SOUTH).with(TrapDoorBlock.HALF, Half.BOTTOM).with(TrapDoorBlock.WATERLOGGED, false).with(TrapDoorBlock.POWERED, false).with(TrapDoorBlock.OPEN, false), 31, 4, -48, start);
        structure.setBlockState(world, Blocks.DARK_OAK_STAIRS.getDefaultState().with(StairsBlock.FACING, Direction.SOUTH).with(StairsBlock.WATERLOGGED, false).with(StairsBlock.SHAPE, StairsShape.STRAIGHT).with(StairsBlock.HALF, Half.BOTTOM), 31, 4, -9, start);
        structure.setBlockState(world, Blocks.OAK_STAIRS.getDefaultState().with(StairsBlock.FACING, Direction.SOUTH).with(StairsBlock.WATERLOGGED, false).with(StairsBlock.SHAPE, StairsShape.STRAIGHT).with(StairsBlock.HALF, Half.BOTTOM), 31, 4, -8, start);
        structure.setBlockState(world, Blocks.DARK_OAK_SLAB.getDefaultState().with(SlabBlock.TYPE, SlabType.TOP).with(SlabBlock.WATERLOGGED, false), 31, 4, -7, start);
        structure.setBlockState(world, Blocks.OAK_STAIRS.getDefaultState().with(StairsBlock.FACING, Direction.NORTH).with(StairsBlock.WATERLOGGED, false).with(StairsBlock.SHAPE, StairsShape.STRAIGHT).with(StairsBlock.HALF, Half.BOTTOM), 31, 4, -6, start);
        structure.setBlockState(world, Blocks.DARK_OAK_STAIRS.getDefaultState().with(StairsBlock.FACING, Direction.NORTH).with(StairsBlock.WATERLOGGED, false).with(StairsBlock.SHAPE, StairsShape.STRAIGHT).with(StairsBlock.HALF, Half.BOTTOM), 31, 4, -5, start);
        structure.setBlockState(world, Blocks.DARK_OAK_SLAB.getDefaultState().with(SlabBlock.TYPE, SlabType.TOP).with(SlabBlock.WATERLOGGED, false), 31, 4, 14, start);
        structure.setBlockState(world, Blocks.SPRUCE_TRAPDOOR.getDefaultState().with(HorizontalBlock.HORIZONTAL_FACING, Direction.NORTH).with(TrapDoorBlock.HALF, Half.BOTTOM).with(TrapDoorBlock.WATERLOGGED, false).with(TrapDoorBlock.POWERED, false).with(TrapDoorBlock.OPEN, false), 31, 4, 50, start);
        structure.setBlockState(world, Blocks.DARK_OAK_STAIRS.getDefaultState().with(StairsBlock.FACING, Direction.SOUTH).with(StairsBlock.WATERLOGGED, false).with(StairsBlock.SHAPE, StairsShape.STRAIGHT).with(StairsBlock.HALF, Half.BOTTOM), 31, 5, -8, start);
        structure.setBlockState(world, Blocks.OAK_SLAB.getDefaultState().with(SlabBlock.TYPE, SlabType.BOTTOM).with(SlabBlock.WATERLOGGED, false), 31, 5, -7, start);
        structure.setBlockState(world, Blocks.DARK_OAK_STAIRS.getDefaultState().with(StairsBlock.FACING, Direction.NORTH).with(StairsBlock.WATERLOGGED, false).with(StairsBlock.SHAPE, StairsShape.STRAIGHT).with(StairsBlock.HALF, Half.BOTTOM), 31, 5, -6, start);
        structure.setBlockState(world, Blocks.DARK_OAK_STAIRS.getDefaultState().with(StairsBlock.FACING, Direction.SOUTH).with(StairsBlock.WATERLOGGED, false).with(StairsBlock.SHAPE, StairsShape.STRAIGHT).with(StairsBlock.HALF, Half.TOP), 31, 6, -8, start);
        structure.setBlockState(world, Blocks.DARK_OAK_SLAB.getDefaultState().with(SlabBlock.TYPE, SlabType.BOTTOM).with(SlabBlock.WATERLOGGED, false), 31, 6, -7, start);
        structure.setBlockState(world, Blocks.DARK_OAK_STAIRS.getDefaultState().with(StairsBlock.FACING, Direction.NORTH).with(StairsBlock.WATERLOGGED, false).with(StairsBlock.SHAPE, StairsShape.STRAIGHT).with(StairsBlock.HALF, Half.TOP), 31, 6, -6, start);
        structure.setBlockState(world, Blocks.OAK_STAIRS.getDefaultState().with(StairsBlock.FACING, Direction.SOUTH).with(StairsBlock.WATERLOGGED, false).with(StairsBlock.SHAPE, StairsShape.OUTER_RIGHT).with(StairsBlock.HALF, Half.BOTTOM), 31, 6, 9, start);
        structure.setBlockState(world, Blocks.OAK_PLANKS.getDefaultState(), 31, 6, 13, start);
        structure.setBlockState(world, Blocks.OAK_PLANKS.getDefaultState(), 31, 6, 15, start);
        structure.setBlockState(world, Blocks.OAK_STAIRS.getDefaultState().with(StairsBlock.FACING, Direction.NORTH).with(StairsBlock.WATERLOGGED, false).with(StairsBlock.SHAPE, StairsShape.OUTER_LEFT).with(StairsBlock.HALF, Half.BOTTOM), 31, 6, 19, start);
        structure.setBlockState(world, Blocks.SNOW.getDefaultState().with(SnowBlock.LAYERS, 1), 31, 7, -8, start);
        structure.setBlockState(world, Blocks.SNOW.getDefaultState().with(SnowBlock.LAYERS, 1), 31, 7, -6, start);
        structure.setBlockState(world, Blocks.SNOW.getDefaultState().with(SnowBlock.LAYERS, 1), 31, 7, 13, start);
        structure.setBlockState(world, Blocks.SNOW.getDefaultState().with(SnowBlock.LAYERS, 1), 31, 7, 15, start);
        structure.setBlockState(world, Blocks.DARK_OAK_STAIRS.getDefaultState().with(StairsBlock.FACING, Direction.WEST).with(StairsBlock.WATERLOGGED, false).with(StairsBlock.SHAPE, StairsShape.STRAIGHT).with(StairsBlock.HALF, Half.TOP), 31, 13, 14, start);
        structure.setBlockState(world, Blocks.SNOW.getDefaultState().with(SnowBlock.LAYERS, 1), 31, 14, 14, start);
        structure.setBlockState(world, Blocks.COAL_ORE.getDefaultState(), 32, -7, 49, start);
        structure.setBlockState(world, Blocks.STONE.getDefaultState(), 32, -6, 44, start);
        structure.setBlockState(world, Blocks.ICE.getDefaultState(), 32, -1, -37, start);
        structure.setBlockState(world, Blocks.GRASS_BLOCK.getDefaultState().with(SnowyDirtBlock.SNOWY, false), 32, -1, -35, start);
        structure.setBlockState(world, Blocks.COBBLESTONE.getDefaultState(), 32, -1, -9, start);
        structure.setBlockState(world, Blocks.BEETROOTS.getDefaultState().with(BeetrootBlock.BEETROOT_AGE, 3), 32, 0, -38, start);
        structure.setBlockState(world, Blocks.CARROTS.getDefaultState().with(CropsBlock.AGE, 7), 32, 0, -36, start);
        structure.setBlockState(world, Blocks.COBBLESTONE_WALL.getDefaultState().with(WallBlock.WATERLOGGED, false).with(WallBlock.UP, true).with(WallBlock.WALL_HEIGHT_NORTH, WallHeight.LOW).with(WallBlock.WALL_HEIGHT_SOUTH, WallHeight.LOW).with(WallBlock.WALL_HEIGHT_EAST, WallHeight.LOW).with(WallBlock.WALL_HEIGHT_WEST, WallHeight.LOW), 32, 0, -34, start);
        structure.setBlockState(world, Blocks.DARK_OAK_STAIRS.getDefaultState().with(StairsBlock.FACING, Direction.WEST).with(StairsBlock.WATERLOGGED, false).with(StairsBlock.SHAPE, StairsShape.STRAIGHT).with(StairsBlock.HALF, Half.TOP), 32, 0, -32, start);
        structure.setBlockState(world, Blocks.DARK_OAK_STAIRS.getDefaultState().with(StairsBlock.FACING, Direction.WEST).with(StairsBlock.WATERLOGGED, false).with(StairsBlock.SHAPE, StairsShape.STRAIGHT).with(StairsBlock.HALF, Half.TOP), 32, 0, -28, start);
        structure.setBlockState(world, Blocks.AIR.getDefaultState(), 32, 0, -26, start);
        structure.setBlockState(world, Blocks.DARK_OAK_STAIRS.getDefaultState().with(StairsBlock.FACING, Direction.WEST).with(StairsBlock.WATERLOGGED, false).with(StairsBlock.SHAPE, StairsShape.STRAIGHT).with(StairsBlock.HALF, Half.TOP), 32, 0, -24, start);
        structure.setBlockState(world, Blocks.DARK_OAK_STAIRS.getDefaultState().with(StairsBlock.FACING, Direction.WEST).with(StairsBlock.WATERLOGGED, false).with(StairsBlock.SHAPE, StairsShape.STRAIGHT).with(StairsBlock.HALF, Half.TOP), 32, 0, -20, start);
        structure.setBlockState(world, Blocks.SNOW.getDefaultState().with(SnowBlock.LAYERS, 1), 32, 0, -17, start);
        structure.setBlockState(world, Blocks.SNOW.getDefaultState().with(SnowBlock.LAYERS, 1), 32, 0, 34, start);
        structure.setBlockState(world, Blocks.JUNGLE_FENCE_GATE.getDefaultState().with(FenceGateBlock.IN_WALL, false).with(FenceGateBlock.OPEN, false).with(FenceGateBlock.POWERED, false), 32, 0, 52, start);
        structure.setBlockState(world, Blocks.DARK_OAK_STAIRS.getDefaultState().with(StairsBlock.FACING, Direction.EAST).with(StairsBlock.WATERLOGGED, false).with(StairsBlock.SHAPE, StairsShape.STRAIGHT).with(StairsBlock.HALF, Half.BOTTOM), 32, 1, -32, start);
        structure.setBlockState(world, Blocks.DARK_OAK_STAIRS.getDefaultState().with(StairsBlock.FACING, Direction.EAST).with(StairsBlock.WATERLOGGED, false).with(StairsBlock.SHAPE, StairsShape.STRAIGHT).with(StairsBlock.HALF, Half.BOTTOM), 32, 1, -28, start);
        structure.setBlockState(world, Blocks.DARK_OAK_STAIRS.getDefaultState().with(StairsBlock.FACING, Direction.EAST).with(StairsBlock.WATERLOGGED, false).with(StairsBlock.SHAPE, StairsShape.STRAIGHT).with(StairsBlock.HALF, Half.BOTTOM), 32, 1, -24, start);
        structure.setBlockState(world, Blocks.DARK_OAK_STAIRS.getDefaultState().with(StairsBlock.FACING, Direction.EAST).with(StairsBlock.WATERLOGGED, false).with(StairsBlock.SHAPE, StairsShape.STRAIGHT).with(StairsBlock.HALF, Half.BOTTOM), 32, 1, -20, start);
        structure.setBlockState(world, Blocks.DARK_OAK_STAIRS.getDefaultState().with(StairsBlock.FACING, Direction.EAST).with(StairsBlock.WATERLOGGED, false).with(StairsBlock.SHAPE, StairsShape.STRAIGHT).with(StairsBlock.HALF, Half.TOP), 32, 1, 9, start);
        structure.setBlockState(world, Blocks.DARK_OAK_STAIRS.getDefaultState().with(StairsBlock.FACING, Direction.EAST).with(StairsBlock.WATERLOGGED, false).with(StairsBlock.SHAPE, StairsShape.STRAIGHT).with(StairsBlock.HALF, Half.TOP), 32, 1, 12, start);
        structure.setBlockState(world, Blocks.DARK_OAK_STAIRS.getDefaultState().with(StairsBlock.FACING, Direction.EAST).with(StairsBlock.WATERLOGGED, false).with(StairsBlock.SHAPE, StairsShape.STRAIGHT).with(StairsBlock.HALF, Half.TOP), 32, 1, 16, start);
        structure.setBlockState(world, Blocks.DARK_OAK_STAIRS.getDefaultState().with(StairsBlock.FACING, Direction.EAST).with(StairsBlock.WATERLOGGED, false).with(StairsBlock.SHAPE, StairsShape.STRAIGHT).with(StairsBlock.HALF, Half.TOP), 32, 1, 19, start);
        structure.setBlockState(world, Blocks.SNOW.getDefaultState().with(SnowBlock.LAYERS, 1), 32, 1, 51, start);
        structure.setBlockState(world, Blocks.SPRUCE_TRAPDOOR.getDefaultState().with(HorizontalBlock.HORIZONTAL_FACING, Direction.NORTH).with(TrapDoorBlock.HALF, Half.BOTTOM).with(TrapDoorBlock.WATERLOGGED, false).with(TrapDoorBlock.POWERED, false).with(TrapDoorBlock.OPEN, false), 32, 2, -42, start);
        structure.setBlockState(world, Blocks.DARK_OAK_STAIRS.getDefaultState().with(StairsBlock.FACING, Direction.EAST).with(StairsBlock.WATERLOGGED, false).with(StairsBlock.SHAPE, StairsShape.STRAIGHT).with(StairsBlock.HALF, Half.BOTTOM), 32, 2, -33, start);
        structure.setBlockState(world, Blocks.OAK_STAIRS.getDefaultState().with(StairsBlock.FACING, Direction.NORTH).with(StairsBlock.WATERLOGGED, false).with(StairsBlock.SHAPE, StairsShape.STRAIGHT).with(StairsBlock.HALF, Half.TOP), 32, 2, -27, start);
        structure.setBlockState(world, Blocks.OAK_STAIRS.getDefaultState().with(StairsBlock.FACING, Direction.SOUTH).with(StairsBlock.WATERLOGGED, false).with(StairsBlock.SHAPE, StairsShape.STRAIGHT).with(StairsBlock.HALF, Half.TOP), 32, 2, -25, start);
        structure.setBlockState(world, Blocks.DARK_OAK_STAIRS.getDefaultState().with(StairsBlock.FACING, Direction.EAST).with(StairsBlock.WATERLOGGED, false).with(StairsBlock.SHAPE, StairsShape.STRAIGHT).with(StairsBlock.HALF, Half.BOTTOM), 32, 2, -19, start);
        structure.setBlockState(world, Blocks.OAK_STAIRS.getDefaultState().with(StairsBlock.FACING, Direction.EAST).with(StairsBlock.WATERLOGGED, false).with(StairsBlock.SHAPE, StairsShape.INNER_RIGHT).with(StairsBlock.HALF, Half.BOTTOM), 32, 2, -10, start);
        structure.setBlockState(world, Blocks.DARK_OAK_STAIRS.getDefaultState().with(StairsBlock.FACING, Direction.WEST).with(StairsBlock.WATERLOGGED, false).with(StairsBlock.SHAPE, StairsShape.STRAIGHT).with(StairsBlock.HALF, Half.BOTTOM), 32, 2, 9, start);
        structure.setBlockState(world, Blocks.DARK_OAK_STAIRS.getDefaultState().with(StairsBlock.FACING, Direction.WEST).with(StairsBlock.WATERLOGGED, false).with(StairsBlock.SHAPE, StairsShape.STRAIGHT).with(StairsBlock.HALF, Half.BOTTOM), 32, 2, 12, start);
        structure.setBlockState(world, Blocks.DARK_OAK_STAIRS.getDefaultState().with(StairsBlock.FACING, Direction.WEST).with(StairsBlock.WATERLOGGED, false).with(StairsBlock.SHAPE, StairsShape.STRAIGHT).with(StairsBlock.HALF, Half.BOTTOM), 32, 2, 16, start);
        structure.setBlockState(world, Blocks.DARK_OAK_STAIRS.getDefaultState().with(StairsBlock.FACING, Direction.WEST).with(StairsBlock.WATERLOGGED, false).with(StairsBlock.SHAPE, StairsShape.STRAIGHT).with(StairsBlock.HALF, Half.BOTTOM), 32, 2, 19, start);
        structure.setBlockState(world, Blocks.SPRUCE_SLAB.getDefaultState().with(SlabBlock.TYPE, SlabType.BOTTOM).with(SlabBlock.WATERLOGGED, false), 32, 2, 43, start);
        structure.setBlockState(world, Blocks.SPRUCE_LOG.getDefaultState(), 32, 2, 45, start);
        structure.setBlockState(world, Blocks.SPRUCE_TRAPDOOR.getDefaultState().with(HorizontalBlock.HORIZONTAL_FACING, Direction.SOUTH).with(TrapDoorBlock.HALF, Half.BOTTOM).with(TrapDoorBlock.WATERLOGGED, false).with(TrapDoorBlock.POWERED, false).with(TrapDoorBlock.OPEN, false), 32, 3, -49, start);
        structure.setBlockState(world, Blocks.SPRUCE_LOG.getDefaultState(), 32, 3, -48, start);
        structure.setBlockState(world, Blocks.SPRUCE_TRAPDOOR.getDefaultState().with(HorizontalBlock.HORIZONTAL_FACING, Direction.NORTH).with(TrapDoorBlock.HALF, Half.BOTTOM).with(TrapDoorBlock.WATERLOGGED, false).with(TrapDoorBlock.POWERED, false).with(TrapDoorBlock.OPEN, false), 32, 3, -44, start);
        structure.setBlockState(world, Blocks.SNOW.getDefaultState().with(SnowBlock.LAYERS, 1), 32, 3, -32, start);
        structure.setBlockState(world, Blocks.OAK_STAIRS.getDefaultState().with(StairsBlock.FACING, Direction.EAST).with(StairsBlock.WATERLOGGED, false).with(StairsBlock.SHAPE, StairsShape.STRAIGHT).with(StairsBlock.HALF, Half.BOTTOM), 32, 3, -31, start);
        structure.setBlockState(world, Blocks.OAK_STAIRS.getDefaultState().with(StairsBlock.FACING, Direction.SOUTH).with(StairsBlock.WATERLOGGED, false).with(StairsBlock.SHAPE, StairsShape.STRAIGHT).with(StairsBlock.HALF, Half.BOTTOM), 32, 3, -30, start);
        structure.setBlockState(world, Blocks.OAK_STAIRS.getDefaultState().with(StairsBlock.FACING, Direction.NORTH).with(StairsBlock.WATERLOGGED, false).with(StairsBlock.SHAPE, StairsShape.STRAIGHT).with(StairsBlock.HALF, Half.BOTTOM), 32, 3, -22, start);
        structure.setBlockState(world, Blocks.OAK_STAIRS.getDefaultState().with(StairsBlock.FACING, Direction.EAST).with(StairsBlock.WATERLOGGED, false).with(StairsBlock.SHAPE, StairsShape.STRAIGHT).with(StairsBlock.HALF, Half.BOTTOM), 32, 3, -21, start);
        structure.setBlockState(world, Blocks.SNOW.getDefaultState().with(SnowBlock.LAYERS, 1), 32, 3, -20, start);
        structure.setBlockState(world, Blocks.OAK_STAIRS.getDefaultState().with(StairsBlock.FACING, Direction.EAST).with(StairsBlock.WATERLOGGED, false).with(StairsBlock.SHAPE, StairsShape.INNER_RIGHT).with(StairsBlock.HALF, Half.BOTTOM), 32, 3, -9, start);
        structure.setBlockState(world, Blocks.DARK_OAK_SLAB.getDefaultState().with(SlabBlock.TYPE, SlabType.DOUBLE).with(SlabBlock.WATERLOGGED, false), 32, 3, -8, start);
        structure.setBlockState(world, Blocks.DARK_OAK_SLAB.getDefaultState().with(SlabBlock.TYPE, SlabType.DOUBLE).with(SlabBlock.WATERLOGGED, false), 32, 3, -6, start);
        structure.setBlockState(world, Blocks.OAK_STAIRS.getDefaultState().with(StairsBlock.FACING, Direction.EAST).with(StairsBlock.WATERLOGGED, false).with(StairsBlock.SHAPE, StairsShape.INNER_LEFT).with(StairsBlock.HALF, Half.BOTTOM), 32, 3, -5, start);
        structure.setBlockState(world, Blocks.OAK_STAIRS.getDefaultState().with(StairsBlock.FACING, Direction.EAST).with(StairsBlock.WATERLOGGED, false).with(StairsBlock.SHAPE, StairsShape.OUTER_LEFT).with(StairsBlock.HALF, Half.BOTTOM), 32, 3, -4, start);
        structure.setBlockState(world, Blocks.SPRUCE_SLAB.getDefaultState().with(SlabBlock.TYPE, SlabType.BOTTOM).with(SlabBlock.WATERLOGGED, false), 32, 3, 45, start);
        structure.setBlockState(world, Blocks.SPRUCE_TRAPDOOR.getDefaultState().with(HorizontalBlock.HORIZONTAL_FACING, Direction.NORTH).with(TrapDoorBlock.HALF, Half.BOTTOM).with(TrapDoorBlock.WATERLOGGED, false).with(TrapDoorBlock.POWERED, false).with(TrapDoorBlock.OPEN, false), 32, 3, 50, start);
        structure.setBlockState(world, Blocks.SPRUCE_SLAB.getDefaultState().with(SlabBlock.TYPE, SlabType.BOTTOM).with(SlabBlock.WATERLOGGED, false), 32, 4, -48, start);
        structure.setBlockState(world, Blocks.OAK_STAIRS.getDefaultState().with(StairsBlock.FACING, Direction.EAST).with(StairsBlock.WATERLOGGED, false).with(StairsBlock.SHAPE, StairsShape.INNER_RIGHT).with(StairsBlock.HALF, Half.BOTTOM), 32, 4, -8, start);
        structure.setBlockState(world, Blocks.DARK_OAK_SLAB.getDefaultState().with(SlabBlock.TYPE, SlabType.DOUBLE).with(SlabBlock.WATERLOGGED, false), 32, 4, -7, start);
        structure.setBlockState(world, Blocks.OAK_STAIRS.getDefaultState().with(StairsBlock.FACING, Direction.EAST).with(StairsBlock.WATERLOGGED, false).with(StairsBlock.SHAPE, StairsShape.INNER_LEFT).with(StairsBlock.HALF, Half.BOTTOM), 32, 4, -6, start);
        structure.setBlockState(world, Blocks.OAK_PLANKS.getDefaultState(), 32, 4, 12, start);
        structure.setBlockState(world, Blocks.OAK_STAIRS.getDefaultState().with(StairsBlock.FACING, Direction.WEST).with(StairsBlock.WATERLOGGED, false).with(StairsBlock.SHAPE, StairsShape.INNER_RIGHT).with(StairsBlock.HALF, Half.TOP), 32, 4, 13, start);
        structure.setBlockState(world, Blocks.OAK_STAIRS.getDefaultState().with(StairsBlock.FACING, Direction.WEST).with(StairsBlock.WATERLOGGED, false).with(StairsBlock.SHAPE, StairsShape.INNER_LEFT).with(StairsBlock.HALF, Half.TOP), 32, 4, 15, start);
        structure.setBlockState(world, Blocks.OAK_PLANKS.getDefaultState(), 32, 4, 16, start);
        structure.setBlockState(world, Blocks.OAK_STAIRS.getDefaultState().with(StairsBlock.FACING, Direction.WEST).with(StairsBlock.WATERLOGGED, false).with(StairsBlock.SHAPE, StairsShape.OUTER_RIGHT).with(StairsBlock.HALF, Half.BOTTOM), 32, 4, 20, start);
        structure.setBlockState(world, Blocks.SPRUCE_SLAB.getDefaultState().with(SlabBlock.TYPE, SlabType.BOTTOM).with(SlabBlock.WATERLOGGED, false), 32, 4, 49, start);
        structure.setBlockState(world, Blocks.OAK_STAIRS.getDefaultState().with(StairsBlock.FACING, Direction.WEST).with(StairsBlock.WATERLOGGED, false).with(StairsBlock.SHAPE, StairsShape.STRAIGHT).with(StairsBlock.HALF, Half.BOTTOM), 32, 5, -7, start);
        structure.setBlockState(world, Blocks.SNOW.getDefaultState().with(SnowBlock.LAYERS, 1), 32, 5, 12, start);
        structure.setBlockState(world, Blocks.DARK_OAK_SLAB.getDefaultState().with(SlabBlock.TYPE, SlabType.TOP).with(SlabBlock.WATERLOGGED, false), 32, 5, 14, start);
        structure.setBlockState(world, Blocks.SNOW.getDefaultState().with(SnowBlock.LAYERS, 1), 32, 5, 16, start);
        structure.setBlockState(world, Blocks.STONE.getDefaultState(), 33, -7, -30, start);
        structure.setBlockState(world, Blocks.STONE.getDefaultState(), 33, -7, 0, start);
        structure.setBlockState(world, Blocks.GRANITE.getDefaultState(), 33, -7, 22, start);
        structure.setBlockState(world, Blocks.STONE.getDefaultState(), 33, -6, 1, start);
        structure.setBlockState(world, Blocks.COAL_ORE.getDefaultState(), 33, -6, 4, start);
        structure.setBlockState(world, Blocks.ICE.getDefaultState(), 33, -3, 55, start);
        structure.setBlockState(world, Blocks.FARMLAND.getDefaultState().with(FarmlandBlock.MOISTURE, 0), 33, -1, -35, start);
        structure.setBlockState(world, Blocks.MELON.getDefaultState(), 33, 0, -36, start);
        structure.setBlockState(world, Blocks.ATTACHED_MELON_STEM.getDefaultState(), 33, 0, -35, start);
        structure.setBlockState(world, Blocks.DARK_OAK_DOOR.getDefaultState().with(DoorBlock.FACING, Direction.EAST).with(DoorBlock.HALF, DoubleBlockHalf.LOWER).with(DoorBlock.HINGE, DoorHingeSide.RIGHT).with(DoorBlock.OPEN, false).with(DoorBlock.POWERED, false), 33, 0, -26, start);
        structure.setBlockState(world, Blocks.COBBLESTONE_WALL.getDefaultState().with(WallBlock.WATERLOGGED, false).with(WallBlock.UP, true).with(WallBlock.WALL_HEIGHT_NORTH, WallHeight.LOW).with(WallBlock.WALL_HEIGHT_SOUTH, WallHeight.LOW).with(WallBlock.WALL_HEIGHT_EAST, WallHeight.LOW).with(WallBlock.WALL_HEIGHT_WEST, WallHeight.LOW), 33, 0, -18, start);
        structure.setBlockState(world, Blocks.DARK_OAK_STAIRS.getDefaultState().with(StairsBlock.FACING, Direction.EAST).with(StairsBlock.WATERLOGGED, false).with(StairsBlock.SHAPE, StairsShape.STRAIGHT).with(StairsBlock.HALF, Half.TOP), 33, 0, 9, start);
        structure.setBlockState(world, Blocks.DARK_OAK_STAIRS.getDefaultState().with(StairsBlock.FACING, Direction.EAST).with(StairsBlock.WATERLOGGED, false).with(StairsBlock.SHAPE, StairsShape.STRAIGHT).with(StairsBlock.HALF, Half.TOP), 33, 0, 12, start);
        structure.setBlockState(world, Blocks.DARK_OAK_STAIRS.getDefaultState().with(StairsBlock.FACING, Direction.EAST).with(StairsBlock.WATERLOGGED, false).with(StairsBlock.SHAPE, StairsShape.STRAIGHT).with(StairsBlock.HALF, Half.TOP), 33, 0, 16, start);
        structure.setBlockState(world, Blocks.DARK_OAK_STAIRS.getDefaultState().with(StairsBlock.FACING, Direction.EAST).with(StairsBlock.WATERLOGGED, false).with(StairsBlock.SHAPE, StairsShape.STRAIGHT).with(StairsBlock.HALF, Half.TOP), 33, 0, 19, start);
        structure.setBlockState(world, Blocks.OAK_FENCE.getDefaultState().with(FourWayBlock.WATERLOGGED, false).with(FourWayBlock.NORTH, false).with(FourWayBlock.SOUTH, false).with(FourWayBlock.EAST, false).with(FourWayBlock.WEST, true), 33, 0, 35, start);
        structure.setBlockState(world, Blocks.SNOW.getDefaultState().with(SnowBlock.LAYERS, 1), 33, 0, 52, start);
        structure.setBlockState(world, Blocks.SNOW.getDefaultState().with(SnowBlock.LAYERS, 1), 33, 1, -36, start);
        structure.setBlockState(world, Blocks.DARK_OAK_DOOR.getDefaultState().with(DoorBlock.FACING, Direction.EAST).with(DoorBlock.HALF, DoubleBlockHalf.UPPER).with(DoorBlock.HINGE, DoorHingeSide.RIGHT).with(DoorBlock.OPEN, false).with(DoorBlock.POWERED, false), 33, 1, -26, start);
        structure.setBlockState(world, Blocks.DARK_OAK_STAIRS.getDefaultState().with(StairsBlock.FACING, Direction.WEST).with(StairsBlock.WATERLOGGED, false).with(StairsBlock.SHAPE, StairsShape.STRAIGHT).with(StairsBlock.HALF, Half.BOTTOM), 33, 1, 9, start);
        structure.setBlockState(world, Blocks.DARK_OAK_STAIRS.getDefaultState().with(StairsBlock.FACING, Direction.WEST).with(StairsBlock.WATERLOGGED, false).with(StairsBlock.SHAPE, StairsShape.STRAIGHT).with(StairsBlock.HALF, Half.BOTTOM), 33, 1, 12, start);
        structure.setBlockState(world, Blocks.DARK_OAK_STAIRS.getDefaultState().with(StairsBlock.FACING, Direction.WEST).with(StairsBlock.WATERLOGGED, false).with(StairsBlock.SHAPE, StairsShape.STRAIGHT).with(StairsBlock.HALF, Half.BOTTOM), 33, 1, 16, start);
        structure.setBlockState(world, Blocks.DARK_OAK_STAIRS.getDefaultState().with(StairsBlock.FACING, Direction.WEST).with(StairsBlock.WATERLOGGED, false).with(StairsBlock.SHAPE, StairsShape.STRAIGHT).with(StairsBlock.HALF, Half.BOTTOM), 33, 1, 19, start);
        structure.setBlockState(world, Blocks.JUNGLE_FENCE_GATE.getDefaultState().with(FenceGateBlock.IN_WALL, false).with(FenceGateBlock.OPEN, false).with(FenceGateBlock.POWERED, false), 33, 1, 51, start);
        structure.setBlockState(world, Blocks.SPRUCE_SLAB.getDefaultState().with(SlabBlock.TYPE, SlabType.BOTTOM).with(SlabBlock.WATERLOGGED, false), 33, 2, -42, start);
        structure.setBlockState(world, Blocks.DARK_OAK_STAIRS.getDefaultState().with(StairsBlock.FACING, Direction.WEST).with(StairsBlock.WATERLOGGED, false).with(StairsBlock.SHAPE, StairsShape.STRAIGHT).with(StairsBlock.HALF, Half.TOP), 33, 2, -33, start);
        structure.setBlockState(world, Blocks.DARK_OAK_STAIRS.getDefaultState().with(StairsBlock.FACING, Direction.WEST).with(StairsBlock.WATERLOGGED, false).with(StairsBlock.SHAPE, StairsShape.STRAIGHT).with(StairsBlock.HALF, Half.TOP), 33, 2, -19, start);
        structure.setBlockState(world, Blocks.OAK_PLANKS.getDefaultState(), 33, 2, -10, start);
        structure.setBlockState(world, Blocks.DARK_OAK_STAIRS.getDefaultState().with(StairsBlock.FACING, Direction.EAST).with(StairsBlock.WATERLOGGED, false).with(StairsBlock.SHAPE, StairsShape.STRAIGHT).with(StairsBlock.HALF, Half.BOTTOM), 33, 2, 26, start);
        structure.setBlockState(world, Blocks.OAK_STAIRS.getDefaultState().with(StairsBlock.FACING, Direction.NORTH).with(StairsBlock.WATERLOGGED, false).with(StairsBlock.SHAPE, StairsShape.STRAIGHT).with(StairsBlock.HALF, Half.TOP), 33, 2, 30, start);
        structure.setBlockState(world, Blocks.OAK_STAIRS.getDefaultState().with(StairsBlock.FACING, Direction.SOUTH).with(StairsBlock.WATERLOGGED, false).with(StairsBlock.SHAPE, StairsShape.STRAIGHT).with(StairsBlock.HALF, Half.TOP), 33, 2, 32, start);
        structure.setBlockState(world, Blocks.DARK_OAK_STAIRS.getDefaultState().with(StairsBlock.FACING, Direction.EAST).with(StairsBlock.WATERLOGGED, false).with(StairsBlock.SHAPE, StairsShape.STRAIGHT).with(StairsBlock.HALF, Half.BOTTOM), 33, 2, 36, start);
        structure.setBlockState(world, Blocks.SPRUCE_TRAPDOOR.getDefaultState().with(HorizontalBlock.HORIZONTAL_FACING, Direction.SOUTH).with(TrapDoorBlock.HALF, Half.BOTTOM).with(TrapDoorBlock.WATERLOGGED, false).with(TrapDoorBlock.POWERED, false).with(TrapDoorBlock.OPEN, false), 33, 2, 43, start);
        structure.setBlockState(world, Blocks.OAK_LOG.getDefaultState(), 33, 2, 45, start);
        structure.setBlockState(world, Blocks.SPRUCE_SLAB.getDefaultState().with(SlabBlock.TYPE, SlabType.BOTTOM).with(SlabBlock.WATERLOGGED, false), 33, 3, -48, start);
        structure.setBlockState(world, Blocks.SPRUCE_SLAB.getDefaultState().with(SlabBlock.TYPE, SlabType.BOTTOM).with(SlabBlock.WATERLOGGED, false), 33, 3, -44, start);
        structure.setBlockState(world, Blocks.DARK_OAK_STAIRS.getDefaultState().with(StairsBlock.FACING, Direction.EAST).with(StairsBlock.WATERLOGGED, false).with(StairsBlock.SHAPE, StairsShape.STRAIGHT).with(StairsBlock.HALF, Half.BOTTOM), 33, 3, -33, start);
        structure.setBlockState(world, Blocks.DARK_OAK_STAIRS.getDefaultState().with(StairsBlock.FACING, Direction.EAST).with(StairsBlock.WATERLOGGED, false).with(StairsBlock.SHAPE, StairsShape.STRAIGHT).with(StairsBlock.HALF, Half.BOTTOM), 33, 3, -19, start);
        structure.setBlockState(world, Blocks.SNOW.getDefaultState().with(SnowBlock.LAYERS, 1), 33, 3, -10, start);
        structure.setBlockState(world, Blocks.OAK_PLANKS.getDefaultState(), 33, 3, -5, start);
        structure.setBlockState(world, Blocks.OAK_STAIRS.getDefaultState().with(StairsBlock.FACING, Direction.NORTH).with(StairsBlock.WATERLOGGED, false).with(StairsBlock.SHAPE, StairsShape.STRAIGHT).with(StairsBlock.HALF, Half.BOTTOM), 33, 3, -4, start);
        structure.setBlockState(world, Blocks.OAK_PLANKS.getDefaultState(), 33, 3, 12, start);
        structure.setBlockState(world, Blocks.OAK_PLANKS.getDefaultState(), 33, 3, 16, start);
        structure.setBlockState(world, Blocks.SNOW.getDefaultState().with(SnowBlock.LAYERS, 1), 33, 3, 27, start);
        structure.setBlockState(world, Blocks.OAK_STAIRS.getDefaultState().with(StairsBlock.FACING, Direction.EAST).with(StairsBlock.WATERLOGGED, false).with(StairsBlock.SHAPE, StairsShape.STRAIGHT).with(StairsBlock.HALF, Half.BOTTOM), 33, 3, 28, start);
        structure.setBlockState(world, Blocks.OAK_STAIRS.getDefaultState().with(StairsBlock.FACING, Direction.SOUTH).with(StairsBlock.WATERLOGGED, false).with(StairsBlock.SHAPE, StairsShape.STRAIGHT).with(StairsBlock.HALF, Half.BOTTOM), 33, 3, 29, start);
        structure.setBlockState(world, Blocks.OAK_STAIRS.getDefaultState().with(StairsBlock.FACING, Direction.NORTH).with(StairsBlock.WATERLOGGED, false).with(StairsBlock.SHAPE, StairsShape.STRAIGHT).with(StairsBlock.HALF, Half.BOTTOM), 33, 3, 33, start);
        structure.setBlockState(world, Blocks.OAK_STAIRS.getDefaultState().with(StairsBlock.FACING, Direction.EAST).with(StairsBlock.WATERLOGGED, false).with(StairsBlock.SHAPE, StairsShape.STRAIGHT).with(StairsBlock.HALF, Half.BOTTOM), 33, 3, 34, start);
        structure.setBlockState(world, Blocks.SNOW.getDefaultState().with(SnowBlock.LAYERS, 1), 33, 3, 35, start);
        structure.setBlockState(world, Blocks.SPRUCE_TRAPDOOR.getDefaultState().with(HorizontalBlock.HORIZONTAL_FACING, Direction.SOUTH).with(TrapDoorBlock.HALF, Half.BOTTOM).with(TrapDoorBlock.WATERLOGGED, false).with(TrapDoorBlock.POWERED, false).with(TrapDoorBlock.OPEN, false), 33, 3, 45, start);
        structure.setBlockState(world, Blocks.OAK_LOG.getDefaultState(), 33, 3, 49, start);
        structure.setBlockState(world, Blocks.SPRUCE_SLAB.getDefaultState().with(SlabBlock.TYPE, SlabType.BOTTOM).with(SlabBlock.WATERLOGGED, false), 33, 3, 50, start);
        structure.setBlockState(world, Blocks.SPRUCE_TRAPDOOR.getDefaultState().with(HorizontalBlock.HORIZONTAL_FACING, Direction.SOUTH).with(TrapDoorBlock.HALF, Half.BOTTOM).with(TrapDoorBlock.WATERLOGGED, false).with(TrapDoorBlock.POWERED, false).with(TrapDoorBlock.OPEN, false), 33, 4, -47, start);
        structure.setBlockState(world, Blocks.SNOW.getDefaultState().with(SnowBlock.LAYERS, 1), 33, 4, -32, start);
        structure.setBlockState(world, Blocks.OAK_STAIRS.getDefaultState().with(StairsBlock.FACING, Direction.EAST).with(StairsBlock.WATERLOGGED, false).with(StairsBlock.SHAPE, StairsShape.STRAIGHT).with(StairsBlock.HALF, Half.BOTTOM), 33, 4, -31, start);
        structure.setBlockState(world, Blocks.OAK_STAIRS.getDefaultState().with(StairsBlock.FACING, Direction.SOUTH).with(StairsBlock.WATERLOGGED, false).with(StairsBlock.SHAPE, StairsShape.STRAIGHT).with(StairsBlock.HALF, Half.BOTTOM), 33, 4, -30, start);
        structure.setBlockState(world, Blocks.OAK_STAIRS.getDefaultState().with(StairsBlock.FACING, Direction.NORTH).with(StairsBlock.WATERLOGGED, false).with(StairsBlock.SHAPE, StairsShape.STRAIGHT).with(StairsBlock.HALF, Half.BOTTOM), 33, 4, -22, start);
        structure.setBlockState(world, Blocks.OAK_STAIRS.getDefaultState().with(StairsBlock.FACING, Direction.EAST).with(StairsBlock.WATERLOGGED, false).with(StairsBlock.SHAPE, StairsShape.STRAIGHT).with(StairsBlock.HALF, Half.BOTTOM), 33, 4, -21, start);
        structure.setBlockState(world, Blocks.SNOW.getDefaultState().with(SnowBlock.LAYERS, 1), 33, 4, -20, start);
        structure.setBlockState(world, Blocks.SNOW.getDefaultState().with(SnowBlock.LAYERS, 1), 33, 4, -9, start);
        structure.setBlockState(world, Blocks.OAK_PLANKS.getDefaultState(), 33, 4, -8, start);
        structure.setBlockState(world, Blocks.OAK_SLAB.getDefaultState().with(SlabBlock.TYPE, SlabType.TOP).with(SlabBlock.WATERLOGGED, false), 33, 4, -7, start);
        structure.setBlockState(world, Blocks.OAK_PLANKS.getDefaultState(), 33, 4, -6, start);
        structure.setBlockState(world, Blocks.SNOW.getDefaultState().with(SnowBlock.LAYERS, 1), 33, 4, -5, start);
        structure.setBlockState(world, Blocks.OAK_STAIRS.getDefaultState().with(StairsBlock.FACING, Direction.SOUTH).with(StairsBlock.WATERLOGGED, false).with(StairsBlock.SHAPE, StairsShape.STRAIGHT).with(StairsBlock.HALF, Half.BOTTOM), 33, 4, 12, start);
        structure.setBlockState(world, Blocks.OAK_STAIRS.getDefaultState().with(StairsBlock.FACING, Direction.NORTH).with(StairsBlock.WATERLOGGED, false).with(StairsBlock.SHAPE, StairsShape.STRAIGHT).with(StairsBlock.HALF, Half.TOP), 33, 4, 13, start);
        structure.setBlockState(world, Blocks.OAK_STAIRS.getDefaultState().with(StairsBlock.FACING, Direction.SOUTH).with(StairsBlock.WATERLOGGED, false).with(StairsBlock.SHAPE, StairsShape.STRAIGHT).with(StairsBlock.HALF, Half.TOP), 33, 4, 15, start);
        structure.setBlockState(world, Blocks.OAK_STAIRS.getDefaultState().with(StairsBlock.FACING, Direction.NORTH).with(StairsBlock.WATERLOGGED, false).with(StairsBlock.SHAPE, StairsShape.STRAIGHT).with(StairsBlock.HALF, Half.BOTTOM), 33, 4, 16, start);
        structure.setBlockState(world, Blocks.SPRUCE_TRAPDOOR.getDefaultState().with(HorizontalBlock.HORIZONTAL_FACING, Direction.NORTH).with(TrapDoorBlock.HALF, Half.BOTTOM).with(TrapDoorBlock.WATERLOGGED, false).with(TrapDoorBlock.POWERED, false).with(TrapDoorBlock.OPEN, false), 33, 4, 49, start);
        structure.setBlockState(world, Blocks.SNOW.getDefaultState().with(SnowBlock.LAYERS, 1), 33, 5, -8, start);
        structure.setBlockState(world, Blocks.SNOW.getDefaultState().with(SnowBlock.LAYERS, 1), 33, 5, -6, start);
        structure.setBlockState(world, Blocks.DARK_OAK_STAIRS.getDefaultState().with(StairsBlock.FACING, Direction.WEST).with(StairsBlock.WATERLOGGED, false).with(StairsBlock.SHAPE, StairsShape.STRAIGHT).with(StairsBlock.HALF, Half.TOP), 33, 6, 14, start);
        structure.setBlockState(world, Blocks.STONE.getDefaultState(), 34, -7, -43, start);
        structure.setBlockState(world, Blocks.STONE.getDefaultState(), 34, -6, -44, start);
        structure.setBlockState(world, Blocks.STONE.getDefaultState(), 34, -6, 51, start);
        structure.setBlockState(world, Blocks.ICE.getDefaultState(), 34, -1, -37, start);
        structure.setBlockState(world, Blocks.DIRT.getDefaultState(), 34, -1, -35, start);
        structure.setBlockState(world, Blocks.DIRT.getDefaultState(), 34, -1, 9, start);
        structure.setBlockState(world, Blocks.DIRT.getDefaultState(), 34, -1, 12, start);
        structure.setBlockState(world, Blocks.DIRT.getDefaultState(), 34, -1, 16, start);
        structure.setBlockState(world, Blocks.DIRT.getDefaultState(), 34, -1, 19, start);
        structure.setBlockState(world, Blocks.COBBLESTONE_WALL.getDefaultState().with(WallBlock.WATERLOGGED, false).with(WallBlock.UP, true).with(WallBlock.WALL_HEIGHT_NORTH, WallHeight.LOW).with(WallBlock.WALL_HEIGHT_SOUTH, WallHeight.LOW).with(WallBlock.WALL_HEIGHT_EAST, WallHeight.LOW).with(WallBlock.WALL_HEIGHT_WEST, WallHeight.LOW), 34, 0, -18, start);
        structure.setBlockState(world, Blocks.COBBLESTONE_WALL.getDefaultState().with(WallBlock.WATERLOGGED, false).with(WallBlock.UP, true).with(WallBlock.WALL_HEIGHT_NORTH, WallHeight.LOW).with(WallBlock.WALL_HEIGHT_SOUTH, WallHeight.LOW).with(WallBlock.WALL_HEIGHT_EAST, WallHeight.LOW).with(WallBlock.WALL_HEIGHT_WEST, WallHeight.LOW), 34, 0, -10, start);
        structure.setBlockState(world, Blocks.DARK_OAK_STAIRS.getDefaultState().with(StairsBlock.FACING, Direction.WEST).with(StairsBlock.WATERLOGGED, false).with(StairsBlock.SHAPE, StairsShape.STRAIGHT).with(StairsBlock.HALF, Half.BOTTOM), 34, 0, 9, start);
        structure.setBlockState(world, Blocks.DARK_OAK_STAIRS.getDefaultState().with(StairsBlock.FACING, Direction.WEST).with(StairsBlock.WATERLOGGED, false).with(StairsBlock.SHAPE, StairsShape.STRAIGHT).with(StairsBlock.HALF, Half.BOTTOM), 34, 0, 12, start);
        structure.setBlockState(world, Blocks.DARK_OAK_STAIRS.getDefaultState().with(StairsBlock.FACING, Direction.WEST).with(StairsBlock.WATERLOGGED, false).with(StairsBlock.SHAPE, StairsShape.STRAIGHT).with(StairsBlock.HALF, Half.BOTTOM), 34, 0, 16, start);
        structure.setBlockState(world, Blocks.DARK_OAK_STAIRS.getDefaultState().with(StairsBlock.FACING, Direction.WEST).with(StairsBlock.WATERLOGGED, false).with(StairsBlock.SHAPE, StairsShape.STRAIGHT).with(StairsBlock.HALF, Half.BOTTOM), 34, 0, 19, start);
        structure.setBlockState(world, Blocks.AIR.getDefaultState(), 34, 0, 31, start);
        structure.setBlockState(world, Blocks.JUNGLE_FENCE_GATE.getDefaultState().with(FenceGateBlock.IN_WALL, false).with(FenceGateBlock.OPEN, false).with(FenceGateBlock.POWERED, false), 34, 0, 51, start);
        structure.setBlockState(world, Blocks.SNOW.getDefaultState().with(SnowBlock.LAYERS, 1), 34, 1, 50, start);
        structure.setBlockState(world, Blocks.SPRUCE_TRAPDOOR.getDefaultState().with(HorizontalBlock.HORIZONTAL_FACING, Direction.NORTH).with(TrapDoorBlock.HALF, Half.BOTTOM).with(TrapDoorBlock.WATERLOGGED, false).with(TrapDoorBlock.POWERED, false).with(TrapDoorBlock.OPEN, false), 34, 2, -41, start);
        structure.setBlockState(world, Index.CANDLE.getDefaultState().with(Candle.FACING, Direction.WEST).with(Candle.LIT, true), 34, 2, -31, start);
        structure.setBlockState(world, Index.CANDLE.getDefaultState().with(Candle.FACING, Direction.EAST).with(Candle.LIT, true), 34, 2, -21, start);
        structure.setBlockState(world, Blocks.OAK_STAIRS.getDefaultState().with(StairsBlock.FACING, Direction.WEST).with(StairsBlock.WATERLOGGED, false).with(StairsBlock.SHAPE, StairsShape.INNER_LEFT).with(StairsBlock.HALF, Half.BOTTOM), 34, 2, -10, start);
        structure.setBlockState(world, Blocks.DARK_OAK_STAIRS.getDefaultState().with(StairsBlock.FACING, Direction.WEST).with(StairsBlock.WATERLOGGED, false).with(StairsBlock.SHAPE, StairsShape.STRAIGHT).with(StairsBlock.HALF, Half.TOP), 34, 2, 26, start);
        structure.setBlockState(world, Blocks.DARK_OAK_STAIRS.getDefaultState().with(StairsBlock.FACING, Direction.WEST).with(StairsBlock.WATERLOGGED, false).with(StairsBlock.SHAPE, StairsShape.STRAIGHT).with(StairsBlock.HALF, Half.TOP), 34, 2, 36, start);
        structure.setBlockState(world, Blocks.SPRUCE_SLAB.getDefaultState().with(SlabBlock.TYPE, SlabType.BOTTOM).with(SlabBlock.WATERLOGGED, false), 34, 2, 43, start);
        structure.setBlockState(world, Blocks.SPRUCE_LOG.getDefaultState(), 34, 2, 45, start);
        structure.setBlockState(world, Blocks.SPRUCE_TRAPDOOR.getDefaultState().with(HorizontalBlock.HORIZONTAL_FACING, Direction.SOUTH).with(TrapDoorBlock.HALF, Half.BOTTOM).with(TrapDoorBlock.WATERLOGGED, false).with(TrapDoorBlock.POWERED, false).with(TrapDoorBlock.OPEN, false), 34, 3, -48, start);
        structure.setBlockState(world, Blocks.SPRUCE_TRAPDOOR.getDefaultState().with(HorizontalBlock.HORIZONTAL_FACING, Direction.NORTH).with(TrapDoorBlock.HALF, Half.BOTTOM).with(TrapDoorBlock.WATERLOGGED, false).with(TrapDoorBlock.POWERED, false).with(TrapDoorBlock.OPEN, false), 34, 3, -44, start);
        structure.setBlockState(world, Blocks.DARK_OAK_STAIRS.getDefaultState().with(StairsBlock.FACING, Direction.WEST).with(StairsBlock.WATERLOGGED, false).with(StairsBlock.SHAPE, StairsShape.STRAIGHT).with(StairsBlock.HALF, Half.TOP), 34, 3, -33, start);
        structure.setBlockState(world, Blocks.DARK_OAK_STAIRS.getDefaultState().with(StairsBlock.FACING, Direction.WEST).with(StairsBlock.WATERLOGGED, false).with(StairsBlock.SHAPE, StairsShape.STRAIGHT).with(StairsBlock.HALF, Half.TOP), 34, 3, -19, start);
        structure.setBlockState(world, Blocks.OAK_STAIRS.getDefaultState().with(StairsBlock.FACING, Direction.WEST).with(StairsBlock.WATERLOGGED, false).with(StairsBlock.SHAPE, StairsShape.INNER_LEFT).with(StairsBlock.HALF, Half.BOTTOM), 34, 3, -9, start);
        structure.setBlockState(world, Blocks.OAK_PLANKS.getDefaultState(), 34, 3, -8, start);
        structure.setBlockState(world, Blocks.OAK_PLANKS.getDefaultState(), 34, 3, -6, start);
        structure.setBlockState(world, Blocks.OAK_STAIRS.getDefaultState().with(StairsBlock.FACING, Direction.WEST).with(StairsBlock.WATERLOGGED, false).with(StairsBlock.SHAPE, StairsShape.INNER_RIGHT).with(StairsBlock.HALF, Half.BOTTOM), 34, 3, -5, start);
        structure.setBlockState(world, Blocks.OAK_STAIRS.getDefaultState().with(StairsBlock.FACING, Direction.NORTH).with(StairsBlock.WATERLOGGED, false).with(StairsBlock.SHAPE, StairsShape.OUTER_LEFT).with(StairsBlock.HALF, Half.BOTTOM), 34, 3, -4, start);
        structure.setBlockState(world, Blocks.DARK_OAK_STAIRS.getDefaultState().with(StairsBlock.FACING, Direction.EAST).with(StairsBlock.WATERLOGGED, false).with(StairsBlock.SHAPE, StairsShape.STRAIGHT).with(StairsBlock.HALF, Half.BOTTOM), 34, 3, 26, start);
        structure.setBlockState(world, Blocks.DARK_OAK_STAIRS.getDefaultState().with(StairsBlock.FACING, Direction.EAST).with(StairsBlock.WATERLOGGED, false).with(StairsBlock.SHAPE, StairsShape.STRAIGHT).with(StairsBlock.HALF, Half.BOTTOM), 34, 3, 36, start);
        structure.setBlockState(world, Blocks.SPRUCE_SLAB.getDefaultState().with(SlabBlock.TYPE, SlabType.BOTTOM).with(SlabBlock.WATERLOGGED, false), 34, 3, 45, start);
        structure.setBlockState(world, Blocks.SPRUCE_TRAPDOOR.getDefaultState().with(HorizontalBlock.HORIZONTAL_FACING, Direction.NORTH).with(TrapDoorBlock.HALF, Half.BOTTOM).with(TrapDoorBlock.WATERLOGGED, false).with(TrapDoorBlock.POWERED, false).with(TrapDoorBlock.OPEN, false), 34, 3, 49, start);
        structure.setBlockState(world, Blocks.SPRUCE_SLAB.getDefaultState().with(SlabBlock.TYPE, SlabType.BOTTOM).with(SlabBlock.WATERLOGGED, false), 34, 4, -47, start);
        structure.setBlockState(world, Blocks.DARK_OAK_STAIRS.getDefaultState().with(StairsBlock.FACING, Direction.EAST).with(StairsBlock.WATERLOGGED, false).with(StairsBlock.SHAPE, StairsShape.STRAIGHT).with(StairsBlock.HALF, Half.BOTTOM), 34, 4, -33, start);
        structure.setBlockState(world, Blocks.DARK_OAK_STAIRS.getDefaultState().with(StairsBlock.FACING, Direction.EAST).with(StairsBlock.WATERLOGGED, false).with(StairsBlock.SHAPE, StairsShape.STRAIGHT).with(StairsBlock.HALF, Half.BOTTOM), 34, 4, -19, start);
        structure.setBlockState(world, Blocks.OAK_STAIRS.getDefaultState().with(StairsBlock.FACING, Direction.WEST).with(StairsBlock.WATERLOGGED, false).with(StairsBlock.SHAPE, StairsShape.INNER_LEFT).with(StairsBlock.HALF, Half.BOTTOM), 34, 4, -8, start);
        structure.setBlockState(world, Blocks.OAK_STAIRS.getDefaultState().with(StairsBlock.FACING, Direction.WEST).with(StairsBlock.WATERLOGGED, false).with(StairsBlock.SHAPE, StairsShape.INNER_RIGHT).with(StairsBlock.HALF, Half.BOTTOM), 34, 4, -6, start);
        structure.setBlockState(world, Blocks.SNOW.getDefaultState().with(SnowBlock.LAYERS, 1), 34, 4, 27, start);
        structure.setBlockState(world, Blocks.OAK_STAIRS.getDefaultState().with(StairsBlock.FACING, Direction.EAST).with(StairsBlock.WATERLOGGED, false).with(StairsBlock.SHAPE, StairsShape.STRAIGHT).with(StairsBlock.HALF, Half.BOTTOM), 34, 4, 28, start);
        structure.setBlockState(world, Blocks.OAK_STAIRS.getDefaultState().with(StairsBlock.FACING, Direction.SOUTH).with(StairsBlock.WATERLOGGED, false).with(StairsBlock.SHAPE, StairsShape.STRAIGHT).with(StairsBlock.HALF, Half.BOTTOM), 34, 4, 29, start);
        structure.setBlockState(world, Blocks.OAK_STAIRS.getDefaultState().with(StairsBlock.FACING, Direction.NORTH).with(StairsBlock.WATERLOGGED, false).with(StairsBlock.SHAPE, StairsShape.STRAIGHT).with(StairsBlock.HALF, Half.BOTTOM), 34, 4, 33, start);
        structure.setBlockState(world, Blocks.OAK_STAIRS.getDefaultState().with(StairsBlock.FACING, Direction.EAST).with(StairsBlock.WATERLOGGED, false).with(StairsBlock.SHAPE, StairsShape.STRAIGHT).with(StairsBlock.HALF, Half.BOTTOM), 34, 4, 34, start);
        structure.setBlockState(world, Blocks.SNOW.getDefaultState().with(SnowBlock.LAYERS, 1), 34, 4, 35, start);
        structure.setBlockState(world, Blocks.SPRUCE_SLAB.getDefaultState().with(SlabBlock.TYPE, SlabType.BOTTOM).with(SlabBlock.WATERLOGGED, false), 34, 4, 48, start);
        structure.setBlockState(world, Blocks.SNOW.getDefaultState().with(SnowBlock.LAYERS, 1), 34, 5, -32, start);
        structure.setBlockState(world, Blocks.OAK_STAIRS.getDefaultState().with(StairsBlock.FACING, Direction.EAST).with(StairsBlock.WATERLOGGED, false).with(StairsBlock.SHAPE, StairsShape.STRAIGHT).with(StairsBlock.HALF, Half.BOTTOM), 34, 5, -31, start);
        structure.setBlockState(world, Blocks.OAK_STAIRS.getDefaultState().with(StairsBlock.FACING, Direction.SOUTH).with(StairsBlock.WATERLOGGED, false).with(StairsBlock.SHAPE, StairsShape.STRAIGHT).with(StairsBlock.HALF, Half.BOTTOM), 34, 5, -30, start);
        structure.setBlockState(world, Blocks.OAK_STAIRS.getDefaultState().with(StairsBlock.FACING, Direction.NORTH).with(StairsBlock.WATERLOGGED, false).with(StairsBlock.SHAPE, StairsShape.STRAIGHT).with(StairsBlock.HALF, Half.BOTTOM), 34, 5, -22, start);
        structure.setBlockState(world, Blocks.OAK_STAIRS.getDefaultState().with(StairsBlock.FACING, Direction.EAST).with(StairsBlock.WATERLOGGED, false).with(StairsBlock.SHAPE, StairsShape.STRAIGHT).with(StairsBlock.HALF, Half.BOTTOM), 34, 5, -21, start);
        structure.setBlockState(world, Blocks.SNOW.getDefaultState().with(SnowBlock.LAYERS, 1), 34, 5, -20, start);
        structure.setBlockState(world, Blocks.DARK_OAK_STAIRS.getDefaultState().with(StairsBlock.FACING, Direction.WEST).with(StairsBlock.WATERLOGGED, false).with(StairsBlock.SHAPE, StairsShape.STRAIGHT).with(StairsBlock.HALF, Half.TOP), 34, 7, 14, start);
        structure.setBlockState(world, Blocks.DARK_OAK_STAIRS.getDefaultState().with(StairsBlock.FACING, Direction.EAST).with(StairsBlock.WATERLOGGED, false).with(StairsBlock.SHAPE, StairsShape.STRAIGHT).with(StairsBlock.HALF, Half.BOTTOM), 34, 8, 14, start);
        structure.setBlockState(world, Blocks.DARK_OAK_SLAB.getDefaultState().with(SlabBlock.TYPE, SlabType.BOTTOM).with(SlabBlock.WATERLOGGED, false), 34, 9, 14, start);
        structure.setBlockState(world, Blocks.DIORITE.getDefaultState(), 35, -7, 6, start);
        structure.setBlockState(world, Blocks.IRON_ORE.getDefaultState(), 35, -6, -13, start);
        structure.setBlockState(world, Blocks.COBBLESTONE_WALL.getDefaultState().with(WallBlock.WATERLOGGED, false).with(WallBlock.UP, true).with(WallBlock.WALL_HEIGHT_NORTH, WallHeight.LOW).with(WallBlock.WALL_HEIGHT_SOUTH, WallHeight.LOW).with(WallBlock.WALL_HEIGHT_EAST, WallHeight.LOW).with(WallBlock.WALL_HEIGHT_WEST, WallHeight.LOW), 35, 0, -40, start);
        structure.setBlockState(world, Blocks.ATTACHED_MELON_STEM.getDefaultState(), 35, 0, -35, start);
        structure.setBlockState(world, Index.BEDSIDE_TABLE_OAK.getDefaultState().with(BedsideTable.FACING, Direction.NORTH).with(BedsideTable.WATERLOGGED, false), 35, 0, -31, start);
        structure.setBlockState(world, Index.TABLE_OAK.getDefaultState().with(Table.NE, true).with(Table.NW, true).with(Table.SE, true).with(Table.SW, true), 35, 0, -23, start);
        structure.setBlockState(world, Index.STOOL_OAK.getDefaultState().with(Stool.PILLOW, StoolState.NONE), 35, 0, -22, start);
        structure.setBlockState(world, Blocks.OAK_FENCE.getDefaultState().with(FourWayBlock.WATERLOGGED, false).with(FourWayBlock.NORTH, false).with(FourWayBlock.SOUTH, true).with(FourWayBlock.EAST, false).with(FourWayBlock.WEST, true), 35, 0, 24, start);
        structure.setBlockState(world, Blocks.YELLOW_CARPET.getDefaultState(), 35, 0, 34, start);
        structure.setBlockState(world, Blocks.SNOW.getDefaultState().with(SnowBlock.LAYERS, 1), 35, 0, 51, start);
        structure.setBlockState(world, Blocks.JUNGLE_FENCE_GATE.getDefaultState().with(FenceGateBlock.IN_WALL, false).with(FenceGateBlock.OPEN, false).with(FenceGateBlock.POWERED, false), 35, 1, 50, start);
        structure.setBlockState(world, Blocks.SPRUCE_LOG.getDefaultState(), 35, 2, -43, start);
        structure.setBlockState(world, Blocks.SPRUCE_SLAB.getDefaultState().with(SlabBlock.TYPE, SlabType.BOTTOM).with(SlabBlock.WATERLOGGED, false), 35, 2, -41, start);
        structure.setBlockState(world, Blocks.DARK_OAK_STAIRS.getDefaultState().with(StairsBlock.FACING, Direction.SOUTH).with(StairsBlock.WATERLOGGED, false).with(StairsBlock.SHAPE, StairsShape.STRAIGHT).with(StairsBlock.HALF, Half.BOTTOM), 35, 2, -10, start);
        structure.setBlockState(world, Blocks.DARK_OAK_STAIRS.getDefaultState().with(StairsBlock.FACING, Direction.NORTH).with(StairsBlock.WATERLOGGED, false).with(StairsBlock.SHAPE, StairsShape.STRAIGHT).with(StairsBlock.HALF, Half.TOP), 35, 2, -9, start);
        structure.setBlockState(world, Blocks.DARK_OAK_STAIRS.getDefaultState().with(StairsBlock.FACING, Direction.SOUTH).with(StairsBlock.WATERLOGGED, false).with(StairsBlock.SHAPE, StairsShape.STRAIGHT).with(StairsBlock.HALF, Half.TOP), 35, 2, -5, start);
        structure.setBlockState(world, Blocks.DARK_OAK_STAIRS.getDefaultState().with(StairsBlock.FACING, Direction.NORTH).with(StairsBlock.WATERLOGGED, false).with(StairsBlock.SHAPE, StairsShape.STRAIGHT).with(StairsBlock.HALF, Half.BOTTOM), 35, 2, -4, start);
        structure.setBlockState(world, Index.CANDLE.getDefaultState().with(Candle.FACING, Direction.SOUTH).with(Candle.LIT, true), 35, 2, 29, start);
        structure.setBlockState(world, Index.CANDLE.getDefaultState().with(Candle.FACING, Direction.SOUTH).with(Candle.LIT, true), 35, 2, 33, start);
        structure.setBlockState(world, Blocks.SPRUCE_TRAPDOOR.getDefaultState().with(HorizontalBlock.HORIZONTAL_FACING, Direction.SOUTH).with(TrapDoorBlock.HALF, Half.BOTTOM).with(TrapDoorBlock.WATERLOGGED, false).with(TrapDoorBlock.POWERED, false).with(TrapDoorBlock.OPEN, false), 35, 2, 42, start);
        structure.setBlockState(world, Blocks.OAK_LOG.getDefaultState(), 35, 2, 45, start);
        structure.setBlockState(world, Blocks.SPRUCE_SLAB.getDefaultState().with(SlabBlock.TYPE, SlabType.BOTTOM).with(SlabBlock.WATERLOGGED, false), 35, 3, -48, start);
        structure.setBlockState(world, Blocks.SPRUCE_SLAB.getDefaultState().with(SlabBlock.TYPE, SlabType.BOTTOM).with(SlabBlock.WATERLOGGED, false), 35, 3, -43, start);
        structure.setBlockState(world, Blocks.DARK_OAK_SLAB.getDefaultState().with(SlabBlock.TYPE, SlabType.BOTTOM).with(SlabBlock.WATERLOGGED, false), 35, 3, -32, start);
        structure.setBlockState(world, Blocks.DARK_OAK_SLAB.getDefaultState().with(SlabBlock.TYPE, SlabType.BOTTOM).with(SlabBlock.WATERLOGGED, false), 35, 3, -20, start);
        structure.setBlockState(world, Blocks.DARK_OAK_STAIRS.getDefaultState().with(StairsBlock.FACING, Direction.SOUTH).with(StairsBlock.WATERLOGGED, false).with(StairsBlock.SHAPE, StairsShape.STRAIGHT).with(StairsBlock.HALF, Half.BOTTOM), 35, 3, -9, start);
        structure.setBlockState(world, Blocks.DARK_OAK_STAIRS.getDefaultState().with(StairsBlock.FACING, Direction.NORTH).with(StairsBlock.WATERLOGGED, false).with(StairsBlock.SHAPE, StairsShape.STRAIGHT).with(StairsBlock.HALF, Half.TOP), 35, 3, -8, start);
        structure.setBlockState(world, Blocks.DARK_OAK_STAIRS.getDefaultState().with(StairsBlock.FACING, Direction.SOUTH).with(StairsBlock.WATERLOGGED, false).with(StairsBlock.SHAPE, StairsShape.STRAIGHT).with(StairsBlock.HALF, Half.TOP), 35, 3, -6, start);
        structure.setBlockState(world, Blocks.DARK_OAK_STAIRS.getDefaultState().with(StairsBlock.FACING, Direction.NORTH).with(StairsBlock.WATERLOGGED, false).with(StairsBlock.SHAPE, StairsShape.STRAIGHT).with(StairsBlock.HALF, Half.BOTTOM), 35, 3, -5, start);
        structure.setBlockState(world, Blocks.DARK_OAK_STAIRS.getDefaultState().with(StairsBlock.FACING, Direction.WEST).with(StairsBlock.WATERLOGGED, false).with(StairsBlock.SHAPE, StairsShape.STRAIGHT).with(StairsBlock.HALF, Half.TOP), 35, 3, 26, start);
        structure.setBlockState(world, Blocks.DARK_OAK_STAIRS.getDefaultState().with(StairsBlock.FACING, Direction.WEST).with(StairsBlock.WATERLOGGED, false).with(StairsBlock.SHAPE, StairsShape.STRAIGHT).with(StairsBlock.HALF, Half.TOP), 35, 3, 36, start);
        structure.setBlockState(world, Blocks.SPRUCE_TRAPDOOR.getDefaultState().with(HorizontalBlock.HORIZONTAL_FACING, Direction.SOUTH).with(TrapDoorBlock.HALF, Half.BOTTOM).with(TrapDoorBlock.WATERLOGGED, false).with(TrapDoorBlock.POWERED, false).with(TrapDoorBlock.OPEN, false), 35, 3, 45, start);
        structure.setBlockState(world, Blocks.SPRUCE_SLAB.getDefaultState().with(SlabBlock.TYPE, SlabType.BOTTOM).with(SlabBlock.WATERLOGGED, false), 35, 3, 49, start);
        structure.setBlockState(world, Blocks.SPRUCE_TRAPDOOR.getDefaultState().with(HorizontalBlock.HORIZONTAL_FACING, Direction.SOUTH).with(TrapDoorBlock.HALF, Half.BOTTOM).with(TrapDoorBlock.WATERLOGGED, false).with(TrapDoorBlock.POWERED, false).with(TrapDoorBlock.OPEN, false), 35, 4, -47, start);
        structure.setBlockState(world, Blocks.DARK_OAK_STAIRS.getDefaultState().with(StairsBlock.FACING, Direction.WEST).with(StairsBlock.WATERLOGGED, false).with(StairsBlock.SHAPE, StairsShape.STRAIGHT).with(StairsBlock.HALF, Half.TOP), 35, 4, -33, start);
        structure.setBlockState(world, Blocks.DARK_OAK_STAIRS.getDefaultState().with(StairsBlock.FACING, Direction.WEST).with(StairsBlock.WATERLOGGED, false).with(StairsBlock.SHAPE, StairsShape.STRAIGHT).with(StairsBlock.HALF, Half.TOP), 35, 4, -19, start);
        structure.setBlockState(world, Blocks.DARK_OAK_STAIRS.getDefaultState().with(StairsBlock.FACING, Direction.SOUTH).with(StairsBlock.WATERLOGGED, false).with(StairsBlock.SHAPE, StairsShape.STRAIGHT).with(StairsBlock.HALF, Half.BOTTOM), 35, 4, -8, start);
        structure.setBlockState(world, Blocks.DARK_OAK_STAIRS.getDefaultState().with(StairsBlock.FACING, Direction.WEST).with(StairsBlock.WATERLOGGED, false).with(StairsBlock.SHAPE, StairsShape.STRAIGHT).with(StairsBlock.HALF, Half.TOP), 35, 4, -7, start);
        structure.setBlockState(world, Blocks.DARK_OAK_STAIRS.getDefaultState().with(StairsBlock.FACING, Direction.NORTH).with(StairsBlock.WATERLOGGED, false).with(StairsBlock.SHAPE, StairsShape.STRAIGHT).with(StairsBlock.HALF, Half.BOTTOM), 35, 4, -6, start);
        structure.setBlockState(world, Blocks.DARK_OAK_STAIRS.getDefaultState().with(StairsBlock.FACING, Direction.EAST).with(StairsBlock.WATERLOGGED, false).with(StairsBlock.SHAPE, StairsShape.STRAIGHT).with(StairsBlock.HALF, Half.BOTTOM), 35, 4, 26, start);
        structure.setBlockState(world, Blocks.DARK_OAK_STAIRS.getDefaultState().with(StairsBlock.FACING, Direction.EAST).with(StairsBlock.WATERLOGGED, false).with(StairsBlock.SHAPE, StairsShape.STRAIGHT).with(StairsBlock.HALF, Half.BOTTOM), 35, 4, 36, start);
        structure.setBlockState(world, Blocks.SPRUCE_TRAPDOOR.getDefaultState().with(HorizontalBlock.HORIZONTAL_FACING, Direction.NORTH).with(TrapDoorBlock.HALF, Half.BOTTOM).with(TrapDoorBlock.WATERLOGGED, false).with(TrapDoorBlock.POWERED, false).with(TrapDoorBlock.OPEN, false), 35, 4, 48, start);
        structure.setBlockState(world, Blocks.DARK_OAK_STAIRS.getDefaultState().with(StairsBlock.FACING, Direction.EAST).with(StairsBlock.WATERLOGGED, false).with(StairsBlock.SHAPE, StairsShape.STRAIGHT).with(StairsBlock.HALF, Half.BOTTOM), 35, 5, -33, start);
        structure.setBlockState(world, Blocks.DARK_OAK_STAIRS.getDefaultState().with(StairsBlock.FACING, Direction.EAST).with(StairsBlock.WATERLOGGED, false).with(StairsBlock.SHAPE, StairsShape.STRAIGHT).with(StairsBlock.HALF, Half.BOTTOM), 35, 5, -19, start);
        structure.setBlockState(world, Blocks.DARK_OAK_SLAB.getDefaultState().with(SlabBlock.TYPE, SlabType.BOTTOM).with(SlabBlock.WATERLOGGED, false), 35, 5, -7, start);
        structure.setBlockState(world, Blocks.DARK_OAK_STAIRS.getDefaultState().with(StairsBlock.FACING, Direction.EAST).with(StairsBlock.WATERLOGGED, false).with(StairsBlock.SHAPE, StairsShape.STRAIGHT).with(StairsBlock.HALF, Half.TOP), 35, 5, 26, start);
        structure.setBlockState(world, Blocks.SNOW.getDefaultState().with(SnowBlock.LAYERS, 1), 35, 5, 27, start);
        structure.setBlockState(world, Blocks.OAK_STAIRS.getDefaultState().with(StairsBlock.FACING, Direction.EAST).with(StairsBlock.WATERLOGGED, false).with(StairsBlock.SHAPE, StairsShape.STRAIGHT).with(StairsBlock.HALF, Half.BOTTOM), 35, 5, 28, start);
        structure.setBlockState(world, Blocks.OAK_STAIRS.getDefaultState().with(StairsBlock.FACING, Direction.SOUTH).with(StairsBlock.WATERLOGGED, false).with(StairsBlock.SHAPE, StairsShape.STRAIGHT).with(StairsBlock.HALF, Half.BOTTOM), 35, 5, 29, start);
        structure.setBlockState(world, Blocks.OAK_STAIRS.getDefaultState().with(StairsBlock.FACING, Direction.NORTH).with(StairsBlock.WATERLOGGED, false).with(StairsBlock.SHAPE, StairsShape.STRAIGHT).with(StairsBlock.HALF, Half.BOTTOM), 35, 5, 33, start);
        structure.setBlockState(world, Blocks.OAK_STAIRS.getDefaultState().with(StairsBlock.FACING, Direction.EAST).with(StairsBlock.WATERLOGGED, false).with(StairsBlock.SHAPE, StairsShape.STRAIGHT).with(StairsBlock.HALF, Half.BOTTOM), 35, 5, 34, start);
        structure.setBlockState(world, Blocks.SNOW.getDefaultState().with(SnowBlock.LAYERS, 1), 35, 5, 35, start);
        structure.setBlockState(world, Blocks.DARK_OAK_STAIRS.getDefaultState().with(StairsBlock.FACING, Direction.EAST).with(StairsBlock.WATERLOGGED, false).with(StairsBlock.SHAPE, StairsShape.STRAIGHT).with(StairsBlock.HALF, Half.TOP), 35, 5, 36, start);
        structure.setBlockState(world, Blocks.SNOW.getDefaultState().with(SnowBlock.LAYERS, 1), 35, 6, -32, start);
        structure.setBlockState(world, Blocks.OAK_STAIRS.getDefaultState().with(StairsBlock.FACING, Direction.EAST).with(StairsBlock.WATERLOGGED, false).with(StairsBlock.SHAPE, StairsShape.STRAIGHT).with(StairsBlock.HALF, Half.BOTTOM), 35, 6, -31, start);
        structure.setBlockState(world, Blocks.OAK_STAIRS.getDefaultState().with(StairsBlock.FACING, Direction.SOUTH).with(StairsBlock.WATERLOGGED, false).with(StairsBlock.SHAPE, StairsShape.STRAIGHT).with(StairsBlock.HALF, Half.BOTTOM), 35, 6, -30, start);
        structure.setBlockState(world, Blocks.OAK_STAIRS.getDefaultState().with(StairsBlock.FACING, Direction.NORTH).with(StairsBlock.WATERLOGGED, false).with(StairsBlock.SHAPE, StairsShape.STRAIGHT).with(StairsBlock.HALF, Half.BOTTOM), 35, 6, -22, start);
        structure.setBlockState(world, Blocks.OAK_STAIRS.getDefaultState().with(StairsBlock.FACING, Direction.EAST).with(StairsBlock.WATERLOGGED, false).with(StairsBlock.SHAPE, StairsShape.STRAIGHT).with(StairsBlock.HALF, Half.BOTTOM), 35, 6, -21, start);
        structure.setBlockState(world, Blocks.SNOW.getDefaultState().with(SnowBlock.LAYERS, 1), 35, 6, -20, start);
        structure.setBlockState(world, Blocks.SNOW.getDefaultState().with(SnowBlock.LAYERS, 1), 35, 6, 36, start);
        structure.setBlockState(world, Blocks.DARK_OAK_STAIRS.getDefaultState().with(StairsBlock.FACING, Direction.EAST).with(StairsBlock.WATERLOGGED, false).with(StairsBlock.SHAPE, StairsShape.STRAIGHT).with(StairsBlock.HALF, Half.TOP), 35, 7, -33, start);
        structure.setBlockState(world, Blocks.DARK_OAK_STAIRS.getDefaultState().with(StairsBlock.FACING, Direction.EAST).with(StairsBlock.WATERLOGGED, false).with(StairsBlock.SHAPE, StairsShape.STRAIGHT).with(StairsBlock.HALF, Half.TOP), 35, 7, -19, start);
        structure.setBlockState(world, Blocks.SNOW.getDefaultState().with(SnowBlock.LAYERS, 1), 35, 8, -33, start);
        structure.setBlockState(world, Blocks.SNOW.getDefaultState().with(SnowBlock.LAYERS, 1), 35, 8, -19, start);
        structure.setBlockState(world, Blocks.DARK_OAK_STAIRS.getDefaultState().with(StairsBlock.FACING, Direction.WEST).with(StairsBlock.WATERLOGGED, false).with(StairsBlock.SHAPE, StairsShape.STRAIGHT).with(StairsBlock.HALF, Half.TOP), 35, 8, 14, start);
        structure.setBlockState(world, Blocks.SNOW.getDefaultState().with(SnowBlock.LAYERS, 1), 35, 9, 14, start);
        structure.setBlockState(world, Blocks.ICE.getDefaultState(), 36, -1, -37, start);
        structure.setBlockState(world, Blocks.DIRT.getDefaultState(), 36, -1, -35, start);
        structure.setBlockState(world, Blocks.GRASS_BLOCK.getDefaultState().with(SnowyDirtBlock.SNOWY, true), 36, -1, 33, start);
        structure.setBlockState(world, Blocks.MELON.getDefaultState(), 36, 0, -35, start);
        structure.setBlockState(world, Index.CUT_COBBLESTONE_PILLAR.getDefaultState().with(Pillar.WATERLOGGED, false).with(Pillar.STATE, PillarState.BOTH), 36, 0, -26, start);
        structure.setBlockState(world, Index.STOOL_OAK.getDefaultState().with(Stool.PILLOW, StoolState.NONE), 36, 0, -23, start);
        structure.setBlockState(world, Blocks.YELLOW_CARPET.getDefaultState(), 36, 0, 33, start);
        structure.setBlockState(world, Blocks.OAK_SLAB.getDefaultState().with(SlabBlock.TYPE, SlabType.BOTTOM).with(SlabBlock.WATERLOGGED, false), 36, 0, 34, start);
        structure.setBlockState(world, Blocks.JUNGLE_FENCE_GATE.getDefaultState().with(FenceGateBlock.IN_WALL, false).with(FenceGateBlock.OPEN, false).with(FenceGateBlock.POWERED, false), 36, 0, 51, start);
        structure.setBlockState(world, Blocks.SNOW.getDefaultState().with(SnowBlock.LAYERS, 1), 36, 1, -35, start);
        structure.setBlockState(world, Blocks.FLOWER_POT.getDefaultState(), 36, 1, -26, start);
        structure.setBlockState(world, Blocks.SNOW.getDefaultState().with(SnowBlock.LAYERS, 1), 36, 1, 50, start);
        structure.setBlockState(world, Blocks.OAK_LOG.getDefaultState(), 36, 2, -43, start);
        structure.setBlockState(world, Blocks.SPRUCE_TRAPDOOR.getDefaultState().with(HorizontalBlock.HORIZONTAL_FACING, Direction.NORTH).with(TrapDoorBlock.HALF, Half.BOTTOM).with(TrapDoorBlock.WATERLOGGED, false).with(TrapDoorBlock.POWERED, false).with(TrapDoorBlock.OPEN, false), 36, 2, -40, start);
        structure.setBlockState(world, Blocks.DARK_OAK_STAIRS.getDefaultState().with(StairsBlock.FACING, Direction.EAST).with(StairsBlock.WATERLOGGED, false).with(StairsBlock.SHAPE, StairsShape.STRAIGHT).with(StairsBlock.HALF, Half.BOTTOM), 36, 2, 6, start);
        structure.setBlockState(world, Blocks.OAK_STAIRS.getDefaultState().with(StairsBlock.FACING, Direction.NORTH).with(StairsBlock.WATERLOGGED, false).with(StairsBlock.SHAPE, StairsShape.STRAIGHT).with(StairsBlock.HALF, Half.TOP), 36, 2, 10, start);
        structure.setBlockState(world, Blocks.OAK_STAIRS.getDefaultState().with(StairsBlock.FACING, Direction.SOUTH).with(StairsBlock.WATERLOGGED, false).with(StairsBlock.SHAPE, StairsShape.STRAIGHT).with(StairsBlock.HALF, Half.TOP), 36, 2, 12, start);
        structure.setBlockState(world, Blocks.DARK_OAK_STAIRS.getDefaultState().with(StairsBlock.FACING, Direction.EAST).with(StairsBlock.WATERLOGGED, false).with(StairsBlock.SHAPE, StairsShape.STRAIGHT).with(StairsBlock.HALF, Half.BOTTOM), 36, 2, 16, start);
        structure.setBlockState(world, Blocks.SPRUCE_SLAB.getDefaultState().with(SlabBlock.TYPE, SlabType.BOTTOM).with(SlabBlock.WATERLOGGED, false), 36, 2, 42, start);
        structure.setBlockState(world, Blocks.SPRUCE_LOG.getDefaultState(), 36, 2, 44, start);
        structure.setBlockState(world, Blocks.SPRUCE_TRAPDOOR.getDefaultState().with(HorizontalBlock.HORIZONTAL_FACING, Direction.SOUTH).with(TrapDoorBlock.HALF, Half.BOTTOM).with(TrapDoorBlock.WATERLOGGED, false).with(TrapDoorBlock.POWERED, false).with(TrapDoorBlock.OPEN, false), 36, 3, -48, start);
        structure.setBlockState(world, Blocks.SPRUCE_LOG.getDefaultState(), 36, 3, -47, start);
        structure.setBlockState(world, Blocks.SPRUCE_TRAPDOOR.getDefaultState().with(HorizontalBlock.HORIZONTAL_FACING, Direction.NORTH).with(TrapDoorBlock.HALF, Half.BOTTOM).with(TrapDoorBlock.WATERLOGGED, false).with(TrapDoorBlock.POWERED, false).with(TrapDoorBlock.OPEN, false), 36, 3, -43, start);
        structure.setBlockState(world, Blocks.LANTERN.getDefaultState().with(LanternBlock.WATERLOGGED, false).with(LanternBlock.HANGING, true), 36, 3, -26, start);
        structure.setBlockState(world, Blocks.SNOW.getDefaultState().with(SnowBlock.LAYERS, 1), 36, 3, 7, start);
        structure.setBlockState(world, Blocks.OAK_STAIRS.getDefaultState().with(StairsBlock.FACING, Direction.EAST).with(StairsBlock.WATERLOGGED, false).with(StairsBlock.SHAPE, StairsShape.STRAIGHT).with(StairsBlock.HALF, Half.BOTTOM), 36, 3, 8, start);
        structure.setBlockState(world, Blocks.OAK_STAIRS.getDefaultState().with(StairsBlock.FACING, Direction.SOUTH).with(StairsBlock.WATERLOGGED, false).with(StairsBlock.SHAPE, StairsShape.STRAIGHT).with(StairsBlock.HALF, Half.BOTTOM), 36, 3, 9, start);
        structure.setBlockState(world, Blocks.OAK_STAIRS.getDefaultState().with(StairsBlock.FACING, Direction.NORTH).with(StairsBlock.WATERLOGGED, false).with(StairsBlock.SHAPE, StairsShape.STRAIGHT).with(StairsBlock.HALF, Half.BOTTOM), 36, 3, 13, start);
        structure.setBlockState(world, Blocks.OAK_STAIRS.getDefaultState().with(StairsBlock.FACING, Direction.EAST).with(StairsBlock.WATERLOGGED, false).with(StairsBlock.SHAPE, StairsShape.STRAIGHT).with(StairsBlock.HALF, Half.BOTTOM), 36, 3, 14, start);
        structure.setBlockState(world, Blocks.SNOW.getDefaultState().with(SnowBlock.LAYERS, 1), 36, 3, 15, start);
        structure.setBlockState(world, Blocks.SPRUCE_SLAB.getDefaultState().with(SlabBlock.TYPE, SlabType.BOTTOM).with(SlabBlock.WATERLOGGED, false), 36, 3, 44, start);
        structure.setBlockState(world, Blocks.SPRUCE_TRAPDOOR.getDefaultState().with(HorizontalBlock.HORIZONTAL_FACING, Direction.NORTH).with(TrapDoorBlock.HALF, Half.BOTTOM).with(TrapDoorBlock.WATERLOGGED, false).with(TrapDoorBlock.POWERED, false).with(TrapDoorBlock.OPEN, false), 36, 3, 49, start);
        structure.setBlockState(world, Blocks.SPRUCE_SLAB.getDefaultState().with(SlabBlock.TYPE, SlabType.BOTTOM).with(SlabBlock.WATERLOGGED, false), 36, 4, -47, start);
        structure.setBlockState(world, Blocks.CHAIN.getDefaultState().with(ChainBlock.WATERLOGGED, false), 36, 4, -26, start);
        structure.setBlockState(world, Blocks.SPRUCE_SLAB.getDefaultState().with(SlabBlock.TYPE, SlabType.BOTTOM).with(SlabBlock.WATERLOGGED, false), 36, 4, 48, start);
        structure.setBlockState(world, Blocks.DARK_OAK_SLAB.getDefaultState().with(SlabBlock.TYPE, SlabType.TOP).with(SlabBlock.WATERLOGGED, false), 36, 5, -33, start);
        structure.setBlockState(world, Blocks.DARK_OAK_SLAB.getDefaultState().with(SlabBlock.TYPE, SlabType.TOP).with(SlabBlock.WATERLOGGED, false), 36, 5, -19, start);
        structure.setBlockState(world, Blocks.DARK_OAK_SLAB.getDefaultState().with(SlabBlock.TYPE, SlabType.DOUBLE).with(SlabBlock.WATERLOGGED, false), 36, 6, -33, start);
        structure.setBlockState(world, Blocks.DARK_OAK_SLAB.getDefaultState().with(SlabBlock.TYPE, SlabType.DOUBLE).with(SlabBlock.WATERLOGGED, false), 36, 6, -19, start);
        structure.setBlockState(world, Blocks.DARK_OAK_SLAB.getDefaultState().with(SlabBlock.TYPE, SlabType.BOTTOM).with(SlabBlock.WATERLOGGED, false), 36, 7, -33, start);
        structure.setBlockState(world, Blocks.OAK_STAIRS.getDefaultState().with(StairsBlock.FACING, Direction.SOUTH).with(StairsBlock.WATERLOGGED, false).with(StairsBlock.SHAPE, StairsShape.STRAIGHT).with(StairsBlock.HALF, Half.BOTTOM), 36, 7, -30, start);
        structure.setBlockState(world, Blocks.OAK_STAIRS.getDefaultState().with(StairsBlock.FACING, Direction.NORTH).with(StairsBlock.WATERLOGGED, false).with(StairsBlock.SHAPE, StairsShape.STRAIGHT).with(StairsBlock.HALF, Half.BOTTOM), 36, 7, -22, start);
        structure.setBlockState(world, Blocks.DARK_OAK_SLAB.getDefaultState().with(SlabBlock.TYPE, SlabType.BOTTOM).with(SlabBlock.WATERLOGGED, false), 36, 7, -19, start);
        structure.setBlockState(world, Blocks.STONE.getDefaultState(), 37, -6, 52, start);
        structure.setBlockState(world, Blocks.ICE.getDefaultState(), 37, -3, 53, start);
        structure.setBlockState(world, Blocks.DIRT.getDefaultState(), 37, -1, 50, start);
        structure.setBlockState(world, Blocks.MELON_STEM.getDefaultState().with(StemBlock.AGE, 7), 37, 0, -35, start);
        structure.setBlockState(world, Blocks.COBBLESTONE_WALL.getDefaultState().with(WallBlock.WATERLOGGED, false).with(WallBlock.UP, true).with(WallBlock.WALL_HEIGHT_NORTH, WallHeight.LOW).with(WallBlock.WALL_HEIGHT_SOUTH, WallHeight.LOW).with(WallBlock.WALL_HEIGHT_EAST, WallHeight.LOW).with(WallBlock.WALL_HEIGHT_WEST, WallHeight.LOW), 37, 0, -14, start);
        structure.setBlockState(world, Blocks.COBBLESTONE_WALL.getDefaultState().with(WallBlock.WATERLOGGED, false).with(WallBlock.UP, true).with(WallBlock.WALL_HEIGHT_NORTH, WallHeight.LOW).with(WallBlock.WALL_HEIGHT_SOUTH, WallHeight.LOW).with(WallBlock.WALL_HEIGHT_EAST, WallHeight.LOW).with(WallBlock.WALL_HEIGHT_WEST, WallHeight.LOW), 37, 0, -3, start);
        structure.setBlockState(world, Blocks.AIR.getDefaultState(), 37, 0, 2, start);
        structure.setBlockState(world, Blocks.DARK_OAK_DOOR.getDefaultState().with(DoorBlock.FACING, Direction.EAST).with(DoorBlock.HALF, DoubleBlockHalf.LOWER).with(DoorBlock.HINGE, DoorHingeSide.LEFT).with(DoorBlock.OPEN, false).with(DoorBlock.POWERED, false), 37, 0, 11, start);
        structure.setBlockState(world, Blocks.YELLOW_CARPET.getDefaultState(), 37, 0, 32, start);
        structure.setBlockState(world, Blocks.OAK_SLAB.getDefaultState().with(SlabBlock.TYPE, SlabType.BOTTOM).with(SlabBlock.WATERLOGGED, false), 37, 0, 33, start);
        structure.setBlockState(world, Blocks.SNOW.getDefaultState().with(SnowBlock.LAYERS, 1), 37, 0, 51, start);
        structure.setBlockState(world, Blocks.SNOW.getDefaultState().with(SnowBlock.LAYERS, 1), 37, 1, 2, start);
        structure.setBlockState(world, Blocks.DARK_OAK_DOOR.getDefaultState().with(DoorBlock.FACING, Direction.EAST).with(DoorBlock.HALF, DoubleBlockHalf.UPPER).with(DoorBlock.HINGE, DoorHingeSide.LEFT).with(DoorBlock.OPEN, false).with(DoorBlock.POWERED, false), 37, 1, 11, start);
        structure.setBlockState(world, Blocks.OAK_SLAB.getDefaultState().with(SlabBlock.TYPE, SlabType.BOTTOM).with(SlabBlock.WATERLOGGED, false), 37, 1, 34, start);
        structure.setBlockState(world, Blocks.JUNGLE_FENCE_GATE.getDefaultState().with(FenceGateBlock.IN_WALL, false).with(FenceGateBlock.OPEN, false).with(FenceGateBlock.POWERED, false), 37, 1, 50, start);
        structure.setBlockState(world, Blocks.SPRUCE_LOG.getDefaultState(), 37, 2, -42, start);
        structure.setBlockState(world, Blocks.SPRUCE_SLAB.getDefaultState().with(SlabBlock.TYPE, SlabType.BOTTOM).with(SlabBlock.WATERLOGGED, false), 37, 2, -40, start);
        structure.setBlockState(world, Blocks.DARK_OAK_STAIRS.getDefaultState().with(StairsBlock.FACING, Direction.WEST).with(StairsBlock.WATERLOGGED, false).with(StairsBlock.SHAPE, StairsShape.STRAIGHT).with(StairsBlock.HALF, Half.TOP), 37, 2, 6, start);
        structure.setBlockState(world, Blocks.DARK_OAK_STAIRS.getDefaultState().with(StairsBlock.FACING, Direction.WEST).with(StairsBlock.WATERLOGGED, false).with(StairsBlock.SHAPE, StairsShape.STRAIGHT).with(StairsBlock.HALF, Half.TOP), 37, 2, 16, start);
        structure.setBlockState(world, Blocks.SPRUCE_TRAPDOOR.getDefaultState().with(HorizontalBlock.HORIZONTAL_FACING, Direction.SOUTH).with(TrapDoorBlock.HALF, Half.BOTTOM).with(TrapDoorBlock.WATERLOGGED, false).with(TrapDoorBlock.POWERED, false).with(TrapDoorBlock.OPEN, false), 37, 2, 42, start);
        structure.setBlockState(world, Blocks.OAK_LOG.getDefaultState(), 37, 2, 44, start);
        structure.setBlockState(world, Blocks.SPRUCE_SLAB.getDefaultState().with(SlabBlock.TYPE, SlabType.BOTTOM).with(SlabBlock.WATERLOGGED, false), 37, 3, -47, start);
        structure.setBlockState(world, Blocks.SPRUCE_SLAB.getDefaultState().with(SlabBlock.TYPE, SlabType.BOTTOM).with(SlabBlock.WATERLOGGED, false), 37, 3, -42, start);
        structure.setBlockState(world, Blocks.DARK_OAK_SLAB.getDefaultState().with(SlabBlock.TYPE, SlabType.BOTTOM).with(SlabBlock.WATERLOGGED, false), 37, 3, -32, start);
        structure.setBlockState(world, Blocks.DARK_OAK_SLAB.getDefaultState().with(SlabBlock.TYPE, SlabType.BOTTOM).with(SlabBlock.WATERLOGGED, false), 37, 3, -20, start);
        structure.setBlockState(world, Blocks.DARK_OAK_STAIRS.getDefaultState().with(StairsBlock.FACING, Direction.EAST).with(StairsBlock.WATERLOGGED, false).with(StairsBlock.SHAPE, StairsShape.STRAIGHT).with(StairsBlock.HALF, Half.BOTTOM), 37, 3, 6, start);
        structure.setBlockState(world, Blocks.DARK_OAK_STAIRS.getDefaultState().with(StairsBlock.FACING, Direction.EAST).with(StairsBlock.WATERLOGGED, false).with(StairsBlock.SHAPE, StairsShape.STRAIGHT).with(StairsBlock.HALF, Half.BOTTOM), 37, 3, 16, start);
        structure.setBlockState(world, Blocks.SPRUCE_TRAPDOOR.getDefaultState().with(HorizontalBlock.HORIZONTAL_FACING, Direction.SOUTH).with(TrapDoorBlock.HALF, Half.BOTTOM).with(TrapDoorBlock.WATERLOGGED, false).with(TrapDoorBlock.POWERED, false).with(TrapDoorBlock.OPEN, false), 37, 3, 44, start);
        structure.setBlockState(world, Blocks.OAK_LOG.getDefaultState(), 37, 3, 48, start);
        structure.setBlockState(world, Blocks.SPRUCE_SLAB.getDefaultState().with(SlabBlock.TYPE, SlabType.BOTTOM).with(SlabBlock.WATERLOGGED, false), 37, 3, 49, start);
        structure.setBlockState(world, Blocks.SPRUCE_TRAPDOOR.getDefaultState().with(HorizontalBlock.HORIZONTAL_FACING, Direction.SOUTH).with(TrapDoorBlock.HALF, Half.BOTTOM).with(TrapDoorBlock.WATERLOGGED, false).with(TrapDoorBlock.POWERED, false).with(TrapDoorBlock.OPEN, false), 37, 4, -46, start);
        structure.setBlockState(world, Blocks.DARK_OAK_STAIRS.getDefaultState().with(StairsBlock.FACING, Direction.EAST).with(StairsBlock.WATERLOGGED, false).with(StairsBlock.SHAPE, StairsShape.STRAIGHT).with(StairsBlock.HALF, Half.TOP), 37, 4, -33, start);
        structure.setBlockState(world, Blocks.DARK_OAK_STAIRS.getDefaultState().with(StairsBlock.FACING, Direction.EAST).with(StairsBlock.WATERLOGGED, false).with(StairsBlock.SHAPE, StairsShape.STRAIGHT).with(StairsBlock.HALF, Half.TOP), 37, 4, -19, start);
        structure.setBlockState(world, Blocks.SNOW.getDefaultState().with(SnowBlock.LAYERS, 1), 37, 4, 7, start);
        structure.setBlockState(world, Blocks.OAK_STAIRS.getDefaultState().with(StairsBlock.FACING, Direction.EAST).with(StairsBlock.WATERLOGGED, false).with(StairsBlock.SHAPE, StairsShape.STRAIGHT).with(StairsBlock.HALF, Half.BOTTOM), 37, 4, 8, start);
        structure.setBlockState(world, Blocks.OAK_STAIRS.getDefaultState().with(StairsBlock.FACING, Direction.SOUTH).with(StairsBlock.WATERLOGGED, false).with(StairsBlock.SHAPE, StairsShape.STRAIGHT).with(StairsBlock.HALF, Half.BOTTOM), 37, 4, 9, start);
        structure.setBlockState(world, Blocks.OAK_STAIRS.getDefaultState().with(StairsBlock.FACING, Direction.NORTH).with(StairsBlock.WATERLOGGED, false).with(StairsBlock.SHAPE, StairsShape.STRAIGHT).with(StairsBlock.HALF, Half.BOTTOM), 37, 4, 13, start);
        structure.setBlockState(world, Blocks.OAK_STAIRS.getDefaultState().with(StairsBlock.FACING, Direction.EAST).with(StairsBlock.WATERLOGGED, false).with(StairsBlock.SHAPE, StairsShape.STRAIGHT).with(StairsBlock.HALF, Half.BOTTOM), 37, 4, 14, start);
        structure.setBlockState(world, Blocks.SNOW.getDefaultState().with(SnowBlock.LAYERS, 1), 37, 4, 15, start);
        structure.setBlockState(world, Blocks.SPRUCE_TRAPDOOR.getDefaultState().with(HorizontalBlock.HORIZONTAL_FACING, Direction.NORTH).with(TrapDoorBlock.HALF, Half.BOTTOM).with(TrapDoorBlock.WATERLOGGED, false).with(TrapDoorBlock.POWERED, false).with(TrapDoorBlock.OPEN, false), 37, 4, 48, start);
        structure.setBlockState(world, Blocks.DARK_OAK_STAIRS.getDefaultState().with(StairsBlock.FACING, Direction.WEST).with(StairsBlock.WATERLOGGED, false).with(StairsBlock.SHAPE, StairsShape.STRAIGHT).with(StairsBlock.HALF, Half.BOTTOM), 37, 5, -33, start);
        structure.setBlockState(world, Blocks.DARK_OAK_STAIRS.getDefaultState().with(StairsBlock.FACING, Direction.WEST).with(StairsBlock.WATERLOGGED, false).with(StairsBlock.SHAPE, StairsShape.STRAIGHT).with(StairsBlock.HALF, Half.BOTTOM), 37, 5, -19, start);
        structure.setBlockState(world, Blocks.SNOW.getDefaultState().with(SnowBlock.LAYERS, 1), 37, 6, -32, start);
        structure.setBlockState(world, Blocks.OAK_STAIRS.getDefaultState().with(StairsBlock.FACING, Direction.WEST).with(StairsBlock.WATERLOGGED, false).with(StairsBlock.SHAPE, StairsShape.STRAIGHT).with(StairsBlock.HALF, Half.BOTTOM), 37, 6, -31, start);
        structure.setBlockState(world, Blocks.OAK_STAIRS.getDefaultState().with(StairsBlock.FACING, Direction.SOUTH).with(StairsBlock.WATERLOGGED, false).with(StairsBlock.SHAPE, StairsShape.STRAIGHT).with(StairsBlock.HALF, Half.BOTTOM), 37, 6, -30, start);
        structure.setBlockState(world, Blocks.OAK_STAIRS.getDefaultState().with(StairsBlock.FACING, Direction.NORTH).with(StairsBlock.WATERLOGGED, false).with(StairsBlock.SHAPE, StairsShape.STRAIGHT).with(StairsBlock.HALF, Half.BOTTOM), 37, 6, -22, start);
        structure.setBlockState(world, Blocks.OAK_STAIRS.getDefaultState().with(StairsBlock.FACING, Direction.WEST).with(StairsBlock.WATERLOGGED, false).with(StairsBlock.SHAPE, StairsShape.STRAIGHT).with(StairsBlock.HALF, Half.BOTTOM), 37, 6, -21, start);
        structure.setBlockState(world, Blocks.SNOW.getDefaultState().with(SnowBlock.LAYERS, 1), 37, 6, -20, start);
        structure.setBlockState(world, Blocks.DARK_OAK_STAIRS.getDefaultState().with(StairsBlock.FACING, Direction.WEST).with(StairsBlock.WATERLOGGED, false).with(StairsBlock.SHAPE, StairsShape.STRAIGHT).with(StairsBlock.HALF, Half.TOP), 37, 7, -33, start);
        structure.setBlockState(world, Blocks.DARK_OAK_STAIRS.getDefaultState().with(StairsBlock.FACING, Direction.WEST).with(StairsBlock.WATERLOGGED, false).with(StairsBlock.SHAPE, StairsShape.STRAIGHT).with(StairsBlock.HALF, Half.TOP), 37, 7, -19, start);
        structure.setBlockState(world, Blocks.SNOW.getDefaultState().with(SnowBlock.LAYERS, 1), 37, 8, -33, start);
        structure.setBlockState(world, Blocks.SNOW.getDefaultState().with(SnowBlock.LAYERS, 1), 37, 8, -19, start);
        structure.setBlockState(world, Blocks.COAL_ORE.getDefaultState(), 38, -7, -63, start);
        structure.setBlockState(world, Blocks.COAL_ORE.getDefaultState(), 38, -7, 52, start);
        structure.setBlockState(world, Blocks.DIRT.getDefaultState(), 38, -7, 78, start);
        structure.setBlockState(world, Blocks.GRASS_BLOCK.getDefaultState().with(SnowyDirtBlock.SNOWY, true), 38, -6, 78, start);
        structure.setBlockState(world, Blocks.SNOW.getDefaultState().with(SnowBlock.LAYERS, 1), 38, -5, 78, start);
        structure.setBlockState(world, Blocks.ICE.getDefaultState(), 38, -3, -52, start);
        structure.setBlockState(world, Blocks.DIRT.getDefaultState(), 38, -1, 7, start);
        structure.setBlockState(world, Blocks.GRASS_BLOCK.getDefaultState().with(SnowyDirtBlock.SNOWY, true), 38, -1, 31, start);
        structure.setBlockState(world, Blocks.COBBLESTONE_WALL.getDefaultState().with(WallBlock.WATERLOGGED, false).with(WallBlock.UP, true).with(WallBlock.WALL_HEIGHT_NORTH, WallHeight.LOW).with(WallBlock.WALL_HEIGHT_SOUTH, WallHeight.LOW).with(WallBlock.WALL_HEIGHT_EAST, WallHeight.LOW).with(WallBlock.WALL_HEIGHT_WEST, WallHeight.LOW), 38, 0, -39, start);
        structure.setBlockState(world, Blocks.COBBLESTONE_WALL.getDefaultState().with(WallBlock.WATERLOGGED, false).with(WallBlock.UP, true).with(WallBlock.WALL_HEIGHT_NORTH, WallHeight.LOW).with(WallBlock.WALL_HEIGHT_SOUTH, WallHeight.LOW).with(WallBlock.WALL_HEIGHT_EAST, WallHeight.LOW).with(WallBlock.WALL_HEIGHT_WEST, WallHeight.LOW), 38, 0, -34, start);
        structure.setBlockState(world, Index.BEDSIDE_TABLE_OAK.getDefaultState().with(BedsideTable.FACING, Direction.NORTH).with(BedsideTable.WATERLOGGED, false), 38, 0, -31, start);
        structure.setBlockState(world, Index.COUNTER_OAK_ANDESITE.getDefaultState().with(Counter.FACING, Direction.WEST).with(Counter.WATERLOGGED, false), 38, 0, -24, start);
        structure.setBlockState(world, Blocks.FURNACE.getDefaultState().with(AbstractFurnaceBlock.FACING, Direction.WEST).with(AbstractFurnaceBlock.LIT, false), 38, 0, -23, start);
        structure.setBlockState(world, Blocks.CRAFTING_TABLE.getDefaultState(), 38, 0, -22, start);
        structure.setBlockState(world, Index.COUNTER_OAK_ANDESITE.getDefaultState().with(Counter.FACING, Direction.WEST).with(Counter.WATERLOGGED, false), 38, 0, -21, start);
        structure.setBlockState(world, Blocks.COBBLESTONE_WALL.getDefaultState().with(WallBlock.WATERLOGGED, false).with(WallBlock.UP, false).with(WallBlock.WALL_HEIGHT_NORTH, WallHeight.LOW).with(WallBlock.WALL_HEIGHT_SOUTH, WallHeight.LOW).with(WallBlock.WALL_HEIGHT_EAST, WallHeight.LOW).with(WallBlock.WALL_HEIGHT_WEST, WallHeight.LOW), 38, 0, -3, start);
        structure.setBlockState(world, Blocks.OAK_SLAB.getDefaultState().with(SlabBlock.TYPE, SlabType.BOTTOM).with(SlabBlock.WATERLOGGED, false), 38, 0, 30, start);
        structure.setBlockState(world, Blocks.YELLOW_CARPET.getDefaultState(), 38, 0, 31, start);
        structure.setBlockState(world, Blocks.OAK_SLAB.getDefaultState().with(SlabBlock.TYPE, SlabType.BOTTOM).with(SlabBlock.WATERLOGGED, false), 38, 0, 32, start);
        structure.setBlockState(world, Blocks.GRASS_BLOCK.getDefaultState().with(SnowyDirtBlock.SNOWY, true), 38, 0, 33, start);
        structure.setBlockState(world, Blocks.JUNGLE_FENCE_GATE.getDefaultState().with(FenceGateBlock.IN_WALL, false).with(FenceGateBlock.OPEN, false).with(FenceGateBlock.POWERED, false), 38, 0, 50, start);
        structure.setBlockState(world, Blocks.BARREL.getDefaultState().with(BarrelBlock.PROPERTY_FACING, Direction.NORTH).with(BarrelBlock.PROPERTY_OPEN, false), 38, 1, 14, start);
        structure.setBlockState(world, Blocks.HAY_BLOCK.getDefaultState(), 38, 1, 28, start);
        structure.setBlockState(world, Blocks.OAK_SLAB.getDefaultState().with(SlabBlock.TYPE, SlabType.BOTTOM).with(SlabBlock.WATERLOGGED, false), 38, 1, 29, start);
        structure.setBlockState(world, Blocks.HAY_BLOCK.getDefaultState(), 38, 1, 34, start);
        structure.setBlockState(world, Blocks.SNOW.getDefaultState().with(SnowBlock.LAYERS, 1), 38, 1, 49, start);
        structure.setBlockState(world, Blocks.OAK_LOG.getDefaultState(), 38, 2, -42, start);
        structure.setBlockState(world, Blocks.SPRUCE_TRAPDOOR.getDefaultState().with(HorizontalBlock.HORIZONTAL_FACING, Direction.NORTH).with(TrapDoorBlock.HALF, Half.BOTTOM).with(TrapDoorBlock.WATERLOGGED, false).with(TrapDoorBlock.POWERED, false).with(TrapDoorBlock.OPEN, false), 38, 2, -40, start);
        structure.setBlockState(world, Index.CANDLE.getDefaultState().with(Candle.FACING, Direction.WEST).with(Candle.LIT, true), 38, 2, -31, start);
        structure.setBlockState(world, Blocks.SPRUCE_SLAB.getDefaultState().with(SlabBlock.TYPE, SlabType.BOTTOM).with(SlabBlock.WATERLOGGED, false), 38, 2, 41, start);
        structure.setBlockState(world, Blocks.SPRUCE_LOG.getDefaultState(), 38, 2, 44, start);
        structure.setBlockState(world, Blocks.SPRUCE_TRAPDOOR.getDefaultState().with(HorizontalBlock.HORIZONTAL_FACING, Direction.SOUTH).with(TrapDoorBlock.HALF, Half.BOTTOM).with(TrapDoorBlock.WATERLOGGED, false).with(TrapDoorBlock.POWERED, false).with(TrapDoorBlock.OPEN, false), 38, 3, -47, start);
        structure.setBlockState(world, Blocks.SPRUCE_TRAPDOOR.getDefaultState().with(HorizontalBlock.HORIZONTAL_FACING, Direction.NORTH).with(TrapDoorBlock.HALF, Half.BOTTOM).with(TrapDoorBlock.WATERLOGGED, false).with(TrapDoorBlock.POWERED, false).with(TrapDoorBlock.OPEN, false), 38, 3, -42, start);
        structure.setBlockState(world, Blocks.DARK_OAK_STAIRS.getDefaultState().with(StairsBlock.FACING, Direction.EAST).with(StairsBlock.WATERLOGGED, false).with(StairsBlock.SHAPE, StairsShape.STRAIGHT).with(StairsBlock.HALF, Half.TOP), 38, 3, -33, start);
        structure.setBlockState(world, Blocks.DARK_OAK_STAIRS.getDefaultState().with(StairsBlock.FACING, Direction.EAST).with(StairsBlock.WATERLOGGED, false).with(StairsBlock.SHAPE, StairsShape.STRAIGHT).with(StairsBlock.HALF, Half.TOP), 38, 3, -19, start);
        structure.setBlockState(world, Blocks.DARK_OAK_STAIRS.getDefaultState().with(StairsBlock.FACING, Direction.WEST).with(StairsBlock.WATERLOGGED, false).with(StairsBlock.SHAPE, StairsShape.STRAIGHT).with(StairsBlock.HALF, Half.TOP), 38, 3, 6, start);
        structure.setBlockState(world, Blocks.DARK_OAK_SLAB.getDefaultState().with(SlabBlock.TYPE, SlabType.BOTTOM).with(SlabBlock.WATERLOGGED, false), 38, 3, 7, start);
        structure.setBlockState(world, Blocks.DARK_OAK_STAIRS.getDefaultState().with(StairsBlock.FACING, Direction.WEST).with(StairsBlock.WATERLOGGED, false).with(StairsBlock.SHAPE, StairsShape.STRAIGHT).with(StairsBlock.HALF, Half.TOP), 38, 3, 16, start);
        structure.setBlockState(world, Blocks.DARK_OAK_STAIRS.getDefaultState().with(StairsBlock.FACING, Direction.EAST).with(StairsBlock.WATERLOGGED, false).with(StairsBlock.SHAPE, StairsShape.STRAIGHT).with(StairsBlock.HALF, Half.TOP), 38, 3, 26, start);
        structure.setBlockState(world, Blocks.DARK_OAK_STAIRS.getDefaultState().with(StairsBlock.FACING, Direction.EAST).with(StairsBlock.WATERLOGGED, false).with(StairsBlock.SHAPE, StairsShape.STRAIGHT).with(StairsBlock.HALF, Half.TOP), 38, 3, 36, start);
        structure.setBlockState(world, Blocks.SPRUCE_SLAB.getDefaultState().with(SlabBlock.TYPE, SlabType.BOTTOM).with(SlabBlock.WATERLOGGED, false), 38, 3, 44, start);
        structure.setBlockState(world, Blocks.SPRUCE_TRAPDOOR.getDefaultState().with(HorizontalBlock.HORIZONTAL_FACING, Direction.NORTH).with(TrapDoorBlock.HALF, Half.BOTTOM).with(TrapDoorBlock.WATERLOGGED, false).with(TrapDoorBlock.POWERED, false).with(TrapDoorBlock.OPEN, false), 38, 3, 48, start);
        structure.setBlockState(world, Blocks.SPRUCE_SLAB.getDefaultState().with(SlabBlock.TYPE, SlabType.BOTTOM).with(SlabBlock.WATERLOGGED, false), 38, 4, -46, start);
        structure.setBlockState(world, Blocks.DARK_OAK_STAIRS.getDefaultState().with(StairsBlock.FACING, Direction.WEST).with(StairsBlock.WATERLOGGED, false).with(StairsBlock.SHAPE, StairsShape.STRAIGHT).with(StairsBlock.HALF, Half.BOTTOM), 38, 4, -33, start);
        structure.setBlockState(world, Blocks.DARK_OAK_STAIRS.getDefaultState().with(StairsBlock.FACING, Direction.WEST).with(StairsBlock.WATERLOGGED, false).with(StairsBlock.SHAPE, StairsShape.STRAIGHT).with(StairsBlock.HALF, Half.BOTTOM), 38, 4, -19, start);
        structure.setBlockState(world, Blocks.DARK_OAK_STAIRS.getDefaultState().with(StairsBlock.FACING, Direction.EAST).with(StairsBlock.WATERLOGGED, false).with(StairsBlock.SHAPE, StairsShape.STRAIGHT).with(StairsBlock.HALF, Half.BOTTOM), 38, 4, 6, start);
        structure.setBlockState(world, Blocks.DARK_OAK_STAIRS.getDefaultState().with(StairsBlock.FACING, Direction.EAST).with(StairsBlock.WATERLOGGED, false).with(StairsBlock.SHAPE, StairsShape.STRAIGHT).with(StairsBlock.HALF, Half.BOTTOM), 38, 4, 16, start);
        structure.setBlockState(world, Blocks.DARK_OAK_STAIRS.getDefaultState().with(StairsBlock.FACING, Direction.WEST).with(StairsBlock.WATERLOGGED, false).with(StairsBlock.SHAPE, StairsShape.STRAIGHT).with(StairsBlock.HALF, Half.BOTTOM), 38, 4, 26, start);
        structure.setBlockState(world, Blocks.DARK_OAK_STAIRS.getDefaultState().with(StairsBlock.FACING, Direction.WEST).with(StairsBlock.WATERLOGGED, false).with(StairsBlock.SHAPE, StairsShape.STRAIGHT).with(StairsBlock.HALF, Half.BOTTOM), 38, 4, 36, start);
        structure.setBlockState(world, Blocks.SPRUCE_SLAB.getDefaultState().with(SlabBlock.TYPE, SlabType.BOTTOM).with(SlabBlock.WATERLOGGED, false), 38, 4, 47, start);
        structure.setBlockState(world, Blocks.SNOW.getDefaultState().with(SnowBlock.LAYERS, 1), 38, 5, -32, start);
        structure.setBlockState(world, Blocks.OAK_STAIRS.getDefaultState().with(StairsBlock.FACING, Direction.WEST).with(StairsBlock.WATERLOGGED, false).with(StairsBlock.SHAPE, StairsShape.STRAIGHT).with(StairsBlock.HALF, Half.BOTTOM), 38, 5, -31, start);
        structure.setBlockState(world, Blocks.OAK_STAIRS.getDefaultState().with(StairsBlock.FACING, Direction.SOUTH).with(StairsBlock.WATERLOGGED, false).with(StairsBlock.SHAPE, StairsShape.STRAIGHT).with(StairsBlock.HALF, Half.BOTTOM), 38, 5, -30, start);
        structure.setBlockState(world, Blocks.OAK_STAIRS.getDefaultState().with(StairsBlock.FACING, Direction.NORTH).with(StairsBlock.WATERLOGGED, false).with(StairsBlock.SHAPE, StairsShape.STRAIGHT).with(StairsBlock.HALF, Half.BOTTOM), 38, 5, -22, start);
        structure.setBlockState(world, Blocks.OAK_STAIRS.getDefaultState().with(StairsBlock.FACING, Direction.WEST).with(StairsBlock.WATERLOGGED, false).with(StairsBlock.SHAPE, StairsShape.STRAIGHT).with(StairsBlock.HALF, Half.BOTTOM), 38, 5, -21, start);
        structure.setBlockState(world, Blocks.SNOW.getDefaultState().with(SnowBlock.LAYERS, 1), 38, 5, -20, start);
        structure.setBlockState(world, Blocks.SNOW.getDefaultState().with(SnowBlock.LAYERS, 1), 38, 5, 7, start);
        structure.setBlockState(world, Blocks.OAK_STAIRS.getDefaultState().with(StairsBlock.FACING, Direction.EAST).with(StairsBlock.WATERLOGGED, false).with(StairsBlock.SHAPE, StairsShape.STRAIGHT).with(StairsBlock.HALF, Half.BOTTOM), 38, 5, 8, start);
        structure.setBlockState(world, Blocks.OAK_STAIRS.getDefaultState().with(StairsBlock.FACING, Direction.SOUTH).with(StairsBlock.WATERLOGGED, false).with(StairsBlock.SHAPE, StairsShape.STRAIGHT).with(StairsBlock.HALF, Half.BOTTOM), 38, 5, 9, start);
        structure.setBlockState(world, Blocks.OAK_STAIRS.getDefaultState().with(StairsBlock.FACING, Direction.NORTH).with(StairsBlock.WATERLOGGED, false).with(StairsBlock.SHAPE, StairsShape.STRAIGHT).with(StairsBlock.HALF, Half.BOTTOM), 38, 5, 13, start);
        structure.setBlockState(world, Blocks.OAK_STAIRS.getDefaultState().with(StairsBlock.FACING, Direction.EAST).with(StairsBlock.WATERLOGGED, false).with(StairsBlock.SHAPE, StairsShape.STRAIGHT).with(StairsBlock.HALF, Half.BOTTOM), 38, 5, 14, start);
        structure.setBlockState(world, Blocks.SNOW.getDefaultState().with(SnowBlock.LAYERS, 1), 38, 5, 15, start);
        structure.setBlockState(world, Blocks.DARK_OAK_STAIRS.getDefaultState().with(StairsBlock.FACING, Direction.WEST).with(StairsBlock.WATERLOGGED, false).with(StairsBlock.SHAPE, StairsShape.STRAIGHT).with(StairsBlock.HALF, Half.TOP), 38, 5, 26, start);
        structure.setBlockState(world, Blocks.SNOW.getDefaultState().with(SnowBlock.LAYERS, 1), 38, 5, 27, start);
        structure.setBlockState(world, Blocks.OAK_STAIRS.getDefaultState().with(StairsBlock.FACING, Direction.WEST).with(StairsBlock.WATERLOGGED, false).with(StairsBlock.SHAPE, StairsShape.STRAIGHT).with(StairsBlock.HALF, Half.BOTTOM), 38, 5, 28, start);
        structure.setBlockState(world, Blocks.OAK_STAIRS.getDefaultState().with(StairsBlock.FACING, Direction.SOUTH).with(StairsBlock.WATERLOGGED, false).with(StairsBlock.SHAPE, StairsShape.STRAIGHT).with(StairsBlock.HALF, Half.BOTTOM), 38, 5, 29, start);
        structure.setBlockState(world, Blocks.OAK_STAIRS.getDefaultState().with(StairsBlock.FACING, Direction.NORTH).with(StairsBlock.WATERLOGGED, false).with(StairsBlock.SHAPE, StairsShape.STRAIGHT).with(StairsBlock.HALF, Half.BOTTOM), 38, 5, 33, start);
        structure.setBlockState(world, Blocks.OAK_STAIRS.getDefaultState().with(StairsBlock.FACING, Direction.WEST).with(StairsBlock.WATERLOGGED, false).with(StairsBlock.SHAPE, StairsShape.STRAIGHT).with(StairsBlock.HALF, Half.BOTTOM), 38, 5, 34, start);
        structure.setBlockState(world, Blocks.SNOW.getDefaultState().with(SnowBlock.LAYERS, 1), 38, 5, 35, start);
