package mod.arcalitegames.odyssey.world.structure.town.saxon_snow;

import mod.arcalitegames.buildersaddition.Index;
import mod.arcalitegames.buildersaddition.blocks.Bookshelf;
import mod.arcalitegames.buildersaddition.blocks.Cabinet;
import mod.arcalitegames.buildersaddition.blocks.Cupboard;
import mod.arcalitegames.buildersaddition.blocks.IronFence;
import mod.arcalitegames.buildersaddition.blocks.Shelf;
import mod.arcalitegames.buildersaddition.blocks.Stool;
import mod.arcalitegames.buildersaddition.blocks.SupportBracket;
import mod.arcalitegames.buildersaddition.state.MountState;
import mod.arcalitegames.buildersaddition.state.StoolState;
import mod.arcalitegames.odyssey.world.structure.StructureBase;
import net.minecraft.block.BarrelBlock;
import net.minecraft.block.BedBlock;
import net.minecraft.block.BeetrootBlock;
import net.minecraft.block.Blocks;
import net.minecraft.block.BrewingStandBlock;
import net.minecraft.block.CakeBlock;
import net.minecraft.block.CampfireBlock;
import net.minecraft.block.CauldronBlock;
import net.minecraft.block.ChainBlock;
import net.minecraft.block.ComposterBlock;
import net.minecraft.block.CropsBlock;
import net.minecraft.block.FarmlandBlock;
import net.minecraft.block.FenceGateBlock;
import net.minecraft.block.FourWayBlock;
import net.minecraft.block.HorizontalBlock;
import net.minecraft.block.NetherWartBlock;
import net.minecraft.block.RedstoneTorchBlock;
import net.minecraft.block.SlabBlock;
import net.minecraft.block.SnowBlock;
import net.minecraft.block.SnowyDirtBlock;
import net.minecraft.block.StairsBlock;
import net.minecraft.block.TrapDoorBlock;
import net.minecraft.block.WallBlock;
import net.minecraft.block.WallHeight;
import net.minecraft.state.properties.BedPart;
import net.minecraft.state.properties.DoubleBlockHalf;
import net.minecraft.state.properties.Half;
import net.minecraft.state.properties.SlabType;
import net.minecraft.state.properties.StairsShape;
import net.minecraft.util.Direction;
import net.minecraft.util.math.BlockPos;
import net.minecraft.world.World;

public class SaxonSnowComponent2
{

	public static BlockPos start;
    public static World world;
    public static StructureBase structure;

    public static void init(World worldIn, BlockPos blockPos, StructureBase structureIn)
    {
        world = worldIn; start = blockPos; structure = structureIn;
    }
    
    public static void generatePart21()
    {
        structure.fillWithBlocks(world, start, 2, 0, -49, 2, 2, -49, Blocks.OAK_LOG.getDefaultState());
        structure.fillWithBlocks(world, start, 2, 0, -48, 3, 1, -48, Blocks.SPRUCE_LOG.getDefaultState());
        structure.fillWithBlocks(world, start, 2, 0, -47, 4, 1, -47, Blocks.OAK_LOG.getDefaultState());
        structure.fillWithBlocks(world, start, 2, 0, -46, 3, 1, -46, Blocks.SPRUCE_LOG.getDefaultState());
        structure.fillWithBlocks(world, start, 2, 0, -45, 2, 3, -45, Blocks.OAK_LOG.getDefaultState());
        structure.fillWithBlocks(world, start, 2, 0, -43, 3, 0, -41, Blocks.SNOW.getDefaultState().with(SnowBlock.LAYERS, 1));
        structure.fillWithBlocks(world, start, 2, 0, -40, 2, 0, -34, Blocks.SNOW.getDefaultState().with(SnowBlock.LAYERS, 1));
        structure.fillWithBlocks(world, start, 2, 0, -32, 2, 0, -31, Blocks.SNOW.getDefaultState().with(SnowBlock.LAYERS, 1));
        structure.fillWithBlocks(world, start, 2, 0, -27, 2, 0, -26, Blocks.SNOW.getDefaultState().with(SnowBlock.LAYERS, 1));
        structure.fillWithBlocks(world, start, 2, 0, -24, 2, 0, -23, Blocks.SNOW.getDefaultState().with(SnowBlock.LAYERS, 1));
        structure.fillWithBlocks(world, start, 2, 0, -18, 2, 0, -8, Blocks.SNOW.getDefaultState().with(SnowBlock.LAYERS, 1));
        structure.fillWithBlocks(world, start, 2, 0, -6, 2, 0, -3, Blocks.SNOW.getDefaultState().with(SnowBlock.LAYERS, 1));
        structure.fillWithBlocks(world, start, 2, 0, 2, 4, 0, 4, Blocks.SNOW.getDefaultState().with(SnowBlock.LAYERS, 1));
        structure.fillWithBlocks(world, start, 2, 0, 6, 3, 0, 6, Blocks.BARREL.getDefaultState().with(BarrelBlock.PROPERTY_FACING, Direction.UP).with(BarrelBlock.PROPERTY_OPEN, false));
        structure.fillWithBlocks(world, start, 2, 0, 7, 2, 0, 11, Blocks.SNOW.getDefaultState().with(SnowBlock.LAYERS, 1));
        structure.fillWithBlocks(world, start, 2, 0, 17, 2, 0, 30, Blocks.SNOW.getDefaultState().with(SnowBlock.LAYERS, 1));
        structure.fillWithBlocks(world, start, 2, 0, 33, 2, 0, 46, Blocks.SNOW.getDefaultState().with(SnowBlock.LAYERS, 1));
        structure.fillWithBlocks(world, start, 2, 0, 48, 2, 3, 48, Blocks.OAK_LOG.getDefaultState());
        structure.fillWithBlocks(world, start, 2, 0, 49, 2, 5, 49, Blocks.SPRUCE_LOG.getDefaultState());
        structure.fillWithBlocks(world, start, 2, 0, 50, 2, 2, 50, Blocks.OAK_LOG.getDefaultState());
        structure.fillWithBlocks(world, start, 2, 0, 51, 2, 2, 51, Blocks.SPRUCE_LOG.getDefaultState());
        structure.fillWithBlocks(world, start, 2, 0, 52, 2, 2, 52, Blocks.OAK_LOG.getDefaultState());
        structure.fillWithBlocks(world, start, 2, 0, 53, 2, 8, 53, Blocks.SPRUCE_LOG.getDefaultState());
        structure.fillWithBlocks(world, start, 2, 0, 54, 4, 2, 54, Blocks.OAK_LOG.getDefaultState());
        structure.fillWithBlocks(world, start, 2, 0, 55, 3, 1, 55, Blocks.SPRUCE_LOG.getDefaultState());
        structure.fillWithBlocks(world, start, 2, 0, 56, 2, 3, 56, Blocks.OAK_LOG.getDefaultState());
        structure.fillWithBlocks(world, start, 2, 1, 6, 2, 1, 6, Blocks.SNOW.getDefaultState().with(SnowBlock.LAYERS, 1));
        structure.fillWithBlocks(world, start, 2, 2, -48, 3, 2, -48, Blocks.SPRUCE_LOG.getDefaultState());
        structure.fillWithBlocks(world, start, 2, 2, -47, 3, 2, -47, Blocks.OAK_LOG.getDefaultState());
        structure.fillWithBlocks(world, start, 2, 2, -46, 3, 3, -46, Blocks.SPRUCE_LOG.getDefaultState());
        structure.fillWithBlocks(world, start, 2, 2, 55, 3, 3, 55, Blocks.SPRUCE_LOG.getDefaultState());
        structure.fillWithBlocks(world, start, 2, 3, -48, 2, 7, -48, Blocks.SPRUCE_LOG.getDefaultState());
        structure.fillWithBlocks(world, start, 2, 3, -47, 3, 3, -47, Blocks.SPRUCE_PLANKS.getDefaultState());
        structure.fillWithBlocks(world, start, 2, 3, 51, 2, 3, 52, Blocks.SPRUCE_SLAB.getDefaultState().with(SlabBlock.TYPE, SlabType.DOUBLE).with(SlabBlock.WATERLOGGED, false));
        structure.fillWithBlocks(world, start, 2, 3, 54, 2, 4, 54, Blocks.SPRUCE_SLAB.getDefaultState().with(SlabBlock.TYPE, SlabType.DOUBLE).with(SlabBlock.WATERLOGGED, false));
        structure.fillWithBlocks(world, start, 2, 4, -46, 2, 5, -46, Blocks.OAK_LOG.getDefaultState());
        structure.fillWithBlocks(world, start, 2, 4, 51, 2, 8, 51, Blocks.SPRUCE_LOG.getDefaultState());
        structure.fillWithBlocks(world, start, 2, 7, -49, 2, 8, -49, Blocks.SPRUCE_LOG.getDefaultState());
        structure.fillWithBlocks(world, start, 2, 7, 49, 2, 7, 50, Blocks.SPRUCE_SLAB.getDefaultState().with(SlabBlock.TYPE, SlabType.TOP).with(SlabBlock.WATERLOGGED, false));
        structure.fillWithBlocks(world, start, 3, -7, -75, 15, -7, -75, Blocks.GRASS_BLOCK.getDefaultState().with(SnowyDirtBlock.SNOWY, true));
        structure.fillWithBlocks(world, start, 3, -7, -74, 4, -7, -73, Blocks.DIRT.getDefaultState());
        structure.fillWithBlocks(world, start, 3, -7, -59, 5, -7, -46, Blocks.STONE.getDefaultState());
        structure.fillWithBlocks(world, start, 3, -7, -24, 9, -7, -18, Blocks.STONE.getDefaultState());
        structure.fillWithBlocks(world, start, 3, -7, 0, 4, -7, 10, Blocks.DIORITE.getDefaultState());
        structure.fillWithBlocks(world, start, 3, -7, 24, 3, -6, 24, Blocks.IRON_ORE.getDefaultState());
        structure.fillWithBlocks(world, start, 3, -7, 25, 9, -7, 32, Blocks.STONE.getDefaultState());
        structure.fillWithBlocks(world, start, 3, -7, 33, 4, -7, 64, Blocks.STONE.getDefaultState());
        structure.fillWithBlocks(world, start, 3, -6, -75, 15, -6, -75, Blocks.SNOW.getDefaultState().with(SnowBlock.LAYERS, 1));
        structure.fillWithBlocks(world, start, 3, -6, -73, 4, -6, -72, Blocks.DIRT.getDefaultState());
        structure.fillWithBlocks(world, start, 3, -6, -71, 3, -6, -60, Blocks.DIORITE.getDefaultState());
        structure.fillWithBlocks(world, start, 3, -6, -59, 4, -6, -58, Blocks.STONE.getDefaultState());
        structure.fillWithBlocks(world, start, 3, -6, -57, 4, -6, -56, Blocks.DIRT.getDefaultState());
        structure.fillWithBlocks(world, start, 3, -6, -55, 3, -5, -54, Blocks.DIRT.getDefaultState());
        structure.fillWithBlocks(world, start, 3, -6, -53, 4, -6, -53, Blocks.IRON_ORE.getDefaultState());
        structure.fillWithBlocks(world, start, 3, -6, -32, 10, -6, -18, Blocks.STONE.getDefaultState());
        structure.fillWithBlocks(world, start, 3, -6, -17, 3, -6, -16, Blocks.COAL_ORE.getDefaultState());
        structure.fillWithBlocks(world, start, 3, -6, -15, 7, -6, -11, Blocks.STONE.getDefaultState());
        structure.fillWithBlocks(world, start, 3, -6, -10, 4, -6, -1, Blocks.STONE.getDefaultState());
        structure.fillWithBlocks(world, start, 3, -6, 0, 3, -6, 2, Blocks.DIORITE.getDefaultState());
        structure.fillWithBlocks(world, start, 3, -6, 3, 6, -6, 7, Blocks.GRANITE.getDefaultState());
        structure.fillWithBlocks(world, start, 3, -6, 23, 3, -6, 23, Blocks.STONE.getDefaultState());
        structure.fillWithBlocks(world, start, 3, -6, 25, 4, -6, 25, Blocks.IRON_ORE.getDefaultState());
        structure.fillWithBlocks(world, start, 3, -6, 26, 3, -6, 26, Blocks.STONE.getDefaultState());
        structure.fillWithBlocks(world, start, 3, -6, 27, 3, -6, 43, Blocks.DIRT.getDefaultState());
        structure.fillWithBlocks(world, start, 3, -6, 59, 4, -6, 60, Blocks.DIRT.getDefaultState());
        structure.fillWithBlocks(world, start, 3, -6, 65, 4, -6, 66, Blocks.COAL_ORE.getDefaultState());
        structure.fillWithBlocks(world, start, 3, -6, 67, 7, -6, 71, Blocks.STONE.getDefaultState());
        structure.fillWithBlocks(world, start, 3, -6, 72, 4, -6, 73, Blocks.DIRT.getDefaultState());
        structure.fillWithBlocks(world, start, 3, -6, 74, 4, -6, 75, Blocks.GRASS_BLOCK.getDefaultState().with(SnowyDirtBlock.SNOWY, true));
        structure.fillWithBlocks(world, start, 3, -5, -23, 4, -5, -15, Blocks.STONE.getDefaultState());
        structure.fillWithBlocks(world, start, 3, -5, -14, 16, -5, 22, Blocks.DIRT.getDefaultState());
        structure.fillWithBlocks(world, start, 3, -5, 74, 4, -5, 75, Blocks.SNOW.getDefaultState().with(SnowBlock.LAYERS, 1));
        structure.fillWithBlocks(world, start, 3, -2, -70, 46, -2, -70, Blocks.GRASS_BLOCK.getDefaultState().with(SnowyDirtBlock.SNOWY, true));
        structure.fillWithBlocks(world, start, 3, -2, -69, 12, -2, -60, Blocks.DIRT.getDefaultState());
        structure.fillWithBlocks(world, start, 3, -1, -70, 46, -1, -70, Blocks.SNOW.getDefaultState().with(SnowBlock.LAYERS, 1));
        structure.fillWithBlocks(world, start, 3, -1, -69, 12, -1, -60, Blocks.GRASS_BLOCK.getDefaultState().with(SnowyDirtBlock.SNOWY, true));
        structure.fillWithBlocks(world, start, 3, -1, -45, 5, -1, -41, Blocks.GRASS_BLOCK.getDefaultState().with(SnowyDirtBlock.SNOWY, true));
        structure.fillWithBlocks(world, start, 3, -1, -39, 4, -1, -38, Blocks.GRASS_BLOCK.getDefaultState().with(SnowyDirtBlock.SNOWY, true));
        structure.fillWithBlocks(world, start, 3, -1, -37, 3, -1, -37, Blocks.DIRT.getDefaultState());
        structure.fillWithBlocks(world, start, 3, -1, -36, 3, -1, -31, Blocks.GRASS_BLOCK.getDefaultState().with(SnowyDirtBlock.SNOWY, true));
        structure.fillWithBlocks(world, start, 3, -1, -25, 3, -1, -21, Blocks.GRASS_BLOCK.getDefaultState().with(SnowyDirtBlock.SNOWY, true));
        structure.fillWithBlocks(world, start, 3, -1, -19, 3, -1, -18, Blocks.GRASS_BLOCK.getDefaultState().with(SnowyDirtBlock.SNOWY, false));
        structure.fillWithBlocks(world, start, 3, -1, -17, 4, -1, -11, Blocks.GRASS_BLOCK.getDefaultState().with(SnowyDirtBlock.SNOWY, true));
        structure.fillWithBlocks(world, start, 3, -1, -10, 3, -1, -8, Blocks.GRASS_BLOCK.getDefaultState().with(SnowyDirtBlock.SNOWY, true));
        structure.fillWithBlocks(world, start, 3, -1, -1, 5, -1, 1, Blocks.GRASS_PATH.getDefaultState());
        structure.fillWithBlocks(world, start, 3, -1, 5, 3, -1, 7, Blocks.DIRT.getDefaultState());
        structure.fillWithBlocks(world, start, 3, -1, 8, 5, -1, 11, Blocks.GRASS_BLOCK.getDefaultState().with(SnowyDirtBlock.SNOWY, true));
        structure.fillWithBlocks(world, start, 3, -1, 16, 5, -1, 24, Blocks.GRASS_BLOCK.getDefaultState().with(SnowyDirtBlock.SNOWY, true));
        structure.fillWithBlocks(world, start, 3, -1, 26, 4, -1, 28, Blocks.GRASS_BLOCK.getDefaultState().with(SnowyDirtBlock.SNOWY, true));
        structure.fillWithBlocks(world, start, 3, -1, 30, 4, -1, 30, Blocks.GRASS_BLOCK.getDefaultState().with(SnowyDirtBlock.SNOWY, true));
        structure.fillWithBlocks(world, start, 3, -1, 31, 4, -1, 31, Blocks.GRASS_PATH.getDefaultState());
        structure.fillWithBlocks(world, start, 3, -1, 32, 4, -1, 33, Blocks.GRASS_BLOCK.getDefaultState().with(SnowyDirtBlock.SNOWY, true));
        structure.fillWithBlocks(world, start, 3, -1, 35, 5, -1, 37, Blocks.GRASS_BLOCK.getDefaultState().with(SnowyDirtBlock.SNOWY, true));
        structure.fillWithBlocks(world, start, 3, -1, 38, 3, -1, 48, Blocks.GRASS_BLOCK.getDefaultState().with(SnowyDirtBlock.SNOWY, true));
        structure.fillWithBlocks(world, start, 3, -1, 49, 3, -1, 49, Blocks.DIRT.getDefaultState());
        structure.fillWithBlocks(world, start, 3, -1, 51, 8, -1, 51, Blocks.DIRT.getDefaultState());
        structure.fillWithBlocks(world, start, 3, -1, 52, 3, -1, 53, Blocks.GRASS_BLOCK.getDefaultState().with(SnowyDirtBlock.SNOWY, true));
        structure.fillWithBlocks(world, start, 3, -1, 54, 4, -1, 56, Blocks.DIRT.getDefaultState());
        structure.fillWithBlocks(world, start, 3, 0, -69, 12, 0, -60, Blocks.SNOW.getDefaultState().with(SnowBlock.LAYERS, 1));
        structure.fillWithBlocks(world, start, 3, 0, -53, 8, 0, -53, Blocks.GRASS_BLOCK.getDefaultState().with(SnowyDirtBlock.SNOWY, true));
        structure.fillWithBlocks(world, start, 3, 0, -52, 4, 1, -52, Blocks.OAK_LOG.getDefaultState());
        structure.fillWithBlocks(world, start, 3, 0, -51, 3, 0, -49, Blocks.DIRT.getDefaultState());
        structure.fillWithBlocks(world, start, 3, 0, -44, 5, 0, -42, Blocks.SNOW.getDefaultState().with(SnowBlock.LAYERS, 1));
        structure.fillWithBlocks(world, start, 3, 0, -39, 3, 0, -38, Blocks.SNOW.getDefaultState().with(SnowBlock.LAYERS, 1));
        structure.fillWithBlocks(world, start, 3, 0, -17, 3, 0, -12, Blocks.SNOW.getDefaultState().with(SnowBlock.LAYERS, 1));
        structure.fillWithBlocks(world, start, 3, 0, -8, 3, 1, -8, Blocks.DARK_OAK_FENCE.getDefaultState().with(FourWayBlock.WATERLOGGED, false).with(FourWayBlock.NORTH, false).with(FourWayBlock.SOUTH, false).with(FourWayBlock.EAST, true).with(FourWayBlock.WEST, false));
        structure.fillWithBlocks(world, start, 3, 0, -6, 3, 1, -6, Blocks.DARK_OAK_FENCE.getDefaultState().with(FourWayBlock.WATERLOGGED, false).with(FourWayBlock.NORTH, false).with(FourWayBlock.SOUTH, false).with(FourWayBlock.EAST, true).with(FourWayBlock.WEST, false));
        structure.fillWithBlocks(world, start, 3, 0, 8, 5, 0, 11, Blocks.SNOW.getDefaultState().with(SnowBlock.LAYERS, 1));
        structure.fillWithBlocks(world, start, 3, 0, 16, 3, 0, 17, Blocks.SNOW.getDefaultState().with(SnowBlock.LAYERS, 1));
        structure.fillWithBlocks(world, start, 3, 0, 19, 5, 0, 23, Blocks.SNOW.getDefaultState().with(SnowBlock.LAYERS, 1));
        structure.fillWithBlocks(world, start, 3, 0, 26, 3, 0, 28, Blocks.SNOW.getDefaultState().with(SnowBlock.LAYERS, 1));
        structure.fillWithBlocks(world, start, 3, 0, 32, 3, 0, 33, Blocks.SNOW.getDefaultState().with(SnowBlock.LAYERS, 1));
        structure.fillWithBlocks(world, start, 3, 0, 35, 3, 0, 36, Blocks.SNOW.getDefaultState().with(SnowBlock.LAYERS, 1));
        structure.fillWithBlocks(world, start, 3, 0, 46, 4, 0, 47, Blocks.SNOW.getDefaultState().with(SnowBlock.LAYERS, 1));
        structure.fillWithBlocks(world, start, 3, 0, 49, 3, 4, 49, Blocks.OAK_LOG.getDefaultState());
        structure.fillWithBlocks(world, start, 3, 0, 51, 3, 2, 51, Blocks.OAK_LOG.getDefaultState());
        structure.fillWithBlocks(world, start, 3, 0, 56, 4, 0, 56, Blocks.GRASS_BLOCK.getDefaultState().with(SnowyDirtBlock.SNOWY, true));
        structure.fillWithBlocks(world, start, 3, 1, -51, 3, 1, -49, Blocks.DIRT.getDefaultState());
        structure.fillWithBlocks(world, start, 3, 1, 5, 3, 1, 5, Blocks.SNOW.getDefaultState().with(SnowBlock.LAYERS, 1));
        structure.fillWithBlocks(world, start, 3, 2, -52, 4, 2, -52, Blocks.OAK_LOG.getDefaultState());
        structure.fillWithBlocks(world, start, 3, 2, -51, 3, 2, -50, Blocks.DIRT.getDefaultState());
        structure.fillWithBlocks(world, start, 3, 2, -49, 7, 2, -49, Blocks.GRASS_BLOCK.getDefaultState().with(SnowyDirtBlock.SNOWY, true));
        structure.fillWithBlocks(world, start, 3, 2, -36, 3, 2, -31, Blocks.COBBLESTONE.getDefaultState());
        structure.fillWithBlocks(world, start, 3, 2, -27, 3, 3, -26, Blocks.COBBLESTONE.getDefaultState());
        structure.fillWithBlocks(world, start, 3, 2, -25, 3, 2, -22, Blocks.COBBLESTONE.getDefaultState());
        structure.fillWithBlocks(world, start, 3, 3, -52, 3, 5, -52, Blocks.OAK_LOG.getDefaultState());
        structure.fillWithBlocks(world, start, 3, 3, -36, 3, 3, -35, Blocks.SNOW.getDefaultState().with(SnowBlock.LAYERS, 1));
        structure.fillWithBlocks(world, start, 3, 3, -32, 4, 3, -26, Blocks.COBBLESTONE.getDefaultState());
        structure.fillWithBlocks(world, start, 3, 3, -23, 3, 3, -22, Blocks.SNOW.getDefaultState().with(SnowBlock.LAYERS, 1));
        structure.fillWithBlocks(world, start, 3, 3, 51, 3, 3, 51, Blocks.SPRUCE_SLAB.getDefaultState().with(SlabBlock.TYPE, SlabType.BOTTOM).with(SlabBlock.WATERLOGGED, false));
        structure.fillWithBlocks(world, start, 3, 3, 53, 3, 3, 53, Blocks.SPRUCE_SLAB.getDefaultState().with(SlabBlock.TYPE, SlabType.DOUBLE).with(SlabBlock.WATERLOGGED, false));
        structure.fillWithBlocks(world, start, 3, 3, 54, 3, 3, 54, Blocks.OAK_LOG.getDefaultState());
        structure.fillWithBlocks(world, start, 3, 4, -32, 3, 4, -26, Blocks.SNOW.getDefaultState().with(SnowBlock.LAYERS, 1));
        structure.fillWithBlocks(world, start, 3, 4, 53, 3, 4, 54, Blocks.SPRUCE_SLAB.getDefaultState().with(SlabBlock.TYPE, SlabType.BOTTOM).with(SlabBlock.WATERLOGGED, false));
        structure.fillWithBlocks(world, start, 3, 7, 51, 3, 7, 53, Blocks.SPRUCE_SLAB.getDefaultState().with(SlabBlock.TYPE, SlabType.TOP).with(SlabBlock.WATERLOGGED, false));
        structure.fillWithBlocks(world, start, 3, 8, -52, 4, 8, -52, Blocks.SNOW.getDefaultState().with(SnowBlock.LAYERS, 1));
        structure.fillWithBlocks(world, start, 3, 8, -50, 3, 8, -48, Blocks.SPRUCE_PLANKS.getDefaultState());
        structure.fillWithBlocks(world, start, 3, 8, -46, 4, 8, -46, Blocks.SNOW.getDefaultState().with(SnowBlock.LAYERS, 1));
        structure.fillWithBlocks(world, start, 3, 8, 51, 3, 8, 53, Blocks.SPRUCE_SLAB.getDefaultState().with(SlabBlock.TYPE, SlabType.DOUBLE).with(SlabBlock.WATERLOGGED, false));
        structure.fillWithBlocks(world, start, 4, -7, -61, 4, -6, -61, Blocks.DIORITE.getDefaultState());
        structure.fillWithBlocks(world, start, 4, -7, -60, 5, -7, -46, Blocks.STONE.getDefaultState());
        structure.fillWithBlocks(world, start, 4, -7, -28, 21, -7, -10, Blocks.STONE.getDefaultState());
        structure.fillWithBlocks(world, start, 4, -7, 24, 9, -7, 32, Blocks.STONE.getDefaultState());
        structure.fillWithBlocks(world, start, 4, -7, 65, 4, -6, 65, Blocks.COAL_ORE.getDefaultState());
        structure.fillWithBlocks(world, start, 4, -7, 66, 10, -7, 72, Blocks.STONE.getDefaultState());
        structure.fillWithBlocks(world, start, 4, -7, 76, 6, -7, 79, Blocks.GRASS_BLOCK.getDefaultState().with(SnowyDirtBlock.SNOWY, true));
        structure.fillWithBlocks(world, start, 4, -6, -71, 5, -6, -71, Blocks.DIORITE.getDefaultState());
        structure.fillWithBlocks(world, start, 4, -6, -70, 5, -6, -70, Blocks.WATER.getDefaultState());
        structure.fillWithBlocks(world, start, 4, -6, -60, 6, -6, -58, Blocks.STONE.getDefaultState());
        structure.fillWithBlocks(world, start, 4, -6, -55, 5, -6, -54, Blocks.STONE.getDefaultState());
        structure.fillWithBlocks(world, start, 4, -6, -17, 10, -6, -11, Blocks.STONE.getDefaultState());
        structure.fillWithBlocks(world, start, 4, -6, 1, 7, -6, 4, Blocks.GRANITE.getDefaultState());
        structure.fillWithBlocks(world, start, 4, -6, 9, 5, -6, 10, Blocks.DIORITE.getDefaultState());
        structure.fillWithBlocks(world, start, 4, -6, 11, 6, -6, 24, Blocks.STONE.getDefaultState());
        structure.fillWithBlocks(world, start, 4, -6, 26, 5, -6, 27, Blocks.STONE.getDefaultState());
        structure.fillWithBlocks(world, start, 4, -6, 28, 4, -2, 43, Blocks.DIRT.getDefaultState());
        structure.fillWithBlocks(world, start, 4, -6, 76, 6, -6, 79, Blocks.SNOW.getDefaultState().with(SnowBlock.LAYERS, 1));
        structure.fillWithBlocks(world, start, 4, -4, -71, 9, -4, -58, Blocks.DIRT.getDefaultState());
        structure.fillWithBlocks(world, start, 4, -4, -57, 5, -4, -56, Blocks.GRASS_BLOCK.getDefaultState().with(SnowyDirtBlock.SNOWY, false));
        structure.fillWithBlocks(world, start, 4, -4, 59, 4, -4, 60, Blocks.GRASS_BLOCK.getDefaultState().with(SnowyDirtBlock.SNOWY, false));
        structure.fillWithBlocks(world, start, 4, -3, -57, 4, -3, -56, Blocks.ICE.getDefaultState());
        structure.fillWithBlocks(world, start, 4, -2, 62, 11, -2, 69, Blocks.DIRT.getDefaultState());
        structure.fillWithBlocks(world, start, 4, -1, -46, 4, -1, -37, Blocks.GRASS_BLOCK.getDefaultState().with(SnowyDirtBlock.SNOWY, true));
        structure.fillWithBlocks(world, start, 4, -1, -36, 4, -1, -30, Blocks.DIRT.getDefaultState());
        structure.fillWithBlocks(world, start, 4, -1, -29, 4, -1, -29, Blocks.COBBLESTONE.getDefaultState());
        structure.fillWithBlocks(world, start, 4, -1, -28, 4, -1, -22, Blocks.DIRT.getDefaultState());
        structure.fillWithBlocks(world, start, 4, -1, -19, 4, -1, -11, Blocks.GRASS_BLOCK.getDefaultState().with(SnowyDirtBlock.SNOWY, true));
        structure.fillWithBlocks(world, start, 4, -1, -10, 4, -1, -8, Blocks.DIRT.getDefaultState());
        structure.fillWithBlocks(world, start, 4, -1, -7, 4, -1, -7, Blocks.POLISHED_ANDESITE.getDefaultState());
        structure.fillWithBlocks(world, start, 4, -1, -6, 4, -1, -4, Blocks.DIRT.getDefaultState());
        structure.fillWithBlocks(world, start, 4, -1, -3, 4, -1, -3, Blocks.GRASS_BLOCK.getDefaultState().with(SnowyDirtBlock.SNOWY, true));
        structure.fillWithBlocks(world, start, 4, -1, 5, 4, -1, 5, Blocks.GRASS_BLOCK.getDefaultState().with(SnowyDirtBlock.SNOWY, true));
        structure.fillWithBlocks(world, start, 4, -1, 7, 5, -1, 12, Blocks.GRASS_BLOCK.getDefaultState().with(SnowyDirtBlock.SNOWY, true));
        structure.fillWithBlocks(world, start, 4, -1, 13, 6, -1, 15, Blocks.GRASS_PATH.getDefaultState());
        structure.fillWithBlocks(world, start, 4, -1, 25, 4, -1, 30, Blocks.GRASS_BLOCK.getDefaultState().with(SnowyDirtBlock.SNOWY, true));
        structure.fillWithBlocks(world, start, 4, -1, 34, 4, -1, 37, Blocks.GRASS_BLOCK.getDefaultState().with(SnowyDirtBlock.SNOWY, true));
        structure.fillWithBlocks(world, start, 4, -1, 38, 4, -1, 40, Blocks.DIRT.getDefaultState());
        structure.fillWithBlocks(world, start, 4, -1, 41, 4, -1, 41, Blocks.COBBLESTONE.getDefaultState());
        structure.fillWithBlocks(world, start, 4, -1, 42, 4, -1, 44, Blocks.DIRT.getDefaultState());
        structure.fillWithBlocks(world, start, 4, -1, 45, 6, -1, 47, Blocks.GRASS_BLOCK.getDefaultState().with(SnowyDirtBlock.SNOWY, true));
        structure.fillWithBlocks(world, start, 4, -1, 48, 7, -1, 51, Blocks.DIRT.getDefaultState());
        structure.fillWithBlocks(world, start, 4, -1, 52, 9, -1, 52, Blocks.GRASS_BLOCK.getDefaultState().with(SnowyDirtBlock.SNOWY, true));
        structure.fillWithBlocks(world, start, 4, -1, 53, 6, -1, 55, Blocks.DIRT.getDefaultState());
        structure.fillWithBlocks(world, start, 4, -1, 62, 11, -1, 69, Blocks.GRASS_BLOCK.getDefaultState().with(SnowyDirtBlock.SNOWY, true));
        structure.fillWithBlocks(world, start, 4, 0, -51, 4, 4, -51, Blocks.SPRUCE_LOG.getDefaultState());
        structure.fillWithBlocks(world, start, 4, 0, -50, 5, 0, -49, Blocks.DIRT.getDefaultState());
        structure.fillWithBlocks(world, start, 4, 0, -48, 4, 1, -47, Blocks.OAK_LOG.getDefaultState());
        structure.fillWithBlocks(world, start, 4, 0, -36, 4, 2, -36, Blocks.STONE_BRICKS.getDefaultState());
        structure.fillWithBlocks(world, start, 4, 0, -35, 4, 1, -34, Blocks.BRICKS.getDefaultState());
        structure.fillWithBlocks(world, start, 4, 0, -33, 4, 2, -33, Blocks.STONE_BRICKS.getDefaultState());
        structure.fillWithBlocks(world, start, 4, 0, -32, 4, 1, -31, Blocks.BRICKS.getDefaultState());
        structure.fillWithBlocks(world, start, 4, 0, -30, 4, 2, -30, Blocks.STONE_BRICKS.getDefaultState());
        structure.fillWithBlocks(world, start, 4, 0, -28, 4, 2, -28, Blocks.STONE_BRICKS.getDefaultState());
        structure.fillWithBlocks(world, start, 4, 0, -27, 4, 1, -26, Blocks.BRICKS.getDefaultState());
        structure.fillWithBlocks(world, start, 4, 0, -25, 4, 2, -25, Blocks.STONE_BRICKS.getDefaultState());
        structure.fillWithBlocks(world, start, 4, 0, -24, 4, 1, -23, Blocks.BRICKS.getDefaultState());
        structure.fillWithBlocks(world, start, 4, 0, -22, 4, 2, -22, Blocks.STONE_BRICKS.getDefaultState());
        structure.fillWithBlocks(world, start, 4, 0, -18, 4, 0, -12, Blocks.COBBLESTONE_WALL.getDefaultState().with(WallBlock.WATERLOGGED, false).with(WallBlock.UP, false).with(WallBlock.WALL_HEIGHT_NORTH, WallHeight.LOW).with(WallBlock.WALL_HEIGHT_SOUTH, WallHeight.LOW).with(WallBlock.WALL_HEIGHT_EAST, WallHeight.LOW).with(WallBlock.WALL_HEIGHT_WEST, WallHeight.LOW));
        structure.fillWithBlocks(world, start, 4, 0, -10, 4, 2, -10, Blocks.SMOOTH_STONE.getDefaultState());
        structure.fillWithBlocks(world, start, 4, 0, -9, 4, 1, -9, Blocks.COBBLESTONE.getDefaultState());
        structure.fillWithBlocks(world, start, 4, 0, -8, 4, 3, -8, Blocks.SMOOTH_STONE.getDefaultState());
        structure.fillWithBlocks(world, start, 4, 0, -6, 4, 3, -6, Blocks.SMOOTH_STONE.getDefaultState());
        structure.fillWithBlocks(world, start, 4, 0, -5, 4, 1, -5, Blocks.COBBLESTONE.getDefaultState());
        structure.fillWithBlocks(world, start, 4, 0, -4, 4, 2, -4, Blocks.SMOOTH_STONE.getDefaultState());
        structure.fillWithBlocks(world, start, 4, 0, 5, 4, 0, 5, Blocks.SNOW.getDefaultState().with(SnowBlock.LAYERS, 1));
        structure.fillWithBlocks(world, start, 4, 0, 7, 5, 0, 12, Blocks.SNOW.getDefaultState().with(SnowBlock.LAYERS, 1));
        structure.fillWithBlocks(world, start, 4, 0, 16, 4, 0, 16, Blocks.SNOW.getDefaultState().with(SnowBlock.LAYERS, 1));
        structure.fillWithBlocks(world, start, 4, 0, 18, 5, 0, 23, Blocks.SNOW.getDefaultState().with(SnowBlock.LAYERS, 1));
        structure.fillWithBlocks(world, start, 4, 0, 36, 32, 0, 36, Blocks.SNOW.getDefaultState().with(SnowBlock.LAYERS, 1));
        structure.fillWithBlocks(world, start, 4, 0, 38, 4, 1, 39, Blocks.SPRUCE_LOG.getDefaultState());
        structure.fillWithBlocks(world, start, 4, 0, 40, 4, 1, 40, Blocks.OAK_PLANKS.getDefaultState());
        structure.fillWithBlocks(world, start, 4, 0, 42, 4, 1, 42, Blocks.OAK_PLANKS.getDefaultState());
        structure.fillWithBlocks(world, start, 4, 0, 43, 4, 1, 44, Blocks.SPRUCE_LOG.getDefaultState());
        structure.fillWithBlocks(world, start, 4, 0, 48, 4, 1, 48, Blocks.SPRUCE_LOG.getDefaultState());
        structure.fillWithBlocks(world, start, 4, 0, 49, 7, 0, 49, Blocks.DIRT.getDefaultState());
        structure.fillWithBlocks(world, start, 4, 0, 50, 4, 2, 50, Blocks.SPRUCE_LOG.getDefaultState());
        structure.fillWithBlocks(world, start, 4, 0, 51, 8, 1, 51, Blocks.DIRT.getDefaultState());
        structure.fillWithBlocks(world, start, 4, 0, 53, 4, 2, 53, Blocks.SPRUCE_LOG.getDefaultState());
        structure.fillWithBlocks(world, start, 4, 0, 55, 4, 4, 55, Blocks.OAK_LOG.getDefaultState());
        structure.fillWithBlocks(world, start, 4, 0, 62, 11, 0, 69, Blocks.SNOW.getDefaultState().with(SnowBlock.LAYERS, 1));
        structure.fillWithBlocks(world, start, 4, 1, -50, 5, 1, -49, Blocks.DIRT.getDefaultState());
        structure.fillWithBlocks(world, start, 4, 1, 49, 7, 1, 49, Blocks.GRASS_BLOCK.getDefaultState().with(SnowyDirtBlock.SNOWY, true));
        structure.fillWithBlocks(world, start, 4, 2, -50, 8, 2, -50, Blocks.DIRT.getDefaultState());
        structure.fillWithBlocks(world, start, 4, 2, -40, 4, 2, -37, Blocks.COBBLESTONE.getDefaultState());
        structure.fillWithBlocks(world, start, 4, 2, -35, 4, 2, -22, Blocks.STONE_BRICKS.getDefaultState());
        structure.fillWithBlocks(world, start, 4, 2, -11, 5, 2, -11, Blocks.STONE_STAIRS.getDefaultState().with(StairsBlock.FACING, Direction.SOUTH).with(StairsBlock.WATERLOGGED, false).with(StairsBlock.SHAPE, StairsShape.STRAIGHT).with(StairsBlock.HALF, Half.BOTTOM));
        structure.fillWithBlocks(world, start, 4, 2, -9, 4, 2, -4, Blocks.SMOOTH_STONE.getDefaultState());
        structure.fillWithBlocks(world, start, 4, 2, -3, 5, 2, -3, Blocks.STONE_STAIRS.getDefaultState().with(StairsBlock.FACING, Direction.NORTH).with(StairsBlock.WATERLOGGED, false).with(StairsBlock.SHAPE, StairsShape.STRAIGHT).with(StairsBlock.HALF, Half.BOTTOM));
        structure.fillWithBlocks(world, start, 4, 2, 25, 4, 2, 29, Blocks.OAK_STAIRS.getDefaultState().with(StairsBlock.FACING, Direction.EAST).with(StairsBlock.WATERLOGGED, false).with(StairsBlock.SHAPE, StairsShape.STRAIGHT).with(StairsBlock.HALF, Half.BOTTOM));
        structure.fillWithBlocks(world, start, 4, 2, 33, 4, 2, 34, Blocks.OAK_STAIRS.getDefaultState().with(StairsBlock.FACING, Direction.EAST).with(StairsBlock.WATERLOGGED, false).with(StairsBlock.SHAPE, StairsShape.STRAIGHT).with(StairsBlock.HALF, Half.BOTTOM));
        structure.fillWithBlocks(world, start, 4, 2, 37, 12, 2, 37, Blocks.OAK_PLANKS.getDefaultState());
        structure.fillWithBlocks(world, start, 4, 2, 38, 4, 2, 44, Blocks.SPRUCE_LOG.getDefaultState());
        structure.fillWithBlocks(world, start, 4, 2, 45, 12, 2, 45, Blocks.OAK_PLANKS.getDefaultState());
        structure.fillWithBlocks(world, start, 4, 2, 49, 7, 2, 49, Blocks.SNOW.getDefaultState().with(SnowBlock.LAYERS, 1));
        structure.fillWithBlocks(world, start, 4, 2, 51, 8, 2, 51, Blocks.GRASS_BLOCK.getDefaultState().with(SnowyDirtBlock.SNOWY, true));
        structure.fillWithBlocks(world, start, 4, 3, -50, 8, 3, -50, Blocks.SPRUCE_SLAB.getDefaultState().with(SlabBlock.TYPE, SlabType.BOTTOM).with(SlabBlock.WATERLOGGED, false));
        structure.fillWithBlocks(world, start, 4, 3, -40, 4, 3, -38, Blocks.SNOW.getDefaultState().with(SnowBlock.LAYERS, 1));
        structure.fillWithBlocks(world, start, 4, 3, -36, 4, 3, -22, Blocks.COBBLESTONE.getDefaultState());
        structure.fillWithBlocks(world, start, 4, 3, -10, 5, 3, -10, Blocks.STONE_STAIRS.getDefaultState().with(StairsBlock.FACING, Direction.SOUTH).with(StairsBlock.WATERLOGGED, false).with(StairsBlock.SHAPE, StairsShape.STRAIGHT).with(StairsBlock.HALF, Half.BOTTOM));
        structure.fillWithBlocks(world, start, 4, 3, -7, 4, 3, -6, Blocks.SMOOTH_STONE.getDefaultState());
        structure.fillWithBlocks(world, start, 4, 3, -4, 5, 3, -4, Blocks.STONE_STAIRS.getDefaultState().with(StairsBlock.FACING, Direction.NORTH).with(StairsBlock.WATERLOGGED, false).with(StairsBlock.SHAPE, StairsShape.STRAIGHT).with(StairsBlock.HALF, Half.BOTTOM));
        structure.fillWithBlocks(world, start, 4, 3, 31, 4, 3, 31, Blocks.OAK_PLANKS.getDefaultState());
        structure.fillWithBlocks(world, start, 4, 3, 38, 4, 3, 39, Blocks.OAK_PLANKS.getDefaultState());
        structure.fillWithBlocks(world, start, 4, 3, 41, 4, 4, 41, Blocks.SPRUCE_LOG.getDefaultState());
        structure.fillWithBlocks(world, start, 4, 3, 43, 4, 3, 44, Blocks.OAK_PLANKS.getDefaultState());
        structure.fillWithBlocks(world, start, 4, 3, 50, 5, 3, 50, Blocks.SPRUCE_TRAPDOOR.getDefaultState().with(HorizontalBlock.HORIZONTAL_FACING, Direction.SOUTH).with(TrapDoorBlock.HALF, Half.BOTTOM).with(TrapDoorBlock.WATERLOGGED, false).with(TrapDoorBlock.POWERED, false).with(TrapDoorBlock.OPEN, false));
        structure.fillWithBlocks(world, start, 4, 3, 51, 8, 3, 51, Blocks.SNOW.getDefaultState().with(SnowBlock.LAYERS, 1));
        structure.fillWithBlocks(world, start, 4, 3, 52, 4, 3, 52, Blocks.SPRUCE_SLAB.getDefaultState().with(SlabBlock.TYPE, SlabType.BOTTOM).with(SlabBlock.WATERLOGGED, false));
        structure.fillWithBlocks(world, start, 4, 4, -36, 4, 4, -35, Blocks.SNOW.getDefaultState().with(SnowBlock.LAYERS, 1));
        structure.fillWithBlocks(world, start, 4, 4, -32, 5, 4, -26, Blocks.COBBLESTONE.getDefaultState());
        structure.fillWithBlocks(world, start, 4, 4, -23, 4, 4, -22, Blocks.SNOW.getDefaultState().with(SnowBlock.LAYERS, 1));
        structure.fillWithBlocks(world, start, 4, 4, -9, 5, 4, -9, Blocks.STONE_STAIRS.getDefaultState().with(StairsBlock.FACING, Direction.SOUTH).with(StairsBlock.WATERLOGGED, false).with(StairsBlock.SHAPE, StairsShape.STRAIGHT).with(StairsBlock.HALF, Half.BOTTOM));
        structure.fillWithBlocks(world, start, 4, 4, -5, 5, 4, -5, Blocks.STONE_STAIRS.getDefaultState().with(StairsBlock.FACING, Direction.NORTH).with(StairsBlock.WATERLOGGED, false).with(StairsBlock.SHAPE, StairsShape.STRAIGHT).with(StairsBlock.HALF, Half.BOTTOM));
        structure.fillWithBlocks(world, start, 4, 4, 31, 4, 4, 31, Blocks.SNOW.getDefaultState().with(SnowBlock.LAYERS, 1));
        structure.fillWithBlocks(world, start, 4, 4, 39, 4, 4, 40, Blocks.OAK_PLANKS.getDefaultState());
        structure.fillWithBlocks(world, start, 4, 4, 42, 4, 4, 43, Blocks.OAK_PLANKS.getDefaultState());
        structure.fillWithBlocks(world, start, 4, 5, -32, 4, 5, -26, Blocks.SNOW.getDefaultState().with(SnowBlock.LAYERS, 1));
        structure.fillWithBlocks(world, start, 4, 5, -8, 5, 5, -8, Blocks.STONE_STAIRS.getDefaultState().with(StairsBlock.FACING, Direction.SOUTH).with(StairsBlock.WATERLOGGED, false).with(StairsBlock.SHAPE, StairsShape.STRAIGHT).with(StairsBlock.HALF, Half.BOTTOM));
        structure.fillWithBlocks(world, start, 4, 5, -6, 5, 5, -6, Blocks.STONE_STAIRS.getDefaultState().with(StairsBlock.FACING, Direction.NORTH).with(StairsBlock.WATERLOGGED, false).with(StairsBlock.SHAPE, StairsShape.STRAIGHT).with(StairsBlock.HALF, Half.BOTTOM));
        structure.fillWithBlocks(world, start, 4, 5, 40, 6, 5, 42, Blocks.OAK_PLANKS.getDefaultState());
        structure.fillWithBlocks(world, start, 4, 6, -7, 5, 6, -7, Blocks.STONE_SLAB.getDefaultState().with(SlabBlock.TYPE, SlabType.BOTTOM).with(SlabBlock.WATERLOGGED, false));
        structure.fillWithBlocks(world, start, 5, -7, -74, 6, -7, -73, Blocks.DIRT.getDefaultState());
        structure.fillWithBlocks(world, start, 5, -7, -61, 6, -7, -60, Blocks.STONE.getDefaultState());
        structure.fillWithBlocks(world, start, 5, -7, -45, 5, -7, -45, Blocks.GRAVEL.getDefaultState());
        structure.fillWithBlocks(world, start, 5, -7, -44, 5, -7, -10, Blocks.STONE.getDefaultState());
        structure.fillWithBlocks(world, start, 5, -7, -9, 5, -7, -8, Blocks.COAL_ORE.getDefaultState());
        structure.fillWithBlocks(world, start, 5, -7, -7, 7, -7, -4, Blocks.STONE.getDefaultState());
        structure.fillWithBlocks(world, start, 5, -7, -3, 5, -6, -2, Blocks.STONE.getDefaultState());
        structure.fillWithBlocks(world, start, 5, -7, -1, 6, -7, -1, Blocks.COAL_ORE.getDefaultState());
        structure.fillWithBlocks(world, start, 5, -7, 1, 7, -7, 3, Blocks.GRANITE.getDefaultState());
        structure.fillWithBlocks(world, start, 5, -7, 4, 5, -6, 5, Blocks.GRANITE.getDefaultState());
        structure.fillWithBlocks(world, start, 5, -7, 6, 8, -7, 9, Blocks.DIORITE.getDefaultState());
        structure.fillWithBlocks(world, start, 5, -7, 10, 5, -6, 10, Blocks.DIORITE.getDefaultState());
        structure.fillWithBlocks(world, start, 5, -7, 34, 8, -7, 47, Blocks.STONE.getDefaultState());
        structure.fillWithBlocks(world, start, 5, -7, 52, 5, -7, 53, Blocks.COAL_ORE.getDefaultState());
        structure.fillWithBlocks(world, start, 5, -7, 54, 13, -7, 62, Blocks.STONE.getDefaultState());
        structure.fillWithBlocks(world, start, 5, -7, 63, 9, -7, 72, Blocks.STONE.getDefaultState());
        structure.fillWithBlocks(world, start, 5, -7, 73, 7, -7, 75, Blocks.DIRT.getDefaultState());
        structure.fillWithBlocks(world, start, 5, -6, -73, 5, -6, -72, Blocks.DIRT.getDefaultState());
        structure.fillWithBlocks(world, start, 5, -6, -61, 8, -6, -58, Blocks.STONE.getDefaultState());
        structure.fillWithBlocks(world, start, 5, -6, -57, 6, -6, -56, Blocks.DIRT.getDefaultState());
        structure.fillWithBlocks(world, start, 5, -6, -53, 9, -6, -49, Blocks.STONE.getDefaultState());
        structure.fillWithBlocks(world, start, 5, -6, -48, 6, -6, -47, Blocks.GRAVEL.getDefaultState());
        structure.fillWithBlocks(world, start, 5, -6, -45, 5, -6, -45, Blocks.DIRT.getDefaultState());
        structure.fillWithBlocks(world, start, 5, -6, -43, 5, -6, -10, Blocks.STONE.getDefaultState());
        structure.fillWithBlocks(world, start, 5, -6, -9, 6, -6, -9, Blocks.COAL_ORE.getDefaultState());
        structure.fillWithBlocks(world, start, 5, -6, -8, 7, -6, -6, Blocks.STONE.getDefaultState());
        structure.fillWithBlocks(world, start, 5, -6, -5, 6, -6, -4, Blocks.STONE.getDefaultState());
        structure.fillWithBlocks(world, start, 5, -6, -1, 7, -6, 4, Blocks.GRANITE.getDefaultState());
        structure.fillWithBlocks(world, start, 5, -6, 8, 6, -6, 10, Blocks.DIORITE.getDefaultState());
        structure.fillWithBlocks(world, start, 5, -6, 25, 9, -6, 29, Blocks.STONE.getDefaultState());
        structure.fillWithBlocks(world, start, 5, -6, 30, 5, -6, 43, Blocks.DIRT.getDefaultState());
        structure.fillWithBlocks(world, start, 5, -6, 54, 8, -6, 57, Blocks.STONE.getDefaultState());
        structure.fillWithBlocks(world, start, 5, -6, 58, 6, -6, 59, Blocks.DIRT.getDefaultState());
        structure.fillWithBlocks(world, start, 5, -6, 60, 8, -6, 63, Blocks.STONE.getDefaultState());
        structure.fillWithBlocks(world, start, 5, -6, 64, 5, -6, 65, Blocks.COAL_ORE.getDefaultState());
        structure.fillWithBlocks(world, start, 5, -6, 66, 10, -6, 71, Blocks.STONE.getDefaultState());
        structure.fillWithBlocks(world, start, 5, -6, 72, 6, -6, 73, Blocks.DIRT.getDefaultState());
        structure.fillWithBlocks(world, start, 5, -6, 74, 6, -6, 75, Blocks.GRASS_BLOCK.getDefaultState().with(SnowyDirtBlock.SNOWY, true));
        structure.fillWithBlocks(world, start, 5, -5, -23, 38, -2, -23, Blocks.DIRT.getDefaultState());
        structure.fillWithBlocks(world, start, 5, -5, -17, 6, -5, -16, Blocks.STONE.getDefaultState());
        structure.fillWithBlocks(world, start, 5, -5, -15, 17, -5, -1, Blocks.DIRT.getDefaultState());
        structure.fillWithBlocks(world, start, 5, -5, 74, 6, -5, 75, Blocks.SNOW.getDefaultState().with(SnowBlock.LAYERS, 1));
        structure.fillWithBlocks(world, start, 5, -4, -28, 5, -2, -28, Blocks.BROWN_TERRACOTTA.getDefaultState());
        structure.fillWithBlocks(world, start, 5, -4, -27, 6, -4, -26, Blocks.DIRT.getDefaultState());
        structure.fillWithBlocks(world, start, 5, -4, -25, 5, -2, -25, Blocks.BROWN_TERRACOTTA.getDefaultState());
        structure.fillWithBlocks(world, start, 5, -4, -24, 42, -4, 13, Blocks.DIRT.getDefaultState());
        structure.fillWithBlocks(world, start, 5, -4, 14, 14, -4, 28, Blocks.DIRT.getDefaultState());
        structure.fillWithBlocks(world, start, 5, -4, 58, 6, -4, 59, Blocks.GRASS_BLOCK.getDefaultState().with(SnowyDirtBlock.SNOWY, false));
        structure.fillWithBlocks(world, start, 5, -4, 60, 16, -4, 71, Blocks.DIRT.getDefaultState());
        structure.fillWithBlocks(world, start, 5, -3, -27, 6, -3, -26, Blocks.DIRT.getDefaultState());
        structure.fillWithBlocks(world, start, 5, -3, -24, 10, -3, -19, Blocks.DIRT.getDefaultState());
        structure.fillWithBlocks(world, start, 5, -3, -18, 5, -2, -17, Blocks.COARSE_DIRT.getDefaultState());
        structure.fillWithBlocks(world, start, 5, -3, -16, 5, -3, -16, Blocks.DIRT.getDefaultState());
        structure.fillWithBlocks(world, start, 5, -3, -15, 5, -3, -12, Blocks.COARSE_DIRT.getDefaultState());
        structure.fillWithBlocks(world, start, 5, -3, -11, 12, -3, -4, Blocks.DIRT.getDefaultState());
        structure.fillWithBlocks(world, start, 5, -3, -3, 5, -2, 56, Blocks.DIRT.getDefaultState());
        structure.fillWithBlocks(world, start, 5, -3, 60, 15, -3, 70, Blocks.DIRT.getDefaultState());
        structure.fillWithBlocks(world, start, 5, -2, -27, 6, -2, -26, Blocks.DIRT.getDefaultState());
        structure.fillWithBlocks(world, start, 5, -2, -24, 10, -2, -19, Blocks.DIRT.getDefaultState());
        structure.fillWithBlocks(world, start, 5, -2, -16, 5, -2, -16, Blocks.DIRT.getDefaultState());
        structure.fillWithBlocks(world, start, 5, -2, -15, 5, -2, -12, Blocks.COARSE_DIRT.getDefaultState());
        structure.fillWithBlocks(world, start, 5, -2, -11, 12, -2, -4, Blocks.DIRT.getDefaultState());
        structure.fillWithBlocks(world, start, 5, -2, 57, 9, -2, 57, Blocks.GRASS_BLOCK.getDefaultState().with(SnowyDirtBlock.SNOWY, true));
        structure.fillWithBlocks(world, start, 5, -2, 60, 9, -2, 60, Blocks.GRASS_BLOCK.getDefaultState().with(SnowyDirtBlock.SNOWY, true));
        structure.fillWithBlocks(world, start, 5, -2, 61, 13, -2, 69, Blocks.DIRT.getDefaultState());
        structure.fillWithBlocks(world, start, 5, -1, -46, 5, -1, -46, Blocks.DIRT.getDefaultState());
        structure.fillWithBlocks(world, start, 5, -1, -40, 5, -1, -36, Blocks.DIRT.getDefaultState());
        structure.fillWithBlocks(world, start, 5, -1, -35, 9, -1, -23, Blocks.COBBLESTONE.getDefaultState());
        structure.fillWithBlocks(world, start, 5, -1, -22, 10, -1, -22, Blocks.DIRT.getDefaultState());
        structure.fillWithBlocks(world, start, 5, -1, -21, 9, -1, -21, Blocks.GRASS_PATH.getDefaultState());
        structure.fillWithBlocks(world, start, 5, -1, -19, 5, -1, -19, Blocks.GRASS_BLOCK.getDefaultState().with(SnowyDirtBlock.SNOWY, true));
        structure.fillWithBlocks(world, start, 5, -1, -18, 5, -1, -17, Blocks.COARSE_DIRT.getDefaultState());
        structure.fillWithBlocks(world, start, 5, -1, -16, 5, -1, -16, Blocks.GRASS_BLOCK.getDefaultState().with(SnowyDirtBlock.SNOWY, true));
        structure.fillWithBlocks(world, start, 5, -1, -15, 5, -1, -12, Blocks.COARSE_DIRT.getDefaultState());
        structure.fillWithBlocks(world, start, 5, -1, -11, 6, -1, -11, Blocks.GRASS_BLOCK.getDefaultState().with(SnowyDirtBlock.SNOWY, true));
        structure.fillWithBlocks(world, start, 5, -1, -10, 6, -1, -10, Blocks.DIRT.getDefaultState());
        structure.fillWithBlocks(world, start, 5, -1, -9, 9, -1, -5, Blocks.POLISHED_ANDESITE.getDefaultState());
        structure.fillWithBlocks(world, start, 5, -1, -4, 7, -1, -4, Blocks.DIRT.getDefaultState());
        structure.fillWithBlocks(world, start, 5, -1, -3, 5, -1, -2, Blocks.GRASS_BLOCK.getDefaultState().with(SnowyDirtBlock.SNOWY, true));
        structure.fillWithBlocks(world, start, 5, -1, 2, 8, -1, 8, Blocks.GRASS_BLOCK.getDefaultState().with(SnowyDirtBlock.SNOWY, true));
        structure.fillWithBlocks(world, start, 5, -1, 25, 5, -1, 30, Blocks.DIRT.getDefaultState());
        structure.fillWithBlocks(world, start, 5, -1, 31, 5, -1, 31, Blocks.COBBLESTONE.getDefaultState());
        structure.fillWithBlocks(world, start, 5, -1, 32, 5, -1, 34, Blocks.DIRT.getDefaultState());
        structure.fillWithBlocks(world, start, 5, -1, 38, 12, -1, 38, Blocks.DIRT.getDefaultState());
        structure.fillWithBlocks(world, start, 5, -1, 39, 9, -1, 43, Blocks.COBBLESTONE.getDefaultState());
        structure.fillWithBlocks(world, start, 5, -1, 44, 12, -1, 44, Blocks.DIRT.getDefaultState());
        structure.fillWithBlocks(world, start, 5, -1, 56, 9, -1, 56, Blocks.GRASS_BLOCK.getDefaultState().with(SnowyDirtBlock.SNOWY, true));
        structure.fillWithBlocks(world, start, 5, -1, 57, 9, -1, 57, Blocks.SNOW.getDefaultState().with(SnowBlock.LAYERS, 1));
        structure.fillWithBlocks(world, start, 5, -1, 60, 9, -1, 60, Blocks.SNOW.getDefaultState().with(SnowBlock.LAYERS, 1));
        structure.fillWithBlocks(world, start, 5, -1, 61, 13, -1, 69, Blocks.GRASS_BLOCK.getDefaultState().with(SnowyDirtBlock.SNOWY, true));
        structure.fillWithBlocks(world, start, 5, 0, -52, 5, 2, -52, Blocks.SPRUCE_LOG.getDefaultState());
        structure.fillWithBlocks(world, start, 5, 0, -51, 5, 4, -51, Blocks.OAK_LOG.getDefaultState());
        structure.fillWithBlocks(world, start, 5, 0, -48, 5, 2, -48, Blocks.SPRUCE_LOG.getDefaultState());
        structure.fillWithBlocks(world, start, 5, 0, -47, 5, 0, -47, Blocks.DIRT.getDefaultState());
        structure.fillWithBlocks(world, start, 5, 0, -46, 5, 1, -46, Blocks.SPRUCE_LOG.getDefaultState());
        structure.fillWithBlocks(world, start, 5, 0, -45, 5, 0, -42, Blocks.SNOW.getDefaultState().with(SnowBlock.LAYERS, 1));
        structure.fillWithBlocks(world, start, 5, 0, -40, 5, 2, -40, Blocks.STONE_BRICKS.getDefaultState());
        structure.fillWithBlocks(world, start, 5, 0, -39, 5, 1, -38, Blocks.BRICKS.getDefaultState());
        structure.fillWithBlocks(world, start, 5, 0, -37, 5, 2, -37, Blocks.STONE_BRICKS.getDefaultState());
        structure.fillWithBlocks(world, start, 5, 0, -36, 5, 1, -36, Blocks.BRICKS.getDefaultState());
        structure.fillWithBlocks(world, start, 5, 0, -22, 6, 1, -22, Blocks.BRICKS.getDefaultState());
        structure.fillWithBlocks(world, start, 5, 0, -19, 11, 0, -19, Blocks.COBBLESTONE_WALL.getDefaultState().with(WallBlock.WATERLOGGED, false).with(WallBlock.UP, false).with(WallBlock.WALL_HEIGHT_NORTH, WallHeight.LOW).with(WallBlock.WALL_HEIGHT_SOUTH, WallHeight.LOW).with(WallBlock.WALL_HEIGHT_EAST, WallHeight.LOW).with(WallBlock.WALL_HEIGHT_WEST, WallHeight.LOW));
        structure.fillWithBlocks(world, start, 5, 0, -17, 5, 0, -12, Blocks.SNOW.getDefaultState().with(SnowBlock.LAYERS, 1));
        structure.fillWithBlocks(world, start, 5, 0, -10, 5, 1, -10, Blocks.COBBLESTONE.getDefaultState());
        structure.fillWithBlocks(world, start, 5, 0, -4, 6, 0, -4, Blocks.COBBLESTONE.getDefaultState());
        structure.fillWithBlocks(world, start, 5, 0, 2, 8, 0, 7, Blocks.SNOW.getDefaultState().with(SnowBlock.LAYERS, 1));
        structure.fillWithBlocks(world, start, 5, 0, 16, 5, 0, 23, Blocks.SNOW.getDefaultState().with(SnowBlock.LAYERS, 1));
        structure.fillWithBlocks(world, start, 5, 0, 25, 5, 2, 25, Blocks.SPRUCE_LOG.getDefaultState());
        structure.fillWithBlocks(world, start, 5, 0, 26, 5, 0, 29, Blocks.OAK_PLANKS.getDefaultState());
        structure.fillWithBlocks(world, start, 5, 0, 30, 5, 2, 30, Blocks.SPRUCE_LOG.getDefaultState());
        structure.fillWithBlocks(world, start, 5, 0, 32, 5, 2, 32, Blocks.SPRUCE_LOG.getDefaultState());
        structure.fillWithBlocks(world, start, 5, 0, 33, 5, 1, 33, Blocks.OAK_PLANKS.getDefaultState());
        structure.fillWithBlocks(world, start, 5, 0, 34, 5, 2, 34, Blocks.SPRUCE_LOG.getDefaultState());
        structure.fillWithBlocks(world, start, 5, 0, 38, 7, 1, 38, Blocks.OAK_PLANKS.getDefaultState());
        structure.fillWithBlocks(world, start, 5, 0, 44, 7, 1, 44, Blocks.OAK_PLANKS.getDefaultState());
        structure.fillWithBlocks(world, start, 5, 0, 46, 6, 0, 47, Blocks.SNOW.getDefaultState().with(SnowBlock.LAYERS, 1));
        structure.fillWithBlocks(world, start, 5, 0, 48, 5, 1, 48, Blocks.OAK_LOG.getDefaultState());
        structure.fillWithBlocks(world, start, 5, 0, 50, 5, 2, 50, Blocks.OAK_LOG.getDefaultState());
        structure.fillWithBlocks(world, start, 5, 0, 53, 5, 2, 53, Blocks.OAK_LOG.getDefaultState());
        structure.fillWithBlocks(world, start, 5, 0, 54, 5, 5, 54, Blocks.SPRUCE_LOG.getDefaultState());
        structure.fillWithBlocks(world, start, 5, 0, 55, 9, 0, 55, Blocks.GRASS_BLOCK.getDefaultState().with(SnowyDirtBlock.SNOWY, true));
        structure.fillWithBlocks(world, start, 5, 0, 61, 13, 0, 69, Blocks.SNOW.getDefaultState().with(SnowBlock.LAYERS, 1));
        structure.fillWithBlocks(world, start, 5, 1, -47, 5, 1, -47, Blocks.GRASS_BLOCK.getDefaultState().with(SnowyDirtBlock.SNOWY, true));
        structure.fillWithBlocks(world, start, 5, 1, 28, 5, 1, 29, Blocks.OAK_PLANKS.getDefaultState());
        structure.fillWithBlocks(world, start, 5, 2, -47, 5, 2, -47, Blocks.SNOW.getDefaultState().with(SnowBlock.LAYERS, 1));
        structure.fillWithBlocks(world, start, 5, 2, -39, 5, 2, -36, Blocks.STONE_BRICKS.getDefaultState());
        structure.fillWithBlocks(world, start, 5, 2, -22, 10, 2, -22, Blocks.STONE_BRICKS.getDefaultState());
        structure.fillWithBlocks(world, start, 5, 2, -10, 6, 2, -10, Blocks.SMOOTH_STONE.getDefaultState());
        structure.fillWithBlocks(world, start, 5, 2, -4, 6, 2, -4, Blocks.SMOOTH_STONE.getDefaultState());
        structure.fillWithBlocks(world, start, 5, 2, 26, 5, 2, 34, Blocks.SPRUCE_LOG.getDefaultState());
        structure.fillWithBlocks(world, start, 5, 2, 38, 12, 2, 38, Blocks.SPRUCE_LOG.getDefaultState());
        structure.fillWithBlocks(world, start, 5, 2, 44, 12, 2, 44, Blocks.SPRUCE_LOG.getDefaultState());
        structure.fillWithBlocks(world, start, 5, 3, -49, 7, 3, -49, Blocks.SNOW.getDefaultState().with(SnowBlock.LAYERS, 1));
        structure.fillWithBlocks(world, start, 5, 3, -40, 5, 3, -36, Blocks.COBBLESTONE.getDefaultState());
        structure.fillWithBlocks(world, start, 5, 3, -35, 5, 3, -34, Blocks.STONE_BRICK_SLAB.getDefaultState().with(SlabBlock.TYPE, SlabType.TOP).with(SlabBlock.WATERLOGGED, false));
        structure.fillWithBlocks(world, start, 5, 3, -32, 5, 3, -31, Blocks.STONE_BRICK_SLAB.getDefaultState().with(SlabBlock.TYPE, SlabType.TOP).with(SlabBlock.WATERLOGGED, false));
        structure.fillWithBlocks(world, start, 5, 3, -27, 5, 3, -26, Blocks.STONE_BRICK_SLAB.getDefaultState().with(SlabBlock.TYPE, SlabType.TOP).with(SlabBlock.WATERLOGGED, false));
        structure.fillWithBlocks(world, start, 5, 3, -24, 5, 3, -23, Blocks.STONE_BRICK_SLAB.getDefaultState().with(SlabBlock.TYPE, SlabType.TOP).with(SlabBlock.WATERLOGGED, false));
        structure.fillWithBlocks(world, start, 5, 3, -22, 5, 4, -22, Blocks.COBBLESTONE.getDefaultState());
        structure.fillWithBlocks(world, start, 5, 3, 27, 5, 3, 32, Blocks.OAK_PLANKS.getDefaultState());
        structure.fillWithBlocks(world, start, 5, 3, 38, 12, 3, 38, Blocks.OAK_PLANKS.getDefaultState());
        structure.fillWithBlocks(world, start, 5, 3, 39, 11, 3, 39, Blocks.DARK_OAK_SLAB.getDefaultState().with(SlabBlock.TYPE, SlabType.TOP).with(SlabBlock.WATERLOGGED, false));
        structure.fillWithBlocks(world, start, 5, 3, 43, 11, 3, 43, Blocks.DARK_OAK_SLAB.getDefaultState().with(SlabBlock.TYPE, SlabType.TOP).with(SlabBlock.WATERLOGGED, false));
        structure.fillWithBlocks(world, start, 5, 3, 44, 12, 3, 44, Blocks.OAK_PLANKS.getDefaultState());
        structure.fillWithBlocks(world, start, 5, 3, 52, 5, 3, 53, Blocks.SPRUCE_SLAB.getDefaultState().with(SlabBlock.TYPE, SlabType.BOTTOM).with(SlabBlock.WATERLOGGED, false));
        structure.fillWithBlocks(world, start, 5, 4, -40, 5, 4, -38, Blocks.SNOW.getDefaultState().with(SnowBlock.LAYERS, 1));
        structure.fillWithBlocks(world, start, 5, 4, -36, 5, 4, -22, Blocks.COBBLESTONE.getDefaultState());
        structure.fillWithBlocks(world, start, 5, 4, 27, 5, 4, 30, Blocks.SNOW.getDefaultState().with(SnowBlock.LAYERS, 1));
        structure.fillWithBlocks(world, start, 5, 4, 39, 12, 4, 39, Blocks.OAK_PLANKS.getDefaultState());
        structure.fillWithBlocks(world, start, 5, 4, 43, 12, 4, 43, Blocks.OAK_PLANKS.getDefaultState());
        structure.fillWithBlocks(world, start, 5, 5, -36, 5, 5, -35, Blocks.SNOW.getDefaultState().with(SnowBlock.LAYERS, 1));
        structure.fillWithBlocks(world, start, 5, 5, -32, 6, 5, -26, Blocks.COBBLESTONE.getDefaultState());
        structure.fillWithBlocks(world, start, 5, 5, -23, 5, 5, -22, Blocks.SNOW.getDefaultState().with(SnowBlock.LAYERS, 1));
        structure.fillWithBlocks(world, start, 5, 6, -32, 5, 6, -26, Blocks.SNOW.getDefaultState().with(SnowBlock.LAYERS, 1));
        structure.fillWithBlocks(world, start, 5, 6, 41, 11, 6, 41, Blocks.OAK_PLANKS.getDefaultState());
        structure.fillWithBlocks(world, start, 6, -7, -72, 30, -6, -72, Blocks.DIRT.getDefaultState());
        structure.fillWithBlocks(world, start, 6, -7, -71, 9, -7, -68, Blocks.DIORITE.getDefaultState());
        structure.fillWithBlocks(world, start, 6, -7, -67, 7, -7, -66, Blocks.DIORITE.getDefaultState());
        structure.fillWithBlocks(world, start, 6, -7, -65, 6, -6, -64, Blocks.DIORITE.getDefaultState());
        structure.fillWithBlocks(world, start, 6, -7, -63, 9, -7, -60, Blocks.STONE.getDefaultState());
        structure.fillWithBlocks(world, start, 6, -7, -58, 13, -7, -48, Blocks.STONE.getDefaultState());
        structure.fillWithBlocks(world, start, 6, -7, -47, 7, -7, -43, Blocks.GRAVEL.getDefaultState());
        structure.fillWithBlocks(world, start, 6, -7, -42, 6, -7, -3, Blocks.STONE.getDefaultState());
        structure.fillWithBlocks(world, start, 6, -7, -2, 6, -7, -1, Blocks.COAL_ORE.getDefaultState());
        structure.fillWithBlocks(world, start, 6, -7, 0, 7, -7, 3, Blocks.GRANITE.getDefaultState());
        structure.fillWithBlocks(world, start, 6, -7, 4, 6, -6, 4, Blocks.GRANITE.getDefaultState());
        structure.fillWithBlocks(world, start, 6, -7, 5, 9, -7, 8, Blocks.DIORITE.getDefaultState());
        structure.fillWithBlocks(world, start, 6, -7, 10, 12, -7, 16, Blocks.STONE.getDefaultState());
        structure.fillWithBlocks(world, start, 6, -7, 33, 8, -7, 47, Blocks.STONE.getDefaultState());
        structure.fillWithBlocks(world, start, 6, -7, 52, 15, -7, 61, Blocks.STONE.getDefaultState());
        structure.fillWithBlocks(world, start, 6, -6, -73, 28, -6, -73, Blocks.GRASS_BLOCK.getDefaultState().with(SnowyDirtBlock.SNOWY, true));
        structure.fillWithBlocks(world, start, 6, -6, -70, 8, -6, -67, Blocks.DIORITE.getDefaultState());
        structure.fillWithBlocks(world, start, 6, -6, -63, 11, -6, -58, Blocks.STONE.getDefaultState());
        structure.fillWithBlocks(world, start, 6, -6, -55, 8, -6, -49, Blocks.STONE.getDefaultState());
        structure.fillWithBlocks(world, start, 6, -6, -46, 8, -6, -43, Blocks.DIRT.getDefaultState());
        structure.fillWithBlocks(world, start, 6, -6, -42, 12, -6, -34, Blocks.STONE.getDefaultState());
        structure.fillWithBlocks(world, start, 6, -6, -33, 6, -6, -11, Blocks.STONE.getDefaultState());
        structure.fillWithBlocks(world, start, 6, -6, -10, 6, -6, -9, Blocks.COAL_ORE.getDefaultState());
        structure.fillWithBlocks(world, start, 6, -6, -3, 6, -6, 7, Blocks.GRANITE.getDefaultState());
        structure.fillWithBlocks(world, start, 6, -6, 30, 6, -6, 30, Blocks.STONE.getDefaultState());
        structure.fillWithBlocks(world, start, 6, -6, 31, 6, -2, 43, Blocks.DIRT.getDefaultState());
        structure.fillWithBlocks(world, start, 6, -6, 44, 9, -6, 47, Blocks.STONE.getDefaultState());
        structure.fillWithBlocks(world, start, 6, -6, 48, 7, -6, 50, Blocks.ANDESITE.getDefaultState());
        structure.fillWithBlocks(world, start, 6, -6, 51, 11, -6, 56, Blocks.STONE.getDefaultState());
        structure.fillWithBlocks(world, start, 6, -6, 64, 9, -6, 71, Blocks.STONE.getDefaultState());
        structure.fillWithBlocks(world, start, 6, -5, -73, 28, -5, -73, Blocks.SNOW.getDefaultState().with(SnowBlock.LAYERS, 1));
        structure.fillWithBlocks(world, start, 6, -5, -72, 30, -5, -72, Blocks.GRASS_BLOCK.getDefaultState().with(SnowyDirtBlock.SNOWY, true));
        structure.fillWithBlocks(world, start, 6, -5, -47, 16, -5, -23, Blocks.DIRT.getDefaultState());
        structure.fillWithBlocks(world, start, 6, -5, -22, 6, -5, -16, Blocks.STONE.getDefaultState());
        structure.fillWithBlocks(world, start, 6, -4, -72, 30, -4, -72, Blocks.SNOW.getDefaultState().with(SnowBlock.LAYERS, 1));
        structure.fillWithBlocks(world, start, 6, -4, -57, 7, -4, -56, Blocks.GRASS_BLOCK.getDefaultState().with(SnowyDirtBlock.SNOWY, false));
        structure.fillWithBlocks(world, start, 6, -4, -28, 47, -4, 13, Blocks.DIRT.getDefaultState());
        structure.fillWithBlocks(world, start, 6, -3, -55, 8, -3, -17, Blocks.DIRT.getDefaultState());
        structure.fillWithBlocks(world, start, 6, -3, -16, 6, -3, -15, Blocks.DIRT.getDefaultState());
        structure.fillWithBlocks(world, start, 6, -3, -14, 6, -3, -12, Blocks.COARSE_DIRT.getDefaultState());
        structure.fillWithBlocks(world, start, 6, -3, -3, 7, -3, -2, Blocks.COARSE_DIRT.getDefaultState());
        structure.fillWithBlocks(world, start, 6, -3, -1, 20, -3, 13, Blocks.DIRT.getDefaultState());
        structure.fillWithBlocks(world, start, 6, -3, 14, 14, -3, 28, Blocks.DIRT.getDefaultState());
        structure.fillWithBlocks(world, start, 6, -2, -28, 11, -2, -19, Blocks.DIRT.getDefaultState());
        structure.fillWithBlocks(world, start, 6, -2, -18, 7, -2, -17, Blocks.DIRT.getDefaultState());
        structure.fillWithBlocks(world, start, 6, -2, -16, 6, -2, -15, Blocks.DIRT.getDefaultState());
        structure.fillWithBlocks(world, start, 6, -2, -14, 6, -2, -12, Blocks.COARSE_DIRT.getDefaultState());
        structure.fillWithBlocks(world, start, 6, -2, -3, 7, -2, -2, Blocks.COARSE_DIRT.getDefaultState());
        structure.fillWithBlocks(world, start, 6, -2, -1, 19, -2, 12, Blocks.DIRT.getDefaultState());
        structure.fillWithBlocks(world, start, 6, -2, 13, 10, -2, 28, Blocks.DIRT.getDefaultState());
        structure.fillWithBlocks(world, start, 6, -1, -46, 7, -1, -45, Blocks.DIRT.getDefaultState());
        structure.fillWithBlocks(world, start, 6, -1, -44, 9, -1, -41, Blocks.GRASS_BLOCK.getDefaultState().with(SnowyDirtBlock.SNOWY, true));
        structure.fillWithBlocks(world, start, 6, -1, -40, 9, -1, -40, Blocks.DIRT.getDefaultState());
        structure.fillWithBlocks(world, start, 6, -1, -39, 8, -1, -37, Blocks.COBBLESTONE.getDefaultState());
        structure.fillWithBlocks(world, start, 6, -1, -20, 8, -1, -18, Blocks.GRASS_BLOCK.getDefaultState().with(SnowyDirtBlock.SNOWY, true));
        structure.fillWithBlocks(world, start, 6, -1, -17, 6, -1, -16, Blocks.DIRT.getDefaultState());
        structure.fillWithBlocks(world, start, 6, -1, -15, 6, -1, -15, Blocks.GRASS_BLOCK.getDefaultState().with(SnowyDirtBlock.SNOWY, true));
        structure.fillWithBlocks(world, start, 6, -1, -14, 6, -1, -12, Blocks.COARSE_DIRT.getDefaultState());
        structure.fillWithBlocks(world, start, 6, -1, -3, 7, -1, -2, Blocks.COARSE_DIRT.getDefaultState());
        structure.fillWithBlocks(world, start, 6, -1, -1, 8, -1, 1, Blocks.GRASS_PATH.getDefaultState());
        structure.fillWithBlocks(world, start, 6, -1, 10, 7, -1, 11, Blocks.GRASS_BLOCK.getDefaultState().with(SnowyDirtBlock.SNOWY, true));
        structure.fillWithBlocks(world, start, 6, -1, 17, 7, -1, 18, Blocks.GRASS_BLOCK.getDefaultState().with(SnowyDirtBlock.SNOWY, true));
        structure.fillWithBlocks(world, start, 6, -1, 20, 8, -1, 24, Blocks.GRASS_BLOCK.getDefaultState().with(SnowyDirtBlock.SNOWY, true));
        structure.fillWithBlocks(world, start, 6, -1, 25, 7, -1, 25, Blocks.DIRT.getDefaultState());
        structure.fillWithBlocks(world, start, 6, -1, 26, 10, -1, 33, Blocks.COBBLESTONE.getDefaultState());
        structure.fillWithBlocks(world, start, 6, -1, 34, 11, -1, 34, Blocks.DIRT.getDefaultState());
        structure.fillWithBlocks(world, start, 6, -1, 35, 8, -1, 37, Blocks.GRASS_BLOCK.getDefaultState().with(SnowyDirtBlock.SNOWY, true));
        structure.fillWithBlocks(world, start, 6, 0, -52, 6, 2, -52, Blocks.OAK_LOG.getDefaultState());
        structure.fillWithBlocks(world, start, 6, 0, -51, 6, 3, -51, Blocks.SPRUCE_LOG.getDefaultState());
        structure.fillWithBlocks(world, start, 6, 0, -50, 7, 0, -49, Blocks.DIRT.getDefaultState());
        structure.fillWithBlocks(world, start, 6, 0, -48, 6, 2, -48, Blocks.OAK_LOG.getDefaultState());
        structure.fillWithBlocks(world, start, 6, 0, -47, 7, 0, -46, Blocks.DIRT.getDefaultState());
        structure.fillWithBlocks(world, start, 6, 0, -45, 6, 1, -45, Blocks.OAK_LOG.getDefaultState());
        structure.fillWithBlocks(world, start, 6, 0, -44, 8, 0, -42, Blocks.SNOW.getDefaultState().with(SnowBlock.LAYERS, 1));
        structure.fillWithBlocks(world, start, 6, 0, -40, 8, 1, -40, Blocks.BRICKS.getDefaultState());
        structure.fillWithBlocks(world, start, 6, 0, -39, 8, 0, -39, Blocks.BARREL.getDefaultState().with(BarrelBlock.PROPERTY_FACING, Direction.SOUTH).with(BarrelBlock.PROPERTY_OPEN, false));
        structure.fillWithBlocks(world, start, 6, 0, -36, 6, 3, -36, Blocks.STONE_BRICKS.getDefaultState());
        structure.fillWithBlocks(world, start, 6, 0, -20, 9, 0, -20, Blocks.SNOW.getDefaultState().with(SnowBlock.LAYERS, 1));
        structure.fillWithBlocks(world, start, 6, 0, -18, 10, 0, -18, Blocks.SNOW.getDefaultState().with(SnowBlock.LAYERS, 1));
        structure.fillWithBlocks(world, start, 6, 0, -15, 9, 0, -12, Blocks.SNOW.getDefaultState().with(SnowBlock.LAYERS, 1));
        structure.fillWithBlocks(world, start, 6, 0, -10, 6, 2, -10, Blocks.SMOOTH_STONE.getDefaultState());
        structure.fillWithBlocks(world, start, 6, 0, 8, 7, 0, 8, Blocks.SNOW.getDefaultState().with(SnowBlock.LAYERS, 1));
        structure.fillWithBlocks(world, start, 6, 0, 10, 7, 0, 11, Blocks.SNOW.getDefaultState().with(SnowBlock.LAYERS, 1));
        structure.fillWithBlocks(world, start, 6, 0, 17, 7, 0, 18, Blocks.SNOW.getDefaultState().with(SnowBlock.LAYERS, 1));
        structure.fillWithBlocks(world, start, 6, 0, 20, 7, 0, 23, Blocks.SNOW.getDefaultState().with(SnowBlock.LAYERS, 1));
        structure.fillWithBlocks(world, start, 6, 0, 25, 10, 1, 25, Blocks.OAK_PLANKS.getDefaultState());
        structure.fillWithBlocks(world, start, 6, 0, 34, 10, 1, 34, Blocks.OAK_PLANKS.getDefaultState());
        structure.fillWithBlocks(world, start, 6, 0, 48, 6, 1, 48, Blocks.SPRUCE_LOG.getDefaultState());
        structure.fillWithBlocks(world, start, 6, 0, 50, 6, 2, 50, Blocks.SPRUCE_LOG.getDefaultState());
        structure.fillWithBlocks(world, start, 6, 0, 53, 6, 3, 53, Blocks.SPRUCE_LOG.getDefaultState());
        structure.fillWithBlocks(world, start, 6, 0, 54, 6, 2, 54, Blocks.OAK_LOG.getDefaultState());
        structure.fillWithBlocks(world, start, 6, 1, -50, 7, 1, -49, Blocks.DIRT.getDefaultState());
        structure.fillWithBlocks(world, start, 6, 1, -47, 6, 1, -46, Blocks.GRASS_BLOCK.getDefaultState().with(SnowyDirtBlock.SNOWY, true));
        structure.fillWithBlocks(world, start, 6, 2, -47, 6, 2, -46, Blocks.SNOW.getDefaultState().with(SnowBlock.LAYERS, 1));
        structure.fillWithBlocks(world, start, 6, 2, -40, 9, 2, -40, Blocks.STONE_BRICKS.getDefaultState());
        structure.fillWithBlocks(world, start, 6, 2, -3, 6, 2, -2, Blocks.STONE_SLAB.getDefaultState().with(SlabBlock.TYPE, SlabType.TOP).with(SlabBlock.WATERLOGGED, false));
        structure.fillWithBlocks(world, start, 6, 2, 25, 11, 2, 25, Blocks.SPRUCE_LOG.getDefaultState());
        structure.fillWithBlocks(world, start, 6, 2, 34, 11, 2, 34, Blocks.SPRUCE_LOG.getDefaultState());
        structure.fillWithBlocks(world, start, 6, 3, -40, 6, 4, -40, Blocks.COBBLESTONE.getDefaultState());
        structure.fillWithBlocks(world, start, 6, 3, -22, 8, 3, -22, Blocks.STONE_BRICKS.getDefaultState());
        structure.fillWithBlocks(world, start, 6, 3, -3, 9, 3, -3, Blocks.STONE_SLAB.getDefaultState().with(SlabBlock.TYPE, SlabType.BOTTOM).with(SlabBlock.WATERLOGGED, false));
        structure.fillWithBlocks(world, start, 6, 3, -2, 9, 3, -2, Blocks.SNOW.getDefaultState().with(SnowBlock.LAYERS, 1));
        structure.fillWithBlocks(world, start, 6, 3, 52, 9, 3, 52, Blocks.SPRUCE_SLAB.getDefaultState().with(SlabBlock.TYPE, SlabType.BOTTOM).with(SlabBlock.WATERLOGGED, false));
        structure.fillWithBlocks(world, start, 6, 4, -39, 6, 4, -36, Blocks.COBBLESTONE.getDefaultState());
        structure.fillWithBlocks(world, start, 6, 4, -35, 6, 4, -34, Blocks.STONE_BRICK_SLAB.getDefaultState().with(SlabBlock.TYPE, SlabType.TOP).with(SlabBlock.WATERLOGGED, false));
        structure.fillWithBlocks(world, start, 6, 4, -32, 6, 4, -31, Blocks.STONE_BRICK_SLAB.getDefaultState().with(SlabBlock.TYPE, SlabType.TOP).with(SlabBlock.WATERLOGGED, false));
        structure.fillWithBlocks(world, start, 6, 4, -29, 6, 4, -29, Blocks.STONE_BRICK_SLAB.getDefaultState().with(SlabBlock.TYPE, SlabType.TOP).with(SlabBlock.WATERLOGGED, false));
        structure.fillWithBlocks(world, start, 6, 4, -27, 6, 4, -26, Blocks.STONE_BRICK_SLAB.getDefaultState().with(SlabBlock.TYPE, SlabType.TOP).with(SlabBlock.WATERLOGGED, false));
        structure.fillWithBlocks(world, start, 6, 4, -24, 6, 4, -23, Blocks.STONE_BRICK_SLAB.getDefaultState().with(SlabBlock.TYPE, SlabType.TOP).with(SlabBlock.WATERLOGGED, false));
        structure.fillWithBlocks(world, start, 6, 4, -22, 6, 5, -22, Blocks.COBBLESTONE.getDefaultState());
        structure.fillWithBlocks(world, start, 6, 4, 27, 6, 4, 32, Blocks.OAK_PLANKS.getDefaultState());
        structure.fillWithBlocks(world, start, 6, 4, 33, 6, 4, 34, Blocks.OAK_STAIRS.getDefaultState().with(StairsBlock.FACING, Direction.EAST).with(StairsBlock.WATERLOGGED, false).with(StairsBlock.SHAPE, StairsShape.STRAIGHT).with(StairsBlock.HALF, Half.BOTTOM));
        structure.fillWithBlocks(world, start, 6, 5, -40, 6, 5, -38, Blocks.SNOW.getDefaultState().with(SnowBlock.LAYERS, 1));
        structure.fillWithBlocks(world, start, 6, 5, -36, 6, 5, -22, Blocks.COBBLESTONE.getDefaultState());
        structure.fillWithBlocks(world, start, 6, 5, 27, 6, 5, 32, Blocks.SNOW.getDefaultState().with(SnowBlock.LAYERS, 1));
        structure.fillWithBlocks(world, start, 6, 6, -36, 6, 6, -35, Blocks.SNOW.getDefaultState().with(SnowBlock.LAYERS, 1));
        structure.fillWithBlocks(world, start, 6, 6, -32, 8, 6, -26, Blocks.COBBLESTONE.getDefaultState());
        structure.fillWithBlocks(world, start, 6, 6, -23, 6, 6, -22, Blocks.SNOW.getDefaultState().with(SnowBlock.LAYERS, 1));
        structure.fillWithBlocks(world, start, 6, 7, -32, 6, 7, -26, Blocks.SNOW.getDefaultState().with(SnowBlock.LAYERS, 1));
        structure.fillWithBlocks(world, start, 7, -7, -74, 7, -7, -72, Blocks.DIRT.getDefaultState());
        structure.fillWithBlocks(world, start, 7, -7, -65, 17, -7, -54, Blocks.STONE.getDefaultState());
        structure.fillWithBlocks(world, start, 7, -7, -42, 7, -7, -42, Blocks.GRAVEL.getDefaultState());
        structure.fillWithBlocks(world, start, 7, -7, -41, 7, -7, -34, Blocks.STONE.getDefaultState());
        structure.fillWithBlocks(world, start, 7, -7, -33, 7, -6, -33, Blocks.COAL_ORE.getDefaultState());
        structure.fillWithBlocks(world, start, 7, -7, -32, 18, -7, -5, Blocks.STONE.getDefaultState());
        structure.fillWithBlocks(world, start, 7, -7, -3, 9, -7, 0, Blocks.GRANITE.getDefaultState());
        structure.fillWithBlocks(world, start, 7, -7, 4, 9, -7, 8, Blocks.DIORITE.getDefaultState());
        structure.fillWithBlocks(world, start, 7, -7, 48, 7, -7, 49, Blocks.ANDESITE.getDefaultState());
        structure.fillWithBlocks(world, start, 7, -7, 50, 16, -7, 60, Blocks.STONE.getDefaultState());
        structure.fillWithBlocks(world, start, 7, -7, 76, 9, -7, 78, Blocks.GRASS_BLOCK.getDefaultState().with(SnowyDirtBlock.SNOWY, true));
        structure.fillWithBlocks(world, start, 7, -6, -71, 9, -6, -68, Blocks.DIORITE.getDefaultState());
        structure.fillWithBlocks(world, start, 7, -6, -66, 8, -6, -65, Blocks.IRON_ORE.getDefaultState());
        structure.fillWithBlocks(world, start, 7, -6, -64, 13, -6, -58, Blocks.STONE.getDefaultState());
        structure.fillWithBlocks(world, start, 7, -6, -57, 8, -6, -56, Blocks.DIRT.getDefaultState());
        structure.fillWithBlocks(world, start, 7, -6, -48, 7, -6, -47, Blocks.GRAVEL.getDefaultState());
        structure.fillWithBlocks(world, start, 7, -6, -10, 8, -6, -8, Blocks.STONE.getDefaultState());
        structure.fillWithBlocks(world, start, 7, -6, -5, 9, -6, -2, Blocks.DIRT.getDefaultState());
        structure.fillWithBlocks(world, start, 7, -6, 5, 9, -6, 11, Blocks.DIRT.getDefaultState());
        structure.fillWithBlocks(world, start, 7, -6, 23, 13, -6, 32, Blocks.STONE.getDefaultState());
        structure.fillWithBlocks(world, start, 7, -6, 33, 7, -6, 43, Blocks.DIRT.getDefaultState());
        structure.fillWithBlocks(world, start, 7, -6, 58, 8, -6, 59, Blocks.DIRT.getDefaultState());
        structure.fillWithBlocks(world, start, 7, -6, 72, 8, -6, 73, Blocks.DIRT.getDefaultState());
        structure.fillWithBlocks(world, start, 7, -6, 74, 8, -6, 75, Blocks.GRASS_BLOCK.getDefaultState().with(SnowyDirtBlock.SNOWY, true));
        structure.fillWithBlocks(world, start, 7, -6, 76, 9, -6, 78, Blocks.SNOW.getDefaultState().with(SnowBlock.LAYERS, 1));
        structure.fillWithBlocks(world, start, 7, -5, -22, 39, -2, -22, Blocks.DIRT.getDefaultState());
        structure.fillWithBlocks(world, start, 7, -5, -21, 8, -5, -17, Blocks.STONE.getDefaultState());
        structure.fillWithBlocks(world, start, 7, -5, -16, 17, -5, -1, Blocks.DIRT.getDefaultState());
        structure.fillWithBlocks(world, start, 7, -5, 74, 8, -5, 75, Blocks.SNOW.getDefaultState().with(SnowBlock.LAYERS, 1));
        structure.fillWithBlocks(world, start, 7, -4, 58, 8, -4, 59, Blocks.GRASS_BLOCK.getDefaultState().with(SnowyDirtBlock.SNOWY, false));
        structure.fillWithBlocks(world, start, 7, -3, -16, 8, -2, -16, Blocks.COARSE_DIRT.getDefaultState());
        structure.fillWithBlocks(world, start, 7, -3, -15, 7, -2, -14, Blocks.DIRT.getDefaultState());
        structure.fillWithBlocks(world, start, 7, -3, -13, 7, -2, -12, Blocks.COARSE_DIRT.getDefaultState());
        structure.fillWithBlocks(world, start, 7, -2, -59, 64, -2, -59, Blocks.DIRT.getDefaultState());
        structure.fillWithBlocks(world, start, 7, -1, -59, 64, -1, -59, Blocks.GRASS_BLOCK.getDefaultState().with(SnowyDirtBlock.SNOWY, true));
        structure.fillWithBlocks(world, start, 7, -1, -36, 7, -1, -23, Blocks.COBBLESTONE.getDefaultState());
        structure.fillWithBlocks(world, start, 7, -1, -16, 8, -1, -16, Blocks.COARSE_DIRT.getDefaultState());
        structure.fillWithBlocks(world, start, 7, -1, -15, 7, -1, -14, Blocks.GRASS_BLOCK.getDefaultState().with(SnowyDirtBlock.SNOWY, true));
        structure.fillWithBlocks(world, start, 7, -1, -13, 7, -1, -12, Blocks.COARSE_DIRT.getDefaultState());
        structure.fillWithBlocks(world, start, 7, -1, -11, 7, -1, -11, Blocks.DIRT.getDefaultState());
        structure.fillWithBlocks(world, start, 7, -1, -10, 7, -1, -5, Blocks.POLISHED_ANDESITE.getDefaultState());
        structure.fillWithBlocks(world, start, 7, -1, 9, 8, -1, 12, Blocks.GRASS_BLOCK.getDefaultState().with(SnowyDirtBlock.SNOWY, true));
        structure.fillWithBlocks(world, start, 7, -1, 13, 8, -1, 15, Blocks.GRASS_PATH.getDefaultState());
        structure.fillWithBlocks(world, start, 7, -1, 16, 8, -1, 24, Blocks.GRASS_BLOCK.getDefaultState().with(SnowyDirtBlock.SNOWY, true));
        structure.fillWithBlocks(world, start, 7, -1, 45, 8, -1, 46, Blocks.GRASS_BLOCK.getDefaultState().with(SnowyDirtBlock.SNOWY, true));
        structure.fillWithBlocks(world, start, 7, -1, 47, 10, -1, 50, Blocks.DIRT.getDefaultState());
        structure.fillWithBlocks(world, start, 7, -1, 53, 9, -1, 55, Blocks.DIRT.getDefaultState());
        structure.fillWithBlocks(world, start, 7, 0, -59, 64, 0, -59, Blocks.SNOW.getDefaultState().with(SnowBlock.LAYERS, 1));
        structure.fillWithBlocks(world, start, 7, 0, -54, 8, 0, -54, Blocks.SNOW.getDefaultState().with(SnowBlock.LAYERS, 1));
        structure.fillWithBlocks(world, start, 7, 0, -52, 7, 2, -52, Blocks.SPRUCE_LOG.getDefaultState());
        structure.fillWithBlocks(world, start, 7, 0, -51, 7, 3, -51, Blocks.OAK_LOG.getDefaultState());
        structure.fillWithBlocks(world, start, 7, 0, -48, 7, 1, -47, Blocks.DIRT.getDefaultState());
        structure.fillWithBlocks(world, start, 7, 0, -45, 7, 1, -45, Blocks.SPRUCE_LOG.getDefaultState());
        structure.fillWithBlocks(world, start, 7, 0, -22, 7, 3, -22, Blocks.STONE_BRICKS.getDefaultState());
        structure.fillWithBlocks(world, start, 7, 0, -16, 11, 0, -12, Blocks.SNOW.getDefaultState().with(SnowBlock.LAYERS, 1));
        structure.fillWithBlocks(world, start, 7, 0, -11, 10, 2, -11, Blocks.STONE.getDefaultState());
        structure.fillWithBlocks(world, start, 7, 0, -5, 7, 1, -5, Blocks.BIRCH_FENCE.getDefaultState().with(FourWayBlock.WATERLOGGED, false).with(FourWayBlock.NORTH, false).with(FourWayBlock.SOUTH, true).with(FourWayBlock.EAST, true).with(FourWayBlock.WEST, false));
        structure.fillWithBlocks(world, start, 7, 0, -2, 9, 0, -2, Blocks.STONE_BRICK_SLAB.getDefaultState().with(SlabBlock.TYPE, SlabType.TOP).with(SlabBlock.WATERLOGGED, false));
        structure.fillWithBlocks(world, start, 7, 0, 29, 9, 0, 29, Blocks.POLISHED_ANDESITE_STAIRS.getDefaultState().with(StairsBlock.FACING, Direction.NORTH).with(StairsBlock.WATERLOGGED, false).with(StairsBlock.SHAPE, StairsShape.STRAIGHT).with(StairsBlock.HALF, Half.TOP));
        structure.fillWithBlocks(world, start, 7, 0, 46, 18, 0, 46, Blocks.SNOW.getDefaultState().with(SnowBlock.LAYERS, 1));
        structure.fillWithBlocks(world, start, 7, 0, 47, 7, 1, 47, Blocks.OAK_LOG.getDefaultState());
        structure.fillWithBlocks(world, start, 7, 0, 48, 7, 0, 49, Blocks.DIRT.getDefaultState());
        structure.fillWithBlocks(world, start, 7, 0, 50, 7, 2, 50, Blocks.OAK_LOG.getDefaultState());
        structure.fillWithBlocks(world, start, 7, 0, 53, 7, 3, 53, Blocks.OAK_LOG.getDefaultState());
        structure.fillWithBlocks(world, start, 7, 0, 54, 7, 2, 54, Blocks.SPRUCE_LOG.getDefaultState());
        structure.fillWithBlocks(world, start, 7, 1, -46, 16, 1, -46, Blocks.GRASS_BLOCK.getDefaultState().with(SnowyDirtBlock.SNOWY, true));
        structure.fillWithBlocks(world, start, 7, 1, -39, 8, 1, -39, Blocks.BARREL.getDefaultState().with(BarrelBlock.PROPERTY_FACING, Direction.UP).with(BarrelBlock.PROPERTY_OPEN, false));
        structure.fillWithBlocks(world, start, 7, 1, -10, 10, 3, -10, Blocks.STONE.getDefaultState());
        structure.fillWithBlocks(world, start, 7, 1, -4, 7, 3, -4, Blocks.STONE.getDefaultState());
        structure.fillWithBlocks(world, start, 7, 1, 48, 7, 1, 49, Blocks.GRASS_BLOCK.getDefaultState().with(SnowyDirtBlock.SNOWY, true));
        structure.fillWithBlocks(world, start, 7, 2, -48, 17, 2, -48, Blocks.GRASS_BLOCK.getDefaultState().with(SnowyDirtBlock.SNOWY, true));
        structure.fillWithBlocks(world, start, 7, 2, -46, 16, 2, -46, Blocks.SNOW.getDefaultState().with(SnowBlock.LAYERS, 1));
        structure.fillWithBlocks(world, start, 7, 2, -36, 8, 3, -36, Blocks.STONE_BRICKS.getDefaultState());
        structure.fillWithBlocks(world, start, 7, 2, -9, 10, 4, -9, Blocks.STONE.getDefaultState());
        structure.fillWithBlocks(world, start, 7, 2, -5, 8, 2, -4, Blocks.STONE.getDefaultState());
        structure.fillWithBlocks(world, start, 7, 2, -2, 9, 2, -2, Blocks.STONE_SLAB.getDefaultState().with(SlabBlock.TYPE, SlabType.TOP).with(SlabBlock.WATERLOGGED, false));
        structure.fillWithBlocks(world, start, 7, 2, 48, 7, 2, 49, Blocks.SNOW.getDefaultState().with(SnowBlock.LAYERS, 1));
        structure.fillWithBlocks(world, start, 7, 3, -48, 17, 3, -48, Blocks.SNOW.getDefaultState().with(SnowBlock.LAYERS, 1));
        structure.fillWithBlocks(world, start, 7, 3, -11, 10, 3, -11, Blocks.SNOW.getDefaultState().with(SnowBlock.LAYERS, 1));
        structure.fillWithBlocks(world, start, 7, 3, -8, 10, 5, -8, Blocks.STONE.getDefaultState());
        structure.fillWithBlocks(world, start, 7, 3, -6, 9, 3, -4, Blocks.STONE.getDefaultState());
        structure.fillWithBlocks(world, start, 7, 3, 12, 8, 3, 12, Blocks.OAK_PLANKS.getDefaultState());
        structure.fillWithBlocks(world, start, 7, 3, 16, 7, 3, 16, Blocks.OAK_PLANKS.getDefaultState());
        structure.fillWithBlocks(world, start, 7, 3, 37, 8, 3, 38, Blocks.OAK_PLANKS.getDefaultState());
        structure.fillWithBlocks(world, start, 7, 3, 45, 9, 3, 45, Blocks.OAK_PLANKS.getDefaultState());
        structure.fillWithBlocks(world, start, 7, 4, -28, 7, 5, -28, Blocks.STONE_BRICK_SLAB.getDefaultState().with(SlabBlock.TYPE, SlabType.TOP).with(SlabBlock.WATERLOGGED, false));
        structure.fillWithBlocks(world, start, 7, 4, -10, 10, 4, -10, Blocks.SNOW.getDefaultState().with(SnowBlock.LAYERS, 1));
        structure.fillWithBlocks(world, start, 7, 4, -7, 9, 4, -5, Blocks.STONE.getDefaultState());
        structure.fillWithBlocks(world, start, 7, 4, -4, 10, 4, -4, Blocks.SNOW.getDefaultState().with(SnowBlock.LAYERS, 1));
        structure.fillWithBlocks(world, start, 7, 4, 37, 9, 4, 37, Blocks.SNOW.getDefaultState().with(SnowBlock.LAYERS, 1));
        structure.fillWithBlocks(world, start, 7, 4, 38, 8, 4, 39, Blocks.OAK_PLANKS.getDefaultState());
        structure.fillWithBlocks(world, start, 7, 4, 44, 9, 4, 44, Blocks.OAK_PLANKS.getDefaultState());
        structure.fillWithBlocks(world, start, 7, 4, 45, 9, 4, 45, Blocks.SNOW.getDefaultState().with(SnowBlock.LAYERS, 1));
        structure.fillWithBlocks(world, start, 7, 5, -40, 7, 5, -37, Blocks.COBBLESTONE.getDefaultState());
        structure.fillWithBlocks(world, start, 7, 5, -35, 7, 5, -34, Blocks.STONE_BRICK_SLAB.getDefaultState().with(SlabBlock.TYPE, SlabType.TOP).with(SlabBlock.WATERLOGGED, false));
        structure.fillWithBlocks(world, start, 7, 5, -32, 7, 5, -31, Blocks.STONE_BRICK_SLAB.getDefaultState().with(SlabBlock.TYPE, SlabType.TOP).with(SlabBlock.WATERLOGGED, false));
        structure.fillWithBlocks(world, start, 7, 5, -29, 7, 5, -26, Blocks.STONE_BRICK_SLAB.getDefaultState().with(SlabBlock.TYPE, SlabType.TOP).with(SlabBlock.WATERLOGGED, false));
        structure.fillWithBlocks(world, start, 7, 5, -24, 7, 5, -23, Blocks.STONE_BRICK_SLAB.getDefaultState().with(SlabBlock.TYPE, SlabType.TOP).with(SlabBlock.WATERLOGGED, false));
        structure.fillWithBlocks(world, start, 7, 5, -9, 10, 5, -9, Blocks.SNOW.getDefaultState().with(SnowBlock.LAYERS, 1));
        structure.fillWithBlocks(world, start, 7, 5, -7, 8, 5, -6, Blocks.STONE.getDefaultState());
        structure.fillWithBlocks(world, start, 7, 5, -5, 10, 5, -5, Blocks.SNOW.getDefaultState().with(SnowBlock.LAYERS, 1));
        structure.fillWithBlocks(world, start, 7, 5, 13, 9, 5, 13, Blocks.OAK_PLANKS.getDefaultState());
        structure.fillWithBlocks(world, start, 7, 5, 15, 9, 5, 15, Blocks.OAK_PLANKS.getDefaultState());
        structure.fillWithBlocks(world, start, 7, 5, 27, 9, 5, 32, Blocks.OAK_PLANKS.getDefaultState());
        structure.fillWithBlocks(world, start, 7, 5, 38, 9, 5, 38, Blocks.SNOW.getDefaultState().with(SnowBlock.LAYERS, 1));
        structure.fillWithBlocks(world, start, 7, 5, 39, 8, 5, 40, Blocks.OAK_PLANKS.getDefaultState());
        structure.fillWithBlocks(world, start, 7, 5, 41, 7, 5, 43, Blocks.OAK_PLANKS.getDefaultState());
        structure.fillWithBlocks(world, start, 7, 5, 44, 9, 5, 44, Blocks.SNOW.getDefaultState().with(SnowBlock.LAYERS, 1));
        structure.fillWithBlocks(world, start, 7, 6, -40, 7, 6, -38, Blocks.SNOW.getDefaultState().with(SnowBlock.LAYERS, 1));
        structure.fillWithBlocks(world, start, 7, 6, -36, 7, 6, -22, Blocks.COBBLESTONE.getDefaultState());
        structure.fillWithBlocks(world, start, 7, 6, -8, 10, 6, -8, Blocks.SNOW.getDefaultState().with(SnowBlock.LAYERS, 1));
        structure.fillWithBlocks(world, start, 7, 6, -7, 10, 6, -7, Blocks.STONE.getDefaultState());
        structure.fillWithBlocks(world, start, 7, 6, -6, 10, 6, -6, Blocks.SNOW.getDefaultState().with(SnowBlock.LAYERS, 1));
        structure.fillWithBlocks(world, start, 7, 6, 13, 8, 6, 13, Blocks.OAK_STAIRS.getDefaultState().with(StairsBlock.FACING, Direction.SOUTH).with(StairsBlock.WATERLOGGED, false).with(StairsBlock.SHAPE, StairsShape.STRAIGHT).with(StairsBlock.HALF, Half.BOTTOM));
        structure.fillWithBlocks(world, start, 7, 6, 15, 8, 6, 15, Blocks.OAK_STAIRS.getDefaultState().with(StairsBlock.FACING, Direction.NORTH).with(StairsBlock.WATERLOGGED, false).with(StairsBlock.SHAPE, StairsShape.STRAIGHT).with(StairsBlock.HALF, Half.BOTTOM));
        structure.fillWithBlocks(world, start, 7, 6, 27, 7, 6, 32, Blocks.SNOW.getDefaultState().with(SnowBlock.LAYERS, 1));
        structure.fillWithBlocks(world, start, 7, 6, 39, 9, 6, 39, Blocks.SNOW.getDefaultState().with(SnowBlock.LAYERS, 1));
        structure.fillWithBlocks(world, start, 7, 6, 40, 9, 6, 42, Blocks.OAK_PLANKS.getDefaultState());
        structure.fillWithBlocks(world, start, 7, 6, 43, 9, 6, 43, Blocks.SNOW.getDefaultState().with(SnowBlock.LAYERS, 1));
        structure.fillWithBlocks(world, start, 7, 7, -36, 7, 7, -34, Blocks.SNOW.getDefaultState().with(SnowBlock.LAYERS, 1));
        structure.fillWithBlocks(world, start, 7, 7, -32, 7, 7, -26, Blocks.COBBLESTONE.getDefaultState());
        structure.fillWithBlocks(world, start, 7, 7, -24, 7, 7, -22, Blocks.SNOW.getDefaultState().with(SnowBlock.LAYERS, 1));
        structure.fillWithBlocks(world, start, 7, 7, -7, 10, 7, -7, Blocks.SNOW.getDefaultState().with(SnowBlock.LAYERS, 1));
        structure.fillWithBlocks(world, start, 7, 7, 14, 9, 8, 14, Blocks.OAK_PLANKS.getDefaultState());
        structure.fillWithBlocks(world, start, 7, 7, 40, 9, 7, 40, Blocks.SNOW.getDefaultState().with(SnowBlock.LAYERS, 1));
        structure.fillWithBlocks(world, start, 7, 7, 41, 9, 7, 41, Blocks.OAK_PLANKS.getDefaultState());
        structure.fillWithBlocks(world, start, 7, 7, 42, 9, 7, 42, Blocks.SNOW.getDefaultState().with(SnowBlock.LAYERS, 1));
        structure.fillWithBlocks(world, start, 7, 8, -32, 7, 8, -26, Blocks.SNOW.getDefaultState().with(SnowBlock.LAYERS, 1));
        structure.fillWithBlocks(world, start, 7, 8, 41, 9, 8, 41, Blocks.SNOW.getDefaultState().with(SnowBlock.LAYERS, 1));
        structure.fillWithBlocks(world, start, 7, 9, 14, 8, 9, 14, Blocks.SNOW.getDefaultState().with(SnowBlock.LAYERS, 1));
        structure.fillWithBlocks(world, start, 8, -7, -74, 57, -7, -74, Blocks.GRASS_BLOCK.getDefaultState().with(SnowyDirtBlock.SNOWY, true));
        structure.fillWithBlocks(world, start, 8, -7, -73, 9, -7, -72, Blocks.DIRT.getDefaultState());
        structure.fillWithBlocks(world, start, 8, -7, -67, 8, -5, -67, Blocks.DIORITE.getDefaultState());
        structure.fillWithBlocks(world, start, 8, -7, -66, 12, -7, -47, Blocks.STONE.getDefaultState());
        structure.fillWithBlocks(world, start, 8, -7, -46, 8, -7, -41, Blocks.GRAVEL.getDefaultState());
        structure.fillWithBlocks(world, start, 8, -7, -40, 8, -7, -5, Blocks.STONE.getDefaultState());
        structure.fillWithBlocks(world, start, 8, -7, -4, 9, -7, 0, Blocks.GRANITE.getDefaultState());
        structure.fillWithBlocks(world, start, 8, -7, 1, 8, -6, 1, Blocks.GRANITE.getDefaultState());
        structure.fillWithBlocks(world, start, 8, -7, 2, 8, -7, 9, Blocks.DIORITE.getDefaultState());
        structure.fillWithBlocks(world, start, 8, -7, 48, 8, -7, 48, Blocks.STONE.getDefaultState());
        structure.fillWithBlocks(world, start, 8, -7, 49, 8, -6, 49, Blocks.ANDESITE.getDefaultState());
        structure.fillWithBlocks(world, start, 8, -7, 73, 10, -7, 75, Blocks.DIRT.getDefaultState());
        structure.fillWithBlocks(world, start, 8, -6, -74, 57, -6, -74, Blocks.SNOW.getDefaultState().with(SnowBlock.LAYERS, 1));
        structure.fillWithBlocks(world, start, 8, -6, -48, 8, -6, -48, Blocks.STONE.getDefaultState());
        structure.fillWithBlocks(world, start, 8, -6, -33, 11, -6, -30, Blocks.STONE.getDefaultState());
        structure.fillWithBlocks(world, start, 8, -6, -7, 10, -6, -3, Blocks.DIRT.getDefaultState());
        structure.fillWithBlocks(world, start, 8, -6, -1, 8, -2, -1, Blocks.DIRT.getDefaultState());
        structure.fillWithBlocks(world, start, 8, -6, 0, 8, -6, 3, Blocks.GRANITE.getDefaultState());
        structure.fillWithBlocks(world, start, 8, -6, 4, 8, -6, 13, Blocks.DIRT.getDefaultState());
        structure.fillWithBlocks(world, start, 8, -6, 14, 8, -6, 33, Blocks.STONE.getDefaultState());
        structure.fillWithBlocks(world, start, 8, -6, 34, 8, -2, 43, Blocks.DIRT.getDefaultState());
        structure.fillWithBlocks(world, start, 8, -6, 48, 8, -6, 48, Blocks.STONE.getDefaultState());
        structure.fillWithBlocks(world, start, 8, -5, -71, 9, -4, -71, Blocks.DIRT.getDefaultState());
        structure.fillWithBlocks(world, start, 8, -5, -70, 9, -5, -68, Blocks.DIORITE.getDefaultState());
        structure.fillWithBlocks(world, start, 8, -5, -66, 21, -5, -53, Blocks.DIRT.getDefaultState());
        structure.fillWithBlocks(world, start, 8, -5, -52, 13, -5, -22, Blocks.DIRT.getDefaultState());
        structure.fillWithBlocks(world, start, 8, -5, 23, 8, -2, 23, Blocks.DIRT.getDefaultState());
        structure.fillWithBlocks(world, start, 8, -5, 24, 9, -5, 25, Blocks.STONE.getDefaultState());
        structure.fillWithBlocks(world, start, 8, -5, 27, 8, -2, 56, Blocks.DIRT.getDefaultState());
        structure.fillWithBlocks(world, start, 8, -4, -57, 8, -4, -56, Blocks.GRASS_BLOCK.getDefaultState().with(SnowyDirtBlock.SNOWY, false));
        structure.fillWithBlocks(world, start, 8, -3, -58, 8, -3, -58, Blocks.DIRT.getDefaultState());
        structure.fillWithBlocks(world, start, 8, -3, -15, 8, -2, -15, Blocks.DIRT.getDefaultState());
        structure.fillWithBlocks(world, start, 8, -3, -14, 10, -1, -14, Blocks.COARSE_DIRT.getDefaultState());
        structure.fillWithBlocks(world, start, 8, -3, -13, 14, -3, -4, Blocks.DIRT.getDefaultState());
        structure.fillWithBlocks(world, start, 8, -3, -3, 9, -3, -2, Blocks.COARSE_DIRT.getDefaultState());
        structure.fillWithBlocks(world, start, 8, -2, -58, 8, -2, -58, Blocks.GRASS_BLOCK.getDefaultState().with(SnowyDirtBlock.SNOWY, true));
        structure.fillWithBlocks(world, start, 8, -2, -54, 8, -2, -49, Blocks.DIRT.getDefaultState());
        structure.fillWithBlocks(world, start, 8, -2, -47, 25, -2, -30, Blocks.DIRT.getDefaultState());
        structure.fillWithBlocks(world, start, 8, -2, -18, 8, -2, -17, Blocks.DIRT.getDefaultState());
        structure.fillWithBlocks(world, start, 8, -2, -13, 14, -2, -4, Blocks.DIRT.getDefaultState());
        structure.fillWithBlocks(world, start, 8, -2, -3, 9, -2, -2, Blocks.COARSE_DIRT.getDefaultState());
        structure.fillWithBlocks(world, start, 8, -1, -58, 8, -1, -58, Blocks.SNOW.getDefaultState().with(SnowBlock.LAYERS, 1));
        structure.fillWithBlocks(world, start, 8, -1, -53, 8, -1, -49, Blocks.DIRT.getDefaultState());
        structure.fillWithBlocks(world, start, 8, -1, -47, 10, -1, -45, Blocks.DIRT.getDefaultState());
        structure.fillWithBlocks(world, start, 8, -1, -36, 10, -1, -36, Blocks.DIRT.getDefaultState());
        structure.fillWithBlocks(world, start, 8, -1, -17, 8, -1, -17, Blocks.GRASS_BLOCK.getDefaultState().with(SnowyDirtBlock.SNOWY, true));
        structure.fillWithBlocks(world, start, 8, -1, -13, 9, -1, -12, Blocks.GRASS_BLOCK.getDefaultState().with(SnowyDirtBlock.SNOWY, true));
        structure.fillWithBlocks(world, start, 8, -1, -11, 9, -1, -10, Blocks.DIRT.getDefaultState());
        structure.fillWithBlocks(world, start, 8, -1, -4, 10, -1, -4, Blocks.POLISHED_ANDESITE.getDefaultState());
        structure.fillWithBlocks(world, start, 8, -1, -3, 9, -1, -2, Blocks.COARSE_DIRT.getDefaultState());
        structure.fillWithBlocks(world, start, 8, -1, 25, 8, -1, 33, Blocks.COBBLESTONE.getDefaultState());
        structure.fillWithBlocks(world, start, 8, 0, -52, 8, 2, -52, Blocks.OAK_LOG.getDefaultState());
        structure.fillWithBlocks(world, start, 8, 0, -51, 9, 1, -51, Blocks.SPRUCE_LOG.getDefaultState());
        structure.fillWithBlocks(world, start, 8, 0, -50, 8, 0, -48, Blocks.DIRT.getDefaultState());
        structure.fillWithBlocks(world, start, 8, 0, -47, 8, 2, -47, Blocks.OAK_LOG.getDefaultState());
        structure.fillWithBlocks(world, start, 8, 0, -46, 17, 0, -46, Blocks.DIRT.getDefaultState());
        structure.fillWithBlocks(world, start, 8, 0, -45, 8, 1, -45, Blocks.OAK_LOG.getDefaultState());
        structure.fillWithBlocks(world, start, 8, 0, -36, 8, 3, -36, Blocks.STONE_BRICKS.getDefaultState());
        structure.fillWithBlocks(world, start, 8, 0, -34, 8, 0, -32, Index.STOOL_OAK.getDefaultState().with(Stool.PILLOW, StoolState.NONE));
        structure.fillWithBlocks(world, start, 8, 0, -29, 11, 0, -29, Blocks.STONE_BRICKS.getDefaultState());
        structure.fillWithBlocks(world, start, 8, 0, -27, 8, 0, -25, Blocks.STONE_BRICK_STAIRS.getDefaultState().with(StairsBlock.FACING, Direction.EAST).with(StairsBlock.WATERLOGGED, false).with(StairsBlock.SHAPE, StairsShape.STRAIGHT).with(StairsBlock.HALF, Half.TOP));
        structure.fillWithBlocks(world, start, 8, 0, -23, 11, 0, -23, Blocks.STONE_BRICKS.getDefaultState());
        structure.fillWithBlocks(world, start, 8, 0, -22, 9, 1, -22, Blocks.BRICKS.getDefaultState());
        structure.fillWithBlocks(world, start, 8, 0, -17, 11, 0, -12, Blocks.SNOW.getDefaultState().with(SnowBlock.LAYERS, 1));
        structure.fillWithBlocks(world, start, 8, 0, -5, 8, 1, -5, Blocks.BIRCH_FENCE.getDefaultState().with(FourWayBlock.WATERLOGGED, false).with(FourWayBlock.NORTH, false).with(FourWayBlock.SOUTH, false).with(FourWayBlock.EAST, true).with(FourWayBlock.WEST, true));
        structure.fillWithBlocks(world, start, 8, 0, 21, 8, 0, 23, Blocks.SNOW.getDefaultState().with(SnowBlock.LAYERS, 1));
        structure.fillWithBlocks(world, start, 8, 0, 38, 8, 2, 38, Blocks.SPRUCE_LOG.getDefaultState());
        structure.fillWithBlocks(world, start, 8, 0, 39, 8, 0, 43, Blocks.SPRUCE_LOG.getDefaultState());
        structure.fillWithBlocks(world, start, 8, 0, 44, 8, 2, 44, Blocks.SPRUCE_LOG.getDefaultState());
        structure.fillWithBlocks(world, start, 8, 0, 47, 8, 1, 47, Blocks.SPRUCE_LOG.getDefaultState());
        structure.fillWithBlocks(world, start, 8, 0, 48, 19, 0, 48, Blocks.DIRT.getDefaultState());
        structure.fillWithBlocks(world, start, 8, 0, 49, 8, 2, 49, Blocks.SPRUCE_LOG.getDefaultState());
        structure.fillWithBlocks(world, start, 8, 0, 50, 8, 1, 51, Blocks.DIRT.getDefaultState());
        structure.fillWithBlocks(world, start, 8, 0, 53, 8, 3, 53, Blocks.SPRUCE_LOG.getDefaultState());
        structure.fillWithBlocks(world, start, 8, 0, 54, 8, 2, 54, Blocks.OAK_LOG.getDefaultState());
        structure.fillWithBlocks(world, start, 8, 1, -53, 8, 1, -53, Blocks.SNOW.getDefaultState().with(SnowBlock.LAYERS, 1));
        structure.fillWithBlocks(world, start, 8, 1, -50, 8, 1, -48, Blocks.DIRT.getDefaultState());
        structure.fillWithBlocks(world, start, 8, 1, 48, 19, 1, 48, Blocks.GRASS_BLOCK.getDefaultState().with(SnowyDirtBlock.SNOWY, true));
        structure.fillWithBlocks(world, start, 8, 1, 55, 9, 1, 55, Blocks.JUNGLE_FENCE_GATE.getDefaultState().with(FenceGateBlock.IN_WALL, false).with(FenceGateBlock.OPEN, false).with(FenceGateBlock.POWERED, false));
        structure.fillWithBlocks(world, start, 8, 2, -51, 9, 2, -51, Blocks.SPRUCE_LOG.getDefaultState());
        structure.fillWithBlocks(world, start, 8, 2, -49, 18, 2, -49, Blocks.DIRT.getDefaultState());
        structure.fillWithBlocks(world, start, 8, 2, 48, 19, 2, 48, Blocks.SNOW.getDefaultState().with(SnowBlock.LAYERS, 1));
        structure.fillWithBlocks(world, start, 8, 2, 50, 8, 2, 51, Blocks.GRASS_BLOCK.getDefaultState().with(SnowyDirtBlock.SNOWY, true));
        structure.fillWithBlocks(world, start, 8, 3, -49, 18, 3, -49, Blocks.SPRUCE_SLAB.getDefaultState().with(SlabBlock.TYPE, SlabType.BOTTOM).with(SlabBlock.WATERLOGGED, false));
        structure.fillWithBlocks(world, start, 8, 3, -40, 8, 3, -40, Blocks.COBBLESTONE.getDefaultState());
        structure.fillWithBlocks(world, start, 8, 3, 8, 8, 3, 12, Blocks.OAK_PLANKS.getDefaultState());
        structure.fillWithBlocks(world, start, 8, 3, 16, 8, 3, 20, Blocks.OAK_PLANKS.getDefaultState());
        structure.fillWithBlocks(world, start, 8, 3, 50, 8, 3, 51, Blocks.SNOW.getDefaultState().with(SnowBlock.LAYERS, 1));
        structure.fillWithBlocks(world, start, 8, 4, -40, 8, 4, -36, Blocks.COBBLESTONE.getDefaultState());
        structure.fillWithBlocks(world, start, 8, 4, -35, 8, 4, -34, Blocks.STONE_BRICK_SLAB.getDefaultState().with(SlabBlock.TYPE, SlabType.TOP).with(SlabBlock.WATERLOGGED, false));
        structure.fillWithBlocks(world, start, 8, 4, -32, 8, 4, -31, Blocks.STONE_BRICK_SLAB.getDefaultState().with(SlabBlock.TYPE, SlabType.TOP).with(SlabBlock.WATERLOGGED, false));
        structure.fillWithBlocks(world, start, 8, 4, -27, 8, 4, -26, Blocks.STONE_BRICK_SLAB.getDefaultState().with(SlabBlock.TYPE, SlabType.TOP).with(SlabBlock.WATERLOGGED, false));
        structure.fillWithBlocks(world, start, 8, 4, -24, 8, 4, -23, Blocks.STONE_BRICK_SLAB.getDefaultState().with(SlabBlock.TYPE, SlabType.TOP).with(SlabBlock.WATERLOGGED, false));
        structure.fillWithBlocks(world, start, 8, 4, -22, 9, 4, -22, Blocks.COBBLESTONE.getDefaultState());
        structure.fillWithBlocks(world, start, 8, 4, 9, 8, 4, 11, Blocks.OAK_STAIRS.getDefaultState().with(StairsBlock.FACING, Direction.EAST).with(StairsBlock.WATERLOGGED, false).with(StairsBlock.SHAPE, StairsShape.STRAIGHT).with(StairsBlock.HALF, Half.BOTTOM));
        structure.fillWithBlocks(world, start, 8, 4, 17, 8, 4, 19, Blocks.OAK_STAIRS.getDefaultState().with(StairsBlock.FACING, Direction.EAST).with(StairsBlock.WATERLOGGED, false).with(StairsBlock.SHAPE, StairsShape.STRAIGHT).with(StairsBlock.HALF, Half.BOTTOM));
        structure.fillWithBlocks(world, start, 8, 5, -40, 8, 5, -38, Blocks.SNOW.getDefaultState().with(SnowBlock.LAYERS, 1));
        structure.fillWithBlocks(world, start, 8, 5, -36, 8, 5, -22, Blocks.COBBLESTONE.getDefaultState());
        structure.fillWithBlocks(world, start, 8, 5, 26, 8, 5, 33, Blocks.OAK_PLANKS.getDefaultState());
        structure.fillWithBlocks(world, start, 8, 5, 42, 9, 5, 43, Blocks.OAK_PLANKS.getDefaultState());
        structure.fillWithBlocks(world, start, 8, 6, -36, 8, 6, -35, Blocks.SNOW.getDefaultState().with(SnowBlock.LAYERS, 1));
        structure.fillWithBlocks(world, start, 8, 6, -23, 8, 6, -22, Blocks.SNOW.getDefaultState().with(SnowBlock.LAYERS, 1));
        structure.fillWithBlocks(world, start, 8, 6, 27, 8, 6, 32, Blocks.OAK_PLANKS.getDefaultState());
        structure.fillWithBlocks(world, start, 8, 7, -32, 8, 7, -26, Blocks.SNOW.getDefaultState().with(SnowBlock.LAYERS, 1));
        structure.fillWithBlocks(world, start, 8, 7, 27, 8, 7, 32, Blocks.SNOW.getDefaultState().with(SnowBlock.LAYERS, 1));
        structure.fillWithBlocks(world, start, 9, -7, -67, 12, -7, -45, Blocks.STONE.getDefaultState());
        structure.fillWithBlocks(world, start, 9, -7, -44, 9, -7, -40, Blocks.GRAVEL.getDefaultState());
        structure.fillWithBlocks(world, start, 9, -7, -39, 13, -7, -5, Blocks.STONE.getDefaultState());
        structure.fillWithBlocks(world, start, 9, -7, 1, 10, -7, 2, Blocks.STONE.getDefaultState());
        structure.fillWithBlocks(world, start, 9, -7, 3, 9, -7, 8, Blocks.DIORITE.getDefaultState());
        structure.fillWithBlocks(world, start, 9, -7, 9, 16, -7, 16, Blocks.STONE.getDefaultState());
        structure.fillWithBlocks(world, start, 9, -7, 17, 10, -7, 17, Blocks.COAL_ORE.getDefaultState());
        structure.fillWithBlocks(world, start, 9, -7, 18, 14, -7, 23, Blocks.STONE.getDefaultState());
        structure.fillWithBlocks(world, start, 9, -7, 33, 10, -7, 34, Blocks.STONE.getDefaultState());
        structure.fillWithBlocks(world, start, 9, -7, 35, 9, -6, 35, Blocks.STONE.getDefaultState());
        structure.fillWithBlocks(world, start, 9, -7, 36, 10, -7, 36, Blocks.IRON_ORE.getDefaultState());
        structure.fillWithBlocks(world, start, 9, -7, 37, 20, -7, 48, Blocks.STONE.getDefaultState());
        structure.fillWithBlocks(world, start, 9, -7, 49, 16, -7, 60, Blocks.STONE.getDefaultState());
        structure.fillWithBlocks(world, start, 9, -6, -67, 14, -6, -62, Blocks.STONE.getDefaultState());
        structure.fillWithBlocks(world, start, 9, -6, -57, 17, -6, -57, Blocks.STONE.getDefaultState());
        structure.fillWithBlocks(world, start, 9, -6, -55, 27, -5, -55, Blocks.DIRT.getDefaultState());
        structure.fillWithBlocks(world, start, 9, -6, -54, 17, -6, -46, Blocks.STONE.getDefaultState());
        structure.fillWithBlocks(world, start, 9, -6, -45, 9, -5, -44, Blocks.DIRT.getDefaultState());
        structure.fillWithBlocks(world, start, 9, -6, -43, 14, -6, -38, Blocks.STONE.getDefaultState());
        structure.fillWithBlocks(world, start, 9, -6, -10, 10, -6, -9, Blocks.STONE.getDefaultState());
        structure.fillWithBlocks(world, start, 9, -6, -8, 11, -6, -5, Blocks.DIRT.getDefaultState());
        structure.fillWithBlocks(world, start, 9, -6, -1, 9, -6, 0, Blocks.GRANITE.getDefaultState());
        structure.fillWithBlocks(world, start, 9, -6, 1, 11, -6, 3, Blocks.STONE.getDefaultState());
        structure.fillWithBlocks(world, start, 9, -6, 12, 11, -6, 14, Blocks.DIRT.getDefaultState());
        structure.fillWithBlocks(world, start, 9, -6, 15, 9, -6, 35, Blocks.STONE.getDefaultState());
        structure.fillWithBlocks(world, start, 9, -6, 36, 9, -6, 43, Blocks.DIRT.getDefaultState());
        structure.fillWithBlocks(world, start, 9, -6, 48, 12, -6, 51, Blocks.STONE.getDefaultState());
        structure.fillWithBlocks(world, start, 9, -6, 58, 9, -5, 59, Blocks.DIRT.getDefaultState());
        structure.fillWithBlocks(world, start, 9, -6, 60, 12, -6, 63, Blocks.STONE.getDefaultState());
        structure.fillWithBlocks(world, start, 9, -6, 72, 9, -6, 73, Blocks.DIRT.getDefaultState());
        structure.fillWithBlocks(world, start, 9, -6, 74, 10, -6, 75, Blocks.GRASS_BLOCK.getDefaultState().with(SnowyDirtBlock.SNOWY, true));
        structure.fillWithBlocks(world, start, 9, -5, -67, 10, -5, -67, Blocks.STONE.getDefaultState());
        structure.fillWithBlocks(world, start, 9, -5, -21, 9, -5, -21, Blocks.DIRT.getDefaultState());
        structure.fillWithBlocks(world, start, 9, -5, -20, 9, -5, -18, Blocks.STONE.getDefaultState());
        structure.fillWithBlocks(world, start, 9, -5, -17, 15, -5, 22, Blocks.DIRT.getDefaultState());
        structure.fillWithBlocks(world, start, 9, -5, 23, 11, -5, 25, Blocks.STONE.getDefaultState());
        structure.fillWithBlocks(world, start, 9, -5, 26, 9, -5, 27, Blocks.IRON_ORE.getDefaultState());
        structure.fillWithBlocks(world, start, 9, -5, 28, 9, -5, 28, Blocks.STONE.getDefaultState());
