package mod.arcalitegames.odyssey.world.structure.structures.camps.bandit_camp;

import mod.arcalitegames.buildersaddition.Index;
import mod.arcalitegames.buildersaddition.blocks.Stool;
import mod.arcalitegames.buildersaddition.state.StoolState;
import mod.arcalitegames.odyssey.blocks.ChairBlock;
import mod.arcalitegames.odyssey.blocks.ModBlocks;
import mod.arcalitegames.odyssey.world.structure.StructureBase;
import net.minecraft.block.BedBlock;
import net.minecraft.block.Blocks;
import net.minecraft.block.ChestBlock;
import net.minecraft.block.HorizontalBlock;
import net.minecraft.block.LeavesBlock;
import net.minecraft.block.SlabBlock;
import net.minecraft.block.SnowyDirtBlock;
import net.minecraft.block.StairsBlock;
import net.minecraft.block.WallTorchBlock;
import net.minecraft.state.properties.BedPart;
import net.minecraft.state.properties.ChestType;
import net.minecraft.state.properties.Half;
import net.minecraft.state.properties.SlabType;
import net.minecraft.state.properties.StairsShape;
import net.minecraft.util.Direction;
import net.minecraft.util.math.BlockPos;
import net.minecraft.world.World;

public class BanditCampComponents
{
	public static BlockPos start;
    public static World world;
    public static StructureBase structure;

    public static void init(World worldIn, BlockPos blockPos, StructureBase structureIn)
    {
        world = worldIn; start = blockPos; structure = structureIn;
    }
    
    public static void generatePart1()
    {
        structure.setBlockState(world, Blocks.GRASS_BLOCK.getDefaultState().with(SnowyDirtBlock.SNOWY, false), 1, 3, 6, start);
        structure.setBlockState(world, Blocks.GRASS_BLOCK.getDefaultState().with(SnowyDirtBlock.SNOWY, false), 2, 3, 4, start);
        structure.setBlockState(world, Blocks.GRASS_BLOCK.getDefaultState().with(SnowyDirtBlock.SNOWY, false), 2, 3, 20, start);
        structure.setBlockState(world, Blocks.GRASS_BLOCK.getDefaultState().with(SnowyDirtBlock.SNOWY, false), 2, 4, 5, start);
        structure.setBlockState(world, Blocks.GRASS_BLOCK.getDefaultState().with(SnowyDirtBlock.SNOWY, false), 2, 4, 19, start);
        structure.setBlockState(world, Blocks.GRASS.getDefaultState(), 2, 6, 17, start);
        structure.setBlockState(world, Blocks.GRASS_BLOCK.getDefaultState().with(SnowyDirtBlock.SNOWY, false), 3, 2, 2, start);
        structure.setBlockState(world, Blocks.GRASS_BLOCK.getDefaultState().with(SnowyDirtBlock.SNOWY, false), 3, 2, 22, start);
        structure.setBlockState(world, Blocks.GRASS_BLOCK.getDefaultState().with(SnowyDirtBlock.SNOWY, false), 3, 3, 3, start);
        structure.setBlockState(world, Blocks.GRASS_BLOCK.getDefaultState().with(SnowyDirtBlock.SNOWY, false), 3, 4, 4, start);
        structure.setBlockState(world, Blocks.GRASS_BLOCK.getDefaultState().with(SnowyDirtBlock.SNOWY, false), 3, 4, 21, start);
        structure.setBlockState(world, Blocks.GRASS_BLOCK.getDefaultState().with(SnowyDirtBlock.SNOWY, false), 4, 2, 1, start);
        structure.setBlockState(world, Blocks.GRASS_BLOCK.getDefaultState().with(SnowyDirtBlock.SNOWY, false), 4, 3, 2, start);
        structure.setBlockState(world, Blocks.GRASS_BLOCK.getDefaultState().with(SnowyDirtBlock.SNOWY, false), 4, 3, 22, start);
        structure.setBlockState(world, Blocks.GRASS.getDefaultState(), 4, 6, 8, start);
        structure.setBlockState(world, Blocks.DIRT.getDefaultState(), 5, 5, 6, start);
        structure.setBlockState(world, Blocks.GRASS_BLOCK.getDefaultState().with(SnowyDirtBlock.SNOWY, false), 5, 5, 12, start);
        structure.setBlockState(world, Blocks.GRASS.getDefaultState(), 5, 6, 4, start);
        structure.setBlockState(world, Blocks.GRASS.getDefaultState(), 5, 7, 17, start);
        structure.setBlockState(world, Blocks.OAK_LEAVES.getDefaultState().with(LeavesBlock.PERSISTENT, false).with(LeavesBlock.DISTANCE, 1), 5, 12, 6, start);
        structure.setBlockState(world, Blocks.OAK_LEAVES.getDefaultState().with(LeavesBlock.PERSISTENT, false).with(LeavesBlock.DISTANCE, 2), 5, 12, 7, start);
        structure.setBlockState(world, Blocks.GRASS.getDefaultState(), 6, 6, 6, start);
        structure.setBlockState(world, Blocks.GRASS.getDefaultState(), 6, 6, 8, start);
        structure.setBlockState(world, Blocks.GRASS.getDefaultState(), 6, 6, 10, start);
        structure.setBlockState(world, Blocks.OAK_LEAVES.getDefaultState().with(LeavesBlock.PERSISTENT, false).with(LeavesBlock.DISTANCE, 2), 6, 12, 6, start);
        structure.setBlockState(world, Blocks.DIRT.getDefaultState(), 7, 6, 17, start);
        structure.setBlockState(world, Blocks.GRASS.getDefaultState(), 7, 7, 15, start);
        structure.setBlockState(world, Blocks.OAK_LEAVES.getDefaultState().with(LeavesBlock.PERSISTENT, false).with(LeavesBlock.DISTANCE, 4), 7, 9, 4, start);
        structure.setBlockState(world, Blocks.OAK_LEAVES.getDefaultState().with(LeavesBlock.PERSISTENT, false).with(LeavesBlock.DISTANCE, 4), 7, 10, 8, start);
        structure.setBlockState(world, Blocks.OAK_LEAVES.getDefaultState().with(LeavesBlock.PERSISTENT, false).with(LeavesBlock.DISTANCE, 1), 7, 12, 17, start);
        structure.setBlockState(world, Blocks.OAK_LEAVES.getDefaultState().with(LeavesBlock.PERSISTENT, false).with(LeavesBlock.DISTANCE, 2), 7, 12, 18, start);
        structure.setBlockState(world, Blocks.GRASS.getDefaultState(), 8, 6, 5, start);
        structure.setBlockState(world, Blocks.GRASS.getDefaultState(), 8, 7, 10, start);
        structure.setBlockState(world, Blocks.GRASS.getDefaultState(), 8, 7, 13, start);
        structure.setBlockState(world, Blocks.GRASS.getDefaultState(), 8, 7, 17, start);
        structure.setBlockState(world, Blocks.OAK_LEAVES.getDefaultState().with(LeavesBlock.PERSISTENT, false).with(LeavesBlock.DISTANCE, 2), 8, 12, 17, start);
        structure.setBlockState(world, Blocks.GRASS.getDefaultState(), 9, 7, 6, start);
        structure.setBlockState(world, Blocks.OAK_LEAVES.getDefaultState().with(LeavesBlock.PERSISTENT, false).with(LeavesBlock.DISTANCE, 4), 9, 10, 19, start);
        structure.setBlockState(world, Blocks.GRASS.getDefaultState(), 10, 5, 2, start);
        structure.setBlockState(world, Blocks.DIRT.getDefaultState(), 10, 6, 12, start);
        structure.setBlockState(world, Blocks.AIR.getDefaultState(), 10, 7, 7, start);
        structure.setBlockState(world, Blocks.SPRUCE_WOOD.getDefaultState(), 10, 12, 13, start);
        structure.setBlockState(world, Blocks.GRASS.getDefaultState(), 11, 7, 6, start);
        structure.setBlockState(world, Blocks.GRASS.getDefaultState(), 11, 7, 9, start);
        structure.setBlockState(world, Blocks.RED_BED.getDefaultState().with(HorizontalBlock.HORIZONTAL_FACING, Direction.WEST).with(BedBlock.PART, BedPart.HEAD), 11, 7, 12, start);
        structure.setBlockState(world, Blocks.AIR.getDefaultState(), 11, 7, 14, start);
        structure.setBlockState(world, Blocks.WALL_TORCH.getDefaultState().with(WallTorchBlock.HORIZONTAL_FACING, Direction.EAST), 11, 10, 13, start);
        structure.setBlockState(world, Blocks.SPRUCE_WOOD.getDefaultState(), 11, 11, 13, start);
        structure.setBlockState(world, Blocks.RED_BED.getDefaultState().with(HorizontalBlock.HORIZONTAL_FACING, Direction.WEST).with(BedBlock.PART, BedPart.FOOT), 12, 7, 12, start);
        structure.setBlockState(world, Blocks.BROWN_WOOL.getDefaultState(), 12, 11, 13, start);
        structure.setBlockState(world, Blocks.POPPY.getDefaultState(), 13, 7, 9, start);
        structure.setBlockState(world, Blocks.AIR.getDefaultState(), 13, 7, 13, start);
        structure.setBlockState(world, Blocks.AIR.getDefaultState(), 13, 7, 19, start);
        structure.setBlockState(world, Blocks.SPRUCE_WOOD.getDefaultState(), 13, 11, 13, start);
        structure.setBlockState(world, Blocks.GRASS.getDefaultState(), 14, 7, 4, start);
        structure.setBlockState(world, Blocks.BROWN_WOOL.getDefaultState(), 14, 11, 13, start);
        structure.setBlockState(world, Blocks.DIRT.getDefaultState(), 15, 6, 5, start);
        structure.setBlockState(world, Blocks.RED_BED.getDefaultState().with(HorizontalBlock.HORIZONTAL_FACING, Direction.NORTH).with(BedBlock.PART, BedPart.HEAD), 15, 7, 6, start);
        structure.setBlockState(world, Blocks.RED_BED.getDefaultState().with(HorizontalBlock.HORIZONTAL_FACING, Direction.NORTH).with(BedBlock.PART, BedPart.FOOT), 15, 7, 7, start);
        structure.setBlockState(world, Blocks.GRASS.getDefaultState(), 15, 7, 12, start);
        structure.setBlockState(world, Blocks.GRASS.getDefaultState(), 15, 7, 20, start);
        structure.setBlockState(world, Blocks.SPRUCE_WOOD.getDefaultState(), 15, 11, 13, start);
        structure.setBlockState(world, Blocks.AIR.getDefaultState(), 16, 7, 7, start);
        structure.setBlockState(world, ModBlocks.CHAIR.get().getDefaultState().with(ChairBlock.FACING, Direction.EAST), 16, 7, 11, start);
        structure.setBlockState(world, Blocks.GRASS.getDefaultState(), 16, 7, 15, start);
        structure.setBlockState(world, Blocks.GRASS.getDefaultState(), 16, 7, 17, start);
        structure.setBlockState(world, Blocks.SPRUCE_WOOD.getDefaultState(), 16, 12, 13, start);
        structure.setBlockState(world, Blocks.GRASS_BLOCK.getDefaultState().with(SnowyDirtBlock.SNOWY, false), 17, 5, 15, start);
        structure.setBlockState(world, Blocks.COBBLESTONE_STAIRS.getDefaultState().with(StairsBlock.FACING, Direction.NORTH).with(StairsBlock.WATERLOGGED, false).with(StairsBlock.SHAPE, StairsShape.STRAIGHT).with(StairsBlock.HALF, Half.TOP), 17, 6, 15, start);
        structure.setBlockState(world, Blocks.COBBLESTONE_SLAB.getDefaultState().with(SlabBlock.TYPE, SlabType.DOUBLE).with(SlabBlock.WATERLOGGED, false), 17, 6, 18, start);
        structure.setBlockState(world, Blocks.AIR.getDefaultState(), 17, 7, 5, start);
        structure.setBlockState(world, Blocks.AIR.getDefaultState(), 17, 7, 15, start);
        structure.setBlockState(world, Blocks.WALL_TORCH.getDefaultState().with(WallTorchBlock.HORIZONTAL_FACING, Direction.SOUTH), 17, 10, 6, start);
        structure.setBlockState(world, Blocks.BROWN_WOOL.getDefaultState(), 17, 11, 6, start);
        structure.setBlockState(world, Blocks.COBBLESTONE_SLAB.getDefaultState().with(SlabBlock.TYPE, SlabType.BOTTOM).with(SlabBlock.WATERLOGGED, false), 18, 6, 11, start);
        structure.setBlockState(world, Blocks.COBBLESTONE_STAIRS.getDefaultState().with(StairsBlock.FACING, Direction.NORTH).with(StairsBlock.WATERLOGGED, false).with(StairsBlock.SHAPE, StairsShape.STRAIGHT).with(StairsBlock.HALF, Half.BOTTOM), 18, 6, 13, start);
        structure.setBlockState(world, Blocks.CHEST.getDefaultState().with(ChestBlock.FACING, Direction.WEST).with(ChestBlock.WATERLOGGED, false).with(ChestBlock.TYPE, ChestType.RIGHT), 18, 7, 6, start);
        structure.setBlockState(world, Blocks.CHEST.getDefaultState().with(ChestBlock.FACING, Direction.WEST).with(ChestBlock.WATERLOGGED, false).with(ChestBlock.TYPE, ChestType.LEFT), 18, 7, 7, start);
        structure.setBlockState(world, Blocks.GRASS.getDefaultState(), 18, 7, 15, start);
        structure.setBlockState(world, Index.STOOL_OAK.getDefaultState().with(Stool.PILLOW, StoolState.NONE), 18, 7, 17, start);
        structure.setBlockState(world, Blocks.COBBLESTONE_SLAB.getDefaultState().with(SlabBlock.TYPE, SlabType.DOUBLE).with(SlabBlock.WATERLOGGED, false), 19, 6, 17, start);
        structure.setBlockState(world, Blocks.COBBLESTONE_STAIRS.getDefaultState().with(StairsBlock.FACING, Direction.SOUTH).with(StairsBlock.WATERLOGGED, false).with(StairsBlock.SHAPE, StairsShape.OUTER_LEFT).with(StairsBlock.HALF, Half.BOTTOM), 19, 7, 14, start);
        structure.setBlockState(world, Blocks.COBBLESTONE_STAIRS.getDefaultState().with(StairsBlock.FACING, Direction.EAST).with(StairsBlock.WATERLOGGED, false).with(StairsBlock.SHAPE, StairsShape.STRAIGHT).with(StairsBlock.HALF, Half.BOTTOM), 19, 7, 15, start);
        structure.setBlockState(world, Blocks.POPPY.getDefaultState(), 19, 7, 19, start);
        structure.setBlockState(world, Blocks.GRASS.getDefaultState(), 20, 7, 10, start);
        structure.setBlockState(world, Blocks.COBBLESTONE_SLAB.getDefaultState().with(SlabBlock.TYPE, SlabType.BOTTOM).with(SlabBlock.WATERLOGGED, false), 21, 6, 9, start);
        structure.setBlockState(world, Blocks.COBBLESTONE_SLAB.getDefaultState().with(SlabBlock.TYPE, SlabType.DOUBLE).with(SlabBlock.WATERLOGGED, false), 21, 6, 10, start);
        structure.setBlockState(world, Blocks.AIR.getDefaultState(), 21, 7, 10, start);
        structure.setBlockState(world, Blocks.COBBLESTONE_STAIRS.getDefaultState().with(StairsBlock.FACING, Direction.WEST).with(StairsBlock.WATERLOGGED, false).with(StairsBlock.SHAPE, StairsShape.STRAIGHT).with(StairsBlock.HALF, Half.BOTTOM), 21, 7, 13, start);
        structure.setBlockState(world, Blocks.OAK_LEAVES.getDefaultState().with(LeavesBlock.PERSISTENT, false).with(LeavesBlock.DISTANCE, 4), 21, 9, 9, start);
        structure.setBlockState(world, Blocks.COBBLESTONE_STAIRS.getDefaultState().with(StairsBlock.FACING, Direction.NORTH).with(StairsBlock.WATERLOGGED, false).with(StairsBlock.SHAPE, StairsShape.STRAIGHT).with(StairsBlock.HALF, Half.BOTTOM), 22, 6, 18, start);
        structure.setBlockState(world, Blocks.COBBLESTONE_STAIRS.getDefaultState().with(StairsBlock.FACING, Direction.SOUTH).with(StairsBlock.WATERLOGGED, false).with(StairsBlock.SHAPE, StairsShape.STRAIGHT).with(StairsBlock.HALF, Half.BOTTOM), 22, 7, 14, start);
        structure.setBlockState(world, Blocks.COBBLESTONE_SLAB.getDefaultState().with(SlabBlock.TYPE, SlabType.BOTTOM).with(SlabBlock.WATERLOGGED, false), 22, 7, 15, start);
        structure.setBlockState(world, Blocks.DIRT.getDefaultState(), 23, 6, 7, start);
        structure.setBlockState(world, ModBlocks.CHAIR.get().getDefaultState().with(ChairBlock.FACING, Direction.SOUTH), 23, 7, 8, start);
        structure.setBlockState(world, Blocks.GRASS.getDefaultState(), 23, 7, 10, start);
        structure.setBlockState(world, Index.STOOL_OAK.getDefaultState().with(Stool.PILLOW, StoolState.NONE), 23, 7, 17, start);
        structure.setBlockState(world, Blocks.OAK_LEAVES.getDefaultState().with(LeavesBlock.PERSISTENT, false).with(LeavesBlock.DISTANCE, 1), 23, 12, 7, start);
        structure.setBlockState(world, Blocks.OAK_LEAVES.getDefaultState().with(LeavesBlock.PERSISTENT, false).with(LeavesBlock.DISTANCE, 2), 23, 12, 8, start);
        structure.setBlockState(world, Blocks.DIRT.getDefaultState(), 24, 6, 11, start);
        structure.setBlockState(world, Blocks.COBBLESTONE_STAIRS.getDefaultState().with(StairsBlock.FACING, Direction.WEST).with(StairsBlock.WATERLOGGED, false).with(StairsBlock.SHAPE, StairsShape.STRAIGHT).with(StairsBlock.HALF, Half.BOTTOM), 24, 6, 15, start);
        structure.setBlockState(world, Blocks.COBBLESTONE_SLAB.getDefaultState().with(SlabBlock.TYPE, SlabType.BOTTOM).with(SlabBlock.WATERLOGGED, false), 24, 7, 11, start);
        structure.setBlockState(world, Index.STOOL_OAK.getDefaultState().with(Stool.PILLOW, StoolState.NONE), 24, 7, 12, start);
        structure.setBlockState(world, Blocks.AIR.getDefaultState(), 24, 7, 18, start);
        structure.setBlockState(world, Blocks.OAK_LEAVES.getDefaultState().with(LeavesBlock.PERSISTENT, false).with(LeavesBlock.DISTANCE, 2), 24, 12, 7, start);
        structure.setBlockState(world, Blocks.GRASS_BLOCK.getDefaultState().with(SnowyDirtBlock.SNOWY, false), 25, 3, 22, start);
        structure.setBlockState(world, Blocks.GRASS_BLOCK.getDefaultState().with(SnowyDirtBlock.SNOWY, false), 25, 4, 3, start);
        structure.setBlockState(world, Blocks.GRASS.getDefaultState(), 25, 7, 12, start);
        structure.setBlockState(world, Blocks.GRASS_BLOCK.getDefaultState().with(SnowyDirtBlock.SNOWY, false), 26, 3, 3, start);
        structure.setBlockState(world, Blocks.DIRT.getDefaultState(), 26, 4, 20, start);
        structure.setBlockState(world, Blocks.GRASS_BLOCK.getDefaultState().with(SnowyDirtBlock.SNOWY, false), 26, 4, 21, start);
        structure.setBlockState(world, Blocks.GRASS_BLOCK.getDefaultState().with(SnowyDirtBlock.SNOWY, false), 26, 5, 20, start);
        structure.setBlockState(world, Blocks.GRASS.getDefaultState(), 26, 6, 4, start);
        structure.setBlockState(world, Blocks.GRASS.getDefaultState(), 26, 7, 10, start);
        structure.setBlockState(world, Blocks.GRASS_BLOCK.getDefaultState().with(SnowyDirtBlock.SNOWY, false), 27, 1, 1, start);
        structure.setBlockState(world, Blocks.DIRT.getDefaultState(), 27, 2, 20, start);
        structure.setBlockState(world, Blocks.GRASS_BLOCK.getDefaultState().with(SnowyDirtBlock.SNOWY, false), 27, 3, 20, start);
        structure.setBlockState(world, Blocks.GRASS_BLOCK.getDefaultState().with(SnowyDirtBlock.SNOWY, false), 27, 4, 4, start);
        structure.fillWithBlocks(world, start, 1, 0, 1, 2, 0, 4, Blocks.DIRT.getDefaultState());
        structure.fillWithBlocks(world, start, 1, 0, 5, 1, 1, 6, Blocks.DIRT.getDefaultState());
        structure.fillWithBlocks(world, start, 1, 0, 7, 10, 0, 16, Blocks.STONE.getDefaultState());
        structure.fillWithBlocks(world, start, 1, 0, 17, 1, 2, 19, Blocks.DIRT.getDefaultState());
        structure.fillWithBlocks(world, start, 1, 0, 20, 2, 0, 22, Blocks.DIRT.getDefaultState());
        structure.fillWithBlocks(world, start, 1, 1, 1, 1, 1, 2, Blocks.GRASS_BLOCK.getDefaultState().with(SnowyDirtBlock.SNOWY, false));
        structure.fillWithBlocks(world, start, 1, 1, 3, 2, 1, 20, Blocks.DIRT.getDefaultState());
        structure.fillWithBlocks(world, start, 1, 1, 21, 1, 1, 22, Blocks.GRASS_BLOCK.getDefaultState().with(SnowyDirtBlock.SNOWY, false));
        structure.fillWithBlocks(world, start, 1, 2, 3, 1, 2, 5, Blocks.GRASS_BLOCK.getDefaultState().with(SnowyDirtBlock.SNOWY, false));
        structure.fillWithBlocks(world, start, 1, 2, 6, 3, 2, 19, Blocks.DIRT.getDefaultState());
        structure.fillWithBlocks(world, start, 1, 2, 20, 1, 2, 20, Blocks.GRASS_BLOCK.getDefaultState().with(SnowyDirtBlock.SNOWY, false));
        structure.fillWithBlocks(world, start, 1, 3, 7, 3, 3, 18, Blocks.DIRT.getDefaultState());
        structure.fillWithBlocks(world, start, 1, 3, 19, 1, 3, 19, Blocks.GRASS_BLOCK.getDefaultState().with(SnowyDirtBlock.SNOWY, false));
        structure.fillWithBlocks(world, start, 1, 4, 7, 1, 4, 18, Blocks.GRASS_BLOCK.getDefaultState().with(SnowyDirtBlock.SNOWY, false));
        structure.fillWithBlocks(world, start, 2, 0, 5, 15, 0, 18, Blocks.STONE.getDefaultState());
        structure.fillWithBlocks(world, start, 2, 0, 19, 2, 1, 22, Blocks.DIRT.getDefaultState());
        structure.fillWithBlocks(world, start, 2, 1, 1, 3, 1, 1, Blocks.GRASS_BLOCK.getDefaultState().with(SnowyDirtBlock.SNOWY, false));
        structure.fillWithBlocks(world, start, 2, 1, 2, 3, 1, 3, Blocks.DIRT.getDefaultState());
        structure.fillWithBlocks(world, start, 2, 2, 2, 2, 2, 3, Blocks.GRASS_BLOCK.getDefaultState().with(SnowyDirtBlock.SNOWY, false));
        structure.fillWithBlocks(world, start, 2, 2, 4, 3, 2, 20, Blocks.DIRT.getDefaultState());
        structure.fillWithBlocks(world, start, 2, 2, 21, 2, 2, 22, Blocks.GRASS_BLOCK.getDefaultState().with(SnowyDirtBlock.SNOWY, false));
        structure.fillWithBlocks(world, start, 2, 3, 5, 3, 3, 19, Blocks.DIRT.getDefaultState());
        structure.fillWithBlocks(world, start, 2, 4, 6, 3, 4, 18, Blocks.DIRT.getDefaultState());
        structure.fillWithBlocks(world, start, 2, 5, 6, 4, 5, 14, Blocks.GRASS_BLOCK.getDefaultState().with(SnowyDirtBlock.SNOWY, false));
        structure.fillWithBlocks(world, start, 2, 5, 15, 3, 5, 18, Blocks.GRASS_BLOCK.getDefaultState().with(SnowyDirtBlock.SNOWY, false));
        structure.fillWithBlocks(world, start, 3, 0, 1, 3, 0, 2, Blocks.DIRT.getDefaultState());
        structure.fillWithBlocks(world, start, 3, 0, 3, 20, 0, 20, Blocks.STONE.getDefaultState());
        structure.fillWithBlocks(world, start, 3, 0, 21, 3, 0, 22, Blocks.DIRT.getDefaultState());
        structure.fillWithBlocks(world, start, 3, 1, 4, 7, 1, 8, Blocks.STONE.getDefaultState());
        structure.fillWithBlocks(world, start, 3, 1, 9, 3, 4, 20, Blocks.DIRT.getDefaultState());
        structure.fillWithBlocks(world, start, 3, 1, 21, 4, 1, 22, Blocks.DIRT.getDefaultState());
        structure.fillWithBlocks(world, start, 3, 2, 3, 4, 2, 4, Blocks.DIRT.getDefaultState());
        structure.fillWithBlocks(world, start, 3, 2, 21, 3, 2, 21, Blocks.DIRT.getDefaultState());
        structure.fillWithBlocks(world, start, 3, 3, 4, 3, 3, 21, Blocks.DIRT.getDefaultState());
        structure.fillWithBlocks(world, start, 3, 4, 5, 3, 4, 20, Blocks.DIRT.getDefaultState());
        structure.fillWithBlocks(world, start, 3, 5, 5, 4, 5, 14, Blocks.GRASS_BLOCK.getDefaultState().with(SnowyDirtBlock.SNOWY, false));
        structure.fillWithBlocks(world, start, 3, 5, 19, 3, 5, 20, Blocks.GRASS_BLOCK.getDefaultState().with(SnowyDirtBlock.SNOWY, false));
        structure.fillWithBlocks(world, start, 3, 9, 4, 3, 10, 4, Blocks.OAK_LEAVES.getDefaultState().with(LeavesBlock.PERSISTENT, false).with(LeavesBlock.DISTANCE, 4));
        structure.fillWithBlocks(world, start, 3, 9, 5, 3, 10, 5, Blocks.OAK_LEAVES.getDefaultState().with(LeavesBlock.PERSISTENT, false).with(LeavesBlock.DISTANCE, 3));
        structure.fillWithBlocks(world, start, 3, 9, 6, 3, 10, 6, Blocks.OAK_LEAVES.getDefaultState().with(LeavesBlock.PERSISTENT, false).with(LeavesBlock.DISTANCE, 2));
        structure.fillWithBlocks(world, start, 3, 9, 7, 3, 10, 7, Blocks.OAK_LEAVES.getDefaultState().with(LeavesBlock.PERSISTENT, false).with(LeavesBlock.DISTANCE, 3));
        structure.fillWithBlocks(world, start, 3, 9, 8, 3, 10, 8, Blocks.OAK_LEAVES.getDefaultState().with(LeavesBlock.PERSISTENT, false).with(LeavesBlock.DISTANCE, 4));
        structure.fillWithBlocks(world, start, 4, 0, 1, 4, 1, 1, Blocks.DIRT.getDefaultState());
        structure.fillWithBlocks(world, start, 4, 0, 2, 23, 0, 21, Blocks.STONE.getDefaultState());
        structure.fillWithBlocks(world, start, 4, 0, 22, 4, 2, 22, Blocks.DIRT.getDefaultState());
        structure.fillWithBlocks(world, start, 4, 1, 2, 4, 2, 2, Blocks.DIRT.getDefaultState());
        structure.fillWithBlocks(world, start, 4, 1, 3, 21, 1, 20, Blocks.STONE.getDefaultState());
        structure.fillWithBlocks(world, start, 4, 2, 5, 19, 2, 20, Blocks.STONE.getDefaultState());
        structure.fillWithBlocks(world, start, 4, 2, 21, 5, 2, 22, Blocks.DIRT.getDefaultState());
        structure.fillWithBlocks(world, start, 4, 3, 3, 5, 3, 4, Blocks.DIRT.getDefaultState());
        structure.fillWithBlocks(world, start, 4, 3, 5, 19, 3, 20, Blocks.STONE.getDefaultState());
        structure.fillWithBlocks(world, start, 4, 3, 21, 4, 3, 21, Blocks.DIRT.getDefaultState());
        structure.fillWithBlocks(world, start, 4, 4, 3, 5, 4, 3, Blocks.GRASS_BLOCK.getDefaultState().with(SnowyDirtBlock.SNOWY, false));
        structure.fillWithBlocks(world, start, 4, 4, 4, 26, 4, 4, Blocks.DIRT.getDefaultState());
        structure.fillWithBlocks(world, start, 4, 4, 5, 19, 4, 20, Blocks.STONE.getDefaultState());
        structure.fillWithBlocks(world, start, 4, 4, 21, 25, 4, 21, Blocks.DIRT.getDefaultState());
        structure.fillWithBlocks(world, start, 4, 5, 4, 5, 5, 5, Blocks.GRASS_BLOCK.getDefaultState().with(SnowyDirtBlock.SNOWY, false));
        structure.fillWithBlocks(world, start, 4, 5, 15, 7, 5, 18, Blocks.DIRT.getDefaultState());
        structure.fillWithBlocks(world, start, 4, 5, 19, 5, 5, 20, Blocks.STONE.getDefaultState());
        structure.fillWithBlocks(world, start, 4, 5, 21, 5, 5, 21, Blocks.GRASS_BLOCK.getDefaultState().with(SnowyDirtBlock.SNOWY, false));
        structure.fillWithBlocks(world, start, 4, 6, 12, 4, 6, 13, Blocks.GRASS.getDefaultState());
        structure.fillWithBlocks(world, start, 4, 6, 15, 6, 6, 20, Blocks.GRASS_BLOCK.getDefaultState().with(SnowyDirtBlock.SNOWY, false));
        structure.fillWithBlocks(world, start, 4, 9, 4, 4, 10, 4, Blocks.OAK_LEAVES.getDefaultState().with(LeavesBlock.PERSISTENT, false).with(LeavesBlock.DISTANCE, 3));
        structure.fillWithBlocks(world, start, 4, 9, 5, 4, 10, 5, Blocks.OAK_LEAVES.getDefaultState().with(LeavesBlock.PERSISTENT, false).with(LeavesBlock.DISTANCE, 2));
        structure.fillWithBlocks(world, start, 4, 9, 6, 4, 11, 6, Blocks.OAK_LEAVES.getDefaultState().with(LeavesBlock.PERSISTENT, false).with(LeavesBlock.DISTANCE, 1));
        structure.fillWithBlocks(world, start, 4, 9, 7, 4, 11, 7, Blocks.OAK_LEAVES.getDefaultState().with(LeavesBlock.PERSISTENT, false).with(LeavesBlock.DISTANCE, 2));
        structure.fillWithBlocks(world, start, 4, 9, 8, 4, 10, 8, Blocks.OAK_LEAVES.getDefaultState().with(LeavesBlock.PERSISTENT, false).with(LeavesBlock.DISTANCE, 3));
        structure.fillWithBlocks(world, start, 4, 12, 6, 4, 12, 6, Blocks.OAK_LEAVES.getDefaultState().with(LeavesBlock.PERSISTENT, false).with(LeavesBlock.DISTANCE, 2));
        structure.fillWithBlocks(world, start, 5, 0, 1, 23, 0, 22, Blocks.STONE.getDefaultState());
        structure.fillWithBlocks(world, start, 5, 1, 1, 12, 1, 21, Blocks.STONE.getDefaultState());
        structure.fillWithBlocks(world, start, 5, 1, 22, 6, 2, 22, Blocks.DIRT.getDefaultState());
        structure.fillWithBlocks(world, start, 5, 2, 1, 7, 2, 3, Blocks.DIRT.getDefaultState());
        structure.fillWithBlocks(world, start, 5, 2, 4, 18, 2, 20, Blocks.STONE.getDefaultState());
        structure.fillWithBlocks(world, start, 5, 3, 1, 8, 3, 4, Blocks.DIRT.getDefaultState());
        structure.fillWithBlocks(world, start, 5, 3, 21, 6, 3, 22, Blocks.DIRT.getDefaultState());
        structure.fillWithBlocks(world, start, 5, 4, 1, 6, 4, 2, Blocks.GRASS_BLOCK.getDefaultState().with(SnowyDirtBlock.SNOWY, false));
        structure.fillWithBlocks(world, start, 5, 4, 22, 8, 4, 22, Blocks.GRASS_BLOCK.getDefaultState().with(SnowyDirtBlock.SNOWY, false));
        structure.fillWithBlocks(world, start, 5, 5, 7, 7, 5, 9, Blocks.GRASS_BLOCK.getDefaultState().with(SnowyDirtBlock.SNOWY, false));
        structure.fillWithBlocks(world, start, 5, 5, 10, 6, 5, 11, Blocks.GRASS_BLOCK.getDefaultState().with(SnowyDirtBlock.SNOWY, false));
        structure.fillWithBlocks(world, start, 5, 5, 13, 10, 5, 18, Blocks.DIRT.getDefaultState());
        structure.fillWithBlocks(world, start, 5, 6, 6, 5, 11, 6, Blocks.OAK_LOG.getDefaultState());
        structure.fillWithBlocks(world, start, 5, 6, 13, 8, 6, 16, Blocks.GRASS_BLOCK.getDefaultState().with(SnowyDirtBlock.SNOWY, false));
        structure.fillWithBlocks(world, start, 5, 9, 4, 5, 10, 4, Blocks.OAK_LEAVES.getDefaultState().with(LeavesBlock.PERSISTENT, false).with(LeavesBlock.DISTANCE, 2));
        structure.fillWithBlocks(world, start, 5, 9, 5, 5, 11, 5, Blocks.OAK_LEAVES.getDefaultState().with(LeavesBlock.PERSISTENT, false).with(LeavesBlock.DISTANCE, 1));
        structure.fillWithBlocks(world, start, 5, 9, 7, 5, 11, 7, Blocks.OAK_LEAVES.getDefaultState().with(LeavesBlock.PERSISTENT, false).with(LeavesBlock.DISTANCE, 1));
        structure.fillWithBlocks(world, start, 5, 9, 8, 5, 10, 8, Blocks.OAK_LEAVES.getDefaultState().with(LeavesBlock.PERSISTENT, false).with(LeavesBlock.DISTANCE, 2));
        structure.fillWithBlocks(world, start, 5, 9, 15, 5, 10, 15, Blocks.OAK_LEAVES.getDefaultState().with(LeavesBlock.PERSISTENT, false).with(LeavesBlock.DISTANCE, 4));
        structure.fillWithBlocks(world, start, 5, 9, 16, 5, 10, 16, Blocks.OAK_LEAVES.getDefaultState().with(LeavesBlock.PERSISTENT, false).with(LeavesBlock.DISTANCE, 3));
        structure.fillWithBlocks(world, start, 5, 9, 17, 5, 10, 17, Blocks.OAK_LEAVES.getDefaultState().with(LeavesBlock.PERSISTENT, false).with(LeavesBlock.DISTANCE, 2));
        structure.fillWithBlocks(world, start, 5, 9, 18, 5, 10, 18, Blocks.OAK_LEAVES.getDefaultState().with(LeavesBlock.PERSISTENT, false).with(LeavesBlock.DISTANCE, 3));
        structure.fillWithBlocks(world, start, 5, 9, 19, 5, 10, 19, Blocks.OAK_LEAVES.getDefaultState().with(LeavesBlock.PERSISTENT, false).with(LeavesBlock.DISTANCE, 4));
        structure.fillWithBlocks(world, start, 5, 12, 5, 5, 12, 5, Blocks.OAK_LEAVES.getDefaultState().with(LeavesBlock.PERSISTENT, false).with(LeavesBlock.DISTANCE, 2));
        structure.fillWithBlocks(world, start, 6, 2, 21, 7, 2, 22, Blocks.DIRT.getDefaultState());
        structure.fillWithBlocks(world, start, 6, 4, 3, 7, 4, 4, Blocks.DIRT.getDefaultState());
        structure.fillWithBlocks(world, start, 6, 5, 3, 8, 5, 7, Blocks.GRASS_BLOCK.getDefaultState().with(SnowyDirtBlock.SNOWY, false));
        structure.fillWithBlocks(world, start, 6, 5, 12, 12, 5, 18, Blocks.DIRT.getDefaultState());
        structure.fillWithBlocks(world, start, 6, 5, 19, 7, 5, 20, Blocks.STONE.getDefaultState());
        structure.fillWithBlocks(world, start, 6, 5, 21, 22, 5, 21, Blocks.DIRT.getDefaultState());
        structure.fillWithBlocks(world, start, 6, 6, 12, 8, 6, 16, Blocks.GRASS_BLOCK.getDefaultState().with(SnowyDirtBlock.SNOWY, false));
        structure.fillWithBlocks(world, start, 6, 6, 21, 22, 6, 21, Blocks.GRASS_BLOCK.getDefaultState().with(SnowyDirtBlock.SNOWY, false));
        structure.fillWithBlocks(world, start, 6, 9, 4, 6, 10, 4, Blocks.OAK_LEAVES.getDefaultState().with(LeavesBlock.PERSISTENT, false).with(LeavesBlock.DISTANCE, 3));
        structure.fillWithBlocks(world, start, 6, 9, 5, 6, 11, 5, Blocks.OAK_LEAVES.getDefaultState().with(LeavesBlock.PERSISTENT, false).with(LeavesBlock.DISTANCE, 2));
        structure.fillWithBlocks(world, start, 6, 9, 6, 6, 11, 6, Blocks.OAK_LEAVES.getDefaultState().with(LeavesBlock.PERSISTENT, false).with(LeavesBlock.DISTANCE, 1));
        structure.fillWithBlocks(world, start, 6, 9, 7, 6, 10, 7, Blocks.OAK_LEAVES.getDefaultState().with(LeavesBlock.PERSISTENT, false).with(LeavesBlock.DISTANCE, 2));
        structure.fillWithBlocks(world, start, 6, 9, 8, 6, 10, 8, Blocks.OAK_LEAVES.getDefaultState().with(LeavesBlock.PERSISTENT, false).with(LeavesBlock.DISTANCE, 3));
        structure.fillWithBlocks(world, start, 6, 9, 15, 6, 10, 15, Blocks.OAK_LEAVES.getDefaultState().with(LeavesBlock.PERSISTENT, false).with(LeavesBlock.DISTANCE, 3));
        structure.fillWithBlocks(world, start, 6, 9, 16, 6, 11, 16, Blocks.OAK_LEAVES.getDefaultState().with(LeavesBlock.PERSISTENT, false).with(LeavesBlock.DISTANCE, 2));
        structure.fillWithBlocks(world, start, 6, 9, 17, 6, 11, 17, Blocks.OAK_LEAVES.getDefaultState().with(LeavesBlock.PERSISTENT, false).with(LeavesBlock.DISTANCE, 1));
        structure.fillWithBlocks(world, start, 6, 9, 18, 6, 10, 18, Blocks.OAK_LEAVES.getDefaultState().with(LeavesBlock.PERSISTENT, false).with(LeavesBlock.DISTANCE, 2));
        structure.fillWithBlocks(world, start, 6, 9, 19, 6, 10, 19, Blocks.OAK_LEAVES.getDefaultState().with(LeavesBlock.PERSISTENT, false).with(LeavesBlock.DISTANCE, 3));
        structure.fillWithBlocks(world, start, 6, 12, 17, 6, 12, 17, Blocks.OAK_LEAVES.getDefaultState().with(LeavesBlock.PERSISTENT, false).with(LeavesBlock.DISTANCE, 2));
        structure.fillWithBlocks(world, start, 7, 1, 22, 16, 1, 22, Blocks.STONE.getDefaultState());
        structure.fillWithBlocks(world, start, 7, 3, 21, 8, 3, 22, Blocks.DIRT.getDefaultState());
        structure.fillWithBlocks(world, start, 7, 4, 1, 8, 4, 2, Blocks.GRASS_BLOCK.getDefaultState().with(SnowyDirtBlock.SNOWY, false));
        structure.fillWithBlocks(world, start, 7, 5, 10, 15, 5, 18, Blocks.DIRT.getDefaultState());
        structure.fillWithBlocks(world, start, 7, 6, 10, 9, 6, 12, Blocks.GRASS_BLOCK.getDefaultState().with(SnowyDirtBlock.SNOWY, false));
        structure.fillWithBlocks(world, start, 7, 6, 18, 10, 6, 21, Blocks.GRASS_BLOCK.getDefaultState().with(SnowyDirtBlock.SNOWY, false));
        structure.fillWithBlocks(world, start, 7, 7, 17, 7, 11, 17, Blocks.OAK_LOG.getDefaultState());
        structure.fillWithBlocks(world, start, 7, 9, 5, 7, 10, 5, Blocks.OAK_LEAVES.getDefaultState().with(LeavesBlock.PERSISTENT, false).with(LeavesBlock.DISTANCE, 3));
        structure.fillWithBlocks(world, start, 7, 9, 6, 7, 10, 6, Blocks.OAK_LEAVES.getDefaultState().with(LeavesBlock.PERSISTENT, false).with(LeavesBlock.DISTANCE, 2));
        structure.fillWithBlocks(world, start, 7, 9, 7, 7, 10, 7, Blocks.OAK_LEAVES.getDefaultState().with(LeavesBlock.PERSISTENT, false).with(LeavesBlock.DISTANCE, 3));
        structure.fillWithBlocks(world, start, 7, 9, 15, 7, 10, 15, Blocks.OAK_LEAVES.getDefaultState().with(LeavesBlock.PERSISTENT, false).with(LeavesBlock.DISTANCE, 2));
        structure.fillWithBlocks(world, start, 7, 9, 16, 7, 11, 16, Blocks.OAK_LEAVES.getDefaultState().with(LeavesBlock.PERSISTENT, false).with(LeavesBlock.DISTANCE, 1));
        structure.fillWithBlocks(world, start, 7, 9, 18, 7, 11, 18, Blocks.OAK_LEAVES.getDefaultState().with(LeavesBlock.PERSISTENT, false).with(LeavesBlock.DISTANCE, 1));
        structure.fillWithBlocks(world, start, 7, 9, 19, 7, 10, 19, Blocks.OAK_LEAVES.getDefaultState().with(LeavesBlock.PERSISTENT, false).with(LeavesBlock.DISTANCE, 2));
        structure.fillWithBlocks(world, start, 7, 12, 16, 7, 12, 16, Blocks.OAK_LEAVES.getDefaultState().with(LeavesBlock.PERSISTENT, false).with(LeavesBlock.DISTANCE, 2));
        structure.fillWithBlocks(world, start, 8, 2, 1, 9, 2, 2, Blocks.DIRT.getDefaultState());
        structure.fillWithBlocks(world, start, 8, 2, 3, 8, 4, 3, Blocks.DIRT.getDefaultState());
        structure.fillWithBlocks(world, start, 8, 2, 21, 9, 2, 22, Blocks.DIRT.getDefaultState());
        structure.fillWithBlocks(world, start, 8, 5, 8, 16, 5, 18, Blocks.DIRT.getDefaultState());
        structure.fillWithBlocks(world, start, 8, 5, 19, 9, 5, 20, Blocks.STONE.getDefaultState());
        structure.fillWithBlocks(world, start, 8, 6, 8, 10, 6, 11, Blocks.GRASS_BLOCK.getDefaultState().with(SnowyDirtBlock.SNOWY, false));
        structure.fillWithBlocks(world, start, 8, 6, 17, 12, 6, 21, Blocks.GRASS_BLOCK.getDefaultState().with(SnowyDirtBlock.SNOWY, false));
        structure.fillWithBlocks(world, start, 8, 9, 15, 8, 10, 15, Blocks.OAK_LEAVES.getDefaultState().with(LeavesBlock.PERSISTENT, false).with(LeavesBlock.DISTANCE, 3));
        structure.fillWithBlocks(world, start, 8, 9, 16, 8, 10, 16, Blocks.OAK_LEAVES.getDefaultState().with(LeavesBlock.PERSISTENT, false).with(LeavesBlock.DISTANCE, 2));
        structure.fillWithBlocks(world, start, 8, 9, 17, 8, 11, 17, Blocks.OAK_LEAVES.getDefaultState().with(LeavesBlock.PERSISTENT, false).with(LeavesBlock.DISTANCE, 1));
        structure.fillWithBlocks(world, start, 8, 9, 18, 8, 10, 18, Blocks.OAK_LEAVES.getDefaultState().with(LeavesBlock.PERSISTENT, false).with(LeavesBlock.DISTANCE, 2));
        structure.fillWithBlocks(world, start, 8, 9, 19, 8, 10, 19, Blocks.OAK_LEAVES.getDefaultState().with(LeavesBlock.PERSISTENT, false).with(LeavesBlock.DISTANCE, 3));
        structure.fillWithBlocks(world, start, 9, 2, 3, 15, 2, 20, Blocks.STONE.getDefaultState());
        structure.fillWithBlocks(world, start, 9, 3, 1, 12, 3, 4, Blocks.DIRT.getDefaultState());
        structure.fillWithBlocks(world, start, 9, 3, 21, 10, 3, 22, Blocks.DIRT.getDefaultState());
        structure.fillWithBlocks(world, start, 9, 4, 1, 10, 4, 2, Blocks.GRASS_BLOCK.getDefaultState().with(SnowyDirtBlock.SNOWY, false));
        structure.fillWithBlocks(world, start, 9, 4, 3, 10, 4, 4, Blocks.DIRT.getDefaultState());
        structure.fillWithBlocks(world, start, 9, 4, 22, 21, 4, 22, Blocks.DIRT.getDefaultState());
        structure.fillWithBlocks(world, start, 9, 5, 3, 9, 5, 5, Blocks.GRASS_BLOCK.getDefaultState().with(SnowyDirtBlock.SNOWY, false));
        structure.fillWithBlocks(world, start, 9, 5, 6, 17, 5, 14, Blocks.DIRT.getDefaultState());
        structure.fillWithBlocks(world, start, 9, 5, 22, 21, 5, 22, Blocks.GRASS_BLOCK.getDefaultState().with(SnowyDirtBlock.SNOWY, false));
        structure.fillWithBlocks(world, start, 9, 6, 6, 13, 6, 10, Blocks.GRASS_BLOCK.getDefaultState().with(SnowyDirtBlock.SNOWY, false));
        structure.fillWithBlocks(world, start, 9, 6, 13, 9, 6, 13, Blocks.DIRT.getDefaultState());
        structure.fillWithBlocks(world, start, 9, 6, 14, 9, 6, 21, Blocks.GRASS_BLOCK.getDefaultState().with(SnowyDirtBlock.SNOWY, false));
        structure.fillWithBlocks(world, start, 9, 7, 13, 9, 8, 13, Blocks.SPRUCE_WOOD.getDefaultState());
        structure.fillWithBlocks(world, start, 9, 7, 15, 9, 7, 15, Blocks.GRASS.getDefaultState());
        structure.fillWithBlocks(world, start, 9, 7, 19, 9, 7, 20, Blocks.GRASS.getDefaultState());
        structure.fillWithBlocks(world, start, 9, 9, 15, 9, 10, 15, Blocks.OAK_LEAVES.getDefaultState().with(LeavesBlock.PERSISTENT, false).with(LeavesBlock.DISTANCE, 4));
        structure.fillWithBlocks(world, start, 9, 9, 16, 9, 10, 16, Blocks.OAK_LEAVES.getDefaultState().with(LeavesBlock.PERSISTENT, false).with(LeavesBlock.DISTANCE, 3));
        structure.fillWithBlocks(world, start, 9, 9, 17, 9, 10, 17, Blocks.OAK_LEAVES.getDefaultState().with(LeavesBlock.PERSISTENT, false).with(LeavesBlock.DISTANCE, 2));
        structure.fillWithBlocks(world, start, 9, 9, 18, 9, 10, 18, Blocks.OAK_LEAVES.getDefaultState().with(LeavesBlock.PERSISTENT, false).with(LeavesBlock.DISTANCE, 3));
        structure.fillWithBlocks(world, start, 10, 2, 1, 10, 3, 2, Blocks.DIRT.getDefaultState());
        structure.fillWithBlocks(world, start, 10, 2, 21, 11, 2, 22, Blocks.DIRT.getDefaultState());
        structure.fillWithBlocks(world, start, 10, 5, 3, 24, 5, 3, Blocks.GRASS_BLOCK.getDefaultState().with(SnowyDirtBlock.SNOWY, false));
        structure.fillWithBlocks(world, start, 10, 5, 4, 20, 5, 14, Blocks.DIRT.getDefaultState());
        structure.fillWithBlocks(world, start, 10, 5, 19, 11, 5, 20, Blocks.STONE.getDefaultState());
        structure.fillWithBlocks(world, start, 10, 6, 4, 13, 6, 10, Blocks.GRASS_BLOCK.getDefaultState().with(SnowyDirtBlock.SNOWY, false));
        structure.fillWithBlocks(world, start, 10, 6, 13, 10, 6, 13, Blocks.GRASS_BLOCK.getDefaultState().with(SnowyDirtBlock.SNOWY, false));
        structure.fillWithBlocks(world, start, 10, 6, 14, 10, 6, 14, Blocks.DIRT.getDefaultState());
        structure.fillWithBlocks(world, start, 10, 6, 15, 10, 6, 21, Blocks.GRASS_BLOCK.getDefaultState().with(SnowyDirtBlock.SNOWY, false));
        structure.fillWithBlocks(world, start, 10, 7, 12, 10, 8, 12, Blocks.BROWN_WOOL.getDefaultState());
        structure.fillWithBlocks(world, start, 10, 7, 14, 10, 8, 14, Blocks.BROWN_WOOL.getDefaultState());
        structure.fillWithBlocks(world, start, 10, 7, 16, 11, 7, 16, Blocks.GRASS.getDefaultState());
        structure.fillWithBlocks(world, start, 10, 7, 18, 12, 7, 18, Blocks.GRASS.getDefaultState());
        structure.fillWithBlocks(world, start, 10, 7, 20, 10, 7, 21, Blocks.GRASS.getDefaultState());
        structure.fillWithBlocks(world, start, 10, 9, 13, 10, 10, 13, Blocks.SPRUCE_WOOD.getDefaultState());
        structure.fillWithBlocks(world, start, 11, 2, 1, 19, 3, 1, Blocks.DIRT.getDefaultState());
        structure.fillWithBlocks(world, start, 11, 2, 2, 13, 2, 20, Blocks.STONE.getDefaultState());
        structure.fillWithBlocks(world, start, 11, 3, 21, 12, 3, 22, Blocks.DIRT.getDefaultState());
        structure.fillWithBlocks(world, start, 11, 4, 1, 19, 4, 1, Blocks.GRASS_BLOCK.getDefaultState().with(SnowyDirtBlock.SNOWY, false));
        structure.fillWithBlocks(world, start, 11, 4, 2, 13, 4, 4, Blocks.DIRT.getDefaultState());
        structure.fillWithBlocks(world, start, 11, 5, 2, 12, 5, 3, Blocks.GRASS_BLOCK.getDefaultState().with(SnowyDirtBlock.SNOWY, false));
        structure.fillWithBlocks(world, start, 11, 6, 11, 15, 6, 11, Blocks.DIRT.getDefaultState());
        structure.fillWithBlocks(world, start, 11, 6, 12, 13, 6, 14, Blocks.GRASS_BLOCK.getDefaultState().with(SnowyDirtBlock.SNOWY, false));
        structure.fillWithBlocks(world, start, 11, 6, 15, 15, 6, 15, Blocks.DIRT.getDefaultState());
        structure.fillWithBlocks(world, start, 11, 6, 16, 16, 6, 21, Blocks.GRASS_BLOCK.getDefaultState().with(SnowyDirtBlock.SNOWY, false));
        structure.fillWithBlocks(world, start, 11, 7, 11, 11, 8, 11, Blocks.SPRUCE_WOOD.getDefaultState());
        structure.fillWithBlocks(world, start, 11, 7, 15, 11, 8, 15, Blocks.SPRUCE_WOOD.getDefaultState());
        structure.fillWithBlocks(world, start, 11, 7, 20, 11, 7, 20, Blocks.GRASS.getDefaultState());
        structure.fillWithBlocks(world, start, 11, 9, 12, 11, 10, 12, Blocks.SPRUCE_WOOD.getDefaultState());
        structure.fillWithBlocks(world, start, 11, 9, 14, 11, 10, 14, Blocks.SPRUCE_WOOD.getDefaultState());
        structure.fillWithBlocks(world, start, 12, 2, 21, 13, 2, 22, Blocks.DIRT.getDefaultState());
        structure.fillWithBlocks(world, start, 12, 5, 19, 13, 5, 20, Blocks.STONE.getDefaultState());
        structure.fillWithBlocks(world, start, 12, 7, 11, 12, 8, 11, Blocks.BROWN_WOOL.getDefaultState());
        structure.fillWithBlocks(world, start, 12, 7, 15, 12, 8, 15, Blocks.BROWN_WOOL.getDefaultState());
        structure.fillWithBlocks(world, start, 12, 7, 20, 12, 7, 21, Blocks.GRASS.getDefaultState());
        structure.fillWithBlocks(world, start, 12, 9, 12, 12, 10, 12, Blocks.BROWN_WOOL.getDefaultState());
        structure.fillWithBlocks(world, start, 12, 9, 14, 12, 10, 14, Blocks.BROWN_WOOL.getDefaultState());
        structure.fillWithBlocks(world, start, 13, 1, 1, 19, 3, 1, Blocks.DIRT.getDefaultState());
        structure.fillWithBlocks(world, start, 13, 1, 2, 18, 1, 20, Blocks.STONE.getDefaultState());
        structure.fillWithBlocks(world, start, 13, 1, 21, 14, 1, 22, Blocks.STONE.getDefaultState());
        structure.fillWithBlocks(world, start, 13, 3, 2, 15, 3, 4, Blocks.DIRT.getDefaultState());
        structure.fillWithBlocks(world, start, 13, 3, 21, 14, 3, 22, Blocks.DIRT.getDefaultState());
        structure.fillWithBlocks(world, start, 13, 5, 2, 14, 5, 3, Blocks.GRASS_BLOCK.getDefaultState().with(SnowyDirtBlock.SNOWY, false));
        structure.fillWithBlocks(world, start, 13, 7, 11, 13, 8, 11, Blocks.SPRUCE_WOOD.getDefaultState());
        structure.fillWithBlocks(world, start, 13, 7, 15, 13, 8, 15, Blocks.SPRUCE_WOOD.getDefaultState());
        structure.fillWithBlocks(world, start, 13, 9, 12, 13, 10, 12, Blocks.SPRUCE_WOOD.getDefaultState());
        structure.fillWithBlocks(world, start, 13, 9, 14, 13, 10, 14, Blocks.SPRUCE_WOOD.getDefaultState());
        structure.fillWithBlocks(world, start, 14, 2, 2, 18, 4, 2, Blocks.DIRT.getDefaultState());
        structure.fillWithBlocks(world, start, 14, 2, 21, 15, 2, 22, Blocks.DIRT.getDefaultState());
        structure.fillWithBlocks(world, start, 14, 4, 3, 15, 4, 4, Blocks.DIRT.getDefaultState());
        structure.fillWithBlocks(world, start, 14, 5, 19, 15, 5, 20, Blocks.STONE.getDefaultState());
        structure.fillWithBlocks(world, start, 14, 6, 4, 14, 6, 5, Blocks.GRASS_BLOCK.getDefaultState().with(SnowyDirtBlock.SNOWY, false));
        structure.fillWithBlocks(world, start, 14, 6, 6, 14, 6, 7, Blocks.DIRT.getDefaultState());
        structure.fillWithBlocks(world, start, 14, 6, 8, 14, 6, 10, Blocks.GRASS_BLOCK.getDefaultState().with(SnowyDirtBlock.SNOWY, false));
        structure.fillWithBlocks(world, start, 14, 6, 12, 16, 6, 14, Blocks.GRASS_BLOCK.getDefaultState().with(SnowyDirtBlock.SNOWY, false));
        structure.fillWithBlocks(world, start, 14, 7, 6, 14, 8, 7, Blocks.BROWN_WOOL.getDefaultState());
        structure.fillWithBlocks(world, start, 14, 7, 11, 14, 8, 11, Blocks.BROWN_WOOL.getDefaultState());
        structure.fillWithBlocks(world, start, 14, 7, 15, 14, 8, 15, Blocks.BROWN_WOOL.getDefaultState());
        structure.fillWithBlocks(world, start, 14, 9, 12, 14, 10, 12, Blocks.BROWN_WOOL.getDefaultState());
        structure.fillWithBlocks(world, start, 14, 9, 14, 14, 10, 14, Blocks.BROWN_WOOL.getDefaultState());
        structure.fillWithBlocks(world, start, 15, 1, 21, 16, 1, 22, Blocks.STONE.getDefaultState());
        structure.fillWithBlocks(world, start, 15, 3, 21, 16, 3, 22, Blocks.DIRT.getDefaultState());
        structure.fillWithBlocks(world, start, 15, 5, 2, 16, 5, 3, Blocks.GRASS_BLOCK.getDefaultState().with(SnowyDirtBlock.SNOWY, false));
        structure.fillWithBlocks(world, start, 15, 6, 4, 15, 6, 4, Blocks.GRASS_BLOCK.getDefaultState().with(SnowyDirtBlock.SNOWY, false));
        structure.fillWithBlocks(world, start, 15, 6, 6, 16, 6, 7, Blocks.GRASS_BLOCK.getDefaultState().with(SnowyDirtBlock.SNOWY, false));
        structure.fillWithBlocks(world, start, 15, 6, 8, 15, 6, 8, Blocks.DIRT.getDefaultState());
        structure.fillWithBlocks(world, start, 15, 6, 9, 15, 6, 10, Blocks.GRASS_BLOCK.getDefaultState().with(SnowyDirtBlock.SNOWY, false));
        structure.fillWithBlocks(world, start, 15, 7, 5, 15, 8, 5, Blocks.SPRUCE_WOOD.getDefaultState());
        structure.fillWithBlocks(world, start, 15, 7, 8, 15, 8, 8, Blocks.SPRUCE_WOOD.getDefaultState());
        structure.fillWithBlocks(world, start, 15, 7, 11, 15, 8, 11, Blocks.SPRUCE_WOOD.getDefaultState());
        structure.fillWithBlocks(world, start, 15, 7, 15, 15, 8, 15, Blocks.SPRUCE_WOOD.getDefaultState());
        structure.fillWithBlocks(world, start, 15, 9, 6, 15, 10, 6, Blocks.BROWN_WOOL.getDefaultState());
        structure.fillWithBlocks(world, start, 15, 9, 7, 15, 10, 7, Blocks.SPRUCE_WOOD.getDefaultState());
        structure.fillWithBlocks(world, start, 15, 9, 12, 15, 10, 12, Blocks.SPRUCE_WOOD.getDefaultState());
        structure.fillWithBlocks(world, start, 15, 9, 14, 15, 10, 14, Blocks.SPRUCE_WOOD.getDefaultState());
        structure.fillWithBlocks(world, start, 16, 2, 3, 24, 4, 3, Blocks.DIRT.getDefaultState());
        structure.fillWithBlocks(world, start, 16, 2, 21, 17, 2, 22, Blocks.DIRT.getDefaultState());
        structure.fillWithBlocks(world, start, 16, 3, 4, 25, 5, 4, Blocks.DIRT.getDefaultState());
        structure.fillWithBlocks(world, start, 16, 5, 19, 17, 5, 20, Blocks.STONE.getDefaultState());
        structure.fillWithBlocks(world, start, 16, 6, 4, 17, 6, 4, Blocks.DIRT.getDefaultState());
        structure.fillWithBlocks(world, start, 16, 6, 5, 17, 6, 8, Blocks.GRASS_BLOCK.getDefaultState().with(SnowyDirtBlock.SNOWY, false));
        structure.fillWithBlocks(world, start, 16, 6, 9, 17, 6, 9, Blocks.DIRT.getDefaultState());
        structure.fillWithBlocks(world, start, 16, 6, 10, 17, 6, 14, Blocks.GRASS_BLOCK.getDefaultState().with(SnowyDirtBlock.SNOWY, false));
        structure.fillWithBlocks(world, start, 16, 6, 15, 16, 6, 21, Blocks.GRASS_BLOCK.getDefaultState().with(SnowyDirtBlock.SNOWY, false));
        structure.fillWithBlocks(world, start, 16, 7, 4, 17, 8, 4, Blocks.BROWN_WOOL.getDefaultState());
        structure.fillWithBlocks(world, start, 16, 7, 9, 16, 8, 9, Blocks.BROWN_WOOL.getDefaultState());
        structure.fillWithBlocks(world, start, 16, 9, 5, 16, 10, 5, Blocks.BROWN_WOOL.getDefaultState());
        structure.fillWithBlocks(world, start, 16, 9, 8, 16, 10, 8, Blocks.BROWN_WOOL.getDefaultState());
        structure.fillWithBlocks(world, start, 16, 11, 6, 16, 11, 7, Blocks.BROWN_WOOL.getDefaultState());
        structure.fillWithBlocks(world, start, 17, 1, 21, 18, 1, 22, Blocks.DIRT.getDefaultState());
        structure.fillWithBlocks(world, start, 17, 3, 21, 18, 3, 22, Blocks.DIRT.getDefaultState());
        structure.fillWithBlocks(world, start, 17, 5, 2, 18, 5, 3, Blocks.GRASS_BLOCK.getDefaultState().with(SnowyDirtBlock.SNOWY, false));
        structure.fillWithBlocks(world, start, 17, 5, 16, 19, 5, 18, Blocks.DIRT.getDefaultState());
        structure.fillWithBlocks(world, start, 17, 6, 16, 18, 6, 17, Blocks.GRASS_BLOCK.getDefaultState().with(SnowyDirtBlock.SNOWY, false));
        structure.fillWithBlocks(world, start, 17, 6, 19, 19, 6, 21, Blocks.GRASS_BLOCK.getDefaultState().with(SnowyDirtBlock.SNOWY, false));
        structure.fillWithBlocks(world, start, 17, 7, 9, 17, 8, 9, Blocks.SPRUCE_WOOD.getDefaultState());
        structure.fillWithBlocks(world, start, 17, 9, 5, 17, 10, 5, Blocks.SPRUCE_WOOD.getDefaultState());
        structure.fillWithBlocks(world, start, 17, 9, 8, 17, 10, 8, Blocks.SPRUCE_WOOD.getDefaultState());
        structure.fillWithBlocks(world, start, 17, 11, 7, 17, 13, 7, Blocks.SPRUCE_WOOD.getDefaultState());
        structure.fillWithBlocks(world, start, 18, 2, 21, 19, 2, 22, Blocks.DIRT.getDefaultState());
        structure.fillWithBlocks(world, start, 18, 5, 15, 21, 5, 18, Blocks.DIRT.getDefaultState());
        structure.fillWithBlocks(world, start, 18, 5, 19, 19, 5, 20, Blocks.STONE.getDefaultState());
        structure.fillWithBlocks(world, start, 18, 6, 4, 18, 6, 4, Blocks.GRASS_BLOCK.getDefaultState().with(SnowyDirtBlock.SNOWY, false));
        structure.fillWithBlocks(world, start, 18, 6, 5, 18, 6, 5, Blocks.DIRT.getDefaultState());
        structure.fillWithBlocks(world, start, 18, 6, 6, 18, 6, 10, Blocks.GRASS_BLOCK.getDefaultState().with(SnowyDirtBlock.SNOWY, false));
        structure.fillWithBlocks(world, start, 18, 6, 12, 26, 6, 12, Blocks.GRASS_BLOCK.getDefaultState().with(SnowyDirtBlock.SNOWY, false));
        structure.fillWithBlocks(world, start, 18, 6, 14, 18, 6, 21, Blocks.GRASS_BLOCK.getDefaultState().with(SnowyDirtBlock.SNOWY, false));
        structure.fillWithBlocks(world, start, 18, 7, 5, 18, 8, 5, Blocks.SPRUCE_WOOD.getDefaultState());
        structure.fillWithBlocks(world, start, 18, 9, 6, 18, 10, 6, Blocks.BROWN_WOOL.getDefaultState());
        structure.fillWithBlocks(world, start, 18, 9, 7, 18, 10, 7, Blocks.SPRUCE_WOOD.getDefaultState());
        structure.fillWithBlocks(world, start, 19, 1, 2, 22, 3, 2, Blocks.DIRT.getDefaultState());
        structure.fillWithBlocks(world, start, 19, 1, 21, 20, 1, 22, Blocks.DIRT.getDefaultState());
        structure.fillWithBlocks(world, start, 19, 2, 4, 25, 5, 4, Blocks.DIRT.getDefaultState());
        structure.fillWithBlocks(world, start, 19, 3, 21, 20, 3, 22, Blocks.DIRT.getDefaultState());
        structure.fillWithBlocks(world, start, 19, 4, 2, 22, 4, 2, Blocks.GRASS_BLOCK.getDefaultState().with(SnowyDirtBlock.SNOWY, false));
        structure.fillWithBlocks(world, start, 19, 6, 4, 20, 6, 5, Blocks.GRASS_BLOCK.getDefaultState().with(SnowyDirtBlock.SNOWY, false));
        structure.fillWithBlocks(world, start, 19, 6, 6, 19, 6, 7, Blocks.DIRT.getDefaultState());
        structure.fillWithBlocks(world, start, 19, 6, 8, 20, 6, 12, Blocks.GRASS_BLOCK.getDefaultState().with(SnowyDirtBlock.SNOWY, false));
        structure.fillWithBlocks(world, start, 19, 6, 13, 19, 6, 15, Blocks.DIRT.getDefaultState());
        structure.fillWithBlocks(world, start, 19, 6, 16, 19, 6, 16, Blocks.GRASS_BLOCK.getDefaultState().with(SnowyDirtBlock.SNOWY, false));
        structure.fillWithBlocks(world, start, 19, 6, 18, 21, 6, 21, Blocks.GRASS_BLOCK.getDefaultState().with(SnowyDirtBlock.SNOWY, false));
        structure.fillWithBlocks(world, start, 19, 7, 6, 19, 8, 6, Blocks.BROWN_WOOL.getDefaultState());
        structure.fillWithBlocks(world, start, 19, 7, 7, 19, 8, 7, Blocks.SPRUCE_WOOD.getDefaultState());
        structure.fillWithBlocks(world, start, 19, 7, 13, 20, 7, 13, Blocks.COBBLESTONE_SLAB.getDefaultState().with(SlabBlock.TYPE, SlabType.BOTTOM).with(SlabBlock.WATERLOGGED, false));
        structure.fillWithBlocks(world, start, 19, 7, 18, 19, 7, 18, Blocks.GRASS.getDefaultState());
        structure.fillWithBlocks(world, start, 19, 7, 20, 19, 7, 21, Blocks.GRASS.getDefaultState());
        structure.fillWithBlocks(world, start, 20, 1, 1, 21, 1, 2, Blocks.DIRT.getDefaultState());
        structure.fillWithBlocks(world, start, 20, 2, 1, 23, 2, 4, Blocks.DIRT.getDefaultState());
        structure.fillWithBlocks(world, start, 20, 2, 5, 25, 2, 20, Blocks.STONE.getDefaultState());
        structure.fillWithBlocks(world, start, 20, 2, 21, 21, 2, 22, Blocks.DIRT.getDefaultState());
        structure.fillWithBlocks(world, start, 20, 3, 1, 23, 3, 1, Blocks.GRASS_BLOCK.getDefaultState().with(SnowyDirtBlock.SNOWY, false));
        structure.fillWithBlocks(world, start, 20, 3, 5, 25, 3, 20, Blocks.STONE.getDefaultState());
        structure.fillWithBlocks(world, start, 20, 4, 5, 25, 4, 20, Blocks.STONE.getDefaultState());
        structure.fillWithBlocks(world, start, 20, 5, 19, 21, 5, 20, Blocks.STONE.getDefaultState());
        structure.fillWithBlocks(world, start, 20, 6, 6, 22, 6, 8, Blocks.GRASS_BLOCK.getDefaultState().with(SnowyDirtBlock.SNOWY, false));
        structure.fillWithBlocks(world, start, 20, 6, 13, 21, 6, 13, Blocks.DIRT.getDefaultState());
        structure.fillWithBlocks(world, start, 20, 6, 14, 21, 6, 15, Blocks.NETHERRACK.getDefaultState());
        structure.fillWithBlocks(world, start, 20, 6, 16, 21, 6, 16, Blocks.DIRT.getDefaultState());
        structure.fillWithBlocks(world, start, 20, 6, 17, 21, 6, 21, Blocks.GRASS_BLOCK.getDefaultState().with(SnowyDirtBlock.SNOWY, false));
        structure.fillWithBlocks(world, start, 20, 7, 14, 21, 7, 15, Blocks.FIRE.getDefaultState());
        structure.fillWithBlocks(world, start, 20, 7, 16, 21, 7, 16, Blocks.COBBLESTONE_SLAB.getDefaultState().with(SlabBlock.TYPE, SlabType.BOTTOM).with(SlabBlock.WATERLOGGED, false));
        structure.fillWithBlocks(world, start, 20, 7, 17, 20, 7, 17, Blocks.GRASS.getDefaultState());
        structure.fillWithBlocks(world, start, 20, 7, 19, 20, 7, 19, Blocks.GRASS.getDefaultState());
        structure.fillWithBlocks(world, start, 20, 7, 21, 22, 7, 21, Blocks.GRASS.getDefaultState());
        structure.fillWithBlocks(world, start, 21, 1, 21, 22, 1, 22, Blocks.DIRT.getDefaultState());
        structure.fillWithBlocks(world, start, 21, 3, 21, 22, 3, 22, Blocks.DIRT.getDefaultState());
        structure.fillWithBlocks(world, start, 21, 5, 5, 24, 5, 18, Blocks.DIRT.getDefaultState());
        structure.fillWithBlocks(world, start, 21, 6, 4, 23, 6, 6, Blocks.GRASS_BLOCK.getDefaultState().with(SnowyDirtBlock.SNOWY, false));
        structure.fillWithBlocks(world, start, 21, 6, 11, 22, 6, 12, Blocks.GRASS_BLOCK.getDefaultState().with(SnowyDirtBlock.SNOWY, false));
        structure.fillWithBlocks(world, start, 21, 7, 18, 21, 7, 21, Blocks.GRASS.getDefaultState());
        structure.fillWithBlocks(world, start, 21, 9, 5, 21, 10, 5, Blocks.OAK_LEAVES.getDefaultState().with(LeavesBlock.PERSISTENT, false).with(LeavesBlock.DISTANCE, 4));
        structure.fillWithBlocks(world, start, 21, 9, 6, 21, 10, 6, Blocks.OAK_LEAVES.getDefaultState().with(LeavesBlock.PERSISTENT, false).with(LeavesBlock.DISTANCE, 3));
        structure.fillWithBlocks(world, start, 21, 9, 7, 21, 10, 7, Blocks.OAK_LEAVES.getDefaultState().with(LeavesBlock.PERSISTENT, false).with(LeavesBlock.DISTANCE, 2));
        structure.fillWithBlocks(world, start, 21, 9, 8, 21, 10, 8, Blocks.OAK_LEAVES.getDefaultState().with(LeavesBlock.PERSISTENT, false).with(LeavesBlock.DISTANCE, 3));
        structure.fillWithBlocks(world, start, 22, 1, 1, 24, 1, 3, Blocks.DIRT.getDefaultState());
        structure.fillWithBlocks(world, start, 22, 1, 4, 25, 1, 20, Blocks.STONE.getDefaultState());
        structure.fillWithBlocks(world, start, 22, 2, 21, 23, 2, 22, Blocks.DIRT.getDefaultState());
        structure.fillWithBlocks(world, start, 22, 4, 22, 24, 4, 22, Blocks.GRASS_BLOCK.getDefaultState().with(SnowyDirtBlock.SNOWY, false));
        structure.fillWithBlocks(world, start, 22, 5, 19, 23, 5, 20, Blocks.STONE.getDefaultState());
        structure.fillWithBlocks(world, start, 22, 6, 9, 23, 6, 13, Blocks.GRASS_BLOCK.getDefaultState().with(SnowyDirtBlock.SNOWY, false));
        structure.fillWithBlocks(world, start, 22, 6, 14, 22, 6, 15, Blocks.DIRT.getDefaultState());
        structure.fillWithBlocks(world, start, 22, 6, 16, 23, 6, 17, Blocks.GRASS_BLOCK.getDefaultState().with(SnowyDirtBlock.SNOWY, false));
        structure.fillWithBlocks(world, start, 22, 6, 19, 23, 6, 20, Blocks.GRASS_BLOCK.getDefaultState().with(SnowyDirtBlock.SNOWY, false));
        structure.fillWithBlocks(world, start, 22, 7, 10, 22, 7, 11, Blocks.GRASS.getDefaultState());
        structure.fillWithBlocks(world, start, 22, 9, 5, 22, 10, 5, Blocks.OAK_LEAVES.getDefaultState().with(LeavesBlock.PERSISTENT, false).with(LeavesBlock.DISTANCE, 3));
        structure.fillWithBlocks(world, start, 22, 9, 6, 22, 10, 6, Blocks.OAK_LEAVES.getDefaultState().with(LeavesBlock.PERSISTENT, false).with(LeavesBlock.DISTANCE, 2));
        structure.fillWithBlocks(world, start, 22, 9, 7, 22, 11, 7, Blocks.OAK_LEAVES.getDefaultState().with(LeavesBlock.PERSISTENT, false).with(LeavesBlock.DISTANCE, 1));
        structure.fillWithBlocks(world, start, 22, 9, 8, 22, 10, 8, Blocks.OAK_LEAVES.getDefaultState().with(LeavesBlock.PERSISTENT, false).with(LeavesBlock.DISTANCE, 2));
        structure.fillWithBlocks(world, start, 22, 9, 9, 22, 10, 9, Blocks.OAK_LEAVES.getDefaultState().with(LeavesBlock.PERSISTENT, false).with(LeavesBlock.DISTANCE, 3));
        structure.fillWithBlocks(world, start, 22, 12, 7, 22, 12, 7, Blocks.OAK_LEAVES.getDefaultState().with(LeavesBlock.PERSISTENT, false).with(LeavesBlock.DISTANCE, 2));
        structure.fillWithBlocks(world, start, 23, 1, 21, 24, 1, 21, Blocks.STONE.getDefaultState());
        structure.fillWithBlocks(world, start, 23, 1, 22, 25, 2, 22, Blocks.DIRT.getDefaultState());
        structure.fillWithBlocks(world, start, 23, 3, 2, 25, 3, 2, Blocks.GRASS_BLOCK.getDefaultState().with(SnowyDirtBlock.SNOWY, false));
        structure.fillWithBlocks(world, start, 23, 3, 21, 24, 3, 22, Blocks.DIRT.getDefaultState());
        structure.fillWithBlocks(world, start, 23, 5, 21, 25, 5, 21, Blocks.GRASS_BLOCK.getDefaultState().with(SnowyDirtBlock.SNOWY, false));
        structure.fillWithBlocks(world, start, 23, 6, 8, 25, 6, 10, Blocks.GRASS_BLOCK.getDefaultState().with(SnowyDirtBlock.SNOWY, false));
        structure.fillWithBlocks(world, start, 23, 6, 14, 23, 6, 20, Blocks.GRASS_BLOCK.getDefaultState().with(SnowyDirtBlock.SNOWY, false));
        structure.fillWithBlocks(world, start, 23, 7, 7, 23, 11, 7, Blocks.OAK_LOG.getDefaultState());
        structure.fillWithBlocks(world, start, 23, 7, 19, 23, 7, 20, Blocks.GRASS.getDefaultState());
        structure.fillWithBlocks(world, start, 23, 9, 5, 23, 10, 5, Blocks.OAK_LEAVES.getDefaultState().with(LeavesBlock.PERSISTENT, false).with(LeavesBlock.DISTANCE, 2));
        structure.fillWithBlocks(world, start, 23, 9, 6, 23, 11, 6, Blocks.OAK_LEAVES.getDefaultState().with(LeavesBlock.PERSISTENT, false).with(LeavesBlock.DISTANCE, 1));
        structure.fillWithBlocks(world, start, 23, 9, 8, 23, 11, 8, Blocks.OAK_LEAVES.getDefaultState().with(LeavesBlock.PERSISTENT, false).with(LeavesBlock.DISTANCE, 1));
        structure.fillWithBlocks(world, start, 23, 9, 9, 23, 10, 9, Blocks.OAK_LEAVES.getDefaultState().with(LeavesBlock.PERSISTENT, false).with(LeavesBlock.DISTANCE, 2));
        structure.fillWithBlocks(world, start, 23, 12, 6, 23, 12, 6, Blocks.OAK_LEAVES.getDefaultState().with(LeavesBlock.PERSISTENT, false).with(LeavesBlock.DISTANCE, 2));
        structure.fillWithBlocks(world, start, 24, 0, 1, 26, 1, 1, Blocks.DIRT.getDefaultState());
        structure.fillWithBlocks(world, start, 24, 0, 2, 25, 0, 22, Blocks.STONE.getDefaultState());
        structure.fillWithBlocks(world, start, 24, 2, 1, 26, 2, 1, Blocks.GRASS_BLOCK.getDefaultState().with(SnowyDirtBlock.SNOWY, false));
        structure.fillWithBlocks(world, start, 24, 2, 2, 25, 2, 4, Blocks.DIRT.getDefaultState());
        structure.fillWithBlocks(world, start, 24, 2, 21, 25, 2, 22, Blocks.DIRT.getDefaultState());
        structure.fillWithBlocks(world, start, 24, 5, 19, 25, 5, 20, Blocks.STONE.getDefaultState());
        structure.fillWithBlocks(world, start, 24, 6, 4, 25, 6, 10, Blocks.GRASS_BLOCK.getDefaultState().with(SnowyDirtBlock.SNOWY, false));
        structure.fillWithBlocks(world, start, 24, 6, 13, 25, 6, 14, Blocks.GRASS_BLOCK.getDefaultState().with(SnowyDirtBlock.SNOWY, false));
        structure.fillWithBlocks(world, start, 24, 6, 16, 26, 6, 19, Blocks.GRASS_BLOCK.getDefaultState().with(SnowyDirtBlock.SNOWY, false));
        structure.fillWithBlocks(world, start, 24, 6, 20, 25, 6, 20, Blocks.GRASS_BLOCK.getDefaultState().with(SnowyDirtBlock.SNOWY, false));
        structure.fillWithBlocks(world, start, 24, 9, 5, 24, 10, 5, Blocks.OAK_LEAVES.getDefaultState().with(LeavesBlock.PERSISTENT, false).with(LeavesBlock.DISTANCE, 3));
        structure.fillWithBlocks(world, start, 24, 9, 6, 24, 11, 6, Blocks.OAK_LEAVES.getDefaultState().with(LeavesBlock.PERSISTENT, false).with(LeavesBlock.DISTANCE, 2));
        structure.fillWithBlocks(world, start, 24, 9, 7, 24, 11, 7, Blocks.OAK_LEAVES.getDefaultState().with(LeavesBlock.PERSISTENT, false).with(LeavesBlock.DISTANCE, 1));
        structure.fillWithBlocks(world, start, 24, 9, 8, 24, 11, 8, Blocks.OAK_LEAVES.getDefaultState().with(LeavesBlock.PERSISTENT, false).with(LeavesBlock.DISTANCE, 2));
        structure.fillWithBlocks(world, start, 24, 9, 9, 24, 10, 9, Blocks.OAK_LEAVES.getDefaultState().with(LeavesBlock.PERSISTENT, false).with(LeavesBlock.DISTANCE, 3));
        structure.fillWithBlocks(world, start, 25, 1, 2, 26, 1, 3, Blocks.DIRT.getDefaultState());
        structure.fillWithBlocks(world, start, 25, 1, 21, 26, 1, 22, Blocks.DIRT.getDefaultState());
        structure.fillWithBlocks(world, start, 25, 3, 3, 25, 3, 4, Blocks.DIRT.getDefaultState());
        structure.fillWithBlocks(world, start, 25, 3, 21, 26, 3, 21, Blocks.DIRT.getDefaultState());
        structure.fillWithBlocks(world, start, 25, 5, 5, 25, 5, 20, Blocks.STONE.getDefaultState());
        structure.fillWithBlocks(world, start, 25, 6, 11, 26, 6, 19, Blocks.GRASS_BLOCK.getDefaultState().with(SnowyDirtBlock.SNOWY, false));
        structure.fillWithBlocks(world, start, 25, 9, 5, 25, 10, 5, Blocks.OAK_LEAVES.getDefaultState().with(LeavesBlock.PERSISTENT, false).with(LeavesBlock.DISTANCE, 4));
        structure.fillWithBlocks(world, start, 25, 9, 6, 25, 10, 6, Blocks.OAK_LEAVES.getDefaultState().with(LeavesBlock.PERSISTENT, false).with(LeavesBlock.DISTANCE, 3));
        structure.fillWithBlocks(world, start, 25, 9, 7, 25, 10, 7, Blocks.OAK_LEAVES.getDefaultState().with(LeavesBlock.PERSISTENT, false).with(LeavesBlock.DISTANCE, 2));
        structure.fillWithBlocks(world, start, 25, 9, 8, 25, 10, 8, Blocks.OAK_LEAVES.getDefaultState().with(LeavesBlock.PERSISTENT, false).with(LeavesBlock.DISTANCE, 3));
        structure.fillWithBlocks(world, start, 25, 9, 9, 25, 10, 9, Blocks.OAK_LEAVES.getDefaultState().with(LeavesBlock.PERSISTENT, false).with(LeavesBlock.DISTANCE, 4));
        structure.fillWithBlocks(world, start, 26, 0, 2, 26, 0, 2, Blocks.DIRT.getDefaultState());
        structure.fillWithBlocks(world, start, 26, 0, 3, 26, 0, 21, Blocks.STONE.getDefaultState());
        structure.fillWithBlocks(world, start, 26, 0, 22, 27, 1, 22, Blocks.DIRT.getDefaultState());
        structure.fillWithBlocks(world, start, 26, 1, 4, 27, 1, 22, Blocks.DIRT.getDefaultState());
        structure.fillWithBlocks(world, start, 26, 2, 2, 26, 2, 2, Blocks.GRASS_BLOCK.getDefaultState().with(SnowyDirtBlock.SNOWY, false));
        structure.fillWithBlocks(world, start, 26, 2, 3, 26, 2, 21, Blocks.DIRT.getDefaultState());
        structure.fillWithBlocks(world, start, 26, 2, 22, 27, 2, 22, Blocks.GRASS_BLOCK.getDefaultState().with(SnowyDirtBlock.SNOWY, false));
        structure.fillWithBlocks(world, start, 26, 3, 4, 27, 3, 19, Blocks.DIRT.getDefaultState());
        structure.fillWithBlocks(world, start, 26, 3, 20, 26, 3, 21, Blocks.DIRT.getDefaultState());
        structure.fillWithBlocks(world, start, 26, 4, 5, 27, 4, 19, Blocks.DIRT.getDefaultState());
        structure.fillWithBlocks(world, start, 26, 5, 4, 26, 5, 5, Blocks.GRASS_BLOCK.getDefaultState().with(SnowyDirtBlock.SNOWY, false));
        structure.fillWithBlocks(world, start, 26, 5, 6, 26, 5, 19, Blocks.DIRT.getDefaultState());
        structure.fillWithBlocks(world, start, 26, 6, 6, 26, 6, 19, Blocks.GRASS_BLOCK.getDefaultState().with(SnowyDirtBlock.SNOWY, false));
        structure.fillWithBlocks(world, start, 27, 0, 1, 27, 0, 3, Blocks.DIRT.getDefaultState());
        structure.fillWithBlocks(world, start, 27, 0, 4, 27, 0, 20, Blocks.STONE.getDefaultState());
        structure.fillWithBlocks(world, start, 27, 0, 21, 27, 1, 22, Blocks.DIRT.getDefaultState());
        structure.fillWithBlocks(world, start, 27, 1, 2, 27, 1, 22, Blocks.DIRT.getDefaultState());
        structure.fillWithBlocks(world, start, 27, 2, 2, 27, 2, 3, Blocks.GRASS_BLOCK.getDefaultState().with(SnowyDirtBlock.SNOWY, false));
        structure.fillWithBlocks(world, start, 27, 2, 4, 27, 3, 19, Blocks.DIRT.getDefaultState());
        structure.fillWithBlocks(world, start, 27, 2, 21, 27, 2, 22, Blocks.GRASS_BLOCK.getDefaultState().with(SnowyDirtBlock.SNOWY, false));
        structure.fillWithBlocks(world, start, 27, 5, 5, 27, 5, 19, Blocks.GRASS_BLOCK.getDefaultState().with(SnowyDirtBlock.SNOWY, false));

    }
}
